#######################################################################
# +-----------------------------------------------------------------+ #
# |                            BO3 object                           | #
# +-----------------------------------------------------------------+ #
#######################################################################

# The descriptions in this file are accurate only for TerrainControl and OTG.
# For MCW and OTG+ these descriptions are only accurate if the BO3 is used as a CustomObject.
# MCW and OTG+ completely reimplemented CustomStructure, check the MCW/OTG+ documentation for more information.

# This is the config file of a custom object.
# If you add this object correctly to your BiomeConfigs, it will spawn in the world.

# This is the creator of this BO3 object
Author: Unknown

# A short description of this BO3 object
Description: This BO3 was converted from a schematic using OTGEdit. The author and description information of the schematic could not be found. If you know who the author of the schematic is then please add this information.

# The BO3 version, don't change this! It can be used by external applications to do a version check.
Version: 3

# The settings mode, WriteAll, WriteWithoutComments or WriteDisable. See WorldConfig.
SettingsMode: WriteDisable

#######################################################################
# +-----------------------------------------------------------------+ #
# |                          Main settings                          | #
# +-----------------------------------------------------------------+ #
#######################################################################

# This needs to be set to true to spawn the object in the Tree and Sapling resources.
Tree: true

# The frequency of the BO3 from 1 to 200. Tries this many times to spawn this BO3 when using the CustomObject(...) resource.
# Ignored by Tree(..), Sapling(..) and CustomStructure(..)
Frequency: 40

# The rarity of the BO3 from 0 to 100. Each spawn attempt has rarity% chance to succeed when using the CustomObject(...) resource.
# Ignored by Tree(..), Sapling(..) and CustomStructure(..)
Rarity: 100.0

# If you set this to true, the BO3 will be placed with a random rotation.
RotateRandomly: true

# The spawn height of the BO3 - randomY, highestBlock or highestSolidBlock.
SpawnHeight: highestBlock

# The height limits for the BO3.
MinHeight: 63

MaxHeight: 80

# Objects can have other objects attached to it: branches. Branches can also
# have branches attached to it, which can also have branches, etc. This is the
# maximum branch depth for this objects.
MaxBranchDepth: 10

# When spawned with the UseWorld keyword, this BO3 should NOT spawn in the following biomes.
# If you writer.write the BO3 name directly in the BiomeConfigs, this will be ignored.
ExcludedBiomes: All

# To optimise this BO3 for faster loading times you can use Notepad++ to find/replace comments and abbreviate things.
# Notepad++ find/replace with regex:
# Find: ^[#;].* replace to nothing removes all lines starting with # 
# Find: ^\s*$ replace to nothing removes most empty lines 
# Notepad++ find/replace without regex:
# *Warning: This will only work for OTG 1.10.2 v21 / OTG 1.11.2 v6 or higher. B( is not recognised by lower versions.
# Find: Block( replace to B(

#######################################################################
# +-----------------------------------------------------------------+ #
# |                      Source block settings                      | #
# +-----------------------------------------------------------------+ #
#######################################################################

# The block(s) the BO3 should spawn in.
SourceBlocks: STONE:1,STONE:3,STONE:5,DIRT:1,DIRT,SAND,GRASS,DIRT:2,HARD_CLAY,STAINED_CLAY,CLAY,SANDSTONE,SAND:1,AIR,STONE,GRAVEL,LONG_GRASS,LONG_GRASS:1,LONG_GRASS:2,DEAD_BUSH,YELLOW_FLOWER,RED_ROSE,BROWN_MUSHROOM,RED_MUSHROOM
# The maximum percentage of the BO3 that can be outside the SourceBlock.
# The BO3 won't be placed on a location with more blocks outside the SourceBlock than this percentage.
MaxPercentageOutsideSourceBlock: 0

# What to do when a block is about to be placed outside the SourceBlock? (dontPlace, placeAnyway)
OutsideSourceBlock: placeAnyway

#######################################################################
# +-----------------------------------------------------------------+ #
# |                              Blocks                             | #
# +-----------------------------------------------------------------+ #
#######################################################################

# All the blocks used in the BO3 are listed here. Possible blocks:
# Block(x,y,z,id[.data][,nbtfile.nbt) or B(x,y,z,id[.data][,nbtfile.nbt)
# RandomBlock(x,y,z,id[:data][,nbtfile.nbt],chance[,id[:data][,nbtfile.nbt],chance[,...]])
# So RandomBlock(0,0,0,CHEST,chest.nbt,50,CHEST,anotherchest.nbt,100) will spawn a chest at
# the BO3 origin, and give it a 50% chance to have the contents of chest.nbt, or, if that
# fails, a 100% percent chance to have the contents of anotherchest.nbt.

Block(-14,2,2,LEAVES:0)
Block(-13,1,-3,LEAVES:0)
Block(-13,2,1,LEAVES:0)
Block(-13,2,2,LEAVES:0)
Block(-13,3,4,LEAVES:0)
Block(-13,4,1,LEAVES:0)
Block(-13,4,3,LEAVES:0)
Block(-12,1,-4,LEAVES:0)
Block(-12,1,-3,LEAVES:0)
Block(-12,2,-1,LEAVES:0)
Block(-12,2,0,LEAVES:0)
Block(-12,2,1,LEAVES:0)
Block(-12,3,-4,LEAVES:0)
Block(-12,3,-2,LEAVES:0)
Block(-12,3,-1,LEAVES:0)
Block(-12,3,2,LEAVES:0)
Block(-12,3,3,LEAVES:0)
Block(-12,3,4,LEAVES:0)
Block(-12,3,5,LEAVES:0)
Block(-12,4,1,LEAVES:0)
Block(-12,5,2,LEAVES:0)
Block(-11,1,-5,LEAVES:0)
Block(-11,1,-4,LEAVES:0)
Block(-11,2,-6,LEAVES:0)
Block(-11,2,-3,LEAVES:0)
Block(-11,2,-2,LEAVES:0)
Block(-11,2,-1,LEAVES:0)
Block(-11,2,0,LEAVES:0)
Block(-11,3,-4,LEAVES:0)
Block(-11,3,0,LEAVES:0)
Block(-11,3,3,LEAVES:0)
Block(-11,4,-3,LEAVES:0)
Block(-11,4,0,LEAVES:0)
Block(-11,4,1,LEAVES:0)
Block(-11,4,3,LEAVES:0)
Block(-11,4,4,LEAVES:0)
Block(-11,4,7,LEAVES:0)
Block(-11,5,2,LEAVES:0)
Block(-11,6,-1,LEAVES:0)
Block(-11,6,2,LEAVES:0)
Block(-11,6,3,LEAVES:0)
Block(-10,1,-5,LEAVES:0)
Block(-10,2,-5,LEAVES:0)
Block(-10,2,-2,LEAVES:0)
Block(-10,3,-9,LEAVES:0)
Block(-10,3,-5,LEAVES:0)
Block(-10,3,-4,LEAVES:0)
Block(-10,3,-2,LEAVES:0)
Block(-10,3,-1,LEAVES:0)
Block(-10,3,1,LEAVES:0)
Block(-10,4,-3,LEAVES:0)
Block(-10,4,-1,LEAVES:0)
Block(-10,4,1,LEAVES:0)
Block(-10,4,2,17:12)
Block(-10,4,3,LEAVES:0)
Block(-10,4,6,LEAVES:0)
Block(-10,4,7,LEAVES:0)
Block(-10,5,-3,LEAVES:0)
Block(-10,5,-2,LEAVES:0)
Block(-10,5,1,LEAVES:0)
Block(-10,5,2,LEAVES:0)
Block(-10,5,9,LEAVES:0)
Block(-10,6,-2,LEAVES:0)
Block(-10,6,-1,LEAVES:0)
Block(-10,6,0,LEAVES:0)
Block(-10,6,2,LEAVES:0)
Block(-10,6,6,LEAVES:0)
Block(-10,6,8,LEAVES:0)
Block(-10,7,1,LEAVES:0)
Block(-10,8,-2,LEAVES:0)
Block(-10,8,0,LEAVES:0)
Block(-9,2,-4,LEAVES:0)
Block(-9,3,-10,LEAVES:0)
Block(-9,3,-9,LEAVES:0)
Block(-9,3,-6,LEAVES:0)
Block(-9,3,-4,LEAVES:0)
Block(-9,3,-3,17:12)
Block(-9,3,-2,LEAVES:0)
Block(-9,3,3,LEAVES:0)
Block(-9,4,-7,LEAVES:0)
Block(-9,4,-4,LEAVES:0)
Block(-9,4,-3,LEAVES:0)
Block(-9,4,0,LEAVES:0)
Block(-9,4,1,LEAVES:0)
Block(-9,4,2,17:12)
Block(-9,4,3,LEAVES:0)
Block(-9,4,4,LEAVES:0)
Block(-9,4,5,LEAVES:0)
Block(-9,4,6,LEAVES:0)
Block(-9,5,-10,LEAVES:0)
Block(-9,5,-8,LEAVES:0)
Block(-9,5,-5,LEAVES:0)
Block(-9,5,-3,LEAVES:0)
Block(-9,5,4,LEAVES:0)
Block(-9,5,5,LEAVES:0)
Block(-9,5,7,LEAVES:0)
Block(-9,5,8,LEAVES:0)
Block(-9,5,9,LEAVES:0)
Block(-9,5,10,LEAVES:0)
Block(-9,6,-3,LEAVES:0)
Block(-9,6,-2,LEAVES:0)
Block(-9,6,2,LEAVES:0)
Block(-9,6,3,LEAVES:0)
Block(-9,6,6,LEAVES:0)
Block(-9,7,-4,LEAVES:0)
Block(-9,7,-1,LEAVES:0)
Block(-9,7,0,LEAVES:0)
Block(-9,7,1,LEAVES:0)
Block(-9,7,2,LEAVES:0)
Block(-9,7,7,LEAVES:0)
Block(-9,8,-2,LEAVES:0)
Block(-9,9,-1,LEAVES:0)
Block(-8,2,-2,LEAVES:0)
Block(-8,3,-11,LEAVES:0)
Block(-8,3,-10,LEAVES:0)
Block(-8,3,-5,LEAVES:0)
Block(-8,3,-4,LEAVES:0)
Block(-8,3,-3,17:12)
Block(-8,3,-2,LEAVES:0)
Block(-8,3,-1,LEAVES:0)
Block(-8,4,-12,LEAVES:0)
Block(-8,4,-9,LEAVES:0)
Block(-8,4,-8,LEAVES:0)
Block(-8,4,-7,LEAVES:0)
Block(-8,4,-6,LEAVES:0)
Block(-8,4,-1,LEAVES:0)
Block(-8,4,0,LEAVES:0)
Block(-8,4,1,17:12)
Block(-8,4,2,17:12)
Block(-8,4,3,LEAVES:0)
Block(-8,4,4,LEAVES:0)
Block(-8,4,5,LEAVES:0)
Block(-8,5,-10,LEAVES:0)
Block(-8,5,-3,LEAVES:0)
Block(-8,5,-2,LEAVES:0)
Block(-8,5,0,LEAVES:0)
Block(-8,5,5,LEAVES:0)
Block(-8,5,8,LEAVES:0)
Block(-8,6,-9,LEAVES:0)
Block(-8,6,-3,LEAVES:0)
Block(-8,6,3,LEAVES:0)
Block(-8,6,5,LEAVES:0)
Block(-8,6,6,LEAVES:0)
Block(-8,6,8,LEAVES:0)
Block(-8,6,9,LEAVES:0)
Block(-8,7,-3,LEAVES:0)
Block(-8,7,0,LEAVES:0)
Block(-8,7,5,LEAVES:0)
Block(-8,7,7,LEAVES:0)
Block(-8,8,-3,LEAVES:0)
Block(-8,8,-2,LEAVES:0)
Block(-8,8,0,LEAVES:0)
Block(-8,8,1,LEAVES:0)
Block(-8,8,7,LEAVES:0)
Block(-8,8,8,LEAVES:0)
Block(-8,9,-1,LEAVES:0)
Block(-8,10,-1,LEAVES:0)
Block(-8,10,0,LEAVES:0)
Block(-7,2,-6,LEAVES:0)
Block(-7,3,-11,LEAVES:0)
Block(-7,3,-6,LEAVES:0)
Block(-7,3,-5,LEAVES:0)
Block(-7,3,-3,LEAVES:0)
Block(-7,3,-2,LEAVES:0)
Block(-7,3,-1,LEAVES:0)
Block(-7,4,-11,LEAVES:0)
Block(-7,4,-8,LEAVES:0)
Block(-7,4,-5,LEAVES:0)
Block(-7,4,-3,LEAVES:0)
Block(-7,4,-2,17:12)
Block(-7,4,1,17:12)
Block(-7,5,-11,LEAVES:0)
Block(-7,5,-10,LEAVES:0)
Block(-7,5,-8,LEAVES:0)
Block(-7,5,-7,LEAVES:0)
Block(-7,5,-2,LEAVES:0)
Block(-7,5,0,17:12)
Block(-7,5,1,17:12)
Block(-7,5,2,17:12)
Block(-7,5,3,17:12)
Block(-7,5,6,LEAVES:0)
Block(-7,6,-9,LEAVES:0)
Block(-7,6,4,LEAVES:0)
Block(-7,6,5,17:12)
Block(-7,6,6,17:12)
Block(-7,6,7,17:12)
Block(-7,6,8,LEAVES:0)
Block(-7,7,-9,LEAVES:0)
Block(-7,7,-8,LEAVES:0)
Block(-7,7,-2,LEAVES:0)
Block(-7,7,4,LEAVES:0)
Block(-7,7,5,LEAVES:0)
Block(-7,7,6,LEAVES:0)
Block(-7,7,7,LEAVES:0)
Block(-7,8,-4,LEAVES:0)
Block(-7,8,-2,LEAVES:0)
Block(-7,8,-1,17:12)
Block(-7,8,0,LEAVES:0)
Block(-7,8,1,LEAVES:0)
Block(-7,8,5,LEAVES:0)
Block(-7,8,7,LEAVES:0)
Block(-7,9,-2,LEAVES:0)
Block(-7,9,-1,LEAVES:0)
Block(-7,9,4,LEAVES:0)
Block(-7,9,6,LEAVES:0)
Block(-7,10,-3,LEAVES:0)
Block(-7,10,-1,LEAVES:0)
Block(-6,4,-10,LEAVES:0)
Block(-6,4,-5,LEAVES:0)
Block(-6,4,-3,LEAVES:0)
Block(-6,4,-2,17:12)
Block(-6,5,-12,LEAVES:0)
Block(-6,5,-10,LEAVES:0)
Block(-6,5,-9,17:12)
Block(-6,5,-8,17:12)
Block(-6,5,-7,17:12)
Block(-6,5,-1,17:12)
Block(-6,5,0,17:12)
Block(-6,5,3,17:12)
Block(-6,5,4,LEAVES:0)
Block(-6,5,8,LEAVES:0)
Block(-6,6,-10,LEAVES:0)
Block(-6,6,-9,LEAVES:0)
Block(-6,6,4,LEAVES:0)
Block(-6,6,5,17:12)
Block(-6,6,6,LEAVES:0)
Block(-6,6,8,LEAVES:0)
Block(-6,6,9,LEAVES:0)
Block(-6,7,-11,LEAVES:0)
Block(-6,7,-9,LEAVES:0)
Block(-6,7,-5,LEAVES:0)
Block(-6,7,-1,LEAVES:0)
Block(-6,7,0,LEAVES:0)
Block(-6,7,3,LEAVES:0)
Block(-6,7,4,LEAVES:0)
Block(-6,7,10,LEAVES:0)
Block(-6,8,-3,LEAVES:0)
Block(-6,8,-2,LEAVES:0)
Block(-6,8,-1,LEAVES:0)
Block(-6,8,0,LEAVES:0)
Block(-6,8,1,LEAVES:0)
Block(-6,8,2,LEAVES:0)
Block(-6,8,5,LEAVES:0)
Block(-6,8,6,LEAVES:0)
Block(-6,8,7,LEAVES:0)
Block(-6,8,8,LEAVES:0)
Block(-6,9,2,LEAVES:0)
Block(-6,9,3,LEAVES:0)
Block(-6,9,4,LEAVES:0)
Block(-6,10,-1,LEAVES:0)
Block(-6,10,0,LEAVES:0)
Block(-6,10,2,LEAVES:0)
Block(-6,10,5,LEAVES:0)
Block(-5,4,-8,LEAVES:0)
Block(-5,4,-2,17:12)
Block(-5,5,-11,LEAVES:0)
Block(-5,5,-10,LEAVES:0)
Block(-5,5,-8,LEAVES:0)
Block(-5,5,-7,LEAVES:0)
Block(-5,5,-2,17:12)
Block(-5,5,-1,17:12)
Block(-5,5,4,LEAVES:0)
Block(-5,6,-7,LEAVES:0)
Block(-5,6,-6,17:12)
Block(-5,6,-5,17:12)
Block(-5,6,4,LEAVES:0)
Block(-5,6,5,LEAVES:0)
Block(-5,6,7,LEAVES:0)
Block(-5,6,8,LEAVES:0)
Block(-5,6,9,LEAVES:0)
Block(-5,7,-9,LEAVES:0)
Block(-5,7,-8,LEAVES:0)
Block(-5,7,-6,LEAVES:0)
Block(-5,7,-5,LEAVES:0)
Block(-5,7,-4,LEAVES:0)
Block(-5,7,-2,17:12)
Block(-5,7,-1,17:12)
Block(-5,7,3,LEAVES:0)
Block(-5,7,5,LEAVES:0)
Block(-5,8,-4,LEAVES:0)
Block(-5,8,-3,LEAVES:0)
Block(-5,8,-1,LEAVES:0)
Block(-5,8,0,LEAVES:0)
Block(-5,8,1,LEAVES:0)
Block(-5,8,3,LEAVES:0)
Block(-5,8,6,LEAVES:0)
Block(-5,8,8,LEAVES:0)
Block(-5,9,-6,LEAVES:0)
Block(-5,9,-4,LEAVES:0)
Block(-5,9,-3,LEAVES:0)
Block(-5,9,-2,LEAVES:0)
Block(-5,9,1,LEAVES:0)
Block(-5,9,2,LEAVES:0)
Block(-5,9,3,LEAVES:0)
Block(-5,9,4,LEAVES:0)
Block(-5,9,6,LEAVES:0)
Block(-5,9,7,LEAVES:0)
Block(-5,10,0,LEAVES:0)
Block(-5,10,5,LEAVES:0)
Block(-5,11,1,LEAVES:0)
Block(-5,11,5,LEAVES:0)
Block(-5,11,6,LEAVES:0)
Block(-4,4,-12,LEAVES:0)
Block(-4,5,-12,LEAVES:0)
Block(-4,5,-11,LEAVES:0)
Block(-4,5,-9,LEAVES:0)
Block(-4,5,-8,LEAVES:0)
Block(-4,5,-7,LEAVES:0)
Block(-4,5,-4,17:12)
Block(-4,5,-2,17:12)
Block(-4,6,-11,LEAVES:0)
Block(-4,6,-5,17:12)
Block(-4,6,-4,LEAVES:0)
Block(-4,6,-2,17:12)
Block(-4,6,7,LEAVES:0)
Block(-4,7,-8,LEAVES:0)
Block(-4,7,-7,LEAVES:0)
Block(-4,7,-6,LEAVES:0)
Block(-4,7,-2,17:12)
Block(-4,7,5,LEAVES:0)
Block(-4,7,7,LEAVES:0)
Block(-4,8,-8,LEAVES:0)
Block(-4,8,-5,LEAVES:0)
Block(-4,8,-4,LEAVES:0)
Block(-4,8,-3,LEAVES:0)
Block(-4,8,-2,LEAVES:0)
Block(-4,8,-1,LEAVES:0)
Block(-4,8,4,17:12)
Block(-4,8,5,LEAVES:0)
Block(-4,9,-6,LEAVES:0)
Block(-4,9,-3,LEAVES:0)
Block(-4,9,-1,LEAVES:0)
Block(-4,9,2,LEAVES:0)
Block(-4,9,4,LEAVES:0)
Block(-4,9,5,LEAVES:0)
Block(-4,9,6,LEAVES:0)
Block(-4,10,-5,LEAVES:0)
Block(-4,10,-1,LEAVES:0)
Block(-4,10,0,LEAVES:0)
Block(-4,10,2,LEAVES:0)
Block(-4,10,3,LEAVES:0)
Block(-4,10,4,LEAVES:0)
Block(-4,10,5,LEAVES:0)
Block(-4,11,1,LEAVES:0)
Block(-4,11,3,LEAVES:0)
Block(-4,11,5,LEAVES:0)
Block(-4,12,1,LEAVES:0)
Block(-4,12,2,LEAVES:0)
Block(-3,5,-9,LEAVES:0)
Block(-3,5,-8,LEAVES:0)
Block(-3,5,-4,17:12)
Block(-3,5,-3,17:12)
Block(-3,5,-2,17:12)
Block(-3,6,-11,LEAVES:0)
Block(-3,6,-9,LEAVES:0)
Block(-3,6,-6,LEAVES:0)
Block(-3,6,1,17:12)
Block(-3,6,3,17:12)
Block(-3,6,6,LEAVES:0)
Block(-3,6,7,LEAVES:0)
Block(-3,7,-9,LEAVES:0)
Block(-3,7,-7,LEAVES:0)
Block(-3,7,1,17:12)
Block(-3,7,3,17:12)
Block(-3,7,4,LEAVES:0)
Block(-3,7,9,LEAVES:0)
Block(-3,8,-7,LEAVES:0)
Block(-3,8,-4,LEAVES:0)
Block(-3,8,-2,LEAVES:0)
Block(-3,8,1,17:12)
Block(-3,8,4,LEAVES:0)
Block(-3,8,6,LEAVES:0)
Block(-3,8,8,LEAVES:0)
Block(-3,9,-7,LEAVES:0)
Block(-3,9,-6,LEAVES:0)
Block(-3,9,-4,LEAVES:0)
Block(-3,9,-3,LEAVES:0)
Block(-3,9,0,LEAVES:0)
Block(-3,9,1,17:12)
Block(-3,9,3,LEAVES:0)
Block(-3,9,4,LEAVES:0)
Block(-3,9,6,LEAVES:0)
Block(-3,9,7,LEAVES:0)
Block(-3,10,-5,LEAVES:0)
Block(-3,10,-2,LEAVES:0)
Block(-3,10,0,LEAVES:0)
Block(-3,10,1,17:12)
Block(-3,10,2,LEAVES:0)
Block(-3,10,8,LEAVES:0)
Block(-3,11,-5,LEAVES:0)
Block(-3,11,-4,LEAVES:0)
Block(-3,11,0,LEAVES:0)
Block(-3,11,1,LEAVES:0)
Block(-3,11,5,LEAVES:0)
Block(-3,11,6,LEAVES:0)
Block(-3,12,-1,LEAVES:0)
Block(-3,12,1,LEAVES:0)
Block(-2,1,8,LEAVES:0)
Block(-2,3,0,17:12)
Block(-2,3,1,17:12)
Block(-2,4,-3,17:12)
Block(-2,4,-2,17:12)
Block(-2,4,1,17:12)
Block(-2,5,-10,LEAVES:0)
Block(-2,5,-9,LEAVES:0)
Block(-2,5,-3,17:12)
Block(-2,5,1,17:12)
Block(-2,5,2,17:12)
Block(-2,5,3,17:12)
Block(-2,6,-11,LEAVES:0)
Block(-2,6,-8,LEAVES:0)
Block(-2,6,-7,LEAVES:0)
Block(-2,6,-6,LEAVES:0)
Block(-2,6,-5,LEAVES:0)
Block(-2,6,-3,17:12)
Block(-2,6,1,17:12)
Block(-2,6,3,17:12)
Block(-2,6,5,LEAVES:0)
Block(-2,6,6,LEAVES:0)
Block(-2,7,-9,LEAVES:0)
Block(-2,7,-3,17:12)
Block(-2,7,4,LEAVES:0)
Block(-2,7,7,LEAVES:0)
Block(-2,7,8,LEAVES:0)
Block(-2,7,9,LEAVES:0)
Block(-2,7,10,LEAVES:0)
Block(-2,8,-8,LEAVES:0)
Block(-2,8,-6,LEAVES:0)
Block(-2,8,-4,LEAVES:0)
Block(-2,8,-3,17:12)
Block(-2,8,-2,LEAVES:0)
Block(-2,8,2,LEAVES:0)
Block(-2,8,6,LEAVES:0)
Block(-2,9,-8,LEAVES:0)
Block(-2,9,-6,LEAVES:0)
Block(-2,9,-5,17:12)
Block(-2,9,-4,LEAVES:0)
Block(-2,9,0,LEAVES:0)
Block(-2,9,2,LEAVES:0)
Block(-2,9,3,LEAVES:0)
Block(-2,9,5,LEAVES:0)
Block(-2,9,6,LEAVES:0)
Block(-2,9,7,LEAVES:0)
Block(-2,10,-6,LEAVES:0)
Block(-2,10,-5,LEAVES:0)
Block(-2,10,-3,LEAVES:0)
Block(-2,10,-1,LEAVES:0)
Block(-2,10,0,LEAVES:0)
Block(-2,10,1,17:12)
Block(-2,10,2,LEAVES:0)
Block(-2,10,3,LEAVES:0)
Block(-2,11,-7,LEAVES:0)
Block(-2,11,-5,LEAVES:0)
Block(-2,11,1,17:12)
Block(-2,11,4,LEAVES:0)
Block(-2,11,6,LEAVES:0)
Block(-2,12,1,LEAVES:0)
Block(-2,12,2,LEAVES:0)
Block(-1,0,-1,17:12)
Block(-1,0,0,17:12)
Block(-1,1,-1,17:12)
Block(-1,1,0,17:12)
Block(-1,1,1,17:12)
Block(-1,1,7,LEAVES:0)
Block(-1,1,8,LEAVES:0)
Block(-1,2,-2,17:12)
Block(-1,2,-1,17:12)
Block(-1,2,0,17:12)
Block(-1,2,1,17:12)
Block(-1,2,10,LEAVES:0)
Block(-1,3,-2,17:12)
Block(-1,3,0,17:12)
Block(-1,3,1,17:12)
Block(-1,3,7,LEAVES:0)
Block(-1,3,9,LEAVES:0)
Block(-1,4,-2,17:12)
Block(-1,4,1,17:12)
Block(-1,4,2,17:12)
Block(-1,4,3,17:12)
Block(-1,4,4,17:12)
Block(-1,5,-10,LEAVES:0)
Block(-1,5,-5,LEAVES:0)
Block(-1,5,-4,17:12)
Block(-1,5,-3,17:12)
Block(-1,5,1,17:12)
Block(-1,5,2,17:12)
Block(-1,6,-10,LEAVES:0)
Block(-1,6,-7,LEAVES:0)
Block(-1,6,-5,LEAVES:0)
Block(-1,6,-3,17:12)
Block(-1,6,1,17:12)
Block(-1,6,2,17:12)
Block(-1,6,3,17:12)
Block(-1,6,5,LEAVES:0)
Block(-1,7,-10,LEAVES:0)
Block(-1,7,-9,LEAVES:0)
Block(-1,7,-7,LEAVES:0)
Block(-1,7,-6,LEAVES:0)
Block(-1,7,3,17:12)
Block(-1,7,4,17:12)
Block(-1,7,5,LEAVES:0)
Block(-1,7,8,LEAVES:0)
Block(-1,8,-8,LEAVES:0)
Block(-1,8,-4,LEAVES:0)
Block(-1,8,-3,LEAVES:0)
Block(-1,8,5,LEAVES:0)
Block(-1,8,6,LEAVES:0)
Block(-1,8,8,LEAVES:0)
Block(-1,8,9,LEAVES:0)
Block(-1,9,-8,LEAVES:0)
Block(-1,9,-7,LEAVES:0)
Block(-1,9,-6,LEAVES:0)
Block(-1,9,-5,LEAVES:0)
Block(-1,9,-4,LEAVES:0)
Block(-1,9,-3,LEAVES:0)
Block(-1,9,-2,LEAVES:0)
Block(-1,9,-1,LEAVES:0)
Block(-1,9,0,LEAVES:0)
Block(-1,9,1,LEAVES:0)
Block(-1,9,6,17:12)
Block(-1,9,7,LEAVES:0)
Block(-1,10,-4,17:12)
Block(-1,10,-3,LEAVES:0)
Block(-1,10,-2,LEAVES:0)
Block(-1,10,-1,LEAVES:0)
Block(-1,10,1,LEAVES:0)
Block(-1,10,2,LEAVES:0)
Block(-1,10,3,LEAVES:0)
Block(-1,10,5,LEAVES:0)
Block(-1,10,7,LEAVES:0)
Block(-1,10,8,LEAVES:0)
Block(-1,11,-5,LEAVES:0)
Block(-1,11,-4,LEAVES:0)
Block(-1,11,-2,LEAVES:0)
Block(-1,11,-1,LEAVES:0)
Block(-1,12,2,LEAVES:0)
Block(0,0,0,LOG:3)
Block(0,1,0,17:12)
Block(0,1,6,LEAVES:0)
Block(0,1,7,LEAVES:0)
Block(0,2,0,17:12)
Block(0,2,5,LEAVES:0)
Block(0,2,8,LEAVES:0)
Block(0,2,9,LEAVES:0)
Block(0,2,10,LEAVES:0)
Block(0,2,11,LEAVES:0)
Block(0,3,7,LEAVES:0)
Block(0,4,-5,LEAVES:0)
Block(0,4,4,17:12)
Block(0,4,5,17:12)
Block(0,4,8,LEAVES:0)
Block(0,5,4,17:12)
Block(0,5,6,LEAVES:0)
Block(0,6,-9,LEAVES:0)
Block(0,6,-7,LEAVES:0)
Block(0,6,-6,17:12)
Block(0,6,-5,17:12)
Block(0,6,-3,17:12)
Block(0,6,1,17:12)
Block(0,7,-11,LEAVES:0)
Block(0,7,-9,LEAVES:0)
Block(0,7,-8,17:12)
Block(0,7,-7,LEAVES:0)
Block(0,7,-3,17:12)
Block(0,7,-2,17:12)
Block(0,7,1,17:12)
Block(0,7,2,LEAVES:0)
Block(0,7,6,LEAVES:0)
Block(0,8,-9,LEAVES:0)
Block(0,8,-8,LEAVES:0)
Block(0,8,-4,LEAVES:0)
Block(0,8,1,17:12)
Block(0,8,4,LEAVES:0)
Block(0,8,5,17:12)
Block(0,8,6,17:12)
Block(0,8,7,17:12)
Block(0,8,8,LEAVES:0)
Block(0,9,-10,LEAVES:0)
Block(0,9,-8,LEAVES:0)
Block(0,9,-7,LEAVES:0)
Block(0,9,-5,LEAVES:0)
Block(0,9,-4,LEAVES:0)
Block(0,9,-3,LEAVES:0)
Block(0,9,-1,LEAVES:0)
Block(0,9,5,17:12)
Block(0,9,6,LEAVES:0)
Block(0,9,7,LEAVES:0)
Block(0,10,-7,LEAVES:0)
Block(0,10,-4,LEAVES:0)
Block(0,10,-3,LEAVES:0)
Block(0,10,-1,LEAVES:0)
Block(0,10,0,LEAVES:0)
Block(0,10,5,LEAVES:0)
Block(0,10,7,LEAVES:0)
Block(0,11,-4,LEAVES:0)
Block(0,11,-2,LEAVES:0)
Block(0,11,-1,LEAVES:0)
Block(0,11,1,LEAVES:0)
Block(0,12,-2,LEAVES:0)
Block(0,12,-1,LEAVES:0)
Block(1,1,6,LEAVES:0)
Block(1,2,0,17:12)
Block(1,2,6,LEAVES:0)
Block(1,2,9,LEAVES:0)
Block(1,3,0,17:12)
Block(1,3,1,17:12)
Block(1,3,6,LEAVES:0)
Block(1,3,7,LEAVES:0)
Block(1,3,9,LEAVES:0)
Block(1,3,10,LEAVES:0)
Block(1,4,-6,LEAVES:0)
Block(1,4,-5,LEAVES:0)
Block(1,4,5,17:12)
Block(1,4,6,LEAVES:0)
Block(1,4,8,LEAVES:0)
Block(1,5,-3,LEAVES:0)
Block(1,5,4,17:12)
Block(1,5,5,LEAVES:0)
Block(1,5,6,LEAVES:0)
Block(1,5,8,LEAVES:0)
Block(1,5,9,LEAVES:0)
Block(1,6,-7,LEAVES:0)
Block(1,6,-6,LEAVES:0)
Block(1,6,-4,LEAVES:0)
Block(1,6,8,LEAVES:0)
Block(1,7,-10,LEAVES:0)
Block(1,7,-9,LEAVES:0)
Block(1,7,-7,LEAVES:0)
Block(1,7,-6,LEAVES:0)
Block(1,7,-2,17:12)
Block(1,7,1,LEAVES:0)
Block(1,7,2,LEAVES:0)
Block(1,7,5,LEAVES:0)
Block(1,7,7,LEAVES:0)
Block(1,7,8,LEAVES:0)
Block(1,8,-5,LEAVES:0)
Block(1,8,-2,17:12)
Block(1,8,1,17:12)
Block(1,8,4,LEAVES:0)
Block(1,8,5,LEAVES:0)
Block(1,8,6,LEAVES:0)
Block(1,8,8,LEAVES:0)
Block(1,8,9,LEAVES:0)
Block(1,9,-8,LEAVES:0)
Block(1,9,-7,LEAVES:0)
Block(1,9,-3,LEAVES:0)
Block(1,9,-2,17:12)
Block(1,9,1,LEAVES:0)
Block(1,9,3,LEAVES:0)
Block(1,9,10,LEAVES:0)
Block(1,10,-7,LEAVES:0)
Block(1,10,-5,LEAVES:0)
Block(1,10,-3,LEAVES:0)
Block(1,10,-2,17:12)
Block(1,10,-1,LEAVES:0)
Block(1,10,7,LEAVES:0)
Block(1,10,8,LEAVES:0)
Block(1,11,-3,LEAVES:0)
Block(1,11,-2,LEAVES:0)
Block(1,12,-4,LEAVES:0)
Block(1,12,-2,LEAVES:0)
Block(2,2,7,LEAVES:0)
Block(2,3,1,17:12)
Block(2,3,5,LEAVES:0)
Block(2,3,6,17:12)
Block(2,3,7,17:12)
Block(2,3,8,17:12)
Block(2,3,9,LEAVES:0)
Block(2,4,-7,LEAVES:0)
Block(2,4,-6,LEAVES:0)
Block(2,4,1,17:12)
Block(2,4,7,LEAVES:0)
Block(2,4,8,LEAVES:0)
Block(2,5,-8,LEAVES:0)
Block(2,5,-5,LEAVES:0)
Block(2,5,-4,LEAVES:0)
Block(2,5,-3,LEAVES:0)
Block(2,5,-2,LEAVES:0)
Block(2,5,4,LEAVES:0)
Block(2,5,5,LEAVES:0)
Block(2,5,6,LEAVES:0)
Block(2,5,8,LEAVES:0)
Block(2,6,-11,LEAVES:0)
Block(2,6,-6,LEAVES:0)
Block(2,6,3,LEAVES:0)
Block(2,6,4,LEAVES:0)
Block(2,6,5,17:12)
Block(2,6,6,LEAVES:0)
Block(2,6,7,LEAVES:0)
Block(2,6,8,LEAVES:0)
Block(2,6,9,LEAVES:0)
Block(2,7,-11,LEAVES:0)
Block(2,7,-10,LEAVES:0)
Block(2,7,-8,LEAVES:0)
Block(2,7,-7,LEAVES:0)
Block(2,7,-6,LEAVES:0)
Block(2,7,-5,LEAVES:0)
Block(2,7,0,LEAVES:0)
Block(2,7,1,LEAVES:0)
Block(2,7,4,LEAVES:0)
Block(2,7,5,LEAVES:0)
Block(2,8,-10,LEAVES:0)
Block(2,8,-1,LEAVES:0)
Block(2,8,1,LEAVES:0)
Block(2,8,2,LEAVES:0)
Block(2,8,3,LEAVES:0)
Block(2,8,4,LEAVES:0)
Block(2,8,5,LEAVES:0)
Block(2,8,6,LEAVES:0)
Block(2,8,7,LEAVES:0)
Block(2,8,8,LEAVES:0)
Block(2,8,9,LEAVES:0)
Block(2,9,-7,LEAVES:0)
Block(2,9,-1,LEAVES:0)
Block(2,9,1,LEAVES:0)
Block(2,9,2,17:12)
Block(2,9,5,LEAVES:0)
Block(2,10,-4,LEAVES:0)
Block(2,10,-3,LEAVES:0)
Block(2,10,-2,17:12)
Block(2,10,-1,LEAVES:0)
Block(2,10,0,LEAVES:0)
Block(2,10,2,LEAVES:0)
Block(2,10,8,LEAVES:0)
Block(2,11,-2,17:12)
Block(2,11,1,LEAVES:0)
Block(2,12,-2,LEAVES:0)
Block(2,12,-1,LEAVES:0)
Block(3,2,9,LEAVES:0)
Block(3,3,-3,LEAVES:0)
Block(3,3,6,LEAVES:0)
Block(3,3,7,LEAVES:0)
Block(3,3,9,LEAVES:0)
Block(3,3,10,LEAVES:0)
Block(3,4,-7,LEAVES:0)
Block(3,4,0,17:12)
Block(3,4,1,17:12)
Block(3,4,2,17:12)
Block(3,4,11,LEAVES:0)
Block(3,5,-7,LEAVES:0)
Block(3,5,-4,LEAVES:0)
Block(3,5,2,17:12)
Block(3,5,4,LEAVES:0)
Block(3,5,8,LEAVES:0)
Block(3,5,9,LEAVES:0)
Block(3,6,-7,LEAVES:0)
Block(3,6,-6,LEAVES:0)
Block(3,6,-4,LEAVES:0)
Block(3,6,-3,LEAVES:0)
Block(3,6,4,LEAVES:0)
Block(3,6,5,17:12)
Block(3,6,7,LEAVES:0)
Block(3,7,-5,LEAVES:0)
Block(3,7,0,LEAVES:0)
Block(3,7,4,LEAVES:0)
Block(3,7,5,LEAVES:0)
Block(3,7,7,LEAVES:0)
Block(3,7,8,LEAVES:0)
Block(3,8,-10,LEAVES:0)
Block(3,8,-8,LEAVES:0)
Block(3,8,-5,LEAVES:0)
Block(3,8,-4,LEAVES:0)
Block(3,8,0,LEAVES:0)
Block(3,8,3,LEAVES:0)
Block(3,8,6,LEAVES:0)
Block(3,9,-5,LEAVES:0)
Block(3,9,0,LEAVES:0)
Block(3,9,1,LEAVES:0)
Block(3,9,2,17:12)
Block(3,9,3,LEAVES:0)
Block(3,9,4,LEAVES:0)
Block(3,9,5,LEAVES:0)
Block(3,9,6,LEAVES:0)
Block(3,9,7,LEAVES:0)
Block(3,10,-5,LEAVES:0)
Block(3,10,-4,LEAVES:0)
Block(3,10,-2,LEAVES:0)
Block(3,10,-1,LEAVES:0)
Block(3,10,0,LEAVES:0)
Block(3,10,2,LEAVES:0)
Block(3,11,-4,LEAVES:0)
Block(3,11,2,LEAVES:0)
Block(3,11,3,LEAVES:0)
Block(3,12,-1,LEAVES:0)
Block(4,2,5,LEAVES:0)
Block(4,3,-4,LEAVES:0)
Block(4,3,-3,LEAVES:0)
Block(4,3,5,LEAVES:0)
Block(4,3,6,LEAVES:0)
Block(4,3,8,LEAVES:0)
Block(4,3,9,LEAVES:0)
Block(4,3,10,LEAVES:0)
Block(4,4,-2,17:12)
Block(4,4,-1,17:12)
Block(4,4,0,17:12)
Block(4,4,6,LEAVES:0)
Block(4,5,-6,LEAVES:0)
Block(4,5,-4,LEAVES:0)
Block(4,5,-3,LEAVES:0)
Block(4,5,-2,17:12)
Block(4,5,2,17:12)
Block(4,5,9,LEAVES:0)
Block(4,6,-8,LEAVES:0)
Block(4,6,-6,LEAVES:0)
Block(4,6,-5,LEAVES:0)
Block(4,6,-4,LEAVES:0)
Block(4,6,-3,LEAVES:0)
Block(4,6,5,LEAVES:0)
Block(4,7,-6,LEAVES:0)
Block(4,7,-5,LEAVES:0)
Block(4,7,3,LEAVES:0)
Block(4,7,5,LEAVES:0)
Block(4,7,6,17:12)
Block(4,7,7,LEAVES:0)
Block(4,8,-7,LEAVES:0)
Block(4,8,-5,LEAVES:0)
Block(4,8,1,LEAVES:0)
Block(4,8,5,LEAVES:0)
Block(4,8,6,LEAVES:0)
Block(4,9,-1,LEAVES:0)
Block(4,9,1,LEAVES:0)
Block(4,9,2,17:12)
Block(4,9,3,LEAVES:0)
Block(4,9,4,LEAVES:0)
Block(4,9,6,LEAVES:0)
Block(4,10,1,LEAVES:0)
Block(4,10,2,LEAVES:0)
Block(4,11,-4,LEAVES:0)
Block(4,11,-2,LEAVES:0)
Block(4,11,0,LEAVES:0)
Block(4,11,2,LEAVES:0)
Block(5,2,4,LEAVES:0)
Block(5,3,-5,LEAVES:0)
Block(5,3,-4,LEAVES:0)
Block(5,4,-6,LEAVES:0)
Block(5,4,-3,LEAVES:0)
Block(5,4,-2,LEAVES:0)
Block(5,4,-1,LEAVES:0)
Block(5,4,0,LEAVES:0)
Block(5,4,6,LEAVES:0)
Block(5,4,8,LEAVES:0)
Block(5,5,-4,LEAVES:0)
Block(5,5,-1,LEAVES:0)
Block(5,5,2,17:12)
Block(5,5,3,17:12)
Block(5,6,-7,LEAVES:0)
Block(5,6,-6,LEAVES:0)
Block(5,6,-4,LEAVES:0)
Block(5,6,-3,LEAVES:0)
Block(5,6,7,LEAVES:0)
Block(5,7,-2,LEAVES:0)
Block(5,7,4,LEAVES:0)
Block(5,7,5,LEAVES:0)
Block(5,7,7,LEAVES:0)
Block(5,7,8,LEAVES:0)
Block(5,8,-5,LEAVES:0)
Block(5,8,-4,LEAVES:0)
Block(5,8,3,LEAVES:0)
Block(5,8,9,LEAVES:0)
Block(5,9,0,LEAVES:0)
Block(5,9,1,LEAVES:0)
Block(5,9,3,LEAVES:0)
Block(5,9,4,LEAVES:0)
Block(5,9,6,LEAVES:0)
Block(5,9,7,LEAVES:0)
Block(5,10,5,LEAVES:0)
Block(5,11,2,LEAVES:0)
Block(5,11,3,LEAVES:0)
Block(6,2,3,LEAVES:0)
Block(6,2,4,LEAVES:0)
Block(6,3,-5,LEAVES:0)
Block(6,3,6,LEAVES:0)
Block(6,4,-5,LEAVES:0)
Block(6,4,-2,LEAVES:0)
Block(6,4,3,LEAVES:0)
Block(6,4,4,17:12)
Block(6,4,5,LEAVES:0)
Block(6,5,-8,LEAVES:0)
Block(6,5,-5,LEAVES:0)
Block(6,5,-4,LEAVES:0)
Block(6,5,-2,17:12)
Block(6,5,-1,17:12)
Block(6,5,3,LEAVES:0)
Block(6,6,-8,LEAVES:0)
Block(6,6,-7,LEAVES:0)
Block(6,6,-5,LEAVES:0)
Block(6,6,-4,LEAVES:0)
Block(6,6,-3,LEAVES:0)
Block(6,6,3,LEAVES:0)
Block(6,7,-7,LEAVES:0)
Block(6,7,-3,LEAVES:0)
Block(6,7,-2,LEAVES:0)
Block(6,7,3,LEAVES:0)
Block(6,7,4,LEAVES:0)
Block(6,7,6,LEAVES:0)
Block(6,7,7,LEAVES:0)
Block(6,7,8,LEAVES:0)
Block(6,8,-4,LEAVES:0)
Block(6,8,-1,LEAVES:0)
Block(6,8,4,LEAVES:0)
Block(6,9,-1,LEAVES:0)
Block(6,9,0,LEAVES:0)
Block(6,9,2,LEAVES:0)
Block(6,9,3,LEAVES:0)
Block(6,9,4,LEAVES:0)
Block(6,9,7,LEAVES:0)
Block(6,10,0,LEAVES:0)
Block(6,11,3,LEAVES:0)
Block(7,2,2,LEAVES:0)
Block(7,2,3,LEAVES:0)
Block(7,3,1,LEAVES:0)
Block(7,3,4,LEAVES:0)
Block(7,3,5,LEAVES:0)
Block(7,3,6,LEAVES:0)
Block(7,3,7,LEAVES:0)
Block(7,4,-4,LEAVES:0)
Block(7,4,3,LEAVES:0)
Block(7,4,4,17:12)
Block(7,5,-6,LEAVES:0)
Block(7,5,-4,17:12)
Block(7,5,-3,17:12)
Block(7,5,-2,17:12)
Block(7,5,4,LEAVES:0)
Block(7,6,-4,LEAVES:0)
Block(7,6,-3,LEAVES:0)
Block(7,7,-7,LEAVES:0)
Block(7,7,-5,LEAVES:0)
Block(7,7,-3,LEAVES:0)
Block(7,8,4,LEAVES:0)
Block(7,8,6,LEAVES:0)
Block(7,10,0,LEAVES:0)
Block(7,10,2,LEAVES:0)
Block(8,2,2,LEAVES:0)
Block(8,3,2,LEAVES:0)
Block(8,3,5,LEAVES:0)
Block(8,4,-2,LEAVES:0)
Block(8,4,2,LEAVES:0)
Block(8,4,3,LEAVES:0)
Block(8,4,4,17:12)
Block(8,4,5,LEAVES:0)
Block(8,4,6,LEAVES:0)
Block(8,5,-5,LEAVES:0)
Block(8,5,-4,LEAVES:0)
Block(8,5,-2,LEAVES:0)
Block(8,5,-1,LEAVES:0)
Block(8,5,4,LEAVES:0)
Block(8,6,0,LEAVES:0)
Block(8,6,4,LEAVES:0)
Block(8,6,5,LEAVES:0)
Block(8,7,-3,LEAVES:0)
Block(8,7,-2,LEAVES:0)
Block(9,3,3,LEAVES:0)
Block(9,4,-6,LEAVES:0)
Block(9,4,1,LEAVES:0)
Block(9,4,3,LEAVES:0)
Block(9,4,4,17:12)
Block(9,4,5,LEAVES:0)
Block(9,5,-6,LEAVES:0)
Block(9,5,-5,LEAVES:0)
Block(9,5,-3,LEAVES:0)
Block(9,5,-2,LEAVES:0)
Block(9,5,-1,LEAVES:0)
Block(9,5,3,LEAVES:0)
Block(9,5,4,LEAVES:0)
Block(9,6,-5,LEAVES:0)
Block(9,6,2,LEAVES:0)
Block(9,6,4,LEAVES:0)
Block(9,7,-2,LEAVES:0)
Block(10,3,5,LEAVES:0)
Block(10,4,2,LEAVES:0)
Block(10,4,3,LEAVES:0)
Block(10,4,5,LEAVES:0)
Block(10,4,6,LEAVES:0)
Block(10,5,7,LEAVES:0)
Block(10,6,-5,LEAVES:0)
Block(10,6,-3,LEAVES:0)
Block(10,6,4,LEAVES:0)
Block(10,6,5,LEAVES:0)
Block(11,3,1,LEAVES:0)
Block(11,4,1,LEAVES:0)
Block(11,4,2,LEAVES:0)
Block(11,4,4,LEAVES:0)
Block(11,4,5,LEAVES:0)
Block(11,4,6,LEAVES:0)
Block(11,5,2,LEAVES:0)
Block(11,6,5,LEAVES:0)
Block(12,5,2,LEAVES:0)
Block(12,5,4,LEAVES:0)


#######################################################################
# +-----------------------------------------------------------------+ #
# |                             Entities                            | #
# +-----------------------------------------------------------------+ #
#######################################################################

# Entity() spawns an entity instead of a block. The entity is spawned only once when the BO3 is spawned.
# Entities are persistent by default so they don't de-spawn when no player is near, they are only unloaded.
# Usage: Entity(x,y,z,mobName,groupSize,NameTagOrNBTFileName) or Entity(x,y,z,mobName,groupSize)
# Use /tc entities or /otg entities to get a list of entities that can be used as mobName, this includes entities added by other mods.
# NameTagOrNBTFileName can be either a nametag for the mob or an nbt file (such as mymobinfo.nbt or mymobinfo.txt).
# When using a text file you can use the same mob spawning parameters used with the /summon command to equip the
# entity and give it custom attributes etc. You can copy the DATA part of a summon command including surrounding
# curly braces to a .txt file, for instance for: "/summon Skeleton x y z {DATA}"

#######################################################################
# +-----------------------------------------------------------------+ #
# |                            BO3 checks                           | #
# +-----------------------------------------------------------------+ #
#######################################################################

# Require a condition at a certain location in order for the BO3 to be spawned.
# BlockCheck(x,y,z,BlockName[,BlockName[,...]]) - one of the blocks must be at the location
# BlockCheckNot(x,y,z,BlockName[,BlockName[,...]]) - all the blocks must not be at the location
# LightCheck(x,y,z,minLightLevel,maxLightLevel) - light must be between min and max (inclusive)

# You can use "Solid" as a BlockName for matching all solid blocks or "All" to match all blocks that aren't air.

# Examples:
#   BlockCheck(0,-1,0,GRASS,DIRT)  Require grass or dirt just below the object
#   BlockCheck(0,-1,0,Solid)       Require any solid block just below the object
#   BlockCheck(0,-1,0,WOOL)        Require any type of wool just below the object
#   BlockCheck(0,-1,0,WOOL:0)      Require white wool just below the object
#   BlockCheckNot(0,-1,0,WOOL:0)   Require that there is no white wool below the object
#   LightCheck(0,0,0,0,LEAVES:0)          Require almost complete darkness just below the object

BlockCheck(0,-1,0,GRASS,DIRT)