#######################################################################
# +-----------------------------------------------------------------+ #
# |                            BO3 object                           | #
# +-----------------------------------------------------------------+ #
#######################################################################

# The descriptions in this file are accurate only for TerrainControl and OTG.
# For MCW and OTG+ these descriptions are only accurate if the BO3 is used as a CustomObject.
# MCW and OTG+ completely reimplemented CustomStructure, check the MCW/OTG+ documentation for more information.

# This is the config file of a custom object.
# If you add this object correctly to your BiomeConfigs, it will spawn in the world.

# This is the creator of this BO3 object
Author: Unknown

# A short description of this BO3 object
Description: This BO3 was converted from a schematic using OTGEdit. The author and description information of the schematic could not be found. If you know who the author of the schematic is then please add this information.

# The BO3 version, don't change this! It can be used by external applications to do a version check.
Version: 3

# The settings mode, WriteAll, WriteWithoutComments or WriteDisable. See WorldConfig.
SettingsMode: WriteDisable

#######################################################################
# +-----------------------------------------------------------------+ #
# |                          Main settings                          | #
# +-----------------------------------------------------------------+ #
#######################################################################

# This needs to be set to true to spawn the object in the Tree and Sapling resources.
Tree: true

# The frequency of the BO3 from 1 to 200. Tries this many times to spawn this BO3 when using the CustomObject(...) resource.
# Ignored by Tree(..), Sapling(..) and CustomStructure(..)
Frequency: 40

# The rarity of the BO3 from 0 to 100. Each spawn attempt has rarity% chance to succeed when using the CustomObject(...) resource.
# Ignored by Tree(..), Sapling(..) and CustomStructure(..)
Rarity: 100.0

# If you set this to true, the BO3 will be placed with a random rotation.
RotateRandomly: true

# The spawn height of the BO3 - randomY, highestBlock or highestSolidBlock.
SpawnHeight: highestBlock

# The height limits for the BO3.
MinHeight: 63

MaxHeight: 80

# Objects can have other objects attached to it: branches. Branches can also
# have branches attached to it, which can also have branches, etc. This is the
# maximum branch depth for this objects.
MaxBranchDepth: 10

# When spawned with the UseWorld keyword, this BO3 should NOT spawn in the following biomes.
# If you writer.write the BO3 name directly in the BiomeConfigs, this will be ignored.
ExcludedBiomes: All

# To optimise this BO3 for faster loading times you can use Notepad++ to find/replace comments and abbreviate things.
# Notepad++ find/replace with regex:
# Find: ^[#;].* replace to nothing removes all lines starting with # 
# Find: ^\s*$ replace to nothing removes most empty lines 
# Notepad++ find/replace without regex:
# *Warning: This will only work for OTG 1.10.2 v21 / OTG 1.11.2 v6 or higher. B( is not recognised by lower versions.
# Find: Block( replace to B(

#######################################################################
# +-----------------------------------------------------------------+ #
# |                      Source block settings                      | #
# +-----------------------------------------------------------------+ #
#######################################################################

# The block(s) the BO3 should spawn in.
SourceBlocks: STONE:1,STONE:3,STONE:5,DIRT:1,DIRT,SAND,GRASS,DIRT:2,HARD_CLAY,STAINED_CLAY,CLAY,SANDSTONE,SAND:1,AIR,STONE,GRAVEL,LONG_GRASS,LONG_GRASS:1,LONG_GRASS:2,DEAD_BUSH,YELLOW_FLOWER,RED_ROSE,BROWN_MUSHROOM,RED_MUSHROOM
# The maximum percentage of the BO3 that can be outside the SourceBlock.
# The BO3 won't be placed on a location with more blocks outside the SourceBlock than this percentage.
MaxPercentageOutsideSourceBlock: 0

# What to do when a block is about to be placed outside the SourceBlock? (dontPlace, placeAnyway)
OutsideSourceBlock: placeAnyway

#######################################################################
# +-----------------------------------------------------------------+ #
# |                              Blocks                             | #
# +-----------------------------------------------------------------+ #
#######################################################################

# All the blocks used in the BO3 are listed here. Possible blocks:
# Block(x,y,z,id[.data][,nbtfile.nbt) or B(x,y,z,id[.data][,nbtfile.nbt)
# RandomBlock(x,y,z,id[:data][,nbtfile.nbt],chance[,id[:data][,nbtfile.nbt],chance[,...]])
# So RandomBlock(0,0,0,CHEST,chest.nbt,50,CHEST,anotherchest.nbt,100) will spawn a chest at
# the BO3 origin, and give it a 50% chance to have the contents of chest.nbt, or, if that
# fails, a 100% percent chance to have the contents of anotherchest.nbt.

Block(-29,1,19,LEAVES:0)
Block(-28,1,18,LEAVES:0)
Block(-28,1,19,LEAVES:0)
Block(-28,2,21,LEAVES:0)
Block(-28,3,18,LEAVES:0)
Block(-28,3,20,LEAVES:0)
Block(-27,0,25,LEAVES:0)
Block(-27,1,17,LEAVES:0)
Block(-27,1,18,LEAVES:0)
Block(-27,2,16,LEAVES:0)
Block(-27,2,19,LEAVES:0)
Block(-27,2,20,LEAVES:0)
Block(-27,2,21,LEAVES:0)
Block(-27,2,22,LEAVES:0)
Block(-27,3,18,LEAVES:0)
Block(-27,4,19,LEAVES:0)
Block(-26,0,24,LEAVES:0)
Block(-26,0,25,LEAVES:0)
Block(-26,1,17,LEAVES:0)
Block(-26,1,27,LEAVES:0)
Block(-26,2,17,LEAVES:0)
Block(-26,2,20,LEAVES:0)
Block(-26,2,24,LEAVES:0)
Block(-26,2,26,LEAVES:0)
Block(-26,3,15,LEAVES:0)
Block(-26,3,17,LEAVES:0)
Block(-26,3,18,LEAVES:0)
Block(-26,3,20,LEAVES:0)
Block(-26,3,21,LEAVES:0)
Block(-26,3,22,LEAVES:0)
Block(-26,4,18,LEAVES:0)
Block(-26,4,19,LEAVES:0)
Block(-26,5,19,LEAVES:0)
Block(-26,5,20,LEAVES:0)
Block(-26,5,21,LEAVES:0)
Block(-26,6,18,LEAVES:0)
Block(-26,6,20,LEAVES:0)
Block(-25,0,23,LEAVES:0)
Block(-25,0,24,LEAVES:0)
Block(-25,1,22,LEAVES:0)
Block(-25,1,25,LEAVES:0)
Block(-25,1,26,LEAVES:0)
Block(-25,1,27,LEAVES:0)
Block(-25,1,28,LEAVES:0)
Block(-25,2,18,LEAVES:0)
Block(-25,2,24,LEAVES:0)
Block(-25,3,14,LEAVES:0)
Block(-25,3,15,LEAVES:0)
Block(-25,3,16,LEAVES:0)
Block(-25,3,18,LEAVES:0)
Block(-25,3,19,17:12)
Block(-25,3,20,LEAVES:0)
Block(-25,3,21,LEAVES:0)
Block(-25,3,22,LEAVES:0)
Block(-25,3,25,LEAVES:0)
Block(-25,4,17,LEAVES:0)
Block(-25,4,18,LEAVES:0)
Block(-25,4,19,LEAVES:0)
Block(-25,4,24,LEAVES:0)
Block(-25,5,14,LEAVES:0)
Block(-25,5,16,LEAVES:0)
Block(-25,5,17,LEAVES:0)
Block(-25,5,19,LEAVES:0)
Block(-25,5,20,LEAVES:0)
Block(-25,5,21,LEAVES:0)
Block(-25,5,22,LEAVES:0)
Block(-25,5,23,LEAVES:0)
Block(-25,6,18,LEAVES:0)
Block(-25,7,19,LEAVES:0)
Block(-24,0,23,LEAVES:0)
Block(-24,1,23,LEAVES:0)
Block(-24,1,26,LEAVES:0)
Block(-24,2,20,LEAVES:0)
Block(-24,2,23,LEAVES:0)
Block(-24,2,24,LEAVES:0)
Block(-24,2,26,LEAVES:0)
Block(-24,2,27,LEAVES:0)
Block(-24,3,13,LEAVES:0)
Block(-24,3,14,LEAVES:0)
Block(-24,3,17,LEAVES:0)
Block(-24,3,18,LEAVES:0)
Block(-24,3,19,17:12)
Block(-24,3,20,LEAVES:0)
Block(-24,3,21,LEAVES:0)
Block(-24,3,25,LEAVES:0)
Block(-24,4,12,LEAVES:0)
Block(-24,4,15,LEAVES:0)
Block(-24,4,16,LEAVES:0)
Block(-24,4,17,LEAVES:0)
Block(-24,4,18,LEAVES:0)
Block(-24,4,19,LEAVES:0)
Block(-24,4,22,LEAVES:0)
Block(-24,4,23,LEAVES:0)
Block(-24,4,24,LEAVES:0)
Block(-24,4,25,LEAVES:0)
Block(-24,4,26,LEAVES:0)
Block(-24,5,14,LEAVES:0)
Block(-24,5,17,LEAVES:0)
Block(-24,5,19,LEAVES:0)
Block(-24,5,20,LEAVES:0)
Block(-24,5,21,LEAVES:0)
Block(-24,6,15,LEAVES:0)
Block(-24,6,17,LEAVES:0)
Block(-24,6,18,LEAVES:0)
Block(-24,6,20,LEAVES:0)
Block(-24,6,21,LEAVES:0)
Block(-24,6,22,LEAVES:0)
Block(-24,7,19,LEAVES:0)
Block(-24,8,19,LEAVES:0)
Block(-24,8,20,LEAVES:0)
Block(-23,1,24,LEAVES:0)
Block(-23,2,16,LEAVES:0)
Block(-23,2,22,LEAVES:0)
Block(-23,2,24,LEAVES:0)
Block(-23,2,25,17:12)
Block(-23,2,26,LEAVES:0)
Block(-23,3,13,LEAVES:0)
Block(-23,3,16,LEAVES:0)
Block(-23,3,17,LEAVES:0)
Block(-23,3,19,17:12)
Block(-23,3,20,LEAVES:0)
Block(-23,3,21,LEAVES:0)
Block(-23,3,24,LEAVES:0)
Block(-23,3,25,LEAVES:0)
Block(-23,4,13,LEAVES:0)
Block(-23,4,16,LEAVES:0)
Block(-23,4,17,LEAVES:0)
Block(-23,4,20,LEAVES:0)
Block(-23,4,23,LEAVES:0)
Block(-23,4,24,LEAVES:0)
Block(-23,4,25,LEAVES:0)
Block(-23,5,13,LEAVES:0)
Block(-23,5,14,LEAVES:0)
Block(-23,5,16,LEAVES:0)
Block(-23,5,17,LEAVES:0)
Block(-23,5,18,LEAVES:0)
Block(-23,5,20,LEAVES:0)
Block(-23,5,21,LEAVES:0)
Block(-23,5,22,17:12)
Block(-23,5,23,LEAVES:0)
Block(-23,5,24,LEAVES:0)
Block(-23,5,27,LEAVES:0)
Block(-23,6,15,LEAVES:0)
Block(-23,6,16,LEAVES:0)
Block(-23,6,18,LEAVES:0)
Block(-23,6,19,17:12)
Block(-23,6,20,LEAVES:0)
Block(-23,6,22,LEAVES:0)
Block(-23,6,24,LEAVES:0)
Block(-23,6,26,LEAVES:0)
Block(-23,7,15,LEAVES:0)
Block(-23,7,16,LEAVES:0)
Block(-23,7,18,LEAVES:0)
Block(-23,7,19,LEAVES:0)
Block(-23,7,22,LEAVES:0)
Block(-23,7,23,LEAVES:0)
Block(-23,8,17,LEAVES:0)
Block(-23,8,19,LEAVES:0)
Block(-22,1,26,LEAVES:0)
Block(-22,2,23,LEAVES:0)
Block(-22,2,24,LEAVES:0)
Block(-22,2,25,17:12)
Block(-22,2,26,LEAVES:0)
Block(-22,2,27,LEAVES:0)
Block(-22,3,19,17:12)
Block(-22,3,28,LEAVES:0)
Block(-22,4,14,LEAVES:0)
Block(-22,4,17,LEAVES:0)
Block(-22,4,19,LEAVES:0)
Block(-22,4,21,LEAVES:0)
Block(-22,4,23,LEAVES:0)
Block(-22,4,24,LEAVES:0)
Block(-22,4,25,LEAVES:0)
Block(-22,4,26,LEAVES:0)
Block(-22,5,12,LEAVES:0)
Block(-22,5,13,LEAVES:0)
Block(-22,5,14,LEAVES:0)
Block(-22,5,15,17:12)
Block(-22,5,16,LEAVES:0)
Block(-22,5,19,LEAVES:0)
Block(-22,5,20,LEAVES:0)
Block(-22,5,21,LEAVES:0)
Block(-22,5,22,17:12)
Block(-22,5,23,LEAVES:0)
Block(-22,5,25,LEAVES:0)
Block(-22,5,26,LEAVES:0)
Block(-22,5,27,LEAVES:0)
Block(-22,5,28,LEAVES:0)
Block(-22,6,14,LEAVES:0)
Block(-22,6,15,LEAVES:0)
Block(-22,6,17,LEAVES:0)
Block(-22,6,18,17:12)
Block(-22,6,19,17:12)
Block(-22,6,20,LEAVES:0)
Block(-22,6,21,LEAVES:0)
Block(-22,6,22,LEAVES:0)
Block(-22,6,24,LEAVES:0)
Block(-22,7,12,LEAVES:0)
Block(-22,7,13,LEAVES:0)
Block(-22,7,14,LEAVES:0)
Block(-22,7,15,LEAVES:0)
Block(-22,7,20,LEAVES:0)
Block(-22,7,22,LEAVES:0)
Block(-22,7,25,LEAVES:0)
Block(-22,8,19,LEAVES:0)
Block(-22,8,20,LEAVES:0)
Block(-22,8,21,LEAVES:0)
Block(-21,1,22,LEAVES:0)
Block(-21,2,22,LEAVES:0)
Block(-21,2,23,LEAVES:0)
Block(-21,2,24,17:12)
Block(-21,2,25,17:12)
Block(-21,2,26,LEAVES:0)
Block(-21,2,27,LEAVES:0)
Block(-21,3,18,17:12)
Block(-21,3,19,17:12)
Block(-21,3,23,LEAVES:0)
Block(-21,4,16,LEAVES:0)
Block(-21,4,21,LEAVES:0)
Block(-21,4,23,LEAVES:0)
Block(-21,4,26,LEAVES:0)
Block(-21,5,11,LEAVES:0)
Block(-21,5,12,LEAVES:0)
Block(-21,5,13,LEAVES:0)
Block(-21,5,14,LEAVES:0)
Block(-21,5,15,17:12)
Block(-21,5,16,LEAVES:0)
Block(-21,5,17,LEAVES:0)
Block(-21,5,18,LEAVES:0)
Block(-21,5,20,LEAVES:0)
Block(-21,5,21,LEAVES:0)
Block(-21,5,22,17:12)
Block(-21,5,23,LEAVES:0)
Block(-21,5,24,LEAVES:0)
Block(-21,5,26,LEAVES:0)
Block(-21,6,10,LEAVES:0)
Block(-21,6,13,LEAVES:0)
Block(-21,6,14,LEAVES:0)
Block(-21,6,15,LEAVES:0)
Block(-21,6,16,LEAVES:0)
Block(-21,6,17,LEAVES:0)
Block(-21,6,18,LEAVES:0)
Block(-21,6,19,LEAVES:0)
Block(-21,6,20,LEAVES:0)
Block(-21,6,21,LEAVES:0)
Block(-21,6,23,LEAVES:0)
Block(-21,6,24,LEAVES:0)
Block(-21,6,25,LEAVES:0)
Block(-21,6,26,LEAVES:0)
Block(-21,6,27,LEAVES:0)
Block(-21,7,12,LEAVES:0)
Block(-21,7,15,LEAVES:0)
Block(-21,7,16,LEAVES:0)
Block(-21,7,17,LEAVES:0)
Block(-21,7,20,LEAVES:0)
Block(-21,7,21,LEAVES:0)
Block(-21,7,22,LEAVES:0)
Block(-21,7,23,LEAVES:0)
Block(-21,7,25,LEAVES:0)
Block(-21,8,13,LEAVES:0)
Block(-21,8,19,LEAVES:0)
Block(-21,8,20,LEAVES:0)
Block(-21,8,25,LEAVES:0)
Block(-21,8,26,LEAVES:0)
Block(-21,9,20,LEAVES:0)
Block(-20,2,23,17:12)
Block(-20,2,24,17:12)
Block(-20,2,27,LEAVES:0)
Block(-20,3,18,17:12)
Block(-20,3,23,17:12)
Block(-20,3,25,LEAVES:0)
Block(-20,4,12,LEAVES:0)
Block(-20,4,15,LEAVES:0)
Block(-20,4,16,17:12)
Block(-20,4,18,17:12)
Block(-20,4,19,LEAVES:0)
Block(-20,4,21,17:12)
Block(-20,5,11,LEAVES:0)
Block(-20,5,12,LEAVES:0)
Block(-20,5,13,LEAVES:0)
Block(-20,5,15,LEAVES:0)
Block(-20,5,16,LEAVES:0)
Block(-20,5,17,LEAVES:0)
Block(-20,5,18,17:12)
Block(-20,5,19,LEAVES:0)
Block(-20,5,20,LEAVES:0)
Block(-20,5,22,LEAVES:0)
Block(-20,5,23,LEAVES:0)
Block(-20,5,24,LEAVES:0)
Block(-20,6,11,LEAVES:0)
Block(-20,6,13,LEAVES:0)
Block(-20,6,14,LEAVES:0)
Block(-20,6,18,LEAVES:0)
Block(-20,6,20,LEAVES:0)
Block(-20,6,22,LEAVES:0)
Block(-20,6,24,17:12)
Block(-20,6,25,17:12)
Block(-20,6,26,LEAVES:0)
Block(-20,7,11,LEAVES:0)
Block(-20,7,12,LEAVES:0)
Block(-20,7,14,LEAVES:0)
Block(-20,7,15,LEAVES:0)
Block(-20,7,16,LEAVES:0)
Block(-20,7,17,LEAVES:0)
Block(-20,7,18,LEAVES:0)
Block(-20,7,19,LEAVES:0)
Block(-20,7,21,LEAVES:0)
Block(-20,7,23,LEAVES:0)
Block(-20,7,24,LEAVES:0)
Block(-20,7,25,LEAVES:0)
Block(-20,8,13,LEAVES:0)
Block(-20,8,18,LEAVES:0)
Block(-20,8,19,LEAVES:0)
Block(-20,8,21,LEAVES:0)
Block(-20,8,22,LEAVES:0)
Block(-20,8,23,LEAVES:0)
Block(-20,8,25,LEAVES:0)
Block(-20,9,13,LEAVES:0)
Block(-20,9,14,LEAVES:0)
Block(-20,9,20,LEAVES:0)
Block(-20,10,20,LEAVES:0)
Block(-20,10,21,LEAVES:0)
Block(-19,2,26,LEAVES:0)
Block(-19,2,27,LEAVES:0)
Block(-19,3,12,LEAVES:0)
Block(-19,3,21,17:12)
Block(-19,3,22,17:12)
Block(-19,3,23,17:12)
Block(-19,3,29,LEAVES:0)
Block(-19,4,16,17:12)
Block(-19,4,18,17:12)
Block(-19,4,21,17:12)
Block(-19,4,22,17:12)
Block(-19,4,26,LEAVES:0)
Block(-19,4,28,LEAVES:0)
Block(-19,5,22,17:12)
Block(-19,5,23,LEAVES:0)
Block(-19,5,24,LEAVES:0)
Block(-19,5,26,LEAVES:0)
Block(-19,6,12,LEAVES:0)
Block(-19,6,13,LEAVES:0)
Block(-19,6,15,LEAVES:0)
Block(-19,6,19,17:12)
Block(-19,6,20,17:12)
Block(-19,6,22,LEAVES:0)
Block(-19,6,23,LEAVES:0)
Block(-19,6,24,17:12)
Block(-19,6,26,LEAVES:0)
Block(-19,6,27,LEAVES:0)
Block(-19,7,10,LEAVES:0)
Block(-19,7,12,LEAVES:0)
Block(-19,7,13,17:12)
Block(-19,7,14,LEAVES:0)
Block(-19,7,19,LEAVES:0)
Block(-19,7,20,17:12)
Block(-19,7,23,LEAVES:0)
Block(-19,7,25,LEAVES:0)
Block(-19,7,28,LEAVES:0)
Block(-19,8,12,LEAVES:0)
Block(-19,8,13,LEAVES:0)
Block(-19,8,17,LEAVES:0)
Block(-19,8,19,LEAVES:0)
Block(-19,8,20,17:12)
Block(-19,8,21,LEAVES:0)
Block(-19,8,25,LEAVES:0)
Block(-19,8,26,LEAVES:0)
Block(-19,9,11,LEAVES:0)
Block(-19,9,13,LEAVES:0)
Block(-19,9,19,LEAVES:0)
Block(-19,9,20,LEAVES:0)
Block(-19,10,18,LEAVES:0)
Block(-19,10,20,LEAVES:0)
Block(-18,2,20,17:12)
Block(-18,2,21,17:12)
Block(-18,2,25,LEAVES:0)
Block(-18,2,26,LEAVES:0)
Block(-18,3,11,LEAVES:0)
Block(-18,3,12,LEAVES:0)
Block(-18,3,21,17:12)
Block(-18,3,24,LEAVES:0)
Block(-18,3,27,LEAVES:0)
Block(-18,3,28,LEAVES:0)
Block(-18,3,29,LEAVES:0)
Block(-18,3,30,LEAVES:0)
Block(-18,4,14,LEAVES:0)
Block(-18,4,15,17:12)
Block(-18,4,16,17:12)
Block(-18,4,17,17:12)
Block(-18,4,18,17:12)
Block(-18,4,26,LEAVES:0)
Block(-18,5,11,LEAVES:0)
Block(-18,5,13,LEAVES:0)
Block(-18,5,15,17:12)
Block(-18,5,18,17:12)
Block(-18,5,22,LEAVES:0)
Block(-18,5,23,LEAVES:0)
Block(-18,5,27,LEAVES:0)
Block(-18,6,14,LEAVES:0)
Block(-18,6,15,17:12)
Block(-18,6,18,17:12)
Block(-18,6,19,17:12)
Block(-18,6,21,LEAVES:0)
Block(-18,6,22,LEAVES:0)
Block(-18,6,23,LEAVES:0)
Block(-18,6,24,LEAVES:0)
Block(-18,6,25,LEAVES:0)
Block(-18,6,26,LEAVES:0)
Block(-18,6,27,LEAVES:0)
Block(-18,7,11,LEAVES:0)
Block(-18,7,12,LEAVES:0)
Block(-18,7,13,17:12)
Block(-18,7,14,LEAVES:0)
Block(-18,7,15,LEAVES:0)
Block(-18,7,21,LEAVES:0)
Block(-18,7,23,LEAVES:0)
Block(-18,8,16,LEAVES:0)
Block(-18,8,18,LEAVES:0)
Block(-18,8,19,LEAVES:0)
Block(-18,8,21,LEAVES:0)
Block(-18,8,22,LEAVES:0)
Block(-18,8,24,LEAVES:0)
Block(-18,8,26,LEAVES:0)
Block(-18,9,13,LEAVES:0)
Block(-18,9,14,LEAVES:0)
Block(-18,9,23,LEAVES:0)
Block(-18,10,20,LEAVES:0)
Block(-18,10,21,LEAVES:0)
Block(-17,0,19,17:12)
Block(-17,1,19,17:12)
Block(-17,2,19,17:12)
Block(-17,2,20,17:12)
Block(-17,2,25,LEAVES:0)
Block(-17,3,10,LEAVES:0)
Block(-17,3,11,LEAVES:0)
Block(-17,3,17,17:12)
Block(-17,3,18,17:12)
Block(-17,3,21,17:12)
Block(-17,3,22,17:12)
Block(-17,3,23,17:12)
Block(-17,3,25,LEAVES:0)
Block(-17,3,28,LEAVES:0)
Block(-17,4,9,LEAVES:0)
Block(-17,4,12,LEAVES:0)
Block(-17,4,13,LEAVES:0)
Block(-17,4,14,LEAVES:0)
Block(-17,4,15,LEAVES:0)
Block(-17,4,17,17:12)
Block(-17,4,21,17:12)
Block(-17,4,22,LEAVES:0)
Block(-17,4,23,17:12)
Block(-17,4,24,17:12)
Block(-17,4,25,LEAVES:0)
Block(-17,4,26,LEAVES:0)
Block(-17,4,28,LEAVES:0)
Block(-17,4,29,LEAVES:0)
Block(-17,5,11,LEAVES:0)
Block(-17,5,22,LEAVES:0)
Block(-17,5,23,17:12)
Block(-17,5,27,LEAVES:0)
Block(-17,6,10,LEAVES:0)
Block(-17,6,12,LEAVES:0)
Block(-17,6,17,LEAVES:0)
Block(-17,6,18,LEAVES:0)
Block(-17,6,19,LEAVES:0)
Block(-17,6,22,LEAVES:0)
Block(-17,6,23,17:12)
Block(-17,6,25,LEAVES:0)
Block(-17,6,27,LEAVES:0)
Block(-17,6,28,LEAVES:0)
Block(-17,7,10,LEAVES:0)
Block(-17,7,11,LEAVES:0)
Block(-17,7,13,LEAVES:0)
Block(-17,7,14,LEAVES:0)
Block(-17,7,15,LEAVES:0)
Block(-17,7,17,LEAVES:0)
Block(-17,7,19,LEAVES:0)
Block(-17,7,20,LEAVES:0)
Block(-17,7,22,LEAVES:0)
Block(-17,7,23,LEAVES:0)
Block(-17,7,25,LEAVES:0)
Block(-17,7,26,LEAVES:0)
Block(-17,8,11,LEAVES:0)
Block(-17,8,17,LEAVES:0)
Block(-17,8,18,LEAVES:0)
Block(-17,8,19,LEAVES:0)
Block(-17,8,20,LEAVES:0)
Block(-17,8,21,LEAVES:0)
Block(-17,8,22,LEAVES:0)
Block(-17,8,24,LEAVES:0)
Block(-17,9,14,LEAVES:0)
Block(-17,9,18,LEAVES:0)
Block(-17,9,24,LEAVES:0)
Block(-17,9,25,LEAVES:0)
Block(-17,10,21,LEAVES:0)
Block(-16,0,19,17:12)
Block(-16,0,20,17:12)
Block(-16,1,19,17:12)
Block(-16,1,20,17:12)
Block(-16,2,18,17:12)
Block(-16,2,19,17:12)
Block(-16,3,10,LEAVES:0)
Block(-16,3,18,17:12)
Block(-16,3,19,17:12)
Block(-16,3,26,LEAVES:0)
Block(-16,4,10,LEAVES:0)
Block(-16,4,13,LEAVES:0)
Block(-16,4,21,LEAVES:0)
Block(-16,4,22,LEAVES:0)
Block(-16,4,24,17:12)
Block(-16,4,25,17:12)
Block(-16,4,26,17:12)
Block(-16,4,27,17:12)
Block(-16,4,28,LEAVES:0)
Block(-16,5,10,LEAVES:0)
Block(-16,5,11,LEAVES:0)
Block(-16,5,13,LEAVES:0)
Block(-16,5,14,LEAVES:0)
Block(-16,5,21,LEAVES:0)
Block(-16,5,24,LEAVES:0)
Block(-16,5,26,LEAVES:0)
Block(-16,5,27,LEAVES:0)
Block(-16,6,12,LEAVES:0)
Block(-16,6,16,LEAVES:0)
Block(-16,6,17,LEAVES:0)
Block(-16,6,21,LEAVES:0)
Block(-16,6,23,17:12)
Block(-16,6,24,LEAVES:0)
Block(-16,6,25,LEAVES:0)
Block(-16,6,27,LEAVES:0)
Block(-16,7,12,LEAVES:0)
Block(-16,7,13,LEAVES:0)
Block(-16,7,15,LEAVES:0)
Block(-16,7,18,LEAVES:0)
Block(-16,7,19,17:12)
Block(-16,7,20,LEAVES:0)
Block(-16,7,21,LEAVES:0)
Block(-16,7,23,LEAVES:0)
Block(-16,7,24,LEAVES:0)
Block(-16,7,25,LEAVES:0)
Block(-16,8,11,LEAVES:0)
Block(-16,8,13,LEAVES:0)
Block(-16,8,17,LEAVES:0)
Block(-16,8,23,LEAVES:0)
Block(-16,8,24,LEAVES:0)
Block(-16,9,18,LEAVES:0)
Block(-16,9,20,LEAVES:0)
Block(-16,9,22,LEAVES:0)
Block(-16,9,24,LEAVES:0)
Block(-15,3,18,17:12)
Block(-15,3,28,LEAVES:0)
Block(-15,4,11,LEAVES:0)
Block(-15,4,17,17:12)
Block(-15,4,18,17:12)
Block(-15,4,20,LEAVES:0)
Block(-15,4,21,LEAVES:0)
Block(-15,4,25,LEAVES:0)
Block(-15,4,26,LEAVES:0)
Block(-15,4,28,LEAVES:0)
Block(-15,4,29,LEAVES:0)
Block(-15,5,9,LEAVES:0)
Block(-15,5,11,LEAVES:0)
Block(-15,5,12,17:12)
Block(-15,5,13,17:12)
Block(-15,5,14,17:12)
Block(-15,5,19,LEAVES:0)
Block(-15,5,21,17:12)
Block(-15,5,22,17:12)
Block(-15,5,23,LEAVES:0)
Block(-15,5,24,LEAVES:0)
Block(-15,5,25,LEAVES:0)
Block(-15,5,30,LEAVES:0)
Block(-15,6,11,LEAVES:0)
Block(-15,6,12,LEAVES:0)
Block(-15,6,16,LEAVES:0)
Block(-15,6,21,LEAVES:0)
Block(-15,6,25,LEAVES:0)
Block(-15,6,27,LEAVES:0)
Block(-15,6,28,LEAVES:0)
Block(-15,7,10,LEAVES:0)
Block(-15,7,12,LEAVES:0)
Block(-15,7,16,LEAVES:0)
Block(-15,7,18,17:12)
Block(-15,7,19,17:12)
Block(-15,7,22,LEAVES:0)
Block(-15,7,23,LEAVES:0)
Block(-15,7,25,LEAVES:0)
Block(-15,7,26,LEAVES:0)
Block(-15,8,16,LEAVES:0)
Block(-15,8,17,LEAVES:0)
Block(-15,8,19,LEAVES:0)
Block(-15,8,20,LEAVES:0)
Block(-15,8,27,LEAVES:0)
Block(-15,9,18,LEAVES:0)
Block(-15,9,24,LEAVES:0)
Block(-15,9,25,LEAVES:0)
Block(-15,10,18,LEAVES:0)
Block(-15,10,19,LEAVES:0)
Block(-14,1,20,LEAVES:0)
Block(-14,3,24,LEAVES:0)
Block(-14,4,13,LEAVES:0)
Block(-14,4,16,LEAVES:0)
Block(-14,4,17,17:12)
Block(-14,4,18,17:12)
Block(-14,4,20,LEAVES:0)
Block(-14,4,24,LEAVES:0)
Block(-14,4,25,LEAVES:0)
Block(-14,4,27,LEAVES:0)
Block(-14,4,28,LEAVES:0)
Block(-14,4,29,LEAVES:0)
Block(-14,5,10,LEAVES:0)
Block(-14,5,11,LEAVES:0)
Block(-14,5,13,LEAVES:0)
Block(-14,5,14,17:12)
Block(-14,5,15,17:12)
Block(-14,5,16,LEAVES:0)
Block(-14,5,20,LEAVES:0)
Block(-14,5,22,17:12)
Block(-14,5,23,LEAVES:0)
Block(-14,5,25,LEAVES:0)
Block(-14,6,15,LEAVES:0)
Block(-14,6,20,LEAVES:0)
Block(-14,6,21,LEAVES:0)
Block(-14,6,23,LEAVES:0)
Block(-14,6,24,LEAVES:0)
Block(-14,6,28,LEAVES:0)
Block(-14,7,12,LEAVES:0)
Block(-14,7,13,LEAVES:0)
Block(-14,7,17,LEAVES:0)
Block(-14,7,18,LEAVES:0)
Block(-14,7,21,LEAVES:0)
Block(-14,7,22,LEAVES:0)
Block(-14,7,24,LEAVES:0)
Block(-14,7,25,LEAVES:0)
Block(-14,7,26,LEAVES:0)
Block(-14,8,15,LEAVES:0)
Block(-14,8,17,LEAVES:0)
Block(-14,8,18,LEAVES:0)
Block(-14,8,19,LEAVES:0)
Block(-14,8,22,LEAVES:0)
Block(-14,8,23,LEAVES:0)
Block(-14,9,17,LEAVES:0)
Block(-14,9,18,LEAVES:0)
Block(-14,9,25,LEAVES:0)
Block(-14,10,16,LEAVES:0)
Block(-14,10,18,LEAVES:0)
Block(-13,1,19,LEAVES:0)
Block(-13,1,20,LEAVES:0)
Block(-13,2,22,LEAVES:0)
Block(-13,3,15,LEAVES:0)
Block(-13,3,19,LEAVES:0)
Block(-13,3,21,LEAVES:0)
Block(-13,4,9,LEAVES:0)
Block(-13,4,16,17:12)
Block(-13,4,18,17:12)
Block(-13,4,19,17:12)
Block(-13,5,9,LEAVES:0)
Block(-13,5,10,LEAVES:0)
Block(-13,5,12,LEAVES:0)
Block(-13,5,13,LEAVES:0)
Block(-13,5,14,LEAVES:0)
Block(-13,5,21,LEAVES:0)
Block(-13,5,22,LEAVES:0)
Block(-13,5,25,LEAVES:0)
Block(-13,5,27,LEAVES:0)
Block(-13,6,10,LEAVES:0)
Block(-13,6,19,LEAVES:0)
Block(-13,6,21,LEAVES:0)
Block(-13,6,22,LEAVES:0)
Block(-13,6,23,LEAVES:0)
Block(-13,7,13,LEAVES:0)
Block(-13,7,19,LEAVES:0)
Block(-13,7,21,LEAVES:0)
Block(-13,7,22,LEAVES:0)
Block(-13,8,16,LEAVES:0)
Block(-13,8,17,LEAVES:0)
Block(-13,8,19,LEAVES:0)
Block(-13,8,20,LEAVES:0)
Block(-13,8,22,LEAVES:0)
Block(-13,8,24,LEAVES:0)
Block(-13,9,21,LEAVES:0)
Block(-13,10,18,LEAVES:0)
Block(-13,10,19,LEAVES:0)
Block(-12,1,18,LEAVES:0)
Block(-12,1,19,LEAVES:0)
Block(-12,2,17,LEAVES:0)
Block(-12,2,20,LEAVES:0)
Block(-12,2,21,LEAVES:0)
Block(-12,2,22,LEAVES:0)
Block(-12,2,23,LEAVES:0)
Block(-12,3,14,LEAVES:0)
Block(-12,3,15,LEAVES:0)
Block(-12,3,19,LEAVES:0)
Block(-12,4,16,LEAVES:0)
Block(-12,4,17,LEAVES:0)
Block(-12,4,19,17:12)
Block(-12,4,20,LEAVES:0)
Block(-12,5,14,LEAVES:0)
Block(-12,5,15,17:12)
Block(-12,5,16,LEAVES:0)
Block(-12,5,23,LEAVES:0)
Block(-12,6,10,LEAVES:0)
Block(-12,6,12,LEAVES:0)
Block(-12,6,20,LEAVES:0)
Block(-12,6,21,LEAVES:0)
Block(-12,6,23,LEAVES:0)
Block(-12,6,24,LEAVES:0)
Block(-12,7,15,LEAVES:0)
Block(-12,7,25,LEAVES:0)
Block(-12,8,15,LEAVES:0)
Block(-12,8,16,LEAVES:0)
Block(-12,8,18,LEAVES:0)
Block(-12,8,19,LEAVES:0)
Block(-12,8,20,LEAVES:0)
Block(-12,8,22,LEAVES:0)
Block(-12,8,23,LEAVES:0)
Block(-12,9,16,LEAVES:0)
Block(-12,10,19,LEAVES:0)
Block(-11,1,18,LEAVES:0)
Block(-11,2,18,LEAVES:0)
Block(-11,2,21,LEAVES:0)
Block(-11,3,13,LEAVES:0)
Block(-11,3,14,LEAVES:0)
Block(-11,3,18,LEAVES:0)
Block(-11,3,19,LEAVES:0)
Block(-11,3,20,17:12)
Block(-11,3,21,LEAVES:0)
Block(-11,3,22,LEAVES:0)
Block(-11,4,12,LEAVES:0)
Block(-11,4,15,LEAVES:0)
Block(-11,4,16,LEAVES:0)
Block(-11,4,17,LEAVES:0)
Block(-11,4,18,LEAVES:0)
Block(-11,4,19,LEAVES:0)
Block(-11,4,20,LEAVES:0)
Block(-11,5,14,LEAVES:0)
Block(-11,5,15,17:12)
Block(-11,5,19,LEAVES:0)
Block(-11,5,20,LEAVES:0)
Block(-11,5,21,LEAVES:0)
Block(-11,6,15,LEAVES:0)
Block(-11,6,19,LEAVES:0)
Block(-11,6,20,LEAVES:0)
Block(-11,6,22,LEAVES:0)
Block(-11,6,23,LEAVES:0)
Block(-11,6,24,LEAVES:0)
Block(-11,7,20,LEAVES:0)
Block(-11,8,23,LEAVES:0)
Block(-11,9,16,LEAVES:0)
Block(-11,9,18,LEAVES:0)
Block(-10,2,19,LEAVES:0)
Block(-10,3,13,LEAVES:0)
Block(-10,3,17,LEAVES:0)
Block(-10,3,19,LEAVES:0)
Block(-10,3,20,17:12)
Block(-10,3,21,LEAVES:0)
Block(-10,4,13,LEAVES:0)
Block(-10,4,16,LEAVES:0)
Block(-10,4,19,LEAVES:0)
Block(-10,4,20,LEAVES:0)
Block(-10,5,13,LEAVES:0)
Block(-10,5,14,LEAVES:0)
Block(-10,5,15,17:12)
Block(-10,5,16,LEAVES:0)
Block(-10,5,17,LEAVES:0)
Block(-10,5,18,LEAVES:0)
Block(-10,5,20,LEAVES:0)
Block(-10,6,15,LEAVES:0)
Block(-10,7,15,LEAVES:0)
Block(-10,7,16,LEAVES:0)
Block(-10,7,20,LEAVES:0)
Block(-10,7,22,LEAVES:0)
Block(-9,2,21,LEAVES:0)
Block(-9,3,18,LEAVES:0)
Block(-9,3,19,LEAVES:0)
Block(-9,3,21,LEAVES:0)
Block(-9,3,22,LEAVES:0)
Block(-9,4,14,LEAVES:0)
Block(-9,4,23,LEAVES:0)
Block(-9,5,12,LEAVES:0)
Block(-9,5,14,LEAVES:0)
Block(-9,5,15,17:12)
Block(-9,5,16,LEAVES:0)
Block(-9,5,20,LEAVES:0)
Block(-9,5,21,LEAVES:0)
Block(-9,6,14,LEAVES:0)
Block(-9,6,15,LEAVES:0)
Block(-9,7,13,LEAVES:0)
Block(-9,7,15,LEAVES:0)
Block(-8,2,17,LEAVES:0)
Block(-8,3,17,LEAVES:0)
Block(-8,3,18,LEAVES:0)
Block(-8,3,20,LEAVES:0)
Block(-8,3,21,LEAVES:0)
Block(-8,3,22,LEAVES:0)
Block(-8,4,16,LEAVES:0)
Block(-8,4,18,LEAVES:0)
Block(-8,5,13,LEAVES:0)
Block(-8,5,14,LEAVES:0)
Block(-8,5,16,LEAVES:0)
Block(-8,5,17,LEAVES:0)
Block(-8,5,21,LEAVES:0)
Block(-8,6,18,LEAVES:0)
Block(-8,7,15,LEAVES:0)
Block(-8,7,16,LEAVES:0)
Block(-7,4,12,LEAVES:0)
Block(-7,4,18,LEAVES:0)
Block(-7,4,20,LEAVES:0)
Block(-7,5,12,LEAVES:0)
Block(-7,5,13,LEAVES:0)
Block(-7,5,15,LEAVES:0)
Block(-7,5,16,LEAVES:0)
Block(-7,5,17,LEAVES:0)
Block(-7,6,13,LEAVES:0)
Block(-7,7,16,LEAVES:0)
Block(-6,6,13,LEAVES:0)
Block(-6,6,15,LEAVES:0)
#Block(0,0,0,41)


#######################################################################
# +-----------------------------------------------------------------+ #
# |                             Entities                            | #
# +-----------------------------------------------------------------+ #
#######################################################################

# Entity() spawns an entity instead of a block. The entity is spawned only once when the BO3 is spawned.
# Entities are persistent by default so they don't de-spawn when no player is near, they are only unloaded.
# Usage: Entity(x,y,z,mobName,groupSize,NameTagOrNBTFileName) or Entity(x,y,z,mobName,groupSize)
# Use /tc entities or /otg entities to get a list of entities that can be used as mobName, this includes entities added by other mods.
# NameTagOrNBTFileName can be either a nametag for the mob or an nbt file (such as mymobinfo.nbt or mymobinfo.txt).
# When using a text file you can use the same mob spawning parameters used with the /summon command to equip the
# entity and give it custom attributes etc. You can copy the DATA part of a summon command including surrounding
# curly braces to a .txt file, for instance for: "/summon Skeleton x y z {DATA}"

#######################################################################
# +-----------------------------------------------------------------+ #
# |                            BO3 checks                           | #
# +-----------------------------------------------------------------+ #
#######################################################################

# Require a condition at a certain location in order for the BO3 to be spawned.
# BlockCheck(x,y,z,BlockName[,BlockName[,...]]) - one of the blocks must be at the location
# BlockCheckNot(x,y,z,BlockName[,BlockName[,...]]) - all the blocks must not be at the location
# LightCheck(x,y,z,minLightLevel,maxLightLevel) - light must be between min and max (inclusive)

# You can use "Solid" as a BlockName for matching all solid blocks or "All" to match all blocks that aren't air.

# Examples:
#   BlockCheck(0,-1,0,GRASS,DIRT)  Require grass or dirt just below the object
#   BlockCheck(0,-1,0,Solid)       Require any solid block just below the object
#   BlockCheck(0,-1,0,WOOL)        Require any type of wool just below the object
#   BlockCheck(0,-1,0,WOOL:0)      Require white wool just below the object
#   BlockCheckNot(0,-1,0,WOOL:0)   Require that there is no white wool below the object
#   LightCheck(0,0,0,0,LEAVES:0)          Require almost complete darkness just below the object

BlockCheck(0,-1,0,GRASS,DIRT)