#######################################################################
# +-----------------------------------------------------------------+ #
# |                            BO3 object                           | #
# +-----------------------------------------------------------------+ #
#######################################################################

# The descriptions in this file are accurate only for TerrainControl and OTG.
# For MCW and OTG+ these descriptions are only accurate if the BO3 is used as a CustomObject.
# MCW and OTG+ completely reimplemented CustomStructure, check the MCW/OTG+ documentation for more information.

# This is the config file of a custom object.
# If you add this object correctly to your BiomeConfigs, it will spawn in the world.

# This is the creator of this BO3 object
Author: Unknown

# A short description of this BO3 object
Description: This BO3 was converted from a schematic using OTGEdit. The author and description information of the schematic could not be found. If you know who the author of the schematic is then please add this information.

# The BO3 version, don't change this! It can be used by external applications to do a version check.
Version: 3

# The settings mode, WriteAll, WriteWithoutComments or WriteDisable. See WorldConfig.
SettingsMode: WriteDisable

#######################################################################
# +-----------------------------------------------------------------+ #
# |                          Main settings                          | #
# +-----------------------------------------------------------------+ #
#######################################################################

# This needs to be set to true to spawn the object in the Tree and Sapling resources.
Tree: true

# The frequency of the BO3 from 1 to 200. Tries this many times to spawn this BO3 when using the CustomObject(...) resource.
# Ignored by Tree(..), Sapling(..) and CustomStructure(..)
Frequency: 40

# The rarity of the BO3 from 0 to 100. Each spawn attempt has rarity% chance to succeed when using the CustomObject(...) resource.
# Ignored by Tree(..), Sapling(..) and CustomStructure(..)
Rarity: 100.0

# If you set this to true, the BO3 will be placed with a random rotation.
RotateRandomly: true

# The spawn height of the BO3 - randomY, highestBlock or highestSolidBlock.
SpawnHeight: highestSolidBlock

# The height limits for the BO3.
MinHeight: 63

MaxHeight: 120

# Objects can have other objects attached to it: branches. Branches can also
# have branches attached to it, which can also have branches, etc. This is the
# maximum branch depth for this objects.
MaxBranchDepth: 10

# When spawned with the UseWorld keyword, this BO3 should NOT spawn in the following biomes.
# If you writer.write the BO3 name directly in the BiomeConfigs, this will be ignored.
ExcludedBiomes: All

# To optimise this BO3 for faster loading times you can use Notepad++ to find/replace comments and abbreviate things.
# Notepad++ find/replace with regex:
# Find: ^[#;].* replace to nothing removes all lines starting with # 
# Find: ^\s*$ replace to nothing removes most empty lines 
# Notepad++ find/replace without regex:
# *Warning: This will only work for OTG 1.10.2 v21 / OTG 1.11.2 v6 or higher. B( is not recognised by lower versions.
# Find: Block( replace to B(

#######################################################################
# +-----------------------------------------------------------------+ #
# |                      Source block settings                      | #
# +-----------------------------------------------------------------+ #
#######################################################################

# The block(s) the BO3 should spawn in.
SourceBlocks: STONE:1,STONE:3,STONE:5,DIRT:1,DIRT,SAND,GRASS,DIRT:2,STATIONARY_WATER,HARD_CLAY,STAINED_CLAY,CLAY,SANDSTONE,SAND:1,AIR,STONE,GRAVEL,LONG_GRASS,LONG_GRASS:1,LONG_GRASS:2,DEAD_BUSH,YELLOW_FLOWER,RED_ROSE,BROWN_MUSHROOM,RED_MUSHROOM

# The maximum percentage of the BO3 that can be outside the SourceBlock.
# The BO3 won't be placed on a location with more blocks outside the SourceBlock than this percentage.
MaxPercentageOutsideSourceBlock: 0

# What to do when a block is about to be placed outside the SourceBlock? (dontPlace, placeAnyway)
OutsideSourceBlock: placeAnyway

#######################################################################
# +-----------------------------------------------------------------+ #
# |                              Blocks                             | #
# +-----------------------------------------------------------------+ #
#######################################################################

# All the blocks used in the BO3 are listed here. Possible blocks:
# Block(x,y,z,id[.data][,nbtfile.nbt) or B(x,y,z,id[.data][,nbtfile.nbt)
# RandomBlock(x,y,z,id[:data][,nbtfile.nbt],chance[,id[:data][,nbtfile.nbt],chance[,...]])
# So RandomBlock(0,0,0,CHEST,chest.nbt,50,CHEST,anotherchest.nbt,100) will spawn a chest at
# the BO3 origin, and give it a 50% chance to have the contents of chest.nbt, or, if that
# fails, a 100% percent chance to have the contents of anotherchest.nbt.

Block(-8,6,1,LEAVES:3)
Block(-8,7,1,LEAVES:3)
Block(-8,7,5,LEAVES:3)
Block(-8,8,1,LEAVES:3)
Block(-8,8,5,LEAVES:3)
Block(-8,9,1,LEAVES:3)
Block(-8,9,5,LEAVES:3)
Block(-8,10,1,LEAVES:3)
Block(-8,10,5,LEAVES:3)
Block(-8,11,2,LEAVES:3)
Block(-8,11,4,LEAVES:3)
Block(-8,11,5,LEAVES:3)
Block(-7,6,3,LEAVES:3)
Block(-7,7,3,LEAVES:3)
Block(-7,8,3,LEAVES:3)
Block(-7,9,3,LEAVES:3)
Block(-7,10,2,LEAVES:3)
Block(-7,10,3,LEAVES:3)
Block(-7,11,2,LEAVES:3)
Block(-7,11,4,LEAVES:3)
Block(-7,12,3,LEAVES:3)
Block(-7,12,4,LEAVES:3)
Block(-6,3,-5,LEAVES:3)
Block(-6,4,-5,LEAVES:3)
Block(-6,4,-1,LEAVES:3)
Block(-6,5,-5,LEAVES:3)
Block(-6,5,-1,LEAVES:3)
Block(-6,5,4,LEAVES:3)
Block(-6,6,-5,LEAVES:3)
Block(-6,6,-1,LEAVES:3)
Block(-6,6,4,LEAVES:3)
Block(-6,7,-5,LEAVES:3)
Block(-6,7,-1,LEAVES:3)
Block(-6,7,4,LEAVES:3)
Block(-6,8,-4,LEAVES:3)
Block(-6,8,-2,LEAVES:3)
Block(-6,8,-1,LEAVES:3)
Block(-6,8,4,LEAVES:3)
Block(-6,9,4,LEAVES:3)
Block(-6,10,2,LEAVES:3)
Block(-6,10,3,LEAVES:3)
Block(-6,10,4,LEAVES:3)
Block(-6,10,5,LEAVES:3)
Block(-6,11,2,LEAVES:3)
Block(-6,11,3,17:15)
Block(-6,11,4,LEAVES:3)
Block(-6,11,5,LEAVES:3)
Block(-6,12,2,LEAVES:3)
Block(-6,12,3,LEAVES:3)
Block(-6,12,4,LEAVES:3)
Block(-6,12,5,LEAVES:3)
Block(-6,13,3,LEAVES:3)
Block(-6,13,4,LEAVES:3)
Block(-5,0,5,LEAVES:3)
Block(-5,1,5,LEAVES:3)
Block(-5,1,9,LEAVES:3)
Block(-5,2,5,LEAVES:3)
Block(-5,2,9,LEAVES:3)
Block(-5,3,-3,LEAVES:3)
Block(-5,3,5,LEAVES:3)
Block(-5,3,9,LEAVES:3)
Block(-5,4,-3,LEAVES:3)
Block(-5,4,5,LEAVES:3)
Block(-5,4,9,LEAVES:3)
Block(-5,5,-3,LEAVES:3)
Block(-5,5,6,LEAVES:3)
Block(-5,5,8,LEAVES:3)
Block(-5,5,9,LEAVES:3)
Block(-5,6,-3,LEAVES:3)
Block(-5,7,-4,LEAVES:3)
Block(-5,7,-3,17:15)
Block(-5,7,1,LEAVES:3)
Block(-5,8,-4,LEAVES:3)
Block(-5,8,-2,LEAVES:3)
Block(-5,8,1,LEAVES:3)
Block(-5,8,5,LEAVES:3)
Block(-5,9,-3,LEAVES:3)
Block(-5,9,-2,LEAVES:3)
Block(-5,9,1,LEAVES:3)
Block(-5,9,4,LEAVES:3)
Block(-5,9,5,LEAVES:3)
Block(-5,10,1,LEAVES:3)
Block(-5,10,5,LEAVES:3)
Block(-5,11,2,17:15)
Block(-5,11,3,17:15)
Block(-5,11,4,LEAVES:3)
Block(-5,12,2,17:15)
Block(-5,12,3,LEAVES:3)
Block(-4,0,7,LEAVES:3)
Block(-4,1,7,LEAVES:3)
Block(-4,2,-2,LEAVES:3)
Block(-4,2,7,LEAVES:3)
Block(-4,3,-2,LEAVES:3)
Block(-4,3,7,LEAVES:3)
Block(-4,4,-2,LEAVES:3)
Block(-4,4,6,LEAVES:3)
Block(-4,4,7,LEAVES:3)
Block(-4,5,-2,LEAVES:3)
Block(-4,5,6,LEAVES:3)
Block(-4,5,8,LEAVES:3)
Block(-4,6,-2,LEAVES:3)
Block(-4,6,7,LEAVES:3)
Block(-4,6,8,LEAVES:3)
Block(-4,7,-4,LEAVES:3)
Block(-4,7,-3,17:15)
Block(-4,7,-2,LEAVES:3)
Block(-4,7,-1,LEAVES:3)
Block(-4,8,-4,LEAVES:3)
Block(-4,8,-3,17:15)
Block(-4,8,-2,17:15)
Block(-4,8,-1,LEAVES:3)
Block(-4,9,-4,LEAVES:3)
Block(-4,9,-3,LEAVES:3)
Block(-4,9,-2,LEAVES:3)
Block(-4,9,-1,LEAVES:3)
Block(-4,9,3,LEAVES:3)
Block(-4,10,-3,LEAVES:3)
Block(-4,10,-2,LEAVES:3)
Block(-4,10,3,LEAVES:3)
Block(-4,11,3,LEAVES:3)
Block(-4,12,2,17:15)
Block(-4,13,-7,LEAVES:3)
Block(-4,14,-7,LEAVES:3)
Block(-4,14,-3,LEAVES:3)
Block(-4,15,-7,LEAVES:3)
Block(-4,15,-3,LEAVES:3)
Block(-4,16,-7,LEAVES:3)
Block(-4,16,-3,LEAVES:3)
Block(-4,17,-7,LEAVES:3)
Block(-4,17,-3,LEAVES:3)
Block(-4,18,-6,LEAVES:3)
Block(-4,18,-4,LEAVES:3)
Block(-4,18,-3,LEAVES:3)
Block(-3,-1,8,LEAVES:3)
Block(-3,0,8,LEAVES:3)
Block(-3,1,8,LEAVES:3)
Block(-3,2,8,LEAVES:3)
Block(-3,3,8,LEAVES:3)
Block(-3,4,-5,LEAVES:3)
Block(-3,4,6,LEAVES:3)
Block(-3,4,7,LEAVES:3)
Block(-3,4,8,LEAVES:3)
Block(-3,4,9,LEAVES:3)
Block(-3,5,-5,LEAVES:3)
Block(-3,5,-1,LEAVES:3)
Block(-3,5,5,17:15)
Block(-3,5,6,17:15)
Block(-3,5,7,17:15)
Block(-3,5,8,LEAVES:3)
Block(-3,5,9,LEAVES:3)
Block(-3,6,-5,LEAVES:3)
Block(-3,6,-2,LEAVES:3)
Block(-3,6,-1,LEAVES:3)
Block(-3,6,5,17:15)
Block(-3,6,6,LEAVES:3)
Block(-3,6,7,LEAVES:3)
Block(-3,6,8,LEAVES:3)
Block(-3,6,9,LEAVES:3)
Block(-3,7,-5,LEAVES:3)
Block(-3,7,-1,LEAVES:3)
Block(-3,7,7,LEAVES:3)
Block(-3,7,8,LEAVES:3)
Block(-3,8,-3,LEAVES:3)
Block(-3,8,-2,17:15)
Block(-3,9,-3,LEAVES:3)
Block(-3,11,2,17:15)
Block(-3,12,2,17:15)
Block(-3,13,-5,LEAVES:3)
Block(-3,14,-5,LEAVES:3)
Block(-3,15,-5,LEAVES:3)
Block(-3,16,-5,LEAVES:3)
Block(-3,16,2,LEAVES:3)
Block(-3,17,-6,LEAVES:3)
Block(-3,17,-5,LEAVES:3)
Block(-3,17,2,LEAVES:3)
Block(-3,17,6,LEAVES:3)
Block(-3,18,-6,LEAVES:3)
Block(-3,18,-4,LEAVES:3)
Block(-3,18,2,LEAVES:3)
Block(-3,18,6,LEAVES:3)
Block(-3,19,-5,LEAVES:3)
Block(-3,19,-4,LEAVES:3)
Block(-3,19,2,LEAVES:3)
Block(-3,19,6,LEAVES:3)
Block(-3,20,2,LEAVES:3)
Block(-3,20,6,LEAVES:3)
Block(-3,21,3,LEAVES:3)
Block(-3,21,5,LEAVES:3)
Block(-3,21,6,LEAVES:3)
Block(-2,1,5,LEAVES:3)
Block(-2,2,5,LEAVES:3)
Block(-2,2,9,LEAVES:3)
Block(-2,3,5,LEAVES:3)
Block(-2,3,8,LEAVES:3)
Block(-2,3,9,LEAVES:3)
Block(-2,4,5,LEAVES:3)
Block(-2,4,9,LEAVES:3)
Block(-2,5,7,LEAVES:3)
Block(-2,5,8,LEAVES:3)
Block(-2,6,-3,LEAVES:3)
Block(-2,6,3,17:15)
Block(-2,6,4,17:15)
Block(-2,6,5,17:15)
Block(-2,6,7,LEAVES:3)
Block(-2,7,-3,LEAVES:3)
Block(-2,8,-3,LEAVES:3)
Block(-2,8,-2,17:15)
Block(-2,8,-1,17:15)
Block(-2,11,2,17:15)
Block(-2,12,-4,LEAVES:3)
Block(-2,13,-4,LEAVES:3)
Block(-2,14,-4,LEAVES:3)
Block(-2,15,-4,LEAVES:3)
Block(-2,16,-4,LEAVES:3)
Block(-2,16,4,LEAVES:3)
Block(-2,17,-6,LEAVES:3)
Block(-2,17,-5,LEAVES:3)
Block(-2,17,-4,LEAVES:3)
Block(-2,17,-3,LEAVES:3)
Block(-2,17,4,LEAVES:3)
Block(-2,18,-6,LEAVES:3)
Block(-2,18,-5,17:15)
Block(-2,18,-4,17:15)
Block(-2,18,-3,LEAVES:3)
Block(-2,18,4,LEAVES:3)
Block(-2,19,-6,LEAVES:3)
Block(-2,19,-5,LEAVES:3)
Block(-2,19,-4,LEAVES:3)
Block(-2,19,-3,LEAVES:3)
Block(-2,19,4,LEAVES:3)
Block(-2,20,-5,LEAVES:3)
Block(-2,20,-4,LEAVES:3)
Block(-2,20,3,LEAVES:3)
Block(-2,20,4,LEAVES:3)
Block(-2,21,3,LEAVES:3)
Block(-2,21,5,LEAVES:3)
Block(-2,22,4,LEAVES:3)
Block(-2,22,5,LEAVES:3)
Block(-1,3,1,17:15)
Block(-1,3,2,17:15)
Block(-1,3,7,LEAVES:3)
Block(-1,4,2,17:15)
Block(-1,4,7,LEAVES:3)
Block(-1,5,2,17:15)
Block(-1,5,3,17:15)
Block(-1,5,7,LEAVES:3)
Block(-1,6,3,17:15)
Block(-1,7,-1,17:15)
Block(-1,8,-1,17:15)
Block(-1,10,1,17:15)
Block(-1,11,1,17:15)
Block(-1,11,2,17:15)
Block(-1,14,-7,LEAVES:3)
Block(-1,15,-7,LEAVES:3)
Block(-1,15,-3,LEAVES:3)
Block(-1,15,5,LEAVES:3)
Block(-1,16,-7,LEAVES:3)
Block(-1,16,-4,LEAVES:3)
Block(-1,16,-3,LEAVES:3)
Block(-1,16,5,LEAVES:3)
Block(-1,17,-7,LEAVES:3)
Block(-1,17,-3,LEAVES:3)
Block(-1,17,5,LEAVES:3)
Block(-1,18,-5,LEAVES:3)
Block(-1,18,-4,LEAVES:3)
Block(-1,18,5,LEAVES:3)
Block(-1,19,-5,LEAVES:3)
Block(-1,19,-4,17:15)
Block(-1,19,-3,17:15)
Block(-1,19,-2,17:15)
Block(-1,19,5,LEAVES:3)
Block(-1,20,3,17:15)
Block(-1,20,4,LEAVES:3)
Block(-1,20,5,LEAVES:3)
Block(-1,20,6,LEAVES:3)
Block(-1,21,3,17:15)
Block(-1,21,4,17:15)
Block(-1,21,5,LEAVES:3)
Block(-1,21,6,LEAVES:3)
Block(-1,22,3,LEAVES:3)
Block(-1,22,4,LEAVES:3)
Block(-1,22,5,LEAVES:3)
Block(-1,22,6,LEAVES:3)
Block(-1,23,4,LEAVES:3)
Block(-1,23,5,LEAVES:3)
Block(0,-1,0,17:15)
Block(0,-1,1,17:15)
Block(0,0,0,LOG:3)
Block(0,0,1,17:15)
Block(0,1,0,17:15)
Block(0,1,1,17:15)
Block(0,2,0,17:15)
Block(0,2,1,17:15)
Block(0,3,0,17:15)
Block(0,3,1,17:15)
Block(0,4,0,17:15)
Block(0,4,1,17:15)
Block(0,5,-1,17:15)
Block(0,5,0,17:15)
Block(0,6,-1,17:15)
Block(0,6,0,17:15)
Block(0,7,-1,17:15)
Block(0,9,1,17:15)
Block(0,10,1,17:15)
Block(0,16,-5,LEAVES:3)
Block(0,17,-5,LEAVES:3)
Block(0,17,0,17:15)
Block(0,17,2,LEAVES:3)
Block(0,18,-5,LEAVES:3)
Block(0,18,-1,17:15)
Block(0,18,0,17:15)
Block(0,18,2,LEAVES:3)
Block(0,18,6,LEAVES:3)
Block(0,19,-2,17:15)
Block(0,19,-1,17:15)
Block(0,19,2,17:15)
Block(0,19,5,LEAVES:3)
Block(0,19,6,LEAVES:3)
Block(0,20,2,17:15)
Block(0,20,3,17:15)
Block(0,20,6,LEAVES:3)
Block(0,21,4,LEAVES:3)
Block(0,21,5,LEAVES:3)
Block(0,22,4,LEAVES:3)
Block(1,-1,0,17:15)
Block(1,0,0,17:15)
Block(1,1,0,17:15)
Block(1,2,0,17:15)
Block(1,3,-1,17:15)
Block(1,3,0,17:15)
Block(1,4,-1,17:15)
Block(1,5,-1,17:15)
Block(1,6,-1,17:15)
Block(1,6,0,17:15)
Block(1,7,-1,17:15)
Block(1,7,0,17:15)
Block(1,8,-1,17:15)
Block(1,8,0,17:15)
Block(1,8,1,17:15)
Block(1,9,-1,17:15)
Block(1,9,1,17:15)
Block(1,16,0,17:15)
Block(1,16,1,17:15)
Block(1,16,2,17:15)
Block(1,17,0,17:15)
Block(1,17,2,17:15)
Block(1,18,2,17:15)
Block(1,19,2,17:15)
Block(1,19,4,LEAVES:3)
Block(1,20,4,LEAVES:3)
Block(1,21,4,LEAVES:3)
Block(2,5,-9,LEAVES:3)
Block(2,5,-1,17:15)
Block(2,6,-9,LEAVES:3)
Block(2,6,-5,LEAVES:3)
Block(2,7,-9,LEAVES:3)
Block(2,7,-5,LEAVES:3)
Block(2,8,-9,LEAVES:3)
Block(2,8,-5,LEAVES:3)
Block(2,8,-1,17:15)
Block(2,9,-9,LEAVES:3)
Block(2,9,-5,LEAVES:3)
Block(2,9,-2,17:15)
Block(2,9,-1,17:15)
Block(2,9,1,17:15)
Block(2,9,2,17:15)
Block(2,10,-8,LEAVES:3)
Block(2,10,-6,LEAVES:3)
Block(2,10,-5,LEAVES:3)
Block(2,10,-3,17:15)
Block(2,10,-2,17:15)
Block(2,10,-1,17:15)
Block(2,10,2,17:15)
Block(2,11,-4,17:15)
Block(2,11,-3,17:15)
Block(2,11,-1,17:15)
Block(2,12,-1,17:15)
Block(2,12,0,17:15)
Block(2,13,-1,17:15)
Block(2,13,0,17:15)
Block(2,14,-1,17:15)
Block(2,14,0,17:15)
Block(2,14,1,17:15)
Block(2,15,0,17:15)
Block(2,15,1,17:15)
Block(2,16,0,17:15)
Block(2,16,1,17:15)
Block(3,4,3,LEAVES:3)
Block(3,5,-7,LEAVES:3)
Block(3,5,-1,17:15)
Block(3,5,3,LEAVES:3)
Block(3,5,7,LEAVES:3)
Block(3,6,-7,LEAVES:3)
Block(3,6,-2,17:15)
Block(3,6,-1,17:15)
Block(3,6,3,LEAVES:3)
Block(3,6,7,LEAVES:3)
Block(3,7,-7,LEAVES:3)
Block(3,7,3,LEAVES:3)
Block(3,7,7,LEAVES:3)
Block(3,8,-7,LEAVES:3)
Block(3,8,3,LEAVES:3)
Block(3,8,7,LEAVES:3)
Block(3,9,-8,LEAVES:3)
Block(3,9,-7,LEAVES:3)
Block(3,9,4,LEAVES:3)
Block(3,9,6,LEAVES:3)
Block(3,9,7,LEAVES:3)
Block(3,10,-8,LEAVES:3)
Block(3,10,-6,LEAVES:3)
Block(3,10,2,17:15)
Block(3,10,3,17:15)
Block(3,10,4,17:15)
Block(3,11,-7,LEAVES:3)
Block(3,11,-6,17:15)
Block(3,11,-5,17:15)
Block(3,11,-4,17:15)
Block(3,11,-1,17:15)
Block(3,12,-1,17:15)
Block(3,13,-1,17:15)
Block(4,4,-6,LEAVES:3)
Block(4,4,5,LEAVES:3)
Block(4,5,-6,LEAVES:3)
Block(4,5,5,LEAVES:3)
Block(4,6,-6,LEAVES:3)
Block(4,6,-2,17:15)
Block(4,6,5,LEAVES:3)
Block(4,7,-6,LEAVES:3)
Block(4,7,-2,17:15)
Block(4,7,5,LEAVES:3)
Block(4,8,-6,LEAVES:3)
Block(4,8,4,LEAVES:3)
Block(4,8,5,LEAVES:3)
Block(4,9,-8,LEAVES:3)
Block(4,9,-7,LEAVES:3)
Block(4,9,-6,LEAVES:3)
Block(4,9,-5,LEAVES:3)
Block(4,9,4,17:15)
Block(4,9,5,17:15)
Block(4,9,6,LEAVES:3)
Block(4,10,-8,LEAVES:3)
Block(4,10,-7,17:15)
Block(4,10,-6,17:15)
Block(4,10,-5,LEAVES:3)
Block(4,10,4,17:15)
Block(4,10,5,LEAVES:3)
Block(4,10,6,LEAVES:3)
Block(4,11,-8,LEAVES:3)
Block(4,11,-7,LEAVES:3)
Block(4,11,-6,17:15)
Block(4,11,-5,LEAVES:3)
Block(4,12,-7,LEAVES:3)
Block(4,12,-6,LEAVES:3)
Block(4,13,-1,17:15)
Block(4,14,-1,17:15)
Block(5,3,6,LEAVES:3)
Block(5,4,6,LEAVES:3)
Block(5,5,6,LEAVES:3)
Block(5,6,-9,LEAVES:3)
Block(5,6,6,LEAVES:3)
Block(5,7,-9,LEAVES:3)
Block(5,7,-5,LEAVES:3)
Block(5,7,-2,17:15)
Block(5,7,6,LEAVES:3)
Block(5,8,-9,LEAVES:3)
Block(5,8,-6,LEAVES:3)
Block(5,8,-5,LEAVES:3)
Block(5,8,4,LEAVES:3)
Block(5,8,5,LEAVES:3)
Block(5,8,6,LEAVES:3)
Block(5,8,7,LEAVES:3)
Block(5,9,-9,LEAVES:3)
Block(5,9,-5,LEAVES:3)
Block(5,9,4,LEAVES:3)
Block(5,9,5,17:15)
Block(5,9,6,LEAVES:3)
Block(5,9,7,LEAVES:3)
Block(5,10,-7,LEAVES:3)
Block(5,10,-6,LEAVES:3)
Block(5,10,4,LEAVES:3)
Block(5,10,5,LEAVES:3)
Block(5,10,6,LEAVES:3)
Block(5,10,7,LEAVES:3)
Block(5,11,-7,LEAVES:3)
Block(5,11,5,LEAVES:3)
Block(5,11,6,LEAVES:3)
Block(5,14,-1,17:15)
Block(6,5,3,LEAVES:3)
Block(6,6,3,LEAVES:3)
Block(6,6,7,LEAVES:3)
Block(6,7,-3,17:15)
Block(6,7,-2,17:15)
Block(6,7,3,LEAVES:3)
Block(6,7,6,LEAVES:3)
Block(6,7,7,LEAVES:3)
Block(6,8,-7,LEAVES:3)
Block(6,8,3,LEAVES:3)
Block(6,8,7,LEAVES:3)
Block(6,9,-7,LEAVES:3)
Block(6,9,5,LEAVES:3)
Block(6,9,6,LEAVES:3)
Block(6,10,-7,LEAVES:3)
Block(6,10,5,LEAVES:3)
Block(6,14,-1,17:15)
Block(6,15,-1,17:15)
Block(6,15,0,17:15)
Block(7,6,-3,17:15)
Block(7,7,-3,17:15)
Block(7,7,5,LEAVES:3)
Block(7,8,5,LEAVES:3)
Block(7,9,-2,LEAVES:3)
Block(7,9,5,LEAVES:3)
Block(7,10,-2,LEAVES:3)
Block(7,10,2,LEAVES:3)
Block(7,11,-2,LEAVES:3)
Block(7,11,2,LEAVES:3)
Block(7,12,-2,LEAVES:3)
Block(7,12,2,LEAVES:3)
Block(7,13,-2,LEAVES:3)
Block(7,13,2,LEAVES:3)
Block(7,14,-1,LEAVES:3)
Block(7,14,1,LEAVES:3)
Block(7,14,2,LEAVES:3)
Block(7,15,0,17:15)
Block(8,6,-3,17:15)
Block(8,9,0,LEAVES:3)
Block(8,10,0,LEAVES:3)
Block(8,11,0,LEAVES:3)
Block(8,12,0,LEAVES:3)
Block(8,13,-1,LEAVES:3)
Block(8,13,0,LEAVES:3)
Block(8,14,-1,LEAVES:3)
Block(8,14,0,17:15)
Block(8,14,1,LEAVES:3)
Block(8,15,0,17:15)
Block(8,15,1,LEAVES:3)
Block(9,8,1,LEAVES:3)
Block(9,9,1,LEAVES:3)
Block(9,10,1,LEAVES:3)
Block(9,11,1,LEAVES:3)
Block(9,12,1,LEAVES:3)
Block(9,13,-1,LEAVES:3)
Block(9,13,0,LEAVES:3)
Block(9,13,1,LEAVES:3)
Block(9,13,2,LEAVES:3)
Block(9,14,-1,LEAVES:3)
Block(9,14,0,17:15)
Block(9,14,1,LEAVES:3)
Block(9,14,2,LEAVES:3)
Block(9,15,-1,LEAVES:3)
Block(9,15,0,LEAVES:3)
Block(9,15,1,LEAVES:3)
Block(9,15,2,LEAVES:3)
Block(9,16,0,LEAVES:3)
Block(9,16,1,LEAVES:3)
Block(10,10,-2,LEAVES:3)
Block(10,11,-2,LEAVES:3)
Block(10,11,2,LEAVES:3)
Block(10,12,-2,LEAVES:3)
Block(10,12,1,LEAVES:3)
Block(10,12,2,LEAVES:3)
Block(10,13,-2,LEAVES:3)
Block(10,13,2,LEAVES:3)
Block(10,14,0,LEAVES:3)
Block(10,14,1,LEAVES:3)
Block(10,15,0,LEAVES:3)
Block(11,12,0,LEAVES:3)
Block(11,13,0,LEAVES:3)
Block(11,14,0,LEAVES:3)


#######################################################################
# +-----------------------------------------------------------------+ #
# |                             Entities                            | #
# +-----------------------------------------------------------------+ #
#######################################################################

# Entity() spawns an entity instead of a block. The entity is spawned only once when the BO3 is spawned.
# Entities are persistent by default so they don't de-spawn when no player is near, they are only unloaded.
# Usage: Entity(x,y,z,mobName,groupSize,NameTagOrNBTFileName) or Entity(x,y,z,mobName,groupSize)
# Use /tc entities or /otg entities to get a list of entities that can be used as mobName, this includes entities added by other mods.
# NameTagOrNBTFileName can be either a nametag for the mob or an nbt file (such as mymobinfo.nbt or mymobinfo.txt).
# When using a text file you can use the same mob spawning parameters used with the /summon command to equip the
# entity and give it custom attributes etc. You can copy the DATA part of a summon command including surrounding
# curly braces to a .txt file, for instance for: "/summon Skeleton x y z {DATA}"

#######################################################################
# +-----------------------------------------------------------------+ #
# |                            BO3 checks                           | #
# +-----------------------------------------------------------------+ #
#######################################################################

# Require a condition at a certain location in order for the BO3 to be spawned.
# BlockCheck(x,y,z,BlockName[,BlockName[,...]]) - one of the blocks must be at the location
# BlockCheckNot(x,y,z,BlockName[,BlockName[,...]]) - all the blocks must not be at the location
# LightCheck(x,y,z,minLightLevel,maxLightLevel) - light must be between min and max (inclusive)

# You can use "Solid" as a BlockName for matching all solid blocks or "All" to match all blocks that aren't air.

# Examples:
#   BlockCheck(0,-1,0,GRASS,DIRT)  Require grass or dirt just below the object
#   BlockCheck(0,-1,0,Solid)       Require any solid block just below the object
#   BlockCheck(0,-1,0,WOOL)        Require any type of wool just below the object
#   BlockCheck(0,-1,0,WOOL:0)      Require white wool just below the object
#   BlockCheckNot(0,-1,0,WOOL:0)   Require that there is no white wool below the object
#   LightCheck(0,0,0,0,LEAVES:3)          Require almost complete darkness just below the object

