
#######################################################################
# +-----------------------------------------------------------------+ #
# |                            BO3 object                           | #
# +-----------------------------------------------------------------+ #
#######################################################################

Author: LordSmellyPants

Description: No description given

Version: 3

SettingsMode: WriteWithoutComments


#######################################################################
# +-----------------------------------------------------------------+ #
# |                          Main settings                          | #
# +-----------------------------------------------------------------+ #
#######################################################################

Tree: true

Frequency: 1

Rarity: 25.0

RotateRandomly: true

SpawnHeight: highestSolidBlock

SpawnHeightOffset: 0

SpawnHeightVariance: 0

##############################
# Height Limits for the BO3. #
##############################

MinHeight: 63

MaxHeight: 71

######################
# Extrusion settings #
######################

ExtrudeMode: None

ExtrudeThroughBlocks: AIR

MaxBranchDepth: 10

ExcludedBiomes: All


#######################################################################
# +-----------------------------------------------------------------+ #
# |                      Source block settings                      | #
# +-----------------------------------------------------------------+ #
#######################################################################

SourceBlocks: STONE:1,STONE:3,STONE:5,DIRT:1,DIRT:0,SAND:0,GRASS:0,DIRT:2,STATIONARY_WATER:0,HARD_CLAY,STAINED_CLAY:0,CLAY,SANDSTONE:0,SAND:1,AIR,STONE:0,GRAVEL,LONG_GRASS:0,LONG_GRASS:1,LONG_GRASS:2,DEAD_BUSH,YELLOW_FLOWER:0,RED_ROSE:0,BROWN_MUSHROOM,RED_MUSHROOM

MaxPercentageOutsideSourceBlock: 0

OutsideSourceBlock: placeAnyway

DoReplaceBlocks: true

IsOTGPlus: false


#######################################################################
# +-----------------------------------------------------------------+ #
# |                              Blocks                             | #
# +-----------------------------------------------------------------+ #
#######################################################################

Block(-2,-1,-2,LOG:12)
Block(-2,-1,-1,LOG:12)
Block(-1,-1,-2,LOG:12)
Block(-1,-1,-1,LOG:12)
Block(-1,-1,0,LOG:12)
Block(-1,0,-2,LOG:12)
Block(-1,0,-1,LOG:12)
Block(-1,0,0,LOG:12)
Block(-1,1,-1,LOG:12)
Block(-1,9,-5,LEAVES:0)
Block(-1,9,2,LEAVES:0)
Block(-1,9,3,LEAVES:0)
Block(-1,10,4,LEAVES:0)
Block(-1,11,1,LEAVES:0)
Block(-1,11,2,LEAVES:0)
Block(-1,11,3,LEAVES:0)
Block(-1,12,0,LEAVES:0)
Block(-1,12,1,LEAVES:0)
Block(-1,12,2,LEAVES:0)
Block(-1,13,1,LEAVES:0)
Block(-1,13,3,LEAVES:0)
Block(0,-1,-2,LOG:12)
Block(0,-1,-1,LOG:12)
Block(0,-1,0,LOG:12)
Block(0,0,-1,LOG:12)
Block(0,0,0,LOG:12)
Block(0,0,1,LOG:12)
Block(0,1,-1,LOG:12)
Block(0,1,0,LOG:12)
Block(0,1,1,LOG:12)
Block(0,2,-3,LOG:12)
Block(0,2,-2,LOG:12)
Block(0,2,-1,LOG:12)
Block(0,2,1,LOG:12)
Block(0,3,-3,LOG:12)
Block(0,3,-2,LOG:12)
Block(0,7,-9,LEAVES:0)
Block(0,7,-8,LEAVES:0)
Block(0,8,-8,LEAVES:0)
Block(0,8,-7,LEAVES:0)
Block(0,8,-5,LEAVES:0)
Block(0,8,-3,LEAVES:0)
Block(0,8,2,LEAVES:0)
Block(0,8,3,LEAVES:0)
Block(0,9,-10,LEAVES:0)
Block(0,9,-6,LEAVES:0)
Block(0,9,-5,LEAVES:0)
Block(0,9,-4,LEAVES:0)
Block(0,9,1,LEAVES:0)
Block(0,9,2,LOG:12)
Block(0,9,3,LEAVES:0)
Block(0,9,4,LEAVES:0)
Block(0,10,-5,LEAVES:0)
Block(0,10,0,LEAVES:0)
Block(0,10,1,LOG:12)
Block(0,10,2,LOG:12)
Block(0,10,3,LEAVES:0)
Block(0,10,4,LEAVES:0)
Block(0,11,1,LOG:12)
Block(0,11,2,LEAVES:0)
Block(0,11,3,LEAVES:0)
Block(0,12,-1,LEAVES:0)
Block(0,12,0,LEAVES:0)
Block(0,12,1,LEAVES:0)
Block(0,12,3,LEAVES:0)
Block(0,12,5,LEAVES:0)
Block(0,13,0,LEAVES:0)
Block(0,13,1,LEAVES:0)
Block(0,13,2,LEAVES:0)
Block(0,13,3,LEAVES:0)
Block(0,13,4,LEAVES:0)
Block(0,14,3,LEAVES:0)
Block(1,1,0,LOG:12)
Block(1,1,1,LOG:12)
Block(1,2,0,LOG:12)
Block(1,2,1,LOG:12)
Block(1,3,-3,LOG:12)
Block(1,3,-2,LOG:12)
Block(1,3,0,LOG:12)
Block(1,3,1,LOG:12)
Block(1,4,-4,LOG:12)
Block(1,4,-3,LOG:12)
Block(1,5,-5,LOG:12)
Block(1,5,-4,LOG:12)
Block(1,5,-3,LOG:12)
Block(1,6,-10,LEAVES:0)
Block(1,6,-8,LEAVES:0)
Block(1,6,-7,LEAVES:0)
Block(1,6,-6,LOG:12)
Block(1,6,-5,LOG:12)
Block(1,7,-10,LEAVES:0)
Block(1,7,-9,LEAVES:0)
Block(1,7,-7,LOG:12)
Block(1,7,-6,LOG:12)
Block(1,7,-5,LEAVES:0)
Block(1,7,2,LEAVES:0)
Block(1,7,3,LOG:12)
Block(1,8,-10,LEAVES:0)
Block(1,8,-9,LEAVES:0)
Block(1,8,-8,LEAVES:0)
Block(1,8,-7,LEAVES:0)
Block(1,8,-6,LEAVES:0)
Block(1,8,-5,LEAVES:0)
Block(1,8,-4,LEAVES:0)
Block(1,8,-3,LEAVES:0)
Block(1,8,-2,LEAVES:0)
Block(1,8,1,LEAVES:0)
Block(1,8,2,LOG:12)
Block(1,8,3,LOG:12)
Block(1,8,4,LEAVES:0)
Block(1,9,-11,LEAVES:0)
Block(1,9,-10,LEAVES:0)
Block(1,9,-9,LEAVES:0)
Block(1,9,-8,LEAVES:0)
Block(1,9,-7,LEAVES:0)
Block(1,9,-6,LEAVES:0)
Block(1,9,-5,LEAVES:0)
Block(1,9,-4,LEAVES:0)
Block(1,9,-3,LEAVES:0)
Block(1,9,1,LEAVES:0)
Block(1,9,2,LOG:12)
Block(1,9,4,LEAVES:0)
Block(1,9,5,LEAVES:0)
Block(1,10,-10,LEAVES:0)
Block(1,10,-8,LEAVES:0)
Block(1,10,-6,LEAVES:0)
Block(1,10,-4,LEAVES:0)
Block(1,10,-1,LEAVES:0)
Block(1,10,1,LEAVES:0)
Block(1,10,4,LEAVES:0)
Block(1,11,-1,LEAVES:0)
Block(1,11,0,LEAVES:0)
Block(1,11,1,LOG:12)
Block(1,11,3,LEAVES:0)
Block(1,11,4,LEAVES:0)
Block(1,12,-2,LEAVES:0)
Block(1,12,-1,LEAVES:0)
Block(1,12,0,LEAVES:0)
Block(1,12,1,LOG:12)
Block(1,12,3,LEAVES:0)
Block(1,12,4,LEAVES:0)
Block(1,12,5,LEAVES:0)
Block(1,13,-1,LEAVES:0)
Block(1,13,0,LEAVES:0)
Block(1,13,1,LEAVES:0)
Block(1,13,2,LEAVES:0)
Block(1,13,3,LEAVES:0)
Block(1,13,4,LEAVES:0)
Block(1,13,5,LEAVES:0)
Block(1,14,0,LEAVES:0)
Block(1,14,2,LEAVES:0)
Block(1,14,3,LEAVES:0)
Block(1,14,4,LEAVES:0)
Block(2,2,1,LOG:12)
Block(2,3,0,LOG:12)
Block(2,3,1,LOG:12)
Block(2,3,2,LOG:12)
Block(2,4,2,LOG:12)
Block(2,5,-4,LOG:12)
Block(2,5,-3,LOG:12)
Block(2,6,-7,LEAVES:0)
Block(2,6,-3,LOG:12)
Block(2,6,-2,LOG:12)
Block(2,7,-11,LEAVES:0)
Block(2,7,-10,LEAVES:0)
Block(2,7,-9,LEAVES:0)
Block(2,7,-8,LEAVES:0)
Block(2,7,-7,LOG:12)
Block(2,7,-2,LOG:12)
Block(2,7,-1,LOG:12)
Block(2,7,3,LOG:12)
Block(2,8,-11,LEAVES:0)
Block(2,8,-9,LOG:12)
Block(2,8,-8,LOG:12)
Block(2,8,-7,LOG:12)
Block(2,8,-6,LEAVES:0)
Block(2,8,-2,LEAVES:0)
Block(2,8,-1,LEAVES:0)
Block(2,9,-11,LEAVES:0)
Block(2,9,-10,LEAVES:0)
Block(2,9,-9,LEAVES:0)
Block(2,9,-8,LEAVES:0)
Block(2,9,-7,LEAVES:0)
Block(2,9,-6,LEAVES:0)
Block(2,9,-4,LEAVES:0)
Block(2,9,-2,LEAVES:0)
Block(2,9,4,LEAVES:0)
Block(2,10,-9,LEAVES:0)
Block(2,10,-8,LEAVES:0)
Block(2,10,-5,LEAVES:0)
Block(2,10,-4,LEAVES:0)
Block(2,10,-2,LEAVES:0)
Block(2,10,-1,LEAVES:0)
Block(2,10,3,LEAVES:0)
Block(2,10,4,LEAVES:0)
Block(2,10,5,LEAVES:0)
Block(2,11,-8,LEAVES:0)
Block(2,11,-6,LEAVES:0)
Block(2,11,-3,LEAVES:0)
Block(2,11,0,LEAVES:0)
Block(2,11,1,LEAVES:0)
Block(2,11,2,LEAVES:0)
Block(2,11,4,LEAVES:0)
Block(2,12,-3,LEAVES:0)
Block(2,12,-1,LEAVES:0)
Block(2,12,0,LOG:12)
Block(2,12,1,LOG:12)
Block(2,12,2,LEAVES:0)
Block(2,12,3,LEAVES:0)
Block(2,13,-2,LEAVES:0)
Block(2,13,-1,LEAVES:0)
Block(2,13,0,LOG:12)
Block(2,13,1,LEAVES:0)
Block(2,13,2,LEAVES:0)
Block(2,13,3,LEAVES:0)
Block(2,13,4,LEAVES:0)
Block(2,13,5,LEAVES:0)
Block(2,14,-1,LEAVES:0)
Block(2,14,0,LEAVES:0)
Block(2,14,3,LEAVES:0)
Block(2,14,4,LEAVES:0)
Block(2,14,5,LEAVES:0)
Block(3,3,1,LOG:12)
Block(3,4,1,LOG:12)
Block(3,4,2,LOG:12)
Block(3,5,2,LOG:12)
Block(3,5,3,LOG:12)
Block(3,6,-8,LEAVES:0)
Block(3,6,-4,LOG:12)
Block(3,6,-3,LOG:12)
Block(3,6,2,LOG:12)
Block(3,6,3,LOG:12)
Block(3,7,-10,LEAVES:0)
Block(3,7,-9,LEAVES:0)
Block(3,7,-8,LEAVES:0)
Block(3,7,-7,LEAVES:0)
Block(3,7,-4,LOG:12)
Block(3,7,-1,LOG:12)
Block(3,7,3,LOG:12)
Block(3,8,-11,LEAVES:0)
Block(3,8,-10,LOG:12)
Block(3,8,-9,LOG:12)
Block(3,8,-8,LEAVES:0)
Block(3,8,-7,LEAVES:0)
Block(3,8,-5,LEAVES:0)
Block(3,8,-1,LOG:12)
Block(3,9,-10,LEAVES:0)
Block(3,9,-9,LEAVES:0)
Block(3,9,-8,LEAVES:0)
Block(3,9,-7,LEAVES:0)
Block(3,9,-6,LEAVES:0)
Block(3,9,-4,LEAVES:0)
Block(3,9,2,LEAVES:0)
Block(3,9,3,LEAVES:0)
Block(3,10,-10,LEAVES:0)
Block(3,10,-5,LEAVES:0)
Block(3,10,-3,LEAVES:0)
Block(3,10,-2,LEAVES:0)
Block(3,10,1,LEAVES:0)
Block(3,10,2,LEAVES:0)
Block(3,10,3,LEAVES:0)
Block(3,10,4,LEAVES:0)
Block(3,11,-9,LEAVES:0)
Block(3,11,-8,LEAVES:0)
Block(3,11,-7,LEAVES:0)
Block(3,11,-6,LEAVES:0)
Block(3,11,-5,LEAVES:0)
Block(3,11,-3,LEAVES:0)
Block(3,11,-2,LEAVES:0)
Block(3,11,0,LEAVES:0)
Block(3,11,1,LEAVES:0)
Block(3,11,2,LEAVES:0)
Block(3,11,3,LEAVES:0)
Block(3,12,-6,LEAVES:0)
Block(3,12,-4,LEAVES:0)
Block(3,12,-3,LEAVES:0)
Block(3,12,-2,LEAVES:0)
Block(3,12,0,LEAVES:0)
Block(3,12,1,LEAVES:0)
Block(3,12,2,LEAVES:0)
Block(3,12,4,LEAVES:0)
Block(3,13,-3,LEAVES:0)
Block(3,13,-2,LEAVES:0)
Block(3,13,-1,LEAVES:0)
Block(3,13,0,LOG:12)
Block(3,13,1,LEAVES:0)
Block(3,13,2,LEAVES:0)
Block(3,13,3,LEAVES:0)
Block(3,13,4,LEAVES:0)
Block(3,13,5,LEAVES:0)
Block(3,13,6,LEAVES:0)
Block(3,14,-1,LEAVES:0)
Block(3,14,0,LEAVES:0)
Block(3,14,1,LEAVES:0)
Block(3,14,4,LEAVES:0)
Block(4,4,1,LOG:12)
Block(4,5,1,LOG:12)
Block(4,5,2,LOG:12)
Block(4,6,2,LOG:12)
Block(4,6,3,LOG:12)
Block(4,7,-9,LEAVES:0)
Block(4,7,-7,LEAVES:0)
Block(4,7,-5,LOG:12)
Block(4,7,-4,LOG:12)
Block(4,7,3,LOG:12)
Block(4,8,-10,LEAVES:0)
Block(4,8,-9,LEAVES:0)
Block(4,8,-6,LEAVES:0)
Block(4,8,-3,LEAVES:0)
Block(4,8,-1,LOG:12)
Block(4,8,3,LOG:12)
Block(4,8,4,LOG:12)
Block(4,9,-8,LEAVES:0)
Block(4,9,-7,LEAVES:0)
Block(4,9,-6,LEAVES:0)
Block(4,9,-3,LEAVES:0)
Block(4,9,-2,LEAVES:0)
Block(4,9,-1,LOG:12)
Block(4,10,-9,LEAVES:0)
Block(4,10,-8,LEAVES:0)
Block(4,10,-6,LEAVES:0)
Block(4,10,-5,LEAVES:0)
Block(4,10,-3,LEAVES:0)
Block(4,10,-2,LEAVES:0)
Block(4,10,-1,LEAVES:0)
Block(4,10,1,LEAVES:0)
Block(4,10,4,LEAVES:0)
Block(4,10,5,LEAVES:0)
Block(4,11,-10,LEAVES:0)
Block(4,11,-9,LEAVES:0)
Block(4,11,-8,LEAVES:0)
Block(4,11,-7,LEAVES:0)
Block(4,11,-6,LEAVES:0)
Block(4,11,-5,LEAVES:0)
Block(4,11,-4,LEAVES:0)
Block(4,11,-3,LEAVES:0)
Block(4,11,3,LEAVES:0)
Block(4,11,4,LEAVES:0)
Block(4,11,6,LEAVES:0)
Block(4,12,-8,LEAVES:0)
Block(4,12,-7,LEAVES:0)
Block(4,12,-6,LEAVES:0)
Block(4,12,-5,LEAVES:0)
Block(4,12,-4,LEAVES:0)
Block(4,12,-3,LEAVES:0)
Block(4,12,0,LEAVES:0)
Block(4,12,1,LEAVES:0)
Block(4,12,2,LEAVES:0)
Block(4,12,3,LEAVES:0)
Block(4,12,4,LEAVES:0)
Block(4,12,5,LEAVES:0)
Block(4,13,-4,LEAVES:0)
Block(4,13,-2,LEAVES:0)
Block(4,13,-1,LEAVES:0)
Block(4,13,0,LEAVES:0)
Block(4,13,3,LEAVES:0)
Block(4,13,4,LEAVES:0)
Block(4,13,5,LEAVES:0)
Block(4,14,0,LEAVES:0)
Block(4,14,3,LEAVES:0)
Block(4,14,5,LEAVES:0)
Block(5,4,0,LOG:12)
Block(5,4,1,LOG:12)
Block(5,6,2,LOG:12)
Block(5,7,-5,LOG:12)
Block(5,7,2,LOG:12)
Block(5,8,-7,LEAVES:0)
Block(5,8,-3,LEAVES:0)
Block(5,8,-2,LEAVES:0)
Block(5,8,-1,LEAVES:0)
Block(5,8,4,LOG:12)
Block(5,8,5,LOG:12)
Block(5,9,-9,LEAVES:0)
Block(5,9,-8,LEAVES:0)
Block(5,9,-7,LEAVES:0)
Block(5,9,-6,LEAVES:0)
Block(5,9,-5,LEAVES:0)
Block(5,9,-3,LEAVES:0)
Block(5,9,-2,LOG:12)
Block(5,9,-1,LOG:12)
Block(5,9,1,LEAVES:0)
Block(5,9,5,LOG:12)
Block(5,10,-10,LEAVES:0)
Block(5,10,-9,LEAVES:0)
Block(5,10,-8,LEAVES:0)
Block(5,10,-7,LEAVES:0)
Block(5,10,-6,LEAVES:0)
Block(5,10,-5,LEAVES:0)
Block(5,10,-3,LEAVES:0)
Block(5,10,-2,LEAVES:0)
Block(5,10,-1,LEAVES:0)
Block(5,10,1,LEAVES:0)
Block(5,10,2,LEAVES:0)
Block(5,10,3,LEAVES:0)
Block(5,10,4,LEAVES:0)
Block(5,10,6,LEAVES:0)
Block(5,11,-9,LEAVES:0)
Block(5,11,-8,LEAVES:0)
Block(5,11,-7,LEAVES:0)
Block(5,11,-6,LEAVES:0)
Block(5,11,-5,LEAVES:0)
Block(5,11,-4,LEAVES:0)
Block(5,11,-3,LEAVES:0)
Block(5,11,-1,LEAVES:0)
Block(5,11,0,LEAVES:0)
Block(5,11,3,LEAVES:0)
Block(5,11,5,LEAVES:0)
Block(5,11,6,LEAVES:0)
Block(5,12,-9,LEAVES:0)
Block(5,12,-8,LEAVES:0)
Block(5,12,-7,LEAVES:0)
Block(5,12,-6,LEAVES:0)
Block(5,12,-5,LEAVES:0)
Block(5,12,-1,LEAVES:0)
Block(5,12,1,LEAVES:0)
Block(5,12,3,LEAVES:0)
Block(5,12,5,LEAVES:0)
Block(5,13,-6,LEAVES:0)
Block(5,13,-5,LEAVES:0)
Block(5,13,0,LEAVES:0)
Block(5,13,1,LEAVES:0)
Block(5,13,2,LEAVES:0)
Block(5,13,3,LEAVES:0)
Block(5,13,4,LEAVES:0)
Block(5,13,5,LEAVES:0)
Block(5,13,6,LEAVES:0)
Block(5,14,2,LEAVES:0)
Block(5,14,3,LEAVES:0)
Block(5,14,4,LEAVES:0)
Block(6,4,-1,LOG:12)
Block(6,4,0,LOG:12)
Block(6,5,-1,LOG:12)
Block(6,7,-6,LEAVES:0)
Block(6,7,-5,LOG:12)
Block(6,7,-4,LEAVES:0)
Block(6,7,-3,LEAVES:0)
Block(6,7,2,LOG:12)
Block(6,8,-7,LEAVES:0)
Block(6,8,-6,LEAVES:0)
Block(6,8,-5,LOG:12)
Block(6,8,-4,LEAVES:0)
Block(6,8,-3,LEAVES:0)
Block(6,9,-8,LEAVES:0)
Block(6,9,-6,LEAVES:0)
Block(6,9,-5,LEAVES:0)
Block(6,9,-3,LEAVES:0)
Block(6,9,-2,LOG:12)
Block(6,9,-1,LEAVES:0)
Block(6,9,0,LEAVES:0)
Block(6,9,5,LOG:12)
Block(6,9,6,LOG:12)
Block(6,10,-9,LEAVES:0)
Block(6,10,-6,LEAVES:0)
Block(6,10,-5,LEAVES:0)
Block(6,10,-3,LEAVES:0)
Block(6,10,-2,LEAVES:0)
Block(6,10,0,LEAVES:0)
Block(6,10,5,LEAVES:0)
Block(6,10,6,LEAVES:0)
Block(6,10,7,LEAVES:0)
Block(6,11,-8,LEAVES:0)
Block(6,11,-7,LEAVES:0)
Block(6,11,-6,LEAVES:0)
Block(6,11,-5,LEAVES:0)
Block(6,11,-4,LEAVES:0)
Block(6,11,-3,LEAVES:0)
Block(6,11,-2,LEAVES:0)
Block(6,11,-1,LEAVES:0)
Block(6,11,3,LEAVES:0)
Block(6,11,5,LEAVES:0)
Block(6,12,-8,LEAVES:0)
Block(6,12,-7,LEAVES:0)
Block(6,12,-6,LEAVES:0)
Block(6,12,-5,LEAVES:0)
Block(6,12,-4,LEAVES:0)
Block(6,12,0,LEAVES:0)
Block(6,12,3,LEAVES:0)
Block(6,12,4,LEAVES:0)
Block(6,12,5,LEAVES:0)
Block(6,12,6,LEAVES:0)
Block(6,13,-9,LEAVES:0)
Block(6,13,-8,LEAVES:0)
Block(6,13,-6,LEAVES:0)
Block(6,13,0,LEAVES:0)
Block(6,13,1,LEAVES:0)
Block(6,13,2,LEAVES:0)
Block(6,13,3,LEAVES:0)
Block(6,13,4,LEAVES:0)
Block(6,14,1,LEAVES:0)
Block(6,14,2,LEAVES:0)
Block(7,5,-2,LOG:12)
Block(7,5,-1,LOG:12)
Block(7,6,-5,LEAVES:0)
Block(7,6,-2,LOG:12)
Block(7,7,-5,LEAVES:0)
Block(7,7,-4,LEAVES:0)
Block(7,7,-3,LEAVES:0)
Block(7,7,-2,LEAVES:0)
Block(7,7,-1,LEAVES:0)
Block(7,7,2,LOG:12)
Block(7,8,-7,LEAVES:0)
Block(7,8,-6,LEAVES:0)
Block(7,8,-5,LOG:12)
Block(7,8,-4,LEAVES:0)
Block(7,8,-3,LEAVES:0)
Block(7,8,-1,LEAVES:0)
Block(7,8,2,LOG:12)
Block(7,9,-6,LEAVES:0)
Block(7,9,-5,LEAVES:0)
Block(7,9,-4,LEAVES:0)
Block(7,9,-1,LEAVES:0)
Block(7,9,0,LEAVES:0)
Block(7,9,3,LEAVES:0)
Block(7,9,4,LEAVES:0)
Block(7,9,6,LOG:12)
Block(7,10,-7,LEAVES:0)
Block(7,10,-6,LEAVES:0)
Block(7,10,-3,LEAVES:0)
Block(7,10,-1,LEAVES:0)
Block(7,10,4,LEAVES:0)
Block(7,10,5,LEAVES:0)
Block(7,10,6,LOG:12)
Block(7,11,-7,LEAVES:0)
Block(7,11,-6,LEAVES:0)
Block(7,11,-5,LEAVES:0)
Block(7,11,-4,LEAVES:0)
Block(7,11,-3,LEAVES:0)
Block(7,11,-1,LEAVES:0)
Block(7,11,0,LEAVES:0)
Block(7,11,1,LEAVES:0)
Block(7,11,3,LEAVES:0)
Block(7,11,5,LEAVES:0)
Block(7,11,6,LEAVES:0)
Block(7,12,-8,LEAVES:0)
Block(7,12,-7,LEAVES:0)
Block(7,12,-6,LEAVES:0)
Block(7,12,-4,LEAVES:0)
Block(7,12,-3,LEAVES:0)
Block(7,12,-1,LEAVES:0)
Block(7,12,1,LEAVES:0)
Block(7,12,2,LEAVES:0)
Block(7,12,3,LEAVES:0)
Block(7,13,-7,LEAVES:0)
Block(7,13,-6,LEAVES:0)
Block(7,13,-2,LEAVES:0)
Block(7,13,-1,LEAVES:0)
Block(7,13,0,LEAVES:0)
Block(7,13,1,LEAVES:0)
Block(7,13,2,LEAVES:0)
Block(7,13,3,LEAVES:0)
Block(7,13,4,LEAVES:0)
Block(7,14,-1,LEAVES:0)
Block(7,14,0,LEAVES:0)
Block(7,14,1,LEAVES:0)
Block(7,14,2,LEAVES:0)
Block(7,14,3,LEAVES:0)
Block(8,6,-2,LOG:12)
Block(8,7,-3,LEAVES:0)
Block(8,7,-2,LEAVES:0)
Block(8,7,-1,LEAVES:0)
Block(8,8,-6,LEAVES:0)
Block(8,8,-4,LEAVES:0)
Block(8,8,-3,LEAVES:0)
Block(8,8,-2,LEAVES:0)
Block(8,8,-1,LEAVES:0)
Block(8,8,1,LOG:12)
Block(8,8,2,LOG:12)
Block(8,9,-5,LEAVES:0)
Block(8,9,-4,LEAVES:0)
Block(8,9,0,LEAVES:0)
Block(8,9,4,LEAVES:0)
Block(8,9,6,LEAVES:0)
Block(8,10,-8,LEAVES:0)
Block(8,10,-7,LEAVES:0)
Block(8,10,-6,LEAVES:0)
Block(8,10,-5,LEAVES:0)
Block(8,10,-4,LEAVES:0)
Block(8,10,-1,LEAVES:0)
Block(8,10,1,LEAVES:0)
Block(8,10,2,LEAVES:0)
Block(8,10,4,LEAVES:0)
Block(8,10,5,LEAVES:0)
Block(8,10,6,LOG:12)
Block(8,10,7,LEAVES:0)
Block(8,11,-7,LEAVES:0)
Block(8,11,-6,LEAVES:0)
Block(8,11,-5,LEAVES:0)
Block(8,11,-4,LEAVES:0)
Block(8,11,-3,LEAVES:0)
Block(8,11,-2,LEAVES:0)
Block(8,11,-1,LEAVES:0)
Block(8,11,1,LEAVES:0)
Block(8,11,2,LEAVES:0)
Block(8,11,7,LEAVES:0)
Block(8,12,-7,LEAVES:0)
Block(8,12,-5,LEAVES:0)
Block(8,12,-4,LEAVES:0)
Block(8,12,-1,LEAVES:0)
Block(8,12,0,LEAVES:0)
Block(8,12,1,LEAVES:0)
Block(8,12,2,LEAVES:0)
Block(8,12,3,LEAVES:0)
Block(8,12,4,LEAVES:0)
Block(8,12,5,LEAVES:0)
Block(8,13,-1,LEAVES:0)
Block(8,13,1,LEAVES:0)
Block(8,13,2,LEAVES:0)
Block(8,13,4,LEAVES:0)
Block(8,13,5,LEAVES:0)
Block(8,14,0,LEAVES:0)
Block(8,14,1,LEAVES:0)
Block(8,14,2,LEAVES:0)
Block(9,6,-4,LEAVES:0)
Block(9,6,-3,LEAVES:0)
Block(9,6,-2,LEAVES:0)
Block(9,7,-5,LEAVES:0)
Block(9,7,-4,LEAVES:0)
Block(9,7,-3,LEAVES:0)
Block(9,7,-2,LEAVES:0)
Block(9,7,-1,LEAVES:0)
Block(9,7,1,LEAVES:0)
Block(9,7,2,LEAVES:0)
Block(9,8,-5,LEAVES:0)
Block(9,8,-4,LEAVES:0)
Block(9,8,-3,LEAVES:0)
Block(9,8,1,LOG:12)
Block(9,8,3,LEAVES:0)
Block(9,9,-7,LEAVES:0)
Block(9,9,-6,LEAVES:0)
Block(9,9,-5,LEAVES:0)
Block(9,9,-4,LEAVES:0)
Block(9,9,-1,LEAVES:0)
Block(9,9,1,LOG:12)
Block(9,9,2,LEAVES:0)
Block(9,9,3,LEAVES:0)
Block(9,9,4,LEAVES:0)
Block(9,9,5,LEAVES:0)
Block(9,9,6,LEAVES:0)
Block(9,9,7,LEAVES:0)
Block(9,10,-6,LEAVES:0)
Block(9,10,-5,LEAVES:0)
Block(9,10,-2,LEAVES:0)
Block(9,10,-1,LEAVES:0)
Block(9,10,0,LEAVES:0)
Block(9,10,1,LEAVES:0)
Block(9,10,2,LEAVES:0)
Block(9,10,3,LEAVES:0)
Block(9,10,4,LEAVES:0)
Block(9,10,5,LEAVES:0)
Block(9,10,6,LOG:12)
Block(9,10,7,LEAVES:0)
Block(9,11,-6,LEAVES:0)
Block(9,11,-4,LEAVES:0)
Block(9,11,-1,LEAVES:0)
Block(9,11,1,LEAVES:0)
Block(9,11,2,LEAVES:0)
Block(9,11,3,LEAVES:0)
Block(9,11,4,LEAVES:0)
Block(9,12,-2,LEAVES:0)
Block(9,12,-1,LEAVES:0)
Block(9,12,1,LEAVES:0)
Block(9,12,2,LEAVES:0)
Block(9,12,3,LEAVES:0)
Block(9,12,4,LEAVES:0)
Block(9,12,5,LEAVES:0)
Block(9,12,6,LEAVES:0)
Block(9,13,-2,LEAVES:0)
Block(9,13,-1,LEAVES:0)
Block(9,13,1,LEAVES:0)
Block(9,13,2,LEAVES:0)
Block(9,13,3,LEAVES:0)
Block(9,13,4,LEAVES:0)
Block(9,13,5,LEAVES:0)
Block(9,14,2,LEAVES:0)
Block(10,6,-3,LEAVES:0)
Block(10,6,-1,LEAVES:0)
Block(10,7,-4,LEAVES:0)
Block(10,7,-2,LEAVES:0)
Block(10,7,-1,LEAVES:0)
Block(10,7,0,LEAVES:0)
Block(10,8,-5,LEAVES:0)
Block(10,8,-4,LEAVES:0)
Block(10,8,-3,LEAVES:0)
Block(10,8,-2,LEAVES:0)
Block(10,8,-1,LEAVES:0)
Block(10,8,0,LEAVES:0)
Block(10,8,1,LEAVES:0)
Block(10,9,-6,LEAVES:0)
Block(10,9,-5,LEAVES:0)
Block(10,9,-4,LEAVES:0)
Block(10,9,0,LEAVES:0)
Block(10,9,1,LOG:12)
Block(10,9,5,LEAVES:0)
Block(10,10,-2,LEAVES:0)
Block(10,10,-1,LEAVES:0)
Block(10,10,0,LEAVES:0)
Block(10,10,3,LEAVES:0)
Block(10,10,4,LEAVES:0)
Block(10,10,6,LEAVES:0)
Block(10,11,-1,LEAVES:0)
Block(10,11,0,LEAVES:0)
Block(10,11,1,LEAVES:0)
Block(10,11,2,LEAVES:0)
Block(10,11,5,LEAVES:0)
Block(10,11,6,LEAVES:0)
Block(10,12,-2,LEAVES:0)
Block(10,12,0,LEAVES:0)
Block(10,12,1,LEAVES:0)
Block(10,12,2,LEAVES:0)
Block(10,12,3,LEAVES:0)
Block(10,12,4,LEAVES:0)
Block(10,12,5,LEAVES:0)
Block(10,12,6,LEAVES:0)
Block(10,13,2,LEAVES:0)
Block(10,13,3,LEAVES:0)
Block(10,13,5,LEAVES:0)
Block(11,7,-1,LEAVES:0)
Block(11,8,-1,LEAVES:0)
Block(11,8,2,LEAVES:0)
Block(11,9,-5,LEAVES:0)
Block(11,9,1,LOG:12)
Block(11,9,2,LEAVES:0)
Block(11,9,4,LEAVES:0)
Block(11,10,-1,LEAVES:0)
Block(11,10,0,LEAVES:0)
Block(11,10,1,LEAVES:0)
Block(11,10,2,LEAVES:0)
Block(11,10,3,LEAVES:0)
Block(11,10,4,LEAVES:0)
Block(11,10,5,LEAVES:0)
Block(11,10,7,LEAVES:0)
Block(11,11,-2,LEAVES:0)
Block(11,11,-1,LEAVES:0)
Block(11,11,0,LEAVES:0)
Block(11,11,1,LEAVES:0)
Block(11,11,2,LEAVES:0)
Block(11,11,3,LEAVES:0)
Block(11,11,4,LEAVES:0)
Block(11,11,5,LEAVES:0)
Block(11,11,6,LEAVES:0)
Block(11,12,-1,LEAVES:0)
Block(11,12,0,LEAVES:0)
Block(11,12,2,LEAVES:0)
Block(11,12,4,LEAVES:0)
Block(11,12,5,LEAVES:0)
Block(12,8,0,LEAVES:0)
Block(12,8,1,LEAVES:0)
Block(12,9,0,LEAVES:0)
Block(12,9,2,LEAVES:0)
Block(12,10,1,LEAVES:0)
Block(12,11,-1,LEAVES:0)
Block(12,11,2,LEAVES:0)
Block(12,11,3,LEAVES:0)
Block(12,11,5,LEAVES:0)

#######################################################################
# +-----------------------------------------------------------------+ #
# |                            BO3 checks                           | #
# +-----------------------------------------------------------------+ #
#######################################################################

BlockCheck(0,-1,0,GRASS:0)

#######################################################################
# +-----------------------------------------------------------------+ #
# |                             Branches                            | #
# +-----------------------------------------------------------------+ #
#######################################################################


#######################################################################
# +-----------------------------------------------------------------+ #
# |                             Entities                            | #
# +-----------------------------------------------------------------+ #
#######################################################################


#######################################################################
# +-----------------------------------------------------------------+ #
# |                            Particles                            | #
# +-----------------------------------------------------------------+ #
#######################################################################


#######################################################################
# +-----------------------------------------------------------------+ #
# |                             Spawners                            | #
# +-----------------------------------------------------------------+ #
#######################################################################


#######################################################################
# +-----------------------------------------------------------------+ #
# |                             ModData                             | #
# +-----------------------------------------------------------------+ #
#######################################################################

