
#######################################################################
# +-----------------------------------------------------------------+ #
# |                            BO3 object                           | #
# +-----------------------------------------------------------------+ #
#######################################################################

Author: LordSmellyPants

Description: No description given

Version: 3

SettingsMode: WriteWithoutComments


#######################################################################
# +-----------------------------------------------------------------+ #
# |                          Main settings                          | #
# +-----------------------------------------------------------------+ #
#######################################################################

Tree: true

Frequency: 1

Rarity: 25.0

RotateRandomly: true

SpawnHeight: highestSolidBlock

SpawnHeightOffset: 0

SpawnHeightVariance: 0

##############################
# Height Limits for the BO3. #
##############################

MinHeight: 63

MaxHeight: 71

######################
# Extrusion settings #
######################

ExtrudeMode: None

ExtrudeThroughBlocks: AIR

MaxBranchDepth: 10

ExcludedBiomes: All


#######################################################################
# +-----------------------------------------------------------------+ #
# |                      Source block settings                      | #
# +-----------------------------------------------------------------+ #
#######################################################################

SourceBlocks: STONE:1,STONE:3,STONE:5,DIRT:1,DIRT:0,SAND:0,GRASS:0,DIRT:2,STATIONARY_WATER:0,HARD_CLAY,STAINED_CLAY:0,CLAY,SANDSTONE:0,SAND:1,AIR,STONE:0,GRAVEL,LONG_GRASS:0,LONG_GRASS:1,LONG_GRASS:2,DEAD_BUSH,YELLOW_FLOWER:0,RED_ROSE:0,BROWN_MUSHROOM,RED_MUSHROOM

MaxPercentageOutsideSourceBlock: 0

OutsideSourceBlock: placeAnyway

DoReplaceBlocks: true

IsOTGPlus: false


#######################################################################
# +-----------------------------------------------------------------+ #
# |                              Blocks                             | #
# +-----------------------------------------------------------------+ #
#######################################################################

Block(-12,5,6,LEAVES:0)
Block(-12,6,6,LEAVES:0)
Block(-12,7,7,LEAVES:0)
Block(-11,5,4,LEAVES:0)
Block(-11,5,5,LEAVES:0)
Block(-11,5,6,LEAVES:0)
Block(-11,6,3,LEAVES:0)
Block(-11,6,6,LEAVES:0)
Block(-11,7,5,LEAVES:0)
Block(-11,7,6,LEAVES:0)
Block(-11,7,7,LEAVES:0)
Block(-11,8,6,LEAVES:0)
Block(-11,9,6,LEAVES:0)
Block(-10,4,5,LEAVES:0)
Block(-10,5,3,LEAVES:0)
Block(-10,5,4,LEAVES:0)
Block(-10,5,5,LOG:12)
Block(-10,5,6,LOG:12)
Block(-10,5,8,LEAVES:0)
Block(-10,6,2,LEAVES:0)
Block(-10,6,3,LEAVES:0)
Block(-10,6,5,LEAVES:0)
Block(-10,6,7,LEAVES:0)
Block(-10,7,3,LEAVES:0)
Block(-10,7,4,LEAVES:0)
Block(-10,7,5,LEAVES:0)
Block(-10,7,6,LEAVES:0)
Block(-10,7,7,LEAVES:0)
Block(-10,7,8,LEAVES:0)
Block(-10,8,3,LEAVES:0)
Block(-10,8,6,LEAVES:0)
Block(-10,9,2,LEAVES:0)
Block(-10,9,3,LEAVES:0)
Block(-10,9,6,LEAVES:0)
Block(-10,9,7,LEAVES:0)
Block(-10,10,3,LEAVES:0)
Block(-10,10,5,LEAVES:0)
Block(-10,10,7,LEAVES:0)
Block(-10,12,0,LEAVES:0)
Block(-10,12,1,LEAVES:0)
Block(-10,12,4,LEAVES:0)
Block(-10,12,5,LEAVES:0)
Block(-9,4,3,LEAVES:0)
Block(-9,5,2,LEAVES:0)
Block(-9,5,3,LEAVES:0)
Block(-9,5,4,LEAVES:0)
Block(-9,5,5,LOG:12)
Block(-9,5,6,LEAVES:0)
Block(-9,6,2,LEAVES:0)
Block(-9,6,3,LOG:12)
Block(-9,6,4,LOG:12)
Block(-9,6,6,LEAVES:0)
Block(-9,7,4,LEAVES:0)
Block(-9,7,5,LEAVES:0)
Block(-9,7,8,LEAVES:0)
Block(-9,8,4,LEAVES:0)
Block(-9,8,8,LEAVES:0)
Block(-9,9,0,LEAVES:0)
Block(-9,9,2,LEAVES:0)
Block(-9,9,3,LEAVES:0)
Block(-9,9,4,LEAVES:0)
Block(-9,9,5,LEAVES:0)
Block(-9,9,6,LEAVES:0)
Block(-9,10,0,LEAVES:0)
Block(-9,10,2,LEAVES:0)
Block(-9,10,4,LEAVES:0)
Block(-9,10,6,LEAVES:0)
Block(-9,10,7,LEAVES:0)
Block(-9,10,8,LEAVES:0)
Block(-9,11,0,LEAVES:0)
Block(-9,11,1,LEAVES:0)
Block(-9,11,3,LEAVES:0)
Block(-9,11,4,LEAVES:0)
Block(-9,11,6,LEAVES:0)
Block(-9,11,8,LEAVES:0)
Block(-9,12,-1,LEAVES:0)
Block(-9,12,0,LEAVES:0)
Block(-9,12,1,LEAVES:0)
Block(-9,12,2,LEAVES:0)
Block(-9,12,5,LEAVES:0)
Block(-9,13,5,LEAVES:0)
Block(-8,4,6,LEAVES:0)
Block(-8,5,6,LEAVES:0)
Block(-8,5,7,LEAVES:0)
Block(-8,6,3,LOG:12)
Block(-8,7,2,LEAVES:0)
Block(-8,7,3,LOG:12)
Block(-8,7,4,LEAVES:0)
Block(-8,7,6,LEAVES:0)
Block(-8,8,0,LEAVES:0)
Block(-8,8,1,LEAVES:0)
Block(-8,8,2,LEAVES:0)
Block(-8,8,3,LEAVES:0)
Block(-8,8,4,LEAVES:0)
Block(-8,8,5,LEAVES:0)
Block(-8,8,6,LEAVES:0)
Block(-8,8,8,LEAVES:0)
Block(-8,9,2,LEAVES:0)
Block(-8,9,3,LEAVES:0)
Block(-8,9,4,LEAVES:0)
Block(-8,9,5,LEAVES:0)
Block(-8,9,6,LOG:12)
Block(-8,9,7,LEAVES:0)
Block(-8,9,8,LEAVES:0)
Block(-8,10,-1,LEAVES:0)
Block(-8,10,0,LEAVES:0)
Block(-8,10,1,LEAVES:0)
Block(-8,10,4,LEAVES:0)
Block(-8,10,5,LEAVES:0)
Block(-8,10,6,LEAVES:0)
Block(-8,10,7,LOG:12)
Block(-8,11,-1,LEAVES:0)
Block(-8,11,1,LEAVES:0)
Block(-8,11,2,LEAVES:0)
Block(-8,11,4,LEAVES:0)
Block(-8,11,6,LEAVES:0)
Block(-8,11,7,LEAVES:0)
Block(-8,12,-2,LEAVES:0)
Block(-8,12,-1,LEAVES:0)
Block(-8,12,0,LEAVES:0)
Block(-8,12,1,LEAVES:0)
Block(-8,12,2,LEAVES:0)
Block(-8,12,3,LEAVES:0)
Block(-8,12,7,LEAVES:0)
Block(-8,13,-2,LEAVES:0)
Block(-8,13,-1,LEAVES:0)
Block(-8,13,7,LEAVES:0)
Block(-8,14,0,LEAVES:0)
Block(-8,14,2,LEAVES:0)
Block(-8,14,4,LEAVES:0)
Block(-8,14,7,LEAVES:0)
Block(-7,6,4,LEAVES:0)
Block(-7,7,3,LOG:12)
Block(-7,7,4,LOG:12)
Block(-7,8,2,LEAVES:0)
Block(-7,8,5,LOG:12)
Block(-7,9,-1,LEAVES:0)
Block(-7,9,0,LEAVES:0)
Block(-7,9,1,LEAVES:0)
Block(-7,9,2,LEAVES:0)
Block(-7,9,4,LEAVES:0)
Block(-7,9,7,LEAVES:0)
Block(-7,9,8,LEAVES:0)
Block(-7,9,9,LEAVES:0)
Block(-7,10,0,LEAVES:0)
Block(-7,10,3,LEAVES:0)
Block(-7,10,5,LEAVES:0)
Block(-7,10,6,LEAVES:0)
Block(-7,10,7,LEAVES:0)
Block(-7,10,8,LEAVES:0)
Block(-7,11,0,LEAVES:0)
Block(-7,11,4,LEAVES:0)
Block(-7,11,7,LEAVES:0)
Block(-7,11,8,LEAVES:0)
Block(-7,12,-2,LEAVES:0)
Block(-7,12,-1,LEAVES:0)
Block(-7,12,1,LEAVES:0)
Block(-7,12,3,LEAVES:0)
Block(-7,12,7,LEAVES:0)
Block(-7,12,8,LEAVES:0)
Block(-7,13,-3,LEAVES:0)
Block(-7,13,-2,LEAVES:0)
Block(-7,13,-1,LEAVES:0)
Block(-7,13,0,LEAVES:0)
Block(-7,13,1,LEAVES:0)
Block(-7,13,2,LEAVES:0)
Block(-7,13,4,LEAVES:0)
Block(-7,14,-3,LEAVES:0)
Block(-7,14,-2,LEAVES:0)
Block(-7,14,5,LEAVES:0)
Block(-7,14,6,LEAVES:0)
Block(-7,14,8,LEAVES:0)
Block(-7,15,1,LEAVES:0)
Block(-7,15,4,LEAVES:0)
Block(-7,15,7,LEAVES:0)
Block(-7,16,6,LEAVES:0)
Block(-6,7,3,LEAVES:0)
Block(-6,7,4,LOG:12)
Block(-6,8,0,LEAVES:0)
Block(-6,8,3,LEAVES:0)
Block(-6,8,4,LOG:12)
Block(-6,9,0,LEAVES:0)
Block(-6,9,1,LEAVES:0)
Block(-6,9,2,LEAVES:0)
Block(-6,9,6,LEAVES:0)
Block(-6,9,8,LEAVES:0)
Block(-6,10,1,LEAVES:0)
Block(-6,10,5,LEAVES:0)
Block(-6,10,6,LEAVES:0)
Block(-6,10,7,LEAVES:0)
Block(-6,11,-1,LEAVES:0)
Block(-6,11,0,LEAVES:0)
Block(-6,11,1,LEAVES:0)
Block(-6,11,7,LEAVES:0)
Block(-6,12,-4,LEAVES:0)
Block(-6,12,-3,LEAVES:0)
Block(-6,12,-2,LEAVES:0)
Block(-6,12,0,LOG:12)
Block(-6,12,1,LOG:12)
Block(-6,12,7,LEAVES:0)
Block(-6,12,8,LEAVES:0)
Block(-6,13,-2,LEAVES:0)
Block(-6,13,-1,LOG:12)
Block(-6,13,0,LOG:12)
Block(-6,13,1,LEAVES:0)
Block(-6,13,6,LEAVES:0)
Block(-6,13,7,LEAVES:0)
Block(-6,13,8,LEAVES:0)
Block(-6,13,9,LEAVES:0)
Block(-6,14,-3,LEAVES:0)
Block(-6,14,-2,LEAVES:0)
Block(-6,14,-1,LEAVES:0)
Block(-6,14,1,LEAVES:0)
Block(-6,14,2,LEAVES:0)
Block(-6,14,3,LEAVES:0)
Block(-6,14,6,LEAVES:0)
Block(-6,14,8,LEAVES:0)
Block(-6,15,-1,LEAVES:0)
Block(-6,15,0,LEAVES:0)
Block(-6,15,1,LEAVES:0)
Block(-6,15,3,LEAVES:0)
Block(-6,15,7,LEAVES:0)
Block(-5,8,4,LOG:12)
Block(-5,9,0,LEAVES:0)
Block(-5,9,3,LOG:12)
Block(-5,9,4,LOG:12)
Block(-5,10,2,LOG:12)
Block(-5,10,3,LOG:12)
Block(-5,10,6,LEAVES:0)
Block(-5,11,-4,LEAVES:0)
Block(-5,11,-2,LEAVES:0)
Block(-5,11,-1,LEAVES:0)
Block(-5,11,2,LOG:12)
Block(-5,11,6,LEAVES:0)
Block(-5,11,7,LEAVES:0)
Block(-5,11,8,LEAVES:0)
Block(-5,11,9,LEAVES:0)
Block(-5,12,-7,LEAVES:0)
Block(-5,12,-4,LEAVES:0)
Block(-5,12,-3,LEAVES:0)
Block(-5,12,-2,LEAVES:0)
Block(-5,12,0,LEAVES:0)
Block(-5,12,2,LEAVES:0)
Block(-5,12,5,LEAVES:0)
Block(-5,12,6,LEAVES:0)
Block(-5,12,7,LEAVES:0)
Block(-5,12,8,LEAVES:0)
Block(-5,12,9,LEAVES:0)
Block(-5,13,-7,LEAVES:0)
Block(-5,13,-6,LEAVES:0)
Block(-5,13,-4,LEAVES:0)
Block(-5,13,-2,LEAVES:0)
Block(-5,13,0,LEAVES:0)
Block(-5,13,1,LEAVES:0)
Block(-5,13,3,LEAVES:0)
Block(-5,13,4,LEAVES:0)
Block(-5,13,6,LEAVES:0)
Block(-5,13,7,LOG:12)
Block(-5,13,8,LEAVES:0)
Block(-5,14,-6,LEAVES:0)
Block(-5,14,-5,LEAVES:0)
Block(-5,14,-1,LEAVES:0)
Block(-5,14,6,LEAVES:0)
Block(-5,14,7,LOG:12)
Block(-5,14,8,LEAVES:0)
Block(-5,15,-6,LEAVES:0)
Block(-5,15,-4,LEAVES:0)
Block(-5,15,-3,LEAVES:0)
Block(-5,15,1,LEAVES:0)
Block(-5,15,3,LEAVES:0)
Block(-5,15,6,LEAVES:0)
Block(-5,15,7,LEAVES:0)
Block(-4,9,3,LOG:12)
Block(-4,10,1,LEAVES:0)
Block(-4,10,3,LOG:12)
Block(-4,10,7,LEAVES:0)
Block(-4,11,-7,LEAVES:0)
Block(-4,11,-5,LEAVES:0)
Block(-4,11,1,LEAVES:0)
Block(-4,11,7,LEAVES:0)
Block(-4,11,8,LEAVES:0)
Block(-4,12,-7,LEAVES:0)
Block(-4,12,-6,LEAVES:0)
Block(-4,12,-5,LEAVES:0)
Block(-4,12,-4,LEAVES:0)
Block(-4,12,0,LEAVES:0)
Block(-4,12,1,LEAVES:0)
Block(-4,12,3,LEAVES:0)
Block(-4,12,7,LOG:12)
Block(-4,13,-8,LEAVES:0)
Block(-4,13,-7,LEAVES:0)
Block(-4,13,-6,LEAVES:0)
Block(-4,13,-4,LEAVES:0)
Block(-4,13,-3,LEAVES:0)
Block(-4,13,-2,LEAVES:0)
Block(-4,13,1,LEAVES:0)
Block(-4,13,3,LEAVES:0)
Block(-4,13,4,LEAVES:0)
Block(-4,13,7,LOG:12)
Block(-4,13,9,LEAVES:0)
Block(-4,14,0,LEAVES:0)
Block(-4,14,3,LEAVES:0)
Block(-4,14,5,LEAVES:0)
Block(-4,14,6,LEAVES:0)
Block(-4,14,7,LEAVES:0)
Block(-4,14,8,LEAVES:0)
Block(-4,14,9,LEAVES:0)
Block(-4,15,-6,LEAVES:0)
Block(-4,15,-4,LEAVES:0)
Block(-4,15,-2,LEAVES:0)
Block(-4,15,1,LEAVES:0)
Block(-4,15,3,LEAVES:0)
Block(-4,15,5,LEAVES:0)
Block(-4,15,6,LEAVES:0)
Block(-4,15,7,LEAVES:0)
Block(-3,9,3,LOG:12)
Block(-3,9,4,LOG:12)
Block(-3,10,-7,LEAVES:0)
Block(-3,10,5,LOG:12)
Block(-3,10,6,LOG:12)
Block(-3,11,-8,LEAVES:0)
Block(-3,11,-7,LEAVES:0)
Block(-3,11,-6,LEAVES:0)
Block(-3,11,6,LOG:12)
Block(-3,11,9,LEAVES:0)
Block(-3,12,-7,LEAVES:0)
Block(-3,12,-6,LEAVES:0)
Block(-3,12,-5,LEAVES:0)
Block(-3,12,3,LEAVES:0)
Block(-3,12,6,LOG:12)
Block(-3,12,7,LOG:12)
Block(-3,12,9,LEAVES:0)
Block(-3,13,-8,LEAVES:0)
Block(-3,13,-7,LEAVES:0)
Block(-3,13,-6,LEAVES:0)
Block(-3,13,-3,LEAVES:0)
Block(-3,13,-2,LEAVES:0)
Block(-3,13,4,LEAVES:0)
Block(-3,13,5,LOG:12)
Block(-3,13,7,LEAVES:0)
Block(-3,13,8,LEAVES:0)
Block(-3,14,-7,LEAVES:0)
Block(-3,14,-2,LEAVES:0)
Block(-3,14,4,LOG:12)
Block(-3,14,5,LEAVES:0)
Block(-3,14,6,LEAVES:0)
Block(-3,14,7,LEAVES:0)
Block(-3,15,2,LEAVES:0)
Block(-3,15,3,LEAVES:0)
Block(-3,15,4,LEAVES:0)
Block(-3,15,6,LEAVES:0)
Block(-3,15,7,LEAVES:0)
Block(-3,16,3,LEAVES:0)
Block(-2,5,1,LOG:12)
Block(-2,6,1,LOG:12)
Block(-2,7,1,LOG:12)
Block(-2,7,2,LOG:12)
Block(-2,7,3,LOG:12)
Block(-2,8,2,LOG:12)
Block(-2,8,3,LOG:12)
Block(-2,9,3,LOG:12)
Block(-2,9,4,LOG:12)
Block(-2,9,5,LOG:12)
Block(-2,10,-6,LEAVES:0)
Block(-2,10,5,LOG:12)
Block(-2,11,-7,LEAVES:0)
Block(-2,11,-6,LEAVES:0)
Block(-2,11,-5,LEAVES:0)
Block(-2,11,-3,LEAVES:0)
Block(-2,11,6,LEAVES:0)
Block(-2,11,7,LEAVES:0)
Block(-2,12,-8,LEAVES:0)
Block(-2,12,-7,LEAVES:0)
Block(-2,12,-6,LOG:12)
Block(-2,12,-5,LEAVES:0)
Block(-2,12,-3,LEAVES:0)
Block(-2,12,3,LEAVES:0)
Block(-2,12,6,LEAVES:0)
Block(-2,13,-7,LEAVES:0)
Block(-2,13,-6,LEAVES:0)
Block(-2,13,-4,LEAVES:0)
Block(-2,13,5,LEAVES:0)
Block(-2,14,-7,LEAVES:0)
Block(-2,14,-6,LEAVES:0)
Block(-2,14,2,LEAVES:0)
Block(-2,14,3,LOG:12)
Block(-2,14,4,LEAVES:0)
Block(-2,14,5,LEAVES:0)
Block(-2,14,6,LEAVES:0)
Block(-2,15,3,LEAVES:0)
Block(-2,15,4,LEAVES:0)
Block(-2,15,5,LEAVES:0)
Block(-2,15,7,LEAVES:0)
Block(-2,16,3,LEAVES:0)
Block(-2,16,4,LEAVES:0)
Block(-1,-2,-3,LOG:12)
Block(-1,-2,2,LOG:12)
Block(-1,-1,-3,LOG:12)
Block(-1,-1,-2,LOG:12)
Block(-1,-1,1,LOG:12)
Block(-1,-1,2,LOG:12)
Block(-1,0,-2,LOG:12)
Block(-1,0,0,LOG:12)
Block(-1,0,1,LOG:12)
Block(-1,1,-2,LOG:12)
Block(-1,2,0,LOG:12)
Block(-1,3,0,LOG:12)
Block(-1,4,0,LOG:12)
Block(-1,4,1,LOG:12)
Block(-1,5,0,LOG:12)
Block(-1,5,1,LOG:12)
Block(-1,6,0,LOG:12)
Block(-1,6,1,LOG:12)
Block(-1,6,2,LOG:12)
Block(-1,7,-1,LOG:12)
Block(-1,7,0,LOG:12)
Block(-1,7,1,LOG:12)
Block(-1,7,2,LOG:12)
Block(-1,7,3,LOG:12)
Block(-1,8,3,LOG:12)
Block(-1,8,4,LOG:12)
Block(-1,9,3,LOG:12)
Block(-1,9,4,LOG:12)
Block(-1,10,-3,LEAVES:0)
Block(-1,11,-6,LEAVES:0)
Block(-1,11,-5,LOG:12)
Block(-1,11,-4,LEAVES:0)
Block(-1,11,-3,LEAVES:0)
Block(-1,11,-2,LEAVES:0)
Block(-1,11,6,LEAVES:0)
Block(-1,12,-7,LEAVES:0)
Block(-1,12,-6,LEAVES:0)
Block(-1,12,-5,LEAVES:0)
Block(-1,12,-4,LEAVES:0)
Block(-1,12,-3,LEAVES:0)
Block(-1,13,-6,LEAVES:0)
Block(-1,13,-4,LEAVES:0)
Block(-1,13,2,LEAVES:0)
Block(-1,13,5,LEAVES:0)
Block(-1,14,3,LEAVES:0)
Block(-1,14,4,LEAVES:0)
Block(-1,14,5,LEAVES:0)
Block(-1,15,1,LEAVES:0)
Block(-1,15,2,LEAVES:0)
Block(-1,15,3,LEAVES:0)
Block(-1,15,5,LEAVES:0)
Block(-1,15,6,LEAVES:0)
Block(-1,16,3,LEAVES:0)
Block(0,-1,0,LOG:12)
Block(0,0,-1,LOG:12)
Block(0,0,0,LOG:12)
Block(0,1,-2,LOG:12)
Block(0,1,-1,LOG:12)
Block(0,1,0,LOG:12)
Block(0,1,1,LOG:12)
Block(0,2,-1,LOG:12)
Block(0,2,0,LOG:12)
Block(0,3,-1,LOG:12)
Block(0,3,0,LOG:12)
Block(0,3,1,LOG:12)
Block(0,4,-1,LOG:12)
Block(0,4,0,LOG:12)
Block(0,4,1,LOG:12)
Block(0,5,0,LOG:12)
Block(0,5,1,LOG:12)
Block(0,5,2,LOG:12)
Block(0,6,0,LOG:12)
Block(0,6,1,LOG:12)
Block(0,6,2,LOG:12)
Block(0,7,-1,LOG:12)
Block(0,7,0,LOG:12)
Block(0,7,2,LOG:12)
Block(0,7,3,LOG:12)
Block(0,8,-1,LOG:12)
Block(0,10,-5,LOG:12)
Block(0,10,-4,LEAVES:0)
Block(0,10,-2,LEAVES:0)
Block(0,11,-5,LOG:12)
Block(0,11,-4,LEAVES:0)
Block(0,11,-3,LEAVES:0)
Block(0,12,-7,LEAVES:0)
Block(0,12,-6,LEAVES:0)
Block(0,12,-5,LEAVES:0)
Block(0,12,-4,LEAVES:0)
Block(0,12,-3,LEAVES:0)
Block(0,12,-2,LEAVES:0)
Block(0,12,0,LEAVES:0)
Block(0,12,10,LEAVES:0)
Block(0,13,-8,LEAVES:0)
Block(0,13,-6,LEAVES:0)
Block(0,13,-4,LEAVES:0)
Block(0,13,-3,LEAVES:0)
Block(0,13,-1,LEAVES:0)
Block(0,13,0,LEAVES:0)
Block(0,13,2,LEAVES:0)
Block(0,13,4,LEAVES:0)
Block(0,13,9,LEAVES:0)
Block(0,14,-8,LEAVES:0)
Block(0,14,-5,LEAVES:0)
Block(0,14,-4,LEAVES:0)
Block(0,14,-2,LEAVES:0)
Block(0,14,0,LEAVES:0)
Block(0,14,1,LEAVES:0)
Block(0,14,3,LEAVES:0)
Block(0,14,4,LEAVES:0)
Block(0,14,5,LEAVES:0)
Block(0,14,10,LEAVES:0)
Block(0,15,-6,LEAVES:0)
Block(0,15,-5,LEAVES:0)
Block(0,15,1,LEAVES:0)
Block(0,15,3,LEAVES:0)
Block(0,15,4,LEAVES:0)
Block(0,15,5,LEAVES:0)
Block(0,16,1,LEAVES:0)
Block(1,1,-1,LOG:12)
Block(1,1,0,LOG:12)
Block(1,2,-2,LOG:12)
Block(1,2,-1,LOG:12)
Block(1,2,0,LOG:12)
Block(1,3,-1,LOG:12)
Block(1,3,0,LOG:12)
Block(1,4,0,LOG:12)
Block(1,5,0,LOG:12)
Block(1,5,1,LOG:12)
Block(1,7,2,LOG:12)
Block(1,7,3,LOG:12)
Block(1,8,-2,LOG:12)
Block(1,8,-1,LOG:12)
Block(1,8,3,LOG:12)
Block(1,9,-4,LOG:12)
Block(1,9,-2,LOG:12)
Block(1,10,-6,LEAVES:0)
Block(1,10,-5,LOG:12)
Block(1,10,-4,LEAVES:0)
Block(1,10,-3,LEAVES:0)
Block(1,10,-2,LEAVES:0)
Block(1,10,-1,LEAVES:0)
Block(1,11,-7,LEAVES:0)
Block(1,11,-6,LEAVES:0)
Block(1,11,-5,LEAVES:0)
Block(1,11,-3,LEAVES:0)
Block(1,11,-2,LEAVES:0)
Block(1,11,7,LOG:12)
Block(1,11,8,LOG:12)
Block(1,11,9,LOG:12)
Block(1,12,-8,LEAVES:0)
Block(1,12,-6,LEAVES:0)
Block(1,12,-5,LEAVES:0)
Block(1,12,-4,LEAVES:0)
Block(1,12,-3,LEAVES:0)
Block(1,12,-2,LEAVES:0)
Block(1,12,8,LEAVES:0)
Block(1,12,9,LOG:12)
Block(1,12,10,LOG:12)
Block(1,12,11,LEAVES:0)
Block(1,13,-7,LEAVES:0)
Block(1,13,-4,LEAVES:0)
Block(1,13,-1,LEAVES:0)
Block(1,13,0,LEAVES:0)
Block(1,13,1,LEAVES:0)
Block(1,13,3,LEAVES:0)
Block(1,13,4,LEAVES:0)
Block(1,13,9,LEAVES:0)
Block(1,13,10,LEAVES:0)
Block(1,13,11,LEAVES:0)
Block(1,14,-7,LEAVES:0)
Block(1,14,-5,LEAVES:0)
Block(1,14,-4,LEAVES:0)
Block(1,14,-2,LEAVES:0)
Block(1,14,3,LEAVES:0)
Block(1,14,9,LEAVES:0)
Block(1,14,10,LEAVES:0)
Block(1,14,11,LEAVES:0)
Block(1,15,-6,LEAVES:0)
Block(1,15,-5,LEAVES:0)
Block(1,15,-2,LEAVES:0)
Block(1,15,0,LEAVES:0)
Block(1,15,3,LEAVES:0)
Block(1,15,4,LEAVES:0)
Block(1,15,8,LEAVES:0)
Block(1,15,10,LEAVES:0)
Block(1,16,-6,LEAVES:0)
Block(1,16,-5,LEAVES:0)
Block(1,16,-2,LEAVES:0)
Block(1,16,0,LEAVES:0)
Block(1,16,2,LEAVES:0)
Block(1,16,5,LEAVES:0)
Block(2,-2,-2,LOG:12)
Block(2,-2,0,LOG:12)
Block(2,-1,-3,LOG:12)
Block(2,-1,-2,LOG:12)
Block(2,-1,0,LOG:12)
Block(2,0,-3,LOG:12)
Block(2,0,-2,LOG:12)
Block(2,0,0,LOG:12)
Block(2,1,-2,LOG:12)
Block(2,1,-1,LOG:12)
Block(2,1,0,LOG:12)
Block(2,2,-2,LOG:12)
Block(2,2,-1,LOG:12)
Block(2,8,3,LOG:12)
Block(2,9,-3,LOG:12)
Block(2,9,-2,LOG:12)
Block(2,9,3,LOG:12)
Block(2,9,4,LOG:12)
Block(2,10,-6,LOG:12)
Block(2,10,-5,LOG:12)
Block(2,10,-4,LEAVES:0)
Block(2,10,-2,LOG:12)
Block(2,10,-1,LEAVES:0)
Block(2,10,4,LOG:12)
Block(2,10,5,LOG:12)
Block(2,10,6,LOG:12)
Block(2,10,7,LOG:12)
Block(2,11,-7,LEAVES:0)
Block(2,11,-6,LEAVES:0)
Block(2,11,-4,LEAVES:0)
Block(2,11,-2,LEAVES:0)
Block(2,11,-1,LEAVES:0)
Block(2,11,0,LEAVES:0)
Block(2,11,3,LOG:12)
Block(2,11,4,LOG:12)
Block(2,11,7,LOG:12)
Block(2,11,9,LEAVES:0)
Block(2,12,-8,LEAVES:0)
Block(2,12,-6,LEAVES:0)
Block(2,12,-5,LEAVES:0)
Block(2,12,-4,LEAVES:0)
Block(2,12,-3,LEAVES:0)
Block(2,12,-2,LEAVES:0)
Block(2,12,-1,LEAVES:0)
Block(2,12,0,LEAVES:0)
Block(2,12,5,LEAVES:0)
Block(2,12,9,LEAVES:0)
Block(2,12,10,LOG:12)
Block(2,13,-6,LEAVES:0)
Block(2,13,-5,LEAVES:0)
Block(2,13,-4,LEAVES:0)
Block(2,13,-2,LEAVES:0)
Block(2,13,-1,LEAVES:0)
Block(2,13,0,LEAVES:0)
Block(2,13,1,LEAVES:0)
Block(2,13,2,LEAVES:0)
Block(2,13,3,LEAVES:0)
Block(2,13,7,LEAVES:0)
Block(2,13,10,LOG:12)
Block(2,13,11,LEAVES:0)
Block(2,14,-5,LEAVES:0)
Block(2,14,-3,LEAVES:0)
Block(2,14,-2,LEAVES:0)
Block(2,14,-1,LEAVES:0)
Block(2,14,1,LEAVES:0)
Block(2,14,2,LEAVES:0)
Block(2,14,3,LEAVES:0)
Block(2,14,4,LEAVES:0)
Block(2,14,7,LEAVES:0)
Block(2,14,8,LEAVES:0)
Block(2,14,9,LEAVES:0)
Block(2,14,10,LEAVES:0)
Block(2,14,11,LEAVES:0)
Block(2,14,12,LEAVES:0)
Block(2,15,-5,LEAVES:0)
Block(2,15,-3,LEAVES:0)
Block(2,15,-2,LEAVES:0)
Block(2,15,0,LEAVES:0)
Block(2,15,1,LEAVES:0)
Block(2,15,3,LEAVES:0)
Block(2,15,9,LEAVES:0)
Block(2,15,10,LEAVES:0)
Block(2,16,-4,LEAVES:0)
Block(2,16,0,LEAVES:0)
Block(2,16,4,LEAVES:0)
Block(3,-1,-2,LOG:12)
Block(3,0,-2,LOG:12)
Block(3,1,-2,LOG:12)
Block(3,10,-6,LOG:12)
Block(3,10,-4,LEAVES:0)
Block(3,10,-2,LEAVES:0)
Block(3,11,-8,LEAVES:0)
Block(3,11,-6,LOG:12)
Block(3,11,-5,LEAVES:0)
Block(3,11,-3,LOG:12)
Block(3,11,-2,LEAVES:0)
Block(3,11,2,LEAVES:0)
Block(3,11,3,LOG:12)
Block(3,11,9,LEAVES:0)
Block(3,11,10,LEAVES:0)
Block(3,12,-8,LEAVES:0)
Block(3,12,-7,LEAVES:0)
Block(3,12,-6,LEAVES:0)
Block(3,12,-4,LEAVES:0)
Block(3,12,-3,LOG:12)
Block(3,12,-2,LEAVES:0)
Block(3,12,0,LEAVES:0)
Block(3,12,2,LEAVES:0)
Block(3,12,4,LEAVES:0)
Block(3,12,5,LEAVES:0)
Block(3,12,8,LEAVES:0)
Block(3,12,9,LEAVES:0)
Block(3,13,-8,LEAVES:0)
Block(3,13,-7,LEAVES:0)
Block(3,13,-6,LEAVES:0)
Block(3,13,-5,LEAVES:0)
Block(3,13,-3,LEAVES:0)
Block(3,13,0,LEAVES:0)
Block(3,13,1,LEAVES:0)
Block(3,13,2,LEAVES:0)
Block(3,13,3,LEAVES:0)
Block(3,13,4,LEAVES:0)
Block(3,13,5,LEAVES:0)
Block(3,13,6,LEAVES:0)
Block(3,13,8,LEAVES:0)
Block(3,13,9,LEAVES:0)
Block(3,13,10,LOG:12)
Block(3,13,11,LEAVES:0)
Block(3,13,12,LEAVES:0)
Block(3,14,-6,LEAVES:0)
Block(3,14,-5,LEAVES:0)
Block(3,14,-1,LEAVES:0)
Block(3,14,0,LEAVES:0)
Block(3,14,2,LEAVES:0)
Block(3,14,3,LEAVES:0)
Block(3,14,5,LEAVES:0)
Block(3,14,6,LEAVES:0)
Block(3,14,8,LEAVES:0)
Block(3,14,9,LEAVES:0)
Block(3,14,10,LEAVES:0)
Block(3,14,11,LEAVES:0)
Block(3,15,-2,LEAVES:0)
Block(3,15,1,LEAVES:0)
Block(3,15,2,LEAVES:0)
Block(3,15,5,LEAVES:0)
Block(3,15,6,LEAVES:0)
Block(3,15,8,LEAVES:0)
Block(3,15,11,LEAVES:0)
Block(3,16,3,LEAVES:0)
Block(4,10,-7,LEAVES:0)
Block(4,11,-7,LEAVES:0)
Block(4,11,-6,LOG:12)
Block(4,11,-4,LEAVES:0)
Block(4,11,-3,LEAVES:0)
Block(4,11,-2,LEAVES:0)
Block(4,11,9,LEAVES:0)
Block(4,12,-8,LEAVES:0)
Block(4,12,-7,LOG:12)
Block(4,12,-5,LEAVES:0)
Block(4,12,-4,LEAVES:0)
Block(4,12,-3,LEAVES:0)
Block(4,12,-2,LEAVES:0)
Block(4,12,-1,LEAVES:0)
Block(4,12,2,LOG:12)
Block(4,12,3,LOG:12)
Block(4,12,4,LEAVES:0)
Block(4,12,5,LEAVES:0)
Block(4,12,6,LEAVES:0)
Block(4,12,8,LEAVES:0)
Block(4,12,9,LEAVES:0)
Block(4,13,-8,LEAVES:0)
Block(4,13,-7,LEAVES:0)
Block(4,13,-6,LEAVES:0)
Block(4,13,-4,LEAVES:0)
Block(4,13,-3,LEAVES:0)
Block(4,13,-1,LEAVES:0)
Block(4,13,0,LEAVES:0)
Block(4,13,1,LEAVES:0)
Block(4,13,3,LEAVES:0)
Block(4,13,5,LEAVES:0)
Block(4,13,6,LEAVES:0)
Block(4,13,9,LEAVES:0)
Block(4,13,10,LEAVES:0)
Block(4,13,11,LEAVES:0)
Block(4,14,-7,LEAVES:0)
Block(4,14,-5,LEAVES:0)
Block(4,14,-4,LEAVES:0)
Block(4,14,-1,LEAVES:0)
Block(4,14,0,LEAVES:0)
Block(4,14,1,LEAVES:0)
Block(4,14,2,LEAVES:0)
Block(4,14,3,LEAVES:0)
Block(4,14,5,LEAVES:0)
Block(4,14,6,LEAVES:0)
Block(4,14,8,LEAVES:0)
Block(4,14,9,LEAVES:0)
Block(4,14,11,LEAVES:0)
Block(4,15,-4,LEAVES:0)
Block(4,15,-1,LEAVES:0)
Block(4,15,0,LEAVES:0)
Block(4,15,8,LEAVES:0)
Block(4,15,9,LEAVES:0)
Block(4,15,10,LEAVES:0)
Block(4,16,3,LEAVES:0)
Block(5,11,-3,LEAVES:0)
Block(5,11,-2,LEAVES:0)
Block(5,11,-1,LEAVES:0)
Block(5,11,1,LEAVES:0)
Block(5,11,2,LEAVES:0)
Block(5,11,3,LEAVES:0)
Block(5,11,4,LEAVES:0)
Block(5,12,-8,LEAVES:0)
Block(5,12,-7,LEAVES:0)
Block(5,12,-5,LEAVES:0)
Block(5,12,-4,LEAVES:0)
Block(5,12,-3,LEAVES:0)
Block(5,12,-2,LEAVES:0)
Block(5,12,-1,LEAVES:0)
Block(5,12,0,LEAVES:0)
Block(5,12,1,LOG:12)
Block(5,12,2,LEAVES:0)
Block(5,12,3,LEAVES:0)
Block(5,12,4,LEAVES:0)
Block(5,12,5,LEAVES:0)
Block(5,12,9,LEAVES:0)
Block(5,13,-4,LEAVES:0)
Block(5,13,-3,LEAVES:0)
Block(5,13,-1,LEAVES:0)
Block(5,13,0,LOG:12)
Block(5,13,1,LOG:12)
Block(5,13,2,LEAVES:0)
Block(5,13,3,LEAVES:0)
Block(5,13,4,LOG:12)
Block(5,13,5,LEAVES:0)
Block(5,13,6,LEAVES:0)
Block(5,13,7,LEAVES:0)
Block(5,13,9,LEAVES:0)
Block(5,13,10,LEAVES:0)
Block(5,14,-7,LEAVES:0)
Block(5,14,-3,LEAVES:0)
Block(5,14,-1,LEAVES:0)
Block(5,14,0,LEAVES:0)
Block(5,14,1,LEAVES:0)
Block(5,14,2,LEAVES:0)
Block(5,14,4,LEAVES:0)
Block(5,14,6,LEAVES:0)
Block(5,14,8,LEAVES:0)
Block(5,14,9,LEAVES:0)
Block(5,15,-4,LEAVES:0)
Block(5,15,0,LEAVES:0)
Block(5,15,1,LEAVES:0)
Block(5,15,10,LEAVES:0)
Block(6,11,-7,LEAVES:0)
Block(6,11,-6,LEAVES:0)
Block(6,11,-4,LEAVES:0)
Block(6,11,-2,LEAVES:0)
Block(6,11,-1,LEAVES:0)
Block(6,11,1,LEAVES:0)
Block(6,11,2,LEAVES:0)
Block(6,11,4,LEAVES:0)
Block(6,12,-6,LEAVES:0)
Block(6,12,-5,LEAVES:0)
Block(6,12,-4,LEAVES:0)
Block(6,12,-3,LEAVES:0)
Block(6,12,-2,LEAVES:0)
Block(6,12,-1,LEAVES:0)
Block(6,12,1,LEAVES:0)
Block(6,12,2,LEAVES:0)
Block(6,12,3,LEAVES:0)
Block(6,12,4,LEAVES:0)
Block(6,13,-7,LEAVES:0)
Block(6,13,-6,LEAVES:0)
Block(6,13,-2,LEAVES:0)
Block(6,13,-1,LEAVES:0)
Block(6,13,0,LEAVES:0)
Block(6,13,2,LEAVES:0)
Block(6,13,3,LEAVES:0)
Block(6,13,4,LOG:12)
Block(6,13,5,LEAVES:0)
Block(6,13,7,LEAVES:0)
Block(6,14,-1,LEAVES:0)
Block(6,14,1,LEAVES:0)
Block(6,14,3,LEAVES:0)
Block(6,14,4,LEAVES:0)
Block(6,14,5,LEAVES:0)
Block(6,15,-4,LEAVES:0)
Block(6,15,1,LEAVES:0)
Block(7,11,-3,LEAVES:0)
Block(7,11,0,LEAVES:0)
Block(7,12,-6,LEAVES:0)
Block(7,12,-2,LEAVES:0)
Block(7,12,-1,LEAVES:0)
Block(7,12,0,LEAVES:0)
Block(7,12,3,LEAVES:0)
Block(7,12,4,LEAVES:0)
Block(7,13,0,LEAVES:0)
Block(7,13,1,LEAVES:0)
Block(7,13,2,LEAVES:0)
Block(7,13,3,LEAVES:0)
Block(7,13,4,LEAVES:0)
Block(7,14,2,LEAVES:0)
Block(7,14,3,LEAVES:0)
Block(7,14,4,LEAVES:0)
Block(7,15,3,LEAVES:0)
Block(8,12,0,LEAVES:0)
Block(8,12,2,LEAVES:0)
Block(8,13,3,LEAVES:0)
Block(8,13,4,LEAVES:0)
Block(8,14,2,LEAVES:0)

#######################################################################
# +-----------------------------------------------------------------+ #
# |                            BO3 checks                           | #
# +-----------------------------------------------------------------+ #
#######################################################################

BlockCheck(0,-1,0,GRASS:0)

#######################################################################
# +-----------------------------------------------------------------+ #
# |                             Branches                            | #
# +-----------------------------------------------------------------+ #
#######################################################################


#######################################################################
# +-----------------------------------------------------------------+ #
# |                             Entities                            | #
# +-----------------------------------------------------------------+ #
#######################################################################


#######################################################################
# +-----------------------------------------------------------------+ #
# |                            Particles                            | #
# +-----------------------------------------------------------------+ #
#######################################################################


#######################################################################
# +-----------------------------------------------------------------+ #
# |                             Spawners                            | #
# +-----------------------------------------------------------------+ #
#######################################################################


#######################################################################
# +-----------------------------------------------------------------+ #
# |                             ModData                             | #
# +-----------------------------------------------------------------+ #
#######################################################################

