
#######################################################################
# +-----------------------------------------------------------------+ #
# |                            BO3 object                           | #
# +-----------------------------------------------------------------+ #
#######################################################################

Author: Unknown

Description: This BO3 was converted from a schematic using OTGEdit. The author and description information of the schematic could not be found. If you know who the author of the schematic is then please add this information.

Version: 3

SettingsMode: WriteWithoutComments


#######################################################################
# +-----------------------------------------------------------------+ #
# |                          Main settings                          | #
# +-----------------------------------------------------------------+ #
#######################################################################

Tree: true

Frequency: 1

Rarity: 100.0

RotateRandomly: true

SpawnHeight: highestSolidBlock

SpawnHeightOffset: 0

SpawnHeightVariance: 0

##############################
# Height Limits for the BO3. #
##############################

MinHeight: 62

MaxHeight: 255

######################
# Extrusion settings #
######################

ExtrudeMode: BottomDown

ExtrudeThroughBlocks: AIR,STATIONARY_WATER:0

MaxBranchDepth: 10

ExcludedBiomes: All


#######################################################################
# +-----------------------------------------------------------------+ #
# |                      Source block settings                      | #
# +-----------------------------------------------------------------+ #
#######################################################################

SourceBlocks: AIR,STATIONARY_WATER:0

MaxPercentageOutsideSourceBlock: 100

OutsideSourceBlock: dontPlace

DoReplaceBlocks: true

IsOTGPlus: false


#######################################################################
# +-----------------------------------------------------------------+ #
# |                              Blocks                             | #
# +-----------------------------------------------------------------+ #
#######################################################################

Block(-5,9,-5,VINE:1)
Block(-5,10,-5,VINE:1)
Block(-5,10,-1,VINE:8)
Block(-5,11,-5,VINE:1)
Block(-5,11,-1,VINE:8)
Block(-5,12,-5,VINE:1)
Block(-5,12,-1,VINE:8)
Block(-5,13,-5,VINE:1)
Block(-5,13,-1,VINE:8)
Block(-5,14,-5,VINE:1)
Block(-5,14,-1,VINE:8)
Block(-5,15,-5,VINE:1)
Block(-5,15,-4,LEAVES:3)
Block(-5,15,-1,VINE:8)
Block(-5,16,-1,VINE:8)
Block(-5,17,-1,VINE:8)
Block(-4,8,-1,VINE:8)
Block(-4,9,-1,VINE:8)
Block(-4,9,3,VINE:8)
Block(-4,10,-1,VINE:8)
Block(-4,10,3,VINE:8)
Block(-4,11,-1,VINE:8)
Block(-4,11,3,VINE:8)
Block(-4,12,-1,VINE:8)
Block(-4,12,3,VINE:8)
Block(-4,13,-1,VINE:8)
Block(-4,13,3,VINE:8)
Block(-4,14,-1,VINE:8)
Block(-4,14,3,VINE:8)
Block(-4,15,-5,LEAVES:3)
Block(-4,15,-4,LEAVES:3)
Block(-4,15,-3,LEAVES:3)
Block(-4,15,-1,VINE:8)
Block(-4,15,0,LEAVES:3)
Block(-4,15,3,VINE:8)
Block(-4,16,-4,LEAVES:3)
Block(-4,16,-3,VINE:4)
Block(-4,16,-2,LEAVES:3)
Block(-4,16,-1,LEAVES:3)
Block(-4,16,0,LEAVES:3)
Block(-4,16,1,LEAVES:3)
Block(-4,16,3,VINE:8)
Block(-4,17,-2,VINE:1)
Block(-4,17,-1,LEAVES:3)
Block(-4,17,0,LEAVES:3)
Block(-3,13,-4,LEAVES:3)
Block(-3,14,-5,LEAVES:3)
Block(-3,14,-4,LEAVES:3)
Block(-3,14,-3,LEAVES:3)
Block(-3,14,0,LEAVES:3)
Block(-3,14,3,LEAVES:3)
Block(-3,15,-6,LEAVES:3)
Block(-3,15,-5,LEAVES:3)
Block(-3,15,-4,LEAVES:3)
Block(-3,15,-3,LEAVES:3)
Block(-3,15,-2,LEAVES:3)
Block(-3,15,-1,LEAVES:3)
Block(-3,15,0,LEAVES:3)
Block(-3,15,1,LEAVES:3)
Block(-3,15,2,LEAVES:3)
Block(-3,15,3,LEAVES:3)
Block(-3,15,4,LEAVES:3)
Block(-3,16,-5,LEAVES:3)
Block(-3,16,-4,LEAVES:3)
Block(-3,16,-3,LEAVES:3)
Block(-3,16,-2,LEAVES:3)
Block(-3,16,-1,LEAVES:3)
Block(-3,16,0,LEAVES:3)
Block(-3,16,1,LEAVES:3)
Block(-3,16,2,LEAVES:3)
Block(-3,16,3,LEAVES:3)
Block(-3,17,-2,LEAVES:3)
Block(-3,17,-1,LEAVES:3)
Block(-3,17,0,LEAVES:3)
Block(-3,17,1,LEAVES:3)
Block(-3,18,0,LEAVES:3)
Block(-2,4,0,VINE:8)
Block(-2,5,0,VINE:8)
Block(-2,6,-1,VINE:8)
Block(-2,6,0,VINE:8)
Block(-2,7,-1,VINE:8)
Block(-2,7,0,VINE:8)
Block(-2,8,-1,VINE:8)
Block(-2,8,0,VINE:8)
Block(-2,9,-1,VINE:8)
Block(-2,9,0,VINE:8)
Block(-2,10,-1,VINE:8)
Block(-2,10,0,VINE:8)
Block(-2,11,0,VINE:8)
Block(-2,13,-5,LEAVES:3)
Block(-2,13,-4,LEAVES:3)
Block(-2,13,3,LEAVES:3)
Block(-2,14,-6,LEAVES:3)
Block(-2,14,-5,LEAVES:3)
Block(-2,14,-4,LEAVES:3)
Block(-2,14,-3,LEAVES:3)
Block(-2,14,-2,LEAVES:3)
Block(-2,14,-1,LEAVES:3)
Block(-2,14,0,LEAVES:3)
Block(-2,14,1,LEAVES:3)
Block(-2,14,2,LEAVES:3)
Block(-2,14,3,LEAVES:3)
Block(-2,14,4,LEAVES:3)
Block(-2,15,-7,LEAVES:3)
Block(-2,15,-6,LEAVES:3)
Block(-2,15,-5,LEAVES:3)
Block(-2,15,-4,LEAVES:3)
Block(-2,15,-3,LEAVES:3)
Block(-2,15,-2,LEAVES:3)
Block(-2,15,-1,LEAVES:3)
Block(-2,15,0,LEAVES:3)
Block(-2,15,1,LEAVES:3)
Block(-2,15,2,LEAVES:3)
Block(-2,15,3,LEAVES:3)
Block(-2,15,4,LEAVES:3)
Block(-2,15,5,LEAVES:3)
Block(-2,16,-6,LEAVES:3)
Block(-2,16,-5,LEAVES:3)
Block(-2,16,-4,LEAVES:3)
Block(-2,16,-3,LEAVES:3)
Block(-2,16,-2,LEAVES:3)
Block(-2,16,-1,LEAVES:3)
Block(-2,16,0,LEAVES:3)
Block(-2,16,1,LEAVES:3)
Block(-2,16,2,LEAVES:3)
Block(-2,16,3,LEAVES:3)
Block(-2,16,4,LEAVES:3)
Block(-2,17,-5,VINE:1)
Block(-2,17,-4,LEAVES:3)
Block(-2,17,-3,LEAVES:3)
Block(-2,17,-2,LEAVES:3)
Block(-2,17,-1,LEAVES:3)
Block(-2,17,0,LEAVES:3)
Block(-2,17,1,LEAVES:3)
Block(-2,17,2,LEAVES:3)
Block(-2,17,3,LEAVES:3)
Block(-2,18,-1,LEAVES:3)
Block(-2,18,0,LEAVES:3)
Block(-2,18,1,LEAVES:3)
Block(-1,0,-1,LOG:3)
Block(-1,0,0,LOG:3)
Block(-1,1,-1,LOG:3)
Block(-1,1,0,LOG:3)
Block(-1,2,-1,LOG:3)
Block(-1,2,0,LOG:3)
Block(-1,3,-1,LOG:3)
Block(-1,3,0,LOG:3)
Block(-1,4,-1,LOG:3)
Block(-1,4,0,LOG:3)
Block(-1,5,-1,LOG:3)
Block(-1,5,0,LOG:3)
Block(-1,6,-2,VINE:8)
Block(-1,6,-1,LOG:3)
Block(-1,6,0,LOG:3)
Block(-1,6,1,VINE:4)
Block(-1,7,-2,LEAVES:3)
Block(-1,7,-1,LOG:3)
Block(-1,7,0,LOG:3)
Block(-1,7,1,VINE:4)
Block(-1,8,-2,VINE:1)
Block(-1,8,-1,LOG:3)
Block(-1,8,0,LOG:3)
Block(-1,8,1,VINE:4)
Block(-1,9,-2,VINE:1)
Block(-1,9,-1,LOG:3)
Block(-1,9,0,LOG:3)
Block(-1,9,1,VINE:4)
Block(-1,10,-2,VINE:1)
Block(-1,10,-1,LOG:3)
Block(-1,10,0,LOG:3)
Block(-1,11,-2,VINE:1)
Block(-1,11,-1,LOG:3)
Block(-1,11,0,LOG:3)
Block(-1,12,-2,VINE:1)
Block(-1,12,-1,LOG:3)
Block(-1,12,0,LOG:3)
Block(-1,13,-5,LEAVES:3)
Block(-1,13,-4,LEAVES:3)
Block(-1,13,-3,LEAVES:3)
Block(-1,13,-2,VINE:1)
Block(-1,13,-1,LOG:3)
Block(-1,13,0,LOG:3)
Block(-1,13,2,LEAVES:3)
Block(-1,14,-6,LEAVES:3)
Block(-1,14,-5,LEAVES:3)
Block(-1,14,-4,LEAVES:3)
Block(-1,14,-3,LEAVES:3)
Block(-1,14,-2,LEAVES:3)
Block(-1,14,-1,LOG:3)
Block(-1,14,0,LOG:3)
Block(-1,14,1,LEAVES:3)
Block(-1,14,2,LEAVES:3)
Block(-1,14,3,LEAVES:3)
Block(-1,14,4,LEAVES:3)
Block(-1,14,5,LEAVES:3)
Block(-1,15,-7,LEAVES:3)
Block(-1,15,-6,LEAVES:3)
Block(-1,15,-5,LEAVES:3)
Block(-1,15,-4,LOG:15)
Block(-1,15,-3,LOG:11)
Block(-1,15,-2,LEAVES:3)
Block(-1,15,-1,LOG:3)
Block(-1,15,0,LOG:3)
Block(-1,15,1,LEAVES:3)
Block(-1,15,2,LEAVES:3)
Block(-1,15,3,LEAVES:3)
Block(-1,15,4,LEAVES:3)
Block(-1,15,5,LEAVES:3)
Block(-1,15,6,LEAVES:3)
Block(-1,16,-7,LEAVES:3)
Block(-1,16,-6,LEAVES:3)
Block(-1,16,-5,LEAVES:3)
Block(-1,16,-4,LEAVES:3)
Block(-1,16,-3,LEAVES:3)
Block(-1,16,-2,LOG:11)
Block(-1,16,-1,LOG:11)
Block(-1,16,0,LOG:11)
Block(-1,16,1,LOG:11)
Block(-1,16,2,LEAVES:3)
Block(-1,16,3,LEAVES:3)
Block(-1,16,4,LEAVES:3)
Block(-1,16,5,LEAVES:3)
Block(-1,17,-4,LEAVES:3)
Block(-1,17,-3,LEAVES:3)
Block(-1,17,-2,LEAVES:3)
Block(-1,17,-1,LEAVES:3)
Block(-1,17,0,LEAVES:3)
Block(-1,17,1,LEAVES:3)
Block(-1,17,2,LEAVES:3)
Block(-1,17,3,LEAVES:3)
Block(-1,18,-3,LEAVES:3)
Block(-1,18,-2,LEAVES:3)
Block(-1,18,-1,LEAVES:3)
Block(-1,18,0,LEAVES:3)
Block(-1,18,1,LEAVES:3)
Block(0,0,-1,LOG:3)
Block(0,0,0,LOG:3)
Block(0,1,-1,LOG:3)
Block(0,1,0,LOG:3)
Block(0,2,-1,LOG:3)
Block(0,2,0,LOG:3)
Block(0,3,-1,LOG:3)
Block(0,3,0,LOG:3)
Block(0,4,-1,LOG:3)
Block(0,4,0,LOG:3)
Block(0,5,-1,LOG:3)
Block(0,5,0,LOG:3)
Block(0,6,-4,VINE:2)
Block(0,6,-2,LEAVES:3)
Block(0,6,-1,LOG:3)
Block(0,6,0,LOG:3)
Block(0,6,2,VINE:4)
Block(0,7,-4,VINE:2)
Block(0,7,-3,LEAVES:3)
Block(0,7,-2,LEAVES:3)
Block(0,7,-1,LOG:3)
Block(0,7,0,LOG:3)
Block(0,7,1,LEAVES:3)
Block(0,7,2,VINE:4)
Block(0,8,-4,VINE:2)
Block(0,8,-3,VINE:1)
Block(0,8,-2,LEAVES:3)
Block(0,8,-1,LOG:3)
Block(0,8,0,LOG:3)
Block(0,8,1,VINE:12)
Block(0,9,-4,VINE:2)
Block(0,9,-1,LOG:3)
Block(0,9,0,LOG:3)
Block(0,9,1,VINE:12)
Block(0,10,-4,VINE:2)
Block(0,10,-1,LOG:3)
Block(0,10,0,LOG:3)
Block(0,10,1,VINE:12)
Block(0,11,-4,VINE:2)
Block(0,11,-1,LOG:3)
Block(0,11,0,LOG:3)
Block(0,11,1,VINE:12)
Block(0,12,-4,VINE:2)
Block(0,12,-1,LOG:3)
Block(0,12,0,LOG:3)
Block(0,12,1,VINE:12)
Block(0,13,-5,LEAVES:3)
Block(0,13,-4,VINE:2)
Block(0,13,-1,LOG:3)
Block(0,13,0,LOG:3)
Block(0,13,1,VINE:8)
Block(0,13,2,LEAVES:3)
Block(0,13,3,LEAVES:3)
Block(0,14,-6,LEAVES:3)
Block(0,14,-5,LEAVES:3)
Block(0,14,-4,LEAVES:3)
Block(0,14,-3,LEAVES:3)
Block(0,14,-2,LEAVES:3)
Block(0,14,-1,LOG:3)
Block(0,14,0,LOG:3)
Block(0,14,1,LEAVES:3)
Block(0,14,2,LEAVES:3)
Block(0,14,3,LEAVES:3)
Block(0,14,4,LEAVES:3)
Block(0,14,5,LEAVES:3)
Block(0,14,6,LEAVES:3)
Block(0,15,-7,LEAVES:3)
Block(0,15,-6,LEAVES:3)
Block(0,15,-5,LEAVES:3)
Block(0,15,-4,LEAVES:3)
Block(0,15,-3,LEAVES:3)
Block(0,15,-2,LEAVES:3)
Block(0,15,-1,LOG:3)
Block(0,15,0,LOG:3)
Block(0,15,1,LEAVES:3)
Block(0,15,2,LOG:11)
Block(0,15,3,LOG:15)
Block(0,15,4,LEAVES:3)
Block(0,15,5,LEAVES:3)
Block(0,15,6,LEAVES:3)
Block(0,15,7,LEAVES:3)
Block(0,16,-6,LEAVES:3)
Block(0,16,-5,LEAVES:3)
Block(0,16,-4,LEAVES:3)
Block(0,16,-3,LEAVES:3)
Block(0,16,-2,LEAVES:3)
Block(0,16,-1,LOG:15)
Block(0,16,0,LOG:11)
Block(0,16,1,LOG:11)
Block(0,16,2,LEAVES:3)
Block(0,16,3,LEAVES:3)
Block(0,16,4,LEAVES:3)
Block(0,16,5,LEAVES:3)
Block(0,16,6,LEAVES:3)
Block(0,17,-4,LEAVES:3)
Block(0,17,-3,LEAVES:3)
Block(0,17,-2,LEAVES:3)
Block(0,17,-1,LEAVES:3)
Block(0,17,0,LEAVES:3)
Block(0,17,1,LEAVES:3)
Block(0,17,2,LEAVES:3)
Block(0,17,3,LEAVES:3)
Block(0,17,4,LEAVES:3)
Block(0,17,5,LEAVES:3)
Block(0,18,-3,LEAVES:3)
Block(0,18,-2,LEAVES:3)
Block(0,18,-1,LEAVES:3)
Block(0,18,0,LEAVES:3)
Block(0,18,1,LEAVES:3)
Block(0,18,2,LEAVES:3)
Block(1,6,-3,LEAVES:3)
Block(1,6,-2,LEAVES:3)
Block(1,6,-1,LEAVES:3)
Block(1,6,0,LEAVES:3)
Block(1,6,1,LEAVES:3)
Block(1,7,-4,LEAVES:3)
Block(1,7,-3,LEAVES:3)
Block(1,7,-2,LEAVES:3)
Block(1,7,-1,LEAVES:3)
Block(1,7,0,LEAVES:3)
Block(1,7,1,LEAVES:3)
Block(1,7,2,LEAVES:3)
Block(1,8,-3,LEAVES:3)
Block(1,8,-2,LEAVES:3)
Block(1,8,-1,LOG:7)
Block(1,8,0,LEAVES:3)
Block(1,8,1,LEAVES:3)
Block(1,9,-2,LEAVES:3)
Block(1,9,-1,LEAVES:3)
Block(1,9,0,VINE:8)
Block(1,10,-2,VINE:4)
Block(1,10,-1,VINE:2)
Block(1,11,-2,VINE:4)
Block(1,11,-1,VINE:2)
Block(1,12,-2,VINE:4)
Block(1,12,-1,VINE:2)
Block(1,13,-2,VINE:4)
Block(1,13,-1,VINE:2)
Block(1,13,1,LEAVES:3)
Block(1,13,2,LEAVES:3)
Block(1,13,3,LEAVES:3)
Block(1,13,4,LEAVES:3)
Block(1,14,-5,LEAVES:3)
Block(1,14,-4,LEAVES:3)
Block(1,14,-3,LEAVES:3)
Block(1,14,-2,VINE:4)
Block(1,14,-1,LEAVES:3)
Block(1,14,0,LEAVES:3)
Block(1,14,1,LEAVES:3)
Block(1,14,2,LEAVES:3)
Block(1,14,3,LEAVES:3)
Block(1,14,4,LEAVES:3)
Block(1,14,5,LEAVES:3)
Block(1,15,-6,LEAVES:3)
Block(1,15,-5,LEAVES:3)
Block(1,15,-4,LEAVES:3)
Block(1,15,-3,LEAVES:3)
Block(1,15,-2,LEAVES:3)
Block(1,15,-1,LEAVES:3)
Block(1,15,0,LEAVES:3)
Block(1,15,1,LOG:11)
Block(1,15,2,LOG:15)
Block(1,15,3,LEAVES:3)
Block(1,15,4,LEAVES:3)
Block(1,15,5,LEAVES:3)
Block(1,15,6,LEAVES:3)
Block(1,16,-5,LEAVES:3)
Block(1,16,-4,LEAVES:3)
Block(1,16,-3,LEAVES:3)
Block(1,16,-2,LEAVES:3)
Block(1,16,-1,LEAVES:3)
Block(1,16,0,LEAVES:3)
Block(1,16,1,LEAVES:3)
Block(1,16,2,LEAVES:3)
Block(1,16,3,LEAVES:3)
Block(1,16,4,LEAVES:3)
Block(1,16,5,LEAVES:3)
Block(1,17,-5,VINE:1)
Block(1,17,-4,LEAVES:3)
Block(1,17,-3,LEAVES:3)
Block(1,17,-2,LEAVES:3)
Block(1,17,-1,LEAVES:3)
Block(1,17,0,LEAVES:3)
Block(1,17,1,LEAVES:3)
Block(1,17,2,LEAVES:3)
Block(1,17,3,LEAVES:3)
Block(1,18,-2,LEAVES:3)
Block(1,18,-1,LEAVES:3)
Block(1,18,0,LEAVES:3)
Block(1,18,1,LEAVES:3)
Block(2,5,-3,LEAVES:3)
Block(2,5,-2,LEAVES:3)
Block(2,5,-1,LEAVES:3)
Block(2,5,0,LEAVES:3)
Block(2,6,-4,LEAVES:3)
Block(2,6,-3,LEAVES:3)
Block(2,6,-2,LEAVES:3)
Block(2,6,-1,LEAVES:3)
Block(2,6,0,LEAVES:3)
Block(2,6,1,LEAVES:3)
Block(2,6,2,LEAVES:3)
Block(2,7,-4,LEAVES:3)
Block(2,7,-3,LEAVES:3)
Block(2,7,-2,LEAVES:3)
Block(2,7,-1,LOG:15)
Block(2,7,0,LEAVES:3)
Block(2,7,1,LEAVES:3)
Block(2,7,2,LEAVES:3)
Block(2,8,-4,VINE:1)
Block(2,8,-3,LEAVES:3)
Block(2,8,-2,LEAVES:3)
Block(2,8,-1,LEAVES:3)
Block(2,8,0,LEAVES:3)
Block(2,8,1,LEAVES:3)
Block(2,8,2,VINE:4)
Block(2,9,-4,VINE:1)
Block(2,9,-3,LEAVES:3)
Block(2,9,-2,LEAVES:3)
Block(2,9,-1,LEAVES:3)
Block(2,9,0,LEAVES:3)
Block(2,9,1,LEAVES:3)
Block(2,9,2,VINE:4)
Block(2,13,1,LEAVES:3)
Block(2,14,-1,LEAVES:3)
Block(2,14,0,LEAVES:3)
Block(2,14,1,LEAVES:3)
Block(2,14,2,LEAVES:3)
Block(2,14,3,LEAVES:3)
Block(2,14,4,LEAVES:3)
Block(2,15,-5,LEAVES:3)
Block(2,15,-4,LEAVES:3)
Block(2,15,-3,LEAVES:3)
Block(2,15,-2,LEAVES:3)
Block(2,15,-1,LEAVES:3)
Block(2,15,0,LEAVES:3)
Block(2,15,1,LEAVES:3)
Block(2,15,2,LEAVES:3)
Block(2,15,3,LEAVES:3)
Block(2,15,4,LEAVES:3)
Block(2,15,5,LEAVES:3)
Block(2,16,-4,LEAVES:3)
Block(2,16,-3,LEAVES:3)
Block(2,16,-2,LEAVES:3)
Block(2,16,-1,LEAVES:3)
Block(2,16,0,LEAVES:3)
Block(2,16,1,LEAVES:3)
Block(2,16,2,LEAVES:3)
Block(2,16,3,LEAVES:3)
Block(2,16,4,LEAVES:3)
Block(2,17,-4,VINE:2)
Block(2,17,-3,VINE:2)
Block(2,17,-2,LEAVES:3)
Block(2,17,-1,LEAVES:3)
Block(2,17,0,LEAVES:3)
Block(2,17,1,LEAVES:3)
Block(2,17,2,VINE:7)
Block(2,17,3,LEAVES:3)
Block(2,18,0,LEAVES:3)
Block(3,5,-2,LEAVES:3)
Block(3,5,-1,LEAVES:3)
Block(3,5,0,LEAVES:3)
Block(3,6,-3,LEAVES:3)
Block(3,6,-2,LEAVES:3)
Block(3,6,-1,LEAVES:3)
Block(3,6,0,LEAVES:3)
Block(3,6,1,LEAVES:3)
Block(3,7,-4,LEAVES:3)
Block(3,7,-3,LEAVES:3)
Block(3,7,-2,LEAVES:3)
Block(3,7,-1,LEAVES:3)
Block(3,7,0,LEAVES:3)
Block(3,7,1,LEAVES:3)
Block(3,7,2,LEAVES:3)
Block(3,8,-3,LEAVES:3)
Block(3,8,-2,LEAVES:3)
Block(3,8,-1,LEAVES:3)
Block(3,8,0,LEAVES:3)
Block(3,8,1,LEAVES:3)
Block(3,9,-2,LEAVES:3)
Block(3,10,-2,VINE:1)
Block(3,11,-2,VINE:1)
Block(3,12,-2,VINE:1)
Block(3,13,-2,VINE:1)
Block(3,14,-2,VINE:1)
Block(3,14,1,LEAVES:3)
Block(3,14,2,LEAVES:3)
Block(3,14,3,LEAVES:3)
Block(3,15,-2,VINE:1)
Block(3,15,-1,LEAVES:3)
Block(3,15,0,LEAVES:3)
Block(3,15,1,LEAVES:3)
Block(3,15,2,LEAVES:3)
Block(3,15,3,LEAVES:3)
Block(3,15,4,LEAVES:3)
Block(3,16,-2,LEAVES:3)
Block(3,16,-1,LEAVES:3)
Block(3,16,0,LEAVES:3)
Block(3,16,1,LEAVES:3)
Block(3,16,2,LEAVES:3)
Block(3,16,3,LEAVES:3)
Block(3,17,-2,VINE:1)
Block(3,17,-1,LEAVES:3)
Block(3,17,0,VINE:2)
Block(3,17,1,VINE:2)
Block(3,18,0,VINE:2)
Block(4,5,-1,LEAVES:3)
Block(4,6,-2,LEAVES:3)
Block(4,6,-1,LEAVES:3)
Block(4,6,0,LEAVES:3)
Block(4,7,-3,LEAVES:3)
Block(4,7,-2,LEAVES:3)
Block(4,7,-1,LEAVES:3)
Block(4,7,0,LEAVES:3)
Block(4,7,1,LEAVES:3)
Block(4,8,-2,LEAVES:3)
Block(4,8,-1,LEAVES:3)
Block(4,8,0,LEAVES:3)
Block(4,9,-1,VINE:2)
Block(4,10,-1,VINE:2)
Block(4,11,-1,VINE:2)
Block(4,12,-1,VINE:2)
Block(4,13,-1,VINE:2)
Block(4,14,-1,VINE:2)
Block(4,14,2,LEAVES:3)
Block(4,15,-1,VINE:2)
Block(4,15,1,LEAVES:3)
Block(4,15,2,LEAVES:3)
Block(4,15,3,LEAVES:3)
Block(4,16,-1,LEAVES:3)
Block(4,16,0,LEAVES:3)
Block(5,6,-1,LEAVES:3)
Block(5,7,-2,LEAVES:3)
Block(5,7,-1,LEAVES:3)
Block(5,7,0,LEAVES:3)
Block(5,8,-1,LEAVES:3)
Block(5,15,2,LEAVES:3)
Block(6,7,-1,LEAVES:3)

#######################################################################
# +-----------------------------------------------------------------+ #
# |                            BO3 checks                           | #
# +-----------------------------------------------------------------+ #
#######################################################################

BlockCheck(0,-1,0,GRASS:0,DIRT:0)
BlockCheck(1,-1,0,GRASS:0,DIRT:0)
BlockCheck(0,-1,1,GRASS:0,DIRT:0)
BlockCheck(1,-1,1,GRASS:0,DIRT:0)

#######################################################################
# +-----------------------------------------------------------------+ #
# |                             Branches                            | #
# +-----------------------------------------------------------------+ #
#######################################################################


#######################################################################
# +-----------------------------------------------------------------+ #
# |                             Entities                            | #
# +-----------------------------------------------------------------+ #
#######################################################################


#######################################################################
# +-----------------------------------------------------------------+ #
# |                            Particles                            | #
# +-----------------------------------------------------------------+ #
#######################################################################


#######################################################################
# +-----------------------------------------------------------------+ #
# |                             Spawners                            | #
# +-----------------------------------------------------------------+ #
#######################################################################


#######################################################################
# +-----------------------------------------------------------------+ #
# |                             ModData                             | #
# +-----------------------------------------------------------------+ #
#######################################################################

