
#######################################################################
# +-----------------------------------------------------------------+ #
# |                            BO3 object                           | #
# +-----------------------------------------------------------------+ #
#######################################################################

Author: Unknown

Description: No description

Version: 3

SettingsMode: WriteWithoutComments


#######################################################################
# +-----------------------------------------------------------------+ #
# |                          Main settings                          | #
# +-----------------------------------------------------------------+ #
#######################################################################

Tree: false

Frequency: 1

Rarity: 33.0

RotateRandomly: true

SpawnHeight: highestBlock

SpawnHeightOffset: -7

SpawnHeightVariance: 0

##############################
# Height Limits for the BO3. #
##############################

MinHeight: 55

MaxHeight: 62

######################
# Extrusion settings #
######################

ExtrudeMode: None

ExtrudeThroughBlocks: AIR

MaxBranchDepth: 10

ExcludedBiomes: All


#######################################################################
# +-----------------------------------------------------------------+ #
# |                      Source block settings                      | #
# +-----------------------------------------------------------------+ #
#######################################################################

SourceBlocks: AIR

MaxPercentageOutsideSourceBlock: 100

OutsideSourceBlock: placeAnyway

IsOTGPlus: false

InheritBO3: 

InheritBO3Rotation: NORTH

OverrideChildSettings: true

OverrideParentHeight: false

CanOverride: false

BranchFrequency: 0

BranchFrequencyGroup: 

MustBeBelowOther: false

MustBeInside: 

CannotBeInside: 

ReplacesBO3: 

CanSpawnOnWater: true

SpawnOnWaterOnly: false

SpawnUnderWater: false

SpawnAtWaterLevel: false

HeightOffset: 0

RemoveAir: true

ReplaceAbove: 

ReplaceBelow: 

ReplaceWithBiomeBlocks: true

ReplaceWithGroundBlock: DIRT

ReplaceWithSurfaceBlock: GRASS

SmoothRadius: 0

SmoothHeightOffset: 0

SmoothStartTop: false

SmoothStartWood: false

SmoothingSurfaceBlock: 

SmoothingGroundBlock: 

BO3Group: 

IsSpawnPoint: false


#######################################################################
# +-----------------------------------------------------------------+ #
# |                              Blocks                             | #
# +-----------------------------------------------------------------+ #
#######################################################################

Block(-8,3,-2,PACKED_ICE)
Block(-8,4,-3,PACKED_ICE)
Block(-8,4,-2,PACKED_ICE)
Block(-7,2,-4,PACKED_ICE)
Block(-7,2,-3,PACKED_ICE)
Block(-7,2,-2,PACKED_ICE)
Block(-7,3,-5,PACKED_ICE)
Block(-7,3,-4,PACKED_ICE)
Block(-7,3,-3,PACKED_ICE)
Block(-7,3,-2,PACKED_ICE)
Block(-7,3,-1,PACKED_ICE)
Block(-7,4,-7,PACKED_ICE)
Block(-7,4,-5,PACKED_ICE)
Block(-7,4,-4,PACKED_ICE)
Block(-7,4,-3,PACKED_ICE)
Block(-7,4,-2,PACKED_ICE)
Block(-7,4,-1,PACKED_ICE)
Block(-7,5,-5,PACKED_ICE)
Block(-7,5,-4,PACKED_ICE)
Block(-7,5,-3,PACKED_ICE)
Block(-7,5,-2,PACKED_ICE)
Block(-7,5,-1,PACKED_ICE)
Block(-7,6,-4,PACKED_ICE)
Block(-7,6,-2,PACKED_ICE)
Block(-6,1,-1,PACKED_ICE)
Block(-6,2,-6,PACKED_ICE)
Block(-6,2,-5,PACKED_ICE)
Block(-6,2,-4,PACKED_ICE)
Block(-6,2,-3,PACKED_ICE)
Block(-6,2,-2,PACKED_ICE)
Block(-6,2,-1,PACKED_ICE)
Block(-6,3,-6,PACKED_ICE)
Block(-6,3,-5,PACKED_ICE)
Block(-6,3,-4,PACKED_ICE)
Block(-6,3,-3,PACKED_ICE)
Block(-6,3,-2,PACKED_ICE)
Block(-6,3,-1,PACKED_ICE)
Block(-6,3,0,PACKED_ICE)
Block(-6,4,-7,PACKED_ICE)
Block(-6,4,-6,PACKED_ICE)
Block(-6,4,-5,PACKED_ICE)
Block(-6,4,-4,PACKED_ICE)
Block(-6,4,-3,PACKED_ICE)
Block(-6,4,-2,PACKED_ICE)
Block(-6,4,-1,PACKED_ICE)
Block(-6,4,0,PACKED_ICE)
Block(-6,5,-6,PACKED_ICE)
Block(-6,5,-5,PACKED_ICE)
Block(-6,5,-4,PACKED_ICE)
Block(-6,5,-3,PACKED_ICE)
Block(-6,5,-2,PACKED_ICE)
Block(-6,5,-1,PACKED_ICE)
Block(-6,5,0,PACKED_ICE)
Block(-6,6,-6,PACKED_ICE)
Block(-6,6,-5,PACKED_ICE)
Block(-6,6,-4,PACKED_ICE)
Block(-6,6,-3,PACKED_ICE)
Block(-6,6,-2,PACKED_ICE)
Block(-6,6,-1,PACKED_ICE)
Block(-6,7,-1,PACKED_ICE)
Block(-5,0,-4,PACKED_ICE)
Block(-5,0,-1,PACKED_ICE)
Block(-5,1,-5,PACKED_ICE)
Block(-5,1,-4,PACKED_ICE)
Block(-5,1,-3,PACKED_ICE)
Block(-5,1,-2,PACKED_ICE)
Block(-5,1,-1,PACKED_ICE)
Block(-5,1,0,PACKED_ICE)
Block(-5,2,-7,PACKED_ICE)
Block(-5,2,-6,PACKED_ICE)
Block(-5,2,-5,PACKED_ICE)
Block(-5,2,-4,PACKED_ICE)
Block(-5,2,-3,PACKED_ICE)
Block(-5,2,-2,PACKED_ICE)
Block(-5,2,-1,PACKED_ICE)
Block(-5,2,0,PACKED_ICE)
Block(-5,3,-7,PACKED_ICE)
Block(-5,3,-6,PACKED_ICE)
Block(-5,3,-5,PACKED_ICE)
Block(-5,3,-4,PACKED_ICE)
Block(-5,3,-3,PACKED_ICE)
Block(-5,3,-2,PACKED_ICE)
Block(-5,3,-1,PACKED_ICE)
Block(-5,3,0,PACKED_ICE)
Block(-5,4,-7,PACKED_ICE)
Block(-5,4,-6,PACKED_ICE)
Block(-5,4,-5,PACKED_ICE)
Block(-5,4,-4,PACKED_ICE)
Block(-5,4,-3,PACKED_ICE)
Block(-5,4,-2,PACKED_ICE)
Block(-5,4,-1,PACKED_ICE)
Block(-5,4,0,PACKED_ICE)
Block(-5,5,-7,PACKED_ICE)
Block(-5,5,-6,PACKED_ICE)
Block(-5,5,-5,PACKED_ICE)
Block(-5,5,-4,PACKED_ICE)
Block(-5,5,-3,PACKED_ICE)
Block(-5,5,-2,PACKED_ICE)
Block(-5,5,-1,PACKED_ICE)
Block(-5,5,0,PACKED_ICE)
Block(-5,6,-7,PACKED_ICE)
Block(-5,6,-6,PACKED_ICE)
Block(-5,6,-5,PACKED_ICE)
Block(-5,6,-4,PACKED_ICE)
Block(-5,6,-3,PACKED_ICE)
Block(-5,6,-2,PACKED_ICE)
Block(-5,6,-1,PACKED_ICE)
Block(-5,6,0,PACKED_ICE)
Block(-5,7,-5,PACKED_ICE)
Block(-5,7,-4,PACKED_ICE)
Block(-5,7,-3,PACKED_ICE)
Block(-5,7,-2,PACKED_ICE)
Block(-5,7,-1,PACKED_ICE)
Block(-5,7,0,PACKED_ICE)
Block(-5,8,-4,PACKED_ICE)
Block(-5,8,-1,PACKED_ICE)
Block(-4,0,-5,PACKED_ICE)
Block(-4,0,-4,PACKED_ICE)
Block(-4,0,-3,PACKED_ICE)
Block(-4,0,-1,PACKED_ICE)
Block(-4,1,-6,PACKED_ICE)
Block(-4,1,-5,PACKED_ICE)
Block(-4,1,-4,PACKED_ICE)
Block(-4,1,-3,PACKED_ICE)
Block(-4,1,-2,PACKED_ICE)
Block(-4,1,-1,PACKED_ICE)
Block(-4,2,-6,PACKED_ICE)
Block(-4,2,-5,PACKED_ICE)
Block(-4,2,-4,PACKED_ICE)
Block(-4,2,-3,PACKED_ICE)
Block(-4,2,-2,PACKED_ICE)
Block(-4,2,-1,PACKED_ICE)
Block(-4,2,0,PACKED_ICE)
Block(-4,3,-6,PACKED_ICE)
Block(-4,3,-5,PACKED_ICE)
Block(-4,3,-4,PACKED_ICE)
Block(-4,3,-3,PACKED_ICE)
Block(-4,3,-2,PACKED_ICE)
Block(-4,3,-1,PACKED_ICE)
Block(-4,4,-7,PACKED_ICE)
Block(-4,4,-6,PACKED_ICE)
Block(-4,4,-5,PACKED_ICE)
Block(-4,4,-4,PACKED_ICE)
Block(-4,4,-3,PACKED_ICE)
Block(-4,4,-2,PACKED_ICE)
Block(-4,4,-1,PACKED_ICE)
Block(-4,5,-6,PACKED_ICE)
Block(-4,5,-5,PACKED_ICE)
Block(-4,5,-4,PACKED_ICE)
Block(-4,5,-3,PACKED_ICE)
Block(-4,5,-2,PACKED_ICE)
Block(-4,5,-1,PACKED_ICE)
Block(-4,5,0,PACKED_ICE)
Block(-4,6,-6,PACKED_ICE)
Block(-4,6,-5,PACKED_ICE)
Block(-4,6,-4,PACKED_ICE)
Block(-4,6,-3,PACKED_ICE)
Block(-4,6,-2,PACKED_ICE)
Block(-4,6,-1,PACKED_ICE)
Block(-4,6,0,PACKED_ICE)
Block(-4,7,-6,PACKED_ICE)
Block(-4,7,-5,PACKED_ICE)
Block(-4,7,-4,PACKED_ICE)
Block(-4,7,-3,PACKED_ICE)
Block(-4,7,-2,PACKED_ICE)
Block(-4,7,-1,PACKED_ICE)
Block(-4,8,-5,PACKED_ICE)
Block(-4,8,-4,PACKED_ICE)
Block(-4,8,-3,PACKED_ICE)
Block(-4,8,-1,PACKED_ICE)
Block(-3,0,-4,PACKED_ICE)
Block(-3,0,-3,PACKED_ICE)
Block(-3,0,-2,PACKED_ICE)
Block(-3,0,-1,PACKED_ICE)
Block(-3,1,-5,PACKED_ICE)
Block(-3,1,-4,PACKED_ICE)
Block(-3,1,-3,PACKED_ICE)
Block(-3,1,-2,PACKED_ICE)
Block(-3,1,-1,PACKED_ICE)
Block(-3,2,-5,PACKED_ICE)
Block(-3,2,-4,PACKED_ICE)
Block(-3,2,-3,PACKED_ICE)
Block(-3,2,-2,PACKED_ICE)
Block(-3,2,-1,PACKED_ICE)
Block(-3,3,-6,PACKED_ICE)
Block(-3,3,-5,PACKED_ICE)
Block(-3,3,-4,PACKED_ICE)
Block(-3,3,-3,PACKED_ICE)
Block(-3,3,-2,PACKED_ICE)
Block(-3,3,-1,PACKED_ICE)
Block(-3,4,-6,PACKED_ICE)
Block(-3,4,-5,PACKED_ICE)
Block(-3,4,-4,PACKED_ICE)
Block(-3,4,-3,PACKED_ICE)
Block(-3,4,-2,PACKED_ICE)
Block(-3,4,-1,PACKED_ICE)
Block(-3,5,-6,PACKED_ICE)
Block(-3,5,-5,PACKED_ICE)
Block(-3,5,-4,PACKED_ICE)
Block(-3,5,-3,PACKED_ICE)
Block(-3,5,-2,PACKED_ICE)
Block(-3,5,-1,PACKED_ICE)
Block(-3,6,-5,PACKED_ICE)
Block(-3,6,-4,PACKED_ICE)
Block(-3,6,-3,PACKED_ICE)
Block(-3,6,-2,PACKED_ICE)
Block(-3,6,-1,PACKED_ICE)
Block(-3,7,-5,PACKED_ICE)
Block(-3,7,-4,PACKED_ICE)
Block(-3,7,-3,PACKED_ICE)
Block(-3,7,-2,PACKED_ICE)
Block(-3,7,-1,PACKED_ICE)
Block(-3,8,-4,PACKED_ICE)
Block(-3,8,-3,PACKED_ICE)
Block(-3,8,-2,PACKED_ICE)
Block(-3,9,-3,PACKED_ICE)
Block(-2,0,-4,PACKED_ICE)
Block(-2,0,-3,PACKED_ICE)
Block(-2,0,-2,PACKED_ICE)
Block(-2,1,-5,PACKED_ICE)
Block(-2,1,-4,PACKED_ICE)
Block(-2,1,-3,PACKED_ICE)
Block(-2,1,-2,PACKED_ICE)
Block(-2,1,-1,PACKED_ICE)
Block(-2,2,-6,PACKED_ICE)
Block(-2,2,-5,PACKED_ICE)
Block(-2,2,-4,PACKED_ICE)
Block(-2,2,-3,PACKED_ICE)
Block(-2,2,-2,PACKED_ICE)
Block(-2,2,-1,PACKED_ICE)
Block(-2,2,0,PACKED_ICE)
Block(-2,3,-5,PACKED_ICE)
Block(-2,3,-4,PACKED_ICE)
Block(-2,3,-3,PACKED_ICE)
Block(-2,3,-2,PACKED_ICE)
Block(-2,3,-1,PACKED_ICE)
Block(-2,3,0,PACKED_ICE)
Block(-2,4,-5,PACKED_ICE)
Block(-2,4,-4,PACKED_ICE)
Block(-2,4,-3,PACKED_ICE)
Block(-2,4,-2,PACKED_ICE)
Block(-2,4,-1,PACKED_ICE)
Block(-2,4,0,PACKED_ICE)
Block(-2,5,-6,PACKED_ICE)
Block(-2,5,-5,PACKED_ICE)
Block(-2,5,-4,PACKED_ICE)
Block(-2,5,-3,PACKED_ICE)
Block(-2,5,-2,PACKED_ICE)
Block(-2,5,-1,PACKED_ICE)
Block(-2,6,-6,PACKED_ICE)
Block(-2,6,-5,PACKED_ICE)
Block(-2,6,-4,PACKED_ICE)
Block(-2,6,-3,PACKED_ICE)
Block(-2,6,-2,PACKED_ICE)
Block(-2,6,-1,PACKED_ICE)
Block(-2,7,-5,PACKED_ICE)
Block(-2,7,-4,PACKED_ICE)
Block(-2,7,-3,PACKED_ICE)
Block(-2,7,-2,PACKED_ICE)
Block(-2,8,-4,PACKED_ICE)
Block(-2,8,-3,PACKED_ICE)
Block(-2,8,-2,PACKED_ICE)
Block(-2,9,-3,PACKED_ICE)
Block(-1,1,-4,PACKED_ICE)
Block(-1,1,-3,PACKED_ICE)
Block(-1,2,-5,PACKED_ICE)
Block(-1,2,-4,PACKED_ICE)
Block(-1,2,-3,PACKED_ICE)
Block(-1,2,-2,PACKED_ICE)
Block(-1,2,-1,PACKED_ICE)
Block(-1,3,-5,PACKED_ICE)
Block(-1,3,-4,PACKED_ICE)
Block(-1,3,-3,PACKED_ICE)
Block(-1,3,-2,PACKED_ICE)
Block(-1,3,-1,PACKED_ICE)
Block(-1,3,0,PACKED_ICE)
Block(-1,4,-4,PACKED_ICE)
Block(-1,4,-3,PACKED_ICE)
Block(-1,4,-2,PACKED_ICE)
Block(-1,4,-1,PACKED_ICE)
Block(-1,4,0,PACKED_ICE)
Block(-1,5,-5,PACKED_ICE)
Block(-1,5,-4,PACKED_ICE)
Block(-1,5,-3,PACKED_ICE)
Block(-1,5,-2,PACKED_ICE)
Block(-1,5,-1,PACKED_ICE)
Block(-1,5,0,PACKED_ICE)
Block(-1,6,-5,PACKED_ICE)
Block(-1,6,-4,PACKED_ICE)
Block(-1,6,-3,PACKED_ICE)
Block(-1,6,-2,PACKED_ICE)
Block(-1,6,-1,PACKED_ICE)
Block(-1,7,-4,PACKED_ICE)
Block(-1,7,-3,PACKED_ICE)
Block(0,3,-1,PACKED_ICE)
Block(0,4,-3,PACKED_ICE)
Block(0,4,-2,PACKED_ICE)
Block(0,4,-1,PACKED_ICE)
Block(0,5,-3,PACKED_ICE)
Block(0,5,-2,PACKED_ICE)
Block(0,5,-1,PACKED_ICE)

#######################################################################
# +-----------------------------------------------------------------+ #
# |                            BO3 checks                           | #
# +-----------------------------------------------------------------+ #
#######################################################################


#######################################################################
# +-----------------------------------------------------------------+ #
# |                             Branches                            | #
# +-----------------------------------------------------------------+ #
#######################################################################


#######################################################################
# +-----------------------------------------------------------------+ #
# |                             Entities                            | #
# +-----------------------------------------------------------------+ #
#######################################################################


#######################################################################
# +-----------------------------------------------------------------+ #
# |                            Particles                            | #
# +-----------------------------------------------------------------+ #
#######################################################################


#######################################################################
# +-----------------------------------------------------------------+ #
# |                             Spawners                            | #
# +-----------------------------------------------------------------+ #
#######################################################################


#######################################################################
# +-----------------------------------------------------------------+ #
# |                             ModData                             | #
# +-----------------------------------------------------------------+ #
#######################################################################

