#######################################################################
# +-----------------------------------------------------------------+ #
# |                            BO3 object                           | #
# +-----------------------------------------------------------------+ #
#######################################################################

# The descriptions in this file are accurate only for TerrainControl and OTG.
# For MCW and OTG+ these descriptions are only accurate if the BO3 is used as a CustomObject.
# MCW and OTG+ completely reimplemented CustomStructure, check the MCW/OTG+ documentation for more information.

# This is the config file of a custom object.
# If you add this object correctly to your BiomeConfigs, it will spawn in the world.

# This is the creator of this BO3 object
Author: Unknown

# A short description of this BO3 object
Description: This BO3 was converted from a schematic using OTGEdit. The author and description information of the schematic could not be found. If you know who the author of the schematic is then please add this information.

# The BO3 version, don't change this! It can be used by external applications to do a version check.
Version: 3

# The settings mode, WriteAll, WriteWithoutComments or WriteDisable. See WorldConfig.
SettingsMode: WriteDisable

#######################################################################
# +-----------------------------------------------------------------+ #
# |                          Main settings                          | #
# +-----------------------------------------------------------------+ #
#######################################################################

# This needs to be set to true to spawn the object in the Tree and Sapling resources.
Tree: false

# The frequency of the BO3 from 1 to 200. Tries this many times to spawn this BO3 when using the CustomObject(...) resource.
# Ignored by Tree(..), Sapling(..) and CustomStructure(..)
Frequency: 40

# The rarity of the BO3 from 0 to 100. Each spawn attempt has rarity% chance to succeed when using the CustomObject(...) resource.
# Ignored by Tree(..), Sapling(..) and CustomStructure(..)
Rarity: 100.0

# If you set this to true, the BO3 will be placed with a random rotation.
RotateRandomly: true

# The spawn height of the BO3 - randomY, highestBlock or highestSolidBlock.
SpawnHeight: highestSolidBlock

SpawnHeightOffset: -2

# The height limits for the BO3.
MinHeight: 62

MaxHeight: 110

# Objects can have other objects attached to it: branches. Branches can also
# have branches attached to it, which can also have branches, etc. This is the
# maximum branch depth for this objects.
MaxBranchDepth: 10

# When spawned with the UseWorld keyword, this BO3 should NOT spawn in the following biomes.
# If you writer.write the BO3 name directly in the BiomeConfigs, this will be ignored.
ExcludedBiomes: All

# To optimise this BO3 for faster loading times you can use Notepad++ to find/replace comments and abbreviate things.
# Notepad++ find/replace with regex:
# Find: ^[#;].* replace to nothing removes all lines starting with # 
# Find: ^\s*$ replace to nothing removes most empty lines 
# Notepad++ find/replace without regex:
# *Warning: This will only work for OTG 1.10.2 v21 / OTG 1.11.2 v6 or higher. B( is not recognised by lower versions.
# Find: Block( replace to B(

#######################################################################
# +-----------------------------------------------------------------+ #
# |                      Source block settings                      | #
# +-----------------------------------------------------------------+ #
#######################################################################

# The block(s) the BO3 should spawn in.
SourceBlocks: STONE:1,STONE:3,STONE:5,DIRT:1,DIRT,GRASS,DIRT:2,STATIONARY_WATER,HARD_CLAY,STAINED_CLAY,CLAY,SANDSTONE,SAND:1,AIR,STONE,GRAVEL,LONG_GRASS,LONG_GRASS:1,LONG_GRASS:2,DEAD_BUSH,YELLOW_FLOWER,RED_ROSE,BROWN_MUSHROOM,RED_MUSHROOM

# The maximum percentage of the BO3 that can be outside the SourceBlock.
# The BO3 won't be placed on a location with more blocks outside the SourceBlock than this percentage.
MaxPercentageOutsideSourceBlock: 0

# What to do when a block is about to be placed outside the SourceBlock? (dontPlace, placeAnyway)
OutsideSourceBlock: placeAnyway

#######################################################################
# +-----------------------------------------------------------------+ #
# |                              Blocks                             | #
# +-----------------------------------------------------------------+ #
#######################################################################

# All the blocks used in the BO3 are listed here. Possible blocks:
# Block(x,y,z,id[.data][,nbtfile.nbt) or B(x,y,z,id[.data][,nbtfile.nbt)
# RandomBlock(x,y,z,id[:data][,nbtfile.nbt],chance[,id[:data][,nbtfile.nbt],chance[,...]])
# So RandomBlock(0,0,0,CHEST,chest.nbt,50,CHEST,anotherchest.nbt,100) will spawn a chest at
# the BO3 origin, and give it a 50% chance to have the contents of chest.nbt, or, if that
# fails, a 100% percent chance to have the contents of anotherchest.nbt.

Block(-9,16,-3,LEAVES:0)
Block(-8,8,3,LEAVES:0)
Block(-8,9,0,LEAVES:0)
Block(-8,9,2,LEAVES:0)
Block(-8,10,-1,LEAVES:0)
Block(-8,15,-4,LEAVES:0)
Block(-8,16,-5,LEAVES:0)
Block(-8,16,-4,LEAVES:0)
Block(-8,16,-3,LEAVES:0)
Block(-8,16,-2,LEAVES:0)
Block(-8,17,-3,LEAVES:0)
Block(-8,17,0,LEAVES:0)
Block(-7,6,1,LEAVES:0)
Block(-7,6,5,LEAVES:0)
Block(-7,7,2,LEAVES:0)
Block(-7,7,4,LEAVES:0)
Block(-7,8,2,LEAVES:0)
Block(-7,8,3,LEAVES:0)
Block(-7,8,4,LEAVES:0)
Block(-7,9,-1,LEAVES:0)
Block(-7,9,0,LEAVES:0)
Block(-7,9,1,LEAVES:0)
Block(-7,9,2,LEAVES:0)
Block(-7,9,3,LEAVES:0)
Block(-7,10,-2,LEAVES:0)
Block(-7,10,-1,LEAVES:0)
Block(-7,10,0,LEAVES:0)
Block(-7,10,2,LEAVES:0)
Block(-7,10,4,LEAVES:0)
Block(-7,11,-1,LEAVES:0)
Block(-7,11,3,LEAVES:0)
Block(-7,12,4,LEAVES:0)
Block(-7,15,-5,LEAVES:0)
Block(-7,15,-4,LEAVES:0)
Block(-7,15,-3,LEAVES:0)
Block(-7,16,-6,LEAVES:0)
Block(-7,16,-5,LEAVES:0)
Block(-7,16,-4,LEAVES:0)
Block(-7,16,-3,LEAVES:0)
Block(-7,17,-6,LEAVES:0)
Block(-7,17,-5,LEAVES:0)
Block(-7,17,-4,LEAVES:0)
Block(-7,17,-3,LEAVES:0)
Block(-7,17,-2,LEAVES:0)
Block(-7,17,-1,LEAVES:0)
Block(-7,17,0,LEAVES:0)
Block(-7,17,1,LEAVES:0)
Block(-7,18,-7,LEAVES:0)
Block(-7,18,-3,LEAVES:0)
Block(-7,18,0,LEAVES:0)
Block(-7,19,-4,LEAVES:0)
Block(-7,20,-5,LEAVES:0)
Block(-7,20,0,LEAVES:0)
Block(-7,21,-2,LEAVES:0)
Block(-7,21,-1,LEAVES:0)
Block(-7,22,-1,LEAVES:0)
Block(-7,22,2,LEAVES:0)
Block(-7,23,1,LEAVES:0)
Block(-6,6,0,LEAVES:0)
Block(-6,6,1,LEAVES:0)
Block(-6,6,2,LEAVES:0)
Block(-6,6,4,LEAVES:0)
Block(-6,6,5,LEAVES:0)
Block(-6,6,6,LEAVES:0)
Block(-6,7,1,LEAVES:0)
Block(-6,7,2,LEAVES:0)
Block(-6,7,3,LEAVES:0)
Block(-6,7,4,LEAVES:0)
Block(-6,7,5,LEAVES:0)
Block(-6,8,2,LEAVES:0)
Block(-6,8,3,LEAVES:0)
Block(-6,8,4,LEAVES:0)
Block(-6,9,-2,LEAVES:0)
Block(-6,9,-1,LEAVES:0)
Block(-6,9,0,LEAVES:0)
Block(-6,9,2,LEAVES:0)
Block(-6,9,3,LEAVES:0)
Block(-6,9,4,LEAVES:0)
Block(-6,10,-1,LEAVES:0)
Block(-6,10,2,17:12)
Block(-6,10,3,LEAVES:0)
Block(-6,10,4,LEAVES:0)
Block(-6,10,5,LEAVES:0)
Block(-6,11,-9,LEAVES:0)
Block(-6,11,2,LEAVES:0)
Block(-6,11,3,LEAVES:0)
Block(-6,11,4,LEAVES:0)
Block(-6,12,-10,LEAVES:0)
Block(-6,12,3,LEAVES:0)
Block(-6,12,4,LEAVES:0)
Block(-6,12,5,LEAVES:0)
Block(-6,13,4,LEAVES:0)
Block(-6,14,-11,LEAVES:0)
Block(-6,14,-9,LEAVES:0)
Block(-6,15,-12,LEAVES:0)
Block(-6,15,-8,LEAVES:0)
Block(-6,15,-5,LEAVES:0)
Block(-6,15,-4,LEAVES:0)
Block(-6,16,-5,LEAVES:0)
Block(-6,16,-4,LEAVES:0)
Block(-6,16,-3,LEAVES:0)
Block(-6,17,-7,LEAVES:0)
Block(-6,17,-6,LEAVES:0)
Block(-6,17,-5,LEAVES:0)
Block(-6,17,-4,LEAVES:0)
Block(-6,17,-3,LEAVES:0)
Block(-6,17,-2,17:12)
Block(-6,17,-1,LEAVES:0)
Block(-6,17,0,LEAVES:0)
Block(-6,18,-8,LEAVES:0)
Block(-6,18,-7,LEAVES:0)
Block(-6,18,-6,LEAVES:0)
Block(-6,18,-2,17:12)
Block(-6,18,-1,LEAVES:0)
Block(-6,18,0,LEAVES:0)
Block(-6,18,1,LEAVES:0)
Block(-6,19,-7,LEAVES:0)
Block(-6,19,-5,LEAVES:0)
Block(-6,19,-4,LEAVES:0)
Block(-6,19,-3,LEAVES:0)
Block(-6,19,-1,LEAVES:0)
Block(-6,19,0,LEAVES:0)
Block(-6,20,-6,LEAVES:0)
Block(-6,20,-5,LEAVES:0)
Block(-6,20,-4,LEAVES:0)
Block(-6,20,-1,LEAVES:0)
Block(-6,20,0,LEAVES:0)
Block(-6,20,1,LEAVES:0)
Block(-6,21,-5,LEAVES:0)
Block(-6,21,-3,LEAVES:0)
Block(-6,21,-2,LEAVES:0)
Block(-6,21,-1,LEAVES:0)
Block(-6,21,0,LEAVES:0)
Block(-6,22,-2,LEAVES:0)
Block(-6,22,-1,LEAVES:0)
Block(-6,22,0,LEAVES:0)
Block(-6,22,1,LEAVES:0)
Block(-6,22,2,LEAVES:0)
Block(-6,22,3,LEAVES:0)
Block(-6,23,-1,LEAVES:0)
Block(-6,23,0,LEAVES:0)
Block(-6,23,1,LEAVES:0)
Block(-6,23,2,LEAVES:0)
Block(-6,24,1,LEAVES:0)
Block(-6,24,3,LEAVES:0)
Block(-6,25,-1,LEAVES:0)
Block(-6,25,2,LEAVES:0)
Block(-6,26,0,LEAVES:0)
Block(-6,27,2,LEAVES:0)
Block(-6,28,3,LEAVES:0)
Block(-5,6,1,LEAVES:0)
Block(-5,6,2,LEAVES:0)
Block(-5,6,3,LEAVES:0)
Block(-5,6,4,LEAVES:0)
Block(-5,6,5,LEAVES:0)
Block(-5,7,2,LEAVES:0)
Block(-5,7,3,LEAVES:0)
Block(-5,7,4,LEAVES:0)
Block(-5,8,2,LEAVES:0)
Block(-5,9,-1,LEAVES:0)
Block(-5,9,2,17:12)
Block(-5,9,3,LEAVES:0)
Block(-5,10,1,LEAVES:0)
Block(-5,10,2,17:12)
Block(-5,10,3,LEAVES:0)
Block(-5,10,4,LEAVES:0)
Block(-5,11,-10,LEAVES:0)
Block(-5,11,-9,LEAVES:0)
Block(-5,11,-8,LEAVES:0)
Block(-5,11,3,LEAVES:0)
Block(-5,12,-11,LEAVES:0)
Block(-5,12,-10,LEAVES:0)
Block(-5,12,-9,LEAVES:0)
Block(-5,12,2,LEAVES:0)
Block(-5,12,3,LEAVES:0)
Block(-5,12,4,LEAVES:0)
Block(-5,13,-10,LEAVES:0)
Block(-5,13,3,LEAVES:0)
Block(-5,14,-12,LEAVES:0)
Block(-5,14,-11,LEAVES:0)
Block(-5,14,-10,LEAVES:0)
Block(-5,14,-9,LEAVES:0)
Block(-5,14,-8,LEAVES:0)
Block(-5,15,-13,LEAVES:0)
Block(-5,15,-12,LEAVES:0)
Block(-5,15,-11,LEAVES:0)
Block(-5,15,-9,LEAVES:0)
Block(-5,15,-8,LEAVES:0)
Block(-5,15,-7,LEAVES:0)
Block(-5,15,-6,LEAVES:0)
Block(-5,15,-5,LEAVES:0)
Block(-5,15,-4,LEAVES:0)
Block(-5,16,-12,LEAVES:0)
Block(-5,16,-8,LEAVES:0)
Block(-5,16,-6,LEAVES:0)
Block(-5,16,-5,17:12)
Block(-5,16,-4,LEAVES:0)
Block(-5,16,-3,17:12)
Block(-5,17,-8,LEAVES:0)
Block(-5,17,-7,LEAVES:0)
Block(-5,17,-6,LEAVES:0)
Block(-5,17,-3,LEAVES:0)
Block(-5,17,-1,LEAVES:0)
Block(-5,18,-9,LEAVES:0)
Block(-5,18,-8,LEAVES:0)
Block(-5,18,-7,LEAVES:0)
Block(-5,18,-3,LEAVES:0)
Block(-5,18,-2,LEAVES:0)
Block(-5,18,-1,LEAVES:0)
Block(-5,18,0,LEAVES:0)
Block(-5,19,-8,LEAVES:0)
Block(-5,19,-7,LEAVES:0)
Block(-5,19,-6,LEAVES:0)
Block(-5,19,-5,LEAVES:0)
Block(-5,19,-4,LEAVES:0)
Block(-5,19,-2,LEAVES:0)
Block(-5,19,-1,LEAVES:0)
Block(-5,19,0,LEAVES:0)
Block(-5,20,-7,LEAVES:0)
Block(-5,20,-5,LEAVES:0)
Block(-5,20,-4,LEAVES:0)
Block(-5,20,-3,LEAVES:0)
Block(-5,20,-1,LEAVES:0)
Block(-5,20,0,LEAVES:0)
Block(-5,21,-4,LEAVES:0)
Block(-5,21,-2,LEAVES:0)
Block(-5,21,-1,LEAVES:0)
Block(-5,21,0,LEAVES:0)
Block(-5,21,1,LEAVES:0)
Block(-5,22,-3,LEAVES:0)
Block(-5,22,-2,LEAVES:0)
Block(-5,22,-1,LEAVES:0)
Block(-5,22,0,LEAVES:0)
Block(-5,22,2,LEAVES:0)
Block(-5,23,-8,LEAVES:0)
Block(-5,23,-2,LEAVES:0)
Block(-5,23,1,LEAVES:0)
Block(-5,23,2,LEAVES:0)
Block(-5,23,3,LEAVES:0)
Block(-5,24,2,LEAVES:0)
Block(-5,24,3,LEAVES:0)
Block(-5,24,4,LEAVES:0)
Block(-5,25,-7,LEAVES:0)
Block(-5,25,-2,LEAVES:0)
Block(-5,25,-1,LEAVES:0)
Block(-5,25,0,LEAVES:0)
Block(-5,25,1,LEAVES:0)
Block(-5,25,2,LEAVES:0)
Block(-5,25,3,LEAVES:0)
Block(-5,26,-1,LEAVES:0)
Block(-5,26,0,LEAVES:0)
Block(-5,26,1,LEAVES:0)
Block(-5,26,2,LEAVES:0)
Block(-5,27,0,LEAVES:0)
Block(-5,27,1,LEAVES:0)
Block(-5,27,2,LEAVES:0)
Block(-5,27,3,LEAVES:0)
Block(-5,28,-4,LEAVES:0)
Block(-5,28,2,LEAVES:0)
Block(-5,28,3,LEAVES:0)
Block(-5,28,4,LEAVES:0)
Block(-5,29,3,LEAVES:0)
Block(-4,0,-4,17:12)
Block(-4,6,2,LEAVES:0)
Block(-4,6,3,LEAVES:0)
Block(-4,6,4,LEAVES:0)
Block(-4,7,3,LEAVES:0)
Block(-4,7,4,LEAVES:0)
Block(-4,7,5,LEAVES:0)
Block(-4,8,2,LEAVES:0)
Block(-4,8,3,17:12)
Block(-4,8,4,LEAVES:0)
Block(-4,8,5,17:12)
Block(-4,9,2,17:12)
Block(-4,9,3,17:12)
Block(-4,9,4,LEAVES:0)
Block(-4,9,6,LEAVES:0)
Block(-4,10,2,LEAVES:0)
Block(-4,10,3,LEAVES:0)
Block(-4,10,5,LEAVES:0)
Block(-4,11,-11,LEAVES:0)
Block(-4,11,-10,LEAVES:0)
Block(-4,11,-9,LEAVES:0)
Block(-4,11,5,LEAVES:0)
Block(-4,12,-11,LEAVES:0)
Block(-4,12,-10,LEAVES:0)
Block(-4,12,-9,17:12)
Block(-4,12,1,LEAVES:0)
Block(-4,12,3,LEAVES:0)
Block(-4,13,-9,17:12)
Block(-4,13,-8,17:12)
Block(-4,14,-11,LEAVES:0)
Block(-4,14,-10,LEAVES:0)
Block(-4,14,-9,LEAVES:0)
Block(-4,14,-4,LEAVES:0)
Block(-4,15,-12,LEAVES:0)
Block(-4,15,-11,LEAVES:0)
Block(-4,15,-10,LEAVES:0)
Block(-4,15,-9,LEAVES:0)
Block(-4,15,-8,LEAVES:0)
Block(-4,15,-7,LEAVES:0)
Block(-4,15,-6,LEAVES:0)
Block(-4,15,-5,LEAVES:0)
Block(-4,15,-4,LEAVES:0)
Block(-4,15,-3,LEAVES:0)
Block(-4,16,-11,LEAVES:0)
Block(-4,16,-9,LEAVES:0)
Block(-4,16,-8,LEAVES:0)
Block(-4,16,-7,LEAVES:0)
Block(-4,16,-6,LEAVES:0)
Block(-4,16,-5,17:12)
Block(-4,16,-4,17:12)
Block(-4,16,-3,17:12)
Block(-4,16,-1,LEAVES:0)
Block(-4,17,-8,LEAVES:0)
Block(-4,17,-7,LEAVES:0)
Block(-4,17,-6,LEAVES:0)
Block(-4,17,-5,17:12)
Block(-4,17,-4,LEAVES:0)
Block(-4,17,-3,LEAVES:0)
Block(-4,17,-2,LEAVES:0)
Block(-4,17,-1,LEAVES:0)
Block(-4,17,0,LEAVES:0)
Block(-4,17,4,LEAVES:0)
Block(-4,18,-8,LEAVES:0)
Block(-4,18,-7,17:12)
Block(-4,18,-6,17:12)
Block(-4,18,-5,LEAVES:0)
Block(-4,18,-4,LEAVES:0)
Block(-4,18,-3,LEAVES:0)
Block(-4,18,-2,LEAVES:0)
Block(-4,18,-1,LEAVES:0)
Block(-4,18,0,LEAVES:0)
Block(-4,18,3,LEAVES:0)
Block(-4,19,-7,LEAVES:0)
Block(-4,19,-6,LEAVES:0)
Block(-4,19,-5,LEAVES:0)
Block(-4,19,-4,LEAVES:0)
Block(-4,19,-1,LEAVES:0)
Block(-4,19,0,LEAVES:0)
Block(-4,19,1,LEAVES:0)
Block(-4,20,-5,LEAVES:0)
Block(-4,20,-4,LEAVES:0)
Block(-4,20,-3,LEAVES:0)
Block(-4,20,-1,17:12)
Block(-4,20,0,LEAVES:0)
Block(-4,20,3,LEAVES:0)
Block(-4,21,0,LEAVES:0)
Block(-4,21,1,17:12)
Block(-4,22,-2,LEAVES:0)
Block(-4,23,-9,LEAVES:0)
Block(-4,23,-8,LEAVES:0)
Block(-4,23,-7,LEAVES:0)
Block(-4,23,0,LEAVES:0)
Block(-4,23,2,LEAVES:0)
Block(-4,24,-8,LEAVES:0)
Block(-4,24,3,LEAVES:0)
Block(-4,25,-8,LEAVES:0)
Block(-4,25,-7,LEAVES:0)
Block(-4,25,-6,LEAVES:0)
Block(-4,25,-1,LEAVES:0)
Block(-4,25,2,LEAVES:0)
Block(-4,25,3,LEAVES:0)
Block(-4,25,4,LEAVES:0)
Block(-4,26,-7,LEAVES:0)
Block(-4,26,-2,LEAVES:0)
Block(-4,26,-1,LEAVES:0)
Block(-4,26,0,LEAVES:0)
Block(-4,26,2,17:12)
Block(-4,26,3,LEAVES:0)
Block(-4,27,-4,LEAVES:0)
Block(-4,27,-1,LEAVES:0)
Block(-4,27,0,LEAVES:0)
Block(-4,27,2,LEAVES:0)
Block(-4,27,3,LEAVES:0)
Block(-4,27,4,LEAVES:0)
Block(-4,28,-5,LEAVES:0)
Block(-4,28,-4,LEAVES:0)
Block(-4,28,-3,LEAVES:0)
Block(-4,28,3,LEAVES:0)
Block(-4,29,-4,LEAVES:0)
Block(-3,0,-3,17:12)
Block(-3,0,-1,17:12)
Block(-3,6,2,LEAVES:0)
Block(-3,6,3,LEAVES:0)
Block(-3,6,4,LEAVES:0)
Block(-3,7,3,LEAVES:0)
Block(-3,7,4,LEAVES:0)
Block(-3,8,1,LEAVES:0)
Block(-3,8,2,LEAVES:0)
Block(-3,8,3,LEAVES:0)
Block(-3,8,4,LEAVES:0)
Block(-3,8,5,LEAVES:0)
Block(-3,9,1,17:12)
Block(-3,9,2,17:12)
Block(-3,9,3,LEAVES:0)
Block(-3,9,4,LEAVES:0)
Block(-3,9,5,LEAVES:0)
Block(-3,9,6,LEAVES:0)
Block(-3,9,7,LEAVES:0)
Block(-3,10,4,LEAVES:0)
Block(-3,10,5,LEAVES:0)
Block(-3,10,6,LEAVES:0)
Block(-3,11,-10,LEAVES:0)
Block(-3,11,-8,LEAVES:0)
Block(-3,11,1,LEAVES:0)
Block(-3,11,4,LEAVES:0)
Block(-3,11,5,LEAVES:0)
Block(-3,11,6,LEAVES:0)
Block(-3,12,-12,LEAVES:0)
Block(-3,12,-11,LEAVES:0)
Block(-3,12,-10,LEAVES:0)
Block(-3,12,0,LEAVES:0)
Block(-3,12,1,LEAVES:0)
Block(-3,12,2,LEAVES:0)
Block(-3,12,3,LEAVES:0)
Block(-3,12,4,LEAVES:0)
Block(-3,12,5,LEAVES:0)
Block(-3,13,-11,LEAVES:0)
Block(-3,13,-8,17:12)
Block(-3,13,1,LEAVES:0)
Block(-3,13,3,LEAVES:0)
Block(-3,14,-11,LEAVES:0)
Block(-3,14,-10,17:12)
Block(-3,14,-5,LEAVES:0)
Block(-3,14,-4,LEAVES:0)
Block(-3,14,-3,LEAVES:0)
Block(-3,15,-11,LEAVES:0)
Block(-3,15,-10,LEAVES:0)
Block(-3,15,-9,LEAVES:0)
Block(-3,15,-8,LEAVES:0)
Block(-3,15,-7,LEAVES:0)
Block(-3,15,-6,LEAVES:0)
Block(-3,15,-5,LEAVES:0)
Block(-3,15,-4,LEAVES:0)
Block(-3,16,-8,LEAVES:0)
Block(-3,16,-7,LEAVES:0)
Block(-3,16,-6,LEAVES:0)
Block(-3,16,-5,LEAVES:0)
Block(-3,16,-4,17:12)
Block(-3,16,-2,LEAVES:0)
Block(-3,16,-1,LEAVES:0)
Block(-3,16,0,LEAVES:0)
Block(-3,17,-7,LEAVES:0)
Block(-3,17,-5,LEAVES:0)
Block(-3,17,-4,17:12)
Block(-3,17,-3,LEAVES:0)
Block(-3,17,-2,LEAVES:0)
Block(-3,17,-1,LEAVES:0)
Block(-3,17,1,LEAVES:0)
Block(-3,17,3,LEAVES:0)
Block(-3,17,4,LEAVES:0)
Block(-3,17,5,LEAVES:0)
Block(-3,18,-6,LEAVES:0)
Block(-3,18,-5,LEAVES:0)
Block(-3,18,-4,LEAVES:0)
Block(-3,18,-3,LEAVES:0)
Block(-3,18,-2,LEAVES:0)
Block(-3,18,-1,LEAVES:0)
Block(-3,18,2,LEAVES:0)
Block(-3,18,3,LEAVES:0)
Block(-3,18,4,LEAVES:0)
Block(-3,19,-5,LEAVES:0)
Block(-3,19,-4,LEAVES:0)
Block(-3,19,-3,LEAVES:0)
Block(-3,19,0,LEAVES:0)
Block(-3,19,3,LEAVES:0)
Block(-3,20,-4,LEAVES:0)
Block(-3,20,-3,LEAVES:0)
Block(-3,20,-2,LEAVES:0)
Block(-3,20,0,LEAVES:0)
Block(-3,20,2,LEAVES:0)
Block(-3,20,3,LEAVES:0)
Block(-3,20,4,LEAVES:0)
Block(-3,21,-3,LEAVES:0)
Block(-3,21,-1,17:12)
Block(-3,21,0,17:12)
Block(-3,21,1,17:12)
Block(-3,21,2,LEAVES:0)
Block(-3,21,3,LEAVES:0)
Block(-3,22,-8,LEAVES:0)
Block(-3,22,0,LEAVES:0)
Block(-3,22,1,17:12)
Block(-3,23,-8,LEAVES:0)
Block(-3,23,-7,LEAVES:0)
Block(-3,23,-6,LEAVES:0)
Block(-3,23,-4,LEAVES:0)
Block(-3,23,-1,LEAVES:0)
Block(-3,23,0,LEAVES:0)
Block(-3,23,1,LEAVES:0)
Block(-3,24,-9,LEAVES:0)
Block(-3,24,-8,LEAVES:0)
Block(-3,24,-7,LEAVES:0)
Block(-3,24,-5,LEAVES:0)
Block(-3,24,-1,LEAVES:0)
Block(-3,24,0,17:12)
Block(-3,24,1,17:12)
Block(-3,25,-8,LEAVES:0)
Block(-3,25,-7,LEAVES:0)
Block(-3,25,-6,LEAVES:0)
Block(-3,25,-5,LEAVES:0)
Block(-3,25,-4,LEAVES:0)
Block(-3,25,0,17:12)
Block(-3,25,3,LEAVES:0)
Block(-3,26,-8,LEAVES:0)
Block(-3,26,-7,LEAVES:0)
Block(-3,26,-6,LEAVES:0)
Block(-3,26,-4,LEAVES:0)
Block(-3,26,-1,LEAVES:0)
Block(-3,26,3,LEAVES:0)
Block(-3,27,-8,LEAVES:0)
Block(-3,27,-7,LEAVES:0)
Block(-3,27,-6,LEAVES:0)
Block(-3,27,-5,LEAVES:0)
Block(-3,27,-4,LEAVES:0)
Block(-3,27,-3,LEAVES:0)
Block(-3,27,-1,LEAVES:0)
Block(-3,27,0,LEAVES:0)
Block(-3,27,1,LEAVES:0)
Block(-3,27,2,LEAVES:0)
Block(-3,27,3,LEAVES:0)
Block(-3,28,-11,LEAVES:0)
Block(-3,28,-7,LEAVES:0)
Block(-3,28,-6,LEAVES:0)
Block(-3,28,-5,LEAVES:0)
Block(-3,28,-4,LEAVES:0)
Block(-3,28,0,LEAVES:0)
Block(-3,29,-5,LEAVES:0)
Block(-2,0,-3,17:12)
Block(-2,0,-2,17:12)
Block(-2,0,-1,17:12)
Block(-2,0,0,17:12)
Block(-2,0,2,17)
Block(-2,0,3,17:12)
Block(-2,1,-1,17:12)
Block(-2,1,2,17:12)
Block(-2,2,-1,17:12)
Block(-2,3,-1,17:12)
Block(-2,6,3,LEAVES:0)
Block(-2,6,4,LEAVES:0)
Block(-2,6,5,LEAVES:0)
Block(-2,7,2,LEAVES:0)
Block(-2,7,3,LEAVES:0)
Block(-2,7,4,LEAVES:0)
Block(-2,8,-1,17:12)
Block(-2,8,0,17:12)
Block(-2,8,2,LEAVES:0)
Block(-2,8,3,LEAVES:0)
Block(-2,8,4,LEAVES:0)
Block(-2,9,0,17:12)
Block(-2,9,1,17:12)
Block(-2,9,2,17:12)
Block(-2,9,3,LEAVES:0)
Block(-2,9,4,LEAVES:0)
Block(-2,9,5,LEAVES:0)
Block(-2,9,6,LEAVES:0)
Block(-2,10,2,LEAVES:0)
Block(-2,10,3,17:12)
Block(-2,10,5,LEAVES:0)
Block(-2,10,6,LEAVES:0)
Block(-2,10,7,LEAVES:0)
Block(-2,11,-9,LEAVES:0)
Block(-2,11,-8,LEAVES:0)
Block(-2,11,-7,LEAVES:0)
Block(-2,11,0,LEAVES:0)
Block(-2,11,1,LEAVES:0)
Block(-2,11,2,LEAVES:0)
Block(-2,11,3,17:12)
Block(-2,11,4,17:12)
Block(-2,11,5,LEAVES:0)
Block(-2,11,6,LEAVES:0)
Block(-2,12,-13,LEAVES:0)
Block(-2,12,-12,LEAVES:0)
Block(-2,12,-11,LEAVES:0)
Block(-2,12,-10,LEAVES:0)
Block(-2,12,-8,17:12)
Block(-2,12,-7,17:12)
Block(-2,12,1,LEAVES:0)
Block(-2,12,2,LEAVES:0)
Block(-2,12,3,LEAVES:0)
Block(-2,12,4,LEAVES:0)
Block(-2,12,5,LEAVES:0)
Block(-2,12,6,LEAVES:0)
Block(-2,13,-12,LEAVES:0)
Block(-2,13,-11,LEAVES:0)
Block(-2,13,-10,LEAVES:0)
Block(-2,13,-9,17:12)
Block(-2,13,-8,17:12)
Block(-2,13,2,LEAVES:0)
Block(-2,13,4,LEAVES:0)
Block(-2,13,5,LEAVES:0)
Block(-2,14,-11,LEAVES:0)
Block(-2,14,-10,LEAVES:0)
Block(-2,14,-9,17:12)
Block(-2,14,-4,LEAVES:0)
Block(-2,15,-11,LEAVES:0)
Block(-2,15,-10,LEAVES:0)
Block(-2,15,-9,LEAVES:0)
Block(-2,15,-8,LEAVES:0)
Block(-2,15,-6,LEAVES:0)
Block(-2,15,-5,LEAVES:0)
Block(-2,15,-4,17:12)
Block(-2,16,-10,LEAVES:0)
Block(-2,16,-7,LEAVES:0)
Block(-2,16,-4,17:12)
Block(-2,16,-1,LEAVES:0)
Block(-2,16,0,LEAVES:0)
Block(-2,16,1,LEAVES:0)
Block(-2,17,-5,LEAVES:0)
Block(-2,17,-2,LEAVES:0)
Block(-2,17,0,LEAVES:0)
Block(-2,17,1,LEAVES:0)
Block(-2,17,2,LEAVES:0)
Block(-2,17,3,LEAVES:0)
Block(-2,17,4,LEAVES:0)
Block(-2,18,-12,LEAVES:0)
Block(-2,18,-5,LEAVES:0)
Block(-2,18,-4,LEAVES:0)
Block(-2,18,1,LEAVES:0)
Block(-2,18,3,LEAVES:0)
Block(-2,18,4,17:12)
Block(-2,19,-4,LEAVES:0)
Block(-2,19,-3,LEAVES:0)
Block(-2,19,-2,LEAVES:0)
Block(-2,19,0,LEAVES:0)
Block(-2,20,-5,LEAVES:0)
Block(-2,20,-4,LEAVES:0)
Block(-2,20,-3,LEAVES:0)
Block(-2,20,-1,LEAVES:0)
Block(-2,20,0,LEAVES:0)
Block(-2,20,1,LEAVES:0)
Block(-2,20,3,LEAVES:0)
Block(-2,20,4,LEAVES:0)
Block(-2,20,5,LEAVES:0)
Block(-2,21,-8,LEAVES:0)
Block(-2,21,-4,LEAVES:0)
Block(-2,21,0,LEAVES:0)
Block(-2,21,2,LEAVES:0)
Block(-2,21,3,LEAVES:0)
Block(-2,21,4,LEAVES:0)
Block(-2,22,-9,LEAVES:0)
Block(-2,22,-8,LEAVES:0)
Block(-2,22,-7,LEAVES:0)
Block(-2,22,-1,LEAVES:0)
Block(-2,22,0,LEAVES:0)
Block(-2,22,1,17:12)
Block(-2,22,3,LEAVES:0)
Block(-2,23,-8,LEAVES:0)
Block(-2,23,-7,LEAVES:0)
Block(-2,23,-5,LEAVES:0)
Block(-2,23,-4,LEAVES:0)
Block(-2,23,-3,LEAVES:0)
Block(-2,23,-2,LEAVES:0)
Block(-2,23,-1,LEAVES:0)
Block(-2,23,0,LEAVES:0)
Block(-2,23,1,17:12)
Block(-2,24,-8,LEAVES:0)
Block(-2,24,-6,LEAVES:0)
Block(-2,24,-5,LEAVES:0)
Block(-2,24,-4,LEAVES:0)
Block(-2,24,-2,LEAVES:0)
Block(-2,24,-1,LEAVES:0)
Block(-2,24,0,LEAVES:0)
Block(-2,24,1,17:12)
Block(-2,25,-10,LEAVES:0)
Block(-2,25,-7,LEAVES:0)
Block(-2,25,-6,LEAVES:0)
Block(-2,25,-5,17:12)
Block(-2,25,-4,LEAVES:0)
Block(-2,25,-3,LEAVES:0)
Block(-2,25,-1,LEAVES:0)
Block(-2,25,1,LEAVES:0)
Block(-2,25,3,LEAVES:0)
Block(-2,26,-9,LEAVES:0)
Block(-2,26,-8,LEAVES:0)
Block(-2,26,-7,LEAVES:0)
Block(-2,26,-5,17:12)
Block(-2,26,-4,LEAVES:0)
Block(-2,26,-3,LEAVES:0)
Block(-2,26,2,LEAVES:0)
Block(-2,26,3,LEAVES:0)
Block(-2,26,4,LEAVES:0)
Block(-2,27,-9,LEAVES:0)
Block(-2,27,-8,LEAVES:0)
Block(-2,27,-7,LEAVES:0)
Block(-2,27,-6,LEAVES:0)
Block(-2,27,-5,LEAVES:0)
Block(-2,27,-4,LEAVES:0)
Block(-2,27,0,LEAVES:0)
Block(-2,27,1,LEAVES:0)
Block(-2,27,2,LEAVES:0)
Block(-2,27,3,LEAVES:0)
Block(-2,28,-12,LEAVES:0)
Block(-2,28,-11,LEAVES:0)
Block(-2,28,-10,LEAVES:0)
Block(-2,28,-8,LEAVES:0)
Block(-2,28,-7,LEAVES:0)
Block(-2,28,-6,LEAVES:0)
Block(-2,28,-5,LEAVES:0)
Block(-2,28,-1,LEAVES:0)
Block(-2,28,0,LEAVES:0)
Block(-2,28,1,LEAVES:0)
Block(-2,29,-11,LEAVES:0)
Block(-2,29,-7,LEAVES:0)
Block(-2,29,0,LEAVES:0)
Block(-1,0,-2,17:12)
Block(-1,0,-1,17)
Block(-1,0,0,17:12)
Block(-1,0,1,17)
Block(-1,0,2,17:12)
Block(-1,1,-2,17:12)
Block(-1,1,-1,17:12)
Block(-1,1,0,17:12)
Block(-1,1,1,17:12)
Block(-1,1,2,17:12)
Block(-1,2,-2,17:12)
Block(-1,2,-1,17:12)
Block(-1,2,0,17:12)
Block(-1,2,1,17:12)
Block(-1,3,-2,17:12)
Block(-1,3,-1,17:12)
Block(-1,3,0,17:12)
Block(-1,4,-2,17:12)
Block(-1,4,-1,17:12)
Block(-1,5,-2,17:12)
Block(-1,5,-1,17:12)
Block(-1,6,-2,17:12)
Block(-1,6,-1,17:12)
Block(-1,6,4,LEAVES:0)
Block(-1,7,-3,17:12)
Block(-1,7,-2,17:12)
Block(-1,7,-1,17:12)
Block(-1,7,3,LEAVES:0)
Block(-1,8,-4,17:12)
Block(-1,8,-3,17:12)
Block(-1,8,-2,17:12)
Block(-1,8,-1,17:12)
Block(-1,9,-4,17:12)
Block(-1,9,-3,17:12)
Block(-1,9,-1,17:12)
Block(-1,9,0,17:12)
Block(-1,9,2,LEAVES:0)
Block(-1,9,3,LEAVES:0)
Block(-1,9,4,LEAVES:0)
Block(-1,9,5,LEAVES:0)
Block(-1,10,-3,17:12)
Block(-1,10,1,LEAVES:0)
Block(-1,10,2,LEAVES:0)
Block(-1,10,3,LEAVES:0)
Block(-1,10,5,LEAVES:0)
Block(-1,10,6,LEAVES:0)
Block(-1,11,-10,LEAVES:0)
Block(-1,11,-9,LEAVES:0)
Block(-1,11,-8,LEAVES:0)
Block(-1,11,-7,LEAVES:0)
Block(-1,11,-6,LEAVES:0)
Block(-1,11,1,LEAVES:0)
Block(-1,11,2,LEAVES:0)
Block(-1,11,4,17:12)
Block(-1,12,-14,LEAVES:0)
Block(-1,12,-13,LEAVES:0)
Block(-1,12,-12,LEAVES:0)
Block(-1,12,-11,LEAVES:0)
Block(-1,12,-10,LEAVES:0)
Block(-1,12,-9,LEAVES:0)
Block(-1,12,-8,17:12)
Block(-1,12,-7,17:12)
Block(-1,12,-6,17:12)
Block(-1,12,2,LEAVES:0)
Block(-1,12,4,LEAVES:0)
Block(-1,12,5,LEAVES:0)
Block(-1,12,6,LEAVES:0)
Block(-1,12,7,LEAVES:0)
Block(-1,13,-13,LEAVES:0)
Block(-1,13,-12,LEAVES:0)
Block(-1,13,-11,LEAVES:0)
Block(-1,13,-10,LEAVES:0)
Block(-1,13,4,LEAVES:0)
Block(-1,13,5,LEAVES:0)
Block(-1,13,6,LEAVES:0)
Block(-1,14,-12,LEAVES:0)
Block(-1,14,-11,LEAVES:0)
Block(-1,14,-10,LEAVES:0)
Block(-1,14,-9,LEAVES:0)
Block(-1,14,-4,17:12)
Block(-1,14,5,LEAVES:0)
Block(-1,15,-10,LEAVES:0)
Block(-1,15,-9,LEAVES:0)
Block(-1,15,-8,LEAVES:0)
Block(-1,15,-7,LEAVES:0)
Block(-1,15,-6,LEAVES:0)
Block(-1,15,-5,LEAVES:0)
Block(-1,15,-4,17:12)
Block(-1,16,-9,LEAVES:0)
Block(-1,16,-6,LEAVES:0)
Block(-1,16,-4,17:12)
Block(-1,16,0,LEAVES:0)
Block(-1,16,5,LEAVES:0)
Block(-1,17,-1,LEAVES:0)
Block(-1,17,0,LEAVES:0)
Block(-1,17,1,LEAVES:0)
Block(-1,17,3,LEAVES:0)
Block(-1,17,4,LEAVES:0)
Block(-1,18,-13,LEAVES:0)
Block(-1,18,-12,LEAVES:0)
Block(-1,18,-11,LEAVES:0)
Block(-1,18,-8,LEAVES:0)
Block(-1,18,0,LEAVES:0)
Block(-1,18,2,LEAVES:0)
Block(-1,18,3,17:12)
Block(-1,19,-12,LEAVES:0)
Block(-1,19,-3,LEAVES:0)
Block(-1,19,-1,LEAVES:0)
Block(-1,19,0,LEAVES:0)
Block(-1,19,1,LEAVES:0)
Block(-1,19,2,17:12)
Block(-1,19,3,17:12)
Block(-1,20,-10,17:12)
Block(-1,20,-4,LEAVES:0)
Block(-1,20,0,LEAVES:0)
Block(-1,20,1,LEAVES:0)
Block(-1,20,2,LEAVES:0)
Block(-1,20,3,LEAVES:0)
Block(-1,20,4,LEAVES:0)
Block(-1,21,-9,LEAVES:0)
Block(-1,21,-8,LEAVES:0)
Block(-1,21,-7,LEAVES:0)
Block(-1,21,1,17:12)
Block(-1,21,3,LEAVES:0)
Block(-1,21,4,LEAVES:0)
Block(-1,21,5,LEAVES:0)
Block(-1,21,6,LEAVES:0)
Block(-1,22,-12,LEAVES:0)
Block(-1,22,-10,LEAVES:0)
Block(-1,22,-9,LEAVES:0)
Block(-1,22,-8,LEAVES:0)
Block(-1,22,-2,LEAVES:0)
Block(-1,22,0,LEAVES:0)
Block(-1,22,1,17:12)
Block(-1,22,4,LEAVES:0)
Block(-1,22,5,LEAVES:0)
Block(-1,23,-9,LEAVES:0)
Block(-1,23,-8,LEAVES:0)
Block(-1,23,-6,17:12)
Block(-1,23,-5,LEAVES:0)
Block(-1,23,-4,LEAVES:0)
Block(-1,23,-2,LEAVES:0)
Block(-1,23,-1,LEAVES:0)
Block(-1,23,0,LEAVES:0)
Block(-1,23,3,LEAVES:0)
Block(-1,24,-7,LEAVES:0)
Block(-1,24,-6,LEAVES:0)
Block(-1,24,-5,LEAVES:0)
Block(-1,24,-4,LEAVES:0)
Block(-1,24,-3,LEAVES:0)
Block(-1,24,-1,LEAVES:0)
Block(-1,24,0,LEAVES:0)
Block(-1,24,1,LEAVES:0)
Block(-1,24,2,LEAVES:0)
Block(-1,25,-11,LEAVES:0)
Block(-1,25,-10,LEAVES:0)
Block(-1,25,-9,LEAVES:0)
Block(-1,25,-8,LEAVES:0)
Block(-1,25,-7,LEAVES:0)
Block(-1,25,-4,LEAVES:0)
Block(-1,25,0,LEAVES:0)
Block(-1,25,1,LEAVES:0)
Block(-1,25,2,LEAVES:0)
Block(-1,25,3,LEAVES:0)
Block(-1,25,4,LEAVES:0)
Block(-1,26,-10,LEAVES:0)
Block(-1,26,-9,LEAVES:0)
Block(-1,26,-8,LEAVES:0)
Block(-1,26,-7,LEAVES:0)
Block(-1,26,-5,LEAVES:0)
Block(-1,26,-4,LEAVES:0)
Block(-1,26,1,LEAVES:0)
Block(-1,26,2,LEAVES:0)
Block(-1,26,3,LEAVES:0)
Block(-1,27,-9,LEAVES:0)
Block(-1,27,-8,LEAVES:0)
Block(-1,27,-7,LEAVES:0)
Block(-1,27,-6,LEAVES:0)
Block(-1,27,-5,LEAVES:0)
Block(-1,27,-4,LEAVES:0)
Block(-1,27,-3,LEAVES:0)
Block(-1,27,1,LEAVES:0)
Block(-1,27,2,LEAVES:0)
Block(-1,28,-11,LEAVES:0)
Block(-1,28,-10,LEAVES:0)
Block(-1,28,-9,LEAVES:0)
Block(-1,28,-8,LEAVES:0)
Block(-1,28,-7,LEAVES:0)
Block(-1,28,-6,LEAVES:0)
Block(-1,28,-5,LEAVES:0)
Block(-1,28,-4,LEAVES:0)
Block(-1,28,0,LEAVES:0)
Block(-1,29,-12,LEAVES:0)
Block(-1,29,-11,LEAVES:0)
Block(-1,29,-10,LEAVES:0)
Block(-1,29,-8,LEAVES:0)
Block(-1,29,-5,LEAVES:0)
Block(-1,30,-11,LEAVES:0)
Block(0,0,-1,17)
Block(0,0,0,17:12)
Block(0,0,1,17:12)
Block(0,0,2,17:12)
Block(0,1,-1,17:12)
Block(0,1,0,17:12)
Block(0,1,1,17:12)
Block(0,2,-1,17:12)
Block(0,2,0,17:12)
Block(0,2,1,17:12)
Block(0,3,-1,17:12)
Block(0,3,0,17:12)
Block(0,3,1,17:12)
Block(0,4,-2,17:12)
Block(0,4,-1,17:12)
Block(0,4,0,17:12)
Block(0,4,1,17:12)
Block(0,5,-2,17:12)
Block(0,5,-1,17:12)
Block(0,5,0,17:12)
Block(0,5,1,17:12)
Block(0,6,-2,17:12)
Block(0,6,-1,17:12)
Block(0,6,0,17:12)
Block(0,7,-3,17:12)
Block(0,7,-2,17:12)
Block(0,7,-1,17:12)
Block(0,7,0,17:12)
Block(0,8,-4,17:12)
Block(0,8,-3,17:12)
Block(0,8,-2,17:12)
Block(0,8,-1,17:12)
Block(0,9,-4,17:12)
Block(0,9,-3,17:12)
Block(0,9,-2,17:12)
Block(0,9,1,LEAVES:0)
Block(0,9,2,LEAVES:0)
Block(0,9,3,LEAVES:0)
Block(0,9,4,LEAVES:0)
Block(0,9,5,LEAVES:0)
Block(0,9,6,LEAVES:0)
Block(0,10,-4,17:12)
Block(0,10,-3,17:12)
Block(0,10,-2,17:12)
Block(0,10,2,LEAVES:0)
Block(0,10,5,LEAVES:0)
Block(0,10,6,LEAVES:0)
Block(0,10,7,LEAVES:0)
Block(0,11,-9,LEAVES:0)
Block(0,11,-7,LEAVES:0)
Block(0,11,-6,17:12)
Block(0,11,-5,17:12)
Block(0,11,-4,17:12)
Block(0,11,-3,17:12)
Block(0,11,-2,17:12)
Block(0,11,6,LEAVES:0)
Block(0,12,-13,LEAVES:0)
Block(0,12,-10,LEAVES:0)
Block(0,12,-9,17:12)
Block(0,12,-8,17:12)
Block(0,12,-6,17:12)
Block(0,12,-5,17:12)
Block(0,12,-4,17:12)
Block(0,12,-3,17:12)
Block(0,12,-2,17:12)
Block(0,12,2,LEAVES:0)
Block(0,12,4,LEAVES:0)
Block(0,12,6,LEAVES:0)
Block(0,13,-14,LEAVES:0)
Block(0,13,-13,LEAVES:0)
Block(0,13,-12,LEAVES:0)
Block(0,13,-10,17:12)
Block(0,13,-9,17:12)
Block(0,13,-3,17:12)
Block(0,13,3,LEAVES:0)
Block(0,13,5,LEAVES:0)
Block(0,13,6,LEAVES:0)
Block(0,13,7,LEAVES:0)
Block(0,14,-13,LEAVES:0)
Block(0,14,-12,LEAVES:0)
Block(0,14,-10,LEAVES:0)
Block(0,14,-9,LEAVES:0)
Block(0,14,-8,LEAVES:0)
Block(0,14,-4,17:12)
Block(0,14,-3,17:12)
Block(0,14,-2,17:12)
Block(0,14,6,LEAVES:0)
Block(0,15,-9,LEAVES:0)
Block(0,15,-6,LEAVES:0)
Block(0,15,-4,17:12)
Block(0,15,-3,17:12)
Block(0,15,1,LEAVES:0)
Block(0,16,-5,17:12)
Block(0,16,-4,17:12)
Block(0,16,4,LEAVES:0)
Block(0,16,5,LEAVES:0)
Block(0,16,6,LEAVES:0)
Block(0,17,-5,17:12)
Block(0,17,-4,17:12)
Block(0,17,0,LEAVES:0)
Block(0,17,2,LEAVES:0)
Block(0,17,3,LEAVES:0)
Block(0,17,4,LEAVES:0)
Block(0,17,5,LEAVES:0)
Block(0,18,-12,LEAVES:0)
Block(0,18,-11,LEAVES:0)
Block(0,18,-10,LEAVES:0)
Block(0,18,-9,LEAVES:0)
Block(0,18,-8,LEAVES:0)
Block(0,18,-7,LEAVES:0)
Block(0,18,-6,17:12)
Block(0,18,-5,17:12)
Block(0,18,2,LEAVES:0)
Block(0,18,4,LEAVES:0)
Block(0,19,-13,LEAVES:0)
Block(0,19,-12,LEAVES:0)
Block(0,19,-11,LEAVES:0)
Block(0,19,-8,LEAVES:0)
Block(0,19,-6,17:12)
Block(0,19,-5,17:12)
Block(0,19,0,LEAVES:0)
Block(0,19,1,17:12)
Block(0,19,2,17:12)
Block(0,20,-12,LEAVES:0)
Block(0,20,-10,17:12)
Block(0,20,-9,17:12)
Block(0,20,-6,17:12)
Block(0,20,-5,17:12)
Block(0,20,1,LEAVES:0)
Block(0,20,2,LEAVES:0)
Block(0,20,3,LEAVES:0)
Block(0,21,-12,LEAVES:0)
Block(0,21,-10,LEAVES:0)
Block(0,21,-8,LEAVES:0)
Block(0,21,-6,17:12)
Block(0,21,-1,LEAVES:0)
Block(0,21,1,LEAVES:0)
Block(0,21,2,LEAVES:0)
Block(0,21,3,LEAVES:0)
Block(0,21,4,LEAVES:0)
Block(0,21,5,LEAVES:0)
Block(0,21,6,LEAVES:0)
Block(0,21,7,LEAVES:0)
Block(0,22,-13,LEAVES:0)
Block(0,22,-12,LEAVES:0)
Block(0,22,-11,LEAVES:0)
Block(0,22,-10,LEAVES:0)
Block(0,22,-9,LEAVES:0)
Block(0,22,-6,17:12)
Block(0,22,-3,LEAVES:0)
Block(0,22,-2,LEAVES:0)
Block(0,22,-1,LEAVES:0)
Block(0,22,1,17:12)
Block(0,22,2,LEAVES:0)
Block(0,22,3,LEAVES:0)
Block(0,22,4,LEAVES:0)
Block(0,22,5,LEAVES:0)
Block(0,22,6,LEAVES:0)
Block(0,23,-12,LEAVES:0)
Block(0,23,-9,LEAVES:0)
Block(0,23,-8,LEAVES:0)
Block(0,23,-7,LEAVES:0)
Block(0,23,-6,17:12)
Block(0,23,-5,LEAVES:0)
Block(0,23,-2,LEAVES:0)
Block(0,23,-1,LEAVES:0)
Block(0,23,0,LEAVES:0)
Block(0,23,2,LEAVES:0)
Block(0,23,3,LEAVES:0)
Block(0,23,4,LEAVES:0)
Block(0,23,5,LEAVES:0)
Block(0,24,-8,LEAVES:0)
Block(0,24,-7,LEAVES:0)
Block(0,24,-6,LEAVES:0)
Block(0,24,-5,LEAVES:0)
Block(0,24,-4,LEAVES:0)
Block(0,24,-1,LEAVES:0)
Block(0,24,0,LEAVES:0)
Block(0,24,1,LEAVES:0)
Block(0,24,2,LEAVES:0)
Block(0,24,3,LEAVES:0)
Block(0,25,-10,LEAVES:0)
Block(0,25,-9,LEAVES:0)
Block(0,25,-8,LEAVES:0)
Block(0,25,-7,LEAVES:0)
Block(0,25,-6,LEAVES:0)
Block(0,25,0,LEAVES:0)
Block(0,25,1,LEAVES:0)
Block(0,25,2,LEAVES:0)
Block(0,25,3,LEAVES:0)
Block(0,25,4,LEAVES:0)
Block(0,26,-11,LEAVES:0)
Block(0,26,-10,LEAVES:0)
Block(0,26,-9,LEAVES:0)
Block(0,26,-8,LEAVES:0)
Block(0,26,-7,LEAVES:0)
Block(0,26,-6,LEAVES:0)
Block(0,26,-5,LEAVES:0)
Block(0,26,-4,LEAVES:0)
Block(0,26,-3,LEAVES:0)
Block(0,26,1,LEAVES:0)
Block(0,26,2,LEAVES:0)
Block(0,26,3,LEAVES:0)
Block(0,27,-10,LEAVES:0)
Block(0,27,-9,LEAVES:0)
Block(0,27,-8,LEAVES:0)
Block(0,27,-7,LEAVES:0)
Block(0,27,-6,LEAVES:0)
Block(0,27,-5,LEAVES:0)
Block(0,27,-4,LEAVES:0)
Block(0,28,-10,LEAVES:0)
Block(0,28,-9,LEAVES:0)
Block(0,28,-8,LEAVES:0)
Block(0,28,-5,LEAVES:0)
Block(0,28,-4,LEAVES:0)
Block(0,28,-3,LEAVES:0)
Block(0,29,-11,LEAVES:0)
Block(0,29,-10,LEAVES:0)
Block(0,29,-4,LEAVES:0)
Block(0,30,-12,LEAVES:0)
Block(1,0,0,17:12)
Block(1,1,0,17:12)
Block(1,2,-1,17:12)
Block(1,2,0,17:12)
Block(1,3,-1,17:12)
Block(1,3,0,17:12)
Block(1,4,-11,LEAVES:0)
Block(1,4,-1,17:12)
Block(1,4,0,17:12)
Block(1,5,-1,17:12)
Block(1,5,0,17:12)
Block(1,6,-1,17:12)
Block(1,6,0,17:12)
Block(1,7,-4,17:12)
Block(1,7,-1,17:12)
Block(1,8,-4,17:12)
Block(1,8,-3,17:12)
Block(1,8,-2,17:12)
Block(1,8,-1,17:12)
Block(1,9,-3,17:12)
Block(1,9,-2,17:12)
Block(1,9,2,LEAVES:0)
Block(1,9,5,LEAVES:0)
Block(1,9,6,LEAVES:0)
Block(1,9,7,LEAVES:0)
Block(1,10,-4,17:12)
Block(1,10,-3,17:12)
Block(1,10,-2,17:12)
Block(1,10,3,LEAVES:0)
Block(1,10,6,LEAVES:0)
Block(1,11,-13,LEAVES:0)
Block(1,11,-4,17:12)
Block(1,11,-3,17:12)
Block(1,11,2,LEAVES:0)
Block(1,12,-5,17:12)
Block(1,12,-4,17:12)
Block(1,12,-3,17:12)
Block(1,12,-2,17:12)
Block(1,12,1,LEAVES:0)
Block(1,12,2,LEAVES:0)
Block(1,12,3,LEAVES:0)
Block(1,13,-13,LEAVES:0)
Block(1,13,-10,17:12)
Block(1,13,-9,LEAVES:0)
Block(1,13,-4,17:12)
Block(1,13,-3,17:12)
Block(1,13,-2,17:12)
Block(1,13,1,LEAVES:0)
Block(1,13,2,LEAVES:0)
Block(1,13,3,LEAVES:0)
Block(1,13,4,LEAVES:0)
Block(1,13,6,LEAVES:0)
Block(1,14,-13,LEAVES:0)
Block(1,14,-12,LEAVES:0)
Block(1,14,-11,LEAVES:0)
Block(1,14,-10,LEAVES:0)
Block(1,14,-9,LEAVES:0)
Block(1,14,-3,17:12)
Block(1,14,-2,17:12)
Block(1,14,2,LEAVES:0)
Block(1,14,3,LEAVES:0)
Block(1,15,-12,LEAVES:0)
Block(1,15,-3,17:12)
Block(1,15,0,LEAVES:0)
Block(1,15,1,LEAVES:0)
Block(1,15,2,LEAVES:0)
Block(1,16,-4,17:12)
Block(1,16,-3,17:12)
Block(1,16,-1,17:12)
Block(1,16,1,LEAVES:0)
Block(1,16,3,LEAVES:0)
Block(1,16,4,LEAVES:0)
Block(1,16,5,LEAVES:0)
Block(1,17,-6,17:12)
Block(1,17,-5,17:12)
Block(1,17,-4,17:12)
Block(1,17,0,17:12)
Block(1,17,3,LEAVES:0)
Block(1,17,4,LEAVES:0)
Block(1,18,-11,LEAVES:0)
Block(1,18,-10,LEAVES:0)
Block(1,18,-9,LEAVES:0)
Block(1,18,-8,LEAVES:0)
Block(1,18,-7,17:12)
Block(1,18,-6,17:12)
Block(1,18,-5,17:12)
Block(1,18,0,17:12)
Block(1,18,1,17:12)
Block(1,19,-14,LEAVES:0)
Block(1,19,-13,LEAVES:0)
Block(1,19,-12,LEAVES:0)
Block(1,19,-11,LEAVES:0)
Block(1,19,-9,17:12)
Block(1,19,-8,LEAVES:0)
Block(1,19,-7,LEAVES:0)
Block(1,19,-5,17:12)
Block(1,19,-1,LEAVES:0)
Block(1,19,0,LEAVES:0)
Block(1,19,1,17:12)
Block(1,20,-13,LEAVES:0)
Block(1,20,-9,LEAVES:0)
Block(1,20,-8,LEAVES:0)
Block(1,20,-6,17:12)
Block(1,20,0,LEAVES:0)
Block(1,20,1,17:12)
Block(1,20,2,LEAVES:0)
Block(1,21,-13,LEAVES:0)
Block(1,21,-12,LEAVES:0)
Block(1,21,-11,LEAVES:0)
Block(1,21,-10,LEAVES:0)
Block(1,21,-2,LEAVES:0)
Block(1,21,-1,LEAVES:0)
Block(1,21,0,LEAVES:0)
Block(1,21,1,LEAVES:0)
Block(1,21,2,LEAVES:0)
Block(1,21,3,LEAVES:0)
Block(1,21,6,LEAVES:0)
Block(1,22,-12,LEAVES:0)
Block(1,22,-11,LEAVES:0)
Block(1,22,-10,LEAVES:0)
Block(1,22,-9,LEAVES:0)
Block(1,22,-2,LEAVES:0)
Block(1,22,-1,LEAVES:0)
Block(1,22,1,17:12)
Block(1,22,2,LEAVES:0)
Block(1,22,3,LEAVES:0)
Block(1,22,4,17:12)
Block(1,22,5,LEAVES:0)
Block(1,22,6,LEAVES:0)
Block(1,22,7,LEAVES:0)
Block(1,23,-11,LEAVES:0)
Block(1,23,-10,LEAVES:0)
Block(1,23,-8,LEAVES:0)
Block(1,23,-7,LEAVES:0)
Block(1,23,-6,17:12)
Block(1,23,-5,LEAVES:0)
Block(1,23,-4,LEAVES:0)
Block(1,23,-3,LEAVES:0)
Block(1,23,-2,LEAVES:0)
Block(1,23,-1,LEAVES:0)
Block(1,23,0,17:12)
Block(1,23,1,17:12)
Block(1,23,2,LEAVES:0)
Block(1,23,3,LEAVES:0)
Block(1,23,5,LEAVES:0)
Block(1,23,6,LEAVES:0)
Block(1,24,-9,LEAVES:0)
Block(1,24,-8,LEAVES:0)
Block(1,24,-7,LEAVES:0)
Block(1,24,-6,LEAVES:0)
Block(1,24,-5,LEAVES:0)
Block(1,24,-2,LEAVES:0)
Block(1,24,2,LEAVES:0)
Block(1,24,3,LEAVES:0)
Block(1,24,4,LEAVES:0)
Block(1,25,-9,LEAVES:0)
Block(1,25,-8,LEAVES:0)
Block(1,25,-7,LEAVES:0)
Block(1,25,1,LEAVES:0)
Block(1,25,2,LEAVES:0)
Block(1,25,3,LEAVES:0)
Block(1,26,-10,LEAVES:0)
Block(1,26,-8,LEAVES:0)
Block(1,26,-7,17:12)
Block(1,26,-4,LEAVES:0)
Block(1,26,2,LEAVES:0)
Block(1,27,-9,LEAVES:0)
Block(1,27,-8,17:12)
Block(1,27,-5,LEAVES:0)
Block(1,27,-4,LEAVES:0)
Block(1,27,-3,LEAVES:0)
Block(1,28,-10,LEAVES:0)
Block(1,28,-9,LEAVES:0)
Block(1,28,-4,LEAVES:0)
Block(1,29,-12,LEAVES:0)
Block(1,30,-13,LEAVES:0)
Block(1,30,-12,LEAVES:0)
Block(1,30,-11,LEAVES:0)
Block(1,30,-8,LEAVES:0)
Block(1,31,-12,LEAVES:0)
Block(2,0,0,17)
Block(2,0,1,17:12)
Block(2,0,2,17:12)
Block(2,1,0,17:12)
Block(2,1,1,17:12)
Block(2,1,2,17:12)
Block(2,4,-12,LEAVES:0)
Block(2,4,-11,LEAVES:0)
Block(2,4,-10,LEAVES:0)
Block(2,5,-11,LEAVES:0)
Block(2,5,-8,LEAVES:0)
Block(2,6,-9,LEAVES:0)
Block(2,7,-4,17:12)
Block(2,8,-8,LEAVES:0)
Block(2,9,-9,LEAVES:0)
Block(2,9,6,LEAVES:0)
Block(2,10,-13,LEAVES:0)
Block(2,10,-2,17:12)
Block(2,10,-1,17:12)
Block(2,10,0,LEAVES:0)
Block(2,10,2,LEAVES:0)
Block(2,10,3,LEAVES:0)
Block(2,10,4,LEAVES:0)
Block(2,11,-14,LEAVES:0)
Block(2,11,-13,LEAVES:0)
Block(2,11,-12,LEAVES:0)
Block(2,11,-1,17:12)
Block(2,11,0,17:12)
Block(2,11,1,LEAVES:0)
Block(2,11,2,LEAVES:0)
Block(2,11,3,LEAVES:0)
Block(2,12,-13,LEAVES:0)
Block(2,12,-11,LEAVES:0)
Block(2,12,-9,LEAVES:0)
Block(2,12,-3,17:12)
Block(2,12,2,LEAVES:0)
Block(2,13,-10,LEAVES:0)
Block(2,13,-9,LEAVES:0)
Block(2,13,-8,LEAVES:0)
Block(2,13,-3,17:12)
Block(2,13,0,LEAVES:0)
Block(2,13,1,LEAVES:0)
Block(2,13,2,LEAVES:0)
Block(2,13,3,LEAVES:0)
Block(2,14,-12,LEAVES:0)
Block(2,14,-11,LEAVES:0)
Block(2,14,-10,LEAVES:0)
Block(2,14,-9,LEAVES:0)
Block(2,14,-3,17:12)
Block(2,14,-2,17:12)
Block(2,14,1,LEAVES:0)
Block(2,14,2,LEAVES:0)
Block(2,14,3,LEAVES:0)
Block(2,15,-13,LEAVES:0)
Block(2,15,-12,LEAVES:0)
Block(2,15,-11,LEAVES:0)
Block(2,15,-3,17:12)
Block(2,15,-2,17:12)
Block(2,15,-1,17:12)
Block(2,15,1,LEAVES:0)
Block(2,15,2,LEAVES:0)
Block(2,15,3,LEAVES:0)
Block(2,16,-12,LEAVES:0)
Block(2,16,-2,17:12)
Block(2,16,-1,17:12)
Block(2,16,0,17:12)
Block(2,16,1,LEAVES:0)
Block(2,16,2,LEAVES:0)
Block(2,16,4,LEAVES:0)
Block(2,17,-1,17:12)
Block(2,17,0,17:12)
Block(2,17,1,17:12)
Block(2,18,-12,LEAVES:0)
Block(2,18,-11,LEAVES:0)
Block(2,18,-10,LEAVES:0)
Block(2,18,-9,LEAVES:0)
Block(2,18,-8,17:12)
Block(2,18,-7,17:12)
Block(2,18,0,17:12)
Block(2,18,1,17:12)
Block(2,19,-13,LEAVES:0)
Block(2,19,-12,LEAVES:0)
Block(2,19,-11,LEAVES:0)
Block(2,19,-9,17:12)
Block(2,19,-8,LEAVES:0)
Block(2,19,-7,LEAVES:0)
Block(2,19,-6,LEAVES:0)
Block(2,19,0,LEAVES:0)
Block(2,19,1,17:12)
Block(2,19,5,LEAVES:0)
Block(2,20,-14,LEAVES:0)
Block(2,20,-13,LEAVES:0)
Block(2,20,-12,LEAVES:0)
Block(2,20,-11,LEAVES:0)
Block(2,20,-10,LEAVES:0)
Block(2,20,-9,LEAVES:0)
Block(2,20,-8,LEAVES:0)
Block(2,20,-7,LEAVES:0)
Block(2,20,-6,17:12)
Block(2,20,1,17:12)
Block(2,20,4,LEAVES:0)
Block(2,20,6,LEAVES:0)
Block(2,21,-14,LEAVES:0)
Block(2,21,-13,LEAVES:0)
Block(2,21,-12,LEAVES:0)
Block(2,21,-11,LEAVES:0)
Block(2,21,-10,LEAVES:0)
Block(2,21,-9,LEAVES:0)
Block(2,21,-5,LEAVES:0)
Block(2,21,-1,LEAVES:0)
Block(2,21,0,LEAVES:0)
Block(2,21,1,LEAVES:0)
Block(2,21,2,LEAVES:0)
Block(2,21,3,17:12)
Block(2,22,-13,LEAVES:0)
Block(2,22,-12,LEAVES:0)
Block(2,22,-11,LEAVES:0)
Block(2,22,-10,LEAVES:0)
Block(2,22,-2,LEAVES:0)
Block(2,22,-1,LEAVES:0)
Block(2,22,0,LEAVES:0)
Block(2,22,2,LEAVES:0)
Block(2,22,3,LEAVES:0)
Block(2,22,5,LEAVES:0)
Block(2,22,6,LEAVES:0)
Block(2,22,7,LEAVES:0)
Block(2,23,-11,LEAVES:0)
Block(2,23,-7,LEAVES:0)
Block(2,23,-5,LEAVES:0)
Block(2,23,-2,LEAVES:0)
Block(2,23,-1,17:12)
Block(2,23,0,LEAVES:0)
Block(2,23,1,17:12)
Block(2,23,2,LEAVES:0)
Block(2,23,3,LEAVES:0)
Block(2,23,4,LEAVES:0)
Block(2,23,5,LEAVES:0)
Block(2,23,6,LEAVES:0)
Block(2,24,-8,LEAVES:0)
Block(2,24,-7,LEAVES:0)
Block(2,24,-3,LEAVES:0)
Block(2,24,-1,LEAVES:0)
Block(2,24,0,LEAVES:0)
Block(2,24,1,LEAVES:0)
Block(2,24,2,LEAVES:0)
Block(2,24,3,LEAVES:0)
Block(2,24,5,LEAVES:0)
Block(2,25,-8,17:12)
Block(2,25,-7,LEAVES:0)
Block(2,25,-6,LEAVES:0)
Block(2,25,-1,LEAVES:0)
Block(2,25,0,LEAVES:0)
Block(2,25,2,LEAVES:0)
Block(2,26,-11,LEAVES:0)
Block(2,26,-10,LEAVES:0)
Block(2,26,-9,LEAVES:0)
Block(2,26,-8,LEAVES:0)
Block(2,26,-7,LEAVES:0)
Block(2,26,-3,LEAVES:0)
Block(2,27,-10,LEAVES:0)
Block(2,27,-4,LEAVES:0)
Block(2,27,-3,LEAVES:0)
Block(2,27,-2,LEAVES:0)
Block(2,28,-11,LEAVES:0)
Block(2,28,-10,LEAVES:0)
Block(2,28,-9,LEAVES:0)
Block(2,28,-6,LEAVES:0)
Block(2,28,-3,LEAVES:0)
Block(2,29,-13,LEAVES:0)
Block(2,29,-12,LEAVES:0)
Block(2,29,-11,LEAVES:0)
Block(2,29,-10,LEAVES:0)
Block(2,29,-8,LEAVES:0)
Block(2,30,-12,LEAVES:0)
Block(2,30,-11,LEAVES:0)
Block(2,30,-10,LEAVES:0)
Block(2,30,-9,LEAVES:0)
Block(2,30,-8,LEAVES:0)
Block(2,30,-7,LEAVES:0)
Block(2,31,-11,LEAVES:0)
Block(2,31,-8,LEAVES:0)
Block(3,0,2,17:12)
Block(3,0,3,17:12)
Block(3,4,-11,LEAVES:0)
Block(3,5,-9,LEAVES:0)
Block(3,5,-8,LEAVES:0)
Block(3,5,-7,LEAVES:0)
Block(3,6,-10,LEAVES:0)
Block(3,6,-9,LEAVES:0)
Block(3,6,-8,LEAVES:0)
Block(3,7,-9,LEAVES:0)
Block(3,7,-6,17:12)
Block(3,7,-5,17:12)
Block(3,7,-4,17:12)
Block(3,8,-9,LEAVES:0)
Block(3,8,-8,LEAVES:0)
Block(3,8,-7,LEAVES:0)
Block(3,8,-5,LEAVES:0)
Block(3,9,-10,LEAVES:0)
Block(3,9,-9,LEAVES:0)
Block(3,9,-8,LEAVES:0)
Block(3,9,-6,LEAVES:0)
Block(3,10,-14,LEAVES:0)
Block(3,10,-13,LEAVES:0)
Block(3,10,-12,LEAVES:0)
Block(3,10,-9,LEAVES:0)
Block(3,10,-8,LEAVES:0)
Block(3,10,-3,LEAVES:0)
Block(3,10,-1,LEAVES:0)
Block(3,10,0,LEAVES:0)
Block(3,10,1,LEAVES:0)
Block(3,10,2,LEAVES:0)
Block(3,10,3,LEAVES:0)
Block(3,11,-13,LEAVES:0)
Block(3,11,-12,LEAVES:0)
Block(3,11,-11,LEAVES:0)
Block(3,11,-1,17:12)
Block(3,11,0,17:12)
Block(3,11,1,17:12)
Block(3,11,2,LEAVES:0)
Block(3,12,-12,LEAVES:0)
Block(3,12,-10,LEAVES:0)
Block(3,12,-9,LEAVES:0)
Block(3,12,-8,LEAVES:0)
Block(3,12,0,LEAVES:0)
Block(3,13,-11,LEAVES:0)
Block(3,13,-10,LEAVES:0)
Block(3,13,-9,LEAVES:0)
Block(3,13,-4,17:12)
Block(3,13,-3,17:12)
Block(3,13,0,LEAVES:0)
Block(3,13,1,LEAVES:0)
Block(3,13,2,LEAVES:0)
Block(3,14,-11,LEAVES:0)
Block(3,14,-10,LEAVES:0)
Block(3,14,-8,LEAVES:0)
Block(3,14,0,LEAVES:0)
Block(3,14,1,LEAVES:0)
Block(3,14,2,LEAVES:0)
Block(3,15,-12,LEAVES:0)
Block(3,15,-9,LEAVES:0)
Block(3,15,-3,17:12)
Block(3,15,-2,17:12)
Block(3,15,1,LEAVES:0)
Block(3,15,2,LEAVES:0)
Block(3,16,-2,17:12)
Block(3,16,-1,LEAVES:0)
Block(3,16,1,LEAVES:0)
Block(3,17,-2,LEAVES:0)
Block(3,17,-1,17:12)
Block(3,17,0,17:12)
Block(3,18,-13,LEAVES:0)
Block(3,18,-12,LEAVES:0)
Block(3,18,-11,LEAVES:0)
Block(3,18,-10,LEAVES:0)
Block(3,18,-8,17:12)
Block(3,18,-5,LEAVES:0)
Block(3,19,-12,LEAVES:0)
Block(3,19,-11,LEAVES:0)
Block(3,19,-10,17:12)
Block(3,19,-9,17:12)
Block(3,19,-8,LEAVES:0)
Block(3,19,-7,LEAVES:0)
Block(3,19,-4,LEAVES:0)
Block(3,19,4,LEAVES:0)
Block(3,19,5,LEAVES:0)
Block(3,19,6,LEAVES:0)
Block(3,20,-13,LEAVES:0)
Block(3,20,-12,17:12)
Block(3,20,-11,17:12)
Block(3,20,-9,LEAVES:0)
Block(3,20,-8,LEAVES:0)
Block(3,20,-7,LEAVES:0)
Block(3,20,-6,17:12)
Block(3,20,2,17:12)
Block(3,20,3,17:12)
Block(3,20,4,LEAVES:0)
Block(3,20,5,LEAVES:0)
Block(3,20,6,LEAVES:0)
Block(3,20,7,LEAVES:0)
Block(3,21,-15,LEAVES:0)
Block(3,21,-14,LEAVES:0)
Block(3,21,-13,LEAVES:0)
Block(3,21,-11,LEAVES:0)
Block(3,21,-10,LEAVES:0)
Block(3,21,-9,LEAVES:0)
Block(3,21,-8,LEAVES:0)
Block(3,21,-7,LEAVES:0)
Block(3,21,-6,17:12)
Block(3,21,-5,LEAVES:0)
Block(3,21,-4,LEAVES:0)
Block(3,21,0,LEAVES:0)
Block(3,21,1,LEAVES:0)
Block(3,21,2,LEAVES:0)
Block(3,21,3,17:12)
Block(3,21,4,17:12)
Block(3,21,6,LEAVES:0)
Block(3,22,-14,LEAVES:0)
Block(3,22,-13,LEAVES:0)
Block(3,22,-12,LEAVES:0)
Block(3,22,-11,LEAVES:0)
Block(3,22,-9,LEAVES:0)
Block(3,22,-5,LEAVES:0)
Block(3,22,-1,LEAVES:0)
Block(3,22,0,LEAVES:0)
Block(3,22,1,LEAVES:0)
Block(3,22,2,LEAVES:0)
Block(3,22,3,LEAVES:0)
Block(3,22,4,LEAVES:0)
Block(3,22,5,LEAVES:0)
Block(3,22,6,LEAVES:0)
Block(3,23,-13,LEAVES:0)
Block(3,23,-12,LEAVES:0)
Block(3,23,-11,LEAVES:0)
Block(3,23,-10,LEAVES:0)
Block(3,23,-7,LEAVES:0)
Block(3,23,-3,LEAVES:0)
Block(3,23,-2,LEAVES:0)
Block(3,23,-1,LEAVES:0)
Block(3,23,0,LEAVES:0)
Block(3,23,1,LEAVES:0)
Block(3,23,2,LEAVES:0)
Block(3,23,3,LEAVES:0)
Block(3,23,4,LEAVES:0)
Block(3,23,5,LEAVES:0)
Block(3,24,-11,LEAVES:0)
Block(3,24,-9,LEAVES:0)
Block(3,24,-8,LEAVES:0)
Block(3,24,-7,LEAVES:0)
Block(3,24,-4,LEAVES:0)
Block(3,24,-3,LEAVES:0)
Block(3,24,-2,LEAVES:0)
Block(3,24,-1,LEAVES:0)
Block(3,24,0,LEAVES:0)
Block(3,24,1,LEAVES:0)
Block(3,24,2,LEAVES:0)
Block(3,24,4,LEAVES:0)
Block(3,24,5,LEAVES:0)
Block(3,24,6,LEAVES:0)
Block(3,25,-8,LEAVES:0)
Block(3,25,-3,LEAVES:0)
Block(3,25,-2,LEAVES:0)
Block(3,25,-1,LEAVES:0)
Block(3,25,0,LEAVES:0)
Block(3,25,1,17:12)
Block(3,25,5,LEAVES:0)
Block(3,26,-12,LEAVES:0)
Block(3,26,-11,LEAVES:0)
Block(3,26,-10,LEAVES:0)
Block(3,26,-4,LEAVES:0)
Block(3,26,-3,LEAVES:0)
Block(3,26,-2,LEAVES:0)
Block(3,26,0,LEAVES:0)
Block(3,27,-11,LEAVES:0)
Block(3,27,-10,LEAVES:0)
Block(3,27,-9,LEAVES:0)
Block(3,27,-6,LEAVES:0)
Block(3,27,-3,LEAVES:0)
Block(3,27,-2,LEAVES:0)
Block(3,27,-1,LEAVES:0)
Block(3,28,-10,LEAVES:0)
Block(3,28,-9,LEAVES:0)
Block(3,28,-8,LEAVES:0)
Block(3,28,-7,LEAVES:0)
Block(3,28,-6,LEAVES:0)
Block(3,28,-5,LEAVES:0)
Block(3,28,-2,LEAVES:0)
Block(3,29,-12,LEAVES:0)
Block(3,29,-9,LEAVES:0)
Block(3,29,-8,LEAVES:0)
Block(3,29,-7,LEAVES:0)
Block(3,29,-6,LEAVES:0)
Block(3,30,-11,LEAVES:0)
Block(3,30,-10,LEAVES:0)
Block(3,30,-9,LEAVES:0)
Block(3,30,-8,LEAVES:0)
Block(3,31,-9,LEAVES:0)
Block(4,0,3,17:12)
Block(4,4,-12,LEAVES:0)
Block(4,4,-11,LEAVES:0)
Block(4,4,-10,LEAVES:0)
Block(4,5,-11,LEAVES:0)
Block(4,5,-10,LEAVES:0)
Block(4,5,-9,LEAVES:0)
Block(4,5,-8,LEAVES:0)
Block(4,6,-10,17:12)
Block(4,6,-9,LEAVES:0)
Block(4,6,-8,LEAVES:0)
Block(4,6,-6,17:12)
Block(4,7,-12,LEAVES:0)
Block(4,7,-10,LEAVES:0)
Block(4,7,-8,17:12)
Block(4,7,-7,17:12)
Block(4,7,-6,17:12)
Block(4,7,-4,LEAVES:0)
Block(4,8,-8,LEAVES:0)
Block(4,8,-6,LEAVES:0)
Block(4,8,-5,LEAVES:0)
Block(4,8,-4,LEAVES:0)
Block(4,9,-10,LEAVES:0)
Block(4,9,-9,LEAVES:0)
Block(4,9,-8,LEAVES:0)
Block(4,9,-7,LEAVES:0)
Block(4,9,-6,LEAVES:0)
Block(4,9,-5,LEAVES:0)
Block(4,10,-13,LEAVES:0)
Block(4,10,-9,LEAVES:0)
Block(4,10,-8,LEAVES:0)
Block(4,10,-7,LEAVES:0)
Block(4,10,-6,LEAVES:0)
Block(4,10,-4,LEAVES:0)
Block(4,10,-3,LEAVES:0)
Block(4,10,-2,LEAVES:0)
Block(4,10,0,LEAVES:0)
Block(4,10,1,LEAVES:0)
Block(4,10,2,LEAVES:0)
Block(4,11,-12,LEAVES:0)
Block(4,11,-11,LEAVES:0)
Block(4,11,-10,LEAVES:0)
Block(4,11,-8,LEAVES:0)
Block(4,11,-3,LEAVES:0)
Block(4,11,-1,17:12)
Block(4,11,1,17:12)
Block(4,11,2,17:12)
Block(4,12,-11,LEAVES:0)
Block(4,12,-10,LEAVES:0)
Block(4,12,-9,LEAVES:0)
Block(4,12,-6,LEAVES:0)
Block(4,12,0,LEAVES:0)
Block(4,12,2,17:12)
Block(4,13,-10,LEAVES:0)
Block(4,13,-7,LEAVES:0)
Block(4,13,-4,17:12)
Block(4,13,-1,LEAVES:0)
Block(4,13,0,LEAVES:0)
Block(4,13,1,LEAVES:0)
Block(4,13,2,LEAVES:0)
Block(4,14,-9,LEAVES:0)
Block(4,14,-8,LEAVES:0)
Block(4,14,-7,LEAVES:0)
Block(4,14,-5,17:12)
Block(4,14,-4,17:12)
Block(4,14,0,LEAVES:0)
Block(4,14,1,LEAVES:0)
Block(4,14,3,LEAVES:0)
Block(4,15,-10,LEAVES:0)
Block(4,15,-9,LEAVES:0)
Block(4,15,-8,LEAVES:0)
Block(4,16,-9,LEAVES:0)
Block(4,16,-2,LEAVES:0)
Block(4,16,-1,LEAVES:0)
Block(4,16,0,LEAVES:0)
Block(4,17,-3,LEAVES:0)
Block(4,17,-2,LEAVES:0)
Block(4,17,-1,LEAVES:0)
Block(4,17,0,LEAVES:0)
Block(4,18,-13,LEAVES:0)
Block(4,18,-12,LEAVES:0)
Block(4,18,-11,LEAVES:0)
Block(4,18,-10,LEAVES:0)
Block(4,18,-9,LEAVES:0)
Block(4,18,-6,LEAVES:0)
Block(4,18,-5,LEAVES:0)
Block(4,18,-4,LEAVES:0)
Block(4,18,-2,LEAVES:0)
Block(4,18,-1,17:12)
Block(4,18,1,LEAVES:0)
Block(4,18,3,LEAVES:0)
Block(4,19,-14,LEAVES:0)
Block(4,19,-12,LEAVES:0)
Block(4,19,-11,LEAVES:0)
Block(4,19,-10,LEAVES:0)
Block(4,19,-8,LEAVES:0)
Block(4,19,-5,LEAVES:0)
Block(4,19,-4,LEAVES:0)
Block(4,19,-3,LEAVES:0)
Block(4,19,3,LEAVES:0)
Block(4,19,4,LEAVES:0)
Block(4,19,5,LEAVES:0)
Block(4,19,6,LEAVES:0)
Block(4,19,7,LEAVES:0)
Block(4,20,-13,LEAVES:0)
Block(4,20,-11,LEAVES:0)
Block(4,20,-9,17:12)
Block(4,20,-7,LEAVES:0)
Block(4,20,-4,LEAVES:0)
Block(4,20,-3,LEAVES:0)
Block(4,20,4,LEAVES:0)
Block(4,20,5,LEAVES:0)
Block(4,20,6,LEAVES:0)
Block(4,21,-14,LEAVES:0)
Block(4,21,-11,LEAVES:0)
Block(4,21,-10,LEAVES:0)
Block(4,21,-9,LEAVES:0)
Block(4,21,-8,LEAVES:0)
Block(4,21,-5,LEAVES:0)
Block(4,21,-2,LEAVES:0)
Block(4,21,-1,LEAVES:0)
Block(4,21,0,LEAVES:0)
Block(4,21,1,LEAVES:0)
Block(4,21,2,LEAVES:0)
Block(4,21,3,LEAVES:0)
Block(4,21,5,LEAVES:0)
Block(4,22,-15,LEAVES:0)
Block(4,22,-14,LEAVES:0)
Block(4,22,-13,LEAVES:0)
Block(4,22,-12,LEAVES:0)
Block(4,22,-11,LEAVES:0)
Block(4,22,-10,LEAVES:0)
Block(4,22,-7,LEAVES:0)
Block(4,22,-6,17:12)
Block(4,22,-5,17:12)
Block(4,22,-2,LEAVES:0)
Block(4,22,-1,LEAVES:0)
Block(4,22,0,LEAVES:0)
Block(4,22,1,LEAVES:0)
Block(4,22,2,LEAVES:0)
Block(4,22,3,LEAVES:0)
Block(4,22,5,LEAVES:0)
Block(4,23,-14,LEAVES:0)
Block(4,23,-11,LEAVES:0)
Block(4,23,-10,LEAVES:0)
Block(4,23,-9,LEAVES:0)
Block(4,23,-8,LEAVES:0)
Block(4,23,-7,LEAVES:0)
Block(4,23,-6,LEAVES:0)
Block(4,23,-4,LEAVES:0)
Block(4,23,-3,LEAVES:0)
Block(4,23,-2,LEAVES:0)
Block(4,23,-1,LEAVES:0)
Block(4,23,0,LEAVES:0)
Block(4,23,1,LEAVES:0)
Block(4,23,2,LEAVES:0)
Block(4,23,3,LEAVES:0)
Block(4,24,-10,LEAVES:0)
Block(4,24,-9,LEAVES:0)
Block(4,24,-8,LEAVES:0)
Block(4,24,-7,LEAVES:0)
Block(4,24,-3,LEAVES:0)
Block(4,24,-1,LEAVES:0)
Block(4,24,0,LEAVES:0)
Block(4,24,1,LEAVES:0)
Block(4,24,2,LEAVES:0)
Block(4,24,5,LEAVES:0)
Block(4,25,-9,LEAVES:0)
Block(4,25,-8,LEAVES:0)
Block(4,25,-7,LEAVES:0)
Block(4,25,-3,LEAVES:0)
Block(4,25,-2,LEAVES:0)
Block(4,25,-1,LEAVES:0)
Block(4,25,0,LEAVES:0)
Block(4,25,1,LEAVES:0)
Block(4,26,-11,LEAVES:0)
Block(4,26,-8,LEAVES:0)
Block(4,26,-4,LEAVES:0)
Block(4,26,-3,LEAVES:0)
Block(4,26,-2,LEAVES:0)
Block(4,27,-10,LEAVES:0)
Block(4,27,-7,LEAVES:0)
Block(4,27,-6,LEAVES:0)
Block(4,27,-5,LEAVES:0)
Block(4,27,-3,LEAVES:0)
Block(4,27,-2,LEAVES:0)
Block(4,28,-9,LEAVES:0)
Block(4,28,-8,LEAVES:0)
Block(4,28,-7,LEAVES:0)
Block(4,28,-6,LEAVES:0)
Block(4,29,-8,LEAVES:0)
Block(4,29,-7,LEAVES:0)
Block(4,30,-9,LEAVES:0)
Block(5,4,-13,LEAVES:0)
Block(5,4,-12,LEAVES:0)
Block(5,4,-11,LEAVES:0)
Block(5,5,-12,LEAVES:0)
Block(5,5,-11,LEAVES:0)
Block(5,5,-10,LEAVES:0)
Block(5,5,-9,LEAVES:0)
Block(5,5,-8,LEAVES:0)
Block(5,6,-11,LEAVES:0)
Block(5,6,-9,LEAVES:0)
Block(5,6,-8,LEAVES:0)
Block(5,6,-7,LEAVES:0)
Block(5,6,-6,17:12)
Block(5,7,-13,LEAVES:0)
Block(5,7,-12,LEAVES:0)
Block(5,7,-11,LEAVES:0)
Block(5,7,-10,LEAVES:0)
Block(5,7,-8,LEAVES:0)
Block(5,7,-7,17:12)
Block(5,7,-5,LEAVES:0)
Block(5,7,-4,LEAVES:0)
Block(5,7,-3,LEAVES:0)
Block(5,8,-12,LEAVES:0)
Block(5,8,-11,LEAVES:0)
Block(5,8,-6,LEAVES:0)
Block(5,8,-5,LEAVES:0)
Block(5,8,-4,LEAVES:0)
Block(5,9,-9,LEAVES:0)
Block(5,9,-8,LEAVES:0)
Block(5,9,-6,LEAVES:0)
Block(5,9,-5,LEAVES:0)
Block(5,9,-4,LEAVES:0)
Block(5,10,-10,LEAVES:0)
Block(5,10,-9,LEAVES:0)
Block(5,10,-8,LEAVES:0)
Block(5,10,-6,LEAVES:0)
Block(5,10,-5,LEAVES:0)
Block(5,10,-3,LEAVES:0)
Block(5,10,-2,LEAVES:0)
Block(5,10,-1,LEAVES:0)
Block(5,10,0,LEAVES:0)
Block(5,10,1,LEAVES:0)
Block(5,10,2,LEAVES:0)
Block(5,11,-11,LEAVES:0)
Block(5,11,-10,LEAVES:0)
Block(5,11,-9,LEAVES:0)
Block(5,11,-5,LEAVES:0)
Block(5,11,-4,LEAVES:0)
Block(5,11,-3,LEAVES:0)
Block(5,11,-2,17:12)
Block(5,11,-1,17:12)
Block(5,11,1,LEAVES:0)
Block(5,12,-10,LEAVES:0)
Block(5,12,-7,LEAVES:0)
Block(5,12,-6,LEAVES:0)
Block(5,12,-5,LEAVES:0)
Block(5,12,-3,LEAVES:0)
Block(5,12,-2,LEAVES:0)
Block(5,12,-1,LEAVES:0)
Block(5,12,0,LEAVES:0)
Block(5,12,1,LEAVES:0)
Block(5,13,-9,LEAVES:0)
Block(5,13,-8,LEAVES:0)
Block(5,13,-7,LEAVES:0)
Block(5,13,-6,LEAVES:0)
Block(5,13,-3,LEAVES:0)
Block(5,13,-2,LEAVES:0)
Block(5,13,-1,LEAVES:0)
Block(5,13,0,LEAVES:0)
Block(5,13,3,LEAVES:0)
Block(5,14,-8,LEAVES:0)
Block(5,14,-7,LEAVES:0)
Block(5,14,-6,LEAVES:0)
Block(5,14,-5,17:12)
Block(5,14,-2,LEAVES:0)
Block(5,14,-1,LEAVES:0)
Block(5,14,2,LEAVES:0)
Block(5,14,3,LEAVES:0)
Block(5,14,4,LEAVES:0)
Block(5,15,-9,LEAVES:0)
Block(5,15,-8,LEAVES:0)
Block(5,15,-7,LEAVES:0)
Block(5,15,-6,17:12)
Block(5,15,-5,17:12)
Block(5,15,3,LEAVES:0)
Block(5,16,-8,LEAVES:0)
Block(5,16,-1,LEAVES:0)
Block(5,17,-9,LEAVES:0)
Block(5,17,-2,LEAVES:0)
Block(5,17,-1,LEAVES:0)
Block(5,17,0,LEAVES:0)
Block(5,17,1,LEAVES:0)
Block(5,18,-14,LEAVES:0)
Block(5,18,-13,LEAVES:0)
Block(5,18,-12,LEAVES:0)
Block(5,18,-10,LEAVES:0)
Block(5,18,-5,LEAVES:0)
Block(5,18,-3,LEAVES:0)
Block(5,18,-2,17:12)
Block(5,18,-1,17:12)
Block(5,18,0,LEAVES:0)
Block(5,18,1,LEAVES:0)
Block(5,18,2,LEAVES:0)
Block(5,18,3,LEAVES:0)
Block(5,18,4,LEAVES:0)
Block(5,19,-15,LEAVES:0)
Block(5,19,-14,LEAVES:0)
Block(5,19,-13,LEAVES:0)
Block(5,19,-11,LEAVES:0)
Block(5,19,-10,LEAVES:0)
Block(5,19,-9,LEAVES:0)
Block(5,19,-6,LEAVES:0)
Block(5,19,-5,LEAVES:0)
Block(5,19,-4,LEAVES:0)
Block(5,19,-2,17:12)
Block(5,19,1,LEAVES:0)
Block(5,19,3,LEAVES:0)
Block(5,19,4,LEAVES:0)
Block(5,19,5,LEAVES:0)
Block(5,19,6,LEAVES:0)
Block(5,20,-14,LEAVES:0)
Block(5,20,-12,LEAVES:0)
Block(5,20,-11,LEAVES:0)
Block(5,20,-10,LEAVES:0)
Block(5,20,-9,LEAVES:0)
Block(5,20,-5,LEAVES:0)
Block(5,20,-4,LEAVES:0)
Block(5,20,-3,LEAVES:0)
Block(5,20,-2,LEAVES:0)
Block(5,20,0,LEAVES:0)
Block(5,20,4,LEAVES:0)
Block(5,20,5,LEAVES:0)
Block(5,21,-11,LEAVES:0)
Block(5,21,-10,LEAVES:0)
Block(5,21,-9,17:12)
Block(5,21,-8,LEAVES:0)
Block(5,21,-6,LEAVES:0)
Block(5,21,-5,LEAVES:0)
Block(5,21,-4,LEAVES:0)
Block(5,21,-3,LEAVES:0)
Block(5,21,-2,LEAVES:0)
Block(5,21,-1,LEAVES:0)
Block(5,21,0,LEAVES:0)
Block(5,21,2,LEAVES:0)
Block(5,21,3,LEAVES:0)
Block(5,22,-14,LEAVES:0)
Block(5,22,-11,LEAVES:0)
Block(5,22,-10,LEAVES:0)
Block(5,22,-9,LEAVES:0)
Block(5,22,-8,LEAVES:0)
Block(5,22,-7,LEAVES:0)
Block(5,22,-6,LEAVES:0)
Block(5,22,-5,LEAVES:0)
Block(5,22,-3,LEAVES:0)
Block(5,22,-2,LEAVES:0)
Block(5,22,-1,LEAVES:0)
Block(5,22,0,LEAVES:0)
Block(5,22,1,LEAVES:0)
Block(5,23,-10,LEAVES:0)
Block(5,23,-9,LEAVES:0)
Block(5,23,-8,LEAVES:0)
Block(5,23,-7,LEAVES:0)
Block(5,23,-6,17:12)
Block(5,23,-4,17:12)
Block(5,23,-3,LEAVES:0)
Block(5,23,-2,LEAVES:0)
Block(5,23,0,LEAVES:0)
Block(5,23,1,LEAVES:0)
Block(5,23,2,LEAVES:0)
Block(5,24,-9,LEAVES:0)
Block(5,24,-8,LEAVES:0)
Block(5,24,-6,LEAVES:0)
Block(5,24,-4,LEAVES:0)
Block(5,24,1,LEAVES:0)
Block(5,24,2,LEAVES:0)
Block(5,24,3,LEAVES:0)
Block(5,25,-8,LEAVES:0)
Block(5,25,-2,LEAVES:0)
Block(5,25,2,LEAVES:0)
Block(5,26,-3,LEAVES:0)
Block(5,26,-2,LEAVES:0)
Block(5,26,-1,LEAVES:0)
Block(5,27,-6,LEAVES:0)
Block(5,27,-2,LEAVES:0)
Block(5,28,-7,LEAVES:0)
Block(6,4,-12,LEAVES:0)
Block(6,4,-9,LEAVES:0)
Block(6,4,-6,LEAVES:0)
Block(6,5,-11,LEAVES:0)
Block(6,5,-10,LEAVES:0)
Block(6,5,-9,LEAVES:0)
Block(6,5,-8,LEAVES:0)
Block(6,5,-6,17:12)
Block(6,6,-9,LEAVES:0)
Block(6,6,-8,LEAVES:0)
Block(6,6,-7,LEAVES:0)
Block(6,6,-6,17:12)
Block(6,7,-14,LEAVES:0)
Block(6,7,-13,LEAVES:0)
Block(6,7,-12,LEAVES:0)
Block(6,7,-8,LEAVES:0)
Block(6,7,-7,17:12)
Block(6,7,-4,LEAVES:0)
Block(6,8,-13,LEAVES:0)
Block(6,8,-12,LEAVES:0)
Block(6,8,-11,LEAVES:0)
Block(6,8,-10,17:12)
Block(6,8,-9,17:12)
Block(6,8,-8,17:12)
Block(6,8,-7,LEAVES:0)
Block(6,8,-5,LEAVES:0)
Block(6,8,-4,LEAVES:0)
Block(6,8,-3,LEAVES:0)
Block(6,9,-12,LEAVES:0)
Block(6,9,-10,LEAVES:0)
Block(6,9,-9,LEAVES:0)
Block(6,9,-8,LEAVES:0)
Block(6,9,-5,LEAVES:0)
Block(6,9,-4,LEAVES:0)
Block(6,9,-3,LEAVES:0)
Block(6,10,-9,LEAVES:0)
Block(6,10,-7,LEAVES:0)
Block(6,10,-6,LEAVES:0)
Block(6,10,-5,LEAVES:0)
Block(6,10,-2,LEAVES:0)
Block(6,10,-1,LEAVES:0)
Block(6,10,0,LEAVES:0)
Block(6,10,1,LEAVES:0)
Block(6,10,2,LEAVES:0)
Block(6,10,3,LEAVES:0)
Block(6,11,-10,LEAVES:0)
Block(6,11,-8,LEAVES:0)
Block(6,11,-6,LEAVES:0)
Block(6,11,-5,LEAVES:0)
Block(6,11,-4,LEAVES:0)
Block(6,11,-3,LEAVES:0)
Block(6,11,-2,LEAVES:0)
Block(6,11,-1,17:12)
Block(6,11,0,LEAVES:0)
Block(6,11,1,LEAVES:0)
Block(6,11,2,LEAVES:0)
Block(6,12,-8,17:12)
Block(6,12,-7,LEAVES:0)
Block(6,12,-6,LEAVES:0)
Block(6,12,-5,LEAVES:0)
Block(6,12,-3,LEAVES:0)
Block(6,12,-2,LEAVES:0)
Block(6,12,-1,17:12)
Block(6,12,0,LEAVES:0)
Block(6,12,1,LEAVES:0)
Block(6,13,-8,17:12)
Block(6,13,-7,LEAVES:0)
Block(6,13,-6,LEAVES:0)
Block(6,13,-5,17:12)
Block(6,13,-4,LEAVES:0)
Block(6,13,-3,LEAVES:0)
Block(6,13,-2,LEAVES:0)
Block(6,13,-1,LEAVES:0)
Block(6,13,2,LEAVES:0)
Block(6,13,3,LEAVES:0)
Block(6,13,4,LEAVES:0)
Block(6,14,-7,LEAVES:0)
Block(6,14,-6,LEAVES:0)
Block(6,14,-5,17:12)
Block(6,14,-3,LEAVES:0)
Block(6,14,-2,LEAVES:0)
Block(6,14,-1,LEAVES:0)
Block(6,14,3,LEAVES:0)
Block(6,14,4,LEAVES:0)
Block(6,14,5,LEAVES:0)
Block(6,15,-9,LEAVES:0)
Block(6,15,-8,LEAVES:0)
Block(6,15,-7,LEAVES:0)
Block(6,15,-6,17:12)
Block(6,15,-5,LEAVES:0)
Block(6,15,-2,LEAVES:0)
Block(6,15,4,LEAVES:0)
Block(6,16,-9,LEAVES:0)
Block(6,16,-8,LEAVES:0)
Block(6,16,-7,LEAVES:0)
Block(6,16,-4,LEAVES:0)
Block(6,17,-10,LEAVES:0)
Block(6,17,-9,LEAVES:0)
Block(6,17,-8,LEAVES:0)
Block(6,17,-1,LEAVES:0)
Block(6,17,0,LEAVES:0)
Block(6,18,-15,LEAVES:0)
Block(6,18,-14,LEAVES:0)
Block(6,18,-13,LEAVES:0)
Block(6,18,-9,LEAVES:0)
Block(6,18,-5,LEAVES:0)
Block(6,18,0,17:12)
Block(6,18,1,LEAVES:0)
Block(6,18,3,LEAVES:0)
Block(6,18,4,LEAVES:0)
Block(6,18,5,LEAVES:0)
Block(6,19,-14,LEAVES:0)
Block(6,19,-10,LEAVES:0)
Block(6,19,-5,LEAVES:0)
Block(6,19,-3,17:12)
Block(6,19,-2,17:12)
Block(6,19,-1,LEAVES:0)
Block(6,19,0,17:12)
Block(6,19,3,LEAVES:0)
Block(6,19,4,LEAVES:0)
Block(6,19,5,LEAVES:0)
Block(6,20,-11,LEAVES:0)
Block(6,20,-10,LEAVES:0)
Block(6,20,-9,LEAVES:0)
Block(6,20,-8,LEAVES:0)
Block(6,20,-5,LEAVES:0)
Block(6,20,-4,LEAVES:0)
Block(6,20,-3,LEAVES:0)
Block(6,20,-2,LEAVES:0)
Block(6,20,-1,LEAVES:0)
Block(6,20,0,LEAVES:0)
Block(6,20,1,LEAVES:0)
Block(6,20,4,LEAVES:0)
Block(6,21,-9,LEAVES:0)
Block(6,21,-8,LEAVES:0)
Block(6,21,-7,LEAVES:0)
Block(6,21,-6,LEAVES:0)
Block(6,21,-5,LEAVES:0)
Block(6,21,-2,LEAVES:0)
Block(6,21,-1,LEAVES:0)
Block(6,21,0,LEAVES:0)
Block(6,22,-12,LEAVES:0)
Block(6,22,-11,LEAVES:0)
Block(6,22,-10,LEAVES:0)
Block(6,22,-9,LEAVES:0)
Block(6,22,-8,LEAVES:0)
Block(6,22,-7,LEAVES:0)
Block(6,22,-6,LEAVES:0)
Block(6,22,-5,LEAVES:0)
Block(6,22,-4,LEAVES:0)
Block(6,22,-3,LEAVES:0)
Block(6,22,-2,LEAVES:0)
Block(6,22,-1,LEAVES:0)
Block(6,22,0,LEAVES:0)
Block(6,23,-11,LEAVES:0)
Block(6,23,-10,LEAVES:0)
Block(6,23,-9,LEAVES:0)
Block(6,23,-8,LEAVES:0)
Block(6,23,-5,LEAVES:0)
Block(6,23,-3,LEAVES:0)
Block(6,23,-2,LEAVES:0)
Block(6,23,-1,LEAVES:0)
Block(6,23,1,LEAVES:0)
Block(6,24,-10,LEAVES:0)
Block(6,24,-7,LEAVES:0)
Block(6,24,-6,LEAVES:0)
Block(6,24,-5,LEAVES:0)
Block(6,24,-4,LEAVES:0)
Block(6,24,-2,LEAVES:0)
Block(6,24,2,LEAVES:0)
Block(6,25,-6,LEAVES:0)
Block(6,25,-5,LEAVES:0)
Block(6,26,-3,LEAVES:0)
Block(6,26,-2,LEAVES:0)
Block(7,3,-6,LEAVES:0)
Block(7,4,-10,LEAVES:0)
Block(7,4,-9,LEAVES:0)
Block(7,4,-8,LEAVES:0)
Block(7,4,-7,LEAVES:0)
Block(7,4,-6,LEAVES:0)
Block(7,4,-5,LEAVES:0)
Block(7,5,-9,LEAVES:0)
Block(7,5,-8,LEAVES:0)
Block(7,5,-7,LEAVES:0)
Block(7,5,-6,17:12)
Block(7,5,-5,LEAVES:0)
Block(7,6,-8,LEAVES:0)
Block(7,6,-7,LEAVES:0)
Block(7,6,-6,LEAVES:0)
Block(7,7,-13,LEAVES:0)
Block(7,7,-11,LEAVES:0)
Block(7,7,-9,LEAVES:0)
Block(7,7,-8,LEAVES:0)
Block(7,7,-7,LEAVES:0)
Block(7,7,-4,LEAVES:0)
Block(7,8,-12,LEAVES:0)
Block(7,8,-9,LEAVES:0)
Block(7,8,-8,LEAVES:0)
Block(7,8,-7,LEAVES:0)
Block(7,8,-6,LEAVES:0)
Block(7,8,-4,LEAVES:0)
Block(7,9,-11,LEAVES:0)
Block(7,9,-10,LEAVES:0)
Block(7,9,-9,LEAVES:0)
Block(7,9,-7,LEAVES:0)
Block(7,9,-4,LEAVES:0)
Block(7,9,-3,LEAVES:0)
Block(7,9,-2,LEAVES:0)
Block(7,10,-10,LEAVES:0)
Block(7,10,-8,LEAVES:0)
Block(7,10,-7,LEAVES:0)
Block(7,10,-6,LEAVES:0)
Block(7,10,-3,LEAVES:0)
Block(7,10,-2,LEAVES:0)
Block(7,10,-1,LEAVES:0)
Block(7,10,0,LEAVES:0)
Block(7,10,1,LEAVES:0)
Block(7,10,2,LEAVES:0)
Block(7,11,-9,LEAVES:0)
Block(7,11,-8,LEAVES:0)
Block(7,11,-7,LEAVES:0)
Block(7,11,-6,LEAVES:0)
Block(7,11,-5,LEAVES:0)
Block(7,11,-4,LEAVES:0)
Block(7,11,-3,LEAVES:0)
Block(7,11,-2,LEAVES:0)
Block(7,11,1,LEAVES:0)
Block(7,12,-8,LEAVES:0)
Block(7,12,-7,LEAVES:0)
Block(7,12,-6,LEAVES:0)
Block(7,12,-3,LEAVES:0)
Block(7,12,-2,LEAVES:0)
Block(7,12,-1,17:12)
Block(7,13,-7,LEAVES:0)
Block(7,13,-6,LEAVES:0)
Block(7,13,-5,17:12)
Block(7,13,-3,LEAVES:0)
Block(7,13,-2,LEAVES:0)
Block(7,13,-1,LEAVES:0)
Block(7,13,1,LEAVES:0)
Block(7,13,3,LEAVES:0)
Block(7,14,-9,LEAVES:0)
Block(7,14,-8,LEAVES:0)
Block(7,14,-7,LEAVES:0)
Block(7,14,-6,LEAVES:0)
Block(7,14,-4,LEAVES:0)
Block(7,14,-3,LEAVES:0)
Block(7,14,-2,LEAVES:0)
Block(7,14,0,LEAVES:0)
Block(7,14,4,LEAVES:0)
Block(7,15,-10,LEAVES:0)
Block(7,15,-9,LEAVES:0)
Block(7,15,-8,LEAVES:0)
Block(7,15,-7,LEAVES:0)
Block(7,15,-6,LEAVES:0)
Block(7,15,-5,LEAVES:0)
Block(7,15,-4,LEAVES:0)
Block(7,15,-3,LEAVES:0)
Block(7,16,-9,LEAVES:0)
Block(7,16,-8,LEAVES:0)
Block(7,16,-7,LEAVES:0)
Block(7,16,-5,LEAVES:0)
Block(7,16,-4,LEAVES:0)
Block(7,16,-3,LEAVES:0)
Block(7,16,-1,LEAVES:0)
Block(7,17,-9,LEAVES:0)
Block(7,17,-8,LEAVES:0)
Block(7,17,-7,LEAVES:0)
Block(7,17,-5,LEAVES:0)
Block(7,17,-4,LEAVES:0)
Block(7,17,0,LEAVES:0)
Block(7,18,-14,LEAVES:0)
Block(7,18,-8,LEAVES:0)
Block(7,18,-6,LEAVES:0)
Block(7,18,-5,LEAVES:0)
Block(7,18,-4,LEAVES:0)
Block(7,18,-1,LEAVES:0)
Block(7,18,4,LEAVES:0)
Block(7,19,-5,LEAVES:0)
Block(7,19,-4,LEAVES:0)
Block(7,19,-2,LEAVES:0)
Block(7,19,-1,LEAVES:0)
Block(7,19,0,LEAVES:0)
Block(7,19,1,17:12)
Block(7,19,2,LEAVES:0)
Block(7,19,4,LEAVES:0)
Block(7,20,-9,LEAVES:0)
Block(7,20,-8,LEAVES:0)
Block(7,20,-7,LEAVES:0)
Block(7,20,-6,LEAVES:0)
Block(7,20,-5,LEAVES:0)
Block(7,20,-4,LEAVES:0)
Block(7,20,-2,LEAVES:0)
Block(7,20,-1,LEAVES:0)
Block(7,20,0,LEAVES:0)
Block(7,21,-8,LEAVES:0)
Block(7,21,-6,LEAVES:0)
Block(7,21,-5,LEAVES:0)
Block(7,21,-1,LEAVES:0)
Block(7,21,0,LEAVES:0)
Block(7,21,1,LEAVES:0)
Block(7,22,-11,LEAVES:0)
Block(7,22,-5,LEAVES:0)
Block(7,22,-3,LEAVES:0)
Block(7,22,-2,LEAVES:0)
Block(7,22,-1,LEAVES:0)
Block(7,22,0,LEAVES:0)
Block(7,23,-12,LEAVES:0)
Block(7,23,-11,LEAVES:0)
Block(7,23,-10,LEAVES:0)
Block(7,23,-2,LEAVES:0)
Block(7,24,-11,LEAVES:0)
Block(7,24,-8,LEAVES:0)
Block(7,24,-7,LEAVES:0)
Block(7,24,-6,LEAVES:0)
Block(7,25,-7,LEAVES:0)
Block(7,25,-6,LEAVES:0)
Block(7,25,-5,LEAVES:0)
Block(7,25,-3,LEAVES:0)
Block(7,26,-6,LEAVES:0)
Block(7,26,-4,LEAVES:0)
Block(7,26,-3,LEAVES:0)
Block(7,26,-2,LEAVES:0)
Block(7,27,-3,LEAVES:0)
Block(8,3,-7,LEAVES:0)
Block(8,3,-6,LEAVES:0)
Block(8,3,-5,LEAVES:0)
Block(8,4,-9,LEAVES:0)
Block(8,4,-6,LEAVES:0)
Block(8,4,-5,LEAVES:0)
Block(8,4,-4,LEAVES:0)
Block(8,5,-8,LEAVES:0)
Block(8,5,-5,LEAVES:0)
Block(8,6,-7,LEAVES:0)
Block(8,6,-4,LEAVES:0)
Block(8,7,-12,LEAVES:0)
Block(8,7,-11,LEAVES:0)
Block(8,7,-10,LEAVES:0)
Block(8,7,-8,LEAVES:0)
Block(8,7,-7,LEAVES:0)
Block(8,7,-6,LEAVES:0)
Block(8,7,-5,LEAVES:0)
Block(8,7,-4,LEAVES:0)
Block(8,7,-3,LEAVES:0)
Block(8,8,-11,LEAVES:0)
Block(8,8,-9,LEAVES:0)
Block(8,8,-8,LEAVES:0)
Block(8,8,-7,LEAVES:0)
Block(8,8,-4,LEAVES:0)
Block(8,9,-10,LEAVES:0)
Block(8,9,-8,LEAVES:0)
Block(8,9,-7,LEAVES:0)
Block(8,9,-6,LEAVES:0)
Block(8,9,-3,LEAVES:0)
Block(8,9,-2,LEAVES:0)
Block(8,9,-1,LEAVES:0)
Block(8,10,-7,LEAVES:0)
Block(8,10,-6,LEAVES:0)
Block(8,10,-5,LEAVES:0)
Block(8,10,-4,LEAVES:0)
Block(8,10,-3,LEAVES:0)
Block(8,10,-2,LEAVES:0)
Block(8,10,1,LEAVES:0)
Block(8,11,-10,LEAVES:0)
Block(8,11,-9,LEAVES:0)
Block(8,11,-8,LEAVES:0)
Block(8,11,-6,LEAVES:0)
Block(8,11,-4,LEAVES:0)
Block(8,11,-3,LEAVES:0)
Block(8,12,-9,LEAVES:0)
Block(8,12,-8,LEAVES:0)
Block(8,12,-7,LEAVES:0)
Block(8,12,-5,17:12)
Block(8,12,-4,LEAVES:0)
Block(8,13,-8,LEAVES:0)
Block(8,13,-7,LEAVES:0)
Block(8,13,-6,LEAVES:0)
Block(8,13,-5,LEAVES:0)
Block(8,13,-2,LEAVES:0)
Block(8,13,0,LEAVES:0)
Block(8,13,1,LEAVES:0)
Block(8,13,2,LEAVES:0)
Block(8,14,-10,LEAVES:0)
Block(8,14,-9,LEAVES:0)
Block(8,14,-8,LEAVES:0)
Block(8,14,-7,LEAVES:0)
Block(8,14,-6,LEAVES:0)
Block(8,14,-3,LEAVES:0)
Block(8,14,-1,LEAVES:0)
Block(8,14,0,LEAVES:0)
Block(8,14,1,LEAVES:0)
Block(8,15,-11,LEAVES:0)
Block(8,15,-10,LEAVES:0)
Block(8,15,-9,LEAVES:0)
Block(8,15,-8,LEAVES:0)
Block(8,15,-7,LEAVES:0)
Block(8,15,-6,LEAVES:0)
Block(8,15,-5,LEAVES:0)
Block(8,15,0,LEAVES:0)
Block(8,16,-10,LEAVES:0)
Block(8,16,-7,LEAVES:0)
Block(8,16,-6,LEAVES:0)
Block(8,16,-5,LEAVES:0)
Block(8,16,-4,LEAVES:0)
Block(8,16,-2,LEAVES:0)
Block(8,16,-1,LEAVES:0)
Block(8,16,0,LEAVES:0)
Block(8,17,-8,LEAVES:0)
Block(8,17,-6,LEAVES:0)
Block(8,17,-5,LEAVES:0)
Block(8,17,-4,LEAVES:0)
Block(8,17,-1,LEAVES:0)
Block(8,17,0,LEAVES:0)
Block(8,17,1,LEAVES:0)
Block(8,18,-5,LEAVES:0)
Block(8,18,-4,LEAVES:0)
Block(8,18,-3,LEAVES:0)
Block(8,18,-2,LEAVES:0)
Block(8,18,-1,LEAVES:0)
Block(8,18,0,LEAVES:0)
Block(8,19,-4,LEAVES:0)
Block(8,19,-3,LEAVES:0)
Block(8,19,-2,LEAVES:0)
Block(8,19,-1,LEAVES:0)
Block(8,19,0,LEAVES:0)
Block(8,19,1,LEAVES:0)
Block(8,20,-8,LEAVES:0)
Block(8,20,-5,LEAVES:0)
Block(8,20,-4,LEAVES:0)
Block(8,20,-3,LEAVES:0)
Block(8,20,-2,LEAVES:0)
Block(8,21,-6,LEAVES:0)
Block(8,21,-5,LEAVES:0)
Block(8,21,-4,LEAVES:0)
Block(8,21,0,LEAVES:0)
Block(8,21,2,LEAVES:0)
Block(8,22,-5,LEAVES:0)
Block(8,22,-2,LEAVES:0)
Block(8,23,-11,LEAVES:0)
Block(8,24,-7,LEAVES:0)
Block(8,25,-6,LEAVES:0)
Block(8,25,-4,LEAVES:0)
Block(8,25,-3,LEAVES:0)
Block(8,25,-2,LEAVES:0)
Block(8,26,-5,LEAVES:0)
Block(8,26,-4,LEAVES:0)
Block(8,26,-3,LEAVES:0)
Block(8,27,-4,LEAVES:0)
Block(9,3,-6,LEAVES:0)
Block(9,4,-5,LEAVES:0)
Block(9,6,-8,LEAVES:0)
Block(9,6,-7,LEAVES:0)
Block(9,6,-6,LEAVES:0)
Block(9,6,-5,LEAVES:0)
Block(9,6,-4,LEAVES:0)
Block(9,6,-3,LEAVES:0)
Block(9,7,-11,LEAVES:0)
Block(9,7,-10,LEAVES:0)
Block(9,7,-9,LEAVES:0)
Block(9,7,-8,LEAVES:0)
Block(9,7,-7,LEAVES:0)
Block(9,7,-6,LEAVES:0)
Block(9,7,-5,LEAVES:0)
Block(9,7,-4,LEAVES:0)
Block(9,8,-12,LEAVES:0)
Block(9,8,-11,LEAVES:0)
Block(9,8,-10,LEAVES:0)
Block(9,8,-8,LEAVES:0)
Block(9,8,-5,LEAVES:0)
Block(9,9,-11,LEAVES:0)
Block(9,9,-7,LEAVES:0)
Block(9,9,-2,LEAVES:0)
Block(9,10,-6,LEAVES:0)
Block(9,10,-3,LEAVES:0)
Block(9,11,-9,LEAVES:0)
Block(9,11,-7,LEAVES:0)
Block(9,11,-6,LEAVES:0)
Block(9,11,-5,LEAVES:0)
Block(9,11,-4,LEAVES:0)
Block(9,11,-3,LEAVES:0)
Block(9,12,-8,LEAVES:0)
Block(9,12,-7,LEAVES:0)
Block(9,12,-6,LEAVES:0)
Block(9,13,-8,LEAVES:0)
Block(9,13,-7,LEAVES:0)
Block(9,13,-6,LEAVES:0)
Block(9,13,-5,LEAVES:0)
Block(9,13,-4,LEAVES:0)
Block(9,13,1,LEAVES:0)
Block(9,14,-9,LEAVES:0)
Block(9,14,-7,LEAVES:0)
Block(9,14,-6,LEAVES:0)
Block(9,14,-5,LEAVES:0)
Block(9,14,0,LEAVES:0)
Block(9,14,1,LEAVES:0)
Block(9,14,2,LEAVES:0)
Block(9,15,-10,LEAVES:0)
Block(9,15,-7,LEAVES:0)
Block(9,15,-6,LEAVES:0)
Block(9,15,-5,LEAVES:0)
Block(9,15,1,LEAVES:0)
Block(9,16,-6,LEAVES:0)
Block(9,16,-5,LEAVES:0)
Block(9,16,-1,LEAVES:0)
Block(9,17,-7,LEAVES:0)
Block(9,17,-6,LEAVES:0)
Block(9,17,-5,LEAVES:0)
Block(9,17,-2,LEAVES:0)
Block(9,17,-1,LEAVES:0)
Block(9,17,0,LEAVES:0)
Block(9,18,-6,LEAVES:0)
Block(9,18,-4,LEAVES:0)
Block(9,18,-1,LEAVES:0)
Block(9,18,0,LEAVES:0)
Block(9,19,-2,LEAVES:0)
Block(9,20,-4,LEAVES:0)
Block(9,20,-3,LEAVES:0)
Block(9,20,-2,LEAVES:0)
Block(9,20,-1,LEAVES:0)
Block(9,20,2,LEAVES:0)
Block(9,21,-5,LEAVES:0)
Block(9,21,-2,LEAVES:0)
Block(9,21,1,LEAVES:0)
Block(9,21,2,LEAVES:0)
Block(9,21,3,LEAVES:0)
Block(9,22,2,LEAVES:0)
Block(9,25,-3,LEAVES:0)
Block(9,26,-4,LEAVES:0)
Block(10,6,-7,LEAVES:0)
Block(10,6,-4,LEAVES:0)
Block(10,7,-10,LEAVES:0)
Block(10,7,-8,LEAVES:0)
Block(10,7,-5,LEAVES:0)
Block(10,8,-11,LEAVES:0)
Block(10,10,-4,LEAVES:0)
Block(10,10,-3,LEAVES:0)
Block(10,10,-2,LEAVES:0)
Block(10,11,-8,LEAVES:0)
Block(10,11,-7,LEAVES:0)
Block(10,11,-6,LEAVES:0)
Block(10,11,-5,LEAVES:0)
Block(10,11,-4,LEAVES:0)
Block(10,11,-3,LEAVES:0)
Block(10,12,-7,LEAVES:0)
Block(10,12,-4,LEAVES:0)
Block(10,13,-9,LEAVES:0)
Block(10,13,-8,LEAVES:0)
Block(10,13,-7,LEAVES:0)
Block(10,13,-5,LEAVES:0)
Block(10,13,-4,LEAVES:0)
Block(10,13,-3,LEAVES:0)
Block(10,14,-8,LEAVES:0)
Block(10,14,-7,LEAVES:0)
Block(10,14,-6,LEAVES:0)
Block(10,14,-5,LEAVES:0)
Block(10,14,-4,LEAVES:0)
Block(10,14,1,LEAVES:0)
Block(10,15,-7,LEAVES:0)
Block(10,15,-6,LEAVES:0)
Block(10,15,-5,LEAVES:0)
Block(10,16,-7,LEAVES:0)
Block(10,16,-6,LEAVES:0)
Block(10,16,-5,LEAVES:0)
Block(10,17,-8,LEAVES:0)
Block(10,17,-7,LEAVES:0)
Block(10,17,-6,LEAVES:0)
Block(10,17,-1,LEAVES:0)
Block(10,18,-7,LEAVES:0)
Block(10,19,-3,LEAVES:0)
Block(10,19,-2,LEAVES:0)
Block(10,19,-1,LEAVES:0)
Block(10,20,-2,LEAVES:0)
Block(10,20,-1,LEAVES:0)
Block(10,20,0,LEAVES:0)
Block(10,20,1,LEAVES:0)
Block(10,20,2,LEAVES:0)
Block(10,20,3,LEAVES:0)
Block(10,21,-1,LEAVES:0)
Block(10,21,0,LEAVES:0)
Block(10,21,1,LEAVES:0)
Block(10,21,2,LEAVES:0)
Block(10,22,1,LEAVES:0)
Block(11,10,-5,LEAVES:0)
Block(11,10,-4,LEAVES:0)
Block(11,10,-3,LEAVES:0)
Block(11,11,-7,LEAVES:0)
Block(11,11,-4,LEAVES:0)
Block(11,13,-8,LEAVES:0)
Block(11,13,-4,LEAVES:0)
Block(11,14,-7,LEAVES:0)
Block(11,14,-5,LEAVES:0)
Block(11,16,-6,LEAVES:0)
Block(11,17,-7,LEAVES:0)
Block(11,19,-2,LEAVES:0)
Block(11,20,-1,LEAVES:0)
Block(11,20,2,LEAVES:0)
Block(11,21,1,LEAVES:0)
Block(12,10,-4,LEAVES:0)


#######################################################################
# +-----------------------------------------------------------------+ #
# |                             Entities                            | #
# +-----------------------------------------------------------------+ #
#######################################################################

# Entity() spawns an entity instead of a block. The entity is spawned only once when the BO3 is spawned.
# Entities are persistent by default so they don't de-spawn when no player is near, they are only unloaded.
# Usage: Entity(x,y,z,mobName,groupSize,NameTagOrNBTFileName) or Entity(x,y,z,mobName,groupSize)
# Use /tc entities or /otg entities to get a list of entities that can be used as mobName, this includes entities added by other mods.
# NameTagOrNBTFileName can be either a nametag for the mob or an nbt file (such as mymobinfo.nbt or mymobinfo.txt).
# When using a text file you can use the same mob spawning parameters used with the /summon command to equip the
# entity and give it custom attributes etc. You can copy the DATA part of a summon command including surrounding
# curly braces to a .txt file, for instance for: "/summon Skeleton x y z {DATA}"

#######################################################################
# +-----------------------------------------------------------------+ #
# |                            BO3 checks                           | #
# +-----------------------------------------------------------------+ #
#######################################################################

# Require a condition at a certain location in order for the BO3 to be spawned.
# BlockCheck(x,y,z,BlockName[,BlockName[,...]]) - one of the blocks must be at the location
# BlockCheckNot(x,y,z,BlockName[,BlockName[,...]]) - all the blocks must not be at the location
# LightCheck(x,y,z,minLightLevel,maxLightLevel) - light must be between min and max (inclusive)

# You can use "Solid" as a BlockName for matching all solid blocks or "All" to match all blocks that aren't air.

# Examples:
#   BlockCheck(0,-1,0,GRASS,DIRT)  Require grass or dirt just below the object
#   BlockCheck(0,-1,0,Solid)       Require any solid block just below the object
#   BlockCheck(0,-1,0,WOOL)        Require any type of wool just below the object
#   BlockCheck(0,-1,0,WOOL:0)      Require white wool just below the object
#   BlockCheckNot(0,-1,0,WOOL:0)   Require that there is no white wool below the object
#   LightCheck(0,0,0,0,LEAVES:0)          Require almost complete darkness just below the object

BlockCheck(0,-1,0,GRASS,DIRT)