
#######################################################################
# +-----------------------------------------------------------------+ #
# |                            BO3 object                           | #
# +-----------------------------------------------------------------+ #
#######################################################################

Author: LordSmellyPants

Description: No description given

Version: 3

SettingsMode: WriteWithoutComments


#######################################################################
# +-----------------------------------------------------------------+ #
# |                          Main settings                          | #
# +-----------------------------------------------------------------+ #
#######################################################################

Tree: false

Frequency: 10

Rarity: 100.0

RotateRandomly: true

SpawnHeight: highestSolidBlock

SpawnHeightOffset: -32

SpawnHeightVariance: 0

##############################
# Height Limits for the BO3. #
##############################

MinHeight: 0

MaxHeight: 66

######################
# Extrusion settings #
######################

ExtrudeMode: BottomDown

ExtrudeThroughBlocks: AIR

MaxBranchDepth: 10

ExcludedBiomes: All


#######################################################################
# +-----------------------------------------------------------------+ #
# |                      Source block settings                      | #
# +-----------------------------------------------------------------+ #
#######################################################################

SourceBlocks: GRASS:0,DIRT:0,GRAVEL,SAND:0,SAND:1,SANDSTONE:0,STONE:0,STONE:1,STONE:3,STONE:5,DIRT:1,CLAY,HARD_CLAY,STAINED_CLAY:0,RED_ROSE:0,RED_ROSE:1,RED_ROSE:2,RED_ROSE:3,RED_ROSE:4,RED_ROSE:5,RED_ROSE:6,RED_ROSE:7,RED_ROSE:8,BROWN_MUSHROOM,RED_MUSHROOM,DOUBLE_PLANT:0,DOUBLE_PLANT:1,DOUBLE_PLANT:2,DOUBLE_PLANT:3,DOUBLE_PLANT:4,DOUBLE_PLANT:5,LONG_GRASS:0,LONG_GRASS:1,LONG_GRASS:2,DEAD_BUSH,COAL_ORE,IRON_ORE,GOLD_ORE,REDSTONE_ORE,DIAMOND_ORE,LAPIS_ORE,EMERALD_ORE,VINE:0,AIR,STATIONARY_WATER:0

MaxPercentageOutsideSourceBlock: 20

OutsideSourceBlock: placeAnyway

DoReplaceBlocks: true

IsOTGPlus: false


#######################################################################
# +-----------------------------------------------------------------+ #
# |                              Blocks                             | #
# +-----------------------------------------------------------------+ #
#######################################################################

Block(-5,0,-4,STONE:1)
Block(-5,0,-2,STONE:1)
Block(-5,1,-4,STONE:1)
Block(-5,1,-3,STONE:1)
Block(-5,1,-2,STONE:1)
Block(-5,1,0,STONE:1)
Block(-5,1,1,STONE:1)
Block(-5,1,2,STONE:1)
Block(-5,1,3,STONE:1)
Block(-5,2,-4,STONE:1)
Block(-5,2,-3,STONE:1)
Block(-5,2,-2,STONE:1)
Block(-5,2,-1,STONE:1)
Block(-5,2,1,STONE:1)
Block(-5,2,2,STONE:1)
Block(-5,2,3,STONE:1)
Block(-5,3,-4,STONE:1)
Block(-5,3,-3,STONE:1)
Block(-5,3,-2,STONE:1)
Block(-5,3,-1,STONE:1)
Block(-5,3,0,STONE:1)
Block(-5,3,1,STONE:1)
Block(-5,3,2,STONE:1)
Block(-5,3,3,STONE:1)
Block(-5,4,-2,STONE:1)
Block(-5,4,-1,STONE:1)
Block(-4,-1,-2,STONE:1)
Block(-4,-1,-1,STONE:1)
Block(-4,0,-4,STONE:1)
Block(-4,0,-3,STONE:1)
Block(-4,0,-2,STONE:1)
Block(-4,0,-1,STONE:1)
Block(-4,0,0,STONE:1)
Block(-4,0,1,STONE:1)
Block(-4,0,2,STONE:1)
Block(-4,0,3,STONE:1)
Block(-4,0,4,STONE:1)
Block(-4,1,-5,STONE:1)
Block(-4,1,-4,STONE:1)
Block(-4,1,-3,STONE:1)
Block(-4,1,-2,STONE:1)
Block(-4,1,-1,STONE:1)
Block(-4,1,0,STONE:1)
Block(-4,1,1,STONE:1)
Block(-4,1,2,STONE:1)
Block(-4,1,3,STONE:1)
Block(-4,1,4,STONE:1)
Block(-4,2,-5,STONE:1)
Block(-4,2,-4,STONE:1)
Block(-4,2,-3,STONE:1)
Block(-4,2,-2,STONE:1)
Block(-4,2,-1,STONE:1)
Block(-4,2,0,STONE:1)
Block(-4,2,1,STONE:1)
Block(-4,2,2,STONE:1)
Block(-4,2,3,STONE:1)
Block(-4,2,4,STONE:1)
Block(-4,3,-5,STONE:1)
Block(-4,3,-4,STONE:1)
Block(-4,3,-3,STONE:1)
Block(-4,3,-2,STONE:1)
Block(-4,3,-1,STONE:1)
Block(-4,3,0,STONE:1)
Block(-4,3,1,STONE:1)
Block(-4,3,2,STONE:1)
Block(-4,3,3,STONE:1)
Block(-4,3,4,STONE:1)
Block(-4,4,-4,STONE:1)
Block(-4,4,-3,STONE:1)
Block(-4,4,-2,STONE:1)
Block(-4,4,-1,STONE:1)
Block(-4,4,0,STONE:1)
Block(-4,4,1,STONE:1)
Block(-4,4,2,STONE:1)
Block(-4,4,3,STONE:1)
Block(-4,5,-3,STONE:1)
Block(-4,5,-2,STONE:1)
Block(-4,5,-1,STONE:1)
Block(-4,5,0,STONE:1)
Block(-4,5,1,STONE:1)
Block(-4,6,-3,STONE:1)
Block(-4,6,-2,STONE:1)
Block(-3,-3,-1,STONE:1)
Block(-3,-2,-3,STONE:1)
Block(-3,-2,-2,STONE:1)
Block(-3,-2,-1,STONE:1)
Block(-3,-2,0,STONE:1)
Block(-3,-2,2,STONE:1)
Block(-3,-1,-3,STONE:1)
Block(-3,-1,-2,STONE:1)
Block(-3,-1,-1,STONE:1)
Block(-3,-1,0,STONE:1)
Block(-3,-1,1,STONE:1)
Block(-3,-1,2,STONE:1)
Block(-3,-1,3,STONE:1)
Block(-3,-1,4,STONE:1)
Block(-3,0,-5,STONE:1)
Block(-3,0,-4,STONE:1)
Block(-3,0,-3,STONE:1)
Block(-3,0,-2,STONE:1)
Block(-3,0,-1,STONE:1)
Block(-3,0,0,STONE:1)
Block(-3,0,1,STONE:1)
Block(-3,0,2,STONE:1)
Block(-3,0,3,STONE:1)
Block(-3,0,4,STONE:1)
Block(-3,1,-6,STONE:1)
Block(-3,1,-5,STONE:1)
Block(-3,1,-4,STONE:1)
Block(-3,1,-3,STONE:1)
Block(-3,1,-2,STONE:1)
Block(-3,1,-1,STONE:1)
Block(-3,1,0,STONE:1)
Block(-3,1,1,STONE:1)
Block(-3,1,2,STONE:1)
Block(-3,1,3,STONE:1)
Block(-3,1,4,STONE:1)
Block(-3,1,5,STONE:1)
Block(-3,2,-6,STONE:1)
Block(-3,2,-5,STONE:1)
Block(-3,2,-4,STONE:1)
Block(-3,2,-3,STONE:1)
Block(-3,2,-2,STONE:1)
Block(-3,2,-1,STONE:1)
Block(-3,2,0,STONE:1)
Block(-3,2,1,STONE:1)
Block(-3,2,2,STONE:1)
Block(-3,2,3,STONE:1)
Block(-3,2,4,STONE:1)
Block(-3,2,5,STONE:1)
Block(-3,3,-6,STONE:1)
Block(-3,3,-5,STONE:1)
Block(-3,3,-4,STONE:1)
Block(-3,3,-3,STONE:1)
Block(-3,3,-2,STONE:1)
Block(-3,3,-1,STONE:1)
Block(-3,3,0,STONE:1)
Block(-3,3,1,STONE:1)
Block(-3,3,2,STONE:1)
Block(-3,3,3,STONE:1)
Block(-3,3,4,STONE:1)
Block(-3,3,5,STONE:1)
Block(-3,4,-5,STONE:1)
Block(-3,4,-4,STONE:1)
Block(-3,4,-3,STONE:1)
Block(-3,4,-2,STONE:1)
Block(-3,4,-1,STONE:1)
Block(-3,4,0,STONE:1)
Block(-3,4,1,STONE:1)
Block(-3,4,2,STONE:1)
Block(-3,4,3,STONE:1)
Block(-3,4,4,STONE:1)
Block(-3,5,-4,STONE:1)
Block(-3,5,-3,STONE:1)
Block(-3,5,-2,STONE:1)
Block(-3,5,-1,STONE:1)
Block(-3,5,0,STONE:1)
Block(-3,5,1,STONE:1)
Block(-3,5,2,STONE:1)
Block(-3,5,3,STONE:1)
Block(-3,6,-4,STONE:1)
Block(-3,6,-3,STONE:1)
Block(-3,6,-2,STONE:1)
Block(-3,6,-1,STONE:1)
Block(-3,6,0,STONE:1)
Block(-3,6,1,STONE:1)
Block(-3,7,-3,STONE:1)
Block(-3,7,-2,STONE:1)
Block(-3,8,-3,STONE:1)
Block(-3,8,-2,STONE:1)
Block(-3,9,-3,STONE:1)
Block(-3,9,-2,STONE:1)
Block(-3,10,-3,STONE:1)
Block(-3,10,-2,STONE:1)
Block(-3,11,-2,STONE:1)
Block(-2,-3,-3,STONE:1)
Block(-2,-3,-2,STONE:1)
Block(-2,-3,-1,STONE:1)
Block(-2,-3,0,STONE:1)
Block(-2,-2,-4,STONE:1)
Block(-2,-2,-3,STONE:1)
Block(-2,-2,-2,STONE:1)
Block(-2,-2,-1,STONE:1)
Block(-2,-2,0,STONE:1)
Block(-2,-2,1,STONE:1)
Block(-2,-2,2,STONE:1)
Block(-2,-2,3,STONE:1)
Block(-2,-2,4,STONE:1)
Block(-2,-1,-4,STONE:1)
Block(-2,-1,-3,STONE:1)
Block(-2,-1,-2,STONE:1)
Block(-2,-1,-1,STONE:1)
Block(-2,-1,0,STONE:1)
Block(-2,-1,1,STONE:1)
Block(-2,-1,2,STONE:1)
Block(-2,-1,3,STONE:1)
Block(-2,-1,4,STONE:1)
Block(-2,0,-6,STONE:1)
Block(-2,0,-5,STONE:1)
Block(-2,0,-4,STONE:1)
Block(-2,0,-3,STONE:1)
Block(-2,0,-2,STONE:1)
Block(-2,0,-1,STONE:1)
Block(-2,0,0,STONE:1)
Block(-2,0,1,STONE:1)
Block(-2,0,2,STONE:1)
Block(-2,0,3,STONE:1)
Block(-2,0,4,STONE:1)
Block(-2,0,5,STONE:1)
Block(-2,0,6,STONE:1)
Block(-2,1,-7,STONE:1)
Block(-2,1,-6,STONE:1)
Block(-2,1,-5,STONE:1)
Block(-2,1,-4,STONE:1)
Block(-2,1,-3,STONE:1)
Block(-2,1,-2,STONE:1)
Block(-2,1,-1,STONE:1)
Block(-2,1,0,STONE:1)
Block(-2,1,1,STONE:1)
Block(-2,1,2,STONE:1)
Block(-2,1,3,STONE:1)
Block(-2,1,4,STONE:1)
Block(-2,1,5,STONE:1)
Block(-2,1,6,STONE:1)
Block(-2,2,-7,STONE:1)
Block(-2,2,-6,STONE:1)
Block(-2,2,-5,STONE:1)
Block(-2,2,-4,STONE:1)
Block(-2,2,-3,STONE:1)
Block(-2,2,-2,STONE:1)
Block(-2,2,-1,STONE:1)
Block(-2,2,0,STONE:1)
Block(-2,2,1,STONE:1)
Block(-2,2,2,STONE:1)
Block(-2,2,3,STONE:1)
Block(-2,2,4,STONE:1)
Block(-2,2,5,STONE:1)
Block(-2,2,6,STONE:1)
Block(-2,3,-7,STONE:1)
Block(-2,3,-6,STONE:1)
Block(-2,3,-5,STONE:1)
Block(-2,3,-4,STONE:1)
Block(-2,3,-3,STONE:1)
Block(-2,3,-2,STONE:1)
Block(-2,3,-1,STONE:1)
Block(-2,3,0,STONE:1)
Block(-2,3,1,STONE:1)
Block(-2,3,2,STONE:1)
Block(-2,3,3,STONE:1)
Block(-2,3,4,STONE:1)
Block(-2,3,5,STONE:1)
Block(-2,3,6,STONE:1)
Block(-2,4,-6,STONE:1)
Block(-2,4,-5,STONE:1)
Block(-2,4,-4,STONE:1)
Block(-2,4,-3,STONE:1)
Block(-2,4,-2,STONE:1)
Block(-2,4,-1,STONE:1)
Block(-2,4,0,STONE:1)
Block(-2,4,1,STONE:1)
Block(-2,4,2,STONE:1)
Block(-2,4,3,STONE:1)
Block(-2,4,4,STONE:1)
Block(-2,4,5,STONE:1)
Block(-2,5,-5,STONE:1)
Block(-2,5,-4,STONE:1)
Block(-2,5,-3,STONE:1)
Block(-2,5,-2,STONE:1)
Block(-2,5,-1,STONE:1)
Block(-2,5,0,STONE:1)
Block(-2,5,1,STONE:1)
Block(-2,5,2,STONE:1)
Block(-2,5,3,STONE:1)
Block(-2,5,4,STONE:1)
Block(-2,6,-4,STONE:1)
Block(-2,6,-3,STONE:1)
Block(-2,6,-2,STONE:1)
Block(-2,6,-1,STONE:1)
Block(-2,6,0,STONE:1)
Block(-2,6,1,STONE:1)
Block(-2,6,2,STONE:1)
Block(-2,6,3,STONE:1)
Block(-2,7,-4,STONE:1)
Block(-2,7,-3,STONE:1)
Block(-2,7,-2,STONE:1)
Block(-2,7,-1,STONE:1)
Block(-2,7,0,STONE:1)
Block(-2,7,1,STONE:1)
Block(-2,7,2,STONE:1)
Block(-2,8,-4,STONE:1)
Block(-2,8,-3,STONE:1)
Block(-2,8,-2,STONE:1)
Block(-2,8,-1,STONE:1)
Block(-2,8,0,STONE:1)
Block(-2,8,1,STONE:1)
Block(-2,8,2,STONE:1)
Block(-2,9,-3,STONE:1)
Block(-2,9,-2,STONE:1)
Block(-2,9,-1,STONE:1)
Block(-2,9,0,STONE:1)
Block(-2,9,1,STONE:1)
Block(-2,9,2,STONE:1)
Block(-2,10,-3,STONE:1)
Block(-2,10,-2,STONE:1)
Block(-2,10,-1,STONE:1)
Block(-2,10,0,STONE:1)
Block(-2,10,1,STONE:1)
Block(-2,11,-3,STONE:1)
Block(-2,11,-2,STONE:1)
Block(-2,11,-1,STONE:1)
Block(-2,11,0,STONE:1)
Block(-2,11,1,STONE:1)
Block(-2,12,-2,STONE:1)
Block(-2,12,-1,STONE:1)
Block(-2,12,0,STONE:1)
Block(-2,12,1,STONE:1)
Block(-2,13,-2,STONE:1)
Block(-2,13,-1,STONE:1)
Block(-2,13,0,STONE:1)
Block(-2,13,1,STONE:1)
Block(-2,14,-2,STONE:1)
Block(-2,14,-1,STONE:1)
Block(-2,14,0,STONE:1)
Block(-2,14,1,STONE:1)
Block(-2,15,-2,STONE:1)
Block(-2,15,-1,STONE:1)
Block(-2,15,0,STONE:1)
Block(-2,15,1,STONE:1)
Block(-2,16,-2,STONE:1)
Block(-2,16,-1,STONE:1)
Block(-2,16,0,STONE:1)
Block(-2,16,1,STONE:1)
Block(-2,17,-2,STONE:1)
Block(-2,17,-1,STONE:1)
Block(-2,17,0,STONE:1)
Block(-2,17,1,STONE:1)
Block(-2,18,-2,STONE:1)
Block(-2,18,-1,STONE:1)
Block(-2,18,0,STONE:1)
Block(-2,19,-1,STONE:1)
Block(-2,19,0,STONE:1)
Block(-2,20,-1,STONE:1)
Block(-2,20,0,STONE:1)
Block(-1,-3,-4,STONE:1)
Block(-1,-3,-3,STONE:1)
Block(-1,-3,-2,STONE:1)
Block(-1,-3,-1,STONE:1)
Block(-1,-3,0,STONE:1)
Block(-1,-3,1,STONE:1)
Block(-1,-2,-4,STONE:1)
Block(-1,-2,-3,STONE:1)
Block(-1,-2,-2,STONE:1)
Block(-1,-2,-1,STONE:1)
Block(-1,-2,0,STONE:1)
Block(-1,-2,1,STONE:1)
Block(-1,-2,2,STONE:1)
Block(-1,-2,3,STONE:1)
Block(-1,-2,4,STONE:1)
Block(-1,-1,-5,STONE:1)
Block(-1,-1,-4,STONE:1)
Block(-1,-1,-3,STONE:1)
Block(-1,-1,-2,STONE:1)
Block(-1,-1,-1,STONE:1)
Block(-1,-1,0,STONE:1)
Block(-1,-1,1,STONE:1)
Block(-1,-1,2,STONE:1)
Block(-1,-1,3,STONE:1)
Block(-1,-1,4,STONE:1)
Block(-1,0,-6,STONE:1)
Block(-1,0,-5,STONE:1)
Block(-1,0,-4,STONE:1)
Block(-1,0,-3,STONE:1)
Block(-1,0,-2,STONE:1)
Block(-1,0,-1,STONE:1)
Block(-1,0,0,STONE:1)
Block(-1,0,1,STONE:1)
Block(-1,0,2,STONE:1)
Block(-1,0,3,STONE:1)
Block(-1,0,4,STONE:1)
Block(-1,0,5,STONE:1)
Block(-1,1,-7,STONE:1)
Block(-1,1,-6,STONE:1)
Block(-1,1,-5,STONE:1)
Block(-1,1,-4,STONE:1)
Block(-1,1,-3,STONE:1)
Block(-1,1,-2,STONE:1)
Block(-1,1,-1,STONE:1)
Block(-1,1,0,STONE:1)
Block(-1,1,1,STONE:1)
Block(-1,1,2,STONE:1)
Block(-1,1,3,STONE:1)
Block(-1,1,4,STONE:1)
Block(-1,1,5,STONE:1)
Block(-1,1,6,STONE:1)
Block(-1,2,-7,STONE:1)
Block(-1,2,-6,STONE:1)
Block(-1,2,-5,STONE:1)
Block(-1,2,-4,STONE:1)
Block(-1,2,-3,STONE:1)
Block(-1,2,-2,STONE:1)
Block(-1,2,-1,STONE:1)
Block(-1,2,0,STONE:1)
Block(-1,2,1,STONE:1)
Block(-1,2,2,STONE:1)
Block(-1,2,3,STONE:1)
Block(-1,2,4,STONE:1)
Block(-1,2,5,STONE:1)
Block(-1,2,6,STONE:1)
Block(-1,3,-7,STONE:1)
Block(-1,3,-6,STONE:1)
Block(-1,3,-5,STONE:1)
Block(-1,3,-4,STONE:1)
Block(-1,3,-3,STONE:1)
Block(-1,3,-2,STONE:1)
Block(-1,3,-1,STONE:1)
Block(-1,3,0,STONE:1)
Block(-1,3,1,STONE:1)
Block(-1,3,2,STONE:1)
Block(-1,3,3,STONE:1)
Block(-1,3,4,STONE:1)
Block(-1,3,5,STONE:1)
Block(-1,3,6,STONE:1)
Block(-1,4,-7,STONE:1)
Block(-1,4,-6,STONE:1)
Block(-1,4,-5,STONE:1)
Block(-1,4,-4,STONE:1)
Block(-1,4,-3,STONE:1)
Block(-1,4,-2,STONE:1)
Block(-1,4,-1,STONE:1)
Block(-1,4,0,STONE:1)
Block(-1,4,1,STONE:1)
Block(-1,4,2,STONE:1)
Block(-1,4,3,STONE:1)
Block(-1,4,4,STONE:1)
Block(-1,4,5,STONE:1)
Block(-1,5,-6,STONE:1)
Block(-1,5,-5,STONE:1)
Block(-1,5,-4,STONE:1)
Block(-1,5,-3,STONE:1)
Block(-1,5,-2,STONE:1)
Block(-1,5,-1,STONE:1)
Block(-1,5,0,STONE:1)
Block(-1,5,1,STONE:1)
Block(-1,5,2,STONE:1)
Block(-1,5,3,STONE:1)
Block(-1,5,4,STONE:1)
Block(-1,6,-5,STONE:1)
Block(-1,6,-4,STONE:1)
Block(-1,6,-3,STONE:1)
Block(-1,6,-2,STONE:1)
Block(-1,6,-1,STONE:1)
Block(-1,6,0,STONE:1)
Block(-1,6,1,STONE:1)
Block(-1,6,2,STONE:1)
Block(-1,6,3,STONE:1)
Block(-1,6,4,STONE:1)
Block(-1,7,-4,STONE:1)
Block(-1,7,-3,STONE:1)
Block(-1,7,-2,STONE:1)
Block(-1,7,-1,STONE:1)
Block(-1,7,0,STONE:1)
Block(-1,7,1,STONE:1)
Block(-1,7,2,STONE:1)
Block(-1,7,3,STONE:1)
Block(-1,8,-4,STONE:1)
Block(-1,8,-3,STONE:1)
Block(-1,8,-2,STONE:1)
Block(-1,8,-1,STONE:1)
Block(-1,8,0,STONE:1)
Block(-1,8,1,STONE:1)
Block(-1,8,2,STONE:1)
Block(-1,9,-4,STONE:1)
Block(-1,9,-3,STONE:1)
Block(-1,9,-2,STONE:1)
Block(-1,9,-1,STONE:1)
Block(-1,9,0,STONE:1)
Block(-1,9,1,STONE:1)
Block(-1,9,2,STONE:1)
Block(-1,10,-4,STONE:1)
Block(-1,10,-3,STONE:1)
Block(-1,10,-2,STONE:1)
Block(-1,10,-1,STONE:1)
Block(-1,10,0,STONE:1)
Block(-1,10,1,STONE:1)
Block(-1,10,2,STONE:1)
Block(-1,11,-4,STONE:1)
Block(-1,11,-3,STONE:1)
Block(-1,11,-2,STONE:1)
Block(-1,11,-1,STONE:1)
Block(-1,11,0,STONE:1)
Block(-1,11,1,STONE:1)
Block(-1,11,2,STONE:1)
Block(-1,12,-4,STONE:1)
Block(-1,12,-3,STONE:1)
Block(-1,12,-2,STONE:1)
Block(-1,12,-1,STONE:1)
Block(-1,12,0,STONE:1)
Block(-1,12,1,STONE:1)
Block(-1,12,2,STONE:1)
Block(-1,13,-3,STONE:1)
Block(-1,13,-2,STONE:1)
Block(-1,13,-1,STONE:1)
Block(-1,13,0,STONE:1)
Block(-1,13,1,STONE:1)
Block(-1,13,2,STONE:1)
Block(-1,14,-3,STONE:1)
Block(-1,14,-2,STONE:1)
Block(-1,14,-1,STONE:1)
Block(-1,14,0,STONE:1)
Block(-1,14,1,STONE:1)
Block(-1,14,2,STONE:1)
Block(-1,15,-3,STONE:1)
Block(-1,15,-2,STONE:1)
Block(-1,15,-1,STONE:1)
Block(-1,15,0,STONE:1)
Block(-1,15,1,STONE:1)
Block(-1,15,2,STONE:1)
Block(-1,16,-3,STONE:1)
Block(-1,16,-2,STONE:1)
Block(-1,16,-1,STONE:1)
Block(-1,16,0,STONE:1)
Block(-1,16,1,STONE:1)
Block(-1,16,2,STONE:1)
Block(-1,17,-3,STONE:1)
Block(-1,17,-2,STONE:1)
Block(-1,17,-1,STONE:1)
Block(-1,17,0,STONE:1)
Block(-1,17,1,STONE:1)
Block(-1,17,2,STONE:1)
Block(-1,18,-3,STONE:1)
Block(-1,18,-2,STONE:1)
Block(-1,18,-1,STONE:1)
Block(-1,18,0,STONE:1)
Block(-1,18,1,STONE:1)
Block(-1,18,2,STONE:1)
Block(-1,19,-3,STONE:1)
Block(-1,19,-2,STONE:1)
Block(-1,19,-1,STONE:1)
Block(-1,19,0,STONE:1)
Block(-1,19,1,STONE:1)
Block(-1,19,2,STONE:1)
Block(-1,20,-3,STONE:1)
Block(-1,20,-2,STONE:1)
Block(-1,20,-1,STONE:1)
Block(-1,20,0,STONE:1)
Block(-1,20,1,STONE:1)
Block(-1,20,2,STONE:1)
Block(-1,21,-1,STONE:1)
Block(-1,21,0,STONE:1)
Block(-1,22,-1,STONE:1)
Block(-1,22,0,STONE:1)
Block(-1,23,-1,STONE:1)
Block(-1,23,0,STONE:1)
Block(-1,24,-1,STONE:1)
Block(-1,25,-1,STONE:1)
Block(-1,26,-1,STONE:1)
Block(-1,27,-1,STONE:1)
Block(-1,28,-1,STONE:1)
Block(0,-3,-3,STONE:1)
Block(0,-3,-2,STONE:1)
Block(0,-3,-1,STONE:1)
Block(0,-3,0,STONE:1)
Block(0,-3,1,STONE:1)
Block(0,-3,2,STONE:1)
Block(0,-2,-4,STONE:1)
Block(0,-2,-3,STONE:1)
Block(0,-2,-2,STONE:1)
Block(0,-2,-1,STONE:1)
Block(0,-2,0,STONE:1)
Block(0,-2,1,STONE:1)
Block(0,-2,2,STONE:1)
Block(0,-2,3,STONE:1)
Block(0,-2,4,STONE:1)
Block(0,-1,-5,STONE:1)
Block(0,-1,-4,STONE:1)
Block(0,-1,-3,STONE:1)
Block(0,-1,-2,STONE:1)
Block(0,-1,-1,STONE:1)
Block(0,-1,0,STONE:1)
Block(0,-1,1,STONE:1)
Block(0,-1,2,STONE:1)
Block(0,-1,3,STONE:1)
Block(0,-1,4,STONE:1)
Block(0,0,-5,STONE:1)
Block(0,0,-4,STONE:1)
Block(0,0,-3,STONE:1)
Block(0,0,-2,STONE:1)
Block(0,0,-1,STONE:1)
Block(0,0,0,STONE:1)
Block(0,0,1,STONE:1)
Block(0,0,2,STONE:1)
Block(0,0,3,STONE:1)
Block(0,0,4,STONE:1)
Block(0,0,5,STONE:1)
Block(0,1,-6,STONE:1)
Block(0,1,-5,STONE:1)
Block(0,1,-4,STONE:1)
Block(0,1,-3,STONE:1)
Block(0,1,-2,STONE:1)
Block(0,1,-1,STONE:1)
Block(0,1,0,STONE:1)
Block(0,1,1,STONE:1)
Block(0,1,2,STONE:1)
Block(0,1,3,STONE:1)
Block(0,1,4,STONE:1)
Block(0,1,5,STONE:1)
Block(0,1,6,STONE:1)
Block(0,2,-7,STONE:1)
Block(0,2,-6,STONE:1)
Block(0,2,-5,STONE:1)
Block(0,2,-4,STONE:1)
Block(0,2,-3,STONE:1)
Block(0,2,-2,STONE:1)
Block(0,2,-1,STONE:1)
Block(0,2,0,STONE:1)
Block(0,2,1,STONE:1)
Block(0,2,2,STONE:1)
Block(0,2,3,STONE:1)
Block(0,2,4,STONE:1)
Block(0,2,5,STONE:1)
Block(0,2,6,STONE:1)
Block(0,3,-7,STONE:1)
Block(0,3,-6,STONE:1)
Block(0,3,-5,STONE:1)
Block(0,3,-4,STONE:1)
Block(0,3,-3,STONE:1)
Block(0,3,-2,STONE:1)
Block(0,3,-1,STONE:1)
Block(0,3,0,STONE:1)
Block(0,3,1,STONE:1)
Block(0,3,2,STONE:1)
Block(0,3,3,STONE:1)
Block(0,3,4,STONE:1)
Block(0,3,5,STONE:1)
Block(0,3,6,STONE:1)
Block(0,4,-7,STONE:1)
Block(0,4,-6,STONE:1)
Block(0,4,-5,STONE:1)
Block(0,4,-4,STONE:1)
Block(0,4,-3,STONE:1)
Block(0,4,-2,STONE:1)
Block(0,4,-1,STONE:1)
Block(0,4,0,STONE:1)
Block(0,4,1,STONE:1)
Block(0,4,2,STONE:1)
Block(0,4,3,STONE:1)
Block(0,4,4,STONE:1)
Block(0,4,5,STONE:1)
Block(0,4,6,STONE:1)
Block(0,5,-6,STONE:1)
Block(0,5,-5,STONE:1)
Block(0,5,-4,STONE:1)
Block(0,5,-3,STONE:1)
Block(0,5,-2,STONE:1)
Block(0,5,-1,STONE:1)
Block(0,5,0,STONE:1)
Block(0,5,1,STONE:1)
Block(0,5,2,STONE:1)
Block(0,5,3,STONE:1)
Block(0,5,4,STONE:1)
Block(0,5,5,STONE:1)
Block(0,6,-6,STONE:1)
Block(0,6,-5,STONE:1)
Block(0,6,-4,STONE:1)
Block(0,6,-3,STONE:1)
Block(0,6,-2,STONE:1)
Block(0,6,-1,STONE:1)
Block(0,6,0,STONE:1)
Block(0,6,1,STONE:1)
Block(0,6,2,STONE:1)
Block(0,6,3,STONE:1)
Block(0,6,4,STONE:1)
Block(0,7,-5,STONE:1)
Block(0,7,-4,STONE:1)
Block(0,7,-3,STONE:1)
Block(0,7,-2,STONE:1)
Block(0,7,-1,STONE:1)
Block(0,7,0,STONE:1)
Block(0,7,1,STONE:1)
Block(0,7,2,STONE:1)
Block(0,7,3,STONE:1)
Block(0,8,-5,STONE:1)
Block(0,8,-4,STONE:1)
Block(0,8,-3,STONE:1)
Block(0,8,-2,STONE:1)
Block(0,8,-1,STONE:1)
Block(0,8,0,STONE:1)
Block(0,8,1,STONE:1)
Block(0,8,2,STONE:1)
Block(0,8,3,STONE:1)
Block(0,9,-4,STONE:1)
Block(0,9,-3,STONE:1)
Block(0,9,-2,STONE:1)
Block(0,9,-1,STONE:1)
Block(0,9,0,STONE:1)
Block(0,9,1,STONE:1)
Block(0,9,2,STONE:1)
Block(0,9,3,STONE:1)
Block(0,10,-4,STONE:1)
Block(0,10,-3,STONE:1)
Block(0,10,-2,STONE:1)
Block(0,10,-1,STONE:1)
Block(0,10,0,STONE:1)
Block(0,10,1,STONE:1)
Block(0,10,2,STONE:1)
Block(0,10,3,STONE:1)
Block(0,11,-4,STONE:1)
Block(0,11,-3,STONE:1)
Block(0,11,-2,STONE:1)
Block(0,11,-1,STONE:1)
Block(0,11,0,STONE:1)
Block(0,11,1,STONE:1)
Block(0,11,2,STONE:1)
Block(0,11,3,STONE:1)
Block(0,12,-4,STONE:1)
Block(0,12,-3,STONE:1)
Block(0,12,-2,STONE:1)
Block(0,12,-1,STONE:1)
Block(0,12,0,STONE:1)
Block(0,12,1,STONE:1)
Block(0,12,2,STONE:1)
Block(0,12,3,STONE:1)
Block(0,13,-3,STONE:1)
Block(0,13,-2,STONE:1)
Block(0,13,-1,STONE:1)
Block(0,13,0,STONE:1)
Block(0,13,1,STONE:1)
Block(0,13,2,STONE:1)
Block(0,13,3,STONE:1)
Block(0,14,-3,STONE:1)
Block(0,14,-2,STONE:1)
Block(0,14,-1,STONE:1)
Block(0,14,0,STONE:1)
Block(0,14,1,STONE:1)
Block(0,14,2,STONE:1)
Block(0,14,3,STONE:1)
Block(0,15,-3,STONE:1)
Block(0,15,-2,STONE:1)
Block(0,15,-1,STONE:1)
Block(0,15,0,STONE:1)
Block(0,15,1,STONE:1)
Block(0,15,2,STONE:1)
Block(0,15,3,STONE:1)
Block(0,16,-3,STONE:1)
Block(0,16,-2,STONE:1)
Block(0,16,-1,STONE:1)
Block(0,16,0,STONE:1)
Block(0,16,1,STONE:1)
Block(0,16,2,STONE:1)
Block(0,16,3,STONE:1)
Block(0,17,-3,STONE:1)
Block(0,17,-2,STONE:1)
Block(0,17,-1,STONE:1)
Block(0,17,0,STONE:1)
Block(0,17,1,STONE:1)
Block(0,17,2,STONE:1)
Block(0,17,3,STONE:1)
Block(0,18,-3,STONE:1)
Block(0,18,-2,STONE:1)
Block(0,18,-1,STONE:1)
Block(0,18,0,STONE:1)
Block(0,18,1,STONE:1)
Block(0,18,2,STONE:1)
Block(0,19,-3,STONE:1)
Block(0,19,-2,STONE:1)
Block(0,19,-1,STONE:1)
Block(0,19,0,STONE:1)
Block(0,19,1,STONE:1)
Block(0,19,2,STONE:1)
Block(0,20,-3,STONE:1)
Block(0,20,-2,STONE:1)
Block(0,20,-1,STONE:1)
Block(0,20,0,STONE:1)
Block(0,20,1,STONE:1)
Block(0,20,2,STONE:1)
Block(0,21,-2,STONE:1)
Block(0,21,-1,STONE:1)
Block(0,21,0,STONE:1)
Block(0,21,1,STONE:1)
Block(0,22,-2,STONE:1)
Block(0,22,-1,STONE:1)
Block(0,22,0,STONE:1)
Block(0,22,1,STONE:1)
Block(0,23,-2,STONE:1)
Block(0,23,-1,STONE:1)
Block(0,23,0,STONE:1)
Block(0,23,1,STONE:1)
Block(0,24,-2,STONE:1)
Block(0,24,-1,STONE:1)
Block(0,24,0,STONE:1)
Block(0,24,1,STONE:1)
Block(0,25,-2,STONE:1)
Block(0,25,-1,STONE:1)
Block(0,25,0,STONE:1)
Block(0,25,1,STONE:1)
Block(0,26,-2,STONE:1)
Block(0,26,-1,STONE:1)
Block(0,26,0,STONE:1)
Block(0,26,1,STONE:1)
Block(0,27,-2,STONE:1)
Block(0,27,-1,STONE:1)
Block(0,27,0,STONE:1)
Block(0,27,1,STONE:1)
Block(0,28,-2,STONE:1)
Block(0,28,-1,STONE:1)
Block(0,28,0,STONE:1)
Block(1,-3,-3,STONE:1)
Block(1,-3,-2,STONE:1)
Block(1,-3,-1,STONE:1)
Block(1,-3,0,STONE:1)
Block(1,-3,1,STONE:1)
Block(1,-3,2,STONE:1)
Block(1,-2,-5,STONE:1)
Block(1,-2,-4,STONE:1)
Block(1,-2,-3,STONE:1)
Block(1,-2,-2,STONE:1)
Block(1,-2,-1,STONE:1)
Block(1,-2,0,STONE:1)
Block(1,-2,1,STONE:1)
Block(1,-2,2,STONE:1)
Block(1,-2,3,STONE:1)
Block(1,-2,4,STONE:1)
Block(1,-1,-5,STONE:1)
Block(1,-1,-4,STONE:1)
Block(1,-1,-3,STONE:1)
Block(1,-1,-2,STONE:1)
Block(1,-1,-1,STONE:1)
Block(1,-1,0,STONE:1)
Block(1,-1,1,STONE:1)
Block(1,-1,2,STONE:1)
Block(1,-1,3,STONE:1)
Block(1,-1,4,STONE:1)
Block(1,-1,5,STONE:1)
Block(1,0,-6,STONE:1)
Block(1,0,-5,STONE:1)
Block(1,0,-4,STONE:1)
Block(1,0,-3,STONE:1)
Block(1,0,-2,STONE:1)
Block(1,0,-1,STONE:1)
Block(1,0,0,STONE:1)
Block(1,0,1,STONE:1)
Block(1,0,2,STONE:1)
Block(1,0,3,STONE:1)
Block(1,0,4,STONE:1)
Block(1,0,5,STONE:1)
Block(1,0,6,STONE:1)
Block(1,1,-7,STONE:1)
Block(1,1,-6,STONE:1)
Block(1,1,-5,STONE:1)
Block(1,1,-4,STONE:1)
Block(1,1,-3,STONE:1)
Block(1,1,-2,STONE:1)
Block(1,1,-1,STONE:1)
Block(1,1,0,STONE:1)
Block(1,1,1,STONE:1)
Block(1,1,2,STONE:1)
Block(1,1,3,STONE:1)
Block(1,1,4,STONE:1)
Block(1,1,5,STONE:1)
Block(1,1,6,STONE:1)
Block(1,1,7,STONE:1)
Block(1,2,-7,STONE:1)
Block(1,2,-6,STONE:1)
Block(1,2,-5,STONE:1)
Block(1,2,-4,STONE:1)
Block(1,2,-3,STONE:1)
Block(1,2,-2,STONE:1)
Block(1,2,-1,STONE:1)
Block(1,2,0,STONE:1)
Block(1,2,1,STONE:1)
Block(1,2,2,STONE:1)
Block(1,2,3,STONE:1)
Block(1,2,4,STONE:1)
Block(1,2,5,STONE:1)
Block(1,2,6,STONE:1)
Block(1,2,7,STONE:1)
Block(1,3,-7,STONE:1)
Block(1,3,-6,STONE:1)
Block(1,3,-5,STONE:1)
Block(1,3,-4,STONE:1)
Block(1,3,-3,STONE:1)
Block(1,3,-2,STONE:1)
Block(1,3,-1,STONE:1)
Block(1,3,0,STONE:1)
Block(1,3,1,STONE:1)
Block(1,3,2,STONE:1)
Block(1,3,3,STONE:1)
Block(1,3,4,STONE:1)
Block(1,3,5,STONE:1)
Block(1,3,6,STONE:1)
Block(1,3,7,STONE:1)
Block(1,4,-7,STONE:1)
Block(1,4,-6,STONE:1)
Block(1,4,-5,STONE:1)
Block(1,4,-4,STONE:1)
Block(1,4,-3,STONE:1)
Block(1,4,-2,STONE:1)
Block(1,4,-1,STONE:1)
Block(1,4,0,STONE:1)
Block(1,4,1,STONE:1)
Block(1,4,2,STONE:1)
Block(1,4,3,STONE:1)
Block(1,4,4,STONE:1)
Block(1,4,5,STONE:1)
Block(1,4,6,STONE:1)
Block(1,5,-6,STONE:1)
Block(1,5,-5,STONE:1)
Block(1,5,-4,STONE:1)
Block(1,5,-3,STONE:1)
Block(1,5,-2,STONE:1)
Block(1,5,-1,STONE:1)
Block(1,5,0,STONE:1)
Block(1,5,1,STONE:1)
Block(1,5,2,STONE:1)
Block(1,5,3,STONE:1)
Block(1,5,4,STONE:1)
Block(1,5,5,STONE:1)
Block(1,6,-6,STONE:1)
Block(1,6,-5,STONE:1)
Block(1,6,-4,STONE:1)
Block(1,6,-3,STONE:1)
Block(1,6,-2,STONE:1)
Block(1,6,-1,STONE:1)
Block(1,6,0,STONE:1)
Block(1,6,1,STONE:1)
Block(1,6,2,STONE:1)
Block(1,6,3,STONE:1)
Block(1,6,4,STONE:1)
Block(1,6,5,STONE:1)
Block(1,7,-4,STONE:1)
Block(1,7,-3,STONE:1)
Block(1,7,-2,STONE:1)
Block(1,7,-1,STONE:1)
Block(1,7,0,STONE:1)
Block(1,7,1,STONE:1)
Block(1,7,2,STONE:1)
Block(1,7,3,STONE:1)
Block(1,7,4,STONE:1)
Block(1,8,-4,STONE:1)
Block(1,8,-3,STONE:1)
Block(1,8,-2,STONE:1)
Block(1,8,-1,STONE:1)
Block(1,8,0,STONE:1)
Block(1,8,1,STONE:1)
Block(1,8,2,STONE:1)
Block(1,8,3,STONE:1)
Block(1,9,-4,STONE:1)
Block(1,9,-3,STONE:1)
Block(1,9,-2,STONE:1)
Block(1,9,-1,STONE:1)
Block(1,9,0,STONE:1)
Block(1,9,1,STONE:1)
Block(1,9,2,STONE:1)
Block(1,9,3,STONE:1)
Block(1,10,-4,STONE:1)
Block(1,10,-3,STONE:1)
Block(1,10,-2,STONE:1)
Block(1,10,-1,STONE:1)
Block(1,10,0,STONE:1)
Block(1,10,1,STONE:1)
Block(1,10,2,STONE:1)
Block(1,10,3,STONE:1)
Block(1,11,-4,STONE:1)
Block(1,11,-3,STONE:1)
Block(1,11,-2,STONE:1)
Block(1,11,-1,STONE:1)
Block(1,11,0,STONE:1)
Block(1,11,1,STONE:1)
Block(1,11,2,STONE:1)
Block(1,11,3,STONE:1)
Block(1,12,-4,STONE:1)
Block(1,12,-3,STONE:1)
Block(1,12,-2,STONE:1)
Block(1,12,-1,STONE:1)
Block(1,12,0,STONE:1)
Block(1,12,1,STONE:1)
Block(1,12,2,STONE:1)
Block(1,12,3,STONE:1)
Block(1,13,-4,STONE:1)
Block(1,13,-3,STONE:1)
Block(1,13,-2,STONE:1)
Block(1,13,-1,STONE:1)
Block(1,13,0,STONE:1)
Block(1,13,1,STONE:1)
Block(1,13,2,STONE:1)
Block(1,13,3,STONE:1)
Block(1,14,-3,STONE:1)
Block(1,14,-2,STONE:1)
Block(1,14,-1,STONE:1)
Block(1,14,0,STONE:1)
Block(1,14,1,STONE:1)
Block(1,14,2,STONE:1)
Block(1,14,3,STONE:1)
Block(1,15,-3,STONE:1)
Block(1,15,-2,STONE:1)
Block(1,15,-1,STONE:1)
Block(1,15,0,STONE:1)
Block(1,15,1,STONE:1)
Block(1,15,2,STONE:1)
Block(1,15,3,STONE:1)
Block(1,16,-3,STONE:1)
Block(1,16,-2,STONE:1)
Block(1,16,-1,STONE:1)
Block(1,16,0,STONE:1)
Block(1,16,1,STONE:1)
Block(1,16,2,STONE:1)
Block(1,16,3,STONE:1)
Block(1,17,-3,STONE:1)
Block(1,17,-2,STONE:1)
Block(1,17,-1,STONE:1)
Block(1,17,0,STONE:1)
Block(1,17,1,STONE:1)
Block(1,17,2,STONE:1)
Block(1,17,3,STONE:1)
Block(1,18,-3,STONE:1)
Block(1,18,-2,STONE:1)
Block(1,18,-1,STONE:1)
Block(1,18,0,STONE:1)
Block(1,18,1,STONE:1)
Block(1,18,2,STONE:1)
Block(1,18,3,STONE:1)
Block(1,19,-3,STONE:1)
Block(1,19,-2,STONE:1)
Block(1,19,-1,STONE:1)
Block(1,19,0,STONE:1)
Block(1,19,1,STONE:1)
Block(1,19,2,STONE:1)
Block(1,19,3,STONE:1)
Block(1,20,-3,STONE:1)
Block(1,20,-2,STONE:1)
Block(1,20,-1,STONE:1)
Block(1,20,0,STONE:1)
Block(1,20,1,STONE:1)
Block(1,20,2,STONE:1)
Block(1,20,3,STONE:1)
Block(1,21,-2,STONE:1)
Block(1,21,-1,STONE:1)
Block(1,21,0,STONE:1)
Block(1,21,1,STONE:1)
Block(1,21,2,STONE:1)
Block(1,22,-2,STONE:1)
Block(1,22,-1,STONE:1)
Block(1,22,0,STONE:1)
Block(1,22,1,STONE:1)
Block(1,22,2,STONE:1)
Block(1,23,-2,STONE:1)
Block(1,23,-1,STONE:1)
Block(1,23,0,STONE:1)
Block(1,23,1,STONE:1)
Block(1,23,2,STONE:1)
Block(1,24,-2,STONE:1)
Block(1,24,-1,STONE:1)
Block(1,24,0,STONE:1)
Block(1,24,1,STONE:1)
Block(1,25,-2,STONE:1)
Block(1,25,-1,STONE:1)
Block(1,25,0,STONE:1)
Block(1,25,1,STONE:1)
Block(1,26,-2,STONE:1)
Block(1,26,-1,STONE:1)
Block(1,26,0,STONE:1)
Block(1,26,1,STONE:1)
Block(1,27,-2,STONE:1)
Block(1,27,-1,STONE:1)
Block(1,27,0,STONE:1)
Block(1,27,1,STONE:1)
Block(1,28,-2,STONE:1)
Block(1,28,-1,STONE:1)
Block(1,28,0,STONE:1)
Block(1,28,1,STONE:1)
Block(2,-3,-2,STONE:1)
Block(2,-3,-1,STONE:1)
Block(2,-3,0,STONE:1)
Block(2,-3,1,STONE:1)
Block(2,-2,-4,STONE:1)
Block(2,-2,-3,STONE:1)
Block(2,-2,-2,STONE:1)
Block(2,-2,-1,STONE:1)
Block(2,-2,0,STONE:1)
Block(2,-2,1,STONE:1)
Block(2,-2,2,STONE:1)
Block(2,-1,-6,STONE:1)
Block(2,-1,-5,STONE:1)
Block(2,-1,-4,STONE:1)
Block(2,-1,-3,STONE:1)
Block(2,-1,-2,STONE:1)
Block(2,-1,-1,STONE:1)
Block(2,-1,0,STONE:1)
Block(2,-1,1,STONE:1)
Block(2,-1,2,STONE:1)
Block(2,-1,3,STONE:1)
Block(2,-1,4,STONE:1)
Block(2,0,-7,STONE:1)
Block(2,0,-6,STONE:1)
Block(2,0,-5,STONE:1)
Block(2,0,-4,STONE:1)
Block(2,0,-3,STONE:1)
Block(2,0,-2,STONE:1)
Block(2,0,-1,STONE:1)
Block(2,0,0,STONE:1)
Block(2,0,1,STONE:1)
Block(2,0,2,STONE:1)
Block(2,0,3,STONE:1)
Block(2,0,4,STONE:1)
Block(2,0,5,STONE:1)
Block(2,1,-7,STONE:1)
Block(2,1,-6,STONE:1)
Block(2,1,-5,STONE:1)
Block(2,1,-4,STONE:1)
Block(2,1,-3,STONE:1)
Block(2,1,-2,STONE:1)
Block(2,1,-1,STONE:1)
Block(2,1,0,STONE:1)
Block(2,1,1,STONE:1)
Block(2,1,2,STONE:1)
Block(2,1,3,STONE:1)
Block(2,1,4,STONE:1)
Block(2,1,5,STONE:1)
Block(2,1,6,STONE:1)
Block(2,1,7,STONE:1)
Block(2,2,-7,STONE:1)
Block(2,2,-6,STONE:1)
Block(2,2,-5,STONE:1)
Block(2,2,-4,STONE:1)
Block(2,2,-3,STONE:1)
Block(2,2,-2,STONE:1)
Block(2,2,-1,STONE:1)
Block(2,2,0,STONE:1)
Block(2,2,1,STONE:1)
Block(2,2,2,STONE:1)
Block(2,2,3,STONE:1)
Block(2,2,4,STONE:1)
Block(2,2,5,STONE:1)
Block(2,2,6,STONE:1)
Block(2,2,7,STONE:1)
Block(2,3,-7,STONE:1)
Block(2,3,-6,STONE:1)
Block(2,3,-5,STONE:1)
Block(2,3,-4,STONE:1)
Block(2,3,-3,STONE:1)
Block(2,3,-2,STONE:1)
Block(2,3,-1,STONE:1)
Block(2,3,0,STONE:1)
Block(2,3,1,STONE:1)
Block(2,3,2,STONE:1)
Block(2,3,3,STONE:1)
Block(2,3,4,STONE:1)
Block(2,3,5,STONE:1)
Block(2,3,6,STONE:1)
Block(2,3,7,STONE:1)
Block(2,4,-7,STONE:1)
Block(2,4,-6,STONE:1)
Block(2,4,-5,STONE:1)
Block(2,4,-4,STONE:1)
Block(2,4,-3,STONE:1)
Block(2,4,-2,STONE:1)
Block(2,4,-1,STONE:1)
Block(2,4,0,STONE:1)
Block(2,4,1,STONE:1)
Block(2,4,2,STONE:1)
Block(2,4,3,STONE:1)
Block(2,4,4,STONE:1)
Block(2,4,5,STONE:1)
Block(2,4,6,STONE:1)
Block(2,5,-6,STONE:1)
Block(2,5,-5,STONE:1)
Block(2,5,-4,STONE:1)
Block(2,5,-3,STONE:1)
Block(2,5,-2,STONE:1)
Block(2,5,-1,STONE:1)
Block(2,5,0,STONE:1)
Block(2,5,1,STONE:1)
Block(2,5,2,STONE:1)
Block(2,5,3,STONE:1)
Block(2,5,4,STONE:1)
Block(2,5,5,STONE:1)
Block(2,6,-5,STONE:1)
Block(2,6,-4,STONE:1)
Block(2,6,-3,STONE:1)
Block(2,6,-2,STONE:1)
Block(2,6,-1,STONE:1)
Block(2,6,0,STONE:1)
Block(2,6,1,STONE:1)
Block(2,6,2,STONE:1)
Block(2,6,3,STONE:1)
Block(2,6,4,STONE:1)
Block(2,6,5,STONE:1)
Block(2,7,-4,STONE:1)
Block(2,7,-3,STONE:1)
Block(2,7,-2,STONE:1)
Block(2,7,-1,STONE:1)
Block(2,7,0,STONE:1)
Block(2,7,1,STONE:1)
Block(2,7,2,STONE:1)
Block(2,7,3,STONE:1)
Block(2,7,4,STONE:1)
Block(2,8,-4,STONE:1)
Block(2,8,-3,STONE:1)
Block(2,8,-2,STONE:1)
Block(2,8,-1,STONE:1)
Block(2,8,0,STONE:1)
Block(2,8,1,STONE:1)
Block(2,8,2,STONE:1)
Block(2,8,3,STONE:1)
Block(2,9,-4,STONE:1)
Block(2,9,-3,STONE:1)
Block(2,9,-2,STONE:1)
Block(2,9,-1,STONE:1)
Block(2,9,0,STONE:1)
Block(2,9,1,STONE:1)
Block(2,9,2,STONE:1)
Block(2,9,3,STONE:1)
Block(2,10,-4,STONE:1)
Block(2,10,-3,STONE:1)
Block(2,10,-2,STONE:1)
Block(2,10,-1,STONE:1)
Block(2,10,0,STONE:1)
Block(2,10,1,STONE:1)
Block(2,10,2,STONE:1)
Block(2,10,3,STONE:1)
Block(2,11,-4,STONE:1)
Block(2,11,-3,STONE:1)
Block(2,11,-2,STONE:1)
Block(2,11,-1,STONE:1)
Block(2,11,0,STONE:1)
Block(2,11,1,STONE:1)
Block(2,11,2,STONE:1)
Block(2,12,-4,STONE:1)
Block(2,12,-3,STONE:1)
Block(2,12,-2,STONE:1)
Block(2,12,-1,STONE:1)
Block(2,12,0,STONE:1)
Block(2,12,1,STONE:1)
Block(2,12,2,STONE:1)
Block(2,13,-4,STONE:1)
Block(2,13,-3,STONE:1)
Block(2,13,-2,STONE:1)
Block(2,13,-1,STONE:1)
Block(2,13,0,STONE:1)
Block(2,13,1,STONE:1)
Block(2,13,2,STONE:1)
Block(2,14,-3,STONE:1)
Block(2,14,-2,STONE:1)
Block(2,14,-1,STONE:1)
Block(2,14,0,STONE:1)
Block(2,14,1,STONE:1)
Block(2,14,2,STONE:1)
Block(2,15,-3,STONE:1)
Block(2,15,-2,STONE:1)
Block(2,15,-1,STONE:1)
Block(2,15,0,STONE:1)
Block(2,15,1,STONE:1)
Block(2,15,2,STONE:1)
Block(2,16,-3,STONE:1)
Block(2,16,-2,STONE:1)
Block(2,16,-1,STONE:1)
Block(2,16,0,STONE:1)
Block(2,16,1,STONE:1)
Block(2,16,2,STONE:1)
Block(2,17,-3,STONE:1)
Block(2,17,-2,STONE:1)
Block(2,17,-1,STONE:1)
Block(2,17,0,STONE:1)
Block(2,17,1,STONE:1)
Block(2,17,2,STONE:1)
Block(2,18,-3,STONE:1)
Block(2,18,-2,STONE:1)
Block(2,18,-1,STONE:1)
Block(2,18,0,STONE:1)
Block(2,18,1,STONE:1)
Block(2,18,2,STONE:1)
Block(2,19,-2,STONE:1)
Block(2,19,-1,STONE:1)
Block(2,19,0,STONE:1)
Block(2,19,1,STONE:1)
Block(2,19,2,STONE:1)
Block(2,20,-2,STONE:1)
Block(2,20,-1,STONE:1)
Block(2,20,0,STONE:1)
Block(2,20,1,STONE:1)
Block(2,20,2,STONE:1)
Block(2,21,-1,STONE:1)
Block(2,21,0,STONE:1)
Block(2,21,1,STONE:1)
Block(2,22,-1,STONE:1)
Block(2,22,0,STONE:1)
Block(2,22,1,STONE:1)
Block(2,23,0,STONE:1)
Block(2,23,1,STONE:1)
Block(2,24,0,STONE:1)
Block(2,24,1,STONE:1)
Block(2,25,0,STONE:1)
Block(2,25,1,STONE:1)
Block(2,26,0,STONE:1)
Block(2,26,1,STONE:1)
Block(2,27,0,STONE:1)
Block(2,27,1,STONE:1)
Block(2,28,1,STONE:1)
Block(3,-3,-1,STONE:1)
Block(3,-3,0,STONE:1)
Block(3,-2,-3,STONE:1)
Block(3,-2,-2,STONE:1)
Block(3,-2,-1,STONE:1)
Block(3,-2,0,STONE:1)
Block(3,-2,1,STONE:1)
Block(3,-1,-5,STONE:1)
Block(3,-1,-4,STONE:1)
Block(3,-1,-3,STONE:1)
Block(3,-1,-2,STONE:1)
Block(3,-1,-1,STONE:1)
Block(3,-1,0,STONE:1)
Block(3,-1,1,STONE:1)
Block(3,-1,2,STONE:1)
Block(3,0,-6,STONE:1)
Block(3,0,-5,STONE:1)
Block(3,0,-4,STONE:1)
Block(3,0,-3,STONE:1)
Block(3,0,-2,STONE:1)
Block(3,0,-1,STONE:1)
Block(3,0,0,STONE:1)
Block(3,0,1,STONE:1)
Block(3,0,2,STONE:1)
Block(3,0,3,STONE:1)
Block(3,0,5,STONE:1)
Block(3,1,-6,STONE:1)
Block(3,1,-5,STONE:1)
Block(3,1,-4,STONE:1)
Block(3,1,-3,STONE:1)
Block(3,1,-2,STONE:1)
Block(3,1,-1,STONE:1)
Block(3,1,0,STONE:1)
Block(3,1,1,STONE:1)
Block(3,1,2,STONE:1)
Block(3,1,3,STONE:1)
Block(3,1,4,STONE:1)
Block(3,1,5,STONE:1)
Block(3,1,6,STONE:1)
Block(3,2,-7,STONE:1)
Block(3,2,-6,STONE:1)
Block(3,2,-5,STONE:1)
Block(3,2,-4,STONE:1)
Block(3,2,-3,STONE:1)
Block(3,2,-2,STONE:1)
Block(3,2,-1,STONE:1)
Block(3,2,0,STONE:1)
Block(3,2,1,STONE:1)
Block(3,2,2,STONE:1)
Block(3,2,3,STONE:1)
Block(3,2,4,STONE:1)
Block(3,2,5,STONE:1)
Block(3,2,6,STONE:1)
Block(3,2,7,STONE:1)
Block(3,3,-7,STONE:1)
Block(3,3,-6,STONE:1)
Block(3,3,-5,STONE:1)
Block(3,3,-4,STONE:1)
Block(3,3,-3,STONE:1)
Block(3,3,-2,STONE:1)
Block(3,3,-1,STONE:1)
Block(3,3,0,STONE:1)
Block(3,3,1,STONE:1)
Block(3,3,2,STONE:1)
Block(3,3,3,STONE:1)
Block(3,3,4,STONE:1)
Block(3,3,5,STONE:1)
Block(3,3,6,STONE:1)
Block(3,3,7,STONE:1)
Block(3,4,-6,STONE:1)
Block(3,4,-5,STONE:1)
Block(3,4,-4,STONE:1)
Block(3,4,-3,STONE:1)
Block(3,4,-2,STONE:1)
Block(3,4,-1,STONE:1)
Block(3,4,0,STONE:1)
Block(3,4,1,STONE:1)
Block(3,4,2,STONE:1)
Block(3,4,3,STONE:1)
Block(3,4,4,STONE:1)
Block(3,4,5,STONE:1)
Block(3,4,6,STONE:1)
Block(3,5,-5,STONE:1)
Block(3,5,-4,STONE:1)
Block(3,5,-3,STONE:1)
Block(3,5,-2,STONE:1)
Block(3,5,-1,STONE:1)
Block(3,5,0,STONE:1)
Block(3,5,1,STONE:1)
Block(3,5,2,STONE:1)
Block(3,5,3,STONE:1)
Block(3,5,4,STONE:1)
Block(3,5,5,STONE:1)
Block(3,6,-5,STONE:1)
Block(3,6,-4,STONE:1)
Block(3,6,-3,STONE:1)
Block(3,6,-2,STONE:1)
Block(3,6,-1,STONE:1)
Block(3,6,0,STONE:1)
Block(3,6,1,STONE:1)
Block(3,6,2,STONE:1)
Block(3,6,3,STONE:1)
Block(3,6,4,STONE:1)
Block(3,7,-4,STONE:1)
Block(3,7,-3,STONE:1)
Block(3,7,-2,STONE:1)
Block(3,7,-1,STONE:1)
Block(3,7,0,STONE:1)
Block(3,7,1,STONE:1)
Block(3,7,2,STONE:1)
Block(3,7,3,STONE:1)
Block(3,8,-4,STONE:1)
Block(3,8,-3,STONE:1)
Block(3,8,-2,STONE:1)
Block(3,8,-1,STONE:1)
Block(3,8,0,STONE:1)
Block(3,8,1,STONE:1)
Block(3,8,2,STONE:1)
Block(3,8,3,STONE:1)
Block(3,9,-4,STONE:1)
Block(3,9,-3,STONE:1)
Block(3,9,-2,STONE:1)
Block(3,9,-1,STONE:1)
Block(3,9,0,STONE:1)
Block(3,9,1,STONE:1)
Block(3,9,2,STONE:1)
Block(3,10,-4,STONE:1)
Block(3,10,-3,STONE:1)
Block(3,10,-2,STONE:1)
Block(3,10,-1,STONE:1)
Block(3,10,0,STONE:1)
Block(3,10,1,STONE:1)
Block(3,10,2,STONE:1)
Block(3,11,-4,STONE:1)
Block(3,11,-3,STONE:1)
Block(3,11,-2,STONE:1)
Block(3,11,-1,STONE:1)
Block(3,11,0,STONE:1)
Block(3,11,1,STONE:1)
Block(3,11,2,STONE:1)
Block(3,12,-4,STONE:1)
Block(3,12,-3,STONE:1)
Block(3,12,-2,STONE:1)
Block(3,12,-1,STONE:1)
Block(3,12,0,STONE:1)
Block(3,12,1,STONE:1)
Block(3,12,2,STONE:1)
Block(3,13,-2,STONE:1)
Block(3,13,-1,STONE:1)
Block(3,13,0,STONE:1)
Block(3,13,1,STONE:1)
Block(3,13,2,STONE:1)
Block(3,14,-2,STONE:1)
Block(3,14,-1,STONE:1)
Block(3,14,0,STONE:1)
Block(3,14,1,STONE:1)
Block(3,14,2,STONE:1)
Block(3,15,-2,STONE:1)
Block(3,15,-1,STONE:1)
Block(3,15,0,STONE:1)
Block(3,15,1,STONE:1)
Block(3,15,2,STONE:1)
Block(3,16,-2,STONE:1)
Block(3,16,-1,STONE:1)
Block(3,16,0,STONE:1)
Block(3,16,1,STONE:1)
Block(3,16,2,STONE:1)
Block(3,17,-2,STONE:1)
Block(3,17,-1,STONE:1)
Block(3,17,0,STONE:1)
Block(3,17,1,STONE:1)
Block(3,17,2,STONE:1)
Block(3,18,-2,STONE:1)
Block(3,18,-1,STONE:1)
Block(3,18,0,STONE:1)
Block(3,18,1,STONE:1)
Block(3,18,2,STONE:1)
Block(3,19,-2,STONE:1)
Block(3,19,-1,STONE:1)
Block(3,19,0,STONE:1)
Block(3,19,1,STONE:1)
Block(3,19,2,STONE:1)
Block(3,20,-2,STONE:1)
Block(3,20,-1,STONE:1)
Block(3,20,0,STONE:1)
Block(3,20,1,STONE:1)
Block(3,20,2,STONE:1)
Block(4,-2,-4,STONE:1)
Block(4,-2,-3,STONE:1)
Block(4,-2,-2,STONE:1)
Block(4,-2,-1,STONE:1)
Block(4,-2,0,STONE:1)
Block(4,-1,-4,STONE:1)
Block(4,-1,-3,STONE:1)
Block(4,-1,-2,STONE:1)
Block(4,-1,-1,STONE:1)
Block(4,-1,0,STONE:1)
Block(4,-1,1,STONE:1)
Block(4,0,-4,STONE:1)
Block(4,0,-3,STONE:1)
Block(4,0,-2,STONE:1)
Block(4,0,-1,STONE:1)
Block(4,0,0,STONE:1)
Block(4,0,1,STONE:1)
Block(4,0,2,STONE:1)
Block(4,0,3,STONE:1)
Block(4,0,4,STONE:1)
Block(4,1,-6,STONE:1)
Block(4,1,-5,STONE:1)
Block(4,1,-4,STONE:1)
Block(4,1,-3,STONE:1)
Block(4,1,-2,STONE:1)
Block(4,1,-1,STONE:1)
Block(4,1,0,STONE:1)
Block(4,1,1,STONE:1)
Block(4,1,2,STONE:1)
Block(4,1,3,STONE:1)
Block(4,1,4,STONE:1)
Block(4,1,5,STONE:1)
Block(4,2,-7,STONE:1)
Block(4,2,-6,STONE:1)
Block(4,2,-5,STONE:1)
Block(4,2,-4,STONE:1)
Block(4,2,-3,STONE:1)
Block(4,2,-2,STONE:1)
Block(4,2,-1,STONE:1)
Block(4,2,0,STONE:1)
Block(4,2,1,STONE:1)
Block(4,2,2,STONE:1)
Block(4,2,3,STONE:1)
Block(4,2,4,STONE:1)
Block(4,2,5,STONE:1)
Block(4,2,6,STONE:1)
Block(4,3,-7,STONE:1)
Block(4,3,-6,STONE:1)
Block(4,3,-5,STONE:1)
Block(4,3,-4,STONE:1)
Block(4,3,-3,STONE:1)
Block(4,3,-2,STONE:1)
Block(4,3,-1,STONE:1)
Block(4,3,0,STONE:1)
Block(4,3,1,STONE:1)
Block(4,3,2,STONE:1)
Block(4,3,3,STONE:1)
Block(4,3,4,STONE:1)
Block(4,3,5,STONE:1)
Block(4,3,6,STONE:1)
Block(4,4,-6,STONE:1)
Block(4,4,-5,STONE:1)
Block(4,4,-4,STONE:1)
Block(4,4,-3,STONE:1)
Block(4,4,-2,STONE:1)
Block(4,4,-1,STONE:1)
Block(4,4,0,STONE:1)
Block(4,4,1,STONE:1)
Block(4,4,2,STONE:1)
Block(4,4,3,STONE:1)
Block(4,4,4,STONE:1)
Block(4,4,5,STONE:1)
Block(4,5,-5,STONE:1)
Block(4,5,-4,STONE:1)
Block(4,5,-3,STONE:1)
Block(4,5,-2,STONE:1)
Block(4,5,-1,STONE:1)
Block(4,5,0,STONE:1)
Block(4,5,1,STONE:1)
Block(4,5,2,STONE:1)
Block(4,5,3,STONE:1)
Block(4,5,4,STONE:1)
Block(4,6,-4,STONE:1)
Block(4,6,-3,STONE:1)
Block(4,6,-2,STONE:1)
Block(4,6,-1,STONE:1)
Block(4,6,0,STONE:1)
Block(4,6,1,STONE:1)
Block(4,6,2,STONE:1)
Block(4,6,3,STONE:1)
Block(4,7,-4,STONE:1)
Block(4,7,-3,STONE:1)
Block(4,7,-2,STONE:1)
Block(4,7,-1,STONE:1)
Block(4,7,0,STONE:1)
Block(4,7,1,STONE:1)
Block(4,7,2,STONE:1)
Block(4,8,-3,STONE:1)
Block(4,8,-2,STONE:1)
Block(4,8,-1,STONE:1)
Block(4,8,0,STONE:1)
Block(4,8,1,STONE:1)
Block(4,8,2,STONE:1)
Block(4,9,-3,STONE:1)
Block(4,9,-2,STONE:1)
Block(4,9,-1,STONE:1)
Block(4,9,0,STONE:1)
Block(4,9,1,STONE:1)
Block(4,10,-3,STONE:1)
Block(4,10,-2,STONE:1)
Block(4,10,-1,STONE:1)
Block(4,10,0,STONE:1)
Block(4,11,-3,STONE:1)
Block(4,11,-2,STONE:1)
Block(4,11,-1,STONE:1)
Block(4,11,0,STONE:1)
Block(4,12,-3,STONE:1)
Block(4,12,-2,STONE:1)
Block(4,12,-1,STONE:1)
Block(4,12,0,STONE:1)
Block(4,13,-2,STONE:1)
Block(4,13,-1,STONE:1)
Block(4,14,-2,STONE:1)
Block(4,14,-1,STONE:1)
Block(4,15,-2,STONE:1)
Block(4,15,-1,STONE:1)
Block(4,16,-2,STONE:1)
Block(4,16,-1,STONE:1)
Block(4,17,-2,STONE:1)
Block(4,17,-1,STONE:1)
Block(4,18,-1,STONE:1)
Block(4,19,-1,STONE:1)
Block(4,20,-1,STONE:1)
Block(5,-2,-2,STONE:1)
Block(5,-2,-1,STONE:1)
Block(5,-1,-4,STONE:1)
Block(5,-1,-3,STONE:1)
Block(5,-1,-2,STONE:1)
Block(5,-1,-1,STONE:1)
Block(5,-1,0,STONE:1)
Block(5,-1,1,STONE:1)
Block(5,0,-5,STONE:1)
Block(5,0,-4,STONE:1)
Block(5,0,-3,STONE:1)
Block(5,0,-2,STONE:1)
Block(5,0,-1,STONE:1)
Block(5,0,0,STONE:1)
Block(5,0,1,STONE:1)
Block(5,0,2,STONE:1)
Block(5,0,3,STONE:1)
Block(5,1,-5,STONE:1)
Block(5,1,-4,STONE:1)
Block(5,1,-3,STONE:1)
Block(5,1,-2,STONE:1)
Block(5,1,-1,STONE:1)
Block(5,1,0,STONE:1)
Block(5,1,1,STONE:1)
Block(5,1,2,STONE:1)
Block(5,1,3,STONE:1)
Block(5,1,4,STONE:1)
Block(5,2,-6,STONE:1)
Block(5,2,-5,STONE:1)
Block(5,2,-4,STONE:1)
Block(5,2,-3,STONE:1)
Block(5,2,-2,STONE:1)
Block(5,2,-1,STONE:1)
Block(5,2,0,STONE:1)
Block(5,2,1,STONE:1)
Block(5,2,2,STONE:1)
Block(5,2,3,STONE:1)
Block(5,2,4,STONE:1)
Block(5,2,5,STONE:1)
Block(5,3,-6,STONE:1)
Block(5,3,-5,STONE:1)
Block(5,3,-4,STONE:1)
Block(5,3,-3,STONE:1)
Block(5,3,-2,STONE:1)
Block(5,3,-1,STONE:1)
Block(5,3,0,STONE:1)
Block(5,3,1,STONE:1)
Block(5,3,2,STONE:1)
Block(5,3,3,STONE:1)
Block(5,3,4,STONE:1)
Block(5,3,5,STONE:1)
Block(5,4,-5,STONE:1)
Block(5,4,-4,STONE:1)
Block(5,4,-3,STONE:1)
Block(5,4,-2,STONE:1)
Block(5,4,-1,STONE:1)
Block(5,4,0,STONE:1)
Block(5,4,1,STONE:1)
Block(5,4,2,STONE:1)
Block(5,4,3,STONE:1)
Block(5,4,4,STONE:1)
Block(5,5,-4,STONE:1)
Block(5,5,-3,STONE:1)
Block(5,5,-2,STONE:1)
Block(5,5,-1,STONE:1)
Block(5,5,0,STONE:1)
Block(5,5,1,STONE:1)
Block(5,5,2,STONE:1)
Block(5,5,3,STONE:1)
Block(5,6,-3,STONE:1)
Block(5,6,-2,STONE:1)
Block(5,6,-1,STONE:1)
Block(5,6,0,STONE:1)
Block(5,6,1,STONE:1)
Block(5,6,2,STONE:1)
Block(5,7,-2,STONE:1)
Block(5,7,-1,STONE:1)
Block(5,8,-2,STONE:1)
Block(5,8,-1,STONE:1)
Block(5,9,-2,STONE:1)
Block(5,10,-2,STONE:1)
Block(5,11,-2,STONE:1)
Block(6,-1,-3,STONE:1)
Block(6,-1,-2,STONE:1)
Block(6,-1,-1,STONE:1)
Block(6,-1,0,STONE:1)
Block(6,-1,1,STONE:1)
Block(6,0,-4,STONE:1)
Block(6,0,-3,STONE:1)
Block(6,0,-2,STONE:1)
Block(6,0,-1,STONE:1)
Block(6,0,0,STONE:1)
Block(6,0,1,STONE:1)
Block(6,0,2,STONE:1)
Block(6,1,-5,STONE:1)
Block(6,1,-4,STONE:1)
Block(6,1,-3,STONE:1)
Block(6,1,-2,STONE:1)
Block(6,1,-1,STONE:1)
Block(6,1,0,STONE:1)
Block(6,1,1,STONE:1)
Block(6,1,2,STONE:1)
Block(6,1,3,STONE:1)
Block(6,1,4,STONE:1)
Block(6,2,-5,STONE:1)
Block(6,2,-4,STONE:1)
Block(6,2,-3,STONE:1)
Block(6,2,-2,STONE:1)
Block(6,2,-1,STONE:1)
Block(6,2,0,STONE:1)
Block(6,2,1,STONE:1)
Block(6,2,2,STONE:1)
Block(6,2,3,STONE:1)
Block(6,2,4,STONE:1)
Block(6,3,-5,STONE:1)
Block(6,3,-4,STONE:1)
Block(6,3,-3,STONE:1)
Block(6,3,-2,STONE:1)
Block(6,3,-1,STONE:1)
Block(6,3,0,STONE:1)
Block(6,3,1,STONE:1)
Block(6,3,2,STONE:1)
Block(6,3,3,STONE:1)
Block(6,3,4,STONE:1)
Block(6,4,-4,STONE:1)
Block(6,4,-3,STONE:1)
Block(6,4,-2,STONE:1)
Block(6,4,-1,STONE:1)
Block(6,4,0,STONE:1)
Block(6,4,1,STONE:1)
Block(6,4,2,STONE:1)
Block(6,4,3,STONE:1)
Block(6,5,-2,STONE:1)
Block(6,5,-1,STONE:1)
Block(6,5,0,STONE:1)
Block(6,5,1,STONE:1)
Block(6,5,2,STONE:1)
Block(6,6,-2,STONE:1)
Block(7,0,-3,STONE:1)
Block(7,0,-2,STONE:1)
Block(7,0,-1,STONE:1)
Block(7,0,0,STONE:1)
Block(7,0,1,STONE:1)
Block(7,1,-4,STONE:1)
Block(7,1,-3,STONE:1)
Block(7,1,-2,STONE:1)
Block(7,1,-1,STONE:1)
Block(7,1,0,STONE:1)
Block(7,1,1,STONE:1)
Block(7,1,2,STONE:1)
Block(7,1,3,STONE:1)
Block(7,2,-4,STONE:1)
Block(7,2,-3,STONE:1)
Block(7,2,-2,STONE:1)
Block(7,2,-1,STONE:1)
Block(7,2,0,STONE:1)
Block(7,2,1,STONE:1)
Block(7,2,2,STONE:1)
Block(7,2,3,STONE:1)
Block(7,3,-4,STONE:1)
Block(7,3,-3,STONE:1)
Block(7,3,-2,STONE:1)
Block(7,3,-1,STONE:1)
Block(7,3,0,STONE:1)
Block(7,3,1,STONE:1)
Block(7,3,2,STONE:1)
Block(7,4,-2,STONE:1)
Block(7,4,-1,STONE:1)
Block(7,4,0,STONE:1)
Block(7,4,1,STONE:1)
Block(8,0,-1,STONE:1)
Block(8,1,-1,STONE:1)
Block(8,1,0,STONE:1)
Block(8,1,1,STONE:1)
Block(8,2,-1,STONE:1)
Block(8,2,0,STONE:1)
Block(8,2,1,STONE:1)
Block(8,2,2,STONE:1)
Block(8,3,-1,STONE:1)
Block(8,3,0,STONE:1)
Block(8,3,1,STONE:1)

#######################################################################
# +-----------------------------------------------------------------+ #
# |                            BO3 checks                           | #
# +-----------------------------------------------------------------+ #
#######################################################################

BlockCheck(0,-1,0,STONE:1)

#######################################################################
# +-----------------------------------------------------------------+ #
# |                             Branches                            | #
# +-----------------------------------------------------------------+ #
#######################################################################


#######################################################################
# +-----------------------------------------------------------------+ #
# |                             Entities                            | #
# +-----------------------------------------------------------------+ #
#######################################################################


#######################################################################
# +-----------------------------------------------------------------+ #
# |                            Particles                            | #
# +-----------------------------------------------------------------+ #
#######################################################################


#######################################################################
# +-----------------------------------------------------------------+ #
# |                             Spawners                            | #
# +-----------------------------------------------------------------+ #
#######################################################################


#######################################################################
# +-----------------------------------------------------------------+ #
# |                             ModData                             | #
# +-----------------------------------------------------------------+ #
#######################################################################

