#######################################################################
# +-----------------------------------------------------------------+ #
# |                            BO3 object                           | #
# +-----------------------------------------------------------------+ #
#######################################################################

# The descriptions in this file are accurate only for TerrainControl and OTG.
# For MCW and OTG+ these descriptions are only accurate if the BO3 is used as a CustomObject.
# MCW and OTG+ completely reimplemented CustomStructure, check the MCW/OTG+ documentation for more information.

# This is the config file of a custom object.
# If you add this object correctly to your BiomeConfigs, it will spawn in the world.

# This is the creator of this BO3 object
Author: Unknown

# A short description of this BO3 object
Description: This BO3 was converted from a schematic using OTGEdit. The author and description information of the schematic could not be found. If you know who the author of the schematic is then please add this information.

# The BO3 version, don't change this! It can be used by external applications to do a version check.
Version: 3

# The settings mode, WriteAll, WriteWithoutComments or WriteDisable. See WorldConfig.
SettingsMode: WriteDisable

#######################################################################
# +-----------------------------------------------------------------+ #
# |                          Main settings                          | #
# +-----------------------------------------------------------------+ #
#######################################################################

# This needs to be set to true to spawn the object in the Tree and Sapling resources.
Tree: true

# The frequency of the BO3 from 1 to 200. Tries this many times to spawn this BO3 when using the CustomObject(...) resource.
# Ignored by Tree(..), Sapling(..) and CustomStructure(..)
Frequency: 40

# The rarity of the BO3 from 0 to 100. Each spawn attempt has rarity% chance to succeed when using the CustomObject(...) resource.
# Ignored by Tree(..), Sapling(..) and CustomStructure(..)
Rarity: 100.0

# If you set this to true, the BO3 will be placed with a random rotation.
RotateRandomly: true

# The spawn height of the BO3 - randomY, highestBlock or highestSolidBlock.
SpawnHeight: highestSolidBlock

# The height limits for the BO3.
MinHeight: 60

MaxHeight: 100

# Objects can have other objects attached to it: branches. Branches can also
# have branches attached to it, which can also have branches, etc. This is the
# maximum branch depth for this objects.
MaxBranchDepth: 10

# When spawned with the UseWorld keyword, this BO3 should NOT spawn in the following biomes.
# If you writer.write the BO3 name directly in the BiomeConfigs, this will be ignored.
ExcludedBiomes: All

# To optimise this BO3 for faster loading times you can use Notepad++ to find/replace comments and abbreviate things.
# Notepad++ find/replace with regex:
# Find: ^[#;].* replace to nothing removes all lines starting with # 
# Find: ^\s*$ replace to nothing removes most empty lines 
# Notepad++ find/replace without regex:
# *Warning: This will only work for OTG 1.10.2 v21 / OTG 1.11.2 v6 or higher. B( is not recognised by lower versions.
# Find: Block( replace to B(

# The style of extrusion you wish to use - BottomDown, TopUp, None (Default)
ExtrudeMode: BottomDown

# The blocks to extrude your BO3 through
ExtrudeThroughBlocks: AIR

#######################################################################
# +-----------------------------------------------------------------+ #
# |                      Source block settings                      | #
# +-----------------------------------------------------------------+ #
#######################################################################

SourceBlocks: STONE:1,STONE:3,STONE:5,DIRT:1,DIRT:0,SAND:0,GRASS:0,DIRT:2,STATIONARY_WATER:0,HARD_CLAY,STAINED_CLAY:0,CLAY,SANDSTONE:0,SAND:1,AIR,STONE:0,GRAVEL,LONG_GRASS:0,LONG_GRASS:1,LONG_GRASS:2,DEAD_BUSH,YELLOW_FLOWER:0,RED_ROSE:0,BROWN_MUSHROOM,RED_MUSHROOM

MaxPercentageOutsideSourceBlock: 0

OutsideSourceBlock: placeAnyway

#######################################################################
# +-----------------------------------------------------------------+ #
# |                              Blocks                             | #
# +-----------------------------------------------------------------+ #
#######################################################################

# All the blocks used in the BO3 are listed here. Possible blocks:
# Block(x,y,z,id[.data][,nbtfile.nbt) or B(x,y,z,id[.data][,nbtfile.nbt)
# RandomBlock(x,y,z,id[:data][,nbtfile.nbt],chance[,id[:data][,nbtfile.nbt],chance[,...]])
# So RandomBlock(0,0,0,CHEST,chest.nbt,50,CHEST,anotherchest.nbt,100) will spawn a chest at
# the BO3 origin, and give it a 50% chance to have the contents of chest.nbt, or, if that
# fails, a 100% percent chance to have the contents of anotherchest.nbt.

Block(-8,30,-1,LEAVES:2)
Block(-8,30,1,LEAVES:2)
Block(-7,30,0,LEAVES:2)
Block(-7,30,1,17:14)
Block(-7,31,-2,LEAVES:2)
Block(-7,31,-1,LEAVES:2)
Block(-7,31,0,LEAVES:2)
Block(-7,31,1,LEAVES:2)
Block(-7,32,-1,LEAVES:2)
Block(-7,32,0,LEAVES:2)
Block(-6,29,0,17:14)
Block(-6,30,1,LEAVES:2)
Block(-6,30,2,LEAVES:2)
Block(-6,31,1,LEAVES:2)
Block(-6,32,-3,LEAVES:2)
Block(-6,32,-2,LEAVES:2)
Block(-6,32,-1,LEAVES:2)
Block(-6,32,0,LEAVES:2)
Block(-5,30,0,17:14)
Block(-5,31,-1,17:14)
Block(-5,31,1,LEAVES:2)
Block(-5,32,-3,LEAVES:2)
Block(-5,32,-2,LEAVES:2)
Block(-5,32,-1,LEAVES:2)
Block(-5,32,0,LEAVES:2)
Block(-5,32,1,LEAVES:2)
Block(-4,29,0,17:14)
Block(-4,29,5,LEAVES:2)
Block(-4,29,7,LEAVES:2)
Block(-4,30,0,17:14)
Block(-4,31,-2,LEAVES:2)
Block(-4,31,-1,LEAVES:2)
Block(-4,31,0,LEAVES:2)
Block(-4,32,1,LEAVES:2)
Block(-4,32,2,LEAVES:2)
Block(-4,32,4,LEAVES:2)
Block(-4,33,1,LEAVES:2)
Block(-3,29,-1,17:14)
Block(-3,29,0,17:14)
Block(-3,29,5,LEAVES:2)
Block(-3,29,6,LEAVES:2)
Block(-3,29,7,LEAVES:2)
Block(-3,29,8,LEAVES:2)
Block(-3,30,6,LEAVES:2)
Block(-3,31,-2,LEAVES:2)
Block(-3,31,-1,LEAVES:2)
Block(-3,32,1,LEAVES:2)
Block(-3,32,2,LEAVES:2)
Block(-3,32,3,LEAVES:2)
Block(-3,32,4,LEAVES:2)
Block(-3,32,5,LEAVES:2)
Block(-3,33,0,LEAVES:2)
Block(-3,33,2,LEAVES:2)
Block(-2,28,0,17:14)
Block(-2,29,-1,17:14)
Block(-2,29,0,17:14)
Block(-2,29,4,LEAVES:2)
Block(-2,29,5,LEAVES:2)
Block(-2,29,6,17:14)
Block(-2,29,7,LEAVES:2)
Block(-2,29,8,LEAVES:2)
Block(-2,29,9,LEAVES:2)
Block(-2,30,6,LEAVES:2)
Block(-2,30,8,LEAVES:2)
Block(-2,32,1,LEAVES:2)
Block(-2,32,2,LEAVES:2)
Block(-2,32,3,17:14)
Block(-2,32,4,LEAVES:2)
Block(-2,33,0,LEAVES:2)
Block(-2,33,3,LEAVES:2)
Block(-1,0,-1,17:2)
Block(-1,0,0,17:2)
Block(-1,0,1,17:2)
Block(-1,1,-1,17:2)
Block(-1,1,0,17:14)
Block(-1,1,1,17:2)
Block(-1,2,-1,17:14)
Block(-1,2,0,17:14)
Block(-1,2,1,17:14)
Block(-1,3,-1,17:14)
Block(-1,3,0,17:14)
Block(-1,3,1,17:14)
Block(-1,4,-1,17:14)
Block(-1,4,0,17:14)
Block(-1,4,1,17:14)
Block(-1,5,0,17:14)
Block(-1,5,1,17:14)
Block(-1,6,0,17:14)
Block(-1,6,1,17:14)
Block(-1,7,0,17:14)
Block(-1,7,1,17:14)
Block(-1,8,0,17:14)
Block(-1,8,1,17:14)
Block(-1,9,-1,17:14)
Block(-1,9,0,17:14)
Block(-1,9,1,17:14)
Block(-1,10,-1,17:14)
Block(-1,10,0,17:14)
Block(-1,10,1,17:14)
Block(-1,11,-1,17:14)
Block(-1,11,0,17:14)
Block(-1,12,-1,17:14)
Block(-1,12,0,17:14)
Block(-1,12,1,17:14)
Block(-1,13,-1,17:14)
Block(-1,13,0,17:14)
Block(-1,13,1,17:14)
Block(-1,14,-1,17:14)
Block(-1,14,0,17:14)
Block(-1,15,-1,17:14)
Block(-1,15,0,17:14)
Block(-1,16,0,17:14)
Block(-1,17,0,17:14)
Block(-1,18,0,17:14)
Block(-1,19,0,17:14)
Block(-1,20,0,17:14)
Block(-1,21,0,17:14)
Block(-1,22,0,17:14)
Block(-1,23,0,17:14)
Block(-1,24,-1,17:14)
Block(-1,24,0,17:14)
Block(-1,24,1,17:14)
Block(-1,25,-1,17:14)
Block(-1,25,0,17:14)
Block(-1,26,-1,17:14)
Block(-1,26,0,17:14)
Block(-1,27,-1,17:14)
Block(-1,27,0,17:14)
Block(-1,28,-1,17:14)
Block(-1,28,0,17:14)
Block(-1,28,1,17:14)
Block(-1,28,4,17:14)
Block(-1,28,5,17:14)
Block(-1,28,6,17:14)
Block(-1,29,-1,17:14)
Block(-1,29,0,17:14)
Block(-1,29,1,17:14)
Block(-1,29,2,17:14)
Block(-1,29,3,17:14)
Block(-1,29,4,LEAVES:2)
Block(-1,29,5,LEAVES:2)
Block(-1,29,6,LEAVES:2)
Block(-1,29,7,LEAVES:2)
Block(-1,29,8,LEAVES:2)
Block(-1,30,5,LEAVES:2)
Block(-1,30,7,LEAVES:2)
Block(-1,30,8,LEAVES:2)
Block(-1,31,2,17:14)
Block(-1,32,1,LEAVES:2)
Block(-1,32,2,LEAVES:2)
Block(-1,32,3,LEAVES:2)
Block(-1,33,0,LEAVES:2)
Block(0,0,-1,17:2)
Block(0,0,0,17:14)
Block(0,0,1,17:2)
Block(0,1,-1,17:14)
Block(0,1,0,17:2)
Block(0,1,1,17:14)
Block(0,2,-1,17:14)
Block(0,2,0,17:2)
Block(0,2,1,17:14)
Block(0,3,-1,17:14)
Block(0,3,0,17:14)
Block(0,3,1,17:14)
Block(0,4,-1,17:14)
Block(0,4,0,17:14)
Block(0,4,1,17:14)
Block(0,5,-1,17:14)
Block(0,5,0,17:14)
Block(0,5,1,17:14)
Block(0,6,-1,17:14)
Block(0,6,0,17:14)
Block(0,6,1,17:14)
Block(0,7,-1,17:14)
Block(0,7,0,17:14)
Block(0,7,1,17:14)
Block(0,8,-1,17:14)
Block(0,8,0,17:14)
Block(0,8,1,17:14)
Block(0,9,-1,17:14)
Block(0,9,0,17:14)
Block(0,9,1,17:14)
Block(0,10,-1,17:14)
Block(0,10,0,17:14)
Block(0,10,1,17:14)
Block(0,11,-1,17:14)
Block(0,11,0,17:14)
Block(0,11,1,17:14)
Block(0,12,-1,17:14)
Block(0,12,0,17:14)
Block(0,12,1,17:14)
Block(0,13,-1,17:14)
Block(0,13,0,17:14)
Block(0,13,1,17:14)
Block(0,14,-1,17:14)
Block(0,14,0,17:14)
Block(0,14,1,17:14)
Block(0,15,-1,17:14)
Block(0,15,0,17:14)
Block(0,15,1,17:14)
Block(0,16,-1,17:14)
Block(0,16,0,17:14)
Block(0,16,1,17:14)
Block(0,17,-1,17:14)
Block(0,17,0,17:14)
Block(0,17,1,17:14)
Block(0,18,-1,17:14)
Block(0,18,0,17:14)
Block(0,18,1,17:14)
Block(0,19,-1,17:14)
Block(0,19,0,17:14)
Block(0,19,1,17:14)
Block(0,20,-1,17:14)
Block(0,20,0,17:14)
Block(0,20,1,17:14)
Block(0,21,-1,17:14)
Block(0,21,0,17:14)
Block(0,21,1,17:14)
Block(0,22,-1,17:14)
Block(0,22,0,17:14)
Block(0,22,1,17:14)
Block(0,23,-1,17:14)
Block(0,23,0,17:14)
Block(0,23,1,17:14)
Block(0,24,-1,17:14)
Block(0,24,0,17:14)
Block(0,24,1,17:14)
Block(0,25,-1,17:14)
Block(0,25,0,17:14)
Block(0,25,1,17:14)
Block(0,26,-1,17:14)
Block(0,26,0,17:14)
Block(0,26,1,17:14)
Block(0,27,-1,17:14)
Block(0,27,0,17:14)
Block(0,27,1,17:14)
Block(0,28,-2,17:14)
Block(0,28,-1,17:14)
Block(0,28,0,17:14)
Block(0,28,1,17:14)
Block(0,29,-3,17:14)
Block(0,29,-2,17:14)
Block(0,29,-1,17:14)
Block(0,29,0,17:14)
Block(0,29,1,17:14)
Block(0,29,6,LEAVES:2)
Block(0,29,7,17:14)
Block(0,29,8,LEAVES:2)
Block(0,29,9,LEAVES:2)
Block(0,30,-6,LEAVES:2)
Block(0,30,-5,LEAVES:2)
Block(0,30,0,17:14)
Block(0,30,6,LEAVES:2)
Block(0,30,7,LEAVES:2)
Block(0,31,-5,LEAVES:2)
Block(0,31,-4,LEAVES:2)
Block(0,31,2,17:14)
Block(0,31,3,LEAVES:2)
Block(0,32,1,LEAVES:2)
Block(0,32,2,LEAVES:2)
Block(0,32,3,LEAVES:2)
Block(0,32,4,LEAVES:2)
Block(1,0,-1,17:2)
Block(1,0,0,17:2)
Block(1,0,1,17:2)
Block(1,1,-1,17:14)
Block(1,1,0,17:2)
Block(1,1,1,17:14)
Block(1,2,-1,17:14)
Block(1,2,0,17:14)
Block(1,2,1,17:14)
Block(1,3,-1,17:14)
Block(1,3,0,17:14)
Block(1,3,1,17:14)
Block(1,4,-1,17:14)
Block(1,4,0,17:14)
Block(1,4,1,17:14)
Block(1,5,-1,17:14)
Block(1,5,0,17:14)
Block(1,5,1,17:14)
Block(1,6,-1,17:14)
Block(1,6,0,17:14)
Block(1,6,1,17:14)
Block(1,7,-1,17:14)
Block(1,7,0,17:14)
Block(1,7,1,17:14)
Block(1,8,0,17:14)
Block(1,8,1,17:14)
Block(1,9,0,17:14)
Block(1,9,1,17:14)
Block(1,10,0,17:14)
Block(1,11,0,17:14)
Block(1,12,0,17:14)
Block(1,13,0,17:14)
Block(1,14,0,17:14)
Block(1,14,1,17:14)
Block(1,15,0,17:14)
Block(1,15,1,17:14)
Block(1,16,-1,17:14)
Block(1,16,0,17:14)
Block(1,16,1,17:14)
Block(1,17,-1,17:14)
Block(1,17,0,17:14)
Block(1,17,1,17:14)
Block(1,18,-1,17:14)
Block(1,18,0,17:14)
Block(1,18,1,17:14)
Block(1,19,-1,17:14)
Block(1,19,0,17:14)
Block(1,19,1,17:14)
Block(1,20,0,17:14)
Block(1,21,0,17:14)
Block(1,22,0,17:14)
Block(1,23,0,17:14)
Block(1,24,0,17:14)
Block(1,25,0,17:14)
Block(1,26,0,17:14)
Block(1,27,0,17:14)
Block(1,28,-1,17:14)
Block(1,28,0,17:14)
Block(1,29,-4,17:14)
Block(1,29,-3,17:14)
Block(1,29,-1,17:14)
Block(1,29,0,17:14)
Block(1,29,7,LEAVES:2)
Block(1,29,8,LEAVES:2)
Block(1,30,-6,LEAVES:2)
Block(1,30,-5,LEAVES:2)
Block(1,30,-4,LEAVES:2)
Block(1,30,-3,LEAVES:2)
Block(1,30,1,17:14)
Block(1,31,-5,LEAVES:2)
Block(1,31,-4,LEAVES:2)
Block(1,31,1,17:14)
Block(1,32,0,17:14)
Block(1,32,2,LEAVES:2)
Block(1,33,0,LEAVES:2)
Block(1,33,2,LEAVES:2)
Block(1,33,3,LEAVES:2)
Block(2,28,0,17:14)
Block(2,29,-1,17:14)
Block(2,29,0,17:14)
Block(2,29,7,LEAVES:2)
Block(2,30,-7,LEAVES:2)
Block(2,30,-6,LEAVES:2)
Block(2,30,-5,17:14)
Block(2,30,-4,LEAVES:2)
Block(2,30,-3,LEAVES:2)
Block(2,31,-6,LEAVES:2)
Block(2,31,-5,LEAVES:2)
Block(2,31,-4,LEAVES:2)
Block(2,31,1,17:14)
Block(2,32,-2,LEAVES:2)
Block(2,32,-1,LEAVES:2)
Block(2,32,0,LEAVES:2)
Block(2,32,1,LEAVES:2)
Block(2,32,2,LEAVES:2)
Block(2,33,-1,LEAVES:2)
Block(2,33,0,LEAVES:2)
Block(3,29,-1,17:14)
Block(3,29,0,17:14)
Block(3,30,-7,LEAVES:2)
Block(3,30,-6,LEAVES:2)
Block(3,30,-5,LEAVES:2)
Block(3,31,-5,LEAVES:2)
Block(3,31,-4,LEAVES:2)
Block(3,31,-3,LEAVES:2)
Block(3,32,0,LEAVES:2)
Block(3,32,1,LEAVES:2)
Block(3,32,2,17:14)
Block(3,32,3,LEAVES:2)
Block(3,33,-2,LEAVES:2)
Block(3,33,-1,LEAVES:2)
Block(3,33,0,LEAVES:2)
Block(3,33,1,LEAVES:2)
Block(3,33,2,LEAVES:2)
Block(4,29,-1,17:14)
Block(4,30,-2,LEAVES:2)
Block(4,30,-1,LEAVES:2)
Block(4,30,0,LEAVES:2)
Block(4,31,-4,LEAVES:2)
Block(4,32,0,LEAVES:2)
Block(4,32,1,LEAVES:2)
Block(4,32,2,LEAVES:2)
Block(4,33,-1,LEAVES:2)
Block(4,33,0,LEAVES:2)
Block(4,33,1,LEAVES:2)
Block(5,30,-3,LEAVES:2)
Block(5,30,-2,LEAVES:2)
Block(5,30,-1,17:14)
Block(5,30,0,LEAVES:2)
Block(5,31,-1,LEAVES:2)
Block(6,30,-2,LEAVES:2)
Block(6,30,-1,LEAVES:2)
Block(6,30,0,LEAVES:2)
Block(7,30,-1,LEAVES:2)


#######################################################################
# +-----------------------------------------------------------------+ #
# |                             Entities                            | #
# +-----------------------------------------------------------------+ #
#######################################################################

# Entity() spawns an entity instead of a block. The entity is spawned only once when the BO3 is spawned.
# Entities are persistent by default so they don't de-spawn when no player is near, they are only unloaded.
# Usage: Entity(x,y,z,mobName,groupSize,NameTagOrNBTFileName) or Entity(x,y,z,mobName,groupSize)
# Use /tc entities or /otg entities to get a list of entities that can be used as mobName, this includes entities added by other mods.
# NameTagOrNBTFileName can be either a nametag for the mob or an nbt file (such as mymobinfo.nbt or mymobinfo.txt).
# When using a text file you can use the same mob spawning parameters used with the /summon command to equip the
# entity and give it custom attributes etc. You can copy the DATA part of a summon command including surrounding
# curly braces to a .txt file, for instance for: "/summon Skeleton x y z {DATA}"

#######################################################################
# +-----------------------------------------------------------------+ #
# |                            BO3 checks                           | #
# +-----------------------------------------------------------------+ #
#######################################################################

# Require a condition at a certain location in order for the BO3 to be spawned.
# BlockCheck(x,y,z,BlockName[,BlockName[,...]]) - one of the blocks must be at the location
# BlockCheckNot(x,y,z,BlockName[,BlockName[,...]]) - all the blocks must not be at the location
# LightCheck(x,y,z,minLightLevel,maxLightLevel) - light must be between min and max (inclusive)

# You can use "Solid" as a BlockName for matching all solid blocks or "All" to match all blocks that aren't air.

# Examples:
#   BlockCheck(0,-1,0,GRASS,DIRT)  Require grass or dirt just below the object
#   BlockCheck(0,-1,0,Solid)       Require any solid block just below the object
#   BlockCheck(0,-1,0,WOOL)        Require any type of wool just below the object
#   BlockCheck(0,-1,0,WOOL:0)      Require white wool just below the object
#   BlockCheckNot(0,-1,0,WOOL:0)   Require that there is no white wool below the object
#   LightCheck(0,0,0,0,LEAVES:2)          Require almost complete darkness just below the object

BlockCheck(0,-1,0,GRASS,DIRT,SAND)