#######################################################################
# +-----------------------------------------------------------------+ #
# |                            BO3 object                           | #
# +-----------------------------------------------------------------+ #
#######################################################################

# The descriptions in this file are accurate only for TerrainControl and OTG.
# For MCW and OTG+ these descriptions are only accurate if the BO3 is used as a CustomObject.
# MCW and OTG+ completely reimplemented CustomStructure, check the MCW/OTG+ documentation for more information.

# This is the config file of a custom object.
# If you add this object correctly to your BiomeConfigs, it will spawn in the world.

# This is the creator of this BO3 object
Author: Unknown

# A short description of this BO3 object
Description: This BO3 was converted from a schematic using OTGEdit. The author and description information of the schematic could not be found. If you know who the author of the schematic is then please add this information.

# The BO3 version, don't change this! It can be used by external applications to do a version check.
Version: 3

# The settings mode, WriteAll, WriteWithoutComments or WriteDisable. See WorldConfig.
SettingsMode: WriteDisable

#######################################################################
# +-----------------------------------------------------------------+ #
# |                          Main settings                          | #
# +-----------------------------------------------------------------+ #
#######################################################################

# This needs to be set to true to spawn the object in the Tree and Sapling resources.
Tree: true

# The frequency of the BO3 from 1 to 200. Tries this many times to spawn this BO3 when using the CustomObject(...) resource.
# Ignored by Tree(..), Sapling(..) and CustomStructure(..)
Frequency: 40

# The rarity of the BO3 from 0 to 100. Each spawn attempt has rarity% chance to succeed when using the CustomObject(...) resource.
# Ignored by Tree(..), Sapling(..) and CustomStructure(..)
Rarity: 100.0

# If you set this to true, the BO3 will be placed with a random rotation.
RotateRandomly: true

# The spawn height of the BO3 - randomY, highestBlock or highestSolidBlock.
SpawnHeight: highestSolidBlock

# The height limits for the BO3.
MinHeight: 61

MaxHeight: 256

# Objects can have other objects attached to it: branches. Branches can also
# have branches attached to it, which can also have branches, etc. This is the
# maximum branch depth for this objects.
MaxBranchDepth: 10

# When spawned with the UseWorld keyword, this BO3 should NOT spawn in the following biomes.
# If you writer.write the BO3 name directly in the BiomeConfigs, this will be ignored.
ExcludedBiomes: All

# To optimise this BO3 for faster loading times you can use Notepad++ to find/replace comments and abbreviate things.
# Notepad++ find/replace with regex:
# Find: ^[#;].* replace to nothing removes all lines starting with # 
# Find: ^\s*$ replace to nothing removes most empty lines 
# Notepad++ find/replace without regex:
# *Warning: This will only work for OTG 1.10.2 v21 / OTG 1.11.2 v6 or higher. B( is not recognised by lower versions.
# Find: Block( replace to B(

# The style of extrusion you wish to use - BottomDown, TopUp, None (Default)
ExtrudeMode: BottomDown

# The blocks to extrude your BO3 through
ExtrudeThroughBlocks: AIR

#######################################################################
# +-----------------------------------------------------------------+ #
# |                      Source block settings                      | #
# +-----------------------------------------------------------------+ #
#######################################################################

SourceBlocks: STONE:1,STONE:3,STONE:5,DIRT:1,DIRT:0,SAND:0,GRASS:0,DIRT:2,STATIONARY_WATER:0,HARD_CLAY,STAINED_CLAY:0,CLAY,SANDSTONE:0,SAND:1,AIR,STONE:0,GRAVEL,LONG_GRASS:0,LONG_GRASS:1,LONG_GRASS:2,DEAD_BUSH,YELLOW_FLOWER:0,RED_ROSE:0,BROWN_MUSHROOM,RED_MUSHROOM

MaxPercentageOutsideSourceBlock: 0

OutsideSourceBlock: placeAnyway

#######################################################################
# +-----------------------------------------------------------------+ #
# |                              Blocks                             | #
# +-----------------------------------------------------------------+ #
#######################################################################

# All the blocks used in the BO3 are listed here. Possible blocks:
# Block(x,y,z,id[.data][,nbtfile.nbt) or B(x,y,z,id[.data][,nbtfile.nbt)
# RandomBlock(x,y,z,id[:data][,nbtfile.nbt],chance[,id[:data][,nbtfile.nbt],chance[,...]])
# So RandomBlock(0,0,0,CHEST,chest.nbt,50,CHEST,anotherchest.nbt,100) will spawn a chest at
# the BO3 origin, and give it a 50% chance to have the contents of chest.nbt, or, if that
# fails, a 100% percent chance to have the contents of anotherchest.nbt.

Block(-10,18,0,LEAVES:2)
Block(-10,19,0,LEAVES:2)
Block(-10,19,1,LEAVES:2)
Block(-9,18,-1,LEAVES:2)
Block(-9,18,0,LEAVES:2)
Block(-9,18,1,LEAVES:2)
Block(-9,18,3,LEAVES:2)
Block(-9,19,0,LEAVES:2)
Block(-9,19,1,LEAVES:2)
Block(-9,19,3,LEAVES:2)
Block(-9,20,1,LEAVES:2)
Block(-9,21,0,LEAVES:2)
Block(-9,21,1,LEAVES:2)
Block(-9,22,0,LEAVES:2)
Block(-8,17,2,LEAVES:2)
Block(-8,18,1,LEAVES:2)
Block(-8,18,2,LEAVES:2)
Block(-8,19,0,LEAVES:2)
Block(-8,19,1,17:14)
Block(-8,19,2,LEAVES:2)
Block(-8,19,3,LEAVES:2)
Block(-8,20,0,LEAVES:2)
Block(-8,20,2,LEAVES:2)
Block(-8,21,-1,LEAVES:2)
Block(-8,21,0,LEAVES:2)
Block(-8,21,1,LEAVES:2)
Block(-8,21,2,LEAVES:2)
Block(-8,22,0,LEAVES:2)
Block(-8,22,2,LEAVES:2)
Block(-8,23,1,LEAVES:2)
Block(-8,25,-7,LEAVES:2)
Block(-8,25,-6,LEAVES:2)
Block(-8,25,-2,LEAVES:2)
Block(-8,25,-1,LEAVES:2)
Block(-8,26,-7,LEAVES:2)
Block(-8,26,-6,LEAVES:2)
Block(-8,26,-1,LEAVES:2)
Block(-8,27,-6,LEAVES:2)
Block(-7,18,2,LEAVES:2)
Block(-7,18,3,LEAVES:2)
Block(-7,19,0,LEAVES:2)
Block(-7,19,1,LEAVES:2)
Block(-7,19,2,LEAVES:2)
Block(-7,20,-1,LEAVES:2)
Block(-7,20,0,LEAVES:2)
Block(-7,20,1,17:14)
Block(-7,20,3,LEAVES:2)
Block(-7,21,-1,LEAVES:2)
Block(-7,21,0,17:14)
Block(-7,21,1,LEAVES:2)
Block(-7,21,2,LEAVES:2)
Block(-7,22,0,LEAVES:2)
Block(-7,22,2,LEAVES:2)
Block(-7,23,0,LEAVES:2)
Block(-7,24,-2,LEAVES:2)
Block(-7,25,-5,LEAVES:2)
Block(-7,25,-4,LEAVES:2)
Block(-7,25,-3,LEAVES:2)
Block(-7,25,-2,LEAVES:2)
Block(-7,25,1,LEAVES:2)
Block(-7,26,-7,LEAVES:2)
Block(-7,26,-6,LEAVES:2)
Block(-7,26,-5,LEAVES:2)
Block(-7,26,-4,LEAVES:2)
Block(-7,26,-2,LEAVES:2)
Block(-7,26,-1,LEAVES:2)
Block(-7,26,0,LEAVES:2)
Block(-7,26,1,LEAVES:2)
Block(-7,26,2,LEAVES:2)
Block(-7,27,-6,LEAVES:2)
Block(-7,27,-4,LEAVES:2)
Block(-7,27,-2,LEAVES:2)
Block(-7,27,-1,LEAVES:2)
Block(-7,28,-6,LEAVES:2)
Block(-6,20,0,LEAVES:2)
Block(-6,20,1,17:14)
Block(-6,21,-2,LEAVES:2)
Block(-6,21,-1,LEAVES:2)
Block(-6,21,0,LEAVES:2)
Block(-6,21,1,LEAVES:2)
Block(-6,22,1,LEAVES:2)
Block(-6,23,0,LEAVES:2)
Block(-6,23,1,LEAVES:2)
Block(-6,24,-7,LEAVES:2)
Block(-6,24,-6,LEAVES:2)
Block(-6,24,-5,LEAVES:2)
Block(-6,24,-1,LEAVES:2)
Block(-6,24,0,LEAVES:2)
Block(-6,24,1,LEAVES:2)
Block(-6,24,2,LEAVES:2)
Block(-6,25,-8,LEAVES:2)
Block(-6,25,-7,LEAVES:2)
Block(-6,25,-6,LEAVES:2)
Block(-6,25,-5,17:14)
Block(-6,25,-4,LEAVES:2)
Block(-6,25,-3,LEAVES:2)
Block(-6,25,-2,LEAVES:2)
Block(-6,25,-1,LEAVES:2)
Block(-6,25,0,LEAVES:2)
Block(-6,25,1,LEAVES:2)
Block(-6,26,-8,LEAVES:2)
Block(-6,26,-7,LEAVES:2)
Block(-6,26,-6,17:14)
Block(-6,26,-5,LEAVES:2)
Block(-6,26,-3,LEAVES:2)
Block(-6,26,-1,17:14)
Block(-6,26,0,LEAVES:2)
Block(-6,26,1,LEAVES:2)
Block(-6,26,3,LEAVES:2)
Block(-6,27,-7,LEAVES:2)
Block(-6,27,-6,LEAVES:2)
Block(-6,27,-4,LEAVES:2)
Block(-6,27,-3,LEAVES:2)
Block(-6,27,-1,LEAVES:2)
Block(-6,27,0,LEAVES:2)
Block(-6,27,3,LEAVES:2)
Block(-6,28,-2,LEAVES:2)
Block(-6,28,-1,LEAVES:2)
Block(-6,28,0,LEAVES:2)
Block(-6,28,3,LEAVES:2)
Block(-6,28,4,LEAVES:2)
Block(-5,19,1,17:14)
Block(-5,20,1,LEAVES:2)
Block(-5,21,-1,LEAVES:2)
Block(-5,21,1,LEAVES:2)
Block(-5,22,1,LEAVES:2)
Block(-5,23,-4,17:14)
Block(-5,24,-6,LEAVES:2)
Block(-5,24,-5,17:14)
Block(-5,24,-4,LEAVES:2)
Block(-5,24,-2,LEAVES:2)
Block(-5,24,-1,17:14)
Block(-5,24,2,LEAVES:2)
Block(-5,25,-7,LEAVES:2)
Block(-5,25,-5,LEAVES:2)
Block(-5,25,-1,17:14)
Block(-5,25,0,LEAVES:2)
Block(-5,25,1,LEAVES:2)
Block(-5,25,2,LEAVES:2)
Block(-5,25,3,LEAVES:2)
Block(-5,25,4,LEAVES:2)
Block(-5,25,5,LEAVES:2)
Block(-5,26,-8,LEAVES:2)
Block(-5,26,-7,LEAVES:2)
Block(-5,26,-6,LEAVES:2)
Block(-5,26,-4,LEAVES:2)
Block(-5,26,-2,LEAVES:2)
Block(-5,26,-1,LEAVES:2)
Block(-5,26,0,LEAVES:2)
Block(-5,26,1,LEAVES:2)
Block(-5,26,2,LEAVES:2)
Block(-5,26,3,17:14)
Block(-5,26,4,LEAVES:2)
Block(-5,27,-6,LEAVES:2)
Block(-5,27,-4,LEAVES:2)
Block(-5,27,-2,LEAVES:2)
Block(-5,27,-1,LEAVES:2)
Block(-5,27,1,LEAVES:2)
Block(-5,27,2,LEAVES:2)
Block(-5,27,3,LEAVES:2)
Block(-5,27,4,LEAVES:2)
Block(-5,28,-6,LEAVES:2)
Block(-5,28,-1,LEAVES:2)
Block(-5,28,0,LEAVES:2)
Block(-4,19,1,17:14)
Block(-4,21,-3,17:14)
Block(-4,22,-4,17:14)
Block(-4,23,0,17:14)
Block(-4,24,-5,LEAVES:2)
Block(-4,24,2,17:14)
Block(-4,24,3,LEAVES:2)
Block(-4,25,-5,LEAVES:2)
Block(-4,25,0,LEAVES:2)
Block(-4,25,1,LEAVES:2)
Block(-4,25,3,17:14)
Block(-4,25,4,LEAVES:2)
Block(-4,25,5,LEAVES:2)
Block(-4,26,-7,LEAVES:2)
Block(-4,26,-5,LEAVES:2)
Block(-4,26,-2,LEAVES:2)
Block(-4,26,-1,LEAVES:2)
Block(-4,26,3,LEAVES:2)
Block(-4,26,4,LEAVES:2)
Block(-4,26,5,LEAVES:2)
Block(-4,27,-6,LEAVES:2)
Block(-4,27,-5,LEAVES:2)
Block(-4,27,-2,LEAVES:2)
Block(-4,27,-1,LEAVES:2)
Block(-4,27,0,LEAVES:2)
Block(-4,27,3,LEAVES:2)
Block(-4,27,4,LEAVES:2)
Block(-4,28,2,LEAVES:2)
Block(-4,28,3,LEAVES:2)
Block(-3,19,0,17:14)
Block(-3,20,-3,17:14)
Block(-3,22,1,17:14)
Block(-3,23,-2,LEAVES:2)
Block(-3,23,2,17:14)
Block(-3,24,-2,LEAVES:2)
Block(-3,25,-2,LEAVES:2)
Block(-3,25,0,LEAVES:2)
Block(-3,25,8,LEAVES:2)
Block(-3,26,-2,LEAVES:2)
Block(-3,26,2,LEAVES:2)
Block(-3,26,3,LEAVES:2)
Block(-3,26,4,LEAVES:2)
Block(-3,26,6,LEAVES:2)
Block(-3,26,7,LEAVES:2)
Block(-3,27,-3,LEAVES:2)
Block(-3,27,-2,LEAVES:2)
Block(-2,18,-1,17:14)
Block(-2,19,-2,17:14)
Block(-2,21,-3,17:14)
Block(-2,21,1,17:14)
Block(-2,22,-4,17:14)
Block(-2,23,-3,LEAVES:2)
Block(-2,23,-2,LEAVES:2)
Block(-2,24,-5,LEAVES:2)
Block(-2,24,-4,LEAVES:2)
Block(-2,24,-3,LEAVES:2)
Block(-2,24,-2,LEAVES:2)
Block(-2,24,0,LEAVES:2)
Block(-2,24,5,LEAVES:2)
Block(-2,24,6,LEAVES:2)
Block(-2,24,7,LEAVES:2)
Block(-2,25,-4,LEAVES:2)
Block(-2,25,-3,LEAVES:2)
Block(-2,25,-2,17:14)
Block(-2,25,-1,LEAVES:2)
Block(-2,25,0,LEAVES:2)
Block(-2,25,4,LEAVES:2)
Block(-2,25,5,LEAVES:2)
Block(-2,25,6,LEAVES:2)
Block(-2,25,7,LEAVES:2)
Block(-2,25,8,LEAVES:2)
Block(-2,26,-3,LEAVES:2)
Block(-2,26,0,LEAVES:2)
Block(-2,26,5,LEAVES:2)
Block(-2,26,6,17:14)
Block(-2,26,7,LEAVES:2)
Block(-2,26,8,LEAVES:2)
Block(-2,27,-3,LEAVES:2)
Block(-2,27,-2,LEAVES:2)
Block(-2,27,4,LEAVES:2)
Block(-2,27,5,LEAVES:2)
Block(-2,27,6,LEAVES:2)
Block(-2,27,7,LEAVES:2)
Block(-2,27,8,LEAVES:2)
Block(-2,28,7,LEAVES:2)
Block(-1,16,0,17:14)
Block(-1,17,-1,17:14)
Block(-1,19,2,17:14)
Block(-1,20,2,17:14)
Block(-1,21,3,17:14)
Block(-1,23,-4,17:14)
Block(-1,23,-2,LEAVES:2)
Block(-1,23,-1,LEAVES:2)
Block(-1,23,0,LEAVES:2)
Block(-1,23,6,LEAVES:2)
Block(-1,24,-6,LEAVES:2)
Block(-1,24,-5,17:14)
Block(-1,24,-4,LEAVES:2)
Block(-1,24,-3,17:14)
Block(-1,24,-2,LEAVES:2)
Block(-1,24,0,LEAVES:2)
Block(-1,24,1,LEAVES:2)
Block(-1,24,5,LEAVES:2)
Block(-1,24,6,LEAVES:2)
Block(-1,25,-6,LEAVES:2)
Block(-1,25,-5,LEAVES:2)
Block(-1,25,-4,LEAVES:2)
Block(-1,25,-2,LEAVES:2)
Block(-1,25,-1,LEAVES:2)
Block(-1,25,0,LEAVES:2)
Block(-1,25,1,LEAVES:2)
Block(-1,25,3,LEAVES:2)
Block(-1,25,4,LEAVES:2)
Block(-1,25,5,17:14)
Block(-1,25,7,LEAVES:2)
Block(-1,26,-6,LEAVES:2)
Block(-1,26,-3,LEAVES:2)
Block(-1,26,-1,LEAVES:2)
Block(-1,26,1,LEAVES:2)
Block(-1,26,5,LEAVES:2)
Block(-1,26,6,LEAVES:2)
Block(-1,26,7,LEAVES:2)
Block(-1,27,-6,LEAVES:2)
Block(-1,27,-3,LEAVES:2)
Block(-1,27,6,LEAVES:2)
Block(-1,28,6,LEAVES:2)
Block(0,0,0,17:14)
Block(0,1,0,17:14)
Block(0,2,0,17:14)
Block(0,3,0,17:14)
Block(0,4,0,17:14)
Block(0,5,0,17:14)
Block(0,6,0,17:14)
Block(0,7,0,17:14)
Block(0,8,0,17:14)
Block(0,9,0,17:14)
Block(0,10,0,17:14)
Block(0,11,0,17:14)
Block(0,12,0,17:14)
Block(0,13,0,17:14)
Block(0,14,0,17:14)
Block(0,15,0,17:14)
Block(0,16,0,17:2)
Block(0,18,1,17:14)
Block(0,19,1,17:14)
Block(0,22,3,17:14)
Block(0,23,0,LEAVES:2)
Block(0,23,1,LEAVES:2)
Block(0,23,4,17:14)
Block(0,24,-5,LEAVES:2)
Block(0,24,-3,LEAVES:2)
Block(0,24,-2,LEAVES:2)
Block(0,24,1,LEAVES:2)
Block(0,24,4,17:14)
Block(0,24,5,LEAVES:2)
Block(0,24,6,LEAVES:2)
Block(0,25,-7,LEAVES:2)
Block(0,25,-6,LEAVES:2)
Block(0,25,-5,17:14)
Block(0,25,-2,LEAVES:2)
Block(0,25,-1,LEAVES:2)
Block(0,25,0,17:14)
Block(0,25,1,LEAVES:2)
Block(0,25,4,LEAVES:2)
Block(0,25,5,LEAVES:2)
Block(0,25,6,LEAVES:2)
Block(0,26,-7,LEAVES:2)
Block(0,26,-6,17:14)
Block(0,26,-2,LEAVES:2)
Block(0,26,-1,LEAVES:2)
Block(0,26,0,LEAVES:2)
Block(0,26,1,LEAVES:2)
Block(0,26,3,LEAVES:2)
Block(0,26,4,LEAVES:2)
Block(0,26,5,17:14)
Block(0,26,6,LEAVES:2)
Block(0,26,7,LEAVES:2)
Block(0,27,-6,LEAVES:2)
Block(0,27,-1,LEAVES:2)
Block(0,27,0,LEAVES:2)
Block(0,27,1,LEAVES:2)
Block(0,27,3,LEAVES:2)
Block(0,27,4,LEAVES:2)
Block(0,27,5,LEAVES:2)
Block(0,27,6,LEAVES:2)
Block(0,27,7,LEAVES:2)
Block(0,29,-7,LEAVES:2)
Block(1,16,0,17:14)
Block(1,17,-1,17:14)
Block(1,17,1,17:14)
Block(1,18,-2,17:14)
Block(1,23,2,17:14)
Block(1,24,-1,LEAVES:2)
Block(1,24,0,17:14)
Block(1,24,1,17:14)
Block(1,24,4,LEAVES:2)
Block(1,24,5,LEAVES:2)
Block(1,24,6,LEAVES:2)
Block(1,25,-6,LEAVES:2)
Block(1,25,-5,LEAVES:2)
Block(1,25,-3,LEAVES:2)
Block(1,25,1,LEAVES:2)
Block(1,25,3,LEAVES:2)
Block(1,25,4,LEAVES:2)
Block(1,25,5,LEAVES:2)
Block(1,25,6,LEAVES:2)
Block(1,26,-6,LEAVES:2)
Block(1,26,-4,LEAVES:2)
Block(1,26,-2,LEAVES:2)
Block(1,26,-1,LEAVES:2)
Block(1,26,0,LEAVES:2)
Block(1,26,1,LEAVES:2)
Block(1,26,2,LEAVES:2)
Block(1,26,5,LEAVES:2)
Block(1,26,7,LEAVES:2)
Block(1,27,-7,LEAVES:2)
Block(1,27,-6,17:14)
Block(1,27,-5,LEAVES:2)
Block(1,27,-4,LEAVES:2)
Block(1,27,0,LEAVES:2)
Block(1,28,-7,LEAVES:2)
Block(1,28,-6,LEAVES:2)
Block(1,28,-4,LEAVES:2)
Block(1,29,-7,LEAVES:2)
Block(1,29,-5,LEAVES:2)
Block(2,18,2,17:14)
Block(2,19,-2,17:14)
Block(2,19,2,17:14)
Block(2,20,-3,17:14)
Block(2,24,-6,LEAVES:2)
Block(2,24,0,LEAVES:2)
Block(2,24,1,LEAVES:2)
Block(2,25,-8,LEAVES:2)
Block(2,25,-7,LEAVES:2)
Block(2,25,-6,LEAVES:2)
Block(2,25,-5,LEAVES:2)
Block(2,25,-3,LEAVES:2)
Block(2,25,-2,LEAVES:2)
Block(2,25,-1,17:14)
Block(2,25,0,LEAVES:2)
Block(2,25,1,LEAVES:2)
Block(2,25,6,LEAVES:2)
Block(2,26,-8,LEAVES:2)
Block(2,26,-7,LEAVES:2)
Block(2,26,-6,LEAVES:2)
Block(2,26,-5,LEAVES:2)
Block(2,26,-4,LEAVES:2)
Block(2,26,-1,17:14)
Block(2,26,0,LEAVES:2)
Block(2,26,1,LEAVES:2)
Block(2,27,-8,LEAVES:2)
Block(2,27,-7,LEAVES:2)
Block(2,27,-6,LEAVES:2)
Block(2,27,-5,LEAVES:2)
Block(2,27,-4,LEAVES:2)
Block(2,27,-3,LEAVES:2)
Block(2,27,-1,LEAVES:2)
Block(2,27,0,LEAVES:2)
Block(2,28,-6,LEAVES:2)
Block(2,28,-5,LEAVES:2)
Block(2,28,-2,LEAVES:2)
Block(2,28,-1,LEAVES:2)
Block(2,29,-6,LEAVES:2)
Block(3,20,3,17:14)
Block(3,21,-3,17:14)
Block(3,21,3,17:14)
Block(3,22,-2,17:14)
Block(3,23,-6,LEAVES:2)
Block(3,23,-5,17:14)
Block(3,23,-2,17:14)
Block(3,24,-7,LEAVES:2)
Block(3,24,-6,17:14)
Block(3,24,-5,LEAVES:2)
Block(3,24,-2,LEAVES:2)
Block(3,24,-1,LEAVES:2)
Block(3,25,-8,LEAVES:2)
Block(3,25,-7,LEAVES:2)
Block(3,25,-6,17:14)
Block(3,25,-5,LEAVES:2)
Block(3,25,-1,LEAVES:2)
Block(3,25,1,LEAVES:2)
Block(3,26,-8,LEAVES:2)
Block(3,26,-6,LEAVES:2)
Block(3,26,-5,LEAVES:2)
Block(3,26,-3,LEAVES:2)
Block(3,26,-1,LEAVES:2)
Block(3,27,-6,LEAVES:2)
Block(3,27,-5,LEAVES:2)
Block(3,27,-3,LEAVES:2)
Block(3,27,-1,LEAVES:2)
Block(3,27,0,LEAVES:2)
Block(3,28,-7,LEAVES:2)
Block(3,28,-6,LEAVES:2)
Block(3,28,-2,LEAVES:2)
Block(3,28,-1,LEAVES:2)
Block(3,28,0,LEAVES:2)
Block(4,22,-4,17:14)
Block(4,22,2,17:14)
Block(4,22,4,17:14)
Block(4,23,5,LEAVES:2)
Block(4,24,-7,LEAVES:2)
Block(4,24,-1,17:14)
Block(4,25,-8,LEAVES:2)
Block(4,25,-7,LEAVES:2)
Block(4,25,-6,LEAVES:2)
Block(4,25,-5,LEAVES:2)
Block(4,25,-1,17:14)
Block(4,25,6,LEAVES:2)
Block(4,26,-9,LEAVES:2)
Block(4,26,-8,LEAVES:2)
Block(4,26,-7,17:14)
Block(4,26,-6,LEAVES:2)
Block(4,26,-5,LEAVES:2)
Block(4,26,-2,LEAVES:2)
Block(4,26,-1,LEAVES:2)
Block(4,27,-9,LEAVES:2)
Block(4,27,-7,LEAVES:2)
Block(4,27,-5,LEAVES:2)
Block(4,27,-1,LEAVES:2)
Block(4,27,0,LEAVES:2)
Block(4,28,-7,LEAVES:2)
Block(4,28,-6,LEAVES:2)
Block(5,22,5,LEAVES:2)
Block(5,23,-4,17:14)
Block(5,23,2,17:14)
Block(5,23,4,LEAVES:2)
Block(5,23,5,17:14)
Block(5,23,6,LEAVES:2)
Block(5,24,-8,LEAVES:2)
Block(5,24,5,LEAVES:2)
Block(5,24,6,LEAVES:2)
Block(5,25,-9,LEAVES:2)
Block(5,25,-8,LEAVES:2)
Block(5,25,-7,LEAVES:2)
Block(5,25,1,LEAVES:2)
Block(5,25,5,LEAVES:2)
Block(5,25,6,LEAVES:2)
Block(5,25,7,LEAVES:2)
Block(5,25,8,LEAVES:2)
Block(5,26,-7,LEAVES:2)
Block(5,26,-6,LEAVES:2)
Block(5,26,-5,LEAVES:2)
Block(5,26,1,LEAVES:2)
Block(5,26,2,LEAVES:2)
Block(5,27,-5,LEAVES:2)
Block(5,27,0,LEAVES:2)
Block(6,22,5,LEAVES:2)
Block(6,23,2,17:14)
Block(6,23,4,LEAVES:2)
Block(6,23,5,LEAVES:2)
Block(6,23,6,LEAVES:2)
Block(6,24,-4,17:14)
Block(6,24,1,17:14)
Block(6,24,4,LEAVES:2)
Block(6,24,5,LEAVES:2)
Block(6,24,6,17:14)
Block(6,24,7,LEAVES:2)
Block(6,25,-6,LEAVES:2)
Block(6,25,-1,LEAVES:2)
Block(6,25,0,LEAVES:2)
Block(6,25,1,17:14)
Block(6,25,2,LEAVES:2)
Block(6,25,5,LEAVES:2)
Block(6,25,6,LEAVES:2)
Block(6,26,-7,LEAVES:2)
Block(6,26,-6,LEAVES:2)
Block(6,26,-5,LEAVES:2)
Block(6,26,-4,LEAVES:2)
Block(6,26,-1,LEAVES:2)
Block(6,26,0,LEAVES:2)
Block(6,26,1,LEAVES:2)
Block(6,26,2,LEAVES:2)
Block(6,26,6,LEAVES:2)
Block(6,26,7,LEAVES:2)
Block(6,27,-8,LEAVES:2)
Block(6,27,-3,LEAVES:2)
Block(6,27,-1,LEAVES:2)
Block(6,27,0,LEAVES:2)
Block(6,27,1,LEAVES:2)
Block(6,27,2,LEAVES:2)
Block(6,27,3,LEAVES:2)
Block(6,28,1,LEAVES:2)
Block(6,29,-1,LEAVES:2)
Block(7,24,0,LEAVES:2)
Block(7,24,1,LEAVES:2)
Block(7,24,2,LEAVES:2)
Block(7,24,5,LEAVES:2)
Block(7,24,6,LEAVES:2)
Block(7,24,7,LEAVES:2)
Block(7,25,-5,17:14)
Block(7,25,0,LEAVES:2)
Block(7,25,1,LEAVES:2)
Block(7,25,6,LEAVES:2)
Block(7,25,7,LEAVES:2)
Block(7,26,-7,LEAVES:2)
Block(7,26,-6,LEAVES:2)
Block(7,26,-4,17:14)
Block(7,26,-3,LEAVES:2)
Block(7,26,-1,LEAVES:2)
Block(7,26,0,LEAVES:2)
Block(7,26,1,17:14)
Block(7,26,2,LEAVES:2)
Block(7,26,3,LEAVES:2)
Block(7,26,6,LEAVES:2)
Block(7,26,7,LEAVES:2)
Block(7,27,-8,LEAVES:2)
Block(7,27,-4,LEAVES:2)
Block(7,27,-3,17:14)
Block(7,27,-2,LEAVES:2)
Block(7,27,-1,LEAVES:2)
Block(7,27,0,LEAVES:2)
Block(7,27,1,LEAVES:2)
Block(7,27,2,LEAVES:2)
Block(7,27,3,LEAVES:2)
Block(7,28,-7,LEAVES:2)
Block(7,28,-5,LEAVES:2)
Block(7,28,-3,LEAVES:2)
Block(7,28,-2,LEAVES:2)
Block(7,28,-1,LEAVES:2)
Block(7,28,0,LEAVES:2)
Block(7,28,1,LEAVES:2)
Block(7,28,2,LEAVES:2)
Block(7,29,-3,LEAVES:2)
Block(7,29,-2,LEAVES:2)
Block(7,29,-1,LEAVES:2)
Block(7,29,0,LEAVES:2)
Block(7,29,1,LEAVES:2)
Block(7,30,0,LEAVES:2)
Block(7,30,1,LEAVES:2)
Block(8,24,0,LEAVES:2)
Block(8,24,1,LEAVES:2)
Block(8,24,6,LEAVES:2)
Block(8,25,-6,LEAVES:2)
Block(8,25,1,LEAVES:2)
Block(8,26,-9,LEAVES:2)
Block(8,26,-7,LEAVES:2)
Block(8,26,-6,17:14)
Block(8,26,-5,LEAVES:2)
Block(8,26,1,LEAVES:2)
Block(8,26,3,LEAVES:2)
Block(8,27,-9,LEAVES:2)
Block(8,27,-8,LEAVES:2)
Block(8,27,-7,17:14)
Block(8,27,-6,LEAVES:2)
Block(8,27,-5,LEAVES:2)
Block(8,27,-3,LEAVES:2)
Block(8,27,-2,LEAVES:2)
Block(8,27,-1,LEAVES:2)
Block(8,28,-7,LEAVES:2)
Block(8,28,-6,LEAVES:2)
Block(8,28,-5,LEAVES:2)
Block(8,28,-3,LEAVES:2)
Block(8,28,-2,17:14)
Block(8,28,-1,LEAVES:2)
Block(8,28,0,LEAVES:2)
Block(8,28,1,LEAVES:2)
Block(8,29,-6,LEAVES:2)
Block(8,29,-4,LEAVES:2)
Block(8,29,-3,LEAVES:2)
Block(8,29,-2,LEAVES:2)
Block(8,29,-1,17:14)
Block(8,29,0,LEAVES:2)
Block(8,29,1,LEAVES:2)
Block(8,30,-3,LEAVES:2)
Block(8,30,-2,LEAVES:2)
Block(8,30,-1,LEAVES:2)
Block(8,30,1,LEAVES:2)
Block(9,25,1,LEAVES:2)
Block(9,25,2,LEAVES:2)
Block(9,26,-9,LEAVES:2)
Block(9,26,-7,LEAVES:2)
Block(9,26,-6,LEAVES:2)
Block(9,26,1,LEAVES:2)
Block(9,27,-8,LEAVES:2)
Block(9,27,-7,LEAVES:2)
Block(9,27,-6,LEAVES:2)
Block(9,27,-5,LEAVES:2)
Block(9,27,-2,LEAVES:2)
Block(9,28,-8,LEAVES:2)
Block(9,28,-7,LEAVES:2)
Block(9,28,-6,LEAVES:2)
Block(9,28,-3,LEAVES:2)
Block(9,28,-2,LEAVES:2)
Block(9,28,-1,LEAVES:2)
Block(9,28,0,LEAVES:2)
Block(9,28,1,LEAVES:2)
Block(9,29,-8,LEAVES:2)
Block(9,29,-7,LEAVES:2)
Block(9,29,-3,LEAVES:2)
Block(9,29,-1,LEAVES:2)
Block(9,29,0,LEAVES:2)
Block(9,29,1,LEAVES:2)
Block(9,30,-3,LEAVES:2)
Block(10,26,-6,LEAVES:2)
Block(10,28,-8,LEAVES:2)
Block(10,28,-6,LEAVES:2)
Block(10,29,-1,LEAVES:2)
Block(10,30,-1,LEAVES:2)


#######################################################################
# +-----------------------------------------------------------------+ #
# |                             Entities                            | #
# +-----------------------------------------------------------------+ #
#######################################################################

# Entity() spawns an entity instead of a block. The entity is spawned only once when the BO3 is spawned.
# Entities are persistent by default so they don't de-spawn when no player is near, they are only unloaded.
# Usage: Entity(x,y,z,mobName,groupSize,NameTagOrNBTFileName) or Entity(x,y,z,mobName,groupSize)
# Use /tc entities or /otg entities to get a list of entities that can be used as mobName, this includes entities added by other mods.
# NameTagOrNBTFileName can be either a nametag for the mob or an nbt file (such as mymobinfo.nbt or mymobinfo.txt).
# When using a text file you can use the same mob spawning parameters used with the /summon command to equip the
# entity and give it custom attributes etc. You can copy the DATA part of a summon command including surrounding
# curly braces to a .txt file, for instance for: "/summon Skeleton x y z {DATA}"

#######################################################################
# +-----------------------------------------------------------------+ #
# |                            BO3 checks                           | #
# +-----------------------------------------------------------------+ #
#######################################################################

# Require a condition at a certain location in order for the BO3 to be spawned.
# BlockCheck(x,y,z,BlockName[,BlockName[,...]]) - one of the blocks must be at the location
# BlockCheckNot(x,y,z,BlockName[,BlockName[,...]]) - all the blocks must not be at the location
# LightCheck(x,y,z,minLightLevel,maxLightLevel) - light must be between min and max (inclusive)

# You can use "Solid" as a BlockName for matching all solid blocks or "All" to match all blocks that aren't air.

# Examples:
#   BlockCheck(0,-1,0,GRASS,DIRT)  Require grass or dirt just below the object
#   BlockCheck(0,-1,0,Solid)       Require any solid block just below the object
#   BlockCheck(0,-1,0,WOOL)        Require any type of wool just below the object
#   BlockCheck(0,-1,0,WOOL:0)      Require white wool just below the object
#   BlockCheckNot(0,-1,0,WOOL:0)   Require that there is no white wool below the object
#   LightCheck(0,0,0,0,LEAVES:2)          Require almost complete darkness just below the object

BlockCheck(0,-1,0,GRASS,DIRT)