
#######################################################################
# +-----------------------------------------------------------------+ #
# |                            BO3 object                           | #
# +-----------------------------------------------------------------+ #
#######################################################################

# This is the config file of a custom object.
# If you add this object correctly to your BiomeConfigs, it will spawn in the world.

# This is the creator of this BO3 object
Author: Unknown

# A short description of this BO3 object
Description: No description

# The settings mode, WriteAll, WriteWithoutComments or WriteDisable. See WorldConfig.
SettingsMode: WriteAll


#######################################################################
# +-----------------------------------------------------------------+ #
# |                          Main settings                          | #
# +-----------------------------------------------------------------+ #
#######################################################################

# This BO3 can only spawn at least Frequency chunks distance away from any other BO3 with the exact same name.
# You can use this to make this BO3 spawn in groups or make sure that this BO3 only spawns once every X chunks.
Frequency: 0

# If you set this to true, the BO3 will be placed with a random rotation.
# This is broken for BO4's atm, will fix this a.s.a.p.
RotateRandomly: false

# The spawn height of the BO3: randomY, highestBlock or highestSolidBlock.
SpawnHeight: highestBlock

##############################
# Height Limits for the BO3. #
##############################

# When in randomY mode used as the minimum Y or in atMinY mode as the actual Y to spawn this BO3 at.
MinHeight: 0

# When in randomY mode used as the maximum Y to spawn this BO3 at.
MaxHeight: 256

# Copies the blocks and branches of an existing BO3 into this BO3. You can still add blocks and branches in this BO3, they will be added on top of the inherited blocks and branches.
InheritBO3: 

# Rotates the inheritedBO3's resources (blocks, spawners, checks etc) and branches, defaults to NORTH (no rotation).
InheritBO3Rotation: NORTH

# Defaults to true, if true and this is the starting BO3 for this branching structure then this BO3's smoothing and height settings are used for all children (branches).
OverrideChildSettings: true

# Defaults to false, if true then this branch uses it's own height settings (SpawnHeight, minHeight, maxHeight, spawnAtWaterLevel) instead of those defined in the starting BO3 for this branching structure.
OverrideParentHeight: false

# If this is set to true then this BO3 can spawn on top of or inside an existing BO3. If this is set to false then this BO3 will use a bounding box to detect collisions with other BO3's, if a collision is detected then this BO3 won't spawn and the current branch is rolled back.
CanOverride: false

# This branch can only spawn at least branchFrequency chunks (x,z) distance away from any other branch with the exact same name.
BranchFrequency: 0

# Define groups that this branch belongs to along with a minimum (x,z) range in chunks that this branch must have between it and any other members of this group if it is to be allowed to spawn. Syntax is "GroupName:Frequency, GoupName2:Frequency2" etc so for example a branch that belongs to 3 groups: "BranchFrequencyGroup: Ships:10, Vehicles:5, FloatingThings:3".
BranchFrequencyGroup: 

# If this is set to true then this BO3 can only spawn underneath an existing BO3. Used to make sure that dungeons only appear underneath buildings.
MustBeBelowOther: false

# Used with CanOverride: true. A comma-seperated list of BO3s, this BO3's bounding box must collide with one of the BO3's in the list or this BO3 fails to spawn and the current branch is rolled back.
MustBeInside: 

# Used with CanOverride: true. A comma-seperated list of BO3s, this BO3's bounding box cannot collide with any of the BO3's in the list or this BO3 fails to spawn and the current branch is rolled back.
CannotBeInside: 

# Used with CanOverride: true. A comma-seperated list of BO3s, if this BO3's bounding box collides with any of the BO3's in the list then those BO3's won't spawn any blocks. This does not remove or roll back any BO3's.
ReplacesBO3: 

# Defaults to true. Set to false if the BO3 is not allowed to spawn on a water block
CanSpawnOnWater: true

# Defaults to false. Set to true if the BO3 is allowed to spawn only on a water block
SpawnOnWaterOnly: false

# Defaults to false. Set to true if the BO3 and its smoothing area should ignore water when looking for the highest block to spawn on. Defaults to false (things spawn on top of water)
SpawnUnderWater: false

# Defaults to false. Set to true if the BO3 should spawn at water level
SpawnAtWaterLevel: false

# Spawns the BO3 at a Y offset of this value. Handy when using highestBlock for lowering BO3s into the surrounding terrain when there are layers of ground included in the BO3, also handy when using SpawnAtWaterLevel to lower objects like ships into the water.
HeightOffset: 0

# If set to true removes all AIR blocks from the BO3 so that it can be flooded or buried.
RemoveAir: true

# Replaces all the non-air blocks that are above this BO3 or its smoothing area with the given block material (should be WATER or AIR or NONE), also applies to smoothing areas although OTG intentionally leaves some of the terrain above them intact. WATER can be used in combination with SpawnUnderWater to fill any air blocks underneath waterlevel with water (and any above waterlevel with air).
ReplaceAbove: 

# Replaces all air blocks underneath the BO3 (but not its smoothing area) with the specified material until a solid block is found.
ReplaceBelow: 

# Defaults to true. If set to true then every block in the BO3 of the materials defined in ReplaceWithGroundBlock or ReplaceWithSurfaceBlock will be replaced by the GroundBlock or SurfaceBlock materials configured for the biome the block is spawned in.
ReplaceWithBiomeBlocks: true

# Defaults to DIRT, Replaces all the blocks of the given material in the BO3 with the GroundBlock configured for the biome it spawns in.
ReplaceWithGroundBlock: DIRT

# Defaults to GRASS, Replaces all the blocks of the given material in the BO3 with the SurfaceBlock configured for the biome it spawns in.
ReplaceWithSurfaceBlock: GRASS

# Makes the terrain around the BO3 slope evenly towards the edges of the BO3. The given value is the distance in blocks around the BO3 from where the slope should start and can be any positive number.
SmoothRadius: 0

# Moves the smoothing area up or down relative to the BO3 (at the points where the smoothing area is connected to the BO3). Handy when using SmoothStartTop: false and the BO3 has some layers of ground included, in that case we can set the HeightOffset to a negative value to lower the BO3 into the ground and we can set the SmoothHeightOffset to a positive value to move the smoothing area starting height up.
SmoothHeightOffset: 0

# Should the smoothing area be attached at the bottom or the top of the edges of the BO3? Defaults to false (bottom). Using this setting can make things slower so try to avoid using it and use SmoothHeightOffset instead if for instance you have a BO3 with some ground layers included. The only reason you should need to use this setting is if you have a BO3 with edges that have an irregular height (like some hills).
SmoothStartTop: false

# Should the smoothing area attach itself to "log" block or ignore them? Defaults to false (ignore logs).
SmoothStartWood: false

# The block used for smoothing area surface blocks, defaults to biome SurfaceBlock.
SmoothingSurfaceBlock: 

# The block used for smoothing area ground blocks, defaults to biome GroundBlock.
SmoothingGroundBlock: 

# Define groups that this BO3 belongs to along with a minimum range in chunks that this BO3 must have between it and any other members of this group if it is to be allowed to spawn. Syntax is "GroupName:Frequency, GoupName2:Frequency2" etc so for example a BO3 that belongs to 3 groups: "BO3Group: Ships:10, Vehicles:5, FloatingThings:3".
BO3Group: 

# Defaults to false. Set to true if this BO3 should spawn at the player spawn point. When the server starts the spawn point is determined and the BO3's for the biome it is in are loaded, one of these BO3s that has IsSpawnPoint set to true (if any) is selected randomly and is spawned at the spawn point regardless of its rarity (so even Rarity:0, IsSpawnPoint: true BO3's can get spawned as the spawn point!).
IsSpawnPoint: false


#######################################################################
# +-----------------------------------------------------------------+ #
# |                              Blocks                             | #
# +-----------------------------------------------------------------+ #
#######################################################################

# All the blocks used in the BO3 are listed here. Possible blocks:
# Block(x,y,z,id[.data][,nbtfile.nbt)
# RandomBlock(x,y,z,id[:data][,nbtfile.nbt],chance[,id[:data][,nbtfile.nbt],chance[,...]])
#  So RandomBlock(0,0,0,CHEST,chest.nbt,50,CHEST,anotherchest.nbt,100) will spawn a chest at
#  the BO3 origin, and give it a 50% chance to have the contents of chest.nbt, or, if that
#  fails, a 100% percent chance to have the contents of anotherchest.nbt.
# MinecraftObject(x,y,z,name) (TODO: This may not work anymore and needs to be tested.
#  Spawns an object in the Mojang NBT structure format. For example, 
#  MinecraftObject(0,0,0,minecraft:igloo/igloo_bottom)
#  spawns the bottom part of an igloo.
Block(0,13,0,biomesoplenty:leaves_0:3)
Block(0,14,0,biomesoplenty:leaves_0:3)
Block(0,15,0,biomesoplenty:leaves_0:3)
Block(0,13,1,biomesoplenty:leaves_0:3)
Block(0,14,1,biomesoplenty:leaves_0:15)
Block(0,15,1,biomesoplenty:leaves_0:15)
Block(0,12,2,biomesoplenty:leaves_0:7)
Block(0,13,2,biomesoplenty:leaves_0:3)
Block(0,14,2,biomesoplenty:leaves_0:3)
Block(0,15,2,biomesoplenty:leaves_0:3)
Block(0,12,3,biomesoplenty:leaves_0:3)
Block(0,13,3,biomesoplenty:log_1:5)
Block(0,14,3,biomesoplenty:log_1:1)
Block(0,15,3,biomesoplenty:leaves_0:15)
Block(0,16,3,biomesoplenty:leaves_0:15)
Block(0,13,4,biomesoplenty:leaves_0:3)
Block(0,14,4,biomesoplenty:leaves_0:3)
Block(0,15,4,biomesoplenty:leaves_0:3)
Block(0,13,5,biomesoplenty:log_1:1)
Block(0,14,5,biomesoplenty:leaves_0:3)
Block(0,15,5,biomesoplenty:leaves_0:15)
Block(0,10,6,biomesoplenty:leaves_0:7)
Block(0,11,6,biomesoplenty:leaves_0:15)
Block(0,12,6,biomesoplenty:leaves_0:15)
Block(0,13,6,biomesoplenty:leaves_0:15)
Block(0,14,6,biomesoplenty:leaves_0:15)
Block(0,15,6,biomesoplenty:leaves_0:15)
Block(0,14,7,biomesoplenty:leaves_0:15)
Block(0,9,15,biomesoplenty:leaves_0:3)
Block(1,13,1,biomesoplenty:leaves_0:15)
Block(1,13,2,biomesoplenty:leaves_0:3)
Block(1,14,2,biomesoplenty:leaves_0:3)
Block(1,13,3,biomesoplenty:leaves_0:3)
Block(1,14,3,biomesoplenty:log_1:9)
Block(1,15,3,biomesoplenty:leaves_0:3)
Block(1,13,4,biomesoplenty:log_1:1)
Block(1,14,4,biomesoplenty:log_1:5)
Block(1,15,4,biomesoplenty:leaves_0:15)
Block(1,13,5,biomesoplenty:leaves_0:15)
Block(1,14,5,biomesoplenty:leaves_0:15)
Block(1,14,6,biomesoplenty:leaves_0:15)
Block(1,14,7,biomesoplenty:leaves_0:15)
Block(1,9,8,biomesoplenty:leaves_0:7)
Block(1,9,9,biomesoplenty:leaves_0:7)
Block(1,8,15,biomesoplenty:leaves_0:7)
Block(1,9,15,biomesoplenty:leaves_0:3)
Block(1,10,15,biomesoplenty:leaves_0:3)
Block(2,14,2,biomesoplenty:leaves_0:15)
Block(2,14,3,biomesoplenty:leaves_0:15)
Block(2,13,4,biomesoplenty:log_1:9)
Block(2,14,4,biomesoplenty:leaves_0:15)
Block(2,12,5,biomesoplenty:log_1:1)
Block(2,13,5,biomesoplenty:log_1:5)
Block(2,9,6,biomesoplenty:leaves_0:15)
Block(2,9,7,biomesoplenty:leaves_0:7)
Block(2,9,8,biomesoplenty:leaves_0:7)
Block(2,10,8,biomesoplenty:leaves_0:7)
Block(2,9,9,biomesoplenty:leaves_0:7)
Block(2,9,10,biomesoplenty:leaves_0:7)
Block(2,8,15,biomesoplenty:leaves_0:3)
Block(2,9,15,biomesoplenty:leaves_0:7)
Block(3,12,5,biomesoplenty:log_1:9)
Block(3,19,5,biomesoplenty:leaves_0:3)
Block(3,9,6,biomesoplenty:leaves_0:15)
Block(3,11,6,biomesoplenty:log_1:1)
Block(3,12,6,biomesoplenty:log_1:5)
Block(3,8,7,biomesoplenty:leaves_0:7)
Block(3,9,7,biomesoplenty:leaves_0:7)
Block(3,10,7,biomesoplenty:leaves_0:7)
Block(3,19,7,biomesoplenty:leaves_0:7)
Block(3,8,8,biomesoplenty:leaves_0:7)
Block(3,9,8,biomesoplenty:leaves_0:7)
Block(3,10,8,biomesoplenty:leaves_0:7)
Block(3,9,9,biomesoplenty:leaves_0:7)
Block(3,10,9,biomesoplenty:leaves_0:7)
Block(3,9,10,biomesoplenty:leaves_0:7)
Block(3,10,10,biomesoplenty:leaves_0:7)
Block(3,9,11,biomesoplenty:leaves_0:7)
Block(3,8,15,biomesoplenty:leaves_0:3)
Block(3,9,15,biomesoplenty:leaves_0:3)
Block(4,0,5,biomesoplenty:log_1:1)
Block(4,1,5,biomesoplenty:log_1:1)
Block(4,9,5,biomesoplenty:leaves_0:15)
Block(4,18,5,biomesoplenty:leaves_0:3)
Block(4,19,5,biomesoplenty:leaves_0:15)
Block(4,0,6,biomesoplenty:leaves_0:15)
Block(4,1,6,biomesoplenty:log_1:9)
Block(4,9,6,biomesoplenty:leaves_0:15)
Block(4,11,6,biomesoplenty:log_1:9)
Block(4,17,6,biomesoplenty:leaves_0:3)
Block(4,18,6,biomesoplenty:leaves_0:3)
Block(4,19,6,biomesoplenty:leaves_0:3)
Block(4,9,7,biomesoplenty:leaves_0:7)
Block(4,10,7,biomesoplenty:leaves_0:7)
Block(4,11,7,biomesoplenty:log_1:9)
Block(4,12,7,biomesoplenty:leaves_0:7)
Block(4,19,7,biomesoplenty:leaves_0:3)
Block(4,20,7,biomesoplenty:leaves_0:3)
Block(4,8,8,biomesoplenty:leaves_0:7)
Block(4,9,8,biomesoplenty:leaves_0:7)
Block(4,10,8,biomesoplenty:log_1:9)
Block(4,11,8,biomesoplenty:log_1:5)
Block(4,19,8,biomesoplenty:leaves_0:3)
Block(4,20,8,biomesoplenty:leaves_0:3)
Block(4,8,9,biomesoplenty:leaves_0:7)
Block(4,9,9,biomesoplenty:log_1:1)
Block(4,10,9,biomesoplenty:log_1:5)
Block(4,19,9,biomesoplenty:leaves_0:15)
Block(4,9,10,biomesoplenty:leaves_0:7)
Block(4,10,10,biomesoplenty:leaves_0:7)
Block(4,20,10,biomesoplenty:leaves_0:15)
Block(4,9,11,biomesoplenty:leaves_0:7)
Block(4,20,11,biomesoplenty:leaves_0:3)
Block(4,19,12,biomesoplenty:leaves_0:3)
Block(4,20,12,biomesoplenty:leaves_0:3)
Block(4,21,12,biomesoplenty:leaves_0:3)
Block(4,9,13,biomesoplenty:log_1:1)
Block(4,20,13,biomesoplenty:leaves_0:3)
Block(4,9,14,biomesoplenty:log_1:9)
Block(4,10,14,biomesoplenty:log_1:5)
Block(4,20,14,biomesoplenty:leaves_0:7)
Block(4,6,15,biomesoplenty:leaves_0:15)
Block(4,7,15,biomesoplenty:leaves_0:15)
Block(4,8,15,biomesoplenty:leaves_0:3)
Block(4,9,15,biomesoplenty:leaves_0:15)
Block(4,10,15,biomesoplenty:log_1:9)
Block(5,0,4,biomesoplenty:log_1:9)
Block(5,19,4,biomesoplenty:leaves_0:3)
Block(5,20,4,biomesoplenty:leaves_0:3)
Block(5,0,5,biomesoplenty:log_1:5)
Block(5,1,5,biomesoplenty:log_1:5)
Block(5,2,5,biomesoplenty:leaves_0:15)
Block(5,12,5,biomesoplenty:leaves_0:7)
Block(5,18,5,biomesoplenty:leaves_0:3)
Block(5,19,5,biomesoplenty:leaves_0:3)
Block(5,20,5,biomesoplenty:leaves_0:3)
Block(5,0,6,biomesoplenty:log_1:5)
Block(5,1,6,biomesoplenty:log_1:9)
Block(5,2,6,biomesoplenty:log_1:5)
Block(5,9,6,biomesoplenty:leaves_0:7)
Block(5,11,6,biomesoplenty:log_1:5)
Block(5,12,6,biomesoplenty:log_1:9)
Block(5,13,6,biomesoplenty:leaves_0:7)
Block(5,17,6,biomesoplenty:leaves_0:3)
Block(5,18,6,biomesoplenty:leaves_0:3)
Block(5,19,6,biomesoplenty:log_1:1)
Block(5,20,6,biomesoplenty:leaves_0:3)
Block(5,21,6,biomesoplenty:leaves_0:3)
Block(5,0,7,biomesoplenty:log_1:5)
Block(5,8,7,biomesoplenty:leaves_0:7)
Block(5,9,7,biomesoplenty:leaves_0:7)
Block(5,10,7,biomesoplenty:log_1:9)
Block(5,11,7,biomesoplenty:log_1:9)
Block(5,12,7,biomesoplenty:log_1:5)
Block(5,18,7,biomesoplenty:leaves_0:3)
Block(5,19,7,biomesoplenty:leaves_0:3)
Block(5,20,7,biomesoplenty:leaves_0:3)
Block(5,21,7,biomesoplenty:leaves_0:3)
Block(5,8,8,biomesoplenty:leaves_0:7)
Block(5,9,8,biomesoplenty:log_1:5)
Block(5,10,8,biomesoplenty:log_1:9)
Block(5,11,8,biomesoplenty:log_1:5)
Block(5,12,8,biomesoplenty:log_1:5)
Block(5,18,8,biomesoplenty:leaves_0:3)
Block(5,19,8,biomesoplenty:leaves_0:3)
Block(5,20,8,biomesoplenty:leaves_0:3)
Block(5,21,8,biomesoplenty:leaves_0:3)
Block(5,22,8,biomesoplenty:leaves_0:3)
Block(5,8,9,biomesoplenty:leaves_0:7)
Block(5,9,9,biomesoplenty:log_1:9)
Block(5,10,9,biomesoplenty:log_1:5)
Block(5,11,9,biomesoplenty:leaves_0:7)
Block(5,19,9,biomesoplenty:leaves_0:15)
Block(5,20,9,biomesoplenty:leaves_0:3)
Block(5,21,9,biomesoplenty:leaves_0:3)
Block(5,8,10,biomesoplenty:log_1:1)
Block(5,9,10,biomesoplenty:log_1:9)
Block(5,10,10,biomesoplenty:log_1:5)
Block(5,19,10,biomesoplenty:leaves_0:15)
Block(5,20,10,biomesoplenty:leaves_0:3)
Block(5,9,11,biomesoplenty:log_1:1)
Block(5,19,11,biomesoplenty:leaves_0:3)
Block(5,20,11,biomesoplenty:leaves_0:3)
Block(5,18,12,biomesoplenty:leaves_0:3)
Block(5,20,12,biomesoplenty:leaves_0:3)
Block(5,21,12,biomesoplenty:leaves_0:3)
Block(5,8,13,biomesoplenty:log_1:9)
Block(5,9,13,biomesoplenty:log_1:5)
Block(5,19,13,biomesoplenty:leaves_0:3)
Block(5,20,13,biomesoplenty:leaves_0:7)
Block(5,21,13,biomesoplenty:leaves_0:7)
Block(5,10,14,biomesoplenty:leaves_0:7)
Block(5,19,14,biomesoplenty:leaves_0:7)
Block(5,20,14,biomesoplenty:leaves_0:3)
Block(5,9,15,biomesoplenty:leaves_0:15)
Block(5,20,15,biomesoplenty:leaves_0:3)
Block(6,19,2,biomesoplenty:leaves_0:3)
Block(6,18,3,biomesoplenty:leaves_0:3)
Block(6,19,3,biomesoplenty:leaves_0:3)
Block(6,20,3,biomesoplenty:leaves_0:3)
Block(6,0,4,biomesoplenty:log_1:5)
Block(6,2,4,biomesoplenty:leaves_0:15)
Block(6,12,4,biomesoplenty:leaves_0:7)
Block(6,19,4,biomesoplenty:leaves_0:3)
Block(6,20,4,biomesoplenty:leaves_0:3)
Block(6,0,5,biomesoplenty:log_1:5)
Block(6,1,5,biomesoplenty:log_1:5)
Block(6,2,5,biomesoplenty:log_1:5)
Block(6,12,5,biomesoplenty:log_1:5)
Block(6,13,5,biomesoplenty:log_1:9)
Block(6,14,5,biomesoplenty:leaves_0:7)
Block(6,17,5,biomesoplenty:leaves_0:3)
Block(6,18,5,biomesoplenty:leaves_0:3)
Block(6,19,5,biomesoplenty:leaves_0:3)
Block(6,20,5,biomesoplenty:leaves_0:3)
Block(6,21,5,biomesoplenty:leaves_0:15)
Block(6,0,6,biomesoplenty:log_1:5)
Block(6,1,6,biomesoplenty:log_1:5)
Block(6,2,6,biomesoplenty:log_1:5)
Block(6,3,6,biomesoplenty:leaves_0:15)
Block(6,11,6,biomesoplenty:log_1:1)
Block(6,12,6,biomesoplenty:log_1:1)
Block(6,13,6,biomesoplenty:log_1:5)
Block(6,17,6,biomesoplenty:leaves_0:3)
Block(6,18,6,biomesoplenty:leaves_0:3)
Block(6,19,6,biomesoplenty:log_1:9)
Block(6,20,6,biomesoplenty:leaves_0:3)
Block(6,21,6,biomesoplenty:leaves_0:3)
Block(6,1,7,biomesoplenty:log_1:9)
Block(6,2,7,biomesoplenty:log_1:5)
Block(6,3,7,biomesoplenty:leaves_0:15)
Block(6,10,7,biomesoplenty:log_1:5)
Block(6,11,7,biomesoplenty:log_1:5)
Block(6,12,7,biomesoplenty:log_1:1)
Block(6,13,7,biomesoplenty:leaves_0:7)
Block(6,14,7,biomesoplenty:leaves_0:7)
Block(6,18,7,biomesoplenty:leaves_0:3)
Block(6,19,7,biomesoplenty:leaves_0:3)
Block(6,20,7,biomesoplenty:leaves_0:3)
Block(6,21,7,biomesoplenty:leaves_0:3)
Block(6,22,7,biomesoplenty:leaves_0:3)
Block(6,8,8,biomesoplenty:leaves_0:7)
Block(6,9,8,biomesoplenty:leaves_0:7)
Block(6,12,8,biomesoplenty:leaves_0:7)
Block(6,18,8,biomesoplenty:leaves_0:3)
Block(6,19,8,biomesoplenty:leaves_0:3)
Block(6,20,8,biomesoplenty:log_1:1)
Block(6,21,8,biomesoplenty:leaves_0:3)
Block(6,8,9,biomesoplenty:log_1:9)
Block(6,9,9,biomesoplenty:log_1:9)
Block(6,10,9,biomesoplenty:leaves_0:7)
Block(6,18,9,biomesoplenty:leaves_0:3)
Block(6,19,9,biomesoplenty:leaves_0:3)
Block(6,20,9,biomesoplenty:leaves_0:3)
Block(6,21,9,biomesoplenty:leaves_0:3)
Block(6,22,9,biomesoplenty:leaves_0:3)
Block(6,7,10,biomesoplenty:log_1:1)
Block(6,8,10,biomesoplenty:log_1:5)
Block(6,9,10,biomesoplenty:log_1:5)
Block(6,10,10,biomesoplenty:leaves_0:7)
Block(6,19,10,biomesoplenty:leaves_0:3)
Block(6,20,10,biomesoplenty:leaves_0:3)
Block(6,21,10,biomesoplenty:leaves_0:3)
Block(6,8,11,biomesoplenty:log_1:1)
Block(6,9,11,biomesoplenty:log_1:5)
Block(6,10,11,biomesoplenty:leaves_0:7)
Block(6,18,11,biomesoplenty:leaves_0:3)
Block(6,19,11,biomesoplenty:leaves_0:3)
Block(6,20,11,biomesoplenty:leaves_0:3)
Block(6,21,11,biomesoplenty:leaves_0:3)
Block(6,8,12,biomesoplenty:log_1:9)
Block(6,9,12,biomesoplenty:leaves_0:7)
Block(6,18,12,biomesoplenty:leaves_0:3)
Block(6,19,12,biomesoplenty:log_1:9)
Block(6,20,12,biomesoplenty:log_1:5)
Block(6,21,12,biomesoplenty:leaves_0:3)
Block(6,22,12,biomesoplenty:leaves_0:3)
Block(6,9,13,biomesoplenty:leaves_0:7)
Block(6,18,13,biomesoplenty:leaves_0:3)
Block(6,19,13,biomesoplenty:log_1:1)
Block(6,20,13,biomesoplenty:leaves_0:3)
Block(6,21,13,biomesoplenty:leaves_0:3)
Block(6,18,14,biomesoplenty:leaves_0:3)
Block(6,19,14,biomesoplenty:leaves_0:3)
Block(6,20,14,biomesoplenty:leaves_0:3)
Block(6,21,14,biomesoplenty:leaves_0:3)
Block(6,19,15,biomesoplenty:leaves_0:3)
Block(6,20,15,biomesoplenty:leaves_0:3)
Block(6,21,15,biomesoplenty:leaves_0:3)
Block(7,19,1,biomesoplenty:leaves_0:7)
Block(7,18,2,biomesoplenty:leaves_0:3)
Block(7,19,2,biomesoplenty:leaves_0:3)
Block(7,20,2,biomesoplenty:leaves_0:3)
Block(7,18,3,biomesoplenty:leaves_0:3)
Block(7,19,3,biomesoplenty:leaves_0:3)
Block(7,20,3,biomesoplenty:leaves_0:3)
Block(7,15,4,biomesoplenty:leaves_0:15)
Block(7,16,4,biomesoplenty:leaves_0:15)
Block(7,17,4,biomesoplenty:leaves_0:15)
Block(7,18,4,biomesoplenty:log_1:5)
Block(7,19,4,biomesoplenty:leaves_0:3)
Block(7,20,4,biomesoplenty:leaves_0:3)
Block(7,21,4,biomesoplenty:leaves_0:15)
Block(7,1,5,biomesoplenty:leaves_0:15)
Block(7,3,5,biomesoplenty:leaves_0:15)
Block(7,12,5,biomesoplenty:leaves_0:7)
Block(7,13,5,biomesoplenty:log_1:9)
Block(7,14,5,biomesoplenty:log_1:5)
Block(7,17,5,biomesoplenty:log_1:1)
Block(7,18,5,biomesoplenty:log_1:5)
Block(7,19,5,biomesoplenty:leaves_0:3)
Block(7,20,5,biomesoplenty:leaves_0:3)
Block(7,21,5,biomesoplenty:leaves_0:3)
Block(7,22,5,biomesoplenty:leaves_0:3)
Block(7,1,6,biomesoplenty:log_1:1)
Block(7,2,6,biomesoplenty:log_1:5)
Block(7,3,6,biomesoplenty:leaves_0:15)
Block(7,11,6,biomesoplenty:leaves_0:7)
Block(7,12,6,biomesoplenty:log_1:5)
Block(7,13,6,biomesoplenty:log_1:1)
Block(7,14,6,biomesoplenty:log_1:5)
Block(7,15,6,biomesoplenty:leaves_0:7)
Block(7,18,6,biomesoplenty:leaves_0:3)
Block(7,19,6,biomesoplenty:leaves_0:3)
Block(7,20,6,biomesoplenty:leaves_0:3)
Block(7,21,6,biomesoplenty:leaves_0:3)
Block(7,22,6,biomesoplenty:leaves_0:7)
Block(7,1,7,biomesoplenty:log_1:1)
Block(7,2,7,biomesoplenty:log_1:5)
Block(7,3,7,biomesoplenty:log_1:5)
Block(7,4,7,biomesoplenty:leaves_0:15)
Block(7,10,7,biomesoplenty:leaves_0:7)
Block(7,11,7,biomesoplenty:leaves_0:7)
Block(7,13,7,biomesoplenty:leaves_0:7)
Block(7,15,7,biomesoplenty:leaves_0:7)
Block(7,18,7,biomesoplenty:leaves_0:3)
Block(7,19,7,biomesoplenty:log_1:9)
Block(7,20,7,biomesoplenty:leaves_0:3)
Block(7,21,7,biomesoplenty:leaves_0:3)
Block(7,22,7,biomesoplenty:leaves_0:3)
Block(7,3,8,biomesoplenty:log_1:1)
Block(7,4,8,biomesoplenty:leaves_0:15)
Block(7,18,8,biomesoplenty:leaves_0:3)
Block(7,19,8,biomesoplenty:log_1:9)
Block(7,20,8,biomesoplenty:log_1:5)
Block(7,21,8,biomesoplenty:leaves_0:3)
Block(7,22,8,biomesoplenty:leaves_0:3)
Block(7,5,9,biomesoplenty:leaves_0:15)
Block(7,6,9,biomesoplenty:log_1:1)
Block(7,7,9,biomesoplenty:leaves_0:7)
Block(7,9,9,biomesoplenty:leaves_0:7)
Block(7,18,9,biomesoplenty:leaves_0:3)
Block(7,19,9,biomesoplenty:log_1:1)
Block(7,20,9,biomesoplenty:leaves_0:3)
Block(7,22,9,biomesoplenty:leaves_0:3)
Block(7,6,10,biomesoplenty:leaves_0:15)
Block(7,7,10,biomesoplenty:log_1:1)
Block(7,8,10,biomesoplenty:log_1:5)
Block(7,9,10,biomesoplenty:leaves_0:7)
Block(7,18,10,biomesoplenty:leaves_0:3)
Block(7,19,10,biomesoplenty:leaves_0:3)
Block(7,20,10,biomesoplenty:leaves_0:3)
Block(7,21,10,biomesoplenty:leaves_0:3)
Block(7,22,10,biomesoplenty:leaves_0:3)
Block(7,8,11,biomesoplenty:log_1:9)
Block(7,9,11,biomesoplenty:leaves_0:7)
Block(7,19,11,biomesoplenty:leaves_0:3)
Block(7,20,11,biomesoplenty:leaves_0:3)
Block(7,21,11,biomesoplenty:leaves_0:3)
Block(7,22,11,biomesoplenty:leaves_0:7)
Block(7,14,12,biomesoplenty:leaves_0:7)
Block(7,15,12,biomesoplenty:leaves_0:7)
Block(7,16,12,biomesoplenty:leaves_0:7)
Block(7,17,12,biomesoplenty:leaves_0:15)
Block(7,18,12,biomesoplenty:log_1:1)
Block(7,19,12,biomesoplenty:leaves_0:3)
Block(7,20,12,biomesoplenty:leaves_0:3)
Block(7,22,12,biomesoplenty:leaves_0:3)
Block(7,18,13,biomesoplenty:log_1:9)
Block(7,19,13,biomesoplenty:leaves_0:3)
Block(7,20,13,biomesoplenty:leaves_0:3)
Block(7,22,13,biomesoplenty:leaves_0:3)
Block(7,14,14,biomesoplenty:leaves_0:7)
Block(7,15,14,biomesoplenty:leaves_0:7)
Block(7,16,14,biomesoplenty:leaves_0:7)
Block(7,17,14,biomesoplenty:leaves_0:7)
Block(7,18,14,biomesoplenty:log_1:9)
Block(7,19,14,biomesoplenty:log_1:1)
Block(7,20,14,biomesoplenty:log_1:5)
Block(7,21,14,biomesoplenty:leaves_0:3)
Block(7,18,15,biomesoplenty:leaves_0:3)
Block(7,19,15,biomesoplenty:leaves_0:3)
Block(7,20,15,biomesoplenty:leaves_0:3)
Block(7,21,15,biomesoplenty:leaves_0:3)
Block(8,18,0,biomesoplenty:leaves_0:7)
Block(8,17,1,biomesoplenty:leaves_0:3)
Block(8,18,1,biomesoplenty:leaves_0:3)
Block(8,19,1,biomesoplenty:leaves_0:3)
Block(8,17,2,biomesoplenty:leaves_0:3)
Block(8,18,2,biomesoplenty:leaves_0:3)
Block(8,20,2,biomesoplenty:leaves_0:3)
Block(8,17,3,biomesoplenty:leaves_0:3)
Block(8,18,3,biomesoplenty:leaves_0:3)
Block(8,19,3,biomesoplenty:log_1:1)
Block(8,20,3,biomesoplenty:leaves_0:3)
Block(8,21,3,biomesoplenty:leaves_0:3)
Block(8,18,4,biomesoplenty:leaves_0:3)
Block(8,19,4,biomesoplenty:leaves_0:3)
Block(8,20,4,biomesoplenty:leaves_0:3)
Block(8,21,4,biomesoplenty:leaves_0:3)
Block(8,22,4,biomesoplenty:leaves_0:3)
Block(8,13,5,biomesoplenty:log_1:1)
Block(8,14,5,biomesoplenty:leaves_0:7)
Block(8,17,5,biomesoplenty:leaves_0:3)
Block(8,18,5,biomesoplenty:leaves_0:3)
Block(8,19,5,biomesoplenty:leaves_0:3)
Block(8,20,5,biomesoplenty:leaves_0:3)
Block(8,22,5,biomesoplenty:leaves_0:3)
Block(8,1,6,biomesoplenty:leaves_0:15)
Block(8,2,6,biomesoplenty:leaves_0:15)
Block(8,3,6,biomesoplenty:log_1:9)
Block(8,4,6,biomesoplenty:leaves_0:15)
Block(8,12,6,biomesoplenty:leaves_0:7)
Block(8,13,6,biomesoplenty:log_1:1)
Block(8,14,6,biomesoplenty:log_1:5)
Block(8,15,6,biomesoplenty:log_1:5)
Block(8,19,6,biomesoplenty:leaves_0:3)
Block(8,20,6,biomesoplenty:leaves_0:3)
Block(8,21,6,biomesoplenty:leaves_0:3)
Block(8,22,6,biomesoplenty:leaves_0:3)
Block(8,23,6,biomesoplenty:leaves_0:3)
Block(8,2,7,biomesoplenty:log_1:1)
Block(8,3,7,biomesoplenty:log_1:5)
Block(8,4,7,biomesoplenty:log_1:5)
Block(8,13,7,biomesoplenty:log_1:1)
Block(8,14,7,biomesoplenty:log_1:5)
Block(8,15,7,biomesoplenty:log_1:5)
Block(8,16,7,biomesoplenty:leaves_0:7)
Block(8,19,7,biomesoplenty:leaves_0:3)
Block(8,20,7,biomesoplenty:leaves_0:3)
Block(8,21,7,biomesoplenty:leaves_0:3)
Block(8,22,7,biomesoplenty:leaves_0:7)
Block(8,2,8,biomesoplenty:log_1:1)
Block(8,3,8,biomesoplenty:log_1:5)
Block(8,4,8,biomesoplenty:log_1:5)
Block(8,5,8,biomesoplenty:leaves_0:15)
Block(8,7,8,biomesoplenty:leaves_0:7)
Block(8,15,8,biomesoplenty:log_1:9)
Block(8,16,8,biomesoplenty:leaves_0:7)
Block(8,19,8,biomesoplenty:leaves_0:3)
Block(8,20,8,biomesoplenty:leaves_0:3)
Block(8,21,8,biomesoplenty:leaves_0:3)
Block(8,22,8,biomesoplenty:leaves_0:3)
Block(8,3,9,biomesoplenty:log_1:9)
Block(8,4,9,biomesoplenty:log_1:9)
Block(8,5,9,biomesoplenty:log_1:5)
Block(8,6,9,biomesoplenty:log_1:1)
Block(8,7,9,biomesoplenty:log_1:5)
Block(8,8,9,biomesoplenty:leaves_0:7)
Block(8,17,9,biomesoplenty:leaves_0:3)
Block(8,18,9,biomesoplenty:leaves_0:3)
Block(8,19,9,biomesoplenty:log_1:9)
Block(8,20,9,biomesoplenty:leaves_0:3)
Block(8,22,9,biomesoplenty:leaves_0:7)
Block(8,4,10,biomesoplenty:leaves_0:15)
Block(8,5,10,biomesoplenty:log_1:9)
Block(8,6,10,biomesoplenty:log_1:1)
Block(8,7,10,biomesoplenty:log_1:5)
Block(8,17,10,biomesoplenty:leaves_0:3)
Block(8,18,10,biomesoplenty:log_1:1)
Block(8,19,10,biomesoplenty:log_1:5)
Block(8,20,10,biomesoplenty:leaves_0:3)
Block(8,21,10,biomesoplenty:leaves_0:3)
Block(8,23,10,biomesoplenty:leaves_0:3)
Block(8,5,11,biomesoplenty:leaves_0:15)
Block(8,6,11,biomesoplenty:leaves_0:15)
Block(8,7,11,biomesoplenty:log_1:9)
Block(8,8,11,biomesoplenty:leaves_0:7)
Block(8,17,11,biomesoplenty:leaves_0:3)
Block(8,18,11,biomesoplenty:leaves_0:3)
Block(8,19,11,biomesoplenty:leaves_0:3)
Block(8,20,11,biomesoplenty:leaves_0:3)
Block(8,21,11,biomesoplenty:leaves_0:3)
Block(8,22,11,biomesoplenty:leaves_0:3)
Block(8,6,12,biomesoplenty:leaves_0:15)
Block(8,18,12,biomesoplenty:log_1:1)
Block(8,19,12,biomesoplenty:leaves_0:3)
Block(8,20,12,biomesoplenty:leaves_0:3)
Block(8,21,12,biomesoplenty:leaves_0:3)
Block(8,22,12,biomesoplenty:leaves_0:7)
Block(8,17,13,biomesoplenty:leaves_0:3)
Block(8,19,13,biomesoplenty:log_1:1)
Block(8,20,13,biomesoplenty:leaves_0:3)
Block(8,21,13,biomesoplenty:leaves_0:3)
Block(8,17,14,biomesoplenty:leaves_0:3)
Block(8,18,14,biomesoplenty:leaves_0:3)
Block(8,19,14,biomesoplenty:log_1:9)
Block(8,20,14,biomesoplenty:leaves_0:3)
Block(8,21,14,biomesoplenty:leaves_0:3)
Block(8,17,15,biomesoplenty:leaves_0:3)
Block(8,18,15,biomesoplenty:leaves_0:3)
Block(8,19,15,biomesoplenty:leaves_0:3)
Block(8,20,15,biomesoplenty:leaves_0:3)
Block(8,21,15,biomesoplenty:leaves_0:3)
Block(9,18,0,biomesoplenty:leaves_0:3)
Block(9,16,1,biomesoplenty:leaves_0:3)
Block(9,19,1,biomesoplenty:leaves_0:3)
Block(9,20,1,biomesoplenty:leaves_0:3)
Block(9,17,2,biomesoplenty:leaves_0:3)
Block(9,18,2,biomesoplenty:leaves_0:3)
Block(9,19,2,biomesoplenty:leaves_0:3)
Block(9,20,2,biomesoplenty:leaves_0:3)
Block(9,21,2,biomesoplenty:leaves_0:15)
Block(9,18,3,biomesoplenty:leaves_0:3)
Block(9,19,3,biomesoplenty:log_1:1)
Block(9,20,3,biomesoplenty:leaves_0:3)
Block(9,21,3,biomesoplenty:leaves_0:15)
Block(9,18,4,biomesoplenty:leaves_0:3)
Block(9,19,4,biomesoplenty:leaves_0:3)
Block(9,20,4,biomesoplenty:leaves_0:3)
Block(9,21,4,biomesoplenty:leaves_0:3)
Block(9,22,4,biomesoplenty:leaves_0:3)
Block(9,19,5,biomesoplenty:leaves_0:3)
Block(9,20,5,biomesoplenty:log_1:1)
Block(9,21,5,biomesoplenty:leaves_0:3)
Block(9,22,5,biomesoplenty:leaves_0:3)
Block(9,12,6,biomesoplenty:leaves_0:7)
Block(9,13,6,biomesoplenty:log_1:1)
Block(9,14,6,biomesoplenty:log_1:5)
Block(9,15,6,biomesoplenty:log_1:5)
Block(9,16,6,biomesoplenty:leaves_0:7)
Block(9,18,6,biomesoplenty:log_1:1)
Block(9,19,6,biomesoplenty:leaves_0:3)
Block(9,20,6,biomesoplenty:log_1:9)
Block(9,21,6,biomesoplenty:log_1:5)
Block(9,22,6,biomesoplenty:leaves_0:3)
Block(9,23,6,biomesoplenty:leaves_0:3)
Block(9,3,7,biomesoplenty:leaves_0:15)
Block(9,4,7,biomesoplenty:log_1:1)
Block(9,5,7,biomesoplenty:leaves_0:15)
Block(9,13,7,biomesoplenty:leaves_0:7)
Block(9,14,7,biomesoplenty:log_1:1)
Block(9,15,7,biomesoplenty:log_1:5)
Block(9,16,7,biomesoplenty:log_1:5)
Block(9,17,7,biomesoplenty:leaves_0:15)
Block(9,19,7,biomesoplenty:leaves_0:3)
Block(9,20,7,biomesoplenty:leaves_0:3)
Block(9,22,7,biomesoplenty:leaves_0:3)
Block(9,3,8,biomesoplenty:log_1:1)
Block(9,4,8,biomesoplenty:log_1:1)
Block(9,5,8,biomesoplenty:log_1:5)
Block(9,6,8,biomesoplenty:log_1:5)
Block(9,7,8,biomesoplenty:leaves_0:7)
Block(9,15,8,biomesoplenty:log_1:9)
Block(9,16,8,biomesoplenty:log_1:5)
Block(9,20,8,biomesoplenty:log_1:9)
Block(9,21,8,biomesoplenty:leaves_0:3)
Block(9,22,8,biomesoplenty:leaves_0:3)
Block(9,23,8,biomesoplenty:leaves_0:7)
Block(9,3,9,biomesoplenty:leaves_0:15)
Block(9,4,9,biomesoplenty:log_1:9)
Block(9,5,9,biomesoplenty:log_1:5)
Block(9,6,9,biomesoplenty:log_1:5)
Block(9,7,9,biomesoplenty:log_1:5)
Block(9,18,9,biomesoplenty:leaves_0:3)
Block(9,19,9,biomesoplenty:leaves_0:3)
Block(9,20,9,biomesoplenty:log_1:5)
Block(9,21,9,biomesoplenty:leaves_0:3)
Block(9,22,9,biomesoplenty:leaves_0:3)
Block(9,23,9,biomesoplenty:leaves_0:7)
Block(9,4,10,biomesoplenty:leaves_0:15)
Block(9,5,10,biomesoplenty:leaves_0:15)
Block(9,6,10,biomesoplenty:log_1:9)
Block(9,7,10,biomesoplenty:leaves_0:7)
Block(9,17,10,biomesoplenty:leaves_0:3)
Block(9,18,10,biomesoplenty:log_1:9)
Block(9,19,10,biomesoplenty:leaves_0:3)
Block(9,21,10,biomesoplenty:leaves_0:3)
Block(9,22,10,biomesoplenty:leaves_0:3)
Block(9,23,10,biomesoplenty:leaves_0:3)
Block(9,5,11,biomesoplenty:leaves_0:15)
Block(9,6,11,biomesoplenty:leaves_0:15)
Block(9,7,11,biomesoplenty:leaves_0:7)
Block(9,8,11,biomesoplenty:leaves_0:7)
Block(9,18,11,biomesoplenty:log_1:1)
Block(9,19,11,biomesoplenty:leaves_0:3)
Block(9,20,11,biomesoplenty:leaves_0:3)
Block(9,21,11,biomesoplenty:leaves_0:3)
Block(9,22,11,biomesoplenty:leaves_0:3)
Block(9,23,11,biomesoplenty:leaves_0:7)
Block(9,6,12,biomesoplenty:leaves_0:15)
Block(9,7,12,biomesoplenty:leaves_0:7)
Block(9,18,12,biomesoplenty:log_1:9)
Block(9,19,12,biomesoplenty:log_1:5)
Block(9,20,12,biomesoplenty:leaves_0:3)
Block(9,21,12,biomesoplenty:leaves_0:3)
Block(9,22,12,biomesoplenty:leaves_0:7)
Block(9,6,13,biomesoplenty:leaves_0:7)
Block(9,17,13,biomesoplenty:leaves_0:3)
Block(9,18,13,biomesoplenty:leaves_0:3)
Block(9,19,13,biomesoplenty:log_1:9)
Block(9,20,13,biomesoplenty:leaves_0:3)
Block(9,21,13,biomesoplenty:leaves_0:3)
Block(9,22,13,biomesoplenty:leaves_0:7)
Block(9,17,14,biomesoplenty:leaves_0:3)
Block(9,18,14,biomesoplenty:leaves_0:3)
Block(9,20,14,biomesoplenty:leaves_0:3)
Block(9,21,14,biomesoplenty:leaves_0:3)
Block(9,18,15,biomesoplenty:leaves_0:3)
Block(9,19,15,biomesoplenty:leaves_0:3)
Block(9,20,15,biomesoplenty:leaves_0:3)
Block(10,16,0,biomesoplenty:leaves_0:3)
Block(10,18,0,biomesoplenty:leaves_0:3)
Block(10,19,0,biomesoplenty:leaves_0:7)
Block(10,16,1,biomesoplenty:leaves_0:3)
Block(10,17,1,biomesoplenty:leaves_0:3)
Block(10,18,1,biomesoplenty:log_1:9)
Block(10,19,1,biomesoplenty:leaves_0:7)
Block(10,20,1,biomesoplenty:leaves_0:3)
Block(10,16,2,biomesoplenty:leaves_0:3)
Block(10,17,2,biomesoplenty:leaves_0:3)
Block(10,18,2,biomesoplenty:log_1:5)
Block(10,19,2,biomesoplenty:log_1:9)
Block(10,20,2,biomesoplenty:leaves_0:3)
Block(10,21,2,biomesoplenty:leaves_0:15)
Block(10,17,3,biomesoplenty:leaves_0:3)
Block(10,18,3,biomesoplenty:leaves_0:3)
Block(10,19,3,biomesoplenty:log_1:9)
Block(10,20,3,biomesoplenty:leaves_0:3)
Block(10,21,3,biomesoplenty:leaves_0:15)
Block(10,17,4,biomesoplenty:leaves_0:3)
Block(10,19,4,biomesoplenty:log_1:1)
Block(10,20,4,biomesoplenty:log_1:5)
Block(10,21,4,biomesoplenty:leaves_0:3)
Block(10,22,4,biomesoplenty:leaves_0:7)
Block(10,18,5,biomesoplenty:leaves_0:3)
Block(10,19,5,biomesoplenty:leaves_0:3)
Block(10,20,5,biomesoplenty:log_1:9)
Block(10,21,5,biomesoplenty:leaves_0:3)
Block(10,22,5,biomesoplenty:leaves_0:7)
Block(10,14,6,biomesoplenty:leaves_0:7)
Block(10,15,6,biomesoplenty:leaves_0:7)
Block(10,19,6,biomesoplenty:leaves_0:3)
Block(10,22,6,biomesoplenty:leaves_0:3)
Block(10,23,6,biomesoplenty:leaves_0:3)
Block(10,5,7,biomesoplenty:leaves_0:15)
Block(10,15,7,biomesoplenty:log_1:1)
Block(10,16,7,biomesoplenty:leaves_0:7)
Block(10,17,7,biomesoplenty:log_1:5)
Block(10,20,7,biomesoplenty:leaves_0:3)
Block(10,21,7,biomesoplenty:leaves_0:3)
Block(10,22,7,biomesoplenty:leaves_0:3)
Block(10,23,7,biomesoplenty:leaves_0:3)
Block(10,5,8,biomesoplenty:log_1:9)
Block(10,6,8,biomesoplenty:leaves_0:15)
Block(10,15,8,biomesoplenty:log_1:9)
Block(10,16,8,biomesoplenty:log_1:5)
Block(10,17,8,biomesoplenty:leaves_0:7)
Block(10,20,8,biomesoplenty:leaves_0:3)
Block(10,21,8,biomesoplenty:leaves_0:3)
Block(10,22,8,biomesoplenty:leaves_0:3)
Block(10,23,8,biomesoplenty:leaves_0:7)
Block(10,5,9,biomesoplenty:log_1:1)
Block(10,6,9,biomesoplenty:log_1:5)
Block(10,16,9,biomesoplenty:log_1:9)
Block(10,17,9,biomesoplenty:log_1:5)
Block(10,19,9,biomesoplenty:leaves_0:3)
Block(10,20,9,biomesoplenty:log_1:1)
Block(10,21,9,biomesoplenty:log_1:5)
Block(10,22,9,biomesoplenty:leaves_0:3)
Block(10,23,9,biomesoplenty:leaves_0:3)
Block(10,4,10,biomesoplenty:leaves_0:15)
Block(10,5,10,biomesoplenty:leaves_0:15)
Block(10,6,10,biomesoplenty:log_1:9)
Block(10,7,10,biomesoplenty:leaves_0:7)
Block(10,17,10,biomesoplenty:log_1:9)
Block(10,19,10,biomesoplenty:leaves_0:3)
Block(10,20,10,biomesoplenty:leaves_0:3)
Block(10,21,10,biomesoplenty:leaves_0:3)
Block(10,22,10,biomesoplenty:leaves_0:7)
Block(10,23,10,biomesoplenty:leaves_0:3)
Block(10,5,11,biomesoplenty:leaves_0:15)
Block(10,6,11,biomesoplenty:leaves_0:15)
Block(10,7,11,biomesoplenty:leaves_0:7)
Block(10,13,11,biomesoplenty:leaves_0:7)
Block(10,14,11,biomesoplenty:leaves_0:7)
Block(10,15,11,biomesoplenty:leaves_0:7)
Block(10,16,11,biomesoplenty:leaves_0:7)
Block(10,17,11,biomesoplenty:log_1:9)
Block(10,18,11,biomesoplenty:log_1:5)
Block(10,19,11,biomesoplenty:leaves_0:3)
Block(10,20,11,biomesoplenty:leaves_0:3)
Block(10,21,11,biomesoplenty:leaves_0:3)
Block(10,22,11,biomesoplenty:leaves_0:7)
Block(10,5,12,biomesoplenty:leaves_0:15)
Block(10,6,12,biomesoplenty:leaves_0:15)
Block(10,7,12,biomesoplenty:leaves_0:7)
Block(10,18,12,biomesoplenty:leaves_0:3)
Block(10,19,12,biomesoplenty:leaves_0:3)
Block(10,20,12,biomesoplenty:leaves_0:3)
Block(10,21,12,biomesoplenty:leaves_0:3)
Block(10,22,12,biomesoplenty:leaves_0:3)
Block(10,6,13,biomesoplenty:leaves_0:7)
Block(10,18,13,biomesoplenty:leaves_0:3)
Block(10,19,13,biomesoplenty:log_1:1)
Block(10,20,13,biomesoplenty:log_1:5)
Block(10,21,13,biomesoplenty:leaves_0:3)
Block(10,22,13,biomesoplenty:leaves_0:3)
Block(10,17,14,biomesoplenty:leaves_0:3)
Block(10,18,14,biomesoplenty:leaves_0:3)
Block(10,19,14,biomesoplenty:leaves_0:3)
Block(10,20,14,biomesoplenty:leaves_0:3)
Block(10,21,14,biomesoplenty:leaves_0:3)
Block(10,22,14,biomesoplenty:leaves_0:3)
Block(10,16,15,biomesoplenty:leaves_0:3)
Block(10,17,15,biomesoplenty:leaves_0:3)
Block(10,18,15,biomesoplenty:leaves_0:3)
Block(10,19,15,biomesoplenty:leaves_0:3)
Block(10,20,15,biomesoplenty:leaves_0:3)
Block(11,18,0,biomesoplenty:leaves_0:3)
Block(11,19,0,biomesoplenty:leaves_0:7)
Block(11,16,1,biomesoplenty:leaves_0:3)
Block(11,17,1,biomesoplenty:leaves_0:3)
Block(11,18,1,biomesoplenty:log_1:1)
Block(11,19,1,biomesoplenty:leaves_0:7)
Block(11,20,1,biomesoplenty:leaves_0:3)
Block(11,18,2,biomesoplenty:leaves_0:3)
Block(11,19,2,biomesoplenty:leaves_0:3)
Block(11,20,2,biomesoplenty:leaves_0:3)
Block(11,21,2,biomesoplenty:leaves_0:3)
Block(11,20,3,biomesoplenty:leaves_0:3)
Block(11,21,3,biomesoplenty:leaves_0:3)
Block(11,18,4,biomesoplenty:log_1:1)
Block(11,19,4,biomesoplenty:log_1:5)
Block(11,20,4,biomesoplenty:leaves_0:3)
Block(11,21,4,biomesoplenty:leaves_0:15)
Block(11,17,5,biomesoplenty:leaves_0:3)
Block(11,18,5,biomesoplenty:leaves_0:3)
Block(11,19,5,biomesoplenty:leaves_0:3)
Block(11,20,5,biomesoplenty:leaves_0:3)
Block(11,21,5,biomesoplenty:leaves_0:3)
Block(11,22,5,biomesoplenty:leaves_0:3)
Block(11,19,6,biomesoplenty:leaves_0:3)
Block(11,20,6,biomesoplenty:leaves_0:3)
Block(11,21,6,biomesoplenty:leaves_0:3)
Block(11,22,6,biomesoplenty:leaves_0:3)
Block(11,15,7,biomesoplenty:leaves_0:7)
Block(11,16,7,biomesoplenty:leaves_0:7)
Block(11,20,7,biomesoplenty:leaves_0:3)
Block(11,21,7,biomesoplenty:leaves_0:3)
Block(11,22,7,biomesoplenty:leaves_0:3)
Block(11,23,7,biomesoplenty:leaves_0:3)
Block(11,14,8,biomesoplenty:leaves_0:7)
Block(11,15,8,biomesoplenty:log_1:1)
Block(11,16,8,biomesoplenty:log_1:1)
Block(11,17,8,biomesoplenty:log_1:5)
Block(11,21,8,biomesoplenty:leaves_0:3)
Block(11,23,8,biomesoplenty:leaves_0:3)
Block(11,5,9,biomesoplenty:leaves_0:15)
Block(11,6,9,biomesoplenty:leaves_0:15)
Block(11,15,9,biomesoplenty:log_1:9)
Block(11,16,9,biomesoplenty:log_1:5)
Block(11,17,9,biomesoplenty:log_1:5)
Block(11,20,9,biomesoplenty:leaves_0:3)
Block(11,21,9,biomesoplenty:log_1:1)
Block(11,22,9,biomesoplenty:leaves_0:3)
Block(11,23,9,biomesoplenty:leaves_0:3)
Block(11,5,10,biomesoplenty:leaves_0:15)
Block(11,6,10,biomesoplenty:leaves_0:15)
Block(11,7,10,biomesoplenty:leaves_0:7)
Block(11,17,10,biomesoplenty:log_1:9)
Block(11,21,10,biomesoplenty:leaves_0:3)
Block(11,22,10,biomesoplenty:leaves_0:3)
Block(11,5,11,biomesoplenty:leaves_0:15)
Block(11,6,11,biomesoplenty:leaves_0:15)
Block(11,7,11,biomesoplenty:leaves_0:7)
Block(11,20,11,biomesoplenty:leaves_0:3)
Block(11,21,11,biomesoplenty:leaves_0:3)
Block(11,22,11,biomesoplenty:leaves_0:7)
Block(11,6,12,biomesoplenty:leaves_0:15)
Block(11,7,12,biomesoplenty:leaves_0:7)
Block(11,18,12,biomesoplenty:leaves_0:3)
Block(11,19,12,biomesoplenty:leaves_0:3)
Block(11,20,12,biomesoplenty:leaves_0:3)
Block(11,21,12,biomesoplenty:leaves_0:3)
Block(11,22,12,biomesoplenty:leaves_0:3)
Block(11,6,13,biomesoplenty:leaves_0:7)
Block(11,17,13,biomesoplenty:leaves_0:3)
Block(11,18,13,biomesoplenty:leaves_0:3)
Block(11,19,13,biomesoplenty:leaves_0:3)
Block(11,20,13,biomesoplenty:log_1:1)
Block(11,21,13,biomesoplenty:leaves_0:3)
Block(11,22,13,biomesoplenty:leaves_0:3)
Block(11,17,14,biomesoplenty:leaves_0:3)
Block(11,18,14,biomesoplenty:leaves_0:3)
Block(11,19,14,biomesoplenty:leaves_0:3)
Block(11,20,14,biomesoplenty:leaves_0:3)
Block(11,21,14,biomesoplenty:leaves_0:3)
Block(11,15,15,biomesoplenty:leaves_0:3)
Block(11,16,15,biomesoplenty:leaves_0:3)
Block(11,17,15,biomesoplenty:log_1:1)
Block(11,18,15,biomesoplenty:leaves_0:15)
Block(11,19,15,biomesoplenty:leaves_0:3)
Block(11,20,15,biomesoplenty:leaves_0:3)
Block(12,18,0,biomesoplenty:leaves_0:7)
Block(12,18,1,biomesoplenty:leaves_0:3)
Block(12,19,1,biomesoplenty:leaves_0:3)
Block(12,20,1,biomesoplenty:leaves_0:7)
Block(12,18,2,biomesoplenty:leaves_0:3)
Block(12,19,2,biomesoplenty:leaves_0:3)
Block(12,20,2,biomesoplenty:leaves_0:3)
Block(12,21,2,biomesoplenty:leaves_0:3)
Block(12,19,3,biomesoplenty:leaves_0:3)
Block(12,20,3,biomesoplenty:leaves_0:3)
Block(12,21,3,biomesoplenty:leaves_0:3)
Block(12,14,4,biomesoplenty:leaves_0:15)
Block(12,15,4,biomesoplenty:leaves_0:15)
Block(12,16,4,biomesoplenty:leaves_0:15)
Block(12,17,4,biomesoplenty:leaves_0:3)
Block(12,18,4,biomesoplenty:log_1:9)
Block(12,19,4,biomesoplenty:leaves_0:3)
Block(12,20,4,biomesoplenty:leaves_0:3)
Block(12,21,4,biomesoplenty:leaves_0:3)
Block(12,22,4,biomesoplenty:leaves_0:3)
Block(12,18,5,biomesoplenty:log_1:1)
Block(12,20,5,biomesoplenty:leaves_0:3)
Block(12,21,5,biomesoplenty:leaves_0:3)
Block(12,22,5,biomesoplenty:leaves_0:3)
Block(12,23,5,biomesoplenty:leaves_0:3)
Block(12,17,6,biomesoplenty:log_1:9)
Block(12,18,6,biomesoplenty:leaves_0:3)
Block(12,20,6,biomesoplenty:leaves_0:3)
Block(12,21,6,biomesoplenty:leaves_0:3)
Block(12,22,6,biomesoplenty:leaves_0:3)
Block(12,23,6,biomesoplenty:leaves_0:3)
Block(12,24,6,biomesoplenty:leaves_0:3)
Block(12,16,7,biomesoplenty:log_1:9)
Block(12,17,7,biomesoplenty:log_1:5)
Block(12,20,7,biomesoplenty:leaves_0:3)
Block(12,21,7,biomesoplenty:log_1:5)
Block(12,22,7,biomesoplenty:log_1:5)
Block(12,23,7,biomesoplenty:leaves_0:3)
Block(12,24,7,biomesoplenty:leaves_0:3)
Block(12,16,8,biomesoplenty:log_1:1)
Block(12,20,8,biomesoplenty:leaves_0:3)
Block(12,21,8,biomesoplenty:leaves_0:3)
Block(12,23,8,biomesoplenty:leaves_0:3)
Block(12,16,9,biomesoplenty:leaves_0:7)
Block(12,19,9,biomesoplenty:leaves_0:3)
Block(12,21,9,biomesoplenty:leaves_0:3)
Block(12,22,9,biomesoplenty:leaves_0:3)
Block(12,23,9,biomesoplenty:leaves_0:3)
Block(12,6,10,biomesoplenty:leaves_0:7)
Block(12,17,10,biomesoplenty:log_1:1)
Block(12,18,10,biomesoplenty:log_1:5)
Block(12,19,10,biomesoplenty:log_1:5)
Block(12,20,10,biomesoplenty:leaves_0:3)
Block(12,21,10,biomesoplenty:leaves_0:3)
Block(12,22,10,biomesoplenty:leaves_0:3)
Block(12,6,11,biomesoplenty:leaves_0:7)
Block(12,18,11,biomesoplenty:log_1:9)
Block(12,20,11,biomesoplenty:leaves_0:3)
Block(12,21,11,biomesoplenty:leaves_0:3)
Block(12,22,11,biomesoplenty:leaves_0:3)
Block(12,6,12,biomesoplenty:leaves_0:7)
Block(12,19,12,biomesoplenty:leaves_0:3)
Block(12,20,12,biomesoplenty:leaves_0:3)
Block(12,21,12,biomesoplenty:leaves_0:3)
Block(12,22,12,biomesoplenty:leaves_0:7)
Block(12,16,13,biomesoplenty:leaves_0:3)
Block(12,17,13,biomesoplenty:leaves_0:3)
Block(12,18,13,biomesoplenty:leaves_0:3)
Block(12,19,13,biomesoplenty:leaves_0:3)
Block(12,20,13,biomesoplenty:leaves_0:3)
Block(12,21,13,biomesoplenty:leaves_0:3)
Block(12,22,13,biomesoplenty:leaves_0:3)
Block(12,15,14,biomesoplenty:leaves_0:3)
Block(12,16,14,biomesoplenty:leaves_0:3)
Block(12,17,14,biomesoplenty:log_1:1)
Block(12,19,14,biomesoplenty:leaves_0:3)
Block(12,20,14,biomesoplenty:leaves_0:3)
Block(12,15,15,biomesoplenty:leaves_0:3)
Block(12,16,15,biomesoplenty:leaves_0:3)
Block(12,17,15,biomesoplenty:log_1:9)
Block(12,18,15,biomesoplenty:leaves_0:3)
Block(12,19,15,biomesoplenty:leaves_0:3)
Block(12,20,15,biomesoplenty:leaves_0:3)
Block(13,18,0,biomesoplenty:leaves_0:7)
Block(13,18,1,biomesoplenty:leaves_0:3)
Block(13,19,1,biomesoplenty:leaves_0:7)
Block(13,13,2,biomesoplenty:leaves_0:7)
Block(13,14,2,biomesoplenty:leaves_0:7)
Block(13,15,2,biomesoplenty:leaves_0:7)
Block(13,16,2,biomesoplenty:leaves_0:3)
Block(13,17,2,biomesoplenty:log_1:1)
Block(13,18,2,biomesoplenty:leaves_0:3)
Block(13,19,2,biomesoplenty:leaves_0:3)
Block(13,20,2,biomesoplenty:leaves_0:7)
Block(13,17,3,biomesoplenty:log_1:1)
Block(13,20,3,biomesoplenty:leaves_0:3)
Block(13,21,3,biomesoplenty:leaves_0:3)
Block(13,18,4,biomesoplenty:leaves_0:3)
Block(13,19,4,biomesoplenty:leaves_0:3)
Block(13,20,4,biomesoplenty:leaves_0:3)
Block(13,21,4,biomesoplenty:leaves_0:3)
Block(13,18,5,biomesoplenty:log_1:9)
Block(13,19,5,biomesoplenty:leaves_0:3)
Block(13,20,5,biomesoplenty:leaves_0:3)
Block(13,21,5,biomesoplenty:leaves_0:3)
Block(13,22,5,biomesoplenty:leaves_0:3)
Block(13,17,6,biomesoplenty:log_1:1)
Block(13,18,6,biomesoplenty:log_1:5)
Block(13,19,6,biomesoplenty:leaves_0:3)
Block(13,20,6,biomesoplenty:leaves_0:3)
Block(13,21,6,biomesoplenty:leaves_0:3)
Block(13,22,6,biomesoplenty:leaves_0:3)
Block(13,20,7,biomesoplenty:log_1:1)
Block(13,21,7,biomesoplenty:leaves_0:3)
Block(13,22,7,biomesoplenty:leaves_0:3)
Block(13,23,7,biomesoplenty:leaves_0:3)
Block(13,20,8,biomesoplenty:leaves_0:3)
Block(13,21,8,biomesoplenty:leaves_0:3)
Block(13,22,8,biomesoplenty:leaves_0:3)
Block(13,23,8,biomesoplenty:leaves_0:3)
Block(13,21,9,biomesoplenty:leaves_0:3)
Block(13,22,9,biomesoplenty:leaves_0:3)
Block(13,23,9,biomesoplenty:leaves_0:7)
Block(13,20,10,biomesoplenty:leaves_0:3)
Block(13,21,10,biomesoplenty:leaves_0:3)
Block(13,22,10,biomesoplenty:leaves_0:3)
Block(13,18,11,biomesoplenty:log_1:1)
Block(13,19,11,biomesoplenty:leaves_0:3)
Block(13,20,11,biomesoplenty:leaves_0:3)
Block(13,21,11,biomesoplenty:leaves_0:3)
Block(13,22,11,biomesoplenty:leaves_0:3)
Block(13,18,12,biomesoplenty:log_1:9)
Block(13,19,12,biomesoplenty:log_1:5)
Block(13,20,12,biomesoplenty:leaves_0:3)
Block(13,21,12,biomesoplenty:leaves_0:3)
Block(13,22,12,biomesoplenty:leaves_0:3)
Block(13,17,13,biomesoplenty:log_1:5)
Block(13,19,13,biomesoplenty:log_1:9)
Block(13,20,13,biomesoplenty:leaves_0:3)
Block(13,21,13,biomesoplenty:leaves_0:3)
Block(13,16,14,biomesoplenty:leaves_0:3)
Block(13,17,14,biomesoplenty:log_1:9)
Block(13,18,14,biomesoplenty:leaves_0:3)
Block(13,19,14,biomesoplenty:leaves_0:3)
Block(13,20,14,biomesoplenty:leaves_0:3)
Block(13,15,15,biomesoplenty:leaves_0:3)
Block(13,16,15,biomesoplenty:leaves_0:3)
Block(13,17,15,biomesoplenty:leaves_0:3)
Block(13,18,15,biomesoplenty:leaves_0:3)
Block(13,19,15,biomesoplenty:leaves_0:3)
Block(14,18,0,biomesoplenty:leaves_0:3)
Block(14,19,0,biomesoplenty:leaves_0:3)
Block(14,16,1,biomesoplenty:leaves_0:3)
Block(14,18,1,biomesoplenty:leaves_0:3)
Block(14,19,1,biomesoplenty:leaves_0:7)
Block(14,16,2,biomesoplenty:leaves_0:3)
Block(14,17,2,biomesoplenty:log_1:5)
Block(14,18,2,biomesoplenty:log_1:1)
Block(14,19,2,biomesoplenty:leaves_0:7)
Block(14,20,2,biomesoplenty:leaves_0:3)
Block(14,16,3,biomesoplenty:leaves_0:3)
Block(14,17,3,biomesoplenty:leaves_0:3)
Block(14,18,3,biomesoplenty:leaves_0:3)
Block(14,19,3,biomesoplenty:leaves_0:3)
Block(14,20,3,biomesoplenty:leaves_0:3)
Block(14,21,3,biomesoplenty:leaves_0:3)
Block(14,22,3,biomesoplenty:leaves_0:3)
Block(14,17,4,biomesoplenty:leaves_0:3)
Block(14,18,4,biomesoplenty:leaves_0:3)
Block(14,19,4,biomesoplenty:log_1:9)
Block(14,20,4,biomesoplenty:leaves_0:3)
Block(14,21,4,biomesoplenty:leaves_0:3)
Block(14,22,4,biomesoplenty:leaves_0:3)
Block(14,18,5,biomesoplenty:log_1:1)
Block(14,19,5,biomesoplenty:log_1:5)
Block(14,20,5,biomesoplenty:leaves_0:3)
Block(14,21,5,biomesoplenty:leaves_0:3)
Block(14,18,6,biomesoplenty:leaves_0:3)
Block(14,19,6,biomesoplenty:leaves_0:3)
Block(14,20,6,biomesoplenty:log_1:5)
Block(14,21,6,biomesoplenty:leaves_0:3)
Block(14,22,6,biomesoplenty:leaves_0:3)
Block(14,18,7,biomesoplenty:leaves_0:3)
Block(14,20,7,biomesoplenty:log_1:9)
Block(14,21,7,biomesoplenty:log_1:5)
Block(14,22,7,biomesoplenty:leaves_0:3)
Block(14,19,8,biomesoplenty:leaves_0:3)
Block(14,20,8,biomesoplenty:leaves_0:3)
Block(14,22,8,biomesoplenty:leaves_0:3)
Block(14,17,9,biomesoplenty:leaves_0:3)
Block(14,20,9,biomesoplenty:leaves_0:3)
Block(14,21,9,biomesoplenty:leaves_0:3)
Block(14,22,9,biomesoplenty:leaves_0:7)
Block(14,17,10,biomesoplenty:log_1:9)
Block(14,18,10,biomesoplenty:leaves_0:3)
Block(14,19,10,biomesoplenty:leaves_0:3)
Block(14,20,10,biomesoplenty:leaves_0:3)
Block(14,21,10,biomesoplenty:leaves_0:3)
Block(14,22,10,biomesoplenty:leaves_0:3)
Block(14,23,10,biomesoplenty:leaves_0:3)
Block(14,17,11,biomesoplenty:log_1:5)
Block(14,18,11,biomesoplenty:log_1:1)
Block(14,19,11,biomesoplenty:leaves_0:3)
Block(14,20,11,biomesoplenty:leaves_0:3)
Block(14,21,11,biomesoplenty:log_1:9)
Block(14,22,11,biomesoplenty:leaves_0:3)
Block(14,23,11,biomesoplenty:leaves_0:3)
Block(14,17,12,biomesoplenty:leaves_0:3)
Block(14,19,12,biomesoplenty:leaves_0:3)
Block(14,20,12,biomesoplenty:leaves_0:3)
Block(14,21,12,biomesoplenty:log_1:5)
Block(14,22,12,biomesoplenty:leaves_0:3)
Block(14,17,13,biomesoplenty:leaves_0:3)
Block(14,18,13,biomesoplenty:leaves_0:3)
Block(14,19,13,biomesoplenty:log_1:1)
Block(14,20,13,biomesoplenty:log_1:5)
Block(14,21,13,biomesoplenty:leaves_0:3)
Block(14,22,13,biomesoplenty:leaves_0:3)
Block(14,13,14,biomesoplenty:leaves_0:15)
Block(14,14,14,biomesoplenty:leaves_0:15)
Block(14,15,14,biomesoplenty:leaves_0:15)
Block(14,16,14,biomesoplenty:leaves_0:15)
Block(14,17,14,biomesoplenty:log_1:1)
Block(14,18,14,biomesoplenty:leaves_0:3)
Block(14,19,14,biomesoplenty:leaves_0:3)
Block(14,20,14,biomesoplenty:leaves_0:3)
Block(14,21,14,biomesoplenty:leaves_0:3)
Block(14,16,15,biomesoplenty:leaves_0:3)
Block(14,17,15,biomesoplenty:leaves_0:3)
Block(14,18,15,biomesoplenty:leaves_0:3)
Block(14,19,15,biomesoplenty:leaves_0:3)
Block(14,20,15,biomesoplenty:leaves_0:15)
Block(15,17,1,biomesoplenty:leaves_0:3)
Block(15,18,1,biomesoplenty:leaves_0:7)
Block(15,19,1,biomesoplenty:leaves_0:7)
Block(15,17,2,biomesoplenty:leaves_0:3)
Block(15,18,2,biomesoplenty:log_1:9)
Block(15,19,2,biomesoplenty:leaves_0:3)
Block(15,20,2,biomesoplenty:leaves_0:3)
Block(15,21,2,biomesoplenty:leaves_0:3)
Block(15,16,3,biomesoplenty:leaves_0:7)
Block(15,17,3,biomesoplenty:leaves_0:7)
Block(15,18,3,biomesoplenty:log_1:5)
Block(15,19,3,biomesoplenty:log_1:9)
Block(15,20,3,biomesoplenty:leaves_0:3)
Block(15,22,3,biomesoplenty:leaves_0:3)
Block(15,17,4,biomesoplenty:leaves_0:3)
Block(15,18,4,biomesoplenty:leaves_0:3)
Block(15,19,4,biomesoplenty:log_1:1)
Block(15,20,4,biomesoplenty:log_1:5)
Block(15,21,4,biomesoplenty:leaves_0:3)
Block(15,22,4,biomesoplenty:leaves_0:3)
Block(15,17,5,biomesoplenty:leaves_0:3)
Block(15,19,5,biomesoplenty:leaves_0:3)
Block(15,20,5,biomesoplenty:leaves_0:3)
Block(15,22,5,biomesoplenty:leaves_0:3)
Block(15,16,6,biomesoplenty:leaves_0:3)
Block(15,17,6,biomesoplenty:leaves_0:3)
Block(15,18,6,biomesoplenty:leaves_0:3)
Block(15,19,6,biomesoplenty:leaves_0:3)
Block(15,20,6,biomesoplenty:leaves_0:3)
Block(15,21,6,biomesoplenty:leaves_0:3)
Block(15,22,6,biomesoplenty:leaves_0:3)
Block(15,17,7,biomesoplenty:leaves_0:3)
Block(15,19,7,biomesoplenty:leaves_0:3)
Block(15,20,7,biomesoplenty:leaves_0:3)
Block(15,21,7,biomesoplenty:leaves_0:3)
Block(15,22,7,biomesoplenty:leaves_0:7)
Block(15,19,8,biomesoplenty:leaves_0:3)
Block(15,20,8,biomesoplenty:log_1:9)
Block(15,21,8,biomesoplenty:leaves_0:3)
Block(15,22,8,biomesoplenty:leaves_0:3)
Block(15,16,9,biomesoplenty:leaves_0:3)
Block(15,20,9,biomesoplenty:leaves_0:3)
Block(15,21,9,biomesoplenty:leaves_0:3)
Block(15,22,9,biomesoplenty:leaves_0:7)
Block(15,15,10,biomesoplenty:leaves_0:3)
Block(15,16,10,biomesoplenty:leaves_0:3)
Block(15,17,10,biomesoplenty:log_1:1)
Block(15,20,10,biomesoplenty:leaves_0:3)
Block(15,21,10,biomesoplenty:leaves_0:15)
Block(15,22,10,biomesoplenty:leaves_0:7)
Block(15,17,11,biomesoplenty:log_1:1)
Block(15,19,11,biomesoplenty:leaves_0:3)
Block(15,20,11,biomesoplenty:leaves_0:3)
Block(15,21,11,biomesoplenty:leaves_0:3)
Block(15,22,11,biomesoplenty:leaves_0:3)
Block(15,17,12,biomesoplenty:log_1:5)
Block(15,18,12,biomesoplenty:leaves_0:3)
Block(15,19,12,biomesoplenty:leaves_0:3)
Block(15,20,12,biomesoplenty:leaves_0:3)
Block(15,21,12,biomesoplenty:leaves_0:3)
Block(15,22,12,biomesoplenty:leaves_0:3)
Block(15,17,13,biomesoplenty:leaves_0:7)
Block(15,18,13,biomesoplenty:leaves_0:3)
Block(15,19,13,biomesoplenty:leaves_0:3)
Block(15,20,13,biomesoplenty:leaves_0:3)
Block(15,21,13,biomesoplenty:leaves_0:3)
Block(15,17,14,biomesoplenty:leaves_0:3)
Block(15,19,14,biomesoplenty:leaves_0:3)
Block(15,20,14,biomesoplenty:log_1:1)
Block(15,21,14,biomesoplenty:leaves_0:3)
Block(15,18,15,biomesoplenty:leaves_0:3)
Block(15,19,15,biomesoplenty:leaves_0:15)
Block(15,20,15,biomesoplenty:leaves_0:15)

#######################################################################
# +-----------------------------------------------------------------+ #
# |                             Branches                            | #
# +-----------------------------------------------------------------+ #
#######################################################################

# Branches are child-BO3's that spawn if this BO3 is configured to spawn as a
# CustomStructure resource in a biome config. Branches can have branches,
# making complex structures possible. See the wiki for more details.

# Regular Branches spawn each branch with an independent chance of spawning.
# Branch(x,y,z,isRequiredBranch,branchName,rotation,chance,branchDepth[,anotherBranchName,rotation,chance,branchDepth[,...]][IndividualChance])
# branchName - name of the object to spawn.
# rotation - NORTH, SOUTH, EAST or WEST.
# IndividualChance - The chance each branch has to spawn, assumed to be 100 when left blank
# isRequiredBranch - If this is set to true then at least one of the branches in this BO3 must spawn at these x,y,z coordinates. If no branch can spawn there then this BO3 fails to spawn and its branch is rolled back.
# isRequiredBranch:true branches must spawn or the current branch is rolled back entirely. This is useful for grouping BO3's that must spawn together, for instance a single room made of multiple BO3's/branches.
# If all parts of the room are connected together via isRequiredBranch:true branches then either the entire room will spawns or no part of it will spawn.
# *Note: When isRequiredBranch:true only one BO3 can be added per Branch() and it will automatically have a rarity of 100.0.
# isRequiredBranch:false branches are used to make optional parts of structures, for instance the middle section of a tunnel that has a beginning, middle and end BO3/branch and can have a variable length by repeating the middle BO3/branch.
# By making the start and end branches isRequiredBranch:true and the middle branch isRequiredbranch:false you can make it so that either:
# A. A tunnel spawns with at least a beginning and end branch
# B. A tunnel spawns with a beginning and end branch and as many middle branches as will fit in the available space.
# C. No tunnel spawns at all because there wasn't enough space to spawn at least a beginning and end branch.
# branchDepth - When creating a chain of branches that contains optional (isRequiredBranch:false) branches branch depth is configured for the first BO3 in the chain to determine the maximum length of the chain.
# branchDepth - 1 is inherited by each isRequiredBranch:false branch in the chain. When branchDepth is zero isRequiredBranch:false branches cannot spawn and the chain ends. In the case of the tunnel this means the last middle branch would be
# rolled back and an IsRequiredBranch:true end branch could be spawned in its place to make sure the tunnel has a proper ending.
# Instead of inheriting branchDepth - 1 from the parent branchDepth can be overridden by child branches if it is set higher than 0 (the default value).
# isRequiredBranch:true branches do inherit branchDepth and pass it on to their own branches, however they cannot be prevented from spawning by it and also don't subtract 1 from branchDepth when inheriting it.

# Weighted Branches spawn branches with a dependent chance of spawning.
# WeightedBranch(x,y,z,isRequiredBranch,branchName,rotation,chance,branchDepth[,anotherBranchName,rotation,chance,branchDepth[,...]][MaxChanceOutOf])
# *Note: isRequiredBranch must be set to false. It is not possible to use isRequiredBranch:true with WeightedBranch() since isRequired:true branches must spawn and automatically have a rarity of 100.0.
# MaxChanceOutOf - The chance all branches have to spawn out of, assumed to be 100 when left blank
Branch(16,0,0,true,mmagic1C2R1,NORTH,100.0,0)

#######################################################################
# +-----------------------------------------------------------------+ #
# |                             Entities                            | #
# +-----------------------------------------------------------------+ #
#######################################################################

# Forge only (this may have changed, check for updates).
# An EntityFunction spawns an entity instead of a block. The entity is spawned only once when the BO3 is spawned.
# Entities are persistent by default so they don't de-spawn when no player is near, they are only unloaded.
# Usage: Entity(x,y,z,entityName,groupSize,NameTagOrNBTFileName) or Entity(x,y,z,mobName,groupSize)
# Use /otg entities to get a list of entities that can be used as entityName, this includes entities added by other mods and non-living entities.
# NameTagOrNBTFileName can be either a nametag for the mob or an .txt file with nbt data (such as myentityinfo.txt).
# In the text file you can use the same mob spawning parameters used with the /summon command to equip the
# entity and give it custom attributes etc. You can copy the DATA part of a summon command including surrounding 
# curly braces to a .txt file, for instance for: "/summon Skeleton x y z {DATA}"

#######################################################################
# +-----------------------------------------------------------------+ #
# |                            Particles                            | #
# +-----------------------------------------------------------------+ #
#######################################################################

# Forge only (this may have changed, check for updates).
# Creates an invisible particle spawner at the given location that spawns particles every x milliseconds.
# Usage: Particle(x,y,z,particleName,interval,velocityX,velocityY,velocityZ)
# velocityX, velocityY and velocityZ are optional.
# Only vanilla particle names can be used, for 1.11.2 these are;
# explode, largeexplode, hugeexplosion, fireworksSpark, bubble, splash, wake, suspended
# depthsuspend, crit, magicCrit, smoke, largesmoke, spell, instantSpell, mobSpell
# mobSpellAmbient, witchMagic, dripWater, dripLava, angryVillager, happyVillager
# townaura, note, portal, enchantmenttable, flame, lava, footstep, cloud, reddust
# snowballpoof,  snowshovel, slime, heart, barrier, iconcrack, blockcrack, blockdust
# droplet, take, mobappearance, dragonbreath, endRod, damageIndicator, sweepAttack
# fallingdust, totem, spit.
# velocityX,velocityY,velocityZ - Spawn the enemy with the given velocity. If this is not filled in then a small random velocity is applied.

#######################################################################
# +-----------------------------------------------------------------+ #
# |                             Spawners                            | #
# +-----------------------------------------------------------------+ #
#######################################################################

# Forge only (this may have changed, check for updates).
# Creates an invisible entity spawner at the given location that spawns entities every x seconds.
# Entities can only spawn if their spawn requirements are met (zombies/skeletons only spawn in the dark etc). Max entity count for the server is ignored, each spawner has its own maxCount setting.
# Usage: Spawner(x,y,z,entityName,nbtFileName,groupSize,interval,spawnChance,maxCount,despawnTime,velocityX,velocityY,velocityZ,yaw,pitch)
# nbtFileName, despawnTime, velocityX, velocityY, velocityZ, yaw and pitch are optional
# Example Spawner(0, 0, 0, Villager, 1, 5, 100, 5) or Spawner(0, 0, 0, Villager, villager1.txt, 1, 5, 100, 5) or Spawner(0, 0, 0, Villager, 1, 5, 100, 5, 30, 1, 1, 1, 0, 0)
# entityName - Name of the entity to spawn, use /otg entities to get a list of entities that can be used as entityName, this includes entities added by other mods and non-living entities.
# nbtFileName - A .txt file with nbt data (such as myentityinfo.txt).
# In the text file you can use the same mob spawning parameters used with the /summon command to equip the
# entity and give it custom attributes etc. You can copy the DATA part of a summon command including surrounding 
# curly braces to a .txt file, for instance for: "/summon Skeleton x y z {DATA}"
# groupSize - Number of entities that should spawn for each successful spawn attempt.
# interval - Time in seconds between each spawn attempt.
# spawnChance - For each spawn attempt, the chance between 0-100 that the spawn attempt will succeed.
# maxCount - The maximum amount of this kind of entity that can exist within 32 blocks. If there are already maxCount or more entities of this type in a 32 radius this spawner will not spawn anything.
# despawnTime - After despawnTime seconds, if there is no player within 32 blocks of the entity it will despawn..
# velocityX,velocityY,velocityZ,yaw,pitch - Spawn the enemy with the given velocity and angle, handy for making traps and launchers (shooting arrows and fireballs etc).

#######################################################################
# +-----------------------------------------------------------------+ #
# |                             ModData                             | #
# +-----------------------------------------------------------------+ #
#######################################################################

# Forge only.
# Use the ModData() tag to include data that other mods can use
# Mod makers can use ModData and the /otg GetModData command to test IMC communications between OTG
# and their mod.
# Normal users can use it to spawn some mobs and blocks on command.
# ModData(x,y,z,"ModName", "MyModDataAsText"
# Example: ModData(x,y,z,MyCystomNPCMod,SpawnBobHere/WithAPotato/And50Health)
# Try not to use exotic/reserved characters, like brackets and comma's etc, this stuff isn't fool-proof.
# Also, use this only to store IDs/object names etc for your mod, DO NOT include things like character dialogue,
# messages on signs, loot lists etc in this file. As much as possible just store id's/names here and store all the data related to those id's/names in your own mod.
# OTG has some built in ModData commands for basic mob and block spawning.
# These are mostly just a demonstration for mod makers to show how ModData.
# can be used by other mods.
# For mob spawning in OTG use: ModData(x,y,z,OTG,mob/MobType/Count/Persistent/Name)
# mob: Makes OTG recognise this as a mob spawning command.
# MobType: Lower-case, no spaces. Any vanilla mob like dragon, skeleton, wither, villager etc
# Count: The number of mobs to spawn
# Persistent (true/false): Should the mobs never de-spawn? If set to true the mob will get a
# name-tag ingame so you can recognise it.
# Name: A name-tag for the monster/npc.
# Example: ModData(0,0,0,OTG,villager/1/true/Bob)
# To spawn blocks using ModData use: ModData(x,y,z,OTG,block/material)
# block: Makes OTG recognise this as a block spawning command.
# material: id or text, custom blocks can be added using ModName:MaterialName.
# To send all ModData within a radius in chunks around the player to the specified mod
# use this console command: /otg GetModData ModName Radius
# ModName: name of the mod, for OTG commands use OTG 
# Radius (optional): Radius in chunks around the player.
