
#######################################################################
# +-----------------------------------------------------------------+ #
# |                            BO3 object                           | #
# +-----------------------------------------------------------------+ #
#######################################################################

# This is the config file of a custom object.
# If you add this object correctly to your BiomeConfigs, it will spawn in the world.

# This is the creator of this BO3 object
Author: Unknown

# A short description of this BO3 object
Description: No description

# The settings mode, WriteAll, WriteWithoutComments or WriteDisable. See WorldConfig.
SettingsMode: WriteAll


#######################################################################
# +-----------------------------------------------------------------+ #
# |                          Main settings                          | #
# +-----------------------------------------------------------------+ #
#######################################################################

# This BO3 can only spawn at least Frequency chunks distance away from any other BO3 with the exact same name.
# You can use this to make this BO3 spawn in groups or make sure that this BO3 only spawns once every X chunks.
Frequency: 0

# If you set this to true, the BO3 will be placed with a random rotation.
# This is broken for BO4's atm, will fix this a.s.a.p.
RotateRandomly: false

# The spawn height of the BO3: randomY, highestBlock or highestSolidBlock.
SpawnHeight: highestBlock

##############################
# Height Limits for the BO3. #
##############################

# When in randomY mode used as the minimum Y or in atMinY mode as the actual Y to spawn this BO3 at.
MinHeight: 0

# When in randomY mode used as the maximum Y to spawn this BO3 at.
MaxHeight: 256

# Copies the blocks and branches of an existing BO3 into this BO3. You can still add blocks and branches in this BO3, they will be added on top of the inherited blocks and branches.
InheritBO3: 

# Rotates the inheritedBO3's resources (blocks, spawners, checks etc) and branches, defaults to NORTH (no rotation).
InheritBO3Rotation: NORTH

# Defaults to true, if true and this is the starting BO3 for this branching structure then this BO3's smoothing and height settings are used for all children (branches).
OverrideChildSettings: true

# Defaults to false, if true then this branch uses it's own height settings (SpawnHeight, minHeight, maxHeight, spawnAtWaterLevel) instead of those defined in the starting BO3 for this branching structure.
OverrideParentHeight: false

# If this is set to true then this BO3 can spawn on top of or inside an existing BO3. If this is set to false then this BO3 will use a bounding box to detect collisions with other BO3's, if a collision is detected then this BO3 won't spawn and the current branch is rolled back.
CanOverride: false

# This branch can only spawn at least branchFrequency chunks (x,z) distance away from any other branch with the exact same name.
BranchFrequency: 0

# Define groups that this branch belongs to along with a minimum (x,z) range in chunks that this branch must have between it and any other members of this group if it is to be allowed to spawn. Syntax is "GroupName:Frequency, GoupName2:Frequency2" etc so for example a branch that belongs to 3 groups: "BranchFrequencyGroup: Ships:10, Vehicles:5, FloatingThings:3".
BranchFrequencyGroup: 

# If this is set to true then this BO3 can only spawn underneath an existing BO3. Used to make sure that dungeons only appear underneath buildings.
MustBeBelowOther: false

# Used with CanOverride: true. A comma-seperated list of BO3s, this BO3's bounding box must collide with one of the BO3's in the list or this BO3 fails to spawn and the current branch is rolled back.
MustBeInside: 

# Used with CanOverride: true. A comma-seperated list of BO3s, this BO3's bounding box cannot collide with any of the BO3's in the list or this BO3 fails to spawn and the current branch is rolled back.
CannotBeInside: 

# Used with CanOverride: true. A comma-seperated list of BO3s, if this BO3's bounding box collides with any of the BO3's in the list then those BO3's won't spawn any blocks. This does not remove or roll back any BO3's.
ReplacesBO3: 

# Defaults to true. Set to false if the BO3 is not allowed to spawn on a water block
CanSpawnOnWater: true

# Defaults to false. Set to true if the BO3 is allowed to spawn only on a water block
SpawnOnWaterOnly: false

# Defaults to false. Set to true if the BO3 and its smoothing area should ignore water when looking for the highest block to spawn on. Defaults to false (things spawn on top of water)
SpawnUnderWater: false

# Defaults to false. Set to true if the BO3 should spawn at water level
SpawnAtWaterLevel: false

# Spawns the BO3 at a Y offset of this value. Handy when using highestBlock for lowering BO3s into the surrounding terrain when there are layers of ground included in the BO3, also handy when using SpawnAtWaterLevel to lower objects like ships into the water.
HeightOffset: 0

# If set to true removes all AIR blocks from the BO3 so that it can be flooded or buried.
RemoveAir: true

# Replaces all the non-air blocks that are above this BO3 or its smoothing area with the given block material (should be WATER or AIR or NONE), also applies to smoothing areas although OTG intentionally leaves some of the terrain above them intact. WATER can be used in combination with SpawnUnderWater to fill any air blocks underneath waterlevel with water (and any above waterlevel with air).
ReplaceAbove: 

# Replaces all air blocks underneath the BO3 (but not its smoothing area) with the specified material until a solid block is found.
ReplaceBelow: 

# Defaults to true. If set to true then every block in the BO3 of the materials defined in ReplaceWithGroundBlock or ReplaceWithSurfaceBlock will be replaced by the GroundBlock or SurfaceBlock materials configured for the biome the block is spawned in.
ReplaceWithBiomeBlocks: true

# Defaults to DIRT, Replaces all the blocks of the given material in the BO3 with the GroundBlock configured for the biome it spawns in.
ReplaceWithGroundBlock: DIRT

# Defaults to GRASS, Replaces all the blocks of the given material in the BO3 with the SurfaceBlock configured for the biome it spawns in.
ReplaceWithSurfaceBlock: GRASS

# Makes the terrain around the BO3 slope evenly towards the edges of the BO3. The given value is the distance in blocks around the BO3 from where the slope should start and can be any positive number.
SmoothRadius: 0

# Moves the smoothing area up or down relative to the BO3 (at the points where the smoothing area is connected to the BO3). Handy when using SmoothStartTop: false and the BO3 has some layers of ground included, in that case we can set the HeightOffset to a negative value to lower the BO3 into the ground and we can set the SmoothHeightOffset to a positive value to move the smoothing area starting height up.
SmoothHeightOffset: 0

# Should the smoothing area be attached at the bottom or the top of the edges of the BO3? Defaults to false (bottom). Using this setting can make things slower so try to avoid using it and use SmoothHeightOffset instead if for instance you have a BO3 with some ground layers included. The only reason you should need to use this setting is if you have a BO3 with edges that have an irregular height (like some hills).
SmoothStartTop: false

# Should the smoothing area attach itself to "log" block or ignore them? Defaults to false (ignore logs).
SmoothStartWood: false

# The block used for smoothing area surface blocks, defaults to biome SurfaceBlock.
SmoothingSurfaceBlock: 

# The block used for smoothing area ground blocks, defaults to biome GroundBlock.
SmoothingGroundBlock: 

# Define groups that this BO3 belongs to along with a minimum range in chunks that this BO3 must have between it and any other members of this group if it is to be allowed to spawn. Syntax is "GroupName:Frequency, GoupName2:Frequency2" etc so for example a BO3 that belongs to 3 groups: "BO3Group: Ships:10, Vehicles:5, FloatingThings:3".
BO3Group: 

# Defaults to false. Set to true if this BO3 should spawn at the player spawn point. When the server starts the spawn point is determined and the BO3's for the biome it is in are loaded, one of these BO3s that has IsSpawnPoint set to true (if any) is selected randomly and is spawned at the spawn point regardless of its rarity (so even Rarity:0, IsSpawnPoint: true BO3's can get spawned as the spawn point!).
IsSpawnPoint: false


#######################################################################
# +-----------------------------------------------------------------+ #
# |                              Blocks                             | #
# +-----------------------------------------------------------------+ #
#######################################################################

# All the blocks used in the BO3 are listed here. Possible blocks:
# Block(x,y,z,id[.data][,nbtfile.nbt)
# RandomBlock(x,y,z,id[:data][,nbtfile.nbt],chance[,id[:data][,nbtfile.nbt],chance[,...]])
#  So RandomBlock(0,0,0,CHEST,chest.nbt,50,CHEST,anotherchest.nbt,100) will spawn a chest at
#  the BO3 origin, and give it a 50% chance to have the contents of chest.nbt, or, if that
#  fails, a 100% percent chance to have the contents of anotherchest.nbt.
# MinecraftObject(x,y,z,name) (TODO: This may not work anymore and needs to be tested.
#  Spawns an object in the Mojang NBT structure format. For example, 
#  MinecraftObject(0,0,0,minecraft:igloo/igloo_bottom)
#  spawns the bottom part of an igloo.
Block(0,23,0,biomesoplenty:leaves_0:3)
Block(0,24,0,biomesoplenty:leaves_0:3)
Block(0,25,0,biomesoplenty:leaves_0:3)
Block(0,26,0,biomesoplenty:leaves_0:3)
Block(0,27,0,biomesoplenty:leaves_0:3)
Block(0,28,0,biomesoplenty:log_1:9)
Block(0,29,0,biomesoplenty:leaves_0:3)
Block(0,30,0,biomesoplenty:leaves_0:3)
Block(0,25,1,biomesoplenty:leaves_0:3)
Block(0,27,1,biomesoplenty:leaves_0:3)
Block(0,28,1,biomesoplenty:log_1:1)
Block(0,29,1,biomesoplenty:leaves_0:3)
Block(0,30,1,biomesoplenty:leaves_0:3)
Block(0,18,2,biomesoplenty:leaves_0:3)
Block(0,19,2,biomesoplenty:leaves_0:3)
Block(0,20,2,biomesoplenty:leaves_0:3)
Block(0,21,2,biomesoplenty:leaves_0:3)
Block(0,22,2,biomesoplenty:log_1:5)
Block(0,23,2,biomesoplenty:log_1:5)
Block(0,28,2,biomesoplenty:leaves_0:3)
Block(0,29,2,biomesoplenty:leaves_0:3)
Block(0,30,2,biomesoplenty:leaves_0:3)
Block(0,31,2,biomesoplenty:leaves_0:3)
Block(0,21,3,biomesoplenty:log_1:5)
Block(0,22,3,biomesoplenty:log_1:5)
Block(0,23,3,biomesoplenty:log_1:5)
Block(0,24,3,biomesoplenty:log_1:5)
Block(0,27,3,biomesoplenty:log_1:1)
Block(0,28,3,biomesoplenty:log_1:1)
Block(0,29,3,biomesoplenty:log_1:5)
Block(0,30,3,biomesoplenty:leaves_0:3)
Block(0,31,3,biomesoplenty:leaves_0:3)
Block(0,17,4,biomesoplenty:leaves_0:3)
Block(0,21,4,biomesoplenty:log_1:5)
Block(0,22,4,biomesoplenty:log_1:5)
Block(0,23,4,biomesoplenty:log_1:5)
Block(0,24,4,biomesoplenty:log_1:5)
Block(0,27,4,biomesoplenty:log_1:1)
Block(0,28,4,biomesoplenty:log_1:5)
Block(0,29,4,biomesoplenty:leaves_0:3)
Block(0,30,4,biomesoplenty:leaves_0:3)
Block(0,31,4,biomesoplenty:leaves_0:3)
Block(0,17,5,biomesoplenty:leaves_0:3)
Block(0,18,5,biomesoplenty:leaves_0:3)
Block(0,23,5,biomesoplenty:leaves_0:3)
Block(0,27,5,biomesoplenty:leaves_0:3)
Block(0,28,5,biomesoplenty:log_1:9)
Block(0,30,5,biomesoplenty:leaves_0:3)
Block(0,31,5,biomesoplenty:leaves_0:3)
Block(0,32,5,biomesoplenty:leaves_0:3)
Block(0,16,6,biomesoplenty:leaves_0:3)
Block(0,17,6,biomesoplenty:leaves_0:3)
Block(0,18,6,biomesoplenty:leaves_0:3)
Block(0,22,6,biomesoplenty:leaves_0:3)
Block(0,23,6,biomesoplenty:leaves_0:3)
Block(0,24,6,biomesoplenty:leaves_0:3)
Block(0,25,6,biomesoplenty:log_1:1)
Block(0,28,6,biomesoplenty:leaves_0:3)
Block(0,29,6,biomesoplenty:leaves_0:3)
Block(0,31,6,biomesoplenty:leaves_0:3)
Block(0,16,7,biomesoplenty:leaves_0:3)
Block(0,17,7,biomesoplenty:leaves_0:3)
Block(0,18,7,biomesoplenty:leaves_0:3)
Block(0,25,7,biomesoplenty:log_1:1)
Block(0,27,7,biomesoplenty:leaves_0:3)
Block(0,28,7,biomesoplenty:leaves_0:3)
Block(0,29,7,biomesoplenty:leaves_0:3)
Block(0,30,7,biomesoplenty:leaves_0:3)
Block(0,31,7,biomesoplenty:leaves_0:3)
Block(0,16,8,biomesoplenty:leaves_0:3)
Block(0,17,8,biomesoplenty:leaves_0:3)
Block(0,18,8,biomesoplenty:leaves_0:3)
Block(0,25,8,biomesoplenty:log_1:9)
Block(0,26,8,biomesoplenty:log_1:5)
Block(0,27,8,biomesoplenty:leaves_0:3)
Block(0,28,8,biomesoplenty:leaves_0:3)
Block(0,29,8,biomesoplenty:leaves_0:3)
Block(0,30,8,biomesoplenty:leaves_0:3)
Block(0,31,8,biomesoplenty:leaves_0:3)
Block(0,15,9,biomesoplenty:log_1:9)
Block(0,17,9,biomesoplenty:leaves_0:3)
Block(0,24,9,biomesoplenty:leaves_0:3)
Block(0,25,9,biomesoplenty:log_1:9)
Block(0,26,9,biomesoplenty:log_1:5)
Block(0,27,9,biomesoplenty:leaves_0:3)
Block(0,28,9,biomesoplenty:leaves_0:3)
Block(0,29,9,biomesoplenty:leaves_0:3)
Block(0,30,9,biomesoplenty:leaves_0:3)
Block(0,15,10,biomesoplenty:log_1:5)
Block(0,23,10,biomesoplenty:leaves_0:3)
Block(0,24,10,biomesoplenty:leaves_0:3)
Block(0,25,10,biomesoplenty:log_1:9)
Block(0,28,10,biomesoplenty:leaves_0:3)
Block(0,29,10,biomesoplenty:leaves_0:3)
Block(0,14,11,biomesoplenty:log_1:5)
Block(0,15,11,biomesoplenty:log_1:5)
Block(0,16,11,biomesoplenty:leaves_0:3)
Block(0,24,11,biomesoplenty:leaves_0:3)
Block(0,25,11,biomesoplenty:log_1:9)
Block(0,26,11,biomesoplenty:leaves_0:3)
Block(0,27,11,biomesoplenty:leaves_0:3)
Block(0,28,11,biomesoplenty:leaves_0:3)
Block(0,13,12,biomesoplenty:log_1:5)
Block(0,14,12,biomesoplenty:log_1:5)
Block(0,20,12,biomesoplenty:leaves_0:3)
Block(0,21,12,biomesoplenty:leaves_0:3)
Block(0,22,12,biomesoplenty:leaves_0:3)
Block(0,23,12,biomesoplenty:leaves_0:3)
Block(0,24,12,biomesoplenty:log_1:5)
Block(0,25,12,biomesoplenty:leaves_0:3)
Block(0,26,12,biomesoplenty:leaves_0:3)
Block(0,27,12,biomesoplenty:leaves_0:3)
Block(0,28,12,biomesoplenty:leaves_0:3)
Block(0,12,13,biomesoplenty:log_1:5)
Block(0,13,13,biomesoplenty:log_1:5)
Block(0,14,13,biomesoplenty:log_1:5)
Block(0,15,13,biomesoplenty:log_1:5)
Block(0,24,13,biomesoplenty:leaves_0:3)
Block(0,25,13,biomesoplenty:leaves_0:3)
Block(0,26,13,biomesoplenty:leaves_0:3)
Block(0,27,13,biomesoplenty:leaves_0:3)
Block(0,12,14,biomesoplenty:log_1:5)
Block(0,13,14,biomesoplenty:log_1:5)
Block(0,14,14,biomesoplenty:log_1:5)
Block(0,24,14,biomesoplenty:leaves_0:3)
Block(0,25,14,biomesoplenty:leaves_0:3)
Block(0,26,14,biomesoplenty:leaves_0:3)
Block(0,13,15,biomesoplenty:leaves_0:3)
Block(0,25,15,biomesoplenty:leaves_0:3)
Block(1,22,0,biomesoplenty:leaves_0:3)
Block(1,23,0,biomesoplenty:leaves_0:3)
Block(1,24,0,biomesoplenty:log_1:9)
Block(1,25,0,biomesoplenty:log_1:5)
Block(1,26,0,biomesoplenty:leaves_0:3)
Block(1,27,0,biomesoplenty:leaves_0:3)
Block(1,28,0,biomesoplenty:leaves_0:3)
Block(1,29,0,biomesoplenty:log_1:9)
Block(1,30,0,biomesoplenty:leaves_0:3)
Block(1,23,1,biomesoplenty:leaves_0:3)
Block(1,24,1,biomesoplenty:log_1:9)
Block(1,25,1,biomesoplenty:log_1:5)
Block(1,28,1,biomesoplenty:log_1:9)
Block(1,29,1,biomesoplenty:log_1:5)
Block(1,30,1,biomesoplenty:leaves_0:3)
Block(1,21,2,biomesoplenty:leaves_0:3)
Block(1,22,2,biomesoplenty:log_1:5)
Block(1,23,2,biomesoplenty:log_1:9)
Block(1,24,2,biomesoplenty:log_1:9)
Block(1,25,2,biomesoplenty:leaves_0:3)
Block(1,28,2,biomesoplenty:log_1:9)
Block(1,29,2,biomesoplenty:leaves_0:3)
Block(1,30,2,biomesoplenty:leaves_0:3)
Block(1,17,3,biomesoplenty:leaves_0:3)
Block(1,21,3,biomesoplenty:log_1:5)
Block(1,22,3,biomesoplenty:log_1:5)
Block(1,23,3,biomesoplenty:log_1:5)
Block(1,24,3,biomesoplenty:log_1:5)
Block(1,25,3,biomesoplenty:log_1:5)
Block(1,26,3,biomesoplenty:log_1:5)
Block(1,27,3,biomesoplenty:log_1:5)
Block(1,28,3,biomesoplenty:log_1:5)
Block(1,29,3,biomesoplenty:log_1:5)
Block(1,30,3,biomesoplenty:log_1:5)
Block(1,31,3,biomesoplenty:leaves_0:3)
Block(1,17,4,biomesoplenty:leaves_0:3)
Block(1,20,4,biomesoplenty:log_1:5)
Block(1,21,4,biomesoplenty:log_1:5)
Block(1,22,4,biomesoplenty:log_1:5)
Block(1,23,4,biomesoplenty:log_1:5)
Block(1,24,4,biomesoplenty:log_1:5)
Block(1,25,4,biomesoplenty:log_1:5)
Block(1,27,4,biomesoplenty:log_1:9)
Block(1,28,4,biomesoplenty:log_1:5)
Block(1,29,4,biomesoplenty:leaves_0:3)
Block(1,30,4,biomesoplenty:leaves_0:3)
Block(1,31,4,biomesoplenty:leaves_0:3)
Block(1,32,4,biomesoplenty:leaves_0:3)
Block(1,16,5,biomesoplenty:leaves_0:3)
Block(1,17,5,biomesoplenty:leaves_0:3)
Block(1,18,5,biomesoplenty:leaves_0:3)
Block(1,21,5,biomesoplenty:log_1:5)
Block(1,22,5,biomesoplenty:log_1:5)
Block(1,23,5,biomesoplenty:leaves_0:3)
Block(1,25,5,biomesoplenty:log_1:9)
Block(1,28,5,biomesoplenty:log_1:9)
Block(1,29,5,biomesoplenty:log_1:5)
Block(1,30,5,biomesoplenty:leaves_0:3)
Block(1,31,5,biomesoplenty:leaves_0:3)
Block(1,32,5,biomesoplenty:leaves_0:3)
Block(1,16,6,biomesoplenty:leaves_0:3)
Block(1,17,6,biomesoplenty:leaves_0:3)
Block(1,18,6,biomesoplenty:leaves_0:3)
Block(1,25,6,biomesoplenty:log_1:9)
Block(1,28,6,biomesoplenty:log_1:9)
Block(1,29,6,biomesoplenty:leaves_0:3)
Block(1,30,6,biomesoplenty:leaves_0:3)
Block(1,31,6,biomesoplenty:leaves_0:3)
Block(1,32,6,biomesoplenty:leaves_0:3)
Block(1,16,7,biomesoplenty:leaves_0:3)
Block(1,17,7,biomesoplenty:leaves_0:3)
Block(1,18,7,biomesoplenty:leaves_0:3)
Block(1,19,7,biomesoplenty:leaves_0:3)
Block(1,25,7,biomesoplenty:log_1:9)
Block(1,26,7,biomesoplenty:leaves_0:3)
Block(1,27,7,biomesoplenty:leaves_0:3)
Block(1,28,7,biomesoplenty:leaves_0:3)
Block(1,29,7,biomesoplenty:leaves_0:3)
Block(1,30,7,biomesoplenty:leaves_0:3)
Block(1,31,7,biomesoplenty:leaves_0:3)
Block(1,12,8,biomesoplenty:leaves_0:3)
Block(1,13,8,biomesoplenty:leaves_0:3)
Block(1,14,8,biomesoplenty:leaves_0:3)
Block(1,15,8,biomesoplenty:leaves_0:3)
Block(1,16,8,biomesoplenty:log_1:5)
Block(1,17,8,biomesoplenty:log_1:5)
Block(1,18,8,biomesoplenty:leaves_0:3)
Block(1,25,8,biomesoplenty:log_1:9)
Block(1,26,8,biomesoplenty:leaves_0:3)
Block(1,28,8,biomesoplenty:leaves_0:3)
Block(1,29,8,biomesoplenty:leaves_0:3)
Block(1,15,9,biomesoplenty:log_1:5)
Block(1,16,9,biomesoplenty:log_1:5)
Block(1,17,9,biomesoplenty:leaves_0:3)
Block(1,24,9,biomesoplenty:leaves_0:3)
Block(1,25,9,biomesoplenty:leaves_0:3)
Block(1,27,9,biomesoplenty:leaves_0:3)
Block(1,28,9,biomesoplenty:leaves_0:3)
Block(1,29,9,biomesoplenty:leaves_0:3)
Block(1,30,9,biomesoplenty:leaves_0:3)
Block(1,14,10,biomesoplenty:log_1:5)
Block(1,15,10,biomesoplenty:log_1:5)
Block(1,16,10,biomesoplenty:log_1:5)
Block(1,17,10,biomesoplenty:leaves_0:3)
Block(1,23,10,biomesoplenty:leaves_0:3)
Block(1,26,10,biomesoplenty:leaves_0:3)
Block(1,29,10,biomesoplenty:leaves_0:3)
Block(1,13,11,biomesoplenty:log_1:5)
Block(1,14,11,biomesoplenty:log_1:5)
Block(1,15,11,biomesoplenty:log_1:5)
Block(1,16,11,biomesoplenty:log_1:5)
Block(1,24,11,biomesoplenty:leaves_0:3)
Block(1,25,11,biomesoplenty:leaves_0:3)
Block(1,26,11,biomesoplenty:leaves_0:3)
Block(1,27,11,biomesoplenty:leaves_0:3)
Block(1,28,11,biomesoplenty:leaves_0:3)
Block(1,9,12,biomesoplenty:leaves_0:3)
Block(1,10,12,biomesoplenty:leaves_0:3)
Block(1,11,12,biomesoplenty:leaves_0:3)
Block(1,12,12,biomesoplenty:leaves_0:3)
Block(1,13,12,biomesoplenty:log_1:5)
Block(1,14,12,biomesoplenty:log_1:5)
Block(1,15,12,biomesoplenty:log_1:5)
Block(1,16,12,biomesoplenty:leaves_0:3)
Block(1,24,12,biomesoplenty:leaves_0:3)
Block(1,25,12,biomesoplenty:leaves_0:3)
Block(1,26,12,biomesoplenty:leaves_0:3)
Block(1,27,12,biomesoplenty:leaves_0:3)
Block(1,13,13,biomesoplenty:log_1:5)
Block(1,14,13,biomesoplenty:log_1:5)
Block(1,15,13,biomesoplenty:leaves_0:3)
Block(1,24,13,biomesoplenty:leaves_0:3)
Block(1,25,13,biomesoplenty:leaves_0:3)
Block(1,26,13,biomesoplenty:leaves_0:3)
Block(1,13,14,biomesoplenty:leaves_0:3)
Block(1,14,14,biomesoplenty:leaves_0:3)
Block(1,15,14,biomesoplenty:leaves_0:3)
Block(1,24,14,biomesoplenty:leaves_0:3)
Block(1,14,15,biomesoplenty:leaves_0:3)
Block(1,15,15,biomesoplenty:leaves_0:3)
Block(1,24,15,biomesoplenty:leaves_0:3)
Block(2,24,0,biomesoplenty:leaves_0:3)
Block(2,25,0,biomesoplenty:leaves_0:3)
Block(2,26,0,biomesoplenty:leaves_0:3)
Block(2,27,0,biomesoplenty:leaves_0:3)
Block(2,28,0,biomesoplenty:leaves_0:3)
Block(2,29,0,biomesoplenty:log_1:1)
Block(2,30,0,biomesoplenty:leaves_0:3)
Block(2,24,1,biomesoplenty:leaves_0:3)
Block(2,25,1,biomesoplenty:leaves_0:3)
Block(2,26,1,biomesoplenty:leaves_0:3)
Block(2,27,1,biomesoplenty:leaves_0:3)
Block(2,28,1,biomesoplenty:leaves_0:3)
Block(2,29,1,biomesoplenty:leaves_0:3)
Block(2,30,1,biomesoplenty:leaves_0:3)
Block(2,22,2,biomesoplenty:leaves_0:3)
Block(2,23,2,biomesoplenty:log_1:9)
Block(2,24,2,biomesoplenty:leaves_0:3)
Block(2,25,2,biomesoplenty:leaves_0:3)
Block(2,26,2,biomesoplenty:leaves_0:3)
Block(2,27,2,biomesoplenty:leaves_0:3)
Block(2,28,2,biomesoplenty:log_1:9)
Block(2,29,2,biomesoplenty:leaves_0:3)
Block(2,30,2,biomesoplenty:leaves_0:3)
Block(2,17,3,biomesoplenty:leaves_0:3)
Block(2,20,3,biomesoplenty:log_1:5)
Block(2,21,3,biomesoplenty:log_1:5)
Block(2,22,3,biomesoplenty:log_1:5)
Block(2,23,3,biomesoplenty:log_1:1)
Block(2,24,3,biomesoplenty:log_1:5)
Block(2,27,3,biomesoplenty:leaves_0:3)
Block(2,28,3,biomesoplenty:log_1:1)
Block(2,29,3,biomesoplenty:log_1:5)
Block(2,30,3,biomesoplenty:leaves_0:3)
Block(2,31,3,biomesoplenty:leaves_0:3)
Block(2,17,4,biomesoplenty:leaves_0:3)
Block(2,18,4,biomesoplenty:leaves_0:3)
Block(2,19,4,biomesoplenty:log_1:5)
Block(2,20,4,biomesoplenty:log_1:5)
Block(2,21,4,biomesoplenty:log_1:5)
Block(2,22,4,biomesoplenty:log_1:5)
Block(2,23,4,biomesoplenty:log_1:1)
Block(2,29,4,biomesoplenty:leaves_0:3)
Block(2,30,4,biomesoplenty:leaves_0:3)
Block(2,31,4,biomesoplenty:leaves_0:3)
Block(2,17,5,biomesoplenty:leaves_0:3)
Block(2,18,5,biomesoplenty:leaves_0:3)
Block(2,19,5,biomesoplenty:log_1:5)
Block(2,20,5,biomesoplenty:log_1:5)
Block(2,21,5,biomesoplenty:log_1:5)
Block(2,23,5,biomesoplenty:log_1:9)
Block(2,24,5,biomesoplenty:log_1:5)
Block(2,26,5,biomesoplenty:leaves_0:3)
Block(2,27,5,biomesoplenty:leaves_0:3)
Block(2,28,5,biomesoplenty:log_1:1)
Block(2,29,5,biomesoplenty:log_1:5)
Block(2,30,5,biomesoplenty:leaves_0:3)
Block(2,31,5,biomesoplenty:leaves_0:3)
Block(2,32,5,biomesoplenty:leaves_0:3)
Block(2,16,6,biomesoplenty:leaves_0:3)
Block(2,17,6,biomesoplenty:leaves_0:3)
Block(2,18,6,biomesoplenty:log_1:5)
Block(2,20,6,biomesoplenty:leaves_0:3)
Block(2,21,6,biomesoplenty:leaves_0:3)
Block(2,22,6,biomesoplenty:leaves_0:3)
Block(2,25,6,biomesoplenty:leaves_0:3)
Block(2,26,6,biomesoplenty:leaves_0:3)
Block(2,27,6,biomesoplenty:leaves_0:3)
Block(2,28,6,biomesoplenty:log_1:9)
Block(2,29,6,biomesoplenty:leaves_0:3)
Block(2,31,6,biomesoplenty:leaves_0:3)
Block(2,32,6,biomesoplenty:leaves_0:3)
Block(2,16,7,biomesoplenty:log_1:5)
Block(2,17,7,biomesoplenty:log_1:5)
Block(2,18,7,biomesoplenty:log_1:5)
Block(2,19,7,biomesoplenty:leaves_0:3)
Block(2,24,7,biomesoplenty:leaves_0:3)
Block(2,26,7,biomesoplenty:leaves_0:3)
Block(2,27,7,biomesoplenty:leaves_0:3)
Block(2,28,7,biomesoplenty:log_1:9)
Block(2,29,7,biomesoplenty:leaves_0:3)
Block(2,30,7,biomesoplenty:leaves_0:3)
Block(2,31,7,biomesoplenty:leaves_0:3)
Block(2,15,8,biomesoplenty:log_1:5)
Block(2,16,8,biomesoplenty:log_1:5)
Block(2,17,8,biomesoplenty:log_1:5)
Block(2,18,8,biomesoplenty:log_1:5)
Block(2,24,8,biomesoplenty:leaves_0:3)
Block(2,25,8,biomesoplenty:log_1:1)
Block(2,26,8,biomesoplenty:leaves_0:3)
Block(2,27,8,biomesoplenty:leaves_0:3)
Block(2,28,8,biomesoplenty:leaves_0:3)
Block(2,29,8,biomesoplenty:leaves_0:3)
Block(2,30,8,biomesoplenty:leaves_0:3)
Block(2,31,8,biomesoplenty:leaves_0:3)
Block(2,15,9,biomesoplenty:log_1:5)
Block(2,16,9,biomesoplenty:log_1:5)
Block(2,17,9,biomesoplenty:log_1:5)
Block(2,24,9,biomesoplenty:leaves_0:3)
Block(2,25,9,biomesoplenty:log_1:9)
Block(2,26,9,biomesoplenty:leaves_0:3)
Block(2,27,9,biomesoplenty:leaves_0:3)
Block(2,28,9,biomesoplenty:leaves_0:3)
Block(2,29,9,biomesoplenty:leaves_0:3)
Block(2,30,9,biomesoplenty:leaves_0:3)
Block(2,31,9,biomesoplenty:leaves_0:3)
Block(2,14,10,biomesoplenty:log_1:5)
Block(2,15,10,biomesoplenty:log_1:5)
Block(2,16,10,biomesoplenty:log_1:5)
Block(2,17,10,biomesoplenty:log_1:5)
Block(2,24,10,biomesoplenty:leaves_0:3)
Block(2,25,10,biomesoplenty:leaves_0:3)
Block(2,26,10,biomesoplenty:leaves_0:3)
Block(2,27,10,biomesoplenty:leaves_0:3)
Block(2,28,10,biomesoplenty:leaves_0:3)
Block(2,30,10,biomesoplenty:leaves_0:3)
Block(2,14,11,biomesoplenty:log_1:5)
Block(2,15,11,biomesoplenty:log_1:5)
Block(2,16,11,biomesoplenty:log_1:5)
Block(2,23,11,biomesoplenty:leaves_0:3)
Block(2,24,11,biomesoplenty:leaves_0:3)
Block(2,25,11,biomesoplenty:log_1:1)
Block(2,26,11,biomesoplenty:leaves_0:3)
Block(2,27,11,biomesoplenty:leaves_0:3)
Block(2,28,11,biomesoplenty:leaves_0:3)
Block(2,29,11,biomesoplenty:leaves_0:3)
Block(2,13,12,biomesoplenty:leaves_0:3)
Block(2,14,12,biomesoplenty:log_1:5)
Block(2,15,12,biomesoplenty:leaves_0:3)
Block(2,16,12,biomesoplenty:leaves_0:3)
Block(2,23,12,biomesoplenty:leaves_0:3)
Block(2,24,12,biomesoplenty:leaves_0:3)
Block(2,25,12,biomesoplenty:leaves_0:3)
Block(2,26,12,biomesoplenty:leaves_0:3)
Block(2,27,12,biomesoplenty:leaves_0:3)
Block(2,13,13,biomesoplenty:leaves_0:3)
Block(2,14,13,biomesoplenty:leaves_0:3)
Block(2,15,13,biomesoplenty:leaves_0:3)
Block(2,16,13,biomesoplenty:leaves_0:3)
Block(2,24,13,biomesoplenty:leaves_0:3)
Block(2,25,13,biomesoplenty:leaves_0:3)
Block(2,26,13,biomesoplenty:leaves_0:3)
Block(2,27,13,biomesoplenty:leaves_0:3)
Block(2,14,14,biomesoplenty:leaves_0:3)
Block(2,15,14,biomesoplenty:leaves_0:3)
Block(2,16,14,biomesoplenty:leaves_0:3)
Block(2,24,14,biomesoplenty:leaves_0:3)
Block(2,25,14,biomesoplenty:leaves_0:3)
Block(2,26,14,biomesoplenty:leaves_0:3)
Block(2,15,15,biomesoplenty:leaves_0:3)
Block(2,25,15,biomesoplenty:leaves_0:3)
Block(3,23,0,biomesoplenty:leaves_0:3)
Block(3,24,0,biomesoplenty:leaves_0:3)
Block(3,25,0,biomesoplenty:leaves_0:3)
Block(3,26,0,biomesoplenty:leaves_0:3)
Block(3,27,0,biomesoplenty:leaves_0:3)
Block(3,28,0,biomesoplenty:log_1:9)
Block(3,29,0,biomesoplenty:leaves_0:3)
Block(3,30,0,biomesoplenty:leaves_0:3)
Block(3,22,1,biomesoplenty:leaves_0:3)
Block(3,23,1,biomesoplenty:leaves_0:3)
Block(3,24,1,biomesoplenty:log_1:9)
Block(3,27,1,biomesoplenty:leaves_0:3)
Block(3,28,1,biomesoplenty:log_1:9)
Block(3,29,1,biomesoplenty:leaves_0:3)
Block(3,30,1,biomesoplenty:leaves_0:3)
Block(3,19,2,biomesoplenty:leaves_0:3)
Block(3,20,2,biomesoplenty:leaves_0:3)
Block(3,21,2,biomesoplenty:leaves_0:3)
Block(3,22,2,biomesoplenty:leaves_0:3)
Block(3,23,2,biomesoplenty:log_1:1)
Block(3,24,2,biomesoplenty:log_1:5)
Block(3,26,2,biomesoplenty:leaves_0:3)
Block(3,27,2,biomesoplenty:leaves_0:3)
Block(3,28,2,biomesoplenty:log_1:1)
Block(3,29,2,biomesoplenty:leaves_0:3)
Block(3,30,2,biomesoplenty:leaves_0:3)
Block(3,31,2,biomesoplenty:leaves_0:3)
Block(3,16,3,biomesoplenty:leaves_0:3)
Block(3,17,3,biomesoplenty:leaves_0:3)
Block(3,18,3,biomesoplenty:leaves_0:3)
Block(3,19,3,biomesoplenty:leaves_0:3)
Block(3,20,3,biomesoplenty:log_1:5)
Block(3,24,3,biomesoplenty:log_1:1)
Block(3,25,3,biomesoplenty:log_1:5)
Block(3,26,3,biomesoplenty:leaves_0:3)
Block(3,27,3,biomesoplenty:leaves_0:3)
Block(3,28,3,biomesoplenty:leaves_0:3)
Block(3,29,3,biomesoplenty:leaves_0:3)
Block(3,30,3,biomesoplenty:leaves_0:3)
Block(3,31,3,biomesoplenty:leaves_0:3)
Block(3,17,4,biomesoplenty:leaves_0:3)
Block(3,19,4,biomesoplenty:log_1:5)
Block(3,20,4,biomesoplenty:log_1:5)
Block(3,21,4,biomesoplenty:log_1:5)
Block(3,22,4,biomesoplenty:leaves_0:3)
Block(3,23,4,biomesoplenty:leaves_0:3)
Block(3,24,4,biomesoplenty:leaves_0:3)
Block(3,26,4,biomesoplenty:leaves_0:3)
Block(3,28,4,biomesoplenty:leaves_0:3)
Block(3,29,4,biomesoplenty:leaves_0:3)
Block(3,30,4,biomesoplenty:leaves_0:3)
Block(3,31,4,biomesoplenty:leaves_0:3)
Block(3,17,5,biomesoplenty:leaves_0:3)
Block(3,18,5,biomesoplenty:log_1:5)
Block(3,19,5,biomesoplenty:log_1:5)
Block(3,20,5,biomesoplenty:log_1:5)
Block(3,21,5,biomesoplenty:log_1:5)
Block(3,22,5,biomesoplenty:leaves_0:3)
Block(3,24,5,biomesoplenty:log_1:1)
Block(3,25,5,biomesoplenty:leaves_0:3)
Block(3,27,5,biomesoplenty:leaves_0:3)
Block(3,28,5,biomesoplenty:leaves_0:3)
Block(3,30,5,biomesoplenty:leaves_0:3)
Block(3,31,5,biomesoplenty:leaves_0:3)
Block(3,32,5,biomesoplenty:leaves_0:3)
Block(3,13,6,biomesoplenty:leaves_0:3)
Block(3,14,6,biomesoplenty:leaves_0:3)
Block(3,15,6,biomesoplenty:leaves_0:3)
Block(3,16,6,biomesoplenty:leaves_0:3)
Block(3,17,6,biomesoplenty:log_1:5)
Block(3,18,6,biomesoplenty:log_1:5)
Block(3,19,6,biomesoplenty:log_1:5)
Block(3,20,6,biomesoplenty:log_1:5)
Block(3,23,6,biomesoplenty:leaves_0:3)
Block(3,24,6,biomesoplenty:log_1:9)
Block(3,25,6,biomesoplenty:log_1:5)
Block(3,26,6,biomesoplenty:leaves_0:3)
Block(3,27,6,biomesoplenty:leaves_0:3)
Block(3,28,6,biomesoplenty:leaves_0:3)
Block(3,29,6,biomesoplenty:leaves_0:3)
Block(3,31,6,biomesoplenty:leaves_0:3)
Block(3,16,7,biomesoplenty:log_1:5)
Block(3,17,7,biomesoplenty:log_1:5)
Block(3,18,7,biomesoplenty:log_1:5)
Block(3,19,7,biomesoplenty:log_1:5)
Block(3,23,7,biomesoplenty:leaves_0:3)
Block(3,24,7,biomesoplenty:log_1:9)
Block(3,25,7,biomesoplenty:leaves_0:3)
Block(3,26,7,biomesoplenty:leaves_0:3)
Block(3,27,7,biomesoplenty:leaves_0:3)
Block(3,28,7,biomesoplenty:log_1:1)
Block(3,29,7,biomesoplenty:leaves_0:3)
Block(3,30,7,biomesoplenty:leaves_0:3)
Block(3,31,7,biomesoplenty:leaves_0:3)
Block(3,13,8,biomesoplenty:leaves_0:3)
Block(3,14,8,biomesoplenty:leaves_0:3)
Block(3,15,8,biomesoplenty:leaves_0:3)
Block(3,16,8,biomesoplenty:log_1:5)
Block(3,17,8,biomesoplenty:log_1:5)
Block(3,18,8,biomesoplenty:log_1:5)
Block(3,26,8,biomesoplenty:leaves_0:3)
Block(3,27,8,biomesoplenty:leaves_0:3)
Block(3,28,8,biomesoplenty:log_1:9)
Block(3,29,8,biomesoplenty:leaves_0:3)
Block(3,30,8,biomesoplenty:leaves_0:3)
Block(3,31,8,biomesoplenty:leaves_0:3)
Block(3,16,9,biomesoplenty:log_1:5)
Block(3,17,9,biomesoplenty:log_1:5)
Block(3,25,9,biomesoplenty:log_1:1)
Block(3,27,9,biomesoplenty:leaves_0:3)
Block(3,28,9,biomesoplenty:log_1:9)
Block(3,29,9,biomesoplenty:leaves_0:3)
Block(3,30,9,biomesoplenty:leaves_0:3)
Block(3,31,9,biomesoplenty:leaves_0:3)
Block(3,15,10,biomesoplenty:log_1:5)
Block(3,16,10,biomesoplenty:log_1:5)
Block(3,24,10,biomesoplenty:leaves_0:3)
Block(3,25,10,biomesoplenty:log_1:9)
Block(3,26,10,biomesoplenty:leaves_0:3)
Block(3,27,10,biomesoplenty:leaves_0:3)
Block(3,28,10,biomesoplenty:leaves_0:3)
Block(3,29,10,biomesoplenty:leaves_0:3)
Block(3,30,10,biomesoplenty:leaves_0:3)
Block(3,14,11,biomesoplenty:leaves_0:3)
Block(3,15,11,biomesoplenty:leaves_0:3)
Block(3,16,11,biomesoplenty:leaves_0:3)
Block(3,23,11,biomesoplenty:leaves_0:3)
Block(3,25,11,biomesoplenty:leaves_0:3)
Block(3,26,11,biomesoplenty:leaves_0:3)
Block(3,27,11,biomesoplenty:leaves_0:3)
Block(3,28,11,biomesoplenty:leaves_0:3)
Block(3,29,11,biomesoplenty:leaves_0:3)
Block(3,14,12,biomesoplenty:log_1:1)
Block(3,15,12,biomesoplenty:leaves_0:3)
Block(3,16,12,biomesoplenty:leaves_0:3)
Block(3,25,12,biomesoplenty:log_1:9)
Block(3,26,12,biomesoplenty:leaves_0:3)
Block(3,27,12,biomesoplenty:leaves_0:3)
Block(3,28,12,biomesoplenty:leaves_0:3)
Block(3,13,13,biomesoplenty:leaves_0:3)
Block(3,14,13,biomesoplenty:log_1:9)
Block(3,15,13,biomesoplenty:log_1:5)
Block(3,16,13,biomesoplenty:leaves_0:3)
Block(3,24,13,biomesoplenty:leaves_0:3)
Block(3,25,13,biomesoplenty:leaves_0:3)
Block(3,26,13,biomesoplenty:leaves_0:3)
Block(3,27,13,biomesoplenty:leaves_0:3)
Block(3,28,13,biomesoplenty:leaves_0:3)
Block(3,14,14,biomesoplenty:leaves_0:3)
Block(3,15,14,biomesoplenty:leaves_0:3)
Block(3,16,14,biomesoplenty:leaves_0:3)
Block(3,24,14,biomesoplenty:leaves_0:3)
Block(3,25,14,biomesoplenty:leaves_0:3)
Block(3,26,14,biomesoplenty:leaves_0:3)
Block(3,11,15,biomesoplenty:leaves_0:3)
Block(3,12,15,biomesoplenty:leaves_0:3)
Block(3,13,15,biomesoplenty:leaves_0:3)
Block(3,14,15,biomesoplenty:leaves_0:3)
Block(3,15,15,biomesoplenty:log_1:1)
Block(4,22,0,biomesoplenty:leaves_0:3)
Block(4,23,0,biomesoplenty:leaves_0:3)
Block(4,24,0,biomesoplenty:log_1:9)
Block(4,25,0,biomesoplenty:leaves_0:3)
Block(4,26,0,biomesoplenty:leaves_0:3)
Block(4,27,0,biomesoplenty:leaves_0:3)
Block(4,28,0,biomesoplenty:log_1:1)
Block(4,29,0,biomesoplenty:leaves_0:3)
Block(4,30,0,biomesoplenty:leaves_0:3)
Block(4,20,1,biomesoplenty:leaves_0:3)
Block(4,21,1,biomesoplenty:leaves_0:3)
Block(4,22,1,biomesoplenty:leaves_0:3)
Block(4,23,1,biomesoplenty:leaves_0:3)
Block(4,24,1,biomesoplenty:log_1:1)
Block(4,25,1,biomesoplenty:leaves_0:3)
Block(4,26,1,biomesoplenty:leaves_0:3)
Block(4,27,1,biomesoplenty:leaves_0:3)
Block(4,28,1,biomesoplenty:leaves_0:3)
Block(4,29,1,biomesoplenty:leaves_0:3)
Block(4,30,1,biomesoplenty:leaves_0:3)
Block(4,21,2,biomesoplenty:leaves_0:3)
Block(4,22,2,biomesoplenty:leaves_0:3)
Block(4,23,2,biomesoplenty:leaves_0:3)
Block(4,24,2,biomesoplenty:leaves_0:3)
Block(4,25,2,biomesoplenty:log_1:9)
Block(4,26,2,biomesoplenty:leaves_0:3)
Block(4,27,2,biomesoplenty:leaves_0:3)
Block(4,28,2,biomesoplenty:leaves_0:3)
Block(4,29,2,biomesoplenty:leaves_0:3)
Block(4,30,2,biomesoplenty:leaves_0:3)
Block(4,23,3,biomesoplenty:leaves_0:3)
Block(4,24,3,biomesoplenty:log_1:1)
Block(4,25,3,biomesoplenty:log_1:1)
Block(4,26,3,biomesoplenty:log_1:1)
Block(4,27,3,biomesoplenty:leaves_0:3)
Block(4,28,3,biomesoplenty:leaves_0:3)
Block(4,29,3,biomesoplenty:leaves_0:3)
Block(4,30,3,biomesoplenty:leaves_0:3)
Block(4,31,3,biomesoplenty:leaves_0:3)
Block(4,20,4,biomesoplenty:log_1:5)
Block(4,24,4,biomesoplenty:leaves_0:3)
Block(4,25,4,biomesoplenty:leaves_0:3)
Block(4,26,4,biomesoplenty:leaves_0:3)
Block(4,27,4,biomesoplenty:leaves_0:3)
Block(4,28,4,biomesoplenty:leaves_0:3)
Block(4,31,4,biomesoplenty:leaves_0:3)
Block(4,16,5,biomesoplenty:leaves_0:3)
Block(4,17,5,biomesoplenty:leaves_0:3)
Block(4,18,5,biomesoplenty:leaves_0:3)
Block(4,19,5,biomesoplenty:log_1:5)
Block(4,20,5,biomesoplenty:log_1:5)
Block(4,24,5,biomesoplenty:leaves_0:3)
Block(4,26,5,biomesoplenty:leaves_0:3)
Block(4,27,5,biomesoplenty:leaves_0:3)
Block(4,28,5,biomesoplenty:leaves_0:3)
Block(4,29,5,biomesoplenty:leaves_0:3)
Block(4,30,5,biomesoplenty:leaves_0:3)
Block(4,31,5,biomesoplenty:leaves_0:3)
Block(4,18,6,biomesoplenty:log_1:5)
Block(4,19,6,biomesoplenty:leaves_0:3)
Block(4,23,6,biomesoplenty:leaves_0:3)
Block(4,24,6,biomesoplenty:log_1:1)
Block(4,26,6,biomesoplenty:leaves_0:3)
Block(4,27,6,biomesoplenty:leaves_0:3)
Block(4,28,6,biomesoplenty:leaves_0:3)
Block(4,29,6,biomesoplenty:leaves_0:3)
Block(4,30,6,biomesoplenty:leaves_0:3)
Block(4,31,6,biomesoplenty:leaves_0:3)
Block(4,17,7,biomesoplenty:log_1:5)
Block(4,18,7,biomesoplenty:log_1:5)
Block(4,23,7,biomesoplenty:leaves_0:3)
Block(4,24,7,biomesoplenty:log_1:9)
Block(4,25,7,biomesoplenty:log_1:5)
Block(4,26,7,biomesoplenty:leaves_0:3)
Block(4,27,7,biomesoplenty:leaves_0:3)
Block(4,28,7,biomesoplenty:leaves_0:3)
Block(4,29,7,biomesoplenty:leaves_0:3)
Block(4,30,7,biomesoplenty:leaves_0:3)
Block(4,17,8,biomesoplenty:log_1:5)
Block(4,18,8,biomesoplenty:leaves_0:3)
Block(4,21,8,biomesoplenty:leaves_0:3)
Block(4,22,8,biomesoplenty:leaves_0:3)
Block(4,23,8,biomesoplenty:leaves_0:3)
Block(4,25,8,biomesoplenty:leaves_0:3)
Block(4,26,8,biomesoplenty:leaves_0:3)
Block(4,27,8,biomesoplenty:leaves_0:3)
Block(4,29,8,biomesoplenty:leaves_0:3)
Block(4,30,8,biomesoplenty:leaves_0:3)
Block(4,25,9,biomesoplenty:leaves_0:3)
Block(4,26,9,biomesoplenty:leaves_0:3)
Block(4,27,9,biomesoplenty:leaves_0:3)
Block(4,28,9,biomesoplenty:leaves_0:3)
Block(4,29,9,biomesoplenty:leaves_0:3)
Block(4,30,9,biomesoplenty:leaves_0:3)
Block(4,15,10,biomesoplenty:leaves_0:3)
Block(4,25,10,biomesoplenty:leaves_0:3)
Block(4,26,10,biomesoplenty:leaves_0:3)
Block(4,27,10,biomesoplenty:leaves_0:3)
Block(4,28,10,biomesoplenty:leaves_0:3)
Block(4,29,10,biomesoplenty:leaves_0:3)
Block(4,30,10,biomesoplenty:leaves_0:3)
Block(4,15,11,biomesoplenty:leaves_0:3)
Block(4,24,11,biomesoplenty:leaves_0:3)
Block(4,25,11,biomesoplenty:log_1:1)
Block(4,26,11,biomesoplenty:log_1:5)
Block(4,27,11,biomesoplenty:leaves_0:3)
Block(4,28,11,biomesoplenty:leaves_0:3)
Block(4,29,11,biomesoplenty:leaves_0:3)
Block(4,14,12,biomesoplenty:leaves_0:3)
Block(4,15,12,biomesoplenty:leaves_0:3)
Block(4,16,12,biomesoplenty:leaves_0:3)
Block(4,24,12,biomesoplenty:leaves_0:3)
Block(4,25,12,biomesoplenty:leaves_0:3)
Block(4,26,12,biomesoplenty:leaves_0:3)
Block(4,27,12,biomesoplenty:leaves_0:3)
Block(4,28,12,biomesoplenty:leaves_0:3)
Block(4,29,12,biomesoplenty:leaves_0:3)
Block(4,14,13,biomesoplenty:leaves_0:3)
Block(4,15,13,biomesoplenty:log_1:1)
Block(4,16,13,biomesoplenty:leaves_0:3)
Block(4,24,13,biomesoplenty:leaves_0:3)
Block(4,25,13,biomesoplenty:leaves_0:3)
Block(4,26,13,biomesoplenty:leaves_0:3)
Block(4,27,13,biomesoplenty:leaves_0:3)
Block(4,15,14,biomesoplenty:leaves_0:3)
Block(4,26,14,biomesoplenty:leaves_0:3)
Block(4,15,15,biomesoplenty:leaves_0:3)
Block(4,26,15,biomesoplenty:leaves_0:3)
Block(5,24,0,biomesoplenty:log_1:1)
Block(5,25,0,biomesoplenty:log_1:5)
Block(5,26,0,biomesoplenty:log_1:5)
Block(5,27,0,biomesoplenty:leaves_0:3)
Block(5,28,0,biomesoplenty:log_1:1)
Block(5,29,0,biomesoplenty:leaves_0:3)
Block(5,30,0,biomesoplenty:leaves_0:3)
Block(5,21,1,biomesoplenty:leaves_0:3)
Block(5,23,1,biomesoplenty:leaves_0:3)
Block(5,24,1,biomesoplenty:leaves_0:3)
Block(5,26,1,biomesoplenty:leaves_0:3)
Block(5,27,1,biomesoplenty:leaves_0:3)
Block(5,28,1,biomesoplenty:leaves_0:3)
Block(5,29,1,biomesoplenty:leaves_0:3)
Block(5,30,1,biomesoplenty:leaves_0:3)
Block(5,23,2,biomesoplenty:leaves_0:3)
Block(5,25,2,biomesoplenty:leaves_0:3)
Block(5,26,2,biomesoplenty:leaves_0:3)
Block(5,27,2,biomesoplenty:leaves_0:3)
Block(5,28,2,biomesoplenty:leaves_0:3)
Block(5,29,2,biomesoplenty:leaves_0:3)
Block(5,30,2,biomesoplenty:leaves_0:3)
Block(5,22,3,biomesoplenty:leaves_0:3)
Block(5,24,3,biomesoplenty:leaves_0:3)
Block(5,25,3,biomesoplenty:log_1:1)
Block(5,26,3,biomesoplenty:leaves_0:3)
Block(5,27,3,biomesoplenty:leaves_0:3)
Block(5,28,3,biomesoplenty:leaves_0:3)
Block(5,29,3,biomesoplenty:leaves_0:3)
Block(5,30,3,biomesoplenty:leaves_0:3)
Block(5,21,4,biomesoplenty:leaves_0:3)
Block(5,22,4,biomesoplenty:leaves_0:3)
Block(5,23,4,biomesoplenty:leaves_0:3)
Block(5,24,4,biomesoplenty:log_1:1)
Block(5,25,4,biomesoplenty:leaves_0:3)
Block(5,26,4,biomesoplenty:leaves_0:3)
Block(5,27,4,biomesoplenty:leaves_0:3)
Block(5,28,4,biomesoplenty:leaves_0:3)
Block(5,29,4,biomesoplenty:leaves_0:3)
Block(5,30,4,biomesoplenty:leaves_0:3)
Block(5,31,4,biomesoplenty:leaves_0:3)
Block(5,25,5,biomesoplenty:leaves_0:3)
Block(5,26,5,biomesoplenty:leaves_0:3)
Block(5,27,5,biomesoplenty:leaves_0:3)
Block(5,28,5,biomesoplenty:leaves_0:3)
Block(5,29,5,biomesoplenty:log_1:5)
Block(5,30,5,biomesoplenty:leaves_0:3)
Block(5,18,6,biomesoplenty:leaves_0:3)
Block(5,25,6,biomesoplenty:leaves_0:3)
Block(5,26,6,biomesoplenty:leaves_0:3)
Block(5,27,6,biomesoplenty:leaves_0:3)
Block(5,29,6,biomesoplenty:leaves_0:3)
Block(5,30,6,biomesoplenty:leaves_0:3)
Block(5,24,7,biomesoplenty:leaves_0:3)
Block(5,25,7,biomesoplenty:log_1:1)
Block(5,26,7,biomesoplenty:leaves_0:3)
Block(5,27,7,biomesoplenty:leaves_0:3)
Block(5,28,7,biomesoplenty:leaves_0:3)
Block(5,29,7,biomesoplenty:leaves_0:3)
Block(5,30,7,biomesoplenty:leaves_0:3)
Block(5,25,8,biomesoplenty:log_1:9)
Block(5,26,8,biomesoplenty:log_1:5)
Block(5,27,8,biomesoplenty:leaves_0:3)
Block(5,28,8,biomesoplenty:leaves_0:3)
Block(5,29,8,biomesoplenty:leaves_0:3)
Block(5,30,8,biomesoplenty:leaves_0:3)
Block(5,25,9,biomesoplenty:leaves_0:3)
Block(5,26,9,biomesoplenty:log_1:9)
Block(5,27,9,biomesoplenty:leaves_0:3)
Block(5,28,9,biomesoplenty:leaves_0:3)
Block(5,29,9,biomesoplenty:leaves_0:3)
Block(5,25,10,biomesoplenty:leaves_0:3)
Block(5,26,10,biomesoplenty:leaves_0:3)
Block(5,27,10,biomesoplenty:leaves_0:3)
Block(5,28,10,biomesoplenty:leaves_0:3)
Block(5,29,10,biomesoplenty:leaves_0:3)
Block(5,15,11,biomesoplenty:leaves_0:3)
Block(5,24,11,biomesoplenty:leaves_0:3)
Block(5,25,11,biomesoplenty:log_1:1)
Block(5,26,11,biomesoplenty:leaves_0:3)
Block(5,27,11,biomesoplenty:leaves_0:3)
Block(5,28,11,biomesoplenty:leaves_0:3)
Block(5,15,12,biomesoplenty:leaves_0:3)
Block(5,24,12,biomesoplenty:log_1:9)
Block(5,25,12,biomesoplenty:leaves_0:3)
Block(5,26,12,biomesoplenty:leaves_0:3)
Block(5,27,12,biomesoplenty:leaves_0:3)
Block(5,28,12,biomesoplenty:leaves_0:3)
Block(5,11,13,biomesoplenty:leaves_0:3)
Block(5,12,13,biomesoplenty:leaves_0:3)
Block(5,13,13,biomesoplenty:leaves_0:3)
Block(5,14,13,biomesoplenty:leaves_0:3)
Block(5,15,13,biomesoplenty:log_1:1)
Block(5,24,13,biomesoplenty:leaves_0:3)
Block(5,25,13,biomesoplenty:leaves_0:3)
Block(5,26,13,biomesoplenty:leaves_0:3)
Block(5,27,13,biomesoplenty:leaves_0:3)
Block(5,15,14,biomesoplenty:leaves_0:3)
Block(5,24,14,biomesoplenty:leaves_0:3)
Block(5,26,14,biomesoplenty:leaves_0:3)
Block(5,15,15,biomesoplenty:leaves_0:3)
Block(6,23,0,biomesoplenty:leaves_0:3)
Block(6,24,0,biomesoplenty:leaves_0:3)
Block(6,25,0,biomesoplenty:leaves_0:3)
Block(6,26,0,biomesoplenty:leaves_0:3)
Block(6,27,0,biomesoplenty:leaves_0:3)
Block(6,28,0,biomesoplenty:leaves_0:3)
Block(6,29,0,biomesoplenty:leaves_0:3)
Block(6,23,1,biomesoplenty:leaves_0:3)
Block(6,24,1,biomesoplenty:leaves_0:3)
Block(6,25,1,biomesoplenty:leaves_0:3)
Block(6,26,1,biomesoplenty:leaves_0:3)
Block(6,27,1,biomesoplenty:leaves_0:3)
Block(6,28,1,biomesoplenty:leaves_0:3)
Block(6,29,1,biomesoplenty:leaves_0:3)
Block(6,30,1,biomesoplenty:leaves_0:3)
Block(6,23,2,biomesoplenty:leaves_0:3)
Block(6,24,2,biomesoplenty:leaves_0:3)
Block(6,25,2,biomesoplenty:log_1:9)
Block(6,26,2,biomesoplenty:leaves_0:3)
Block(6,27,2,biomesoplenty:leaves_0:3)
Block(6,28,2,biomesoplenty:leaves_0:3)
Block(6,29,2,biomesoplenty:leaves_0:3)
Block(6,23,3,biomesoplenty:leaves_0:3)
Block(6,24,3,biomesoplenty:leaves_0:3)
Block(6,25,3,biomesoplenty:log_1:1)
Block(6,26,3,biomesoplenty:leaves_0:3)
Block(6,27,3,biomesoplenty:leaves_0:3)
Block(6,28,3,biomesoplenty:leaves_0:3)
Block(6,29,3,biomesoplenty:leaves_0:3)
Block(6,30,3,biomesoplenty:leaves_0:3)
Block(6,25,4,biomesoplenty:log_1:9)
Block(6,26,4,biomesoplenty:leaves_0:3)
Block(6,27,4,biomesoplenty:leaves_0:3)
Block(6,28,4,biomesoplenty:leaves_0:3)
Block(6,29,4,biomesoplenty:leaves_0:3)
Block(6,30,4,biomesoplenty:leaves_0:3)
Block(6,31,4,biomesoplenty:leaves_0:3)
Block(6,24,5,biomesoplenty:leaves_0:3)
Block(6,25,5,biomesoplenty:log_1:9)
Block(6,26,5,biomesoplenty:leaves_0:3)
Block(6,27,5,biomesoplenty:leaves_0:3)
Block(6,28,5,biomesoplenty:leaves_0:3)
Block(6,29,5,biomesoplenty:leaves_0:3)
Block(6,30,5,biomesoplenty:leaves_0:3)
Block(6,25,6,biomesoplenty:leaves_0:3)
Block(6,26,6,biomesoplenty:leaves_0:3)
Block(6,27,6,biomesoplenty:leaves_0:3)
Block(6,28,6,biomesoplenty:leaves_0:3)
Block(6,29,6,biomesoplenty:leaves_0:3)
Block(6,30,6,biomesoplenty:leaves_0:3)
Block(6,25,7,biomesoplenty:log_1:1)
Block(6,26,7,biomesoplenty:leaves_0:3)
Block(6,27,7,biomesoplenty:leaves_0:3)
Block(6,28,7,biomesoplenty:leaves_0:3)
Block(6,29,7,biomesoplenty:leaves_0:3)
Block(6,24,8,biomesoplenty:leaves_0:3)
Block(6,25,8,biomesoplenty:log_1:9)
Block(6,26,8,biomesoplenty:leaves_0:3)
Block(6,27,8,biomesoplenty:leaves_0:3)
Block(6,28,8,biomesoplenty:leaves_0:3)
Block(6,29,8,biomesoplenty:leaves_0:3)
Block(6,24,9,biomesoplenty:leaves_0:3)
Block(6,25,9,biomesoplenty:leaves_0:3)
Block(6,26,9,biomesoplenty:log_1:1)
Block(6,27,9,biomesoplenty:leaves_0:3)
Block(6,29,9,biomesoplenty:leaves_0:3)
Block(6,25,10,biomesoplenty:leaves_0:3)
Block(6,26,10,biomesoplenty:log_1:9)
Block(6,27,10,biomesoplenty:leaves_0:3)
Block(6,28,10,biomesoplenty:leaves_0:3)
Block(6,24,11,biomesoplenty:leaves_0:3)
Block(6,25,11,biomesoplenty:leaves_0:3)
Block(6,26,11,biomesoplenty:log_1:9)
Block(6,27,11,biomesoplenty:leaves_0:3)
Block(6,28,11,biomesoplenty:leaves_0:3)
Block(6,15,12,biomesoplenty:leaves_0:3)
Block(6,24,12,biomesoplenty:leaves_0:3)
Block(6,25,12,biomesoplenty:log_1:5)
Block(6,26,12,biomesoplenty:leaves_0:3)
Block(6,27,12,biomesoplenty:leaves_0:3)
Block(6,15,13,biomesoplenty:leaves_0:3)
Block(6,24,13,biomesoplenty:leaves_0:3)
Block(6,25,13,biomesoplenty:leaves_0:3)
Block(6,26,13,biomesoplenty:leaves_0:3)
Block(6,27,13,biomesoplenty:leaves_0:3)
Block(6,15,14,biomesoplenty:leaves_0:3)
Block(6,24,14,biomesoplenty:leaves_0:3)
Block(6,26,14,biomesoplenty:leaves_0:3)
Block(6,26,15,biomesoplenty:leaves_0:3)
Block(7,23,0,biomesoplenty:leaves_0:3)
Block(7,24,0,biomesoplenty:leaves_0:3)
Block(7,25,0,biomesoplenty:leaves_0:3)
Block(7,26,0,biomesoplenty:leaves_0:3)
Block(7,28,0,biomesoplenty:leaves_0:3)
Block(7,29,0,biomesoplenty:leaves_0:3)
Block(7,30,0,biomesoplenty:leaves_0:3)
Block(7,19,1,biomesoplenty:leaves_0:3)
Block(7,20,1,biomesoplenty:leaves_0:3)
Block(7,21,1,biomesoplenty:leaves_0:3)
Block(7,22,1,biomesoplenty:leaves_0:3)
Block(7,23,1,biomesoplenty:log_1:1)
Block(7,25,1,biomesoplenty:leaves_0:3)
Block(7,26,1,biomesoplenty:leaves_0:3)
Block(7,27,1,biomesoplenty:leaves_0:3)
Block(7,28,1,biomesoplenty:leaves_0:3)
Block(7,29,1,biomesoplenty:leaves_0:3)
Block(7,23,2,biomesoplenty:leaves_0:3)
Block(7,24,2,biomesoplenty:leaves_0:3)
Block(7,25,2,biomesoplenty:leaves_0:3)
Block(7,26,2,biomesoplenty:leaves_0:3)
Block(7,27,2,biomesoplenty:leaves_0:3)
Block(7,28,2,biomesoplenty:leaves_0:3)
Block(7,29,2,biomesoplenty:leaves_0:3)
Block(7,23,3,biomesoplenty:leaves_0:3)
Block(7,24,3,biomesoplenty:leaves_0:3)
Block(7,25,3,biomesoplenty:log_1:1)
Block(7,26,3,biomesoplenty:log_1:5)
Block(7,27,3,biomesoplenty:leaves_0:3)
Block(7,28,3,biomesoplenty:leaves_0:3)
Block(7,29,3,biomesoplenty:leaves_0:3)
Block(7,30,3,biomesoplenty:leaves_0:3)
Block(7,23,4,biomesoplenty:leaves_0:3)
Block(7,25,4,biomesoplenty:log_1:1)
Block(7,26,4,biomesoplenty:leaves_0:3)
Block(7,27,4,biomesoplenty:leaves_0:3)
Block(7,28,4,biomesoplenty:leaves_0:3)
Block(7,29,4,biomesoplenty:leaves_0:3)
Block(7,30,4,biomesoplenty:leaves_0:3)
Block(7,24,5,biomesoplenty:leaves_0:3)
Block(7,25,5,biomesoplenty:leaves_0:3)
Block(7,26,5,biomesoplenty:leaves_0:3)
Block(7,27,5,biomesoplenty:leaves_0:3)
Block(7,28,5,biomesoplenty:leaves_0:3)
Block(7,29,5,biomesoplenty:leaves_0:3)
Block(7,30,5,biomesoplenty:leaves_0:3)
Block(7,23,6,biomesoplenty:leaves_0:3)
Block(7,24,6,biomesoplenty:leaves_0:3)
Block(7,26,6,biomesoplenty:leaves_0:3)
Block(7,27,6,biomesoplenty:leaves_0:3)
Block(7,28,6,biomesoplenty:leaves_0:3)
Block(7,29,6,biomesoplenty:leaves_0:3)
Block(7,30,6,biomesoplenty:leaves_0:3)
Block(7,23,7,biomesoplenty:leaves_0:3)
Block(7,25,7,biomesoplenty:leaves_0:3)
Block(7,26,7,biomesoplenty:leaves_0:3)
Block(7,27,7,biomesoplenty:leaves_0:3)
Block(7,28,7,biomesoplenty:leaves_0:3)
Block(7,29,7,biomesoplenty:leaves_0:3)
Block(7,24,8,biomesoplenty:leaves_0:3)
Block(7,25,8,biomesoplenty:log_1:1)
Block(7,26,8,biomesoplenty:log_1:5)
Block(7,28,8,biomesoplenty:leaves_0:3)
Block(7,29,8,biomesoplenty:leaves_0:3)
Block(7,24,9,biomesoplenty:leaves_0:3)
Block(7,25,9,biomesoplenty:leaves_0:3)
Block(7,26,9,biomesoplenty:log_1:1)
Block(7,27,9,biomesoplenty:leaves_0:3)
Block(7,28,9,biomesoplenty:leaves_0:3)
Block(7,29,9,biomesoplenty:leaves_0:3)
Block(7,24,10,biomesoplenty:leaves_0:3)
Block(7,25,10,biomesoplenty:leaves_0:3)
Block(7,26,10,biomesoplenty:leaves_0:3)
Block(7,27,10,biomesoplenty:leaves_0:3)
Block(7,28,10,biomesoplenty:leaves_0:3)
Block(7,20,11,biomesoplenty:leaves_0:3)
Block(7,21,11,biomesoplenty:leaves_0:3)
Block(7,22,11,biomesoplenty:leaves_0:3)
Block(7,23,11,biomesoplenty:leaves_0:3)
Block(7,24,11,biomesoplenty:log_1:5)
Block(7,25,11,biomesoplenty:log_1:5)
Block(7,26,11,biomesoplenty:log_1:1)
Block(7,27,11,biomesoplenty:leaves_0:3)
Block(7,28,11,biomesoplenty:leaves_0:3)
Block(7,24,12,biomesoplenty:leaves_0:3)
Block(7,25,12,biomesoplenty:leaves_0:3)
Block(7,26,12,biomesoplenty:leaves_0:3)
Block(7,27,12,biomesoplenty:leaves_0:3)
Block(7,24,13,biomesoplenty:leaves_0:3)
Block(7,25,13,biomesoplenty:leaves_0:3)
Block(7,26,13,biomesoplenty:leaves_0:3)
Block(7,27,13,biomesoplenty:leaves_0:3)
Block(8,23,0,biomesoplenty:leaves_0:3)
Block(8,24,0,biomesoplenty:leaves_0:3)
Block(8,25,0,biomesoplenty:leaves_0:3)
Block(8,26,0,biomesoplenty:leaves_0:3)
Block(8,27,0,biomesoplenty:leaves_0:3)
Block(8,28,0,biomesoplenty:leaves_0:3)
Block(8,29,0,biomesoplenty:leaves_0:3)
Block(8,23,1,biomesoplenty:leaves_0:3)
Block(8,24,1,biomesoplenty:leaves_0:3)
Block(8,25,1,biomesoplenty:leaves_0:3)
Block(8,26,1,biomesoplenty:leaves_0:3)
Block(8,27,1,biomesoplenty:leaves_0:3)
Block(8,28,1,biomesoplenty:leaves_0:3)
Block(8,24,2,biomesoplenty:leaves_0:3)
Block(8,25,2,biomesoplenty:leaves_0:3)
Block(8,26,2,biomesoplenty:leaves_0:3)
Block(8,27,2,biomesoplenty:leaves_0:3)
Block(8,28,2,biomesoplenty:leaves_0:3)
Block(8,29,2,biomesoplenty:leaves_0:3)
Block(8,24,3,biomesoplenty:leaves_0:3)
Block(8,25,3,biomesoplenty:leaves_0:3)
Block(8,26,3,biomesoplenty:log_1:1)
Block(8,27,3,biomesoplenty:leaves_0:3)
Block(8,28,3,biomesoplenty:leaves_0:3)
Block(8,29,3,biomesoplenty:leaves_0:3)
Block(8,23,4,biomesoplenty:leaves_0:3)
Block(8,25,4,biomesoplenty:log_1:1)
Block(8,26,4,biomesoplenty:leaves_0:3)
Block(8,27,4,biomesoplenty:leaves_0:3)
Block(8,28,4,biomesoplenty:leaves_0:3)
Block(8,29,4,biomesoplenty:leaves_0:3)
Block(8,23,5,biomesoplenty:leaves_0:3)
Block(8,25,5,biomesoplenty:log_1:9)
Block(8,26,5,biomesoplenty:log_1:5)
Block(8,27,5,biomesoplenty:leaves_0:3)
Block(8,28,5,biomesoplenty:leaves_0:3)
Block(8,29,5,biomesoplenty:leaves_0:3)
Block(8,23,6,biomesoplenty:leaves_0:3)
Block(8,24,6,biomesoplenty:leaves_0:3)
Block(8,25,6,biomesoplenty:leaves_0:3)
Block(8,26,6,biomesoplenty:leaves_0:3)
Block(8,27,6,biomesoplenty:leaves_0:3)
Block(8,28,6,biomesoplenty:leaves_0:3)
Block(8,23,7,biomesoplenty:leaves_0:3)
Block(8,24,7,biomesoplenty:leaves_0:3)
Block(8,25,7,biomesoplenty:leaves_0:3)
Block(8,26,7,biomesoplenty:leaves_0:3)
Block(8,27,7,biomesoplenty:leaves_0:3)
Block(8,28,7,biomesoplenty:leaves_0:3)
Block(8,24,8,biomesoplenty:leaves_0:3)
Block(8,25,8,biomesoplenty:leaves_0:3)
Block(8,26,8,biomesoplenty:leaves_0:3)
Block(8,27,8,biomesoplenty:leaves_0:3)
Block(8,24,9,biomesoplenty:leaves_0:3)
Block(8,25,9,biomesoplenty:leaves_0:3)
Block(8,26,9,biomesoplenty:log_1:9)
Block(8,27,9,biomesoplenty:leaves_0:3)
Block(8,24,10,biomesoplenty:leaves_0:3)
Block(8,25,10,biomesoplenty:leaves_0:3)
Block(8,26,10,biomesoplenty:leaves_0:3)
Block(8,27,10,biomesoplenty:leaves_0:3)
Block(8,24,11,biomesoplenty:leaves_0:3)
Block(8,25,11,biomesoplenty:leaves_0:3)
Block(8,26,11,biomesoplenty:leaves_0:3)
Block(8,27,11,biomesoplenty:leaves_0:3)
Block(8,24,12,biomesoplenty:leaves_0:3)
Block(8,25,12,biomesoplenty:leaves_0:3)
Block(8,26,12,biomesoplenty:leaves_0:3)
Block(8,26,13,biomesoplenty:leaves_0:3)
Block(8,26,14,biomesoplenty:leaves_0:3)
Block(9,22,0,biomesoplenty:leaves_0:3)
Block(9,23,0,biomesoplenty:leaves_0:3)
Block(9,24,0,biomesoplenty:leaves_0:3)
Block(9,25,0,biomesoplenty:log_1:9)
Block(9,26,0,biomesoplenty:log_1:5)
Block(9,27,0,biomesoplenty:leaves_0:3)
Block(9,28,0,biomesoplenty:leaves_0:3)
Block(9,23,1,biomesoplenty:leaves_0:3)
Block(9,24,1,biomesoplenty:leaves_0:3)
Block(9,25,1,biomesoplenty:leaves_0:3)
Block(9,26,1,biomesoplenty:leaves_0:3)
Block(9,27,1,biomesoplenty:leaves_0:3)
Block(9,28,1,biomesoplenty:leaves_0:3)
Block(9,29,1,biomesoplenty:leaves_0:3)
Block(9,24,2,biomesoplenty:leaves_0:3)
Block(9,25,2,biomesoplenty:leaves_0:3)
Block(9,26,2,biomesoplenty:leaves_0:3)
Block(9,27,2,biomesoplenty:leaves_0:3)
Block(9,28,2,biomesoplenty:leaves_0:3)
Block(9,29,2,biomesoplenty:leaves_0:3)
Block(9,25,3,biomesoplenty:leaves_0:3)
Block(9,26,3,biomesoplenty:leaves_0:3)
Block(9,27,3,biomesoplenty:leaves_0:3)
Block(9,28,3,biomesoplenty:leaves_0:3)
Block(9,29,3,biomesoplenty:leaves_0:3)
Block(9,25,4,biomesoplenty:leaves_0:3)
Block(9,26,4,biomesoplenty:leaves_0:3)
Block(9,27,4,biomesoplenty:leaves_0:3)
Block(9,28,4,biomesoplenty:leaves_0:3)
Block(9,29,4,biomesoplenty:leaves_0:3)
Block(9,23,5,biomesoplenty:leaves_0:3)
Block(9,24,5,biomesoplenty:leaves_0:3)
Block(9,25,5,biomesoplenty:leaves_0:3)
Block(9,26,5,biomesoplenty:log_1:1)
Block(9,27,5,biomesoplenty:leaves_0:3)
Block(9,28,5,biomesoplenty:log_1:1)
Block(9,29,5,biomesoplenty:leaves_0:3)
Block(9,20,6,biomesoplenty:leaves_0:3)
Block(9,21,6,biomesoplenty:leaves_0:3)
Block(9,22,6,biomesoplenty:leaves_0:3)
Block(9,23,6,biomesoplenty:leaves_0:3)
Block(9,24,6,biomesoplenty:log_1:1)
Block(9,25,6,biomesoplenty:leaves_0:3)
Block(9,26,6,biomesoplenty:log_1:9)
Block(9,27,6,biomesoplenty:leaves_0:3)
Block(9,28,6,biomesoplenty:leaves_0:3)
Block(9,24,7,biomesoplenty:leaves_0:3)
Block(9,25,7,biomesoplenty:leaves_0:3)
Block(9,26,7,biomesoplenty:leaves_0:3)
Block(9,27,7,biomesoplenty:leaves_0:3)
Block(9,28,7,biomesoplenty:leaves_0:3)
Block(9,25,8,biomesoplenty:leaves_0:3)
Block(9,26,8,biomesoplenty:leaves_0:3)
Block(9,27,8,biomesoplenty:leaves_0:3)
Block(9,24,9,biomesoplenty:leaves_0:3)
Block(9,26,9,biomesoplenty:leaves_0:3)
Block(9,27,9,biomesoplenty:leaves_0:3)
Block(9,24,10,biomesoplenty:leaves_0:3)
Block(9,26,10,biomesoplenty:leaves_0:3)
Block(9,27,10,biomesoplenty:leaves_0:3)
Block(9,26,11,biomesoplenty:leaves_0:3)
Block(9,27,11,biomesoplenty:leaves_0:3)
Block(9,26,12,biomesoplenty:leaves_0:3)
Block(10,25,0,biomesoplenty:leaves_0:3)
Block(10,26,0,biomesoplenty:leaves_0:3)
Block(10,27,0,biomesoplenty:leaves_0:3)
Block(10,24,1,biomesoplenty:leaves_0:3)
Block(10,26,1,biomesoplenty:leaves_0:3)
Block(10,27,1,biomesoplenty:leaves_0:3)
Block(10,28,1,biomesoplenty:leaves_0:3)
Block(10,26,2,biomesoplenty:leaves_0:3)
Block(10,27,2,biomesoplenty:leaves_0:3)
Block(10,28,2,biomesoplenty:leaves_0:3)
Block(10,24,3,biomesoplenty:leaves_0:3)
Block(10,25,3,biomesoplenty:leaves_0:3)
Block(10,26,3,biomesoplenty:leaves_0:3)
Block(10,27,3,biomesoplenty:leaves_0:3)
Block(10,25,4,biomesoplenty:leaves_0:3)
Block(10,26,4,biomesoplenty:leaves_0:3)
Block(10,27,4,biomesoplenty:leaves_0:3)
Block(10,28,4,biomesoplenty:leaves_0:3)
Block(10,24,5,biomesoplenty:leaves_0:3)
Block(10,25,5,biomesoplenty:leaves_0:3)
Block(10,26,5,biomesoplenty:leaves_0:3)
Block(10,27,5,biomesoplenty:leaves_0:3)
Block(10,28,5,biomesoplenty:leaves_0:3)
Block(10,24,6,biomesoplenty:leaves_0:3)
Block(10,25,6,biomesoplenty:leaves_0:3)
Block(10,26,6,biomesoplenty:leaves_0:3)
Block(10,27,6,biomesoplenty:leaves_0:3)
Block(10,28,6,biomesoplenty:leaves_0:3)
Block(10,26,7,biomesoplenty:leaves_0:3)
Block(10,27,7,biomesoplenty:leaves_0:3)
Block(10,26,8,biomesoplenty:leaves_0:3)
Block(10,26,9,biomesoplenty:leaves_0:3)
Block(10,25,10,biomesoplenty:leaves_0:3)
Block(10,26,10,biomesoplenty:leaves_0:3)
Block(10,26,11,biomesoplenty:leaves_0:3)
Block(11,26,0,biomesoplenty:leaves_0:3)
Block(11,26,1,biomesoplenty:leaves_0:3)
Block(11,26,2,biomesoplenty:leaves_0:3)
Block(11,26,3,biomesoplenty:leaves_0:3)
Block(11,27,3,biomesoplenty:leaves_0:3)
Block(11,28,3,biomesoplenty:leaves_0:3)
Block(11,25,4,biomesoplenty:leaves_0:3)
Block(11,26,4,biomesoplenty:leaves_0:3)
Block(11,27,4,biomesoplenty:leaves_0:3)
Block(11,28,4,biomesoplenty:leaves_0:3)
Block(11,26,5,biomesoplenty:leaves_0:3)
Block(11,27,5,biomesoplenty:leaves_0:3)
Block(11,25,6,biomesoplenty:leaves_0:3)
Block(11,26,6,biomesoplenty:leaves_0:3)
Block(11,27,6,biomesoplenty:leaves_0:3)
Block(11,26,7,biomesoplenty:leaves_0:3)
Block(11,26,8,biomesoplenty:leaves_0:3)
Block(11,26,9,biomesoplenty:leaves_0:3)
Block(12,26,1,biomesoplenty:leaves_0:3)
Block(12,26,3,biomesoplenty:leaves_0:3)
Block(12,26,4,biomesoplenty:leaves_0:3)
Block(12,26,5,biomesoplenty:leaves_0:3)
Block(12,26,6,biomesoplenty:leaves_0:3)

#######################################################################
# +-----------------------------------------------------------------+ #
# |                             Branches                            | #
# +-----------------------------------------------------------------+ #
#######################################################################

# Branches are child-BO3's that spawn if this BO3 is configured to spawn as a
# CustomStructure resource in a biome config. Branches can have branches,
# making complex structures possible. See the wiki for more details.

# Regular Branches spawn each branch with an independent chance of spawning.
# Branch(x,y,z,isRequiredBranch,branchName,rotation,chance,branchDepth[,anotherBranchName,rotation,chance,branchDepth[,...]][IndividualChance])
# branchName - name of the object to spawn.
# rotation - NORTH, SOUTH, EAST or WEST.
# IndividualChance - The chance each branch has to spawn, assumed to be 100 when left blank
# isRequiredBranch - If this is set to true then at least one of the branches in this BO3 must spawn at these x,y,z coordinates. If no branch can spawn there then this BO3 fails to spawn and its branch is rolled back.
# isRequiredBranch:true branches must spawn or the current branch is rolled back entirely. This is useful for grouping BO3's that must spawn together, for instance a single room made of multiple BO3's/branches.
# If all parts of the room are connected together via isRequiredBranch:true branches then either the entire room will spawns or no part of it will spawn.
# *Note: When isRequiredBranch:true only one BO3 can be added per Branch() and it will automatically have a rarity of 100.0.
# isRequiredBranch:false branches are used to make optional parts of structures, for instance the middle section of a tunnel that has a beginning, middle and end BO3/branch and can have a variable length by repeating the middle BO3/branch.
# By making the start and end branches isRequiredBranch:true and the middle branch isRequiredbranch:false you can make it so that either:
# A. A tunnel spawns with at least a beginning and end branch
# B. A tunnel spawns with a beginning and end branch and as many middle branches as will fit in the available space.
# C. No tunnel spawns at all because there wasn't enough space to spawn at least a beginning and end branch.
# branchDepth - When creating a chain of branches that contains optional (isRequiredBranch:false) branches branch depth is configured for the first BO3 in the chain to determine the maximum length of the chain.
# branchDepth - 1 is inherited by each isRequiredBranch:false branch in the chain. When branchDepth is zero isRequiredBranch:false branches cannot spawn and the chain ends. In the case of the tunnel this means the last middle branch would be
# rolled back and an IsRequiredBranch:true end branch could be spawned in its place to make sure the tunnel has a proper ending.
# Instead of inheriting branchDepth - 1 from the parent branchDepth can be overridden by child branches if it is set higher than 0 (the default value).
# isRequiredBranch:true branches do inherit branchDepth and pass it on to their own branches, however they cannot be prevented from spawning by it and also don't subtract 1 from branchDepth when inheriting it.

# Weighted Branches spawn branches with a dependent chance of spawning.
# WeightedBranch(x,y,z,isRequiredBranch,branchName,rotation,chance,branchDepth[,anotherBranchName,rotation,chance,branchDepth[,...]][MaxChanceOutOf])
# *Note: isRequiredBranch must be set to false. It is not possible to use isRequiredBranch:true with WeightedBranch() since isRequired:true branches must spawn and automatically have a rarity of 100.0.
# MaxChanceOutOf - The chance all branches have to spawn out of, assumed to be 100 when left blank

#######################################################################
# +-----------------------------------------------------------------+ #
# |                             Entities                            | #
# +-----------------------------------------------------------------+ #
#######################################################################

# Forge only (this may have changed, check for updates).
# An EntityFunction spawns an entity instead of a block. The entity is spawned only once when the BO3 is spawned.
# Entities are persistent by default so they don't de-spawn when no player is near, they are only unloaded.
# Usage: Entity(x,y,z,entityName,groupSize,NameTagOrNBTFileName) or Entity(x,y,z,mobName,groupSize)
# Use /otg entities to get a list of entities that can be used as entityName, this includes entities added by other mods and non-living entities.
# NameTagOrNBTFileName can be either a nametag for the mob or an .txt file with nbt data (such as myentityinfo.txt).
# In the text file you can use the same mob spawning parameters used with the /summon command to equip the
# entity and give it custom attributes etc. You can copy the DATA part of a summon command including surrounding 
# curly braces to a .txt file, for instance for: "/summon Skeleton x y z {DATA}"

#######################################################################
# +-----------------------------------------------------------------+ #
# |                            Particles                            | #
# +-----------------------------------------------------------------+ #
#######################################################################

# Forge only (this may have changed, check for updates).
# Creates an invisible particle spawner at the given location that spawns particles every x milliseconds.
# Usage: Particle(x,y,z,particleName,interval,velocityX,velocityY,velocityZ)
# velocityX, velocityY and velocityZ are optional.
# Only vanilla particle names can be used, for 1.11.2 these are;
# explode, largeexplode, hugeexplosion, fireworksSpark, bubble, splash, wake, suspended
# depthsuspend, crit, magicCrit, smoke, largesmoke, spell, instantSpell, mobSpell
# mobSpellAmbient, witchMagic, dripWater, dripLava, angryVillager, happyVillager
# townaura, note, portal, enchantmenttable, flame, lava, footstep, cloud, reddust
# snowballpoof,  snowshovel, slime, heart, barrier, iconcrack, blockcrack, blockdust
# droplet, take, mobappearance, dragonbreath, endRod, damageIndicator, sweepAttack
# fallingdust, totem, spit.
# velocityX,velocityY,velocityZ - Spawn the enemy with the given velocity. If this is not filled in then a small random velocity is applied.

#######################################################################
# +-----------------------------------------------------------------+ #
# |                             Spawners                            | #
# +-----------------------------------------------------------------+ #
#######################################################################

# Forge only (this may have changed, check for updates).
# Creates an invisible entity spawner at the given location that spawns entities every x seconds.
# Entities can only spawn if their spawn requirements are met (zombies/skeletons only spawn in the dark etc). Max entity count for the server is ignored, each spawner has its own maxCount setting.
# Usage: Spawner(x,y,z,entityName,nbtFileName,groupSize,interval,spawnChance,maxCount,despawnTime,velocityX,velocityY,velocityZ,yaw,pitch)
# nbtFileName, despawnTime, velocityX, velocityY, velocityZ, yaw and pitch are optional
# Example Spawner(0, 0, 0, Villager, 1, 5, 100, 5) or Spawner(0, 0, 0, Villager, villager1.txt, 1, 5, 100, 5) or Spawner(0, 0, 0, Villager, 1, 5, 100, 5, 30, 1, 1, 1, 0, 0)
# entityName - Name of the entity to spawn, use /otg entities to get a list of entities that can be used as entityName, this includes entities added by other mods and non-living entities.
# nbtFileName - A .txt file with nbt data (such as myentityinfo.txt).
# In the text file you can use the same mob spawning parameters used with the /summon command to equip the
# entity and give it custom attributes etc. You can copy the DATA part of a summon command including surrounding 
# curly braces to a .txt file, for instance for: "/summon Skeleton x y z {DATA}"
# groupSize - Number of entities that should spawn for each successful spawn attempt.
# interval - Time in seconds between each spawn attempt.
# spawnChance - For each spawn attempt, the chance between 0-100 that the spawn attempt will succeed.
# maxCount - The maximum amount of this kind of entity that can exist within 32 blocks. If there are already maxCount or more entities of this type in a 32 radius this spawner will not spawn anything.
# despawnTime - After despawnTime seconds, if there is no player within 32 blocks of the entity it will despawn..
# velocityX,velocityY,velocityZ,yaw,pitch - Spawn the enemy with the given velocity and angle, handy for making traps and launchers (shooting arrows and fireballs etc).

#######################################################################
# +-----------------------------------------------------------------+ #
# |                             ModData                             | #
# +-----------------------------------------------------------------+ #
#######################################################################

# Forge only.
# Use the ModData() tag to include data that other mods can use
# Mod makers can use ModData and the /otg GetModData command to test IMC communications between OTG
# and their mod.
# Normal users can use it to spawn some mobs and blocks on command.
# ModData(x,y,z,"ModName", "MyModDataAsText"
# Example: ModData(x,y,z,MyCystomNPCMod,SpawnBobHere/WithAPotato/And50Health)
# Try not to use exotic/reserved characters, like brackets and comma's etc, this stuff isn't fool-proof.
# Also, use this only to store IDs/object names etc for your mod, DO NOT include things like character dialogue,
# messages on signs, loot lists etc in this file. As much as possible just store id's/names here and store all the data related to those id's/names in your own mod.
# OTG has some built in ModData commands for basic mob and block spawning.
# These are mostly just a demonstration for mod makers to show how ModData.
# can be used by other mods.
# For mob spawning in OTG use: ModData(x,y,z,OTG,mob/MobType/Count/Persistent/Name)
# mob: Makes OTG recognise this as a mob spawning command.
# MobType: Lower-case, no spaces. Any vanilla mob like dragon, skeleton, wither, villager etc
# Count: The number of mobs to spawn
# Persistent (true/false): Should the mobs never de-spawn? If set to true the mob will get a
# name-tag ingame so you can recognise it.
# Name: A name-tag for the monster/npc.
# Example: ModData(0,0,0,OTG,villager/1/true/Bob)
# To spawn blocks using ModData use: ModData(x,y,z,OTG,block/material)
# block: Makes OTG recognise this as a block spawning command.
# material: id or text, custom blocks can be added using ModName:MaterialName.
# To send all ModData within a radius in chunks around the player to the specified mod
# use this console command: /otg GetModData ModName Radius
# ModName: name of the mod, for OTG commands use OTG 
# Radius (optional): Radius in chunks around the player.
