#######################################################################
# +-----------------------------------------------------------------+ #
# |                            BO3 object                           | #
# +-----------------------------------------------------------------+ #
#######################################################################

# The descriptions in this file are accurate only for TerrainControl and OTG.
# For MCW and OTG+ these descriptions are only accurate if the BO3 is used as a CustomObject.
# MCW and OTG+ completely reimplemented CustomStructure, check the MCW/OTG+ documentation for more information.

# This is the config file of a custom object.
# If you add this object correctly to your BiomeConfigs, it will spawn in the world.

# This is the creator of this BO3 object
Author: Unknown

# A short description of this BO3 object
Description: This BO3 was converted from a schematic using OTGEdit. The author and description information of the schematic could not be found. If you know who the author of the schematic is then please add this information.

# The BO3 version, don't change this! It can be used by external applications to do a version check.
Version: 3

# The settings mode, WriteAll, WriteWithoutComments or WriteDisable. See WorldConfig.
SettingsMode: WriteDisable

#######################################################################
# +-----------------------------------------------------------------+ #
# |                          Main settings                          | #
# +-----------------------------------------------------------------+ #
#######################################################################

# This needs to be set to true to spawn the object in the Tree and Sapling resources.
Tree: false

# The frequency of the BO3 from 1 to 200. Tries this many times to spawn this BO3 when using the CustomObject(...) resource.
# Ignored by Tree(..), Sapling(..) and CustomStructure(..)
Frequency: 1

# The rarity of the BO3 from 0 to 100. Each spawn attempt has rarity% chance to succeed when using the CustomObject(...) resource.
# Ignored by Tree(..), Sapling(..) and CustomStructure(..)
Rarity: 100.0

# If you set this to true, the BO3 will be placed with a random rotation.
RotateRandomly: true

# The spawn height of the BO3 - randomY, highestBlock or highestSolidBlock.
SpawnHeight: highestBlock

SpawnHeightOffset: 0

SpawnHeightVariance: 0

# The height limits for the BO3.
MinHeight: 0

MaxHeight: 256

# Objects can have other objects attached to it: branches. Branches can also
# have branches attached to it, which can also have branches, etc. This is the
# maximum branch depth for this objects.
MaxBranchDepth: 10

# When spawned with the UseWorld keyword, this BO3 should NOT spawn in the following biomes.
# If you writer.write the BO3 name directly in the BiomeConfigs, this will be ignored.
ExcludedBiomes: All

# To optimise this BO3 for faster loading times you can use Notepad++ to find/replace comments and abbreviate things.
# Notepad++ find/replace with regex:
# Find: ^[#;].* replace to nothing removes all lines starting with # 
# Find: ^\s*$ replace to nothing removes most empty lines 
# Notepad++ find/replace without regex:
# *Warning: This will only work for OTG 1.10.2 v21 / OTG 1.11.2 v6 or higher. B( is not recognised by lower versions.
# Find: Block( replace to B(

#######################################################################
# +-----------------------------------------------------------------+ #
# |                      Source block settings                      | #
# +-----------------------------------------------------------------+ #
#######################################################################

# The block(s) the BO3 should spawn in.
SourceBlocks: STONE:0

# The maximum percentage of the BO3 that can be outside the SourceBlock.
# The BO3 won't be placed on a location with more blocks outside the SourceBlock than this percentage.
MaxPercentageOutsideSourceBlock: 100

# What to do when a block is about to be placed outside the SourceBlock? (dontPlace, placeAnyway)
OutsideSourceBlock: dontPlace

#######################################################################
# +-----------------------------------------------------------------+ #
# |                              Blocks                             | #
# +-----------------------------------------------------------------+ #
#######################################################################

# All the blocks used in the BO3 are listed here. Possible blocks:
# Block(x,y,z,id[.data][,nbtfile.nbt) or B(x,y,z,id[.data][,nbtfile.nbt)
# RandomBlock(x,y,z,id[:data][,nbtfile.nbt],chance[,id[:data][,nbtfile.nbt],chance[,...]])
# So RandomBlock(0,0,0,CHEST,chest.nbt,50,CHEST,anotherchest.nbt,100) will spawn a chest at
# the BO3 origin, and give it a 50% chance to have the contents of chest.nbt, or, if that
# fails, a 100% percent chance to have the contents of anotherchest.nbt.

Block(-7,-33,-8,1:1)
Block(-7,-33,-7,1:1)
Block(-7,-33,-6,1:1)
Block(-7,-33,-5,1:1)
Block(-7,-33,-4,1:1)
Block(-7,-33,-3,1:1)
Block(-7,-33,-2,1:1)
Block(-7,-33,-1,1:1)
Block(-7,-33,0,1:1)
Block(-7,-33,1,1:1)
Block(-7,-33,2,1:1)
Block(-7,-33,3,1:1)
Block(-7,-33,4,1:1)
Block(-7,-33,5,1:1)
Block(-7,-33,6,1:1)
Block(-7,-33,7,1:1)
Block(-7,-32,-8,1:1)
Block(-7,-32,-7,1:1)
Block(-7,-32,-6,1:1)
Block(-7,-32,-5,1:1)
Block(-7,-32,-4,1:1)
Block(-7,-32,-3,1:1)
Block(-7,-32,-2,1:1)
Block(-7,-32,-1,1:1)
Block(-7,-32,0,1:1)
Block(-7,-32,1,1:1)
Block(-7,-32,2,1:1)
Block(-7,-32,3,1:1)
Block(-7,-32,4,1:1)
Block(-7,-32,5,1:1)
Block(-7,-32,6,1:1)
Block(-7,-32,7,1:1)
Block(-7,-31,-8,1:1)
Block(-7,-31,-7,1:1)
Block(-7,-31,-6,1:1)
Block(-7,-31,-5,1:1)
Block(-7,-31,-4,1:1)
Block(-7,-31,-3,1:1)
Block(-7,-31,-2,1:1)
Block(-7,-31,-1,1:1)
Block(-7,-31,0,1:1)
Block(-7,-31,1,1:1)
Block(-7,-31,2,1:1)
Block(-7,-31,3,1:1)
Block(-7,-31,4,1:1)
Block(-7,-31,5,1:1)
Block(-7,-31,6,1:1)
Block(-7,-31,7,1:1)
Block(-7,-30,-8,1:1)
Block(-7,-30,-7,1:1)
Block(-7,-30,-6,1:1)
Block(-7,-30,-5,1:1)
Block(-7,-30,-4,1:1)
Block(-7,-30,-3,1:1)
Block(-7,-30,-2,1:1)
Block(-7,-30,-1,1:1)
Block(-7,-30,0,1:1)
Block(-7,-30,1,1:1)
Block(-7,-30,2,1:1)
Block(-7,-30,3,1:1)
Block(-7,-30,4,1:1)
Block(-7,-30,5,1:1)
Block(-7,-30,6,1:1)
Block(-7,-30,7,1:3)
Block(-7,-29,-8,1:1)
Block(-7,-29,-7,1:1)
Block(-7,-29,-6,1:1)
Block(-7,-29,-5,1:1)
Block(-7,-29,-4,1:1)
Block(-7,-29,-3,1:1)
Block(-7,-29,-2,1:1)
Block(-7,-29,-1,1:1)
Block(-7,-29,0,1:1)
Block(-7,-29,1,1:1)
Block(-7,-29,2,1:1)
Block(-7,-29,3,1:1)
Block(-7,-29,4,1:1)
Block(-7,-29,5,1:3)
Block(-7,-29,6,1:3)
Block(-7,-29,7,1:3)
Block(-7,-28,-8,1:1)
Block(-7,-28,-7,1:1)
Block(-7,-28,-6,1:1)
Block(-7,-28,-5,1:1)
Block(-7,-28,-4,1:1)
Block(-7,-28,-3,1:1)
Block(-7,-28,-2,1:1)
Block(-7,-28,-1,1:1)
Block(-7,-28,0,1:1)
Block(-7,-28,1,1:1)
Block(-7,-28,2,1:1)
Block(-7,-28,3,1:1)
Block(-7,-28,4,1:1)
Block(-7,-28,5,1:3)
Block(-7,-28,6,1:3)
Block(-7,-28,7,1:3)
Block(-7,-27,-8,1:1)
Block(-7,-27,-7,1:1)
Block(-7,-27,-6,1:1)
Block(-7,-27,-5,1:1)
Block(-7,-27,-4,1:1)
Block(-7,-27,-3,1:1)
Block(-7,-27,-2,1:1)
Block(-7,-27,-1,1:1)
Block(-7,-27,0,1:1)
Block(-7,-27,1,1:1)
Block(-7,-27,2,1:1)
Block(-7,-27,3,1:1)
Block(-7,-27,4,1:3)
Block(-7,-27,5,1:3)
Block(-7,-27,6,1:3)
Block(-7,-27,7,1:1)
Block(-7,-26,-8,1:1)
Block(-7,-26,-7,1:1)
Block(-7,-26,-6,1:1)
Block(-7,-26,-5,1:1)
Block(-7,-26,-4,1:1)
Block(-7,-26,-3,1:1)
Block(-7,-26,-2,1:1)
Block(-7,-26,-1,1:1)
Block(-7,-26,0,1:1)
Block(-7,-26,1,1:3)
Block(-7,-26,2,1:1)
Block(-7,-26,3,1:3)
Block(-7,-26,4,1:3)
Block(-7,-26,5,1:3)
Block(-7,-26,6,1:3)
Block(-7,-26,7,1:1)
Block(-7,-25,-8,1:1)
Block(-7,-25,-7,1:1)
Block(-7,-25,-6,1:1)
Block(-7,-25,-5,1:1)
Block(-7,-25,-4,1:1)
Block(-7,-25,-3,1:1)
Block(-7,-25,-2,1:1)
Block(-7,-25,-1,1:1)
Block(-7,-25,0,1:1)
Block(-7,-25,1,1:3)
Block(-7,-25,2,1:3)
Block(-7,-25,3,1:3)
Block(-7,-25,4,1:3)
Block(-7,-25,5,1:3)
Block(-7,-25,6,1:1)
Block(-7,-25,7,1:1)
Block(-7,-24,-8,1:1)
Block(-7,-24,-7,1:1)
Block(-7,-24,-6,1:1)
Block(-7,-24,-5,1:1)
Block(-7,-24,-4,1:1)
Block(-7,-24,-3,1:1)
Block(-7,-24,-2,1:1)
Block(-7,-24,-1,1:1)
Block(-7,-24,0,1:1)
Block(-7,-24,1,1:3)
Block(-7,-24,2,1:3)
Block(-7,-24,3,1:3)
Block(-7,-24,4,1:3)
Block(-7,-24,5,1:3)
Block(-7,-24,6,1:1)
Block(-7,-24,7,1:1)
Block(-7,-23,-8,1:1)
Block(-7,-23,-7,1:1)
Block(-7,-23,-6,1:1)
Block(-7,-23,-5,1:1)
Block(-7,-23,-4,1:1)
Block(-7,-23,-3,1:1)
Block(-7,-23,-2,1:1)
Block(-7,-23,-1,1:1)
Block(-7,-23,0,1:3)
Block(-7,-23,1,1:3)
Block(-7,-23,2,1:3)
Block(-7,-23,3,1:3)
Block(-7,-23,4,1:3)
Block(-7,-23,5,1:3)
Block(-7,-23,6,1:3)
Block(-7,-23,7,1:1)
Block(-7,-22,-8,1:1)
Block(-7,-22,-7,1:1)
Block(-7,-22,-6,1:1)
Block(-7,-22,-5,1:1)
Block(-7,-22,-4,1:1)
Block(-7,-22,-3,1:1)
Block(-7,-22,-2,1:1)
Block(-7,-22,-1,1:3)
Block(-7,-22,0,1:3)
Block(-7,-22,1,1:3)
Block(-7,-22,2,1:3)
Block(-7,-22,3,1:3)
Block(-7,-22,4,1:3)
Block(-7,-22,5,1:3)
Block(-7,-22,6,1:3)
Block(-7,-22,7,1:3)
Block(-7,-21,-8,1:1)
Block(-7,-21,-7,1:1)
Block(-7,-21,-6,1:1)
Block(-7,-21,-5,1:1)
Block(-7,-21,-4,1:1)
Block(-7,-21,-3,1:1)
Block(-7,-21,-2,1:3)
Block(-7,-21,-1,1:3)
Block(-7,-21,0,1:3)
Block(-7,-21,1,1:3)
Block(-7,-21,2,1:3)
Block(-7,-21,3,1:3)
Block(-7,-21,4,1:3)
Block(-7,-21,5,1:3)
Block(-7,-21,6,1:3)
Block(-7,-21,7,1:3)
Block(-7,-20,-8,1:1)
Block(-7,-20,-7,1:1)
Block(-7,-20,-6,1:1)
Block(-7,-20,-5,1:1)
Block(-7,-20,-4,1:1)
Block(-7,-20,-3,1:1)
Block(-7,-20,-2,1:3)
Block(-7,-20,-1,1:3)
Block(-7,-20,0,1:3)
Block(-7,-20,1,1:3)
Block(-7,-20,2,1:3)
Block(-7,-20,3,1:3)
Block(-7,-20,4,1:3)
Block(-7,-20,5,1:3)
Block(-7,-20,6,1:3)
Block(-7,-20,7,1:3)
Block(-7,-19,-8,1:1)
Block(-7,-19,-7,1:1)
Block(-7,-19,-6,1:1)
Block(-7,-19,-5,1:1)
Block(-7,-19,-4,1:1)
Block(-7,-19,-3,1:3)
Block(-7,-19,-2,1:3)
Block(-7,-19,-1,1:3)
Block(-7,-19,0,1:3)
Block(-7,-19,1,1:3)
Block(-7,-19,2,1:3)
Block(-7,-19,3,1:3)
Block(-7,-19,4,1:3)
Block(-7,-19,5,1:3)
Block(-7,-19,6,1:3)
Block(-7,-19,7,1:3)
Block(-7,-18,-8,1:1)
Block(-7,-18,-7,1:1)
Block(-7,-18,-6,1:1)
Block(-7,-18,-5,1:1)
Block(-7,-18,-4,1:3)
Block(-7,-18,-3,1:3)
Block(-7,-18,-2,1:3)
Block(-7,-18,-1,1:3)
Block(-7,-18,0,1:3)
Block(-7,-18,1,1:3)
Block(-7,-18,2,1:3)
Block(-7,-18,3,1:3)
Block(-7,-18,4,1:3)
Block(-7,-18,5,1:3)
Block(-7,-18,6,1:3)
Block(-7,-18,7,1:3)
Block(-7,-17,-8,1:3)
Block(-7,-17,-7,1:1)
Block(-7,-17,-6,1:1)
Block(-7,-17,-5,1:1)
Block(-7,-17,-4,1:3)
Block(-7,-17,-3,1:3)
Block(-7,-17,-2,1:3)
Block(-7,-17,-1,1:3)
Block(-7,-17,0,1:3)
Block(-7,-17,1,1:3)
Block(-7,-17,2,1:3)
Block(-7,-17,3,1:3)
Block(-7,-17,4,1:3)
Block(-7,-17,5,1:3)
Block(-7,-17,6,1:3)
Block(-7,-17,7,1:3)
Block(-7,-16,-8,1:3)
Block(-7,-16,-7,1:3)
Block(-7,-16,-6,1:3)
Block(-7,-16,-5,1:3)
Block(-7,-16,-4,1:3)
Block(-7,-16,-3,1:3)
Block(-7,-16,-2,1:3)
Block(-7,-16,-1,1:3)
Block(-7,-16,0,1:3)
Block(-7,-16,1,1:3)
Block(-7,-16,2,1:3)
Block(-7,-16,3,1:3)
Block(-7,-16,4,1:3)
Block(-7,-16,5,1:3)
Block(-7,-16,6,1:3)
Block(-7,-16,7,1:3)
Block(-7,-15,-8,1:3)
Block(-7,-15,-7,1:3)
Block(-7,-15,-6,1:3)
Block(-7,-15,-5,1:3)
Block(-7,-15,-4,1:3)
Block(-7,-15,-3,1:3)
Block(-7,-15,-2,1:3)
Block(-7,-15,-1,1:3)
Block(-7,-15,0,1:3)
Block(-7,-15,1,1:3)
Block(-7,-15,2,1:3)
Block(-7,-15,3,1:3)
Block(-7,-15,4,1:3)
Block(-7,-15,5,1:3)
Block(-7,-15,6,1:3)
Block(-7,-15,7,1:3)
Block(-7,-14,-8,1:3)
Block(-7,-14,-7,1:3)
Block(-7,-14,-6,1:3)
Block(-7,-14,-5,1:3)
Block(-7,-14,-4,1:3)
Block(-7,-14,-3,1:3)
Block(-7,-14,-2,1:3)
Block(-7,-14,-1,1:3)
Block(-7,-14,0,1:3)
Block(-7,-14,1,1:3)
Block(-7,-14,2,1:3)
Block(-7,-14,3,1:3)
Block(-7,-14,4,1:3)
Block(-7,-14,5,1:3)
Block(-7,-14,6,1:3)
Block(-7,-14,7,1:3)
Block(-7,-13,-8,1:3)
Block(-7,-13,-7,1:3)
Block(-7,-13,-6,1:3)
Block(-7,-13,-5,1:3)
Block(-7,-13,-4,1:3)
Block(-7,-13,-3,1:3)
Block(-7,-13,-2,1:3)
Block(-7,-13,-1,1:3)
Block(-7,-13,0,1:3)
Block(-7,-13,1,1:3)
Block(-7,-13,2,1:3)
Block(-7,-13,3,1:3)
Block(-7,-13,4,1:3)
Block(-7,-13,5,1:3)
Block(-7,-13,6,1:3)
Block(-7,-13,7,1:3)
Block(-7,-12,-8,1:3)
Block(-7,-12,-7,1:3)
Block(-7,-12,-6,1:3)
Block(-7,-12,-5,1:3)
Block(-7,-12,-4,1:3)
Block(-7,-12,-3,1:3)
Block(-7,-12,-2,1:3)
Block(-7,-12,-1,1:3)
Block(-7,-12,0,1:3)
Block(-7,-12,1,1:3)
Block(-7,-12,2,1:1)
Block(-7,-12,3,1:3)
Block(-7,-12,4,1:3)
Block(-7,-12,5,1:3)
Block(-7,-12,6,1:3)
Block(-7,-12,7,1:3)
Block(-7,-11,-8,1:3)
Block(-7,-11,-7,1:3)
Block(-7,-11,-6,1:3)
Block(-7,-11,-5,1:3)
Block(-7,-11,-4,1:3)
Block(-7,-11,-3,1:3)
Block(-7,-11,-2,1:3)
Block(-7,-11,-1,1:3)
Block(-7,-11,0,1:3)
Block(-7,-11,1,1:3)
Block(-7,-11,2,1:1)
Block(-7,-11,3,1:1)
Block(-7,-11,4,1:3)
Block(-7,-11,5,1:3)
Block(-7,-11,6,1:3)
Block(-7,-11,7,1:3)
Block(-7,-10,-8,1:3)
Block(-7,-10,-7,1:3)
Block(-7,-10,-6,1:3)
Block(-7,-10,-5,1:3)
Block(-7,-10,-4,1:3)
Block(-7,-10,-3,1:3)
Block(-7,-10,-2,1:3)
Block(-7,-10,-1,1:3)
Block(-7,-10,0,1:3)
Block(-7,-10,1,1:3)
Block(-7,-10,2,1:1)
Block(-7,-10,3,1:1)
Block(-7,-10,4,1:3)
Block(-7,-10,5,1:3)
Block(-7,-10,6,1:3)
Block(-7,-10,7,1:3)
Block(-7,-9,-8,1:3)
Block(-7,-9,-7,1:3)
Block(-7,-9,-6,1:3)
Block(-7,-9,-5,1:3)
Block(-7,-9,-4,1:3)
Block(-7,-9,-3,1:3)
Block(-7,-9,-2,1:3)
Block(-7,-9,-1,1:3)
Block(-7,-9,0,1:3)
Block(-7,-9,1,1:1)
Block(-7,-9,2,1:1)
Block(-7,-9,3,1:1)
Block(-7,-9,4,1:3)
Block(-7,-9,5,1:3)
Block(-7,-9,6,1:3)
Block(-7,-9,7,1:3)
Block(-7,-8,-8,1:3)
Block(-7,-8,-7,1:3)
Block(-7,-8,-6,1:3)
Block(-7,-8,-5,1:3)
Block(-7,-8,-4,1:3)
Block(-7,-8,-3,1:3)
Block(-7,-8,-2,1:3)
Block(-7,-8,-1,1:3)
Block(-7,-8,0,1:1)
Block(-7,-8,1,1:1)
Block(-7,-8,2,1:1)
Block(-7,-8,3,1:1)
Block(-7,-8,4,1:3)
Block(-7,-8,5,1:3)
Block(-7,-8,6,1:3)
Block(-7,-8,7,1:3)
Block(-7,-7,-8,1:3)
Block(-7,-7,-7,1:3)
Block(-7,-7,-6,1:3)
Block(-7,-7,-5,1:3)
Block(-7,-7,-4,1:3)
Block(-7,-7,-3,1:3)
Block(-7,-7,-2,1:3)
Block(-7,-7,-1,1:1)
Block(-7,-7,0,1:1)
Block(-7,-7,1,1:1)
Block(-7,-7,2,1:1)
Block(-7,-7,3,1:1)
Block(-7,-7,4,1:1)
Block(-7,-7,5,1:3)
Block(-7,-7,6,1:3)
Block(-7,-7,7,1:3)
Block(-7,-6,-8,1:3)
Block(-7,-6,-7,1:3)
Block(-7,-6,-6,1:3)
Block(-7,-6,-5,1:3)
Block(-7,-6,-4,1:3)
Block(-7,-6,-3,1:1)
Block(-7,-6,-2,1:1)
Block(-7,-6,-1,1:1)
Block(-7,-6,0,1:1)
Block(-7,-6,1,1:1)
Block(-7,-6,2,1:1)
Block(-7,-6,3,1:1)
Block(-7,-6,4,1:1)
Block(-7,-6,5,1:3)
Block(-7,-6,6,1:3)
Block(-7,-6,7,1:3)
Block(-7,-5,-8,1:3)
Block(-7,-5,-7,1:3)
Block(-7,-5,-6,1:3)
Block(-7,-5,-5,1:3)
Block(-7,-5,-4,1:1)
Block(-7,-5,-3,1:1)
Block(-7,-5,-2,1:1)
Block(-7,-5,-1,1:1)
Block(-7,-5,0,1:1)
Block(-7,-5,1,1:1)
Block(-7,-5,2,1:1)
Block(-7,-5,3,1:1)
Block(-7,-5,4,1:3)
Block(-7,-5,5,1:3)
Block(-7,-5,6,1:3)
Block(-7,-5,7,1:3)
Block(-7,-4,-8,1:3)
Block(-7,-4,-7,1:3)
Block(-7,-4,-6,1:3)
Block(-7,-4,-5,1:1)
Block(-7,-4,-4,1:1)
Block(-7,-4,-3,1:1)
Block(-7,-4,-2,1:1)
Block(-7,-4,-1,1:1)
Block(-7,-4,0,1:1)
Block(-7,-4,1,1:1)
Block(-7,-4,2,1:1)
Block(-7,-4,3,1:1)
Block(-7,-4,4,1:3)
Block(-7,-4,5,1:3)
Block(-7,-4,6,1:3)
Block(-7,-4,7,1:3)
Block(-7,-3,-8,1:1)
Block(-7,-3,-7,1:1)
Block(-7,-3,-6,1:1)
Block(-7,-3,-5,1:1)
Block(-7,-3,-4,1:1)
Block(-7,-3,-3,1:1)
Block(-7,-3,-2,1:1)
Block(-7,-3,-1,1:1)
Block(-7,-3,0,1:1)
Block(-7,-3,1,1:1)
Block(-7,-3,2,1:1)
Block(-7,-3,3,1:1)
Block(-7,-3,4,1:3)
Block(-7,-3,5,1:3)
Block(-7,-3,6,1:3)
Block(-7,-3,7,1:3)
Block(-7,-2,-8,1:1)
Block(-7,-2,-7,1:1)
Block(-7,-2,-6,1:1)
Block(-7,-2,-5,1:1)
Block(-7,-2,-4,1:1)
Block(-7,-2,-3,1:1)
Block(-7,-2,-2,1:1)
Block(-7,-2,-1,1:1)
Block(-7,-2,0,1:1)
Block(-7,-2,1,1:1)
Block(-7,-2,2,1:1)
Block(-7,-2,3,1:1)
Block(-7,-2,4,1:3)
Block(-7,-2,5,1:3)
Block(-7,-2,6,1:3)
Block(-7,-2,7,1:3)
Block(-7,-1,-8,1:1)
Block(-7,-1,-7,1:1)
Block(-7,-1,-6,1:1)
Block(-7,-1,-5,1:1)
Block(-7,-1,-4,1:1)
Block(-7,-1,-3,1:1)
Block(-7,-1,-2,1:1)
Block(-7,-1,-1,1:1)
Block(-7,-1,0,1:1)
Block(-7,-1,1,1:1)
Block(-7,-1,2,1:1)
Block(-7,-1,3,1:3)
Block(-7,-1,4,1:3)
Block(-7,-1,5,1:3)
Block(-7,-1,6,1:3)
Block(-7,-1,7,1:3)
Block(-7,0,-8,1:1)
Block(-7,0,-7,1:1)
Block(-7,0,-6,1:1)
Block(-7,0,-5,1:1)
Block(-7,0,-4,1:1)
Block(-7,0,-3,1:1)
Block(-7,0,-2,1:1)
Block(-7,0,-1,1:1)
Block(-7,0,0,1:1)
Block(-7,0,1,1:1)
Block(-7,0,2,1:1)
Block(-7,0,3,1:3)
Block(-7,0,4,1:3)
Block(-7,0,5,1:3)
Block(-7,0,6,1:3)
Block(-7,0,7,1:3)
Block(-7,1,-8,1:1)
Block(-7,1,-7,1:1)
Block(-7,1,-6,1:1)
Block(-7,1,-5,1:1)
Block(-7,1,-4,1:1)
Block(-7,1,-3,1:1)
Block(-7,1,-2,1:1)
Block(-7,1,-1,1:1)
Block(-7,1,0,1:1)
Block(-7,1,1,1:1)
Block(-7,1,2,1:1)
Block(-7,1,3,1:3)
Block(-7,1,4,1:3)
Block(-7,1,5,1:3)
Block(-7,1,6,1:3)
Block(-7,1,7,1:1)
Block(-7,2,-8,1:1)
Block(-7,2,-7,1:1)
Block(-7,2,-6,1:1)
Block(-7,2,-5,1:1)
Block(-7,2,-4,1:1)
Block(-7,2,-3,1:1)
Block(-7,2,-2,1:1)
Block(-7,2,-1,1:1)
Block(-7,2,0,1:1)
Block(-7,2,1,1:1)
Block(-7,2,2,1:3)
Block(-7,2,3,1:3)
Block(-7,2,4,1:3)
Block(-7,2,5,1:3)
Block(-7,2,6,1:1)
Block(-7,2,7,1:1)
Block(-7,3,-8,1:1)
Block(-7,3,-7,1:1)
Block(-7,3,-6,1:1)
Block(-7,3,-5,1:1)
Block(-7,3,-4,1:1)
Block(-7,3,-3,1:1)
Block(-7,3,-2,1:1)
Block(-7,3,-1,1:1)
Block(-7,3,0,1:1)
Block(-7,3,1,1:1)
Block(-7,3,2,1:3)
Block(-7,3,3,1:1)
Block(-7,3,4,1:1)
Block(-7,3,5,1:1)
Block(-7,3,6,1:1)
Block(-7,3,7,1:1)
Block(-7,4,-8,1:1)
Block(-7,4,-7,1:1)
Block(-7,4,-6,1:1)
Block(-7,4,-5,1:1)
Block(-7,4,-4,1:1)
Block(-7,4,-3,1:1)
Block(-7,4,-2,1:1)
Block(-7,4,-1,1:1)
Block(-7,4,0,1:1)
Block(-7,4,1,1:1)
Block(-7,4,2,1:1)
Block(-7,4,3,1:1)
Block(-7,4,4,1:1)
Block(-7,4,5,1:1)
Block(-7,4,6,1:1)
Block(-7,4,7,1:1)
Block(-7,5,-8,1:1)
Block(-7,5,-7,1:1)
Block(-7,5,-6,1:1)
Block(-7,5,-5,1:1)
Block(-7,5,-4,1:1)
Block(-7,5,-3,1:1)
Block(-7,5,-2,1:1)
Block(-7,5,-1,1:1)
Block(-7,5,0,1:1)
Block(-7,5,1,1:1)
Block(-7,5,2,1:1)
Block(-7,5,3,1:1)
Block(-7,5,4,1:1)
Block(-7,5,5,1:1)
Block(-7,5,6,1:1)
Block(-7,5,7,1:1)
Block(-7,6,-8,1:1)
Block(-7,6,-7,1:1)
Block(-7,6,-6,1:1)
Block(-7,6,-5,1:1)
Block(-7,6,-4,1:1)
Block(-7,6,-3,1:1)
Block(-7,6,-2,1:1)
Block(-7,6,-1,1:1)
Block(-7,6,0,1:1)
Block(-7,6,1,1:1)
Block(-7,6,2,1:1)
Block(-7,6,3,1:1)
Block(-7,6,4,1:1)
Block(-7,6,5,1:1)
Block(-7,6,6,1:3)
Block(-7,6,7,1:3)
Block(-7,7,-8,1:1)
Block(-7,7,-7,1:1)
Block(-7,7,-6,1:1)
Block(-7,7,-5,1:1)
Block(-7,7,-4,1:1)
Block(-7,7,-3,1:1)
Block(-7,7,-2,1:1)
Block(-7,7,-1,1:1)
Block(-7,7,0,1:1)
Block(-7,7,1,1:1)
Block(-7,7,2,1:1)
Block(-7,7,3,1:1)
Block(-7,7,4,1:3)
Block(-7,7,5,1:3)
Block(-7,7,6,1:3)
Block(-7,7,7,1:3)
Block(-7,8,-8,1:1)
Block(-7,8,-7,1:1)
Block(-7,8,-6,1:1)
Block(-7,8,-5,1:1)
Block(-7,8,-4,1:1)
Block(-7,8,-3,1:1)
Block(-7,8,-2,1:1)
Block(-7,8,-1,1:1)
Block(-7,8,0,1:1)
Block(-7,8,1,1:1)
Block(-7,8,2,1:3)
Block(-7,8,3,1:3)
Block(-7,8,4,1:3)
Block(-7,8,5,1:3)
Block(-7,8,6,1:3)
Block(-7,8,7,1:3)
Block(-7,9,-8,1:3)
Block(-7,9,-7,1:3)
Block(-7,9,-6,1:1)
Block(-7,9,-5,1:3)
Block(-7,9,-4,1:1)
Block(-7,9,-3,1:1)
Block(-7,9,-2,1:1)
Block(-7,9,-1,1:1)
Block(-7,9,0,1:1)
Block(-7,9,1,1:3)
Block(-7,9,2,1:3)
Block(-7,9,3,1:3)
Block(-7,9,4,1:3)
Block(-7,9,5,1:3)
Block(-7,9,6,1:3)
Block(-7,9,7,1:3)
Block(-7,10,-8,1:3)
Block(-7,10,-7,1:3)
Block(-7,10,-6,1:3)
Block(-7,10,-5,1:3)
Block(-7,10,-4,1:1)
Block(-7,10,-3,1:1)
Block(-7,10,-2,1:1)
Block(-7,10,-1,1:1)
Block(-7,10,0,1:3)
Block(-7,10,1,1:3)
Block(-7,10,2,1:3)
Block(-7,10,3,1:3)
Block(-7,10,4,1:3)
Block(-7,10,5,1:3)
Block(-7,10,6,1:3)
Block(-7,10,7,1:3)
Block(-7,11,-8,1:3)
Block(-7,11,-7,1:3)
Block(-7,11,-6,1:3)
Block(-7,11,-5,1:1)
Block(-7,11,-4,1:1)
Block(-7,11,-3,1:1)
Block(-7,11,-2,1:1)
Block(-7,11,-1,1:1)
Block(-7,11,0,1:3)
Block(-7,11,1,1:3)
Block(-7,11,2,1:3)
Block(-7,11,3,1:3)
Block(-7,11,4,1:3)
Block(-7,11,5,1:3)
Block(-7,11,6,1:3)
Block(-7,11,7,1:3)
Block(-7,12,-8,1:3)
Block(-7,12,-7,1:3)
Block(-7,12,-6,1:3)
Block(-7,12,-5,1:1)
Block(-7,12,-4,1:1)
Block(-7,12,-3,1:1)
Block(-7,12,-2,1:1)
Block(-7,12,-1,1:3)
Block(-7,12,0,1:3)
Block(-7,12,1,1:3)
Block(-7,12,2,1:3)
Block(-7,12,3,1:3)
Block(-7,12,4,1:3)
Block(-7,12,5,1:3)
Block(-7,12,6,1:3)
Block(-7,12,7,1:3)
Block(-7,13,-8,1:3)
Block(-7,13,-7,1:3)
Block(-7,13,-6,1:1)
Block(-7,13,-5,1:1)
Block(-7,13,-4,1:1)
Block(-7,13,-3,1:1)
Block(-7,13,-2,1:1)
Block(-7,13,-1,1:1)
Block(-7,13,0,1:3)
Block(-7,13,1,1:3)
Block(-7,13,2,1:3)
Block(-7,13,3,1:3)
Block(-7,13,4,1:3)
Block(-7,13,5,1:3)
Block(-7,13,6,1:3)
Block(-7,13,7,1:3)
Block(-7,14,-8,1:3)
Block(-7,14,-7,1:1)
Block(-7,14,-6,1:1)
Block(-7,14,-5,1:1)
Block(-7,14,-4,1:1)
Block(-7,14,-3,1:1)
Block(-7,14,-2,1:1)
Block(-7,14,-1,1:3)
Block(-7,14,0,1:3)
Block(-7,14,1,1:3)
Block(-7,14,2,1:3)
Block(-7,14,3,1:3)
Block(-7,14,4,1:3)
Block(-7,14,5,1:3)
Block(-7,14,6,1:3)
Block(-7,14,7,1:3)
Block(-7,15,-8,1:3)
Block(-7,15,-7,1:3)
Block(-7,15,-6,1:1)
Block(-7,15,-5,1:1)
Block(-7,15,-4,1:1)
Block(-7,15,-3,1:1)
Block(-7,15,-2,1:1)
Block(-7,15,-1,1:3)
Block(-7,15,0,1:3)
Block(-7,15,1,1:3)
Block(-7,15,2,1:3)
Block(-7,15,3,1:3)
Block(-7,15,4,1:3)
Block(-7,15,5,1:3)
Block(-7,15,6,1:3)
Block(-7,15,7,1:3)
Block(-7,16,-8,1:3)
Block(-7,16,-7,1:1)
Block(-7,16,-6,1:1)
Block(-7,16,-5,1:1)
Block(-7,16,-4,1:1)
Block(-7,16,-3,1:1)
Block(-7,16,-2,1:1)
Block(-7,16,-1,1:3)
Block(-7,16,0,1:3)
Block(-7,16,1,1:3)
Block(-7,16,2,1:3)
Block(-7,16,3,1:3)
Block(-7,16,4,1:3)
Block(-7,16,5,1:3)
Block(-7,16,6,1:3)
Block(-7,16,7,1:3)
Block(-7,17,-8,1:3)
Block(-7,17,-7,1:1)
Block(-7,17,-6,1:1)
Block(-7,17,-5,1:1)
Block(-7,17,-4,1:1)
Block(-7,17,-3,1:1)
Block(-7,17,-2,1:1)
Block(-7,17,-1,1:3)
Block(-7,17,0,1:3)
Block(-7,17,1,1:3)
Block(-7,17,2,1:3)
Block(-7,17,3,1:3)
Block(-7,17,4,1:3)
Block(-7,17,5,1:3)
Block(-7,17,6,1:3)
Block(-7,17,7,1:3)
Block(-7,18,-8,1:3)
Block(-7,18,-7,1:3)
Block(-7,18,-6,1:1)
Block(-7,18,-5,1:1)
Block(-7,18,-4,1:1)
Block(-7,18,-3,1:1)
Block(-7,18,-2,1:1)
Block(-7,18,-1,1:3)
Block(-7,18,0,1:3)
Block(-7,18,1,1:3)
Block(-7,18,2,1:3)
Block(-7,18,3,1:3)
Block(-7,18,4,1:3)
Block(-7,18,5,1:3)
Block(-7,18,6,1:3)
Block(-7,18,7,1:3)
Block(-7,19,-8,1:3)
Block(-7,19,-7,1:3)
Block(-7,19,-6,1:3)
Block(-7,19,-5,1:1)
Block(-7,19,-4,1:1)
Block(-7,19,-3,1:1)
Block(-7,19,-2,1:1)
Block(-7,19,-1,1:3)
Block(-7,19,0,1:3)
Block(-7,19,1,1:3)
Block(-7,19,2,1:3)
Block(-7,19,3,1:3)
Block(-7,19,4,1:3)
Block(-7,19,5,1:3)
Block(-7,19,6,1:3)
Block(-7,19,7,1:3)
Block(-7,20,-8,1:3)
Block(-7,20,-7,1:3)
Block(-7,20,-6,1:3)
Block(-7,20,-5,1:3)
Block(-7,20,-4,1:3)
Block(-7,20,-3,1:1)
Block(-7,20,-2,1:1)
Block(-7,20,-1,1:3)
Block(-7,20,0,1:3)
Block(-7,20,1,1:3)
Block(-7,20,2,1:3)
Block(-7,20,3,1:3)
Block(-7,20,4,1:3)
Block(-7,20,5,1:3)
Block(-7,20,6,1:3)
Block(-7,20,7,1:3)
Block(-7,21,-8,1:3)
Block(-7,21,-7,1:3)
Block(-7,21,-6,1:3)
Block(-7,21,-5,1:3)
Block(-7,21,-4,1:3)
Block(-7,21,-3,1:3)
Block(-7,21,-2,1:1)
Block(-7,21,-1,1:1)
Block(-7,21,0,1:3)
Block(-7,21,1,1:3)
Block(-7,21,2,1:3)
Block(-7,21,3,1:3)
Block(-7,21,4,1:3)
Block(-7,21,5,1:3)
Block(-7,21,6,1:3)
Block(-7,21,7,1:3)
Block(-7,22,-8,1:3)
Block(-7,22,-7,1:3)
Block(-7,22,-6,1:3)
Block(-7,22,-5,1:3)
Block(-7,22,-4,1:3)
Block(-7,22,-3,1:3)
Block(-7,22,-2,1:3)
Block(-7,22,-1,1:1)
Block(-7,22,0,1:1)
Block(-7,22,1,1:1)
Block(-7,22,2,1:3)
Block(-7,22,3,1:3)
Block(-7,22,4,1:3)
Block(-7,22,5,1:3)
Block(-7,22,6,1:3)
Block(-7,22,7,1:3)
Block(-7,23,-8,1:3)
Block(-7,23,-7,1:3)
Block(-7,23,-6,1:3)
Block(-7,23,-5,1:3)
Block(-7,23,-4,1:3)
Block(-7,23,-3,1:3)
Block(-7,23,-2,1:3)
Block(-7,23,-1,1:3)
Block(-7,23,0,1:1)
Block(-7,23,1,1:1)
Block(-7,23,2,1:1)
Block(-7,23,3,1:3)
Block(-7,23,4,1:3)
Block(-7,23,5,1:3)
Block(-7,23,6,1:1)
Block(-7,23,7,1:3)
Block(-7,24,-8,1:1)
Block(-7,24,-7,1:1)
Block(-7,24,-6,1:3)
Block(-7,24,-5,1:3)
Block(-7,24,-4,1:3)
Block(-7,24,-3,1:3)
Block(-7,24,-2,1:3)
Block(-7,24,-1,1:3)
Block(-7,24,0,1:3)
Block(-7,24,1,1:1)
Block(-7,24,2,1:1)
Block(-7,24,3,1:1)
Block(-7,24,4,1:1)
Block(-7,24,5,1:1)
Block(-7,24,6,1:1)
Block(-7,24,7,1:1)
Block(-7,25,-8,1:1)
Block(-7,25,-7,1:1)
Block(-7,25,-6,1:1)
Block(-7,25,-5,1:3)
Block(-7,25,-4,1:3)
Block(-7,25,-3,1:3)
Block(-7,25,-2,1:3)
Block(-7,25,-1,1:3)
Block(-7,25,0,1:3)
Block(-7,25,1,1:3)
Block(-7,25,2,1:1)
Block(-7,25,3,1:1)
Block(-7,25,4,1:1)
Block(-7,25,5,1:1)
Block(-7,25,6,1:1)
Block(-7,25,7,1:1)
Block(-7,26,-8,1:1)
Block(-7,26,-7,1:1)
Block(-7,26,-6,1:1)
Block(-7,26,-5,1:3)
Block(-7,26,-4,1:3)
Block(-7,26,-3,1:3)
Block(-7,26,-2,1:3)
Block(-7,26,-1,1:3)
Block(-7,26,0,1:3)
Block(-7,26,1,1:3)
Block(-7,26,2,1:3)
Block(-7,26,3,1:3)
Block(-7,26,4,1:1)
Block(-7,26,5,1:1)
Block(-7,26,6,1:1)
Block(-7,26,7,1:1)
Block(-7,27,-8,1:1)
Block(-7,27,-7,1:1)
Block(-7,27,-6,1:1)
Block(-7,27,-5,1:1)
Block(-7,27,-4,1:1)
Block(-7,27,-3,1:3)
Block(-7,27,-2,1:3)
Block(-7,27,-1,1:3)
Block(-7,27,0,1:3)
Block(-7,27,1,1:3)
Block(-7,27,2,1:3)
Block(-7,27,3,1:3)
Block(-7,27,4,1:3)
Block(-7,27,5,1:1)
Block(-7,27,6,1:1)
Block(-7,27,7,1:1)
Block(-7,28,-8,1:1)
Block(-7,28,-7,1:1)
Block(-7,28,-6,1:1)
Block(-7,28,-5,1:1)
Block(-7,28,-4,1:1)
Block(-7,28,-3,1:3)
Block(-7,28,-2,1:3)
Block(-7,28,-1,1:3)
Block(-7,28,0,1:3)
Block(-7,28,1,1:3)
Block(-7,28,2,1:3)
Block(-7,28,3,1:3)
Block(-7,28,4,1:3)
Block(-7,28,5,1:3)
Block(-7,28,6,1:1)
Block(-7,28,7,1:1)
Block(-7,29,-8,1:1)
Block(-7,29,-7,1:1)
Block(-7,29,-6,1:1)
Block(-7,29,-5,1:1)
Block(-7,29,-4,1:1)
Block(-7,29,-3,1:3)
Block(-7,29,-2,1:3)
Block(-7,29,-1,1:3)
Block(-7,29,0,1:3)
Block(-7,29,1,1:3)
Block(-7,29,2,1:3)
Block(-7,29,3,1:3)
Block(-7,29,4,1:3)
Block(-7,29,5,1:3)
Block(-7,29,6,1:3)
Block(-7,29,7,1:1)
Block(-7,30,-8,1:1)
Block(-7,30,-7,1:1)
Block(-7,30,-6,1:1)
Block(-7,30,-5,1:1)
Block(-7,30,-4,1:1)
Block(-7,30,-3,1:3)
Block(-7,30,-2,1:3)
Block(-7,30,-1,1:3)
Block(-7,30,0,1:3)
Block(-7,30,1,1:3)
Block(-7,30,2,1:3)
Block(-7,30,3,1:3)
Block(-7,30,4,1:3)
Block(-7,30,5,1:3)
Block(-7,30,6,1:3)
Block(-7,30,7,1:3)
Block(-7,31,-8,1:3)
Block(-7,31,-7,1:1)
Block(-7,31,-6,1:1)
Block(-7,31,-5,1:1)
Block(-7,31,-4,1:3)
Block(-7,31,-3,1:3)
Block(-7,31,-2,1:3)
Block(-7,31,-1,1:3)
Block(-7,31,0,1:3)
Block(-7,31,1,1:3)
Block(-7,31,2,1:3)
Block(-7,31,3,1:3)
Block(-7,31,4,1:3)
Block(-7,31,5,1:3)
Block(-7,31,6,1:3)
Block(-7,31,7,1:3)
Block(-7,32,-8,1:3)
Block(-7,32,-7,1:3)
Block(-7,32,-6,1:1)
Block(-7,32,-5,1:3)
Block(-7,32,-4,1:3)
Block(-7,32,-3,1:3)
Block(-7,32,-2,1:3)
Block(-7,32,-1,1:3)
Block(-7,32,0,1:3)
Block(-7,32,1,1:3)
Block(-7,32,2,1:3)
Block(-7,32,3,1:3)
Block(-7,32,4,1:3)
Block(-7,32,5,1:3)
Block(-7,32,6,1:3)
Block(-7,32,7,1:3)
Block(-7,33,-8,1:3)
Block(-7,33,-7,1:3)
Block(-7,33,-6,1:3)
Block(-7,33,-5,1:3)
Block(-7,33,-4,1:3)
Block(-7,33,-3,1:3)
Block(-7,33,-2,1:3)
Block(-7,33,-1,1:3)
Block(-7,33,0,1:3)
Block(-7,33,1,1:3)
Block(-7,33,2,1:3)
Block(-7,33,3,1:1)
Block(-7,33,4,1:1)
Block(-7,33,5,1:1)
Block(-7,33,6,1:1)
Block(-7,33,7,1:1)
Block(-7,34,-8,1:3)
Block(-7,34,-7,1:3)
Block(-7,34,-6,1:3)
Block(-7,34,-5,1:3)
Block(-7,34,-4,1:3)
Block(-7,34,-3,1:3)
Block(-7,34,-2,1:3)
Block(-7,34,-1,1:3)
Block(-7,34,0,1:3)
Block(-7,34,1,1:3)
Block(-7,34,2,1:1)
Block(-7,34,3,1:1)
Block(-7,34,4,1:1)
Block(-7,34,5,1:1)
Block(-7,34,6,1:1)
Block(-7,34,7,1:1)
Block(-7,35,-8,1:3)
Block(-7,35,-7,1:3)
Block(-7,35,-6,1:3)
Block(-7,35,-5,1:3)
Block(-7,35,-4,1:3)
Block(-7,35,-3,1:3)
Block(-7,35,-2,1:3)
Block(-7,35,-1,1:3)
Block(-7,35,0,1:1)
Block(-7,35,1,1:1)
Block(-7,35,2,1:1)
Block(-7,35,3,1:1)
Block(-7,35,4,1:1)
Block(-7,35,5,1:1)
Block(-7,35,6,1:1)
Block(-7,35,7,1:1)
Block(-7,36,-8,1:3)
Block(-7,36,-7,1:3)
Block(-7,36,-6,1:3)
Block(-7,36,-5,1:3)
Block(-7,36,-4,1:3)
Block(-7,36,-3,1:3)
Block(-7,36,-2,1:3)
Block(-7,36,-1,1:1)
Block(-7,36,0,1:1)
Block(-7,36,1,1:1)
Block(-7,36,2,1:1)
Block(-7,36,3,1:1)
Block(-7,36,4,1:1)
Block(-7,36,5,1:1)
Block(-7,36,6,1:1)
Block(-7,36,7,1:1)
Block(-7,37,-8,1:3)
Block(-7,37,-7,1:3)
Block(-7,37,-6,1:3)
Block(-7,37,-5,1:3)
Block(-7,37,-4,1:3)
Block(-7,37,-3,1:3)
Block(-7,37,-2,1:1)
Block(-7,37,-1,1:1)
Block(-7,37,0,1:1)
Block(-7,37,1,1:1)
Block(-7,37,2,1:1)
Block(-7,37,3,1:1)
Block(-7,37,4,1:1)
Block(-7,37,5,1:1)
Block(-7,37,6,1:1)
Block(-7,37,7,1:1)
Block(-7,38,-8,1:3)
Block(-7,38,-7,1:3)
Block(-7,38,-6,1:3)
Block(-7,38,-5,1:3)
Block(-7,38,-4,1:1)
Block(-7,38,-3,1:1)
Block(-7,38,-2,1:1)
Block(-7,38,-1,1:1)
Block(-7,38,0,1:1)
Block(-7,38,1,1:1)
Block(-7,38,2,1:1)
Block(-7,38,3,1:1)
Block(-7,38,4,1:1)
Block(-7,38,5,1:1)
Block(-7,38,6,1:1)
Block(-7,38,7,1:1)
Block(-7,39,-8,1:3)
Block(-7,39,-7,1:3)
Block(-7,39,-6,1:3)
Block(-7,39,-5,1:3)
Block(-7,39,-4,1:1)
Block(-7,39,-3,1:1)
Block(-7,39,-2,1:1)
Block(-7,39,-1,1:1)
Block(-7,39,0,1:1)
Block(-7,39,1,1:3)
Block(-7,39,2,1:3)
Block(-7,39,3,1:3)
Block(-7,39,4,1:3)
Block(-7,39,5,1:3)
Block(-7,39,6,1:3)
Block(-7,39,7,1:3)
Block(-7,40,-8,1:3)
Block(-7,40,-7,1:3)
Block(-7,40,-6,1:3)
Block(-7,40,-5,1:1)
Block(-7,40,-4,1:1)
Block(-7,40,-3,1:1)
Block(-7,40,-2,1:1)
Block(-7,40,-1,1:1)
Block(-7,40,0,1:3)
Block(-7,40,1,1:3)
Block(-7,40,2,1:3)
Block(-7,40,3,1:3)
Block(-7,40,4,1:3)
Block(-7,40,5,1:3)
Block(-7,40,6,1:3)
Block(-7,40,7,1:3)
Block(-7,41,-8,1:3)
Block(-7,41,-7,1:3)
Block(-7,41,-6,1:3)
Block(-7,41,-5,1:1)
Block(-7,41,-4,1:1)
Block(-7,41,-3,1:1)
Block(-7,41,-2,1:1)
Block(-7,41,-1,1:1)
Block(-7,41,0,1:3)
Block(-7,41,1,1:3)
Block(-7,41,2,1:3)
Block(-7,41,3,1:3)
Block(-7,41,4,1:3)
Block(-7,41,5,1:3)
Block(-7,41,6,1:3)
Block(-7,41,7,1:3)
Block(-7,42,-8,1:3)
Block(-7,42,-7,1:3)
Block(-7,42,-6,1:3)
Block(-7,42,-5,1:1)
Block(-7,42,-4,1:1)
Block(-7,42,-3,1:1)
Block(-7,42,-2,1:1)
Block(-7,42,-1,1:3)
Block(-7,42,0,1:3)
Block(-7,42,1,1:3)
Block(-7,42,2,1:3)
Block(-7,42,3,1:3)
Block(-7,42,4,1:3)
Block(-7,42,5,1:3)
Block(-7,42,6,1:3)
Block(-7,42,7,1:3)
Block(-7,43,-8,1:3)
Block(-7,43,-7,1:3)
Block(-7,43,-6,1:3)
Block(-7,43,-5,1:1)
Block(-7,43,-4,1:1)
Block(-7,43,-3,1:1)
Block(-7,43,-2,1:1)
Block(-7,43,-1,1:3)
Block(-7,43,0,1:3)
Block(-7,43,1,1:3)
Block(-7,43,2,1:3)
Block(-7,43,3,1:3)
Block(-7,43,4,1:3)
Block(-7,43,5,1:3)
Block(-7,43,6,1:3)
Block(-7,43,7,1:3)
Block(-7,44,-8,1:3)
Block(-7,44,-7,1:3)
Block(-7,44,-6,1:3)
Block(-7,44,-5,1:1)
Block(-7,44,-4,1:1)
Block(-7,44,-3,1:1)
Block(-7,44,-2,1:3)
Block(-7,44,-1,1:3)
Block(-7,44,0,1:3)
Block(-7,44,1,1:3)
Block(-7,44,2,1:3)
Block(-7,44,3,1:3)
Block(-7,44,4,1:3)
Block(-7,44,5,1:3)
Block(-7,44,6,1:3)
Block(-7,44,7,1:3)
Block(-7,45,-8,1:3)
Block(-7,45,-7,1:3)
Block(-7,45,-6,1:3)
Block(-7,45,-5,1:1)
Block(-7,45,-4,1:1)
Block(-7,45,-3,1:1)
Block(-7,45,-2,1:3)
Block(-7,45,-1,1:3)
Block(-7,45,0,1:3)
Block(-7,45,1,1:3)
Block(-7,45,2,1:3)
Block(-7,45,3,1:3)
Block(-7,45,4,1:3)
Block(-7,45,5,1:3)
Block(-7,45,6,1:3)
Block(-7,45,7,1:3)
Block(-7,46,-8,1:3)
Block(-7,46,-7,1:3)
Block(-7,46,-6,1:3)
Block(-7,46,-5,1:1)
Block(-7,46,-4,1:1)
Block(-7,46,-3,1:1)
Block(-7,46,-2,1:3)
Block(-7,46,-1,1:3)
Block(-7,46,0,1:3)
Block(-7,46,1,1:3)
Block(-7,46,2,1:3)
Block(-7,46,3,1:3)
Block(-7,46,4,1:3)
Block(-7,46,5,1:3)
Block(-7,46,6,1:3)
Block(-7,46,7,1:3)
Block(-7,47,-8,1:3)
Block(-7,47,-7,1:3)
Block(-7,47,-6,1:1)
Block(-7,47,-5,1:1)
Block(-7,47,-4,1:3)
Block(-7,47,-3,1:3)
Block(-7,47,-2,1:3)
Block(-7,47,-1,1:3)
Block(-7,47,0,1:3)
Block(-7,47,1,1:3)
Block(-7,47,2,1:3)
Block(-7,47,3,1:3)
Block(-7,47,4,1:3)
Block(-7,47,5,1:3)
Block(-7,47,6,1:3)
Block(-7,47,7,1:3)
Block(-6,-33,-8,1:1)
Block(-6,-33,-7,1:1)
Block(-6,-33,-6,1:1)
Block(-6,-33,-5,1:1)
Block(-6,-33,-4,1:1)
Block(-6,-33,-3,1:1)
Block(-6,-33,-2,1:1)
Block(-6,-33,-1,1:1)
Block(-6,-33,0,1:1)
Block(-6,-33,1,1:1)
Block(-6,-33,2,1:1)
Block(-6,-33,3,1:1)
Block(-6,-33,4,1:1)
Block(-6,-33,5,1:1)
Block(-6,-33,6,1:1)
Block(-6,-33,7,1:1)
Block(-6,-32,-8,1:1)
Block(-6,-32,-7,1:1)
Block(-6,-32,-6,1:1)
Block(-6,-32,-5,1:1)
Block(-6,-32,-4,1:1)
Block(-6,-32,-3,1:1)
Block(-6,-32,-2,1:1)
Block(-6,-32,-1,1:1)
Block(-6,-32,0,1:1)
Block(-6,-32,1,1:1)
Block(-6,-32,2,1:1)
Block(-6,-32,3,1:1)
Block(-6,-32,4,1:1)
Block(-6,-32,5,1:1)
Block(-6,-32,6,1:1)
Block(-6,-32,7,1:1)
Block(-6,-31,-8,1:1)
Block(-6,-31,-7,1:1)
Block(-6,-31,-6,1:1)
Block(-6,-31,-5,1:1)
Block(-6,-31,-4,1:1)
Block(-6,-31,-3,1:1)
Block(-6,-31,-2,1:1)
Block(-6,-31,-1,1:1)
Block(-6,-31,0,1:1)
Block(-6,-31,1,1:1)
Block(-6,-31,2,1:1)
Block(-6,-31,3,1:1)
Block(-6,-31,4,1:1)
Block(-6,-31,5,1:1)
Block(-6,-31,6,1:1)
Block(-6,-31,7,1:1)
Block(-6,-30,-8,1:1)
Block(-6,-30,-7,1:1)
Block(-6,-30,-6,1:1)
Block(-6,-30,-5,1:1)
Block(-6,-30,-4,1:1)
Block(-6,-30,-3,1:1)
Block(-6,-30,-2,1:1)
Block(-6,-30,-1,1:1)
Block(-6,-30,0,1:1)
Block(-6,-30,1,1:1)
Block(-6,-30,2,1:1)
Block(-6,-30,3,1:1)
Block(-6,-30,4,1:1)
Block(-6,-30,5,1:1)
Block(-6,-30,6,1:1)
Block(-6,-30,7,1:3)
Block(-6,-29,-8,1:1)
Block(-6,-29,-7,1:1)
Block(-6,-29,-6,1:1)
Block(-6,-29,-5,1:1)
Block(-6,-29,-4,1:1)
Block(-6,-29,-3,1:1)
Block(-6,-29,-2,1:1)
Block(-6,-29,-1,1:1)
Block(-6,-29,0,1:1)
Block(-6,-29,1,1:1)
Block(-6,-29,2,1:1)
Block(-6,-29,3,1:1)
Block(-6,-29,4,1:1)
Block(-6,-29,5,1:1)
Block(-6,-29,6,1:1)
Block(-6,-29,7,1:3)
Block(-6,-28,-8,1:1)
Block(-6,-28,-7,1:1)
Block(-6,-28,-6,1:1)
Block(-6,-28,-5,1:1)
Block(-6,-28,-4,1:1)
Block(-6,-28,-3,1:1)
Block(-6,-28,-2,1:1)
Block(-6,-28,-1,1:1)
Block(-6,-28,0,1:1)
Block(-6,-28,1,1:1)
Block(-6,-28,2,1:1)
Block(-6,-28,3,1:1)
Block(-6,-28,4,1:1)
Block(-6,-28,5,1:1)
Block(-6,-28,6,1:1)
Block(-6,-28,7,1:3)
Block(-6,-27,-8,1:1)
Block(-6,-27,-7,1:1)
Block(-6,-27,-6,1:1)
Block(-6,-27,-5,1:1)
Block(-6,-27,-4,1:1)
Block(-6,-27,-3,1:1)
Block(-6,-27,-2,1:1)
Block(-6,-27,-1,1:1)
Block(-6,-27,0,1:1)
Block(-6,-27,1,1:1)
Block(-6,-27,2,1:1)
Block(-6,-27,3,1:1)
Block(-6,-27,4,1:1)
Block(-6,-27,5,1:1)
Block(-6,-27,6,1:1)
Block(-6,-27,7,1:1)
Block(-6,-26,-8,1:1)
Block(-6,-26,-7,1:1)
Block(-6,-26,-6,1:1)
Block(-6,-26,-5,1:1)
Block(-6,-26,-4,1:1)
Block(-6,-26,-3,1:1)
Block(-6,-26,-2,1:1)
Block(-6,-26,-1,1:1)
Block(-6,-26,0,1:1)
Block(-6,-26,1,1:1)
Block(-6,-26,2,1:3)
Block(-6,-26,3,1:1)
Block(-6,-26,4,1:1)
Block(-6,-26,5,1:1)
Block(-6,-26,6,1:1)
Block(-6,-26,7,1:1)
Block(-6,-25,-8,1:1)
Block(-6,-25,-7,1:1)
Block(-6,-25,-6,1:1)
Block(-6,-25,-5,1:1)
Block(-6,-25,-4,1:1)
Block(-6,-25,-3,1:1)
Block(-6,-25,-2,1:1)
Block(-6,-25,-1,1:1)
Block(-6,-25,0,1:1)
Block(-6,-25,1,1:3)
Block(-6,-25,2,1:3)
Block(-6,-25,3,1:1)
Block(-6,-25,4,1:3)
Block(-6,-25,5,1:1)
Block(-6,-25,6,1:1)
Block(-6,-25,7,1:1)
Block(-6,-24,-8,1:1)
Block(-6,-24,-7,1:1)
Block(-6,-24,-6,1:1)
Block(-6,-24,-5,1:1)
Block(-6,-24,-4,1:1)
Block(-6,-24,-3,1:1)
Block(-6,-24,-2,1:1)
Block(-6,-24,-1,1:1)
Block(-6,-24,0,1:3)
Block(-6,-24,1,1:3)
Block(-6,-24,2,1:3)
Block(-6,-24,3,1:3)
Block(-6,-24,4,1:3)
Block(-6,-24,5,1:1)
Block(-6,-24,6,1:1)
Block(-6,-24,7,1:1)
Block(-6,-23,-8,1:1)
Block(-6,-23,-7,1:1)
Block(-6,-23,-6,1:1)
Block(-6,-23,-5,1:1)
Block(-6,-23,-4,1:1)
Block(-6,-23,-3,1:1)
Block(-6,-23,-2,1:1)
Block(-6,-23,-1,1:3)
Block(-6,-23,0,1:3)
Block(-6,-23,1,1:3)
Block(-6,-23,2,1:3)
Block(-6,-23,3,1:3)
Block(-6,-23,4,1:3)
Block(-6,-23,5,1:3)
Block(-6,-23,6,1:3)
Block(-6,-23,7,1:1)
Block(-6,-22,-8,1:1)
Block(-6,-22,-7,1:1)
Block(-6,-22,-6,1:1)
Block(-6,-22,-5,1:1)
Block(-6,-22,-4,1:1)
Block(-6,-22,-3,1:1)
Block(-6,-22,-2,1:1)
Block(-6,-22,-1,1:3)
Block(-6,-22,0,1:3)
Block(-6,-22,1,1:3)
Block(-6,-22,2,1:3)
Block(-6,-22,3,1:3)
Block(-6,-22,4,1:3)
Block(-6,-22,5,1:3)
Block(-6,-22,6,1:3)
Block(-6,-22,7,1:3)
Block(-6,-21,-8,1:1)
Block(-6,-21,-7,1:1)
Block(-6,-21,-6,1:1)
Block(-6,-21,-5,1:1)
Block(-6,-21,-4,1:1)
Block(-6,-21,-3,1:1)
Block(-6,-21,-2,1:3)
Block(-6,-21,-1,1:3)
Block(-6,-21,0,1:3)
Block(-6,-21,1,1:3)
Block(-6,-21,2,1:3)
Block(-6,-21,3,1:3)
Block(-6,-21,4,1:3)
Block(-6,-21,5,1:3)
Block(-6,-21,6,1:3)
Block(-6,-21,7,1:3)
Block(-6,-20,-8,1:1)
Block(-6,-20,-7,1:1)
Block(-6,-20,-6,1:1)
Block(-6,-20,-5,1:1)
Block(-6,-20,-4,1:1)
Block(-6,-20,-3,1:3)
Block(-6,-20,-2,1:3)
Block(-6,-20,-1,1:3)
Block(-6,-20,0,1:3)
Block(-6,-20,1,1:3)
Block(-6,-20,2,1:3)
Block(-6,-20,3,1:3)
Block(-6,-20,4,1:3)
Block(-6,-20,5,1:3)
Block(-6,-20,6,1:3)
Block(-6,-20,7,1:3)
Block(-6,-19,-8,1:1)
Block(-6,-19,-7,1:1)
Block(-6,-19,-6,1:1)
Block(-6,-19,-5,1:1)
Block(-6,-19,-4,1:1)
Block(-6,-19,-3,1:3)
Block(-6,-19,-2,1:3)
Block(-6,-19,-1,1:3)
Block(-6,-19,0,1:3)
Block(-6,-19,1,1:3)
Block(-6,-19,2,1:3)
Block(-6,-19,3,1:3)
Block(-6,-19,4,1:3)
Block(-6,-19,5,1:3)
Block(-6,-19,6,1:3)
Block(-6,-19,7,1:3)
Block(-6,-18,-8,1:1)
Block(-6,-18,-7,1:1)
Block(-6,-18,-6,1:1)
Block(-6,-18,-5,1:1)
Block(-6,-18,-4,1:1)
Block(-6,-18,-3,1:3)
Block(-6,-18,-2,1:3)
Block(-6,-18,-1,1:3)
Block(-6,-18,0,1:3)
Block(-6,-18,1,1:3)
Block(-6,-18,2,1:3)
Block(-6,-18,3,1:3)
Block(-6,-18,4,1:3)
Block(-6,-18,5,1:3)
Block(-6,-18,6,1:3)
Block(-6,-18,7,1:3)
Block(-6,-17,-8,1:3)
Block(-6,-17,-7,1:3)
Block(-6,-17,-6,1:1)
Block(-6,-17,-5,1:1)
Block(-6,-17,-4,1:3)
Block(-6,-17,-3,1:3)
Block(-6,-17,-2,1:3)
Block(-6,-17,-1,1:3)
Block(-6,-17,0,1:3)
Block(-6,-17,1,1:3)
Block(-6,-17,2,1:3)
Block(-6,-17,3,1:3)
Block(-6,-17,4,1:3)
Block(-6,-17,5,1:3)
Block(-6,-17,6,1:3)
Block(-6,-17,7,1:3)
Block(-6,-16,-8,1:3)
Block(-6,-16,-7,1:3)
Block(-6,-16,-6,1:3)
Block(-6,-16,-5,1:3)
Block(-6,-16,-4,1:3)
Block(-6,-16,-3,1:3)
Block(-6,-16,-2,1:3)
Block(-6,-16,-1,1:3)
Block(-6,-16,0,1:3)
Block(-6,-16,1,1:3)
Block(-6,-16,2,1:3)
Block(-6,-16,3,1:3)
Block(-6,-16,4,1:3)
Block(-6,-16,5,1:3)
Block(-6,-16,6,1:3)
Block(-6,-16,7,1:3)
Block(-6,-15,-8,1:3)
Block(-6,-15,-7,1:3)
Block(-6,-15,-6,1:3)
Block(-6,-15,-5,1:3)
Block(-6,-15,-4,1:3)
Block(-6,-15,-3,1:3)
Block(-6,-15,-2,1:3)
Block(-6,-15,-1,1:3)
Block(-6,-15,0,1:3)
Block(-6,-15,1,1:3)
Block(-6,-15,2,1:3)
Block(-6,-15,3,1:3)
Block(-6,-15,4,1:3)
Block(-6,-15,5,1:3)
Block(-6,-15,6,1:3)
Block(-6,-15,7,1:3)
Block(-6,-14,-8,1:3)
Block(-6,-14,-7,1:3)
Block(-6,-14,-6,1:3)
Block(-6,-14,-5,1:3)
Block(-6,-14,-4,1:3)
Block(-6,-14,-3,1:3)
Block(-6,-14,-2,1:3)
Block(-6,-14,-1,1:3)
Block(-6,-14,0,1:3)
Block(-6,-14,1,1:3)
Block(-6,-14,2,1:3)
Block(-6,-14,3,1:3)
Block(-6,-14,4,1:3)
Block(-6,-14,5,1:3)
Block(-6,-14,6,1:3)
Block(-6,-14,7,1:3)
Block(-6,-13,-8,1:3)
Block(-6,-13,-7,1:3)
Block(-6,-13,-6,1:3)
Block(-6,-13,-5,1:3)
Block(-6,-13,-4,1:3)
Block(-6,-13,-3,1:3)
Block(-6,-13,-2,1:3)
Block(-6,-13,-1,1:3)
Block(-6,-13,0,1:3)
Block(-6,-13,1,1:3)
Block(-6,-13,2,1:3)
Block(-6,-13,3,1:3)
Block(-6,-13,4,1:3)
Block(-6,-13,5,1:3)
Block(-6,-13,6,1:3)
Block(-6,-13,7,1:3)
Block(-6,-12,-8,1:3)
Block(-6,-12,-7,1:3)
Block(-6,-12,-6,1:3)
Block(-6,-12,-5,1:3)
Block(-6,-12,-4,1:3)
Block(-6,-12,-3,1:3)
Block(-6,-12,-2,1:3)
Block(-6,-12,-1,1:3)
Block(-6,-12,0,1:3)
Block(-6,-12,1,1:3)
Block(-6,-12,2,1:3)
Block(-6,-12,3,1:3)
Block(-6,-12,4,1:3)
Block(-6,-12,5,1:3)
Block(-6,-12,6,1:3)
Block(-6,-12,7,1:3)
Block(-6,-11,-8,1:3)
Block(-6,-11,-7,1:3)
Block(-6,-11,-6,1:3)
Block(-6,-11,-5,1:3)
Block(-6,-11,-4,1:3)
Block(-6,-11,-3,1:3)
Block(-6,-11,-2,1:3)
Block(-6,-11,-1,1:3)
Block(-6,-11,0,1:3)
Block(-6,-11,1,1:3)
Block(-6,-11,2,1:1)
Block(-6,-11,3,1:3)
Block(-6,-11,4,1:3)
Block(-6,-11,5,1:3)
Block(-6,-11,6,1:3)
Block(-6,-11,7,1:3)
Block(-6,-10,-8,1:3)
Block(-6,-10,-7,1:3)
Block(-6,-10,-6,1:3)
Block(-6,-10,-5,1:3)
Block(-6,-10,-4,1:3)
Block(-6,-10,-3,1:3)
Block(-6,-10,-2,1:3)
Block(-6,-10,-1,1:3)
Block(-6,-10,0,1:3)
Block(-6,-10,1,1:1)
Block(-6,-10,2,1:1)
Block(-6,-10,3,1:3)
Block(-6,-10,4,1:3)
Block(-6,-10,5,1:3)
Block(-6,-10,6,1:3)
Block(-6,-10,7,1:3)
Block(-6,-9,-8,1:3)
Block(-6,-9,-7,1:3)
Block(-6,-9,-6,1:3)
Block(-6,-9,-5,1:3)
Block(-6,-9,-4,1:3)
Block(-6,-9,-3,1:3)
Block(-6,-9,-2,1:3)
Block(-6,-9,-1,1:3)
Block(-6,-9,0,1:3)
Block(-6,-9,1,1:3)
Block(-6,-9,2,1:1)
Block(-6,-9,3,1:1)
Block(-6,-9,4,1:1)
Block(-6,-9,5,1:3)
Block(-6,-9,6,1:3)
Block(-6,-9,7,1:3)
Block(-6,-8,-8,1:3)
Block(-6,-8,-7,1:3)
Block(-6,-8,-6,1:3)
Block(-6,-8,-5,1:3)
Block(-6,-8,-4,1:3)
Block(-6,-8,-3,1:3)
Block(-6,-8,-2,1:3)
Block(-6,-8,-1,1:1)
Block(-6,-8,0,1:3)
Block(-6,-8,1,1:1)
Block(-6,-8,2,1:1)
Block(-6,-8,3,1:1)
Block(-6,-8,4,1:1)
Block(-6,-8,5,1:3)
Block(-6,-8,6,1:3)
Block(-6,-8,7,1:3)
Block(-6,-7,-8,1:3)
Block(-6,-7,-7,1:3)
Block(-6,-7,-6,1:3)
Block(-6,-7,-5,1:3)
Block(-6,-7,-4,1:3)
Block(-6,-7,-3,1:3)
Block(-6,-7,-2,1:1)
Block(-6,-7,-1,1:1)
Block(-6,-7,0,1:1)
Block(-6,-7,1,1:1)
Block(-6,-7,2,1:1)
Block(-6,-7,3,1:1)
Block(-6,-7,4,1:1)
Block(-6,-7,5,1:3)
Block(-6,-7,6,1:3)
Block(-6,-7,7,1:3)
Block(-6,-6,-8,1:3)
Block(-6,-6,-7,1:3)
Block(-6,-6,-6,1:3)
Block(-6,-6,-5,1:3)
Block(-6,-6,-4,1:3)
Block(-6,-6,-3,1:1)
Block(-6,-6,-2,1:1)
Block(-6,-6,-1,1:1)
Block(-6,-6,0,1:1)
Block(-6,-6,1,1:1)
Block(-6,-6,2,1:1)
Block(-6,-6,3,1:1)
Block(-6,-6,4,1:3)
Block(-6,-6,5,1:3)
Block(-6,-6,6,1:3)
Block(-6,-6,7,1:3)
Block(-6,-5,-8,1:3)
Block(-6,-5,-7,1:3)
Block(-6,-5,-6,1:3)
Block(-6,-5,-5,1:3)
Block(-6,-5,-4,1:1)
Block(-6,-5,-3,1:1)
Block(-6,-5,-2,1:1)
Block(-6,-5,-1,1:1)
Block(-6,-5,0,1:1)
Block(-6,-5,1,1:1)
Block(-6,-5,2,1:1)
Block(-6,-5,3,1:1)
Block(-6,-5,4,1:3)
Block(-6,-5,5,1:3)
Block(-6,-5,6,1:3)
Block(-6,-5,7,1:3)
Block(-6,-4,-8,1:3)
Block(-6,-4,-7,1:3)
Block(-6,-4,-6,1:3)
Block(-6,-4,-5,1:1)
Block(-6,-4,-4,1:1)
Block(-6,-4,-3,1:1)
Block(-6,-4,-2,1:1)
Block(-6,-4,-1,1:1)
Block(-6,-4,0,1:1)
Block(-6,-4,1,1:1)
Block(-6,-4,2,1:1)
Block(-6,-4,3,1:1)
Block(-6,-4,4,1:3)
Block(-6,-4,5,1:3)
Block(-6,-4,6,1:3)
Block(-6,-4,7,1:1)
Block(-6,-3,-8,1:1)
Block(-6,-3,-7,1:1)
Block(-6,-3,-6,1:1)
Block(-6,-3,-5,1:1)
Block(-6,-3,-4,1:1)
Block(-6,-3,-3,1:1)
Block(-6,-3,-2,1:1)
Block(-6,-3,-1,1:1)
Block(-6,-3,0,1:1)
Block(-6,-3,1,1:1)
Block(-6,-3,2,1:1)
Block(-6,-3,3,1:1)
Block(-6,-3,4,1:3)
Block(-6,-3,5,1:3)
Block(-6,-3,6,1:1)
Block(-6,-3,7,1:1)
Block(-6,-2,-8,1:1)
Block(-6,-2,-7,1:1)
Block(-6,-2,-6,1:1)
Block(-6,-2,-5,1:1)
Block(-6,-2,-4,1:1)
Block(-6,-2,-3,1:1)
Block(-6,-2,-2,1:1)
Block(-6,-2,-1,1:1)
Block(-6,-2,0,1:1)
Block(-6,-2,1,1:1)
Block(-6,-2,2,1:1)
Block(-6,-2,3,1:3)
Block(-6,-2,4,1:3)
Block(-6,-2,5,1:1)
Block(-6,-2,6,1:1)
Block(-6,-2,7,1:1)
Block(-6,-1,-8,1:1)
Block(-6,-1,-7,1:1)
Block(-6,-1,-6,1:1)
Block(-6,-1,-5,1:1)
Block(-6,-1,-4,1:1)
Block(-6,-1,-3,1:1)
Block(-6,-1,-2,1:1)
Block(-6,-1,-1,1:1)
Block(-6,-1,0,1:1)
Block(-6,-1,1,1:1)
Block(-6,-1,2,1:1)
Block(-6,-1,3,1:3)
Block(-6,-1,4,1:1)
Block(-6,-1,5,1:1)
Block(-6,-1,6,1:1)
Block(-6,-1,7,1:1)
Block(-6,0,-8,1:1)
Block(-6,0,-7,1:1)
Block(-6,0,-6,1:1)
Block(-6,0,-5,1:1)
Block(-6,0,-4,1:1)
Block(-6,0,-3,1:1)
Block(-6,0,-2,1:1)
Block(-6,0,-1,1:1)
Block(-6,0,0,1:1)
Block(-6,0,1,1:1)
Block(-6,0,2,1:1)
Block(-6,0,3,1:1)
Block(-6,0,4,1:1)
Block(-6,0,5,1:1)
Block(-6,0,6,1:1)
Block(-6,0,7,1:1)
Block(-6,1,-8,1:1)
Block(-6,1,-7,1:1)
Block(-6,1,-6,1:1)
Block(-6,1,-5,1:1)
Block(-6,1,-4,1:1)
Block(-6,1,-3,1:1)
Block(-6,1,-2,1:1)
Block(-6,1,-1,1:1)
Block(-6,1,0,1:1)
Block(-6,1,1,1:1)
Block(-6,1,2,1:1)
Block(-6,1,3,1:3)
Block(-6,1,4,1:1)
Block(-6,1,5,1:1)
Block(-6,1,6,1:1)
Block(-6,1,7,1:1)
Block(-6,2,-8,1:1)
Block(-6,2,-7,1:1)
Block(-6,2,-6,1:1)
Block(-6,2,-5,1:1)
Block(-6,2,-4,1:1)
Block(-6,2,-3,1:1)
Block(-6,2,-2,1:1)
Block(-6,2,-1,1:1)
Block(-6,2,0,1:1)
Block(-6,2,1,1:1)
Block(-6,2,2,1:3)
Block(-6,2,3,1:3)
Block(-6,2,4,1:1)
Block(-6,2,5,1:1)
Block(-6,2,6,1:1)
Block(-6,2,7,1:1)
Block(-6,3,-8,1:1)
Block(-6,3,-7,1:1)
Block(-6,3,-6,1:1)
Block(-6,3,-5,1:1)
Block(-6,3,-4,1:1)
Block(-6,3,-3,1:1)
Block(-6,3,-2,1:1)
Block(-6,3,-1,1:1)
Block(-6,3,0,1:1)
Block(-6,3,1,1:1)
Block(-6,3,2,1:3)
Block(-6,3,3,1:1)
Block(-6,3,4,1:1)
Block(-6,3,5,1:1)
Block(-6,3,6,1:1)
Block(-6,3,7,1:1)
Block(-6,4,-8,1:1)
Block(-6,4,-7,1:1)
Block(-6,4,-6,1:1)
Block(-6,4,-5,1:1)
Block(-6,4,-4,1:1)
Block(-6,4,-3,1:1)
Block(-6,4,-2,1:1)
Block(-6,4,-1,1:1)
Block(-6,4,0,1:1)
Block(-6,4,1,1:1)
Block(-6,4,2,1:1)
Block(-6,4,3,1:1)
Block(-6,4,4,1:1)
Block(-6,4,5,1:1)
Block(-6,4,6,1:1)
Block(-6,4,7,1:1)
Block(-6,5,-8,1:1)
Block(-6,5,-7,1:1)
Block(-6,5,-6,1:1)
Block(-6,5,-5,1:1)
Block(-6,5,-4,1:1)
Block(-6,5,-3,1:1)
Block(-6,5,-2,1:1)
Block(-6,5,-1,1:1)
Block(-6,5,0,1:1)
Block(-6,5,1,1:1)
Block(-6,5,2,1:1)
Block(-6,5,3,1:1)
Block(-6,5,4,1:1)
Block(-6,5,5,1:1)
Block(-6,5,6,1:1)
Block(-6,5,7,1:3)
Block(-6,6,-8,1:1)
Block(-6,6,-7,1:1)
Block(-6,6,-6,1:1)
Block(-6,6,-5,1:1)
Block(-6,6,-4,1:1)
Block(-6,6,-3,1:1)
Block(-6,6,-2,1:1)
Block(-6,6,-1,1:1)
Block(-6,6,0,1:1)
Block(-6,6,1,1:1)
Block(-6,6,2,1:1)
Block(-6,6,3,1:1)
Block(-6,6,4,1:1)
Block(-6,6,5,1:3)
Block(-6,6,6,1:3)
Block(-6,6,7,1:3)
Block(-6,7,-8,1:1)
Block(-6,7,-7,1:1)
Block(-6,7,-6,1:1)
Block(-6,7,-5,1:1)
Block(-6,7,-4,1:1)
Block(-6,7,-3,1:1)
Block(-6,7,-2,1:1)
Block(-6,7,-1,1:1)
Block(-6,7,0,1:1)
Block(-6,7,1,1:3)
Block(-6,7,2,1:1)
Block(-6,7,3,1:3)
Block(-6,7,4,1:3)
Block(-6,7,5,1:3)
Block(-6,7,6,1:3)
Block(-6,7,7,1:3)
Block(-6,8,-8,1:1)
Block(-6,8,-7,1:1)
Block(-6,8,-6,1:1)
Block(-6,8,-5,1:1)
Block(-6,8,-4,1:1)
Block(-6,8,-3,1:1)
Block(-6,8,-2,1:1)
Block(-6,8,-1,1:1)
Block(-6,8,0,1:3)
Block(-6,8,1,1:3)
Block(-6,8,2,1:3)
Block(-6,8,3,1:3)
Block(-6,8,4,1:3)
Block(-6,8,5,1:3)
Block(-6,8,6,1:3)
Block(-6,8,7,1:3)
Block(-6,9,-8,1:3)
Block(-6,9,-7,1:3)
Block(-6,9,-6,1:3)
Block(-6,9,-5,1:1)
Block(-6,9,-4,1:1)
Block(-6,9,-3,1:1)
Block(-6,9,-2,1:1)
Block(-6,9,-1,1:3)
Block(-6,9,0,1:3)
Block(-6,9,1,1:3)
Block(-6,9,2,1:3)
Block(-6,9,3,1:3)
Block(-6,9,4,1:3)
Block(-6,9,5,1:3)
Block(-6,9,6,1:3)
Block(-6,9,7,1:3)
Block(-6,10,-8,1:3)
Block(-6,10,-7,1:3)
Block(-6,10,-6,1:3)
Block(-6,10,-5,1:3)
Block(-6,10,-4,1:1)
Block(-6,10,-3,1:1)
Block(-6,10,-2,1:1)
Block(-6,10,-1,1:3)
Block(-6,10,0,1:3)
Block(-6,10,1,1:3)
Block(-6,10,2,1:3)
Block(-6,10,3,1:3)
Block(-6,10,4,1:3)
Block(-6,10,5,1:3)
Block(-6,10,6,1:3)
Block(-6,10,7,1:3)
Block(-6,11,-8,1:3)
Block(-6,11,-7,1:3)
Block(-6,11,-6,1:3)
Block(-6,11,-5,1:1)
Block(-6,11,-4,1:1)
Block(-6,11,-3,1:1)
Block(-6,11,-2,1:1)
Block(-6,11,-1,1:1)
Block(-6,11,0,1:3)
Block(-6,11,1,1:3)
Block(-6,11,2,1:3)
Block(-6,11,3,1:3)
Block(-6,11,4,1:3)
Block(-6,11,5,1:3)
Block(-6,11,6,1:3)
Block(-6,11,7,1:3)
Block(-6,12,-8,1:3)
Block(-6,12,-7,1:3)
Block(-6,12,-6,1:3)
Block(-6,12,-5,1:1)
Block(-6,12,-4,1:1)
Block(-6,12,-3,1:1)
Block(-6,12,-2,1:1)
Block(-6,12,-1,1:1)
Block(-6,12,0,1:3)
Block(-6,12,1,1:3)
Block(-6,12,2,1:3)
Block(-6,12,3,1:3)
Block(-6,12,4,1:3)
Block(-6,12,5,1:3)
Block(-6,12,6,1:3)
Block(-6,12,7,1:3)
Block(-6,13,-8,1:3)
Block(-6,13,-7,1:3)
Block(-6,13,-6,1:3)
Block(-6,13,-5,1:1)
Block(-6,13,-4,1:1)
Block(-6,13,-3,1:1)
Block(-6,13,-2,1:1)
Block(-6,13,-1,1:3)
Block(-6,13,0,1:3)
Block(-6,13,1,1:3)
Block(-6,13,2,1:3)
Block(-6,13,3,1:3)
Block(-6,13,4,1:3)
Block(-6,13,5,1:3)
Block(-6,13,6,1:3)
Block(-6,13,7,1:3)
Block(-6,14,-8,1:3)
Block(-6,14,-7,1:3)
Block(-6,14,-6,1:3)
Block(-6,14,-5,1:1)
Block(-6,14,-4,1:1)
Block(-6,14,-3,1:1)
Block(-6,14,-2,1:1)
Block(-6,14,-1,1:1)
Block(-6,14,0,1:3)
Block(-6,14,1,1:3)
Block(-6,14,2,1:3)
Block(-6,14,3,1:3)
Block(-6,14,4,1:3)
Block(-6,14,5,1:3)
Block(-6,14,6,1:3)
Block(-6,14,7,1:3)
Block(-6,15,-8,1:3)
Block(-6,15,-7,1:3)
Block(-6,15,-6,1:1)
Block(-6,15,-5,1:1)
Block(-6,15,-4,1:1)
Block(-6,15,-3,1:1)
Block(-6,15,-2,1:1)
Block(-6,15,-1,1:3)
Block(-6,15,0,1:3)
Block(-6,15,1,1:3)
Block(-6,15,2,1:3)
Block(-6,15,3,1:3)
Block(-6,15,4,1:3)
Block(-6,15,5,1:3)
Block(-6,15,6,1:3)
Block(-6,15,7,1:3)
Block(-6,16,-8,1:3)
Block(-6,16,-7,1:3)
Block(-6,16,-6,1:1)
Block(-6,16,-5,1:1)
Block(-6,16,-4,1:1)
Block(-6,16,-3,1:1)
Block(-6,16,-2,1:1)
Block(-6,16,-1,1:3)
Block(-6,16,0,1:3)
Block(-6,16,1,1:3)
Block(-6,16,2,1:3)
Block(-6,16,3,1:3)
Block(-6,16,4,1:3)
Block(-6,16,5,1:3)
Block(-6,16,6,1:3)
Block(-6,16,7,1:3)
Block(-6,17,-8,1:3)
Block(-6,17,-7,1:1)
Block(-6,17,-6,1:1)
Block(-6,17,-5,1:1)
Block(-6,17,-4,1:1)
Block(-6,17,-3,1:1)
Block(-6,17,-2,1:1)
Block(-6,17,-1,1:3)
Block(-6,17,0,1:3)
Block(-6,17,1,1:3)
Block(-6,17,2,1:3)
Block(-6,17,3,1:3)
Block(-6,17,4,1:3)
Block(-6,17,5,1:3)
Block(-6,17,6,1:3)
Block(-6,17,7,1:3)
Block(-6,18,-8,1:3)
Block(-6,18,-7,1:3)
Block(-6,18,-6,1:1)
Block(-6,18,-5,1:1)
Block(-6,18,-4,1:1)
Block(-6,18,-3,1:1)
Block(-6,18,-2,1:1)
Block(-6,18,-1,1:3)
Block(-6,18,0,1:3)
Block(-6,18,1,1:3)
Block(-6,18,2,1:3)
Block(-6,18,3,1:3)
Block(-6,18,4,1:3)
Block(-6,18,5,1:3)
Block(-6,18,6,1:3)
Block(-6,18,7,1:3)
Block(-6,19,-8,1:3)
Block(-6,19,-7,1:3)
Block(-6,19,-6,1:3)
Block(-6,19,-5,1:1)
Block(-6,19,-4,1:1)
Block(-6,19,-3,1:1)
Block(-6,19,-2,1:1)
Block(-6,19,-1,1:3)
Block(-6,19,0,1:3)
Block(-6,19,1,1:3)
Block(-6,19,2,1:3)
Block(-6,19,3,1:3)
Block(-6,19,4,1:3)
Block(-6,19,5,1:3)
Block(-6,19,6,1:3)
Block(-6,19,7,1:3)
Block(-6,20,-8,1:3)
Block(-6,20,-7,1:3)
Block(-6,20,-6,1:3)
Block(-6,20,-5,1:3)
Block(-6,20,-4,1:1)
Block(-6,20,-3,1:1)
Block(-6,20,-2,1:1)
Block(-6,20,-1,1:3)
Block(-6,20,0,1:3)
Block(-6,20,1,1:3)
Block(-6,20,2,1:3)
Block(-6,20,3,1:3)
Block(-6,20,4,1:3)
Block(-6,20,5,1:3)
Block(-6,20,6,1:3)
Block(-6,20,7,1:3)
Block(-6,21,-8,1:3)
Block(-6,21,-7,1:3)
Block(-6,21,-6,1:3)
Block(-6,21,-5,1:3)
Block(-6,21,-4,1:3)
Block(-6,21,-3,1:1)
Block(-6,21,-2,1:1)
Block(-6,21,-1,1:1)
Block(-6,21,0,1:3)
Block(-6,21,1,1:3)
Block(-6,21,2,1:3)
Block(-6,21,3,1:3)
Block(-6,21,4,1:3)
Block(-6,21,5,1:3)
Block(-6,21,6,1:3)
Block(-6,21,7,1:3)
Block(-6,22,-8,1:3)
Block(-6,22,-7,1:3)
Block(-6,22,-6,1:3)
Block(-6,22,-5,1:3)
Block(-6,22,-4,1:3)
Block(-6,22,-3,1:3)
Block(-6,22,-2,1:3)
Block(-6,22,-1,1:1)
Block(-6,22,0,1:1)
Block(-6,22,1,1:1)
Block(-6,22,2,1:3)
Block(-6,22,3,1:3)
Block(-6,22,4,1:3)
Block(-6,22,5,1:3)
Block(-6,22,6,1:3)
Block(-6,22,7,1:3)
Block(-6,23,-8,1:3)
Block(-6,23,-7,1:3)
Block(-6,23,-6,1:3)
Block(-6,23,-5,1:3)
Block(-6,23,-4,1:3)
Block(-6,23,-3,1:3)
Block(-6,23,-2,1:3)
Block(-6,23,-1,1:3)
Block(-6,23,0,1:1)
Block(-6,23,1,1:1)
Block(-6,23,2,1:1)
Block(-6,23,3,1:1)
Block(-6,23,4,1:3)
Block(-6,23,5,1:1)
Block(-6,23,6,1:3)
Block(-6,23,7,1:3)
Block(-6,24,-8,1:3)
Block(-6,24,-7,1:3)
Block(-6,24,-6,1:3)
Block(-6,24,-5,1:3)
Block(-6,24,-4,1:3)
Block(-6,24,-3,1:3)
Block(-6,24,-2,1:3)
Block(-6,24,-1,1:3)
Block(-6,24,0,1:3)
Block(-6,24,1,1:1)
Block(-6,24,2,1:1)
Block(-6,24,3,1:1)
Block(-6,24,4,1:1)
Block(-6,24,5,1:1)
Block(-6,24,6,1:3)
Block(-6,24,7,1:3)
Block(-6,25,-8,1:1)
Block(-6,25,-7,1:1)
Block(-6,25,-6,1:3)
Block(-6,25,-5,1:3)
Block(-6,25,-4,1:3)
Block(-6,25,-3,1:3)
Block(-6,25,-2,1:3)
Block(-6,25,-1,1:3)
Block(-6,25,0,1:3)
Block(-6,25,1,1:3)
Block(-6,25,2,1:1)
Block(-6,25,3,1:1)
Block(-6,25,4,1:1)
Block(-6,25,5,1:1)
Block(-6,25,6,1:1)
Block(-6,25,7,1:1)
Block(-6,26,-8,1:1)
Block(-6,26,-7,1:1)
Block(-6,26,-6,1:1)
Block(-6,26,-5,1:3)
Block(-6,26,-4,1:3)
Block(-6,26,-3,1:3)
Block(-6,26,-2,1:3)
Block(-6,26,-1,1:3)
Block(-6,26,0,1:3)
Block(-6,26,1,1:3)
Block(-6,26,2,1:3)
Block(-6,26,3,1:3)
Block(-6,26,4,1:1)
Block(-6,26,5,1:1)
Block(-6,26,6,1:1)
Block(-6,26,7,1:1)
Block(-6,27,-8,1:1)
Block(-6,27,-7,1:1)
Block(-6,27,-6,1:1)
Block(-6,27,-5,1:1)
Block(-6,27,-4,1:3)
Block(-6,27,-3,1:3)
Block(-6,27,-2,1:3)
Block(-6,27,-1,1:3)
Block(-6,27,0,1:3)
Block(-6,27,1,1:3)
Block(-6,27,2,1:3)
Block(-6,27,3,1:3)
Block(-6,27,4,1:3)
Block(-6,27,5,1:1)
Block(-6,27,6,1:1)
Block(-6,27,7,1:1)
Block(-6,28,-8,1:1)
Block(-6,28,-7,1:1)
Block(-6,28,-6,1:1)
Block(-6,28,-5,1:1)
Block(-6,28,-4,1:1)
Block(-6,28,-3,1:3)
Block(-6,28,-2,1:3)
Block(-6,28,-1,1:3)
Block(-6,28,0,1:3)
Block(-6,28,1,1:3)
Block(-6,28,2,1:3)
Block(-6,28,3,1:3)
Block(-6,28,4,1:3)
Block(-6,28,5,1:3)
Block(-6,28,6,1:1)
Block(-6,28,7,1:1)
Block(-6,29,-8,1:1)
Block(-6,29,-7,1:1)
Block(-6,29,-6,1:1)
Block(-6,29,-5,1:1)
Block(-6,29,-4,1:1)
Block(-6,29,-3,1:3)
Block(-6,29,-2,1:3)
Block(-6,29,-1,1:3)
Block(-6,29,0,1:3)
Block(-6,29,1,1:3)
Block(-6,29,2,1:3)
Block(-6,29,3,1:3)
Block(-6,29,4,1:3)
Block(-6,29,5,1:3)
Block(-6,29,6,1:3)
Block(-6,29,7,1:1)
Block(-6,30,-8,1:1)
Block(-6,30,-7,1:1)
Block(-6,30,-6,1:1)
Block(-6,30,-5,1:1)
Block(-6,30,-4,1:1)
Block(-6,30,-3,1:3)
Block(-6,30,-2,1:3)
Block(-6,30,-1,1:3)
Block(-6,30,0,1:3)
Block(-6,30,1,1:3)
Block(-6,30,2,1:3)
Block(-6,30,3,1:3)
Block(-6,30,4,1:3)
Block(-6,30,5,1:3)
Block(-6,30,6,1:3)
Block(-6,30,7,1:3)
Block(-6,31,-8,1:3)
Block(-6,31,-7,1:1)
Block(-6,31,-6,1:1)
Block(-6,31,-5,1:1)
Block(-6,31,-4,1:1)
Block(-6,31,-3,1:3)
Block(-6,31,-2,1:3)
Block(-6,31,-1,1:3)
Block(-6,31,0,1:3)
Block(-6,31,1,1:3)
Block(-6,31,2,1:3)
Block(-6,31,3,1:3)
Block(-6,31,4,1:3)
Block(-6,31,5,1:3)
Block(-6,31,6,1:3)
Block(-6,31,7,1:3)
Block(-6,32,-8,1:3)
Block(-6,32,-7,1:3)
Block(-6,32,-6,1:3)
Block(-6,32,-5,1:3)
Block(-6,32,-4,1:3)
Block(-6,32,-3,1:3)
Block(-6,32,-2,1:3)
Block(-6,32,-1,1:3)
Block(-6,32,0,1:3)
Block(-6,32,1,1:3)
Block(-6,32,2,1:3)
Block(-6,32,3,1:3)
Block(-6,32,4,1:3)
Block(-6,32,5,1:3)
Block(-6,32,6,1:3)
Block(-6,32,7,1:3)
Block(-6,33,-8,1:3)
Block(-6,33,-7,1:3)
Block(-6,33,-6,1:3)
Block(-6,33,-5,1:3)
Block(-6,33,-4,1:3)
Block(-6,33,-3,1:3)
Block(-6,33,-2,1:3)
Block(-6,33,-1,1:3)
Block(-6,33,0,1:3)
Block(-6,33,1,1:3)
Block(-6,33,2,1:3)
Block(-6,33,3,1:1)
Block(-6,33,4,1:1)
Block(-6,33,5,1:1)
Block(-6,33,6,1:1)
Block(-6,33,7,1:3)
Block(-6,34,-8,1:3)
Block(-6,34,-7,1:3)
Block(-6,34,-6,1:3)
Block(-6,34,-5,1:3)
Block(-6,34,-4,1:3)
Block(-6,34,-3,1:3)
Block(-6,34,-2,1:3)
Block(-6,34,-1,1:3)
Block(-6,34,0,1:3)
Block(-6,34,1,1:1)
Block(-6,34,2,1:1)
Block(-6,34,3,1:1)
Block(-6,34,4,1:1)
Block(-6,34,5,1:1)
Block(-6,34,6,1:1)
Block(-6,34,7,1:1)
Block(-6,35,-8,1:3)
Block(-6,35,-7,1:3)
Block(-6,35,-6,1:3)
Block(-6,35,-5,1:3)
Block(-6,35,-4,1:3)
Block(-6,35,-3,1:3)
Block(-6,35,-2,1:3)
Block(-6,35,-1,1:3)
Block(-6,35,0,1:1)
Block(-6,35,1,1:1)
Block(-6,35,2,1:1)
Block(-6,35,3,1:1)
Block(-6,35,4,1:1)
Block(-6,35,5,1:1)
Block(-6,35,6,1:1)
Block(-6,35,7,1:1)
Block(-6,36,-8,1:3)
Block(-6,36,-7,1:3)
Block(-6,36,-6,1:3)
Block(-6,36,-5,1:3)
Block(-6,36,-4,1:3)
Block(-6,36,-3,1:3)
Block(-6,36,-2,1:1)
Block(-6,36,-1,1:1)
Block(-6,36,0,1:1)
Block(-6,36,1,1:1)
Block(-6,36,2,1:1)
Block(-6,36,3,1:1)
Block(-6,36,4,1:1)
Block(-6,36,5,1:1)
Block(-6,36,6,1:1)
Block(-6,36,7,1:1)
Block(-6,37,-8,1:3)
Block(-6,37,-7,1:3)
Block(-6,37,-6,1:3)
Block(-6,37,-5,1:3)
Block(-6,37,-4,1:3)
Block(-6,37,-3,1:1)
Block(-6,37,-2,1:1)
Block(-6,37,-1,1:1)
Block(-6,37,0,1:1)
Block(-6,37,1,1:1)
Block(-6,37,2,1:1)
Block(-6,37,3,1:1)
Block(-6,37,4,1:1)
Block(-6,37,5,1:1)
Block(-6,37,6,1:1)
Block(-6,37,7,1:1)
Block(-6,38,-8,1:3)
Block(-6,38,-7,1:3)
Block(-6,38,-6,1:3)
Block(-6,38,-5,1:3)
Block(-6,38,-4,1:3)
Block(-6,38,-3,1:1)
Block(-6,38,-2,1:1)
Block(-6,38,-1,1:1)
Block(-6,38,0,1:1)
Block(-6,38,1,1:1)
Block(-6,38,2,1:1)
Block(-6,38,3,1:1)
Block(-6,38,4,1:1)
Block(-6,38,5,1:1)
Block(-6,38,6,1:1)
Block(-6,38,7,1:1)
Block(-6,39,-8,1:3)
Block(-6,39,-7,1:3)
Block(-6,39,-6,1:3)
Block(-6,39,-5,1:3)
Block(-6,39,-4,1:1)
Block(-6,39,-3,1:1)
Block(-6,39,-2,1:1)
Block(-6,39,-1,1:1)
Block(-6,39,0,1:1)
Block(-6,39,1,1:1)
Block(-6,39,2,1:3)
Block(-6,39,3,1:3)
Block(-6,39,4,1:3)
Block(-6,39,5,1:3)
Block(-6,39,6,1:3)
Block(-6,39,7,1:3)
Block(-6,40,-8,1:3)
Block(-6,40,-7,1:3)
Block(-6,40,-6,1:3)
Block(-6,40,-5,1:3)
Block(-6,40,-4,1:1)
Block(-6,40,-3,1:1)
Block(-6,40,-2,1:1)
Block(-6,40,-1,1:1)
Block(-6,40,0,1:3)
Block(-6,40,1,1:3)
Block(-6,40,2,1:3)
Block(-6,40,3,1:3)
Block(-6,40,4,1:3)
Block(-6,40,5,1:3)
Block(-6,40,6,1:3)
Block(-6,40,7,1:3)
Block(-6,41,-8,1:3)
Block(-6,41,-7,1:3)
Block(-6,41,-6,1:3)
Block(-6,41,-5,1:3)
Block(-6,41,-4,1:1)
Block(-6,41,-3,1:1)
Block(-6,41,-2,1:1)
Block(-6,41,-1,1:3)
Block(-6,41,0,1:3)
Block(-6,41,1,1:3)
Block(-6,41,2,1:3)
Block(-6,41,3,1:3)
Block(-6,41,4,1:3)
Block(-6,41,5,1:3)
Block(-6,41,6,1:3)
Block(-6,41,7,1:3)
Block(-6,42,-8,1:3)
Block(-6,42,-7,1:3)
Block(-6,42,-6,1:3)
Block(-6,42,-5,1:1)
Block(-6,42,-4,1:1)
Block(-6,42,-3,1:1)
Block(-6,42,-2,1:1)
Block(-6,42,-1,1:3)
Block(-6,42,0,1:3)
Block(-6,42,1,1:3)
Block(-6,42,2,1:3)
Block(-6,42,3,1:3)
Block(-6,42,4,1:3)
Block(-6,42,5,1:3)
Block(-6,42,6,1:3)
Block(-6,42,7,1:3)
Block(-6,43,-8,1:3)
Block(-6,43,-7,1:3)
Block(-6,43,-6,1:3)
Block(-6,43,-5,1:3)
Block(-6,43,-4,1:1)
Block(-6,43,-3,1:1)
Block(-6,43,-2,1:3)
Block(-6,43,-1,1:3)
Block(-6,43,0,1:3)
Block(-6,43,1,1:3)
Block(-6,43,2,1:3)
Block(-6,43,3,1:3)
Block(-6,43,4,1:3)
Block(-6,43,5,1:3)
Block(-6,43,6,1:3)
Block(-6,43,7,1:3)
Block(-6,44,-8,1:3)
Block(-6,44,-7,1:3)
Block(-6,44,-6,1:3)
Block(-6,44,-5,1:1)
Block(-6,44,-4,1:1)
Block(-6,44,-3,1:1)
Block(-6,44,-2,1:3)
Block(-6,44,-1,1:3)
Block(-6,44,0,1:3)
Block(-6,44,1,1:3)
Block(-6,44,2,1:3)
Block(-6,44,3,1:3)
Block(-6,44,4,1:3)
Block(-6,44,5,1:3)
Block(-6,44,6,1:3)
Block(-6,44,7,1:3)
Block(-6,45,-8,1:3)
Block(-6,45,-7,1:3)
Block(-6,45,-6,1:3)
Block(-6,45,-5,1:1)
Block(-6,45,-4,1:1)
Block(-6,45,-3,1:3)
Block(-6,45,-2,1:3)
Block(-6,45,-1,1:3)
Block(-6,45,0,1:3)
Block(-6,45,1,1:3)
Block(-6,45,2,1:3)
Block(-6,45,3,1:3)
Block(-6,45,4,1:3)
Block(-6,45,5,1:3)
Block(-6,45,6,1:3)
Block(-6,45,7,1:3)
Block(-6,46,-8,1:3)
Block(-6,46,-7,1:3)
Block(-6,46,-6,1:3)
Block(-6,46,-5,1:1)
Block(-6,46,-4,1:1)
Block(-6,46,-3,1:3)
Block(-6,46,-2,1:3)
Block(-6,46,-1,1:3)
Block(-6,46,0,1:3)
Block(-6,46,1,1:3)
Block(-6,46,2,1:3)
Block(-6,46,3,1:3)
Block(-6,46,4,1:3)
Block(-6,46,5,1:3)
Block(-6,46,6,1:3)
Block(-6,46,7,1:3)
Block(-6,47,-8,1:3)
Block(-6,47,-7,1:3)
Block(-6,47,-6,1:1)
Block(-6,47,-5,1:1)
Block(-6,47,-4,1:1)
Block(-6,47,-3,1:3)
Block(-6,47,-2,1:3)
Block(-6,47,-1,1:3)
Block(-6,47,0,1:3)
Block(-6,47,1,1:3)
Block(-6,47,2,1:3)
Block(-6,47,3,1:3)
Block(-6,47,4,1:3)
Block(-6,47,5,1:3)
Block(-6,47,6,1:3)
Block(-6,47,7,1:3)
Block(-5,-33,-8,1:1)
Block(-5,-33,-7,1:1)
Block(-5,-33,-6,1:1)
Block(-5,-33,-5,1:1)
Block(-5,-33,-4,1:1)
Block(-5,-33,-3,1:1)
Block(-5,-33,-2,1:1)
Block(-5,-33,-1,1:1)
Block(-5,-33,0,1:1)
Block(-5,-33,1,1:1)
Block(-5,-33,2,1:1)
Block(-5,-33,3,1:1)
Block(-5,-33,4,1:1)
Block(-5,-33,5,1:1)
Block(-5,-33,6,1:1)
Block(-5,-33,7,1:1)
Block(-5,-32,-8,1:1)
Block(-5,-32,-7,1:1)
Block(-5,-32,-6,1:1)
Block(-5,-32,-5,1:1)
Block(-5,-32,-4,1:1)
Block(-5,-32,-3,1:1)
Block(-5,-32,-2,1:1)
Block(-5,-32,-1,1:1)
Block(-5,-32,0,1:1)
Block(-5,-32,1,1:1)
Block(-5,-32,2,1:1)
Block(-5,-32,3,1:1)
Block(-5,-32,4,1:1)
Block(-5,-32,5,1:1)
Block(-5,-32,6,1:1)
Block(-5,-32,7,1:1)
Block(-5,-31,-8,1:1)
Block(-5,-31,-7,1:1)
Block(-5,-31,-6,1:1)
Block(-5,-31,-5,1:1)
Block(-5,-31,-4,1:1)
Block(-5,-31,-3,1:1)
Block(-5,-31,-2,1:1)
Block(-5,-31,-1,1:1)
Block(-5,-31,0,1:1)
Block(-5,-31,1,1:1)
Block(-5,-31,2,1:1)
Block(-5,-31,3,1:1)
Block(-5,-31,4,1:1)
Block(-5,-31,5,1:1)
Block(-5,-31,6,1:1)
Block(-5,-31,7,1:1)
Block(-5,-30,-8,1:1)
Block(-5,-30,-7,1:1)
Block(-5,-30,-6,1:1)
Block(-5,-30,-5,1:1)
Block(-5,-30,-4,1:1)
Block(-5,-30,-3,1:1)
Block(-5,-30,-2,1:1)
Block(-5,-30,-1,1:1)
Block(-5,-30,0,1:1)
Block(-5,-30,1,1:1)
Block(-5,-30,2,1:1)
Block(-5,-30,3,1:1)
Block(-5,-30,4,1:1)
Block(-5,-30,5,1:1)
Block(-5,-30,6,1:1)
Block(-5,-30,7,1:1)
Block(-5,-29,-8,1:1)
Block(-5,-29,-7,1:1)
Block(-5,-29,-6,1:1)
Block(-5,-29,-5,1:1)
Block(-5,-29,-4,1:1)
Block(-5,-29,-3,1:1)
Block(-5,-29,-2,1:1)
Block(-5,-29,-1,1:1)
Block(-5,-29,0,1:1)
Block(-5,-29,1,1:1)
Block(-5,-29,2,1:1)
Block(-5,-29,3,1:1)
Block(-5,-29,4,1:1)
Block(-5,-29,5,1:1)
Block(-5,-29,6,1:1)
Block(-5,-29,7,1:3)
Block(-5,-28,-8,1:1)
Block(-5,-28,-7,1:1)
Block(-5,-28,-6,1:1)
Block(-5,-28,-5,1:1)
Block(-5,-28,-4,1:1)
Block(-5,-28,-3,1:1)
Block(-5,-28,-2,1:1)
Block(-5,-28,-1,1:1)
Block(-5,-28,0,1:1)
Block(-5,-28,1,1:1)
Block(-5,-28,2,1:1)
Block(-5,-28,3,1:1)
Block(-5,-28,4,1:1)
Block(-5,-28,5,1:1)
Block(-5,-28,6,1:1)
Block(-5,-28,7,1:3)
Block(-5,-27,-8,1:1)
Block(-5,-27,-7,1:1)
Block(-5,-27,-6,1:1)
Block(-5,-27,-5,1:1)
Block(-5,-27,-4,1:1)
Block(-5,-27,-3,1:1)
Block(-5,-27,-2,1:1)
Block(-5,-27,-1,1:1)
Block(-5,-27,0,1:1)
Block(-5,-27,1,1:1)
Block(-5,-27,2,1:1)
Block(-5,-27,3,1:1)
Block(-5,-27,4,1:1)
Block(-5,-27,5,1:1)
Block(-5,-27,6,1:1)
Block(-5,-27,7,1:1)
Block(-5,-26,-8,1:1)
Block(-5,-26,-7,1:1)
Block(-5,-26,-6,1:1)
Block(-5,-26,-5,1:1)
Block(-5,-26,-4,1:1)
Block(-5,-26,-3,1:1)
Block(-5,-26,-2,1:1)
Block(-5,-26,-1,1:1)
Block(-5,-26,0,1:1)
Block(-5,-26,1,1:3)
Block(-5,-26,2,1:1)
Block(-5,-26,3,1:1)
Block(-5,-26,4,1:1)
Block(-5,-26,5,1:1)
Block(-5,-26,6,1:1)
Block(-5,-26,7,1:1)
Block(-5,-25,-8,1:1)
Block(-5,-25,-7,1:1)
Block(-5,-25,-6,1:1)
Block(-5,-25,-5,1:1)
Block(-5,-25,-4,1:1)
Block(-5,-25,-3,1:1)
Block(-5,-25,-2,1:1)
Block(-5,-25,-1,1:1)
Block(-5,-25,0,1:3)
Block(-5,-25,1,1:3)
Block(-5,-25,2,1:3)
Block(-5,-25,3,1:3)
Block(-5,-25,4,1:1)
Block(-5,-25,5,1:1)
Block(-5,-25,6,1:1)
Block(-5,-25,7,1:1)
Block(-5,-24,-8,1:1)
Block(-5,-24,-7,1:1)
Block(-5,-24,-6,1:1)
Block(-5,-24,-5,1:1)
Block(-5,-24,-4,1:1)
Block(-5,-24,-3,1:1)
Block(-5,-24,-2,1:1)
Block(-5,-24,-1,1:1)
Block(-5,-24,0,1:3)
Block(-5,-24,1,1:3)
Block(-5,-24,2,1:3)
Block(-5,-24,3,1:3)
Block(-5,-24,4,1:3)
Block(-5,-24,5,1:1)
Block(-5,-24,6,1:1)
Block(-5,-24,7,1:1)
Block(-5,-23,-8,1:1)
Block(-5,-23,-7,1:1)
Block(-5,-23,-6,1:1)
Block(-5,-23,-5,1:1)
Block(-5,-23,-4,1:1)
Block(-5,-23,-3,1:1)
Block(-5,-23,-2,1:1)
Block(-5,-23,-1,1:3)
Block(-5,-23,0,1:3)
Block(-5,-23,1,1:3)
Block(-5,-23,2,1:3)
Block(-5,-23,3,1:3)
Block(-5,-23,4,1:3)
Block(-5,-23,5,1:3)
Block(-5,-23,6,1:3)
Block(-5,-23,7,1:1)
Block(-5,-22,-8,1:1)
Block(-5,-22,-7,1:1)
Block(-5,-22,-6,1:1)
Block(-5,-22,-5,1:1)
Block(-5,-22,-4,1:1)
Block(-5,-22,-3,1:1)
Block(-5,-22,-2,1:3)
Block(-5,-22,-1,1:3)
Block(-5,-22,0,1:3)
Block(-5,-22,1,1:3)
Block(-5,-22,2,1:3)
Block(-5,-22,3,1:3)
Block(-5,-22,4,1:3)
Block(-5,-22,5,1:3)
Block(-5,-22,6,1:3)
Block(-5,-22,7,1:3)
Block(-5,-21,-8,1:1)
Block(-5,-21,-7,1:1)
Block(-5,-21,-6,1:1)
Block(-5,-21,-5,1:1)
Block(-5,-21,-4,1:1)
Block(-5,-21,-3,1:1)
Block(-5,-21,-2,1:3)
Block(-5,-21,-1,1:3)
Block(-5,-21,0,1:3)
Block(-5,-21,1,1:3)
Block(-5,-21,2,1:3)
Block(-5,-21,3,1:3)
Block(-5,-21,4,1:3)
Block(-5,-21,5,1:3)
Block(-5,-21,6,1:3)
Block(-5,-21,7,1:3)
Block(-5,-20,-8,1:1)
Block(-5,-20,-7,1:1)
Block(-5,-20,-6,1:1)
Block(-5,-20,-5,1:1)
Block(-5,-20,-4,1:1)
Block(-5,-20,-3,1:1)
Block(-5,-20,-2,1:3)
Block(-5,-20,-1,1:3)
Block(-5,-20,0,1:3)
Block(-5,-20,1,1:3)
Block(-5,-20,2,1:3)
Block(-5,-20,3,1:3)
Block(-5,-20,4,1:3)
Block(-5,-20,5,1:3)
Block(-5,-20,6,1:3)
Block(-5,-20,7,1:3)
Block(-5,-19,-8,1:1)
Block(-5,-19,-7,1:1)
Block(-5,-19,-6,1:1)
Block(-5,-19,-5,1:1)
Block(-5,-19,-4,1:1)
Block(-5,-19,-3,1:3)
Block(-5,-19,-2,1:3)
Block(-5,-19,-1,1:3)
Block(-5,-19,0,1:3)
Block(-5,-19,1,1:3)
Block(-5,-19,2,1:3)
Block(-5,-19,3,1:3)
Block(-5,-19,4,1:3)
Block(-5,-19,5,1:3)
Block(-5,-19,6,1:3)
Block(-5,-19,7,1:3)
Block(-5,-18,-8,1:1)
Block(-5,-18,-7,1:1)
Block(-5,-18,-6,1:1)
Block(-5,-18,-5,1:1)
Block(-5,-18,-4,1:3)
Block(-5,-18,-3,1:3)
Block(-5,-18,-2,1:3)
Block(-5,-18,-1,1:3)
Block(-5,-18,0,1:3)
Block(-5,-18,1,1:3)
Block(-5,-18,2,1:3)
Block(-5,-18,3,1:3)
Block(-5,-18,4,1:3)
Block(-5,-18,5,1:3)
Block(-5,-18,6,1:3)
Block(-5,-18,7,1:3)
Block(-5,-17,-8,1:1)
Block(-5,-17,-7,1:1)
Block(-5,-17,-6,1:1)
Block(-5,-17,-5,1:1)
Block(-5,-17,-4,1:3)
Block(-5,-17,-3,1:3)
Block(-5,-17,-2,1:3)
Block(-5,-17,-1,1:3)
Block(-5,-17,0,1:3)
Block(-5,-17,1,1:3)
Block(-5,-17,2,1:3)
Block(-5,-17,3,1:3)
Block(-5,-17,4,1:3)
Block(-5,-17,5,1:3)
Block(-5,-17,6,1:3)
Block(-5,-17,7,1:3)
Block(-5,-16,-8,1:3)
Block(-5,-16,-7,1:3)
Block(-5,-16,-6,1:3)
Block(-5,-16,-5,1:1)
Block(-5,-16,-4,1:3)
Block(-5,-16,-3,1:3)
Block(-5,-16,-2,1:3)
Block(-5,-16,-1,1:3)
Block(-5,-16,0,1:3)
Block(-5,-16,1,1:3)
Block(-5,-16,2,1:3)
Block(-5,-16,3,1:3)
Block(-5,-16,4,1:3)
Block(-5,-16,5,1:3)
Block(-5,-16,6,1:3)
Block(-5,-16,7,1:3)
Block(-5,-15,-8,1:3)
Block(-5,-15,-7,1:3)
Block(-5,-15,-6,1:3)
Block(-5,-15,-5,1:3)
Block(-5,-15,-4,1:3)
Block(-5,-15,-3,1:3)
Block(-5,-15,-2,1:3)
Block(-5,-15,-1,1:3)
Block(-5,-15,0,1:3)
Block(-5,-15,1,1:3)
Block(-5,-15,2,1:3)
Block(-5,-15,3,1:3)
Block(-5,-15,4,1:3)
Block(-5,-15,5,1:3)
Block(-5,-15,6,1:3)
Block(-5,-15,7,1:3)
Block(-5,-14,-8,1:3)
Block(-5,-14,-7,1:3)
Block(-5,-14,-6,1:3)
Block(-5,-14,-5,1:3)
Block(-5,-14,-4,1:3)
Block(-5,-14,-3,1:3)
Block(-5,-14,-2,1:3)
Block(-5,-14,-1,1:3)
Block(-5,-14,0,1:3)
Block(-5,-14,1,1:3)
Block(-5,-14,2,1:3)
Block(-5,-14,3,1:3)
Block(-5,-14,4,1:3)
Block(-5,-14,5,1:3)
Block(-5,-14,6,1:3)
Block(-5,-14,7,1:3)
Block(-5,-13,-8,1:3)
Block(-5,-13,-7,1:3)
Block(-5,-13,-6,1:3)
Block(-5,-13,-5,1:3)
Block(-5,-13,-4,1:3)
Block(-5,-13,-3,1:3)
Block(-5,-13,-2,1:3)
Block(-5,-13,-1,1:3)
Block(-5,-13,0,1:3)
Block(-5,-13,1,1:3)
Block(-5,-13,2,1:3)
Block(-5,-13,3,1:3)
Block(-5,-13,4,1:3)
Block(-5,-13,5,1:3)
Block(-5,-13,6,1:3)
Block(-5,-13,7,1:3)
Block(-5,-12,-8,1:3)
Block(-5,-12,-7,1:3)
Block(-5,-12,-6,1:3)
Block(-5,-12,-5,1:3)
Block(-5,-12,-4,1:3)
Block(-5,-12,-3,1:3)
Block(-5,-12,-2,1:3)
Block(-5,-12,-1,1:3)
Block(-5,-12,0,1:3)
Block(-5,-12,1,1:3)
Block(-5,-12,2,1:3)
Block(-5,-12,3,1:3)
Block(-5,-12,4,1:3)
Block(-5,-12,5,1:3)
Block(-5,-12,6,1:3)
Block(-5,-12,7,1:3)
Block(-5,-11,-8,1:3)
Block(-5,-11,-7,1:3)
Block(-5,-11,-6,1:3)
Block(-5,-11,-5,1:3)
Block(-5,-11,-4,1:3)
Block(-5,-11,-3,1:3)
Block(-5,-11,-2,1:3)
Block(-5,-11,-1,1:3)
Block(-5,-11,0,1:3)
Block(-5,-11,1,1:1)
Block(-5,-11,2,1:3)
Block(-5,-11,3,1:3)
Block(-5,-11,4,1:3)
Block(-5,-11,5,1:3)
Block(-5,-11,6,1:3)
Block(-5,-11,7,1:3)
Block(-5,-10,-8,1:3)
Block(-5,-10,-7,1:3)
Block(-5,-10,-6,1:3)
Block(-5,-10,-5,1:3)
Block(-5,-10,-4,1:3)
Block(-5,-10,-3,1:3)
Block(-5,-10,-2,1:3)
Block(-5,-10,-1,1:3)
Block(-5,-10,0,1:3)
Block(-5,-10,1,1:1)
Block(-5,-10,2,1:3)
Block(-5,-10,3,1:3)
Block(-5,-10,4,1:3)
Block(-5,-10,5,1:3)
Block(-5,-10,6,1:3)
Block(-5,-10,7,1:3)
Block(-5,-9,-8,1:3)
Block(-5,-9,-7,1:3)
Block(-5,-9,-6,1:3)
Block(-5,-9,-5,1:3)
Block(-5,-9,-4,1:3)
Block(-5,-9,-3,1:3)
Block(-5,-9,-2,1:3)
Block(-5,-9,-1,1:1)
Block(-5,-9,0,1:1)
Block(-5,-9,1,1:1)
Block(-5,-9,2,1:1)
Block(-5,-9,3,1:1)
Block(-5,-9,4,1:3)
Block(-5,-9,5,1:3)
Block(-5,-9,6,1:3)
Block(-5,-9,7,1:3)
Block(-5,-8,-8,1:3)
Block(-5,-8,-7,1:3)
Block(-5,-8,-6,1:3)
Block(-5,-8,-5,1:3)
Block(-5,-8,-4,1:3)
Block(-5,-8,-3,1:3)
Block(-5,-8,-2,1:1)
Block(-5,-8,-1,1:1)
Block(-5,-8,0,1:1)
Block(-5,-8,1,1:1)
Block(-5,-8,2,1:1)
Block(-5,-8,3,1:1)
Block(-5,-8,4,1:1)
Block(-5,-8,5,1:3)
Block(-5,-8,6,1:3)
Block(-5,-8,7,1:3)
Block(-5,-7,-8,1:3)
Block(-5,-7,-7,1:3)
Block(-5,-7,-6,1:3)
Block(-5,-7,-5,1:3)
Block(-5,-7,-4,1:3)
Block(-5,-7,-3,1:1)
Block(-5,-7,-2,1:1)
Block(-5,-7,-1,1:1)
Block(-5,-7,0,1:1)
Block(-5,-7,1,1:1)
Block(-5,-7,2,1:1)
Block(-5,-7,3,1:1)
Block(-5,-7,4,1:1)
Block(-5,-7,5,1:3)
Block(-5,-7,6,1:3)
Block(-5,-7,7,1:3)
Block(-5,-6,-8,1:3)
Block(-5,-6,-7,1:3)
Block(-5,-6,-6,1:3)
Block(-5,-6,-5,1:3)
Block(-5,-6,-4,1:1)
Block(-5,-6,-3,1:1)
Block(-5,-6,-2,1:1)
Block(-5,-6,-1,1:1)
Block(-5,-6,0,1:1)
Block(-5,-6,1,1:1)
Block(-5,-6,2,1:1)
Block(-5,-6,3,1:1)
Block(-5,-6,4,1:1)
Block(-5,-6,5,1:1)
Block(-5,-6,6,1:3)
Block(-5,-6,7,1:3)
Block(-5,-5,-8,1:3)
Block(-5,-5,-7,1:3)
Block(-5,-5,-6,1:3)
Block(-5,-5,-5,1:1)
Block(-5,-5,-4,1:1)
Block(-5,-5,-3,1:1)
Block(-5,-5,-2,1:1)
Block(-5,-5,-1,1:1)
Block(-5,-5,0,1:1)
Block(-5,-5,1,1:1)
Block(-5,-5,2,1:1)
Block(-5,-5,3,1:1)
Block(-5,-5,4,1:1)
Block(-5,-5,5,1:1)
Block(-5,-5,6,1:1)
Block(-5,-5,7,1:1)
Block(-5,-4,-8,1:1)
Block(-5,-4,-7,1:3)
Block(-5,-4,-6,1:1)
Block(-5,-4,-5,1:1)
Block(-5,-4,-4,1:1)
Block(-5,-4,-3,1:1)
Block(-5,-4,-2,1:1)
Block(-5,-4,-1,1:1)
Block(-5,-4,0,1:1)
Block(-5,-4,1,1:1)
Block(-5,-4,2,1:1)
Block(-5,-4,3,1:1)
Block(-5,-4,4,1:1)
Block(-5,-4,5,1:1)
Block(-5,-4,6,1:1)
Block(-5,-4,7,1:1)
Block(-5,-3,-8,1:1)
Block(-5,-3,-7,1:1)
Block(-5,-3,-6,1:1)
Block(-5,-3,-5,1:1)
Block(-5,-3,-4,1:1)
Block(-5,-3,-3,1:1)
Block(-5,-3,-2,1:1)
Block(-5,-3,-1,1:1)
Block(-5,-3,0,1:1)
Block(-5,-3,1,1:1)
Block(-5,-3,2,1:1)
Block(-5,-3,3,1:1)
Block(-5,-3,4,1:1)
Block(-5,-3,5,1:1)
Block(-5,-3,6,1:1)
Block(-5,-3,7,1:1)
Block(-5,-2,-8,1:1)
Block(-5,-2,-7,1:1)
Block(-5,-2,-6,1:1)
Block(-5,-2,-5,1:1)
Block(-5,-2,-4,1:1)
Block(-5,-2,-3,1:1)
Block(-5,-2,-2,1:1)
Block(-5,-2,-1,1:1)
Block(-5,-2,0,1:1)
Block(-5,-2,1,1:1)
Block(-5,-2,2,1:1)
Block(-5,-2,3,1:1)
Block(-5,-2,4,1:1)
Block(-5,-2,5,1:1)
Block(-5,-2,6,1:1)
Block(-5,-2,7,1:1)
Block(-5,-1,-8,1:1)
Block(-5,-1,-7,1:1)
Block(-5,-1,-6,1:1)
Block(-5,-1,-5,1:1)
Block(-5,-1,-4,1:1)
Block(-5,-1,-3,1:1)
Block(-5,-1,-2,1:1)
Block(-5,-1,-1,1:1)
Block(-5,-1,0,1:1)
Block(-5,-1,1,1:1)
Block(-5,-1,2,1:1)
Block(-5,-1,3,1:1)
Block(-5,-1,4,1:1)
Block(-5,-1,5,1:1)
Block(-5,-1,6,1:1)
Block(-5,-1,7,1:1)
Block(-5,0,-8,1:1)
Block(-5,0,-7,1:1)
Block(-5,0,-6,1:1)
Block(-5,0,-5,1:1)
Block(-5,0,-4,1:1)
Block(-5,0,-3,1:1)
Block(-5,0,-2,1:1)
Block(-5,0,-1,1:1)
Block(-5,0,0,1:1)
Block(-5,0,1,1:1)
Block(-5,0,2,1:1)
Block(-5,0,3,1:1)
Block(-5,0,4,1:1)
Block(-5,0,5,1:1)
Block(-5,0,6,1:1)
Block(-5,0,7,1:1)
Block(-5,1,-8,1:1)
Block(-5,1,-7,1:1)
Block(-5,1,-6,1:1)
Block(-5,1,-5,1:1)
Block(-5,1,-4,1:1)
Block(-5,1,-3,1:1)
Block(-5,1,-2,1:1)
Block(-5,1,-1,1:1)
Block(-5,1,0,1:1)
Block(-5,1,1,1:1)
Block(-5,1,2,1:3)
Block(-5,1,3,1:1)
Block(-5,1,4,1:1)
Block(-5,1,5,1:1)
Block(-5,1,6,1:1)
Block(-5,1,7,1:1)
Block(-5,2,-8,1:1)
Block(-5,2,-7,1:1)
Block(-5,2,-6,1:1)
Block(-5,2,-5,1:1)
Block(-5,2,-4,1:1)
Block(-5,2,-3,1:1)
Block(-5,2,-2,1:1)
Block(-5,2,-1,1:1)
Block(-5,2,0,1:1)
Block(-5,2,1,1:1)
Block(-5,2,2,1:3)
Block(-5,2,3,1:3)
Block(-5,2,4,1:1)
Block(-5,2,5,1:1)
Block(-5,2,6,1:1)
Block(-5,2,7,1:1)
Block(-5,3,-8,1:1)
Block(-5,3,-7,1:1)
Block(-5,3,-6,1:1)
Block(-5,3,-5,1:1)
Block(-5,3,-4,1:1)
Block(-5,3,-3,1:1)
Block(-5,3,-2,1:1)
Block(-5,3,-1,1:1)
Block(-5,3,0,1:1)
Block(-5,3,1,1:1)
Block(-5,3,2,1:1)
Block(-5,3,3,1:1)
Block(-5,3,4,1:1)
Block(-5,3,5,1:1)
Block(-5,3,6,1:1)
Block(-5,3,7,1:1)
Block(-5,4,-8,1:1)
Block(-5,4,-7,1:1)
Block(-5,4,-6,1:1)
Block(-5,4,-5,1:1)
Block(-5,4,-4,1:1)
Block(-5,4,-3,1:1)
Block(-5,4,-2,1:1)
Block(-5,4,-1,1:1)
Block(-5,4,0,1:1)
Block(-5,4,1,1:1)
Block(-5,4,2,1:1)
Block(-5,4,3,1:1)
Block(-5,4,4,1:1)
Block(-5,4,5,1:3)
Block(-5,4,6,1:3)
Block(-5,4,7,1:1)
Block(-5,5,-8,1:1)
Block(-5,5,-7,1:1)
Block(-5,5,-6,1:1)
Block(-5,5,-5,1:1)
Block(-5,5,-4,1:1)
Block(-5,5,-3,1:1)
Block(-5,5,-2,1:1)
Block(-5,5,-1,1:1)
Block(-5,5,0,1:1)
Block(-5,5,1,1:1)
Block(-5,5,2,1:1)
Block(-5,5,3,1:1)
Block(-5,5,4,1:1)
Block(-5,5,5,1:3)
Block(-5,5,6,1:3)
Block(-5,5,7,1:3)
Block(-5,6,-8,1:1)
Block(-5,6,-7,1:1)
Block(-5,6,-6,1:1)
Block(-5,6,-5,1:1)
Block(-5,6,-4,1:1)
Block(-5,6,-3,1:1)
Block(-5,6,-2,1:1)
Block(-5,6,-1,1:1)
Block(-5,6,0,1:1)
Block(-5,6,1,1:1)
Block(-5,6,2,1:3)
Block(-5,6,3,1:3)
Block(-5,6,4,1:3)
Block(-5,6,5,1:3)
Block(-5,6,6,1:3)
Block(-5,6,7,1:3)
Block(-5,7,-8,1:1)
Block(-5,7,-7,1:1)
Block(-5,7,-6,1:1)
Block(-5,7,-5,1:1)
Block(-5,7,-4,1:1)
Block(-5,7,-3,1:1)
Block(-5,7,-2,1:1)
Block(-5,7,-1,1:3)
Block(-5,7,0,1:1)
Block(-5,7,1,1:3)
Block(-5,7,2,1:3)
Block(-5,7,3,1:3)
Block(-5,7,4,1:3)
Block(-5,7,5,1:3)
Block(-5,7,6,1:3)
Block(-5,7,7,1:3)
Block(-5,8,-8,1:1)
Block(-5,8,-7,1:1)
Block(-5,8,-6,1:1)
Block(-5,8,-5,1:1)
Block(-5,8,-4,1:1)
Block(-5,8,-3,1:1)
Block(-5,8,-2,1:3)
Block(-5,8,-1,1:3)
Block(-5,8,0,1:3)
Block(-5,8,1,1:3)
Block(-5,8,2,1:3)
Block(-5,8,3,1:3)
Block(-5,8,4,1:3)
Block(-5,8,5,1:3)
Block(-5,8,6,1:3)
Block(-5,8,7,1:3)
Block(-5,9,-8,1:3)
Block(-5,9,-7,1:3)
Block(-5,9,-6,1:3)
Block(-5,9,-5,1:1)
Block(-5,9,-4,1:1)
Block(-5,9,-3,1:1)
Block(-5,9,-2,1:1)
Block(-5,9,-1,1:3)
Block(-5,9,0,1:3)
Block(-5,9,1,1:3)
Block(-5,9,2,1:3)
Block(-5,9,3,1:3)
Block(-5,9,4,1:3)
Block(-5,9,5,1:3)
Block(-5,9,6,1:3)
Block(-5,9,7,1:3)
Block(-5,10,-8,1:3)
Block(-5,10,-7,1:3)
Block(-5,10,-6,1:3)
Block(-5,10,-5,1:3)
Block(-5,10,-4,1:1)
Block(-5,10,-3,1:1)
Block(-5,10,-2,1:1)
Block(-5,10,-1,1:3)
Block(-5,10,0,1:3)
Block(-5,10,1,1:3)
Block(-5,10,2,1:3)
Block(-5,10,3,1:3)
Block(-5,10,4,1:3)
Block(-5,10,5,1:3)
Block(-5,10,6,1:3)
Block(-5,10,7,1:3)
Block(-5,11,-8,1:3)
Block(-5,11,-7,1:3)
Block(-5,11,-6,1:3)
Block(-5,11,-5,1:3)
Block(-5,11,-4,1:1)
Block(-5,11,-3,1:1)
Block(-5,11,-2,1:1)
Block(-5,11,-1,1:3)
Block(-5,11,0,1:3)
Block(-5,11,1,1:3)
Block(-5,11,2,1:3)
Block(-5,11,3,1:3)
Block(-5,11,4,1:3)
Block(-5,11,5,1:3)
Block(-5,11,6,1:3)
Block(-5,11,7,1:3)
Block(-5,12,-8,1:3)
Block(-5,12,-7,1:3)
Block(-5,12,-6,1:3)
Block(-5,12,-5,1:3)
Block(-5,12,-4,1:1)
Block(-5,12,-3,1:1)
Block(-5,12,-2,1:1)
Block(-5,12,-1,1:3)
Block(-5,12,0,1:3)
Block(-5,12,1,1:3)
Block(-5,12,2,1:3)
Block(-5,12,3,1:3)
Block(-5,12,4,1:3)
Block(-5,12,5,1:3)
Block(-5,12,6,1:3)
Block(-5,12,7,1:3)
Block(-5,13,-8,1:3)
Block(-5,13,-7,1:3)
Block(-5,13,-6,1:3)
Block(-5,13,-5,1:3)
Block(-5,13,-4,1:1)
Block(-5,13,-3,1:1)
Block(-5,13,-2,1:1)
Block(-5,13,-1,1:3)
Block(-5,13,0,1:3)
Block(-5,13,1,1:3)
Block(-5,13,2,1:3)
Block(-5,13,3,1:3)
Block(-5,13,4,1:3)
Block(-5,13,5,1:3)
Block(-5,13,6,1:3)
Block(-5,13,7,1:3)
Block(-5,14,-8,1:3)
Block(-5,14,-7,1:3)
Block(-5,14,-6,1:3)
Block(-5,14,-5,1:1)
Block(-5,14,-4,1:1)
Block(-5,14,-3,1:1)
Block(-5,14,-2,1:1)
Block(-5,14,-1,1:3)
Block(-5,14,0,1:3)
Block(-5,14,1,1:3)
Block(-5,14,2,1:3)
Block(-5,14,3,1:3)
Block(-5,14,4,1:3)
Block(-5,14,5,1:3)
Block(-5,14,6,1:3)
Block(-5,14,7,1:3)
Block(-5,15,-8,1:3)
Block(-5,15,-7,1:3)
Block(-5,15,-6,1:3)
Block(-5,15,-5,1:1)
Block(-5,15,-4,1:1)
Block(-5,15,-3,1:1)
Block(-5,15,-2,1:1)
Block(-5,15,-1,1:1)
Block(-5,15,0,1:3)
Block(-5,15,1,1:3)
Block(-5,15,2,1:3)
Block(-5,15,3,1:3)
Block(-5,15,4,1:3)
Block(-5,15,5,1:3)
Block(-5,15,6,1:3)
Block(-5,15,7,1:3)
Block(-5,16,-8,1:3)
Block(-5,16,-7,1:3)
Block(-5,16,-6,1:1)
Block(-5,16,-5,1:1)
Block(-5,16,-4,1:1)
Block(-5,16,-3,1:1)
Block(-5,16,-2,1:1)
Block(-5,16,-1,1:3)
Block(-5,16,0,1:3)
Block(-5,16,1,1:3)
Block(-5,16,2,1:3)
Block(-5,16,3,1:3)
Block(-5,16,4,1:3)
Block(-5,16,5,1:3)
Block(-5,16,6,1:3)
Block(-5,16,7,1:3)
Block(-5,17,-8,1:3)
Block(-5,17,-7,1:3)
Block(-5,17,-6,1:1)
Block(-5,17,-5,1:1)
Block(-5,17,-4,1:1)
Block(-5,17,-3,1:1)
Block(-5,17,-2,1:1)
Block(-5,17,-1,1:3)
Block(-5,17,0,1:3)
Block(-5,17,1,1:3)
Block(-5,17,2,1:3)
Block(-5,17,3,1:3)
Block(-5,17,4,1:3)
Block(-5,17,5,1:3)
Block(-5,17,6,1:3)
Block(-5,17,7,1:3)
Block(-5,18,-8,1:3)
Block(-5,18,-7,1:3)
Block(-5,18,-6,1:3)
Block(-5,18,-5,1:1)
Block(-5,18,-4,1:1)
Block(-5,18,-3,1:1)
Block(-5,18,-2,1:1)
Block(-5,18,-1,1:3)
Block(-5,18,0,1:3)
Block(-5,18,1,1:3)
Block(-5,18,2,1:3)
Block(-5,18,3,1:3)
Block(-5,18,4,1:3)
Block(-5,18,5,1:3)
Block(-5,18,6,1:3)
Block(-5,18,7,1:3)
Block(-5,19,-8,1:3)
Block(-5,19,-7,1:3)
Block(-5,19,-6,1:3)
Block(-5,19,-5,1:3)
Block(-5,19,-4,1:1)
Block(-5,19,-3,1:1)
Block(-5,19,-2,1:1)
Block(-5,19,-1,1:3)
Block(-5,19,0,1:3)
Block(-5,19,1,1:3)
Block(-5,19,2,1:3)
Block(-5,19,3,1:3)
Block(-5,19,4,1:3)
Block(-5,19,5,1:3)
Block(-5,19,6,1:3)
Block(-5,19,7,1:3)
Block(-5,20,-8,1:3)
Block(-5,20,-7,1:3)
Block(-5,20,-6,1:3)
Block(-5,20,-5,1:3)
Block(-5,20,-4,1:3)
Block(-5,20,-3,1:1)
Block(-5,20,-2,1:1)
Block(-5,20,-1,1:3)
Block(-5,20,0,1:3)
Block(-5,20,1,1:3)
Block(-5,20,2,1:3)
Block(-5,20,3,1:3)
Block(-5,20,4,1:3)
Block(-5,20,5,1:3)
Block(-5,20,6,1:3)
Block(-5,20,7,1:3)
Block(-5,21,-8,1:3)
Block(-5,21,-7,1:3)
Block(-5,21,-6,1:3)
Block(-5,21,-5,1:3)
Block(-5,21,-4,1:3)
Block(-5,21,-3,1:3)
Block(-5,21,-2,1:1)
Block(-5,21,-1,1:1)
Block(-5,21,0,1:1)
Block(-5,21,1,1:3)
Block(-5,21,2,1:3)
Block(-5,21,3,1:3)
Block(-5,21,4,1:3)
Block(-5,21,5,1:3)
Block(-5,21,6,1:3)
Block(-5,21,7,1:3)
Block(-5,22,-8,1:3)
Block(-5,22,-7,1:3)
Block(-5,22,-6,1:3)
Block(-5,22,-5,1:3)
Block(-5,22,-4,1:3)
Block(-5,22,-3,1:3)
Block(-5,22,-2,1:3)
Block(-5,22,-1,1:1)
Block(-5,22,0,1:1)
Block(-5,22,1,1:1)
Block(-5,22,2,1:3)
Block(-5,22,3,1:3)
Block(-5,22,4,1:3)
Block(-5,22,5,1:3)
Block(-5,22,6,1:3)
Block(-5,22,7,1:3)
Block(-5,23,-8,1:3)
Block(-5,23,-7,1:3)
Block(-5,23,-6,1:3)
Block(-5,23,-5,1:3)
Block(-5,23,-4,1:3)
Block(-5,23,-3,1:3)
Block(-5,23,-2,1:3)
Block(-5,23,-1,1:3)
Block(-5,23,0,1:1)
Block(-5,23,1,1:1)
Block(-5,23,2,1:1)
Block(-5,23,3,1:1)
Block(-5,23,4,1:1)
Block(-5,23,5,1:3)
Block(-5,23,6,1:3)
Block(-5,23,7,1:3)
Block(-5,24,-8,1:1)
Block(-5,24,-7,1:3)
Block(-5,24,-6,1:1)
Block(-5,24,-5,1:3)
Block(-5,24,-4,1:3)
Block(-5,24,-3,1:3)
Block(-5,24,-2,1:3)
Block(-5,24,-1,1:3)
Block(-5,24,0,1:3)
Block(-5,24,1,1:1)
Block(-5,24,2,1:1)
Block(-5,24,3,1:1)
Block(-5,24,4,1:1)
Block(-5,24,5,1:1)
Block(-5,24,6,1:1)
Block(-5,24,7,1:3)
Block(-5,25,-8,1:1)
Block(-5,25,-7,1:1)
Block(-5,25,-6,1:1)
Block(-5,25,-5,1:3)
Block(-5,25,-4,1:3)
Block(-5,25,-3,1:3)
Block(-5,25,-2,1:3)
Block(-5,25,-1,1:3)
Block(-5,25,0,1:3)
Block(-5,25,1,1:3)
Block(-5,25,2,1:1)
Block(-5,25,3,1:1)
Block(-5,25,4,1:1)
Block(-5,25,5,1:1)
Block(-5,25,6,1:1)
Block(-5,25,7,1:1)
Block(-5,26,-8,1:1)
Block(-5,26,-7,1:1)
Block(-5,26,-6,1:1)
Block(-5,26,-5,1:3)
Block(-5,26,-4,1:3)
Block(-5,26,-3,1:3)
Block(-5,26,-2,1:3)
Block(-5,26,-1,1:3)
Block(-5,26,0,1:3)
Block(-5,26,1,1:3)
Block(-5,26,2,1:3)
Block(-5,26,3,1:1)
Block(-5,26,4,1:1)
Block(-5,26,5,1:1)
Block(-5,26,6,1:1)
Block(-5,26,7,1:1)
Block(-5,27,-8,1:1)
Block(-5,27,-7,1:1)
Block(-5,27,-6,1:1)
Block(-5,27,-5,1:3)
Block(-5,27,-4,1:3)
Block(-5,27,-3,1:3)
Block(-5,27,-2,1:3)
Block(-5,27,-1,1:3)
Block(-5,27,0,1:3)
Block(-5,27,1,1:3)
Block(-5,27,2,1:3)
Block(-5,27,3,1:3)
Block(-5,27,4,1:1)
Block(-5,27,5,1:1)
Block(-5,27,6,1:1)
Block(-5,27,7,1:1)
Block(-5,28,-8,1:1)
Block(-5,28,-7,1:1)
Block(-5,28,-6,1:1)
Block(-5,28,-5,1:1)
Block(-5,28,-4,1:1)
Block(-5,28,-3,1:3)
Block(-5,28,-2,1:3)
Block(-5,28,-1,1:3)
Block(-5,28,0,1:3)
Block(-5,28,1,1:3)
Block(-5,28,2,1:3)
Block(-5,28,3,1:3)
Block(-5,28,4,1:3)
Block(-5,28,5,1:1)
Block(-5,28,6,1:1)
Block(-5,28,7,1:3)
Block(-5,29,-8,1:1)
Block(-5,29,-7,1:1)
Block(-5,29,-6,1:1)
Block(-5,29,-5,1:1)
Block(-5,29,-4,1:1)
Block(-5,29,-3,1:3)
Block(-5,29,-2,1:3)
Block(-5,29,-1,1:3)
Block(-5,29,0,1:3)
Block(-5,29,1,1:3)
Block(-5,29,2,1:3)
Block(-5,29,3,1:3)
Block(-5,29,4,1:3)
Block(-5,29,5,1:3)
Block(-5,29,6,1:1)
Block(-5,29,7,1:3)
Block(-5,30,-8,1:1)
Block(-5,30,-7,1:1)
Block(-5,30,-6,1:1)
Block(-5,30,-5,1:1)
Block(-5,30,-4,1:1)
Block(-5,30,-3,1:3)
Block(-5,30,-2,1:3)
Block(-5,30,-1,1:3)
Block(-5,30,0,1:3)
Block(-5,30,1,1:3)
Block(-5,30,2,1:3)
Block(-5,30,3,1:3)
Block(-5,30,4,1:3)
Block(-5,30,5,1:3)
Block(-5,30,6,1:3)
Block(-5,30,7,1:3)
Block(-5,31,-8,1:3)
Block(-5,31,-7,1:3)
Block(-5,31,-6,1:3)
Block(-5,31,-5,1:1)
Block(-5,31,-4,1:3)
Block(-5,31,-3,1:3)
Block(-5,31,-2,1:3)
Block(-5,31,-1,1:3)
Block(-5,31,0,1:3)
Block(-5,31,1,1:3)
Block(-5,31,2,1:3)
Block(-5,31,3,1:3)
Block(-5,31,4,1:3)
Block(-5,31,5,1:3)
Block(-5,31,6,1:3)
Block(-5,31,7,1:3)
Block(-5,32,-8,1:3)
Block(-5,32,-7,1:3)
Block(-5,32,-6,1:3)
Block(-5,32,-5,1:3)
Block(-5,32,-4,1:3)
Block(-5,32,-3,1:3)
Block(-5,32,-2,1:3)
Block(-5,32,-1,1:3)
Block(-5,32,0,1:3)
Block(-5,32,1,1:3)
Block(-5,32,2,1:3)
Block(-5,32,3,1:3)
Block(-5,32,4,1:3)
Block(-5,32,5,1:3)
Block(-5,32,6,1:3)
Block(-5,32,7,1:3)
Block(-5,33,-8,1:3)
Block(-5,33,-7,1:3)
Block(-5,33,-6,1:3)
Block(-5,33,-5,1:3)
Block(-5,33,-4,1:3)
Block(-5,33,-3,1:3)
Block(-5,33,-2,1:3)
Block(-5,33,-1,1:3)
Block(-5,33,0,1:3)
Block(-5,33,1,1:3)
Block(-5,33,2,1:3)
Block(-5,33,3,1:3)
Block(-5,33,4,1:1)
Block(-5,33,5,1:3)
Block(-5,33,6,1:3)
Block(-5,33,7,1:3)
Block(-5,34,-8,1:3)
Block(-5,34,-7,1:3)
Block(-5,34,-6,1:3)
Block(-5,34,-5,1:3)
Block(-5,34,-4,1:3)
Block(-5,34,-3,1:3)
Block(-5,34,-2,1:3)
Block(-5,34,-1,1:3)
Block(-5,34,0,1:3)
Block(-5,34,1,1:1)
Block(-5,34,2,1:1)
Block(-5,34,3,1:1)
Block(-5,34,4,1:1)
Block(-5,34,5,1:1)
Block(-5,34,6,1:1)
Block(-5,34,7,1:1)
Block(-5,35,-8,1:3)
Block(-5,35,-7,1:3)
Block(-5,35,-6,1:3)
Block(-5,35,-5,1:3)
Block(-5,35,-4,1:3)
Block(-5,35,-3,1:3)
Block(-5,35,-2,1:3)
Block(-5,35,-1,1:1)
Block(-5,35,0,1:1)
Block(-5,35,1,1:1)
Block(-5,35,2,1:1)
Block(-5,35,3,1:1)
Block(-5,35,4,1:1)
Block(-5,35,5,1:1)
Block(-5,35,6,1:1)
Block(-5,35,7,1:1)
Block(-5,36,-8,1:3)
Block(-5,36,-7,1:3)
Block(-5,36,-6,1:3)
Block(-5,36,-5,1:3)
Block(-5,36,-4,1:3)
Block(-5,36,-3,1:3)
Block(-5,36,-2,1:1)
Block(-5,36,-1,1:1)
Block(-5,36,0,1:1)
Block(-5,36,1,1:1)
Block(-5,36,2,1:1)
Block(-5,36,3,1:1)
Block(-5,36,4,1:1)
Block(-5,36,5,1:1)
Block(-5,36,6,1:1)
Block(-5,36,7,1:1)
Block(-5,37,-8,1:3)
Block(-5,37,-7,1:3)
Block(-5,37,-6,1:3)
Block(-5,37,-5,1:3)
Block(-5,37,-4,1:3)
Block(-5,37,-3,1:1)
Block(-5,37,-2,1:1)
Block(-5,37,-1,1:1)
Block(-5,37,0,1:1)
Block(-5,37,1,1:1)
Block(-5,37,2,1:1)
Block(-5,37,3,1:1)
Block(-5,37,4,1:1)
Block(-5,37,5,1:1)
Block(-5,37,6,1:1)
Block(-5,37,7,1:1)
Block(-5,38,-8,1:3)
Block(-5,38,-7,1:3)
Block(-5,38,-6,1:3)
Block(-5,38,-5,1:3)
Block(-5,38,-4,1:3)
Block(-5,38,-3,1:1)
Block(-5,38,-2,1:1)
Block(-5,38,-1,1:1)
Block(-5,38,0,1:1)
Block(-5,38,1,1:1)
Block(-5,38,2,1:1)
Block(-5,38,3,1:1)
Block(-5,38,4,1:3)
Block(-5,38,5,1:1)
Block(-5,38,6,1:3)
Block(-5,38,7,1:1)
Block(-5,39,-8,1:3)
Block(-5,39,-7,1:3)
Block(-5,39,-6,1:3)
Block(-5,39,-5,1:3)
Block(-5,39,-4,1:3)
Block(-5,39,-3,1:1)
Block(-5,39,-2,1:1)
Block(-5,39,-1,1:1)
Block(-5,39,0,1:1)
Block(-5,39,1,1:1)
Block(-5,39,2,1:1)
Block(-5,39,3,1:3)
Block(-5,39,4,1:3)
Block(-5,39,5,1:3)
Block(-5,39,6,1:3)
Block(-5,39,7,1:3)
Block(-5,40,-8,1:3)
Block(-5,40,-7,1:3)
Block(-5,40,-6,1:3)
Block(-5,40,-5,1:3)
Block(-5,40,-4,1:1)
Block(-5,40,-3,1:1)
Block(-5,40,-2,1:1)
Block(-5,40,-1,1:1)
Block(-5,40,0,1:1)
Block(-5,40,1,1:3)
Block(-5,40,2,1:3)
Block(-5,40,3,1:3)
Block(-5,40,4,1:3)
Block(-5,40,5,1:3)
Block(-5,40,6,1:3)
Block(-5,40,7,1:3)
Block(-5,41,-8,1:3)
Block(-5,41,-7,1:3)
Block(-5,41,-6,1:3)
Block(-5,41,-5,1:3)
Block(-5,41,-4,1:1)
Block(-5,41,-3,1:1)
Block(-5,41,-2,1:1)
Block(-5,41,-1,1:3)
Block(-5,41,0,1:3)
Block(-5,41,1,1:3)
Block(-5,41,2,1:3)
Block(-5,41,3,1:3)
Block(-5,41,4,1:3)
Block(-5,41,5,1:3)
Block(-5,41,6,1:3)
Block(-5,41,7,1:3)
Block(-5,42,-8,1:3)
Block(-5,42,-7,1:3)
Block(-5,42,-6,1:3)
Block(-5,42,-5,1:3)
Block(-5,42,-4,1:1)
Block(-5,42,-3,1:1)
Block(-5,42,-2,1:3)
Block(-5,42,-1,1:3)
Block(-5,42,0,1:3)
Block(-5,42,1,1:3)
Block(-5,42,2,1:3)
Block(-5,42,3,1:3)
Block(-5,42,4,1:3)
Block(-5,42,5,1:3)
Block(-5,42,6,1:3)
Block(-5,42,7,1:3)
Block(-5,43,-8,1:3)
Block(-5,43,-7,1:3)
Block(-5,43,-6,1:3)
Block(-5,43,-5,1:3)
Block(-5,43,-4,1:1)
Block(-5,43,-3,1:1)
Block(-5,43,-2,1:3)
Block(-5,43,-1,1:3)
Block(-5,43,0,1:3)
Block(-5,43,1,1:3)
Block(-5,43,2,1:3)
Block(-5,43,3,1:3)
Block(-5,43,4,1:3)
Block(-5,43,5,1:3)
Block(-5,43,6,1:3)
Block(-5,43,7,1:3)
Block(-5,44,-8,1:3)
Block(-5,44,-7,1:3)
Block(-5,44,-6,1:3)
Block(-5,44,-5,1:3)
Block(-5,44,-4,1:1)
Block(-5,44,-3,1:3)
Block(-5,44,-2,1:3)
Block(-5,44,-1,1:3)
Block(-5,44,0,1:3)
Block(-5,44,1,1:3)
Block(-5,44,2,1:3)
Block(-5,44,3,1:3)
Block(-5,44,4,1:3)
Block(-5,44,5,1:3)
Block(-5,44,6,1:3)
Block(-5,44,7,1:3)
Block(-5,45,-8,1:3)
Block(-5,45,-7,1:3)
Block(-5,45,-6,1:3)
Block(-5,45,-5,1:3)
Block(-5,45,-4,1:1)
Block(-5,45,-3,1:3)
Block(-5,45,-2,1:3)
Block(-5,45,-1,1:3)
Block(-5,45,0,1:3)
Block(-5,45,1,1:3)
Block(-5,45,2,1:3)
Block(-5,45,3,1:3)
Block(-5,45,4,1:3)
Block(-5,45,5,1:3)
Block(-5,45,6,1:3)
Block(-5,45,7,1:3)
Block(-5,46,-8,1:3)
Block(-5,46,-7,1:3)
Block(-5,46,-6,1:3)
Block(-5,46,-5,1:1)
Block(-5,46,-4,1:1)
Block(-5,46,-3,1:3)
Block(-5,46,-2,1:3)
Block(-5,46,-1,1:3)
Block(-5,46,0,1:3)
Block(-5,46,1,1:3)
Block(-5,46,2,1:3)
Block(-5,46,3,1:3)
Block(-5,46,4,1:3)
Block(-5,46,5,1:3)
Block(-5,46,6,1:3)
Block(-5,46,7,1:3)
Block(-5,47,-8,1:3)
Block(-5,47,-7,1:3)
Block(-5,47,-6,1:3)
Block(-5,47,-5,1:1)
Block(-5,47,-4,1:3)
Block(-5,47,-3,1:3)
Block(-5,47,-2,1:3)
Block(-5,47,-1,1:3)
Block(-5,47,0,1:3)
Block(-5,47,1,1:3)
Block(-5,47,2,1:3)
Block(-5,47,3,1:3)
Block(-5,47,4,1:3)
Block(-5,47,5,1:3)
Block(-5,47,6,1:3)
Block(-5,47,7,1:3)
Block(-4,-33,-8,1:1)
Block(-4,-33,-7,1:1)
Block(-4,-33,-6,1:1)
Block(-4,-33,-5,1:1)
Block(-4,-33,-4,1:1)
Block(-4,-33,-3,1:1)
Block(-4,-33,-2,1:1)
Block(-4,-33,-1,1:1)
Block(-4,-33,0,1:1)
Block(-4,-33,1,1:1)
Block(-4,-33,2,1:1)
Block(-4,-33,3,1:1)
Block(-4,-33,4,1:1)
Block(-4,-33,5,1:1)
Block(-4,-33,6,1:1)
Block(-4,-33,7,1:1)
Block(-4,-32,-8,1:1)
Block(-4,-32,-7,1:1)
Block(-4,-32,-6,1:1)
Block(-4,-32,-5,1:1)
Block(-4,-32,-4,1:1)
Block(-4,-32,-3,1:1)
Block(-4,-32,-2,1:1)
Block(-4,-32,-1,1:1)
Block(-4,-32,0,1:1)
Block(-4,-32,1,1:1)
Block(-4,-32,2,1:1)
Block(-4,-32,3,1:1)
Block(-4,-32,4,1:1)
Block(-4,-32,5,1:1)
Block(-4,-32,6,1:1)
Block(-4,-32,7,1:1)
Block(-4,-31,-8,1:1)
Block(-4,-31,-7,1:1)
Block(-4,-31,-6,1:1)
Block(-4,-31,-5,1:1)
Block(-4,-31,-4,1:1)
Block(-4,-31,-3,1:1)
Block(-4,-31,-2,1:1)
Block(-4,-31,-1,1:1)
Block(-4,-31,0,1:1)
Block(-4,-31,1,1:1)
Block(-4,-31,2,1:1)
Block(-4,-31,3,1:1)
Block(-4,-31,4,1:1)
Block(-4,-31,5,1:1)
Block(-4,-31,6,1:1)
Block(-4,-31,7,1:1)
Block(-4,-30,-8,1:1)
Block(-4,-30,-7,1:1)
Block(-4,-30,-6,1:1)
Block(-4,-30,-5,1:1)
Block(-4,-30,-4,1:1)
Block(-4,-30,-3,1:1)
Block(-4,-30,-2,1:1)
Block(-4,-30,-1,1:1)
Block(-4,-30,0,1:1)
Block(-4,-30,1,1:1)
Block(-4,-30,2,1:1)
Block(-4,-30,3,1:1)
Block(-4,-30,4,1:1)
Block(-4,-30,5,1:1)
Block(-4,-30,6,1:1)
Block(-4,-30,7,1:1)
Block(-4,-29,-8,1:1)
Block(-4,-29,-7,1:1)
Block(-4,-29,-6,1:1)
Block(-4,-29,-5,1:1)
Block(-4,-29,-4,1:1)
Block(-4,-29,-3,1:1)
Block(-4,-29,-2,1:1)
Block(-4,-29,-1,1:1)
Block(-4,-29,0,1:1)
Block(-4,-29,1,1:1)
Block(-4,-29,2,1:1)
Block(-4,-29,3,1:1)
Block(-4,-29,4,1:1)
Block(-4,-29,5,1:1)
Block(-4,-29,6,1:1)
Block(-4,-29,7,1:3)
Block(-4,-28,-8,1:1)
Block(-4,-28,-7,1:1)
Block(-4,-28,-6,1:1)
Block(-4,-28,-5,1:1)
Block(-4,-28,-4,1:1)
Block(-4,-28,-3,1:1)
Block(-4,-28,-2,1:1)
Block(-4,-28,-1,1:1)
Block(-4,-28,0,1:1)
Block(-4,-28,1,1:1)
Block(-4,-28,2,1:1)
Block(-4,-28,3,1:1)
Block(-4,-28,4,1:1)
Block(-4,-28,5,1:1)
Block(-4,-28,6,1:1)
Block(-4,-28,7,1:3)
Block(-4,-27,-8,1:1)
Block(-4,-27,-7,1:1)
Block(-4,-27,-6,1:1)
Block(-4,-27,-5,1:1)
Block(-4,-27,-4,1:1)
Block(-4,-27,-3,1:1)
Block(-4,-27,-2,1:1)
Block(-4,-27,-1,1:1)
Block(-4,-27,0,1:1)
Block(-4,-27,1,1:1)
Block(-4,-27,2,1:1)
Block(-4,-27,3,1:1)
Block(-4,-27,4,1:1)
Block(-4,-27,5,1:1)
Block(-4,-27,6,1:1)
Block(-4,-27,7,1:3)
Block(-4,-26,-8,1:1)
Block(-4,-26,-7,1:1)
Block(-4,-26,-6,1:1)
Block(-4,-26,-5,1:1)
Block(-4,-26,-4,1:1)
Block(-4,-26,-3,1:1)
Block(-4,-26,-2,1:1)
Block(-4,-26,-1,1:1)
Block(-4,-26,0,1:1)
Block(-4,-26,1,1:3)
Block(-4,-26,2,1:1)
Block(-4,-26,3,1:1)
Block(-4,-26,4,1:1)
Block(-4,-26,5,1:1)
Block(-4,-26,6,1:1)
Block(-4,-26,7,1:1)
Block(-4,-25,-8,1:1)
Block(-4,-25,-7,1:1)
Block(-4,-25,-6,1:1)
Block(-4,-25,-5,1:1)
Block(-4,-25,-4,1:1)
Block(-4,-25,-3,1:1)
Block(-4,-25,-2,1:1)
Block(-4,-25,-1,1:1)
Block(-4,-25,0,1:3)
Block(-4,-25,1,1:3)
Block(-4,-25,2,1:3)
Block(-4,-25,3,1:3)
Block(-4,-25,4,1:1)
Block(-4,-25,5,1:1)
Block(-4,-25,6,1:1)
Block(-4,-25,7,1:1)
Block(-4,-24,-8,1:1)
Block(-4,-24,-7,1:1)
Block(-4,-24,-6,1:1)
Block(-4,-24,-5,1:1)
Block(-4,-24,-4,1:1)
Block(-4,-24,-3,1:1)
Block(-4,-24,-2,1:1)
Block(-4,-24,-1,1:3)
Block(-4,-24,0,1:3)
Block(-4,-24,1,1:3)
Block(-4,-24,2,1:3)
Block(-4,-24,3,1:3)
Block(-4,-24,4,1:1)
Block(-4,-24,5,1:3)
Block(-4,-24,6,1:1)
Block(-4,-24,7,1:1)
Block(-4,-23,-8,1:1)
Block(-4,-23,-7,1:1)
Block(-4,-23,-6,1:1)
Block(-4,-23,-5,1:1)
Block(-4,-23,-4,1:1)
Block(-4,-23,-3,1:1)
Block(-4,-23,-2,1:1)
Block(-4,-23,-1,1:3)
Block(-4,-23,0,1:3)
Block(-4,-23,1,1:3)
Block(-4,-23,2,1:3)
Block(-4,-23,3,1:3)
Block(-4,-23,4,1:3)
Block(-4,-23,5,1:3)
Block(-4,-23,6,1:1)
Block(-4,-23,7,1:3)
Block(-4,-22,-8,1:1)
Block(-4,-22,-7,1:1)
Block(-4,-22,-6,1:1)
Block(-4,-22,-5,1:1)
Block(-4,-22,-4,1:1)
Block(-4,-22,-3,1:1)
Block(-4,-22,-2,1:1)
Block(-4,-22,-1,1:3)
Block(-4,-22,0,1:3)
Block(-4,-22,1,1:3)
Block(-4,-22,2,1:3)
Block(-4,-22,3,1:3)
Block(-4,-22,4,1:3)
Block(-4,-22,5,1:3)
Block(-4,-22,6,1:3)
Block(-4,-22,7,1:3)
Block(-4,-21,-8,1:1)
Block(-4,-21,-7,1:1)
Block(-4,-21,-6,1:1)
Block(-4,-21,-5,1:1)
Block(-4,-21,-4,1:1)
Block(-4,-21,-3,1:1)
Block(-4,-21,-2,1:3)
Block(-4,-21,-1,1:3)
Block(-4,-21,0,1:3)
Block(-4,-21,1,1:3)
Block(-4,-21,2,1:3)
Block(-4,-21,3,1:3)
Block(-4,-21,4,1:3)
Block(-4,-21,5,1:3)
Block(-4,-21,6,1:3)
Block(-4,-21,7,1:3)
Block(-4,-20,-8,1:1)
Block(-4,-20,-7,1:1)
Block(-4,-20,-6,1:1)
Block(-4,-20,-5,1:1)
Block(-4,-20,-4,1:1)
Block(-4,-20,-3,1:3)
Block(-4,-20,-2,1:3)
Block(-4,-20,-1,1:3)
Block(-4,-20,0,1:3)
Block(-4,-20,1,1:3)
Block(-4,-20,2,1:3)
Block(-4,-20,3,1:3)
Block(-4,-20,4,1:3)
Block(-4,-20,5,1:3)
Block(-4,-20,6,1:3)
Block(-4,-20,7,1:3)
Block(-4,-19,-8,1:1)
Block(-4,-19,-7,1:1)
Block(-4,-19,-6,1:1)
Block(-4,-19,-5,1:1)
Block(-4,-19,-4,1:1)
Block(-4,-19,-3,1:3)
Block(-4,-19,-2,1:3)
Block(-4,-19,-1,1:3)
Block(-4,-19,0,1:3)
Block(-4,-19,1,1:3)
Block(-4,-19,2,1:3)
Block(-4,-19,3,1:3)
Block(-4,-19,4,1:3)
Block(-4,-19,5,1:3)
Block(-4,-19,6,1:3)
Block(-4,-19,7,1:3)
Block(-4,-18,-8,1:1)
Block(-4,-18,-7,1:1)
Block(-4,-18,-6,1:1)
Block(-4,-18,-5,1:1)
Block(-4,-18,-4,1:1)
Block(-4,-18,-3,1:3)
Block(-4,-18,-2,1:3)
Block(-4,-18,-1,1:3)
Block(-4,-18,0,1:3)
Block(-4,-18,1,1:3)
Block(-4,-18,2,1:3)
Block(-4,-18,3,1:3)
Block(-4,-18,4,1:3)
Block(-4,-18,5,1:3)
Block(-4,-18,6,1:3)
Block(-4,-18,7,1:3)
Block(-4,-17,-8,1:1)
Block(-4,-17,-7,1:1)
Block(-4,-17,-6,1:1)
Block(-4,-17,-5,1:1)
Block(-4,-17,-4,1:3)
Block(-4,-17,-3,1:3)
Block(-4,-17,-2,1:3)
Block(-4,-17,-1,1:3)
Block(-4,-17,0,1:3)
Block(-4,-17,1,1:3)
Block(-4,-17,2,1:3)
Block(-4,-17,3,1:3)
Block(-4,-17,4,1:3)
Block(-4,-17,5,1:3)
Block(-4,-17,6,1:3)
Block(-4,-17,7,1:3)
Block(-4,-16,-8,1:3)
Block(-4,-16,-7,1:3)
Block(-4,-16,-6,1:1)
Block(-4,-16,-5,1:3)
Block(-4,-16,-4,1:3)
Block(-4,-16,-3,1:3)
Block(-4,-16,-2,1:3)
Block(-4,-16,-1,1:3)
Block(-4,-16,0,1:3)
Block(-4,-16,1,1:3)
Block(-4,-16,2,1:3)
Block(-4,-16,3,1:3)
Block(-4,-16,4,1:3)
Block(-4,-16,5,1:3)
Block(-4,-16,6,1:3)
Block(-4,-16,7,1:3)
Block(-4,-15,-8,1:3)
Block(-4,-15,-7,1:3)
Block(-4,-15,-6,1:3)
Block(-4,-15,-5,1:3)
Block(-4,-15,-4,1:3)
Block(-4,-15,-3,1:3)
Block(-4,-15,-2,1:3)
Block(-4,-15,-1,1:3)
Block(-4,-15,0,1:3)
Block(-4,-15,1,1:3)
Block(-4,-15,2,1:3)
Block(-4,-15,3,1:3)
Block(-4,-15,4,1:3)
Block(-4,-15,5,1:3)
Block(-4,-15,6,1:3)
Block(-4,-15,7,1:3)
Block(-4,-14,-8,1:3)
Block(-4,-14,-7,1:3)
Block(-4,-14,-6,1:3)
Block(-4,-14,-5,1:3)
Block(-4,-14,-4,1:3)
Block(-4,-14,-3,1:3)
Block(-4,-14,-2,1:3)
Block(-4,-14,-1,1:3)
Block(-4,-14,0,1:3)
Block(-4,-14,1,1:3)
Block(-4,-14,2,1:3)
Block(-4,-14,3,1:3)
Block(-4,-14,4,1:3)
Block(-4,-14,5,1:3)
Block(-4,-14,6,1:3)
Block(-4,-14,7,1:3)
Block(-4,-13,-8,1:3)
Block(-4,-13,-7,1:3)
Block(-4,-13,-6,1:3)
Block(-4,-13,-5,1:3)
Block(-4,-13,-4,1:3)
Block(-4,-13,-3,1:3)
Block(-4,-13,-2,1:3)
Block(-4,-13,-1,1:3)
Block(-4,-13,0,1:3)
Block(-4,-13,1,1:3)
Block(-4,-13,2,1:3)
Block(-4,-13,3,1:3)
Block(-4,-13,4,1:3)
Block(-4,-13,5,1:3)
Block(-4,-13,6,1:3)
Block(-4,-13,7,1:3)
Block(-4,-12,-8,1:3)
Block(-4,-12,-7,1:3)
Block(-4,-12,-6,1:3)
Block(-4,-12,-5,1:3)
Block(-4,-12,-4,1:3)
Block(-4,-12,-3,1:3)
Block(-4,-12,-2,1:3)
Block(-4,-12,-1,1:3)
Block(-4,-12,0,1:3)
Block(-4,-12,1,1:3)
Block(-4,-12,2,1:3)
Block(-4,-12,3,1:3)
Block(-4,-12,4,1:3)
Block(-4,-12,5,1:3)
Block(-4,-12,6,1:3)
Block(-4,-12,7,1:3)
Block(-4,-11,-8,1:3)
Block(-4,-11,-7,1:3)
Block(-4,-11,-6,1:3)
Block(-4,-11,-5,1:3)
Block(-4,-11,-4,1:3)
Block(-4,-11,-3,1:3)
Block(-4,-11,-2,1:3)
Block(-4,-11,-1,1:3)
Block(-4,-11,0,1:3)
Block(-4,-11,1,1:3)
Block(-4,-11,2,1:3)
Block(-4,-11,3,1:3)
Block(-4,-11,4,1:3)
Block(-4,-11,5,1:3)
Block(-4,-11,6,1:3)
Block(-4,-11,7,1:3)
Block(-4,-10,-8,1:3)
Block(-4,-10,-7,1:3)
Block(-4,-10,-6,1:3)
Block(-4,-10,-5,1:3)
Block(-4,-10,-4,1:3)
Block(-4,-10,-3,1:3)
Block(-4,-10,-2,1:3)
Block(-4,-10,-1,1:3)
Block(-4,-10,0,1:3)
Block(-4,-10,1,1:1)
Block(-4,-10,2,1:3)
Block(-4,-10,3,1:3)
Block(-4,-10,4,1:3)
Block(-4,-10,5,1:3)
Block(-4,-10,6,1:3)
Block(-4,-10,7,1:3)
Block(-4,-9,-8,1:3)
Block(-4,-9,-7,1:3)
Block(-4,-9,-6,1:3)
Block(-4,-9,-5,1:3)
Block(-4,-9,-4,1:3)
Block(-4,-9,-3,1:3)
Block(-4,-9,-2,1:1)
Block(-4,-9,-1,1:1)
Block(-4,-9,0,1:1)
Block(-4,-9,1,1:1)
Block(-4,-9,2,1:3)
Block(-4,-9,3,1:3)
Block(-4,-9,4,1:3)
Block(-4,-9,5,1:3)
Block(-4,-9,6,1:3)
Block(-4,-9,7,1:3)
Block(-4,-8,-8,1:3)
Block(-4,-8,-7,1:3)
Block(-4,-8,-6,1:3)
Block(-4,-8,-5,1:3)
Block(-4,-8,-4,1:3)
Block(-4,-8,-3,1:1)
Block(-4,-8,-2,1:1)
Block(-4,-8,-1,1:1)
Block(-4,-8,0,1:1)
Block(-4,-8,1,1:1)
Block(-4,-8,2,1:1)
Block(-4,-8,3,1:3)
Block(-4,-8,4,1:1)
Block(-4,-8,5,1:3)
Block(-4,-8,6,1:3)
Block(-4,-8,7,1:3)
Block(-4,-7,-8,1:3)
Block(-4,-7,-7,1:3)
Block(-4,-7,-6,1:3)
Block(-4,-7,-5,1:3)
Block(-4,-7,-4,1:1)
Block(-4,-7,-3,1:1)
Block(-4,-7,-2,1:1)
Block(-4,-7,-1,1:1)
Block(-4,-7,0,1:1)
Block(-4,-7,1,1:1)
Block(-4,-7,2,1:1)
Block(-4,-7,3,1:1)
Block(-4,-7,4,1:1)
Block(-4,-7,5,1:1)
Block(-4,-7,6,1:3)
Block(-4,-7,7,1:3)
Block(-4,-6,-8,1:3)
Block(-4,-6,-7,1:3)
Block(-4,-6,-6,1:3)
Block(-4,-6,-5,1:1)
Block(-4,-6,-4,1:1)
Block(-4,-6,-3,1:1)
Block(-4,-6,-2,1:1)
Block(-4,-6,-1,1:1)
Block(-4,-6,0,1:1)
Block(-4,-6,1,1:1)
Block(-4,-6,2,1:1)
Block(-4,-6,3,1:1)
Block(-4,-6,4,1:1)
Block(-4,-6,5,1:1)
Block(-4,-6,6,1:1)
Block(-4,-6,7,1:3)
Block(-4,-5,-8,1:1)
Block(-4,-5,-7,1:3)
Block(-4,-5,-6,1:1)
Block(-4,-5,-5,1:1)
Block(-4,-5,-4,1:1)
Block(-4,-5,-3,1:1)
Block(-4,-5,-2,1:1)
Block(-4,-5,-1,1:1)
Block(-4,-5,0,1:1)
Block(-4,-5,1,1:1)
Block(-4,-5,2,1:1)
Block(-4,-5,3,1:1)
Block(-4,-5,4,1:1)
Block(-4,-5,5,1:1)
Block(-4,-5,6,1:1)
Block(-4,-5,7,1:1)
Block(-4,-4,-8,1:1)
Block(-4,-4,-7,1:1)
Block(-4,-4,-6,1:1)
Block(-4,-4,-5,1:1)
Block(-4,-4,-4,1:1)
Block(-4,-4,-3,1:1)
Block(-4,-4,-2,1:1)
Block(-4,-4,-1,1:1)
Block(-4,-4,0,1:1)
Block(-4,-4,1,1:1)
Block(-4,-4,2,1:1)
Block(-4,-4,3,1:1)
Block(-4,-4,4,1:1)
Block(-4,-4,5,1:1)
Block(-4,-4,6,1:1)
Block(-4,-4,7,1:1)
Block(-4,-3,-8,1:1)
Block(-4,-3,-7,1:1)
Block(-4,-3,-6,1:1)
Block(-4,-3,-5,1:1)
Block(-4,-3,-4,1:1)
Block(-4,-3,-3,1:1)
Block(-4,-3,-2,1:1)
Block(-4,-3,-1,1:1)
Block(-4,-3,0,1:1)
Block(-4,-3,1,1:1)
Block(-4,-3,2,1:1)
Block(-4,-3,3,1:1)
Block(-4,-3,4,1:1)
Block(-4,-3,5,1:1)
Block(-4,-3,6,1:1)
Block(-4,-3,7,1:1)
Block(-4,-2,-8,1:1)
Block(-4,-2,-7,1:1)
Block(-4,-2,-6,1:1)
Block(-4,-2,-5,1:1)
Block(-4,-2,-4,1:1)
Block(-4,-2,-3,1:1)
Block(-4,-2,-2,1:1)
Block(-4,-2,-1,1:1)
Block(-4,-2,0,1:1)
Block(-4,-2,1,1:1)
Block(-4,-2,2,1:1)
Block(-4,-2,3,1:1)
Block(-4,-2,4,1:1)
Block(-4,-2,5,1:1)
Block(-4,-2,6,1:1)
Block(-4,-2,7,1:1)
Block(-4,-1,-8,1:1)
Block(-4,-1,-7,1:1)
Block(-4,-1,-6,1:1)
Block(-4,-1,-5,1:1)
Block(-4,-1,-4,1:1)
Block(-4,-1,-3,1:1)
Block(-4,-1,-2,1:1)
Block(-4,-1,-1,1:1)
Block(-4,-1,0,1:1)
Block(-4,-1,1,1:1)
Block(-4,-1,2,1:1)
Block(-4,-1,3,1:1)
Block(-4,-1,4,1:1)
Block(-4,-1,5,1:1)
Block(-4,-1,6,1:1)
Block(-4,-1,7,1:1)
Block(-4,0,-8,1:1)
Block(-4,0,-7,1:1)
Block(-4,0,-6,1:1)
Block(-4,0,-5,1:1)
Block(-4,0,-4,1:1)
Block(-4,0,-3,1:1)
Block(-4,0,-2,1:1)
Block(-4,0,-1,1:1)
Block(-4,0,0,1:1)
Block(-4,0,1,1:1)
Block(-4,0,2,1:1)
Block(-4,0,3,1:1)
Block(-4,0,4,1:1)
Block(-4,0,5,1:1)
Block(-4,0,6,1:1)
Block(-4,0,7,1:1)
Block(-4,1,-8,1:1)
Block(-4,1,-7,1:1)
Block(-4,1,-6,1:1)
Block(-4,1,-5,1:1)
Block(-4,1,-4,1:1)
Block(-4,1,-3,1:1)
Block(-4,1,-2,1:1)
Block(-4,1,-1,1:1)
Block(-4,1,0,1:1)
Block(-4,1,1,1:1)
Block(-4,1,2,1:1)
Block(-4,1,3,1:1)
Block(-4,1,4,1:1)
Block(-4,1,5,1:1)
Block(-4,1,6,1:1)
Block(-4,1,7,1:1)
Block(-4,2,-8,1:1)
Block(-4,2,-7,1:1)
Block(-4,2,-6,1:1)
Block(-4,2,-5,1:1)
Block(-4,2,-4,1:1)
Block(-4,2,-3,1:1)
Block(-4,2,-2,1:1)
Block(-4,2,-1,1:1)
Block(-4,2,0,1:1)
Block(-4,2,1,1:1)
Block(-4,2,2,1:1)
Block(-4,2,3,1:1)
Block(-4,2,4,1:1)
Block(-4,2,5,1:1)
Block(-4,2,6,1:1)
Block(-4,2,7,1:1)
Block(-4,3,-8,1:1)
Block(-4,3,-7,1:1)
Block(-4,3,-6,1:1)
Block(-4,3,-5,1:1)
Block(-4,3,-4,1:1)
Block(-4,3,-3,1:1)
Block(-4,3,-2,1:1)
Block(-4,3,-1,1:1)
Block(-4,3,0,1:1)
Block(-4,3,1,1:1)
Block(-4,3,2,1:1)
Block(-4,3,3,1:1)
Block(-4,3,4,1:1)
Block(-4,3,5,1:1)
Block(-4,3,6,1:3)
Block(-4,3,7,1:3)
Block(-4,4,-8,1:1)
Block(-4,4,-7,1:1)
Block(-4,4,-6,1:1)
Block(-4,4,-5,1:1)
Block(-4,4,-4,1:1)
Block(-4,4,-3,1:1)
Block(-4,4,-2,1:1)
Block(-4,4,-1,1:1)
Block(-4,4,0,1:1)
Block(-4,4,1,1:1)
Block(-4,4,2,1:1)
Block(-4,4,3,1:3)
Block(-4,4,4,1:3)
Block(-4,4,5,1:3)
Block(-4,4,6,1:3)
Block(-4,4,7,1:3)
Block(-4,5,-8,1:1)
Block(-4,5,-7,1:1)
Block(-4,5,-6,1:1)
Block(-4,5,-5,1:1)
Block(-4,5,-4,1:1)
Block(-4,5,-3,1:1)
Block(-4,5,-2,1:1)
Block(-4,5,-1,1:1)
Block(-4,5,0,1:1)
Block(-4,5,1,1:3)
Block(-4,5,2,1:3)
Block(-4,5,3,1:3)
Block(-4,5,4,1:3)
Block(-4,5,5,1:3)
Block(-4,5,6,1:3)
Block(-4,5,7,1:3)
Block(-4,6,-8,1:1)
Block(-4,6,-7,1:1)
Block(-4,6,-6,1:1)
Block(-4,6,-5,1:1)
Block(-4,6,-4,1:1)
Block(-4,6,-3,1:1)
Block(-4,6,-2,1:1)
Block(-4,6,-1,1:1)
Block(-4,6,0,1:3)
Block(-4,6,1,1:3)
Block(-4,6,2,1:3)
Block(-4,6,3,1:3)
Block(-4,6,4,1:3)
Block(-4,6,5,1:3)
Block(-4,6,6,1:3)
Block(-4,6,7,1:3)
Block(-4,7,-8,1:1)
Block(-4,7,-7,1:1)
Block(-4,7,-6,1:1)
Block(-4,7,-5,1:1)
Block(-4,7,-4,1:1)
Block(-4,7,-3,1:1)
Block(-4,7,-2,1:1)
Block(-4,7,-1,1:3)
Block(-4,7,0,1:3)
Block(-4,7,1,1:3)
Block(-4,7,2,1:3)
Block(-4,7,3,1:3)
Block(-4,7,4,1:3)
Block(-4,7,5,1:3)
Block(-4,7,6,1:3)
Block(-4,7,7,1:3)
Block(-4,8,-8,1:1)
Block(-4,8,-7,1:1)
Block(-4,8,-6,1:1)
Block(-4,8,-5,1:1)
Block(-4,8,-4,1:1)
Block(-4,8,-3,1:3)
Block(-4,8,-2,1:1)
Block(-4,8,-1,1:3)
Block(-4,8,0,1:3)
Block(-4,8,1,1:3)
Block(-4,8,2,1:3)
Block(-4,8,3,1:3)
Block(-4,8,4,1:3)
Block(-4,8,5,1:3)
Block(-4,8,6,1:3)
Block(-4,8,7,1:3)
Block(-4,9,-8,1:3)
Block(-4,9,-7,1:3)
Block(-4,9,-6,1:3)
Block(-4,9,-5,1:1)
Block(-4,9,-4,1:3)
Block(-4,9,-3,1:3)
Block(-4,9,-2,1:3)
Block(-4,9,-1,1:3)
Block(-4,9,0,1:3)
Block(-4,9,1,1:3)
Block(-4,9,2,1:3)
Block(-4,9,3,1:1)
Block(-4,9,4,1:1)
Block(-4,9,5,1:1)
Block(-4,9,6,1:3)
Block(-4,9,7,1:3)
Block(-4,10,-8,1:3)
Block(-4,10,-7,1:3)
Block(-4,10,-6,1:3)
Block(-4,10,-5,1:3)
Block(-4,10,-4,1:3)
Block(-4,10,-3,1:3)
Block(-4,10,-2,1:3)
Block(-4,10,-1,1:3)
Block(-4,10,0,1:3)
Block(-4,10,1,1:3)
Block(-4,10,2,1:1)
Block(-4,10,3,1:3)
Block(-4,10,4,1:3)
Block(-4,10,5,1:3)
Block(-4,10,6,1:1)
Block(-4,10,7,1:1)
Block(-4,11,-8,1:3)
Block(-4,11,-7,1:3)
Block(-4,11,-6,1:3)
Block(-4,11,-5,1:3)
Block(-4,11,-4,1:3)
Block(-4,11,-3,1:1)
Block(-4,11,-2,1:3)
Block(-4,11,-1,1:3)
Block(-4,11,0,1:3)
Block(-4,11,1,1:3)
Block(-4,11,2,1:3)
Block(-4,11,3,1:3)
Block(-4,11,4,1:3)
Block(-4,11,5,1:3)
Block(-4,11,6,1:3)
Block(-4,11,7,1:3)
Block(-4,12,-8,1:3)
Block(-4,12,-7,1:3)
Block(-4,12,-6,1:3)
Block(-4,12,-5,1:3)
Block(-4,12,-4,1:3)
Block(-4,12,-3,1:1)
Block(-4,12,-2,1:3)
Block(-4,12,-1,1:3)
Block(-4,12,0,1:3)
Block(-4,12,1,1:3)
Block(-4,12,2,1:3)
Block(-4,12,3,1:3)
Block(-4,12,4,1:3)
Block(-4,12,5,1:3)
Block(-4,12,6,1:3)
Block(-4,12,7,1:3)
Block(-4,13,-8,1:3)
Block(-4,13,-7,1:3)
Block(-4,13,-6,1:3)
Block(-4,13,-5,1:3)
Block(-4,13,-4,1:1)
Block(-4,13,-3,1:1)
Block(-4,13,-2,1:1)
Block(-4,13,-1,1:3)
Block(-4,13,0,1:3)
Block(-4,13,1,1:3)
Block(-4,13,2,1:3)
Block(-4,13,3,1:3)
Block(-4,13,4,1:3)
Block(-4,13,5,1:3)
Block(-4,13,6,1:3)
Block(-4,13,7,1:3)
Block(-4,14,-8,1:3)
Block(-4,14,-7,1:3)
Block(-4,14,-6,1:3)
Block(-4,14,-5,1:1)
Block(-4,14,-4,1:1)
Block(-4,14,-3,1:1)
Block(-4,14,-2,1:1)
Block(-4,14,-1,1:3)
Block(-4,14,0,1:3)
Block(-4,14,1,1:3)
Block(-4,14,2,1:3)
Block(-4,14,3,1:3)
Block(-4,14,4,1:3)
Block(-4,14,5,1:3)
Block(-4,14,6,1:3)
Block(-4,14,7,1:3)
Block(-4,15,-8,1:3)
Block(-4,15,-7,1:3)
Block(-4,15,-6,1:3)
Block(-4,15,-5,1:1)
Block(-4,15,-4,1:1)
Block(-4,15,-3,1:1)
Block(-4,15,-2,1:1)
Block(-4,15,-1,1:3)
Block(-4,15,0,1:3)
Block(-4,15,1,1:3)
Block(-4,15,2,1:3)
Block(-4,15,3,1:3)
Block(-4,15,4,1:3)
Block(-4,15,5,1:3)
Block(-4,15,6,1:3)
Block(-4,15,7,1:3)
Block(-4,16,-8,1:3)
Block(-4,16,-7,1:3)
Block(-4,16,-6,1:3)
Block(-4,16,-5,1:1)
Block(-4,16,-4,1:1)
Block(-4,16,-3,1:1)
Block(-4,16,-2,1:1)
Block(-4,16,-1,1:3)
Block(-4,16,0,1:3)
Block(-4,16,1,1:3)
Block(-4,16,2,1:3)
Block(-4,16,3,1:3)
Block(-4,16,4,1:3)
Block(-4,16,5,1:3)
Block(-4,16,6,1:3)
Block(-4,16,7,1:3)
Block(-4,17,-8,1:3)
Block(-4,17,-7,1:3)
Block(-4,17,-6,1:3)
Block(-4,17,-5,1:1)
Block(-4,17,-4,1:1)
Block(-4,17,-3,1:1)
Block(-4,17,-2,1:1)
Block(-4,17,-1,1:3)
Block(-4,17,0,1:3)
Block(-4,17,1,1:3)
Block(-4,17,2,1:3)
Block(-4,17,3,1:3)
Block(-4,17,4,1:3)
Block(-4,17,5,1:3)
Block(-4,17,6,1:3)
Block(-4,17,7,1:3)
Block(-4,18,-8,1:3)
Block(-4,18,-7,1:3)
Block(-4,18,-6,1:1)
Block(-4,18,-5,1:1)
Block(-4,18,-4,1:1)
Block(-4,18,-3,1:1)
Block(-4,18,-2,1:1)
Block(-4,18,-1,1:3)
Block(-4,18,0,1:3)
Block(-4,18,1,1:3)
Block(-4,18,2,1:3)
Block(-4,18,3,1:3)
Block(-4,18,4,1:3)
Block(-4,18,5,1:3)
Block(-4,18,6,1:3)
Block(-4,18,7,1:3)
Block(-4,19,-8,1:3)
Block(-4,19,-7,1:3)
Block(-4,19,-6,1:3)
Block(-4,19,-5,1:1)
Block(-4,19,-4,1:1)
Block(-4,19,-3,1:1)
Block(-4,19,-2,1:1)
Block(-4,19,-1,1:3)
Block(-4,19,0,1:3)
Block(-4,19,1,1:3)
Block(-4,19,2,1:3)
Block(-4,19,3,1:3)
Block(-4,19,4,1:3)
Block(-4,19,5,1:3)
Block(-4,19,6,1:3)
Block(-4,19,7,1:3)
Block(-4,20,-8,1:3)
Block(-4,20,-7,1:3)
Block(-4,20,-6,1:3)
Block(-4,20,-5,1:3)
Block(-4,20,-4,1:1)
Block(-4,20,-3,1:1)
Block(-4,20,-2,1:1)
Block(-4,20,-1,1:3)
Block(-4,20,0,1:3)
Block(-4,20,1,1:3)
Block(-4,20,2,1:3)
Block(-4,20,3,1:3)
Block(-4,20,4,1:3)
Block(-4,20,5,1:3)
Block(-4,20,6,1:3)
Block(-4,20,7,1:3)
Block(-4,21,-8,1:3)
Block(-4,21,-7,1:3)
Block(-4,21,-6,1:3)
Block(-4,21,-5,1:3)
Block(-4,21,-4,1:3)
Block(-4,21,-3,1:1)
Block(-4,21,-2,1:1)
Block(-4,21,-1,1:1)
Block(-4,21,0,1:1)
Block(-4,21,1,1:3)
Block(-4,21,2,1:3)
Block(-4,21,3,1:3)
Block(-4,21,4,1:3)
Block(-4,21,5,1:3)
Block(-4,21,6,1:3)
Block(-4,21,7,1:3)
Block(-4,22,-8,1:3)
Block(-4,22,-7,1:3)
Block(-4,22,-6,1:3)
Block(-4,22,-5,1:3)
Block(-4,22,-4,1:3)
Block(-4,22,-3,1:3)
Block(-4,22,-2,1:1)
Block(-4,22,-1,1:3)
Block(-4,22,0,1:1)
Block(-4,22,1,1:1)
Block(-4,22,2,1:1)
Block(-4,22,3,1:3)
Block(-4,22,4,1:1)
Block(-4,22,5,1:3)
Block(-4,22,6,1:3)
Block(-4,22,7,1:3)
Block(-4,23,-8,1:3)
Block(-4,23,-7,1:1)
Block(-4,23,-6,1:3)
Block(-4,23,-5,1:1)
Block(-4,23,-4,1:3)
Block(-4,23,-3,1:3)
Block(-4,23,-2,1:3)
Block(-4,23,-1,1:3)
Block(-4,23,0,1:3)
Block(-4,23,1,1:1)
Block(-4,23,2,1:1)
Block(-4,23,3,1:1)
Block(-4,23,4,1:1)
Block(-4,23,5,1:3)
Block(-4,23,6,1:1)
Block(-4,23,7,1:3)
Block(-4,24,-8,1:1)
Block(-4,24,-7,1:1)
Block(-4,24,-6,1:1)
Block(-4,24,-5,1:1)
Block(-4,24,-4,1:3)
Block(-4,24,-3,1:3)
Block(-4,24,-2,1:3)
Block(-4,24,-1,1:3)
Block(-4,24,0,1:3)
Block(-4,24,1,1:3)
Block(-4,24,2,1:1)
Block(-4,24,3,1:1)
Block(-4,24,4,1:1)
Block(-4,24,5,1:1)
Block(-4,24,6,1:1)
Block(-4,24,7,1:1)
Block(-4,25,-8,1:1)
Block(-4,25,-7,1:1)
Block(-4,25,-6,1:1)
Block(-4,25,-5,1:1)
Block(-4,25,-4,1:3)
Block(-4,25,-3,1:3)
Block(-4,25,-2,1:3)
Block(-4,25,-1,1:3)
Block(-4,25,0,1:3)
