#######################################################################
# +-----------------------------------------------------------------+ #
# |                            BO3 object                           | #
# +-----------------------------------------------------------------+ #
#######################################################################

# The descriptions in this file are accurate only for TerrainControl and OTG.
# For MCW and OTG+ these descriptions are only accurate if the BO3 is used as a CustomObject.
# MCW and OTG+ completely reimplemented CustomStructure, check the MCW/OTG+ documentation for more information.

# This is the config file of a custom object.
# If you add this object correctly to your BiomeConfigs, it will spawn in the world.

# This is the creator of this BO3 object
Author: Unknown

# A short description of this BO3 object
Description: This BO3 was converted from a schematic using OTGEdit. The author and description information of the schematic could not be found. If you know who the author of the schematic is then please add this information.

# The BO3 version, don't change this! It can be used by external applications to do a version check.
Version: 3

# The settings mode, WriteAll, WriteWithoutComments or WriteDisable. See WorldConfig.
SettingsMode: WriteDisable

#######################################################################
# +-----------------------------------------------------------------+ #
# |                          Main settings                          | #
# +-----------------------------------------------------------------+ #
#######################################################################

# This needs to be set to true to spawn the object in the Tree and Sapling resources.
Tree: true

# The frequency of the BO3 from 1 to 200. Tries this many times to spawn this BO3 when using the CustomObject(...) resource.
# Ignored by Tree(..), Sapling(..) and CustomStructure(..)
Frequency: 1

# The rarity of the BO3 from 0 to 100. Each spawn attempt has rarity% chance to succeed when using the CustomObject(...) resource.
# Ignored by Tree(..), Sapling(..) and CustomStructure(..)
Rarity: 33.0

# If you set this to true, the BO3 will be placed with a random rotation.
RotateRandomly: true

# The spawn height of the BO3 - randomY, highestBlock or highestSolidBlock.
SpawnHeight: highestSolidBlock

# The height limits for the BO3.
MinHeight: 63

MaxHeight: 75

# Objects can have other objects attached to it: branches. Branches can also
# have branches attached to it, which can also have branches, etc. This is the
# maximum branch depth for this objects.
MaxBranchDepth: 10

# When spawned with the UseWorld keyword, this BO3 should NOT spawn in the following biomes.
# If you writer.write the BO3 name directly in the BiomeConfigs, this will be ignored.
ExcludedBiomes: All

# To optimise this BO3 for faster loading times you can use Notepad++ to find/replace comments and abbreviate things.
# Notepad++ find/replace with regex:
# Find: ^[#;].* replace to nothing removes all lines starting with # 
# Find: ^\s*$ replace to nothing removes most empty lines 
# Notepad++ find/replace without regex:
# *Warning: This will only work for OTG 1.10.2 v21 / OTG 1.11.2 v6 or higher. B( is not recognised by lower versions.
# Find: Block( replace to B(

#######################################################################
# +-----------------------------------------------------------------+ #
# |                      Source block settings                      | #
# +-----------------------------------------------------------------+ #
#######################################################################

# The block(s) the BO3 should spawn in.
SourceBlocks: STONE:1,STONE:3,STONE:5,DIRT:1,DIRT,SAND,GRASS,DIRT:2,STATIONARY_WATER,HARD_CLAY,STAINED_CLAY,CLAY,SANDSTONE,SAND:1,AIR,STONE,GRAVEL,LONG_GRASS,LONG_GRASS:1,LONG_GRASS:2,DEAD_BUSH,YELLOW_FLOWER,RED_ROSE,BROWN_MUSHROOM,RED_MUSHROOM,LEAVES,LOG

# The maximum percentage of the BO3 that can be outside the SourceBlock.
# The BO3 won't be placed on a location with more blocks outside the SourceBlock than this percentage.
MaxPercentageOutsideSourceBlock: 50

# What to do when a block is about to be placed outside the SourceBlock? (dontPlace, placeAnyway)
OutsideSourceBlock: placeAnyway

#######################################################################
# +-----------------------------------------------------------------+ #
# |                              Blocks                             | #
# +-----------------------------------------------------------------+ #
#######################################################################

# All the blocks used in the BO3 are listed here. Possible blocks:
# Block(x,y,z,id[.data][,nbtfile.nbt) or B(x,y,z,id[.data][,nbtfile.nbt)
# RandomBlock(x,y,z,id[:data][,nbtfile.nbt],chance[,id[:data][,nbtfile.nbt],chance[,...]])
# So RandomBlock(0,0,0,CHEST,chest.nbt,50,CHEST,anotherchest.nbt,100) will spawn a chest at
# the BO3 origin, and give it a 50% chance to have the contents of chest.nbt, or, if that
# fails, a 100% percent chance to have the contents of anotherchest.nbt.

Block(-12,14,-2,106:8)
Block(-12,15,-2,106:8)
Block(-12,16,-2,106:8)
Block(-12,17,-2,106:8)
Block(-12,18,-2,106:8)
Block(-12,19,-2,106:8)
Block(-12,20,-2,106:8)
Block(-12,21,-2,106:8)
Block(-12,22,-2,106:8)
Block(-12,23,-2,106:8)
Block(-12,24,-2,106:8)
Block(-12,25,-3,18:3)
Block(-12,25,-2,18:3)
Block(-12,25,-1,18:3)
Block(-12,26,-2,18:3)
Block(-11,15,0,106:8)
Block(-11,16,0,106:8)
Block(-11,17,0,106:8)
Block(-11,18,0,106:8)
Block(-11,19,0,106:8)
Block(-11,20,0,106:8)
Block(-11,21,0,106:8)
Block(-11,22,-1,106)
Block(-11,22,0,106:8)
Block(-11,23,-3,18:3)
Block(-11,23,-2,18:3)
Block(-11,23,-1,18:3)
Block(-11,23,0,106:8)
Block(-11,24,-3,106:1)
Block(-11,24,-2,18:3)
Block(-11,25,-4,18:3)
Block(-11,25,-3,18:3)
Block(-11,25,-2,18:3)
Block(-11,25,-1,18:3)
Block(-11,25,0,18:3)
Block(-11,26,-3,18:3)
Block(-11,26,-2,18:3)
Block(-11,26,-1,18:3)
Block(-10,23,-4,18:3)
Block(-10,23,-3,18:3)
Block(-10,23,-2,18:3)
Block(-10,23,-1,18:3)
Block(-10,23,0,18:3)
Block(-10,24,-4,106)
Block(-10,24,-3,18:3)
Block(-10,24,-2,18:3)
Block(-10,24,-1,18:3)
Block(-10,25,-4,18:3)
Block(-10,25,-3,18:3)
Block(-10,25,-2,17:15)
Block(-10,25,-1,18:3)
Block(-10,25,0,18:3)
Block(-10,26,-4,18:3)
Block(-10,26,-3,18:3)
Block(-10,26,-2,18:3)
Block(-10,26,-1,18:3)
Block(-10,26,0,18:3)
Block(-9,17,10,106:8)
Block(-9,18,-5,106:1)
Block(-9,18,10,106:8)
Block(-9,19,-5,106:1)
Block(-9,19,8,106:8)
Block(-9,19,10,106:8)
Block(-9,20,-5,106:1)
Block(-9,20,8,106:8)
Block(-9,20,10,106:8)
Block(-9,21,-5,106:1)
Block(-9,21,8,106:8)
Block(-9,21,10,106:8)
Block(-9,22,-5,106:1)
Block(-9,22,8,106:8)
Block(-9,22,10,106:8)
Block(-9,23,-5,106:1)
Block(-9,23,-4,18:3)
Block(-9,23,-3,18:3)
Block(-9,23,-2,17:15)
Block(-9,23,-1,18:3)
Block(-9,23,0,18:3)
Block(-9,23,8,106:8)
Block(-9,23,10,106:8)
Block(-9,24,-5,106:1)
Block(-9,24,-4,18:3)
Block(-9,24,-3,18:3)
Block(-9,24,-2,18:3)
Block(-9,24,-1,18:3)
Block(-9,24,0,18:3)
Block(-9,24,8,106:8)
Block(-9,24,10,106:8)
Block(-9,25,-4,18:3)
Block(-9,25,-3,18:3)
Block(-9,25,-2,18:3)
Block(-9,25,-1,18:3)
Block(-9,25,0,18:3)
Block(-9,26,-3,18:3)
Block(-9,26,-2,18:3)
Block(-9,26,-1,18:3)
Block(-8,14,7,106:8)
Block(-8,15,7,106:8)
Block(-8,16,7,106:8)
Block(-8,17,3,106:8)
Block(-8,17,7,106:8)
Block(-8,18,3,106:8)
Block(-8,18,7,106:8)
Block(-8,19,3,106:8)
Block(-8,19,7,106:8)
Block(-8,20,3,106:8)
Block(-8,20,7,106:8)
Block(-8,21,3,106:8)
Block(-8,21,7,106:8)
Block(-8,22,3,106:8)
Block(-8,22,7,106:8)
Block(-8,23,-4,18:3)
Block(-8,23,-3,18:3)
Block(-8,23,-2,18:3)
Block(-8,23,-1,18:3)
Block(-8,23,0,18:3)
Block(-8,23,3,106:8)
Block(-8,23,7,106:8)
Block(-8,24,-3,18:3)
Block(-8,24,-2,18:3)
Block(-8,24,-1,18:3)
Block(-8,24,3,106:8)
Block(-8,24,7,106:8)
Block(-8,24,8,18:3)
Block(-8,24,9,18:3)
Block(-8,24,10,18:3)
Block(-8,25,-3,18:3)
Block(-8,25,-2,18:3)
Block(-8,25,-1,18:3)
Block(-8,25,0,18:3)
Block(-8,25,1,18:3)
Block(-8,25,9,18:3)
Block(-8,26,-2,18:3)
Block(-8,26,0,18:3)
Block(-8,28,-1,18:3)
Block(-8,28,0,18:3)
Block(-8,28,1,18:3)
Block(-8,29,0,18:3)
Block(-7,16,4,106:8)
Block(-7,17,4,106:8)
Block(-7,18,4,106:8)
Block(-7,19,-5,106:1)
Block(-7,19,4,106:8)
Block(-7,20,-5,106:1)
Block(-7,20,4,106:8)
Block(-7,21,-5,106:1)
Block(-7,21,4,106:8)
Block(-7,22,-5,106:1)
Block(-7,22,4,106:8)
Block(-7,23,-5,106:1)
Block(-7,23,-4,18:3)
Block(-7,23,-3,18:3)
Block(-7,23,-2,17:15)
Block(-7,23,-1,18:3)
Block(-7,23,0,18:3)
Block(-7,23,4,106:8)
Block(-7,24,-5,106:1)
Block(-7,24,-4,18:3)
Block(-7,24,-3,18:3)
Block(-7,24,-2,18:3)
Block(-7,24,-1,18:3)
Block(-7,24,0,18:3)
Block(-7,24,1,18:3)
Block(-7,24,2,18:3)
Block(-7,24,3,18:3)
Block(-7,24,4,106:8)
Block(-7,24,7,18:3)
Block(-7,24,8,18:3)
Block(-7,24,9,18:3)
Block(-7,24,10,18:3)
Block(-7,24,11,18:3)
Block(-7,25,-2,18:3)
Block(-7,25,-1,18:3)
Block(-7,25,0,18:3)
Block(-7,25,1,18:3)
Block(-7,25,2,18:3)
Block(-7,25,8,18:3)
Block(-7,25,9,18:3)
Block(-7,25,10,18:3)
Block(-7,26,-1,18:3)
Block(-7,26,0,18:3)
Block(-7,26,1,18:3)
Block(-7,27,0,18:3)
Block(-7,28,-2,18:3)
Block(-7,28,-1,18:3)
Block(-7,28,0,18:3)
Block(-7,28,1,18:3)
Block(-7,28,2,18:3)
Block(-7,29,-1,18:3)
Block(-7,29,0,18:3)
Block(-7,29,1,18:3)
Block(-6,16,-5,106:1)
Block(-6,16,12,106:4)
Block(-6,17,-5,106:1)
Block(-6,17,12,106:4)
Block(-6,18,-5,106:1)
Block(-6,18,12,106:4)
Block(-6,19,-5,106:1)
Block(-6,19,12,106:4)
Block(-6,20,-5,106:1)
Block(-6,20,12,106:4)
Block(-6,21,-5,106:1)
Block(-6,21,12,106:4)
Block(-6,22,-5,106:1)
Block(-6,22,12,106:4)
Block(-6,23,-5,106:1)
Block(-6,23,-4,18:3)
Block(-6,23,-3,18:3)
Block(-6,23,-2,18:3)
Block(-6,23,-1,18:3)
Block(-6,23,0,18:3)
Block(-6,23,12,106:4)
Block(-6,24,-5,106:1)
Block(-6,24,-4,18:3)
Block(-6,24,-3,18:3)
Block(-6,24,-2,18:3)
Block(-6,24,-1,18:3)
Block(-6,24,0,18:3)
Block(-6,24,1,18:3)
Block(-6,24,2,18:3)
Block(-6,24,3,18:3)
Block(-6,24,4,18:3)
Block(-6,24,7,18:3)
Block(-6,24,8,18:3)
Block(-6,24,9,17:15)
Block(-6,24,10,18:3)
Block(-6,24,11,18:3)
Block(-6,24,12,106:4)
Block(-6,25,-3,18:3)
Block(-6,25,-2,18:3)
Block(-6,25,-1,18:3)
Block(-6,25,0,17:15)
Block(-6,25,1,18:3)
Block(-6,25,2,18:3)
Block(-6,25,3,18:3)
Block(-6,25,4,18:3)
Block(-6,25,7,18:3)
Block(-6,25,8,18:3)
Block(-6,25,9,18:3)
Block(-6,25,10,18:3)
Block(-6,25,11,18:3)
Block(-6,26,-2,18:3)
Block(-6,26,-1,18:3)
Block(-6,26,0,18:3)
Block(-6,26,1,18:3)
Block(-6,26,2,18:3)
Block(-6,26,3,18:3)
Block(-6,26,6,18:3)
Block(-6,26,7,18:3)
Block(-6,26,8,18:3)
Block(-6,27,-4,18:3)
Block(-6,27,-3,18:3)
Block(-6,27,-2,18:3)
Block(-6,27,-1,18:3)
Block(-6,27,0,18:3)
Block(-6,27,1,18:3)
Block(-6,27,7,18:3)
Block(-6,28,-3,18:3)
Block(-6,28,-2,18:3)
Block(-6,28,-1,18:3)
Block(-6,28,0,17:15)
Block(-6,28,1,18:3)
Block(-6,28,2,18:3)
Block(-6,29,-2,18:3)
Block(-6,29,-1,18:3)
Block(-6,29,0,18:3)
Block(-6,29,1,18:3)
Block(-6,29,2,18:3)
Block(-5,16,12,106:4)
Block(-5,17,12,106:4)
Block(-5,18,12,106:4)
Block(-5,19,12,106:4)
Block(-5,20,12,106:4)
Block(-5,21,12,106:4)
Block(-5,22,12,106:4)
Block(-5,23,-3,18:3)
Block(-5,23,-2,18:3)
Block(-5,23,-1,18:3)
Block(-5,23,5,18:3)
Block(-5,23,6,18:3)
Block(-5,23,7,18:3)
Block(-5,23,12,106:4)
Block(-5,24,-5,18:3)
Block(-5,24,-4,18:3)
Block(-5,24,-3,18:3)
Block(-5,24,-2,18:3)
Block(-5,24,-1,18:3)
Block(-5,24,0,18:3)
Block(-5,24,1,18:3)
Block(-5,24,2,17:15)
Block(-5,24,3,18:3)
Block(-5,24,4,18:3)
Block(-5,24,5,106:1)
Block(-5,24,6,18:3)
Block(-5,24,7,18:3)
Block(-5,24,8,18:3)
Block(-5,24,9,18:3)
Block(-5,24,10,18:3)
Block(-5,24,11,18:3)
Block(-5,24,12,106:4)
Block(-5,25,-4,18:3)
Block(-5,25,-3,18:3)
Block(-5,25,-2,18:3)
Block(-5,25,-1,17:15)
Block(-5,25,0,18:3)
Block(-5,25,1,18:3)
Block(-5,25,2,18:3)
Block(-5,25,3,18:3)
Block(-5,25,4,18:3)
Block(-5,25,5,18:3)
Block(-5,25,8,18:3)
Block(-5,25,9,18:3)
Block(-5,25,10,18:3)
Block(-5,26,-3,18:3)
Block(-5,26,-2,18:3)
Block(-5,26,-1,18:3)
Block(-5,26,0,17:15)
Block(-5,26,1,18:3)
Block(-5,26,2,18:3)
Block(-5,26,3,18:3)
Block(-5,26,4,18:3)
Block(-5,26,5,18:3)
Block(-5,26,6,18:3)
Block(-5,26,7,18:3)
Block(-5,26,8,18:3)
Block(-5,26,9,18:3)
Block(-5,27,-5,18:3)
Block(-5,27,-4,18:3)
Block(-5,27,-3,18:3)
Block(-5,27,-2,18:3)
Block(-5,27,-1,18:3)
Block(-5,27,0,17:15)
Block(-5,27,1,18:3)
Block(-5,27,2,18:3)
Block(-5,27,6,18:3)
Block(-5,27,7,18:3)
Block(-5,27,8,18:3)
Block(-5,28,-4,18:3)
Block(-5,28,-3,18:3)
Block(-5,28,-2,18:3)
Block(-5,28,-1,18:3)
Block(-5,28,0,18:3)
Block(-5,28,1,18:3)
Block(-5,28,2,18:3)
Block(-5,29,-1,18:3)
Block(-5,29,0,18:3)
Block(-5,29,1,18:3)
Block(-4,13,-11,106:1)
Block(-4,14,-11,106:1)
Block(-4,15,-11,106:1)
Block(-4,16,-11,106:1)
Block(-4,17,-11,106:1)
Block(-4,18,-11,106:1)
Block(-4,19,-11,106:1)
Block(-4,20,-11,106:1)
Block(-4,21,-11,106:1)
Block(-4,22,-11,106:1)
Block(-4,23,-11,106:1)
Block(-4,23,-2,17:15)
Block(-4,23,4,18:3)
Block(-4,23,5,18:3)
Block(-4,23,6,18:3)
Block(-4,23,7,18:3)
Block(-4,23,8,18:3)
Block(-4,24,-11,106:1)
Block(-4,24,-10,18:3)
Block(-4,24,-9,18:3)
Block(-4,24,-8,18:3)
Block(-4,24,-5,18:3)
Block(-4,24,-4,18:3)
Block(-4,24,-3,17:15)
Block(-4,24,-2,18:3)
Block(-4,24,-1,17:15)
Block(-4,24,0,18:3)
Block(-4,24,1,18:3)
Block(-4,24,2,18:3)
Block(-4,24,3,18:3)
Block(-4,24,4,18:3)
Block(-4,24,5,18:3)
Block(-4,24,6,17:15)
Block(-4,24,7,18:3)
Block(-4,24,8,18:3)
Block(-4,24,9,18:3)
Block(-4,24,10,18:3)
Block(-4,25,-9,18:3)
Block(-4,25,-5,18:3)
Block(-4,25,-4,18:3)
Block(-4,25,-3,18:3)
Block(-4,25,-2,18:3)
Block(-4,25,-1,18:3)
Block(-4,25,0,18:3)
Block(-4,25,1,18:3)
Block(-4,25,2,18:3)
Block(-4,25,3,17:15)
Block(-4,25,4,18:3)
Block(-4,25,5,18:3)
Block(-4,25,7,17:15)
Block(-4,25,9,18:3)
Block(-4,26,-6,18:3)
Block(-4,26,-5,18:3)
Block(-4,26,-4,18:3)
Block(-4,26,-2,17:15)
Block(-4,26,-1,18:3)
Block(-4,26,0,17:15)
Block(-4,26,1,18:3)
Block(-4,26,2,18:3)
Block(-4,26,3,18:3)
Block(-4,26,4,18:3)
Block(-4,26,5,18:3)
Block(-4,26,6,18:3)
Block(-4,26,7,17:15)
Block(-4,26,8,18:3)
Block(-4,26,9,18:3)
Block(-4,27,-5,18:3)
Block(-4,27,-4,18:3)
Block(-4,27,-3,17:15)
Block(-4,27,-2,18:3)
Block(-4,27,-1,18:3)
Block(-4,27,0,18:3)
Block(-4,27,1,18:3)
Block(-4,27,5,18:3)
Block(-4,27,6,18:3)
Block(-4,27,7,18:3)
Block(-4,27,8,18:3)
Block(-4,27,9,18:3)
Block(-4,28,-5,18:3)
Block(-4,28,-4,18:3)
Block(-4,28,-3,18:3)
Block(-4,28,-2,18:3)
Block(-4,28,-1,18:3)
Block(-4,28,0,18:3)
Block(-4,28,1,18:3)
Block(-4,28,2,18:3)
Block(-4,28,3,18:3)
Block(-4,28,4,18:3)
Block(-4,29,-3,18:3)
Block(-4,29,-2,18:3)
Block(-4,29,-1,18:3)
Block(-4,29,0,18:3)
Block(-4,29,3,18:3)
Block(-4,30,-2,18:3)
Block(-4,30,-1,18:3)
Block(-3,16,-12,106:1)
Block(-3,17,-12,106:1)
Block(-3,18,-12,106:1)
Block(-3,19,-12,106:1)
Block(-3,20,-12,106:1)
Block(-3,21,-12,106:1)
Block(-3,22,-12,106:1)
Block(-3,22,-2,17:15)
Block(-3,22,4,17:15)
Block(-3,23,-12,106:1)
Block(-3,23,-11,18:3)
Block(-3,23,-10,18:3)
Block(-3,23,-9,18:3)
Block(-3,23,4,18:3)
Block(-3,23,5,17:15)
Block(-3,23,6,17:15)
Block(-3,23,7,18:3)
Block(-3,23,8,18:3)
Block(-3,24,-12,106:1)
Block(-3,24,-11,18:3)
Block(-3,24,-10,18:3)
Block(-3,24,-9,18:3)
Block(-3,24,-8,18:3)
Block(-3,24,-7,18:3)
Block(-3,24,-5,18:3)
Block(-3,24,-4,18:3)
Block(-3,24,-3,18:3)
Block(-3,24,-2,18:3)
Block(-3,24,-1,18:3)
Block(-3,24,0,18:3)
Block(-3,24,1,18:3)
Block(-3,24,2,18:3)
Block(-3,24,3,18:3)
Block(-3,24,4,18:3)
Block(-3,24,5,18:3)
Block(-3,24,6,18:3)
Block(-3,24,7,18:3)
Block(-3,24,8,18:3)
Block(-3,25,-10,18:3)
Block(-3,25,-9,18:3)
Block(-3,25,-8,18:3)
Block(-3,25,-6,18:3)
Block(-3,25,-5,18:3)
Block(-3,25,-4,18:3)
Block(-3,25,-3,18:3)
Block(-3,25,-2,18:3)
Block(-3,25,-1,17:15)
Block(-3,25,0,17:15)
Block(-3,25,1,18:3)
Block(-3,25,2,18:3)
Block(-3,25,3,18:3)
Block(-3,25,4,18:3)
Block(-3,25,5,18:3)
Block(-3,26,-7,18:3)
Block(-3,26,-6,18:3)
Block(-3,26,-5,18:3)
Block(-3,26,-4,18:3)
Block(-3,26,-3,18:3)
Block(-3,26,-1,18:3)
Block(-3,26,0,18:3)
Block(-3,26,1,18:3)
Block(-3,26,2,18:3)
Block(-3,26,3,18:3)
Block(-3,26,4,18:3)
Block(-3,26,5,18:3)
Block(-3,26,6,18:3)
Block(-3,26,7,17:15)
Block(-3,26,8,18:3)
Block(-3,26,9,18:3)
Block(-3,27,-6,18:3)
Block(-3,27,-5,18:3)
Block(-3,27,-4,18:3)
Block(-3,27,-3,17:15)
Block(-3,27,-2,17:15)
Block(-3,27,-1,18:3)
Block(-3,27,0,18:3)
Block(-3,27,2,18:3)
Block(-3,27,3,18:3)
Block(-3,27,4,18:3)
Block(-3,27,5,18:3)
Block(-3,27,6,18:3)
Block(-3,27,7,18:3)
Block(-3,27,8,18:3)
Block(-3,27,9,18:3)
Block(-3,28,-5,18:3)
Block(-3,28,-4,18:3)
Block(-3,28,-3,18:3)
Block(-3,28,-2,18:3)
Block(-3,28,-1,18:3)
Block(-3,28,0,18:3)
Block(-3,28,1,18:3)
Block(-3,28,2,18:3)
Block(-3,28,3,18:3)
Block(-3,28,4,18:3)
Block(-3,28,5,18:3)
Block(-3,29,-4,18:3)
Block(-3,29,-3,18:3)
Block(-3,29,-2,18:3)
Block(-3,29,-1,18:3)
Block(-3,29,0,18:3)
Block(-3,29,1,18:3)
Block(-3,29,2,18:3)
Block(-3,29,3,18:3)
Block(-3,29,4,18:3)
Block(-3,30,-3,18:3)
Block(-3,30,-2,18:3)
Block(-3,30,-1,18:3)
Block(-3,30,0,18:3)
Block(-3,30,1,18:3)
Block(-3,30,3,18:3)
Block(-2,13,12,106:8)
Block(-2,14,12,106:8)
Block(-2,15,12,106:8)
Block(-2,16,12,106:8)
Block(-2,17,12,106:8)
Block(-2,18,12,106:8)
Block(-2,19,12,106:8)
Block(-2,20,-5,17:15)
Block(-2,20,-1,17:15)
Block(-2,20,3,17:15)
Block(-2,20,12,106:8)
Block(-2,21,-6,17:15)
Block(-2,21,-1,17:15)
Block(-2,21,4,17:15)
Block(-2,21,12,106:8)
Block(-2,22,-7,17:15)
Block(-2,22,12,106:8)
Block(-2,23,-12,18:3)
Block(-2,23,-11,18:3)
Block(-2,23,-10,18:3)
Block(-2,23,-9,18:3)
Block(-2,23,-8,17:15)
Block(-2,23,-5,18:3)
Block(-2,23,-4,18:3)
Block(-2,23,-3,18:3)
Block(-2,23,4,18:3)
Block(-2,23,5,18:3)
Block(-2,23,6,18:3)
Block(-2,23,7,18:3)
Block(-2,23,8,18:3)
Block(-2,23,12,106:8)
Block(-2,24,-12,106:1)
Block(-2,24,-11,18:3)
Block(-2,24,-10,18:3)
Block(-2,24,-9,17:15)
Block(-2,24,-8,18:3)
Block(-2,24,-7,18:3)
Block(-2,24,-4,18:3)
Block(-2,24,-3,18:3)
Block(-2,24,-2,18:3)
Block(-2,24,-1,17:15)
Block(-2,24,0,17:15)
Block(-2,24,5,18:3)
Block(-2,24,6,18:3)
Block(-2,24,7,18:3)
Block(-2,25,-11,18:3)
Block(-2,25,-10,18:3)
Block(-2,25,-9,18:3)
Block(-2,25,-8,18:3)
Block(-2,25,-7,18:3)
Block(-2,25,-6,18:3)
Block(-2,25,-5,18:3)
Block(-2,25,-4,17:15)
Block(-2,25,-3,18:3)
Block(-2,25,-2,18:3)
Block(-2,25,-1,18:3)
Block(-2,25,2,18:3)
Block(-2,25,3,18:3)
Block(-2,25,4,18:3)
Block(-2,26,-7,18:3)
Block(-2,26,-6,18:3)
Block(-2,26,-5,17:15)
Block(-2,26,-4,18:3)
Block(-2,26,-3,18:3)
Block(-2,26,-2,18:3)
Block(-2,26,0,18:3)
Block(-2,26,1,18:3)
Block(-2,26,2,18:3)
Block(-2,26,3,18:3)
Block(-2,26,4,18:3)
Block(-2,26,5,18:3)
Block(-2,26,6,18:3)
Block(-2,26,7,18:3)
Block(-2,26,8,18:3)
Block(-2,26,9,18:3)
Block(-2,27,-7,18:3)
Block(-2,27,-6,18:3)
Block(-2,27,-5,18:3)
Block(-2,27,-4,18:3)
Block(-2,27,-3,18:3)
Block(-2,27,-2,18:3)
Block(-2,27,-1,18:3)
Block(-2,27,0,18:3)
Block(-2,27,1,18:3)
Block(-2,27,2,18:3)
Block(-2,27,3,18:3)
Block(-2,27,4,18:3)
Block(-2,27,5,18:3)
Block(-2,27,6,18:3)
Block(-2,27,7,18:3)
Block(-2,27,8,18:3)
Block(-2,28,-4,18:3)
Block(-2,28,-3,18:3)
Block(-2,28,-2,18:3)
Block(-2,28,-1,18:3)
Block(-2,28,0,18:3)
Block(-2,28,1,18:3)
Block(-2,28,2,18:3)
Block(-2,28,3,17:15)
Block(-2,28,4,18:3)
Block(-2,28,5,18:3)
Block(-2,28,6,18:3)
Block(-2,29,-6,18:3)
Block(-2,29,-5,18:3)
Block(-2,29,-4,18:3)
Block(-2,29,-3,18:3)
Block(-2,29,-2,17:15)
Block(-2,29,-1,17:15)
Block(-2,29,0,18:3)
Block(-2,29,1,18:3)
Block(-2,29,2,18:3)
Block(-2,29,3,18:3)
Block(-2,29,4,18:3)
Block(-2,29,5,18:3)
Block(-2,30,-5,18:3)
Block(-2,30,-4,18:3)
Block(-2,30,-3,18:3)
Block(-2,30,-2,18:3)
Block(-2,30,-1,18:3)
Block(-2,30,0,18:3)
Block(-2,30,1,18:3)
Block(-2,30,2,18:3)
Block(-2,30,3,18:3)
Block(-2,30,4,18:3)
Block(-1,13,0,17:15)
Block(-1,13,15,106:8)
Block(-1,14,-1,17:15)
Block(-1,14,15,106:8)
Block(-1,15,-2,17:15)
Block(-1,15,15,106:8)
Block(-1,16,-13,106:1)
Block(-1,16,-3,17:15)
Block(-1,16,-1,17:15)
Block(-1,16,15,106:8)
Block(-1,17,-13,106:1)
Block(-1,17,-4,17:15)
Block(-1,17,-2,17:15)
Block(-1,17,15,106:8)
Block(-1,18,-13,106:1)
Block(-1,18,-5,17:15)
Block(-1,18,-3,17:15)
Block(-1,18,1,17:15)
Block(-1,18,15,106:8)
Block(-1,19,-13,106:1)
Block(-1,19,-6,17:15)
Block(-1,19,-4,17:15)
Block(-1,19,0,17:15)
Block(-1,19,2,17:15)
Block(-1,19,15,106:8)
Block(-1,20,-13,106:1)
Block(-1,20,-7,17:15)
Block(-1,20,15,106:8)
Block(-1,21,-13,106:1)
Block(-1,21,-8,17:15)
Block(-1,21,15,106:8)
Block(-1,22,-13,106:1)
Block(-1,22,-9,17:15)
Block(-1,22,15,106:8)
Block(-1,23,-13,106:1)
Block(-1,23,-12,18:3)
Block(-1,23,-11,18:3)
Block(-1,23,-10,17:15)
Block(-1,23,-9,18:3)
Block(-1,23,-8,18:3)
Block(-1,23,-6,18:3)
Block(-1,23,-5,18:3)
Block(-1,23,-4,18:3)
Block(-1,23,-3,18:3)
Block(-1,23,-2,18:3)
Block(-1,23,0,17:15)
Block(-1,23,4,18:3)
Block(-1,23,5,18:3)
Block(-1,23,6,17:15)
Block(-1,23,7,18:3)
Block(-1,23,8,18:3)
Block(-1,23,9,18:3)
Block(-1,23,10,18:3)
Block(-1,23,12,18:3)
Block(-1,23,13,18:3)
Block(-1,23,14,18:3)
Block(-1,23,15,106:8)
Block(-1,24,-12,18:3)
Block(-1,24,-11,18:3)
Block(-1,24,-10,18:3)
Block(-1,24,-9,18:3)
Block(-1,24,-8,18:3)
Block(-1,24,-7,18:3)
Block(-1,24,-5,18:3)
Block(-1,24,-4,18:3)
Block(-1,24,-3,18:3)
Block(-1,24,4,18:3)
Block(-1,24,5,18:3)
Block(-1,24,6,18:3)
Block(-1,24,7,18:3)
Block(-1,24,8,18:3)
Block(-1,24,13,18:3)
Block(-1,25,-10,18:3)
Block(-1,25,-9,18:3)
Block(-1,25,-8,18:3)
Block(-1,25,-6,18:3)
Block(-1,25,-5,18:3)
Block(-1,25,-4,18:3)
Block(-1,25,-3,18:3)
Block(-1,25,-2,18:3)
Block(-1,25,3,18:3)
Block(-1,25,4,18:3)
Block(-1,25,5,18:3)
Block(-1,25,6,18:3)
Block(-1,25,7,18:3)
Block(-1,26,-7,18:3)
Block(-1,26,-6,18:3)
Block(-1,26,-5,18:3)
Block(-1,26,-4,18:3)
Block(-1,26,-3,18:3)
Block(-1,26,0,18:3)
Block(-1,26,1,18:3)
Block(-1,26,2,17:15)
Block(-1,26,3,17:15)
Block(-1,26,4,18:3)
Block(-1,26,5,18:3)
Block(-1,26,6,18:3)
Block(-1,26,7,18:3)
Block(-1,26,8,18:3)
Block(-1,27,-6,18:3)
Block(-1,27,-5,18:3)
Block(-1,27,-4,18:3)
Block(-1,27,-3,18:3)
Block(-1,27,-2,18:3)
Block(-1,27,-1,18:3)
Block(-1,27,0,18:3)
Block(-1,27,1,18:3)
Block(-1,27,2,18:3)
Block(-1,27,3,17:15)
Block(-1,27,4,18:3)
Block(-1,27,5,17:15)
Block(-1,27,6,18:3)
Block(-1,27,7,18:3)
Block(-1,28,-4,18:3)
Block(-1,28,-3,18:3)
Block(-1,28,-2,18:3)
Block(-1,28,-1,18:3)
Block(-1,28,0,18:3)
Block(-1,28,1,18:3)
Block(-1,28,2,17:15)
Block(-1,28,3,18:3)
Block(-1,28,4,18:3)
Block(-1,28,5,18:3)
Block(-1,28,6,18:3)
Block(-1,28,7,18:3)
Block(-1,29,-7,18:3)
Block(-1,29,-6,18:3)
Block(-1,29,-5,18:3)
Block(-1,29,-4,18:3)
Block(-1,29,-3,18:3)
Block(-1,29,-2,18:3)
Block(-1,29,-1,18:3)
Block(-1,29,0,18:3)
Block(-1,29,1,17:15)
Block(-1,29,2,18:3)
Block(-1,29,3,17:15)
Block(-1,29,4,18:3)
Block(-1,29,5,18:3)
Block(-1,29,6,18:3)
Block(-1,30,-6,18:3)
Block(-1,30,-5,18:3)
Block(-1,30,-4,18:3)
Block(-1,30,-3,18:3)
Block(-1,30,-2,18:3)
Block(-1,30,-1,18:3)
Block(-1,30,0,18:3)
Block(-1,30,1,18:3)
Block(-1,30,2,18:3)
Block(-1,30,3,18:3)
Block(-1,30,4,18:3)
Block(-1,30,5,18:3)
Block(0,0,0,17:15)
Block(0,1,0,17:15)
Block(0,2,0,17:15)
Block(0,3,0,17:15)
Block(0,4,0,17:15)
Block(0,5,0,17:15)
Block(0,6,0,17:15)
Block(0,7,0,17:15)
Block(0,8,0,17:15)
Block(0,9,0,17:15)
Block(0,10,0,17:15)
Block(0,11,0,17:15)
Block(0,12,0,17:15)
Block(0,12,1,17:15)
Block(0,13,0,17:15)
Block(0,14,0,17:15)
Block(0,15,0,17:15)
Block(0,16,0,17:15)
Block(0,16,1,17:15)
Block(0,17,0,17:15)
Block(0,18,0,17:15)
Block(0,19,0,17:15)
Block(0,20,0,17:15)
Block(0,21,0,17:15)
Block(0,22,0,17:15)
Block(0,23,-12,18:3)
Block(0,23,-11,18:3)
Block(0,23,-10,18:3)
Block(0,23,-9,18:3)
Block(0,23,-8,18:3)
Block(0,23,-6,18:3)
Block(0,23,-5,18:3)
Block(0,23,-4,17:15)
Block(0,23,-3,18:3)
Block(0,23,-2,18:3)
Block(0,23,0,17:15)
Block(0,23,1,17:15)
Block(0,23,3,18:3)
Block(0,23,4,18:3)
Block(0,23,5,18:3)
Block(0,23,6,18:3)
Block(0,23,7,18:3)
Block(0,23,8,18:3)
Block(0,23,9,18:3)
Block(0,23,10,18:3)
Block(0,23,11,18:3)
Block(0,23,12,18:3)
Block(0,23,13,18:3)
Block(0,23,14,18:3)
Block(0,23,15,18:3)
Block(0,24,-11,18:3)
Block(0,24,-10,18:3)
Block(0,24,-9,18:3)
Block(0,24,-8,18:3)
Block(0,24,-6,18:3)
Block(0,24,-5,18:3)
Block(0,24,-4,18:3)
Block(0,24,-3,18:3)
Block(0,24,-2,18:3)
Block(0,24,0,17:15)
Block(0,24,4,18:3)
Block(0,24,5,18:3)
Block(0,24,6,18:3)
Block(0,24,7,18:3)
Block(0,24,8,18:3)
Block(0,24,9,18:3)
Block(0,24,10,18:3)
Block(0,24,12,18:3)
Block(0,24,13,18:3)
Block(0,24,14,18:3)
Block(0,24,15,106:8)
Block(0,25,-9,18:3)
Block(0,25,-5,18:3)
Block(0,25,-4,18:3)
Block(0,25,-3,18:3)
Block(0,25,-1,17:15)
Block(0,25,0,17:15)
Block(0,25,2,18:3)
Block(0,25,3,18:3)
Block(0,25,4,18:3)
Block(0,25,5,18:3)
Block(0,25,6,18:3)
Block(0,25,7,18:3)
Block(0,25,8,18:3)
Block(0,26,-6,18:3)
Block(0,26,-5,18:3)
Block(0,26,-4,18:3)
Block(0,26,-2,17:15)
Block(0,26,0,17:15)
Block(0,26,1,18:3)
Block(0,26,2,18:3)
Block(0,26,3,18:3)
Block(0,26,4,18:3)
Block(0,26,5,18:3)
Block(0,26,6,18:3)
Block(0,26,7,18:3)
Block(0,27,-5,18:3)
Block(0,27,-4,18:3)
Block(0,27,-3,17:15)
Block(0,27,-2,18:3)
Block(0,27,-1,18:3)
Block(0,27,1,17:15)
Block(0,27,2,18:3)
Block(0,27,3,18:3)
Block(0,27,4,17:15)
Block(0,27,5,18:3)
Block(0,27,6,18:3)
Block(0,27,7,18:3)
Block(0,28,-5,18:3)
Block(0,28,-4,18:3)
Block(0,28,-3,18:3)
Block(0,28,-2,17:15)
Block(0,28,-1,18:3)
Block(0,28,0,18:3)
Block(0,28,1,18:3)
Block(0,28,2,18:3)
Block(0,28,3,18:3)
Block(0,28,4,18:3)
Block(0,28,5,17:15)
Block(0,28,6,18:3)
Block(0,28,7,18:3)
Block(0,29,-7,18:3)
Block(0,29,-6,18:3)
Block(0,29,-5,17:15)
Block(0,29,-4,18:3)
Block(0,29,-3,18:3)
Block(0,29,-2,18:3)
Block(0,29,-1,18:3)
Block(0,29,0,18:3)
Block(0,29,1,18:3)
Block(0,29,2,18:3)
Block(0,29,3,18:3)
Block(0,29,4,18:3)
Block(0,29,5,18:3)
Block(0,29,6,18:3)
Block(0,29,7,18:3)
Block(0,30,-7,18:3)
Block(0,30,-6,18:3)
Block(0,30,-5,18:3)
Block(0,30,-4,18:3)
Block(0,30,-3,18:3)
Block(0,30,-2,18:3)
Block(0,30,-1,18:3)
Block(0,30,0,18:3)
Block(0,30,1,18:3)
Block(0,30,2,18:3)
Block(0,30,3,18:3)
Block(0,30,4,18:3)
Block(1,17,1,17:15)
Block(1,18,-12,106:2)
Block(1,19,-12,106:2)
Block(1,20,-12,106:2)
Block(1,21,-12,106:2)
Block(1,22,-12,106:2)
Block(1,23,-12,106:2)
Block(1,23,-11,18:3)
Block(1,23,-10,18:3)
Block(1,23,-9,18:3)
Block(1,23,-6,18:3)
Block(1,23,-5,18:3)
Block(1,23,-4,18:3)
Block(1,23,-3,18:3)
Block(1,23,-2,18:3)
Block(1,23,3,18:3)
Block(1,23,4,18:3)
Block(1,23,5,17:15)
Block(1,23,6,18:3)
Block(1,23,7,18:3)
Block(1,23,9,17:15)
Block(1,23,10,18:3)
Block(1,23,11,18:3)
Block(1,23,12,18:3)
Block(1,23,13,17:15)
Block(1,23,14,18:3)
Block(1,23,15,18:3)
Block(1,24,-10,18:3)
Block(1,24,-5,18:3)
Block(1,24,-4,18:3)
Block(1,24,-3,18:3)
Block(1,24,-2,18:3)
Block(1,24,-1,18:3)
Block(1,24,1,17:15)
Block(1,24,2,17:15)
Block(1,24,3,18:3)
Block(1,24,4,18:3)
Block(1,24,5,18:3)
Block(1,24,6,18:3)
Block(1,24,7,18:3)
Block(1,24,8,18:3)
Block(1,24,9,18:3)
Block(1,24,10,18:3)
Block(1,24,11,18:3)
Block(1,24,12,18:3)
Block(1,24,13,18:3)
Block(1,24,14,18:3)
Block(1,24,15,18:3)
Block(1,25,-2,18:3)
Block(1,25,2,18:3)
Block(1,25,3,17:15)
Block(1,25,4,17:15)
Block(1,25,5,18:3)
Block(1,25,6,17:15)
Block(1,25,7,18:3)
Block(1,25,8,18:3)
Block(1,26,-6,18:3)
Block(1,26,-5,18:3)
Block(1,26,-4,18:3)
Block(1,26,-1,18:3)
Block(1,26,0,18:3)
Block(1,26,1,17:15)
Block(1,26,2,18:3)
Block(1,26,3,18:3)
Block(1,26,4,18:3)
Block(1,26,5,18:3)
Block(1,26,6,18:3)
Block(1,26,7,18:3)
Block(1,26,8,18:3)
Block(1,27,-6,18:3)
Block(1,27,-5,18:3)
Block(1,27,-4,18:3)
Block(1,27,-3,17:15)
Block(1,27,-2,18:3)
Block(1,27,-1,18:3)
Block(1,27,0,18:3)
Block(1,27,2,18:3)
Block(1,27,3,18:3)
Block(1,27,4,18:3)
Block(1,27,5,18:3)
Block(1,27,6,18:3)
Block(1,28,-6,18:3)
Block(1,28,-5,18:3)
Block(1,28,-4,18:3)
Block(1,28,-3,17:15)
Block(1,28,-2,18:3)
Block(1,28,-1,18:3)
Block(1,28,0,18:3)
Block(1,28,1,17:15)
Block(1,28,2,18:3)
Block(1,28,3,18:3)
Block(1,28,4,18:3)
Block(1,28,5,18:3)
Block(1,28,6,18:3)
Block(1,28,7,18:3)
Block(1,29,-7,18:3)
Block(1,29,-6,18:3)
Block(1,29,-5,18:3)
Block(1,29,-4,18:3)
Block(1,29,-3,18:3)
Block(1,29,-2,18:3)
Block(1,29,-1,18:3)
Block(1,29,0,17:15)
Block(1,29,1,18:3)
Block(1,29,2,18:3)
Block(1,29,3,18:3)
Block(1,29,4,18:3)
Block(1,29,5,18:3)
Block(1,29,6,18:3)
Block(1,30,-6,18:3)
Block(1,30,-5,18:3)
Block(1,30,-4,18:3)
Block(1,30,-2,18:3)
Block(1,30,-1,18:3)
Block(1,30,0,18:3)
Block(1,30,1,18:3)
Block(1,30,2,18:3)
Block(1,30,3,18:3)
Block(2,18,2,17:15)
Block(2,23,-5,18:3)
Block(2,23,-4,18:3)
Block(2,23,-3,18:3)
Block(2,23,3,18:3)
Block(2,23,4,18:3)
Block(2,23,5,18:3)
Block(2,23,6,18:3)
Block(2,23,7,18:3)
Block(2,23,8,18:3)
Block(2,23,9,18:3)
Block(2,23,10,18:3)
Block(2,23,11,18:3)
Block(2,23,12,18:3)
Block(2,23,13,18:3)
Block(2,23,14,18:3)
Block(2,23,15,18:3)
Block(2,24,-4,18:3)
Block(2,24,-3,18:3)
Block(2,24,-2,18:3)
Block(2,24,-1,18:3)
Block(2,24,0,18:3)
Block(2,24,1,18:3)
Block(2,24,2,18:3)
Block(2,24,3,18:3)
Block(2,24,4,18:3)
Block(2,24,5,18:3)
Block(2,24,6,18:3)
Block(2,24,8,18:3)
Block(2,24,9,18:3)
Block(2,24,10,18:3)
Block(2,24,12,18:3)
Block(2,24,13,18:3)
Block(2,24,14,18:3)
Block(2,24,15,106:4)
Block(2,25,-3,18:3)
Block(2,25,-2,18:3)
Block(2,25,-1,18:3)
Block(2,25,0,18:3)
Block(2,25,1,18:3)
Block(2,25,2,17:15)
Block(2,25,3,18:3)
Block(2,25,4,18:3)
Block(2,25,5,18:3)
Block(2,25,6,18:3)
Block(2,25,7,18:3)
Block(2,25,8,18:3)
Block(2,26,-7,18:3)
Block(2,26,-6,18:3)
Block(2,26,-5,18:3)
Block(2,26,-4,18:3)
Block(2,26,-3,18:3)
Block(2,26,-2,18:3)
Block(2,26,-1,18:3)
Block(2,26,0,18:3)
Block(2,26,1,18:3)
Block(2,26,2,18:3)
Block(2,26,3,17:15)
Block(2,26,4,17:15)
Block(2,26,5,18:3)
Block(2,26,6,18:3)
Block(2,26,7,18:3)
Block(2,27,-6,18:3)
Block(2,27,-5,18:3)
Block(2,27,-4,17:15)
Block(2,27,-3,18:3)
Block(2,27,-2,18:3)
Block(2,27,-1,18:3)
Block(2,27,0,18:3)
Block(2,27,1,17:15)
Block(2,27,2,18:3)
Block(2,27,3,18:3)
Block(2,27,4,18:3)
Block(2,27,5,18:3)
Block(2,27,6,18:3)
Block(2,28,-6,18:3)
Block(2,28,-5,18:3)
Block(2,28,-4,17:15)
Block(2,28,-3,18:3)
Block(2,28,-2,18:3)
Block(2,28,-1,18:3)
Block(2,28,0,18:3)
Block(2,28,1,18:3)
Block(2,28,2,18:3)
Block(2,28,3,18:3)
Block(2,28,4,17:15)
Block(2,28,5,18:3)
Block(2,28,6,18:3)
Block(2,29,-6,18:3)
Block(2,29,-5,18:3)
Block(2,29,-4,18:3)
Block(2,29,-3,18:3)
Block(2,29,-2,18:3)
Block(2,29,-1,18:3)
Block(2,29,0,17:15)
Block(2,29,1,17:15)
Block(2,29,2,18:3)
Block(2,29,3,18:3)
Block(2,29,4,18:3)
Block(2,29,5,18:3)
Block(2,29,6,18:3)
Block(2,30,-5,18:3)
Block(2,30,-2,18:3)
Block(2,30,-1,18:3)
Block(2,30,0,18:3)
Block(2,30,1,18:3)
Block(2,30,2,18:3)
Block(2,30,3,18:3)
Block(3,19,2,17:15)
Block(3,23,4,18:3)
Block(3,23,5,18:3)
Block(3,23,6,18:3)
Block(3,23,8,18:3)
Block(3,23,9,18:3)
Block(3,23,10,18:3)
Block(3,23,11,18:3)
Block(3,23,12,18:3)
Block(3,23,13,18:3)
Block(3,23,14,18:3)
Block(3,24,-4,18:3)
Block(3,24,-3,18:3)
Block(3,24,-2,17:15)
Block(3,24,-1,18:3)
Block(3,24,0,18:3)
Block(3,24,1,18:3)
Block(3,24,2,17:15)
Block(3,24,3,18:3)
Block(3,24,4,18:3)
Block(3,24,5,18:3)
Block(3,24,10,18:3)
Block(3,24,13,18:3)
Block(3,24,14,106:4)
Block(3,25,-4,18:3)
Block(3,25,-3,18:3)
Block(3,25,-2,18:3)
Block(3,25,-1,18:3)
Block(3,25,0,18:3)
Block(3,25,1,18:3)
Block(3,25,2,18:3)
Block(3,25,3,18:3)
Block(3,25,4,18:3)
Block(3,25,5,18:3)
Block(3,25,6,18:3)
Block(3,25,7,18:3)
Block(3,26,-7,18:3)
Block(3,26,-6,18:3)
Block(3,26,-5,17:15)
Block(3,26,-4,18:3)
Block(3,26,-3,18:3)
Block(3,26,-2,18:3)
Block(3,26,-1,18:3)
Block(3,26,0,17:15)
Block(3,26,1,18:3)
Block(3,26,2,17:15)
Block(3,26,3,18:3)
Block(3,26,4,18:3)
Block(3,26,5,18:3)
Block(3,26,6,18:3)
Block(3,27,-7,18:3)
Block(3,27,-6,18:3)
Block(3,27,-5,18:3)
Block(3,27,-4,18:3)
Block(3,27,-3,18:3)
Block(3,27,-2,18:3)
Block(3,27,-1,18:3)
Block(3,27,0,18:3)
Block(3,27,1,18:3)
Block(3,27,2,18:3)
Block(3,27,3,18:3)
Block(3,27,4,18:3)
Block(3,27,5,18:3)
Block(3,28,-6,18:3)
Block(3,28,-5,18:3)
Block(3,28,-4,18:3)
Block(3,28,-3,18:3)
Block(3,28,-2,18:3)
Block(3,28,-1,18:3)
Block(3,28,0,18:3)
Block(3,28,1,17:15)
Block(3,28,2,18:3)
Block(3,28,3,18:3)
Block(3,28,4,18:3)
Block(3,28,5,18:3)
Block(3,28,6,18:3)
Block(3,29,-5,18:3)
Block(3,29,-4,18:3)
Block(3,29,-3,18:3)
Block(3,29,-2,18:3)
Block(3,29,-1,18:3)
Block(3,29,0,17:15)
Block(3,29,1,18:3)
Block(3,29,2,18:3)
Block(3,29,3,18:3)
Block(3,29,4,18:3)
Block(3,29,5,18:3)
Block(3,30,-2,18:3)
Block(3,30,-1,18:3)
Block(3,30,0,18:3)
Block(3,30,1,18:3)
Block(3,30,2,18:3)
Block(4,17,13,106:4)
Block(4,18,13,106:4)
Block(4,19,13,106:4)
Block(4,20,3,17:15)
Block(4,20,13,106:4)
Block(4,21,3,17:15)
Block(4,21,13,106:4)
Block(4,22,13,106:4)
Block(4,23,8,18:3)
Block(4,23,9,18:3)
Block(4,23,10,18:3)
Block(4,23,11,18:3)
Block(4,23,12,18:3)
Block(4,23,13,106:4)
Block(4,24,-4,18:3)
Block(4,24,-3,18:3)
Block(4,24,-2,18:3)
Block(4,24,-1,18:3)
Block(4,24,0,18:3)
Block(4,24,1,18:3)
Block(4,24,2,17:15)
Block(4,24,3,18:3)
Block(4,24,4,18:3)
Block(4,24,5,18:3)
Block(4,24,9,18:3)
Block(4,24,10,18:3)
Block(4,24,11,18:3)
Block(4,25,-3,18:3)
Block(4,25,-2,18:3)
Block(4,25,-1,17:15)
Block(4,25,0,18:3)
Block(4,25,1,18:3)
Block(4,25,2,18:3)
Block(4,25,3,18:3)
Block(4,25,4,18:3)
Block(4,25,5,18:3)
Block(4,25,6,18:3)
Block(4,26,-7,18:3)
Block(4,26,-6,18:3)
Block(4,26,-5,18:3)
Block(4,26,-4,18:3)
Block(4,26,-3,18:3)
Block(4,26,-2,18:3)
Block(4,26,-1,18:3)
Block(4,26,0,18:3)
Block(4,26,1,18:3)
Block(4,26,2,18:3)
Block(4,26,3,18:3)
Block(4,26,4,18:3)
Block(4,26,5,18:3)
Block(4,27,-6,18:3)
Block(4,27,-5,18:3)
Block(4,27,-4,18:3)
Block(4,27,-3,18:3)
Block(4,27,-1,18:3)
Block(4,27,0,18:3)
Block(4,27,1,18:3)
Block(4,27,2,18:3)
Block(4,27,3,18:3)
Block(4,27,4,18:3)
Block(4,28,-5,18:3)
Block(4,28,-4,18:3)
Block(4,28,-3,18:3)
Block(4,28,-1,18:3)
Block(4,28,0,18:3)
Block(4,28,1,18:3)
Block(4,28,2,18:3)
Block(4,28,3,18:3)
Block(4,28,4,18:3)
Block(4,28,5,18:3)
Block(4,29,-4,18:3)
Block(4,29,-2,18:3)
Block(4,29,-1,18:3)
Block(4,29,0,18:3)
Block(4,29,1,17:15)
Block(4,29,2,18:3)
Block(4,29,3,18:3)
Block(4,29,4,18:3)
Block(4,30,-1,18:3)
Block(4,30,0,18:3)
Block(4,30,1,18:3)
Block(4,30,2,18:3)
Block(4,30,3,18:3)
Block(5,19,13,106:4)
Block(5,20,13,106:4)
Block(5,21,13,106:4)
Block(5,22,4,17:15)
Block(5,22,13,106:4)
Block(5,23,-6,18:3)
Block(5,23,-5,18:3)
Block(5,23,-4,18:3)
Block(5,23,8,18:3)
Block(5,23,9,18:3)
Block(5,23,10,17:15)
Block(5,23,11,18:3)
Block(5,23,12,18:3)
Block(5,23,13,106:4)
Block(5,24,-5,18:3)
Block(5,24,-3,18:3)
Block(5,24,-2,18:3)
Block(5,24,-1,17:15)
Block(5,24,0,18:3)
Block(5,24,1,18:3)
Block(5,24,2,18:3)
Block(5,24,3,18:3)
Block(5,24,4,18:3)
Block(5,24,5,18:3)
Block(5,24,6,18:3)
Block(5,24,8,18:3)
Block(5,24,9,18:3)
Block(5,24,10,18:3)
Block(5,24,11,18:3)
Block(5,24,12,18:3)
Block(5,24,13,106:4)
Block(5,25,-3,18:3)
Block(5,25,-2,18:3)
Block(5,25,-1,18:3)
Block(5,25,0,18:3)
Block(5,25,1,18:3)
Block(5,25,2,18:3)
Block(5,25,3,18:3)
Block(5,25,4,17:15)
Block(5,25,5,18:3)
Block(5,25,6,18:3)
Block(5,26,-6,18:3)
Block(5,26,-5,18:3)
Block(5,26,-4,18:3)
Block(5,26,-2,18:3)
Block(5,26,-1,18:3)
Block(5,26,0,18:3)
Block(5,26,1,18:3)
Block(5,26,2,18:3)
Block(5,26,3,18:3)
Block(5,26,4,18:3)
Block(5,26,5,18:3)
Block(5,26,6,18:3)
Block(5,27,-5,18:3)
Block(5,27,-1,18:3)
Block(5,27,0,18:3)
Block(5,27,1,18:3)
Block(5,27,2,18:3)
Block(5,28,0,18:3)
Block(5,28,1,18:3)
Block(5,28,2,18:3)
Block(5,29,-1,18:3)
Block(5,29,0,18:3)
Block(5,29,1,18:3)
Block(5,29,2,18:3)
Block(5,29,3,18:3)
Block(5,30,0,18:3)
Block(5,30,1,18:3)
Block(5,30,2,18:3)
Block(6,14,-8,106:1)
Block(6,15,-8,106:1)
Block(6,16,-8,106:1)
Block(6,17,-8,106:1)
Block(6,18,-8,106:1)
Block(6,19,-8,106:1)
Block(6,20,-8,106:1)
Block(6,21,-8,106:1)
Block(6,22,-8,106:1)
Block(6,23,-8,106:1)
Block(6,23,-7,18:3)
Block(6,23,-6,18:3)
Block(6,23,-5,18:3)
Block(6,23,-4,18:3)
Block(6,23,-3,18:3)
Block(6,23,4,17:15)
Block(6,23,7,18:3)
Block(6,23,8,18:3)
Block(6,23,9,18:3)
Block(6,23,10,18:3)
Block(6,23,11,18:3)
Block(6,23,12,18:3)
Block(6,24,-6,18:3)
Block(6,24,-5,18:3)
Block(6,24,-4,18:3)
Block(6,24,-3,18:3)
Block(6,24,-2,18:3)
Block(6,24,-1,18:3)
Block(6,24,0,18:3)
Block(6,24,1,18:3)
Block(6,24,2,18:3)
Block(6,24,3,18:3)
Block(6,24,4,17:15)
Block(6,24,5,18:3)
Block(6,24,6,18:3)
Block(6,24,8,18:3)
Block(6,24,9,18:3)
Block(6,24,10,18:3)
Block(6,24,11,18:3)
Block(6,25,-2,18:3)
Block(6,25,-1,18:3)
Block(6,25,0,18:3)
Block(6,25,1,18:3)
Block(6,25,2,18:3)
Block(6,25,3,18:3)
Block(6,25,4,18:3)
Block(6,25,5,18:3)
Block(6,25,6,18:3)
Block(6,26,-1,18:3)
Block(6,26,0,18:3)
Block(6,26,1,18:3)
Block(6,26,3,18:3)
Block(6,26,4,18:3)
Block(6,26,5,18:3)
Block(6,27,-2,18:3)
Block(6,27,-1,18:3)
Block(6,27,0,18:3)
Block(6,27,1,18:3)
Block(6,27,2,18:3)
Block(6,28,-1,18:3)
Block(6,28,0,18:3)
Block(6,28,1,18:3)
Block(6,29,0,18:3)
Block(6,29,1,18:3)
Block(6,29,2,18:3)
Block(6,30,1,18:3)
Block(7,14,12,106:6)
Block(7,15,1,106:4)
Block(7,15,12,106:6)
Block(7,16,1,106:4)
Block(7,16,12,106:6)
Block(7,17,1,106:4)
Block(7,17,12,106:6)
Block(7,18,1,106:4)
Block(7,18,12,106:6)
Block(7,19,1,106:4)
Block(7,19,12,106:6)
Block(7,20,1,106:4)
Block(7,20,12,106:6)
Block(7,21,1,106:4)
Block(7,21,12,106:6)
Block(7,22,1,106:4)
Block(7,22,12,106:6)
Block(7,23,-7,18:3)
Block(7,23,-6,18:3)
Block(7,23,-5,17:15)
Block(7,23,-4,18:3)
Block(7,23,-3,18:3)
Block(7,23,1,106:4)
Block(7,23,7,18:3)
Block(7,23,8,18:3)
Block(7,23,9,17:15)
Block(7,23,10,18:3)
Block(7,23,11,18:3)
Block(7,23,12,106:6)
Block(7,24,-7,18:3)
Block(7,24,-6,18:3)
Block(7,24,-5,18:3)
Block(7,24,-4,18:3)
Block(7,24,-3,18:3)
Block(7,24,-2,18:3)
Block(7,24,-1,18:3)
Block(7,24,0,18:3)
Block(7,24,1,106:4)
Block(7,24,2,18:3)
Block(7,24,3,18:3)
Block(7,24,4,18:3)
Block(7,24,5,17:15)
Block(7,24,6,18:3)
Block(7,24,7,18:3)
Block(7,24,8,18:3)
Block(7,24,9,18:3)
Block(7,24,10,18:3)
Block(7,24,11,18:3)
Block(7,24,12,106:4)
Block(7,25,-2,18:3)
Block(7,25,-1,18:3)
Block(7,25,0,17:15)
Block(7,25,1,18:3)
Block(7,25,2,18:3)
Block(7,25,3,18:3)
Block(7,25,4,18:3)
Block(7,25,5,18:3)
Block(7,25,6,18:3)
Block(7,25,7,18:3)
Block(7,26,-2,18:3)
Block(7,26,-1,18:3)
Block(7,26,0,18:3)
Block(7,26,1,18:3)
Block(7,26,2,18:3)
Block(7,26,4,18:3)
Block(7,26,5,18:3)
Block(7,26,6,18:3)
Block(7,27,-2,18:3)
Block(7,27,-1,18:3)
Block(7,27,0,17:15)
Block(7,27,1,18:3)
Block(7,27,2,18:3)
Block(7,28,-2,18:3)
Block(7,28,-1,18:3)
Block(7,28,0,18:3)
Block(7,28,1,18:3)
Block(7,28,2,18:3)
Block(8,18,6,106:4)
Block(8,19,6,106:4)
Block(8,20,0,106:2)
Block(8,20,6,106:4)
Block(8,21,0,106:2)
Block(8,21,6,106:4)
Block(8,22,0,106:2)
Block(8,22,6,106:4)
Block(8,23,-7,18:3)
Block(8,23,-6,18:3)
Block(8,23,-5,18:3)
Block(8,23,-4,18:3)
Block(8,23,-3,18:3)
Block(8,23,0,106:2)
Block(8,23,6,106:4)
Block(8,23,7,18:3)
Block(8,23,8,18:3)
Block(8,23,9,18:3)
Block(8,23,10,18:3)
Block(8,23,11,18:3)
Block(8,24,-6,18:3)
Block(8,24,-5,18:3)
Block(8,24,-4,18:3)
Block(8,24,0,106:2)
Block(8,24,3,18:3)
Block(8,24,4,18:3)
Block(8,24,5,18:3)
Block(8,24,6,106:4)
Block(8,24,7,106)
Block(8,24,8,18:3)
Block(8,24,9,18:3)
Block(8,24,10,18:3)
Block(8,24,11,106:4)
Block(8,25,-2,18:3)
Block(8,25,-1,18:3)
Block(8,25,0,18:3)
Block(8,25,1,18:3)
Block(8,25,2,18:3)
Block(8,25,3,18:3)
Block(8,25,4,18:3)
Block(8,25,5,17:15)
Block(8,25,6,18:3)
Block(8,25,7,18:3)
Block(8,26,-1,18:3)
Block(8,26,0,18:3)
Block(8,26,1,18:3)
Block(8,26,3,18:3)
Block(8,26,4,18:3)
Block(8,26,5,18:3)
Block(8,26,6,18:3)
Block(8,26,7,18:3)
Block(8,27,-2,18:3)
Block(8,27,-1,18:3)
Block(8,27,0,18:3)
Block(8,27,1,18:3)
Block(8,27,2,18:3)
Block(8,28,-1,18:3)
Block(8,28,0,18:3)
Block(8,28,1,18:3)
Block(9,13,-3,106:2)
Block(9,14,-7,106:2)
Block(9,14,-3,106:2)
Block(9,15,-7,106:2)
Block(9,15,-3,106:2)
Block(9,15,4,106:2)
Block(9,15,5,106:2)
Block(9,16,-7,106:2)
Block(9,16,-3,106:2)
Block(9,16,4,106:2)
Block(9,16,5,106:2)
Block(9,17,-7,106:2)
Block(9,17,-3,106:2)
Block(9,17,4,106:2)
Block(9,17,5,106:2)
Block(9,18,-7,106:2)
Block(9,18,-3,106:2)
Block(9,18,4,106:2)
Block(9,18,5,106:2)
Block(9,19,-7,106:2)
Block(9,19,-3,106:2)
Block(9,19,4,106:2)
Block(9,19,5,106:2)
Block(9,20,-7,106:2)
Block(9,20,-3,106:2)
Block(9,20,4,106:2)
Block(9,20,5,106:2)
Block(9,21,-7,106:2)
Block(9,21,-3,106:2)
Block(9,21,4,106:2)
Block(9,21,5,106:2)
Block(9,22,-7,106:2)
Block(9,22,-3,106:2)
Block(9,22,4,106:2)
Block(9,22,5,106:2)
Block(9,23,-7,106:2)
Block(9,23,-6,18:3)
Block(9,23,-5,18:3)
Block(9,23,-4,18:3)
Block(9,23,-3,106:2)
Block(9,23,4,106:2)
Block(9,23,5,106:2)
Block(9,23,8,18:3)
Block(9,23,9,18:3)
Block(9,23,10,18:3)
Block(9,24,-5,18:3)
Block(9,24,4,106:2)
Block(9,24,5,106:2)
Block(9,24,9,18:3)
Block(9,24,10,106:4)
Block(9,25,-1,18:3)
Block(9,25,0,18:3)
Block(9,25,1,18:3)
Block(9,25,3,18:3)
Block(9,25,4,18:3)
Block(9,25,5,18:3)
Block(9,25,6,18:3)
Block(9,25,7,18:3)
Block(9,26,0,18:3)
Block(9,26,4,18:3)
Block(9,26,5,18:3)
Block(9,26,6,18:3)
Block(9,27,-1,18:3)
Block(9,27,0,18:3)
Block(9,27,1,18:3)
Block(9,28,0,18:3)
Block(10,15,-5,106:2)
Block(10,16,-5,106:2)
Block(10,16,-4,106:2)
Block(10,17,-5,106:2)
Block(10,17,-4,106:2)
Block(10,17,9,106:2)
Block(10,18,-5,106:2)
Block(10,18,-4,106:2)
Block(10,18,9,106:2)
Block(10,19,-5,106:2)
Block(10,19,-4,106:2)
Block(10,19,9,106:2)
Block(10,20,-5,106:2)
Block(10,20,-4,106:2)
Block(10,20,9,106:2)
Block(10,21,-5,106:2)
Block(10,21,-4,106:2)
Block(10,21,9,106:2)
Block(10,22,-5,106:2)
Block(10,22,-4,106:2)
Block(10,22,9,106:2)
Block(10,23,-5,106:2)
Block(10,23,-4,106:2)
Block(10,23,9,106:2)
Block(10,24,-5,106:2)
Block(10,24,9,106:2)
Block(10,25,4,18:3)
Block(10,25,5,18:3)
Block(10,25,6,18:3)
Block(10,26,5,18:3)


#######################################################################
# +-----------------------------------------------------------------+ #
# |                             Entities                            | #
# +-----------------------------------------------------------------+ #
#######################################################################

# Entity() spawns an entity instead of a block. The entity is spawned only once when the BO3 is spawned.
# Entities are persistent by default so they don't de-spawn when no player is near, they are only unloaded.
# Usage: Entity(x,y,z,mobName,groupSize,NameTagOrNBTFileName) or Entity(x,y,z,mobName,groupSize)
# Use /tc entities or /otg entities to get a list of entities that can be used as mobName, this includes entities added by other mods.
# NameTagOrNBTFileName can be either a nametag for the mob or an nbt file (such as mymobinfo.nbt or mymobinfo.txt).
# When using a text file you can use the same mob spawning parameters used with the /summon command to equip the
# entity and give it custom attributes etc. You can copy the DATA part of a summon command including surrounding
# curly braces to a .txt file, for instance for: "/summon Skeleton x y z {DATA}"

#######################################################################
# +-----------------------------------------------------------------+ #
# |                            BO3 checks                           | #
# +-----------------------------------------------------------------+ #
#######################################################################

# Require a condition at a certain location in order for the BO3 to be spawned.
# BlockCheck(x,y,z,BlockName[,BlockName[,...]]) - one of the blocks must be at the location
# BlockCheckNot(x,y,z,BlockName[,BlockName[,...]]) - all the blocks must not be at the location
# LightCheck(x,y,z,minLightLevel,maxLightLevel) - light must be between min and max (inclusive)

# You can use "Solid" as a BlockName for matching all solid blocks or "All" to match all blocks that aren't air.

# Examples:
#   BlockCheck(0,-1,0,GRASS,DIRT)  Require grass or dirt just below the object
#   BlockCheck(0,-1,0,Solid)       Require any solid block just below the object
#   BlockCheck(0,-1,0,WOOL)        Require any type of wool just below the object
#   BlockCheck(0,-1,0,WOOL:0)      Require white wool just below the object
#   BlockCheckNot(0,-1,0,WOOL:0)   Require that there is no white wool below the object
#   LightCheck(0,0,0,0,1)          Require almost complete darkness just below the object

BlockCheck(0,-1,0,GRASS,DIRT)
BlockCheckNot(0,0,0,STATIONARY_LAVA)