#######################################################################
# +-----------------------------------------------------------------+ #
# |                            BO3 object                           | #
# +-----------------------------------------------------------------+ #
#######################################################################

# The descriptions in this file are accurate only for TerrainControl and OTG.
# For MCW and OTG+ these descriptions are only accurate if the BO3 is used as a CustomObject.
# MCW and OTG+ completely reimplemented CustomStructure, check the MCW/OTG+ documentation for more information.

# This is the config file of a custom object.
# If you add this object correctly to your BiomeConfigs, it will spawn in the world.

# This is the creator of this BO3 object
Author: Unknown

# A short description of this BO3 object
Description: This BO3 was converted from a schematic using OTGEdit. The author and description information of the schematic could not be found. If you know who the author of the schematic is then please add this information.

# The BO3 version, don't change this! It can be used by external applications to do a version check.
Version: 3

# The settings mode, WriteAll, WriteWithoutComments or WriteDisable. See WorldConfig.
SettingsMode: WriteDisable

#######################################################################
# +-----------------------------------------------------------------+ #
# |                          Main settings                          | #
# +-----------------------------------------------------------------+ #
#######################################################################

# This needs to be set to true to spawn the object in the Tree and Sapling resources.
Tree: true

# The frequency of the BO3 from 1 to 200. Tries this many times to spawn this BO3 when using the CustomObject(...) resource.
# Ignored by Tree(..), Sapling(..) and CustomStructure(..)
Frequency: 1

# The rarity of the BO3 from 0 to 100. Each spawn attempt has rarity% chance to succeed when using the CustomObject(...) resource.
# Ignored by Tree(..), Sapling(..) and CustomStructure(..)
Rarity: 33.0

# If you set this to true, the BO3 will be placed with a random rotation.
RotateRandomly: true

# The spawn height of the BO3 - randomY, highestBlock or highestSolidBlock.
SpawnHeight: highestSolidBlock

# The height limits for the BO3.
MinHeight: 63

MaxHeight: 75

# Objects can have other objects attached to it: branches. Branches can also
# have branches attached to it, which can also have branches, etc. This is the
# maximum branch depth for this objects.
MaxBranchDepth: 10

# When spawned with the UseWorld keyword, this BO3 should NOT spawn in the following biomes.
# If you writer.write the BO3 name directly in the BiomeConfigs, this will be ignored.
ExcludedBiomes: All

# To optimise this BO3 for faster loading times you can use Notepad++ to find/replace comments and abbreviate things.
# Notepad++ find/replace with regex:
# Find: ^[#;].* replace to nothing removes all lines starting with # 
# Find: ^\s*$ replace to nothing removes most empty lines 
# Notepad++ find/replace without regex:
# *Warning: This will only work for OTG 1.10.2 v21 / OTG 1.11.2 v6 or higher. B( is not recognised by lower versions.
# Find: Block( replace to B(

#######################################################################
# +-----------------------------------------------------------------+ #
# |                      Source block settings                      | #
# +-----------------------------------------------------------------+ #
#######################################################################

# The block(s) the BO3 should spawn in.
SourceBlocks: STONE:1,STONE:3,STONE:5,DIRT:1,DIRT,SAND,GRASS,DIRT:2,STATIONARY_WATER,HARD_CLAY,STAINED_CLAY,CLAY,SANDSTONE,SAND:1,AIR,STONE,GRAVEL,LONG_GRASS,LONG_GRASS:1,LONG_GRASS:2,DEAD_BUSH,YELLOW_FLOWER,RED_ROSE,BROWN_MUSHROOM,RED_MUSHROOM,LEAVES,LOG

# The maximum percentage of the BO3 that can be outside the SourceBlock.
# The BO3 won't be placed on a location with more blocks outside the SourceBlock than this percentage.
MaxPercentageOutsideSourceBlock: 50

# What to do when a block is about to be placed outside the SourceBlock? (dontPlace, placeAnyway)
OutsideSourceBlock: placeAnyway

#######################################################################
# +-----------------------------------------------------------------+ #
# |                              Blocks                             | #
# +-----------------------------------------------------------------+ #
#######################################################################

# All the blocks used in the BO3 are listed here. Possible blocks:
# Block(x,y,z,id[.data][,nbtfile.nbt) or B(x,y,z,id[.data][,nbtfile.nbt)
# RandomBlock(x,y,z,id[:data][,nbtfile.nbt],chance[,id[:data][,nbtfile.nbt],chance[,...]])
# So RandomBlock(0,0,0,CHEST,chest.nbt,50,CHEST,anotherchest.nbt,100) will spawn a chest at
# the BO3 origin, and give it a 50% chance to have the contents of chest.nbt, or, if that
# fails, a 100% percent chance to have the contents of anotherchest.nbt.

Block(-15,32,2,106:8)
Block(-15,32,8,106:8)
Block(-15,32,10,106:8)
Block(-15,33,-11,106:4)
Block(-15,33,2,106:8)
Block(-15,33,8,106:8)
Block(-15,33,10,106:8)
Block(-15,34,-11,106:4)
Block(-15,34,2,106:8)
Block(-15,34,8,106:8)
Block(-15,34,10,106:8)
Block(-15,35,-11,106:4)
Block(-15,35,2,106:8)
Block(-15,35,8,106:8)
Block(-15,35,10,106:8)
Block(-15,36,-11,106:4)
Block(-15,36,2,106:8)
Block(-15,36,8,106:8)
Block(-15,36,10,106:8)
Block(-15,37,-15,106:8)
Block(-15,37,-11,106:4)
Block(-15,37,-1,18:3)
Block(-15,37,0,18:3)
Block(-15,37,1,18:3)
Block(-15,37,2,106:8)
Block(-15,37,8,106:8)
Block(-15,37,9,106:8)
Block(-15,37,10,106:8)
Block(-15,38,-15,106:8)
Block(-15,38,-14,18:3)
Block(-15,38,-13,18:3)
Block(-15,38,-12,18:3)
Block(-15,38,-11,106:4)
Block(-15,38,0,18:3)
Block(-15,38,8,106:8)
Block(-15,38,9,106:8)
Block(-15,38,10,106:8)
Block(-15,39,-13,18:3)
Block(-15,39,8,106:8)
Block(-15,39,9,106:8)
Block(-15,39,10,106:8)
Block(-15,40,9,106:8)
Block(-14,32,-7,106:8)
Block(-14,33,-10,106:4)
Block(-14,33,-7,106:8)
Block(-14,34,-10,106:4)
Block(-14,34,-7,106:8)
Block(-14,35,-10,106:4)
Block(-14,35,-7,106:8)
Block(-14,35,6,106:8)
Block(-14,36,-10,106:4)
Block(-14,36,-7,106:8)
Block(-14,36,-4,106:8)
Block(-14,36,3,106:8)
Block(-14,36,6,106:8)
Block(-14,37,-10,106:4)
Block(-14,37,-7,106:8)
Block(-14,37,-5,106:8)
Block(-14,37,-4,106:8)
Block(-14,37,-3,18:3)
Block(-14,37,-2,18:3)
Block(-14,37,-1,17:15)
Block(-14,37,0,18:3)
Block(-14,37,1,18:3)
Block(-14,37,2,18:3)
Block(-14,37,3,106:8)
Block(-14,37,6,106:8)
Block(-14,38,-15,18:3)
Block(-14,38,-14,18:3)
Block(-14,38,-13,18:3)
Block(-14,38,-12,18:3)
Block(-14,38,-11,18:3)
Block(-14,38,-10,106:4)
Block(-14,38,-7,106:8)
Block(-14,38,-5,106:8)
Block(-14,38,-4,106:8)
Block(-14,38,-3,18:3)
Block(-14,38,-2,18:3)
Block(-14,38,-1,18:3)
Block(-14,38,0,18:3)
Block(-14,38,1,18:3)
Block(-14,38,6,106:8)
Block(-14,39,-14,18:3)
Block(-14,39,-13,18:3)
Block(-14,39,-12,18:3)
Block(-14,39,-7,106:8)
Block(-14,39,-5,106:8)
Block(-14,39,-4,106:8)
Block(-14,39,8,18:3)
Block(-14,39,9,18:3)
Block(-14,39,10,18:3)
Block(-14,40,8,106:1)
Block(-14,40,9,18:3)
Block(-14,40,10,106:4)
Block(-14,42,1,18:3)
Block(-14,42,2,18:3)
Block(-14,42,3,18:3)
Block(-14,43,2,18:3)
Block(-13,31,-10,106:4)
Block(-13,32,-10,106:4)
Block(-13,33,-10,106:4)
Block(-13,34,-10,106:4)
Block(-13,35,-10,106:4)
Block(-13,36,-10,106:4)
Block(-13,37,-13,17:15)
Block(-13,37,-10,106:4)
Block(-13,37,-3,18:3)
Block(-13,37,-2,18:3)
Block(-13,37,-1,18:3)
Block(-13,37,0,17:15)
Block(-13,37,1,18:3)
Block(-13,37,2,18:3)
Block(-13,37,3,18:3)
Block(-13,38,-15,18:3)
Block(-13,38,-14,18:3)
Block(-13,38,-13,17:15)
Block(-13,38,-12,18:3)
Block(-13,38,-11,18:3)
Block(-13,38,-10,106:4)
Block(-13,38,-2,18:3)
Block(-13,38,-1,18:3)
Block(-13,38,0,18:3)
Block(-13,38,1,18:3)
Block(-13,38,2,18:3)
Block(-13,38,5,18:3)
Block(-13,38,6,18:3)
Block(-13,38,7,18:3)
Block(-13,39,-15,18:3)
Block(-13,39,-14,18:3)
Block(-13,39,-13,18:3)
Block(-13,39,-12,18:3)
Block(-13,39,-11,18:3)
Block(-13,39,-10,106:4)
Block(-13,39,-7,18:3)
Block(-13,39,-6,18:3)
Block(-13,39,-5,18:3)
Block(-13,39,-4,18:3)
Block(-13,39,-3,18:3)
Block(-13,39,-2,18:3)
Block(-13,39,6,18:3)
Block(-13,39,7,18:3)
Block(-13,39,8,18:3)
Block(-13,39,9,18:3)
Block(-13,39,10,18:3)
Block(-13,39,11,18:3)
Block(-13,40,-6,18:3)
Block(-13,40,-3,18:3)
Block(-13,40,-1,18:3)
Block(-13,40,0,18:3)
Block(-13,40,1,18:3)
Block(-13,40,8,18:3)
Block(-13,40,9,18:3)
Block(-13,40,10,18:3)
Block(-13,41,0,18:3)
Block(-13,42,0,18:3)
Block(-13,42,1,18:3)
Block(-13,42,2,18:3)
Block(-13,42,3,18:3)
Block(-13,42,4,18:3)
Block(-13,43,1,18:3)
Block(-13,43,2,18:3)
Block(-13,43,3,18:3)
Block(-12,32,-10,106:4)
Block(-12,33,-10,106:4)
Block(-12,33,10,106:4)
Block(-12,34,-10,106:4)
Block(-12,34,10,106:4)
Block(-12,35,-10,106:4)
Block(-12,35,10,106:4)
Block(-12,36,-12,17:15)
Block(-12,36,-10,106:4)
Block(-12,36,10,106:4)
Block(-12,37,-10,106:4)
Block(-12,37,-2,18:3)
Block(-12,37,-1,18:3)
Block(-12,37,0,18:3)
Block(-12,37,1,17:15)
Block(-12,37,2,18:3)
Block(-12,37,3,18:3)
Block(-12,37,7,18:3)
Block(-12,37,8,18:3)
Block(-12,37,9,18:3)
Block(-12,37,10,106:4)
Block(-12,38,-15,18:3)
Block(-12,38,-14,18:3)
Block(-12,38,-13,18:3)
Block(-12,38,-12,18:3)
Block(-12,38,-11,18:3)
Block(-12,38,-10,106:4)
Block(-12,38,-1,18:3)
Block(-12,38,0,18:3)
Block(-12,38,1,18:3)
Block(-12,38,2,18:3)
Block(-12,38,3,18:3)
Block(-12,38,4,18:3)
Block(-12,38,5,18:3)
Block(-12,38,6,18:3)
Block(-12,38,7,18:3)
Block(-12,38,8,18:3)
Block(-12,39,-14,18:3)
Block(-12,39,-13,18:3)
Block(-12,39,-12,18:3)
Block(-12,39,-8,18:3)
Block(-12,39,-7,18:3)
Block(-12,39,-6,18:3)
Block(-12,39,-5,18:3)
Block(-12,39,-4,18:3)
Block(-12,39,-3,18:3)
Block(-12,39,-2,18:3)
Block(-12,39,-1,18:3)
Block(-12,39,1,18:3)
Block(-12,39,2,18:3)
Block(-12,39,3,18:3)
Block(-12,39,5,18:3)
Block(-12,39,6,18:3)
Block(-12,39,7,18:3)
Block(-12,39,8,18:3)
Block(-12,39,9,17:15)
Block(-12,39,10,18:3)
Block(-12,39,11,18:3)
Block(-12,40,-7,18:3)
Block(-12,40,-6,18:3)
Block(-12,40,-5,18:3)
Block(-12,40,-4,18:3)
Block(-12,40,-3,18:3)
Block(-12,40,-2,18:3)
Block(-12,40,-1,18:3)
Block(-12,40,0,18:3)
Block(-12,40,1,18:3)
Block(-12,40,2,18:3)
Block(-12,40,4,18:3)
Block(-12,40,5,18:3)
Block(-12,40,6,18:3)
Block(-12,40,7,18:3)
Block(-12,40,8,18:3)
Block(-12,40,9,18:3)
Block(-12,40,10,18:3)
Block(-12,40,11,18:3)
Block(-12,41,-1,18:3)
Block(-12,41,0,18:3)
Block(-12,41,1,18:3)
Block(-12,41,5,18:3)
Block(-12,42,0,18:3)
Block(-12,42,1,18:3)
Block(-12,42,2,17:15)
Block(-12,42,3,18:3)
Block(-12,42,4,18:3)
Block(-12,43,0,18:3)
Block(-12,43,1,18:3)
Block(-12,43,2,18:3)
Block(-12,43,3,18:3)
Block(-12,43,4,18:3)
Block(-11,34,-11,17:15)
Block(-11,35,-11,17:15)
Block(-11,35,11,106:4)
Block(-11,36,-11,106:8)
Block(-11,36,11,106:4)
Block(-11,37,-11,106:8)
Block(-11,37,-1,18:3)
Block(-11,37,0,18:3)
Block(-11,37,1,18:3)
Block(-11,37,2,18:3)
Block(-11,37,3,18:3)
Block(-11,37,6,18:3)
Block(-11,37,7,18:3)
Block(-11,37,8,18:3)
Block(-11,37,9,18:3)
Block(-11,37,10,18:3)
Block(-11,37,11,106:4)
Block(-11,38,-14,18:3)
Block(-11,38,-13,18:3)
Block(-11,38,-12,18:3)
Block(-11,38,-11,106:8)
Block(-11,38,0,18:3)
Block(-11,38,1,18:3)
Block(-11,38,2,18:3)
Block(-11,38,4,18:3)
Block(-11,38,5,18:3)
Block(-11,38,6,17:15)
Block(-11,38,7,18:3)
Block(-11,38,8,18:3)
Block(-11,38,9,18:3)
Block(-11,39,-13,18:3)
Block(-11,39,-8,18:3)
Block(-11,39,-7,18:3)
Block(-11,39,-6,17:15)
Block(-11,39,-5,18:3)
Block(-11,39,-4,18:3)
Block(-11,39,-3,17:15)
Block(-11,39,-2,18:3)
Block(-11,39,-1,18:3)
Block(-11,39,0,18:3)
Block(-11,39,1,18:3)
Block(-11,39,2,18:3)
Block(-11,39,3,18:3)
Block(-11,39,4,18:3)
Block(-11,39,5,18:3)
Block(-11,39,6,18:3)
Block(-11,39,7,18:3)
Block(-11,39,8,18:3)
Block(-11,39,9,18:3)
Block(-11,39,10,18:3)
Block(-11,39,11,18:3)
Block(-11,40,-13,18:3)
Block(-11,40,-12,18:3)
Block(-11,40,-11,18:3)
Block(-11,40,-8,18:3)
Block(-11,40,-7,18:3)
Block(-11,40,-6,18:3)
Block(-11,40,-5,18:3)
Block(-11,40,-4,18:3)
Block(-11,40,-3,18:3)
Block(-11,40,-2,18:3)
Block(-11,40,-1,18:3)
Block(-11,40,0,17:15)
Block(-11,40,1,18:3)
Block(-11,40,2,18:3)
Block(-11,40,3,18:3)
Block(-11,40,4,18:3)
Block(-11,40,5,18:3)
Block(-11,40,6,18:3)
Block(-11,40,7,18:3)
Block(-11,40,8,18:3)
Block(-11,40,9,18:3)
Block(-11,40,10,18:3)
Block(-11,41,-12,18:3)
Block(-11,41,-2,18:3)
Block(-11,41,-1,18:3)
Block(-11,41,0,18:3)
Block(-11,41,1,18:3)
Block(-11,41,2,18:3)
Block(-11,41,4,18:3)
Block(-11,41,5,18:3)
Block(-11,41,6,18:3)
Block(-11,42,0,18:3)
Block(-11,42,1,18:3)
Block(-11,42,2,18:3)
Block(-11,42,3,18:3)
Block(-11,42,4,18:3)
Block(-11,43,1,18:3)
Block(-11,43,2,18:3)
Block(-11,43,3,18:3)
Block(-11,43,4,18:3)
Block(-11,43,5,18:3)
Block(-11,44,4,18:3)
Block(-10,33,-10,17:15)
Block(-10,37,0,18:3)
Block(-10,37,1,18:3)
Block(-10,37,2,18:3)
Block(-10,37,6,18:3)
Block(-10,37,7,18:3)
Block(-10,37,8,17:15)
Block(-10,37,9,18:3)
Block(-10,37,10,18:3)
Block(-10,38,-11,18:3)
Block(-10,38,-10,18:3)
Block(-10,38,-9,18:3)
Block(-10,38,1,18:3)
Block(-10,38,4,18:3)
Block(-10,38,5,18:3)
Block(-10,38,6,18:3)
Block(-10,38,7,18:3)
Block(-10,38,8,18:3)
Block(-10,38,9,18:3)
Block(-10,38,10,18:3)
Block(-10,39,-10,18:3)
Block(-10,39,-8,18:3)
Block(-10,39,-7,18:3)
Block(-10,39,-6,18:3)
Block(-10,39,-5,18:3)
Block(-10,39,-4,18:3)
Block(-10,39,-3,17:15)
Block(-10,39,-2,18:3)
Block(-10,39,-1,18:3)
Block(-10,39,0,18:3)
Block(-10,39,1,18:3)
Block(-10,39,2,17:15)
Block(-10,39,3,18:3)
Block(-10,39,4,18:3)
Block(-10,39,5,18:3)
Block(-10,39,6,18:3)
Block(-10,39,7,18:3)
Block(-10,39,8,18:3)
Block(-10,39,9,18:3)
Block(-10,39,10,18:3)
Block(-10,40,-14,18:3)
Block(-10,40,-13,18:3)
Block(-10,40,-12,18:3)
Block(-10,40,-11,18:3)
Block(-10,40,-10,18:3)
Block(-10,40,-7,18:3)
Block(-10,40,-6,18:3)
Block(-10,40,-5,18:3)
Block(-10,40,-4,18:3)
Block(-10,40,-3,18:3)
Block(-10,40,-2,18:3)
Block(-10,40,-1,18:3)
Block(-10,40,0,18:3)
Block(-10,40,1,18:3)
Block(-10,40,2,18:3)
Block(-10,40,3,18:3)
Block(-10,40,4,18:3)
Block(-10,40,5,17:15)
Block(-10,40,6,18:3)
Block(-10,40,7,18:3)
Block(-10,40,9,18:3)
Block(-10,41,-13,18:3)
Block(-10,41,-12,18:3)
Block(-10,41,-11,18:3)
Block(-10,41,-1,18:3)
Block(-10,41,0,18:3)
Block(-10,41,1,18:3)
Block(-10,41,3,18:3)
Block(-10,41,4,18:3)
Block(-10,41,5,18:3)
Block(-10,41,6,18:3)
Block(-10,41,7,18:3)
Block(-10,42,-2,18:3)
Block(-10,42,-1,18:3)
Block(-10,42,0,18:3)
Block(-10,42,1,18:3)
Block(-10,42,2,18:3)
Block(-10,42,3,18:3)
Block(-10,43,-5,18:3)
Block(-10,43,-4,18:3)
Block(-10,43,-3,18:3)
Block(-10,43,-1,18:3)
Block(-10,43,0,18:3)
Block(-10,43,1,18:3)
Block(-10,43,2,18:3)
Block(-10,43,3,18:3)
Block(-10,43,4,18:3)
Block(-10,43,5,18:3)
Block(-10,43,6,18:3)
Block(-10,44,-4,18:3)
Block(-10,44,3,18:3)
Block(-10,44,4,18:3)
Block(-10,44,5,18:3)
Block(-9,30,11,106:4)
Block(-9,31,11,106:4)
Block(-9,32,-9,17:15)
Block(-9,32,11,106:4)
Block(-9,33,11,106:4)
Block(-9,34,-13,106:1)
Block(-9,34,11,106:4)
Block(-9,35,-13,106:1)
Block(-9,35,11,106:4)
Block(-9,36,-13,106:1)
Block(-9,36,11,106:4)
Block(-9,37,-13,106:1)
Block(-9,37,6,18:3)
Block(-9,37,7,18:3)
Block(-9,37,8,18:3)
Block(-9,37,9,18:3)
Block(-9,37,10,18:3)
Block(-9,37,11,106:4)
Block(-9,38,-13,106:1)
Block(-9,38,-12,18:3)
Block(-9,38,-11,18:3)
Block(-9,38,-10,18:3)
Block(-9,38,-9,18:3)
Block(-9,38,-8,18:3)
Block(-9,38,-2,18:3)
Block(-9,38,-1,18:3)
Block(-9,38,0,18:3)
Block(-9,38,4,18:3)
Block(-9,38,5,18:3)
Block(-9,38,6,18:3)
Block(-9,38,7,18:3)
Block(-9,38,8,18:3)
Block(-9,38,9,18:3)
Block(-9,39,-11,18:3)
Block(-9,39,-10,18:3)
Block(-9,39,-9,18:3)
Block(-9,39,-8,18:3)
Block(-9,39,-7,18:3)
Block(-9,39,-6,18:3)
Block(-9,39,-5,18:3)
Block(-9,39,-4,18:3)
Block(-9,39,-3,18:3)
Block(-9,39,-2,18:3)
Block(-9,39,-1,18:3)
Block(-9,39,0,18:3)
Block(-9,39,1,18:3)
Block(-9,39,2,18:3)
Block(-9,39,3,18:3)
Block(-9,39,4,18:3)
Block(-9,39,5,18:3)
Block(-9,39,6,18:3)
Block(-9,40,-14,18:3)
Block(-9,40,-13,18:3)
Block(-9,40,-12,17:15)
Block(-9,40,-11,18:3)
Block(-9,40,-10,18:3)
Block(-9,40,-8,18:3)
Block(-9,40,-7,18:3)
Block(-9,40,-6,18:3)
Block(-9,40,-5,18:3)
Block(-9,40,-4,18:3)
Block(-9,40,-3,18:3)
Block(-9,40,-2,18:3)
Block(-9,40,-1,18:3)
Block(-9,40,0,18:3)
Block(-9,40,1,18:3)
Block(-9,40,2,18:3)
Block(-9,40,3,18:3)
Block(-9,40,4,18:3)
Block(-9,40,5,18:3)
Block(-9,40,6,18:3)
Block(-9,40,7,18:3)
Block(-9,41,-14,18:3)
Block(-9,41,-13,18:3)
Block(-9,41,-12,18:3)
Block(-9,41,-11,18:3)
Block(-9,41,-10,18:3)
Block(-9,41,0,18:3)
Block(-9,41,4,18:3)
Block(-9,41,5,18:3)
Block(-9,41,6,18:3)
Block(-9,42,-4,18:3)
Block(-9,42,-3,18:3)
Block(-9,42,-2,18:3)
Block(-9,42,-1,18:3)
Block(-9,42,0,18:3)
Block(-9,42,1,17:15)
Block(-9,42,2,18:3)
Block(-9,42,3,18:3)
Block(-9,43,-6,18:3)
Block(-9,43,-5,18:3)
Block(-9,43,-4,18:3)
Block(-9,43,-3,18:3)
Block(-9,43,-2,18:3)
Block(-9,43,-1,18:3)
Block(-9,43,0,18:3)
Block(-9,43,1,18:3)
Block(-9,43,2,18:3)
Block(-9,43,3,18:3)
Block(-9,43,4,17:15)
Block(-9,43,5,18:3)
Block(-9,43,6,18:3)
Block(-9,44,-5,18:3)
Block(-9,44,-4,18:3)
Block(-9,44,-3,18:3)
Block(-9,44,-2,18:3)
Block(-9,44,-1,18:3)
Block(-9,44,0,18:3)
Block(-9,44,2,18:3)
Block(-9,44,3,18:3)
Block(-9,44,4,18:3)
Block(-9,44,5,18:3)
Block(-9,44,6,18:3)
Block(-9,45,-2,18:3)
Block(-9,45,-1,18:3)
Block(-8,30,-8,17:15)
Block(-8,31,-8,17:15)
Block(-8,32,-13,106:1)
Block(-8,33,-13,106:1)
Block(-8,34,-13,106:1)
Block(-8,35,-13,106:1)
Block(-8,36,-13,106:1)
Block(-8,37,-13,106:1)
Block(-8,37,-2,18:3)
Block(-8,37,-1,18:3)
Block(-8,37,0,18:3)
Block(-8,37,7,18:3)
Block(-8,37,8,18:3)
Block(-8,37,9,18:3)
Block(-8,38,-13,106:1)
Block(-8,38,-12,18:3)
Block(-8,38,-11,18:3)
Block(-8,38,-10,17:15)
Block(-8,38,-9,18:3)
Block(-8,38,-8,18:3)
Block(-8,38,-3,18:3)
Block(-8,38,-2,18:3)
Block(-8,38,-1,18:3)
Block(-8,38,0,18:3)
Block(-8,38,1,18:3)
Block(-8,38,3,18:3)
Block(-8,38,4,18:3)
Block(-8,38,5,18:3)
Block(-8,38,6,18:3)
Block(-8,38,7,18:3)
Block(-8,38,8,18:3)
Block(-8,39,-12,18:3)
Block(-8,39,-11,18:3)
Block(-8,39,-10,18:3)
Block(-8,39,-9,18:3)
Block(-8,39,-8,18:3)
Block(-8,39,-7,17:15)
Block(-8,39,-6,18:3)
Block(-8,39,-5,18:3)
Block(-8,39,-4,18:3)
Block(-8,39,-3,17:15)
Block(-8,39,-2,18:3)
Block(-8,39,-1,18:3)
Block(-8,39,0,17:15)
Block(-8,39,1,18:3)
Block(-8,39,2,18:3)
Block(-8,39,3,18:3)
Block(-8,39,4,18:3)
Block(-8,39,5,18:3)
Block(-8,39,6,18:3)
Block(-8,39,7,18:3)
Block(-8,40,-14,18:3)
Block(-8,40,-13,18:3)
Block(-8,40,-12,18:3)
Block(-8,40,-11,18:3)
Block(-8,40,-10,18:3)
Block(-8,40,-9,18:3)
Block(-8,40,-8,18:3)
Block(-8,40,-7,18:3)
Block(-8,40,-6,18:3)
Block(-8,40,-5,18:3)
Block(-8,40,-4,18:3)
Block(-8,40,-3,18:3)
Block(-8,40,-2,18:3)
Block(-8,40,-1,18:3)
Block(-8,40,0,18:3)
Block(-8,40,1,18:3)
Block(-8,40,2,18:3)
Block(-8,40,4,18:3)
Block(-8,40,5,18:3)
Block(-8,40,6,18:3)
Block(-8,41,-13,18:3)
Block(-8,41,-12,18:3)
Block(-8,41,-11,18:3)
Block(-8,41,-1,18:3)
Block(-8,41,0,18:3)
Block(-8,41,1,18:3)
Block(-8,41,2,18:3)
Block(-8,41,5,18:3)
Block(-8,42,-5,18:3)
Block(-8,42,-4,18:3)
Block(-8,42,-3,18:3)
Block(-8,42,-2,18:3)
Block(-8,42,-1,17:15)
Block(-8,42,0,18:3)
Block(-8,42,1,18:3)
Block(-8,42,2,18:3)
Block(-8,42,3,18:3)
Block(-8,43,-6,18:3)
Block(-8,43,-5,18:3)
Block(-8,43,-4,17:15)
Block(-8,43,-3,18:3)
Block(-8,43,-2,18:3)
Block(-8,43,-1,18:3)
Block(-8,43,0,18:3)
Block(-8,43,1,18:3)
Block(-8,43,2,18:3)
Block(-8,43,3,18:3)
Block(-8,43,4,18:3)
Block(-8,43,5,18:3)
Block(-8,43,6,18:3)
Block(-8,44,-6,18:3)
Block(-8,44,-5,18:3)
Block(-8,44,-4,18:3)
Block(-8,44,-3,18:3)
Block(-8,44,-2,18:3)
Block(-8,44,-1,18:3)
Block(-8,44,0,18:3)
Block(-8,44,1,18:3)
Block(-8,44,3,18:3)
Block(-8,44,4,18:3)
Block(-8,44,5,18:3)
Block(-8,45,-4,18:3)
Block(-8,45,-3,18:3)
Block(-8,45,-2,18:3)
Block(-8,45,-1,18:3)
Block(-8,45,0,18:3)
Block(-8,45,1,18:3)
Block(-8,45,2,18:3)
Block(-8,46,-1,18:3)
Block(-8,46,0,18:3)
Block(-8,46,1,18:3)
Block(-8,47,0,18:3)
Block(-7,29,-7,17:15)
Block(-7,37,-3,18:3)
Block(-7,37,-2,18:3)
Block(-7,37,-1,18:3)
Block(-7,37,0,18:3)
Block(-7,37,1,18:3)
Block(-7,38,-12,18:3)
Block(-7,38,-11,18:3)
Block(-7,38,-10,18:3)
Block(-7,38,-9,18:3)
Block(-7,38,-8,18:3)
Block(-7,38,-3,18:3)
Block(-7,38,-2,18:3)
Block(-7,38,-1,17:15)
Block(-7,38,0,18:3)
Block(-7,38,1,18:3)
Block(-7,38,3,18:3)
Block(-7,38,4,18:3)
Block(-7,38,5,17:15)
Block(-7,38,6,17:15)
Block(-7,38,7,18:3)
Block(-7,38,8,18:3)
Block(-7,39,-12,18:3)
Block(-7,39,-11,18:3)
Block(-7,39,-10,18:3)
Block(-7,39,-9,18:3)
Block(-7,39,-8,18:3)
Block(-7,39,-7,18:3)
Block(-7,39,-6,18:3)
Block(-7,39,-5,17:15)
Block(-7,39,-4,18:3)
Block(-7,39,-3,18:3)
Block(-7,39,-2,18:3)
Block(-7,39,-1,18:3)
Block(-7,39,0,18:3)
Block(-7,39,1,18:3)
Block(-7,39,2,18:3)
Block(-7,39,3,18:3)
Block(-7,39,4,18:3)
Block(-7,39,5,18:3)
Block(-7,39,6,18:3)
Block(-7,39,7,18:3)
Block(-7,39,8,18:3)
Block(-7,40,-13,18:3)
Block(-7,40,-12,18:3)
Block(-7,40,-11,18:3)
Block(-7,40,-10,18:3)
Block(-7,40,-9,18:3)
Block(-7,40,-8,18:3)
Block(-7,40,-7,18:3)
Block(-7,40,-6,18:3)
Block(-7,40,-5,18:3)
Block(-7,40,-4,18:3)
Block(-7,40,-3,18:3)
Block(-7,40,-2,18:3)
Block(-7,40,-1,18:3)
Block(-7,40,0,18:3)
Block(-7,40,1,18:3)
Block(-7,40,3,18:3)
Block(-7,40,4,18:3)
Block(-7,40,5,18:3)
Block(-7,40,6,18:3)
Block(-7,40,7,18:3)
Block(-7,41,-12,18:3)
Block(-7,41,-9,18:3)
Block(-7,41,-8,18:3)
Block(-7,41,-7,18:3)
Block(-7,41,-6,18:3)
Block(-7,41,-4,18:3)
Block(-7,41,-2,18:3)
Block(-7,41,-1,18:3)
Block(-7,41,0,18:3)
Block(-7,41,1,18:3)
Block(-7,41,2,18:3)
Block(-7,41,3,18:3)
Block(-7,41,4,18:3)
Block(-7,41,5,18:3)
Block(-7,41,6,18:3)
Block(-7,41,11,18:3)
Block(-7,41,12,18:3)
Block(-7,41,13,18:3)
Block(-7,42,-7,18:3)
Block(-7,42,-5,18:3)
Block(-7,42,-4,18:3)
Block(-7,42,-3,17:15)
Block(-7,42,-2,18:3)
Block(-7,42,-1,18:3)
Block(-7,42,0,17:15)
Block(-7,42,1,18:3)
Block(-7,42,2,18:3)
Block(-7,42,3,18:3)
Block(-7,42,12,18:3)
Block(-7,43,-6,18:3)
Block(-7,43,-5,18:3)
Block(-7,43,-4,18:3)
Block(-7,43,-3,18:3)
Block(-7,43,-2,18:3)
Block(-7,43,-1,18:3)
Block(-7,43,0,18:3)
Block(-7,43,1,18:3)
Block(-7,43,2,18:3)
Block(-7,43,3,18:3)
Block(-7,43,4,18:3)
Block(-7,43,5,18:3)
Block(-7,43,9,18:3)
Block(-7,43,10,18:3)
Block(-7,43,11,18:3)
Block(-7,44,-6,18:3)
Block(-7,44,-5,18:3)
Block(-7,44,-4,18:3)
Block(-7,44,-3,18:3)
Block(-7,44,-2,17:15)
Block(-7,44,-1,17:15)
Block(-7,44,0,18:3)
Block(-7,44,1,18:3)
Block(-7,44,4,18:3)
Block(-7,44,10,18:3)
Block(-7,45,-5,18:3)
Block(-7,45,-4,18:3)
Block(-7,45,-3,18:3)
Block(-7,45,-2,18:3)
Block(-7,45,-1,18:3)
Block(-7,45,0,18:3)
Block(-7,45,1,18:3)
Block(-7,45,2,18:3)
Block(-7,45,3,18:3)
Block(-7,45,4,18:3)
Block(-7,45,5,18:3)
Block(-7,46,-3,18:3)
Block(-7,46,-2,18:3)
Block(-7,46,-1,18:3)
Block(-7,46,0,18:3)
Block(-7,46,1,18:3)
Block(-7,46,2,18:3)
Block(-7,46,4,18:3)
Block(-7,47,-1,18:3)
Block(-7,47,0,18:3)
Block(-7,47,1,18:3)
Block(-6,27,-6,17:15)
Block(-6,28,-6,17:15)
Block(-6,35,13,106:4)
Block(-6,36,13,106:4)
Block(-6,37,-3,18:3)
Block(-6,37,-2,18:3)
Block(-6,37,-1,17:15)
Block(-6,37,0,18:3)
Block(-6,37,1,18:3)
Block(-6,37,2,18:3)
Block(-6,37,5,18:3)
Block(-6,37,6,18:3)
Block(-6,37,7,18:3)
Block(-6,37,13,106:4)
Block(-6,38,-11,18:3)
Block(-6,38,-10,18:3)
Block(-6,38,-9,18:3)
Block(-6,38,-3,18:3)
Block(-6,38,-2,18:3)
Block(-6,38,-1,18:3)
Block(-6,38,0,18:3)
Block(-6,38,1,18:3)
Block(-6,38,3,18:3)
Block(-6,38,4,18:3)
Block(-6,38,5,18:3)
Block(-6,38,6,18:3)
Block(-6,38,7,18:3)
Block(-6,38,8,18:3)
Block(-6,38,10,18:3)
Block(-6,38,11,18:3)
Block(-6,38,12,18:3)
Block(-6,38,13,106:4)
Block(-6,39,-12,18:3)
Block(-6,39,-11,18:3)
Block(-6,39,-10,17:15)
Block(-6,39,-9,18:3)
Block(-6,39,-8,18:3)
Block(-6,39,-7,18:3)
Block(-6,39,-6,18:3)
Block(-6,39,-5,18:3)
Block(-6,39,-4,18:3)
Block(-6,39,-3,18:3)
Block(-6,39,-2,18:3)
Block(-6,39,-1,18:3)
Block(-6,39,0,18:3)
Block(-6,39,1,18:3)
Block(-6,39,4,18:3)
Block(-6,39,5,18:3)
Block(-6,39,6,18:3)
Block(-6,39,7,18:3)
Block(-6,39,11,18:3)
Block(-6,40,-12,18:3)
Block(-6,40,-11,18:3)
Block(-6,40,-10,18:3)
Block(-6,40,-9,18:3)
Block(-6,40,-8,18:3)
Block(-6,40,-7,18:3)
Block(-6,40,-6,18:3)
Block(-6,40,-5,18:3)
Block(-6,40,-4,18:3)
Block(-6,40,-3,18:3)
Block(-6,40,-2,18:3)
Block(-6,40,-1,17:15)
Block(-6,40,0,18:3)
Block(-6,40,1,18:3)
Block(-6,40,3,18:3)
Block(-6,40,4,18:3)
Block(-6,40,5,17:15)
Block(-6,40,6,18:3)
Block(-6,40,7,18:3)
Block(-6,40,8,18:3)
Block(-6,41,-11,18:3)
Block(-6,41,-10,18:3)
Block(-6,41,-9,18:3)
Block(-6,41,-8,18:3)
Block(-6,41,-7,18:3)
Block(-6,41,-6,18:3)
Block(-6,41,-5,18:3)
Block(-6,41,-4,18:3)
Block(-6,41,-3,18:3)
Block(-6,41,-2,18:3)
Block(-6,41,-1,18:3)
Block(-6,41,0,18:3)
Block(-6,41,1,17:15)
Block(-6,41,2,18:3)
Block(-6,41,3,18:3)
Block(-6,41,4,18:3)
Block(-6,41,5,18:3)
Block(-6,41,6,18:3)
Block(-6,41,7,18:3)
Block(-6,41,8,18:3)
Block(-6,41,9,18:3)
Block(-6,41,10,18:3)
Block(-6,41,11,18:3)
Block(-6,41,12,18:3)
Block(-6,41,13,18:3)
Block(-6,41,14,18:3)
Block(-6,42,-8,18:3)
Block(-6,42,-7,18:3)
Block(-6,42,-6,18:3)
Block(-6,42,-5,18:3)
Block(-6,42,-4,18:3)
Block(-6,42,-3,18:3)
Block(-6,42,-2,18:3)
Block(-6,42,-1,18:3)
Block(-6,42,0,18:3)
Block(-6,42,1,18:3)
Block(-6,42,2,18:3)
Block(-6,42,3,18:3)
Block(-6,42,4,18:3)
Block(-6,42,8,18:3)
Block(-6,42,11,18:3)
Block(-6,42,12,18:3)
Block(-6,42,13,18:3)
Block(-6,43,-5,18:3)
Block(-6,43,-4,18:3)
Block(-6,43,-3,18:3)
Block(-6,43,-2,18:3)
Block(-6,43,-1,18:3)
Block(-6,43,0,18:3)
Block(-6,43,1,18:3)
Block(-6,43,2,18:3)
Block(-6,43,3,18:3)
Block(-6,43,4,18:3)
Block(-6,43,8,18:3)
Block(-6,43,9,18:3)
Block(-6,43,10,18:3)
Block(-6,43,11,18:3)
Block(-6,43,12,18:3)
Block(-6,44,-8,18:3)
Block(-6,44,-7,18:3)
Block(-6,44,-6,18:3)
Block(-6,44,-5,18:3)
Block(-6,44,-4,17:15)
Block(-6,44,-3,18:3)
Block(-6,44,-2,18:3)
Block(-6,44,-1,18:3)
Block(-6,44,0,18:3)
Block(-6,44,1,18:3)
Block(-6,44,3,18:3)
Block(-6,44,9,18:3)
Block(-6,44,10,18:3)
Block(-6,44,11,18:3)
Block(-6,45,-7,18:3)
Block(-6,45,-6,18:3)
Block(-6,45,-5,18:3)
Block(-6,45,-4,18:3)
Block(-6,45,-3,18:3)
Block(-6,45,-2,18:3)
Block(-6,45,-1,18:3)
Block(-6,45,0,18:3)
Block(-6,45,1,17:15)
Block(-6,45,2,18:3)
Block(-6,45,3,18:3)
Block(-6,45,4,18:3)
Block(-6,45,5,18:3)
Block(-6,45,6,18:3)
Block(-6,46,-4,18:3)
Block(-6,46,-3,18:3)
Block(-6,46,-2,18:3)
Block(-6,46,-1,18:3)
Block(-6,46,0,17:15)
Block(-6,46,1,18:3)
Block(-6,46,2,18:3)
Block(-6,46,3,18:3)
Block(-6,46,4,18:3)
Block(-6,46,5,18:3)
Block(-6,47,-2,18:3)
Block(-6,47,-1,18:3)
Block(-6,47,0,18:3)
Block(-6,47,1,18:3)
Block(-6,47,2,18:3)
Block(-5,26,-5,17:15)
Block(-5,33,-16,106:1)
Block(-5,34,-16,106:1)
Block(-5,35,-16,106:1)
Block(-5,36,-16,106:1)
Block(-5,37,-16,106:1)
Block(-5,37,-3,18:3)
Block(-5,37,-2,18:3)
Block(-5,37,-1,18:3)
Block(-5,37,0,17:15)
Block(-5,37,1,18:3)
Block(-5,37,2,18:3)
Block(-5,37,4,18:3)
Block(-5,37,5,18:3)
Block(-5,37,6,18:3)
Block(-5,37,7,18:3)
Block(-5,37,8,18:3)
Block(-5,38,-16,106:1)
Block(-5,38,-15,18:3)
Block(-5,38,-14,18:3)
Block(-5,38,-13,18:3)
Block(-5,38,-2,18:3)
Block(-5,38,-1,18:3)
Block(-5,38,0,18:3)
Block(-5,38,1,18:3)
Block(-5,38,2,18:3)
Block(-5,38,3,18:3)
Block(-5,38,4,18:3)
Block(-5,38,5,18:3)
Block(-5,38,6,18:3)
Block(-5,38,7,18:3)
Block(-5,38,9,18:3)
Block(-5,38,10,18:3)
Block(-5,38,11,18:3)
Block(-5,38,12,18:3)
Block(-5,38,13,18:3)
Block(-5,39,-14,18:3)
Block(-5,39,-12,18:3)
Block(-5,39,-11,18:3)
Block(-5,39,-10,18:3)
Block(-5,39,-9,18:3)
Block(-5,39,-8,18:3)
Block(-5,39,-7,18:3)
Block(-5,39,-6,18:3)
Block(-5,39,-5,18:3)
Block(-5,39,-4,17:15)
Block(-5,39,-3,18:3)
Block(-5,39,-2,18:3)
Block(-5,39,-1,18:3)
Block(-5,39,0,18:3)
Block(-5,39,1,18:3)
Block(-5,39,2,18:3)
Block(-5,39,4,18:3)
Block(-5,39,5,18:3)
Block(-5,39,6,18:3)
Block(-5,39,10,18:3)
Block(-5,39,11,18:3)
Block(-5,39,12,18:3)
Block(-5,40,-13,18:3)
Block(-5,40,-12,18:3)
Block(-5,40,-11,18:3)
Block(-5,40,-10,18:3)
Block(-5,40,-9,17:15)
Block(-5,40,-8,18:3)
Block(-5,40,-7,18:3)
Block(-5,40,-6,18:3)
Block(-5,40,-5,18:3)
Block(-5,40,-4,17:15)
Block(-5,40,-3,18:3)
Block(-5,40,-2,18:3)
Block(-5,40,-1,18:3)
Block(-5,40,0,18:3)
Block(-5,40,1,18:3)
Block(-5,40,3,18:3)
Block(-5,40,4,18:3)
Block(-5,40,5,18:3)
Block(-5,40,6,17:15)
Block(-5,40,7,18:3)
Block(-5,40,8,18:3)
Block(-5,41,-12,18:3)
Block(-5,41,-11,18:3)
Block(-5,41,-10,18:3)
Block(-5,41,-9,18:3)
Block(-5,41,-8,18:3)
Block(-5,41,-7,17:15)
Block(-5,41,-6,18:3)
Block(-5,41,-5,18:3)
Block(-5,41,-4,18:3)
Block(-5,41,-3,18:3)
Block(-5,41,-2,18:3)
Block(-5,41,-1,18:3)
Block(-5,41,0,17:15)
Block(-5,41,1,18:3)
Block(-5,41,2,18:3)
Block(-5,41,3,18:3)
Block(-5,41,4,18:3)
Block(-5,41,5,18:3)
Block(-5,41,6,18:3)
Block(-5,41,7,18:3)
Block(-5,41,8,18:3)
Block(-5,41,9,18:3)
Block(-5,41,10,18:3)
Block(-5,41,11,18:3)
Block(-5,41,12,17:15)
Block(-5,41,13,18:3)
Block(-5,41,14,18:3)
Block(-5,42,-9,18:3)
Block(-5,42,-8,18:3)
Block(-5,42,-7,18:3)
Block(-5,42,-6,18:3)
Block(-5,42,-5,18:3)
Block(-5,42,-4,18:3)
Block(-5,42,-3,18:3)
Block(-5,42,-2,18:3)
Block(-5,42,-1,18:3)
Block(-5,42,0,18:3)
Block(-5,42,1,18:3)
Block(-5,42,2,17:15)
Block(-5,42,3,18:3)
Block(-5,42,4,18:3)
Block(-5,42,7,18:3)
Block(-5,42,8,18:3)
Block(-5,42,9,18:3)
Block(-5,42,10,18:3)
Block(-5,42,11,18:3)
Block(-5,42,12,18:3)
Block(-5,42,13,18:3)
Block(-5,42,14,18:3)
Block(-5,43,-5,18:3)
Block(-5,43,-4,18:3)
Block(-5,43,-3,18:3)
Block(-5,43,-2,18:3)
Block(-5,43,-1,18:3)
Block(-5,43,0,17:15)
Block(-5,43,1,18:3)
Block(-5,43,2,18:3)
Block(-5,43,3,18:3)
Block(-5,43,4,18:3)
Block(-5,43,5,18:3)
Block(-5,43,8,18:3)
Block(-5,43,9,18:3)
Block(-5,43,10,17:15)
Block(-5,43,11,18:3)
Block(-5,43,12,18:3)
Block(-5,44,-9,18:3)
Block(-5,44,-8,18:3)
Block(-5,44,-7,18:3)
Block(-5,44,-6,18:3)
Block(-5,44,-5,18:3)
Block(-5,44,-4,18:3)
Block(-5,44,-3,18:3)
Block(-5,44,-2,18:3)
Block(-5,44,-1,18:3)
Block(-5,44,0,18:3)
Block(-5,44,1,18:3)
Block(-5,44,2,18:3)
Block(-5,44,3,18:3)
Block(-5,44,4,18:3)
Block(-5,44,5,18:3)
Block(-5,44,8,18:3)
Block(-5,44,9,18:3)
Block(-5,44,10,18:3)
Block(-5,44,11,18:3)
Block(-5,44,12,18:3)
Block(-5,45,-8,18:3)
Block(-5,45,-7,18:3)
Block(-5,45,-6,18:3)
Block(-5,45,-5,18:3)
Block(-5,45,-4,18:3)
Block(-5,45,-3,17:15)
Block(-5,45,-2,17:15)
Block(-5,45,-1,18:3)
Block(-5,45,0,18:3)
Block(-5,45,1,18:3)
Block(-5,45,2,18:3)
Block(-5,45,3,18:3)
Block(-5,45,4,17:15)
Block(-5,45,5,18:3)
Block(-5,45,6,18:3)
Block(-5,46,-6,18:3)
Block(-5,46,-5,18:3)
Block(-5,46,-4,18:3)
Block(-5,46,-3,18:3)
Block(-5,46,-2,18:3)
Block(-5,46,-1,18:3)
Block(-5,46,0,18:3)
Block(-5,46,1,18:3)
Block(-5,46,2,18:3)
Block(-5,46,3,18:3)
Block(-5,46,4,18:3)
Block(-5,46,5,18:3)
Block(-5,46,6,18:3)
Block(-5,47,-5,18:3)
Block(-5,47,-1,18:3)
Block(-5,47,0,18:3)
Block(-5,47,1,18:3)
Block(-4,25,-4,17:15)
Block(-4,32,14,106:4)
Block(-4,33,14,106:4)
Block(-4,34,14,106:4)
Block(-4,35,14,106:4)
Block(-4,36,14,106:4)
Block(-4,37,-3,18:3)
Block(-4,37,-2,18:3)
Block(-4,37,-1,17:15)
Block(-4,37,0,18:3)
Block(-4,37,1,18:3)
Block(-4,37,2,18:3)
Block(-4,37,4,18:3)
Block(-4,37,5,18:3)
Block(-4,37,6,17:15)
Block(-4,37,7,18:3)
Block(-4,37,8,18:3)
Block(-4,37,14,106:4)
Block(-4,38,-15,18:3)
Block(-4,38,-14,18:3)
Block(-4,38,-13,18:3)
Block(-4,38,-12,18:3)
Block(-4,38,-9,18:3)
Block(-4,38,-8,18:3)
Block(-4,38,-7,18:3)
Block(-4,38,-3,17:15)
Block(-4,38,-2,18:3)
Block(-4,38,-1,18:3)
Block(-4,38,0,18:3)
Block(-4,38,1,18:3)
Block(-4,38,3,18:3)
Block(-4,38,4,18:3)
Block(-4,38,5,17:15)
Block(-4,38,6,18:3)
Block(-4,38,7,18:3)
Block(-4,38,8,18:3)
Block(-4,38,9,18:3)
Block(-4,38,10,18:3)
Block(-4,38,11,17:15)
Block(-4,38,12,18:3)
Block(-4,38,13,18:3)
Block(-4,38,14,106:4)
Block(-4,39,-15,18:3)
Block(-4,39,-14,18:3)
Block(-4,39,-13,18:3)
Block(-4,39,-11,18:3)
Block(-4,39,-10,18:3)
Block(-4,39,-9,18:3)
Block(-4,39,-8,18:3)
Block(-4,39,-7,18:3)
Block(-4,39,-6,18:3)
Block(-4,39,-5,18:3)
Block(-4,39,-4,18:3)
Block(-4,39,-3,18:3)
Block(-4,39,-2,17:15)
Block(-4,39,-1,18:3)
Block(-4,39,0,17:15)
Block(-4,39,1,18:3)
Block(-4,39,2,18:3)
Block(-4,39,3,18:3)
Block(-4,39,4,18:3)
Block(-4,39,5,18:3)
Block(-4,39,6,18:3)
Block(-4,39,7,18:3)
Block(-4,39,9,18:3)
Block(-4,39,10,18:3)
Block(-4,39,11,18:3)
Block(-4,39,12,18:3)
Block(-4,39,13,18:3)
Block(-4,39,14,106:4)
Block(-4,40,-13,18:3)
Block(-4,40,-12,18:3)
Block(-4,40,-11,17:15)
Block(-4,40,-10,18:3)
Block(-4,40,-9,18:3)
Block(-4,40,-8,18:3)
Block(-4,40,-7,17:15)
Block(-4,40,-6,18:3)
Block(-4,40,-5,18:3)
Block(-4,40,-4,18:3)
Block(-4,40,-3,18:3)
Block(-4,40,-2,18:3)
Block(-4,40,-1,18:3)
Block(-4,40,0,18:3)
Block(-4,40,1,18:3)
Block(-4,40,2,18:3)
Block(-4,40,4,18:3)
Block(-4,40,5,18:3)
Block(-4,40,6,18:3)
Block(-4,40,7,18:3)
Block(-4,40,8,18:3)
Block(-4,41,-13,18:3)
Block(-4,41,-12,18:3)
Block(-4,41,-11,18:3)
Block(-4,41,-10,18:3)
Block(-4,41,-9,18:3)
Block(-4,41,-8,18:3)
Block(-4,41,-7,17:15)
Block(-4,41,-6,18:3)
Block(-4,41,-5,18:3)
Block(-4,41,-4,17:15)
Block(-4,41,-3,17:15)
Block(-4,41,-2,18:3)
Block(-4,41,-1,18:3)
Block(-4,41,0,18:3)
Block(-4,41,1,18:3)
Block(-4,41,2,18:3)
Block(-4,41,3,18:3)
Block(-4,41,4,18:3)
Block(-4,41,5,18:3)
Block(-4,41,6,18:3)
Block(-4,41,7,18:3)
Block(-4,41,8,17:15)
Block(-4,41,9,18:3)
Block(-4,41,10,18:3)
Block(-4,41,11,18:3)
Block(-4,41,12,18:3)
Block(-4,41,13,18:3)
Block(-4,41,14,18:3)
Block(-4,42,-10,18:3)
Block(-4,42,-9,18:3)
Block(-4,42,-8,18:3)
Block(-4,42,-7,18:3)
Block(-4,42,-6,18:3)
Block(-4,42,-5,18:3)
Block(-4,42,-4,17:15)
Block(-4,42,-3,18:3)
Block(-4,42,-2,18:3)
Block(-4,42,-1,18:3)
Block(-4,42,0,18:3)
Block(-4,42,1,18:3)
Block(-4,42,2,17:15)
Block(-4,42,3,18:3)
Block(-4,42,4,18:3)
Block(-4,42,6,18:3)
Block(-4,42,7,18:3)
Block(-4,42,8,18:3)
Block(-4,42,9,18:3)
Block(-4,42,10,18:3)
Block(-4,42,11,18:3)
Block(-4,42,12,18:3)
Block(-4,42,13,18:3)
Block(-4,43,-9,18:3)
Block(-4,43,-8,18:3)
Block(-4,43,-7,18:3)
Block(-4,43,-6,18:3)
Block(-4,43,-5,18:3)
Block(-4,43,-4,18:3)
Block(-4,43,-3,18:3)
Block(-4,43,-2,18:3)
Block(-4,43,-1,18:3)
Block(-4,43,0,17:15)
Block(-4,43,1,18:3)
Block(-4,43,2,18:3)
Block(-4,43,3,17:15)
Block(-4,43,4,18:3)
Block(-4,43,5,18:3)
Block(-4,43,6,18:3)
Block(-4,43,8,18:3)
Block(-4,43,9,18:3)
Block(-4,43,10,18:3)
Block(-4,43,11,18:3)
Block(-4,43,12,18:3)
Block(-4,44,-9,18:3)
Block(-4,44,-8,18:3)
Block(-4,44,-7,17:15)
Block(-4,44,-6,18:3)
Block(-4,44,-5,18:3)
Block(-4,44,-4,18:3)
Block(-4,44,-3,18:3)
Block(-4,44,-2,18:3)
Block(-4,44,-1,18:3)
Block(-4,44,0,17:15)
Block(-4,44,1,18:3)
Block(-4,44,2,18:3)
Block(-4,44,3,18:3)
Block(-4,44,4,18:3)
Block(-4,44,5,18:3)
Block(-4,44,6,18:3)
Block(-4,44,9,18:3)
Block(-4,44,10,18:3)
Block(-4,44,11,18:3)
Block(-4,45,-9,18:3)
Block(-4,45,-8,18:3)
Block(-4,45,-7,18:3)
Block(-4,45,-6,18:3)
Block(-4,45,-5,18:3)
Block(-4,45,-4,18:3)
Block(-4,45,-3,18:3)
Block(-4,45,-2,17:15)
Block(-4,45,-1,17:15)
Block(-4,45,0,17:15)
Block(-4,45,1,18:3)
Block(-4,45,2,18:3)
Block(-4,45,3,18:3)
Block(-4,45,4,18:3)
Block(-4,45,5,18:3)
Block(-4,45,6,18:3)
Block(-4,45,7,18:3)
Block(-4,45,8,18:3)
Block(-4,45,9,18:3)
Block(-4,46,-7,18:3)
Block(-4,46,-6,18:3)
Block(-4,46,-5,18:3)
Block(-4,46,-4,18:3)
Block(-4,46,-3,18:3)
Block(-4,46,-2,18:3)
Block(-4,46,-1,18:3)
Block(-4,46,0,17:15)
Block(-4,46,1,18:3)
Block(-4,46,2,18:3)
Block(-4,46,3,18:3)
Block(-4,46,4,18:3)
Block(-4,46,5,18:3)
Block(-4,46,8,18:3)
Block(-4,47,-6,18:3)
Block(-4,47,-5,18:3)
Block(-4,47,-4,18:3)
Block(-4,47,-2,18:3)
Block(-4,47,-1,18:3)
Block(-4,47,0,18:3)
Block(-4,47,1,18:3)
Block(-4,47,2,18:3)
Block(-3,23,-3,17:15)
Block(-3,24,-3,17:15)
Block(-3,36,-2,17:15)
Block(-3,36,14,106:4)
Block(-3,37,-3,17:15)
Block(-3,37,-2,18:3)
Block(-3,37,-1,18:3)
Block(-3,37,0,18:3)
Block(-3,37,1,18:3)
Block(-3,37,4,18:3)
Block(-3,37,5,18:3)
Block(-3,37,6,18:3)
Block(-3,37,7,18:3)
Block(-3,37,8,18:3)
Block(-3,37,14,106:4)
Block(-3,38,-15,18:3)
Block(-3,38,-14,17:15)
Block(-3,38,-13,18:3)
Block(-3,38,-12,18:3)
Block(-3,38,-10,18:3)
Block(-3,38,-9,18:3)
Block(-3,38,-8,18:3)
Block(-3,38,-7,18:3)
Block(-3,38,-6,18:3)
Block(-3,38,-5,17:15)
Block(-3,38,-4,18:3)
Block(-3,38,-2,18:3)
Block(-3,38,-1,18:3)
Block(-3,38,0,18:3)
Block(-3,38,3,18:3)
Block(-3,38,4,18:3)
Block(-3,38,5,18:3)
Block(-3,38,6,18:3)
Block(-3,38,7,18:3)
Block(-3,38,9,18:3)
Block(-3,38,10,18:3)
Block(-3,38,11,18:3)
Block(-3,38,12,18:3)
Block(-3,38,13,18:3)
Block(-3,38,14,106:4)
Block(-3,39,-15,18:3)
Block(-3,39,-14,18:3)
Block(-3,39,-13,18:3)
Block(-3,39,-12,18:3)
Block(-3,39,-9,18:3)
Block(-3,39,-8,18:3)
Block(-3,39,-7,18:3)
Block(-3,39,-6,17:15)
Block(-3,39,-5,18:3)
Block(-3,39,-4,18:3)
Block(-3,39,-3,18:3)
Block(-3,39,-2,18:3)
Block(-3,39,-1,18:3)
Block(-3,39,0,18:3)
Block(-3,39,1,18:3)
Block(-3,39,2,18:3)
Block(-3,39,4,18:3)
Block(-3,39,5,18:3)
Block(-3,39,6,18:3)
Block(-3,39,10,18:3)
Block(-3,39,11,18:3)
Block(-3,39,12,18:3)
Block(-3,40,-13,18:3)
Block(-3,40,-12,18:3)
Block(-3,40,-11,18:3)
Block(-3,40,-10,18:3)
Block(-3,40,-9,18:3)
Block(-3,40,-8,18:3)
Block(-3,40,-7,18:3)
Block(-3,40,-6,18:3)
Block(-3,40,-5,18:3)
Block(-3,40,-4,18:3)
Block(-3,40,-3,17:15)
Block(-3,40,-2,18:3)
Block(-3,40,-1,18:3)
Block(-3,40,0,18:3)
Block(-3,40,1,18:3)
Block(-3,40,5,18:3)
Block(-3,40,6,18:3)
Block(-3,40,7,18:3)
Block(-3,40,8,18:3)
Block(-3,40,9,18:3)
Block(-3,41,-12,18:3)
Block(-3,41,-11,18:3)
Block(-3,41,-10,18:3)
Block(-3,41,-9,18:3)
Block(-3,41,-8,18:3)
Block(-3,41,-7,18:3)
Block(-3,41,-6,18:3)
Block(-3,41,-5,18:3)
Block(-3,41,-4,18:3)
Block(-3,41,-3,18:3)
Block(-3,41,-2,18:3)
Block(-3,41,-1,18:3)
Block(-3,41,0,18:3)
Block(-3,41,1,17:15)
Block(-3,41,2,18:3)
Block(-3,41,3,17:15)
Block(-3,41,4,18:3)
Block(-3,41,5,18:3)
Block(-3,41,6,18:3)
Block(-3,41,7,18:3)
Block(-3,41,8,18:3)
Block(-3,41,9,18:3)
Block(-3,41,10,17:15)
Block(-3,41,11,18:3)
Block(-3,41,12,18:3)
Block(-3,41,13,18:3)
Block(-3,41,14,18:3)
Block(-3,42,-11,18:3)
Block(-3,42,-10,18:3)
Block(-3,42,-9,18:3)
Block(-3,42,-8,18:3)
Block(-3,42,-7,18:3)
Block(-3,42,-6,18:3)
Block(-3,42,-5,18:3)
Block(-3,42,-4,18:3)
Block(-3,42,-3,18:3)
Block(-3,42,-2,18:3)
Block(-3,42,0,17:15)
Block(-3,42,1,18:3)
Block(-3,42,2,18:3)
Block(-3,42,3,18:3)
Block(-3,42,4,18:3)
Block(-3,42,5,18:3)
Block(-3,42,7,18:3)
Block(-3,42,8,18:3)
Block(-3,42,9,18:3)
Block(-3,42,10,18:3)
Block(-3,42,11,18:3)
Block(-3,42,12,18:3)
Block(-3,42,13,18:3)
Block(-3,43,-10,18:3)
Block(-3,43,-9,18:3)
Block(-3,43,-8,18:3)
Block(-3,43,-7,18:3)
Block(-3,43,-6,18:3)
Block(-3,43,-5,18:3)
Block(-3,43,-4,17:15)
Block(-3,43,-3,18:3)
Block(-3,43,-2,17:15)
Block(-3,43,-1,17:15)
Block(-3,43,0,18:3)
Block(-3,43,1,17:15)
Block(-3,43,2,18:3)
Block(-3,43,3,18:3)
Block(-3,43,4,18:3)
Block(-3,43,5,18:3)
Block(-3,43,6,18:3)
Block(-3,43,7,18:3)
Block(-3,43,9,18:3)
Block(-3,43,10,18:3)
Block(-3,43,11,18:3)
Block(-3,44,-9,18:3)
Block(-3,44,-8,18:3)
Block(-3,44,-7,18:3)
Block(-3,44,-6,18:3)
Block(-3,44,-5,18:3)
Block(-3,44,-4,18:3)
Block(-3,44,-3,18:3)
Block(-3,44,-2,18:3)
Block(-3,44,-1,18:3)
Block(-3,44,0,17:15)
Block(-3,44,1,18:3)
Block(-3,44,2,18:3)
Block(-3,44,3,18:3)
Block(-3,44,4,17:15)
Block(-3,44,5,18:3)
Block(-3,44,6,18:3)
Block(-3,44,7,18:3)
Block(-3,44,10,18:3)
Block(-3,45,-8,18:3)
Block(-3,45,-7,18:3)
Block(-3,45,-6,18:3)
Block(-3,45,-5,17:15)
Block(-3,45,-4,18:3)
Block(-3,45,-3,18:3)
Block(-3,45,-2,17:15)
Block(-3,45,-1,18:3)
Block(-3,45,0,17:15)
Block(-3,45,1,18:3)
Block(-3,45,2,18:3)
Block(-3,45,3,18:3)
Block(-3,45,4,18:3)
Block(-3,45,5,18:3)
Block(-3,45,6,18:3)
Block(-3,45,7,18:3)
Block(-3,45,8,18:3)
Block(-3,45,9,18:3)
Block(-3,45,10,18:3)
Block(-3,46,-7,18:3)
Block(-3,46,-6,18:3)
Block(-3,46,-5,17:15)
Block(-3,46,-4,18:3)
Block(-3,46,-3,18:3)
Block(-3,46,-2,18:3)
Block(-3,46,-1,18:3)
Block(-3,46,0,18:3)
Block(-3,46,1,18:3)
Block(-3,46,2,18:3)
Block(-3,46,3,18:3)
Block(-3,46,4,18:3)
Block(-3,46,5,18:3)
Block(-3,46,6,18:3)
Block(-3,46,7,18:3)
Block(-3,46,8,18:3)
Block(-3,46,9,18:3)
Block(-3,47,-7,18:3)
Block(-3,47,-6,18:3)
Block(-3,47,-5,18:3)
Block(-3,47,-4,18:3)
Block(-3,47,-3,18:3)
Block(-3,47,-2,18:3)
Block(-3,47,-1,18:3)
Block(-3,47,0,18:3)
Block(-3,47,1,18:3)
Block(-3,47,5,18:3)
Block(-3,47,6,18:3)
Block(-3,47,8,18:3)
Block(-2,22,-2,17:15)
Block(-2,35,-2,17:15)
Block(-2,36,-3,17:15)
Block(-2,36,13,106:4)
Block(-2,37,-4,17:15)
Block(-2,37,-2,18:3)
Block(-2,37,-1,18:3)
Block(-2,37,0,18:3)
Block(-2,37,5,18:3)
Block(-2,37,6,18:3)
Block(-2,37,7,18:3)
Block(-2,37,8,18:3)
Block(-2,37,9,18:3)
Block(-2,37,13,106:4)
Block(-2,38,-15,18:3)
Block(-2,38,-14,18:3)
Block(-2,38,-13,18:3)
Block(-2,38,-12,18:3)
Block(-2,38,-10,18:3)
Block(-2,38,-9,18:3)
Block(-2,38,-8,17:15)
Block(-2,38,-7,18:3)
Block(-2,38,-6,18:3)
Block(-2,38,-5,18:3)
Block(-2,38,-4,18:3)
Block(-2,38,-3,18:3)
Block(-2,38,-2,17:15)
Block(-2,38,-1,18:3)
Block(-2,38,4,18:3)
Block(-2,38,5,18:3)
Block(-2,38,6,18:3)
Block(-2,38,8,18:3)
Block(-2,38,10,18:3)
Block(-2,38,11,18:3)
Block(-2,38,12,18:3)
Block(-2,38,13,106:4)
Block(-2,39,-15,18:3)
Block(-2,39,-14,18:3)
Block(-2,39,-13,18:3)
Block(-2,39,-10,18:3)
Block(-2,39,-9,18:3)
Block(-2,39,-8,18:3)
Block(-2,39,-7,18:3)
Block(-2,39,-6,18:3)
Block(-2,39,-5,18:3)
Block(-2,39,-4,18:3)
Block(-2,39,-3,18:3)
Block(-2,39,-2,17:15)
Block(-2,39,-1,18:3)
Block(-2,39,0,18:3)
Block(-2,39,1,18:3)
Block(-2,39,5,18:3)
Block(-2,39,11,18:3)
Block(-2,40,-13,18:3)
Block(-2,40,-12,18:3)
Block(-2,40,-11,18:3)
Block(-2,40,-10,18:3)
Block(-2,40,-9,18:3)
Block(-2,40,-8,18:3)
Block(-2,40,-7,18:3)
Block(-2,40,-6,18:3)
Block(-2,40,-5,18:3)
Block(-2,40,-4,18:3)
Block(-2,40,-3,17:15)
Block(-2,40,-2,18:3)
Block(-2,40,-1,18:3)
Block(-2,40,0,18:3)
Block(-2,40,1,17:15)
Block(-2,40,5,18:3)
Block(-2,40,6,18:3)
Block(-2,40,7,18:3)
Block(-2,40,8,18:3)
Block(-2,40,9,18:3)
Block(-2,40,10,18:3)
Block(-2,41,-11,18:3)
Block(-2,41,-10,18:3)
Block(-2,41,-9,18:3)
Block(-2,41,-8,18:3)
Block(-2,41,-7,18:3)
Block(-2,41,-6,18:3)
Block(-2,41,-5,18:3)
Block(-2,41,-4,18:3)
Block(-2,41,-3,18:3)
Block(-2,41,-2,18:3)
Block(-2,41,-1,18:3)
Block(-2,41,0,17:15)
Block(-2,41,1,18:3)
Block(-2,41,2,18:3)
Block(-2,41,3,18:3)
Block(-2,41,4,18:3)
Block(-2,41,5,18:3)
Block(-2,41,6,18:3)
Block(-2,41,7,18:3)
Block(-2,41,8,18:3)
Block(-2,41,9,18:3)
Block(-2,41,10,18:3)
Block(-2,41,11,18:3)
Block(-2,41,12,18:3)
Block(-2,41,13,18:3)
Block(-2,41,14,18:3)
Block(-2,41,15,18:3)
Block(-2,42,-11,18:3)
Block(-2,42,-10,18:3)
Block(-2,42,-9,17:15)
Block(-2,42,-8,18:3)
Block(-2,42,-7,18:3)
Block(-2,42,-6,18:3)
Block(-2,42,-5,18:3)
Block(-2,42,-4,18:3)
Block(-2,42,-3,18:3)
Block(-2,42,-2,18:3)
Block(-2,42,-1,18:3)
Block(-2,42,0,18:3)
Block(-2,42,1,18:3)
Block(-2,42,2,17:15)
Block(-2,42,3,18:3)
Block(-2,42,4,18:3)
Block(-2,42,7,18:3)
Block(-2,42,8,18:3)
Block(-2,42,9,18:3)
Block(-2,42,10,18:3)
Block(-2,42,11,18:3)
Block(-2,42,12,18:3)
Block(-2,42,13,18:3)
Block(-2,42,14,18:3)
Block(-2,43,-11,18:3)
Block(-2,43,-10,18:3)
Block(-2,43,-9,18:3)
Block(-2,43,-8,17:15)
Block(-2,43,-7,18:3)
Block(-2,43,-6,18:3)
Block(-2,43,-5,18:3)
Block(-2,43,-4,18:3)
Block(-2,43,-3,18:3)
Block(-2,43,-2,18:3)
Block(-2,43,-1,18:3)
Block(-2,43,0,17:15)
Block(-2,43,1,18:3)
Block(-2,43,2,18:3)
Block(-2,43,3,18:3)
Block(-2,43,4,18:3)
Block(-2,43,5,17:15)
Block(-2,43,6,18:3)
Block(-2,43,7,18:3)
Block(-2,43,8,18:3)
Block(-2,43,9,18:3)
Block(-2,43,10,18:3)
Block(-2,44,-10,18:3)
Block(-2,44,-9,18:3)
Block(-2,44,-8,18:3)
Block(-2,44,-7,18:3)
Block(-2,44,-6,18:3)
Block(-2,44,-5,18:3)
Block(-2,44,-4,18:3)
Block(-2,44,-3,18:3)
Block(-2,44,-2,18:3)
Block(-2,44,-1,18:3)
Block(-2,44,0,17:15)
Block(-2,44,1,18:3)
Block(-2,44,2,18:3)
Block(-2,44,3,18:3)
Block(-2,44,4,18:3)
Block(-2,44,5,18:3)
Block(-2,44,6,18:3)
Block(-2,44,7,18:3)
Block(-2,44,8,18:3)
Block(-2,45,-9,18:3)
Block(-2,45,-8,18:3)
Block(-2,45,-7,18:3)
Block(-2,45,-6,18:3)
Block(-2,45,-5,18:3)
Block(-2,45,-4,18:3)
Block(-2,45,-3,18:3)
Block(-2,45,-2,17:15)
Block(-2,45,-1,18:3)
Block(-2,45,0,18:3)
Block(-2,45,1,18:3)
Block(-2,45,2,18:3)
Block(-2,45,3,18:3)
Block(-2,45,4,18:3)
Block(-2,45,5,18:3)
Block(-2,45,6,18:3)
Block(-2,45,7,18:3)
Block(-2,45,8,17:15)
Block(-2,45,9,18:3)
Block(-2,45,10,18:3)
Block(-2,46,-7,18:3)
Block(-2,46,-6,18:3)
Block(-2,46,-5,18:3)
Block(-2,46,-4,17:15)
Block(-2,46,-3,18:3)
Block(-2,46,-2,18:3)
Block(-2,46,-1,17:15)
Block(-2,46,0,18:3)
Block(-2,46,1,18:3)
Block(-2,46,2,18:3)
Block(-2,46,3,18:3)
Block(-2,46,4,18:3)
Block(-2,46,5,18:3)
Block(-2,46,6,18:3)
Block(-2,46,7,18:3)
Block(-2,46,8,18:3)
Block(-2,46,9,18:3)
Block(-2,46,10,18:3)
Block(-2,47,-6,18:3)
Block(-2,47,-5,18:3)
Block(-2,47,-4,18:3)
Block(-2,47,-3,18:3)
Block(-2,47,-2,18:3)
Block(-2,47,-1,18:3)
Block(-2,47,0,18:3)
Block(-2,47,1,18:3)
Block(-2,47,2,18:3)
Block(-2,47,3,18:3)
Block(-2,47,4,18:3)
Block(-2,47,5,18:3)
Block(-2,47,6,18:3)
Block(-2,47,7,18:3)
Block(-2,47,8,18:3)
Block(-2,47,9,18:3)
Block(-1,21,-1,17:15)
Block(-1,32,0,17:15)
Block(-1,33,-16,106:1)
Block(-1,33,1,17:15)
Block(-1,34,-16,106:1)
Block(-1,34,-1,17:15)
Block(-1,34,2,17:15)
Block(-1,34,11,106:4)
Block(-1,35,-16,106:1)
Block(-1,35,-2,17:15)
Block(-1,35,3,17:15)
Block(-1,35,11,106:4)
Block(-1,36,-16,106:1)
Block(-1,36,4,17:15)
Block(-1,36,11,106:6)
Block(-1,37,-16,106:1)
Block(-1,37,-1,17:15)
Block(-1,37,5,17:15)
Block(-1,37,6,18:3)
Block(-1,37,7,18:3)
Block(-1,37,8,18:3)
Block(-1,37,9,18:3)
Block(-1,37,10,18:3)
Block(-1,37,11,106:6)
Block(-1,38,-16,106:1)
Block(-1,38,-15,18:3)
Block(-1,38,-14,18:3)
Block(-1,38,-13,18:3)
Block(-1,38,-12,18:3)
Block(-1,38,-11,18:3)
Block(-1,38,-10,18:3)
Block(-1,38,-9,18:3)
Block(-1,38,-8,18:3)
Block(-1,38,-7,18:3)
Block(-1,38,-6,18:3)
Block(-1,38,-5,17:15)
Block(-1,38,-4,18:3)
Block(-1,38,-3,18:3)
Block(-1,38,6,17:15)
Block(-1,38,7,18:3)
Block(-1,38,8,18:3)
Block(-1,38,9,18:3)
Block(-1,38,11,106:2)
Block(-1,39,-14,18:3)
Block(-1,39,-13,18:3)
Block(-1,39,-12,18:3)
Block(-1,39,-10,18:3)
Block(-1,39,-9,18:3)
Block(-1,39,-8,18:3)
Block(-1,39,-7,18:3)
Block(-1,39,-6,18:3)
Block(-1,39,-5,18:3)
Block(-1,39,-4,18:3)
Block(-1,39,-3,18:3)
Block(-1,39,0,17:15)
Block(-1,39,3,18:3)
Block(-1,39,4,18:3)
Block(-1,39,5,18:3)
Block(-1,39,7,17:15)
Block(-1,39,11,106:2)
Block(-1,40,-13,18:3)
Block(-1,40,-12,18:3)
Block(-1,40,-11,18:3)
Block(-1,40,-10,17:15)
Block(-1,40,-9,18:3)
Block(-1,40,-8,18:3)
Block(-1,40,-7,18:3)
Block(-1,40,-6,18:3)
Block(-1,40,-5,18:3)
Block(-1,40,-4,18:3)
Block(-1,40,-3,18:3)
Block(-1,40,-2,18:3)
Block(-1,40,-1,18:3)
Block(-1,40,0,17:15)
Block(-1,40,4,18:3)
Block(-1,40,5,18:3)
Block(-1,40,6,18:3)
Block(-1,40,7,17:15)
Block(-1,40,8,17:15)
Block(-1,40,9,18:3)
Block(-1,40,10,18:3)
Block(-1,40,11,18:3)
Block(-1,41,-12,18:3)
Block(-1,41,-11,18:3)
Block(-1,41,-10,18:3)
Block(-1,41,-9,18:3)
Block(-1,41,-8,18:3)
Block(-1,41,-7,18:3)
Block(-1,41,-6,18:3)
Block(-1,41,-5,18:3)
Block(-1,41,-4,18:3)
Block(-1,41,-3,18:3)
Block(-1,41,-2,18:3)
Block(-1,41,-1,18:3)
Block(-1,41,2,18:3)
Block(-1,41,3,18:3)
Block(-1,41,4,18:3)
Block(-1,41,5,18:3)
Block(-1,41,6,18:3)
Block(-1,41,7,18:3)
Block(-1,41,8,18:3)
Block(-1,41,9,18:3)
Block(-1,41,10,18:3)
Block(-1,41,11,18:3)
Block(-1,41,12,18:3)
Block(-1,41,13,17:15)
Block(-1,41,14,18:3)
Block(-1,41,15,18:3)
Block(-1,42,-11,18:3)
Block(-1,42,-10,18:3)
Block(-1,42,-9,18:3)
Block(-1,42,-8,18:3)
Block(-1,42,-7,18:3)
Block(-1,42,-6,18:3)
Block(-1,42,-5,18:3)
Block(-1,42,-4,18:3)
Block(-1,42,-3,17:15)
Block(-1,42,-2,18:3)
Block(-1,42,-1,18:3)
Block(-1,42,0,17:15)
Block(-1,42,1,18:3)
Block(-1,42,2,18:3)
Block(-1,42,3,18:3)
Block(-1,42,4,18:3)
Block(-1,42,7,18:3)
Block(-1,42,8,18:3)
Block(-1,42,9,17:15)
Block(-1,42,10,18:3)
Block(-1,42,11,18:3)
Block(-1,42,12,18:3)
Block(-1,42,13,18:3)
Block(-1,42,14,18:3)
Block(-1,42,15,18:3)
Block(-1,43,-10,18:3)
Block(-1,43,-9,18:3)
Block(-1,43,-8,18:3)
Block(-1,43,-7,18:3)
Block(-1,43,-6,18:3)
Block(-1,43,-5,18:3)
Block(-1,43,-4,18:3)
Block(-1,43,-3,18:3)
Block(-1,43,-2,18:3)
Block(-1,43,-1,18:3)
Block(-1,43,0,18:3)
Block(-1,43,1,18:3)
Block(-1,43,2,18:3)
Block(-1,43,3,18:3)
Block(-1,43,4,18:3)
Block(-1,43,5,18:3)
Block(-1,43,6,18:3)
Block(-1,43,7,18:3)
Block(-1,43,8,18:3)
Block(-1,43,9,18:3)
Block(-1,43,10,18:3)
Block(-1,43,11,18:3)
Block(-1,44,-10,18:3)
Block(-1,44,-9,18:3)
Block(-1,44,-8,17:15)
Block(-1,44,-7,18:3)
Block(-1,44,-6,18:3)
Block(-1,44,-5,18:3)
Block(-1,44,-4,18:3)
Block(-1,44,-3,17:15)
Block(-1,44,-2,18:3)
Block(-1,44,-1,18:3)
Block(-1,44,0,18:3)
Block(-1,44,1,18:3)
Block(-1,44,2,18:3)
Block(-1,44,3,18:3)
Block(-1,44,4,18:3)
Block(-1,44,5,18:3)
Block(-1,44,6,17:15)
Block(-1,44,7,18:3)
Block(-1,44,8,18:3)
Block(-1,44,9,18:3)
Block(-1,45,-10,18:3)
Block(-1,45,-9,18:3)
Block(-1,45,-8,18:3)
Block(-1,45,-7,18:3)
Block(-1,45,-6,18:3)
Block(-1,45,-5,18:3)
Block(-1,45,-4,18:3)
Block(-1,45,-3,18:3)
Block(-1,45,-2,18:3)
Block(-1,45,-1,18:3)
Block(-1,45,0,18:3)
Block(-1,45,1,17:15)
Block(-1,45,2,18:3)
Block(-1,45,3,17:15)
Block(-1,45,4,18:3)
Block(-1,45,5,18:3)
Block(-1,45,6,18:3)
Block(-1,45,7,18:3)
Block(-1,45,8,18:3)
Block(-1,45,9,18:3)
Block(-1,45,10,18:3)
Block(-1,46,-8,18:3)
Block(-1,46,-7,18:3)
Block(-1,46,-6,18:3)
Block(-1,46,-5,17:15)
Block(-1,46,-4,18:3)
Block(-1,46,-3,18:3)
Block(-1,46,-2,18:3)
Block(-1,46,-1,18:3)
Block(-1,46,0,18:3)
Block(-1,46,1,18:3)
Block(-1,46,2,18:3)
Block(-1,46,3,18:3)
Block(-1,46,4,18:3)
Block(-1,46,5,17:15)
Block(-1,46,6,17:15)
Block(-1,46,7,18:3)
Block(-1,46,8,17:15)
Block(-1,46,9,18:3)
Block(-1,46,10,18:3)
Block(-1,47,-7,18:3)
Block(-1,47,-6,18:3)
Block(-1,47,-5,18:3)
Block(-1,47,-4,18:3)
Block(-1,47,-3,18:3)
Block(-1,47,-2,18:3)
Block(-1,47,-1,18:3)
Block(-1,47,0,18:3)
Block(-1,47,1,18:3)
Block(-1,47,2,18:3)
Block(-1,47,3,18:3)
Block(-1,47,4,18:3)
Block(-1,47,5,18:3)
Block(-1,47,6,18:3)
Block(-1,47,7,18:3)
Block(-1,47,8,18:3)
Block(-1,47,9,18:3)
Block(-1,47,10,18:3)
Block(0,0,0,17:15)
Block(0,1,0,17:15)
Block(0,2,0,17:15)
Block(0,3,0,17:15)
Block(0,4,0,17:15)
Block(0,5,0,17:15)
Block(0,6,0,17:15)
Block(0,7,0,17:15)
Block(0,8,0,17:15)
Block(0,9,0,17:15)
Block(0,10,0,17:15)
Block(0,11,0,17:15)
Block(0,12,0,17:15)
Block(0,13,0,17:15)
Block(0,14,0,17:15)
Block(0,15,0,17:15)
Block(0,16,0,17:15)
Block(0,17,0,17:15)
Block(0,18,0,17:15)
Block(0,19,0,17:15)
Block(0,20,0,17:15)
Block(0,21,0,17:15)
Block(0,22,0,17:15)
Block(0,23,0,17:15)
Block(0,24,0,17:15)
Block(0,25,0,17:15)
Block(0,26,0,17:15)
Block(0,26,1,17:15)
Block(0,27,0,17:15)
Block(0,28,0,17:15)
Block(0,29,0,17:15)
Block(0,30,0,17:15)
Block(0,30,1,17:15)
Block(0,31,0,17:15)
Block(0,31,2,17:15)
Block(0,32,-1,17:15)
Block(0,32,0,17:15)
Block(0,32,3,17:15)
Block(0,33,-2,17:15)
Block(0,33,0,17:15)
Block(0,33,4,17:15)
Block(0,34,-3,17:15)
Block(0,34,0,17:15)
Block(0,34,5,17:15)
Block(0,35,-16,106:1)
Block(0,35,-4,17:15)
Block(0,35,0,17:15)
Block(0,35,6,17:15)
Block(0,36,-16,106:1)
Block(0,36,-1,17:15)
Block(0,36,0,17:15)
Block(0,36,7,17:15)
Block(0,37,-16,106:1)
Block(0,37,0,17:15)
Block(0,37,6,18:3)
Block(0,37,7,18:3)
Block(0,37,8,17:15)
Block(0,37,9,18:3)
Block(0,37,10,18:3)
Block(0,38,-16,106:1)
Block(0,38,-15,18:3)
Block(0,38,-14,18:3)
Block(0,38,-13,17:15)
Block(0,38,-12,18:3)
Block(0,38,-11,18:3)
Block(0,38,-10,18:3)
Block(0,38,-9,17:15)
Block(0,38,-8,18:3)
Block(0,38,-7,18:3)
Block(0,38,-6,18:3)
Block(0,38,-5,18:3)
Block(0,38,-4,18:3)
Block(0,38,-3,18:3)
Block(0,38,0,17:15)
Block(0,38,6,18:3)
Block(0,38,7,18:3)
Block(0,38,8,18:3)
Block(0,38,9,18:3)
Block(0,38,10,18:3)
Block(0,39,-15,18:3)
Block(0,39,-14,18:3)
Block(0,39,-13,18:3)
Block(0,39,-12,18:3)
Block(0,39,-11,18:3)
Block(0,39,-10,18:3)
Block(0,39,-9,18:3)
Block(0,39,-8,18:3)
Block(0,39,-7,18:3)
Block(0,39,-6,18:3)
Block(0,39,-5,18:3)
Block(0,39,-4,18:3)
Block(0,39,0,17:15)
Block(0,39,2,18:3)
Block(0,39,3,18:3)
Block(0,39,4,18:3)
Block(0,39,5,18:3)
Block(0,39,6,18:3)
Block(0,40,-13,18:3)
Block(0,40,-12,18:3)
Block(0,40,-11,18:3)
Block(0,40,-10,18:3)
Block(0,40,-9,18:3)
Block(0,40,-8,18:3)
Block(0,40,-7,18:3)
Block(0,40,-6,18:3)
Block(0,40,-5,17:15)
Block(0,40,-4,18:3)
Block(0,40,-3,18:3)
Block(0,40,-2,18:3)
Block(0,40,-1,17:15)
Block(0,40,0,17:15)
Block(0,40,1,17:15)
Block(0,40,3,18:3)
Block(0,40,4,18:3)
Block(0,40,5,18:3)
Block(0,40,6,18:3)
Block(0,40,7,18:3)
Block(0,40,8,18:3)
Block(0,40,9,17:15)
Block(0,40,10,18:3)
Block(0,40,11,18:3)
Block(0,41,-11,18:3)
Block(0,41,-10,18:3)
Block(0,41,-9,17:15)
Block(0,41,-8,18:3)
Block(0,41,-7,18:3)
Block(0,41,-6,18:3)
Block(0,41,-5,18:3)
Block(0,41,-4,18:3)
Block(0,41,-3,18:3)
Block(0,41,-2,18:3)
Block(0,41,-1,18:3)
Block(0,41,0,17:15)
Block(0,41,2,17:15)
Block(0,41,5,18:3)
Block(0,41,6,18:3)
Block(0,41,7,18:3)
Block(0,41,8,18:3)
Block(0,41,9,18:3)
Block(0,41,10,18:3)
Block(0,41,11,18:3)
Block(0,41,12,18:3)
Block(0,41,13,18:3)
Block(0,41,14,18:3)
Block(0,41,15,18:3)
Block(0,42,-11,18:3)
Block(0,42,-10,18:3)
Block(0,42,-9,18:3)
Block(0,42,-8,17:15)
Block(0,42,-7,18:3)
Block(0,42,-6,18:3)
Block(0,42,-5,17:15)
Block(0,42,-4,18:3)
Block(0,42,-3,18:3)
Block(0,42,-2,18:3)
Block(0,42,-1,17:15)
Block(0,42,0,17:15)
Block(0,42,1,18:3)
Block(0,42,2,18:3)
Block(0,42,3,17:15)
Block(0,42,6,18:3)
Block(0,42,7,18:3)
Block(0,42,8,18:3)
Block(0,42,9,18:3)
Block(0,42,10,18:3)
Block(0,42,11,18:3)
Block(0,42,12,18:3)
Block(0,42,13,18:3)
Block(0,42,14,18:3)
Block(0,43,-10,18:3)
Block(0,43,-9,18:3)
Block(0,43,-8,18:3)
Block(0,43,-7,18:3)
Block(0,43,-6,18:3)
Block(0,43,-5,18:3)
Block(0,43,-4,18:3)
Block(0,43,-3,18:3)
Block(0,43,-2,18:3)
Block(0,43,-1,17:15)
Block(0,43,0,17:15)
Block(0,43,1,18:3)
Block(0,43,2,17:15)
Block(0,43,3,18:3)
Block(0,43,4,17:15)
Block(0,43,5,18:3)
Block(0,43,6,18:3)
Block(0,43,7,18:3)
Block(0,43,8,17:15)
Block(0,43,9,18:3)
Block(0,43,10,18:3)
Block(0,43,11,18:3)
Block(0,44,-10,18:3)
Block(0,44,-9,18:3)
Block(0,44,-8,18:3)
Block(0,44,-7,18:3)
Block(0,44,-6,18:3)
Block(0,44,-5,18:3)
Block(0,44,-4,18:3)
Block(0,44,-3,18:3)
Block(0,44,-2,18:3)
Block(0,44,-1,17:15)
Block(0,44,0,18:3)
Block(0,44,1,17:15)
Block(0,44,2,18:3)
Block(0,44,3,18:3)
Block(0,44,4,18:3)
Block(0,44,5,18:3)
Block(0,44,6,18:3)
Block(0,44,7,18:3)
Block(0,44,8,18:3)
Block(0,44,9,18:3)
Block(0,44,10,18:3)
Block(0,45,-9,18:3)
Block(0,45,-8,18:3)
Block(0,45,-7,17:15)
Block(0,45,-6,18:3)
Block(0,45,-5,18:3)
Block(0,45,-4,18:3)
Block(0,45,-3,18:3)
Block(0,45,-2,18:3)
Block(0,45,-1,17:15)
Block(0,45,0,18:3)
Block(0,45,1,17:15)
Block(0,45,2,18:3)
Block(0,45,3,18:3)
Block(0,45,4,18:3)
Block(0,45,5,18:3)
Block(0,45,6,18:3)
Block(0,45,7,18:3)
Block(0,45,8,18:3)
Block(0,45,9,18:3)
Block(0,46,-9,18:3)
Block(0,46,-8,18:3)
Block(0,46,-7,18:3)
Block(0,46,-6,18:3)
Block(0,46,-5,18:3)
Block(0,46,-4,18:3)
Block(0,46,-3,18:3)
Block(0,46,-2,18:3)
Block(0,46,-1,17:15)
Block(0,46,0,18:3)
Block(0,46,1,18:3)
Block(0,46,2,17:15)
Block(0,46,3,17:15)
Block(0,46,4,18:3)
Block(0,46,5,18:3)
Block(0,46,6,18:3)
Block(0,46,7,18:3)
Block(0,46,8,18:3)
Block(0,46,9,18:3)
Block(0,46,10,18:3)
Block(0,47,-6,18:3)
Block(0,47,-5,18:3)
Block(0,47,-4,18:3)
Block(0,47,-3,18:3)
Block(0,47,-2,18:3)
Block(0,47,-1,18:3)
Block(0,47,0,18:3)
Block(0,47,1,18:3)
Block(0,47,2,18:3)
Block(0,47,3,18:3)
Block(0,47,4,18:3)
Block(0,47,5,18:3)
Block(0,47,6,18:3)
Block(0,47,7,18:3)
Block(0,47,8,18:3)
Block(0,47,9,18:3)
Block(1,27,2,17:15)
Block(1,28,3,17:15)
Block(1,31,0,17:15)
Block(1,32,-1,17:15)
Block(1,35,-16,106:1)
Block(1,36,-16,106:1)
Block(1,36,-5,17:15)
Block(1,36,11,106:4)
Block(1,37,-16,106:1)
Block(1,37,-13,18:3)
Block(1,37,-12,18:3)
Block(1,37,-11,18:3)
Block(1,37,-6,17:15)
Block(1,37,-1,17:15)
Block(1,37,6,18:3)
Block(1,37,7,18:3)
Block(1,37,8,18:3)
Block(1,37,9,18:3)
Block(1,37,10,18:3)
Block(1,37,11,106:4)
Block(1,38,-16,106:1)
Block(1,38,-15,18:3)
Block(1,38,-14,18:3)
Block(1,38,-13,18:3)
Block(1,38,-12,18:3)
Block(1,38,-11,18:3)
Block(1,38,-10,18:3)
Block(1,38,-9,18:3)
Block(1,38,-8,18:3)
Block(1,38,-7,17:15)
Block(1,38,-6,17:15)
Block(1,38,-5,18:3)
Block(1,38,-4,18:3)
Block(1,38,7,18:3)
Block(1,38,8,18:3)
Block(1,38,9,18:3)
Block(1,39,-14,18:3)
Block(1,39,-13,18:3)
Block(1,39,-12,18:3)
Block(1,39,-10,18:3)
Block(1,39,-9,18:3)
Block(1,39,-8,17:15)
Block(1,39,-7,18:3)
Block(1,39,-6,18:3)
Block(1,39,-5,18:3)
Block(1,39,-4,18:3)
Block(1,39,0,17:15)
Block(1,39,2,18:3)
Block(1,39,3,18:3)
Block(1,39,4,17:15)
Block(1,39,5,18:3)
Block(1,39,6,18:3)
Block(1,39,7,18:3)
Block(1,40,-12,18:3)
Block(1,40,-11,18:3)
Block(1,40,-10,18:3)
Block(1,40,-9,18:3)
Block(1,40,-8,18:3)
Block(1,40,-7,17:15)
Block(1,40,-6,18:3)
Block(1,40,-5,18:3)
Block(1,40,-4,18:3)
Block(1,40,-3,18:3)
Block(1,40,2,18:3)
Block(1,40,3,18:3)
Block(1,40,4,18:3)
Block(1,40,5,18:3)
Block(1,40,6,18:3)
Block(1,40,7,18:3)
Block(1,40,8,18:3)
Block(1,40,9,18:3)
Block(1,40,10,18:3)
Block(1,40,11,18:3)
Block(1,41,-11,18:3)
Block(1,41,-10,18:3)
Block(1,41,-9,18:3)
Block(1,41,-8,18:3)
Block(1,41,-7,18:3)
Block(1,41,-6,18:3)
Block(1,41,-5,17:15)
Block(1,41,-4,18:3)
Block(1,41,-3,18:3)
Block(1,41,-2,17:15)
Block(1,41,-1,17:15)
Block(1,41,0,18:3)
Block(1,41,5,18:3)
Block(1,41,6,18:3)
Block(1,41,7,17:15)
Block(1,41,8,18:3)
Block(1,41,9,18:3)
Block(1,41,10,18:3)
Block(1,41,11,18:3)
Block(1,41,12,18:3)
Block(1,41,13,18:3)
Block(1,41,14,18:3)
Block(1,41,15,18:3)
Block(1,42,-10,18:3)
Block(1,42,-9,18:3)
Block(1,42,-8,18:3)
Block(1,42,-7,18:3)
Block(1,42,-6,18:3)
Block(1,42,-5,18:3)
Block(1,42,-4,18:3)
Block(1,42,-3,18:3)
Block(1,42,-2,18:3)
Block(1,42,-1,18:3)
Block(1,42,0,18:3)
Block(1,42,5,18:3)
Block(1,42,6,18:3)
Block(1,42,7,18:3)
Block(1,42,8,18:3)
Block(1,42,9,18:3)
Block(1,42,10,18:3)
Block(1,42,11,18:3)
Block(1,42,12,18:3)
Block(1,42,13,18:3)
Block(1,42,14,18:3)
Block(1,43,-9,18:3)
Block(1,43,-8,18:3)
Block(1,43,-7,18:3)
Block(1,43,-6,18:3)
Block(1,43,-5,18:3)
Block(1,43,-4,18:3)
Block(1,43,-3,18:3)
Block(1,43,-1,17:15)
Block(1,43,0,17:15)
Block(1,43,1,18:3)
Block(1,43,2,18:3)
Block(1,43,3,18:3)
Block(1,43,4,18:3)
Block(1,43,5,18:3)
Block(1,43,6,17:15)
Block(1,43,7,18:3)
Block(1,43,8,18:3)
Block(1,43,9,18:3)
Block(1,43,10,18:3)
Block(1,43,11,18:3)
Block(1,43,12,18:3)
Block(1,44,-9,18:3)
Block(1,44,-8,18:3)
Block(1,44,-7,18:3)
Block(1,44,-6,18:3)
Block(1,44,-5,18:3)
Block(1,44,-4,18:3)
Block(1,44,-3,18:3)
Block(1,44,-2,18:3)
Block(1,44,-1,18:3)
Block(1,44,0,18:3)
Block(1,44,1,18:3)
Block(1,44,2,18:3)
Block(1,44,3,18:3)
Block(1,44,4,18:3)
Block(1,44,5,18:3)
Block(1,44,6,18:3)
Block(1,44,7,18:3)
Block(1,44,8,18:3)
Block(1,44,9,18:3)
Block(1,45,-9,18:3)
Block(1,45,-8,18:3)
Block(1,45,-7,18:3)
Block(1,45,-6,18:3)
Block(1,45,-5,18:3)
Block(1,45,-4,18:3)
Block(1,45,-3,18:3)
Block(1,45,-2,18:3)
Block(1,45,-1,18:3)
Block(1,45,0,18:3)
Block(1,45,1,17:15)
Block(1,45,2,18:3)
Block(1,45,3,17:15)
Block(1,45,4,18:3)
Block(1,45,5,18:3)
Block(1,45,6,18:3)
Block(1,45,8,18:3)
Block(1,45,9,18:3)
Block(1,45,10,18:3)
Block(1,46,-8,18:3)
Block(1,46,-7,18:3)
Block(1,46,-6,18:3)
Block(1,46,-5,18:3)
Block(1,46,-4,18:3)
Block(1,46,-3,18:3)
Block(1,46,-2,18:3)
Block(1,46,-1,18:3)
Block(1,46,0,18:3)
Block(1,46,1,18:3)
Block(1,46,2,18:3)
Block(1,46,3,18:3)
Block(1,46,4,18:3)
Block(1,46,5,18:3)
Block(1,46,6,18:3)
Block(1,46,7,18:3)
Block(1,46,8,18:3)
Block(1,46,9,18:3)
Block(1,47,-5,18:3)
Block(1,47,-4,18:3)
Block(1,47,-3,18:3)
Block(1,47,-2,18:3)
Block(1,47,-1,18:3)
Block(1,47,0,18:3)
Block(1,47,1,18:3)
Block(1,47,2,18:3)
Block(1,47,3,18:3)
Block(1,47,4,18:3)
Block(1,47,5,18:3)
Block(1,47,6,18:3)
Block(1,47,7,18:3)
Block(1,47,8,18:3)
Block(2,29,4,17:15)
Block(2,30,5,17:15)
Block(2,33,-1,17:15)
Block(2,37,-14,18:3)
Block(2,37,-13,18:3)
Block(2,37,-12,18:3)
Block(2,37,-11,18:3)
Block(2,37,-10,18:3)
Block(2,37,7,18:3)
Block(2,37,8,18:3)
Block(2,37,9,18:3)
Block(2,37,10,18:3)
Block(2,38,-14,18:3)
Block(2,38,-13,18:3)
Block(2,38,-12,18:3)
Block(2,38,-11,18:3)
Block(2,38,-10,18:3)
Block(2,38,-9,17:15)
Block(2,38,-8,18:3)
Block(2,38,-7,18:3)
Block(2,38,-6,18:3)
Block(2,38,-5,18:3)
Block(2,38,-4,18:3)
Block(2,38,-1,17:15)
Block(2,38,8,18:3)
Block(2,38,9,18:3)
Block(2,39,-13,18:3)
Block(2,39,-12,18:3)
Block(2,39,-11,18:3)
Block(2,39,-10,18:3)
Block(2,39,-9,18:3)
Block(2,39,-8,18:3)
Block(2,39,-7,18:3)
Block(2,39,-6,18:3)
Block(2,39,-5,18:3)
Block(2,39,2,18:3)
Block(2,39,3,18:3)
Block(2,39,4,18:3)
Block(2,39,5,17:15)
Block(2,39,6,18:3)
Block(2,39,7,18:3)
Block(2,40,-12,18:3)
Block(2,40,-11,18:3)
Block(2,40,-10,18:3)
Block(2,40,-9,18:3)
Block(2,40,-8,17:15)
Block(2,40,-7,18:3)
Block(2,40,-6,18:3)
Block(2,40,-5,18:3)
Block(2,40,-4,18:3)
Block(2,40,-1,18:3)
Block(2,40,0,17:15)
Block(2,40,1,18:3)
Block(2,40,3,18:3)
Block(2,40,4,18:3)
Block(2,40,5,18:3)
Block(2,40,6,18:3)
Block(2,40,7,18:3)
Block(2,40,8,18:3)
Block(2,40,9,18:3)
Block(2,40,10,18:3)
Block(2,41,-11,18:3)
Block(2,41,-10,18:3)
Block(2,41,-9,17:15)
Block(2,41,-8,18:3)
Block(2,41,-7,18:3)
Block(2,41,-6,18:3)
Block(2,41,-5,18:3)
Block(2,41,-4,18:3)
Block(2,41,-3,18:3)
Block(2,41,-2,18:3)
Block(2,41,-1,18:3)
Block(2,41,0,18:3)
Block(2,41,1,18:3)
Block(2,41,5,18:3)
Block(2,41,6,18:3)
Block(2,41,7,18:3)
Block(2,41,8,18:3)
Block(2,41,9,18:3)
Block(2,41,10,18:3)
Block(2,41,11,18:3)
Block(2,41,12,18:3)
Block(2,41,13,17:15)
Block(2,41,14,18:3)
Block(2,41,15,18:3)
Block(2,42,-11,18:3)
Block(2,42,-10,18:3)
Block(2,42,-9,18:3)
Block(2,42,-8,18:3)
Block(2,42,-7,18:3)
Block(2,42,-6,17:15)
Block(2,42,-5,18:3)
Block(2,42,-4,18:3)
Block(2,42,-3,18:3)
Block(2,42,-2,18:3)
Block(2,42,-1,17:15)
Block(2,42,0,18:3)
Block(2,42,1,18:3)
Block(2,42,2,18:3)
Block(2,42,3,18:3)
Block(2,42,4,18:3)
Block(2,42,5,18:3)
Block(2,42,6,18:3)
Block(2,42,7,18:3)
Block(2,42,8,18:3)
Block(2,42,9,18:3)
Block(2,42,10,18:3)
Block(2,42,11,17:15)
Block(2,42,12,18:3)
Block(2,42,13,18:3)
Block(2,42,14,18:3)
Block(2,42,15,18:3)
Block(2,43,-10,18:3)
Block(2,43,-9,18:3)
Block(2,43,-8,18:3)
Block(2,43,-7,18:3)
Block(2,43,-6,18:3)
Block(2,43,-5,18:3)
Block(2,43,-4,18:3)
Block(2,43,-2,18:3)
Block(2,43,1,18:3)
Block(2,43,2,18:3)
Block(2,43,3,18:3)
Block(2,43,4,18:3)
Block(2,43,5,18:3)
Block(2,43,6,18:3)
Block(2,43,7,18:3)
Block(2,43,8,18:3)
Block(2,43,9,18:3)
Block(2,43,10,18:3)
Block(2,43,11,18:3)
Block(2,43,12,18:3)
Block(2,43,13,18:3)
Block(2,44,-9,18:3)
Block(2,44,-8,18:3)
Block(2,44,-7,17:15)
Block(2,44,-6,18:3)
Block(2,44,-5,17:15)
Block(2,44,-4,18:3)
Block(2,44,-3,18:3)
Block(2,44,-2,18:3)
Block(2,44,-1,17:15)
Block(2,44,0,17:15)
Block(2,44,1,18:3)
Block(2,44,2,17:15)
Block(2,44,3,18:3)
Block(2,44,4,18:3)
Block(2,44,5,18:3)
Block(2,44,6,18:3)
Block(2,44,7,18:3)
Block(2,44,8,18:3)
Block(2,44,9,18:3)
Block(2,44,10,18:3)
Block(2,45,-9,18:3)
Block(2,45,-8,18:3)
Block(2,45,-7,18:3)
Block(2,45,-6,18:3)
Block(2,45,-5,18:3)
Block(2,45,-4,18:3)
Block(2,45,-3,18:3)
Block(2,45,-2,18:3)
Block(2,45,-1,18:3)
Block(2,45,0,18:3)
Block(2,45,1,18:3)
Block(2,45,2,18:3)
Block(2,45,3,18:3)
Block(2,45,4,18:3)
Block(2,45,5,18:3)
Block(2,45,7,18:3)
Block(2,45,8,18:3)
Block(2,45,9,18:3)
Block(2,45,10,18:3)
Block(2,45,11,18:3)
Block(2,46,-7,18:3)
Block(2,46,-5,18:3)
Block(2,46,-4,18:3)
Block(2,46,-3,17:15)
Block(2,46,-2,17:15)
Block(2,46,-1,18:3)
Block(2,46,0,17:15)
Block(2,46,1,17:15)
Block(2,46,2,18:3)
Block(2,46,3,18:3)
Block(2,46,4,17:15)
Block(2,46,5,18:3)
Block(2,46,6,18:3)
Block(2,46,7,18:3)
Block(2,46,8,18:3)
Block(2,46,9,18:3)
Block(2,46,10,18:3)
Block(2,47,-5,18:3)
Block(2,47,-4,18:3)
Block(2,47,-3,18:3)
Block(2,47,-2,18:3)
Block(2,47,-1,18:3)
Block(2,47,0,18:3)
Block(2,47,1,18:3)
Block(2,47,2,18:3)
Block(2,47,3,18:3)
Block(2,47,4,18:3)
Block(2,47,5,18:3)
Block(2,47,6,18:3)
Block(2,47,7,18:3)
Block(2,47,8,18:3)
Block(3,31,6,17:15)
Block(3,32,7,17:15)
Block(3,33,8,17:15)
Block(3,34,-15,106:1)
Block(3,34,-2,17:15)
Block(3,35,-15,106:1)
Block(3,35,-2,17:15)
Block(3,36,-15,106:1)
Block(3,37,-15,106:1)
Block(3,37,-14,18:3)
Block(3,37,-13,18:3)
Block(3,37,-12,17:15)
Block(3,37,-11,18:3)
Block(3,37,-10,18:3)
Block(3,37,-9,18:3)
Block(3,37,-8,18:3)
Block(3,37,-4,18:3)
Block(3,37,-3,18:3)
Block(3,37,-2,18:3)
Block(3,37,7,18:3)
Block(3,37,8,18:3)
Block(3,37,9,18:3)
Block(3,37,10,18:3)
Block(3,37,11,18:3)
Block(3,38,-14,18:3)
Block(3,38,-13,18:3)
Block(3,38,-12,17:15)
Block(3,38,-11,18:3)
Block(3,38,-10,18:3)
Block(3,38,-9,18:3)
Block(3,38,-8,18:3)
Block(3,38,-7,18:3)
Block(3,38,-6,18:3)
Block(3,38,-5,18:3)
Block(3,38,-3,18:3)
Block(3,38,8,18:3)
Block(3,38,9,18:3)
Block(3,38,10,18:3)
Block(3,39,-14,18:3)
Block(3,39,-13,18:3)
Block(3,39,-12,18:3)
Block(3,39,-11,18:3)
Block(3,39,-10,18:3)
Block(3,39,-9,18:3)
Block(3,39,-8,17:15)
Block(3,39,-7,18:3)
Block(3,39,-6,18:3)
Block(3,39,-1,17:15)
Block(3,39,3,18:3)
Block(3,39,4,18:3)
Block(3,39,5,18:3)
Block(3,39,6,18:3)
Block(3,39,7,18:3)
Block(3,40,-11,18:3)
Block(3,40,-10,18:3)
Block(3,40,-9,18:3)
Block(3,40,-8,18:3)
Block(3,40,-7,18:3)
Block(3,40,-6,18:3)
Block(3,40,-5,18:3)
Block(3,40,-2,18:3)
Block(3,40,-1,18:3)
Block(3,40,0,18:3)
Block(3,40,1,18:3)
Block(3,40,2,18:3)
Block(3,40,4,18:3)
Block(3,40,5,18:3)
Block(3,40,6,18:3)
Block(3,40,7,18:3)
Block(3,41,-11,18:3)
Block(3,41,-10,18:3)
Block(3,41,-9,18:3)
Block(3,41,-8,18:3)
Block(3,41,-7,18:3)
Block(3,41,-6,18:3)
Block(3,41,-5,18:3)
Block(3,41,-4,18:3)
Block(3,41,-3,18:3)
Block(3,41,-2,18:3)
Block(3,41,-1,18:3)
Block(3,41,0,17:15)
Block(3,41,1,18:3)
Block(3,41,2,18:3)
Block(3,41,5,18:3)
Block(3,41,6,18:3)
Block(3,41,7,18:3)
Block(3,41,8,18:3)
Block(3,41,10,18:3)
Block(3,41,11,18:3)
Block(3,41,12,17:15)
Block(3,41,13,18:3)
Block(3,41,14,18:3)
Block(3,41,15,18:3)
Block(3,42,-11,18:3)
Block(3,42,-10,18:3)
Block(3,42,-9,17:15)
Block(3,42,-8,18:3)
Block(3,42,-7,18:3)
Block(3,42,-6,18:3)
Block(3,42,-5,18:3)
Block(3,42,-4,18:3)
Block(3,42,-3,18:3)
Block(3,42,-2,18:3)
Block(3,42,-1,18:3)
Block(3,42,0,18:3)
Block(3,42,1,18:3)
Block(3,42,2,18:3)
Block(3,42,3,18:3)
Block(3,42,4,18:3)
Block(3,42,5,18:3)
Block(3,42,6,18:3)
Block(3,42,7,18:3)
Block(3,42,9,18:3)
Block(3,42,10,18:3)
Block(3,42,11,18:3)
Block(3,42,12,18:3)
Block(3,42,13,18:3)
Block(3,42,14,18:3)
Block(3,43,-11,18:3)
Block(3,43,-10,18:3)
Block(3,43,-9,18:3)
Block(3,43,-8,18:3)
Block(3,43,-7,18:3)
Block(3,43,-6,18:3)
Block(3,43,-5,18:3)
Block(3,43,-4,18:3)
Block(3,43,-3,18:3)
Block(3,43,-2,18:3)
Block(3,43,-1,17:15)
Block(3,43,0,18:3)
Block(3,43,1,18:3)
Block(3,43,2,18:3)
Block(3,43,3,17:15)
Block(3,43,4,18:3)
Block(3,43,5,18:3)
Block(3,43,6,17:15)
Block(3,43,7,18:3)
Block(3,43,8,18:3)
Block(3,43,10,18:3)
Block(3,43,11,18:3)
Block(3,43,12,18:3)
Block(3,44,-9,18:3)
Block(3,44,-8,18:3)
Block(3,44,-7,18:3)
Block(3,44,-6,18:3)
Block(3,44,-5,18:3)
Block(3,44,-4,17:15)
Block(3,44,-3,18:3)
Block(3,44,-2,18:3)
Block(3,44,-1,18:3)
Block(3,44,0,18:3)
Block(3,44,1,18:3)
Block(3,44,2,18:3)
Block(3,44,3,18:3)
Block(3,44,4,17:15)
Block(3,44,5,18:3)
Block(3,44,6,18:3)
Block(3,44,7,18:3)
Block(3,44,8,17:15)
Block(3,44,9,18:3)
Block(3,44,10,18:3)
Block(3,45,-8,18:3)
Block(3,45,-7,18:3)
Block(3,45,-6,18:3)
Block(3,45,-5,18:3)
Block(3,45,-4,18:3)
Block(3,45,-3,18:3)
Block(3,45,-2,18:3)
Block(3,45,-1,17:15)
Block(3,45,0,17:15)
Block(3,45,1,18:3)
Block(3,45,2,18:3)
Block(3,45,3,18:3)
Block(3,45,4,18:3)
Block(3,45,5,18:3)
Block(3,45,6,18:3)
Block(3,45,7,18:3)
Block(3,45,8,18:3)
Block(3,45,9,17:15)
Block(3,45,10,18:3)
Block(3,45,11,18:3)
Block(3,46,-6,18:3)
Block(3,46,-5,18:3)
Block(3,46,-4,18:3)
Block(3,46,-3,18:3)
Block(3,46,-2,18:3)
Block(3,46,-1,18:3)
Block(3,46,0,18:3)
Block(3,46,1,18:3)
Block(3,46,2,18:3)
Block(3,46,3,18:3)
Block(3,46,4,18:3)
Block(3,46,5,18:3)
Block(3,46,6,18:3)
Block(3,46,7,17:15)
Block(3,46,8,18:3)
Block(3,46,9,18:3)
Block(3,46,10,18:3)
Block(3,46,11,18:3)
Block(3,47,-4,18:3)
Block(3,47,-3,18:3)
Block(3,47,-2,18:3)
Block(3,47,-1,18:3)
Block(3,47,0,18:3)
Block(3,47,1,18:3)
Block(3,47,2,18:3)
Block(3,47,3,18:3)
Block(3,47,4,18:3)
Block(3,47,5,18:3)
Block(3,47,6,18:3)
Block(3,47,7,18:3)
Block(3,47,8,18:3)
Block(3,47,9,18:3)
Block(4,33,-15,106:1)
Block(4,34,-15,106:1)
Block(4,34,9,17:15)
Block(4,34,15,106:4)
Block(4,35,-15,106:1)
Block(4,35,10,17:15)
Block(4,35,15,106:4)
Block(4,36,-15,106:1)
Block(4,36,-3,17:15)
Block(4,36,15,106:4)
Block(4,37,-15,106:1)
Block(4,37,-14,18:3)
Block(4,37,-13,18:3)
Block(4,37,-12,18:3)
Block(4,37,-11,18:3)
Block(4,37,-10,18:3)
Block(4,37,-9,18:3)
Block(4,37,-8,18:3)
Block(4,37,-7,18:3)
Block(4,37,-5,18:3)
Block(4,37,-4,18:3)
Block(4,37,-3,18:3)
Block(4,37,-2,18:3)
Block(4,37,-1,18:3)
Block(4,37,7,18:3)
Block(4,37,8,18:3)
Block(4,37,9,17:15)
Block(4,37,10,18:3)
Block(4,37,11,18:3)
Block(4,37,15,106:4)
Block(4,38,-14,18:3)
Block(4,38,-13,18:3)
Block(4,38,-12,18:3)
Block(4,38,-11,18:3)
Block(4,38,-10,18:3)
Block(4,38,-9,17:15)
Block(4,38,-8,18:3)
Block(4,38,-7,18:3)
Block(4,38,-6,18:3)
Block(4,38,-5,18:3)
Block(4,38,-4,18:3)
Block(4,38,-3,18:3)
Block(4,38,-2,18:3)
Block(4,38,7,18:3)
Block(4,38,8,18:3)
Block(4,38,9,18:3)
Block(4,38,10,18:3)
Block(4,38,11,18:3)
Block(4,38,12,18:3)
Block(4,38,13,18:3)
Block(4,38,14,18:3)
Block(4,38,15,106:4)
Block(4,39,-13,18:3)
Block(4,39,-12,18:3)
Block(4,39,-11,18:3)
Block(4,39,-10,18:3)
Block(4,39,-9,18:3)
Block(4,39,-8,18:3)
Block(4,39,-7,18:3)
Block(4,39,-6,18:3)
Block(4,39,-5,18:3)
Block(4,39,-4,18:3)
Block(4,39,4,18:3)
Block(4,39,5,18:3)
Block(4,39,6,18:3)
Block(4,39,7,18:3)
Block(4,39,8,18:3)
Block(4,39,9,18:3)
Block(4,39,13,18:3)
Block(4,40,-12,18:3)
Block(4,40,-11,18:3)
Block(4,40,-10,18:3)
Block(4,40,-9,18:3)
Block(4,40,-8,18:3)
Block(4,40,-7,17:15)
Block(4,40,-6,18:3)
Block(4,40,-5,18:3)
Block(4,40,-2,17:15)
Block(4,40,-1,18:3)
Block(4,40,0,17:15)
Block(4,40,1,18:3)
Block(4,40,2,18:3)
Block(4,40,3,18:3)
Block(4,40,4,18:3)
Block(4,40,5,18:3)
Block(4,40,6,18:3)
Block(4,40,7,18:3)
Block(4,40,8,18:3)
Block(4,41,-11,18:3)
Block(4,41,-10,18:3)
Block(4,41,-9,18:3)
Block(4,41,-8,18:3)
Block(4,41,-7,18:3)
Block(4,41,-6,18:3)
Block(4,41,-5,18:3)
Block(4,41,-4,18:3)
Block(4,41,-3,18:3)
Block(4,41,-2,18:3)
Block(4,41,-1,18:3)
Block(4,41,0,17:15)
Block(4,41,1,18:3)
Block(4,41,2,18:3)
Block(4,41,4,18:3)
Block(4,41,5,18:3)
Block(4,41,6,18:3)
Block(4,41,7,18:3)
Block(4,41,10,18:3)
Block(4,41,11,18:3)
Block(4,41,12,18:3)
Block(4,41,13,18:3)
Block(4,41,14,18:3)
Block(4,42,-11,18:3)
Block(4,42,-10,18:3)
Block(4,42,-9,18:3)
Block(4,42,-8,18:3)
Block(4,42,-7,18:3)
Block(4,42,-6,18:3)
Block(4,42,-5,18:3)
Block(4,42,-4,18:3)
Block(4,42,-3,18:3)
Block(4,42,-2,17:15)
Block(4,42,-1,18:3)
Block(4,42,0,17:15)
Block(4,42,1,18:3)
Block(4,42,2,17:15)
Block(4,42,3,18:3)
Block(4,42,4,18:3)
Block(4,42,5,17:15)
Block(4,42,6,18:3)
Block(4,42,7,18:3)
Block(4,42,10,18:3)
Block(4,42,11,18:3)
Block(4,42,12,18:3)
Block(4,42,13,18:3)
Block(4,43,-10,18:3)
Block(4,43,-9,18:3)
Block(4,43,-8,18:3)
Block(4,43,-7,17:15)
Block(4,43,-6,18:3)
Block(4,43,-5,17:15)
Block(4,43,-4,18:3)
Block(4,43,-3,18:3)
Block(4,43,-2,18:3)
Block(4,43,-1,18:3)
Block(4,43,0,18:3)
Block(4,43,1,18:3)
Block(4,43,2,17:15)
Block(4,43,3,18:3)
Block(4,43,4,18:3)
Block(4,43,5,18:3)
Block(4,43,6,18:3)
Block(4,43,7,18:3)
Block(4,43,8,18:3)
Block(4,43,11,18:3)
Block(4,44,-9,18:3)
Block(4,44,-8,18:3)
Block(4,44,-7,18:3)
Block(4,44,-6,18:3)
Block(4,44,-5,18:3)
Block(4,44,-4,18:3)
Block(4,44,-3,18:3)
Block(4,44,-2,18:3)
Block(4,44,-1,17:15)
Block(4,44,0,18:3)
Block(4,44,1,18:3)
Block(4,44,2,18:3)
Block(4,44,3,18:3)
Block(4,44,4,18:3)
Block(4,44,5,18:3)
Block(4,44,6,18:3)
Block(4,44,7,18:3)
Block(4,44,8,18:3)
Block(4,44,9,18:3)
Block(4,44,10,18:3)
Block(4,45,-7,18:3)
Block(4,45,-6,18:3)
Block(4,45,-5,17:15)
Block(4,45,-4,18:3)
Block(4,45,-3,18:3)
Block(4,45,-1,18:3)
Block(4,45,0,18:3)
Block(4,45,2,18:3)
Block(4,45,3,18:3)
Block(4,45,4,18:3)
Block(4,45,5,18:3)
Block(4,45,6,18:3)
Block(4,45,7,18:3)
Block(4,45,8,18:3)
Block(4,45,9,18:3)
Block(4,45,10,18:3)
Block(4,45,11,18:3)
Block(4,46,-7,18:3)
Block(4,46,-6,18:3)
Block(4,46,-5,18:3)
Block(4,46,-4,18:3)
Block(4,46,-3,18:3)
Block(4,46,-2,17:15)
Block(4,46,-1,17:15)
Block(4,46,0,18:3)
Block(4,46,1,17:15)
Block(4,46,2,18:3)
Block(4,46,3,18:3)
Block(4,46,4,18:3)
Block(4,46,5,18:3)
Block(4,46,6,18:3)
Block(4,46,7,18:3)
Block(4,46,8,18:3)
Block(4,46,9,18:3)
Block(4,46,10,18:3)
Block(4,47,-4,18:3)
Block(4,47,-3,18:3)
Block(4,47,-2,18:3)
Block(4,47,-1,18:3)
Block(4,47,0,18:3)
Block(4,47,1,18:3)
Block(4,47,2,18:3)
Block(4,47,3,18:3)
Block(4,47,4,18:3)
Block(4,47,6,18:3)
Block(4,47,7,18:3)
Block(4,47,8,18:3)
Block(5,32,-14,106:1)
Block(5,33,-14,106:1)
Block(5,34,-14,106:1)
Block(5,35,-14,106:3)
Block(5,36,-14,106:3)
Block(5,36,11,17:15)
Block(5,37,-14,106:3)
Block(5,37,-13,18:3)
Block(5,37,-12,18:3)
Block(5,37,-11,18:3)
Block(5,37,-10,18:3)
Block(5,37,-9,17:15)
Block(5,37,-8,18:3)
Block(5,37,-7,18:3)
Block(5,37,-5,18:3)
Block(5,37,-4,18:3)
Block(5,37,-3,17:15)
Block(5,37,-2,18:3)
Block(5,37,-1,18:3)
Block(5,37,0,18:3)
Block(5,37,7,18:3)
Block(5,37,8,18:3)
Block(5,37,9,18:3)
Block(5,37,10,18:3)
Block(5,37,11,18:3)
Block(5,37,12,17:15)
Block(5,38,-14,106:2)
Block(5,38,-13,18:3)
Block(5,38,-12,18:3)
Block(5,38,-11,18:3)
Block(5,38,-10,18:3)
Block(5,38,-9,18:3)
Block(5,38,-8,18:3)
Block(5,38,-7,18:3)
Block(5,38,-6,18:3)
Block(5,38,-5,18:3)
Block(5,38,-4,18:3)
Block(5,38,-3,18:3)
Block(5,38,-2,18:3)
Block(5,38,-1,18:3)
Block(5,38,6,18:3)
Block(5,38,7,18:3)
Block(5,38,8,18:3)
Block(5,38,9,18:3)
Block(5,38,10,18:3)
Block(5,38,11,18:3)
Block(5,38,12,18:3)
Block(5,38,13,18:3)
Block(5,38,14,18:3)
Block(5,38,15,18:3)
Block(5,39,-13,18:3)
Block(5,39,-12,18:3)
Block(5,39,-11,18:3)
Block(5,39,-10,17:15)
Block(5,39,-9,18:3)
Block(5,39,-8,18:3)
Block(5,39,-7,18:3)
Block(5,39,-6,18:3)
Block(5,39,-5,18:3)
Block(5,39,-4,18:3)
Block(5,39,-3,18:3)
Block(5,39,3,18:3)
Block(5,39,4,18:3)
Block(5,39,5,18:3)
Block(5,39,6,18:3)
Block(5,39,7,18:3)
Block(5,39,8,18:3)
Block(5,39,9,18:3)
Block(5,39,10,18:3)
Block(5,39,12,18:3)
Block(5,39,13,18:3)
Block(5,39,14,18:3)
Block(5,40,-13,18:3)
Block(5,40,-12,18:3)
Block(5,40,-11,18:3)
Block(5,40,-10,18:3)
Block(5,40,-9,18:3)
Block(5,40,-8,18:3)
Block(5,40,-7,18:3)
Block(5,40,-6,18:3)
Block(5,40,-5,18:3)
Block(5,40,-4,18:3)
Block(5,40,-2,18:3)
Block(5,40,-1,18:3)
Block(5,40,0,17:15)
Block(5,40,1,18:3)
Block(5,40,2,18:3)
Block(5,40,3,18:3)
Block(5,40,4,18:3)
Block(5,40,5,17:15)
Block(5,40,6,17:15)
Block(5,40,7,18:3)
Block(5,40,8,18:3)
Block(5,40,9,18:3)
Block(5,41,-12,18:3)
Block(5,41,-11,18:3)
Block(5,41,-10,18:3)
Block(5,41,-9,18:3)
Block(5,41,-8,18:3)
Block(5,41,-7,18:3)
Block(5,41,-6,18:3)
Block(5,41,-5,18:3)
Block(5,41,-4,18:3)
Block(5,41,-3,18:3)
Block(5,41,-2,17:15)
Block(5,41,-1,18:3)
Block(5,41,0,18:3)
Block(5,41,1,18:3)
Block(5,41,2,18:3)
Block(5,41,3,18:3)
Block(5,41,4,18:3)
Block(5,41,5,18:3)
Block(5,41,6,18:3)
Block(5,41,7,18:3)
Block(5,41,8,18:3)
Block(5,41,11,18:3)
Block(5,41,12,18:3)
Block(5,41,13,18:3)
Block(5,42,-11,18:3)
Block(5,42,-10,18:3)
Block(5,42,-9,18:3)
Block(5,42,-8,18:3)
Block(5,42,-7,18:3)
Block(5,42,-6,18:3)
Block(5,42,-5,18:3)
Block(5,42,-4,18:3)
Block(5,42,-3,18:3)
Block(5,42,-2,18:3)
Block(5,42,-1,18:3)
Block(5,42,0,18:3)
Block(5,42,1,18:3)
Block(5,42,2,17:15)
Block(5,42,3,18:3)
Block(5,42,4,17:15)
Block(5,42,5,18:3)
Block(5,42,6,18:3)
Block(5,42,7,18:3)
Block(5,42,12,18:3)
Block(5,43,-10,18:3)
Block(5,43,-9,18:3)
Block(5,43,-8,18:3)
Block(5,43,-7,18:3)
Block(5,43,-6,18:3)
Block(5,43,-5,18:3)
Block(5,43,-4,18:3)
Block(5,43,-3,18:3)
Block(5,43,-2,18:3)
Block(5,43,-1,18:3)
Block(5,43,0,17:15)
Block(5,43,1,18:3)
Block(5,43,2,18:3)
Block(5,43,3,18:3)
Block(5,43,4,18:3)
Block(5,43,5,18:3)
Block(5,43,6,18:3)
Block(5,43,7,18:3)
Block(5,44,-8,18:3)
Block(5,44,-7,18:3)
Block(5,44,-6,18:3)
Block(5,44,-5,18:3)
Block(5,44,-4,18:3)
Block(5,44,-3,18:3)
Block(5,44,-1,18:3)
Block(5,44,0,18:3)
Block(5,44,1,18:3)
Block(5,44,2,18:3)
Block(5,44,3,18:3)
Block(5,44,4,18:3)
Block(5,44,5,18:3)
Block(5,44,6,18:3)
Block(5,44,7,18:3)
Block(5,44,8,18:3)
Block(5,44,9,18:3)
Block(5,45,-7,18:3)
Block(5,45,-6,18:3)
Block(5,45,-5,18:3)
Block(5,45,-4,18:3)
Block(5,45,-3,18:3)
Block(5,45,-2,18:3)
Block(5,45,-1,17:15)
Block(5,45,0,18:3)
Block(5,45,1,18:3)
Block(5,45,2,18:3)
Block(5,45,3,18:3)
Block(5,45,4,18:3)
Block(5,45,5,18:3)
Block(5,45,6,17:15)
Block(5,45,7,18:3)
Block(5,45,8,18:3)
Block(5,45,9,18:3)
Block(5,45,10,18:3)
Block(5,46,-6,18:3)
Block(5,46,-5,18:3)
Block(5,46,-4,18:3)
Block(5,46,-3,18:3)
Block(5,46,-2,17:15)
Block(5,46,-1,17:15)
Block(5,46,0,18:3)
Block(5,46,1,18:3)
Block(5,46,2,18:3)
Block(5,46,3,18:3)
Block(5,46,4,18:3)
Block(5,46,5,18:3)
Block(5,46,6,18:3)
Block(5,46,7,18:3)
Block(5,46,8,18:3)
Block(5,46,9,18:3)
Block(5,47,-4,18:3)
Block(5,47,-3,18:3)
Block(5,47,-2,18:3)
Block(5,47,-1,18:3)
Block(5,47,0,18:3)
Block(5,47,1,18:3)
Block(5,47,2,18:3)
Block(5,47,7,18:3)
Block(6,37,-13,18:3)
Block(6,37,-12,18:3)
Block(6,37,-11,18:3)
Block(6,37,-10,18:3)
Block(6,37,-9,18:3)
Block(6,37,-8,18:3)
Block(6,37,-7,18:3)
Block(6,37,-5,18:3)
Block(6,37,-4,18:3)
Block(6,37,-3,18:3)
Block(6,37,-2,18:3)
Block(6,37,-1,18:3)
Block(6,37,0,18:3)
Block(6,37,1,18:3)
Block(6,37,2,18:3)
Block(6,37,3,18:3)
Block(6,37,4,18:3)
Block(6,37,8,18:3)
Block(6,37,9,18:3)
Block(6,37,10,17:15)
Block(6,37,11,18:3)
Block(6,37,12,18:3)
Block(6,38,-13,18:3)
Block(6,38,-12,18:3)
Block(6,38,-11,18:3)
Block(6,38,-10,18:3)
Block(6,38,-9,18:3)
Block(6,38,-8,18:3)
Block(6,38,-7,18:3)
Block(6,38,-6,17:15)
Block(6,38,-5,18:3)
Block(6,38,-4,18:3)
Block(6,38,-3,18:3)
Block(6,38,-2,18:3)
Block(6,38,-1,18:3)
Block(6,38,0,18:3)
Block(6,38,1,18:3)
Block(6,38,3,18:3)
Block(6,38,5,18:3)
Block(6,38,6,18:3)
Block(6,38,7,18:3)
Block(6,38,8,18:3)
Block(6,38,9,18:3)
Block(6,38,10,18:3)
Block(6,38,11,18:3)
Block(6,38,12,18:3)
Block(6,38,13,17:15)
Block(6,38,14,18:3)
Block(6,38,15,18:3)
Block(6,39,-13,18:3)
Block(6,39,-12,18:3)
Block(6,39,-11,18:3)
Block(6,39,-10,18:3)
Block(6,39,-9,18:3)
Block(6,39,-8,18:3)
Block(6,39,-7,18:3)
Block(6,39,-6,18:3)
Block(6,39,-5,17:15)
Block(6,39,-4,18:3)
Block(6,39,-3,18:3)
Block(6,39,3,18:3)
Block(6,39,4,18:3)
Block(6,39,5,17:15)
Block(6,39,6,18:3)
Block(6,39,7,18:3)
Block(6,39,8,17:15)
Block(6,39,9,18:3)
Block(6,39,10,18:3)
Block(6,39,11,18:3)
Block(6,39,12,18:3)
Block(6,39,13,18:3)
Block(6,39,14,18:3)
Block(6,39,15,18:3)
Block(6,40,-13,18:3)
Block(6,40,-12,18:3)
Block(6,40,-11,17:15)
Block(6,40,-10,18:3)
Block(6,40,-9,18:3)
Block(6,40,-8,18:3)
Block(6,40,-7,18:3)
Block(6,40,-6,18:3)
Block(6,40,-5,18:3)
Block(6,40,-4,18:3)
Block(6,40,-3,18:3)
Block(6,40,-2,18:3)
Block(6,40,-1,18:3)
Block(6,40,0,18:3)
Block(6,40,1,18:3)
Block(6,40,2,18:3)
Block(6,40,3,18:3)
Block(6,40,4,18:3)
Block(6,40,5,18:3)
Block(6,40,6,18:3)
Block(6,40,7,18:3)
Block(6,40,8,18:3)
Block(6,40,9,18:3)
Block(6,40,10,18:3)
Block(6,41,-13,18:3)
Block(6,41,-12,18:3)
Block(6,41,-11,18:3)
Block(6,41,-10,18:3)
Block(6,41,-9,18:3)
Block(6,41,-8,17:15)
Block(6,41,-7,17:15)
Block(6,41,-6,18:3)
Block(6,41,-5,18:3)
Block(6,41,-4,17:15)
Block(6,41,-3,18:3)
Block(6,41,-2,18:3)
Block(6,41,-1,18:3)
Block(6,41,0,18:3)
Block(6,41,1,18:3)
Block(6,41,3,18:3)
Block(6,41,4,18:3)
Block(6,41,5,18:3)
Block(6,41,6,18:3)
Block(6,41,7,18:3)
Block(6,42,-11,18:3)
Block(6,42,-10,18:3)
Block(6,42,-9,17:15)
Block(6,42,-8,18:3)
Block(6,42,-7,18:3)
Block(6,42,-6,18:3)
Block(6,42,-5,18:3)
Block(6,42,-4,18:3)
Block(6,42,-3,18:3)
Block(6,42,-2,17:15)
Block(6,42,-1,18:3)
Block(6,42,0,18:3)
Block(6,42,1,18:3)
Block(6,42,2,18:3)
Block(6,42,3,18:3)
Block(6,42,4,18:3)
Block(6,42,5,18:3)
Block(6,42,6,18:3)
Block(6,43,-11,18:3)
Block(6,43,-10,18:3)
Block(6,43,-9,18:3)
Block(6,43,-8,18:3)
Block(6,43,-7,18:3)
Block(6,43,-6,18:3)
Block(6,43,-5,18:3)
Block(6,43,-4,17:15)
Block(6,43,-3,18:3)
Block(6,43,-2,18:3)
Block(6,43,-1,18:3)
Block(6,43,0,17:15)
Block(6,43,1,18:3)
Block(6,43,2,18:3)
Block(6,43,3,18:3)
Block(6,43,4,18:3)
Block(6,43,5,17:15)
Block(6,43,6,18:3)
Block(6,43,7,18:3)
Block(6,44,-7,18:3)
Block(6,44,-6,18:3)
Block(6,44,-5,18:3)
Block(6,44,-4,18:3)
Block(6,44,-3,18:3)
Block(6,44,-2,18:3)
Block(6,44,-1,18:3)
Block(6,44,0,17:15)
Block(6,44,1,18:3)
Block(6,44,2,18:3)
Block(6,44,3,18:3)
Block(6,44,4,18:3)
Block(6,44,5,18:3)
Block(6,44,6,18:3)
Block(6,44,7,18:3)
Block(6,45,-6,18:3)
Block(6,45,-5,18:3)
Block(6,45,-4,18:3)
Block(6,45,-3,18:3)
Block(6,45,-2,18:3)
Block(6,45,-1,18:3)
Block(6,45,0,18:3)
Block(6,45,1,18:3)
Block(6,45,2,18:3)
Block(6,45,3,18:3)
Block(6,45,4,18:3)
Block(6,45,5,18:3)
Block(6,45,6,18:3)
Block(6,45,7,18:3)
Block(6,45,8,18:3)
Block(6,46,-5,18:3)
Block(6,46,-4,18:3)
Block(6,46,-3,18:3)
Block(6,46,-2,18:3)
Block(6,46,-1,17:15)
Block(6,46,0,18:3)
Block(6,46,1,18:3)
Block(6,46,2,18:3)
Block(6,46,5,18:3)
Block(6,46,6,18:3)
Block(6,46,7,18:3)
Block(6,47,-3,18:3)
Block(6,47,-2,18:3)
Block(6,47,-1,18:3)
Block(6,47,0,18:3)
Block(6,47,1,18:3)
Block(7,34,-14,106:1)
Block(7,35,-14,106:1)
Block(7,36,-14,106:1)
Block(7,37,-14,106:1)
Block(7,37,-13,18:3)
Block(7,37,-12,18:3)
Block(7,37,-11,17:15)
Block(7,37,-10,18:3)
Block(7,37,-9,18:3)
Block(7,37,-8,18:3)
Block(7,37,-7,18:3)
Block(7,37,-6,18:3)
Block(7,37,-5,18:3)
Block(7,37,-4,18:3)
Block(7,37,-3,18:3)
Block(7,37,-2,18:3)
Block(7,37,-1,17:15)
Block(7,37,0,18:3)
Block(7,37,1,18:3)
Block(7,37,2,18:3)
Block(7,37,3,18:3)
Block(7,37,4,18:3)
Block(7,37,5,18:3)
Block(7,37,6,18:3)
Block(7,37,8,18:3)
Block(7,37,9,18:3)
Block(7,37,10,18:3)
Block(7,37,11,18:3)
Block(7,37,12,18:3)
Block(7,38,-13,18:3)
Block(7,38,-12,18:3)
Block(7,38,-11,18:3)
Block(7,38,-10,18:3)
Block(7,38,-9,18:3)
Block(7,38,-8,18:3)
Block(7,38,-7,18:3)
Block(7,38,-6,18:3)
Block(7,38,-5,18:3)
Block(7,38,-4,18:3)
Block(7,38,-3,18:3)
Block(7,38,-2,18:3)
Block(7,38,-1,18:3)
Block(7,38,0,18:3)
Block(7,38,1,18:3)
Block(7,38,2,18:3)
Block(7,38,3,18:3)
Block(7,38,4,18:3)
Block(7,38,5,18:3)
Block(7,38,6,18:3)
Block(7,38,7,17:15)
Block(7,38,8,18:3)
Block(7,38,9,18:3)
Block(7,38,10,18:3)
Block(7,38,11,18:3)
Block(7,38,12,18:3)
Block(7,38,13,18:3)
Block(7,38,14,18:3)
Block(7,38,15,18:3)
Block(7,39,-13,18:3)
Block(7,39,-12,18:3)
Block(7,39,-11,18:3)
Block(7,39,-10,18:3)
Block(7,39,-9,18:3)
Block(7,39,-7,18:3)
Block(7,39,-6,18:3)
Block(7,39,-5,18:3)
Block(7,39,-4,18:3)
Block(7,39,-3,18:3)
Block(7,39,-1,18:3)
Block(7,39,0,18:3)
Block(7,39,1,18:3)
Block(7,39,3,18:3)
Block(7,39,4,18:3)
Block(7,39,5,18:3)
Block(7,39,6,18:3)
Block(7,39,7,18:3)
Block(7,39,8,18:3)
Block(7,39,9,17:15)
Block(7,39,10,18:3)
Block(7,39,11,18:3)
Block(7,39,12,18:3)
Block(7,39,13,18:3)
Block(7,39,14,18:3)
Block(7,40,-13,18:3)
Block(7,40,-12,18:3)
Block(7,40,-11,18:3)
Block(7,40,-10,18:3)
Block(7,40,-9,18:3)
Block(7,40,-8,18:3)
Block(7,40,-7,18:3)
Block(7,40,-6,17:15)
Block(7,40,-5,18:3)
Block(7,40,-4,18:3)
Block(7,40,-2,18:3)
Block(7,40,-1,18:3)
Block(7,40,0,18:3)
Block(7,40,1,18:3)
Block(7,40,2,18:3)
Block(7,40,3,18:3)
Block(7,40,4,18:3)
Block(7,40,5,18:3)
Block(7,40,6,18:3)
Block(7,40,7,18:3)
Block(7,40,8,18:3)
Block(7,40,9,18:3)
Block(7,40,10,18:3)
Block(7,40,11,18:3)
Block(7,41,-12,18:3)
Block(7,41,-11,18:3)
Block(7,41,-10,18:3)
Block(7,41,-9,18:3)
Block(7,41,-8,18:3)
Block(7,41,-7,18:3)
Block(7,41,-6,17:15)
Block(7,41,-5,18:3)
Block(7,41,-4,18:3)
Block(7,41,-3,18:3)
Block(7,41,-2,18:3)
Block(7,41,-1,18:3)
Block(7,41,0,18:3)
Block(7,41,1,18:3)
Block(7,41,2,18:3)
Block(7,41,3,18:3)
Block(7,41,4,18:3)
Block(7,41,5,18:3)
Block(7,41,6,18:3)
Block(7,42,-11,18:3)
Block(7,42,-10,18:3)
Block(7,42,-9,18:3)
Block(7,42,-8,18:3)
Block(7,42,-7,18:3)
Block(7,42,-6,18:3)
Block(7,42,-5,18:3)
Block(7,42,-4,18:3)
Block(7,42,-3,18:3)
Block(7,42,-2,18:3)
Block(7,42,-1,18:3)
Block(7,42,0,18:3)
Block(7,42,1,18:3)
Block(7,42,2,18:3)
Block(7,42,3,18:3)
Block(7,42,4,18:3)
Block(7,42,5,18:3)
Block(7,43,-10,18:3)
Block(7,43,-9,18:3)
Block(7,43,-8,18:3)
Block(7,43,-6,18:3)
Block(7,43,-5,18:3)
Block(7,43,-4,18:3)
Block(7,43,-3,18:3)
Block(7,43,-2,17:15)
Block(7,43,-1,18:3)
Block(7,43,0,18:3)
Block(7,43,1,18:3)
Block(7,43,2,18:3)
Block(7,43,3,17:15)
Block(7,43,4,18:3)
Block(7,43,5,18:3)
Block(7,43,6,18:3)
Block(7,43,7,18:3)
Block(7,44,-5,18:3)
Block(7,44,-4,18:3)
Block(7,44,-3,18:3)
Block(7,44,-2,18:3)
Block(7,44,-1,18:3)
Block(7,44,0,18:3)
Block(7,44,1,18:3)
Block(7,44,2,17:15)
Block(7,44,3,17:15)
Block(7,44,4,18:3)
Block(7,44,5,18:3)
Block(7,44,6,18:3)
Block(7,45,-3,18:3)
Block(7,45,-2,18:3)
Block(7,45,-1,17:15)
Block(7,45,0,17:15)
Block(7,45,1,18:3)
Block(7,45,2,18:3)
Block(7,45,3,18:3)
Block(7,45,4,18:3)
Block(7,45,5,18:3)
Block(7,45,6,18:3)
Block(7,45,7,18:3)
Block(7,46,-3,18:3)
Block(7,46,-2,18:3)
Block(7,46,-1,18:3)
Block(7,46,0,18:3)
Block(7,46,1,18:3)
Block(7,46,2,18:3)
Block(7,46,6,18:3)
Block(7,47,-2,18:3)
Block(7,47,-1,18:3)
Block(7,47,0,18:3)
Block(8,32,-14,106:1)
Block(8,33,-14,106:1)
Block(8,34,-14,106:1)
Block(8,35,-14,106:1)
Block(8,36,-14,106:1)
Block(8,36,12,106:4)
Block(8,36,15,106:4)
Block(8,37,-14,106:1)
Block(8,37,-13,18:3)
Block(8,37,-12,18:3)
Block(8,37,-11,18:3)
Block(8,37,-10,18:3)
Block(8,37,-9,18:3)
Block(8,37,-8,18:3)
Block(8,37,-7,18:3)
Block(8,37,-6,18:3)
Block(8,37,-5,18:3)
Block(8,37,-4,18:3)
Block(8,37,-3,18:3)
Block(8,37,-2,18:3)
Block(8,37,-1,18:3)
Block(8,37,0,17:15)
Block(8,37,1,17:15)
Block(8,37,2,18:3)
Block(8,37,3,17:15)
Block(8,37,4,18:3)
Block(8,37,5,18:3)
Block(8,37,6,18:3)
Block(8,37,7,18:3)
Block(8,37,9,18:3)
Block(8,37,10,18:3)
Block(8,37,11,18:3)
Block(8,37,12,106:4)
Block(8,37,15,106:4)
Block(8,38,-12,18:3)
Block(8,38,-11,18:3)
Block(8,38,-10,18:3)
Block(8,38,-9,18:3)
Block(8,38,-8,18:3)
Block(8,38,-7,18:3)
Block(8,38,-6,18:3)
Block(8,38,-5,18:3)
Block(8,38,-4,18:3)
Block(8,38,-3,18:3)
Block(8,38,-2,18:3)
Block(8,38,-1,18:3)
Block(8,38,0,18:3)
Block(8,38,1,18:3)
Block(8,38,2,18:3)
Block(8,38,3,18:3)
Block(8,38,4,18:3)
Block(8,38,5,18:3)
Block(8,38,6,18:3)
Block(8,38,7,18:3)
Block(8,38,8,18:3)
Block(8,38,9,18:3)
Block(8,38,10,18:3)
Block(8,38,12,18:3)
Block(8,38,13,18:3)
Block(8,38,14,18:3)
Block(8,38,15,106:4)
Block(8,39,-12,18:3)
Block(8,39,-11,18:3)
Block(8,39,-10,18:3)
Block(8,39,-9,18:3)
Block(8,39,-8,18:3)
Block(8,39,-7,18:3)
Block(8,39,-6,18:3)
Block(8,39,-5,18:3)
Block(8,39,-4,18:3)
Block(8,39,-3,18:3)
Block(8,39,-2,18:3)
Block(8,39,-1,18:3)
Block(8,39,0,18:3)
Block(8,39,1,18:3)
Block(8,39,2,18:3)
Block(8,39,3,18:3)
Block(8,39,4,18:3)
Block(8,39,5,18:3)
Block(8,39,6,18:3)
Block(8,39,7,18:3)
Block(8,39,8,18:3)
Block(8,39,9,18:3)
Block(8,39,10,18:3)
Block(8,39,11,18:3)
Block(8,39,13,18:3)
Block(8,40,-12,18:3)
Block(8,40,-11,18:3)
Block(8,40,-10,18:3)
Block(8,40,-8,18:3)
Block(8,40,-7,18:3)
Block(8,40,-6,18:3)
Block(8,40,-5,18:3)
Block(8,40,-4,18:3)
Block(8,40,-2,18:3)
Block(8,40,-1,18:3)
Block(8,40,0,17:15)
Block(8,40,1,18:3)
Block(8,40,2,18:3)
Block(8,40,3,18:3)
Block(8,40,5,18:3)
Block(8,40,8,18:3)
Block(8,40,9,18:3)
Block(8,40,10,18:3)
Block(8,41,-11,18:3)
Block(8,41,-9,18:3)
Block(8,41,-8,18:3)
Block(8,41,-7,18:3)
Block(8,41,-6,18:3)
Block(8,41,-5,18:3)
Block(8,41,-4,18:3)
Block(8,41,-3,18:3)
Block(8,41,-2,18:3)
Block(8,41,-1,18:3)
Block(8,41,0,18:3)
Block(8,41,1,18:3)
Block(8,41,2,18:3)
Block(8,41,3,18:3)
Block(8,41,4,17:15)
Block(8,41,5,18:3)
Block(8,41,6,18:3)
Block(8,42,-10,18:3)
Block(8,42,-9,18:3)
Block(8,42,-8,18:3)
Block(8,42,-7,18:3)
Block(8,42,-6,18:3)
Block(8,42,-5,18:3)
Block(8,42,-4,18:3)
Block(8,42,-3,18:3)
Block(8,42,-2,17:15)
Block(8,42,-1,18:3)
Block(8,42,0,18:3)
Block(8,42,2,18:3)
Block(8,42,3,18:3)
Block(8,42,4,18:3)
Block(8,42,5,18:3)
Block(8,42,6,18:3)
Block(8,43,-9,18:3)
Block(8,43,-5,18:3)
Block(8,43,-4,18:3)
Block(8,43,-3,18:3)
Block(8,43,-2,18:3)
Block(8,43,-1,18:3)
Block(8,43,0,18:3)
Block(8,43,1,18:3)
Block(8,43,2,18:3)
Block(8,43,3,18:3)
Block(8,43,4,18:3)
Block(8,43,5,18:3)
Block(8,43,6,18:3)
Block(8,44,-4,18:3)
Block(8,44,-3,18:3)
Block(8,44,-2,17:15)
Block(8,44,-1,18:3)
Block(8,44,0,18:3)
Block(8,44,1,18:3)
Block(8,44,2,18:3)
Block(8,44,3,18:3)
Block(8,44,4,18:3)
Block(8,44,5,18:3)
Block(8,45,-4,18:3)
Block(8,45,-3,18:3)
Block(8,45,-2,18:3)
Block(8,45,-1,18:3)
Block(8,45,0,17:15)
Block(8,45,1,18:3)
Block(8,45,2,18:3)
Block(8,45,3,18:3)
Block(8,45,4,18:3)
Block(8,46,-2,18:3)
Block(8,46,-1,18:3)
Block(8,46,0,18:3)
Block(8,46,1,18:3)
Block(8,46,2,18:3)
Block(8,47,-1,18:3)
Block(9,32,9,106:2)
Block(9,33,9,106:2)
Block(9,34,9,106:2)
Block(9,35,9,106:2)
Block(9,36,-13,106:1)
Block(9,36,9,106:2)
Block(9,36,11,106:2)
Block(9,37,-13,106:1)
Block(9,37,-12,18:3)
Block(9,37,-11,18:3)
Block(9,37,-10,18:3)
Block(9,37,-9,17:15)
Block(9,37,-8,18:3)
Block(9,37,-7,18:3)
Block(9,37,-6,17:15)
Block(9,37,-5,18:3)
Block(9,37,-4,18:3)
Block(9,37,-2,18:3)
Block(9,37,-1,18:3)
Block(9,37,0,18:3)
Block(9,37,1,18:3)
Block(9,37,2,18:3)
Block(9,37,3,18:3)
Block(9,37,4,18:3)
Block(9,37,5,17:15)
Block(9,37,6,18:3)
Block(9,37,7,18:3)
Block(9,37,9,106:2)
Block(9,37,11,106:2)
Block(9,38,-11,18:3)
Block(9,38,-10,18:3)
Block(9,38,-9,18:3)
Block(9,38,-8,18:3)
Block(9,38,-7,18:3)
Block(9,38,-6,18:3)
Block(9,38,-5,18:3)
Block(9,38,-4,17:15)
Block(9,38,-3,18:3)
Block(9,38,-2,18:3)
Block(9,38,-1,18:3)
Block(9,38,0,18:3)
Block(9,38,1,18:3)
Block(9,38,2,18:3)
Block(9,38,3,18:3)
Block(9,38,4,18:3)
Block(9,38,5,18:3)
Block(9,38,6,18:3)
Block(9,38,7,18:3)
Block(9,38,8,18:3)
Block(9,39,-9,18:3)
Block(9,39,-8,18:3)
Block(9,39,-7,18:3)
Block(9,39,-6,18:3)
Block(9,39,-5,18:3)
Block(9,39,-4,18:3)
Block(9,39,-3,18:3)
Block(9,39,-2,18:3)
Block(9,39,-1,18:3)
Block(9,39,0,17:15)
Block(9,39,1,18:3)
Block(9,39,2,18:3)
Block(9,39,3,18:3)
Block(9,39,6,18:3)
Block(9,39,7,18:3)
Block(9,39,8,18:3)
Block(9,39,9,18:3)
Block(9,39,10,18:3)
Block(9,40,-7,18:3)
Block(9,40,-6,18:3)
Block(9,40,-5,18:3)
Block(9,40,-2,18:3)
Block(9,40,-1,18:3)
Block(9,40,0,18:3)
Block(9,40,1,18:3)
Block(9,40,2,18:3)
Block(9,40,3,18:3)
Block(9,40,7,18:3)
Block(9,40,8,18:3)
Block(9,40,9,18:3)
Block(9,41,-7,18:3)
Block(9,41,-6,18:3)
Block(9,41,-5,18:3)
Block(9,41,-1,18:3)
Block(9,41,0,18:3)
Block(9,41,1,18:3)
Block(9,41,2,18:3)
Block(9,41,3,18:3)
Block(9,41,4,18:3)
Block(9,41,5,18:3)
Block(9,41,6,18:3)
Block(9,42,-6,18:3)
Block(9,42,-4,18:3)
Block(9,42,-3,18:3)
Block(9,42,-2,18:3)
Block(9,42,-1,18:3)
Block(9,42,0,18:3)
Block(9,42,1,18:3)
Block(9,42,3,18:3)
Block(9,42,4,18:3)
Block(9,42,5,18:3)
Block(9,43,-3,18:3)
Block(9,43,-2,18:3)
Block(9,43,-1,18:3)
Block(9,43,0,17:15)
Block(9,43,1,18:3)
Block(9,43,2,18:3)
Block(9,43,3,18:3)
Block(9,43,4,18:3)
Block(9,44,-4,18:3)
Block(9,44,-3,18:3)
Block(9,44,-2,18:3)
Block(9,44,-1,18:3)
Block(9,44,0,18:3)
Block(9,44,1,18:3)
Block(9,44,2,18:3)
Block(9,44,3,18:3)
Block(9,44,4,18:3)
Block(9,45,-3,18:3)
Block(9,45,-2,18:3)
Block(9,45,-1,18:3)
Block(9,45,0,18:3)
Block(9,45,1,18:3)
Block(9,45,2,18:3)
Block(9,45,3,18:3)
Block(9,46,-1,18:3)
Block(9,46,0,18:3)
Block(9,46,1,18:3)
Block(10,37,-11,18:3)
Block(10,37,-10,18:3)
Block(10,37,-9,18:3)
Block(10,37,-8,18:3)
Block(10,37,-7,18:3)
Block(10,37,-6,18:3)
Block(10,37,-5,18:3)
Block(10,37,-4,18:3)
Block(10,37,-1,18:3)
Block(10,37,0,18:3)
Block(10,37,1,18:3)
Block(10,37,2,18:3)
Block(10,37,3,18:3)
Block(10,37,4,18:3)
Block(10,37,5,18:3)
Block(10,37,6,18:3)
Block(10,37,7,18:3)
Block(10,38,-10,18:3)
Block(10,38,-9,18:3)
Block(10,38,-8,18:3)
Block(10,38,-7,18:3)
Block(10,38,-6,18:3)
Block(10,38,-5,18:3)
Block(10,38,-4,18:3)
Block(10,38,-3,18:3)
Block(10,38,-2,18:3)
Block(10,38,0,18:3)
Block(10,38,1,18:3)
Block(10,38,3,18:3)
Block(10,38,4,18:3)
Block(10,38,5,18:3)
Block(10,38,6,18:3)
Block(10,39,-5,18:3)
Block(10,39,-4,18:3)
Block(10,39,-3,18:3)
Block(10,39,-2,18:3)
Block(10,39,-1,18:3)
Block(10,39,0,18:3)
Block(10,39,1,18:3)
Block(10,39,2,18:3)
Block(10,39,3,18:3)
Block(10,39,6,18:3)
Block(10,39,7,18:3)
Block(10,39,8,17:15)
Block(10,39,9,18:3)
Block(10,39,10,18:3)
Block(10,40,-1,18:3)
Block(10,40,0,18:3)
Block(10,40,1,18:3)
Block(10,40,2,18:3)
Block(10,40,3,18:3)
Block(10,40,6,18:3)
Block(10,40,7,18:3)
Block(10,40,8,18:3)
Block(10,40,9,18:3)
Block(10,40,10,18:3)
Block(10,41,-2,18:3)
Block(10,41,-1,18:3)
Block(10,41,0,18:3)
Block(10,41,1,18:3)
Block(10,41,2,18:3)
Block(10,41,3,18:3)
Block(10,41,4,18:3)
Block(10,41,5,18:3)
Block(10,42,-3,18:3)
Block(10,42,-2,18:3)
Block(10,42,-1,18:3)
Block(10,42,0,18:3)
Block(10,42,1,18:3)
Block(10,42,2,18:3)
Block(10,42,4,18:3)
Block(10,43,-2,18:3)
Block(10,43,-1,18:3)
Block(10,43,0,18:3)
Block(10,43,1,18:3)
Block(10,43,2,18:3)
Block(10,44,-3,18:3)
Block(10,44,-2,18:3)
Block(10,44,-1,18:3)
Block(10,44,0,18:3)
Block(10,44,1,18:3)
Block(10,44,2,17:15)
Block(10,44,3,18:3)
Block(10,44,4,18:3)
Block(10,45,-2,18:3)
Block(10,45,-1,18:3)
Block(10,45,0,18:3)
Block(10,45,1,18:3)
Block(10,45,2,18:3)
Block(10,45,3,18:3)
Block(10,45,4,18:3)
Block(10,46,0,18:3)
Block(11,31,-11,106:1)
Block(11,32,-11,106:1)
Block(11,33,-11,106:1)
Block(11,34,-11,106:1)
Block(11,35,-11,106:1)
Block(11,35,7,106:2)
Block(11,36,-11,106:1)
Block(11,36,7,106:2)
Block(11,37,-11,106:1)
Block(11,37,-10,18:3)
Block(11,37,-9,18:3)
Block(11,37,-8,18:3)
Block(11,37,-7,18:3)
Block(11,37,-6,18:3)
Block(11,37,-5,18:3)
Block(11,37,4,18:3)
Block(11,37,5,18:3)
Block(11,37,6,18:3)
Block(11,37,7,106:2)
Block(11,38,-9,18:3)
Block(11,38,-6,18:3)
Block(11,38,-5,18:3)
Block(11,38,-4,18:3)
Block(11,38,-3,18:3)
Block(11,38,5,18:3)
Block(11,39,-4,18:3)
Block(11,39,-1,18:3)
Block(11,39,0,18:3)
Block(11,39,1,18:3)
Block(11,39,6,18:3)
Block(11,39,7,18:3)
Block(11,39,8,18:3)
Block(11,39,9,18:3)
Block(11,39,10,18:3)
Block(11,40,0,18:3)
Block(11,40,1,18:3)
Block(11,40,2,18:3)
Block(11,40,3,18:3)
Block(11,40,7,18:3)
Block(11,40,8,18:3)
Block(11,40,9,18:3)
Block(11,41,-3,18:3)
Block(11,41,-2,18:3)
Block(11,41,-1,18:3)
Block(11,41,0,18:3)
Block(11,41,1,18:3)
Block(11,42,-2,18:3)
Block(11,42,-1,18:3)
Block(11,42,0,17:15)
Block(11,42,1,18:3)
Block(11,42,2,18:3)
Block(11,43,-2,18:3)
Block(11,43,-1,18:3)
Block(11,43,0,18:3)
Block(11,43,1,18:3)
Block(11,43,2,18:3)
Block(11,44,0,18:3)
Block(11,44,1,18:3)
Block(11,44,2,18:3)
Block(11,44,3,18:3)
Block(11,44,4,18:3)
Block(11,45,1,18:3)
Block(11,45,2,18:3)
Block(11,45,3,18:3)
Block(12,33,5,106:2)
Block(12,34,-10,106:2)
Block(12,34,5,106:2)
Block(12,35,-10,106:2)
Block(12,35,-7,106:2)
Block(12,35,5,106:2)
Block(12,36,-10,106:2)
Block(12,36,-7,106:2)
Block(12,36,5,106:2)
Block(12,37,-10,106:2)
Block(12,37,-7,106:2)
Block(12,37,5,106:2)
Block(12,37,6,106:2)
Block(12,39,7,18:3)
Block(12,39,8,18:3)
Block(12,39,9,18:3)
Block(12,40,8,18:3)
Block(12,41,-3,18:3)
Block(12,41,-2,18:3)
Block(12,41,-1,17:15)
Block(12,41,0,18:3)
Block(12,41,1,18:3)
Block(12,42,-3,18:3)
Block(12,42,-2,18:3)
Block(12,42,-1,18:3)
Block(12,42,0,18:3)
Block(12,42,1,18:3)
Block(12,42,2,18:3)
Block(12,42,3,18:3)
Block(12,43,-1,18:3)
Block(12,43,0,18:3)
Block(12,43,1,18:3)
Block(12,43,2,18:3)
Block(12,44,1,18:3)
Block(12,44,2,18:3)
Block(12,44,3,18:3)
Block(12,45,2,18:3)
Block(13,41,-3,18:3)
Block(13,41,-2,18:3)
Block(13,41,-1,18:3)
Block(13,41,0,18:3)
Block(13,41,1,18:3)
Block(13,42,-2,18:3)
Block(13,42,-1,18:3)
Block(13,42,0,18:3)
Block(13,42,1,17:15)
Block(13,42,2,18:3)
Block(13,42,3,18:3)
Block(13,43,-1,18:3)
Block(13,43,0,18:3)
Block(13,43,1,18:3)
Block(13,43,2,18:3)
Block(13,43,3,18:3)
Block(14,41,-2,18:3)
Block(14,41,-1,18:3)
Block(14,41,0,18:3)
Block(14,42,-1,18:3)
Block(14,42,0,18:3)
Block(14,42,1,18:3)
Block(14,42,2,18:3)
Block(14,42,3,18:3)
Block(14,43,0,18:3)
Block(14,43,1,18:3)
Block(14,43,2,18:3)
Block(15,42,0,18:3)
Block(15,42,1,18:3)
Block(15,42,2,18:3)
Block(15,43,1,18:3)


#######################################################################
# +-----------------------------------------------------------------+ #
# |                             Entities                            | #
# +-----------------------------------------------------------------+ #
#######################################################################

# Entity() spawns an entity instead of a block. The entity is spawned only once when the BO3 is spawned.
# Entities are persistent by default so they don't de-spawn when no player is near, they are only unloaded.
# Usage: Entity(x,y,z,mobName,groupSize,NameTagOrNBTFileName) or Entity(x,y,z,mobName,groupSize)
# Use /tc entities or /otg entities to get a list of entities that can be used as mobName, this includes entities added by other mods.
# NameTagOrNBTFileName can be either a nametag for the mob or an nbt file (such as mymobinfo.nbt or mymobinfo.txt).
# When using a text file you can use the same mob spawning parameters used with the /summon command to equip the
# entity and give it custom attributes etc. You can copy the DATA part of a summon command including surrounding
# curly braces to a .txt file, for instance for: "/summon Skeleton x y z {DATA}"

#######################################################################
# +-----------------------------------------------------------------+ #
# |                            BO3 checks                           | #
# +-----------------------------------------------------------------+ #
#######################################################################

# Require a condition at a certain location in order for the BO3 to be spawned.
# BlockCheck(x,y,z,BlockName[,BlockName[,...]]) - one of the blocks must be at the location
# BlockCheckNot(x,y,z,BlockName[,BlockName[,...]]) - all the blocks must not be at the location
# LightCheck(x,y,z,minLightLevel,maxLightLevel) - light must be between min and max (inclusive)

# You can use "Solid" as a BlockName for matching all solid blocks or "All" to match all blocks that aren't air.

# Examples:
#   BlockCheck(0,-1,0,GRASS,DIRT)  Require grass or dirt just below the object
#   BlockCheck(0,-1,0,Solid)       Require any solid block just below the object
#   BlockCheck(0,-1,0,WOOL)        Require any type of wool just below the object
#   BlockCheck(0,-1,0,WOOL:0)      Require white wool just below the object
#   BlockCheckNot(0,-1,0,WOOL:0)   Require that there is no white wool below the object
#   LightCheck(0,0,0,0,1)          Require almost complete darkness just below the object

BlockCheck(0,-1,0,GRASS,DIRT)
BlockCheckNot(0,0,0,STATIONARY_LAVA)