#######################################################################
# +-----------------------------------------------------------------+ #
# |                            BO3 object                           | #
# +-----------------------------------------------------------------+ #
#######################################################################

# The descriptions in this file are accurate only for TerrainControl and OTG.
# For MCW and OTG+ these descriptions are only accurate if the BO3 is used as a CustomObject.
# MCW and OTG+ completely reimplemented CustomStructure, check the MCW/OTG+ documentation for more information.

# This is the config file of a custom object.
# If you add this object correctly to your BiomeConfigs, it will spawn in the world.

# This is the creator of this BO3 object
Author: Unknown

# A short description of this BO3 object
Description: This BO3 was converted from a schematic using OTGEdit. The author and description information of the schematic could not be found. If you know who the author of the schematic is then please add this information.

# The BO3 version, don't change this! It can be used by external applications to do a version check.
Version: 3

# The settings mode, WriteAll, WriteWithoutComments or WriteDisable. See WorldConfig.
SettingsMode: WriteDisable

#######################################################################
# +-----------------------------------------------------------------+ #
# |                          Main settings                          | #
# +-----------------------------------------------------------------+ #
#######################################################################

Tree: true

Frequency: 1

Rarity: 10.0

RotateRandomly: true

SpawnHeight: highestSolidBlock

SpawnHeightOffset: 0

SpawnHeightVariance: 0

##############################
# Height Limits for the BO3. #
##############################

MinHeight: 63

MaxHeight: 110

######################
# Extrusion settings #
######################

ExtrudeMode: BottomDown

ExtrudeThroughBlocks: AIR

MaxBranchDepth: 10

ExcludedBiomes: All


#######################################################################
# +-----------------------------------------------------------------+ #
# |                      Source block settings                      | #
# +-----------------------------------------------------------------+ #
#######################################################################

SourceBlocks: STONE:1,STONE:3,STONE:5,DIRT:1,DIRT,SAND,GRASS,DIRT:2,STATIONARY_WATER,HARD_CLAY,STAINED_CLAY,CLAY,SANDSTONE,SAND:1,AIR,STONE,GRAVEL,LONG_GRASS,LONG_GRASS:1,LONG_GRASS:2,DEAD_BUSH,YELLOW_FLOWER,RED_ROSE,BROWN_MUSHROOM,RED_MUSHROOM

MaxPercentageOutsideSourceBlock: 0

OutsideSourceBlock: placeAnyway

#######################################################################
# +-----------------------------------------------------------------+ #
# |                              Blocks                             | #
# +-----------------------------------------------------------------+ #
#######################################################################

# All the blocks used in the BO3 are listed here. Possible blocks:
# Block(x,y,z,id[.data][,nbtfile.nbt) or B(x,y,z,id[.data][,nbtfile.nbt)
# RandomBlock(x,y,z,id[:data][,nbtfile.nbt],chance[,id[:data][,nbtfile.nbt],chance[,...]])
# So RandomBlock(0,0,0,CHEST,chest.nbt,50,CHEST,anotherchest.nbt,100) will spawn a chest at
# the BO3 origin, and give it a 50% chance to have the contents of chest.nbt, or, if that
# fails, a 100% percent chance to have the contents of anotherchest.nbt.

Block(-8,15,0,LEAVES:1)
Block(-8,19,0,LEAVES:1)
Block(-8,23,0,LEAVES:1)
Block(-7,15,-7,LEAVES:1)
Block(-7,15,-6,LEAVES:1)
Block(-7,15,-1,LEAVES:1)
Block(-7,15,0,LOG:13)
Block(-7,15,1,LEAVES:1)
Block(-7,15,6,LEAVES:1)
Block(-7,15,7,LEAVES:1)
Block(-7,16,0,LEAVES:1)
Block(-7,19,-7,LEAVES:1)
Block(-7,19,-6,LEAVES:1)
Block(-7,19,-1,LEAVES:1)
Block(-7,19,0,LOG:13)
Block(-7,19,1,LEAVES:1)
Block(-7,19,6,LEAVES:1)
Block(-7,19,7,LEAVES:1)
Block(-7,20,0,LEAVES:1)
Block(-7,23,-7,LEAVES:1)
Block(-7,23,-6,LEAVES:1)
Block(-7,23,-1,LEAVES:1)
Block(-7,23,0,LOG:13)
Block(-7,23,1,LEAVES:1)
Block(-7,23,6,LEAVES:1)
Block(-7,23,7,LEAVES:1)
Block(-7,24,0,LEAVES:1)
Block(-7,28,0,LEAVES:1)
Block(-6,12,0,LEAVES:1)
Block(-6,15,-7,LEAVES:1)
Block(-6,15,-6,LOG:13)
Block(-6,15,-5,LEAVES:1)
Block(-6,15,-1,LEAVES:1)
Block(-6,15,0,LOG:13)
Block(-6,15,1,LEAVES:1)
Block(-6,15,5,LEAVES:1)
Block(-6,15,6,LOG:13)
Block(-6,15,7,LEAVES:1)
Block(-6,16,-6,LEAVES:1)
Block(-6,16,0,LEAVES:1)
Block(-6,16,6,LEAVES:1)
Block(-6,19,-7,LEAVES:1)
Block(-6,19,-6,LOG:13)
Block(-6,19,-5,LEAVES:1)
Block(-6,19,-1,LEAVES:1)
Block(-6,19,0,LOG:13)
Block(-6,19,1,LEAVES:1)
Block(-6,19,5,LEAVES:1)
Block(-6,19,6,LOG:13)
Block(-6,19,7,LEAVES:1)
Block(-6,20,-6,LEAVES:1)
Block(-6,20,0,LEAVES:1)
Block(-6,20,6,LEAVES:1)
Block(-6,23,-7,LEAVES:1)
Block(-6,23,-6,LOG:13)
Block(-6,23,-5,LEAVES:1)
Block(-6,23,-1,LEAVES:1)
Block(-6,23,0,LOG:13)
Block(-6,23,1,LEAVES:1)
Block(-6,23,5,LEAVES:1)
Block(-6,23,6,LOG:13)
Block(-6,23,7,LEAVES:1)
Block(-6,24,-6,LEAVES:1)
Block(-6,24,0,LEAVES:1)
Block(-6,24,6,LEAVES:1)
Block(-6,28,-6,LEAVES:1)
Block(-6,28,-5,LEAVES:1)
Block(-6,28,-1,LEAVES:1)
Block(-6,28,0,LOG:13)
Block(-6,28,1,LEAVES:1)
Block(-6,28,5,LEAVES:1)
Block(-6,28,6,LEAVES:1)
Block(-6,29,0,LEAVES:1)
Block(-6,32,0,LEAVES:1)
Block(-5,12,-5,LEAVES:1)
Block(-5,12,-4,LEAVES:1)
Block(-5,12,-1,LEAVES:1)
Block(-5,12,0,LOG:13)
Block(-5,12,1,LEAVES:1)
Block(-5,12,4,LEAVES:1)
Block(-5,12,5,LEAVES:1)
Block(-5,13,0,LEAVES:1)
Block(-5,15,-6,LEAVES:1)
Block(-5,15,-5,LOG:13)
Block(-5,15,5,LOG:13)
Block(-5,15,6,LEAVES:1)
Block(-5,16,-5,LEAVES:1)
Block(-5,16,-4,LEAVES:1)
Block(-5,16,-1,LEAVES:1)
Block(-5,16,0,LOG:13)
Block(-5,16,1,LEAVES:1)
Block(-5,16,4,LEAVES:1)
Block(-5,16,5,LEAVES:1)
Block(-5,17,0,LEAVES:1)
Block(-5,19,-6,LEAVES:1)
Block(-5,19,-5,LOG:13)
Block(-5,19,5,LOG:13)
Block(-5,19,6,LEAVES:1)
Block(-5,20,-5,LEAVES:1)
Block(-5,20,-4,LEAVES:1)
Block(-5,20,-1,LEAVES:1)
Block(-5,20,0,LOG:13)
Block(-5,20,1,LEAVES:1)
Block(-5,20,4,LEAVES:1)
Block(-5,20,5,LEAVES:1)
Block(-5,21,0,LEAVES:1)
Block(-5,23,-6,LEAVES:1)
Block(-5,23,-5,LOG:13)
Block(-5,23,5,LOG:13)
Block(-5,23,6,LEAVES:1)
Block(-5,24,-5,LEAVES:1)
Block(-5,24,-4,LEAVES:1)
Block(-5,24,-1,LEAVES:1)
Block(-5,24,0,LOG:13)
Block(-5,24,1,LEAVES:1)
Block(-5,24,4,LEAVES:1)
Block(-5,24,5,LEAVES:1)
Block(-5,25,0,LEAVES:1)
Block(-5,28,-6,LEAVES:1)
Block(-5,28,-5,LOG:13)
Block(-5,28,-4,LEAVES:1)
Block(-5,28,-1,LEAVES:1)
Block(-5,28,0,LOG:13)
Block(-5,28,1,LEAVES:1)
Block(-5,28,4,LEAVES:1)
Block(-5,28,5,LOG:13)
Block(-5,28,6,LEAVES:1)
Block(-5,29,-5,LEAVES:1)
Block(-5,29,0,LEAVES:1)
Block(-5,29,5,LEAVES:1)
Block(-5,32,-5,LEAVES:1)
Block(-5,32,-4,LEAVES:1)
Block(-5,32,-1,LEAVES:1)
Block(-5,32,0,LOG:13)
Block(-5,32,1,LEAVES:1)
Block(-5,32,4,LEAVES:1)
Block(-5,32,5,LEAVES:1)
Block(-5,33,0,LEAVES:1)
Block(-5,36,0,LEAVES:1)
Block(-4,7,0,LEAVES:1)
Block(-4,8,0,LEAVES:1)
Block(-4,12,-5,LEAVES:1)
Block(-4,12,-4,LOG:13)
Block(-4,12,-3,LEAVES:1)
Block(-4,12,-1,LEAVES:1)
Block(-4,12,0,LOG:13)
Block(-4,12,1,LEAVES:1)
Block(-4,12,3,LEAVES:1)
Block(-4,12,4,LOG:13)
Block(-4,12,5,LEAVES:1)
Block(-4,13,-4,LEAVES:1)
Block(-4,13,0,LEAVES:1)
Block(-4,13,4,LEAVES:1)
Block(-4,15,-5,LEAVES:1)
Block(-4,16,-5,LEAVES:1)
Block(-4,16,-4,LOG:13)
Block(-4,16,-3,LEAVES:1)
Block(-4,16,-1,LEAVES:1)
Block(-4,16,0,LOG:13)
Block(-4,16,1,LEAVES:1)
Block(-4,16,3,LEAVES:1)
Block(-4,16,4,LOG:13)
Block(-4,16,5,LEAVES:1)
Block(-4,17,-4,LEAVES:1)
Block(-4,17,-2,LEAVES:1)
Block(-4,17,-1,LEAVES:1)
Block(-4,17,0,LEAVES:1)
Block(-4,17,1,LEAVES:1)
Block(-4,17,2,LEAVES:1)
Block(-4,17,4,LEAVES:1)
Block(-4,19,-5,LEAVES:1)
Block(-4,20,-5,LEAVES:1)
Block(-4,20,-4,LOG:13)
Block(-4,20,-3,LEAVES:1)
Block(-4,20,-1,LEAVES:1)
Block(-4,20,0,LOG:13)
Block(-4,20,1,LEAVES:1)
Block(-4,20,3,LEAVES:1)
Block(-4,20,4,LOG:13)
Block(-4,20,5,LEAVES:1)
Block(-4,21,-4,LEAVES:1)
Block(-4,21,-2,LEAVES:1)
Block(-4,21,-1,LEAVES:1)
Block(-4,21,0,LEAVES:1)
Block(-4,21,1,LEAVES:1)
Block(-4,21,2,LEAVES:1)
Block(-4,21,4,LEAVES:1)
Block(-4,23,-5,LEAVES:1)
Block(-4,24,-5,LEAVES:1)
Block(-4,24,-4,LOG:13)
Block(-4,24,-3,LEAVES:1)
Block(-4,24,-1,LEAVES:1)
Block(-4,24,0,LOG:13)
Block(-4,24,1,LEAVES:1)
Block(-4,24,3,LEAVES:1)
Block(-4,24,4,LOG:13)
Block(-4,24,5,LEAVES:1)
Block(-4,25,-4,LEAVES:1)
Block(-4,25,-2,LEAVES:1)
Block(-4,25,-1,LEAVES:1)
Block(-4,25,0,LEAVES:1)
Block(-4,25,1,LEAVES:1)
Block(-4,25,2,LEAVES:1)
Block(-4,25,4,LEAVES:1)
Block(-4,28,-5,LEAVES:1)
Block(-4,28,-4,LOG:13)
Block(-4,28,-3,LEAVES:1)
Block(-4,28,-1,LEAVES:1)
Block(-4,28,0,LOG:13)
Block(-4,28,1,LEAVES:1)
Block(-4,28,3,LEAVES:1)
Block(-4,28,4,LOG:13)
Block(-4,28,5,LEAVES:1)
Block(-4,29,-4,LEAVES:1)
Block(-4,29,0,LEAVES:1)
Block(-4,29,4,LEAVES:1)
Block(-4,32,-5,LEAVES:1)
Block(-4,32,-4,LOG:13)
Block(-4,32,-3,LEAVES:1)
Block(-4,32,-1,LEAVES:1)
Block(-4,32,0,LOG:13)
Block(-4,32,1,LEAVES:1)
Block(-4,32,3,LEAVES:1)
Block(-4,32,4,LOG:13)
Block(-4,32,5,LEAVES:1)
Block(-4,33,-4,LEAVES:1)
Block(-4,33,0,LEAVES:1)
Block(-4,33,4,LEAVES:1)
Block(-4,36,-3,LEAVES:1)
Block(-4,36,-1,LEAVES:1)
Block(-4,36,0,LOG:13)
Block(-4,36,1,LEAVES:1)
Block(-4,36,3,LEAVES:1)
Block(-4,37,0,LEAVES:1)
Block(-4,40,0,LEAVES:1)
Block(-3,7,0,LEAVES:1)
Block(-3,8,-1,LEAVES:1)
Block(-3,8,0,LOG:13)
Block(-3,8,1,LEAVES:1)
Block(-3,9,0,LEAVES:1)
Block(-3,12,-4,LEAVES:1)
Block(-3,12,-3,LOG:13)
Block(-3,12,3,LOG:13)
Block(-3,12,4,LEAVES:1)
Block(-3,13,-3,LEAVES:1)
Block(-3,13,-2,LEAVES:1)
Block(-3,13,-1,LEAVES:1)
Block(-3,13,0,LOG:13)
Block(-3,13,1,LEAVES:1)
Block(-3,13,2,LEAVES:1)
Block(-3,13,3,LEAVES:1)
Block(-3,14,0,LEAVES:1)
Block(-3,16,-4,LEAVES:1)
Block(-3,16,-3,LOG:13)
Block(-3,16,3,LOG:13)
Block(-3,16,4,LEAVES:1)
Block(-3,17,-3,LEAVES:1)
Block(-3,17,-2,LEAVES:1)
Block(-3,17,-1,LEAVES:1)
Block(-3,17,0,LOG:13)
Block(-3,17,1,LEAVES:1)
Block(-3,17,2,LEAVES:1)
Block(-3,17,3,LEAVES:1)
Block(-3,18,-3,LEAVES:1)
Block(-3,18,0,LEAVES:1)
Block(-3,18,3,LEAVES:1)
Block(-3,20,-4,LEAVES:1)
Block(-3,20,-3,LOG:13)
Block(-3,20,3,LOG:13)
Block(-3,20,4,LEAVES:1)
Block(-3,21,-3,LEAVES:1)
Block(-3,21,-2,LEAVES:1)
Block(-3,21,-1,LEAVES:1)
Block(-3,21,0,LOG:13)
Block(-3,21,1,LEAVES:1)
Block(-3,21,2,LEAVES:1)
Block(-3,21,3,LEAVES:1)
Block(-3,22,-3,LEAVES:1)
Block(-3,22,0,LEAVES:1)
Block(-3,22,3,LEAVES:1)
Block(-3,24,-4,LEAVES:1)
Block(-3,24,-3,LOG:13)
Block(-3,24,3,LOG:13)
Block(-3,24,4,LEAVES:1)
Block(-3,25,-3,LEAVES:1)
Block(-3,25,-2,LEAVES:1)
Block(-3,25,-1,LEAVES:1)
Block(-3,25,0,LOG:13)
Block(-3,25,1,LEAVES:1)
Block(-3,25,2,LEAVES:1)
Block(-3,25,3,LEAVES:1)
Block(-3,26,-3,LEAVES:1)
Block(-3,26,0,LEAVES:1)
Block(-3,26,3,LEAVES:1)
Block(-3,28,-4,LEAVES:1)
Block(-3,28,-3,LOG:13)
Block(-3,28,3,LOG:13)
Block(-3,28,4,LEAVES:1)
Block(-3,29,-3,LEAVES:1)
Block(-3,29,-2,LEAVES:1)
Block(-3,29,-1,LEAVES:1)
Block(-3,29,0,LOG:13)
Block(-3,29,1,LEAVES:1)
Block(-3,29,2,LEAVES:1)
Block(-3,29,3,LEAVES:1)
Block(-3,30,0,LEAVES:1)
Block(-3,32,-4,LEAVES:1)
Block(-3,32,-3,LOG:13)
Block(-3,32,3,LOG:13)
Block(-3,32,4,LEAVES:1)
Block(-3,33,-3,LEAVES:1)
Block(-3,33,-2,LEAVES:1)
Block(-3,33,-1,LEAVES:1)
Block(-3,33,0,LOG:13)
Block(-3,33,1,LEAVES:1)
Block(-3,33,2,LEAVES:1)
Block(-3,33,3,LEAVES:1)
Block(-3,34,0,LEAVES:1)
Block(-3,36,-4,LEAVES:1)
Block(-3,36,-3,LOG:13)
Block(-3,36,3,LOG:13)
Block(-3,36,4,LEAVES:1)
Block(-3,37,-3,LEAVES:1)
Block(-3,37,-2,LEAVES:1)
Block(-3,37,-1,LEAVES:1)
Block(-3,37,0,LOG:13)
Block(-3,37,1,LEAVES:1)
Block(-3,37,2,LEAVES:1)
Block(-3,37,3,LEAVES:1)
Block(-3,38,0,LEAVES:1)
Block(-3,40,-2,LEAVES:1)
Block(-3,40,-1,LEAVES:1)
Block(-3,40,0,LOG:13)
Block(-3,40,1,LEAVES:1)
Block(-3,40,2,LEAVES:1)
Block(-3,41,0,LEAVES:1)
Block(-2,0,0,LOG:13)
Block(-2,1,0,LOG:13)
Block(-2,2,0,LOG:13)
Block(-2,3,0,LOG:13)
Block(-2,4,0,LOG:13)
Block(-2,5,0,LOG:13)
Block(-2,6,0,LOG:13)
Block(-2,7,-3,LEAVES:1)
Block(-2,7,-2,LEAVES:1)
Block(-2,7,0,LOG:13)
Block(-2,8,-1,LEAVES:1)
Block(-2,8,0,LOG:13)
Block(-2,8,1,LEAVES:1)
Block(-2,9,0,LEAVES:1)
Block(-2,13,-3,LEAVES:1)
Block(-2,13,-2,LOG:13)
Block(-2,13,-1,LEAVES:1)
Block(-2,13,0,LOG:13)
Block(-2,13,1,LEAVES:1)
Block(-2,13,2,LOG:13)
Block(-2,13,3,LEAVES:1)
Block(-2,14,-2,LEAVES:1)
Block(-2,14,0,LEAVES:1)
Block(-2,14,2,LEAVES:1)
Block(-2,17,-4,LEAVES:1)
Block(-2,17,-3,LEAVES:1)
Block(-2,17,-2,LOG:13)
Block(-2,17,-1,LEAVES:1)
Block(-2,17,0,LOG:13)
Block(-2,17,1,LEAVES:1)
Block(-2,17,2,LOG:13)
Block(-2,17,3,LEAVES:1)
Block(-2,17,4,LEAVES:1)
Block(-2,18,-2,LEAVES:1)
Block(-2,18,-1,LEAVES:1)
Block(-2,18,0,LEAVES:1)
Block(-2,18,1,LEAVES:1)
Block(-2,18,2,LEAVES:1)
Block(-2,21,-4,LEAVES:1)
Block(-2,21,-3,LEAVES:1)
Block(-2,21,-2,LOG:13)
Block(-2,21,-1,LEAVES:1)
Block(-2,21,0,LOG:13)
Block(-2,21,1,LEAVES:1)
Block(-2,21,2,LOG:13)
Block(-2,21,3,LEAVES:1)
Block(-2,21,4,LEAVES:1)
Block(-2,22,-2,LEAVES:1)
Block(-2,22,-1,LEAVES:1)
Block(-2,22,0,LEAVES:1)
Block(-2,22,1,LEAVES:1)
Block(-2,22,2,LEAVES:1)
Block(-2,25,-4,LEAVES:1)
Block(-2,25,-3,LEAVES:1)
Block(-2,25,-2,LOG:13)
Block(-2,25,-1,LEAVES:1)
Block(-2,25,0,LOG:13)
Block(-2,25,1,LEAVES:1)
Block(-2,25,2,LOG:13)
Block(-2,25,3,LEAVES:1)
Block(-2,25,4,LEAVES:1)
Block(-2,26,-2,LEAVES:1)
Block(-2,26,-1,LEAVES:1)
Block(-2,26,0,LEAVES:1)
Block(-2,26,1,LEAVES:1)
Block(-2,26,2,LEAVES:1)
Block(-2,29,-3,LEAVES:1)
Block(-2,29,-2,LOG:13)
Block(-2,29,-1,LEAVES:1)
Block(-2,29,0,LOG:13)
Block(-2,29,1,LEAVES:1)
Block(-2,29,2,LOG:13)
Block(-2,29,3,LEAVES:1)
Block(-2,30,-2,LEAVES:1)
Block(-2,30,0,LEAVES:1)
Block(-2,30,2,LEAVES:1)
Block(-2,33,-3,LEAVES:1)
Block(-2,33,-2,LOG:13)
Block(-2,33,-1,LEAVES:1)
Block(-2,33,0,LOG:13)
Block(-2,33,1,LEAVES:1)
Block(-2,33,2,LOG:13)
Block(-2,33,3,LEAVES:1)
Block(-2,34,-2,LEAVES:1)
Block(-2,34,0,LEAVES:1)
Block(-2,34,2,LEAVES:1)
Block(-2,37,-3,LEAVES:1)
Block(-2,37,-2,LOG:13)
Block(-2,37,-1,LEAVES:1)
Block(-2,37,0,LOG:13)
Block(-2,37,1,LEAVES:1)
Block(-2,37,2,LOG:13)
Block(-2,37,3,LEAVES:1)
Block(-2,38,-2,LEAVES:1)
Block(-2,38,0,LEAVES:1)
Block(-2,38,2,LEAVES:1)
Block(-2,40,-3,LEAVES:1)
Block(-2,40,-2,LEAVES:1)
Block(-2,40,2,LEAVES:1)
Block(-2,40,3,LEAVES:1)
Block(-2,41,-1,LEAVES:1)
Block(-2,41,0,LOG:13)
Block(-2,41,1,LEAVES:1)
Block(-2,42,0,LEAVES:1)
Block(-2,44,0,LEAVES:1)
Block(-1,0,-1,LOG:13)
Block(-1,0,0,LOG:13)
Block(-1,0,1,LOG:13)
Block(-1,1,-1,LOG:13)
Block(-1,1,0,LOG:13)
Block(-1,1,1,LOG:13)
Block(-1,2,-1,LOG:13)
Block(-1,2,0,LOG:13)
Block(-1,2,1,LOG:13)
Block(-1,3,-1,LOG:13)
Block(-1,3,0,LOG:13)
Block(-1,3,1,LOG:13)
Block(-1,4,-1,LOG:13)
Block(-1,4,1,LOG:13)
Block(-1,5,-1,LOG:13)
Block(-1,5,1,LOG:13)
Block(-1,6,-4,LEAVES:1)
Block(-1,6,-3,LEAVES:1)
Block(-1,6,-2,LEAVES:1)
Block(-1,6,-1,LOG:13)
Block(-1,6,0,LOG:13)
Block(-1,6,1,LOG:13)
Block(-1,7,-4,LEAVES:1)
Block(-1,7,-3,LOG:13)
Block(-1,7,-2,LOG:13)
Block(-1,7,-1,LOG:13)
Block(-1,7,0,LOG:13)
Block(-1,7,1,LOG:13)
Block(-1,8,-3,LEAVES:1)
Block(-1,8,-2,LEAVES:1)
Block(-1,8,-1,LOG:13)
Block(-1,8,0,LOG:13)
Block(-1,8,1,LOG:13)
Block(-1,8,2,LEAVES:1)
Block(-1,8,3,LEAVES:1)
Block(-1,9,-1,LOG:13)
Block(-1,9,0,LOG:13)
Block(-1,9,1,LOG:13)
Block(-1,10,-1,LOG:13)
Block(-1,10,0,LOG:13)
Block(-1,10,1,LOG:13)
Block(-1,11,-1,LOG:13)
Block(-1,11,0,LOG:13)
Block(-1,11,1,LOG:13)
Block(-1,12,-5,LEAVES:1)
Block(-1,12,-4,LEAVES:1)
Block(-1,12,-1,LOG:13)
Block(-1,12,0,LOG:13)
Block(-1,12,1,LOG:13)
Block(-1,12,4,LEAVES:1)
Block(-1,12,5,LEAVES:1)
Block(-1,13,-3,LEAVES:1)
Block(-1,13,-2,LEAVES:1)
Block(-1,13,-1,LOG:13)
Block(-1,13,0,LOG:13)
Block(-1,13,1,LOG:13)
Block(-1,13,2,LEAVES:1)
Block(-1,13,3,LEAVES:1)
Block(-1,14,-1,LOG:13)
Block(-1,14,0,LOG:13)
Block(-1,14,1,LOG:13)
Block(-1,15,-7,LEAVES:1)
Block(-1,15,-6,LEAVES:1)
Block(-1,15,-1,LOG:13)
Block(-1,15,0,LOG:13)
Block(-1,15,1,LOG:13)
Block(-1,15,6,LEAVES:1)
Block(-1,15,7,LEAVES:1)
Block(-1,16,-5,LEAVES:1)
Block(-1,16,-4,LEAVES:1)
Block(-1,16,0,LOG:13)
Block(-1,16,4,LEAVES:1)
Block(-1,16,5,LEAVES:1)
Block(-1,17,-4,LEAVES:1)
Block(-1,17,-3,LEAVES:1)
Block(-1,17,-2,LEAVES:1)
Block(-1,17,-1,LOG:13)
Block(-1,17,0,LOG:13)
Block(-1,17,1,LOG:13)
Block(-1,17,2,LEAVES:1)
Block(-1,17,3,LEAVES:1)
Block(-1,17,4,LEAVES:1)
Block(-1,18,-2,LEAVES:1)
Block(-1,18,-1,LEAVES:1)
Block(-1,18,0,LOG:13)
Block(-1,18,1,LEAVES:1)
Block(-1,18,2,LEAVES:1)
Block(-1,19,-7,LEAVES:1)
Block(-1,19,-6,LEAVES:1)
Block(-1,19,-1,LOG:13)
Block(-1,19,0,LOG:13)
Block(-1,19,1,LOG:13)
Block(-1,19,6,LEAVES:1)
Block(-1,19,7,LEAVES:1)
Block(-1,20,-5,LEAVES:1)
Block(-1,20,-4,LEAVES:1)
Block(-1,20,0,LOG:13)
Block(-1,20,4,LEAVES:1)
Block(-1,20,5,LEAVES:1)
Block(-1,21,-4,LEAVES:1)
Block(-1,21,-3,LEAVES:1)
Block(-1,21,-2,LEAVES:1)
Block(-1,21,-1,LOG:13)
Block(-1,21,0,LOG:13)
Block(-1,21,1,LOG:13)
Block(-1,21,2,LEAVES:1)
Block(-1,21,3,LEAVES:1)
Block(-1,21,4,LEAVES:1)
Block(-1,22,-2,LEAVES:1)
Block(-1,22,-1,LEAVES:1)
Block(-1,22,0,LOG:13)
Block(-1,22,1,LEAVES:1)
Block(-1,22,2,LEAVES:1)
Block(-1,23,-7,LEAVES:1)
Block(-1,23,-6,LEAVES:1)
Block(-1,23,-1,LOG:13)
Block(-1,23,0,LOG:13)
Block(-1,23,1,LOG:13)
Block(-1,23,6,LEAVES:1)
Block(-1,23,7,LEAVES:1)
Block(-1,24,-5,LEAVES:1)
Block(-1,24,-4,LEAVES:1)
Block(-1,24,0,LOG:13)
Block(-1,24,4,LEAVES:1)
Block(-1,24,5,LEAVES:1)
Block(-1,25,-4,LEAVES:1)
Block(-1,25,-3,LEAVES:1)
Block(-1,25,-2,LEAVES:1)
Block(-1,25,-1,LOG:13)
Block(-1,25,0,LOG:13)
Block(-1,25,1,LOG:13)
Block(-1,25,2,LEAVES:1)
Block(-1,25,3,LEAVES:1)
Block(-1,25,4,LEAVES:1)
Block(-1,26,-2,LEAVES:1)
Block(-1,26,-1,LEAVES:1)
Block(-1,26,0,LOG:13)
Block(-1,26,1,LEAVES:1)
Block(-1,26,2,LEAVES:1)
Block(-1,27,0,LOG:13)
Block(-1,28,-6,LEAVES:1)
Block(-1,28,-5,LEAVES:1)
Block(-1,28,-4,LEAVES:1)
Block(-1,28,0,LOG:13)
Block(-1,28,4,LEAVES:1)
Block(-1,28,5,LEAVES:1)
Block(-1,28,6,LEAVES:1)
Block(-1,29,-3,LEAVES:1)
Block(-1,29,-2,LEAVES:1)
Block(-1,29,-1,LOG:13)
Block(-1,29,0,LOG:13)
Block(-1,29,1,LOG:13)
Block(-1,29,2,LEAVES:1)
Block(-1,29,3,LEAVES:1)
Block(-1,30,-1,LEAVES:1)
Block(-1,30,0,LOG:13)
Block(-1,30,1,LEAVES:1)
Block(-1,31,0,LOG:13)
Block(-1,32,-5,LEAVES:1)
Block(-1,32,-4,LEAVES:1)
Block(-1,32,0,LOG:13)
Block(-1,32,4,LEAVES:1)
Block(-1,32,5,LEAVES:1)
Block(-1,33,-3,LEAVES:1)
Block(-1,33,-2,LEAVES:1)
Block(-1,33,-1,LOG:13)
Block(-1,33,0,LOG:13)
Block(-1,33,1,LOG:13)
Block(-1,33,2,LEAVES:1)
Block(-1,33,3,LEAVES:1)
Block(-1,34,-1,LEAVES:1)
Block(-1,34,0,LOG:13)
Block(-1,34,1,LEAVES:1)
Block(-1,35,0,LOG:13)
Block(-1,36,-4,LEAVES:1)
Block(-1,36,0,LOG:13)
Block(-1,36,4,LEAVES:1)
Block(-1,37,-3,LEAVES:1)
Block(-1,37,-2,LEAVES:1)
Block(-1,37,-1,LOG:13)
Block(-1,37,0,LOG:13)
Block(-1,37,1,LOG:13)
Block(-1,37,2,LEAVES:1)
Block(-1,37,3,LEAVES:1)
Block(-1,38,-1,LEAVES:1)
Block(-1,38,0,LOG:13)
Block(-1,38,1,LEAVES:1)
Block(-1,39,0,LOG:13)
Block(-1,40,-3,LEAVES:1)
Block(-1,40,0,LOG:13)
Block(-1,40,3,LEAVES:1)
Block(-1,41,-2,LEAVES:1)
Block(-1,41,-1,LOG:13)
Block(-1,41,0,LOG:13)
Block(-1,41,1,LOG:13)
Block(-1,41,2,LEAVES:1)
Block(-1,42,-1,LEAVES:1)
Block(-1,42,0,LOG:13)
Block(-1,42,1,LEAVES:1)
Block(-1,43,0,LOG:13)
Block(-1,44,-1,LEAVES:1)
Block(-1,44,0,LOG:13)
Block(-1,44,1,LEAVES:1)
Block(-1,45,0,LEAVES:1)
Block(0,0,-2,LOG:13)
Block(0,0,-1,LOG:13)
Block(0,0,0,LOG:13)
Block(0,0,1,LOG:13)
Block(0,0,2,LOG:13)
Block(0,1,-2,LOG:13)
Block(0,1,-1,LOG:13)
Block(0,1,0,LOG:13)
Block(0,1,1,LOG:13)
Block(0,1,2,LOG:13)
Block(0,2,-2,LOG:13)
Block(0,2,-1,LOG:13)
Block(0,2,0,LOG:13)
Block(0,2,1,LOG:13)
Block(0,2,2,LOG:13)
Block(0,3,-2,LOG:13)
Block(0,3,-1,LOG:13)
Block(0,3,0,LOG:13)
Block(0,3,1,LOG:13)
Block(0,3,2,LOG:13)
Block(0,4,-2,LOG:13)
Block(0,4,-1,LOG:13)
Block(0,4,1,LOG:13)
Block(0,4,2,LOG:13)
Block(0,5,-2,LOG:13)
Block(0,5,-1,LOG:13)
Block(0,5,1,LOG:13)
Block(0,5,2,LOG:13)
Block(0,6,-2,LOG:13)
Block(0,6,-1,LOG:13)
Block(0,6,0,LOG:13)
Block(0,6,1,LOG:13)
Block(0,6,2,LOG:13)
Block(0,7,-3,LEAVES:1)
Block(0,7,-2,LOG:13)
Block(0,7,-1,LOG:13)
Block(0,7,0,LOG:13)
Block(0,7,1,LOG:13)
Block(0,7,2,LOG:13)
Block(0,7,3,LEAVES:1)
Block(0,7,4,LEAVES:1)
Block(0,8,-2,LOG:13)
Block(0,8,-1,LOG:13)
Block(0,8,0,LOG:13)
Block(0,8,1,LOG:13)
Block(0,8,2,LOG:13)
Block(0,8,3,LOG:13)
Block(0,8,4,LEAVES:1)
Block(0,9,-1,LOG:13)
Block(0,9,0,LOG:13)
Block(0,9,1,LOG:13)
Block(0,9,2,LEAVES:1)
Block(0,9,3,LEAVES:1)
Block(0,10,-1,LOG:13)
Block(0,10,0,LOG:13)
Block(0,10,1,LOG:13)
Block(0,11,-1,LOG:13)
Block(0,11,0,LOG:13)
Block(0,11,1,LOG:13)
Block(0,12,-6,LEAVES:1)
Block(0,12,-5,LOG:13)
Block(0,12,-4,LOG:13)
Block(0,12,-1,LOG:13)
Block(0,12,0,LOG:13)
Block(0,12,1,LOG:13)
Block(0,12,4,LOG:13)
Block(0,12,5,LOG:13)
Block(0,12,6,LEAVES:1)
Block(0,13,-5,LEAVES:1)
Block(0,13,-4,LEAVES:1)
Block(0,13,-3,LOG:13)
Block(0,13,-2,LOG:13)
Block(0,13,-1,LOG:13)
Block(0,13,0,LOG:13)
Block(0,13,1,LOG:13)
Block(0,13,2,LOG:13)
Block(0,13,3,LOG:13)
Block(0,13,4,LEAVES:1)
Block(0,13,5,LEAVES:1)
Block(0,14,-3,LEAVES:1)
Block(0,14,-2,LEAVES:1)
Block(0,14,-1,LOG:13)
Block(0,14,0,LOG:13)
Block(0,14,1,LOG:13)
Block(0,14,2,LEAVES:1)
Block(0,14,3,LEAVES:1)
Block(0,15,-8,LEAVES:1)
Block(0,15,-7,LOG:13)
Block(0,15,-6,LOG:13)
Block(0,15,-1,LOG:13)
Block(0,15,0,LOG:13)
Block(0,15,1,LOG:13)
Block(0,15,6,LOG:13)
Block(0,15,7,LOG:13)
Block(0,16,-7,LEAVES:1)
Block(0,16,-6,LEAVES:1)
Block(0,16,-5,LOG:13)
Block(0,16,-4,LOG:13)
Block(0,16,-1,LOG:13)
Block(0,16,0,LOG:13)
Block(0,16,1,LOG:13)
Block(0,16,4,LOG:13)
Block(0,16,5,LOG:13)
Block(0,16,6,LEAVES:1)
Block(0,16,7,LEAVES:1)
Block(0,17,-5,LEAVES:1)
Block(0,17,-4,LEAVES:1)
Block(0,17,-3,LOG:13)
Block(0,17,-2,LOG:13)
Block(0,17,-1,LOG:13)
Block(0,17,0,LOG:13)
Block(0,17,1,LOG:13)
Block(0,17,2,LOG:13)
Block(0,17,3,LOG:13)
Block(0,17,4,LEAVES:1)
Block(0,17,5,LEAVES:1)
Block(0,18,-3,LEAVES:1)
Block(0,18,-2,LEAVES:1)
Block(0,18,-1,LOG:13)
Block(0,18,0,LOG:13)
Block(0,18,1,LOG:13)
Block(0,18,2,LEAVES:1)
Block(0,18,3,LEAVES:1)
Block(0,19,-8,LEAVES:1)
Block(0,19,-7,LOG:13)
Block(0,19,-6,LOG:13)
Block(0,19,-1,LOG:13)
Block(0,19,0,LOG:13)
Block(0,19,1,LOG:13)
Block(0,19,6,LOG:13)
Block(0,19,7,LOG:13)
Block(0,20,-7,LEAVES:1)
Block(0,20,-6,LEAVES:1)
Block(0,20,-5,LOG:13)
Block(0,20,-4,LOG:13)
Block(0,20,-1,LOG:13)
Block(0,20,0,LOG:13)
Block(0,20,1,LOG:13)
Block(0,20,4,LOG:13)
Block(0,20,5,LOG:13)
Block(0,20,6,LEAVES:1)
Block(0,20,7,LEAVES:1)
Block(0,21,-5,LEAVES:1)
Block(0,21,-4,LEAVES:1)
Block(0,21,-3,LOG:13)
Block(0,21,-2,LOG:13)
Block(0,21,-1,LOG:13)
Block(0,21,0,LOG:13)
Block(0,21,1,LOG:13)
Block(0,21,2,LOG:13)
Block(0,21,3,LOG:13)
Block(0,21,4,LEAVES:1)
Block(0,21,5,LEAVES:1)
Block(0,22,-3,LEAVES:1)
Block(0,22,-2,LEAVES:1)
Block(0,22,-1,LOG:13)
Block(0,22,0,LOG:13)
Block(0,22,1,LOG:13)
Block(0,22,2,LEAVES:1)
Block(0,22,3,LEAVES:1)
Block(0,23,-8,LEAVES:1)
Block(0,23,-7,LOG:13)
Block(0,23,-6,LOG:13)
Block(0,23,-1,LOG:13)
Block(0,23,0,LOG:13)
Block(0,23,1,LOG:13)
Block(0,23,6,LOG:13)
Block(0,23,7,LOG:13)
Block(0,24,-7,LEAVES:1)
Block(0,24,-6,LEAVES:1)
Block(0,24,-5,LOG:13)
Block(0,24,-4,LOG:13)
Block(0,24,-1,LOG:13)
Block(0,24,0,LOG:13)
Block(0,24,1,LOG:13)
Block(0,24,4,LOG:13)
Block(0,24,5,LOG:13)
Block(0,24,6,LEAVES:1)
Block(0,24,7,LEAVES:1)
Block(0,25,-5,LEAVES:1)
Block(0,25,-4,LEAVES:1)
Block(0,25,-3,LOG:13)
Block(0,25,-2,LOG:13)
Block(0,25,-1,LOG:13)
Block(0,25,0,LOG:13)
Block(0,25,1,LOG:13)
Block(0,25,2,LOG:13)
Block(0,25,3,LOG:13)
Block(0,25,4,LEAVES:1)
Block(0,25,5,LEAVES:1)
Block(0,26,-3,LEAVES:1)
Block(0,26,-2,LEAVES:1)
Block(0,26,-1,LOG:13)
Block(0,26,0,LOG:13)
Block(0,26,1,LOG:13)
Block(0,26,2,LEAVES:1)
Block(0,26,3,LEAVES:1)
Block(0,27,-1,LOG:13)
Block(0,27,0,LOG:13)
Block(0,27,1,LOG:13)
Block(0,28,-7,LEAVES:1)
Block(0,28,-6,LOG:13)
Block(0,28,-5,LOG:13)
Block(0,28,-4,LOG:13)
Block(0,28,-1,LOG:13)
Block(0,28,0,LOG:13)
Block(0,28,1,LOG:13)
Block(0,28,4,LOG:13)
Block(0,28,5,LOG:13)
Block(0,28,6,LOG:13)
Block(0,28,7,LEAVES:1)
Block(0,29,-6,LEAVES:1)
Block(0,29,-5,LEAVES:1)
Block(0,29,-4,LEAVES:1)
Block(0,29,-3,LOG:13)
Block(0,29,-2,LOG:13)
Block(0,29,-1,LOG:13)
Block(0,29,0,LOG:13)
Block(0,29,1,LOG:13)
Block(0,29,2,LOG:13)
Block(0,29,3,LOG:13)
Block(0,29,4,LEAVES:1)
Block(0,29,5,LEAVES:1)
Block(0,29,6,LEAVES:1)
Block(0,30,-3,LEAVES:1)
Block(0,30,-2,LEAVES:1)
Block(0,30,-1,LOG:13)
Block(0,30,0,LOG:13)
Block(0,30,1,LOG:13)
Block(0,30,2,LEAVES:1)
Block(0,30,3,LEAVES:1)
Block(0,31,-1,LOG:13)
Block(0,31,0,LOG:13)
Block(0,31,1,LOG:13)
Block(0,32,-6,LEAVES:1)
Block(0,32,-5,LOG:13)
Block(0,32,-4,LOG:13)
Block(0,32,-1,LOG:13)
Block(0,32,0,LOG:13)
Block(0,32,1,LOG:13)
Block(0,32,4,LOG:13)
Block(0,32,5,LOG:13)
Block(0,32,6,LEAVES:1)
Block(0,33,-5,LEAVES:1)
Block(0,33,-4,LEAVES:1)
Block(0,33,-3,LOG:13)
Block(0,33,-2,LOG:13)
Block(0,33,-1,LOG:13)
Block(0,33,0,LOG:13)
Block(0,33,1,LOG:13)
Block(0,33,2,LOG:13)
Block(0,33,3,LOG:13)
Block(0,33,4,LEAVES:1)
Block(0,33,5,LEAVES:1)
Block(0,34,-3,LEAVES:1)
Block(0,34,-2,LEAVES:1)
Block(0,34,-1,LOG:13)
Block(0,34,0,LOG:13)
Block(0,34,1,LOG:13)
Block(0,34,2,LEAVES:1)
Block(0,34,3,LEAVES:1)
Block(0,35,-1,LOG:13)
Block(0,35,0,LOG:13)
Block(0,35,1,LOG:13)
Block(0,36,-5,LEAVES:1)
Block(0,36,-4,LOG:13)
Block(0,36,-1,LOG:13)
Block(0,36,0,LOG:13)
Block(0,36,1,LOG:13)
Block(0,36,4,LOG:13)
Block(0,36,5,LEAVES:1)
Block(0,37,-4,LEAVES:1)
Block(0,37,-3,LOG:13)
Block(0,37,-2,LOG:13)
Block(0,37,-1,LOG:13)
Block(0,37,0,LOG:13)
Block(0,37,1,LOG:13)
Block(0,37,2,LOG:13)
Block(0,37,3,LOG:13)
Block(0,37,4,LEAVES:1)
Block(0,38,-3,LEAVES:1)
Block(0,38,-2,LEAVES:1)
Block(0,38,-1,LOG:13)
Block(0,38,0,LOG:13)
Block(0,38,1,LOG:13)
Block(0,38,2,LEAVES:1)
Block(0,38,3,LEAVES:1)
Block(0,39,-1,LOG:13)
Block(0,39,0,LOG:13)
Block(0,39,1,LOG:13)
Block(0,40,-4,LEAVES:1)
Block(0,40,-3,LOG:13)
Block(0,40,-1,LOG:13)
Block(0,40,0,LOG:13)
Block(0,40,1,LOG:13)
Block(0,40,3,LOG:13)
Block(0,40,4,LEAVES:1)
Block(0,41,-3,LEAVES:1)
Block(0,41,-2,LOG:13)
Block(0,41,-1,LOG:13)
Block(0,41,0,LOG:13)
Block(0,41,1,LOG:13)
Block(0,41,2,LOG:13)
Block(0,41,3,LEAVES:1)
Block(0,42,-2,LEAVES:1)
Block(0,42,-1,LOG:13)
Block(0,42,0,LOG:13)
Block(0,42,1,LOG:13)
Block(0,42,2,LEAVES:1)
Block(0,43,-1,LOG:13)
Block(0,43,0,LOG:13)
Block(0,43,1,LOG:13)
Block(0,44,-2,LEAVES:1)
Block(0,44,-1,LOG:13)
Block(0,44,0,LOG:13)
Block(0,44,1,LOG:13)
Block(0,44,2,LEAVES:1)
Block(0,45,-1,LEAVES:1)
Block(0,45,0,LEAVES:1)
Block(0,45,1,LEAVES:1)
Block(0,46,0,LEAVES:1)
Block(1,0,-1,LOG:13)
Block(1,0,0,LOG:13)
Block(1,0,1,LOG:13)
Block(1,1,-1,LOG:13)
Block(1,1,0,LOG:13)
Block(1,1,1,LOG:13)
Block(1,2,-1,LOG:13)
Block(1,2,0,LOG:13)
Block(1,2,1,LOG:13)
Block(1,3,-1,LOG:13)
Block(1,3,0,LOG:13)
Block(1,3,1,LOG:13)
Block(1,4,-1,LOG:13)
Block(1,4,0,LOG:13)
Block(1,4,1,LOG:13)
Block(1,5,-1,LOG:13)
Block(1,5,0,LOG:13)
Block(1,5,1,LOG:13)
Block(1,6,-1,LOG:13)
Block(1,6,0,LOG:13)
Block(1,6,1,LOG:13)
Block(1,7,-1,LOG:13)
Block(1,7,0,LOG:13)
Block(1,7,1,LOG:13)
Block(1,8,-1,LOG:13)
Block(1,8,0,LOG:13)
Block(1,8,1,LOG:13)
Block(1,8,2,LEAVES:1)
Block(1,8,3,LEAVES:1)
Block(1,9,-1,LOG:13)
Block(1,9,0,LOG:13)
Block(1,9,1,LOG:13)
Block(1,10,-1,LOG:13)
Block(1,10,0,LOG:13)
Block(1,10,1,LOG:13)
Block(1,11,-1,LOG:13)
Block(1,11,0,LOG:13)
Block(1,11,1,LOG:13)
Block(1,12,-5,LEAVES:1)
Block(1,12,-4,LEAVES:1)
Block(1,12,-1,LOG:13)
Block(1,12,0,LOG:13)
Block(1,12,1,LOG:13)
Block(1,12,4,LEAVES:1)
Block(1,12,5,LEAVES:1)
Block(1,13,-3,LEAVES:1)
Block(1,13,-2,LEAVES:1)
Block(1,13,-1,LOG:13)
Block(1,13,0,LOG:13)
Block(1,13,1,LOG:13)
Block(1,13,2,LEAVES:1)
Block(1,13,3,LEAVES:1)
Block(1,14,-1,LOG:13)
Block(1,14,0,LOG:13)
Block(1,14,1,LOG:13)
Block(1,15,-7,LEAVES:1)
Block(1,15,-6,LEAVES:1)
Block(1,15,-1,LOG:13)
Block(1,15,0,LOG:13)
Block(1,15,1,LOG:13)
Block(1,15,6,LEAVES:1)
Block(1,15,7,LEAVES:1)
Block(1,16,-5,LEAVES:1)
Block(1,16,-4,LEAVES:1)
Block(1,16,0,LOG:13)
Block(1,16,4,LEAVES:1)
Block(1,16,5,LEAVES:1)
Block(1,17,-4,LEAVES:1)
Block(1,17,-3,LEAVES:1)
Block(1,17,-2,LEAVES:1)
Block(1,17,-1,LOG:13)
Block(1,17,0,LOG:13)
Block(1,17,1,LOG:13)
Block(1,17,2,LEAVES:1)
Block(1,17,3,LEAVES:1)
Block(1,17,4,LEAVES:1)
Block(1,18,-2,LEAVES:1)
Block(1,18,-1,LEAVES:1)
Block(1,18,0,LOG:13)
Block(1,18,1,LEAVES:1)
Block(1,18,2,LEAVES:1)
Block(1,19,-7,LEAVES:1)
Block(1,19,-6,LEAVES:1)
Block(1,19,-1,LOG:13)
Block(1,19,0,LOG:13)
Block(1,19,1,LOG:13)
Block(1,19,6,LEAVES:1)
Block(1,19,7,LEAVES:1)
Block(1,20,-5,LEAVES:1)
Block(1,20,-4,LEAVES:1)
Block(1,20,0,LOG:13)
Block(1,20,4,LEAVES:1)
Block(1,20,5,LEAVES:1)
Block(1,21,-4,LEAVES:1)
Block(1,21,-3,LEAVES:1)
Block(1,21,-2,LEAVES:1)
Block(1,21,-1,LOG:13)
Block(1,21,0,LOG:13)
Block(1,21,1,LOG:13)
Block(1,21,2,LEAVES:1)
Block(1,21,3,LEAVES:1)
Block(1,21,4,LEAVES:1)
Block(1,22,-2,LEAVES:1)
Block(1,22,-1,LEAVES:1)
Block(1,22,0,LOG:13)
Block(1,22,1,LEAVES:1)
Block(1,22,2,LEAVES:1)
Block(1,23,-7,LEAVES:1)
Block(1,23,-6,LEAVES:1)
Block(1,23,-1,LOG:13)
Block(1,23,0,LOG:13)
Block(1,23,1,LOG:13)
Block(1,23,6,LEAVES:1)
Block(1,23,7,LEAVES:1)
Block(1,24,-5,LEAVES:1)
Block(1,24,-4,LEAVES:1)
Block(1,24,0,LOG:13)
Block(1,24,4,LEAVES:1)
Block(1,24,5,LEAVES:1)
Block(1,25,-4,LEAVES:1)
Block(1,25,-3,LEAVES:1)
Block(1,25,-2,LEAVES:1)
Block(1,25,-1,LOG:13)
Block(1,25,0,LOG:13)
Block(1,25,1,LOG:13)
Block(1,25,2,LEAVES:1)
Block(1,25,3,LEAVES:1)
Block(1,25,4,LEAVES:1)
Block(1,26,-2,LEAVES:1)
Block(1,26,-1,LEAVES:1)
Block(1,26,0,LOG:13)
Block(1,26,1,LEAVES:1)
Block(1,26,2,LEAVES:1)
Block(1,27,0,LOG:13)
Block(1,28,-6,LEAVES:1)
Block(1,28,-5,LEAVES:1)
Block(1,28,-4,LEAVES:1)
Block(1,28,0,LOG:13)
Block(1,28,4,LEAVES:1)
Block(1,28,5,LEAVES:1)
Block(1,28,6,LEAVES:1)
Block(1,29,-3,LEAVES:1)
Block(1,29,-2,LEAVES:1)
Block(1,29,-1,LOG:13)
Block(1,29,0,LOG:13)
Block(1,29,1,LOG:13)
Block(1,29,2,LEAVES:1)
Block(1,29,3,LEAVES:1)
Block(1,30,-1,LEAVES:1)
Block(1,30,0,LOG:13)
Block(1,30,1,LEAVES:1)
Block(1,31,0,LOG:13)
Block(1,32,-5,LEAVES:1)
Block(1,32,-4,LEAVES:1)
Block(1,32,0,LOG:13)
Block(1,32,4,LEAVES:1)
Block(1,32,5,LEAVES:1)
Block(1,33,-3,LEAVES:1)
Block(1,33,-2,LEAVES:1)
Block(1,33,-1,LOG:13)
Block(1,33,0,LOG:13)
Block(1,33,1,LOG:13)
Block(1,33,2,LEAVES:1)
Block(1,33,3,LEAVES:1)
Block(1,34,-1,LEAVES:1)
Block(1,34,0,LOG:13)
Block(1,34,1,LEAVES:1)
Block(1,35,0,LOG:13)
Block(1,36,-4,LEAVES:1)
Block(1,36,0,LOG:13)
Block(1,36,4,LEAVES:1)
Block(1,37,-3,LEAVES:1)
Block(1,37,-2,LEAVES:1)
Block(1,37,-1,LOG:13)
Block(1,37,0,LOG:13)
Block(1,37,1,LOG:13)
Block(1,37,2,LEAVES:1)
Block(1,37,3,LEAVES:1)
Block(1,38,-1,LEAVES:1)
Block(1,38,0,LOG:13)
Block(1,38,1,LEAVES:1)
Block(1,39,0,LOG:13)
Block(1,40,-3,LEAVES:1)
Block(1,40,0,LOG:13)
Block(1,40,3,LEAVES:1)
Block(1,41,-2,LEAVES:1)
Block(1,41,-1,LOG:13)
Block(1,41,0,LOG:13)
Block(1,41,1,LOG:13)
Block(1,41,2,LEAVES:1)
Block(1,42,-1,LEAVES:1)
Block(1,42,0,LOG:13)
Block(1,42,1,LEAVES:1)
Block(1,43,0,LOG:13)
Block(1,44,-1,LEAVES:1)
Block(1,44,0,LOG:13)
Block(1,44,1,LEAVES:1)
Block(1,45,0,LEAVES:1)
Block(2,0,0,LOG:13)
Block(2,1,0,LOG:13)
Block(2,2,0,LOG:13)
Block(2,3,0,LOG:13)
Block(2,4,0,LOG:13)
Block(2,5,0,LOG:13)
Block(2,6,0,LOG:13)
Block(2,7,0,LOG:13)
Block(2,8,-1,LEAVES:1)
Block(2,8,0,LOG:13)
Block(2,8,1,LEAVES:1)
Block(2,9,0,LEAVES:1)
Block(2,13,-3,LEAVES:1)
Block(2,13,-2,LOG:13)
Block(2,13,-1,LEAVES:1)
Block(2,13,0,LOG:13)
Block(2,13,1,LEAVES:1)
Block(2,13,2,LOG:13)
Block(2,13,3,LEAVES:1)
Block(2,14,-2,LEAVES:1)
Block(2,14,0,LEAVES:1)
Block(2,14,2,LEAVES:1)
Block(2,17,-4,LEAVES:1)
Block(2,17,-3,LEAVES:1)
Block(2,17,-2,LOG:13)
Block(2,17,-1,LEAVES:1)
Block(2,17,0,LOG:13)
Block(2,17,1,LEAVES:1)
Block(2,17,2,LOG:13)
Block(2,17,3,LEAVES:1)
Block(2,17,4,LEAVES:1)
Block(2,18,-2,LEAVES:1)
Block(2,18,-1,LEAVES:1)
Block(2,18,0,LEAVES:1)
Block(2,18,1,LEAVES:1)
Block(2,18,2,LEAVES:1)
Block(2,21,-4,LEAVES:1)
Block(2,21,-3,LEAVES:1)
Block(2,21,-2,LOG:13)
Block(2,21,-1,LEAVES:1)
Block(2,21,0,LOG:13)
Block(2,21,1,LEAVES:1)
Block(2,21,2,LOG:13)
Block(2,21,3,LEAVES:1)
Block(2,21,4,LEAVES:1)
Block(2,22,-2,LEAVES:1)
Block(2,22,-1,LEAVES:1)
Block(2,22,0,LEAVES:1)
Block(2,22,1,LEAVES:1)
Block(2,22,2,LEAVES:1)
Block(2,25,-4,LEAVES:1)
Block(2,25,-3,LEAVES:1)
Block(2,25,-2,LOG:13)
Block(2,25,-1,LEAVES:1)
Block(2,25,0,LOG:13)
Block(2,25,1,LEAVES:1)
Block(2,25,2,LOG:13)
Block(2,25,3,LEAVES:1)
Block(2,25,4,LEAVES:1)
Block(2,26,-2,LEAVES:1)
Block(2,26,-1,LEAVES:1)
Block(2,26,0,LEAVES:1)
Block(2,26,1,LEAVES:1)
Block(2,26,2,LEAVES:1)
Block(2,29,-3,LEAVES:1)
Block(2,29,-2,LOG:13)
Block(2,29,-1,LEAVES:1)
Block(2,29,0,LOG:13)
Block(2,29,1,LEAVES:1)
Block(2,29,2,LOG:13)
Block(2,29,3,LEAVES:1)
Block(2,30,-2,LEAVES:1)
Block(2,30,0,LEAVES:1)
Block(2,30,2,LEAVES:1)
Block(2,33,-3,LEAVES:1)
Block(2,33,-2,LOG:13)
Block(2,33,-1,LEAVES:1)
Block(2,33,0,LOG:13)
Block(2,33,1,LEAVES:1)
Block(2,33,2,LOG:13)
Block(2,33,3,LEAVES:1)
Block(2,34,-2,LEAVES:1)
Block(2,34,0,LEAVES:1)
Block(2,34,2,LEAVES:1)
Block(2,37,-3,LEAVES:1)
Block(2,37,-2,LOG:13)
Block(2,37,-1,LEAVES:1)
Block(2,37,0,LOG:13)
Block(2,37,1,LEAVES:1)
Block(2,37,2,LOG:13)
Block(2,37,3,LEAVES:1)
Block(2,38,-2,LEAVES:1)
Block(2,38,0,LEAVES:1)
Block(2,38,2,LEAVES:1)
Block(2,40,-3,LEAVES:1)
Block(2,40,-2,LEAVES:1)
Block(2,40,2,LEAVES:1)
Block(2,40,3,LEAVES:1)
Block(2,41,-1,LEAVES:1)
Block(2,41,0,LOG:13)
Block(2,41,1,LEAVES:1)
Block(2,42,0,LEAVES:1)
Block(2,44,0,LEAVES:1)
Block(3,7,0,LEAVES:1)
Block(3,8,-1,LEAVES:1)
Block(3,8,0,LOG:13)
Block(3,8,1,LEAVES:1)
Block(3,9,0,LEAVES:1)
Block(3,12,-4,LEAVES:1)
Block(3,12,-3,LOG:13)
Block(3,12,3,LOG:13)
Block(3,12,4,LEAVES:1)
Block(3,13,-3,LEAVES:1)
Block(3,13,-2,LEAVES:1)
Block(3,13,-1,LEAVES:1)
Block(3,13,0,LOG:13)
Block(3,13,1,LEAVES:1)
Block(3,13,2,LEAVES:1)
Block(3,13,3,LEAVES:1)
Block(3,14,0,LEAVES:1)
Block(3,16,-4,LEAVES:1)
Block(3,16,-3,LOG:13)
Block(3,16,3,LOG:13)
Block(3,16,4,LEAVES:1)
Block(3,17,-3,LEAVES:1)
Block(3,17,-2,LEAVES:1)
Block(3,17,-1,LEAVES:1)
Block(3,17,0,LOG:13)
Block(3,17,1,LEAVES:1)
Block(3,17,2,LEAVES:1)
Block(3,17,3,LEAVES:1)
Block(3,18,-3,LEAVES:1)
Block(3,18,0,LEAVES:1)
Block(3,18,3,LEAVES:1)
Block(3,20,-4,LEAVES:1)
Block(3,20,-3,LOG:13)
Block(3,20,3,LOG:13)
Block(3,20,4,LEAVES:1)
Block(3,21,-3,LEAVES:1)
Block(3,21,-2,LEAVES:1)
Block(3,21,-1,LEAVES:1)
Block(3,21,0,LOG:13)
Block(3,21,1,LEAVES:1)
Block(3,21,2,LEAVES:1)
Block(3,21,3,LEAVES:1)
Block(3,22,-3,LEAVES:1)
Block(3,22,0,LEAVES:1)
Block(3,22,3,LEAVES:1)
Block(3,24,-4,LEAVES:1)
Block(3,24,-3,LOG:13)
Block(3,24,3,LOG:13)
Block(3,24,4,LEAVES:1)
Block(3,25,-3,LEAVES:1)
Block(3,25,-2,LEAVES:1)
Block(3,25,-1,LEAVES:1)
Block(3,25,0,LOG:13)
Block(3,25,1,LEAVES:1)
Block(3,25,2,LEAVES:1)
Block(3,25,3,LEAVES:1)
Block(3,26,-3,LEAVES:1)
Block(3,26,0,LEAVES:1)
Block(3,26,3,LEAVES:1)
Block(3,28,-4,LEAVES:1)
Block(3,28,-3,LOG:13)
Block(3,28,3,LOG:13)
Block(3,28,4,LEAVES:1)
Block(3,29,-3,LEAVES:1)
Block(3,29,-2,LEAVES:1)
Block(3,29,-1,LEAVES:1)
Block(3,29,0,LOG:13)
Block(3,29,1,LEAVES:1)
Block(3,29,2,LEAVES:1)
Block(3,29,3,LEAVES:1)
Block(3,30,0,LEAVES:1)
Block(3,32,-4,LEAVES:1)
Block(3,32,-3,LOG:13)
Block(3,32,3,LOG:13)
Block(3,32,4,LEAVES:1)
Block(3,33,-3,LEAVES:1)
Block(3,33,-2,LEAVES:1)
Block(3,33,-1,LEAVES:1)
Block(3,33,0,LOG:13)
Block(3,33,1,LEAVES:1)
Block(3,33,2,LEAVES:1)
Block(3,33,3,LEAVES:1)
Block(3,34,0,LEAVES:1)
Block(3,36,-4,LEAVES:1)
Block(3,36,-3,LOG:13)
Block(3,36,3,LOG:13)
Block(3,36,4,LEAVES:1)
Block(3,37,-3,LEAVES:1)
Block(3,37,-2,LEAVES:1)
Block(3,37,-1,LEAVES:1)
Block(3,37,0,LOG:13)
Block(3,37,1,LEAVES:1)
Block(3,37,2,LEAVES:1)
Block(3,37,3,LEAVES:1)
Block(3,38,0,LEAVES:1)
Block(3,40,-2,LEAVES:1)
Block(3,40,-1,LEAVES:1)
Block(3,40,0,LOG:13)
Block(3,40,1,LEAVES:1)
Block(3,40,2,LEAVES:1)
Block(3,41,0,LEAVES:1)
Block(4,7,0,LEAVES:1)
Block(4,8,0,LEAVES:1)
Block(4,12,-5,LEAVES:1)
Block(4,12,-4,LOG:13)
Block(4,12,-3,LEAVES:1)
Block(4,12,-1,LEAVES:1)
Block(4,12,0,LOG:13)
Block(4,12,1,LEAVES:1)
Block(4,12,3,LEAVES:1)
Block(4,12,4,LOG:13)
Block(4,12,5,LEAVES:1)
Block(4,13,-4,LEAVES:1)
Block(4,13,0,LEAVES:1)
Block(4,13,4,LEAVES:1)
Block(4,16,-5,LEAVES:1)
Block(4,16,-4,LOG:13)
Block(4,16,-3,LEAVES:1)
Block(4,16,-1,LEAVES:1)
Block(4,16,0,LOG:13)
Block(4,16,1,LEAVES:1)
Block(4,16,3,LEAVES:1)
Block(4,16,4,LOG:13)
Block(4,16,5,LEAVES:1)
Block(4,17,-4,LEAVES:1)
Block(4,17,-2,LEAVES:1)
Block(4,17,-1,LEAVES:1)
Block(4,17,0,LEAVES:1)
Block(4,17,1,LEAVES:1)
Block(4,17,2,LEAVES:1)
Block(4,17,4,LEAVES:1)
Block(4,20,-5,LEAVES:1)
Block(4,20,-4,LOG:13)
Block(4,20,-3,LEAVES:1)
Block(4,20,-1,LEAVES:1)
Block(4,20,0,LOG:13)
Block(4,20,1,LEAVES:1)
Block(4,20,3,LEAVES:1)
Block(4,20,4,LOG:13)
Block(4,20,5,LEAVES:1)
Block(4,21,-4,LEAVES:1)
Block(4,21,-2,LEAVES:1)
Block(4,21,-1,LEAVES:1)
Block(4,21,0,LEAVES:1)
Block(4,21,1,LEAVES:1)
Block(4,21,2,LEAVES:1)
Block(4,21,4,LEAVES:1)
Block(4,24,-5,LEAVES:1)
Block(4,24,-4,LOG:13)
Block(4,24,-3,LEAVES:1)
Block(4,24,-1,LEAVES:1)
Block(4,24,0,LOG:13)
Block(4,24,1,LEAVES:1)
Block(4,24,3,LEAVES:1)
Block(4,24,4,LOG:13)
Block(4,24,5,LEAVES:1)
Block(4,25,-4,LEAVES:1)
Block(4,25,-2,LEAVES:1)
Block(4,25,-1,LEAVES:1)
Block(4,25,0,LEAVES:1)
Block(4,25,1,LEAVES:1)
Block(4,25,2,LEAVES:1)
Block(4,25,4,LEAVES:1)
Block(4,28,-5,LEAVES:1)
Block(4,28,-4,LOG:13)
Block(4,28,-3,LEAVES:1)
Block(4,28,-1,LEAVES:1)
Block(4,28,0,LOG:13)
Block(4,28,1,LEAVES:1)
Block(4,28,3,LEAVES:1)
Block(4,28,4,LOG:13)
Block(4,28,5,LEAVES:1)
Block(4,29,-4,LEAVES:1)
Block(4,29,0,LEAVES:1)
Block(4,29,4,LEAVES:1)
Block(4,32,-5,LEAVES:1)
Block(4,32,-4,LOG:13)
Block(4,32,-3,LEAVES:1)
Block(4,32,-1,LEAVES:1)
Block(4,32,0,LOG:13)
Block(4,32,1,LEAVES:1)
Block(4,32,3,LEAVES:1)
Block(4,32,4,LOG:13)
Block(4,32,5,LEAVES:1)
Block(4,33,-4,LEAVES:1)
Block(4,33,0,LEAVES:1)
Block(4,33,4,LEAVES:1)
Block(4,36,-3,LEAVES:1)
Block(4,36,-1,LEAVES:1)
Block(4,36,0,LOG:13)
Block(4,36,1,LEAVES:1)
Block(4,36,3,LEAVES:1)
Block(4,37,0,LEAVES:1)
Block(4,40,0,LEAVES:1)
Block(5,12,-5,LEAVES:1)
Block(5,12,-4,LEAVES:1)
Block(5,12,-1,LEAVES:1)
Block(5,12,0,LOG:13)
Block(5,12,1,LEAVES:1)
Block(5,12,4,LEAVES:1)
Block(5,12,5,LEAVES:1)
Block(5,13,0,LEAVES:1)
Block(5,15,-6,LEAVES:1)
Block(5,15,-5,LOG:13)
Block(5,15,5,LOG:13)
Block(5,15,6,LEAVES:1)
Block(5,16,-5,LEAVES:1)
Block(5,16,-4,LEAVES:1)
Block(5,16,-1,LEAVES:1)
Block(5,16,0,LOG:13)
Block(5,16,1,LEAVES:1)
Block(5,16,4,LEAVES:1)
Block(5,16,5,LEAVES:1)
Block(5,17,0,LEAVES:1)
Block(5,19,-6,LEAVES:1)
Block(5,19,-5,LOG:13)
Block(5,19,5,LOG:13)
Block(5,19,6,LEAVES:1)
Block(5,20,-5,LEAVES:1)
Block(5,20,-4,LEAVES:1)
Block(5,20,-1,LEAVES:1)
Block(5,20,0,LOG:13)
Block(5,20,1,LEAVES:1)
Block(5,20,4,LEAVES:1)
Block(5,20,5,LEAVES:1)
Block(5,21,0,LEAVES:1)
Block(5,23,-6,LEAVES:1)
Block(5,23,-5,LOG:13)
Block(5,23,5,LOG:13)
Block(5,23,6,LEAVES:1)
Block(5,24,-5,LEAVES:1)
Block(5,24,-4,LEAVES:1)
Block(5,24,-1,LEAVES:1)
Block(5,24,0,LOG:13)
Block(5,24,1,LEAVES:1)
Block(5,24,4,LEAVES:1)
Block(5,24,5,LEAVES:1)
Block(5,25,0,LEAVES:1)
Block(5,28,-6,LEAVES:1)
Block(5,28,-5,LOG:13)
Block(5,28,-4,LEAVES:1)
Block(5,28,-1,LEAVES:1)
Block(5,28,0,LOG:13)
Block(5,28,1,LEAVES:1)
Block(5,28,4,LEAVES:1)
Block(5,28,5,LOG:13)
Block(5,28,6,LEAVES:1)
Block(5,29,-5,LEAVES:1)
Block(5,29,0,LEAVES:1)
Block(5,29,5,LEAVES:1)
Block(5,32,-5,LEAVES:1)
Block(5,32,-4,LEAVES:1)
Block(5,32,-1,LEAVES:1)
Block(5,32,0,LOG:13)
Block(5,32,1,LEAVES:1)
Block(5,32,4,LEAVES:1)
Block(5,32,5,LEAVES:1)
Block(5,33,0,LEAVES:1)
Block(5,36,0,LEAVES:1)
Block(6,12,0,LEAVES:1)
Block(6,15,-7,LEAVES:1)
Block(6,15,-6,LOG:13)
Block(6,15,-5,LEAVES:1)
Block(6,15,-1,LEAVES:1)
Block(6,15,0,LOG:13)
Block(6,15,1,LEAVES:1)
Block(6,15,5,LEAVES:1)
Block(6,15,6,LOG:13)
Block(6,15,7,LEAVES:1)
Block(6,16,-6,LEAVES:1)
Block(6,16,0,LEAVES:1)
Block(6,16,6,LEAVES:1)
Block(6,19,-7,LEAVES:1)
Block(6,19,-6,LOG:13)
Block(6,19,-5,LEAVES:1)
Block(6,19,-1,LEAVES:1)
Block(6,19,0,LOG:13)
Block(6,19,1,LEAVES:1)
Block(6,19,5,LEAVES:1)
Block(6,19,6,LOG:13)
Block(6,19,7,LEAVES:1)
Block(6,20,-6,LEAVES:1)
Block(6,20,0,LEAVES:1)
Block(6,20,6,LEAVES:1)
Block(6,23,-7,LEAVES:1)
Block(6,23,-6,LOG:13)
Block(6,23,-5,LEAVES:1)
Block(6,23,-1,LEAVES:1)
Block(6,23,0,LOG:13)
Block(6,23,1,LEAVES:1)
Block(6,23,5,LEAVES:1)
Block(6,23,6,LOG:13)
Block(6,23,7,LEAVES:1)
Block(6,24,-6,LEAVES:1)
Block(6,24,0,LEAVES:1)
Block(6,24,6,LEAVES:1)
Block(6,28,-6,LEAVES:1)
Block(6,28,-5,LEAVES:1)
Block(6,28,-1,LEAVES:1)
Block(6,28,0,LOG:13)
Block(6,28,1,LEAVES:1)
Block(6,28,5,LEAVES:1)
Block(6,28,6,LEAVES:1)
Block(6,29,0,LEAVES:1)
Block(6,32,0,LEAVES:1)
Block(7,15,-7,LEAVES:1)
Block(7,15,-6,LEAVES:1)
Block(7,15,-1,LEAVES:1)
Block(7,15,0,LOG:13)
Block(7,15,1,LEAVES:1)
Block(7,15,6,LEAVES:1)
Block(7,15,7,LEAVES:1)
Block(7,16,0,LEAVES:1)
Block(7,19,-7,LEAVES:1)
Block(7,19,-6,LEAVES:1)
Block(7,19,-1,LEAVES:1)
Block(7,19,0,LOG:13)
Block(7,19,1,LEAVES:1)
Block(7,19,6,LEAVES:1)
Block(7,19,7,LEAVES:1)
Block(7,20,0,LEAVES:1)
Block(7,23,-7,LEAVES:1)
Block(7,23,-6,LEAVES:1)
Block(7,23,-1,LEAVES:1)
Block(7,23,0,LOG:13)
Block(7,23,1,LEAVES:1)
Block(7,23,6,LEAVES:1)
Block(7,23,7,LEAVES:1)
Block(7,24,0,LEAVES:1)
Block(7,28,0,LEAVES:1)
Block(8,15,0,LEAVES:1)
Block(8,19,0,LEAVES:1)
Block(8,23,0,LEAVES:1)


#######################################################################
# +-----------------------------------------------------------------+ #
# |                             Entities                            | #
# +-----------------------------------------------------------------+ #
#######################################################################

# Entity() spawns an entity instead of a block. The entity is spawned only once when the BO3 is spawned.
# Entities are persistent by default so they don't de-spawn when no player is near, they are only unloaded.
# Usage: Entity(x,y,z,mobName,groupSize,NameTagOrNBTFileName) or Entity(x,y,z,mobName,groupSize)
# Use /tc entities or /otg entities to get a list of entities that can be used as mobName, this includes entities added by other mods.
# NameTagOrNBTFileName can be either a nametag for the mob or an nbt file (such as mymobinfo.nbt or mymobinfo.txt).
# When using a text file you can use the same mob spawning parameters used with the /summon command to equip the
# entity and give it custom attributes etc. You can copy the DATA part of a summon command including surrounding
# curly braces to a .txt file, for instance for: "/summon Skeleton x y z {DATA}"

#######################################################################
# +-----------------------------------------------------------------+ #
# |                            BO3 checks                           | #
# +-----------------------------------------------------------------+ #
#######################################################################

# Require a condition at a certain location in order for the BO3 to be spawned.
# BlockCheck(x,y,z,BlockName[,BlockName[,...]]) - one of the blocks must be at the location
# BlockCheckNot(x,y,z,BlockName[,BlockName[,...]]) - all the blocks must not be at the location
# LightCheck(x,y,z,minLightLevel,maxLightLevel) - light must be between min and max (inclusive)

# You can use "Solid" as a BlockName for matching all solid blocks or "All" to match all blocks that aren't air.

# Examples:
#   BlockCheck(0,-1,0,GRASS,DIRT)  Require grass or dirt just below the object
#   BlockCheck(0,-1,0,Solid)       Require any solid block just below the object
#   BlockCheck(0,-1,0,WOOL)        Require any type of wool just below the object
#   BlockCheck(0,-1,0,WOOL:0)      Require white wool just below the object
#   BlockCheckNot(0,-1,0,WOOL:0)   Require that there is no white wool below the object
#   LightCheck(0,0,0,0,LEAVES:1)          Require almost complete darkness just below the object

BlockCheck(0,-1,0,GRASS,DIRT,DIRT:2)