#######################################################################
# +-----------------------------------------------------------------+ #
# |                            BO3 object                           | #
# +-----------------------------------------------------------------+ #
#######################################################################

# The descriptions in this file are accurate only for TerrainControl and OTG.
# For MCW and OTG+ these descriptions are only accurate if the BO3 is used as a CustomObject.
# MCW and OTG+ completely reimplemented CustomStructure, check the MCW/OTG+ documentation for more information.

# This is the config file of a custom object.
# If you add this object correctly to your BiomeConfigs, it will spawn in the world.

# This is the creator of this BO3 object
Author: Unknown

# A short description of this BO3 object
Description: This BO3 was converted from a schematic using OTGEdit. The author and description information of the schematic could not be found. If you know who the author of the schematic is then please add this information.

# The BO3 version, don't change this! It can be used by external applications to do a version check.
Version: 3

# The settings mode, WriteAll, WriteWithoutComments or WriteDisable. See WorldConfig.
SettingsMode: WriteDisable

#######################################################################
# +-----------------------------------------------------------------+ #
# |                          Main settings                          | #
# +-----------------------------------------------------------------+ #
#######################################################################

Tree: true

Frequency: 1

Rarity: 10.0

RotateRandomly: true

SpawnHeight: highestSolidBlock

SpawnHeightOffset: 0

SpawnHeightVariance: 0

##############################
# Height Limits for the BO3. #
##############################

MinHeight: 63

MaxHeight: 110

######################
# Extrusion settings #
######################

ExtrudeMode: BottomDown

ExtrudeThroughBlocks: AIR

MaxBranchDepth: 10

ExcludedBiomes: All


#######################################################################
# +-----------------------------------------------------------------+ #
# |                      Source block settings                      | #
# +-----------------------------------------------------------------+ #
#######################################################################

SourceBlocks: STONE:1,STONE:3,STONE:5,DIRT:1,DIRT,SAND,GRASS,DIRT:2,STATIONARY_WATER,HARD_CLAY,STAINED_CLAY,CLAY,SANDSTONE,SAND:1,AIR,STONE,GRAVEL,LONG_GRASS,LONG_GRASS:1,LONG_GRASS:2,DEAD_BUSH,YELLOW_FLOWER,RED_ROSE,BROWN_MUSHROOM,RED_MUSHROOM

MaxPercentageOutsideSourceBlock: 0

OutsideSourceBlock: placeAnyway

#######################################################################
# +-----------------------------------------------------------------+ #
# |                              Blocks                             | #
# +-----------------------------------------------------------------+ #
#######################################################################

# All the blocks used in the BO3 are listed here. Possible blocks:
# Block(x,y,z,id[.data][,nbtfile.nbt) or B(x,y,z,id[.data][,nbtfile.nbt)
# RandomBlock(x,y,z,id[:data][,nbtfile.nbt],chance[,id[:data][,nbtfile.nbt],chance[,...]])
# So RandomBlock(0,0,0,CHEST,chest.nbt,50,CHEST,anotherchest.nbt,100) will spawn a chest at
# the BO3 origin, and give it a 50% chance to have the contents of chest.nbt, or, if that
# fails, a 100% percent chance to have the contents of anotherchest.nbt.

Block(-6,14,0,LEAVES:1)
Block(-6,18,0,LEAVES:1)
Block(-5,14,-5,LEAVES:1)
Block(-5,14,-4,LEAVES:1)
Block(-5,14,-1,LEAVES:1)
Block(-5,14,0,LOG:13)
Block(-5,14,1,LEAVES:1)
Block(-5,14,4,LEAVES:1)
Block(-5,14,5,LEAVES:1)
Block(-5,15,0,LEAVES:1)
Block(-5,18,-5,LEAVES:1)
Block(-5,18,-4,LEAVES:1)
Block(-5,18,-1,LEAVES:1)
Block(-5,18,0,LOG:13)
Block(-5,18,1,LEAVES:1)
Block(-5,18,4,LEAVES:1)
Block(-5,18,5,LEAVES:1)
Block(-5,19,0,LEAVES:1)
Block(-5,22,0,LEAVES:1)
Block(-4,10,0,LEAVES:1)
Block(-4,11,0,LEAVES:1)
Block(-4,14,-5,LEAVES:1)
Block(-4,14,-4,LOG:13)
Block(-4,14,-3,LEAVES:1)
Block(-4,14,-1,LEAVES:1)
Block(-4,14,0,LOG:13)
Block(-4,14,1,LEAVES:1)
Block(-4,14,3,LEAVES:1)
Block(-4,14,4,LOG:13)
Block(-4,14,5,LEAVES:1)
Block(-4,15,-4,LEAVES:1)
Block(-4,15,0,LEAVES:1)
Block(-4,15,4,LEAVES:1)
Block(-4,18,-5,LEAVES:1)
Block(-4,18,-4,LOG:13)
Block(-4,18,-3,LEAVES:1)
Block(-4,18,-1,LEAVES:1)
Block(-4,18,0,LOG:13)
Block(-4,18,1,LEAVES:1)
Block(-4,18,3,LEAVES:1)
Block(-4,18,4,LOG:13)
Block(-4,18,5,LEAVES:1)
Block(-4,19,-4,LEAVES:1)
Block(-4,19,0,LEAVES:1)
Block(-4,19,4,LEAVES:1)
Block(-4,22,-3,LEAVES:1)
Block(-4,22,-1,LEAVES:1)
Block(-4,22,0,LOG:13)
Block(-4,22,1,LEAVES:1)
Block(-4,22,3,LEAVES:1)
Block(-4,23,0,LEAVES:1)
Block(-4,26,0,LEAVES:1)
Block(-3,10,0,LEAVES:1)
Block(-3,11,-1,LEAVES:1)
Block(-3,11,0,LOG:13)
Block(-3,11,1,LEAVES:1)
Block(-3,12,0,LEAVES:1)
Block(-3,14,-4,LEAVES:1)
Block(-3,14,-3,LOG:13)
Block(-3,14,3,LOG:13)
Block(-3,14,4,LEAVES:1)
Block(-3,15,-3,LEAVES:1)
Block(-3,15,-2,LEAVES:1)
Block(-3,15,-1,LEAVES:1)
Block(-3,15,0,LOG:13)
Block(-3,15,1,LEAVES:1)
Block(-3,15,2,LEAVES:1)
Block(-3,15,3,LEAVES:1)
Block(-3,16,0,LEAVES:1)
Block(-3,18,-4,LEAVES:1)
Block(-3,18,-3,LOG:13)
Block(-3,18,3,LOG:13)
Block(-3,18,4,LEAVES:1)
Block(-3,19,-3,LEAVES:1)
Block(-3,19,-2,LEAVES:1)
Block(-3,19,-1,LEAVES:1)
Block(-3,19,0,LOG:13)
Block(-3,19,1,LEAVES:1)
Block(-3,19,2,LEAVES:1)
Block(-3,19,3,LEAVES:1)
Block(-3,20,0,LEAVES:1)
Block(-3,22,-4,LEAVES:1)
Block(-3,22,-3,LOG:13)
Block(-3,22,3,LOG:13)
Block(-3,22,4,LEAVES:1)
Block(-3,23,-3,LEAVES:1)
Block(-3,23,-2,LEAVES:1)
Block(-3,23,-1,LEAVES:1)
Block(-3,23,0,LOG:13)
Block(-3,23,1,LEAVES:1)
Block(-3,23,2,LEAVES:1)
Block(-3,23,3,LEAVES:1)
Block(-3,24,0,LEAVES:1)
Block(-3,26,-2,LEAVES:1)
Block(-3,26,-1,LEAVES:1)
Block(-3,26,0,LOG:13)
Block(-3,26,1,LEAVES:1)
Block(-3,26,2,LEAVES:1)
Block(-3,27,0,LEAVES:1)
Block(-2,6,-3,LEAVES:1)
Block(-2,6,-2,LEAVES:1)
Block(-2,10,0,LEAVES:1)
Block(-2,11,-1,LEAVES:1)
Block(-2,11,0,LOG:13)
Block(-2,11,1,LEAVES:1)
Block(-2,12,0,LEAVES:1)
Block(-2,15,-3,LEAVES:1)
Block(-2,15,-2,LOG:13)
Block(-2,15,-1,LEAVES:1)
Block(-2,15,0,LOG:13)
Block(-2,15,1,LEAVES:1)
Block(-2,15,2,LOG:13)
Block(-2,15,3,LEAVES:1)
Block(-2,16,-2,LEAVES:1)
Block(-2,16,0,LEAVES:1)
Block(-2,16,2,LEAVES:1)
Block(-2,19,-3,LEAVES:1)
Block(-2,19,-2,LOG:13)
Block(-2,19,-1,LEAVES:1)
Block(-2,19,0,LOG:13)
Block(-2,19,1,LEAVES:1)
Block(-2,19,2,LOG:13)
Block(-2,19,3,LEAVES:1)
Block(-2,20,-2,LEAVES:1)
Block(-2,20,0,LEAVES:1)
Block(-2,20,2,LEAVES:1)
Block(-2,23,-3,LEAVES:1)
Block(-2,23,-2,LOG:13)
Block(-2,23,-1,LEAVES:1)
Block(-2,23,0,LOG:13)
Block(-2,23,1,LEAVES:1)
Block(-2,23,2,LOG:13)
Block(-2,23,3,LEAVES:1)
Block(-2,24,-2,LEAVES:1)
Block(-2,24,0,LEAVES:1)
Block(-2,24,2,LEAVES:1)
Block(-2,26,-3,LEAVES:1)
Block(-2,26,-2,LEAVES:1)
Block(-2,26,2,LEAVES:1)
Block(-2,26,3,LEAVES:1)
Block(-2,27,-1,LEAVES:1)
Block(-2,27,0,LOG:13)
Block(-2,27,1,LEAVES:1)
Block(-2,28,0,LEAVES:1)
Block(-2,30,0,LEAVES:1)
Block(-1,0,-1,LOG:13)
Block(-1,0,0,LOG:13)
Block(-1,0,1,LOG:13)
Block(-1,1,-1,LOG:13)
Block(-1,1,0,LOG:13)
Block(-1,1,1,LOG:13)
Block(-1,2,-1,LOG:13)
Block(-1,2,0,LOG:13)
Block(-1,2,1,LOG:13)
Block(-1,3,-1,LOG:13)
Block(-1,3,0,LOG:13)
Block(-1,3,1,LOG:13)
Block(-1,4,-1,LOG:13)
Block(-1,4,0,LOG:13)
Block(-1,4,1,LOG:13)
Block(-1,5,-4,LEAVES:1)
Block(-1,5,-3,LEAVES:1)
Block(-1,5,-2,LEAVES:1)
Block(-1,5,-1,LOG:13)
Block(-1,5,0,LOG:13)
Block(-1,5,1,LOG:13)
Block(-1,6,-4,LEAVES:1)
Block(-1,6,-3,LOG:13)
Block(-1,6,-2,LOG:13)
Block(-1,6,-1,LOG:13)
Block(-1,6,0,LOG:13)
Block(-1,6,1,LOG:13)
Block(-1,7,-3,LEAVES:1)
Block(-1,7,-2,LEAVES:1)
Block(-1,7,-1,LOG:13)
Block(-1,7,0,LOG:13)
Block(-1,7,1,LOG:13)
Block(-1,8,-1,LOG:13)
Block(-1,8,0,LOG:13)
Block(-1,8,1,LOG:13)
Block(-1,9,-1,LOG:13)
Block(-1,9,0,LOG:13)
Block(-1,9,1,LOG:13)
Block(-1,10,-1,LOG:13)
Block(-1,10,0,LOG:13)
Block(-1,10,1,LOG:13)
Block(-1,10,2,LEAVES:1)
Block(-1,10,3,LEAVES:1)
Block(-1,11,0,LOG:13)
Block(-1,12,0,LOG:13)
Block(-1,13,0,LOG:13)
Block(-1,14,-5,LEAVES:1)
Block(-1,14,-4,LEAVES:1)
Block(-1,14,0,LOG:13)
Block(-1,14,4,LEAVES:1)
Block(-1,14,5,LEAVES:1)
Block(-1,15,-3,LEAVES:1)
Block(-1,15,-2,LEAVES:1)
Block(-1,15,-1,LOG:13)
Block(-1,15,0,LOG:13)
Block(-1,15,1,LOG:13)
Block(-1,15,2,LEAVES:1)
Block(-1,15,3,LEAVES:1)
Block(-1,16,-1,LEAVES:1)
Block(-1,16,0,LOG:13)
Block(-1,16,1,LEAVES:1)
Block(-1,17,0,LOG:13)
Block(-1,18,-5,LEAVES:1)
Block(-1,18,-4,LEAVES:1)
Block(-1,18,0,LOG:13)
Block(-1,18,4,LEAVES:1)
Block(-1,18,5,LEAVES:1)
Block(-1,19,-3,LEAVES:1)
Block(-1,19,-2,LEAVES:1)
Block(-1,19,-1,LOG:13)
Block(-1,19,0,LOG:13)
Block(-1,19,1,LOG:13)
Block(-1,19,2,LEAVES:1)
Block(-1,19,3,LEAVES:1)
Block(-1,20,-1,LEAVES:1)
Block(-1,20,0,LOG:13)
Block(-1,20,1,LEAVES:1)
Block(-1,21,0,LOG:13)
Block(-1,22,-4,LEAVES:1)
Block(-1,22,0,LOG:13)
Block(-1,22,4,LEAVES:1)
Block(-1,23,-3,LEAVES:1)
Block(-1,23,-2,LEAVES:1)
Block(-1,23,-1,LOG:13)
Block(-1,23,0,LOG:13)
Block(-1,23,1,LOG:13)
Block(-1,23,2,LEAVES:1)
Block(-1,23,3,LEAVES:1)
Block(-1,24,-1,LEAVES:1)
Block(-1,24,0,LOG:13)
Block(-1,24,1,LEAVES:1)
Block(-1,25,0,LOG:13)
Block(-1,26,-3,LEAVES:1)
Block(-1,26,0,LOG:13)
Block(-1,26,3,LEAVES:1)
Block(-1,27,-2,LEAVES:1)
Block(-1,27,-1,LOG:13)
Block(-1,27,0,LOG:13)
Block(-1,27,1,LOG:13)
Block(-1,27,2,LEAVES:1)
Block(-1,28,-1,LEAVES:1)
Block(-1,28,0,LOG:13)
Block(-1,28,1,LEAVES:1)
Block(-1,29,0,LOG:13)
Block(-1,30,-1,LEAVES:1)
Block(-1,30,0,LOG:13)
Block(-1,30,1,LEAVES:1)
Block(-1,31,0,LEAVES:1)
Block(0,0,-1,LOG:13)
Block(0,0,0,LOG:13)
Block(0,0,1,LOG:13)
Block(0,1,-1,LOG:13)
Block(0,1,0,LOG:13)
Block(0,1,1,LOG:13)
Block(0,2,-1,LOG:13)
Block(0,2,0,LOG:13)
Block(0,2,1,LOG:13)
Block(0,3,-1,LOG:13)
Block(0,3,0,LOG:13)
Block(0,3,1,LOG:13)
Block(0,4,-1,LOG:13)
Block(0,4,0,LOG:13)
Block(0,4,1,LOG:13)
Block(0,5,-1,LOG:13)
Block(0,5,0,LOG:13)
Block(0,5,1,LOG:13)
Block(0,6,-3,LEAVES:1)
Block(0,6,-2,LEAVES:1)
Block(0,6,-1,LOG:13)
Block(0,6,0,LOG:13)
Block(0,6,1,LOG:13)
Block(0,7,-1,LOG:13)
Block(0,7,0,LOG:13)
Block(0,7,1,LOG:13)
Block(0,8,-1,LOG:13)
Block(0,8,0,LOG:13)
Block(0,8,1,LOG:13)
Block(0,9,-1,LOG:13)
Block(0,9,0,LOG:13)
Block(0,9,1,LOG:13)
Block(0,9,2,LEAVES:1)
Block(0,9,3,LEAVES:1)
Block(0,9,4,LEAVES:1)
Block(0,10,-1,LOG:13)
Block(0,10,0,LOG:13)
Block(0,10,1,LOG:13)
Block(0,10,2,LOG:13)
Block(0,10,3,LOG:13)
Block(0,10,4,LEAVES:1)
Block(0,11,-1,LOG:13)
Block(0,11,0,LOG:13)
Block(0,11,1,LOG:13)
Block(0,11,2,LEAVES:1)
Block(0,11,3,LEAVES:1)
Block(0,12,-1,LOG:13)
Block(0,12,0,LOG:13)
Block(0,12,1,LOG:13)
Block(0,13,-1,LOG:13)
Block(0,13,0,LOG:13)
Block(0,13,1,LOG:13)
Block(0,14,-6,LEAVES:1)
Block(0,14,-5,LOG:13)
Block(0,14,-4,LOG:13)
Block(0,14,-1,LOG:13)
Block(0,14,0,LOG:13)
Block(0,14,1,LOG:13)
Block(0,14,4,LOG:13)
Block(0,14,5,LOG:13)
Block(0,14,6,LEAVES:1)
Block(0,15,-5,LEAVES:1)
Block(0,15,-4,LEAVES:1)
Block(0,15,-3,LOG:13)
Block(0,15,-2,LOG:13)
Block(0,15,-1,LOG:13)
Block(0,15,0,LOG:13)
Block(0,15,1,LOG:13)
Block(0,15,2,LOG:13)
Block(0,15,3,LOG:13)
Block(0,15,4,LEAVES:1)
Block(0,15,5,LEAVES:1)
Block(0,16,-3,LEAVES:1)
Block(0,16,-2,LEAVES:1)
Block(0,16,-1,LOG:13)
Block(0,16,0,LOG:13)
Block(0,16,1,LOG:13)
Block(0,16,2,LEAVES:1)
Block(0,16,3,LEAVES:1)
Block(0,17,-1,LOG:13)
Block(0,17,0,LOG:13)
Block(0,17,1,LOG:13)
Block(0,18,-6,LEAVES:1)
Block(0,18,-5,LOG:13)
Block(0,18,-4,LOG:13)
Block(0,18,-1,LOG:13)
Block(0,18,0,LOG:13)
Block(0,18,1,LOG:13)
Block(0,18,4,LOG:13)
Block(0,18,5,LOG:13)
Block(0,18,6,LEAVES:1)
Block(0,19,-5,LEAVES:1)
Block(0,19,-4,LEAVES:1)
Block(0,19,-3,LOG:13)
Block(0,19,-2,LOG:13)
Block(0,19,-1,LOG:13)
Block(0,19,0,LOG:13)
Block(0,19,1,LOG:13)
Block(0,19,2,LOG:13)
Block(0,19,3,LOG:13)
Block(0,19,4,LEAVES:1)
Block(0,19,5,LEAVES:1)
Block(0,20,-3,LEAVES:1)
Block(0,20,-2,LEAVES:1)
Block(0,20,-1,LOG:13)
Block(0,20,0,LOG:13)
Block(0,20,1,LOG:13)
Block(0,20,2,LEAVES:1)
Block(0,20,3,LEAVES:1)
Block(0,21,-1,LOG:13)
Block(0,21,0,LOG:13)
Block(0,21,1,LOG:13)
Block(0,22,-5,LEAVES:1)
Block(0,22,-4,LOG:13)
Block(0,22,-1,LOG:13)
Block(0,22,0,LOG:13)
Block(0,22,1,LOG:13)
Block(0,22,4,LOG:13)
Block(0,22,5,LEAVES:1)
Block(0,23,-4,LEAVES:1)
Block(0,23,-3,LOG:13)
Block(0,23,-2,LOG:13)
Block(0,23,-1,LOG:13)
Block(0,23,0,LOG:13)
Block(0,23,1,LOG:13)
Block(0,23,2,LOG:13)
Block(0,23,3,LOG:13)
Block(0,23,4,LEAVES:1)
Block(0,24,-3,LEAVES:1)
Block(0,24,-2,LEAVES:1)
Block(0,24,-1,LOG:13)
Block(0,24,0,LOG:13)
Block(0,24,1,LOG:13)
Block(0,24,2,LEAVES:1)
Block(0,24,3,LEAVES:1)
Block(0,25,-1,LOG:13)
Block(0,25,0,LOG:13)
Block(0,25,1,LOG:13)
Block(0,26,-4,LEAVES:1)
Block(0,26,-3,LOG:13)
Block(0,26,-1,LOG:13)
Block(0,26,0,LOG:13)
Block(0,26,1,LOG:13)
Block(0,26,3,LOG:13)
Block(0,26,4,LEAVES:1)
Block(0,27,-3,LEAVES:1)
Block(0,27,-2,LOG:13)
Block(0,27,-1,LOG:13)
Block(0,27,0,LOG:13)
Block(0,27,1,LOG:13)
Block(0,27,2,LOG:13)
Block(0,27,3,LEAVES:1)
Block(0,28,-2,LEAVES:1)
Block(0,28,-1,LOG:13)
Block(0,28,0,LOG:13)
Block(0,28,1,LOG:13)
Block(0,28,2,LEAVES:1)
Block(0,29,-1,LOG:13)
Block(0,29,0,LOG:13)
Block(0,29,1,LOG:13)
Block(0,30,-2,LEAVES:1)
Block(0,30,-1,LOG:13)
Block(0,30,0,LOG:13)
Block(0,30,1,LOG:13)
Block(0,30,2,LEAVES:1)
Block(0,31,-1,LEAVES:1)
Block(0,31,0,LEAVES:1)
Block(0,31,1,LEAVES:1)
Block(0,32,0,LEAVES:1)
Block(1,0,-1,LOG:13)
Block(1,0,0,LOG:13)
Block(1,0,1,LOG:13)
Block(1,1,-1,LOG:13)
Block(1,1,0,LOG:13)
Block(1,1,1,LOG:13)
Block(1,2,-1,LOG:13)
Block(1,2,0,LOG:13)
Block(1,2,1,LOG:13)
Block(1,3,-1,LOG:13)
Block(1,3,0,LOG:13)
Block(1,3,1,LOG:13)
Block(1,4,-1,LOG:13)
Block(1,4,0,LOG:13)
Block(1,4,1,LOG:13)
Block(1,5,-1,LOG:13)
Block(1,5,0,LOG:13)
Block(1,5,1,LOG:13)
Block(1,6,-1,LOG:13)
Block(1,6,0,LOG:13)
Block(1,6,1,LOG:13)
Block(1,7,-1,LOG:13)
Block(1,7,0,LOG:13)
Block(1,7,1,LOG:13)
Block(1,8,-1,LOG:13)
Block(1,8,0,LOG:13)
Block(1,8,1,LOG:13)
Block(1,9,-1,LOG:13)
Block(1,9,0,LOG:13)
Block(1,9,1,LOG:13)
Block(1,10,-1,LOG:13)
Block(1,10,0,LOG:13)
Block(1,10,1,LOG:13)
Block(1,10,2,LEAVES:1)
Block(1,10,3,LEAVES:1)
Block(1,11,0,LOG:13)
Block(1,12,0,LOG:13)
Block(1,13,0,LOG:13)
Block(1,14,-5,LEAVES:1)
Block(1,14,-4,LEAVES:1)
Block(1,14,0,LOG:13)
Block(1,14,4,LEAVES:1)
Block(1,14,5,LEAVES:1)
Block(1,15,-3,LEAVES:1)
Block(1,15,-2,LEAVES:1)
Block(1,15,-1,LOG:13)
Block(1,15,0,LOG:13)
Block(1,15,1,LOG:13)
Block(1,15,2,LEAVES:1)
Block(1,15,3,LEAVES:1)
Block(1,16,-1,LEAVES:1)
Block(1,16,0,LOG:13)
Block(1,16,1,LEAVES:1)
Block(1,17,0,LOG:13)
Block(1,18,-5,LEAVES:1)
Block(1,18,-4,LEAVES:1)
Block(1,18,0,LOG:13)
Block(1,18,4,LEAVES:1)
Block(1,18,5,LEAVES:1)
Block(1,19,-3,LEAVES:1)
Block(1,19,-2,LEAVES:1)
Block(1,19,-1,LOG:13)
Block(1,19,0,LOG:13)
Block(1,19,1,LOG:13)
Block(1,19,2,LEAVES:1)
Block(1,19,3,LEAVES:1)
Block(1,20,-1,LEAVES:1)
Block(1,20,0,LOG:13)
Block(1,20,1,LEAVES:1)
Block(1,21,0,LOG:13)
Block(1,22,-4,LEAVES:1)
Block(1,22,0,LOG:13)
Block(1,22,4,LEAVES:1)
Block(1,23,-3,LEAVES:1)
Block(1,23,-2,LEAVES:1)
Block(1,23,-1,LOG:13)
Block(1,23,0,LOG:13)
Block(1,23,1,LOG:13)
Block(1,23,2,LEAVES:1)
Block(1,23,3,LEAVES:1)
Block(1,24,-1,LEAVES:1)
Block(1,24,0,LOG:13)
Block(1,24,1,LEAVES:1)
Block(1,25,0,LOG:13)
Block(1,26,-3,LEAVES:1)
Block(1,26,0,LOG:13)
Block(1,26,3,LEAVES:1)
Block(1,27,-2,LEAVES:1)
Block(1,27,-1,LOG:13)
Block(1,27,0,LOG:13)
Block(1,27,1,LOG:13)
Block(1,27,2,LEAVES:1)
Block(1,28,-1,LEAVES:1)
Block(1,28,0,LOG:13)
Block(1,28,1,LEAVES:1)
Block(1,29,0,LOG:13)
Block(1,30,-1,LEAVES:1)
Block(1,30,0,LOG:13)
Block(1,30,1,LEAVES:1)
Block(1,31,0,LEAVES:1)
Block(2,8,1,LEAVES:1)
Block(2,9,0,LEAVES:1)
Block(2,9,1,LOG:13)
Block(2,9,2,LEAVES:1)
Block(2,10,1,LEAVES:1)
Block(2,15,-3,LEAVES:1)
Block(2,15,-2,LOG:13)
Block(2,15,-1,LEAVES:1)
Block(2,15,0,LOG:13)
Block(2,15,1,LEAVES:1)
Block(2,15,2,LOG:13)
Block(2,15,3,LEAVES:1)
Block(2,16,-2,LEAVES:1)
Block(2,16,0,LEAVES:1)
Block(2,16,2,LEAVES:1)
Block(2,19,-3,LEAVES:1)
Block(2,19,-2,LOG:13)
Block(2,19,-1,LEAVES:1)
Block(2,19,0,LOG:13)
Block(2,19,1,LEAVES:1)
Block(2,19,2,LOG:13)
Block(2,19,3,LEAVES:1)
Block(2,20,-2,LEAVES:1)
Block(2,20,0,LEAVES:1)
Block(2,20,2,LEAVES:1)
Block(2,23,-3,LEAVES:1)
Block(2,23,-2,LOG:13)
Block(2,23,-1,LEAVES:1)
Block(2,23,0,LOG:13)
Block(2,23,1,LEAVES:1)
Block(2,23,2,LOG:13)
Block(2,23,3,LEAVES:1)
Block(2,24,-2,LEAVES:1)
Block(2,24,0,LEAVES:1)
Block(2,24,2,LEAVES:1)
Block(2,26,-3,LEAVES:1)
Block(2,26,-2,LEAVES:1)
Block(2,26,2,LEAVES:1)
Block(2,26,3,LEAVES:1)
Block(2,27,-1,LEAVES:1)
Block(2,27,0,LOG:13)
Block(2,27,1,LEAVES:1)
Block(2,28,0,LEAVES:1)
Block(2,30,0,LEAVES:1)
Block(3,8,1,LEAVES:1)
Block(3,9,0,LEAVES:1)
Block(3,9,1,LOG:13)
Block(3,9,2,LEAVES:1)
Block(3,10,1,LEAVES:1)
Block(3,14,-4,LEAVES:1)
Block(3,14,-3,LOG:13)
Block(3,14,3,LOG:13)
Block(3,14,4,LEAVES:1)
Block(3,15,-3,LEAVES:1)
Block(3,15,-2,LEAVES:1)
Block(3,15,-1,LEAVES:1)
Block(3,15,0,LOG:13)
Block(3,15,1,LEAVES:1)
Block(3,15,2,LEAVES:1)
Block(3,15,3,LEAVES:1)
Block(3,16,0,LEAVES:1)
Block(3,18,-4,LEAVES:1)
Block(3,18,-3,LOG:13)
Block(3,18,3,LOG:13)
Block(3,18,4,LEAVES:1)
Block(3,19,-3,LEAVES:1)
Block(3,19,-2,LEAVES:1)
Block(3,19,-1,LEAVES:1)
Block(3,19,0,LOG:13)
Block(3,19,1,LEAVES:1)
Block(3,19,2,LEAVES:1)
Block(3,19,3,LEAVES:1)
Block(3,20,0,LEAVES:1)
Block(3,22,-4,LEAVES:1)
Block(3,22,-3,LOG:13)
Block(3,22,3,LOG:13)
Block(3,22,4,LEAVES:1)
Block(3,23,-3,LEAVES:1)
Block(3,23,-2,LEAVES:1)
Block(3,23,-1,LEAVES:1)
Block(3,23,0,LOG:13)
Block(3,23,1,LEAVES:1)
Block(3,23,2,LEAVES:1)
Block(3,23,3,LEAVES:1)
Block(3,24,0,LEAVES:1)
Block(3,26,-2,LEAVES:1)
Block(3,26,-1,LEAVES:1)
Block(3,26,0,LOG:13)
Block(3,26,1,LEAVES:1)
Block(3,26,2,LEAVES:1)
Block(3,27,0,LEAVES:1)
Block(4,8,1,LEAVES:1)
Block(4,9,1,LEAVES:1)
Block(4,14,-5,LEAVES:1)
Block(4,14,-4,LOG:13)
Block(4,14,-3,LEAVES:1)
Block(4,14,-1,LEAVES:1)
Block(4,14,0,LOG:13)
Block(4,14,1,LEAVES:1)
Block(4,14,3,LEAVES:1)
Block(4,14,4,LOG:13)
Block(4,14,5,LEAVES:1)
Block(4,15,-4,LEAVES:1)
Block(4,15,0,LEAVES:1)
Block(4,15,4,LEAVES:1)
Block(4,18,-5,LEAVES:1)
Block(4,18,-4,LOG:13)
Block(4,18,-3,LEAVES:1)
Block(4,18,-1,LEAVES:1)
Block(4,18,0,LOG:13)
Block(4,18,1,LEAVES:1)
Block(4,18,3,LEAVES:1)
Block(4,18,4,LOG:13)
Block(4,18,5,LEAVES:1)
Block(4,19,-4,LEAVES:1)
Block(4,19,0,LEAVES:1)
Block(4,19,4,LEAVES:1)
Block(4,22,-3,LEAVES:1)
Block(4,22,-1,LEAVES:1)
Block(4,22,0,LOG:13)
Block(4,22,1,LEAVES:1)
Block(4,22,3,LEAVES:1)
Block(4,23,0,LEAVES:1)
Block(4,26,0,LEAVES:1)
Block(5,14,-5,LEAVES:1)
Block(5,14,-4,LEAVES:1)
Block(5,14,-1,LEAVES:1)
Block(5,14,0,LOG:13)
Block(5,14,1,LEAVES:1)
Block(5,14,4,LEAVES:1)
Block(5,14,5,LEAVES:1)
Block(5,15,0,LEAVES:1)
Block(5,18,-5,LEAVES:1)
Block(5,18,-4,LEAVES:1)
Block(5,18,-1,LEAVES:1)
Block(5,18,0,LOG:13)
Block(5,18,1,LEAVES:1)
Block(5,18,4,LEAVES:1)
Block(5,18,5,LEAVES:1)
Block(5,19,0,LEAVES:1)
Block(5,22,0,LEAVES:1)
Block(6,14,0,LEAVES:1)
Block(6,18,0,LEAVES:1)


#######################################################################
# +-----------------------------------------------------------------+ #
# |                             Entities                            | #
# +-----------------------------------------------------------------+ #
#######################################################################

# Entity() spawns an entity instead of a block. The entity is spawned only once when the BO3 is spawned.
# Entities are persistent by default so they don't de-spawn when no player is near, they are only unloaded.
# Usage: Entity(x,y,z,mobName,groupSize,NameTagOrNBTFileName) or Entity(x,y,z,mobName,groupSize)
# Use /tc entities or /otg entities to get a list of entities that can be used as mobName, this includes entities added by other mods.
# NameTagOrNBTFileName can be either a nametag for the mob or an nbt file (such as mymobinfo.nbt or mymobinfo.txt).
# When using a text file you can use the same mob spawning parameters used with the /summon command to equip the
# entity and give it custom attributes etc. You can copy the DATA part of a summon command including surrounding
# curly braces to a .txt file, for instance for: "/summon Skeleton x y z {DATA}"

#######################################################################
# +-----------------------------------------------------------------+ #
# |                            BO3 checks                           | #
# +-----------------------------------------------------------------+ #
#######################################################################

# Require a condition at a certain location in order for the BO3 to be spawned.
# BlockCheck(x,y,z,BlockName[,BlockName[,...]]) - one of the blocks must be at the location
# BlockCheckNot(x,y,z,BlockName[,BlockName[,...]]) - all the blocks must not be at the location
# LightCheck(x,y,z,minLightLevel,maxLightLevel) - light must be between min and max (inclusive)

# You can use "Solid" as a BlockName for matching all solid blocks or "All" to match all blocks that aren't air.

# Examples:
#   BlockCheck(0,-1,0,GRASS,DIRT)  Require grass or dirt just below the object
#   BlockCheck(0,-1,0,Solid)       Require any solid block just below the object
#   BlockCheck(0,-1,0,WOOL)        Require any type of wool just below the object
#   BlockCheck(0,-1,0,WOOL:0)      Require white wool just below the object
#   BlockCheckNot(0,-1,0,WOOL:0)   Require that there is no white wool below the object
#   LightCheck(0,0,0,0,LEAVES:1)          Require almost complete darkness just below the object

BlockCheck(0,-1,0,GRASS,DIRT,DIRT:2)