#######################################################################
# +-----------------------------------------------------------------+ #
# |                            BO3 object                           | #
# +-----------------------------------------------------------------+ #
#######################################################################

# The descriptions in this file are accurate only for TerrainControl and OTG.
# For MCW and OTG+ these descriptions are only accurate if the BO3 is used as a CustomObject.
# MCW and OTG+ completely reimplemented CustomStructure, check the MCW/OTG+ documentation for more information.

# This is the config file of a custom object.
# If you add this object correctly to your BiomeConfigs, it will spawn in the world.

# This is the creator of this BO3 object
Author: Unknown

# A short description of this BO3 object
Description: This BO3 was converted from a schematic using OTGEdit. The author and description information of the schematic could not be found. If you know who the author of the schematic is then please add this information.

# The BO3 version, don't change this! It can be used by external applications to do a version check.
Version: 3

# The settings mode, WriteAll, WriteWithoutComments or WriteDisable. See WorldConfig.
SettingsMode: WriteDisable

#######################################################################
# +-----------------------------------------------------------------+ #
# |                          Main settings                          | #
# +-----------------------------------------------------------------+ #
#######################################################################

# This needs to be set to true to spawn the object in the Tree and Sapling resources.
Tree: true

# The frequency of the BO3 from 1 to 200. Tries this many times to spawn this BO3 when using the CustomObject(...) resource.
# Ignored by Tree(..), Sapling(..) and CustomStructure(..)
Frequency: 1

# The rarity of the BO3 from 0 to 100. Each spawn attempt has rarity% chance to succeed when using the CustomObject(...) resource.
# Ignored by Tree(..), Sapling(..) and CustomStructure(..)
Rarity: 100.0

# If you set this to true, the BO3 will be placed with a random rotation.
RotateRandomly: false

# The spawn height of the BO3 - randomY, highestBlock or highestSolidBlock.
SpawnHeight: highestBlock

# The height limits for the BO3.
MinHeight: 64

MaxHeight: 80

# Objects can have other objects attached to it: branches. Branches can also
# have branches attached to it, which can also have branches, etc. This is the
# maximum branch depth for this objects.
MaxBranchDepth: 10

# When spawned with the UseWorld keyword, this BO3 should NOT spawn in the following biomes.
# If you writer.write the BO3 name directly in the BiomeConfigs, this will be ignored.
ExcludedBiomes: All

# To optimise this BO3 for faster loading times you can use Notepad++ to find/replace comments and abbreviate things.
# Notepad++ find/replace with regex:
# Find: ^[#;].* replace to nothing removes all lines starting with # 
# Find: ^\s*$ replace to nothing removes most empty lines 
# Notepad++ find/replace without regex:
# *Warning: This will only work for OTG 1.10.2 v21 / OTG 1.11.2 v6 or higher. B( is not recognised by lower versions.
# Find: Block( replace to B(

#######################################################################
# +-----------------------------------------------------------------+ #
# |                      Source block settings                      | #
# +-----------------------------------------------------------------+ #
#######################################################################

# The block(s) the BO3 should spawn in.
SourceBlocks: STONE:1,STONE:3,STONE:5,DIRT:1,DIRT,SAND,GRASS,DIRT:2,STATIONARY_WATER,HARD_CLAY,STAINED_CLAY,CLAY,SANDSTONE,SAND:1,AIR,STONE,GRAVEL,LONG_GRASS,LONG_GRASS:1,LONG_GRASS:2,DEAD_BUSH,YELLOW_FLOWER,RED_ROSE,BROWN_MUSHROOM,RED_MUSHROOM

# The maximum percentage of the BO3 that can be outside the SourceBlock.
# The BO3 won't be placed on a location with more blocks outside the SourceBlock than this percentage.
MaxPercentageOutsideSourceBlock: 0

# What to do when a block is about to be placed outside the SourceBlock? (dontPlace, placeAnyway)
OutsideSourceBlock: placeAnyway

#######################################################################
# +-----------------------------------------------------------------+ #
# |                              Blocks                             | #
# +-----------------------------------------------------------------+ #
#######################################################################

# All the blocks used in the BO3 are listed here. Possible blocks:
# Block(x,y,z,id[.data][,nbtfile.nbt) or B(x,y,z,id[.data][,nbtfile.nbt)
# RandomBlock(x,y,z,id[:data][,nbtfile.nbt],chance[,id[:data][,nbtfile.nbt],chance[,...]])
# So RandomBlock(0,0,0,CHEST,chest.nbt,50,CHEST,anotherchest.nbt,100) will spawn a chest at
# the BO3 origin, and give it a 50% chance to have the contents of chest.nbt, or, if that
# fails, a 100% percent chance to have the contents of anotherchest.nbt.

Block(-18,27,-5,LEAVES:3)
Block(-18,28,-5,LEAVES:3)
Block(-17,25,0,LEAVES:3)
Block(-17,26,0,LEAVES:3)
Block(-17,27,-6,LEAVES:3)
Block(-17,28,-6,LEAVES:3)
Block(-17,28,-5,LEAVES:3)
Block(-17,28,-4,LEAVES:3)
Block(-17,29,-5,LEAVES:3)
Block(-16,25,-2,LEAVES:3)
Block(-16,26,-1,LEAVES:3)
Block(-16,26,0,LEAVES:3)
Block(-16,26,1,LEAVES:3)
Block(-16,27,-4,LEAVES:3)
Block(-16,27,0,LEAVES:3)
Block(-16,28,-6,LEAVES:3)
Block(-16,28,-5,LEAVES:3)
Block(-16,28,-4,LEAVES:3)
Block(-16,28,-3,LEAVES:3)
Block(-16,29,-5,LEAVES:3)
Block(-16,29,-4,LEAVES:3)
Block(-15,24,3,LEAVES:3)
Block(-15,25,0,LEAVES:3)
Block(-15,25,2,LEAVES:3)
Block(-15,25,3,LEAVES:3)
Block(-15,26,-7,LEAVES:3)
Block(-15,26,-2,LEAVES:3)
Block(-15,26,-1,LEAVES:3)
Block(-15,26,0,LEAVES:3)
Block(-15,26,1,LEAVES:3)
Block(-15,27,-7,LEAVES:3)
Block(-15,27,-6,LEAVES:3)
Block(-15,27,-3,LEAVES:3)
Block(-15,27,-1,LEAVES:3)
Block(-15,27,0,LEAVES:3)
Block(-15,28,-7,LEAVES:3)
Block(-15,28,-6,LEAVES:3)
Block(-15,28,-5,17:15)
Block(-15,28,-4,LEAVES:3)
Block(-15,29,-6,LEAVES:3)
Block(-15,29,-5,LEAVES:3)
Block(-15,30,-5,LEAVES:3)
Block(-15,42,-10,LEAVES:3)
Block(-15,43,-11,LEAVES:3)
Block(-15,54,2,LEAVES:3)
Block(-15,55,1,LEAVES:3)
Block(-14,24,-2,LEAVES:3)
Block(-14,25,-1,LEAVES:3)
Block(-14,25,2,LEAVES:3)
Block(-14,25,3,LEAVES:3)
Block(-14,25,4,LEAVES:3)
Block(-14,26,-9,LEAVES:3)
Block(-14,26,-5,LEAVES:3)
Block(-14,26,-1,LEAVES:3)
Block(-14,26,0,17:15)
Block(-14,26,1,LEAVES:3)
Block(-14,26,3,LEAVES:3)
Block(-14,27,-8,LEAVES:3)
Block(-14,27,-7,LEAVES:3)
Block(-14,27,-6,LEAVES:3)
Block(-14,27,-5,17:15)
Block(-14,27,-4,LEAVES:3)
Block(-14,27,-3,LEAVES:3)
Block(-14,27,0,LEAVES:3)
Block(-14,27,1,LEAVES:3)
Block(-14,28,-7,LEAVES:3)
Block(-14,28,-6,LEAVES:3)
Block(-14,28,-5,LEAVES:3)
Block(-14,28,-4,LEAVES:3)
Block(-14,28,0,LEAVES:3)
Block(-14,29,-5,LEAVES:3)
Block(-14,42,-12,LEAVES:3)
Block(-14,43,-12,LEAVES:3)
Block(-14,43,-11,LEAVES:3)
Block(-14,43,-10,LEAVES:3)
Block(-14,44,-11,LEAVES:3)
Block(-14,54,0,LEAVES:3)
Block(-14,55,0,LEAVES:3)
Block(-14,55,1,LEAVES:3)
Block(-14,55,2,LEAVES:3)
Block(-14,56,1,LEAVES:3)
Block(-13,24,-1,LEAVES:3)
Block(-13,24,4,LEAVES:3)
Block(-13,25,-2,LEAVES:3)
Block(-13,25,-1,LEAVES:3)
Block(-13,25,0,17:15)
Block(-13,25,1,LEAVES:3)
Block(-13,25,2,LEAVES:3)
Block(-13,25,3,17:15)
Block(-13,25,4,LEAVES:3)
Block(-13,26,-8,LEAVES:3)
Block(-13,26,-6,LEAVES:3)
Block(-13,26,-3,LEAVES:3)
Block(-13,26,-1,LEAVES:3)
Block(-13,26,0,LEAVES:3)
Block(-13,26,1,LEAVES:3)
Block(-13,26,3,LEAVES:3)
Block(-13,26,4,LEAVES:3)
Block(-13,27,-9,LEAVES:3)
Block(-13,27,-8,LEAVES:3)
Block(-13,27,-7,LEAVES:3)
Block(-13,27,-6,17:15)
Block(-13,27,-5,LEAVES:3)
Block(-13,27,-4,LEAVES:3)
Block(-13,27,-2,LEAVES:3)
Block(-13,27,0,LEAVES:3)
Block(-13,28,-8,LEAVES:3)
Block(-13,28,-7,LEAVES:3)
Block(-13,28,-6,LEAVES:3)
Block(-13,28,-5,LEAVES:3)
Block(-13,29,-6,LEAVES:3)
Block(-13,41,-8,LEAVES:3)
Block(-13,41,-6,LEAVES:3)
Block(-13,42,-11,LEAVES:3)
Block(-13,42,-8,LEAVES:3)
Block(-13,42,-5,LEAVES:3)
Block(-13,43,-13,LEAVES:3)
Block(-13,43,-12,LEAVES:3)
Block(-13,43,-11,LEAVES:3)
Block(-13,43,-10,LEAVES:3)
Block(-13,43,-6,LEAVES:3)
Block(-13,43,14,LEAVES:3)
Block(-13,44,-12,LEAVES:3)
Block(-13,44,-11,LEAVES:3)
Block(-13,44,13,LEAVES:3)
Block(-13,53,-2,LEAVES:3)
Block(-13,54,-1,LEAVES:3)
Block(-13,54,1,LEAVES:3)
Block(-13,54,3,LEAVES:3)
Block(-13,55,0,LEAVES:3)
Block(-13,55,1,LEAVES:3)
Block(-13,55,2,LEAVES:3)
Block(-13,55,3,LEAVES:3)
Block(-13,56,1,LEAVES:3)
Block(-13,56,2,LEAVES:3)
Block(-12,24,2,LEAVES:3)
Block(-12,25,-1,LEAVES:3)
Block(-12,25,0,LEAVES:3)
Block(-12,25,1,17:15)
Block(-12,25,2,17:15)
Block(-12,25,3,LEAVES:3)
Block(-12,25,4,LEAVES:3)
Block(-12,26,0,LEAVES:3)
Block(-12,26,1,LEAVES:3)
Block(-12,26,2,LEAVES:3)
Block(-12,26,4,LEAVES:3)
Block(-12,27,-8,LEAVES:3)
Block(-12,27,-7,LEAVES:3)
Block(-12,27,-6,17:15)
Block(-12,27,-5,LEAVES:3)
Block(-12,27,-4,LEAVES:3)
Block(-12,27,-3,LEAVES:3)
Block(-12,27,-2,LEAVES:3)
Block(-12,27,-1,LEAVES:3)
Block(-12,27,1,LEAVES:3)
Block(-12,28,-6,LEAVES:3)
Block(-12,28,-5,LEAVES:3)
Block(-12,28,-2,LEAVES:3)
Block(-12,40,4,LEAVES:3)
Block(-12,41,-10,LEAVES:3)
Block(-12,41,3,LEAVES:3)
Block(-12,42,-13,LEAVES:3)
Block(-12,42,-11,LEAVES:3)
Block(-12,42,-9,LEAVES:3)
Block(-12,42,-8,LEAVES:3)
Block(-12,42,-7,LEAVES:3)
Block(-12,42,-6,LEAVES:3)
Block(-12,43,-12,LEAVES:3)
Block(-12,43,-11,17:15)
Block(-12,43,-10,LEAVES:3)
Block(-12,43,-8,LEAVES:3)
Block(-12,43,-7,LEAVES:3)
Block(-12,43,-6,LEAVES:3)
Block(-12,43,-5,LEAVES:3)
Block(-12,43,12,LEAVES:3)
Block(-12,44,-11,LEAVES:3)
Block(-12,44,-6,LEAVES:3)
Block(-12,44,12,LEAVES:3)
Block(-12,44,13,LEAVES:3)
Block(-12,44,14,LEAVES:3)
Block(-12,45,-11,LEAVES:3)
Block(-12,45,13,LEAVES:3)
Block(-12,53,-1,LEAVES:3)
Block(-12,54,-2,LEAVES:3)
Block(-12,54,-1,LEAVES:3)
Block(-12,54,2,LEAVES:3)
Block(-12,55,-1,LEAVES:3)
Block(-12,55,0,LEAVES:3)
Block(-12,55,1,17:15)
Block(-12,55,2,LEAVES:3)
Block(-12,56,0,LEAVES:3)
Block(-12,56,1,LEAVES:3)
Block(-12,57,1,LEAVES:3)
Block(-11,24,-1,LEAVES:3)
Block(-11,24,1,17:15)
Block(-11,24,4,LEAVES:3)
Block(-11,25,1,LEAVES:3)
Block(-11,25,2,LEAVES:3)
Block(-11,25,3,LEAVES:3)
Block(-11,26,-9,LEAVES:3)
Block(-11,26,-7,17:15)
Block(-11,26,-5,LEAVES:3)
Block(-11,26,0,LEAVES:3)
Block(-11,26,1,LEAVES:3)
Block(-11,26,2,LEAVES:3)
Block(-11,26,3,LEAVES:3)
Block(-11,27,-8,LEAVES:3)
Block(-11,27,-7,LEAVES:3)
Block(-11,27,-6,LEAVES:3)
Block(-11,27,-5,LEAVES:3)
Block(-11,27,-3,LEAVES:3)
Block(-11,27,-2,17:15)
Block(-11,27,-1,LEAVES:3)
Block(-11,27,1,LEAVES:3)
Block(-11,27,2,LEAVES:3)
Block(-11,28,-7,LEAVES:3)
Block(-11,28,-3,LEAVES:3)
Block(-11,28,-2,LEAVES:3)
Block(-11,29,-2,LEAVES:3)
Block(-11,37,0,LEAVES:3)
Block(-11,39,4,LEAVES:3)
Block(-11,40,-1,LEAVES:3)
Block(-11,41,2,LEAVES:3)
Block(-11,41,3,LEAVES:3)
Block(-11,41,4,LEAVES:3)
Block(-11,42,-11,LEAVES:3)
Block(-11,42,-10,LEAVES:3)
Block(-11,42,-9,LEAVES:3)
Block(-11,42,-8,17:15)
Block(-11,42,-7,LEAVES:3)
Block(-11,42,-4,LEAVES:3)
Block(-11,42,3,LEAVES:3)
Block(-11,42,10,LEAVES:3)
Block(-11,43,-11,LEAVES:3)
Block(-11,43,-10,17:15)
Block(-11,43,-8,LEAVES:3)
Block(-11,43,-7,17:15)
Block(-11,43,-6,17:15)
Block(-11,43,-5,LEAVES:3)
Block(-11,43,-4,LEAVES:3)
Block(-11,43,11,LEAVES:3)
Block(-11,43,13,LEAVES:3)
Block(-11,43,15,LEAVES:3)
Block(-11,44,-16,LEAVES:3)
Block(-11,44,-11,LEAVES:3)
Block(-11,44,-10,LEAVES:3)
Block(-11,44,-7,LEAVES:3)
Block(-11,44,-6,LEAVES:3)
Block(-11,44,-5,LEAVES:3)
Block(-11,44,12,LEAVES:3)
Block(-11,44,13,LEAVES:3)
Block(-11,44,14,LEAVES:3)
Block(-11,44,15,LEAVES:3)
Block(-11,45,-15,LEAVES:3)
Block(-11,45,-7,LEAVES:3)
Block(-11,45,13,LEAVES:3)
Block(-11,45,14,LEAVES:3)
Block(-11,52,5,LEAVES:3)
Block(-11,53,-3,LEAVES:3)
Block(-11,53,1,LEAVES:3)
Block(-11,53,3,LEAVES:3)
Block(-11,54,-3,LEAVES:3)
Block(-11,54,-2,LEAVES:3)
Block(-11,54,-1,LEAVES:3)
Block(-11,54,0,LEAVES:3)
Block(-11,54,1,17:15)
Block(-11,54,2,LEAVES:3)
Block(-11,54,3,LEAVES:3)
Block(-11,55,-2,LEAVES:3)
Block(-11,55,-1,LEAVES:3)
Block(-11,55,0,LEAVES:3)
Block(-11,55,1,LEAVES:3)
Block(-11,55,2,LEAVES:3)
Block(-11,56,-1,LEAVES:3)
Block(-11,56,1,LEAVES:3)
Block(-10,24,-1,LEAVES:3)
Block(-10,24,1,17:15)
Block(-10,25,-1,LEAVES:3)
Block(-10,25,0,LEAVES:3)
Block(-10,25,2,LEAVES:3)
Block(-10,25,3,LEAVES:3)
Block(-10,26,-7,17:15)
Block(-10,26,-6,17:15)
Block(-10,26,-5,LEAVES:3)
Block(-10,26,-3,LEAVES:3)
Block(-10,26,-2,17:15)
Block(-10,26,-1,LEAVES:3)
Block(-10,26,0,LEAVES:3)
Block(-10,26,1,17:15)
Block(-10,26,2,LEAVES:3)
Block(-10,27,-7,LEAVES:3)
Block(-10,27,-6,LEAVES:3)
Block(-10,27,-2,LEAVES:3)
Block(-10,27,0,LEAVES:3)
Block(-10,27,1,LEAVES:3)
Block(-10,28,1,LEAVES:3)
Block(-10,37,0,LEAVES:3)
Block(-10,37,1,LEAVES:3)
Block(-10,39,-3,LEAVES:3)
Block(-10,39,3,LEAVES:3)
Block(-10,40,-4,LEAVES:3)
Block(-10,40,-2,LEAVES:3)
Block(-10,40,2,LEAVES:3)
Block(-10,40,4,LEAVES:3)
Block(-10,40,5,LEAVES:3)
Block(-10,41,-12,LEAVES:3)
Block(-10,41,-8,LEAVES:3)
Block(-10,41,-3,LEAVES:3)
Block(-10,41,-2,LEAVES:3)
Block(-10,41,-1,LEAVES:3)
Block(-10,41,2,LEAVES:3)
Block(-10,41,3,LEAVES:3)
Block(-10,41,4,LEAVES:3)
Block(-10,41,5,LEAVES:3)
Block(-10,42,-12,LEAVES:3)
Block(-10,42,-11,LEAVES:3)
Block(-10,42,-10,17:15)
Block(-10,42,-9,17:15)
Block(-10,42,-8,LEAVES:3)
Block(-10,42,2,LEAVES:3)
Block(-10,42,3,LEAVES:3)
Block(-10,42,4,LEAVES:3)
Block(-10,42,11,LEAVES:3)
Block(-10,43,-11,LEAVES:3)
Block(-10,43,-10,LEAVES:3)
Block(-10,43,-9,LEAVES:3)
Block(-10,43,-7,LEAVES:3)
Block(-10,43,-6,LEAVES:3)
Block(-10,43,-5,LEAVES:3)
Block(-10,43,3,LEAVES:3)
Block(-10,43,10,LEAVES:3)
Block(-10,43,11,LEAVES:3)
Block(-10,43,14,LEAVES:3)
Block(-10,44,-14,LEAVES:3)
Block(-10,44,-10,LEAVES:3)
Block(-10,44,-7,LEAVES:3)
Block(-10,44,11,LEAVES:3)
Block(-10,44,12,LEAVES:3)
Block(-10,44,13,17:15)
Block(-10,44,14,LEAVES:3)
Block(-10,45,-16,LEAVES:3)
Block(-10,45,-15,LEAVES:3)
Block(-10,45,-14,LEAVES:3)
Block(-10,45,12,LEAVES:3)
Block(-10,45,13,LEAVES:3)
Block(-10,46,-15,LEAVES:3)
Block(-10,46,13,LEAVES:3)
Block(-10,52,5,LEAVES:3)
Block(-10,53,-4,LEAVES:3)
Block(-10,53,-1,LEAVES:3)
Block(-10,53,2,LEAVES:3)
Block(-10,53,5,LEAVES:3)
Block(-10,54,-4,LEAVES:3)
Block(-10,54,-3,LEAVES:3)
Block(-10,54,-2,LEAVES:3)
Block(-10,54,-1,17:15)
Block(-10,54,0,17:15)
Block(-10,54,1,LEAVES:3)
Block(-10,55,-3,LEAVES:3)
Block(-10,55,-1,LEAVES:3)
Block(-10,55,0,LEAVES:3)
Block(-10,55,1,LEAVES:3)
Block(-10,56,0,LEAVES:3)
Block(-10,61,-2,LEAVES:3)
Block(-10,62,-2,LEAVES:3)
Block(-9,24,-8,LEAVES:3)
Block(-9,24,-3,LEAVES:3)
Block(-9,24,1,LEAVES:3)
Block(-9,25,-9,LEAVES:3)
Block(-9,25,-5,17:15)
Block(-9,25,-2,LEAVES:3)
Block(-9,25,-1,LEAVES:3)
Block(-9,25,0,LEAVES:3)
Block(-9,25,1,17:15)
Block(-9,25,2,LEAVES:3)
Block(-9,25,3,LEAVES:3)
Block(-9,26,-6,17:15)
Block(-9,26,-5,17:15)
Block(-9,26,-4,LEAVES:3)
Block(-9,26,-3,17:15)
Block(-9,26,-1,LEAVES:3)
Block(-9,26,0,LEAVES:3)
Block(-9,26,1,LEAVES:3)
Block(-9,26,2,LEAVES:3)
Block(-9,27,-7,LEAVES:3)
Block(-9,27,-6,LEAVES:3)
Block(-9,27,-5,LEAVES:3)
Block(-9,27,-3,LEAVES:3)
Block(-9,27,1,LEAVES:3)
Block(-9,28,-6,LEAVES:3)
Block(-9,34,2,LEAVES:3)
Block(-9,36,-1,LEAVES:3)
Block(-9,37,-5,LEAVES:3)
Block(-9,37,0,17:15)
Block(-9,38,0,LEAVES:3)
Block(-9,40,-3,LEAVES:3)
Block(-9,40,-1,LEAVES:3)
Block(-9,40,3,LEAVES:3)
Block(-9,41,-9,17:15)
Block(-9,41,-4,LEAVES:3)
Block(-9,41,-3,17:15)
Block(-9,41,-2,LEAVES:3)
Block(-9,41,-1,LEAVES:3)
Block(-9,41,0,LEAVES:3)
Block(-9,41,1,LEAVES:3)
Block(-9,41,2,LEAVES:3)
Block(-9,41,3,17:15)
Block(-9,41,4,LEAVES:3)
Block(-9,42,-12,LEAVES:3)
Block(-9,42,-11,LEAVES:3)
Block(-9,42,-10,LEAVES:3)
Block(-9,42,-9,17:15)
Block(-9,42,-6,LEAVES:3)
Block(-9,42,-3,LEAVES:3)
Block(-9,42,-2,LEAVES:3)
Block(-9,42,-1,LEAVES:3)
Block(-9,42,1,LEAVES:3)
Block(-9,42,2,LEAVES:3)
Block(-9,42,3,LEAVES:3)
Block(-9,42,9,LEAVES:3)
Block(-9,42,13,LEAVES:3)
Block(-9,42,15,LEAVES:3)
Block(-9,43,-14,LEAVES:3)
Block(-9,43,-9,LEAVES:3)
Block(-9,43,-7,LEAVES:3)
Block(-9,43,9,LEAVES:3)
Block(-9,43,10,LEAVES:3)
Block(-9,43,11,LEAVES:3)
Block(-9,43,12,LEAVES:3)
Block(-9,43,13,17:15)
Block(-9,43,14,LEAVES:3)
Block(-9,43,15,LEAVES:3)
Block(-9,44,-17,LEAVES:3)
Block(-9,44,-15,LEAVES:3)
Block(-9,44,-14,LEAVES:3)
Block(-9,44,-13,LEAVES:3)
Block(-9,44,10,LEAVES:3)
Block(-9,44,11,LEAVES:3)
Block(-9,44,12,LEAVES:3)
Block(-9,44,13,LEAVES:3)
Block(-9,44,14,LEAVES:3)
Block(-9,45,-16,LEAVES:3)
Block(-9,45,-15,17:15)
Block(-9,45,-14,LEAVES:3)
Block(-9,45,11,LEAVES:3)
Block(-9,45,13,LEAVES:3)
Block(-9,46,-15,LEAVES:3)
Block(-9,51,-7,LEAVES:3)
Block(-9,52,5,17:15)
Block(-9,52,6,LEAVES:3)
Block(-9,53,-3,LEAVES:3)
Block(-9,53,-1,17:15)
Block(-9,54,-5,LEAVES:3)
Block(-9,54,-4,LEAVES:3)
Block(-9,54,-3,17:15)
Block(-9,54,-1,LEAVES:3)
Block(-9,54,0,LEAVES:3)
Block(-9,54,1,LEAVES:3)
Block(-9,54,2,LEAVES:3)
Block(-9,55,-4,LEAVES:3)
Block(-9,55,-3,LEAVES:3)
Block(-9,55,-2,LEAVES:3)
Block(-9,55,0,LEAVES:3)
Block(-9,55,1,LEAVES:3)
Block(-9,56,-3,LEAVES:3)
Block(-9,60,-1,LEAVES:3)
Block(-9,62,-3,LEAVES:3)
Block(-9,62,-2,LEAVES:3)
Block(-9,62,-1,LEAVES:3)
Block(-9,63,-2,LEAVES:3)
Block(-8,23,-9,LEAVES:3)
Block(-8,24,-12,LEAVES:3)
Block(-8,24,-10,LEAVES:3)
Block(-8,24,-2,LEAVES:3)
Block(-8,24,0,LEAVES:3)
Block(-8,24,3,LEAVES:3)
Block(-8,25,-11,LEAVES:3)
Block(-8,25,-10,LEAVES:3)
Block(-8,25,-9,LEAVES:3)
Block(-8,25,-8,LEAVES:3)
Block(-8,25,-7,LEAVES:3)
Block(-8,25,-5,LEAVES:3)
Block(-8,25,-4,17:15)
Block(-8,25,-3,LEAVES:3)
Block(-8,25,-2,LEAVES:3)
Block(-8,25,-1,LEAVES:3)
Block(-8,25,0,17:15)
Block(-8,25,1,LEAVES:3)
Block(-8,25,2,LEAVES:3)
Block(-8,25,7,LEAVES:3)
Block(-8,26,-9,LEAVES:3)
Block(-8,26,-7,LEAVES:3)
Block(-8,26,-6,LEAVES:3)
Block(-8,26,-5,LEAVES:3)
Block(-8,26,-4,17:15)
Block(-8,26,-3,LEAVES:3)
Block(-8,26,-2,LEAVES:3)
Block(-8,26,-1,LEAVES:3)
Block(-8,26,0,LEAVES:3)
Block(-8,26,1,LEAVES:3)
Block(-8,26,6,LEAVES:3)
Block(-8,26,9,LEAVES:3)
Block(-8,27,-6,LEAVES:3)
Block(-8,27,-4,LEAVES:3)
Block(-8,27,0,LEAVES:3)
Block(-8,27,8,LEAVES:3)
Block(-8,34,2,LEAVES:3)
Block(-8,34,3,LEAVES:3)
Block(-8,36,-1,17:15)
Block(-8,36,0,LEAVES:3)
Block(-8,37,-5,LEAVES:3)
Block(-8,39,-1,LEAVES:3)
Block(-8,40,-4,LEAVES:3)
Block(-8,40,-2,LEAVES:3)
Block(-8,40,1,LEAVES:3)
Block(-8,40,5,LEAVES:3)
Block(-8,40,7,LEAVES:3)
Block(-8,41,-13,LEAVES:3)
Block(-8,41,-10,17:15)
Block(-8,41,-9,17:15)
Block(-8,41,-5,LEAVES:3)
Block(-8,41,-4,17:15)
Block(-8,41,-3,LEAVES:3)
Block(-8,41,-2,LEAVES:3)
Block(-8,41,1,LEAVES:3)
Block(-8,41,2,LEAVES:3)
Block(-8,41,3,LEAVES:3)
Block(-8,41,4,17:15)
Block(-8,41,5,LEAVES:3)
Block(-8,41,6,LEAVES:3)
Block(-8,42,-15,LEAVES:3)
Block(-8,42,-13,LEAVES:3)
Block(-8,42,-12,17:15)
Block(-8,42,-11,LEAVES:3)
Block(-8,42,-10,LEAVES:3)
Block(-8,42,-9,LEAVES:3)
Block(-8,42,-8,LEAVES:3)
Block(-8,42,-6,LEAVES:3)
Block(-8,42,-5,LEAVES:3)
Block(-8,42,-4,LEAVES:3)
Block(-8,42,-3,LEAVES:3)
Block(-8,42,4,LEAVES:3)
Block(-8,42,5,LEAVES:3)
Block(-8,42,8,LEAVES:3)
Block(-8,42,11,LEAVES:3)
Block(-8,42,14,LEAVES:3)
Block(-8,43,-16,LEAVES:3)
Block(-8,43,-15,LEAVES:3)
Block(-8,43,-12,LEAVES:3)
Block(-8,43,-11,LEAVES:3)
Block(-8,43,-5,LEAVES:3)
Block(-8,43,8,LEAVES:3)
Block(-8,43,9,LEAVES:3)
Block(-8,43,10,LEAVES:3)
Block(-8,43,11,17:15)
Block(-8,43,12,17:15)
Block(-8,43,13,LEAVES:3)
Block(-8,44,-17,LEAVES:3)
Block(-8,44,-16,LEAVES:3)
Block(-8,44,-15,17:15)
Block(-8,44,-14,LEAVES:3)
Block(-8,44,-13,LEAVES:3)
Block(-8,44,-7,LEAVES:3)
Block(-8,44,9,LEAVES:3)
Block(-8,44,11,LEAVES:3)
Block(-8,44,12,LEAVES:3)
Block(-8,44,13,LEAVES:3)
Block(-8,45,-16,LEAVES:3)
Block(-8,45,-15,LEAVES:3)
Block(-8,45,-14,LEAVES:3)
Block(-8,45,-13,LEAVES:3)
Block(-8,45,12,LEAVES:3)
Block(-8,46,-14,LEAVES:3)
Block(-8,51,-8,LEAVES:3)
Block(-8,51,-7,LEAVES:3)
Block(-8,51,-6,17:15)
Block(-8,52,-7,LEAVES:3)
Block(-8,52,-1,17:15)
Block(-8,52,4,17:15)
Block(-8,53,-5,LEAVES:3)
Block(-8,53,-1,17:15)
Block(-8,53,0,LEAVES:3)
Block(-8,53,2,LEAVES:3)
Block(-8,54,-4,LEAVES:3)
Block(-8,54,-3,LEAVES:3)
Block(-8,54,-2,17:15)
Block(-8,54,-1,LEAVES:3)
Block(-8,54,0,LEAVES:3)
Block(-8,54,1,LEAVES:3)
Block(-8,55,-3,LEAVES:3)
Block(-8,55,-2,LEAVES:3)
Block(-8,55,-1,LEAVES:3)
Block(-8,60,-3,LEAVES:3)
Block(-8,61,-3,LEAVES:3)
Block(-8,61,-1,LEAVES:3)
Block(-8,61,0,LEAVES:3)
Block(-8,62,-4,LEAVES:3)
Block(-8,62,-3,LEAVES:3)
Block(-8,62,-2,LEAVES:3)
Block(-8,62,-1,17:15)
Block(-8,62,0,LEAVES:3)
Block(-8,63,-3,LEAVES:3)
Block(-8,63,-2,LEAVES:3)
Block(-8,63,-1,LEAVES:3)
Block(-8,64,-2,LEAVES:3)
Block(-8,68,-2,LEAVES:3)
Block(-8,69,-2,LEAVES:3)
Block(-7,23,0,17:15)
Block(-7,24,-9,LEAVES:3)
Block(-7,25,-12,LEAVES:3)
Block(-7,25,-11,LEAVES:3)
Block(-7,25,-10,LEAVES:3)
Block(-7,25,-9,17:15)
Block(-7,25,-8,LEAVES:3)
Block(-7,25,-6,LEAVES:3)
Block(-7,25,-4,17:15)
Block(-7,25,-2,LEAVES:3)
Block(-7,25,-1,LEAVES:3)
Block(-7,25,0,17:15)
Block(-7,25,1,LEAVES:3)
Block(-7,25,2,LEAVES:3)
Block(-7,25,4,LEAVES:3)
Block(-7,25,6,LEAVES:3)
Block(-7,26,-11,LEAVES:3)
Block(-7,26,-10,LEAVES:3)
Block(-7,26,-9,LEAVES:3)
Block(-7,26,-7,LEAVES:3)
Block(-7,26,-6,LEAVES:3)
Block(-7,26,-5,LEAVES:3)
Block(-7,26,-4,LEAVES:3)
Block(-7,26,-3,LEAVES:3)
Block(-7,26,0,LEAVES:3)
Block(-7,26,1,LEAVES:3)
Block(-7,26,5,LEAVES:3)
Block(-7,26,6,LEAVES:3)
Block(-7,26,7,LEAVES:3)
Block(-7,27,-9,LEAVES:3)
Block(-7,27,-6,LEAVES:3)
Block(-7,27,-5,LEAVES:3)
Block(-7,27,-4,LEAVES:3)
Block(-7,27,6,LEAVES:3)
Block(-7,27,7,LEAVES:3)
Block(-7,27,8,LEAVES:3)
Block(-7,27,9,LEAVES:3)
Block(-7,28,-5,LEAVES:3)
Block(-7,28,8,LEAVES:3)
Block(-7,34,2,17:15)
Block(-7,34,12,LEAVES:3)
Block(-7,35,2,LEAVES:3)
Block(-7,35,11,LEAVES:3)
Block(-7,36,-3,LEAVES:3)
Block(-7,36,-2,17:15)
Block(-7,37,-6,LEAVES:3)
Block(-7,37,-5,17:15)
Block(-7,38,-5,LEAVES:3)
Block(-7,39,1,LEAVES:3)
Block(-7,39,6,LEAVES:3)
Block(-7,40,-3,LEAVES:3)
Block(-7,40,2,LEAVES:3)
Block(-7,40,3,LEAVES:3)
Block(-7,40,5,LEAVES:3)
Block(-7,41,-8,17:15)
Block(-7,41,-5,17:15)
Block(-7,41,-3,LEAVES:3)
Block(-7,41,-2,LEAVES:3)
Block(-7,41,-1,LEAVES:3)
Block(-7,41,3,LEAVES:3)
Block(-7,41,4,17:15)
Block(-7,41,5,LEAVES:3)
Block(-7,41,6,LEAVES:3)
Block(-7,41,7,LEAVES:3)
Block(-7,42,-12,LEAVES:3)
Block(-7,42,-11,17:15)
Block(-7,42,-9,LEAVES:3)
Block(-7,42,-8,LEAVES:3)
Block(-7,42,-5,17:15)
Block(-7,42,-4,LEAVES:3)
Block(-7,42,-3,LEAVES:3)
Block(-7,42,-2,LEAVES:3)
Block(-7,42,3,LEAVES:3)
Block(-7,42,4,LEAVES:3)
Block(-7,42,5,LEAVES:3)
Block(-7,42,6,LEAVES:3)
Block(-7,42,9,LEAVES:3)
Block(-7,42,11,17:15)
Block(-7,43,-14,LEAVES:3)
Block(-7,43,-12,LEAVES:3)
Block(-7,43,-11,LEAVES:3)
Block(-7,43,-9,LEAVES:3)
Block(-7,43,-8,LEAVES:3)
Block(-7,43,-5,LEAVES:3)
Block(-7,43,-3,LEAVES:3)
Block(-7,43,5,LEAVES:3)
Block(-7,43,7,LEAVES:3)
Block(-7,43,8,LEAVES:3)
Block(-7,43,9,17:15)
Block(-7,43,11,LEAVES:3)
Block(-7,43,12,LEAVES:3)
Block(-7,43,13,LEAVES:3)
Block(-7,43,14,LEAVES:3)
Block(-7,44,-16,LEAVES:3)
Block(-7,44,-15,LEAVES:3)
Block(-7,44,-14,17:15)
Block(-7,44,-11,LEAVES:3)
Block(-7,44,-8,LEAVES:3)
Block(-7,44,-7,LEAVES:3)
Block(-7,44,-6,LEAVES:3)
Block(-7,44,8,LEAVES:3)
Block(-7,44,9,LEAVES:3)
Block(-7,44,10,LEAVES:3)
Block(-7,44,12,LEAVES:3)
Block(-7,44,13,LEAVES:3)
Block(-7,45,-14,LEAVES:3)
Block(-7,45,-7,LEAVES:3)
Block(-7,45,9,LEAVES:3)
Block(-7,51,-5,17:15)
Block(-7,52,-1,17:15)
Block(-7,52,2,LEAVES:3)
Block(-7,52,3,LEAVES:3)
Block(-7,52,4,17:15)
Block(-7,52,5,LEAVES:3)
Block(-7,52,8,LEAVES:3)
Block(-7,53,-3,LEAVES:3)
Block(-7,53,3,LEAVES:3)
Block(-7,54,-2,LEAVES:3)
Block(-7,60,-4,LEAVES:3)
Block(-7,60,0,LEAVES:3)
Block(-7,60,1,LEAVES:3)
Block(-7,60,4,LEAVES:3)
Block(-7,61,-4,LEAVES:3)
Block(-7,61,-3,LEAVES:3)
Block(-7,61,-2,LEAVES:3)
Block(-7,61,-1,17:15)
Block(-7,61,0,LEAVES:3)
Block(-7,61,1,LEAVES:3)
Block(-7,61,4,LEAVES:3)
Block(-7,62,-2,LEAVES:3)
Block(-7,62,-1,LEAVES:3)
Block(-7,62,0,LEAVES:3)
Block(-7,63,-2,LEAVES:3)
Block(-7,67,-3,LEAVES:3)
Block(-7,69,-3,LEAVES:3)
Block(-7,69,-2,LEAVES:3)
Block(-7,69,-1,LEAVES:3)
Block(-7,70,-2,LEAVES:3)
Block(-6,23,-1,17:15)
Block(-6,24,-11,LEAVES:3)
Block(-6,24,-8,LEAVES:3)
Block(-6,24,-4,17:15)
Block(-6,24,-3,LEAVES:3)
Block(-6,24,-1,17:15)
Block(-6,24,0,17:15)
Block(-6,24,1,17:15)
Block(-6,24,2,LEAVES:3)
Block(-6,25,-11,LEAVES:3)
Block(-6,25,-10,LEAVES:3)
Block(-6,25,-9,LEAVES:3)
Block(-6,25,-8,17:15)
Block(-6,25,-4,17:15)
Block(-6,25,-3,17:15)
Block(-6,25,-2,LEAVES:3)
Block(-6,25,-1,LEAVES:3)
Block(-6,25,0,LEAVES:3)
Block(-6,25,1,LEAVES:3)
Block(-6,25,3,LEAVES:3)
Block(-6,26,-9,LEAVES:3)
Block(-6,26,-8,LEAVES:3)
Block(-6,26,-6,LEAVES:3)
Block(-6,26,-5,LEAVES:3)
Block(-6,26,-4,LEAVES:3)
Block(-6,26,-3,LEAVES:3)
Block(-6,26,-1,LEAVES:3)
Block(-6,26,5,LEAVES:3)
Block(-6,26,6,17:15)
Block(-6,26,8,LEAVES:3)
Block(-6,26,10,LEAVES:3)
Block(-6,27,-5,LEAVES:3)
Block(-6,27,5,LEAVES:3)
Block(-6,27,6,LEAVES:3)
Block(-6,27,7,17:15)
Block(-6,27,8,LEAVES:3)
Block(-6,27,9,LEAVES:3)
Block(-6,27,10,LEAVES:3)
Block(-6,28,6,LEAVES:3)
Block(-6,28,7,LEAVES:3)
Block(-6,28,8,LEAVES:3)
Block(-6,28,9,LEAVES:3)
Block(-6,29,7,LEAVES:3)
Block(-6,34,1,17:15)
Block(-6,34,5,LEAVES:3)
Block(-6,34,10,LEAVES:3)
Block(-6,35,0,17:15)
Block(-6,35,4,LEAVES:3)
Block(-6,35,10,LEAVES:3)
Block(-6,35,11,LEAVES:3)
Block(-6,35,12,LEAVES:3)
Block(-6,36,-4,17:15)
Block(-6,36,-3,17:15)
Block(-6,36,-2,17:15)
Block(-6,36,-1,LEAVES:3)
Block(-6,36,11,LEAVES:3)
Block(-6,37,-2,LEAVES:3)
Block(-6,39,3,LEAVES:3)
Block(-6,40,-7,17:15)
Block(-6,40,-6,LEAVES:3)
Block(-6,40,-5,LEAVES:3)
Block(-6,40,-2,LEAVES:3)
Block(-6,40,1,LEAVES:3)
Block(-6,40,6,LEAVES:3)
Block(-6,41,-6,LEAVES:3)
Block(-6,41,-3,LEAVES:3)
Block(-6,41,-2,LEAVES:3)
Block(-6,41,1,LEAVES:3)
Block(-6,41,2,LEAVES:3)
Block(-6,41,3,17:15)
Block(-6,41,5,17:15)
Block(-6,41,6,LEAVES:3)
Block(-6,41,11,17:15)
Block(-6,42,-16,LEAVES:3)
Block(-6,42,-12,LEAVES:3)
Block(-6,42,-6,17:15)
Block(-6,42,-5,LEAVES:3)
Block(-6,42,-3,LEAVES:3)
Block(-6,42,2,LEAVES:3)
Block(-6,42,3,LEAVES:3)
Block(-6,42,5,LEAVES:3)
Block(-6,42,7,LEAVES:3)
Block(-6,42,11,17:15)
Block(-6,42,12,LEAVES:3)
Block(-6,42,14,LEAVES:3)
Block(-6,43,-17,LEAVES:3)
Block(-6,43,-16,LEAVES:3)
Block(-6,43,-15,17:15)
Block(-6,43,-14,LEAVES:3)
Block(-6,43,-12,LEAVES:3)
Block(-6,43,-10,LEAVES:3)
Block(-6,43,-9,LEAVES:3)
Block(-6,43,3,LEAVES:3)
Block(-6,43,5,LEAVES:3)
Block(-6,43,6,LEAVES:3)
Block(-6,43,7,LEAVES:3)
Block(-6,43,8,LEAVES:3)
Block(-6,43,9,LEAVES:3)
Block(-6,43,10,17:15)
Block(-6,43,11,LEAVES:3)
Block(-6,43,12,LEAVES:3)
Block(-6,43,13,LEAVES:3)
Block(-6,44,-16,LEAVES:3)
Block(-6,44,-15,LEAVES:3)
Block(-6,44,-14,17:15)
Block(-6,44,-13,17:15)
Block(-6,44,-12,LEAVES:3)
Block(-6,44,-9,LEAVES:3)
Block(-6,44,-8,LEAVES:3)
Block(-6,44,-7,17:15)
Block(-6,44,-6,LEAVES:3)
Block(-6,44,-5,LEAVES:3)
Block(-6,44,6,LEAVES:3)
Block(-6,44,9,LEAVES:3)
Block(-6,44,10,LEAVES:3)
Block(-6,44,11,LEAVES:3)
Block(-6,45,-15,LEAVES:3)
Block(-6,45,-14,LEAVES:3)
Block(-6,45,-13,LEAVES:3)
Block(-6,45,-7,LEAVES:3)
Block(-6,45,-6,LEAVES:3)
Block(-6,50,-4,17:15)
Block(-6,51,-4,LEAVES:3)
Block(-6,52,-1,17:15)
Block(-6,52,0,17:15)
Block(-6,52,4,17:15)
Block(-6,52,7,17:15)
Block(-6,52,8,LEAVES:3)
Block(-6,52,9,LEAVES:3)
Block(-6,53,8,LEAVES:3)
Block(-6,59,4,LEAVES:3)
Block(-6,60,-6,LEAVES:3)
Block(-6,60,-4,LEAVES:3)
Block(-6,60,-2,LEAVES:3)
Block(-6,60,2,LEAVES:3)
Block(-6,61,-5,LEAVES:3)
Block(-6,61,-4,LEAVES:3)
Block(-6,61,-3,LEAVES:3)
Block(-6,61,-2,17:15)
Block(-6,61,-1,LEAVES:3)
Block(-6,61,3,LEAVES:3)
Block(-6,61,4,LEAVES:3)
Block(-6,61,5,LEAVES:3)
Block(-6,62,-12,LEAVES:3)
Block(-6,62,-4,LEAVES:3)
Block(-6,62,-3,LEAVES:3)
Block(-6,62,-2,LEAVES:3)
Block(-6,62,-1,LEAVES:3)
Block(-6,62,4,LEAVES:3)
Block(-6,63,-11,LEAVES:3)
Block(-6,63,-2,LEAVES:3)
Block(-6,67,-4,LEAVES:3)
Block(-6,68,-3,LEAVES:3)
Block(-6,68,-2,LEAVES:3)
Block(-6,68,4,LEAVES:3)
Block(-6,69,-4,LEAVES:3)
Block(-6,69,-3,LEAVES:3)
Block(-6,69,-2,LEAVES:3)
Block(-6,69,-1,LEAVES:3)
Block(-6,70,-3,LEAVES:3)
Block(-6,70,-2,LEAVES:3)
Block(-5,-4,0,17:15)
Block(-5,-3,0,17:15)
Block(-5,-2,0,17:15)
Block(-5,-1,0,17:15)
Block(-5,23,-1,17:15)
Block(-5,23,2,LEAVES:3)
Block(-5,24,-10,LEAVES:3)
Block(-5,24,-5,17:15)
Block(-5,24,-3,17:15)
Block(-5,24,-1,17:15)
Block(-5,24,1,17:15)
Block(-5,24,2,17:15)
Block(-5,25,-8,LEAVES:3)
Block(-5,25,-7,17:15)
Block(-5,25,-6,17:15)
Block(-5,25,-5,LEAVES:3)
Block(-5,25,-3,17:15)
Block(-5,25,-2,LEAVES:3)
Block(-5,25,-1,LEAVES:3)
Block(-5,25,1,LEAVES:3)
Block(-5,25,2,LEAVES:3)
Block(-5,25,3,17:15)
Block(-5,25,4,17:15)
Block(-5,26,-6,LEAVES:3)
Block(-5,26,-4,LEAVES:3)
Block(-5,26,-3,LEAVES:3)
Block(-5,26,-2,LEAVES:3)
Block(-5,26,1,LEAVES:3)
Block(-5,26,4,LEAVES:3)
Block(-5,26,5,17:15)
Block(-5,27,5,LEAVES:3)
Block(-5,27,6,LEAVES:3)
Block(-5,27,7,LEAVES:3)
Block(-5,27,8,LEAVES:3)
Block(-5,27,9,LEAVES:3)
Block(-5,28,7,LEAVES:3)
Block(-5,33,7,LEAVES:3)
Block(-5,33,10,LEAVES:3)
Block(-5,34,3,LEAVES:3)
Block(-5,34,7,LEAVES:3)
Block(-5,34,11,LEAVES:3)
Block(-5,34,13,LEAVES:3)
Block(-5,35,-2,17:15)
Block(-5,35,-1,17:15)
Block(-5,35,3,LEAVES:3)
Block(-5,35,4,LEAVES:3)
Block(-5,35,5,LEAVES:3)
Block(-5,35,10,LEAVES:3)
Block(-5,35,11,LEAVES:3)
Block(-5,35,12,LEAVES:3)
Block(-5,35,13,LEAVES:3)
Block(-5,36,-4,LEAVES:3)
Block(-5,36,4,LEAVES:3)
Block(-5,36,11,LEAVES:3)
Block(-5,36,12,LEAVES:3)
Block(-5,37,1,LEAVES:3)
Block(-5,40,-7,17:15)
Block(-5,40,-1,LEAVES:3)
Block(-5,40,1,LEAVES:3)
Block(-5,40,3,17:15)
Block(-5,40,4,LEAVES:3)
Block(-5,41,-8,LEAVES:3)
Block(-5,41,-7,17:15)
Block(-5,41,-6,17:15)
Block(-5,41,-5,LEAVES:3)
Block(-5,41,-3,LEAVES:3)
Block(-5,41,0,LEAVES:3)
Block(-5,41,1,LEAVES:3)
Block(-5,41,2,LEAVES:3)
Block(-5,41,3,17:15)
Block(-5,41,5,LEAVES:3)
Block(-5,41,11,17:15)
Block(-5,42,-10,LEAVES:3)
Block(-5,42,-7,LEAVES:3)
Block(-5,42,-3,LEAVES:3)
Block(-5,42,1,LEAVES:3)
Block(-5,42,2,LEAVES:3)
Block(-5,42,3,LEAVES:3)
Block(-5,42,6,LEAVES:3)
Block(-5,42,7,LEAVES:3)
Block(-5,42,9,LEAVES:3)
Block(-5,43,-18,LEAVES:3)
Block(-5,43,-17,LEAVES:3)
Block(-5,43,-16,17:15)
Block(-5,43,-13,LEAVES:3)
Block(-5,43,-12,17:15)
Block(-5,43,-11,17:15)
Block(-5,43,-10,LEAVES:3)
Block(-5,43,-9,LEAVES:3)
Block(-5,43,-7,LEAVES:3)
Block(-5,43,5,LEAVES:3)
Block(-5,43,6,LEAVES:3)
Block(-5,43,7,LEAVES:3)
Block(-5,43,10,LEAVES:3)
Block(-5,43,11,LEAVES:3)
Block(-5,44,-17,LEAVES:3)
Block(-5,44,-16,LEAVES:3)
Block(-5,44,-15,LEAVES:3)
Block(-5,44,-14,LEAVES:3)
Block(-5,44,-13,17:15)
Block(-5,44,-12,17:15)
Block(-5,44,-10,LEAVES:3)
Block(-5,44,-9,LEAVES:3)
Block(-5,44,-8,LEAVES:3)
Block(-5,44,-7,17:15)
Block(-5,44,-6,LEAVES:3)
Block(-5,44,5,LEAVES:3)
Block(-5,44,6,LEAVES:3)
Block(-5,44,12,LEAVES:3)
Block(-5,45,-16,LEAVES:3)
Block(-5,45,-13,17:15)
Block(-5,45,-12,LEAVES:3)
Block(-5,45,-11,LEAVES:3)
Block(-5,45,-9,LEAVES:3)
Block(-5,45,-8,LEAVES:3)
Block(-5,45,-7,LEAVES:3)
Block(-5,45,-6,LEAVES:3)
Block(-5,45,6,LEAVES:3)
Block(-5,46,-15,LEAVES:3)
Block(-5,46,-7,LEAVES:3)
Block(-5,50,-4,17:15)
Block(-5,50,-3,17:15)
Block(-5,51,-5,LEAVES:3)
Block(-5,51,-4,LEAVES:3)
Block(-5,51,-1,LEAVES:3)
Block(-5,51,0,17:15)
Block(-5,51,2,LEAVES:3)
Block(-5,51,4,17:15)
Block(-5,51,5,17:15)
Block(-5,52,-4,LEAVES:3)
Block(-5,52,0,17:15)
Block(-5,52,3,17:15)
Block(-5,52,6,17:15)
Block(-5,53,6,LEAVES:3)
Block(-5,55,-4,LEAVES:3)
Block(-5,55,-2,LEAVES:3)
Block(-5,60,-2,LEAVES:3)
Block(-5,60,1,LEAVES:3)
Block(-5,60,3,LEAVES:3)
Block(-5,60,5,LEAVES:3)
Block(-5,61,-6,LEAVES:3)
Block(-5,61,-5,LEAVES:3)
Block(-5,61,-4,17:15)
Block(-5,61,-3,LEAVES:3)
Block(-5,61,-2,17:15)
Block(-5,61,-1,LEAVES:3)
Block(-5,61,0,LEAVES:3)
Block(-5,61,2,LEAVES:3)
Block(-5,61,3,17:15)
Block(-5,61,4,LEAVES:3)
Block(-5,61,5,LEAVES:3)
Block(-5,62,-10,LEAVES:3)
Block(-5,62,-6,LEAVES:3)
Block(-5,62,-5,LEAVES:3)
Block(-5,62,-4,LEAVES:3)
Block(-5,62,-3,LEAVES:3)
Block(-5,62,-2,LEAVES:3)
Block(-5,62,3,LEAVES:3)
Block(-5,62,4,LEAVES:3)
Block(-5,62,5,LEAVES:3)
Block(-5,63,-12,LEAVES:3)
Block(-5,63,-11,LEAVES:3)
Block(-5,63,-10,LEAVES:3)
Block(-5,63,-7,LEAVES:3)
Block(-5,63,-4,LEAVES:3)
Block(-5,63,4,LEAVES:3)
Block(-5,64,-11,LEAVES:3)
Block(-5,67,0,LEAVES:3)
Block(-5,67,4,LEAVES:3)
Block(-5,68,-1,LEAVES:3)
Block(-5,68,3,LEAVES:3)
Block(-5,68,4,LEAVES:3)
Block(-5,68,5,LEAVES:3)
Block(-5,69,-3,LEAVES:3)
Block(-5,69,-2,17:15)
Block(-5,69,-1,LEAVES:3)
Block(-5,69,4,LEAVES:3)
Block(-5,70,-3,LEAVES:3)
Block(-5,70,-2,LEAVES:3)
Block(-5,70,-1,LEAVES:3)
Block(-5,71,-2,LEAVES:3)
Block(-5,74,-4,LEAVES:3)
Block(-5,74,-2,LEAVES:3)
Block(-5,74,3,LEAVES:3)
Block(-5,75,-3,LEAVES:3)
Block(-5,75,-2,LEAVES:3)
Block(-5,75,3,LEAVES:3)
Block(-4,-4,-2,17:15)
Block(-4,-4,2,17:15)
Block(-4,-3,-2,17:15)
Block(-4,-3,2,17:15)
Block(-4,-2,-2,17:15)
Block(-4,-2,0,17:15)
Block(-4,-2,2,17:15)
Block(-4,-1,-3,17:15)
Block(-4,-1,-2,17:15)
Block(-4,-1,0,17:15)
Block(-4,-1,2,17:15)
Block(-4,0,-3,17:15)
Block(-4,0,-2,17:15)
Block(-4,0,0,17:15)
Block(-4,0,2,17:15)
Block(-4,1,-3,17:15)
Block(-4,1,-2,17:15)
Block(-4,1,0,17:15)
Block(-4,2,-3,17:15)
Block(-4,2,-2,17:15)
Block(-4,2,0,17:15)
Block(-4,3,-2,17:15)
Block(-4,24,-4,17:15)
Block(-4,24,-3,17:15)
Block(-4,24,-2,17:15)
Block(-4,24,2,LEAVES:3)
Block(-4,25,-8,LEAVES:3)
Block(-4,25,-7,LEAVES:3)
Block(-4,25,-6,17:15)
Block(-4,25,-4,LEAVES:3)
Block(-4,25,-3,17:15)
Block(-4,25,-2,LEAVES:3)
Block(-4,25,-1,LEAVES:3)
Block(-4,25,0,LEAVES:3)
Block(-4,25,1,17:15)
Block(-4,25,2,LEAVES:3)
Block(-4,25,3,LEAVES:3)
Block(-4,25,5,LEAVES:3)
Block(-4,26,-7,LEAVES:3)
Block(-4,26,-6,LEAVES:3)
Block(-4,26,-3,LEAVES:3)
Block(-4,26,-2,LEAVES:3)
Block(-4,26,-1,LEAVES:3)
Block(-4,26,1,LEAVES:3)
Block(-4,26,2,LEAVES:3)
Block(-4,26,3,LEAVES:3)
Block(-4,26,4,LEAVES:3)
Block(-4,26,5,17:15)
Block(-4,26,6,LEAVES:3)
Block(-4,26,7,LEAVES:3)
Block(-4,26,8,LEAVES:3)
Block(-4,27,-6,LEAVES:3)
Block(-4,27,-2,LEAVES:3)
Block(-4,27,1,LEAVES:3)
Block(-4,27,4,LEAVES:3)
Block(-4,27,5,LEAVES:3)
Block(-4,34,4,LEAVES:3)
Block(-4,34,5,LEAVES:3)
Block(-4,34,6,LEAVES:3)
Block(-4,34,7,LEAVES:3)
Block(-4,34,8,LEAVES:3)
Block(-4,34,9,LEAVES:3)
Block(-4,34,11,LEAVES:3)
Block(-4,34,12,LEAVES:3)
Block(-4,35,-1,17:15)
Block(-4,35,2,LEAVES:3)
Block(-4,35,3,LEAVES:3)
Block(-4,35,4,LEAVES:3)
Block(-4,35,5,17:15)
Block(-4,35,6,LEAVES:3)
Block(-4,35,7,LEAVES:3)
Block(-4,35,10,LEAVES:3)
Block(-4,35,11,17:15)
Block(-4,35,12,LEAVES:3)
Block(-4,36,-2,LEAVES:3)
Block(-4,36,-1,17:15)
Block(-4,36,0,17:15)
Block(-4,36,3,LEAVES:3)
Block(-4,36,4,LEAVES:3)
Block(-4,36,5,LEAVES:3)
Block(-4,36,6,LEAVES:3)
Block(-4,36,11,LEAVES:3)
Block(-4,37,-2,LEAVES:3)
Block(-4,37,1,17:15)
Block(-4,37,2,LEAVES:3)
Block(-4,37,5,LEAVES:3)
Block(-4,39,0,LEAVES:3)
Block(-4,40,1,LEAVES:3)
Block(-4,40,2,17:15)
Block(-4,40,3,17:15)
Block(-4,41,-13,LEAVES:3)
Block(-4,41,-7,17:15)
Block(-4,41,-1,LEAVES:3)
Block(-4,41,0,LEAVES:3)
Block(-4,41,1,LEAVES:3)
Block(-4,41,2,LEAVES:3)
Block(-4,41,3,LEAVES:3)
Block(-4,42,-18,LEAVES:3)
Block(-4,42,-13,LEAVES:3)
Block(-4,42,-11,17:15)
Block(-4,42,-8,LEAVES:3)
Block(-4,42,-7,17:15)
Block(-4,42,-6,LEAVES:3)
Block(-4,42,0,LEAVES:3)
Block(-4,42,1,LEAVES:3)
Block(-4,42,2,LEAVES:3)
Block(-4,42,6,LEAVES:3)
Block(-4,42,11,LEAVES:3)
Block(-4,43,-17,LEAVES:3)
Block(-4,43,-16,LEAVES:3)
Block(-4,43,-12,LEAVES:3)
Block(-4,43,-11,17:15)
Block(-4,43,-10,17:15)
Block(-4,43,-9,17:15)
Block(-4,43,-6,LEAVES:3)
Block(-4,43,-5,LEAVES:3)
Block(-4,43,2,LEAVES:3)
Block(-4,43,5,LEAVES:3)
Block(-4,43,6,17:15)
Block(-4,43,7,LEAVES:3)
Block(-4,43,10,LEAVES:3)
Block(-4,44,-14,LEAVES:3)
Block(-4,44,-10,LEAVES:3)
Block(-4,44,-9,LEAVES:3)
Block(-4,44,-8,17:15)
Block(-4,44,-7,LEAVES:3)
Block(-4,44,6,LEAVES:3)
Block(-4,44,11,LEAVES:3)
Block(-4,44,12,LEAVES:3)
Block(-4,44,13,LEAVES:3)
Block(-4,45,-14,LEAVES:3)
Block(-4,45,-13,17:15)
Block(-4,45,-12,17:15)
Block(-4,45,-11,LEAVES:3)
Block(-4,45,-10,LEAVES:3)
Block(-4,45,-9,LEAVES:3)
Block(-4,45,-7,LEAVES:3)
Block(-4,45,12,LEAVES:3)
Block(-4,46,-17,LEAVES:3)
Block(-4,46,-16,LEAVES:3)
Block(-4,46,-15,LEAVES:3)
Block(-4,46,-13,LEAVES:3)
Block(-4,46,-12,LEAVES:3)
Block(-4,46,-11,LEAVES:3)
Block(-4,47,-15,LEAVES:3)
Block(-4,47,-12,LEAVES:3)
Block(-4,50,-5,17:15)
Block(-4,50,-2,17:15)
Block(-4,51,-1,17:15)
Block(-4,51,0,17:15)
Block(-4,51,2,17:15)
Block(-4,52,0,17:15)
Block(-4,52,2,17:15)
Block(-4,53,2,LEAVES:3)
Block(-4,53,3,LEAVES:3)
Block(-4,54,2,LEAVES:3)
Block(-4,55,-4,17:15)
Block(-4,55,-2,LEAVES:3)
Block(-4,56,-2,LEAVES:3)
Block(-4,59,1,LEAVES:3)
Block(-4,60,-5,LEAVES:3)
Block(-4,60,-3,LEAVES:3)
Block(-4,60,1,17:15)
Block(-4,60,4,LEAVES:3)
Block(-4,61,-4,LEAVES:3)
Block(-4,61,-3,17:15)
Block(-4,61,-2,17:15)
Block(-4,61,-1,LEAVES:3)
Block(-4,61,0,LEAVES:3)
Block(-4,61,1,LEAVES:3)
Block(-4,61,2,17:15)
Block(-4,61,3,LEAVES:3)
Block(-4,61,4,LEAVES:3)
Block(-4,62,-12,LEAVES:3)
Block(-4,62,-11,LEAVES:3)
Block(-4,62,-9,LEAVES:3)
Block(-4,62,-8,LEAVES:3)
Block(-4,62,-4,LEAVES:3)
Block(-4,62,-2,LEAVES:3)
Block(-4,62,-1,LEAVES:3)
Block(-4,62,0,LEAVES:3)
Block(-4,62,1,LEAVES:3)
Block(-4,62,2,LEAVES:3)
Block(-4,62,3,LEAVES:3)
Block(-4,63,-13,LEAVES:3)
Block(-4,63,-12,LEAVES:3)
Block(-4,63,-11,17:15)
Block(-4,63,-10,LEAVES:3)
Block(-4,63,-9,LEAVES:3)
Block(-4,63,-8,LEAVES:3)
Block(-4,63,-7,LEAVES:3)
Block(-4,63,-6,LEAVES:3)
Block(-4,63,0,LEAVES:3)
Block(-4,64,-12,LEAVES:3)
Block(-4,64,-11,LEAVES:3)
Block(-4,64,-7,LEAVES:3)
Block(-4,67,3,LEAVES:3)
Block(-4,67,6,LEAVES:3)
Block(-4,68,-3,LEAVES:3)
Block(-4,68,-2,17:15)
Block(-4,68,-1,LEAVES:3)
Block(-4,68,0,LEAVES:3)
Block(-4,68,3,LEAVES:3)
Block(-4,68,4,17:15)
Block(-4,68,5,LEAVES:3)
Block(-4,68,6,LEAVES:3)
Block(-4,69,-2,LEAVES:3)
Block(-4,69,-1,LEAVES:3)
Block(-4,69,4,LEAVES:3)
Block(-4,69,5,LEAVES:3)
Block(-4,70,-2,LEAVES:3)
Block(-4,70,4,LEAVES:3)
Block(-4,74,-6,LEAVES:3)
Block(-4,74,4,LEAVES:3)
Block(-4,75,-5,LEAVES:3)
Block(-4,75,-4,LEAVES:3)
Block(-4,75,-3,LEAVES:3)
Block(-4,75,-2,LEAVES:3)
Block(-4,75,2,LEAVES:3)
Block(-4,75,3,LEAVES:3)
Block(-4,75,4,LEAVES:3)
Block(-4,76,-4,LEAVES:3)
Block(-4,76,-3,LEAVES:3)
Block(-4,76,3,LEAVES:3)
Block(-3,-4,-3,17:15)
Block(-3,-4,-2,17:15)
Block(-3,-3,-3,17:15)
Block(-3,-3,-1,17:15)
Block(-3,-3,2,17:15)
Block(-3,-2,-3,17:15)
Block(-3,-2,-2,17:15)
Block(-3,-2,-1,17:15)
Block(-3,-2,2,17:15)
Block(-3,-2,3,17:15)
Block(-3,-1,-3,17:15)
Block(-3,-1,-1,17:15)
Block(-3,-1,0,17:15)
Block(-3,-1,2,17:15)
Block(-3,-1,3,17:15)
Block(-3,0,-3,17:15)
Block(-3,0,-1,17:15)
Block(-3,0,0,17:15)
Block(-3,0,2,17:15)
Block(-3,0,3,17:15)
Block(-3,1,-3,17:15)
Block(-3,1,-2,17:15)
Block(-3,1,-1,17:15)
Block(-3,1,0,17:15)
Block(-3,1,2,17:15)
Block(-3,1,3,17:15)
Block(-3,2,-2,17:15)
Block(-3,2,0,17:15)
Block(-3,2,3,17:15)
Block(-3,3,-2,17:15)
Block(-3,3,0,17:15)
Block(-3,4,-2,17:15)
Block(-3,5,-2,17:15)
Block(-3,23,1,LEAVES:3)
Block(-3,24,-3,LEAVES:3)
Block(-3,24,-2,17:15)
Block(-3,25,-9,LEAVES:3)
Block(-3,25,-8,LEAVES:3)
Block(-3,25,-7,17:15)
Block(-3,25,-5,LEAVES:3)
Block(-3,25,-4,LEAVES:3)
Block(-3,25,-3,LEAVES:3)
Block(-3,25,-2,LEAVES:3)
Block(-3,25,-1,LEAVES:3)
Block(-3,25,0,LEAVES:3)
Block(-3,25,1,LEAVES:3)
Block(-3,25,2,LEAVES:3)
Block(-3,25,8,LEAVES:3)
Block(-3,26,-8,LEAVES:3)
Block(-3,26,-7,LEAVES:3)
Block(-3,26,-6,LEAVES:3)
Block(-3,26,-5,LEAVES:3)
Block(-3,26,-4,LEAVES:3)
Block(-3,26,-2,LEAVES:3)
Block(-3,26,1,LEAVES:3)
Block(-3,26,4,LEAVES:3)
Block(-3,26,5,LEAVES:3)
Block(-3,26,6,17:15)
Block(-3,26,7,LEAVES:3)
Block(-3,26,8,LEAVES:3)
Block(-3,27,-4,LEAVES:3)
Block(-3,27,6,LEAVES:3)
Block(-3,27,7,LEAVES:3)
Block(-3,33,5,LEAVES:3)
Block(-3,33,9,LEAVES:3)
Block(-3,34,2,LEAVES:3)
Block(-3,34,6,LEAVES:3)
Block(-3,34,7,17:15)
Block(-3,34,8,LEAVES:3)
Block(-3,34,10,LEAVES:3)
Block(-3,34,11,17:15)
Block(-3,34,12,LEAVES:3)
Block(-3,34,15,LEAVES:3)
Block(-3,35,-1,17:15)
Block(-3,35,3,LEAVES:3)
Block(-3,35,4,LEAVES:3)
Block(-3,35,5,LEAVES:3)
Block(-3,35,6,17:15)
Block(-3,35,7,LEAVES:3)
Block(-3,35,10,LEAVES:3)
Block(-3,35,11,LEAVES:3)
Block(-3,35,12,LEAVES:3)
Block(-3,35,13,LEAVES:3)
Block(-3,35,14,LEAVES:3)
Block(-3,36,-2,LEAVES:3)
Block(-3,36,6,LEAVES:3)
Block(-3,36,7,LEAVES:3)
Block(-3,39,1,LEAVES:3)
Block(-3,39,2,17:15)
Block(-3,40,-1,LEAVES:3)
Block(-3,40,1,LEAVES:3)
Block(-3,40,2,17:15)
Block(-3,40,3,LEAVES:3)
Block(-3,41,-6,17:15)
Block(-3,41,0,LEAVES:3)
Block(-3,41,1,LEAVES:3)
Block(-3,41,2,LEAVES:3)
Block(-3,42,-16,LEAVES:3)
Block(-3,42,-14,LEAVES:3)
Block(-3,42,-13,17:15)
Block(-3,42,-12,17:15)
Block(-3,42,-8,17:15)
Block(-3,42,-7,17:15)
Block(-3,42,-6,17:15)
Block(-3,42,4,LEAVES:3)
Block(-3,42,5,17:15)
Block(-3,42,9,LEAVES:3)
Block(-3,43,-12,LEAVES:3)
Block(-3,43,-9,17:15)
Block(-3,43,-8,17:15)
Block(-3,43,-7,LEAVES:3)
Block(-3,43,-6,LEAVES:3)
Block(-3,43,-5,LEAVES:3)
Block(-3,43,-4,LEAVES:3)
Block(-3,43,4,LEAVES:3)
Block(-3,43,5,LEAVES:3)
Block(-3,43,6,LEAVES:3)
Block(-3,43,9,LEAVES:3)
Block(-3,43,10,LEAVES:3)
Block(-3,43,11,LEAVES:3)
Block(-3,43,13,LEAVES:3)
Block(-3,44,-8,LEAVES:3)
Block(-3,44,-6,LEAVES:3)
Block(-3,44,-5,LEAVES:3)
Block(-3,44,5,LEAVES:3)
Block(-3,44,10,LEAVES:3)
Block(-3,44,11,LEAVES:3)
Block(-3,44,12,17:15)
Block(-3,44,13,LEAVES:3)
Block(-3,44,14,LEAVES:3)
Block(-3,45,-18,LEAVES:3)
Block(-3,45,-15,LEAVES:3)
Block(-3,45,-14,17:15)
Block(-3,45,-13,LEAVES:3)
Block(-3,45,-12,LEAVES:3)
Block(-3,45,-11,LEAVES:3)
Block(-3,45,-6,LEAVES:3)
Block(-3,45,12,LEAVES:3)
Block(-3,45,13,LEAVES:3)
Block(-3,46,-18,LEAVES:3)
Block(-3,46,-17,LEAVES:3)
Block(-3,46,-16,17:15)
Block(-3,46,-15,17:15)
Block(-3,46,-14,LEAVES:3)
Block(-3,46,-12,17:15)
Block(-3,46,-11,LEAVES:3)
Block(-3,47,-17,LEAVES:3)
Block(-3,47,-16,LEAVES:3)
Block(-3,47,-15,LEAVES:3)
Block(-3,47,-12,LEAVES:3)
Block(-3,47,-11,LEAVES:3)
Block(-3,48,-15,LEAVES:3)
Block(-3,51,-8,LEAVES:3)
Block(-3,51,-7,LEAVES:3)
Block(-3,51,-6,17:15)
Block(-3,51,0,17:15)
Block(-3,51,1,17:15)
Block(-3,52,-6,LEAVES:3)
Block(-3,54,8,LEAVES:3)
Block(-3,55,-7,LEAVES:3)
Block(-3,55,-6,LEAVES:3)
Block(-3,55,-5,17:15)
Block(-3,55,-3,17:15)
Block(-3,55,-2,17:15)
Block(-3,56,-5,LEAVES:3)
Block(-3,60,-2,17:15)
Block(-3,60,-1,17:15)
Block(-3,60,0,17:15)
Block(-3,60,2,LEAVES:3)
Block(-3,61,-12,LEAVES:3)
Block(-3,61,-5,LEAVES:3)
Block(-3,61,-4,LEAVES:3)
Block(-3,61,-3,LEAVES:3)
Block(-3,61,-2,LEAVES:3)
Block(-3,61,-1,LEAVES:3)
Block(-3,61,0,LEAVES:3)
Block(-3,61,1,LEAVES:3)
Block(-3,61,2,LEAVES:3)
Block(-3,61,3,LEAVES:3)
Block(-3,62,-13,LEAVES:3)
Block(-3,62,-10,LEAVES:3)
Block(-3,62,-7,LEAVES:3)
Block(-3,62,-6,LEAVES:3)
Block(-3,62,-1,LEAVES:3)
Block(-3,62,0,LEAVES:3)
Block(-3,62,1,LEAVES:3)
Block(-3,62,2,LEAVES:3)
Block(-3,63,-12,LEAVES:3)
Block(-3,63,-11,LEAVES:3)
Block(-3,63,-10,LEAVES:3)
Block(-3,63,-9,LEAVES:3)
Block(-3,63,-8,LEAVES:3)
Block(-3,63,-7,17:15)
Block(-3,63,-6,LEAVES:3)
Block(-3,63,0,LEAVES:3)
Block(-3,63,1,LEAVES:3)
Block(-3,64,-10,17:15)
Block(-3,64,-9,LEAVES:3)
Block(-3,64,-7,LEAVES:3)
Block(-3,64,0,LEAVES:3)
Block(-3,65,-10,LEAVES:3)
Block(-3,67,3,17:15)
Block(-3,67,4,LEAVES:3)
Block(-3,68,-1,17:15)
Block(-3,68,0,LEAVES:3)
Block(-3,68,1,LEAVES:3)
Block(-3,68,3,LEAVES:3)
Block(-3,68,5,LEAVES:3)
Block(-3,69,-2,LEAVES:3)
Block(-3,69,-1,LEAVES:3)
Block(-3,69,0,LEAVES:3)
Block(-3,69,4,LEAVES:3)
Block(-3,73,-5,LEAVES:3)
Block(-3,73,0,LEAVES:3)
Block(-3,73,6,LEAVES:3)
Block(-3,74,-4,LEAVES:3)
Block(-3,74,-2,LEAVES:3)
Block(-3,74,-1,LEAVES:3)
Block(-3,74,2,LEAVES:3)
Block(-3,75,-6,LEAVES:3)
Block(-3,75,-5,LEAVES:3)
Block(-3,75,-4,LEAVES:3)
Block(-3,75,-3,17:15)
Block(-3,75,2,LEAVES:3)
Block(-3,75,3,17:15)
Block(-3,75,4,LEAVES:3)
Block(-3,75,5,LEAVES:3)
Block(-3,75,6,LEAVES:3)
Block(-3,76,-5,LEAVES:3)
Block(-3,76,-4,LEAVES:3)
Block(-3,76,-3,LEAVES:3)
Block(-3,76,3,LEAVES:3)
Block(-3,76,4,LEAVES:3)
Block(-3,77,-4,LEAVES:3)
Block(-2,-4,5,17:15)
Block(-2,-3,5,17:15)
Block(-2,-2,1,17:15)
Block(-2,-2,4,17:15)
Block(-2,-2,5,17:15)
Block(-2,-1,-4,17:15)
Block(-2,-1,-3,17:15)
Block(-2,-1,0,17:15)
Block(-2,-1,1,17:15)
Block(-2,-1,4,17:15)
Block(-2,-1,5,17:15)
Block(-2,0,-3,17:15)
Block(-2,0,0,17:15)
Block(-2,0,1,17:15)
Block(-2,0,4,17:15)
Block(-2,0,5,17:15)
Block(-2,1,-4,17:15)
Block(-2,1,-3,17:15)
Block(-2,1,0,17:15)
Block(-2,1,1,17:15)
Block(-2,1,4,17:15)
Block(-2,2,-3,17:15)
Block(-2,2,0,17:15)
Block(-2,2,1,17:15)
Block(-2,2,4,17:15)
Block(-2,3,-3,17:15)
Block(-2,3,-2,17:15)
Block(-2,3,-1,17:15)
Block(-2,3,0,17:15)
Block(-2,3,1,17:15)
Block(-2,3,4,17:15)
Block(-2,4,-1,17:15)
Block(-2,4,0,17:15)
Block(-2,4,1,17:15)
Block(-2,5,-2,17:15)
Block(-2,5,-1,17:15)
Block(-2,5,0,17:15)
Block(-2,5,1,17:15)
Block(-2,6,-1,17:15)
Block(-2,6,0,17:15)
Block(-2,7,0,17:15)
Block(-2,8,0,17:15)
Block(-2,9,0,17:15)
Block(-2,10,0,17:15)
Block(-2,11,0,17:15)
Block(-2,12,0,17:15)
Block(-2,13,0,17:15)
Block(-2,14,0,17:15)
Block(-2,15,0,17:15)
Block(-2,23,-2,17:15)
Block(-2,23,-1,17:15)
Block(-2,24,-9,LEAVES:3)
Block(-2,24,-5,LEAVES:3)
Block(-2,24,-2,17:15)
Block(-2,24,-1,LEAVES:3)
Block(-2,24,2,LEAVES:3)
Block(-2,25,-8,LEAVES:3)
Block(-2,25,-5,LEAVES:3)
Block(-2,25,-4,LEAVES:3)
Block(-2,25,-3,LEAVES:3)
Block(-2,25,1,LEAVES:3)
Block(-2,25,2,LEAVES:3)
Block(-2,25,4,LEAVES:3)
Block(-2,25,6,LEAVES:3)
Block(-2,26,-9,LEAVES:3)
Block(-2,26,-8,LEAVES:3)
Block(-2,26,-7,17:15)
Block(-2,26,-6,LEAVES:3)
Block(-2,26,-4,LEAVES:3)
Block(-2,26,5,LEAVES:3)
Block(-2,26,6,LEAVES:3)
Block(-2,26,7,LEAVES:3)
Block(-2,27,-8,LEAVES:3)
Block(-2,27,-7,LEAVES:3)
Block(-2,27,5,LEAVES:3)
Block(-2,27,6,LEAVES:3)
Block(-2,32,8,LEAVES:3)
Block(-2,32,10,LEAVES:3)
Block(-2,33,8,17:15)
Block(-2,33,9,17:15)
Block(-2,33,10,17:15)
Block(-2,33,11,LEAVES:3)
Block(-2,34,-1,17:15)
Block(-2,34,5,LEAVES:3)
Block(-2,34,6,LEAVES:3)
Block(-2,34,7,17:15)
Block(-2,34,8,17:15)
Block(-2,34,9,LEAVES:3)
Block(-2,34,10,17:15)
Block(-2,34,11,LEAVES:3)
Block(-2,34,12,LEAVES:3)
Block(-2,34,13,LEAVES:3)
Block(-2,34,14,LEAVES:3)
Block(-2,35,-1,17:15)
Block(-2,35,7,LEAVES:3)
Block(-2,35,10,LEAVES:3)
Block(-2,35,11,LEAVES:3)
Block(-2,35,12,LEAVES:3)
Block(-2,35,13,17:15)
Block(-2,35,14,LEAVES:3)
Block(-2,35,15,LEAVES:3)
Block(-2,36,11,LEAVES:3)
Block(-2,36,13,LEAVES:3)
Block(-2,36,14,LEAVES:3)
Block(-2,37,13,LEAVES:3)
Block(-2,38,-6,LEAVES:3)
Block(-2,39,1,17:15)
Block(-2,39,2,17:15)
Block(-2,39,3,17:15)
Block(-2,40,-5,17:15)
Block(-2,40,-4,17:15)
Block(-2,40,-3,17:15)
Block(-2,40,1,17:15)
Block(-2,40,2,LEAVES:3)
Block(-2,40,3,17:15)
Block(-2,40,4,17:15)
Block(-2,41,-14,LEAVES:3)
Block(-2,41,-6,17:15)
Block(-2,41,-5,17:15)
Block(-2,41,-4,17:15)
Block(-2,41,4,17:15)
Block(-2,41,5,17:15)
Block(-2,42,-13,LEAVES:3)
Block(-2,42,-9,LEAVES:3)
Block(-2,42,-8,LEAVES:3)
Block(-2,42,4,LEAVES:3)
Block(-2,42,5,LEAVES:3)
Block(-2,42,10,LEAVES:3)
Block(-2,43,-12,LEAVES:3)
Block(-2,43,-11,LEAVES:3)
Block(-2,43,-9,17:15)
Block(-2,43,-6,LEAVES:3)
Block(-2,43,-5,LEAVES:3)
Block(-2,43,5,LEAVES:3)
Block(-2,43,8,LEAVES:3)
Block(-2,43,9,LEAVES:3)
Block(-2,43,10,LEAVES:3)
Block(-2,44,-12,LEAVES:3)
Block(-2,44,-6,LEAVES:3)
Block(-2,44,9,LEAVES:3)
Block(-2,44,10,LEAVES:3)
Block(-2,44,11,17:15)
Block(-2,44,12,LEAVES:3)
Block(-2,44,14,LEAVES:3)
Block(-2,45,-16,LEAVES:3)
Block(-2,45,-15,LEAVES:3)
Block(-2,45,-14,LEAVES:3)
Block(-2,45,-13,LEAVES:3)
Block(-2,45,-11,LEAVES:3)
Block(-2,45,-9,LEAVES:3)
Block(-2,45,11,LEAVES:3)
Block(-2,45,12,LEAVES:3)
Block(-2,45,13,LEAVES:3)
Block(-2,46,-17,LEAVES:3)
Block(-2,46,-16,LEAVES:3)
Block(-2,46,-15,LEAVES:3)
Block(-2,46,-14,LEAVES:3)
Block(-2,46,-12,LEAVES:3)
Block(-2,46,-11,17:15)
Block(-2,46,-10,LEAVES:3)
Block(-2,46,11,LEAVES:3)
Block(-2,47,-16,LEAVES:3)
Block(-2,47,-11,LEAVES:3)
Block(-2,48,-11,LEAVES:3)
Block(-2,50,0,17:15)
Block(-2,51,-6,LEAVES:3)
Block(-2,51,0,17:15)
Block(-2,51,1,17:15)
Block(-2,52,7,LEAVES:3)
Block(-2,53,8,LEAVES:3)
Block(-2,53,10,LEAVES:3)
Block(-2,54,-1,17:15)
Block(-2,54,0,17:15)
Block(-2,54,6,LEAVES:3)
Block(-2,54,8,LEAVES:3)
Block(-2,54,9,LEAVES:3)
Block(-2,55,-6,LEAVES:3)
Block(-2,55,-1,17:15)
Block(-2,55,8,LEAVES:3)
Block(-2,56,-3,17:15)
Block(-2,57,-3,LEAVES:3)
Block(-2,60,-2,17:15)
Block(-2,60,1,LEAVES:3)
Block(-2,61,-8,LEAVES:3)
Block(-2,61,-6,LEAVES:3)
Block(-2,61,0,LEAVES:3)
Block(-2,62,-11,LEAVES:3)
Block(-2,62,-9,LEAVES:3)
Block(-2,62,-8,17:15)
Block(-2,62,-7,17:15)
Block(-2,62,-6,LEAVES:3)
Block(-2,62,-5,LEAVES:3)
Block(-2,62,0,LEAVES:3)
Block(-2,62,1,LEAVES:3)
Block(-2,63,-12,LEAVES:3)
Block(-2,63,-11,LEAVES:3)
Block(-2,63,-10,LEAVES:3)
Block(-2,63,-9,17:15)
Block(-2,63,-8,LEAVES:3)
Block(-2,63,-7,LEAVES:3)
Block(-2,63,-6,LEAVES:3)
Block(-2,63,0,LEAVES:3)
Block(-2,64,-11,LEAVES:3)
Block(-2,64,-10,LEAVES:3)
Block(-2,64,-9,LEAVES:3)
Block(-2,64,-8,LEAVES:3)
Block(-2,65,-10,LEAVES:3)
Block(-2,67,-2,LEAVES:3)
Block(-2,67,-1,17:15)
Block(-2,67,2,LEAVES:3)
Block(-2,67,3,17:15)
Block(-2,67,4,LEAVES:3)
Block(-2,67,5,LEAVES:3)
Block(-2,67,7,LEAVES:3)
Block(-2,68,-1,LEAVES:3)
Block(-2,68,2,LEAVES:3)
Block(-2,68,3,LEAVES:3)
Block(-2,68,4,LEAVES:3)
Block(-2,68,5,LEAVES:3)
Block(-2,68,6,LEAVES:3)
Block(-2,69,3,LEAVES:3)
Block(-2,69,5,LEAVES:3)
Block(-2,70,-2,LEAVES:3)
Block(-2,73,4,LEAVES:3)
Block(-2,74,-5,LEAVES:3)
Block(-2,74,-3,LEAVES:3)
Block(-2,74,-2,17:15)
Block(-2,74,-1,LEAVES:3)
Block(-2,74,2,LEAVES:3)
Block(-2,74,3,17:15)
Block(-2,74,6,LEAVES:3)
Block(-2,74,8,LEAVES:3)
Block(-2,75,-5,LEAVES:3)
Block(-2,75,-4,LEAVES:3)
Block(-2,75,-3,LEAVES:3)
Block(-2,75,-2,LEAVES:3)
Block(-2,75,-1,LEAVES:3)
Block(-2,75,0,LEAVES:3)
Block(-2,75,3,LEAVES:3)
Block(-2,75,5,LEAVES:3)
Block(-2,75,6,LEAVES:3)
Block(-2,75,7,LEAVES:3)
Block(-2,76,-4,LEAVES:3)
Block(-2,76,-1,LEAVES:3)
Block(-2,76,6,LEAVES:3)
Block(-2,76,7,LEAVES:3)
Block(-1,-4,-6,17:15)
Block(-1,-3,-6,17:15)
Block(-1,-3,-5,17:15)
Block(-1,-3,1,17:15)
Block(-1,-2,-6,17:15)
Block(-1,-2,-5,17:15)
Block(-1,-2,-4,17:15)
Block(-1,-2,1,17:15)
Block(-1,-1,-6,17:15)
Block(-1,-1,-5,17:15)
Block(-1,-1,-4,17:15)
Block(-1,-1,1,17:15)
Block(-1,-1,3,17:15)
Block(-1,-1,4,17:15)
Block(-1,0,-6,17:15)
Block(-1,0,-5,17:15)
Block(-1,0,-4,17:15)
Block(-1,0,1,17:15)
Block(-1,0,2,17:15)
Block(-1,0,3,17:15)
Block(-1,1,-4,17:15)
Block(-1,1,-3,17:15)
Block(-1,1,-2,17:15)
Block(-1,1,1,17:15)
Block(-1,1,2,17:15)
Block(-1,1,3,17:15)
Block(-1,1,4,17:15)
Block(-1,2,-4,17:15)
Block(-1,2,-3,17:15)
Block(-1,2,-2,17:15)
Block(-1,2,0,17:15)
Block(-1,2,1,17:15)
Block(-1,2,2,17:15)
Block(-1,2,3,17:15)
Block(-1,3,-3,17:15)
Block(-1,3,-2,17:15)
Block(-1,3,-1,17:15)
Block(-1,3,0,17:15)
Block(-1,3,1,17:15)
Block(-1,3,2,17:15)
Block(-1,3,3,17:15)
Block(-1,4,-3,17:15)
Block(-1,4,-2,17:15)
Block(-1,4,-1,17:15)
Block(-1,4,0,17:15)
Block(-1,4,1,17:15)
Block(-1,4,2,17:15)
Block(-1,5,-3,17:15)
Block(-1,5,-2,17:15)
Block(-1,5,-1,17:15)
Block(-1,5,0,17:15)
Block(-1,5,1,17:15)
Block(-1,5,2,17:15)
Block(-1,6,-3,17:15)
Block(-1,6,-2,17:15)
Block(-1,6,-1,17:15)
Block(-1,6,0,17:15)
Block(-1,6,1,17:15)
Block(-1,6,2,17:15)
Block(-1,7,-2,17:15)
Block(-1,7,-1,17:15)
Block(-1,7,0,17:15)
Block(-1,7,1,17:15)
Block(-1,8,-2,17:15)
Block(-1,8,-1,17:15)
Block(-1,8,0,17:15)
Block(-1,8,1,17:15)
Block(-1,9,-2,17:15)
Block(-1,9,-1,17:15)
Block(-1,9,0,17:15)
Block(-1,9,1,17:15)
Block(-1,10,-2,17:15)
Block(-1,10,-1,17:15)
Block(-1,10,0,17:15)
Block(-1,10,1,17:15)
Block(-1,11,-2,17:15)
Block(-1,11,-1,17:15)
Block(-1,11,0,17:15)
Block(-1,11,1,17:15)
Block(-1,12,-2,17:15)
Block(-1,12,-1,17:15)
Block(-1,12,0,17:15)
Block(-1,12,1,17:15)
Block(-1,13,-2,17:15)
Block(-1,13,-1,17:15)
Block(-1,13,0,17:15)
Block(-1,13,1,17:15)
Block(-1,14,-2,17:15)
Block(-1,14,-1,17:15)
Block(-1,14,0,17:15)
Block(-1,14,1,17:15)
Block(-1,15,-2,17:15)
Block(-1,15,-1,17:15)
Block(-1,15,0,17:15)
Block(-1,15,1,17:15)
Block(-1,16,-2,17:15)
Block(-1,16,-1,17:15)
Block(-1,16,0,17:15)
Block(-1,16,1,17:15)
Block(-1,17,-2,17:15)
Block(-1,17,-1,17:15)
Block(-1,17,0,17:15)
Block(-1,17,1,17:15)
Block(-1,18,-2,17:15)
Block(-1,18,-1,17:15)
Block(-1,18,0,17:15)
Block(-1,18,1,17:15)
Block(-1,19,-1,17:15)
Block(-1,19,0,17:15)
Block(-1,19,1,17:15)
Block(-1,20,-1,17:15)
Block(-1,20,0,17:15)
Block(-1,20,1,17:15)
Block(-1,21,-1,17:15)
Block(-1,21,0,17:15)
Block(-1,21,1,17:15)
Block(-1,22,-1,17:15)
Block(-1,22,0,17:15)
Block(-1,22,1,17:15)
Block(-1,23,-1,17:15)
Block(-1,23,0,17:15)
Block(-1,23,1,17:15)
Block(-1,24,-3,LEAVES:3)
Block(-1,24,-1,17:15)
Block(-1,24,0,17:15)
Block(-1,25,-10,LEAVES:3)
Block(-1,25,-7,LEAVES:3)
Block(-1,25,-4,LEAVES:3)
Block(-1,25,-1,17:15)
Block(-1,25,0,17:15)
Block(-1,26,-11,LEAVES:3)
Block(-1,26,-10,LEAVES:3)
Block(-1,26,-9,LEAVES:3)
Block(-1,26,-8,17:15)
Block(-1,26,-7,LEAVES:3)
Block(-1,26,-1,17:15)
Block(-1,26,0,17:15)
Block(-1,27,-10,LEAVES:3)
Block(-1,27,-9,LEAVES:3)
Block(-1,27,-8,LEAVES:3)
Block(-1,27,-7,LEAVES:3)
Block(-1,27,-1,17:15)
Block(-1,27,0,17:15)
Block(-1,28,-8,LEAVES:3)
Block(-1,28,-1,17:15)
Block(-1,28,0,17:15)
Block(-1,29,-1,17:15)
Block(-1,29,0,17:15)
Block(-1,29,1,17:15)
Block(-1,30,-1,17:15)
Block(-1,30,0,17:15)
Block(-1,31,-1,17:15)
Block(-1,31,0,17:15)
Block(-1,31,4,LEAVES:3)
Block(-1,31,9,LEAVES:3)
Block(-1,32,-1,17:15)
Block(-1,32,0,17:15)
Block(-1,32,7,LEAVES:3)
Block(-1,32,8,17:15)
Block(-1,32,9,17:15)
Block(-1,33,-1,17:15)
Block(-1,33,0,17:15)
Block(-1,33,4,LEAVES:3)
Block(-1,33,7,LEAVES:3)
Block(-1,33,9,17:15)
Block(-1,34,-1,17:15)
Block(-1,34,0,17:15)
Block(-1,34,4,LEAVES:3)
Block(-1,34,5,LEAVES:3)
Block(-1,34,6,17:15)
Block(-1,34,7,LEAVES:3)
Block(-1,34,10,LEAVES:3)
Block(-1,34,11,LEAVES:3)
Block(-1,34,12,LEAVES:3)
Block(-1,34,16,LEAVES:3)
Block(-1,35,-1,17:15)
Block(-1,35,0,17:15)
Block(-1,35,5,LEAVES:3)
Block(-1,35,6,LEAVES:3)
Block(-1,35,11,LEAVES:3)
Block(-1,35,13,17:15)
Block(-1,35,14,LEAVES:3)
Block(-1,35,15,LEAVES:3)
Block(-1,35,16,LEAVES:3)
Block(-1,35,23,LEAVES:3)
Block(-1,36,-1,17:15)
Block(-1,36,0,17:15)
Block(-1,36,13,LEAVES:3)
Block(-1,36,15,LEAVES:3)
Block(-1,36,22,LEAVES:3)
Block(-1,37,-1,17:15)
Block(-1,37,0,17:15)
Block(-1,38,-7,LEAVES:3)
Block(-1,38,-6,17:15)
Block(-1,38,-1,17:15)
Block(-1,38,0,17:15)
Block(-1,39,-3,17:15)
Block(-1,39,-2,17:15)
Block(-1,39,-1,17:15)
Block(-1,39,1,17:15)
Block(-1,40,-4,17:15)
Block(-1,40,-3,17:15)
Block(-1,40,-2,17:15)
Block(-1,40,-1,17:15)
Block(-1,40,1,17:15)
Block(-1,41,-1,17:15)
Block(-1,41,1,LEAVES:3)
Block(-1,41,4,LEAVES:3)
Block(-1,41,5,17:15)
Block(-1,41,6,17:15)
Block(-1,42,-1,17:15)
Block(-1,42,5,LEAVES:3)
Block(-1,42,6,17:15)
Block(-1,42,7,17:15)
Block(-1,42,8,LEAVES:3)
Block(-1,43,-11,LEAVES:3)
Block(-1,43,-9,17:15)
Block(-1,43,-8,LEAVES:3)
Block(-1,43,-1,17:15)
Block(-1,43,8,LEAVES:3)
Block(-1,43,9,LEAVES:3)
Block(-1,43,10,17:15)
Block(-1,43,11,LEAVES:3)
Block(-1,43,14,LEAVES:3)
Block(-1,44,-16,LEAVES:3)
Block(-1,44,-14,LEAVES:3)
Block(-1,44,-10,LEAVES:3)
Block(-1,44,-9,LEAVES:3)
Block(-1,44,-8,LEAVES:3)
Block(-1,44,-7,LEAVES:3)
Block(-1,44,-1,17:15)
Block(-1,44,10,LEAVES:3)
Block(-1,44,11,LEAVES:3)
Block(-1,44,13,LEAVES:3)
Block(-1,45,-17,LEAVES:3)
Block(-1,45,-14,LEAVES:3)
Block(-1,45,-11,LEAVES:3)
Block(-1,45,-9,LEAVES:3)
Block(-1,45,-1,17:15)
Block(-1,45,11,LEAVES:3)
Block(-1,46,-16,LEAVES:3)
Block(-1,46,-12,LEAVES:3)
Block(-1,46,-11,LEAVES:3)
Block(-1,46,-10,LEAVES:3)
Block(-1,46,-9,LEAVES:3)
Block(-1,46,-1,17:15)
Block(-1,47,-11,LEAVES:3)
Block(-1,47,-10,LEAVES:3)
Block(-1,47,-1,17:15)
Block(-1,48,-1,17:15)
Block(-1,48,0,17:15)
Block(-1,49,-1,17:15)
Block(-1,49,0,17:15)
Block(-1,49,1,17:15)
Block(-1,50,-1,17:15)
Block(-1,50,0,17:15)
Block(-1,50,1,17:15)
Block(-1,51,-1,17:15)
Block(-1,52,-1,17:15)
Block(-1,52,0,17:15)
Block(-1,53,-1,17:15)
Block(-1,53,0,17:15)
Block(-1,53,5,LEAVES:3)
Block(-1,53,7,LEAVES:3)
Block(-1,53,9,LEAVES:3)
Block(-1,54,-1,17:15)
Block(-1,54,0,17:15)
Block(-1,54,5,LEAVES:3)
Block(-1,54,6,LEAVES:3)
Block(-1,54,7,LEAVES:3)
Block(-1,54,8,LEAVES:3)
Block(-1,54,9,LEAVES:3)
Block(-1,55,-1,17:15)
Block(-1,55,6,LEAVES:3)
Block(-1,55,8,LEAVES:3)
Block(-1,56,-1,17:15)
Block(-1,57,-1,17:15)
Block(-1,58,-1,17:15)
Block(-1,59,-2,17:15)
Block(-1,59,-1,17:15)
Block(-1,60,-3,17:15)
Block(-1,60,-2,17:15)
Block(-1,60,-1,17:15)
Block(-1,61,-8,LEAVES:3)
Block(-1,61,-6,17:15)
Block(-1,61,-5,17:15)
Block(-1,61,-4,17:15)
Block(-1,61,-3,17:15)
Block(-1,61,-2,LEAVES:3)
Block(-1,62,-12,LEAVES:3)
Block(-1,62,-7,17:15)
Block(-1,62,-6,17:15)
Block(-1,62,-5,LEAVES:3)
Block(-1,62,-4,LEAVES:3)
Block(-1,63,-11,LEAVES:3)
Block(-1,63,-10,LEAVES:3)
Block(-1,63,-9,LEAVES:3)
Block(-1,63,-8,LEAVES:3)
Block(-1,63,-7,LEAVES:3)
Block(-1,63,-6,LEAVES:3)
Block(-1,63,-5,LEAVES:3)
Block(-1,64,-10,LEAVES:3)
Block(-1,64,-7,LEAVES:3)
Block(-1,66,0,17:15)
Block(-1,66,3,LEAVES:3)
Block(-1,67,0,17:15)
Block(-1,67,1,17:15)
Block(-1,67,2,17:15)
Block(-1,67,3,17:15)
Block(-1,68,1,LEAVES:3)
Block(-1,68,2,LEAVES:3)
Block(-1,68,3,17:15)
Block(-1,68,4,17:15)
Block(-1,68,5,LEAVES:3)
Block(-1,68,6,LEAVES:3)
Block(-1,68,7,LEAVES:3)
Block(-1,69,-4,LEAVES:3)
Block(-1,69,0,LEAVES:3)
Block(-1,69,2,LEAVES:3)
Block(-1,69,3,LEAVES:3)
Block(-1,69,4,LEAVES:3)
Block(-1,69,5,LEAVES:3)
Block(-1,69,6,LEAVES:3)
Block(-1,70,-4,LEAVES:3)
Block(-1,70,-3,LEAVES:3)
Block(-1,70,-2,LEAVES:3)
Block(-1,70,-1,LEAVES:3)
Block(-1,70,3,LEAVES:3)
Block(-1,70,5,LEAVES:3)
Block(-1,71,-2,LEAVES:3)
Block(-1,73,-3,LEAVES:3)
Block(-1,73,-1,17:15)
Block(-1,73,0,LEAVES:3)
Block(-1,74,-2,LEAVES:3)
Block(-1,74,-1,17:15)
Block(-1,74,1,LEAVES:3)
Block(-1,74,2,17:15)
Block(-1,74,3,LEAVES:3)
Block(-1,74,4,17:15)
Block(-1,75,-2,LEAVES:3)
Block(-1,75,-1,LEAVES:3)
Block(-1,75,0,LEAVES:3)
Block(-1,75,1,LEAVES:3)
Block(-1,75,2,LEAVES:3)
Block(-1,75,3,LEAVES:3)
Block(-1,75,4,LEAVES:3)
Block(-1,75,5,17:15)
Block(-1,75,6,LEAVES:3)
Block(-1,75,7,LEAVES:3)
Block(-1,75,8,LEAVES:3)
Block(-1,76,-2,LEAVES:3)
Block(-1,76,-1,LEAVES:3)
Block(-1,76,0,LEAVES:3)
Block(-1,76,5,LEAVES:3)
Block(-1,76,6,LEAVES:3)
Block(-1,76,7,LEAVES:3)
Block(-1,77,-1,LEAVES:3)
Block(-1,77,6,LEAVES:3)
Block(0,-4,2,17:15)
Block(0,-3,-5,17:15)
Block(0,-3,-1,17:15)
Block(0,-3,2,17:15)
Block(0,-2,-5,17:15)
Block(0,-2,-2,17:15)
Block(0,-2,-1,17:15)
Block(0,-2,2,17:15)
Block(0,-2,3,17:15)
Block(0,-1,-5,17:15)
Block(0,-1,-3,17:15)
Block(0,-1,-2,17:15)
Block(0,-1,-1,17:15)
Block(0,-1,2,17:15)
Block(0,-1,3,17:15)
Block(0,-1,5,17:15)
Block(0,0,-5,17:15)
Block(0,0,-3,17:15)
Block(0,0,-2,17:15)
Block(0,0,-1,17:15)
Block(0,0,0,17:15)
Block(0,0,2,17:15)
Block(0,0,3,17:15)
Block(0,0,4,17:15)
Block(0,0,5,17:15)
Block(0,1,-5,17:15)
Block(0,1,-3,17:15)
Block(0,1,-2,17:15)
Block(0,1,0,17:15)
Block(0,1,1,17:15)
Block(0,1,3,17:15)
Block(0,1,4,17:15)
Block(0,1,5,17:15)
Block(0,2,-3,17:15)
Block(0,2,-2,17:15)
Block(0,2,-1,17:15)
Block(0,2,0,17:15)
Block(0,2,1,17:15)
Block(0,2,4,17:15)
Block(0,2,5,17:15)
Block(0,3,-3,17:15)
Block(0,3,-2,17:15)
Block(0,3,-1,17:15)
Block(0,3,0,17:15)
Block(0,3,1,17:15)
Block(0,3,2,17:15)
Block(0,3,4,17:15)
Block(0,3,5,17:15)
Block(0,4,-3,17:15)
Block(0,4,-2,17:15)
Block(0,4,-1,17:15)
Block(0,4,0,17:15)
Block(0,4,1,17:15)
Block(0,4,2,17:15)
Block(0,4,4,17:15)
Block(0,5,-3,17:15)
Block(0,5,-2,17:15)
Block(0,5,-1,17:15)
Block(0,5,0,17:15)
Block(0,5,1,17:15)
Block(0,5,2,17:15)
Block(0,6,-3,17:15)
Block(0,6,-2,17:15)
Block(0,6,-1,17:15)
Block(0,6,0,17:15)
Block(0,6,1,17:15)
Block(0,6,2,17:15)
Block(0,7,-3,17:15)
Block(0,7,-2,17:15)
Block(0,7,-1,17:15)
Block(0,7,0,17:15)
Block(0,7,1,17:15)
Block(0,7,2,17:15)
Block(0,8,-3,17:15)
Block(0,8,-2,17:15)
Block(0,8,-1,17:15)
Block(0,8,0,17:15)
Block(0,8,1,17:15)
Block(0,8,2,17:15)
Block(0,9,-3,17:15)
Block(0,9,-2,17:15)
Block(0,9,-1,17:15)
Block(0,9,0,17:15)
Block(0,9,1,17:15)
Block(0,9,2,17:15)
Block(0,10,-3,17:15)
Block(0,10,-2,17:15)
Block(0,10,-1,17:15)
Block(0,10,0,17:15)
Block(0,10,1,17:15)
Block(0,10,2,17:15)
Block(0,11,-2,17:15)
Block(0,11,-1,17:15)
Block(0,11,0,17:15)
Block(0,11,1,17:15)
Block(0,12,-2,17:15)
Block(0,12,-1,17:15)
Block(0,12,0,17:15)
Block(0,12,1,17:15)
Block(0,13,-2,17:15)
Block(0,13,-1,17:15)
Block(0,13,0,17:15)
Block(0,13,1,17:15)
Block(0,14,-2,17:15)
Block(0,14,-1,17:15)
Block(0,14,0,17:15)
Block(0,14,1,17:15)
Block(0,15,-2,17:15)
Block(0,15,-1,17:15)
Block(0,15,0,17:15)
Block(0,15,1,17:15)
Block(0,16,-2,17:15)
Block(0,16,-1,17:15)
Block(0,16,0,17:15)
Block(0,16,1,17:15)
Block(0,17,-2,17:15)
Block(0,17,-1,17:15)
Block(0,17,0,17:15)
Block(0,17,1,17:15)
Block(0,18,-2,17:15)
Block(0,18,-1,17:15)
Block(0,18,0,17:15)
Block(0,18,1,17:15)
Block(0,19,-2,17:15)
Block(0,19,-1,17:15)
Block(0,19,0,17:15)
Block(0,19,1,17:15)
Block(0,20,-2,17:15)
Block(0,20,-1,17:15)
Block(0,20,0,17:15)
Block(0,20,1,17:15)
Block(0,21,-2,17:15)
Block(0,21,-1,17:15)
Block(0,21,0,17:15)
Block(0,21,1,17:15)
Block(0,22,-2,17:15)
Block(0,22,-1,17:15)
Block(0,22,0,17:15)
Block(0,22,1,17:15)
Block(0,23,-2,17:15)
Block(0,23,-1,17:15)
Block(0,23,0,17:15)
Block(0,23,1,17:15)
Block(0,24,-10,LEAVES:3)
Block(0,24,-7,LEAVES:3)
Block(0,24,-1,17:15)
Block(0,24,0,17:15)
Block(0,24,1,17:15)
Block(0,25,-11,LEAVES:3)
Block(0,25,-8,LEAVES:3)
Block(0,25,-1,17:15)
Block(0,25,0,17:15)
Block(0,25,1,17:15)
Block(0,26,-10,LEAVES:3)
Block(0,26,-9,LEAVES:3)
Block(0,26,-8,LEAVES:3)
Block(0,26,-7,LEAVES:3)
Block(0,26,-1,17:15)
Block(0,26,0,17:15)
Block(0,26,1,17:15)
Block(0,27,-8,LEAVES:3)
Block(0,27,-1,17:15)
Block(0,27,0,17:15)
Block(0,27,1,17:15)
Block(0,28,-1,17:15)
Block(0,28,0,17:15)
Block(0,28,1,17:15)
Block(0,29,-1,17:15)
Block(0,29,0,17:15)
Block(0,29,1,17:15)
Block(0,29,2,17:15)
Block(0,30,-1,17:15)
Block(0,30,0,17:15)
Block(0,30,1,17:15)
Block(0,30,2,17:15)
Block(0,30,3,17:15)
Block(0,31,-1,17:15)
Block(0,31,0,17:15)
Block(0,31,1,17:15)
Block(0,31,4,17:15)
Block(0,31,5,LEAVES:3)
Block(0,31,7,LEAVES:3)
Block(0,32,-1,17:15)
Block(0,32,0,17:15)
Block(0,32,1,17:15)
Block(0,32,7,17:15)
Block(0,32,8,17:15)
Block(0,33,-1,17:15)
Block(0,33,0,17:15)
Block(0,33,1,17:15)
Block(0,33,6,LEAVES:3)
Block(0,34,-1,17:15)
Block(0,34,0,17:15)
Block(0,34,1,17:15)
Block(0,34,5,LEAVES:3)
Block(0,34,6,LEAVES:3)
Block(0,34,11,LEAVES:3)
Block(0,34,12,LEAVES:3)
Block(0,34,14,LEAVES:3)
Block(0,35,-1,17:15)
Block(0,35,0,17:15)
Block(0,35,1,17:15)
Block(0,35,5,LEAVES:3)
Block(0,35,6,17:15)
Block(0,35,7,LEAVES:3)
Block(0,35,8,LEAVES:3)
Block(0,35,12,LEAVES:3)
Block(0,35,14,17:15)
Block(0,35,15,LEAVES:3)
Block(0,35,16,LEAVES:3)
Block(0,35,17,LEAVES:3)
Block(0,35,21,LEAVES:3)
Block(0,36,-1,17:15)
Block(0,36,0,17:15)
Block(0,36,1,17:15)
Block(0,36,6,LEAVES:3)
Block(0,36,7,LEAVES:3)
Block(0,36,13,LEAVES:3)
Block(0,36,15,LEAVES:3)
Block(0,36,16,LEAVES:3)
Block(0,36,18,LEAVES:3)
Block(0,36,21,LEAVES:3)
Block(0,36,22,LEAVES:3)
Block(0,36,23,LEAVES:3)
Block(0,37,-5,17:15)
Block(0,37,-1,17:15)
Block(0,37,0,17:15)
Block(0,37,1,17:15)
Block(0,37,6,LEAVES:3)
Block(0,37,15,LEAVES:3)
Block(0,37,22,LEAVES:3)
Block(0,38,-1,17:15)
Block(0,38,0,17:15)
Block(0,38,1,17:15)
Block(0,39,-1,17:15)
Block(0,39,0,17:15)
Block(0,39,1,17:15)
Block(0,40,-1,17:15)
Block(0,40,0,17:15)
Block(0,40,1,17:15)
Block(0,41,-1,17:15)
Block(0,41,0,17:15)
Block(0,41,1,17:15)
Block(0,41,5,17:15)
Block(0,42,-1,17:15)
Block(0,42,0,17:15)
Block(0,42,1,17:15)
Block(0,42,7,17:15)
Block(0,42,8,17:15)
Block(0,42,9,17:15)
Block(0,42,11,LEAVES:3)
Block(0,43,-10,LEAVES:3)
Block(0,43,-9,17:15)
Block(0,43,-6,LEAVES:3)
Block(0,43,-1,17:15)
Block(0,43,0,17:15)
Block(0,43,1,17:15)
Block(0,43,7,LEAVES:3)
Block(0,43,8,LEAVES:3)
Block(0,43,9,17:15)
Block(0,43,10,17:15)
Block(0,43,15,LEAVES:3)
Block(0,44,-13,LEAVES:3)
Block(0,44,-11,LEAVES:3)
Block(0,44,-10,LEAVES:3)
Block(0,44,-9,17:15)
Block(0,44,-8,LEAVES:3)
Block(0,44,-7,LEAVES:3)
Block(0,44,-6,LEAVES:3)
Block(0,44,-1,17:15)
Block(0,44,0,17:15)
Block(0,44,1,17:15)
Block(0,44,8,LEAVES:3)
Block(0,44,9,LEAVES:3)
Block(0,44,10,LEAVES:3)
Block(0,44,11,LEAVES:3)
Block(0,44,12,LEAVES:3)
Block(0,44,13,LEAVES:3)
Block(0,44,14,LEAVES:3)
Block(0,45,-12,LEAVES:3)
Block(0,45,-11,LEAVES:3)
Block(0,45,-10,LEAVES:3)
Block(0,45,-9,LEAVES:3)
Block(0,45,-7,LEAVES:3)
Block(0,45,-1,17:15)
Block(0,45,0,17:15)
Block(0,45,1,17:15)
Block(0,45,10,LEAVES:3)
Block(0,45,13,LEAVES:3)
Block(0,46,-12,LEAVES:3)
Block(0,46,-11,LEAVES:3)
Block(0,46,-10,LEAVES:3)
Block(0,46,-1,17:15)
Block(0,46,0,17:15)
Block(0,46,1,17:15)
Block(0,47,-11,LEAVES:3)
Block(0,47,-1,17:15)
Block(0,47,0,17:15)
Block(0,47,1,17:15)
Block(0,48,-1,17:15)
Block(0,48,0,17:15)
Block(0,48,1,17:15)
Block(0,49,-1,17:15)
Block(0,49,0,17:15)
Block(0,49,1,17:15)
Block(0,50,-1,17:15)
Block(0,50,0,17:15)
Block(0,50,1,17:15)
Block(0,51,-1,17:15)
Block(0,51,0,17:15)
Block(0,51,1,17:15)
Block(0,52,-1,17:15)
Block(0,52,0,17:15)
Block(0,52,1,17:15)
Block(0,52,9,LEAVES:3)
Block(0,53,-1,17:15)
Block(0,53,0,17:15)
Block(0,53,1,17:15)
Block(0,53,6,LEAVES:3)
Block(0,53,8,LEAVES:3)
Block(0,54,-1,17:15)
Block(0,54,0,17:15)
Block(0,54,4,LEAVES:3)
Block(0,54,5,LEAVES:3)
Block(0,54,6,LEAVES:3)
Block(0,54,7,LEAVES:3)
Block(0,54,8,17:15)
Block(0,54,9,LEAVES:3)
Block(0,55,-1,17:15)
Block(0,55,0,17:15)
Block(0,55,4,LEAVES:3)
Block(0,55,5,LEAVES:3)
Block(0,55,6,LEAVES:3)
Block(0,55,7,LEAVES:3)
Block(0,55,8,LEAVES:3)
Block(0,56,-1,17:15)
Block(0,56,0,17:15)
Block(0,56,6,LEAVES:3)
Block(0,57,-1,17:15)
Block(0,57,0,17:15)
Block(0,58,-1,17:15)
Block(0,58,0,17:15)
Block(0,59,-1,17:15)
Block(0,59,0,17:15)
Block(0,60,-1,17:15)
Block(0,60,0,17:15)
Block(0,61,-5,LEAVES:3)
Block(0,61,-4,17:15)
Block(0,61,-1,17:15)
Block(0,61,0,17:15)
Block(0,62,-11,LEAVES:3)
Block(0,62,-8,LEAVES:3)
Block(0,62,-7,17:15)
Block(0,62,-6,LEAVES:3)
Block(0,62,-5,LEAVES:3)
Block(0,62,-1,17:15)
Block(0,62,0,17:15)
Block(0,63,-10,LEAVES:3)
Block(0,63,-8,LEAVES:3)
Block(0,63,-7,LEAVES:3)
Block(0,63,-1,17:15)
Block(0,63,0,17:15)
Block(0,64,-8,LEAVES:3)
Block(0,64,-1,17:15)
Block(0,64,0,17:15)
Block(0,65,-1,17:15)
Block(0,65,0,17:15)
Block(0,66,0,17:15)
Block(0,67,0,17:15)
Block(0,67,2,17:15)
Block(0,67,5,LEAVES:3)
Block(0,68,0,17:15)
Block(0,68,2,LEAVES:3)
Block(0,68,3,LEAVES:3)
Block(0,68,4,LEAVES:3)
Block(0,68,5,17:15)
Block(0,68,6,LEAVES:3)
Block(0,68,8,LEAVES:3)
Block(0,69,0,17:15)
Block(0,69,3,LEAVES:3)
Block(0,69,5,LEAVES:3)
Block(0,69,6,LEAVES:3)
Block(0,69,7,LEAVES:3)
Block(0,69,8,LEAVES:3)
Block(0,70,-3,LEAVES:3)
Block(0,70,-2,LEAVES:3)
Block(0,70,-1,17:15)
Block(0,70,0,17:15)
Block(0,71,-4,LEAVES:3)
Block(0,71,-3,LEAVES:3)
Block(0,71,-2,LEAVES:3)
Block(0,71,-1,LEAVES:3)
Block(0,71,0,17:15)
Block(0,72,-2,LEAVES:3)
Block(0,72,0,17:15)
Block(0,73,0,17:15)
Block(0,73,4,LEAVES:3)
Block(0,74,0,LEAVES:3)
Block(0,74,1,17:15)
Block(0,74,4,LEAVES:3)
Block(0,74,5,LEAVES:3)
Block(0,74,7,LEAVES:3)
Block(0,75,-1,LEAVES:3)
Block(0,75,0,LEAVES:3)
Block(0,75,1,LEAVES:3)
Block(0,75,2,17:15)
Block(0,75,3,LEAVES:3)
Block(0,75,4,LEAVES:3)
Block(0,75,5,LEAVES:3)
Block(0,75,6,LEAVES:3)
Block(0,75,7,LEAVES:3)
Block(0,76,-1,LEAVES:3)
Block(0,76,2,LEAVES:3)
Block(0,76,3,LEAVES:3)
Block(1,-4,-6,17:15)
Block(1,-4,-1,17:15)
Block(1,-4,3,17:15)
Block(1,-4,5,17:15)
Block(1,-3,-6,17:15)
Block(1,-3,-1,17:15)
Block(1,-3,3,17:15)
Block(1,-3,5,17:15)
Block(1,-2,-6,17:15)
Block(1,-2,-1,17:15)
Block(1,-2,3,17:15)
Block(1,-2,5,17:15)
Block(1,-1,-6,17:15)
Block(1,-1,-1,17:15)
Block(1,-1,3,17:15)
Block(1,-1,5,17:15)
Block(1,0,0,17:15)
Block(1,0,1,17:15)
Block(1,0,5,17:15)
Block(1,1,-2,17:15)
Block(1,1,-1,17:15)
Block(1,1,0,17:15)
Block(1,1,5,17:15)
Block(1,2,-2,17:15)
Block(1,2,-1,17:15)
Block(1,2,0,17:15)
Block(1,2,1,17:15)
Block(1,2,4,17:15)
Block(1,3,-2,17:15)
Block(1,3,-1,17:15)
Block(1,3,0,17:15)
Block(1,3,2,17:15)
Block(1,3,3,17:15)
Block(1,3,4,17:15)
Block(1,4,-2,17:15)
Block(1,4,-1,17:15)
Block(1,4,0,17:15)
Block(1,4,2,17:15)
Block(1,4,3,17:15)
Block(1,4,4,17:15)
Block(1,5,-2,17:15)
Block(1,5,-1,17:15)
Block(1,5,0,17:15)
Block(1,5,1,17:15)
Block(1,5,2,17:15)
Block(1,5,3,17:15)
Block(1,5,4,17:15)
Block(1,6,-2,17:15)
Block(1,6,-1,17:15)
Block(1,6,0,17:15)
Block(1,6,1,17:15)
Block(1,6,2,17:15)
Block(1,6,3,17:15)
Block(1,7,-2,17:15)
Block(1,7,-1,17:15)
Block(1,7,0,17:15)
Block(1,7,1,17:15)
Block(1,7,2,17:15)
Block(1,8,-2,17:15)
Block(1,8,-1,17:15)
Block(1,8,0,17:15)
Block(1,8,1,17:15)
Block(1,8,2,17:15)
Block(1,9,-2,17:15)
Block(1,9,-1,17:15)
Block(1,9,0,17:15)
Block(1,9,1,17:15)
Block(1,10,-2,17:15)
Block(1,10,-1,17:15)
Block(1,10,0,17:15)
Block(1,10,1,17:15)
Block(1,11,-2,17:15)
Block(1,11,-1,17:15)
Block(1,11,0,17:15)
Block(1,11,1,17:15)
Block(1,12,-2,17:15)
Block(1,12,-1,17:15)
Block(1,12,0,17:15)
Block(1,13,-2,17:15)
Block(1,13,-1,17:15)
Block(1,13,0,17:15)
Block(1,14,-2,17:15)
Block(1,14,-1,17:15)
Block(1,14,0,17:15)
Block(1,15,-2,17:15)
Block(1,15,-1,17:15)
Block(1,15,0,17:15)
Block(1,16,-2,17:15)
Block(1,16,-1,17:15)
Block(1,16,0,17:15)
Block(1,17,-1,17:15)
Block(1,17,0,17:15)
Block(1,18,-1,17:15)
Block(1,18,0,17:15)
Block(1,19,-1,17:15)
Block(1,19,0,17:15)
Block(1,20,0,17:15)
Block(1,21,0,17:15)
Block(1,22,0,17:15)
Block(1,23,0,17:15)
Block(1,24,-2,LEAVES:3)
Block(1,24,-1,17:15)
Block(1,24,0,17:15)
Block(1,25,-9,LEAVES:3)
Block(1,25,-4,LEAVES:3)
Block(1,25,-1,17:15)
Block(1,25,0,17:15)
Block(1,26,-8,LEAVES:3)
Block(1,26,-4,LEAVES:3)
Block(1,26,-1,17:15)
Block(1,26,0,17:15)
Block(1,27,0,17:15)
Block(1,28,0,17:15)
Block(1,29,0,17:15)
Block(1,30,0,17:15)
Block(1,30,3,17:15)
Block(1,30,4,17:15)
Block(1,30,5,17:15)
Block(1,31,0,17:15)
Block(1,31,4,17:15)
Block(1,31,5,17:15)
Block(1,31,6,17:15)
Block(1,31,7,17:15)
Block(1,32,0,17:15)
Block(1,32,6,17:15)
Block(1,32,7,17:15)
Block(1,33,0,17:15)
Block(1,33,4,LEAVES:3)
Block(1,33,9,LEAVES:3)
Block(1,33,10,LEAVES:3)
Block(1,33,11,LEAVES:3)
Block(1,33,14,LEAVES:3)
Block(1,34,-1,17:15)
Block(1,34,0,17:15)
Block(1,34,5,LEAVES:3)
Block(1,34,8,LEAVES:3)
Block(1,34,10,LEAVES:3)
Block(1,34,11,LEAVES:3)
Block(1,34,12,17:15)
Block(1,34,13,LEAVES:3)
Block(1,35,-2,17:15)
Block(1,35,-1,17:15)
Block(1,35,0,17:15)
Block(1,35,4,LEAVES:3)
Block(1,35,5,LEAVES:3)
Block(1,35,6,17:15)
Block(1,35,7,LEAVES:3)
Block(1,35,11,LEAVES:3)
Block(1,35,12,LEAVES:3)
Block(1,35,13,17:15)
Block(1,35,14,LEAVES:3)
Block(1,35,15,LEAVES:3)
Block(1,35,16,LEAVES:3)
Block(1,35,19,LEAVES:3)
Block(1,35,20,LEAVES:3)
Block(1,35,22,LEAVES:3)
Block(1,35,23,LEAVES:3)
Block(1,36,-3,17:15)
Block(1,36,-2,17:15)
Block(1,36,0,17:15)
Block(1,36,5,LEAVES:3)
Block(1,36,6,LEAVES:3)
Block(1,36,12,LEAVES:3)
Block(1,36,13,LEAVES:3)
Block(1,36,14,LEAVES:3)
Block(1,36,15,LEAVES:3)
Block(1,36,17,LEAVES:3)
Block(1,36,18,LEAVES:3)
Block(1,36,19,LEAVES:3)
Block(1,36,20,LEAVES:3)
Block(1,36,21,LEAVES:3)
Block(1,36,22,17:15)
Block(1,36,23,LEAVES:3)
Block(1,36,24,LEAVES:3)
Block(1,37,-6,LEAVES:3)
Block(1,37,-5,LEAVES:3)
Block(1,37,-4,17:15)
Block(1,37,0,17:15)
Block(1,37,13,LEAVES:3)
Block(1,37,18,LEAVES:3)
Block(1,37,22,LEAVES:3)
Block(1,37,23,LEAVES:3)
Block(1,38,-5,LEAVES:3)
Block(1,38,0,17:15)
Block(1,39,0,17:15)
Block(1,40,0,17:15)
Block(1,41,0,17:15)
Block(1,42,0,17:15)
Block(1,42,4,17:15)
Block(1,42,9,LEAVES:3)
Block(1,42,11,LEAVES:3)
Block(1,43,-7,LEAVES:3)
Block(1,43,0,17:15)
Block(1,43,8,LEAVES:3)
Block(1,43,9,LEAVES:3)
Block(1,43,10,17:15)
Block(1,43,11,17:15)
Block(1,43,12,LEAVES:3)
Block(1,43,14,LEAVES:3)
Block(1,44,-11,LEAVES:3)
Block(1,44,-10,17:15)
Block(1,44,-9,17:15)
Block(1,44,-8,17:15)
Block(1,44,-7,LEAVES:3)
Block(1,44,-6,LEAVES:3)
Block(1,44,-5,LEAVES:3)
Block(1,44,0,17:15)
Block(1,44,9,LEAVES:3)
Block(1,44,10,LEAVES:3)
Block(1,44,11,LEAVES:3)
Block(1,44,12,17:15)
Block(1,44,13,LEAVES:3)
Block(1,44,14,LEAVES:3)
Block(1,44,15,LEAVES:3)
Block(1,45,-13,LEAVES:3)
Block(1,45,-12,LEAVES:3)
Block(1,45,-11,17:15)
Block(1,45,-10,LEAVES:3)
Block(1,45,-9,LEAVES:3)
Block(1,45,-8,LEAVES:3)
Block(1,45,-7,LEAVES:3)
Block(1,45,-6,LEAVES:3)
Block(1,45,0,17:15)
Block(1,45,11,LEAVES:3)
Block(1,45,12,LEAVES:3)
Block(1,45,13,LEAVES:3)
Block(1,45,14,LEAVES:3)
Block(1,46,-12,LEAVES:3)
Block(1,46,-11,LEAVES:3)
Block(1,46,-9,LEAVES:3)
Block(1,46,0,17:15)
Block(1,46,13,LEAVES:3)
Block(1,53,0,17:15)
Block(1,53,1,17:15)
Block(1,53,7,LEAVES:3)
Block(1,53,9,LEAVES:3)
Block(1,54,1,17:15)
Block(1,54,7,17:15)
Block(1,54,8,LEAVES:3)
Block(1,55,6,LEAVES:3)
Block(1,55,7,LEAVES:3)
Block(1,55,10,LEAVES:3)
Block(1,56,2,LEAVES:3)
Block(1,56,10,LEAVES:3)
Block(1,57,-3,LEAVES:3)
Block(1,58,-4,LEAVES:3)
Block(1,61,-7,LEAVES:3)
Block(1,62,-7,LEAVES:3)
Block(1,62,-6,LEAVES:3)
Block(1,62,-5,LEAVES:3)
Block(1,63,-11,LEAVES:3)
Block(1,63,-9,LEAVES:3)
Block(1,63,-8,17:15)
Block(1,63,-7,LEAVES:3)
Block(1,63,-6,LEAVES:3)
Block(1,64,-10,LEAVES:3)
Block(1,64,-9,LEAVES:3)
Block(1,64,-8,LEAVES:3)
Block(1,65,-8,LEAVES:3)
Block(1,67,1,LEAVES:3)
Block(1,67,2,LEAVES:3)
Block(1,67,3,LEAVES:3)
Block(1,68,2,LEAVES:3)
Block(1,68,3,LEAVES:3)
Block(1,68,4,LEAVES:3)
Block(1,68,5,LEAVES:3)
Block(1,69,5,LEAVES:3)
Block(1,69,6,17:15)
Block(1,69,7,LEAVES:3)
Block(1,69,8,LEAVES:3)
Block(1,69,9,LEAVES:3)
Block(1,70,-5,LEAVES:3)
Block(1,70,-2,17:15)
Block(1,70,5,LEAVES:3)
Block(1,70,6,LEAVES:3)
Block(1,70,7,LEAVES:3)
Block(1,70,8,LEAVES:3)
Block(1,71,-6,LEAVES:3)
Block(1,71,-5,LEAVES:3)
Block(1,71,-4,LEAVES:3)
Block(1,71,-3,17:15)
Block(1,71,-2,LEAVES:3)
Block(1,71,6,LEAVES:3)
Block(1,72,-4,LEAVES:3)
Block(1,72,-3,LEAVES:3)
Block(1,72,-1,LEAVES:3)
Block(1,72,0,17:15)
Block(1,73,0,LEAVES:3)
Block(1,74,4,LEAVES:3)
Block(1,74,6,LEAVES:3)
Block(1,75,1,LEAVES:3)
Block(1,75,2,17:15)
Block(1,75,3,LEAVES:3)
Block(1,76,2,LEAVES:3)
Block(2,-4,2,17:15)
Block(2,-4,5,17:15)
Block(2,-3,1,17:15)
Block(2,-3,2,17:15)
Block(2,-2,-3,17:15)
Block(2,-2,1,17:15)
Block(2,-2,2,17:15)
Block(2,-2,5,17:15)
Block(2,-1,-3,17:15)
Block(2,-1,-2,17:15)
Block(2,-1,0,17:15)
Block(2,-1,1,17:15)
Block(2,-1,2,17:15)
Block(2,-1,5,17:15)
Block(2,0,-3,17:15)
Block(2,0,-2,17:15)
Block(2,0,0,17:15)
Block(2,0,1,17:15)
Block(2,0,4,17:15)
Block(2,0,5,17:15)
Block(2,1,-3,17:15)
Block(2,1,-2,17:15)
Block(2,1,0,17:15)
Block(2,1,1,17:15)
Block(2,1,4,17:15)
Block(2,1,5,17:15)
Block(2,2,-2,17:15)
Block(2,2,-1,17:15)
Block(2,2,0,17:15)
Block(2,2,1,17:15)
Block(2,2,3,17:15)
Block(2,2,4,17:15)
Block(2,2,5,17:15)
Block(2,3,-2,17:15)
Block(2,3,-1,17:15)
Block(2,3,0,17:15)
Block(2,3,1,17:15)
Block(2,3,3,17:15)
Block(2,3,4,17:15)
Block(2,4,-1,17:15)
Block(2,4,0,17:15)
Block(2,4,1,17:15)
Block(2,4,3,17:15)
Block(2,4,4,17:15)
Block(2,5,-1,17:15)
Block(2,5,0,17:15)
Block(2,5,1,17:15)
Block(2,5,3,17:15)
Block(2,6,-1,17:15)
Block(2,6,0,17:15)
Block(2,6,1,17:15)
Block(2,7,-1,17:15)
Block(2,7,0,17:15)
Block(2,8,-1,17:15)
Block(2,9,-1,17:15)
Block(2,10,-1,17:15)
Block(2,11,-1,17:15)
Block(2,12,-1,17:15)
Block(2,13,-1,17:15)
Block(2,23,-5,LEAVES:3)
Block(2,24,-6,LEAVES:3)
Block(2,24,-4,LEAVES:3)
Block(2,25,-5,LEAVES:3)
Block(2,25,-4,LEAVES:3)
Block(2,25,-3,LEAVES:3)
Block(2,25,-2,17:15)
Block(2,25,-1,17:15)
Block(2,26,-4,LEAVES:3)
Block(2,26,-2,LEAVES:3)
Block(2,26,-1,LEAVES:3)
Block(2,26,0,LEAVES:3)
Block(2,27,-1,LEAVES:3)
Block(2,31,5,17:15)
Block(2,31,6,17:15)
Block(2,32,6,17:15)
Block(2,33,9,LEAVES:3)
Block(2,33,10,LEAVES:3)
Block(2,33,11,LEAVES:3)
Block(2,34,0,17:15)
Block(2,34,4,LEAVES:3)
Block(2,34,9,LEAVES:3)
Block(2,34,10,LEAVES:3)
Block(2,34,12,17:15)
Block(2,34,16,LEAVES:3)
Block(2,34,23,LEAVES:3)
Block(2,35,5,LEAVES:3)
Block(2,35,6,LEAVES:3)
Block(2,35,7,LEAVES:3)
Block(2,35,10,LEAVES:3)
Block(2,35,12,LEAVES:3)
Block(2,35,13,LEAVES:3)
Block(2,35,14,LEAVES:3)
Block(2,35,17,LEAVES:3)
Block(2,35,18,LEAVES:3)
Block(2,35,21,LEAVES:3)
Block(2,35,24,LEAVES:3)
Block(2,36,-3,17:15)
Block(2,36,6,LEAVES:3)
Block(2,36,11,LEAVES:3)
Block(2,36,13,LEAVES:3)
Block(2,36,17,LEAVES:3)
Block(2,36,18,17:15)
Block(2,36,19,LEAVES:3)
Block(2,36,20,LEAVES:3)
Block(2,36,21,LEAVES:3)
Block(2,36,22,LEAVES:3)
Block(2,36,23,LEAVES:3)
Block(2,37,18,LEAVES:3)
Block(2,37,20,LEAVES:3)
Block(2,37,21,17:15)
Block(2,38,21,LEAVES:3)
Block(2,42,2,LEAVES:3)
Block(2,42,3,17:15)
Block(2,42,8,LEAVES:3)
Block(2,42,15,LEAVES:3)
Block(2,43,-10,LEAVES:3)
Block(2,43,-9,LEAVES:3)
Block(2,43,-5,LEAVES:3)
Block(2,43,3,LEAVES:3)
Block(2,43,9,LEAVES:3)
Block(2,43,10,LEAVES:3)
Block(2,43,13,LEAVES:3)
Block(2,43,16,LEAVES:3)
Block(2,44,-12,LEAVES:3)
Block(2,44,-10,17:15)
Block(2,44,-8,LEAVES:3)
Block(2,44,-6,LEAVES:3)
Block(2,44,-4,LEAVES:3)
Block(2,44,9,LEAVES:3)
Block(2,44,10,17:15)
Block(2,44,11,LEAVES:3)
Block(2,44,12,LEAVES:3)
Block(2,44,13,LEAVES:3)
Block(2,44,14,LEAVES:3)
Block(2,44,15,LEAVES:3)
Block(2,45,-12,LEAVES:3)
Block(2,45,-11,LEAVES:3)
Block(2,45,-10,LEAVES:3)
Block(2,45,-9,LEAVES:3)
Block(2,45,-8,LEAVES:3)
Block(2,45,-7,17:15)
Block(2,45,-6,LEAVES:3)
Block(2,45,-5,LEAVES:3)
Block(2,45,10,LEAVES:3)
Block(2,45,12,LEAVES:3)
Block(2,45,13,17:15)
Block(2,46,-10,LEAVES:3)
Block(2,46,-8,LEAVES:3)
Block(2,46,-7,LEAVES:3)
Block(2,46,13,LEAVES:3)
Block(2,47,-7,LEAVES:3)
Block(2,53,1,17:15)
Block(2,53,5,LEAVES:3)
Block(2,54,1,17:15)
Block(2,54,4,LEAVES:3)
Block(2,54,6,17:15)
Block(2,54,7,LEAVES:3)
Block(2,55,5,LEAVES:3)
Block(2,55,6,17:15)
Block(2,55,7,LEAVES:3)
Block(2,55,12,LEAVES:3)
Block(2,56,-3,LEAVES:3)
Block(2,56,1,LEAVES:3)
Block(2,56,2,LEAVES:3)
Block(2,56,3,LEAVES:3)
Block(2,56,6,LEAVES:3)
Block(2,56,7,LEAVES:3)
Block(2,56,9,LEAVES:3)
Block(2,56,10,LEAVES:3)
Block(2,56,11,LEAVES:3)
Block(2,57,-2,LEAVES:3)
Block(2,57,2,LEAVES:3)
Block(2,57,5,LEAVES:3)
Block(2,57,10,LEAVES:3)
Block(2,58,-5,LEAVES:3)
Block(2,58,-4,LEAVES:3)
Block(2,58,-3,LEAVES:3)
Block(2,59,-4,LEAVES:3)
Block(2,61,-6,LEAVES:3)
Block(2,62,-10,LEAVES:3)
Block(2,62,-8,LEAVES:3)
Block(2,62,-7,LEAVES:3)
Block(2,62,-6,LEAVES:3)
Block(2,63,-11,LEAVES:3)
Block(2,63,-10,LEAVES:3)
Block(2,63,-9,17:15)
Block(2,63,-8,LEAVES:3)
Block(2,63,-7,LEAVES:3)
Block(2,64,-10,LEAVES:3)
Block(2,64,-9,LEAVES:3)
Block(2,66,3,LEAVES:3)
Block(2,67,2,LEAVES:3)
Block(2,67,5,LEAVES:3)
Block(2,68,5,LEAVES:3)
Block(2,68,7,LEAVES:3)
Block(2,68,9,LEAVES:3)
Block(2,69,6,LEAVES:3)
Block(2,69,7,LEAVES:3)
Block(2,69,8,LEAVES:3)
Block(2,70,-7,LEAVES:3)
Block(2,70,-5,LEAVES:3)
Block(2,70,-3,LEAVES:3)
Block(2,70,0,LEAVES:3)
Block(2,70,7,LEAVES:3)
Block(2,71,-7,LEAVES:3)
Block(2,71,-6,LEAVES:3)
Block(2,71,-5,LEAVES:3)
Block(2,71,-4,17:15)
Block(2,71,-3,LEAVES:3)
Block(2,71,-1,LEAVES:3)
Block(2,72,-6,LEAVES:3)
Block(2,72,-5,LEAVES:3)
Block(2,72,-4,LEAVES:3)
Block(2,72,-2,LEAVES:3)
Block(2,72,-1,LEAVES:3)
Block(2,72,0,17:15)
Block(2,73,-5,LEAVES:3)
Block(2,73,-1,LEAVES:3)
Block(2,73,0,LEAVES:3)
Block(2,73,3,LEAVES:3)
Block(2,74,1,LEAVES:3)
Block(2,75,2,LEAVES:3)
Block(2,75,3,17:15)
Block(2,75,4,LEAVES:3)
Block(2,76,3,LEAVES:3)
Block(3,-4,-4,17:15)
Block(3,-4,-1,17:15)
Block(3,-4,0,17:15)
Block(3,-4,6,17:15)
Block(3,-3,-4,17:15)
Block(3,-3,0,17:15)
Block(3,-3,6,17:15)
Block(3,-2,-4,17:15)
Block(3,-2,-1,17:15)
Block(3,-2,0,17:15)
Block(3,-2,6,17:15)
Block(3,-1,-4,17:15)
Block(3,-1,0,17:15)
Block(3,-1,1,17:15)
Block(3,-1,2,17:15)
Block(3,-1,6,17:15)
Block(3,0,-4,17:15)
Block(3,0,-1,17:15)
Block(3,0,0,17:15)
Block(3,0,2,17:15)
Block(3,0,6,17:15)
Block(3,1,-1,17:15)
Block(3,1,0,17:15)
Block(3,1,1,17:15)
Block(3,1,2,17:15)
Block(3,1,6,17:15)
Block(3,2,-1,17:15)
Block(3,2,1,17:15)
Block(3,2,2,17:15)
Block(3,3,-1,17:15)
Block(3,3,2,17:15)
Block(3,4,-1,17:15)
Block(3,4,1,17:15)
Block(3,4,2,17:15)
Block(3,5,-1,17:15)
Block(3,24,-5,LEAVES:3)
Block(3,24,-2,LEAVES:3)
Block(3,25,-6,LEAVES:3)
Block(3,25,-5,LEAVES:3)
Block(3,25,-4,LEAVES:3)
Block(3,25,-3,LEAVES:3)
Block(3,25,-2,17:15)
Block(3,25,1,LEAVES:3)
Block(3,26,-5,LEAVES:3)
Block(3,26,-4,LEAVES:3)
Block(3,26,-2,17:15)
Block(3,26,-1,17:15)
Block(3,26,0,LEAVES:3)
Block(3,26,1,LEAVES:3)
Block(3,27,-2,LEAVES:3)
Block(3,27,-1,LEAVES:3)
Block(3,27,0,LEAVES:3)
Block(3,28,-1,LEAVES:3)
Block(3,32,6,17:15)
Block(3,32,7,17:15)
Block(3,32,8,17:15)
Block(3,33,8,17:15)
Block(3,33,9,17:15)
Block(3,33,10,17:15)
Block(3,33,11,17:15)
Block(3,33,12,17:15)
Block(3,33,14,LEAVES:3)
Block(3,34,5,LEAVES:3)
Block(3,34,6,LEAVES:3)
Block(3,34,9,LEAVES:3)
Block(3,34,11,LEAVES:3)
Block(3,34,12,17:15)
Block(3,34,13,17:15)
Block(3,34,14,17:15)
Block(3,34,15,17:15)
Block(3,34,17,LEAVES:3)
Block(3,34,19,LEAVES:3)
Block(3,35,0,17:15)
Block(3,35,1,LEAVES:3)
Block(3,35,6,LEAVES:3)
Block(3,35,14,17:15)
Block(3,35,15,LEAVES:3)
Block(3,35,16,LEAVES:3)
Block(3,35,17,LEAVES:3)
Block(3,35,18,17:15)
Block(3,35,19,17:15)
Block(3,35,20,LEAVES:3)
Block(3,35,22,LEAVES:3)
Block(3,36,-4,17:15)
Block(3,36,-3,LEAVES:3)
Block(3,36,0,LEAVES:3)
Block(3,36,10,LEAVES:3)
Block(3,36,11,LEAVES:3)
Block(3,36,12,LEAVES:3)
Block(3,36,14,LEAVES:3)
Block(3,36,17,LEAVES:3)
Block(3,36,18,LEAVES:3)
Block(3,36,19,LEAVES:3)
Block(3,36,20,17:15)
Block(3,36,21,LEAVES:3)
Block(3,36,22,LEAVES:3)
Block(3,36,23,LEAVES:3)
Block(3,37,-5,17:15)
Block(3,37,-3,LEAVES:3)
Block(3,37,11,LEAVES:3)
Block(3,37,19,LEAVES:3)
Block(3,37,20,LEAVES:3)
Block(3,37,21,LEAVES:3)
Block(3,37,22,LEAVES:3)
Block(3,38,21,LEAVES:3)
Block(3,42,3,17:15)
Block(3,43,11,LEAVES:3)
Block(3,43,12,LEAVES:3)
Block(3,43,14,LEAVES:3)
Block(3,43,15,LEAVES:3)
Block(3,44,-12,LEAVES:3)
Block(3,44,-10,LEAVES:3)
Block(3,44,9,LEAVES:3)
Block(3,44,10,LEAVES:3)
Block(3,44,11,LEAVES:3)
Block(3,44,12,LEAVES:3)
Block(3,44,13,LEAVES:3)
Block(3,44,14,17:15)
Block(3,44,15,LEAVES:3)
Block(3,44,16,LEAVES:3)
Block(3,45,-12,LEAVES:3)
Block(3,45,-11,LEAVES:3)
Block(3,45,-10,17:15)
Block(3,45,-9,LEAVES:3)
Block(3,45,-7,LEAVES:3)
Block(3,45,-6,17:15)
Block(3,45,-5,LEAVES:3)
Block(3,45,-4,LEAVES:3)
Block(3,45,10,LEAVES:3)
Block(3,45,14,LEAVES:3)
Block(3,45,15,LEAVES:3)
Block(3,46,-11,LEAVES:3)
Block(3,46,-10,LEAVES:3)
Block(3,46,-7,LEAVES:3)
Block(3,46,-6,LEAVES:3)
Block(3,46,-5,LEAVES:3)
Block(3,53,5,LEAVES:3)
Block(3,54,1,17:15)
Block(3,54,2,17:15)
Block(3,54,4,17:15)
Block(3,54,5,LEAVES:3)
Block(3,54,12,LEAVES:3)
Block(3,55,2,17:15)
Block(3,55,3,LEAVES:3)
Block(3,55,5,17:15)
Block(3,55,7,LEAVES:3)
Block(3,55,8,LEAVES:3)
Block(3,55,11,LEAVES:3)
Block(3,56,-1,LEAVES:3)
Block(3,56,1,LEAVES:3)
Block(3,56,2,LEAVES:3)
Block(3,56,3,LEAVES:3)
Block(3,56,9,LEAVES:3)
Block(3,56,10,17:15)
Block(3,56,11,LEAVES:3)
Block(3,56,12,LEAVES:3)
Block(3,57,-5,LEAVES:3)
Block(3,57,-3,LEAVES:3)
Block(3,57,-2,LEAVES:3)
Block(3,57,-1,LEAVES:3)
Block(3,57,1,LEAVES:3)
Block(3,57,2,LEAVES:3)
Block(3,57,4,LEAVES:3)
Block(3,57,5,LEAVES:3)
Block(3,57,6,LEAVES:3)
Block(3,57,10,LEAVES:3)
Block(3,57,11,LEAVES:3)
Block(3,58,-6,LEAVES:3)
Block(3,58,-5,LEAVES:3)
Block(3,58,-4,17:15)
Block(3,58,-3,LEAVES:3)
Block(3,58,-2,LEAVES:3)
Block(3,58,2,LEAVES:3)
Block(3,58,4,LEAVES:3)
Block(3,58,5,LEAVES:3)
Block(3,59,-5,LEAVES:3)
Block(3,59,-4,LEAVES:3)
Block(3,61,-8,LEAVES:3)
Block(3,62,-7,LEAVES:3)
Block(3,63,-10,LEAVES:3)
Block(3,63,-9,LEAVES:3)
Block(3,63,-8,LEAVES:3)
Block(3,64,-9,LEAVES:3)
Block(3,69,-5,LEAVES:3)
Block(3,69,7,LEAVES:3)
Block(3,70,-3,LEAVES:3)
Block(3,71,-6,LEAVES:3)
Block(3,71,-5,LEAVES:3)
Block(3,71,-4,LEAVES:3)
Block(3,72,-5,LEAVES:3)
Block(3,72,-1,LEAVES:3)
Block(3,72,0,LEAVES:3)
Block(3,72,1,17:15)
Block(3,73,1,LEAVES:3)
Block(3,73,2,LEAVES:3)
Block(3,74,4,LEAVES:3)
Block(3,75,2,LEAVES:3)
Block(3,75,3,LEAVES:3)
Block(3,75,4,LEAVES:3)
Block(3,76,3,LEAVES:3)
Block(4,-4,0,17:15)
Block(4,-3,0,17:15)
Block(4,-3,4,17:15)
Block(4,-2,-2,17:15)
Block(4,-2,0,17:15)
Block(4,-2,3,17:15)
Block(4,-2,4,17:15)
Block(4,-1,-2,17:15)
Block(4,-1,-1,17:15)
Block(4,-1,0,17:15)
Block(4,-1,2,17:15)
Block(4,-1,3,17:15)
Block(4,-1,4,17:15)
Block(4,0,-2,17:15)
Block(4,0,-1,17:15)
Block(4,0,2,17:15)
Block(4,0,3,17:15)
Block(4,0,4,17:15)
Block(4,1,-2,17:15)
Block(4,1,-1,17:15)
Block(4,1,2,17:15)
Block(4,1,3,17:15)
Block(4,1,4,17:15)
Block(4,2,-1,17:15)
Block(4,2,2,17:15)
Block(4,2,3,17:15)
Block(4,3,2,17:15)
Block(4,24,-3,LEAVES:3)
Block(4,25,-7,LEAVES:3)
Block(4,25,-5,LEAVES:3)
Block(4,25,-4,17:15)
Block(4,25,-3,17:15)
Block(4,25,-1,LEAVES:3)
Block(4,26,-5,LEAVES:3)
Block(4,26,-4,LEAVES:3)
Block(4,26,-3,LEAVES:3)
Block(4,26,-2,LEAVES:3)
Block(4,26,-1,LEAVES:3)
Block(4,26,0,17:15)
Block(4,26,1,LEAVES:3)
Block(4,26,2,LEAVES:3)
Block(4,27,-3,LEAVES:3)
Block(4,27,-1,LEAVES:3)
Block(4,27,0,LEAVES:3)
Block(4,27,1,LEAVES:3)
Block(4,27,2,LEAVES:3)
Block(4,28,1,LEAVES:3)
Block(4,32,4,LEAVES:3)
Block(4,32,7,17:15)
Block(4,33,4,LEAVES:3)
Block(4,33,5,LEAVES:3)
Block(4,33,8,LEAVES:3)
Block(4,33,9,17:15)
Block(4,33,14,LEAVES:3)
Block(4,34,8,LEAVES:3)
Block(4,34,9,17:15)
Block(4,34,11,LEAVES:3)
Block(4,34,12,LEAVES:3)
Block(4,34,14,LEAVES:3)
Block(4,34,15,17:15)
Block(4,34,16,17:15)
Block(4,34,17,17:15)
Block(4,34,19,LEAVES:3)
Block(4,35,-1,17:15)
Block(4,35,9,LEAVES:3)
Block(4,35,16,LEAVES:3)
Block(4,35,17,17:15)
Block(4,35,18,17:15)
Block(4,35,23,LEAVES:3)
Block(4,36,-3,LEAVES:3)
Block(4,36,10,LEAVES:3)
Block(4,36,11,17:15)
Block(4,36,12,LEAVES:3)
Block(4,36,13,LEAVES:3)
Block(4,36,14,17:15)
Block(4,36,15,LEAVES:3)
Block(4,36,16,LEAVES:3)
Block(4,36,17,LEAVES:3)
Block(4,36,18,LEAVES:3)
Block(4,36,19,LEAVES:3)
Block(4,36,20,LEAVES:3)
Block(4,36,21,LEAVES:3)
Block(4,36,22,LEAVES:3)
Block(4,37,-8,LEAVES:3)
Block(4,37,-7,LEAVES:3)
Block(4,37,-6,17:15)
Block(4,37,10,LEAVES:3)
Block(4,37,11,LEAVES:3)
Block(4,37,14,LEAVES:3)
Block(4,37,18,LEAVES:3)
Block(4,37,21,LEAVES:3)
Block(4,38,-7,LEAVES:3)
Block(4,38,11,LEAVES:3)
Block(4,38,14,LEAVES:3)
Block(4,42,4,17:15)
Block(4,43,4,LEAVES:3)
Block(4,43,9,LEAVES:3)
Block(4,43,13,LEAVES:3)
Block(4,44,-13,LEAVES:3)
Block(4,44,-11,LEAVES:3)
Block(4,44,-6,LEAVES:3)
Block(4,44,10,LEAVES:3)
Block(4,44,13,LEAVES:3)
Block(4,44,14,LEAVES:3)
Block(4,44,15,LEAVES:3)
Block(4,45,-13,LEAVES:3)
Block(4,45,-12,LEAVES:3)
Block(4,45,-11,LEAVES:3)
Block(4,45,-10,LEAVES:3)
Block(4,45,-9,LEAVES:3)
Block(4,45,-8,LEAVES:3)
Block(4,45,-6,LEAVES:3)
Block(4,45,-5,LEAVES:3)
Block(4,45,14,LEAVES:3)
Block(4,46,-11,17:15)
Block(4,46,-10,LEAVES:3)
Block(4,46,-9,LEAVES:3)
Block(4,46,-7,LEAVES:3)
Block(4,46,-6,LEAVES:3)
Block(4,47,-11,LEAVES:3)
Block(4,47,-10,LEAVES:3)
Block(4,53,4,17:15)
Block(4,53,5,17:15)
Block(4,54,3,17:15)
Block(4,54,4,17:15)
Block(4,55,2,17:15)
Block(4,55,3,17:15)
Block(4,55,4,LEAVES:3)
Block(4,55,10,LEAVES:3)
Block(4,55,11,LEAVES:3)
Block(4,56,-2,LEAVES:3)
Block(4,56,2,LEAVES:3)
Block(4,56,4,LEAVES:3)
Block(4,56,8,LEAVES:3)
Block(4,56,9,LEAVES:3)
Block(4,56,10,17:15)
Block(4,56,11,LEAVES:3)
Block(4,57,-2,LEAVES:3)
Block(4,57,-1,LEAVES:3)
Block(4,57,0,LEAVES:3)
Block(4,57,3,LEAVES:3)
Block(4,57,4,17:15)
Block(4,57,5,17:15)
Block(4,57,6,LEAVES:3)
Block(4,57,7,LEAVES:3)
Block(4,57,9,LEAVES:3)
Block(4,57,10,LEAVES:3)
Block(4,58,-6,LEAVES:3)
Block(4,58,-4,LEAVES:3)
Block(4,58,-3,17:15)
Block(4,58,-2,LEAVES:3)
Block(4,58,-1,LEAVES:3)
Block(4,58,3,LEAVES:3)
Block(4,58,4,LEAVES:3)
Block(4,58,5,LEAVES:3)
Block(4,58,6,LEAVES:3)
Block(4,58,10,LEAVES:3)
Block(4,59,-5,LEAVES:3)
Block(4,59,-4,LEAVES:3)
Block(4,59,-3,LEAVES:3)
Block(4,59,4,LEAVES:3)
Block(4,60,-3,LEAVES:3)
Block(4,62,-8,LEAVES:3)
Block(4,63,-9,LEAVES:3)
Block(4,70,-5,LEAVES:3)
Block(4,71,-5,LEAVES:3)
Block(4,72,-1,LEAVES:3)
Block(4,72,1,LEAVES:3)
Block(4,72,3,LEAVES:3)
Block(4,73,-1,LEAVES:3)
Block(4,73,0,LEAVES:3)
Block(4,73,1,17:15)
Block(4,73,2,LEAVES:3)
Block(4,74,0,LEAVES:3)
Block(4,74,1,LEAVES:3)
Block(4,74,2,LEAVES:3)
Block(4,75,1,LEAVES:3)
Block(4,75,2,LEAVES:3)
Block(4,75,3,LEAVES:3)
Block(5,-4,-3,17:15)
Block(5,-4,-2,17:15)
Block(5,-4,4,17:15)
Block(5,-3,-2,17:15)
Block(5,-3,4,17:15)
Block(5,-2,-3,17:15)
Block(5,-2,-2,17:15)
Block(5,-2,4,17:15)
Block(5,-1,-2,17:15)
Block(5,-1,4,17:15)
Block(5,0,-2,17:15)
Block(5,0,4,17:15)
Block(5,24,-6,LEAVES:3)
Block(5,24,0,LEAVES:3)
Block(5,25,-8,LEAVES:3)
Block(5,25,-6,LEAVES:3)
Block(5,25,-5,17:15)
Block(5,25,-3,17:15)
Block(5,25,0,LEAVES:3)
Block(5,25,1,LEAVES:3)
Block(5,26,-9,LEAVES:3)
Block(5,26,-8,LEAVES:3)
Block(5,26,-7,LEAVES:3)
Block(5,26,-6,17:15)
Block(5,26,-4,LEAVES:3)
Block(5,26,-3,LEAVES:3)
Block(5,26,-2,LEAVES:3)
Block(5,27,-7,LEAVES:3)
Block(5,27,-6,LEAVES:3)
Block(5,27,-3,LEAVES:3)
Block(5,27,-2,LEAVES:3)
Block(5,27,0,LEAVES:3)
Block(5,27,1,17:15)
Block(5,27,2,LEAVES:3)
Block(5,27,3,LEAVES:3)
Block(5,28,-3,LEAVES:3)
Block(5,28,1,LEAVES:3)
Block(5,28,2,LEAVES:3)
Block(5,29,1,LEAVES:3)
Block(5,32,3,LEAVES:3)
Block(5,32,5,LEAVES:3)
Block(5,33,3,LEAVES:3)
Block(5,33,4,LEAVES:3)
Block(5,33,5,LEAVES:3)
Block(5,33,6,LEAVES:3)
Block(5,33,7,17:15)
Block(5,34,4,LEAVES:3)
Block(5,34,5,LEAVES:3)
Block(5,34,7,LEAVES:3)
Block(5,34,8,LEAVES:3)
Block(5,34,9,17:15)
Block(5,34,16,LEAVES:3)
Block(5,35,-1,17:15)
Block(5,35,8,LEAVES:3)
Block(5,35,9,LEAVES:3)
Block(5,35,10,LEAVES:3)
Block(5,35,11,17:15)
Block(5,35,12,17:15)
Block(5,35,13,LEAVES:3)
Block(5,35,14,LEAVES:3)
Block(5,35,16,LEAVES:3)
Block(5,35,17,LEAVES:3)
Block(5,35,18,17:15)
Block(5,35,19,LEAVES:3)
Block(5,35,22,LEAVES:3)
Block(5,36,9,LEAVES:3)
Block(5,36,11,LEAVES:3)
Block(5,36,12,LEAVES:3)
Block(5,36,13,LEAVES:3)
Block(5,36,14,LEAVES:3)
Block(5,36,15,LEAVES:3)
Block(5,36,16,LEAVES:3)
Block(5,36,18,LEAVES:3)
Block(5,36,19,LEAVES:3)
Block(5,36,21,LEAVES:3)
Block(5,37,-6,LEAVES:3)
Block(5,37,14,LEAVES:3)
Block(5,37,15,LEAVES:3)
Block(5,37,19,LEAVES:3)
Block(5,42,4,LEAVES:3)
Block(5,42,5,LEAVES:3)
Block(5,43,15,LEAVES:3)
Block(5,44,-12,LEAVES:3)
Block(5,44,-10,LEAVES:3)
Block(5,44,-8,LEAVES:3)
Block(5,44,14,LEAVES:3)
Block(5,45,-14,LEAVES:3)
Block(5,45,-13,LEAVES:3)
Block(5,45,-12,17:15)
Block(5,45,-11,LEAVES:3)
Block(5,45,-10,LEAVES:3)
Block(5,45,-9,LEAVES:3)
Block(5,45,-7,LEAVES:3)
Block(5,45,-6,LEAVES:3)
Block(5,46,-13,LEAVES:3)
Block(5,46,-12,LEAVES:3)
Block(5,46,-10,LEAVES:3)
Block(5,54,4,LEAVES:3)
Block(5,54,6,17:15)
Block(5,54,9,LEAVES:3)
Block(5,54,12,LEAVES:3)
Block(5,55,1,LEAVES:3)
Block(5,55,2,17:15)
Block(5,55,3,LEAVES:3)
Block(5,55,6,LEAVES:3)
Block(5,55,7,LEAVES:3)
Block(5,55,9,LEAVES:3)
Block(5,55,10,17:15)
Block(5,55,11,LEAVES:3)
Block(5,55,12,LEAVES:3)
Block(5,56,0,LEAVES:3)
Block(5,56,2,17:15)
Block(5,56,6,LEAVES:3)
Block(5,56,10,LEAVES:3)
Block(5,56,11,LEAVES:3)
Block(5,57,-6,LEAVES:3)
Block(5,57,-3,LEAVES:3)
Block(5,57,-2,17:15)
Block(5,57,-1,LEAVES:3)
Block(5,57,0,LEAVES:3)
Block(5,57,2,LEAVES:3)
Block(5,57,3,17:15)
Block(5,57,4,LEAVES:3)
Block(5,57,5,LEAVES:3)
Block(5,57,6,LEAVES:3)
Block(5,58,-5,LEAVES:3)
Block(5,58,-3,LEAVES:3)
Block(5,58,-2,LEAVES:3)
Block(5,58,4,LEAVES:3)
Block(5,59,-3,LEAVES:3)
Block(5,72,0,LEAVES:3)
Block(5,73,0,LEAVES:3)
Block(5,73,1,LEAVES:3)
Block(5,73,2,LEAVES:3)
Block(5,73,3,LEAVES:3)
Block(5,74,1,LEAVES:3)
Block(5,74,2,LEAVES:3)
Block(6,24,-10,LEAVES:3)
Block(6,24,-2,LEAVES:3)
Block(6,25,-9,LEAVES:3)
Block(6,25,-5,LEAVES:3)
Block(6,25,-2,17:15)
Block(6,25,-1,LEAVES:3)
Block(6,26,-10,LEAVES:3)
Block(6,26,-9,LEAVES:3)
Block(6,26,-8,LEAVES:3)
Block(6,26,-7,17:15)
Block(6,26,-4,LEAVES:3)
Block(6,26,-3,LEAVES:3)
Block(6,26,-2,LEAVES:3)
Block(6,26,1,LEAVES:3)
Block(6,26,3,LEAVES:3)
Block(6,27,-9,LEAVES:3)
Block(6,27,-8,LEAVES:3)
Block(6,27,-7,LEAVES:3)
Block(6,27,-6,LEAVES:3)
Block(6,27,-3,LEAVES:3)
Block(6,27,0,LEAVES:3)
Block(6,27,1,LEAVES:3)
Block(6,27,2,LEAVES:3)
Block(6,28,-7,LEAVES:3)
Block(6,28,1,LEAVES:3)
Block(6,32,4,LEAVES:3)
Block(6,33,2,LEAVES:3)
Block(6,33,3,LEAVES:3)
Block(6,33,4,LEAVES:3)
Block(6,33,5,17:15)
Block(6,33,6,17:15)
Block(6,33,7,LEAVES:3)
Block(6,34,3,LEAVES:3)
Block(6,34,4,LEAVES:3)
Block(6,34,5,LEAVES:3)
Block(6,34,6,LEAVES:3)
Block(6,34,8,LEAVES:3)
Block(6,34,9,LEAVES:3)
Block(6,34,10,17:15)
Block(6,34,11,LEAVES:3)
Block(6,34,18,LEAVES:3)
Block(6,35,0,17:15)
Block(6,35,1,LEAVES:3)
Block(6,35,4,LEAVES:3)
Block(6,35,9,LEAVES:3)
Block(6,35,10,17:15)
Block(6,35,11,LEAVES:3)
Block(6,35,12,LEAVES:3)
Block(6,35,16,LEAVES:3)
Block(6,35,17,LEAVES:3)
Block(6,35,18,LEAVES:3)
Block(6,36,0,LEAVES:3)
Block(6,36,9,LEAVES:3)
Block(6,36,10,LEAVES:3)
Block(6,36,11,LEAVES:3)
Block(6,36,13,LEAVES:3)
Block(6,36,14,LEAVES:3)
Block(6,36,15,LEAVES:3)
Block(6,36,17,LEAVES:3)
Block(6,36,18,LEAVES:3)
Block(6,36,19,17:15)
Block(6,36,20,LEAVES:3)
Block(6,36,22,LEAVES:3)
Block(6,37,10,LEAVES:3)
Block(6,37,14,LEAVES:3)
Block(6,37,19,LEAVES:3)
Block(6,37,20,LEAVES:3)
Block(6,37,21,LEAVES:3)
Block(6,38,19,LEAVES:3)
Block(6,42,4,LEAVES:3)
Block(6,43,-11,LEAVES:3)
Block(6,44,-14,LEAVES:3)
Block(6,44,-12,LEAVES:3)
Block(6,44,-9,LEAVES:3)
Block(6,45,-13,LEAVES:3)
Block(6,45,-12,LEAVES:3)
Block(6,45,-11,LEAVES:3)
Block(6,45,-10,LEAVES:3)
Block(6,46,-12,LEAVES:3)
Block(6,54,7,17:15)
Block(6,54,8,17:15)
Block(6,55,1,LEAVES:3)
Block(6,55,6,LEAVES:3)
Block(6,55,7,LEAVES:3)
Block(6,55,8,17:15)
Block(6,55,9,17:15)
Block(6,55,10,LEAVES:3)
Block(6,55,11,LEAVES:3)
Block(6,56,-3,LEAVES:3)
Block(6,56,-1,17:15)
Block(6,56,0,17:15)
Block(6,56,1,17:15)
Block(6,56,2,17:15)
Block(6,56,3,17:15)
Block(6,56,4,LEAVES:3)
Block(6,56,5,LEAVES:3)
Block(6,56,6,LEAVES:3)
Block(6,56,8,LEAVES:3)
Block(6,56,9,LEAVES:3)
Block(6,57,-7,LEAVES:3)
Block(6,57,-2,17:15)
Block(6,57,-1,17:15)
Block(6,57,0,LEAVES:3)
Block(6,57,3,LEAVES:3)
Block(6,57,4,LEAVES:3)
Block(6,57,5,LEAVES:3)
Block(6,58,-6,LEAVES:3)
Block(6,58,-5,LEAVES:3)
Block(6,58,-4,LEAVES:3)
Block(6,58,-3,LEAVES:3)
Block(6,58,-2,LEAVES:3)
Block(6,58,-1,LEAVES:3)
Block(6,58,0,LEAVES:3)
Block(6,58,1,LEAVES:3)
Block(6,58,3,LEAVES:3)
Block(6,58,4,LEAVES:3)
Block(6,59,-5,LEAVES:3)
Block(6,59,-2,LEAVES:3)
Block(6,59,0,LEAVES:3)
Block(6,71,1,LEAVES:3)
Block(6,72,2,LEAVES:3)
Block(6,73,0,LEAVES:3)
Block(6,73,1,LEAVES:3)
Block(6,73,2,LEAVES:3)
Block(6,74,1,LEAVES:3)
Block(7,24,0,LEAVES:3)
Block(7,25,-7,LEAVES:3)
Block(7,25,-4,LEAVES:3)
Block(7,25,-3,LEAVES:3)
Block(7,25,-1,LEAVES:3)
Block(7,26,-9,LEAVES:3)
Block(7,26,-8,LEAVES:3)
Block(7,26,-7,LEAVES:3)
Block(7,26,-6,LEAVES:3)
Block(7,26,-3,LEAVES:3)
Block(7,26,-2,17:15)
Block(7,26,0,LEAVES:3)
Block(7,27,-8,LEAVES:3)
Block(7,27,-7,LEAVES:3)
Block(7,27,-2,LEAVES:3)
Block(7,27,0,LEAVES:3)
Block(7,27,1,LEAVES:3)
Block(7,27,2,LEAVES:3)
Block(7,28,1,LEAVES:3)
Block(7,32,2,LEAVES:3)
Block(7,32,4,LEAVES:3)
Block(7,33,3,LEAVES:3)
Block(7,33,4,LEAVES:3)
Block(7,33,6,LEAVES:3)
Block(7,33,8,LEAVES:3)
Block(7,34,4,LEAVES:3)
Block(7,34,5,17:15)
Block(7,34,6,LEAVES:3)
Block(7,34,8,LEAVES:3)
Block(7,34,10,LEAVES:3)
Block(7,34,12,LEAVES:3)
Block(7,34,17,LEAVES:3)
Block(7,35,0,LEAVES:3)
Block(7,35,5,LEAVES:3)
Block(7,35,9,LEAVES:3)
Block(7,35,10,17:15)
Block(7,35,11,17:15)
Block(7,35,12,LEAVES:3)
Block(7,35,13,LEAVES:3)
Block(7,35,14,LEAVES:3)
Block(7,35,15,LEAVES:3)
Block(7,35,17,LEAVES:3)
Block(7,35,18,LEAVES:3)
Block(7,35,19,LEAVES:3)
Block(7,35,21,LEAVES:3)
Block(7,36,10,LEAVES:3)
Block(7,36,12,LEAVES:3)
Block(7,36,14,LEAVES:3)
Block(7,36,18,LEAVES:3)
Block(7,36,19,LEAVES:3)
Block(7,36,20,17:15)
Block(7,36,21,LEAVES:3)
Block(7,36,22,LEAVES:3)
Block(7,37,12,LEAVES:3)
Block(7,37,20,LEAVES:3)
Block(7,37,21,LEAVES:3)
Block(7,44,-11,LEAVES:3)
Block(7,45,-12,LEAVES:3)
Block(7,54,7,17:15)
Block(7,54,11,LEAVES:3)
Block(7,55,4,LEAVES:3)
Block(7,55,7,LEAVES:3)
Block(7,55,8,LEAVES:3)
Block(7,55,9,17:15)
Block(7,55,10,LEAVES:3)
Block(7,55,14,LEAVES:3)
Block(7,56,-3,LEAVES:3)
Block(7,56,-1,LEAVES:3)
Block(7,56,3,17:15)
Block(7,56,4,LEAVES:3)
Block(7,56,5,LEAVES:3)
Block(7,56,9,LEAVES:3)
Block(7,56,10,17:15)
Block(7,56,11,LEAVES:3)
Block(7,56,12,LEAVES:3)
Block(7,56,13,LEAVES:3)
Block(7,57,-6,LEAVES:3)
Block(7,57,-4,LEAVES:3)
Block(7,57,-3,17:15)
Block(7,57,-2,17:15)
Block(7,57,-1,LEAVES:3)
Block(7,57,0,LEAVES:3)
Block(7,57,3,LEAVES:3)
Block(7,57,4,LEAVES:3)
Block(7,57,9,LEAVES:3)
Block(7,57,10,LEAVES:3)
Block(7,58,-7,LEAVES:3)
Block(7,58,-6,LEAVES:3)
Block(7,58,-5,LEAVES:3)
Block(7,58,-4,17:15)
Block(7,58,-3,LEAVES:3)
Block(7,58,-2,LEAVES:3)
Block(7,58,-1,LEAVES:3)
Block(7,58,3,LEAVES:3)
Block(7,59,-6,LEAVES:3)
Block(7,59,-5,LEAVES:3)
Block(7,59,-4,LEAVES:3)
Block(7,59,-3,LEAVES:3)
Block(7,59,-1,LEAVES:3)
Block(7,59,0,LEAVES:3)
Block(7,59,1,LEAVES:3)
Block(7,60,-5,LEAVES:3)
Block(7,60,0,LEAVES:3)
Block(7,72,0,LEAVES:3)
Block(7,73,1,LEAVES:3)
Block(8,25,-9,LEAVES:3)
Block(8,25,-1,LEAVES:3)
Block(8,25,1,LEAVES:3)
Block(8,26,-8,LEAVES:3)
Block(8,26,-2,LEAVES:3)
Block(8,26,-1,17:15)
Block(8,26,0,LEAVES:3)
Block(8,26,1,LEAVES:3)
Block(8,27,-1,LEAVES:3)
Block(8,27,0,LEAVES:3)
Block(8,27,1,LEAVES:3)
Block(8,32,5,LEAVES:3)
Block(8,33,5,LEAVES:3)
Block(8,34,4,LEAVES:3)
Block(8,34,5,LEAVES:3)
Block(8,34,6,LEAVES:3)
Block(8,34,13,LEAVES:3)
Block(8,34,19,LEAVES:3)
Block(8,35,0,LEAVES:3)
Block(8,35,5,LEAVES:3)
Block(8,35,10,LEAVES:3)
Block(8,35,11,17:15)
Block(8,35,12,LEAVES:3)
Block(8,35,18,LEAVES:3)
Block(8,36,9,LEAVES:3)
Block(8,36,10,LEAVES:3)
Block(8,36,11,17:15)
Block(8,36,14,LEAVES:3)
Block(8,36,19,LEAVES:3)
Block(8,36,20,LEAVES:3)
Block(8,36,21,LEAVES:3)
Block(8,37,13,LEAVES:3)
Block(8,37,20,LEAVES:3)
Block(8,55,3,17:15)
Block(8,55,6,17:15)
Block(8,55,7,LEAVES:3)
Block(8,55,8,LEAVES:3)
Block(8,55,9,LEAVES:3)
Block(8,55,10,LEAVES:3)
Block(8,55,11,LEAVES:3)
Block(8,55,12,LEAVES:3)
Block(8,56,-7,LEAVES:3)
Block(8,56,0,LEAVES:3)
Block(8,56,1,LEAVES:3)
Block(8,56,3,17:15)
Block(8,56,4,17:15)
Block(8,56,6,LEAVES:3)
Block(8,56,7,LEAVES:3)
Block(8,56,9,LEAVES:3)
Block(8,56,10,LEAVES:3)
Block(8,56,11,17:15)
Block(8,56,12,LEAVES:3)
Block(8,56,13,LEAVES:3)
Block(8,56,14,LEAVES:3)
Block(8,57,-8,LEAVES:3)
Block(8,57,-5,LEAVES:3)
Block(8,57,-2,LEAVES:3)
Block(8,57,-1,LEAVES:3)
Block(8,57,6,LEAVES:3)
Block(8,57,10,LEAVES:3)
Block(8,57,11,LEAVES:3)
Block(8,57,12,LEAVES:3)
Block(8,57,13,LEAVES:3)
Block(8,58,-7,LEAVES:3)
Block(8,58,-6,LEAVES:3)
Block(8,58,-5,LEAVES:3)
Block(8,58,-4,LEAVES:3)
Block(8,58,-3,LEAVES:3)
Block(8,58,-2,17:15)
Block(8,58,-1,LEAVES:3)
Block(8,58,0,LEAVES:3)
Block(8,58,1,LEAVES:3)
Block(8,58,2,LEAVES:3)
Block(8,58,3,LEAVES:3)
Block(8,58,4,LEAVES:3)
Block(8,58,11,LEAVES:3)
Block(8,59,-5,17:15)
Block(8,59,-4,LEAVES:3)
Block(8,59,-2,LEAVES:3)
Block(8,59,-1,LEAVES:3)
Block(8,59,0,LEAVES:3)
Block(8,59,1,17:15)
Block(8,59,2,LEAVES:3)
Block(8,59,3,LEAVES:3)
Block(8,60,-5,LEAVES:3)
Block(8,60,-1,LEAVES:3)
Block(8,60,0,LEAVES:3)
Block(8,60,1,LEAVES:3)
Block(8,60,2,LEAVES:3)
Block(8,61,1,LEAVES:3)
Block(9,25,-3,LEAVES:3)
Block(9,25,0,LEAVES:3)
Block(9,26,-3,LEAVES:3)
Block(9,26,-2,LEAVES:3)
Block(9,26,-1,LEAVES:3)
Block(9,26,0,LEAVES:3)
Block(9,27,-2,LEAVES:3)
Block(9,27,-1,LEAVES:3)
Block(9,28,-1,LEAVES:3)
Block(9,33,4,LEAVES:3)
Block(9,33,6,LEAVES:3)
Block(9,34,5,LEAVES:3)
Block(9,34,6,LEAVES:3)
Block(9,35,8,LEAVES:3)
Block(9,35,12,LEAVES:3)
Block(9,35,19,LEAVES:3)
Block(9,36,8,LEAVES:3)
Block(9,36,9,LEAVES:3)
Block(9,36,10,17:15)
Block(9,36,11,17:15)
Block(9,36,12,LEAVES:3)
Block(9,36,20,LEAVES:3)
Block(9,37,9,LEAVES:3)
Block(9,37,10,LEAVES:3)
Block(9,37,11,LEAVES:3)
Block(9,37,13,LEAVES:3)
Block(9,37,14,LEAVES:3)
Block(9,37,15,LEAVES:3)
Block(9,38,10,LEAVES:3)
Block(9,38,13,LEAVES:3)
Block(9,54,9,LEAVES:3)
Block(9,55,2,17:15)
Block(9,55,5,LEAVES:3)
Block(9,55,6,LEAVES:3)
Block(9,55,7,17:15)
Block(9,55,8,LEAVES:3)
Block(9,55,9,LEAVES:3)
Block(9,55,13,LEAVES:3)
Block(9,56,1,LEAVES:3)
Block(9,56,2,LEAVES:3)
Block(9,56,3,LEAVES:3)
Block(9,56,4,17:15)
Block(9,56,5,LEAVES:3)
Block(9,56,6,LEAVES:3)
Block(9,56,7,LEAVES:3)
Block(9,56,11,LEAVES:3)
Block(9,56,12,LEAVES:3)
Block(9,56,13,LEAVES:3)
Block(9,57,-7,LEAVES:3)
Block(9,57,-6,LEAVES:3)
Block(9,57,-4,LEAVES:3)
Block(9,57,-3,LEAVES:3)
Block(9,57,1,LEAVES:3)
Block(9,57,4,17:15)
Block(9,57,5,LEAVES:3)
Block(9,57,12,LEAVES:3)
Block(9,58,-8,LEAVES:3)
Block(9,58,-7,LEAVES:3)
Block(9,58,-6,17:15)
Block(9,58,-5,LEAVES:3)
Block(9,58,-4,LEAVES:3)
Block(9,58,-3,LEAVES:3)
Block(9,58,-2,LEAVES:3)
Block(9,58,-1,LEAVES:3)
Block(9,58,2,LEAVES:3)
Block(9,58,3,17:15)
Block(9,58,4,LEAVES:3)
Block(9,59,-7,LEAVES:3)
Block(9,59,-6,LEAVES:3)
Block(9,59,-2,LEAVES:3)
Block(9,59,-1,LEAVES:3)
Block(9,59,0,LEAVES:3)
Block(9,59,1,LEAVES:3)
Block(9,59,2,17:15)
Block(9,59,3,LEAVES:3)
Block(9,60,2,LEAVES:3)
Block(9,60,3,LEAVES:3)
Block(10,25,-1,LEAVES:3)
Block(10,26,-2,LEAVES:3)
Block(10,26,-1,LEAVES:3)
Block(10,26,0,LEAVES:3)
Block(10,27,-1,LEAVES:3)
Block(10,36,9,LEAVES:3)
Block(10,36,10,LEAVES:3)
Block(10,36,11,LEAVES:3)
Block(10,36,12,17:15)
Block(10,36,13,LEAVES:3)
Block(10,36,16,LEAVES:3)
Block(10,37,9,LEAVES:3)
Block(10,37,10,17:15)
Block(10,37,12,LEAVES:3)
Block(10,37,13,17:15)
Block(10,37,14,17:15)
Block(10,37,15,LEAVES:3)
Block(10,37,16,LEAVES:3)
Block(10,38,9,LEAVES:3)
Block(10,38,10,LEAVES:3)
Block(10,38,13,LEAVES:3)
Block(10,38,14,LEAVES:3)
Block(10,38,15,LEAVES:3)
Block(10,39,13,LEAVES:3)
Block(10,54,3,LEAVES:3)
Block(10,54,7,LEAVES:3)
Block(10,55,1,LEAVES:3)
Block(10,55,2,17:15)
Block(10,55,3,LEAVES:3)
Block(10,55,7,LEAVES:3)
Block(10,55,11,LEAVES:3)
Block(10,56,4,LEAVES:3)
Block(10,56,12,LEAVES:3)
Block(10,57,-5,LEAVES:3)
Block(10,57,-1,LEAVES:3)
Block(10,57,4,17:15)
Block(10,57,5,17:15)
Block(10,57,7,LEAVES:3)
Block(10,57,8,LEAVES:3)
Block(10,58,-7,LEAVES:3)
Block(10,58,-6,LEAVES:3)
Block(10,58,-5,LEAVES:3)
Block(10,58,-2,LEAVES:3)
Block(10,58,1,LEAVES:3)
Block(10,58,2,LEAVES:3)
Block(10,58,3,17:15)
Block(10,58,4,17:15)
Block(10,58,5,LEAVES:3)
Block(10,58,7,LEAVES:3)
Block(10,59,-6,LEAVES:3)
Block(10,59,3,LEAVES:3)
Block(11,26,-1,LEAVES:3)
Block(11,35,10,LEAVES:3)
Block(11,36,7,LEAVES:3)
Block(11,36,9,LEAVES:3)
Block(11,36,11,LEAVES:3)
Block(11,36,12,LEAVES:3)
Block(11,36,13,LEAVES:3)
Block(11,36,14,LEAVES:3)
Block(11,37,8,LEAVES:3)
Block(11,37,9,17:15)
Block(11,37,10,LEAVES:3)
Block(11,37,12,LEAVES:3)
Block(11,37,13,LEAVES:3)
Block(11,37,14,LEAVES:3)
Block(11,37,15,LEAVES:3)
Block(11,38,9,LEAVES:3)
Block(11,38,14,LEAVES:3)
Block(11,39,9,LEAVES:3)
Block(11,54,1,LEAVES:3)
Block(11,55,2,LEAVES:3)
Block(11,56,5,LEAVES:3)
Block(11,56,6,LEAVES:3)
Block(11,56,8,LEAVES:3)
Block(11,57,-7,LEAVES:3)
Block(11,57,0,LEAVES:3)
Block(11,57,3,LEAVES:3)
Block(11,57,4,LEAVES:3)
Block(11,57,5,17:15)
Block(11,57,6,17:15)
Block(11,57,7,LEAVES:3)
