#######################################################################
# +-----------------------------------------------------------------+ #
# |                            BO3 object                           | #
# +-----------------------------------------------------------------+ #
#######################################################################

# The descriptions in this file are accurate only for TerrainControl and OTG.
# For MCW and OTG+ these descriptions are only accurate if the BO3 is used as a CustomObject.
# MCW and OTG+ completely reimplemented CustomStructure, check the MCW/OTG+ documentation for more information.

# This is the config file of a custom object.
# If you add this object correctly to your BiomeConfigs, it will spawn in the world.

# This is the creator of this BO3 object
Author: Unknown

# A short description of this BO3 object
Description: This BO3 was converted from a schematic using OTGEdit. The author and description information of the schematic could not be found. If you know who the author of the schematic is then please add this information.

# The BO3 version, don't change this! It can be used by external applications to do a version check.
Version: 3

# The settings mode, WriteAll, WriteWithoutComments or WriteDisable. See WorldConfig.
SettingsMode: WriteDisable

#######################################################################
# +-----------------------------------------------------------------+ #
# |                          Main settings                          | #
# +-----------------------------------------------------------------+ #
#######################################################################

# This needs to be set to true to spawn the object in the Tree and Sapling resources.
Tree: true

# The frequency of the BO3 from 1 to 200. Tries this many times to spawn this BO3 when using the CustomObject(...) resource.
# Ignored by Tree(..), Sapling(..) and CustomStructure(..)
Frequency: 1

# The rarity of the BO3 from 0 to 100. Each spawn attempt has rarity% chance to succeed when using the CustomObject(...) resource.
# Ignored by Tree(..), Sapling(..) and CustomStructure(..)
Rarity: 100.0

# If you set this to true, the BO3 will be placed with a random rotation.
RotateRandomly: false

# The spawn height of the BO3 - randomY, highestBlock or highestSolidBlock.
SpawnHeight: highestBlock

# The height limits for the BO3.
MinHeight: 64

MaxHeight: 80

# Objects can have other objects attached to it: branches. Branches can also
# have branches attached to it, which can also have branches, etc. This is the
# maximum branch depth for this objects.
MaxBranchDepth: 10

# When spawned with the UseWorld keyword, this BO3 should NOT spawn in the following biomes.
# If you writer.write the BO3 name directly in the BiomeConfigs, this will be ignored.
ExcludedBiomes: All

# To optimise this BO3 for faster loading times you can use Notepad++ to find/replace comments and abbreviate things.
# Notepad++ find/replace with regex:
# Find: ^[#;].* replace to nothing removes all lines starting with # 
# Find: ^\s*$ replace to nothing removes most empty lines 
# Notepad++ find/replace without regex:
# *Warning: This will only work for OTG 1.10.2 v21 / OTG 1.11.2 v6 or higher. B( is not recognised by lower versions.
# Find: Block( replace to B(

#######################################################################
# +-----------------------------------------------------------------+ #
# |                      Source block settings                      | #
# +-----------------------------------------------------------------+ #
#######################################################################

# The block(s) the BO3 should spawn in.
SourceBlocks: STONE:1,STONE:3,STONE:5,DIRT:1,DIRT,SAND,GRASS,DIRT:2,STATIONARY_WATER,HARD_CLAY,STAINED_CLAY,CLAY,SANDSTONE,SAND:1,AIR,STONE,GRAVEL,LONG_GRASS,LONG_GRASS:1,LONG_GRASS:2,DEAD_BUSH,YELLOW_FLOWER,RED_ROSE,BROWN_MUSHROOM,RED_MUSHROOM

# The maximum percentage of the BO3 that can be outside the SourceBlock.
# The BO3 won't be placed on a location with more blocks outside the SourceBlock than this percentage.
MaxPercentageOutsideSourceBlock: 0

# What to do when a block is about to be placed outside the SourceBlock? (dontPlace, placeAnyway)
OutsideSourceBlock: placeAnyway

#######################################################################
# +-----------------------------------------------------------------+ #
# |                              Blocks                             | #
# +-----------------------------------------------------------------+ #
#######################################################################

# All the blocks used in the BO3 are listed here. Possible blocks:
# Block(x,y,z,id[.data][,nbtfile.nbt) or B(x,y,z,id[.data][,nbtfile.nbt)
# RandomBlock(x,y,z,id[:data][,nbtfile.nbt],chance[,id[:data][,nbtfile.nbt],chance[,...]])
# So RandomBlock(0,0,0,CHEST,chest.nbt,50,CHEST,anotherchest.nbt,100) will spawn a chest at
# the BO3 origin, and give it a 50% chance to have the contents of chest.nbt, or, if that
# fails, a 100% percent chance to have the contents of anotherchest.nbt.

Block(-18,38,-3,LEAVES:3)
Block(-18,39,-3,LEAVES:3)
Block(-17,36,2,LEAVES:3)
Block(-17,37,2,LEAVES:3)
Block(-17,38,-4,LEAVES:3)
Block(-17,39,-4,LEAVES:3)
Block(-17,39,-3,LEAVES:3)
Block(-17,39,-2,LEAVES:3)
Block(-17,40,-3,LEAVES:3)
Block(-16,36,0,LEAVES:3)
Block(-16,37,1,LEAVES:3)
Block(-16,37,2,LEAVES:3)
Block(-16,37,3,LEAVES:3)
Block(-16,38,-2,LEAVES:3)
Block(-16,38,2,LEAVES:3)
Block(-16,39,-4,LEAVES:3)
Block(-16,39,-3,LEAVES:3)
Block(-16,39,-2,LEAVES:3)
Block(-16,39,-1,LEAVES:3)
Block(-16,40,-3,LEAVES:3)
Block(-16,40,-2,LEAVES:3)
Block(-15,16,-8,LEAVES:3)
Block(-15,16,-6,LEAVES:3)
Block(-15,17,-7,LEAVES:3)
Block(-15,35,5,LEAVES:3)
Block(-15,36,2,LEAVES:3)
Block(-15,36,4,LEAVES:3)
Block(-15,36,5,LEAVES:3)
Block(-15,37,-5,LEAVES:3)
Block(-15,37,0,LEAVES:3)
Block(-15,37,1,LEAVES:3)
Block(-15,37,2,LEAVES:3)
Block(-15,37,3,LEAVES:3)
Block(-15,38,-5,LEAVES:3)
Block(-15,38,-4,LEAVES:3)
Block(-15,38,-1,LEAVES:3)
Block(-15,38,1,LEAVES:3)
Block(-15,38,2,LEAVES:3)
Block(-15,39,-5,LEAVES:3)
Block(-15,39,-4,LEAVES:3)
Block(-15,39,-3,17:15)
Block(-15,39,-2,LEAVES:3)
Block(-15,40,-4,LEAVES:3)
Block(-15,40,-3,LEAVES:3)
Block(-15,41,-3,LEAVES:3)
Block(-14,16,-5,LEAVES:3)
Block(-14,17,-8,LEAVES:3)
Block(-14,17,-7,LEAVES:3)
Block(-14,17,-6,LEAVES:3)
Block(-14,17,-5,LEAVES:3)
Block(-14,18,-7,LEAVES:3)
Block(-14,35,0,LEAVES:3)
Block(-14,36,1,LEAVES:3)
Block(-14,36,4,LEAVES:3)
Block(-14,36,5,LEAVES:3)
Block(-14,36,6,LEAVES:3)
Block(-14,37,-7,LEAVES:3)
Block(-14,37,-3,LEAVES:3)
Block(-14,37,1,LEAVES:3)
Block(-14,37,2,17:15)
Block(-14,37,3,LEAVES:3)
Block(-14,37,5,LEAVES:3)
Block(-14,38,-6,LEAVES:3)
Block(-14,38,-5,LEAVES:3)
Block(-14,38,-4,LEAVES:3)
Block(-14,38,-3,17:15)
Block(-14,38,-2,LEAVES:3)
Block(-14,38,-1,LEAVES:3)
Block(-14,38,2,LEAVES:3)
Block(-14,38,3,LEAVES:3)
Block(-14,39,-5,LEAVES:3)
Block(-14,39,-4,LEAVES:3)
Block(-14,39,-3,LEAVES:3)
Block(-14,39,-2,LEAVES:3)
Block(-14,39,2,LEAVES:3)
Block(-14,40,-3,LEAVES:3)
Block(-13,15,-9,LEAVES:3)
Block(-13,15,-7,LEAVES:3)
Block(-13,16,-9,LEAVES:3)
Block(-13,16,-8,LEAVES:3)
Block(-13,16,-7,LEAVES:3)
Block(-13,16,-4,LEAVES:3)
Block(-13,16,-2,LEAVES:3)
Block(-13,17,-8,LEAVES:3)
Block(-13,17,-7,17:15)
Block(-13,17,-6,LEAVES:3)
Block(-13,17,-3,LEAVES:3)
Block(-13,18,-7,LEAVES:3)
Block(-13,35,1,LEAVES:3)
Block(-13,35,6,LEAVES:3)
Block(-13,36,0,LEAVES:3)
Block(-13,36,1,LEAVES:3)
Block(-13,36,2,17:15)
Block(-13,36,3,LEAVES:3)
Block(-13,36,4,LEAVES:3)
Block(-13,36,5,17:15)
Block(-13,36,6,LEAVES:3)
Block(-13,37,-6,LEAVES:3)
Block(-13,37,-4,LEAVES:3)
Block(-13,37,-1,LEAVES:3)
Block(-13,37,1,LEAVES:3)
Block(-13,37,2,LEAVES:3)
Block(-13,37,3,LEAVES:3)
Block(-13,37,5,LEAVES:3)
Block(-13,37,6,LEAVES:3)
Block(-13,38,-7,LEAVES:3)
Block(-13,38,-6,LEAVES:3)
Block(-13,38,-5,LEAVES:3)
Block(-13,38,-4,17:15)
Block(-13,38,-3,LEAVES:3)
Block(-13,38,-2,LEAVES:3)
Block(-13,38,0,LEAVES:3)
Block(-13,38,2,LEAVES:3)
Block(-13,39,-6,LEAVES:3)
Block(-13,39,-5,LEAVES:3)
Block(-13,39,-4,LEAVES:3)
Block(-13,39,-3,LEAVES:3)
Block(-13,40,-4,LEAVES:3)
Block(-12,15,-8,LEAVES:3)
Block(-12,16,-9,LEAVES:3)
Block(-12,16,-8,LEAVES:3)
Block(-12,16,-7,17:15)
Block(-12,16,-6,LEAVES:3)
Block(-12,17,-8,LEAVES:3)
Block(-12,17,-7,LEAVES:3)
Block(-12,17,-6,LEAVES:3)
Block(-12,17,-4,LEAVES:3)
Block(-12,17,-3,LEAVES:3)
Block(-12,17,-2,LEAVES:3)
Block(-12,18,-3,LEAVES:3)
Block(-12,35,4,LEAVES:3)
Block(-12,36,1,LEAVES:3)
Block(-12,36,2,LEAVES:3)
Block(-12,36,3,17:15)
Block(-12,36,4,17:15)
Block(-12,36,5,LEAVES:3)
Block(-12,36,6,LEAVES:3)
Block(-12,37,2,LEAVES:3)
Block(-12,37,3,LEAVES:3)
Block(-12,37,4,LEAVES:3)
Block(-12,37,6,LEAVES:3)
Block(-12,38,-6,LEAVES:3)
Block(-12,38,-5,LEAVES:3)
Block(-12,38,-4,17:15)
Block(-12,38,-3,LEAVES:3)
Block(-12,38,-2,LEAVES:3)
Block(-12,38,-1,LEAVES:3)
Block(-12,38,0,LEAVES:3)
Block(-12,38,1,LEAVES:3)
Block(-12,38,3,LEAVES:3)
Block(-12,39,-4,LEAVES:3)
Block(-12,39,-3,LEAVES:3)
Block(-12,39,0,LEAVES:3)
Block(-12,46,0,LEAVES:3)
Block(-11,15,-6,LEAVES:3)
Block(-11,15,-4,LEAVES:3)
Block(-11,16,-8,LEAVES:3)
Block(-11,16,-7,LEAVES:3)
Block(-11,16,-6,17:15)
Block(-11,16,-5,LEAVES:3)
Block(-11,16,-3,LEAVES:3)
Block(-11,17,-7,LEAVES:3)
Block(-11,17,-6,LEAVES:3)
Block(-11,17,-4,LEAVES:3)
Block(-11,17,-3,17:15)
Block(-11,17,-2,LEAVES:3)
Block(-11,17,0,LEAVES:3)
Block(-11,18,-6,LEAVES:3)
Block(-11,18,-4,LEAVES:3)
Block(-11,18,-3,LEAVES:3)
Block(-11,35,1,LEAVES:3)
Block(-11,35,3,17:15)
Block(-11,35,6,LEAVES:3)
Block(-11,36,3,LEAVES:3)
Block(-11,36,4,LEAVES:3)
Block(-11,36,5,LEAVES:3)
Block(-11,37,-7,LEAVES:3)
Block(-11,37,-5,17:15)
Block(-11,37,-3,LEAVES:3)
Block(-11,37,2,LEAVES:3)
Block(-11,37,3,LEAVES:3)
Block(-11,37,4,LEAVES:3)
Block(-11,37,5,LEAVES:3)
Block(-11,38,-6,LEAVES:3)
Block(-11,38,-5,LEAVES:3)
Block(-11,38,-4,LEAVES:3)
Block(-11,38,-3,LEAVES:3)
Block(-11,38,-1,LEAVES:3)
Block(-11,38,0,17:15)
Block(-11,38,1,LEAVES:3)
Block(-11,38,3,LEAVES:3)
Block(-11,38,4,LEAVES:3)
Block(-11,39,-5,LEAVES:3)
Block(-11,39,-1,LEAVES:3)
Block(-11,39,0,LEAVES:3)
Block(-11,40,0,LEAVES:3)
Block(-11,45,0,LEAVES:3)
Block(-11,45,2,LEAVES:3)
Block(-11,46,-1,LEAVES:3)
Block(-11,46,0,LEAVES:3)
Block(-11,46,1,LEAVES:3)
Block(-11,47,0,LEAVES:3)
Block(-10,15,-1,LEAVES:3)
Block(-10,16,-8,LEAVES:3)
Block(-10,16,-7,LEAVES:3)
Block(-10,16,-6,17:15)
Block(-10,16,-4,LEAVES:3)
Block(-10,16,2,LEAVES:3)
Block(-10,17,-7,LEAVES:3)
Block(-10,17,-6,LEAVES:3)
Block(-10,17,-5,LEAVES:3)
Block(-10,17,-4,17:15)
Block(-10,17,-3,LEAVES:3)
Block(-10,17,-1,LEAVES:3)
Block(-10,17,0,LEAVES:3)
Block(-10,17,1,LEAVES:3)
Block(-10,18,-5,LEAVES:3)
Block(-10,18,-4,LEAVES:3)
Block(-10,18,0,LEAVES:3)
Block(-10,19,-4,LEAVES:3)
Block(-10,35,1,LEAVES:3)
Block(-10,35,3,17:15)
Block(-10,36,1,LEAVES:3)
Block(-10,36,2,LEAVES:3)
Block(-10,36,4,LEAVES:3)
Block(-10,36,5,LEAVES:3)
Block(-10,37,-5,17:15)
Block(-10,37,-4,17:15)
Block(-10,37,-3,LEAVES:3)
Block(-10,37,-1,LEAVES:3)
Block(-10,37,0,17:15)
Block(-10,37,1,LEAVES:3)
Block(-10,37,2,LEAVES:3)
Block(-10,37,3,17:15)
Block(-10,37,4,LEAVES:3)
Block(-10,38,-5,LEAVES:3)
Block(-10,38,-4,LEAVES:3)
Block(-10,38,0,LEAVES:3)
Block(-10,38,2,LEAVES:3)
Block(-10,38,3,LEAVES:3)
Block(-10,39,3,LEAVES:3)
Block(-10,44,-3,LEAVES:3)
Block(-10,45,-4,LEAVES:3)
Block(-10,45,-2,LEAVES:3)
Block(-10,45,4,LEAVES:3)
Block(-10,46,-2,LEAVES:3)
Block(-10,46,-1,LEAVES:3)
Block(-10,46,0,LEAVES:3)
Block(-10,46,1,LEAVES:3)
Block(-10,46,2,LEAVES:3)
Block(-10,46,3,LEAVES:3)
Block(-10,47,0,LEAVES:3)
Block(-9,14,-4,LEAVES:3)
Block(-9,15,-5,17:15)
Block(-9,16,-9,LEAVES:3)
Block(-9,16,-8,LEAVES:3)
Block(-9,16,-7,LEAVES:3)
Block(-9,16,-6,17:15)
Block(-9,16,-5,17:15)
Block(-9,16,-4,LEAVES:3)
Block(-9,16,-2,LEAVES:3)
Block(-9,16,-1,LEAVES:3)
Block(-9,16,0,LEAVES:3)
Block(-9,17,-9,LEAVES:3)
Block(-9,17,-8,LEAVES:3)
Block(-9,17,-7,LEAVES:3)
Block(-9,17,-6,LEAVES:3)
Block(-9,17,-5,LEAVES:3)
Block(-9,17,-2,LEAVES:3)
Block(-9,17,-1,LEAVES:3)
Block(-9,17,0,LEAVES:3)
Block(-9,17,1,LEAVES:3)
Block(-9,17,2,LEAVES:3)
Block(-9,18,-7,LEAVES:3)
Block(-9,18,0,LEAVES:3)
Block(-9,18,1,LEAVES:3)
Block(-9,35,-6,LEAVES:3)
Block(-9,35,-1,LEAVES:3)
Block(-9,35,3,LEAVES:3)
Block(-9,36,-7,LEAVES:3)
Block(-9,36,-3,17:15)
Block(-9,36,0,LEAVES:3)
Block(-9,36,1,LEAVES:3)
Block(-9,36,2,LEAVES:3)
Block(-9,36,3,17:15)
Block(-9,36,4,LEAVES:3)
Block(-9,36,5,LEAVES:3)
Block(-9,37,-4,17:15)
Block(-9,37,-3,17:15)
Block(-9,37,-2,LEAVES:3)
Block(-9,37,-1,17:15)
Block(-9,37,1,LEAVES:3)
Block(-9,37,2,LEAVES:3)
Block(-9,37,3,LEAVES:3)
Block(-9,37,4,LEAVES:3)
Block(-9,38,-5,LEAVES:3)
Block(-9,38,-4,LEAVES:3)
Block(-9,38,-3,LEAVES:3)
Block(-9,38,-1,LEAVES:3)
Block(-9,38,3,LEAVES:3)
Block(-9,39,-4,LEAVES:3)
Block(-9,44,-4,LEAVES:3)
Block(-9,45,-5,LEAVES:3)
Block(-9,45,-4,LEAVES:3)
Block(-9,45,-3,LEAVES:3)
Block(-9,45,0,LEAVES:3)
Block(-9,45,3,LEAVES:3)
Block(-9,46,-4,LEAVES:3)
Block(-9,46,-2,LEAVES:3)
Block(-9,46,-1,LEAVES:3)
Block(-9,46,0,17:15)
Block(-9,46,1,LEAVES:3)
Block(-9,46,2,LEAVES:3)
Block(-9,46,3,LEAVES:3)
Block(-9,46,4,LEAVES:3)
Block(-9,47,-1,LEAVES:3)
Block(-9,47,0,LEAVES:3)
Block(-9,47,3,LEAVES:3)
Block(-9,48,0,LEAVES:3)
Block(-8,15,-10,LEAVES:3)
Block(-8,15,-7,LEAVES:3)
Block(-8,15,-5,17:15)
Block(-8,15,-4,LEAVES:3)
Block(-8,15,-2,LEAVES:3)
Block(-8,16,-8,LEAVES:3)
Block(-8,16,-7,LEAVES:3)
Block(-8,16,-5,LEAVES:3)
Block(-8,16,-3,LEAVES:3)
Block(-8,16,-2,LEAVES:3)
Block(-8,16,-1,17:15)
Block(-8,16,1,LEAVES:3)
Block(-8,17,-10,LEAVES:3)
Block(-8,17,-9,LEAVES:3)
Block(-8,17,-8,LEAVES:3)
Block(-8,17,-7,LEAVES:3)
Block(-8,17,-6,LEAVES:3)
Block(-8,17,-3,LEAVES:3)
Block(-8,17,-2,LEAVES:3)
Block(-8,17,-1,LEAVES:3)
Block(-8,17,0,17:15)
Block(-8,17,1,LEAVES:3)
Block(-8,18,-9,LEAVES:3)
Block(-8,18,-8,LEAVES:3)
Block(-8,18,-2,LEAVES:3)
Block(-8,18,0,LEAVES:3)
Block(-8,18,1,LEAVES:3)
Block(-8,19,0,LEAVES:3)
Block(-8,24,-10,LEAVES:3)
Block(-8,25,-11,LEAVES:3)
Block(-8,27,0,LEAVES:3)
Block(-8,28,1,LEAVES:3)
Block(-8,34,-7,LEAVES:3)
Block(-8,35,-10,LEAVES:3)
Block(-8,35,-8,LEAVES:3)
Block(-8,35,0,LEAVES:3)
Block(-8,35,2,LEAVES:3)
Block(-8,35,5,LEAVES:3)
Block(-8,36,-9,LEAVES:3)
Block(-8,36,-8,LEAVES:3)
Block(-8,36,-7,LEAVES:3)
Block(-8,36,-6,LEAVES:3)
Block(-8,36,-5,LEAVES:3)
Block(-8,36,-3,LEAVES:3)
Block(-8,36,-2,17:15)
Block(-8,36,-1,LEAVES:3)
Block(-8,36,0,LEAVES:3)
Block(-8,36,1,LEAVES:3)
Block(-8,36,2,17:15)
Block(-8,36,3,LEAVES:3)
Block(-8,36,4,LEAVES:3)
Block(-8,36,9,LEAVES:3)
Block(-8,37,-7,LEAVES:3)
Block(-8,37,-5,LEAVES:3)
Block(-8,37,-4,LEAVES:3)
Block(-8,37,-3,LEAVES:3)
Block(-8,37,-2,17:15)
Block(-8,37,-1,LEAVES:3)
Block(-8,37,0,LEAVES:3)
Block(-8,37,1,LEAVES:3)
Block(-8,37,2,LEAVES:3)
Block(-8,37,3,LEAVES:3)
Block(-8,37,8,LEAVES:3)
Block(-8,37,11,LEAVES:3)
Block(-8,38,-4,LEAVES:3)
Block(-8,38,-2,LEAVES:3)
Block(-8,38,2,LEAVES:3)
Block(-8,38,10,LEAVES:3)
Block(-8,44,-5,LEAVES:3)
Block(-8,44,-1,LEAVES:3)
Block(-8,45,-6,LEAVES:3)
Block(-8,45,-5,LEAVES:3)
Block(-8,45,-4,LEAVES:3)
Block(-8,45,-3,LEAVES:3)
Block(-8,45,-1,LEAVES:3)
Block(-8,45,0,17:15)
Block(-8,45,1,LEAVES:3)
Block(-8,45,5,LEAVES:3)
Block(-8,46,-5,LEAVES:3)
Block(-8,46,-4,LEAVES:3)
Block(-8,46,0,LEAVES:3)
Block(-8,46,2,LEAVES:3)
Block(-8,46,3,17:15)
Block(-8,46,4,LEAVES:3)
Block(-8,46,5,LEAVES:3)
Block(-8,47,0,LEAVES:3)
Block(-8,47,3,LEAVES:3)
Block(-8,47,4,LEAVES:3)
Block(-7,-6,-1,17:15)
Block(-7,-5,-1,17:15)
Block(-7,-4,-1,17:15)
Block(-7,15,-6,LEAVES:3)
Block(-7,15,-5,17:15)
Block(-7,15,-3,17:15)
Block(-7,15,1,LEAVES:3)
Block(-7,16,-10,LEAVES:3)
Block(-7,16,-3,LEAVES:3)
Block(-7,16,-2,17:15)
Block(-7,16,-1,LEAVES:3)
Block(-7,16,0,LEAVES:3)
Block(-7,17,-11,LEAVES:3)
Block(-7,17,-10,LEAVES:3)
Block(-7,17,-9,LEAVES:3)
Block(-7,17,-8,17:15)
Block(-7,17,-7,LEAVES:3)
Block(-7,17,-6,LEAVES:3)
Block(-7,17,-5,LEAVES:3)
Block(-7,17,-4,LEAVES:3)
Block(-7,17,-2,LEAVES:3)
Block(-7,17,-1,LEAVES:3)
Block(-7,17,0,LEAVES:3)
Block(-7,18,-10,LEAVES:3)
Block(-7,18,-9,LEAVES:3)
Block(-7,18,-8,LEAVES:3)
Block(-7,18,-6,LEAVES:3)
Block(-7,18,0,LEAVES:3)
Block(-7,19,-9,LEAVES:3)
Block(-7,23,-10,LEAVES:3)
Block(-7,24,-13,LEAVES:3)
Block(-7,24,-11,LEAVES:3)
Block(-7,24,-8,LEAVES:3)
Block(-7,25,-12,LEAVES:3)
Block(-7,25,-11,LEAVES:3)
Block(-7,25,-10,LEAVES:3)
Block(-7,25,-9,LEAVES:3)
Block(-7,26,-11,LEAVES:3)
Block(-7,26,1,LEAVES:3)
Block(-7,27,2,LEAVES:3)
Block(-7,28,0,LEAVES:3)
Block(-7,28,1,LEAVES:3)
Block(-7,28,2,LEAVES:3)
Block(-7,28,9,LEAVES:3)
Block(-7,28,14,LEAVES:3)
Block(-7,29,1,LEAVES:3)
Block(-7,29,10,LEAVES:3)
Block(-7,29,13,LEAVES:3)
Block(-7,34,2,17:15)
Block(-7,35,-7,LEAVES:3)
Block(-7,36,-10,LEAVES:3)
Block(-7,36,-9,LEAVES:3)
Block(-7,36,-8,LEAVES:3)
Block(-7,36,-7,17:15)
Block(-7,36,-6,LEAVES:3)
Block(-7,36,-4,LEAVES:3)
Block(-7,36,-2,17:15)
Block(-7,36,0,LEAVES:3)
Block(-7,36,1,LEAVES:3)
Block(-7,36,2,17:15)
Block(-7,36,3,LEAVES:3)
Block(-7,36,4,LEAVES:3)
Block(-7,36,6,LEAVES:3)
Block(-7,36,8,LEAVES:3)
Block(-7,37,-9,LEAVES:3)
Block(-7,37,-8,LEAVES:3)
Block(-7,37,-7,LEAVES:3)
Block(-7,37,-5,LEAVES:3)
Block(-7,37,-4,LEAVES:3)
Block(-7,37,-3,LEAVES:3)
Block(-7,37,-2,LEAVES:3)
Block(-7,37,-1,LEAVES:3)
Block(-7,37,2,LEAVES:3)
Block(-7,37,3,LEAVES:3)
Block(-7,37,7,LEAVES:3)
Block(-7,37,8,LEAVES:3)
Block(-7,37,9,LEAVES:3)
Block(-7,38,-7,LEAVES:3)
Block(-7,38,-4,LEAVES:3)
Block(-7,38,-3,LEAVES:3)
Block(-7,38,-2,LEAVES:3)
Block(-7,38,8,LEAVES:3)
Block(-7,38,9,LEAVES:3)
Block(-7,38,10,LEAVES:3)
Block(-7,38,11,LEAVES:3)
Block(-7,39,-3,LEAVES:3)
Block(-7,39,10,LEAVES:3)
Block(-7,43,5,LEAVES:3)
Block(-7,44,-4,LEAVES:3)
Block(-7,44,-1,LEAVES:3)
Block(-7,44,1,LEAVES:3)
Block(-7,44,4,LEAVES:3)
Block(-7,45,-5,LEAVES:3)
Block(-7,45,-4,17:15)
Block(-7,45,-3,LEAVES:3)
Block(-7,45,-2,LEAVES:3)
Block(-7,45,-1,LEAVES:3)
Block(-7,45,1,17:15)
Block(-7,45,3,LEAVES:3)
Block(-7,45,4,LEAVES:3)
Block(-7,46,-5,LEAVES:3)
Block(-7,46,-4,LEAVES:3)
Block(-7,46,-1,LEAVES:3)
Block(-7,46,1,LEAVES:3)
Block(-7,46,2,17:15)
Block(-7,46,3,LEAVES:3)
Block(-7,46,4,LEAVES:3)
Block(-7,47,1,LEAVES:3)
Block(-7,47,2,LEAVES:3)
Block(-7,48,2,LEAVES:3)
Block(-6,-6,1,17:15)
Block(-6,-5,0,17:15)
Block(-6,-4,0,17:15)
Block(-6,15,-5,17:15)
Block(-6,15,-4,17:15)
Block(-6,15,-3,17:15)
Block(-6,15,0,LEAVES:3)
Block(-6,16,-11,LEAVES:3)
Block(-6,16,-9,LEAVES:3)
Block(-6,16,-7,LEAVES:3)
Block(-6,16,-6,17:15)
Block(-6,16,-5,17:15)
Block(-6,16,-4,LEAVES:3)
Block(-6,16,-3,LEAVES:3)
Block(-6,16,-1,LEAVES:3)
Block(-6,16,0,LEAVES:3)
Block(-6,16,1,LEAVES:3)
Block(-6,17,-10,LEAVES:3)
Block(-6,17,-9,LEAVES:3)
Block(-6,17,-8,LEAVES:3)
Block(-6,17,-7,17:15)
Block(-6,17,-6,LEAVES:3)
Block(-6,17,-5,LEAVES:3)
Block(-6,17,-4,LEAVES:3)
Block(-6,17,-3,LEAVES:3)
Block(-6,17,0,LEAVES:3)
Block(-6,18,-9,LEAVES:3)
Block(-6,18,-8,LEAVES:3)
Block(-6,18,-7,LEAVES:3)
Block(-6,18,-6,LEAVES:3)
Block(-6,18,-4,LEAVES:3)
Block(-6,19,-7,LEAVES:3)
Block(-6,24,-11,LEAVES:3)
Block(-6,24,-9,LEAVES:3)
Block(-6,24,-7,LEAVES:3)
Block(-6,25,-13,LEAVES:3)
Block(-6,25,-12,LEAVES:3)
Block(-6,25,-11,17:15)
Block(-6,25,-10,LEAVES:3)
Block(-6,25,-9,LEAVES:3)
Block(-6,25,-8,LEAVES:3)
Block(-6,25,-6,LEAVES:3)
Block(-6,25,-5,LEAVES:3)
Block(-6,26,-12,LEAVES:3)
Block(-6,26,-11,LEAVES:3)
Block(-6,26,-9,LEAVES:3)
Block(-6,27,0,LEAVES:3)
Block(-6,27,3,LEAVES:3)
Block(-6,28,0,LEAVES:3)
Block(-6,28,1,LEAVES:3)
Block(-6,28,2,LEAVES:3)
Block(-6,28,3,LEAVES:3)
Block(-6,28,11,LEAVES:3)
Block(-6,28,13,LEAVES:3)
Block(-6,29,0,LEAVES:3)
Block(-6,29,1,LEAVES:3)
Block(-6,29,2,LEAVES:3)
Block(-6,29,9,LEAVES:3)
Block(-6,29,10,LEAVES:3)
Block(-6,29,11,LEAVES:3)
Block(-6,29,12,LEAVES:3)
Block(-6,29,13,LEAVES:3)
Block(-6,29,14,LEAVES:3)
Block(-6,30,1,LEAVES:3)
Block(-6,30,10,LEAVES:3)
Block(-6,30,13,LEAVES:3)
Block(-6,34,1,17:15)
Block(-6,35,-9,LEAVES:3)
Block(-6,35,-6,LEAVES:3)
Block(-6,35,-2,17:15)
Block(-6,35,-1,LEAVES:3)
Block(-6,35,1,17:15)
Block(-6,35,2,17:15)
Block(-6,35,3,17:15)
Block(-6,35,4,LEAVES:3)
Block(-6,36,-9,LEAVES:3)
Block(-6,36,-8,LEAVES:3)
Block(-6,36,-7,LEAVES:3)
Block(-6,36,-6,17:15)
Block(-6,36,-2,17:15)
Block(-6,36,-1,17:15)
Block(-6,36,0,LEAVES:3)
Block(-6,36,1,LEAVES:3)
Block(-6,36,2,LEAVES:3)
Block(-6,36,3,LEAVES:3)
Block(-6,36,5,LEAVES:3)
Block(-6,37,-7,LEAVES:3)
Block(-6,37,-6,LEAVES:3)
Block(-6,37,-4,LEAVES:3)
Block(-6,37,-3,LEAVES:3)
Block(-6,37,-2,LEAVES:3)
Block(-6,37,-1,LEAVES:3)
Block(-6,37,1,LEAVES:3)
Block(-6,37,7,LEAVES:3)
Block(-6,37,8,17:15)
Block(-6,37,10,LEAVES:3)
Block(-6,37,12,LEAVES:3)
Block(-6,38,-3,LEAVES:3)
Block(-6,38,7,LEAVES:3)
Block(-6,38,8,LEAVES:3)
Block(-6,38,9,17:15)
Block(-6,38,10,LEAVES:3)
Block(-6,38,11,LEAVES:3)
Block(-6,38,12,LEAVES:3)
Block(-6,39,8,LEAVES:3)
Block(-6,39,9,LEAVES:3)
Block(-6,39,10,LEAVES:3)
Block(-6,39,11,LEAVES:3)
Block(-6,40,9,LEAVES:3)
Block(-6,42,3,LEAVES:3)
Block(-6,43,4,LEAVES:3)
Block(-6,44,-5,LEAVES:3)
Block(-6,44,-2,LEAVES:3)
Block(-6,44,0,17:15)
Block(-6,44,3,LEAVES:3)
Block(-6,44,4,LEAVES:3)
Block(-6,44,5,LEAVES:3)
Block(-6,45,-5,LEAVES:3)
Block(-6,45,-4,17:15)
Block(-6,45,-3,LEAVES:3)
Block(-6,45,-2,LEAVES:3)
Block(-6,45,-1,LEAVES:3)
Block(-6,45,0,17:15)
Block(-6,45,1,LEAVES:3)
Block(-6,45,2,LEAVES:3)
Block(-6,45,4,LEAVES:3)
Block(-6,46,-4,LEAVES:3)
Block(-6,46,-3,LEAVES:3)
Block(-6,46,-2,LEAVES:3)
Block(-6,46,-1,LEAVES:3)
Block(-6,46,0,LEAVES:3)
Block(-6,46,2,LEAVES:3)
Block(-6,46,3,LEAVES:3)
Block(-6,46,4,LEAVES:3)
Block(-6,47,-1,LEAVES:3)
Block(-6,47,2,LEAVES:3)
Block(-6,47,3,LEAVES:3)
Block(-5,-6,-2,17:15)
Block(-5,-6,1,17:15)
Block(-5,-5,1,17:15)
Block(-5,-4,0,17:15)
Block(-5,-3,0,17:15)
Block(-5,-2,0,17:15)
Block(-5,15,-4,17:15)
Block(-5,15,2,LEAVES:3)
Block(-5,16,-6,LEAVES:3)
Block(-5,16,-5,LEAVES:3)
Block(-5,16,-4,LEAVES:3)
Block(-5,16,-2,LEAVES:3)
Block(-5,16,-1,LEAVES:3)
Block(-5,16,0,17:15)
Block(-5,16,1,LEAVES:3)
Block(-5,16,2,LEAVES:3)
Block(-5,17,-7,LEAVES:3)
Block(-5,17,-6,LEAVES:3)
Block(-5,17,-5,LEAVES:3)
Block(-5,17,-4,LEAVES:3)
Block(-5,17,-3,LEAVES:3)
Block(-5,17,-2,LEAVES:3)
Block(-5,17,-1,LEAVES:3)
Block(-5,17,0,LEAVES:3)
Block(-5,17,1,LEAVES:3)
Block(-5,18,-7,LEAVES:3)
Block(-5,18,-5,LEAVES:3)
Block(-5,18,-4,LEAVES:3)
Block(-5,18,-3,LEAVES:3)
Block(-5,18,0,LEAVES:3)
Block(-5,19,-4,LEAVES:3)
Block(-5,24,-12,LEAVES:3)
Block(-5,24,-10,LEAVES:3)
Block(-5,24,-5,LEAVES:3)
Block(-5,25,-12,LEAVES:3)
Block(-5,25,-11,LEAVES:3)
Block(-5,25,-10,LEAVES:3)
Block(-5,25,-9,LEAVES:3)
Block(-5,25,-8,LEAVES:3)
Block(-5,25,-7,LEAVES:3)
Block(-5,25,-5,LEAVES:3)
Block(-5,25,-4,LEAVES:3)
Block(-5,26,-10,17:15)
Block(-5,26,-9,LEAVES:3)
Block(-5,26,-8,LEAVES:3)
Block(-5,26,-6,LEAVES:3)
Block(-5,26,-5,LEAVES:3)
Block(-5,26,0,LEAVES:3)
Block(-5,27,-10,LEAVES:3)
Block(-5,27,-9,LEAVES:3)
Block(-5,27,1,LEAVES:3)
Block(-5,27,7,LEAVES:3)
Block(-5,27,9,LEAVES:3)
Block(-5,27,14,LEAVES:3)
Block(-5,28,-1,LEAVES:3)
Block(-5,28,0,LEAVES:3)
Block(-5,28,1,17:15)
Block(-5,28,2,LEAVES:3)
Block(-5,28,8,LEAVES:3)
Block(-5,28,9,LEAVES:3)
Block(-5,28,15,LEAVES:3)
Block(-5,29,0,LEAVES:3)
Block(-5,29,1,LEAVES:3)
Block(-5,29,2,LEAVES:3)
Block(-5,29,9,LEAVES:3)
Block(-5,29,10,17:15)
Block(-5,29,11,17:15)
Block(-5,29,12,17:15)
Block(-5,29,13,LEAVES:3)
Block(-5,29,14,LEAVES:3)
Block(-5,29,15,LEAVES:3)
Block(-5,30,10,LEAVES:3)
Block(-5,30,11,LEAVES:3)
Block(-5,30,12,LEAVES:3)
Block(-5,30,13,LEAVES:3)
Block(-5,30,14,LEAVES:3)
Block(-5,31,12,LEAVES:3)
Block(-5,34,1,17:15)
Block(-5,34,4,LEAVES:3)
Block(-5,35,-8,LEAVES:3)
Block(-5,35,-3,17:15)
Block(-5,35,-1,17:15)
Block(-5,35,1,17:15)
Block(-5,35,3,17:15)
Block(-5,35,4,17:15)
Block(-5,36,-6,LEAVES:3)
Block(-5,36,-5,17:15)
Block(-5,36,-4,17:15)
Block(-5,36,-3,LEAVES:3)
Block(-5,36,-1,17:15)
Block(-5,36,0,LEAVES:3)
Block(-5,36,1,LEAVES:3)
Block(-5,36,3,LEAVES:3)
Block(-5,36,4,LEAVES:3)
Block(-5,36,5,17:15)
Block(-5,36,6,17:15)
Block(-5,37,-4,LEAVES:3)
Block(-5,37,-2,LEAVES:3)
Block(-5,37,-1,LEAVES:3)
Block(-5,37,0,LEAVES:3)
Block(-5,37,3,LEAVES:3)
Block(-5,37,6,LEAVES:3)
Block(-5,37,7,17:15)
Block(-5,38,7,LEAVES:3)
Block(-5,38,8,LEAVES:3)
Block(-5,38,9,LEAVES:3)
Block(-5,38,10,LEAVES:3)
Block(-5,38,11,LEAVES:3)
Block(-5,39,9,LEAVES:3)
Block(-5,43,-1,LEAVES:3)
Block(-5,43,2,LEAVES:3)
Block(-5,43,6,LEAVES:3)
Block(-5,44,-3,LEAVES:3)
Block(-5,44,-1,17:15)
Block(-5,44,0,LEAVES:3)
Block(-5,44,3,LEAVES:3)
Block(-5,44,4,LEAVES:3)
Block(-5,44,5,LEAVES:3)
Block(-5,44,6,LEAVES:3)
Block(-5,45,-4,LEAVES:3)
Block(-5,45,-3,17:15)
Block(-5,45,-2,17:15)
Block(-5,45,-1,LEAVES:3)
Block(-5,45,0,LEAVES:3)
Block(-5,45,1,LEAVES:3)
Block(-5,45,3,LEAVES:3)
Block(-5,45,4,LEAVES:3)
Block(-5,45,5,LEAVES:3)
Block(-5,46,-3,LEAVES:3)
Block(-5,46,-2,LEAVES:3)
Block(-5,46,0,LEAVES:3)
Block(-5,46,1,LEAVES:3)
Block(-5,46,2,LEAVES:3)
Block(-5,46,3,LEAVES:3)
Block(-5,47,-2,LEAVES:3)
Block(-5,47,2,LEAVES:3)
Block(-4,-6,-4,17:15)
Block(-4,-6,-1,17:15)
Block(-4,-6,4,17:15)
Block(-4,-5,-1,17:15)
Block(-4,-5,2,17:15)
Block(-4,-4,-1,17:15)
Block(-4,-4,2,17:15)
Block(-4,-2,0,17:15)
Block(-4,-1,0,17:15)
Block(-4,14,-6,LEAVES:3)
Block(-4,14,-3,17:15)
Block(-4,15,-5,LEAVES:3)
Block(-4,15,-4,17:15)
Block(-4,15,-3,17:15)
Block(-4,15,-2,LEAVES:3)
Block(-4,15,0,LEAVES:3)
Block(-4,16,-7,LEAVES:3)
Block(-4,16,-4,LEAVES:3)
Block(-4,16,-3,LEAVES:3)
Block(-4,16,-2,17:15)
Block(-4,16,-1,17:15)
Block(-4,16,0,LEAVES:3)
Block(-4,16,1,LEAVES:3)
Block(-4,17,-4,LEAVES:3)
Block(-4,17,-2,LEAVES:3)
Block(-4,17,-1,LEAVES:3)
Block(-4,18,-3,LEAVES:3)
Block(-4,24,-11,LEAVES:3)
Block(-4,24,-9,LEAVES:3)
Block(-4,25,-11,LEAVES:3)
Block(-4,25,-10,LEAVES:3)
Block(-4,25,-9,17:15)
Block(-4,25,-8,LEAVES:3)
Block(-4,25,-6,LEAVES:3)
Block(-4,25,-5,17:15)
Block(-4,25,-4,LEAVES:3)
Block(-4,25,-3,LEAVES:3)
Block(-4,26,-10,LEAVES:3)
Block(-4,26,-9,LEAVES:3)
Block(-4,26,-6,LEAVES:3)
Block(-4,26,-5,LEAVES:3)
Block(-4,26,-4,LEAVES:3)
Block(-4,27,0,LEAVES:3)
Block(-4,27,3,17:15)
Block(-4,27,4,LEAVES:3)
Block(-4,27,6,LEAVES:3)
Block(-4,28,0,LEAVES:3)
Block(-4,28,1,LEAVES:3)
Block(-4,28,2,17:15)
Block(-4,28,3,LEAVES:3)
Block(-4,28,6,LEAVES:3)
Block(-4,28,7,LEAVES:3)
Block(-4,28,8,LEAVES:3)
Block(-4,28,9,17:15)
Block(-4,28,10,17:15)
Block(-4,28,12,LEAVES:3)
Block(-4,29,1,LEAVES:3)
Block(-4,29,2,LEAVES:3)
Block(-4,29,3,LEAVES:3)
Block(-4,29,8,LEAVES:3)
Block(-4,29,10,17:15)
Block(-4,29,11,LEAVES:3)
Block(-4,29,12,LEAVES:3)
Block(-4,29,13,LEAVES:3)
Block(-4,29,14,LEAVES:3)
Block(-4,30,2,LEAVES:3)
Block(-4,30,11,LEAVES:3)
Block(-4,30,12,LEAVES:3)
Block(-4,35,-2,17:15)
Block(-4,35,-1,17:15)
Block(-4,35,0,17:15)
Block(-4,35,4,LEAVES:3)
Block(-4,36,-6,LEAVES:3)
Block(-4,36,-5,LEAVES:3)
Block(-4,36,-4,17:15)
Block(-4,36,-2,LEAVES:3)
Block(-4,36,-1,17:15)
Block(-4,36,0,LEAVES:3)
Block(-4,36,1,LEAVES:3)
Block(-4,36,2,LEAVES:3)
Block(-4,36,3,17:15)
Block(-4,36,4,LEAVES:3)
Block(-4,36,5,LEAVES:3)
Block(-4,36,7,LEAVES:3)
Block(-4,37,-5,LEAVES:3)
Block(-4,37,-4,LEAVES:3)
Block(-4,37,-1,LEAVES:3)
Block(-4,37,0,LEAVES:3)
Block(-4,37,1,LEAVES:3)
Block(-4,37,3,LEAVES:3)
Block(-4,37,4,LEAVES:3)
Block(-4,37,5,LEAVES:3)
Block(-4,37,6,LEAVES:3)
Block(-4,37,7,17:15)
Block(-4,37,8,LEAVES:3)
Block(-4,37,9,LEAVES:3)
Block(-4,37,10,LEAVES:3)
Block(-4,38,-4,LEAVES:3)
Block(-4,38,0,LEAVES:3)
Block(-4,38,3,LEAVES:3)
Block(-4,38,6,LEAVES:3)
Block(-4,38,7,LEAVES:3)
Block(-4,41,-6,LEAVES:3)
Block(-4,42,-7,LEAVES:3)
Block(-4,43,8,LEAVES:3)
Block(-4,44,-3,LEAVES:3)
Block(-4,44,-2,17:15)
Block(-4,44,-1,17:15)
Block(-4,44,2,LEAVES:3)
Block(-4,44,3,LEAVES:3)
Block(-4,44,4,17:15)
Block(-4,44,5,17:15)
Block(-4,44,6,LEAVES:3)
Block(-4,44,7,LEAVES:3)
Block(-4,44,8,LEAVES:3)
Block(-4,45,-2,LEAVES:3)
Block(-4,45,-1,LEAVES:3)
Block(-4,45,0,LEAVES:3)
Block(-4,45,4,LEAVES:3)
Block(-4,45,5,LEAVES:3)
Block(-4,45,6,LEAVES:3)
Block(-4,46,-2,LEAVES:3)
Block(-4,46,-1,LEAVES:3)
Block(-4,46,2,LEAVES:3)
Block(-4,48,0,LEAVES:3)
Block(-4,49,0,LEAVES:3)
Block(-4,49,2,LEAVES:3)
Block(-4,50,2,LEAVES:3)
Block(-3,-6,-3,17:15)
Block(-3,-6,4,17:15)
Block(-3,-6,6,17:15)
Block(-3,-5,-3,17:15)
Block(-3,-5,-2,17:15)
Block(-3,-5,4,17:15)
Block(-3,-5,5,17:15)
Block(-3,-4,-2,17:15)
Block(-3,-4,2,17:15)
Block(-3,-4,4,17:15)
Block(-3,-3,-2,17:15)
Block(-3,-3,-1,17:15)
Block(-3,-3,2,17:15)
Block(-3,-2,-1,17:15)
Block(-3,-2,2,17:15)
Block(-3,-1,0,17:15)
Block(-3,-1,2,17:15)
Block(-3,0,0,17:15)
Block(-3,0,2,17:15)
Block(-3,14,-3,17:15)
Block(-3,15,-5,LEAVES:3)
Block(-3,15,-4,LEAVES:3)
Block(-3,15,-3,17:15)
Block(-3,16,-4,LEAVES:3)
Block(-3,16,-3,LEAVES:3)
Block(-3,16,-2,LEAVES:3)
Block(-3,16,-1,LEAVES:3)
Block(-3,17,-2,LEAVES:3)
Block(-3,23,-9,LEAVES:3)
Block(-3,23,-8,LEAVES:3)
Block(-3,23,-4,LEAVES:3)
Block(-3,24,-11,LEAVES:3)
Block(-3,24,-9,17:15)
Block(-3,24,-7,LEAVES:3)
Block(-3,24,-5,LEAVES:3)
Block(-3,24,-3,LEAVES:3)
Block(-3,25,-11,LEAVES:3)
Block(-3,25,-10,LEAVES:3)
Block(-3,25,-9,LEAVES:3)
Block(-3,25,-8,LEAVES:3)
Block(-3,25,-7,LEAVES:3)
Block(-3,25,-6,17:15)
Block(-3,25,-5,LEAVES:3)
Block(-3,25,-4,LEAVES:3)
Block(-3,26,-9,LEAVES:3)
Block(-3,26,-7,LEAVES:3)
Block(-3,26,-6,LEAVES:3)
Block(-3,26,7,LEAVES:3)
Block(-3,27,-6,LEAVES:3)
Block(-3,27,1,LEAVES:3)
Block(-3,27,4,17:15)
Block(-3,27,7,LEAVES:3)
Block(-3,27,8,17:15)
Block(-3,27,11,LEAVES:3)
Block(-3,28,2,LEAVES:3)
Block(-3,28,5,LEAVES:3)
Block(-3,28,6,LEAVES:3)
Block(-3,28,7,LEAVES:3)
Block(-3,28,8,17:15)
Block(-3,28,9,17:15)
Block(-3,28,11,LEAVES:3)
Block(-3,29,2,LEAVES:3)
Block(-3,29,6,LEAVES:3)
Block(-3,29,7,LEAVES:3)
Block(-3,29,8,LEAVES:3)
Block(-3,29,9,LEAVES:3)
Block(-3,29,10,LEAVES:3)
Block(-3,29,11,LEAVES:3)
Block(-3,29,12,LEAVES:3)
Block(-3,30,7,LEAVES:3)
Block(-3,30,8,LEAVES:3)
Block(-3,30,11,LEAVES:3)
Block(-3,34,3,LEAVES:3)
Block(-3,35,-1,LEAVES:3)
Block(-3,35,0,17:15)
Block(-3,36,-7,LEAVES:3)
Block(-3,36,-6,LEAVES:3)
Block(-3,36,-5,17:15)
Block(-3,36,-3,LEAVES:3)
Block(-3,36,-2,LEAVES:3)
Block(-3,36,-1,LEAVES:3)
Block(-3,36,0,LEAVES:3)
Block(-3,36,1,LEAVES:3)
Block(-3,36,2,LEAVES:3)
Block(-3,36,3,LEAVES:3)
Block(-3,36,4,LEAVES:3)
Block(-3,36,10,LEAVES:3)
Block(-3,37,-6,LEAVES:3)
Block(-3,37,-5,LEAVES:3)
Block(-3,37,-4,LEAVES:3)
Block(-3,37,-3,LEAVES:3)
Block(-3,37,-2,LEAVES:3)
Block(-3,37,0,LEAVES:3)
Block(-3,37,3,LEAVES:3)
Block(-3,37,6,LEAVES:3)
Block(-3,37,7,LEAVES:3)
Block(-3,37,8,17:15)
Block(-3,37,9,LEAVES:3)
Block(-3,37,10,LEAVES:3)
Block(-3,38,-2,LEAVES:3)
Block(-3,38,8,LEAVES:3)
Block(-3,38,9,LEAVES:3)
Block(-3,40,-6,LEAVES:3)
Block(-3,41,-5,LEAVES:3)
Block(-3,42,-8,LEAVES:3)
Block(-3,42,-7,LEAVES:3)
Block(-3,42,-6,LEAVES:3)
Block(-3,43,-7,LEAVES:3)
Block(-3,43,-3,LEAVES:3)
Block(-3,43,-2,LEAVES:3)
Block(-3,43,-1,17:15)
Block(-3,43,0,17:15)
Block(-3,43,2,LEAVES:3)
Block(-3,43,3,LEAVES:3)
Block(-3,43,11,LEAVES:3)
Block(-3,44,-2,LEAVES:3)
Block(-3,44,-1,17:15)
Block(-3,44,0,LEAVES:3)
Block(-3,44,2,LEAVES:3)
Block(-3,44,3,17:15)
Block(-3,44,4,LEAVES:3)
Block(-3,44,5,LEAVES:3)
Block(-3,44,6,LEAVES:3)
Block(-3,44,7,LEAVES:3)
Block(-3,44,8,LEAVES:3)
Block(-3,44,9,LEAVES:3)
Block(-3,44,10,LEAVES:3)
Block(-3,45,-2,LEAVES:3)
Block(-3,45,-1,LEAVES:3)
Block(-3,45,3,LEAVES:3)
Block(-3,45,4,LEAVES:3)
Block(-3,45,8,LEAVES:3)
Block(-3,45,9,LEAVES:3)
Block(-3,48,-3,LEAVES:3)
Block(-3,48,-1,LEAVES:3)
Block(-3,49,-2,LEAVES:3)
Block(-3,49,0,LEAVES:3)
Block(-3,49,1,LEAVES:3)
Block(-3,49,4,LEAVES:3)
Block(-3,50,0,LEAVES:3)
Block(-3,50,1,LEAVES:3)
Block(-3,50,2,LEAVES:3)
Block(-3,50,3,LEAVES:3)
Block(-3,51,2,LEAVES:3)
Block(-2,-6,-4,17:15)
Block(-2,-4,4,17:15)
Block(-2,-3,3,17:15)
Block(-2,-3,4,17:15)
Block(-2,-2,-1,17:15)
Block(-2,-2,2,17:15)
Block(-2,-2,3,17:15)
Block(-2,-2,4,17:15)
Block(-2,-1,-1,17:15)
Block(-2,-1,2,17:15)
Block(-2,-1,3,17:15)
Block(-2,0,-1,17:15)
Block(-2,0,0,17:15)
Block(-2,0,2,17:15)
Block(-2,1,0,17:15)
Block(-2,1,1,17:15)
Block(-2,1,2,17:15)
Block(-2,2,0,17:15)
Block(-2,2,1,17:15)
Block(-2,2,2,17:15)
Block(-2,3,0,17:15)
Block(-2,3,1,17:15)
Block(-2,4,1,17:15)
Block(-2,5,1,17:15)
Block(-2,6,1,17:15)
Block(-2,7,1,17:15)
Block(-2,8,1,17:15)
Block(-2,12,8,LEAVES:3)
Block(-2,13,8,LEAVES:3)
Block(-2,13,10,LEAVES:3)
Block(-2,14,-4,LEAVES:3)
Block(-2,14,-3,17:15)
Block(-2,14,-2,17:15)
Block(-2,14,10,LEAVES:3)
Block(-2,15,-4,LEAVES:3)
Block(-2,15,-1,LEAVES:3)
Block(-2,16,-2,LEAVES:3)
Block(-2,23,-6,LEAVES:3)
Block(-2,24,-10,LEAVES:3)
Block(-2,24,-9,17:15)
Block(-2,24,-8,17:15)
Block(-2,24,-7,17:15)
Block(-2,24,-6,LEAVES:3)
Block(-2,24,-5,LEAVES:3)
Block(-2,24,-4,LEAVES:3)
Block(-2,25,-12,LEAVES:3)
Block(-2,25,-11,LEAVES:3)
Block(-2,25,-10,17:15)
Block(-2,25,-9,LEAVES:3)
Block(-2,25,-8,LEAVES:3)
Block(-2,25,-7,LEAVES:3)
Block(-2,25,-6,LEAVES:3)
Block(-2,25,-5,LEAVES:3)
Block(-2,26,-11,LEAVES:3)
Block(-2,26,-10,LEAVES:3)
Block(-2,26,-8,LEAVES:3)
Block(-2,26,2,LEAVES:3)
Block(-2,27,2,LEAVES:3)
Block(-2,27,3,LEAVES:3)
Block(-2,27,4,17:15)
Block(-2,27,7,17:15)
Block(-2,27,8,17:15)
Block(-2,27,9,LEAVES:3)
Block(-2,28,3,LEAVES:3)
Block(-2,28,4,LEAVES:3)
Block(-2,28,6,LEAVES:3)
Block(-2,28,7,LEAVES:3)
Block(-2,28,8,17:15)
Block(-2,28,12,LEAVES:3)
Block(-2,29,7,LEAVES:3)
Block(-2,29,8,LEAVES:3)
Block(-2,29,9,LEAVES:3)
Block(-2,29,10,LEAVES:3)
Block(-2,29,11,LEAVES:3)
Block(-2,30,7,LEAVES:3)
Block(-2,30,8,LEAVES:3)
Block(-2,30,9,LEAVES:3)
Block(-2,31,8,LEAVES:3)
Block(-2,34,0,17:15)
Block(-2,34,1,17:15)
Block(-2,35,-7,LEAVES:3)
Block(-2,35,-3,LEAVES:3)
Block(-2,35,0,17:15)
Block(-2,35,1,LEAVES:3)
Block(-2,35,4,LEAVES:3)
Block(-2,36,-6,LEAVES:3)
Block(-2,36,-3,LEAVES:3)
Block(-2,36,-2,LEAVES:3)
Block(-2,36,-1,LEAVES:3)
Block(-2,36,3,LEAVES:3)
Block(-2,36,4,LEAVES:3)
Block(-2,36,6,LEAVES:3)
Block(-2,36,8,LEAVES:3)
Block(-2,37,-7,LEAVES:3)
Block(-2,37,-6,LEAVES:3)
Block(-2,37,-5,17:15)
Block(-2,37,-4,LEAVES:3)
Block(-2,37,-2,LEAVES:3)
Block(-2,37,7,LEAVES:3)
Block(-2,37,8,LEAVES:3)
Block(-2,37,9,LEAVES:3)
Block(-2,38,-6,LEAVES:3)
Block(-2,38,-5,LEAVES:3)
Block(-2,38,7,LEAVES:3)
Block(-2,38,8,LEAVES:3)
Block(-2,40,-4,LEAVES:3)
Block(-2,41,-8,LEAVES:3)
Block(-2,41,-6,LEAVES:3)
Block(-2,41,-5,LEAVES:3)
Block(-2,41,-4,LEAVES:3)
Block(-2,42,-9,LEAVES:3)
Block(-2,42,-8,LEAVES:3)
Block(-2,42,-7,17:15)
Block(-2,42,-6,LEAVES:3)
Block(-2,42,-5,LEAVES:3)
Block(-2,43,-8,LEAVES:3)
Block(-2,43,-7,LEAVES:3)
Block(-2,43,-2,LEAVES:3)
Block(-2,43,0,17:15)
Block(-2,43,2,17:15)
Block(-2,43,6,LEAVES:3)
Block(-2,43,9,LEAVES:3)
Block(-2,44,-1,LEAVES:3)
Block(-2,44,1,LEAVES:3)
Block(-2,44,2,LEAVES:3)
Block(-2,44,3,17:15)
Block(-2,44,4,LEAVES:3)
Block(-2,44,5,LEAVES:3)
Block(-2,44,7,LEAVES:3)
Block(-2,44,8,17:15)
Block(-2,44,9,LEAVES:3)
Block(-2,44,10,LEAVES:3)
Block(-2,44,11,LEAVES:3)
Block(-2,45,2,LEAVES:3)
Block(-2,45,3,LEAVES:3)
Block(-2,45,4,LEAVES:3)
Block(-2,45,7,LEAVES:3)
Block(-2,45,8,LEAVES:3)
Block(-2,45,9,LEAVES:3)
Block(-2,45,10,LEAVES:3)
Block(-2,46,3,LEAVES:3)
Block(-2,48,0,LEAVES:3)
Block(-2,49,-3,LEAVES:3)
Block(-2,49,-2,LEAVES:3)
Block(-2,49,-1,LEAVES:3)
Block(-2,49,0,17:15)
Block(-2,49,2,LEAVES:3)
Block(-2,50,-2,LEAVES:3)
Block(-2,50,-1,LEAVES:3)
Block(-2,50,0,LEAVES:3)
Block(-2,50,1,17:15)
Block(-2,50,2,LEAVES:3)
Block(-2,50,3,LEAVES:3)
Block(-2,50,4,LEAVES:3)
Block(-2,51,0,LEAVES:3)
Block(-2,51,1,LEAVES:3)
Block(-2,51,2,LEAVES:3)
Block(-2,51,3,LEAVES:3)
Block(-2,52,1,LEAVES:3)
Block(-1,-6,-5,17:15)
Block(-1,-6,5,17:15)
Block(-1,-5,-5,17:15)
Block(-1,-5,0,17:15)
Block(-1,-5,5,17:15)
Block(-1,-4,0,17:15)
Block(-1,-3,-1,17:15)
Block(-1,-3,0,17:15)
Block(-1,-2,-1,17:15)
Block(-1,-2,1,17:15)
Block(-1,-1,1,17:15)
Block(-1,-1,2,17:15)
Block(-1,0,1,17:15)
Block(-1,0,2,17:15)
Block(-1,1,0,17:15)
Block(-1,1,1,17:15)
Block(-1,1,2,17:15)
Block(-1,2,0,17:15)
Block(-1,2,1,17:15)
Block(-1,2,2,17:15)
Block(-1,3,0,17:15)
Block(-1,3,1,17:15)
Block(-1,3,2,17:15)
Block(-1,4,0,17:15)
Block(-1,4,1,17:15)
Block(-1,4,2,17:15)
Block(-1,5,0,17:15)
Block(-1,5,1,17:15)
Block(-1,6,0,17:15)
Block(-1,6,1,17:15)
Block(-1,7,0,17:15)
Block(-1,7,1,17:15)
Block(-1,8,0,17:15)
Block(-1,8,1,17:15)
Block(-1,9,0,17:15)
Block(-1,9,1,17:15)
Block(-1,10,0,17:15)
Block(-1,10,1,17:15)
Block(-1,11,0,17:15)
Block(-1,11,1,17:15)
Block(-1,12,0,17:15)
Block(-1,12,1,17:15)
Block(-1,12,5,LEAVES:3)
Block(-1,12,7,LEAVES:3)
Block(-1,13,0,17:15)
Block(-1,13,1,17:15)
Block(-1,13,6,LEAVES:3)
Block(-1,13,8,LEAVES:3)
Block(-1,13,9,LEAVES:3)
Block(-1,13,12,LEAVES:3)
Block(-1,14,-3,LEAVES:3)
Block(-1,14,-2,17:15)
Block(-1,14,0,17:15)
Block(-1,14,1,17:15)
Block(-1,14,8,LEAVES:3)
Block(-1,14,9,LEAVES:3)
Block(-1,14,10,LEAVES:3)
Block(-1,14,11,LEAVES:3)
Block(-1,15,-2,LEAVES:3)
Block(-1,15,0,17:15)
Block(-1,15,1,17:15)
Block(-1,15,10,LEAVES:3)
Block(-1,16,-2,LEAVES:3)
Block(-1,16,0,17:15)
Block(-1,16,1,17:15)
Block(-1,17,0,17:15)
Block(-1,17,1,17:15)
Block(-1,18,0,17:15)
Block(-1,19,0,17:15)
Block(-1,20,0,17:15)
Block(-1,23,-9,LEAVES:3)
Block(-1,23,-8,17:15)
Block(-1,23,-5,LEAVES:3)
Block(-1,24,-12,LEAVES:3)
Block(-1,24,-10,LEAVES:3)
Block(-1,24,-9,LEAVES:3)
Block(-1,24,-8,17:15)
Block(-1,24,-7,LEAVES:3)
Block(-1,24,-6,LEAVES:3)
Block(-1,24,-5,LEAVES:3)
Block(-1,25,-11,LEAVES:3)
Block(-1,25,-10,LEAVES:3)
Block(-1,25,-9,LEAVES:3)
Block(-1,25,-8,LEAVES:3)
Block(-1,25,-6,LEAVES:3)
Block(-1,26,-11,LEAVES:3)
Block(-1,26,-10,LEAVES:3)
Block(-1,26,-9,LEAVES:3)
Block(-1,26,4,17:15)
Block(-1,27,-10,LEAVES:3)
Block(-1,27,3,LEAVES:3)
Block(-1,27,4,LEAVES:3)
Block(-1,27,5,LEAVES:3)
Block(-1,27,6,17:15)
Block(-1,27,7,17:15)
Block(-1,28,3,LEAVES:3)
Block(-1,28,4,LEAVES:3)
Block(-1,28,5,LEAVES:3)
Block(-1,28,6,LEAVES:3)
Block(-1,28,10,LEAVES:3)
Block(-1,29,6,LEAVES:3)
Block(-1,29,8,LEAVES:3)
Block(-1,29,9,LEAVES:3)
Block(-1,30,8,LEAVES:3)
Block(-1,33,1,17:15)
Block(-1,34,1,17:15)
Block(-1,35,-1,LEAVES:3)
Block(-1,36,-8,LEAVES:3)
Block(-1,36,-5,LEAVES:3)
Block(-1,36,-2,LEAVES:3)
Block(-1,36,7,LEAVES:3)
Block(-1,37,-9,LEAVES:3)
Block(-1,37,-8,LEAVES:3)
Block(-1,37,-7,LEAVES:3)
Block(-1,37,-6,17:15)
Block(-1,37,-5,LEAVES:3)
Block(-1,37,2,LEAVES:3)
Block(-1,37,4,LEAVES:3)
Block(-1,37,5,LEAVES:3)
Block(-1,37,6,LEAVES:3)
Block(-1,37,7,LEAVES:3)
Block(-1,38,-8,LEAVES:3)
Block(-1,38,-7,LEAVES:3)
Block(-1,38,-6,LEAVES:3)
Block(-1,38,-5,LEAVES:3)
Block(-1,38,6,LEAVES:3)
Block(-1,39,-6,LEAVES:3)
Block(-1,40,-5,LEAVES:3)
Block(-1,41,-5,LEAVES:3)
Block(-1,41,-4,LEAVES:3)
Block(-1,41,-3,LEAVES:3)
Block(-1,42,-9,LEAVES:3)
Block(-1,42,-7,LEAVES:3)
Block(-1,42,-6,17:15)
Block(-1,42,-5,LEAVES:3)
Block(-1,42,-4,LEAVES:3)
Block(-1,42,0,17:15)
Block(-1,42,3,LEAVES:3)
Block(-1,43,-8,LEAVES:3)
Block(-1,43,-7,LEAVES:3)
Block(-1,43,-6,LEAVES:3)
Block(-1,43,0,17:15)
Block(-1,43,1,17:15)
Block(-1,43,2,17:15)
Block(-1,43,3,LEAVES:3)
Block(-1,43,5,LEAVES:3)
Block(-1,43,7,LEAVES:3)
Block(-1,43,10,LEAVES:3)
Block(-1,44,-6,LEAVES:3)
Block(-1,44,1,LEAVES:3)
Block(-1,44,2,LEAVES:3)
Block(-1,44,3,LEAVES:3)
Block(-1,44,4,LEAVES:3)
Block(-1,44,6,LEAVES:3)
Block(-1,44,7,17:15)
Block(-1,44,8,LEAVES:3)
Block(-1,44,9,LEAVES:3)
Block(-1,44,10,LEAVES:3)
Block(-1,45,2,LEAVES:3)
Block(-1,45,6,LEAVES:3)
Block(-1,45,7,LEAVES:3)
Block(-1,45,8,LEAVES:3)
Block(-1,45,9,LEAVES:3)
Block(-1,46,7,LEAVES:3)
Block(-1,48,-3,LEAVES:3)
Block(-1,49,-3,LEAVES:3)
Block(-1,49,-2,LEAVES:3)
Block(-1,49,-1,17:15)
Block(-1,49,0,LEAVES:3)
Block(-1,49,3,LEAVES:3)
Block(-1,50,-2,LEAVES:3)
Block(-1,50,-1,LEAVES:3)
Block(-1,50,0,LEAVES:3)
Block(-1,50,1,LEAVES:3)
Block(-1,50,2,LEAVES:3)
Block(-1,50,3,LEAVES:3)
Block(-1,51,-1,LEAVES:3)
Block(-1,51,1,LEAVES:3)
Block(0,-6,-5,17:15)
Block(0,-6,0,17:15)
Block(0,-6,6,17:15)
Block(0,-5,-5,17:15)
Block(0,-5,0,17:15)
Block(0,-4,-5,17:15)
Block(0,-4,0,17:15)
Block(0,-3,-3,17:15)
Block(0,-2,-3,17:15)
Block(0,-1,-3,17:15)
Block(0,-1,-2,17:15)
Block(0,-1,1,17:15)
Block(0,0,-3,17:15)
Block(0,0,-2,17:15)
Block(0,0,0,17:15)
Block(0,0,1,17:15)
Block(0,1,-2,17:15)
Block(0,1,-1,17:15)
Block(0,1,0,17:15)
Block(0,1,1,17:15)
Block(0,2,-2,17:15)
Block(0,2,-1,17:15)
Block(0,2,0,17:15)
Block(0,2,1,17:15)
Block(0,2,2,17:15)
Block(0,3,-2,17:15)
Block(0,3,-1,17:15)
Block(0,3,0,17:15)
Block(0,3,1,17:15)
Block(0,3,2,17:15)
Block(0,4,-2,17:15)
Block(0,4,-1,17:15)
Block(0,4,0,17:15)
Block(0,4,1,17:15)
Block(0,4,2,17:15)
Block(0,5,-2,17:15)
Block(0,5,-1,17:15)
Block(0,5,0,17:15)
Block(0,5,1,17:15)
Block(0,5,2,17:15)
Block(0,6,-2,17:15)
Block(0,6,-1,17:15)
Block(0,6,0,17:15)
Block(0,6,1,17:15)
Block(0,6,2,17:15)
Block(0,7,-1,17:15)
Block(0,7,0,17:15)
Block(0,7,1,17:15)
Block(0,7,2,17:15)
Block(0,8,-1,17:15)
Block(0,8,0,17:15)
Block(0,8,1,17:15)
Block(0,8,2,17:15)
Block(0,9,-1,17:15)
Block(0,9,0,17:15)
Block(0,9,1,17:15)
Block(0,9,2,17:15)
Block(0,10,-1,17:15)
Block(0,10,0,17:15)
Block(0,10,1,17:15)
Block(0,10,2,17:15)
Block(0,11,-1,17:15)
Block(0,11,0,17:15)
Block(0,11,1,17:15)
Block(0,11,2,17:15)
Block(0,12,-1,17:15)
Block(0,12,0,17:15)
Block(0,12,1,17:15)
Block(0,12,2,17:15)
Block(0,12,8,LEAVES:3)
Block(0,13,-1,17:15)
Block(0,13,0,17:15)
Block(0,13,1,17:15)
Block(0,13,2,17:15)
Block(0,13,5,LEAVES:3)
Block(0,13,6,LEAVES:3)
Block(0,13,7,LEAVES:3)
Block(0,13,8,17:15)
Block(0,13,10,LEAVES:3)
Block(0,14,-2,17:15)
Block(0,14,-1,17:15)
Block(0,14,0,17:15)
Block(0,14,1,17:15)
Block(0,14,6,LEAVES:3)
Block(0,14,7,LEAVES:3)
Block(0,14,8,LEAVES:3)
Block(0,14,9,17:15)
Block(0,14,10,LEAVES:3)
Block(0,14,11,LEAVES:3)
Block(0,14,12,LEAVES:3)
Block(0,15,-2,LEAVES:3)
Block(0,15,-1,17:15)
Block(0,15,0,17:15)
Block(0,15,1,17:15)
Block(0,15,8,LEAVES:3)
Block(0,15,9,LEAVES:3)
Block(0,15,10,LEAVES:3)
Block(0,15,11,LEAVES:3)
Block(0,16,-1,17:15)
Block(0,16,0,17:15)
Block(0,16,1,17:15)
Block(0,16,9,LEAVES:3)
Block(0,17,-1,17:15)
Block(0,17,0,17:15)
Block(0,17,1,17:15)
Block(0,18,-1,17:15)
Block(0,18,0,17:15)
Block(0,18,1,17:15)
Block(0,19,-2,17:15)
Block(0,19,-1,17:15)
Block(0,19,0,17:15)
Block(0,19,1,17:15)
Block(0,20,-3,17:15)
Block(0,20,-2,17:15)
Block(0,20,-1,17:15)
Block(0,20,0,17:15)
Block(0,20,1,17:15)
Block(0,21,-1,17:15)
Block(0,21,0,17:15)
Block(0,21,1,17:15)
Block(0,22,-1,17:15)
Block(0,22,0,17:15)
Block(0,22,1,17:15)
Block(0,23,-10,LEAVES:3)
Block(0,23,-8,17:15)
Block(0,23,-7,LEAVES:3)
Block(0,23,0,17:15)
Block(0,23,1,17:15)
Block(0,24,-15,LEAVES:3)
Block(0,24,-13,LEAVES:3)
Block(0,24,-9,LEAVES:3)
Block(0,24,-8,LEAVES:3)
Block(0,24,-7,LEAVES:3)
Block(0,24,-6,LEAVES:3)
Block(0,24,0,17:15)
Block(0,24,1,17:15)
Block(0,24,2,17:15)
Block(0,25,-16,LEAVES:3)
Block(0,25,-13,LEAVES:3)
Block(0,25,-10,LEAVES:3)
Block(0,25,-8,LEAVES:3)
Block(0,25,0,17:15)
Block(0,25,1,17:15)
Block(0,25,2,17:15)
Block(0,25,3,17:15)
Block(0,26,-15,LEAVES:3)
Block(0,26,-11,LEAVES:3)
Block(0,26,-10,LEAVES:3)
Block(0,26,-9,LEAVES:3)
Block(0,26,-8,LEAVES:3)
Block(0,26,0,17:15)
Block(0,26,1,17:15)
Block(0,26,4,17:15)
Block(0,26,5,17:15)
Block(0,26,6,17:15)
Block(0,27,-10,LEAVES:3)
Block(0,27,-9,LEAVES:3)
Block(0,27,0,17:15)
Block(0,27,1,17:15)
Block(0,27,4,LEAVES:3)
Block(0,27,6,17:15)
Block(0,28,0,17:15)
Block(0,28,1,17:15)
Block(0,28,4,LEAVES:3)
Block(0,28,5,LEAVES:3)
Block(0,28,6,LEAVES:3)
Block(0,28,7,17:15)
Block(0,28,8,LEAVES:3)
Block(0,29,0,17:15)
Block(0,29,1,17:15)
Block(0,29,6,LEAVES:3)
Block(0,29,7,LEAVES:3)
Block(0,29,10,LEAVES:3)
Block(0,30,0,17:15)
Block(0,30,1,17:15)
Block(0,30,6,LEAVES:3)
Block(0,31,0,17:15)
Block(0,31,1,17:15)
Block(0,32,0,17:15)
Block(0,32,1,17:15)
Block(0,33,0,17:15)
Block(0,33,1,17:15)
Block(0,34,0,17:15)
Block(0,34,1,17:15)
Block(0,35,-8,LEAVES:3)
Block(0,35,-5,LEAVES:3)
Block(0,35,0,17:15)
Block(0,35,1,17:15)
Block(0,35,7,LEAVES:3)
Block(0,36,-9,LEAVES:3)
Block(0,36,-6,LEAVES:3)
Block(0,36,0,17:15)
Block(0,36,1,17:15)
Block(0,36,5,LEAVES:3)
Block(0,36,6,LEAVES:3)
Block(0,37,-8,LEAVES:3)
Block(0,37,-7,LEAVES:3)
Block(0,37,-6,LEAVES:3)
Block(0,37,-5,LEAVES:3)
Block(0,37,-1,17:15)
Block(0,37,0,17:15)
Block(0,37,1,17:15)
Block(0,37,2,LEAVES:3)
Block(0,37,3,LEAVES:3)
Block(0,37,4,17:15)
Block(0,37,5,17:15)
Block(0,37,6,LEAVES:3)
Block(0,37,7,LEAVES:3)
Block(0,37,8,LEAVES:3)
Block(0,38,-6,LEAVES:3)
Block(0,38,-1,17:15)
Block(0,38,0,17:15)
Block(0,38,1,17:15)
Block(0,38,2,LEAVES:3)
Block(0,38,4,LEAVES:3)
Block(0,38,5,LEAVES:3)
Block(0,38,6,LEAVES:3)
Block(0,38,7,LEAVES:3)
Block(0,39,0,17:15)
Block(0,39,1,17:15)
Block(0,39,6,LEAVES:3)
Block(0,40,-3,LEAVES:3)
Block(0,40,0,17:15)
Block(0,40,1,17:15)
Block(0,41,-9,LEAVES:3)
Block(0,41,-6,LEAVES:3)
Block(0,41,-5,17:15)
Block(0,41,-4,LEAVES:3)
Block(0,41,-3,LEAVES:3)
Block(0,41,0,17:15)
Block(0,41,1,17:15)
Block(0,42,-8,LEAVES:3)
Block(0,42,-6,LEAVES:3)
Block(0,42,-5,LEAVES:3)
Block(0,42,0,17:15)
Block(0,42,1,17:15)
Block(0,42,6,LEAVES:3)
Block(0,42,8,LEAVES:3)
Block(0,43,-6,LEAVES:3)
Block(0,43,0,17:15)
Block(0,43,1,17:15)
Block(0,43,2,LEAVES:3)
Block(0,43,3,LEAVES:3)
Block(0,43,4,LEAVES:3)
Block(0,43,6,17:15)
Block(0,43,7,LEAVES:3)
Block(0,43,8,LEAVES:3)
Block(0,44,0,17:15)
Block(0,44,2,LEAVES:3)
Block(0,44,4,LEAVES:3)
Block(0,44,5,LEAVES:3)
Block(0,44,6,LEAVES:3)
Block(0,44,7,LEAVES:3)
Block(0,45,0,17:15)
Block(0,45,6,LEAVES:3)
Block(0,46,0,17:15)
Block(0,47,-4,17:15)
Block(0,47,-3,17:15)
Block(0,47,0,17:15)
Block(0,48,-3,17:15)
Block(0,48,-2,17:15)
Block(0,48,-1,LEAVES:3)
Block(0,48,0,17:15)
Block(0,48,1,LEAVES:3)
Block(0,49,-3,LEAVES:3)
Block(0,49,-2,LEAVES:3)
Block(0,49,-1,17:15)
Block(0,49,0,LEAVES:3)
Block(0,49,1,LEAVES:3)
Block(0,49,2,LEAVES:3)
Block(0,50,-3,LEAVES:3)
Block(0,50,-1,LEAVES:3)
Block(0,50,0,LEAVES:3)
Block(0,50,1,LEAVES:3)
Block(0,51,0,LEAVES:3)
Block(1,-6,0,17:15)
Block(1,-6,1,17:15)
Block(1,-6,5,17:15)
Block(1,-5,-4,17:15)
Block(1,-5,4,17:15)
Block(1,-4,-4,17:15)
Block(1,-4,-3,17:15)
Block(1,-4,0,17:15)
Block(1,-4,1,17:15)
Block(1,-4,3,17:15)
Block(1,-4,4,17:15)
Block(1,-3,-4,17:15)
Block(1,-3,-3,17:15)
Block(1,-3,1,17:15)
Block(1,-3,2,17:15)
Block(1,-3,3,17:15)
Block(1,-3,4,17:15)
Block(1,-2,-3,17:15)
Block(1,-2,2,17:15)
Block(1,-2,3,17:15)
Block(1,-1,-3,17:15)
Block(1,-1,0,17:15)
Block(1,-1,1,17:15)
Block(1,-1,2,17:15)
Block(1,-1,3,17:15)
Block(1,0,-1,17:15)
Block(1,0,0,17:15)
Block(1,0,1,17:15)
Block(1,0,2,17:15)
Block(1,1,-1,17:15)
Block(1,1,0,17:15)
Block(1,1,1,17:15)
Block(1,1,2,17:15)
Block(1,2,-1,17:15)
Block(1,2,0,17:15)
Block(1,2,1,17:15)
Block(1,2,2,17:15)
Block(1,3,-1,17:15)
Block(1,3,0,17:15)
Block(1,3,1,17:15)
Block(1,4,-1,17:15)
Block(1,4,0,17:15)
Block(1,4,1,17:15)
Block(1,5,-1,17:15)
Block(1,5,0,17:15)
Block(1,5,1,17:15)
Block(1,6,-1,17:15)
Block(1,6,0,17:15)
Block(1,6,1,17:15)
Block(1,7,-1,17:15)
Block(1,7,0,17:15)
Block(1,7,1,17:15)
Block(1,8,-1,17:15)
Block(1,8,0,17:15)
Block(1,8,1,17:15)
Block(1,9,-1,17:15)
Block(1,9,0,17:15)
Block(1,9,1,17:15)
Block(1,10,-1,17:15)
Block(1,10,0,17:15)
Block(1,10,1,17:15)
Block(1,11,-1,17:15)
Block(1,11,0,17:15)
Block(1,11,1,17:15)
Block(1,12,-1,17:15)
Block(1,12,0,17:15)
Block(1,12,1,17:15)
Block(1,12,5,LEAVES:3)
Block(1,13,0,17:15)
Block(1,13,1,17:15)
Block(1,13,5,LEAVES:3)
Block(1,13,6,LEAVES:3)
Block(1,13,7,17:15)
Block(1,13,8,LEAVES:3)
Block(1,13,11,LEAVES:3)
Block(1,14,0,17:15)
Block(1,14,1,17:15)
Block(1,14,6,LEAVES:3)
Block(1,14,7,LEAVES:3)
Block(1,14,8,LEAVES:3)
Block(1,14,9,LEAVES:3)
Block(1,14,10,LEAVES:3)
Block(1,14,11,LEAVES:3)
Block(1,15,0,17:15)
Block(1,15,1,17:15)
Block(1,15,7,LEAVES:3)
Block(1,15,9,LEAVES:3)
Block(1,16,0,17:15)
Block(1,16,1,17:15)
Block(1,17,0,17:15)
Block(1,17,1,17:15)
Block(1,18,0,17:15)
Block(1,18,1,17:15)
Block(1,19,0,17:15)
Block(1,19,1,17:15)
Block(1,20,-4,17:15)
Block(1,20,-3,17:15)
Block(1,20,-2,17:15)
Block(1,20,0,17:15)
Block(1,20,1,17:15)
Block(1,21,-13,LEAVES:3)
Block(1,21,-5,17:15)
Block(1,21,-4,17:15)
Block(1,21,-3,17:15)
Block(1,21,0,17:15)
Block(1,21,1,17:15)
Block(1,22,-12,LEAVES:3)
Block(1,22,-8,LEAVES:3)
Block(1,22,-7,LEAVES:3)
Block(1,22,0,17:15)
Block(1,22,1,17:15)
Block(1,23,-11,LEAVES:3)
Block(1,23,-10,LEAVES:3)
Block(1,23,-8,17:15)
Block(1,23,-5,LEAVES:3)
Block(1,23,-4,LEAVES:3)
Block(1,23,0,17:15)
Block(1,23,1,17:15)
Block(1,24,-11,LEAVES:3)
Block(1,24,-5,LEAVES:3)
Block(1,24,0,17:15)
Block(1,24,1,17:15)
Block(1,24,2,17:15)
Block(1,24,3,17:15)
Block(1,25,-15,LEAVES:3)
Block(1,25,-14,LEAVES:3)
Block(1,25,-13,LEAVES:3)
Block(1,25,-12,LEAVES:3)
Block(1,25,-10,LEAVES:3)
Block(1,25,-8,LEAVES:3)
Block(1,25,0,17:15)
Block(1,25,3,17:15)
Block(1,25,4,17:15)
Block(1,26,-16,LEAVES:3)
Block(1,26,-15,LEAVES:3)
Block(1,26,-14,LEAVES:3)
Block(1,26,-13,LEAVES:3)
Block(1,26,-11,LEAVES:3)
Block(1,26,-10,17:15)
Block(1,26,-9,LEAVES:3)
Block(1,26,0,17:15)
Block(1,26,2,LEAVES:3)
Block(1,26,4,17:15)
Block(1,27,-15,LEAVES:3)
Block(1,27,-10,LEAVES:3)
Block(1,27,0,17:15)
Block(1,27,3,LEAVES:3)
Block(1,27,4,LEAVES:3)
Block(1,27,10,LEAVES:3)
Block(1,28,-10,LEAVES:3)
Block(1,28,0,17:15)
Block(1,28,5,LEAVES:3)
Block(1,28,6,LEAVES:3)
Block(1,28,7,LEAVES:3)
Block(1,28,8,17:15)
Block(1,28,10,LEAVES:3)
Block(1,28,11,LEAVES:3)
Block(1,29,0,17:15)
Block(1,29,6,LEAVES:3)
Block(1,29,9,LEAVES:3)
Block(1,29,10,LEAVES:3)
Block(1,29,11,LEAVES:3)
Block(1,30,0,17:15)
Block(1,30,10,LEAVES:3)
Block(1,31,0,17:15)
Block(1,32,0,17:15)
Block(1,33,0,17:15)
Block(1,33,1,17:15)
Block(1,34,0,17:15)
Block(1,34,1,17:15)
Block(1,35,0,17:15)
Block(1,35,4,LEAVES:3)
Block(1,36,-7,LEAVES:3)
Block(1,36,0,17:15)
Block(1,36,3,17:15)
Block(1,36,8,LEAVES:3)
Block(1,37,-6,LEAVES:3)
Block(1,37,2,LEAVES:3)
Block(1,37,3,LEAVES:3)
Block(1,37,4,LEAVES:3)
Block(1,37,5,LEAVES:3)
Block(1,37,6,LEAVES:3)
Block(1,37,7,LEAVES:3)
Block(1,38,-1,17:15)
Block(1,38,5,LEAVES:3)
Block(1,38,6,LEAVES:3)
Block(1,39,-2,17:15)
Block(1,39,-1,17:15)
Block(1,40,-6,LEAVES:3)
Block(1,40,-4,17:15)
Block(1,40,-3,17:15)
Block(1,40,-2,17:15)
Block(1,41,-10,LEAVES:3)
Block(1,41,-5,17:15)
Block(1,41,-4,17:15)
Block(1,41,-3,LEAVES:3)
Block(1,41,-2,LEAVES:3)
Block(1,41,1,17:15)
Block(1,42,-9,LEAVES:3)
Block(1,42,-8,LEAVES:3)
Block(1,42,-7,LEAVES:3)
Block(1,42,-6,LEAVES:3)
Block(1,42,-5,LEAVES:3)
Block(1,42,-4,LEAVES:3)
Block(1,42,-3,LEAVES:3)
Block(1,42,1,17:15)
Block(1,42,2,17:15)
Block(1,42,3,17:15)
Block(1,43,-8,LEAVES:3)
Block(1,43,-5,LEAVES:3)
Block(1,43,3,17:15)
Block(1,43,4,17:15)
Block(1,43,5,17:15)
Block(1,43,7,LEAVES:3)
Block(1,44,3,LEAVES:3)
Block(1,44,4,LEAVES:3)
Block(1,44,5,LEAVES:3)
Block(1,44,6,LEAVES:3)
Block(1,48,2,LEAVES:3)
Block(1,49,-4,LEAVES:3)
Block(1,49,-3,17:15)
Block(1,49,-1,LEAVES:3)
Block(1,49,0,LEAVES:3)
Block(1,49,1,LEAVES:3)
Block(1,50,-3,LEAVES:3)
Block(1,50,-2,LEAVES:3)
Block(1,50,0,LEAVES:3)
Block(2,-6,-4,17:15)
Block(2,-6,-1,17:15)
Block(2,-5,-4,17:15)
Block(2,-5,-2,17:15)
Block(2,-5,3,17:15)
Block(2,-4,-2,17:15)
Block(2,-4,3,17:15)
Block(2,-3,-2,17:15)
Block(2,-3,-1,17:15)
Block(2,-3,1,17:15)
Block(2,-3,3,17:15)
Block(2,-2,-2,17:15)
Block(2,-2,-1,17:15)
Block(2,-2,0,17:15)
Block(2,-2,1,17:15)
Block(2,-1,-2,17:15)
Block(2,-1,-1,17:15)
Block(2,-1,0,17:15)
Block(2,-1,1,17:15)
Block(2,0,-2,17:15)
Block(2,0,-1,17:15)
Block(2,0,0,17:15)
Block(2,0,1,17:15)
Block(2,1,-2,17:15)
Block(2,1,-1,17:15)
Block(2,1,0,17:15)
Block(2,1,1,17:15)
Block(2,2,-1,17:15)
Block(2,2,0,17:15)
Block(2,3,-1,17:15)
Block(2,3,0,17:15)
Block(2,4,-1,17:15)
Block(2,4,0,17:15)
Block(2,5,-1,17:15)
Block(2,5,0,17:15)
Block(2,6,-1,17:15)
Block(2,6,0,17:15)
Block(2,7,-1,17:15)
Block(2,7,0,17:15)
Block(2,8,0,17:15)
Block(2,11,4,17:15)
Block(2,11,5,17:15)
Block(2,12,0,17:15)
Block(2,12,5,17:15)
Block(2,12,6,17:15)
Block(2,12,7,LEAVES:3)
Block(2,12,9,LEAVES:3)
Block(2,13,-2,LEAVES:3)
Block(2,13,5,LEAVES:3)
Block(2,13,6,LEAVES:3)
Block(2,13,7,17:15)
Block(2,13,8,LEAVES:3)
Block(2,13,9,LEAVES:3)
Block(2,13,10,LEAVES:3)
Block(2,14,-1,LEAVES:3)
Block(2,14,5,LEAVES:3)
Block(2,14,7,LEAVES:3)
Block(2,14,8,LEAVES:3)
Block(2,14,9,LEAVES:3)
Block(2,15,8,LEAVES:3)
Block(2,21,-5,17:15)
Block(2,22,-15,LEAVES:3)
Block(2,22,-13,LEAVES:3)
Block(2,22,-12,17:15)
Block(2,22,-11,17:15)
Block(2,22,-7,17:15)
Block(2,22,-6,17:15)
Block(2,22,-5,17:15)
Block(2,23,-11,LEAVES:3)
Block(2,23,-8,17:15)
Block(2,23,-7,17:15)
Block(2,23,-6,LEAVES:3)
Block(2,23,-5,LEAVES:3)
Block(2,23,-4,LEAVES:3)
Block(2,23,-3,LEAVES:3)
Block(2,24,-7,LEAVES:3)
Block(2,24,-5,LEAVES:3)
Block(2,24,-4,LEAVES:3)
Block(2,25,-17,LEAVES:3)
Block(2,25,-14,LEAVES:3)
Block(2,25,-13,17:15)
Block(2,25,-12,LEAVES:3)
Block(2,25,-11,LEAVES:3)
Block(2,25,-10,LEAVES:3)
Block(2,25,-5,LEAVES:3)
Block(2,26,-17,LEAVES:3)
Block(2,26,-16,LEAVES:3)
Block(2,26,-15,17:15)
Block(2,26,-14,17:15)
Block(2,26,-13,LEAVES:3)
Block(2,26,-11,17:15)
Block(2,26,-10,LEAVES:3)
Block(2,26,3,LEAVES:3)
Block(2,26,4,17:15)
Block(2,27,-16,LEAVES:3)
Block(2,27,-15,LEAVES:3)
Block(2,27,-14,LEAVES:3)
Block(2,27,-11,LEAVES:3)
Block(2,27,-10,LEAVES:3)
Block(2,27,3,LEAVES:3)
Block(2,27,4,LEAVES:3)
Block(2,27,5,LEAVES:3)
Block(2,28,-14,LEAVES:3)
Block(2,28,4,LEAVES:3)
Block(2,28,6,LEAVES:3)
Block(2,28,7,LEAVES:3)
Block(2,28,8,17:15)
Block(2,28,9,17:15)
Block(2,29,8,LEAVES:3)
Block(2,29,9,17:15)
Block(2,29,10,LEAVES:3)
Block(2,29,11,LEAVES:3)
Block(2,30,9,LEAVES:3)
Block(2,30,10,LEAVES:3)
Block(2,30,11,LEAVES:3)
Block(2,31,10,LEAVES:3)
Block(2,34,1,17:15)
Block(2,35,1,17:15)
Block(2,35,2,17:15)
Block(2,36,2,17:15)
Block(2,36,3,17:15)
Block(2,36,4,17:15)
Block(2,36,6,LEAVES:3)
Block(2,37,2,LEAVES:3)
Block(2,37,3,LEAVES:3)
Block(2,37,4,LEAVES:3)
Block(2,37,5,LEAVES:3)
Block(2,38,3,LEAVES:3)
Block(2,40,-6,LEAVES:3)
Block(2,40,-4,LEAVES:3)
Block(2,41,-9,LEAVES:3)
Block(2,41,-7,LEAVES:3)
Block(2,41,-6,17:15)
Block(2,41,-5,17:15)
Block(2,41,-4,LEAVES:3)
Block(2,41,-3,LEAVES:3)
Block(2,42,-10,LEAVES:3)
Block(2,42,-9,LEAVES:3)
Block(2,42,-8,LEAVES:3)
Block(2,42,-7,17:15)
Block(2,42,-6,LEAVES:3)
Block(2,42,-5,LEAVES:3)
Block(2,42,-4,LEAVES:3)
Block(2,42,7,LEAVES:3)
Block(2,43,-9,LEAVES:3)
Block(2,43,-8,LEAVES:3)
Block(2,43,-7,LEAVES:3)
Block(2,43,-6,LEAVES:3)
Block(2,43,6,LEAVES:3)
Block(2,43,8,LEAVES:3)
Block(2,44,-8,LEAVES:3)
Block(2,44,3,LEAVES:3)
Block(2,44,4,17:15)
Block(2,44,5,LEAVES:3)
Block(2,44,6,LEAVES:3)
Block(2,44,7,LEAVES:3)
Block(2,45,4,LEAVES:3)
Block(2,48,-4,LEAVES:3)
Block(2,48,-2,LEAVES:3)
Block(2,48,0,LEAVES:3)
Block(2,49,-3,LEAVES:3)
Block(2,49,-2,17:15)
Block(2,49,-1,LEAVES:3)
Block(2,49,0,LEAVES:3)
Block(2,50,-3,LEAVES:3)
Block(2,50,-2,LEAVES:3)
Block(2,50,-1,LEAVES:3)
Block(2,51,-2,LEAVES:3)
Block(3,-6,-5,17:15)
Block(3,-6,-1,17:15)
Block(3,-6,3,17:15)
Block(3,-5,-2,17:15)
Block(3,-5,-1,17:15)
Block(3,-5,3,17:15)
Block(3,-4,-2,17:15)
Block(3,-3,-2,17:15)
Block(3,-3,0,17:15)
Block(3,-3,1,17:15)
Block(3,-3,2,17:15)
Block(3,-2,0,17:15)
Block(3,-1,0,17:15)
Block(3,0,0,17:15)
Block(3,12,0,17:15)
Block(3,12,10,LEAVES:3)
Block(3,13,-4,LEAVES:3)
Block(3,13,0,17:15)
Block(3,13,1,LEAVES:3)
Block(3,13,3,LEAVES:3)
Block(3,13,4,LEAVES:3)
Block(3,13,5,17:15)
Block(3,13,7,LEAVES:3)
Block(3,13,8,LEAVES:3)
Block(3,13,9,LEAVES:3)
Block(3,14,-3,LEAVES:3)
Block(3,14,-2,LEAVES:3)
Block(3,14,-1,17:15)
Block(3,14,0,LEAVES:3)
Block(3,14,1,LEAVES:3)
Block(3,14,2,LEAVES:3)
Block(3,14,5,LEAVES:3)
Block(3,14,6,LEAVES:3)
Block(3,14,8,LEAVES:3)
Block(3,15,-2,LEAVES:3)
Block(3,15,-1,LEAVES:3)
Block(3,15,0,LEAVES:3)
Block(3,21,-12,LEAVES:3)
Block(3,21,-6,17:15)
Block(3,22,-17,LEAVES:3)
Block(3,22,-12,LEAVES:3)
Block(3,22,-10,17:15)
Block(3,22,-7,LEAVES:3)
Block(3,22,-6,17:15)
Block(3,22,-5,LEAVES:3)
Block(3,23,-16,LEAVES:3)
Block(3,23,-15,LEAVES:3)
Block(3,23,-11,LEAVES:3)
Block(3,23,-10,17:15)
Block(3,23,-9,17:15)
Block(3,23,-8,17:15)
Block(3,23,-5,LEAVES:3)
Block(3,23,-4,LEAVES:3)
Block(3,24,-13,LEAVES:3)
Block(3,24,-9,LEAVES:3)
Block(3,24,-8,LEAVES:3)
Block(3,24,-7,17:15)
Block(3,24,-6,LEAVES:3)
Block(3,25,-13,LEAVES:3)
Block(3,25,-12,17:15)
Block(3,25,-11,17:15)
Block(3,25,-10,LEAVES:3)
Block(3,25,-9,LEAVES:3)
Block(3,25,-8,LEAVES:3)
Block(3,25,-6,LEAVES:3)
Block(3,26,-16,LEAVES:3)
Block(3,26,-15,LEAVES:3)
Block(3,26,-14,LEAVES:3)
Block(3,26,-12,LEAVES:3)
Block(3,26,-11,LEAVES:3)
Block(3,26,-10,LEAVES:3)
Block(3,26,2,LEAVES:3)
Block(3,26,3,17:15)
Block(3,27,-14,LEAVES:3)
Block(3,27,-11,LEAVES:3)
Block(3,27,3,LEAVES:3)
Block(3,27,4,LEAVES:3)
Block(3,27,8,LEAVES:3)
Block(3,28,3,LEAVES:3)
Block(3,28,5,LEAVES:3)
Block(3,28,6,LEAVES:3)
Block(3,28,7,17:15)
Block(3,28,8,LEAVES:3)
Block(3,28,12,LEAVES:3)
Block(3,29,6,LEAVES:3)
Block(3,29,7,LEAVES:3)
Block(3,29,9,17:15)
Block(3,29,10,17:15)
Block(3,29,11,LEAVES:3)
Block(3,29,13,LEAVES:3)
Block(3,30,9,LEAVES:3)
Block(3,30,10,LEAVES:3)
Block(3,30,11,LEAVES:3)
Block(3,30,12,LEAVES:3)
Block(3,30,13,LEAVES:3)
Block(3,31,11,LEAVES:3)
Block(3,35,6,LEAVES:3)
Block(3,36,2,17:15)
Block(3,36,8,LEAVES:3)
Block(3,37,3,LEAVES:3)
Block(3,37,5,17:15)
Block(3,37,6,LEAVES:3)
Block(3,37,7,LEAVES:3)
Block(3,38,3,LEAVES:3)
Block(3,38,5,LEAVES:3)
Block(3,40,-10,LEAVES:3)
Block(3,40,-3,LEAVES:3)
Block(3,41,-11,LEAVES:3)
Block(3,41,-8,LEAVES:3)
Block(3,41,-5,LEAVES:3)
Block(3,41,-4,LEAVES:3)
Block(3,42,-10,LEAVES:3)
Block(3,42,-9,LEAVES:3)
Block(3,42,-8,LEAVES:3)
Block(3,42,-7,LEAVES:3)
Block(3,42,-6,LEAVES:3)
Block(3,42,-5,17:15)
Block(3,42,-4,LEAVES:3)
Block(3,43,-8,17:15)
Block(3,43,-7,LEAVES:3)
Block(3,43,-5,LEAVES:3)
Block(3,43,5,LEAVES:3)
Block(3,44,-8,LEAVES:3)
Block(3,44,4,LEAVES:3)
Block(3,44,5,17:15)
Block(3,44,6,LEAVES:3)
Block(3,44,7,LEAVES:3)
Block(3,44,8,LEAVES:3)
Block(3,45,5,LEAVES:3)
Block(3,45,6,LEAVES:3)
Block(3,45,7,LEAVES:3)
Block(3,46,6,LEAVES:3)
Block(3,48,-1,LEAVES:3)
Block(3,49,-3,LEAVES:3)
Block(3,49,-2,LEAVES:3)
Block(3,49,-1,LEAVES:3)
Block(3,50,-2,LEAVES:3)
Block(4,-6,-3,17:15)
Block(4,-6,-1,17:15)
Block(4,-5,-3,17:15)
Block(4,-5,2,17:15)
Block(4,-4,-3,17:15)
Block(4,-4,1,17:15)
Block(4,-4,2,17:15)
Block(4,-3,1,17:15)
Block(4,-2,1,17:15)
Block(4,12,4,LEAVES:3)
Block(4,12,6,LEAVES:3)
Block(4,12,8,LEAVES:3)
Block(4,13,-2,LEAVES:3)
Block(4,13,0,17:15)
Block(4,13,5,LEAVES:3)
Block(4,13,6,17:15)
Block(4,13,7,LEAVES:3)
Block(4,13,8,LEAVES:3)
Block(4,14,-4,LEAVES:3)
Block(4,14,-3,LEAVES:3)
Block(4,14,-2,17:15)
Block(4,14,0,LEAVES:3)
Block(4,14,1,LEAVES:3)
Block(4,14,2,LEAVES:3)
Block(4,14,3,LEAVES:3)
Block(4,14,5,LEAVES:3)
Block(4,14,6,LEAVES:3)
Block(4,14,7,LEAVES:3)
Block(4,15,-3,LEAVES:3)
Block(4,15,-2,LEAVES:3)
Block(4,15,-1,LEAVES:3)
Block(4,15,1,LEAVES:3)
Block(4,15,2,LEAVES:3)
Block(4,15,6,LEAVES:3)
Block(4,16,-2,LEAVES:3)
Block(4,20,-6,17:15)
Block(4,21,-7,LEAVES:3)
Block(4,21,-6,17:15)
Block(4,21,-5,17:15)
Block(4,21,-4,LEAVES:3)
Block(4,21,-2,LEAVES:3)
Block(4,22,-9,LEAVES:3)
Block(4,22,-6,LEAVES:3)
Block(4,22,-2,LEAVES:3)
Block(4,23,-17,LEAVES:3)
Block(4,23,-16,LEAVES:3)
Block(4,23,-15,17:15)
Block(4,23,-12,LEAVES:3)
Block(4,23,-11,17:15)
Block(4,23,-10,17:15)
Block(4,23,-9,LEAVES:3)
Block(4,23,-8,LEAVES:3)
Block(4,23,-6,LEAVES:3)
Block(4,24,-16,LEAVES:3)
Block(4,24,-15,LEAVES:3)
Block(4,24,-14,LEAVES:3)
Block(4,24,-13,LEAVES:3)
Block(4,24,-12,17:15)
Block(4,24,-11,17:15)
Block(4,24,-9,LEAVES:3)
Block(4,24,-8,LEAVES:3)
Block(4,24,-7,LEAVES:3)
Block(4,24,-6,17:15)
Block(4,24,-5,LEAVES:3)
Block(4,25,-15,LEAVES:3)
Block(4,25,-12,17:15)
Block(4,25,-11,LEAVES:3)
Block(4,25,-10,LEAVES:3)
Block(4,25,-8,LEAVES:3)
Block(4,25,-7,LEAVES:3)
Block(4,25,-6,LEAVES:3)
Block(4,25,-5,LEAVES:3)
Block(4,25,1,LEAVES:3)
Block(4,26,-14,LEAVES:3)
Block(4,26,-6,LEAVES:3)
Block(4,26,-1,LEAVES:3)
Block(4,26,4,LEAVES:3)
Block(4,27,0,LEAVES:3)
Block(4,27,1,LEAVES:3)
Block(4,27,2,LEAVES:3)
Block(4,27,3,17:15)
Block(4,27,4,LEAVES:3)
Block(4,28,1,LEAVES:3)
Block(4,28,2,LEAVES:3)
Block(4,28,3,LEAVES:3)
Block(4,28,4,LEAVES:3)
Block(4,28,5,LEAVES:3)
Block(4,28,6,LEAVES:3)
Block(4,28,7,17:15)
Block(4,28,13,LEAVES:3)
Block(4,29,3,LEAVES:3)
Block(4,29,5,LEAVES:3)
Block(4,29,6,LEAVES:3)
Block(4,29,7,LEAVES:3)
Block(4,29,8,LEAVES:3)
Block(4,29,9,LEAVES:3)
Block(4,29,10,LEAVES:3)
Block(4,30,6,LEAVES:3)
Block(4,30,9,LEAVES:3)
Block(4,30,11,17:15)
Block(4,30,12,LEAVES:3)
Block(4,30,13,LEAVES:3)
Block(4,30,14,LEAVES:3)
Block(4,31,10,LEAVES:3)
Block(4,31,11,LEAVES:3)
Block(4,31,12,LEAVES:3)
Block(4,32,11,LEAVES:3)
Block(4,36,2,17:15)
Block(4,36,7,LEAVES:3)
Block(4,37,2,17:15)
Block(4,37,3,LEAVES:3)
Block(4,37,4,LEAVES:3)
Block(4,37,5,LEAVES:3)
Block(4,37,6,17:15)
Block(4,37,7,LEAVES:3)
Block(4,37,8,LEAVES:3)
Block(4,38,1,LEAVES:3)
Block(4,38,3,LEAVES:3)
Block(4,38,6,LEAVES:3)
Block(4,38,7,LEAVES:3)
Block(4,39,1,LEAVES:3)
Block(4,39,3,LEAVES:3)
Block(4,39,6,LEAVES:3)
Block(4,40,3,LEAVES:3)
Block(4,41,-10,LEAVES:3)
Block(4,41,-9,LEAVES:3)
Block(4,41,-7,LEAVES:3)
Block(4,41,-6,LEAVES:3)
Block(4,42,-11,LEAVES:3)
Block(4,42,-10,LEAVES:3)
Block(4,42,-9,17:15)
Block(4,42,-8,LEAVES:3)
Block(4,42,-7,LEAVES:3)
Block(4,42,-6,LEAVES:3)
Block(4,42,-5,LEAVES:3)
Block(4,42,-4,LEAVES:3)
Block(4,43,-10,LEAVES:3)
Block(4,43,-9,LEAVES:3)
Block(4,43,-5,LEAVES:3)
Block(4,43,7,LEAVES:3)
Block(4,44,4,LEAVES:3)
Block(4,44,5,LEAVES:3)
Block(4,44,6,LEAVES:3)
Block(4,44,7,LEAVES:3)
Block(4,45,5,LEAVES:3)
Block(4,45,6,LEAVES:3)
Block(4,48,-3,LEAVES:3)
Block(4,49,-2,LEAVES:3)
Block(5,-6,2,17:15)
Block(5,-5,2,17:15)
Block(5,12,7,LEAVES:3)
Block(5,13,-3,LEAVES:3)
Block(5,13,0,LEAVES:3)
Block(5,13,3,LEAVES:3)
Block(5,13,5,LEAVES:3)
Block(5,13,6,LEAVES:3)
Block(5,13,7,LEAVES:3)
Block(5,14,-3,LEAVES:3)
Block(5,14,-2,LEAVES:3)
Block(5,14,-1,LEAVES:3)
Block(5,14,0,17:15)
Block(5,14,1,17:15)
Block(5,14,2,LEAVES:3)
Block(5,14,6,LEAVES:3)
Block(5,15,-2,LEAVES:3)
Block(5,15,0,LEAVES:3)
Block(5,15,1,LEAVES:3)
Block(5,15,2,LEAVES:3)
Block(5,16,1,LEAVES:3)
Block(5,20,-6,17:15)
Block(5,20,-5,LEAVES:3)
Block(5,20,-4,LEAVES:3)
Block(5,20,-1,LEAVES:3)
Block(5,21,-5,LEAVES:3)
Block(5,21,-2,LEAVES:3)
Block(5,21,-1,LEAVES:3)
Block(5,22,-15,LEAVES:3)
Block(5,22,-11,LEAVES:3)
Block(5,22,-5,17:15)
Block(5,22,-4,LEAVES:3)
Block(5,22,-2,LEAVES:3)
Block(5,23,-16,LEAVES:3)
Block(5,23,-15,LEAVES:3)
Block(5,23,-14,17:15)
Block(5,23,-13,LEAVES:3)
Block(5,23,-11,LEAVES:3)
Block(5,23,-9,LEAVES:3)
Block(5,23,-8,LEAVES:3)
Block(5,24,-15,LEAVES:3)
Block(5,24,-14,LEAVES:3)
Block(5,24,-13,17:15)
Block(5,24,-12,17:15)
Block(5,24,-11,LEAVES:3)
Block(5,24,-8,LEAVES:3)
Block(5,24,-7,LEAVES:3)
Block(5,24,-6,17:15)
Block(5,24,-5,LEAVES:3)
Block(5,24,-4,LEAVES:3)
Block(5,25,-14,LEAVES:3)
Block(5,25,-13,LEAVES:3)
Block(5,25,-12,LEAVES:3)
Block(5,25,-6,LEAVES:3)
Block(5,25,-5,LEAVES:3)
Block(5,26,1,LEAVES:3)
Block(5,27,-1,LEAVES:3)
Block(5,27,0,LEAVES:3)
Block(5,27,1,LEAVES:3)
Block(5,27,2,17:15)
Block(5,27,3,LEAVES:3)
Block(5,27,6,LEAVES:3)
Block(5,27,8,LEAVES:3)
Block(5,28,0,LEAVES:3)
Block(5,28,1,LEAVES:3)
Block(5,28,2,LEAVES:3)
Block(5,28,3,LEAVES:3)
Block(5,28,5,LEAVES:3)
Block(5,28,6,LEAVES:3)
Block(5,28,9,LEAVES:3)
Block(5,29,1,LEAVES:3)
Block(5,29,6,LEAVES:3)
Block(5,29,7,17:15)
Block(5,29,8,LEAVES:3)
Block(5,29,9,LEAVES:3)
Block(5,29,10,LEAVES:3)
Block(5,29,12,LEAVES:3)
Block(5,29,14,LEAVES:3)
Block(5,30,7,LEAVES:3)
Block(5,30,8,LEAVES:3)
Block(5,30,11,LEAVES:3)
Block(5,30,12,LEAVES:3)
Block(5,30,13,LEAVES:3)
Block(5,31,11,LEAVES:3)
Block(5,31,12,LEAVES:3)
Block(5,31,13,LEAVES:3)
Block(5,36,8,LEAVES:3)
Block(5,37,1,17:15)
Block(5,37,2,17:15)
Block(5,37,3,LEAVES:3)
Block(5,37,5,LEAVES:3)
Block(5,37,6,LEAVES:3)
Block(5,37,7,LEAVES:3)
Block(5,38,-2,LEAVES:3)
Block(5,38,0,LEAVES:3)
Block(5,38,6,LEAVES:3)
Block(5,39,-1,LEAVES:3)
Block(5,39,1,LEAVES:3)
Block(5,39,2,LEAVES:3)
Block(5,39,5,LEAVES:3)
Block(5,40,1,LEAVES:3)
Block(5,40,2,LEAVES:3)
Block(5,40,3,LEAVES:3)
Block(5,40,4,LEAVES:3)
Block(5,41,-8,LEAVES:3)
Block(5,41,-4,LEAVES:3)
Block(5,41,3,LEAVES:3)
Block(5,42,-10,LEAVES:3)
Block(5,42,-9,LEAVES:3)
Block(5,42,-8,LEAVES:3)
Block(5,42,-5,LEAVES:3)
Block(5,43,-9,LEAVES:3)
Block(5,43,5,LEAVES:3)
Block(5,44,5,LEAVES:3)
Block(6,12,5,LEAVES:3)
Block(6,13,-2,LEAVES:3)
Block(6,13,2,LEAVES:3)
Block(6,13,4,LEAVES:3)
Block(6,13,6,LEAVES:3)
Block(6,14,-2,LEAVES:3)
Block(6,14,-1,LEAVES:3)
Block(6,14,0,LEAVES:3)
Block(6,14,1,LEAVES:3)
Block(6,14,2,17:15)
Block(6,14,3,LEAVES:3)
Block(6,14,4,LEAVES:3)
Block(6,15,-1,LEAVES:3)
Block(6,15,0,LEAVES:3)
Block(6,15,1,LEAVES:3)
Block(6,15,2,LEAVES:3)
Block(6,15,3,LEAVES:3)
Block(6,16,0,LEAVES:3)
Block(6,16,2,LEAVES:3)
Block(6,20,-2,LEAVES:3)
Block(6,21,-7,17:15)
Block(6,21,-4,17:15)
Block(6,21,-2,LEAVES:3)
Block(6,21,-1,LEAVES:3)
Block(6,21,0,LEAVES:3)
Block(6,22,-11,LEAVES:3)
Block(6,22,-10,17:15)
Block(6,22,-8,LEAVES:3)
Block(6,22,-7,LEAVES:3)
Block(6,22,-4,17:15)
Block(6,22,-3,LEAVES:3)
Block(6,22,-2,LEAVES:3)
Block(6,22,-1,LEAVES:3)
Block(6,23,-13,LEAVES:3)
Block(6,23,-11,LEAVES:3)
Block(6,23,-10,LEAVES:3)
Block(6,23,-8,LEAVES:3)
Block(6,23,-7,LEAVES:3)
Block(6,23,-4,LEAVES:3)
Block(6,23,-2,LEAVES:3)
Block(6,24,-15,LEAVES:3)
Block(6,24,-14,LEAVES:3)
Block(6,24,-13,17:15)
Block(6,24,-10,LEAVES:3)
Block(6,24,-7,LEAVES:3)
Block(6,24,-6,LEAVES:3)
Block(6,24,-5,LEAVES:3)
Block(6,25,-13,LEAVES:3)
Block(6,25,-6,LEAVES:3)
Block(6,26,3,LEAVES:3)
Block(6,27,0,LEAVES:3)
Block(6,27,1,LEAVES:3)
Block(6,27,2,LEAVES:3)
Block(6,27,3,LEAVES:3)
Block(6,28,1,LEAVES:3)
Block(6,28,2,LEAVES:3)
Block(6,28,8,LEAVES:3)
Block(6,29,6,LEAVES:3)
Block(6,29,7,LEAVES:3)
Block(6,29,8,LEAVES:3)
Block(6,30,6,LEAVES:3)
Block(6,30,7,LEAVES:3)
Block(6,30,8,LEAVES:3)
Block(6,30,12,LEAVES:3)
Block(6,35,6,LEAVES:3)
Block(6,36,5,LEAVES:3)
Block(6,36,7,LEAVES:3)
Block(6,37,0,17:15)
Block(6,37,1,17:15)
Block(6,37,5,LEAVES:3)
Block(6,37,6,LEAVES:3)
Block(6,37,7,LEAVES:3)
Block(6,38,0,17:15)
Block(6,38,1,LEAVES:3)
Block(6,38,6,LEAVES:3)
Block(6,39,-2,LEAVES:3)
Block(6,39,-1,LEAVES:3)
Block(6,39,0,LEAVES:3)
Block(6,39,1,17:15)
Block(6,39,3,LEAVES:3)
Block(6,40,-1,LEAVES:3)
Block(6,40,0,LEAVES:3)
Block(6,40,1,LEAVES:3)
Block(6,40,2,17:15)
Block(6,40,3,LEAVES:3)
Block(6,40,4,LEAVES:3)
Block(6,40,5,LEAVES:3)
Block(6,41,-10,LEAVES:3)
Block(6,41,1,LEAVES:3)
Block(6,41,2,LEAVES:3)
Block(6,41,3,LEAVES:3)
Block(6,41,4,LEAVES:3)
Block(6,42,-9,LEAVES:3)
Block(6,42,2,LEAVES:3)
Block(7,13,0,LEAVES:3)
Block(7,14,-1,LEAVES:3)
Block(7,14,0,LEAVES:3)
Block(7,14,3,LEAVES:3)
Block(7,15,0,LEAVES:3)
Block(7,15,1,LEAVES:3)
Block(7,15,2,17:15)
Block(7,15,3,LEAVES:3)
Block(7,16,1,LEAVES:3)
Block(7,16,2,LEAVES:3)
Block(7,17,2,LEAVES:3)
Block(7,19,0,LEAVES:3)
Block(7,20,-3,LEAVES:3)
Block(7,20,-1,LEAVES:3)
Block(7,21,-12,LEAVES:3)
Block(7,21,-9,17:15)
Block(7,21,-8,17:15)
Block(7,21,-4,LEAVES:3)
Block(7,21,-3,17:15)
Block(7,21,-2,LEAVES:3)
Block(7,21,-1,LEAVES:3)
Block(7,22,-14,LEAVES:3)
Block(7,22,-12,LEAVES:3)
Block(7,22,-11,17:15)
Block(7,22,-10,LEAVES:3)
Block(7,22,-9,LEAVES:3)
Block(7,22,-8,LEAVES:3)
Block(7,22,-7,LEAVES:3)
Block(7,22,-5,LEAVES:3)
Block(7,22,-4,LEAVES:3)
Block(7,22,-3,LEAVES:3)
Block(7,22,-2,LEAVES:3)
Block(7,23,-15,LEAVES:3)
Block(7,23,-14,LEAVES:3)
Block(7,23,-11,LEAVES:3)
Block(7,23,-10,LEAVES:3)
Block(7,23,-4,LEAVES:3)
Block(7,24,-16,LEAVES:3)
Block(7,24,-15,LEAVES:3)
Block(7,24,-14,17:15)
Block(7,24,-13,LEAVES:3)
Block(7,24,-12,LEAVES:3)
Block(7,24,-6,LEAVES:3)
Block(7,25,-15,LEAVES:3)
Block(7,25,-14,LEAVES:3)
Block(7,25,-13,LEAVES:3)
Block(7,25,-12,LEAVES:3)
Block(7,26,-13,LEAVES:3)
Block(7,26,1,LEAVES:3)
Block(7,27,2,LEAVES:3)
Block(7,28,7,LEAVES:3)
Block(7,29,6,LEAVES:3)
Block(7,29,7,LEAVES:3)
Block(7,29,8,LEAVES:3)
Block(7,30,7,LEAVES:3)
Block(7,31,7,LEAVES:3)
Block(7,36,5,LEAVES:3)
Block(7,37,6,LEAVES:3)
Block(7,38,-2,LEAVES:3)
Block(7,38,0,17:15)
Block(7,39,-2,LEAVES:3)
Block(7,39,-1,LEAVES:3)
Block(7,39,0,17:15)
Block(7,39,1,LEAVES:3)
Block(7,39,4,LEAVES:3)
Block(7,40,-1,LEAVES:3)
Block(7,40,0,LEAVES:3)
Block(7,40,1,LEAVES:3)
Block(7,40,2,LEAVES:3)
Block(7,40,3,LEAVES:3)
Block(7,40,4,LEAVES:3)
Block(7,41,0,LEAVES:3)
Block(7,41,2,LEAVES:3)
Block(8,13,-1,LEAVES:3)
Block(8,14,0,LEAVES:3)
Block(8,14,2,LEAVES:3)
Block(8,14,4,LEAVES:3)
Block(8,15,1,LEAVES:3)
Block(8,15,2,LEAVES:3)
Block(8,15,3,LEAVES:3)
Block(8,15,4,LEAVES:3)
Block(8,16,2,LEAVES:3)
Block(8,16,3,LEAVES:3)
Block(8,20,-2,LEAVES:3)
Block(8,20,0,LEAVES:3)
Block(8,21,-8,17:15)
Block(8,21,-3,LEAVES:3)
Block(8,21,-2,17:15)
Block(8,21,-1,LEAVES:3)
Block(8,21,0,LEAVES:3)
Block(8,21,1,LEAVES:3)
Block(8,22,-11,LEAVES:3)
Block(8,22,-10,LEAVES:3)
Block(8,22,-9,LEAVES:3)
Block(8,22,-8,17:15)
Block(8,22,-5,LEAVES:3)
Block(8,22,-2,LEAVES:3)
Block(8,22,-1,LEAVES:3)
Block(8,22,0,LEAVES:3)
Block(8,23,-13,LEAVES:3)
Block(8,23,-8,LEAVES:3)
Block(8,23,-6,LEAVES:3)
Block(8,24,-16,LEAVES:3)
Block(8,24,-14,LEAVES:3)
Block(8,24,-13,LEAVES:3)
Block(8,24,-12,LEAVES:3)
Block(8,25,-15,LEAVES:3)
Block(8,25,-14,17:15)
Block(8,25,-13,LEAVES:3)
Block(8,26,-14,LEAVES:3)
Block(8,28,8,LEAVES:3)
Block(8,29,7,LEAVES:3)
Block(8,36,7,LEAVES:3)
Block(8,38,0,LEAVES:3)
Block(8,38,2,LEAVES:3)
Block(8,39,-2,LEAVES:3)
Block(8,39,-1,LEAVES:3)
Block(8,39,0,17:15)
Block(8,39,1,LEAVES:3)
Block(8,39,2,LEAVES:3)
Block(8,39,3,LEAVES:3)
Block(8,40,-2,LEAVES:3)
Block(8,40,0,LEAVES:3)
Block(8,40,1,LEAVES:3)
Block(8,40,2,LEAVES:3)
Block(8,41,1,LEAVES:3)
Block(9,14,1,LEAVES:3)
Block(9,15,1,LEAVES:3)
Block(9,15,2,LEAVES:3)
Block(9,15,3,LEAVES:3)
Block(9,16,2,LEAVES:3)
Block(9,19,-2,LEAVES:3)
Block(9,20,-3,LEAVES:3)
Block(9,20,-1,LEAVES:3)
Block(9,21,-11,LEAVES:3)
Block(9,21,-7,LEAVES:3)
Block(9,21,-2,LEAVES:3)
Block(9,21,-1,LEAVES:3)
Block(9,21,0,LEAVES:3)
Block(9,22,-11,LEAVES:3)
Block(9,22,-10,LEAVES:3)
Block(9,22,-9,17:15)
Block(9,22,-8,17:15)
Block(9,22,-7,LEAVES:3)
Block(9,23,-10,LEAVES:3)
Block(9,23,-9,LEAVES:3)
Block(9,23,-8,LEAVES:3)
Block(9,23,-6,LEAVES:3)
Block(9,23,-5,LEAVES:3)
Block(9,23,-4,LEAVES:3)
Block(9,24,-13,LEAVES:3)
Block(9,24,-9,LEAVES:3)
Block(9,24,-6,LEAVES:3)
Block(9,25,-15,LEAVES:3)
Block(9,25,-14,LEAVES:3)
Block(9,25,-13,LEAVES:3)
Block(9,26,-14,LEAVES:3)
Block(9,38,3,LEAVES:3)
Block(9,39,-3,LEAVES:3)
Block(9,39,-2,17:15)
Block(9,39,0,LEAVES:3)
Block(9,39,1,LEAVES:3)
Block(9,39,2,LEAVES:3)
Block(9,40,-2,LEAVES:3)
Block(9,40,-1,LEAVES:3)
Block(9,40,1,LEAVES:3)
Block(10,14,3,LEAVES:3)
Block(10,15,2,LEAVES:3)
Block(10,20,0,LEAVES:3)
Block(10,22,-10,LEAVES:3)
Block(10,22,-9,LEAVES:3)
Block(10,22,-8,LEAVES:3)
Block(10,22,-7,17:15)
Block(10,22,-6,LEAVES:3)
Block(10,22,-3,LEAVES:3)
Block(10,23,-10,LEAVES:3)
Block(10,23,-9,17:15)
Block(10,23,-7,LEAVES:3)
Block(10,23,-6,17:15)
Block(10,23,-5,17:15)
Block(10,23,-4,LEAVES:3)
Block(10,23,-3,LEAVES:3)
Block(10,24,-15,LEAVES:3)
Block(10,24,-10,LEAVES:3)
Block(10,24,-9,LEAVES:3)
Block(10,24,-6,LEAVES:3)
Block(10,24,-5,LEAVES:3)
Block(10,24,-4,LEAVES:3)
Block(10,25,-14,LEAVES:3)
Block(10,25,-6,LEAVES:3)
Block(10,38,-3,LEAVES:3)
Block(10,38,-1,LEAVES:3)
Block(10,38,1,LEAVES:3)
Block(10,39,-2,LEAVES:3)
Block(10,39,-1,17:15)
Block(10,39,0,LEAVES:3)
Block(10,39,1,LEAVES:3)
Block(10,40,-2,LEAVES:3)
Block(10,40,-1,LEAVES:3)
Block(10,40,0,LEAVES:3)
Block(10,41,-1,LEAVES:3)
Block(11,21,-9,LEAVES:3)
Block(11,22,-12,LEAVES:3)
Block(11,22,-10,LEAVES:3)
Block(11,22,-8,LEAVES:3)
Block(11,22,-7,LEAVES:3)
Block(11,22,-6,LEAVES:3)
Block(11,22,-5,LEAVES:3)
Block(11,23,-11,LEAVES:3)
Block(11,23,-10,17:15)
Block(11,23,-9,LEAVES:3)
Block(11,23,-7,LEAVES:3)
Block(11,23,-6,LEAVES:3)
Block(11,23,-5,LEAVES:3)
Block(11,23,-4,LEAVES:3)
Block(11,24,-10,LEAVES:3)
Block(11,24,-5,LEAVES:3)
Block(11,25,-10,LEAVES:3)
Block(11,38,0,LEAVES:3)
Block(11,39,-2,LEAVES:3)
Block(11,39,-1,LEAVES:3)
Block(11,39,0,LEAVES:3)
Block(11,40,-1,LEAVES:3)
Block(12,21,-7,LEAVES:3)
Block(12,21,-5,LEAVES:3)
Block(12,22,-10,LEAVES:3)
Block(12,22,-7,LEAVES:3)
Block(12,22,-4,LEAVES:3)
Block(12,23,-12,LEAVES:3)
Block(12,23,-11,LEAVES:3)
Block(12,23,-10,LEAVES:3)
Block(12,23,-9,LEAVES:3)
Block(12,23,-5,LEAVES:3)
Block(12,24,-11,LEAVES:3)
Block(12,24,-10,LEAVES:3)
Block(12,38,-2,LEAVES:3)
Block(12,39,-1,LEAVES:3)
Block(13,22,-11,LEAVES:3)
Block(13,23,-11,LEAVES:3)
Block(13,23,-10,LEAVES:3)
Block(13,23,-9,LEAVES:3)
Block(13,24,-10,LEAVES:3)
Block(14,22,-9,LEAVES:3)
Block(14,23,-10,LEAVES:3)


#######################################################################
# +-----------------------------------------------------------------+ #
# |                             Entities                            | #
# +-----------------------------------------------------------------+ #
#######################################################################

# Entity() spawns an entity instead of a block. The entity is spawned only once when the BO3 is spawned.
# Entities are persistent by default so they don't de-spawn when no player is near, they are only unloaded.
# Usage: Entity(x,y,z,mobName,groupSize,NameTagOrNBTFileName) or Entity(x,y,z,mobName,groupSize)
# Use /tc entities or /otg entities to get a list of entities that can be used as mobName, this includes entities added by other mods.
# NameTagOrNBTFileName can be either a nametag for the mob or an nbt file (such as mymobinfo.nbt or mymobinfo.txt).
# When using a text file you can use the same mob spawning parameters used with the /summon command to equip the
# entity and give it custom attributes etc. You can copy the DATA part of a summon command including surrounding
# curly braces to a .txt file, for instance for: "/summon Skeleton x y z {DATA}"

#######################################################################
# +-----------------------------------------------------------------+ #
# |                            BO3 checks                           | #
# +-----------------------------------------------------------------+ #
#######################################################################

# Require a condition at a certain location in order for the BO3 to be spawned.
# BlockCheck(x,y,z,BlockName[,BlockName[,...]]) - one of the blocks must be at the location
# BlockCheckNot(x,y,z,BlockName[,BlockName[,...]]) - all the blocks must not be at the location
# LightCheck(x,y,z,minLightLevel,maxLightLevel) - light must be between min and max (inclusive)

# You can use "Solid" as a BlockName for matching all solid blocks or "All" to match all blocks that aren't air.

# Examples:
#   BlockCheck(0,-1,0,GRASS,DIRT)  Require grass or dirt just below the object
#   BlockCheck(0,-1,0,Solid)       Require any solid block just below the object
#   BlockCheck(0,-1,0,WOOL)        Require any type of wool just below the object
#   BlockCheck(0,-1,0,WOOL:0)      Require white wool just below the object
#   BlockCheckNot(0,-1,0,WOOL:0)   Require that there is no white wool below the object
#   LightCheck(0,0,0,0,LEAVES:3)          Require almost complete darkness just below the object

