#######################################################################
# +-----------------------------------------------------------------+ #
# |                            BO3 object                           | #
# +-----------------------------------------------------------------+ #
#######################################################################

# The descriptions in this file are accurate only for TerrainControl and OTG.
# For MCW and OTG+ these descriptions are only accurate if the BO3 is used as a CustomObject.
# MCW and OTG+ completely reimplemented CustomStructure, check the MCW/OTG+ documentation for more information.

# This is the config file of a custom object.
# If you add this object correctly to your BiomeConfigs, it will spawn in the world.

# This is the creator of this BO3 object
Author: Unknown

# A short description of this BO3 object
Description: This BO3 was converted from a schematic using OTGEdit. The author and description information of the schematic could not be found. If you know who the author of the schematic is then please add this information.

# The BO3 version, don't change this! It can be used by external applications to do a version check.
Version: 3

# The settings mode, WriteAll, WriteWithoutComments or WriteDisable. See WorldConfig.
SettingsMode: WriteDisable

#######################################################################
# +-----------------------------------------------------------------+ #
# |                          Main settings                          | #
# +-----------------------------------------------------------------+ #
#######################################################################

# This needs to be set to true to spawn the object in the Tree and Sapling resources.
Tree: true

# The frequency of the BO3 from 1 to 200. Tries this many times to spawn this BO3 when using the CustomObject(...) resource.
# Ignored by Tree(..), Sapling(..) and CustomStructure(..)
Frequency: 1

# The rarity of the BO3 from 0 to 100. Each spawn attempt has rarity% chance to succeed when using the CustomObject(...) resource.
# Ignored by Tree(..), Sapling(..) and CustomStructure(..)
Rarity: 100.0

# If you set this to true, the BO3 will be placed with a random rotation.
RotateRandomly: false

# The spawn height of the BO3 - randomY, highestBlock or highestSolidBlock.
SpawnHeight: highestBlock

# The height limits for the BO3.
MinHeight: 64

MaxHeight: 80

# Objects can have other objects attached to it: branches. Branches can also
# have branches attached to it, which can also have branches, etc. This is the
# maximum branch depth for this objects.
MaxBranchDepth: 10

# When spawned with the UseWorld keyword, this BO3 should NOT spawn in the following biomes.
# If you writer.write the BO3 name directly in the BiomeConfigs, this will be ignored.
ExcludedBiomes: All

# To optimise this BO3 for faster loading times you can use Notepad++ to find/replace comments and abbreviate things.
# Notepad++ find/replace with regex:
# Find: ^[#;].* replace to nothing removes all lines starting with # 
# Find: ^\s*$ replace to nothing removes most empty lines 
# Notepad++ find/replace without regex:
# *Warning: This will only work for OTG 1.10.2 v21 / OTG 1.11.2 v6 or higher. B( is not recognised by lower versions.
# Find: Block( replace to B(

#######################################################################
# +-----------------------------------------------------------------+ #
# |                      Source block settings                      | #
# +-----------------------------------------------------------------+ #
#######################################################################

# The block(s) the BO3 should spawn in.
SourceBlocks: STONE:1,STONE:3,STONE:5,DIRT:1,DIRT,SAND,GRASS,DIRT:2,STATIONARY_WATER,HARD_CLAY,STAINED_CLAY,CLAY,SANDSTONE,SAND:1,AIR,STONE,GRAVEL,LONG_GRASS,LONG_GRASS:1,LONG_GRASS:2,DEAD_BUSH,YELLOW_FLOWER,RED_ROSE,BROWN_MUSHROOM,RED_MUSHROOM

# The maximum percentage of the BO3 that can be outside the SourceBlock.
# The BO3 won't be placed on a location with more blocks outside the SourceBlock than this percentage.
MaxPercentageOutsideSourceBlock: 0

# What to do when a block is about to be placed outside the SourceBlock? (dontPlace, placeAnyway)
OutsideSourceBlock: placeAnyway

#######################################################################
# +-----------------------------------------------------------------+ #
# |                              Blocks                             | #
# +-----------------------------------------------------------------+ #
#######################################################################

# All the blocks used in the BO3 are listed here. Possible blocks:
# Block(x,y,z,id[.data][,nbtfile.nbt) or B(x,y,z,id[.data][,nbtfile.nbt)
# RandomBlock(x,y,z,id[:data][,nbtfile.nbt],chance[,id[:data][,nbtfile.nbt],chance[,...]])
# So RandomBlock(0,0,0,CHEST,chest.nbt,50,CHEST,anotherchest.nbt,100) will spawn a chest at
# the BO3 origin, and give it a 50% chance to have the contents of chest.nbt, or, if that
# fails, a 100% percent chance to have the contents of anotherchest.nbt.

Block(-19,68,-4,LEAVES:3)
Block(-19,69,-4,LEAVES:3)
Block(-18,68,-6,LEAVES:3)
Block(-18,69,-5,LEAVES:3)
Block(-18,69,-4,LEAVES:3)
Block(-18,69,-3,LEAVES:3)
Block(-18,70,-4,LEAVES:3)
Block(-17,67,-1,LEAVES:3)
Block(-17,68,-4,LEAVES:3)
Block(-17,68,-2,LEAVES:3)
Block(-17,68,-1,LEAVES:3)
Block(-17,68,4,LEAVES:3)
Block(-17,69,-6,LEAVES:3)
Block(-17,69,-5,LEAVES:3)
Block(-17,69,-4,LEAVES:3)
Block(-17,69,-3,LEAVES:3)
Block(-17,69,5,LEAVES:3)
Block(-17,70,-5,LEAVES:3)
Block(-17,70,-4,LEAVES:3)
Block(-16,67,-6,LEAVES:3)
Block(-16,68,-5,LEAVES:3)
Block(-16,68,-2,LEAVES:3)
Block(-16,68,-1,LEAVES:3)
Block(-16,68,0,LEAVES:3)
Block(-16,68,6,LEAVES:3)
Block(-16,69,-5,LEAVES:3)
Block(-16,69,-4,17:15)
Block(-16,69,-3,LEAVES:3)
Block(-16,69,-1,LEAVES:3)
Block(-16,69,0,LEAVES:3)
Block(-16,69,4,LEAVES:3)
Block(-16,69,5,LEAVES:3)
Block(-16,69,6,LEAVES:3)
Block(-16,70,-4,LEAVES:3)
Block(-16,70,-3,LEAVES:3)
Block(-16,70,5,LEAVES:3)
Block(-16,71,-4,LEAVES:3)
Block(-15,24,6,LEAVES:3)
Block(-15,25,6,LEAVES:3)
Block(-15,67,-5,LEAVES:3)
Block(-15,67,0,LEAVES:3)
Block(-15,68,-6,LEAVES:3)
Block(-15,68,-5,LEAVES:3)
Block(-15,68,-4,17:15)
Block(-15,68,-2,LEAVES:3)
Block(-15,68,-1,17:15)
Block(-15,68,0,LEAVES:3)
Block(-15,68,2,LEAVES:3)
Block(-15,68,4,LEAVES:3)
Block(-15,69,-5,LEAVES:3)
Block(-15,69,-4,LEAVES:3)
Block(-15,69,-3,LEAVES:3)
Block(-15,69,-2,LEAVES:3)
Block(-15,69,-1,LEAVES:3)
Block(-15,69,0,LEAVES:3)
Block(-15,69,1,LEAVES:3)
Block(-15,69,5,17:15)
Block(-15,69,6,LEAVES:3)
Block(-15,69,7,LEAVES:3)
Block(-15,70,-4,LEAVES:3)
Block(-15,70,-3,LEAVES:3)
Block(-15,70,0,LEAVES:3)
Block(-15,70,4,LEAVES:3)
Block(-15,70,5,LEAVES:3)
Block(-15,70,6,LEAVES:3)
Block(-14,23,6,LEAVES:3)
Block(-14,24,8,LEAVES:3)
Block(-14,25,-4,LEAVES:3)
Block(-14,25,5,LEAVES:3)
Block(-14,25,6,LEAVES:3)
Block(-14,25,7,LEAVES:3)
Block(-14,26,-3,LEAVES:3)
Block(-14,26,6,LEAVES:3)
Block(-14,67,-2,LEAVES:3)
Block(-14,68,-5,LEAVES:3)
Block(-14,68,-4,LEAVES:3)
Block(-14,68,-3,17:15)
Block(-14,68,-2,17:15)
Block(-14,68,-1,LEAVES:3)
Block(-14,68,0,LEAVES:3)
Block(-14,68,2,LEAVES:3)
Block(-14,68,5,LEAVES:3)
Block(-14,68,7,LEAVES:3)
Block(-14,69,-4,LEAVES:3)
Block(-14,69,-3,LEAVES:3)
Block(-14,69,-2,LEAVES:3)
Block(-14,69,-1,LEAVES:3)
Block(-14,69,0,LEAVES:3)
Block(-14,69,1,17:15)
Block(-14,69,2,LEAVES:3)
Block(-14,69,3,LEAVES:3)
Block(-14,69,4,17:15)
Block(-14,69,5,LEAVES:3)
Block(-14,69,6,LEAVES:3)
Block(-14,70,-4,LEAVES:3)
Block(-14,70,-3,LEAVES:3)
Block(-14,70,-2,LEAVES:3)
Block(-14,70,-1,LEAVES:3)
Block(-14,70,0,LEAVES:3)
Block(-14,70,1,LEAVES:3)
Block(-14,70,3,LEAVES:3)
Block(-14,70,4,LEAVES:3)
Block(-14,70,5,LEAVES:3)
Block(-14,71,-3,LEAVES:3)
Block(-14,71,0,LEAVES:3)
Block(-14,71,4,LEAVES:3)
Block(-13,24,-3,LEAVES:3)
Block(-13,24,7,LEAVES:3)
Block(-13,25,-2,LEAVES:3)
Block(-13,25,5,LEAVES:3)
Block(-13,25,6,LEAVES:3)
Block(-13,25,7,LEAVES:3)
Block(-13,25,8,LEAVES:3)
Block(-13,26,-4,LEAVES:3)
Block(-13,26,-3,LEAVES:3)
Block(-13,26,-2,LEAVES:3)
Block(-13,26,6,LEAVES:3)
Block(-13,26,7,LEAVES:3)
Block(-13,27,-4,LEAVES:3)
Block(-13,67,-5,LEAVES:3)
Block(-13,67,-3,17:15)
Block(-13,67,0,LEAVES:3)
Block(-13,68,-6,LEAVES:3)
Block(-13,68,-3,LEAVES:3)
Block(-13,68,-2,LEAVES:3)
Block(-13,68,-1,LEAVES:3)
Block(-13,68,0,LEAVES:3)
Block(-13,68,2,17:15)
Block(-13,68,3,17:15)
Block(-13,68,4,LEAVES:3)
Block(-13,69,-5,LEAVES:3)
Block(-13,69,-2,LEAVES:3)
Block(-13,69,-1,LEAVES:3)
Block(-13,69,0,LEAVES:3)
Block(-13,69,1,LEAVES:3)
Block(-13,69,2,LEAVES:3)
Block(-13,69,3,LEAVES:3)
Block(-13,69,4,LEAVES:3)
Block(-13,69,5,LEAVES:3)
Block(-13,70,-4,LEAVES:3)
Block(-13,70,-3,LEAVES:3)
Block(-13,70,-2,LEAVES:3)
Block(-13,70,-1,LEAVES:3)
Block(-13,70,2,LEAVES:3)
Block(-13,70,4,LEAVES:3)
Block(-13,71,-3,LEAVES:3)
Block(-13,71,-2,LEAVES:3)
Block(-12,24,-2,LEAVES:3)
Block(-12,24,3,LEAVES:3)
Block(-12,24,5,LEAVES:3)
Block(-12,25,-4,LEAVES:3)
Block(-12,25,4,LEAVES:3)
Block(-12,25,5,LEAVES:3)
Block(-12,25,6,17:15)
Block(-12,25,7,LEAVES:3)
Block(-12,26,-5,LEAVES:3)
Block(-12,26,-4,LEAVES:3)
Block(-12,26,-3,LEAVES:3)
Block(-12,26,-2,LEAVES:3)
Block(-12,26,5,LEAVES:3)
Block(-12,26,6,LEAVES:3)
Block(-12,27,-4,LEAVES:3)
Block(-12,27,-3,LEAVES:3)
Block(-12,27,6,LEAVES:3)
Block(-12,41,-5,LEAVES:3)
Block(-12,67,-3,17:15)
Block(-12,67,2,LEAVES:3)
Block(-12,67,3,17:15)
Block(-12,68,-8,LEAVES:3)
Block(-12,68,-2,LEAVES:3)
Block(-12,68,3,17:15)
Block(-12,68,4,LEAVES:3)
Block(-12,68,5,LEAVES:3)
Block(-12,69,-8,LEAVES:3)
Block(-12,69,-6,LEAVES:3)
Block(-12,69,-5,LEAVES:3)
Block(-12,69,-4,LEAVES:3)
Block(-12,69,2,LEAVES:3)
Block(-12,69,3,LEAVES:3)
Block(-12,69,4,LEAVES:3)
Block(-12,69,7,LEAVES:3)
Block(-12,70,-5,LEAVES:3)
Block(-12,70,-4,LEAVES:3)
Block(-12,70,-3,17:15)
Block(-12,70,-2,LEAVES:3)
Block(-12,70,6,LEAVES:3)
Block(-12,71,-3,LEAVES:3)
Block(-12,72,-3,LEAVES:3)
Block(-11,23,4,LEAVES:3)
Block(-11,24,0,LEAVES:3)
Block(-11,24,4,LEAVES:3)
Block(-11,24,7,LEAVES:3)
Block(-11,25,-2,LEAVES:3)
Block(-11,25,-1,LEAVES:3)
Block(-11,25,0,LEAVES:3)
Block(-11,25,3,LEAVES:3)
Block(-11,25,4,LEAVES:3)
Block(-11,25,5,LEAVES:3)
Block(-11,25,6,17:15)
Block(-11,25,7,LEAVES:3)
Block(-11,26,-4,LEAVES:3)
Block(-11,26,-3,17:15)
Block(-11,26,-2,LEAVES:3)
Block(-11,26,-1,LEAVES:3)
Block(-11,26,4,LEAVES:3)
Block(-11,26,5,LEAVES:3)
Block(-11,26,6,LEAVES:3)
Block(-11,27,-4,LEAVES:3)
Block(-11,27,-3,LEAVES:3)
Block(-11,27,-2,LEAVES:3)
Block(-11,28,-3,LEAVES:3)
Block(-11,32,-6,LEAVES:3)
Block(-11,33,-6,LEAVES:3)
Block(-11,40,0,LEAVES:3)
Block(-11,41,-6,LEAVES:3)
Block(-11,41,-5,LEAVES:3)
Block(-11,67,-4,17:15)
Block(-11,67,3,17:15)
Block(-11,68,-6,LEAVES:3)
Block(-11,68,-4,LEAVES:3)
Block(-11,68,-2,LEAVES:3)
Block(-11,68,0,LEAVES:3)
Block(-11,68,2,LEAVES:3)
Block(-11,68,3,17:15)
Block(-11,68,4,LEAVES:3)
Block(-11,69,-9,LEAVES:3)
Block(-11,69,-8,LEAVES:3)
Block(-11,69,-7,LEAVES:3)
Block(-11,69,-6,LEAVES:3)
Block(-11,69,-5,LEAVES:3)
Block(-11,69,-4,17:15)
Block(-11,69,-3,LEAVES:3)
Block(-11,69,-2,LEAVES:3)
Block(-11,69,3,LEAVES:3)
Block(-11,70,-8,LEAVES:3)
Block(-11,70,-6,LEAVES:3)
Block(-11,70,-5,LEAVES:3)
Block(-11,70,-4,LEAVES:3)
Block(-11,70,-3,LEAVES:3)
Block(-11,70,5,LEAVES:3)
Block(-11,70,6,LEAVES:3)
Block(-11,70,7,LEAVES:3)
Block(-11,71,-5,LEAVES:3)
Block(-11,71,-3,LEAVES:3)
Block(-11,71,6,LEAVES:3)
Block(-10,23,0,LEAVES:3)
Block(-10,24,0,LEAVES:3)
Block(-10,24,2,LEAVES:3)
Block(-10,24,5,17:15)
Block(-10,25,-4,LEAVES:3)
Block(-10,25,-3,LEAVES:3)
Block(-10,25,-2,17:15)
Block(-10,25,-1,LEAVES:3)
Block(-10,25,0,LEAVES:3)
Block(-10,25,1,LEAVES:3)
Block(-10,25,3,LEAVES:3)
Block(-10,25,4,LEAVES:3)
Block(-10,25,5,17:15)
Block(-10,25,6,17:15)
Block(-10,25,7,LEAVES:3)
Block(-10,25,8,LEAVES:3)
Block(-10,26,-2,LEAVES:3)
Block(-10,26,-1,LEAVES:3)
Block(-10,26,0,LEAVES:3)
Block(-10,26,6,LEAVES:3)
Block(-10,26,7,LEAVES:3)
Block(-10,27,-3,LEAVES:3)
Block(-10,27,-1,LEAVES:3)
Block(-10,32,-8,LEAVES:3)
Block(-10,33,-7,LEAVES:3)
Block(-10,33,-6,LEAVES:3)
Block(-10,33,-5,LEAVES:3)
Block(-10,34,-6,LEAVES:3)
Block(-10,40,-1,LEAVES:3)
Block(-10,40,0,LEAVES:3)
Block(-10,41,-5,17:15)
Block(-10,41,0,LEAVES:3)
Block(-10,42,-5,LEAVES:3)
Block(-10,47,10,LEAVES:3)
Block(-10,48,9,LEAVES:3)
Block(-10,67,-4,17:15)
Block(-10,68,-9,LEAVES:3)
Block(-10,68,-7,LEAVES:3)
Block(-10,68,-6,LEAVES:3)
Block(-10,68,1,LEAVES:3)
Block(-10,68,2,17:15)
Block(-10,68,3,LEAVES:3)
Block(-10,69,-10,LEAVES:3)
Block(-10,69,-9,LEAVES:3)
Block(-10,69,-8,17:15)
Block(-10,69,-6,LEAVES:3)
Block(-10,69,-5,17:15)
Block(-10,69,-4,LEAVES:3)
Block(-10,69,-3,LEAVES:3)
Block(-10,69,0,LEAVES:3)
Block(-10,69,2,LEAVES:3)
Block(-10,69,5,LEAVES:3)
Block(-10,69,7,LEAVES:3)
Block(-10,70,-9,LEAVES:3)
Block(-10,70,-8,LEAVES:3)
Block(-10,70,-7,LEAVES:3)
Block(-10,70,-5,LEAVES:3)
Block(-10,70,5,LEAVES:3)
Block(-10,70,6,LEAVES:3)
Block(-10,70,7,LEAVES:3)
Block(-10,70,8,LEAVES:3)
Block(-10,71,-8,LEAVES:3)
Block(-10,71,6,LEAVES:3)
Block(-10,71,7,LEAVES:3)
Block(-10,72,6,LEAVES:3)
Block(-9,23,3,LEAVES:3)
Block(-9,23,6,LEAVES:3)
Block(-9,24,-4,LEAVES:3)
Block(-9,24,-1,17:15)
Block(-9,24,4,17:15)
Block(-9,24,5,17:15)
Block(-9,24,6,LEAVES:3)
Block(-9,24,8,LEAVES:3)
Block(-9,25,-4,LEAVES:3)
Block(-9,25,-3,LEAVES:3)
Block(-9,25,-2,17:15)
Block(-9,25,-1,17:15)
Block(-9,25,0,LEAVES:3)
Block(-9,25,2,LEAVES:3)
Block(-9,25,3,LEAVES:3)
Block(-9,25,4,LEAVES:3)
Block(-9,25,6,LEAVES:3)
Block(-9,25,7,LEAVES:3)
Block(-9,26,-3,LEAVES:3)
Block(-9,26,-2,LEAVES:3)
Block(-9,26,-1,LEAVES:3)
Block(-9,26,3,LEAVES:3)
Block(-9,31,-3,LEAVES:3)
Block(-9,32,-6,LEAVES:3)
Block(-9,32,-4,LEAVES:3)
Block(-9,32,-3,LEAVES:3)
Block(-9,33,-8,LEAVES:3)
Block(-9,33,-7,LEAVES:3)
Block(-9,33,-6,LEAVES:3)
Block(-9,33,-5,LEAVES:3)
Block(-9,34,-7,LEAVES:3)
Block(-9,34,-6,LEAVES:3)
Block(-9,40,0,17:15)
Block(-9,40,1,LEAVES:3)
Block(-9,41,-7,LEAVES:3)
Block(-9,41,-4,17:15)
Block(-9,41,-3,LEAVES:3)
Block(-9,42,-4,LEAVES:3)
Block(-9,47,8,LEAVES:3)
Block(-9,48,2,LEAVES:3)
Block(-9,48,8,LEAVES:3)
Block(-9,48,9,LEAVES:3)
Block(-9,48,10,LEAVES:3)
Block(-9,49,3,LEAVES:3)
Block(-9,49,9,LEAVES:3)
Block(-9,66,-4,17:15)
Block(-9,67,-5,LEAVES:3)
Block(-9,67,-2,LEAVES:3)
Block(-9,67,0,LEAVES:3)
Block(-9,67,10,LEAVES:3)
Block(-9,68,-8,LEAVES:3)
Block(-9,68,-7,17:15)
Block(-9,68,-6,17:15)
Block(-9,68,-5,17:15)
Block(-9,68,-3,LEAVES:3)
Block(-9,68,-1,LEAVES:3)
Block(-9,68,1,LEAVES:3)
Block(-9,68,2,17:15)
Block(-9,68,3,LEAVES:3)
Block(-9,69,-9,LEAVES:3)
Block(-9,69,-8,LEAVES:3)
Block(-9,69,-7,LEAVES:3)
Block(-9,69,-6,LEAVES:3)
Block(-9,69,-5,17:15)
Block(-9,69,-4,LEAVES:3)
Block(-9,69,-3,LEAVES:3)
Block(-9,69,-1,LEAVES:3)
Block(-9,69,0,LEAVES:3)
Block(-9,69,1,LEAVES:3)
Block(-9,69,2,LEAVES:3)
Block(-9,69,3,LEAVES:3)
Block(-9,70,-6,LEAVES:3)
Block(-9,70,-5,LEAVES:3)
Block(-9,70,-4,LEAVES:3)
Block(-9,70,0,LEAVES:3)
Block(-9,70,2,LEAVES:3)
Block(-9,70,5,LEAVES:3)
Block(-9,70,6,17:15)
Block(-9,70,7,LEAVES:3)
Block(-9,71,-5,LEAVES:3)
Block(-9,71,6,LEAVES:3)
Block(-8,23,-4,LEAVES:3)
Block(-8,23,-2,LEAVES:3)
Block(-8,23,3,17:15)
Block(-8,23,4,17:15)
Block(-8,24,-7,LEAVES:3)
Block(-8,24,-5,LEAVES:3)
Block(-8,24,-2,LEAVES:3)
Block(-8,24,-1,17:15)
Block(-8,24,0,17:15)
Block(-8,24,1,LEAVES:3)
Block(-8,24,3,17:15)
Block(-8,24,4,17:15)
Block(-8,24,5,LEAVES:3)
Block(-8,24,6,LEAVES:3)
Block(-8,25,-6,LEAVES:3)
Block(-8,25,-5,LEAVES:3)
Block(-8,25,-4,LEAVES:3)
Block(-8,25,-3,LEAVES:3)
Block(-8,25,-1,LEAVES:3)
Block(-8,25,2,LEAVES:3)
Block(-8,25,3,LEAVES:3)
Block(-8,25,4,LEAVES:3)
Block(-8,25,5,LEAVES:3)
Block(-8,26,-5,LEAVES:3)
Block(-8,26,-4,LEAVES:3)
Block(-8,26,2,LEAVES:3)
Block(-8,26,3,LEAVES:3)
Block(-8,26,4,LEAVES:3)
Block(-8,27,3,LEAVES:3)
Block(-8,31,-8,LEAVES:3)
Block(-8,32,-11,LEAVES:3)
Block(-8,32,-7,LEAVES:3)
Block(-8,32,-4,LEAVES:3)
Block(-8,32,-3,LEAVES:3)
Block(-8,32,-2,LEAVES:3)
Block(-8,33,-11,LEAVES:3)
Block(-8,33,-7,LEAVES:3)
Block(-8,33,-6,17:15)
Block(-8,33,-5,LEAVES:3)
Block(-8,33,-3,LEAVES:3)
Block(-8,34,-6,LEAVES:3)
Block(-8,34,-5,LEAVES:3)
Block(-8,35,-6,LEAVES:3)
Block(-8,39,0,17:15)
Block(-8,41,-8,LEAVES:3)
Block(-8,41,-7,LEAVES:3)
Block(-8,41,-3,17:15)
Block(-8,47,2,LEAVES:3)
Block(-8,47,7,LEAVES:3)
Block(-8,47,10,LEAVES:3)
Block(-8,48,3,LEAVES:3)
Block(-8,48,8,LEAVES:3)
Block(-8,48,9,LEAVES:3)
Block(-8,48,10,LEAVES:3)
Block(-8,49,2,LEAVES:3)
Block(-8,49,3,LEAVES:3)
Block(-8,49,9,LEAVES:3)
Block(-8,50,3,LEAVES:3)
Block(-8,57,3,LEAVES:3)
Block(-8,66,-4,17:15)
Block(-8,66,-3,17:15)
Block(-8,66,8,LEAVES:3)
Block(-8,66,10,LEAVES:3)
Block(-8,67,8,LEAVES:3)
Block(-8,67,9,LEAVES:3)
Block(-8,67,10,LEAVES:3)
Block(-8,67,11,LEAVES:3)
Block(-8,68,-6,LEAVES:3)
Block(-8,68,-5,17:15)
Block(-8,68,-4,17:15)
Block(-8,68,-3,LEAVES:3)
Block(-8,68,-2,LEAVES:3)
Block(-8,68,0,LEAVES:3)
Block(-8,68,1,17:15)
Block(-8,68,2,LEAVES:3)
Block(-8,68,4,LEAVES:3)
Block(-8,68,9,LEAVES:3)
Block(-8,68,10,LEAVES:3)
Block(-8,69,-6,LEAVES:3)
Block(-8,69,-5,LEAVES:3)
Block(-8,69,-4,LEAVES:3)
Block(-8,69,-3,LEAVES:3)
Block(-8,69,-2,LEAVES:3)
Block(-8,69,-1,LEAVES:3)
Block(-8,69,0,17:15)
Block(-8,69,1,LEAVES:3)
Block(-8,69,2,LEAVES:3)
Block(-8,69,5,17:15)
Block(-8,69,6,LEAVES:3)
Block(-8,69,7,LEAVES:3)
Block(-8,70,-5,LEAVES:3)
Block(-8,70,-1,LEAVES:3)
Block(-8,70,0,LEAVES:3)
Block(-8,70,4,LEAVES:3)
Block(-8,70,5,LEAVES:3)
Block(-8,70,6,LEAVES:3)
Block(-8,71,5,LEAVES:3)
Block(-7,22,4,LEAVES:3)
Block(-7,23,2,17:15)
Block(-7,23,3,17:15)
Block(-7,23,4,LEAVES:3)
Block(-7,23,6,LEAVES:3)
Block(-7,24,-6,LEAVES:3)
Block(-7,24,-3,17:15)
Block(-7,24,-2,17:15)
Block(-7,24,-1,LEAVES:3)
Block(-7,24,0,LEAVES:3)
Block(-7,24,1,17:15)
Block(-7,24,3,LEAVES:3)
Block(-7,24,4,LEAVES:3)
Block(-7,24,5,LEAVES:3)
Block(-7,25,-7,LEAVES:3)
Block(-7,25,-6,LEAVES:3)
Block(-7,25,-5,LEAVES:3)
Block(-7,25,-4,17:15)
Block(-7,25,-3,LEAVES:3)
Block(-7,25,-2,LEAVES:3)
Block(-7,25,1,LEAVES:3)
Block(-7,25,3,LEAVES:3)
Block(-7,25,4,LEAVES:3)
Block(-7,26,-6,LEAVES:3)
Block(-7,26,-5,LEAVES:3)
Block(-7,26,-4,LEAVES:3)
Block(-7,26,3,LEAVES:3)
Block(-7,26,4,LEAVES:3)
Block(-7,27,-6,LEAVES:3)
Block(-7,31,-7,LEAVES:3)
Block(-7,31,-2,LEAVES:3)
Block(-7,32,-13,LEAVES:3)
Block(-7,32,-8,LEAVES:3)
Block(-7,32,-7,LEAVES:3)
Block(-7,32,-6,17:15)
Block(-7,32,-4,LEAVES:3)
Block(-7,32,-3,17:15)
Block(-7,32,-2,LEAVES:3)
Block(-7,33,-12,LEAVES:3)
Block(-7,33,-11,LEAVES:3)
Block(-7,33,-10,LEAVES:3)
Block(-7,33,-7,LEAVES:3)
Block(-7,33,-6,LEAVES:3)
Block(-7,33,-5,LEAVES:3)
Block(-7,33,-4,LEAVES:3)
Block(-7,33,-3,LEAVES:3)
Block(-7,33,-2,LEAVES:3)
Block(-7,34,-11,LEAVES:3)
Block(-7,34,-6,LEAVES:3)
Block(-7,39,-1,17:15)
Block(-7,39,0,LEAVES:3)
Block(-7,39,1,LEAVES:3)
Block(-7,40,-4,LEAVES:3)
Block(-7,40,-3,17:15)
Block(-7,40,-1,LEAVES:3)
Block(-7,41,-7,17:15)
Block(-7,46,10,LEAVES:3)
Block(-7,47,4,LEAVES:3)
Block(-7,47,9,LEAVES:3)
Block(-7,48,1,LEAVES:3)
Block(-7,48,5,LEAVES:3)
Block(-7,48,8,LEAVES:3)
Block(-7,48,9,17:15)
Block(-7,48,10,LEAVES:3)
Block(-7,48,11,LEAVES:3)
Block(-7,49,2,LEAVES:3)
Block(-7,49,3,LEAVES:3)
Block(-7,49,4,LEAVES:3)
Block(-7,49,8,LEAVES:3)
Block(-7,49,9,LEAVES:3)
Block(-7,49,10,LEAVES:3)
Block(-7,49,13,LEAVES:3)
Block(-7,49,16,LEAVES:3)
Block(-7,50,3,LEAVES:3)
Block(-7,50,9,LEAVES:3)
Block(-7,50,15,LEAVES:3)
Block(-7,57,2,LEAVES:3)
Block(-7,57,3,LEAVES:3)
Block(-7,58,3,LEAVES:3)
Block(-7,66,-3,17:15)
Block(-7,66,9,LEAVES:3)
Block(-7,66,11,LEAVES:3)
Block(-7,67,-11,LEAVES:3)
Block(-7,67,-8,LEAVES:3)
Block(-7,67,-5,17:15)
Block(-7,67,0,17:15)
Block(-7,67,1,17:15)
Block(-7,67,2,17:15)
Block(-7,67,7,LEAVES:3)
Block(-7,67,8,17:15)
Block(-7,67,9,17:15)
Block(-7,67,10,LEAVES:3)
Block(-7,67,11,LEAVES:3)
Block(-7,67,12,LEAVES:3)
Block(-7,68,-10,LEAVES:3)
Block(-7,68,-5,17:15)
Block(-7,68,-3,LEAVES:3)
Block(-7,68,-1,LEAVES:3)
Block(-7,68,1,LEAVES:3)
Block(-7,68,2,17:15)
Block(-7,68,3,17:15)
Block(-7,68,4,17:15)
Block(-7,68,8,LEAVES:3)
Block(-7,68,9,LEAVES:3)
Block(-7,68,10,LEAVES:3)
Block(-7,68,11,LEAVES:3)
Block(-7,69,-5,LEAVES:3)
Block(-7,69,-1,LEAVES:3)
Block(-7,69,0,LEAVES:3)
Block(-7,69,4,17:15)
Block(-7,69,5,17:15)
Block(-7,70,4,LEAVES:3)
Block(-7,70,5,LEAVES:3)
Block(-7,70,6,LEAVES:3)
Block(-7,71,6,LEAVES:3)
Block(-6,-5,4,17:15)
Block(-6,-4,4,17:15)
Block(-6,-3,4,17:15)
Block(-6,-2,4,17:15)
Block(-6,22,1,17:15)
Block(-6,23,-4,LEAVES:3)
Block(-6,23,1,17:15)
Block(-6,23,2,17:15)
Block(-6,23,5,LEAVES:3)
Block(-6,24,-4,LEAVES:3)
Block(-6,24,-3,LEAVES:3)
Block(-6,24,-2,LEAVES:3)
Block(-6,24,-1,LEAVES:3)
Block(-6,24,0,LEAVES:3)
Block(-6,24,1,LEAVES:3)
Block(-6,24,2,LEAVES:3)
Block(-6,24,3,LEAVES:3)
Block(-6,24,4,LEAVES:3)
Block(-6,24,5,LEAVES:3)
Block(-6,25,-6,LEAVES:3)
Block(-6,25,-5,LEAVES:3)
Block(-6,25,-4,LEAVES:3)
Block(-6,25,-3,LEAVES:3)
Block(-6,25,-2,LEAVES:3)
Block(-6,25,0,LEAVES:3)
Block(-6,25,1,LEAVES:3)
Block(-6,25,2,LEAVES:3)
Block(-6,25,4,LEAVES:3)
Block(-6,26,-5,LEAVES:3)
Block(-6,26,-3,LEAVES:3)
Block(-6,26,1,LEAVES:3)
Block(-6,31,-9,LEAVES:3)
Block(-6,31,-4,LEAVES:3)
Block(-6,31,0,LEAVES:3)
Block(-6,32,-12,LEAVES:3)
Block(-6,32,-10,LEAVES:3)
Block(-6,32,-8,LEAVES:3)
Block(-6,32,-7,LEAVES:3)
Block(-6,32,-6,LEAVES:3)
Block(-6,32,-5,17:15)
Block(-6,32,-4,17:15)
Block(-6,32,-3,LEAVES:3)
Block(-6,32,-2,LEAVES:3)
Block(-6,32,-1,LEAVES:3)
Block(-6,32,2,LEAVES:3)
Block(-6,33,-13,LEAVES:3)
Block(-6,33,-12,LEAVES:3)
Block(-6,33,-11,17:15)
Block(-6,33,-10,LEAVES:3)
Block(-6,33,-6,LEAVES:3)
Block(-6,33,-5,LEAVES:3)
Block(-6,33,-4,LEAVES:3)
Block(-6,33,-3,LEAVES:3)
Block(-6,33,-2,LEAVES:3)
Block(-6,33,1,LEAVES:3)
Block(-6,34,-12,LEAVES:3)
Block(-6,34,-11,LEAVES:3)
Block(-6,39,-3,17:15)
Block(-6,39,-2,17:15)
Block(-6,40,-7,17:15)
Block(-6,40,-5,LEAVES:3)
Block(-6,40,-4,LEAVES:3)
Block(-6,40,-3,17:15)
Block(-6,40,2,LEAVES:3)
Block(-6,41,-9,LEAVES:3)
Block(-6,41,-8,17:15)
Block(-6,41,-4,LEAVES:3)
Block(-6,42,-8,LEAVES:3)
Block(-6,47,8,LEAVES:3)
Block(-6,47,11,LEAVES:3)
Block(-6,48,2,LEAVES:3)
Block(-6,48,4,LEAVES:3)
Block(-6,48,5,LEAVES:3)
Block(-6,48,6,LEAVES:3)
Block(-6,48,7,LEAVES:3)
Block(-6,48,8,17:15)
Block(-6,48,9,LEAVES:3)
Block(-6,48,10,LEAVES:3)
Block(-6,49,1,LEAVES:3)
Block(-6,49,2,LEAVES:3)
Block(-6,49,3,17:15)
Block(-6,49,4,LEAVES:3)
Block(-6,49,5,LEAVES:3)
Block(-6,49,8,LEAVES:3)
Block(-6,49,15,LEAVES:3)
Block(-6,50,2,LEAVES:3)
Block(-6,50,3,LEAVES:3)
Block(-6,50,4,LEAVES:3)
Block(-6,50,13,LEAVES:3)
Block(-6,50,14,LEAVES:3)
Block(-6,50,15,LEAVES:3)
Block(-6,50,16,LEAVES:3)
Block(-6,51,3,LEAVES:3)
Block(-6,51,15,LEAVES:3)
Block(-6,56,-10,LEAVES:3)
Block(-6,57,-9,LEAVES:3)
Block(-6,57,3,17:15)
Block(-6,57,4,LEAVES:3)
Block(-6,57,6,LEAVES:3)
Block(-6,65,5,LEAVES:3)
Block(-6,66,-3,17:15)
Block(-6,66,-2,17:15)
Block(-6,66,6,LEAVES:3)
Block(-6,66,7,LEAVES:3)
Block(-6,66,12,LEAVES:3)
Block(-6,67,-10,LEAVES:3)
Block(-6,67,-5,17:15)
Block(-6,67,-4,17:15)
Block(-6,67,-1,17:15)
Block(-6,67,1,17:15)
Block(-6,67,7,17:15)
Block(-6,67,8,LEAVES:3)
Block(-6,67,9,LEAVES:3)
Block(-6,67,10,LEAVES:3)
Block(-6,67,11,LEAVES:3)
Block(-6,68,-11,LEAVES:3)
Block(-6,68,-10,LEAVES:3)
Block(-6,68,-9,LEAVES:3)
Block(-6,68,-8,LEAVES:3)
Block(-6,68,0,LEAVES:3)
Block(-6,68,4,17:15)
Block(-6,68,7,LEAVES:3)
Block(-6,68,8,LEAVES:3)
Block(-6,69,-10,LEAVES:3)
Block(-6,69,3,LEAVES:3)
Block(-6,69,4,LEAVES:3)
Block(-6,69,5,LEAVES:3)
Block(-6,69,7,LEAVES:3)
Block(-6,69,9,LEAVES:3)
Block(-6,70,4,LEAVES:3)
Block(-6,70,5,LEAVES:3)
Block(-6,70,6,17:15)
Block(-6,70,8,LEAVES:3)
Block(-6,71,5,LEAVES:3)
Block(-6,71,6,LEAVES:3)
Block(-6,71,7,LEAVES:3)
Block(-6,72,6,LEAVES:3)
Block(-5,-5,-1,17:15)
Block(-5,-5,2,17:15)
Block(-5,-5,3,17:15)
Block(-5,-4,-1,17:15)
Block(-5,-4,2,17:15)
Block(-5,-3,-1,17:15)
Block(-5,-3,2,17:15)
Block(-5,-3,3,17:15)
Block(-5,-2,1,17:15)
Block(-5,-2,2,17:15)
Block(-5,-2,3,17:15)
Block(-5,-1,1,17:15)
Block(-5,-1,3,17:15)
Block(-5,0,1,17:15)
Block(-5,22,1,17:15)
Block(-5,23,-1,LEAVES:3)
Block(-5,23,2,LEAVES:3)
Block(-5,24,-4,LEAVES:3)
Block(-5,24,-3,LEAVES:3)
Block(-5,24,-2,LEAVES:3)
Block(-5,24,0,LEAVES:3)
Block(-5,24,1,LEAVES:3)
Block(-5,24,2,LEAVES:3)
Block(-5,24,4,LEAVES:3)
Block(-5,25,-3,LEAVES:3)
Block(-5,31,-12,LEAVES:3)
Block(-5,31,-8,LEAVES:3)
Block(-5,31,-7,LEAVES:3)
Block(-5,31,-5,17:15)
Block(-5,31,-3,LEAVES:3)
Block(-5,31,-2,LEAVES:3)
Block(-5,31,-1,LEAVES:3)
Block(-5,32,-12,LEAVES:3)
Block(-5,32,-11,17:15)
Block(-5,32,-10,17:15)
Block(-5,32,-9,LEAVES:3)
Block(-5,32,-8,LEAVES:3)
Block(-5,32,-7,LEAVES:3)
Block(-5,32,-5,LEAVES:3)
Block(-5,32,-4,LEAVES:3)
Block(-5,32,-3,LEAVES:3)
Block(-5,32,-2,LEAVES:3)
Block(-5,32,-1,LEAVES:3)
Block(-5,32,0,LEAVES:3)
Block(-5,33,-11,LEAVES:3)
Block(-5,33,-10,LEAVES:3)
Block(-5,33,-9,LEAVES:3)
Block(-5,33,-8,LEAVES:3)
Block(-5,33,-4,LEAVES:3)
Block(-5,33,-1,LEAVES:3)
Block(-5,33,0,LEAVES:3)
Block(-5,33,1,LEAVES:3)
Block(-5,33,2,LEAVES:3)
Block(-5,34,1,LEAVES:3)
Block(-5,37,7,LEAVES:3)
Block(-5,38,3,LEAVES:3)
Block(-5,39,-3,17:15)
Block(-5,40,-6,17:15)
Block(-5,40,1,17:15)
Block(-5,40,2,LEAVES:3)
Block(-5,40,3,LEAVES:3)
Block(-5,47,2,LEAVES:3)
Block(-5,48,3,LEAVES:3)
Block(-5,48,5,17:15)
Block(-5,48,6,LEAVES:3)
Block(-5,48,7,17:15)
Block(-5,48,10,LEAVES:3)
Block(-5,49,2,LEAVES:3)
Block(-5,49,3,LEAVES:3)
Block(-5,49,4,17:15)
Block(-5,49,5,LEAVES:3)
Block(-5,49,6,LEAVES:3)
Block(-5,49,9,LEAVES:3)
Block(-5,49,10,LEAVES:3)
Block(-5,49,12,17:15)
Block(-5,49,13,17:15)
Block(-5,49,17,LEAVES:3)
Block(-5,50,3,LEAVES:3)
Block(-5,50,4,LEAVES:3)
Block(-5,50,11,LEAVES:3)
Block(-5,50,12,LEAVES:3)
Block(-5,50,13,LEAVES:3)
Block(-5,50,14,LEAVES:3)
Block(-5,50,15,LEAVES:3)
Block(-5,50,16,LEAVES:3)
Block(-5,50,17,LEAVES:3)
Block(-5,51,13,LEAVES:3)
Block(-5,51,15,LEAVES:3)
Block(-5,51,16,LEAVES:3)
Block(-5,51,17,LEAVES:3)
Block(-5,56,-8,LEAVES:3)
Block(-5,56,-3,LEAVES:3)
Block(-5,56,3,17:15)
Block(-5,57,-10,LEAVES:3)
Block(-5,57,-9,LEAVES:3)
Block(-5,57,-8,LEAVES:3)
Block(-5,57,-2,LEAVES:3)
Block(-5,57,6,LEAVES:3)
Block(-5,58,-9,LEAVES:3)
Block(-5,58,1,LEAVES:3)
Block(-5,58,6,LEAVES:3)
Block(-5,58,8,LEAVES:3)
Block(-5,65,4,LEAVES:3)
Block(-5,65,5,LEAVES:3)
Block(-5,66,-2,17:15)
Block(-5,66,-1,17:15)
Block(-5,66,5,LEAVES:3)
Block(-5,66,6,17:15)
Block(-5,66,8,LEAVES:3)
Block(-5,67,-12,LEAVES:3)
Block(-5,67,-8,17:15)
Block(-5,67,-7,17:15)
Block(-5,67,-6,17:15)
Block(-5,67,-5,LEAVES:3)
Block(-5,67,-3,17:15)
Block(-5,67,-2,LEAVES:3)
Block(-5,67,5,LEAVES:3)
Block(-5,67,6,LEAVES:3)
Block(-5,67,7,17:15)
Block(-5,67,8,LEAVES:3)
Block(-5,67,9,LEAVES:3)
Block(-5,67,12,LEAVES:3)
Block(-5,68,-12,LEAVES:3)
Block(-5,68,-11,LEAVES:3)
Block(-5,68,-10,LEAVES:3)
Block(-5,68,-9,LEAVES:3)
Block(-5,68,-8,LEAVES:3)
Block(-5,68,-7,LEAVES:3)
Block(-5,68,-5,LEAVES:3)
Block(-5,68,-1,LEAVES:3)
Block(-5,68,0,LEAVES:3)
Block(-5,68,1,17:15)
Block(-5,68,6,LEAVES:3)
Block(-5,68,7,LEAVES:3)
Block(-5,68,8,LEAVES:3)
Block(-5,68,11,LEAVES:3)
Block(-5,68,12,LEAVES:3)
Block(-5,69,-12,LEAVES:3)
Block(-5,69,-11,LEAVES:3)
Block(-5,69,-10,LEAVES:3)
Block(-5,69,-8,LEAVES:3)
Block(-5,69,0,LEAVES:3)
Block(-5,69,1,LEAVES:3)
Block(-5,69,4,LEAVES:3)
Block(-5,69,6,LEAVES:3)
Block(-5,69,7,LEAVES:3)
Block(-5,70,1,LEAVES:3)
Block(-5,70,5,LEAVES:3)
Block(-5,70,6,LEAVES:3)
Block(-5,70,7,17:15)
Block(-5,70,8,LEAVES:3)
Block(-5,70,9,LEAVES:3)
Block(-5,71,6,LEAVES:3)
Block(-5,71,7,LEAVES:3)
Block(-5,71,8,LEAVES:3)
Block(-4,-5,6,17:15)
Block(-4,-4,5,17:15)
Block(-4,-4,6,17:15)
Block(-4,-3,-1,17:15)
Block(-4,-3,5,17:15)
Block(-4,-3,6,17:15)
Block(-4,-2,-1,17:15)
Block(-4,-2,0,17:15)
Block(-4,-2,5,17:15)
Block(-4,-1,-1,17:15)
Block(-4,-1,1,17:15)
Block(-4,-1,3,17:15)
Block(-4,0,-1,17:15)
Block(-4,0,1,17:15)
Block(-4,0,3,17:15)
Block(-4,1,1,17:15)
Block(-4,1,2,17:15)
Block(-4,1,3,17:15)
Block(-4,2,2,17:15)
Block(-4,21,0,17:15)
Block(-4,22,-3,LEAVES:3)
Block(-4,22,-1,17:15)
Block(-4,22,0,17:15)
Block(-4,22,1,17:15)
Block(-4,22,2,17:15)
Block(-4,23,-3,LEAVES:3)
Block(-4,23,-2,LEAVES:3)
Block(-4,23,-1,LEAVES:3)
Block(-4,23,0,LEAVES:3)
Block(-4,23,1,LEAVES:3)
Block(-4,23,2,LEAVES:3)
Block(-4,23,3,17:15)
Block(-4,23,4,17:15)
Block(-4,23,5,LEAVES:3)
Block(-4,24,-3,LEAVES:3)
Block(-4,24,-1,LEAVES:3)
Block(-4,24,1,LEAVES:3)
Block(-4,24,2,LEAVES:3)
Block(-4,24,3,LEAVES:3)
Block(-4,31,-10,LEAVES:3)
Block(-4,31,-7,LEAVES:3)
Block(-4,31,-5,17:15)
Block(-4,32,-11,LEAVES:3)
Block(-4,32,-10,LEAVES:3)
Block(-4,32,-9,17:15)
Block(-4,32,-8,17:15)
Block(-4,32,-7,LEAVES:3)
Block(-4,32,-4,LEAVES:3)
Block(-4,32,-2,LEAVES:3)
Block(-4,32,-1,17:15)
Block(-4,32,1,LEAVES:3)
Block(-4,32,3,LEAVES:3)
Block(-4,33,-9,LEAVES:3)
Block(-4,33,-8,LEAVES:3)
Block(-4,33,-2,LEAVES:3)
Block(-4,33,-1,LEAVES:3)
Block(-4,33,0,17:15)
Block(-4,33,1,LEAVES:3)
Block(-4,33,2,LEAVES:3)
Block(-4,33,3,LEAVES:3)
Block(-4,34,-9,LEAVES:3)
Block(-4,34,-8,LEAVES:3)
Block(-4,34,-1,LEAVES:3)
Block(-4,34,0,LEAVES:3)
Block(-4,34,1,LEAVES:3)
Block(-4,34,2,LEAVES:3)
Block(-4,35,0,LEAVES:3)
Block(-4,37,7,LEAVES:3)
Block(-4,37,8,LEAVES:3)
Block(-4,38,2,LEAVES:3)
Block(-4,38,3,LEAVES:3)
Block(-4,38,7,LEAVES:3)
Block(-4,39,-4,17:15)
Block(-4,39,-3,17:15)
Block(-4,39,-2,17:15)
Block(-4,39,-1,17:15)
Block(-4,40,-10,LEAVES:3)
Block(-4,40,-5,17:15)
Block(-4,40,-3,LEAVES:3)
Block(-4,40,0,17:15)
Block(-4,41,-3,LEAVES:3)
Block(-4,41,0,LEAVES:3)
Block(-4,48,6,17:15)
Block(-4,48,7,17:15)
Block(-4,48,9,LEAVES:3)
Block(-4,49,4,LEAVES:3)
Block(-4,49,5,LEAVES:3)
Block(-4,49,6,LEAVES:3)
Block(-4,49,7,LEAVES:3)
Block(-4,49,8,LEAVES:3)
Block(-4,49,9,LEAVES:3)
Block(-4,49,10,LEAVES:3)
Block(-4,49,11,17:15)
Block(-4,49,12,17:15)
Block(-4,49,15,LEAVES:3)
Block(-4,50,6,LEAVES:3)
Block(-4,50,9,LEAVES:3)
Block(-4,50,10,LEAVES:3)
Block(-4,50,11,LEAVES:3)
Block(-4,50,12,LEAVES:3)
Block(-4,50,13,LEAVES:3)
Block(-4,50,14,17:15)
Block(-4,50,15,17:15)
Block(-4,50,16,LEAVES:3)
Block(-4,50,17,LEAVES:3)
Block(-4,50,19,LEAVES:3)
Block(-4,51,11,LEAVES:3)
Block(-4,51,14,LEAVES:3)
Block(-4,51,15,LEAVES:3)
Block(-4,51,16,LEAVES:3)
Block(-4,51,17,LEAVES:3)
Block(-4,51,18,LEAVES:3)
Block(-4,51,19,LEAVES:3)
Block(-4,52,15,LEAVES:3)
Block(-4,52,17,LEAVES:3)
Block(-4,55,-8,LEAVES:3)
Block(-4,55,-5,LEAVES:3)
Block(-4,56,-11,LEAVES:3)
Block(-4,56,-9,LEAVES:3)
Block(-4,56,-5,LEAVES:3)
Block(-4,56,-1,LEAVES:3)
Block(-4,56,4,17:15)
Block(-4,57,-11,LEAVES:3)
Block(-4,57,-10,LEAVES:3)
Block(-4,57,-9,LEAVES:3)
Block(-4,57,-8,LEAVES:3)
Block(-4,57,-3,LEAVES:3)
Block(-4,57,-2,LEAVES:3)
Block(-4,57,-1,LEAVES:3)
Block(-4,57,6,17:15)
Block(-4,58,-10,LEAVES:3)
Block(-4,58,-9,LEAVES:3)
Block(-4,58,-2,LEAVES:3)
Block(-4,58,1,17:15)
Block(-4,58,2,LEAVES:3)
Block(-4,58,7,17:15)
Block(-4,58,8,LEAVES:3)
Block(-4,58,9,LEAVES:3)
Block(-4,59,1,LEAVES:3)
Block(-4,59,7,LEAVES:3)
Block(-4,65,-1,17:15)
Block(-4,65,5,17:15)
Block(-4,65,7,LEAVES:3)
Block(-4,66,-4,17:15)
Block(-4,66,-3,17:15)
Block(-4,66,-1,17:15)
Block(-4,66,4,LEAVES:3)
Block(-4,66,5,17:15)
Block(-4,66,6,17:15)
Block(-4,66,7,17:15)
Block(-4,66,9,LEAVES:3)
Block(-4,66,10,LEAVES:3)
Block(-4,67,-10,LEAVES:3)
Block(-4,67,-6,LEAVES:3)
Block(-4,67,-5,17:15)
Block(-4,67,-4,LEAVES:3)
Block(-4,67,-3,17:15)
Block(-4,67,-2,LEAVES:3)
Block(-4,67,-1,LEAVES:3)
Block(-4,67,5,LEAVES:3)
Block(-4,67,6,LEAVES:3)
Block(-4,67,7,LEAVES:3)
Block(-4,67,8,LEAVES:3)
Block(-4,67,9,LEAVES:3)
Block(-4,67,10,LEAVES:3)
Block(-4,68,-14,LEAVES:3)
Block(-4,68,-12,LEAVES:3)
Block(-4,68,-11,LEAVES:3)
Block(-4,68,-10,17:15)
Block(-4,68,-9,17:15)
Block(-4,68,-8,LEAVES:3)
Block(-4,68,-5,LEAVES:3)
Block(-4,68,-4,LEAVES:3)
Block(-4,68,-3,LEAVES:3)
Block(-4,68,-2,LEAVES:3)
Block(-4,68,6,LEAVES:3)
Block(-4,68,8,LEAVES:3)
Block(-4,68,9,LEAVES:3)
Block(-4,68,11,LEAVES:3)
Block(-4,68,12,LEAVES:3)
Block(-4,68,13,LEAVES:3)
Block(-4,69,-14,LEAVES:3)
Block(-4,69,-13,LEAVES:3)
Block(-4,69,-12,LEAVES:3)
Block(-4,69,-11,LEAVES:3)
Block(-4,69,-10,LEAVES:3)
Block(-4,69,-9,LEAVES:3)
Block(-4,69,-5,LEAVES:3)
Block(-4,69,-1,LEAVES:3)
Block(-4,69,0,LEAVES:3)
Block(-4,69,1,17:15)
Block(-4,69,2,LEAVES:3)
Block(-4,69,8,LEAVES:3)
Block(-4,69,11,LEAVES:3)
Block(-4,70,-12,LEAVES:3)
Block(-4,70,-10,LEAVES:3)
Block(-4,70,0,LEAVES:3)
Block(-4,70,1,LEAVES:3)
Block(-4,70,2,LEAVES:3)
Block(-4,70,6,LEAVES:3)
Block(-4,70,7,LEAVES:3)
Block(-4,70,8,LEAVES:3)
Block(-4,71,1,LEAVES:3)
Block(-4,71,7,LEAVES:3)
Block(-4,76,-4,LEAVES:3)
Block(-4,77,-4,LEAVES:3)
Block(-4,77,1,LEAVES:3)
Block(-4,78,2,LEAVES:3)
Block(-3,-5,2,17:15)
Block(-3,-4,2,17:15)
Block(-3,-3,-2,17:15)
Block(-3,-3,1,17:15)
Block(-3,-3,5,17:15)
Block(-3,-2,-2,17:15)
Block(-3,-2,0,17:15)
Block(-3,-2,1,17:15)
Block(-3,-2,5,17:15)
Block(-3,-1,-2,17:15)
Block(-3,-1,0,17:15)
Block(-3,-1,5,17:15)
Block(-3,0,0,17:15)
Block(-3,1,3,17:15)
Block(-3,2,2,17:15)
Block(-3,2,3,17:15)
Block(-3,3,2,17:15)
Block(-3,20,0,17:15)
Block(-3,21,0,17:15)
Block(-3,21,1,17:15)
Block(-3,22,-5,LEAVES:3)
Block(-3,22,-2,17:15)
Block(-3,22,-1,LEAVES:3)
Block(-3,23,-5,LEAVES:3)
Block(-3,23,-4,LEAVES:3)
Block(-3,23,-3,17:15)
Block(-3,23,-2,LEAVES:3)
Block(-3,23,-1,LEAVES:3)
Block(-3,23,0,LEAVES:3)
Block(-3,23,2,LEAVES:3)
Block(-3,23,3,LEAVES:3)
Block(-3,23,5,17:15)
Block(-3,23,7,LEAVES:3)
Block(-3,24,-4,LEAVES:3)
Block(-3,24,-3,LEAVES:3)
Block(-3,24,-2,LEAVES:3)
Block(-3,24,2,LEAVES:3)
Block(-3,24,3,LEAVES:3)
Block(-3,24,5,LEAVES:3)
Block(-3,24,7,LEAVES:3)
Block(-3,25,-3,LEAVES:3)
Block(-3,25,5,LEAVES:3)
Block(-3,30,-10,LEAVES:3)
Block(-3,30,-5,17:15)
Block(-3,31,-12,LEAVES:3)
Block(-3,31,-8,LEAVES:3)
Block(-3,31,-7,17:15)
Block(-3,31,-4,17:15)
Block(-3,31,-3,17:15)
Block(-3,32,-14,LEAVES:3)
Block(-3,32,-12,LEAVES:3)
Block(-3,32,-11,LEAVES:3)
Block(-3,32,-10,17:15)
Block(-3,32,-9,LEAVES:3)
Block(-3,32,-8,17:15)
Block(-3,32,-7,LEAVES:3)
Block(-3,32,-3,LEAVES:3)
Block(-3,32,-2,17:15)
Block(-3,33,-16,LEAVES:3)
Block(-3,33,-15,LEAVES:3)
Block(-3,33,-11,LEAVES:3)
Block(-3,33,-10,LEAVES:3)
Block(-3,33,-9,LEAVES:3)
Block(-3,33,-8,LEAVES:3)
Block(-3,33,-2,LEAVES:3)
Block(-3,33,-1,LEAVES:3)
Block(-3,33,0,LEAVES:3)
Block(-3,33,1,LEAVES:3)
Block(-3,33,2,LEAVES:3)
Block(-3,34,-17,LEAVES:3)
Block(-3,34,0,LEAVES:3)
Block(-3,37,7,17:15)
Block(-3,38,3,17:15)
Block(-3,38,4,LEAVES:3)
Block(-3,39,-6,17:15)
Block(-3,39,-5,17:15)
Block(-3,39,-2,17:15)
Block(-3,39,3,LEAVES:3)
Block(-3,40,-12,LEAVES:3)
Block(-3,40,-11,LEAVES:3)
Block(-3,40,-10,17:15)
Block(-3,40,-6,LEAVES:3)
Block(-3,40,-3,LEAVES:3)
Block(-3,40,0,LEAVES:3)
Block(-3,41,-11,LEAVES:3)
Block(-3,41,-6,LEAVES:3)
Block(-3,47,4,LEAVES:3)
Block(-3,47,7,17:15)
Block(-3,48,4,LEAVES:3)
Block(-3,48,5,LEAVES:3)
Block(-3,48,7,LEAVES:3)
Block(-3,48,10,LEAVES:3)
Block(-3,48,11,17:15)
Block(-3,49,5,LEAVES:3)
Block(-3,49,8,LEAVES:3)
Block(-3,49,9,LEAVES:3)
Block(-3,49,10,LEAVES:3)
Block(-3,49,11,17:15)
Block(-3,49,12,LEAVES:3)
Block(-3,49,13,LEAVES:3)
Block(-3,49,16,LEAVES:3)
Block(-3,50,8,LEAVES:3)
Block(-3,50,9,LEAVES:3)
Block(-3,50,11,LEAVES:3)
Block(-3,50,13,LEAVES:3)
Block(-3,50,14,LEAVES:3)
Block(-3,50,15,LEAVES:3)
Block(-3,50,16,17:15)
Block(-3,50,20,LEAVES:3)
Block(-3,51,9,LEAVES:3)
Block(-3,51,14,LEAVES:3)
Block(-3,51,15,LEAVES:3)
Block(-3,51,16,LEAVES:3)
Block(-3,51,17,17:15)
Block(-3,51,18,LEAVES:3)
Block(-3,51,19,LEAVES:3)
Block(-3,51,20,LEAVES:3)
Block(-3,52,16,LEAVES:3)
Block(-3,52,17,LEAVES:3)
Block(-3,52,18,LEAVES:3)
Block(-3,52,19,LEAVES:3)
Block(-3,53,17,LEAVES:3)
Block(-3,56,-10,LEAVES:3)
Block(-3,56,-9,LEAVES:3)
Block(-3,56,-7,LEAVES:3)
Block(-3,56,-6,LEAVES:3)
Block(-3,56,-5,LEAVES:3)
Block(-3,56,-4,LEAVES:3)
Block(-3,56,-3,LEAVES:3)
Block(-3,56,-2,LEAVES:3)
Block(-3,56,4,17:15)
Block(-3,57,-10,LEAVES:3)
Block(-3,57,-9,17:15)
Block(-3,57,-8,LEAVES:3)
Block(-3,57,-5,LEAVES:3)
Block(-3,57,-4,LEAVES:3)
Block(-3,57,-3,17:15)
Block(-3,57,-2,LEAVES:3)
Block(-3,57,-1,LEAVES:3)
Block(-3,57,0,LEAVES:3)
Block(-3,57,1,17:15)
Block(-3,57,3,LEAVES:3)
Block(-3,57,5,17:15)
Block(-3,58,-9,LEAVES:3)
Block(-3,58,-4,LEAVES:3)
Block(-3,58,-3,LEAVES:3)
Block(-3,58,-2,LEAVES:3)
Block(-3,58,-1,LEAVES:3)
Block(-3,59,-3,LEAVES:3)
Block(-3,64,0,17:15)
Block(-3,64,3,17:15)
Block(-3,65,-1,17:15)
Block(-3,65,0,17:15)
Block(-3,65,4,17:15)
Block(-3,65,5,17:15)
Block(-3,66,5,LEAVES:3)
Block(-3,66,7,LEAVES:3)
Block(-3,66,8,17:15)
Block(-3,67,-11,LEAVES:3)
Block(-3,67,-8,LEAVES:3)
Block(-3,67,-6,LEAVES:3)
Block(-3,67,-5,LEAVES:3)
Block(-3,67,-4,LEAVES:3)
Block(-3,67,-3,17:15)
Block(-3,67,-2,LEAVES:3)
Block(-3,67,6,LEAVES:3)
Block(-3,67,7,LEAVES:3)
Block(-3,67,8,17:15)
Block(-3,67,10,17:15)
Block(-3,67,11,LEAVES:3)
Block(-3,67,13,LEAVES:3)
Block(-3,68,-15,LEAVES:3)
Block(-3,68,-11,17:15)
Block(-3,68,-10,LEAVES:3)
Block(-3,68,-9,LEAVES:3)
Block(-3,68,-8,LEAVES:3)
Block(-3,68,-5,LEAVES:3)
Block(-3,68,-4,LEAVES:3)
Block(-3,68,7,LEAVES:3)
Block(-3,68,8,LEAVES:3)
Block(-3,68,10,LEAVES:3)
Block(-3,68,11,17:15)
Block(-3,68,12,LEAVES:3)
Block(-3,68,13,LEAVES:3)
Block(-3,68,14,LEAVES:3)
Block(-3,69,-15,LEAVES:3)
Block(-3,69,-14,LEAVES:3)
Block(-3,69,-13,LEAVES:3)
Block(-3,69,-12,17:15)
Block(-3,69,-11,LEAVES:3)
Block(-3,69,-10,LEAVES:3)
Block(-3,69,-9,LEAVES:3)
Block(-3,69,-2,LEAVES:3)
Block(-3,69,-1,LEAVES:3)
Block(-3,69,0,17:15)
Block(-3,69,1,LEAVES:3)
Block(-3,69,2,LEAVES:3)
Block(-3,69,6,LEAVES:3)
Block(-3,69,10,LEAVES:3)
Block(-3,69,11,LEAVES:3)
Block(-3,69,12,LEAVES:3)
Block(-3,69,13,LEAVES:3)
Block(-3,70,-14,LEAVES:3)
Block(-3,70,-13,LEAVES:3)
Block(-3,70,-12,LEAVES:3)
Block(-3,70,-11,LEAVES:3)
Block(-3,70,-1,LEAVES:3)
Block(-3,70,0,LEAVES:3)
Block(-3,70,1,LEAVES:3)
Block(-3,70,7,LEAVES:3)
Block(-3,70,11,LEAVES:3)
Block(-3,71,-12,LEAVES:3)
Block(-3,76,-6,LEAVES:3)
Block(-3,77,-5,LEAVES:3)
Block(-3,77,-4,LEAVES:3)
Block(-3,77,-3,LEAVES:3)
Block(-3,77,3,LEAVES:3)
Block(-3,78,-4,LEAVES:3)
Block(-3,78,-3,LEAVES:3)
Block(-3,78,1,LEAVES:3)
Block(-3,78,2,LEAVES:3)
Block(-3,78,3,LEAVES:3)
Block(-3,79,2,LEAVES:3)
Block(-2,-5,-3,17:15)
Block(-2,-5,1,17:15)
Block(-2,-5,3,17:15)
Block(-2,-4,-3,17:15)
Block(-2,-4,-2,17:15)
Block(-2,-4,1,17:15)
Block(-2,-4,3,17:15)
Block(-2,-3,-3,17:15)
Block(-2,-3,-2,17:15)
Block(-2,-3,1,17:15)
Block(-2,-2,-2,17:15)
Block(-2,-2,4,17:15)
Block(-2,-2,5,17:15)
Block(-2,-1,0,17:15)
Block(-2,-1,4,17:15)
Block(-2,-1,5,17:15)
Block(-2,0,0,17:15)
Block(-2,0,4,17:15)
Block(-2,0,5,17:15)
Block(-2,1,0,17:15)
Block(-2,1,4,17:15)
Block(-2,2,0,17:15)
Block(-2,2,1,17:15)
Block(-2,2,2,17:15)
Block(-2,3,0,17:15)
Block(-2,3,1,17:15)
Block(-2,3,2,17:15)
Block(-2,4,1,17:15)
Block(-2,4,2,17:15)
Block(-2,5,1,17:15)
Block(-2,5,2,17:15)
Block(-2,6,1,17:15)
Block(-2,7,1,17:15)
Block(-2,20,0,17:15)
Block(-2,20,1,17:15)
Block(-2,21,1,17:15)
Block(-2,22,-2,LEAVES:3)
Block(-2,22,0,LEAVES:3)
Block(-2,22,3,LEAVES:3)
Block(-2,23,-6,LEAVES:3)
Block(-2,23,-5,LEAVES:3)
Block(-2,23,-4,17:15)
Block(-2,23,-3,LEAVES:3)
Block(-2,23,3,LEAVES:3)
Block(-2,23,8,LEAVES:3)
Block(-2,24,-5,LEAVES:3)
Block(-2,24,-4,LEAVES:3)
Block(-2,24,-3,LEAVES:3)
Block(-2,24,4,LEAVES:3)
Block(-2,24,5,17:15)
Block(-2,24,6,LEAVES:3)
Block(-2,24,7,LEAVES:3)
Block(-2,24,8,LEAVES:3)
Block(-2,25,4,LEAVES:3)
Block(-2,25,5,LEAVES:3)
Block(-2,25,6,LEAVES:3)
Block(-2,25,7,LEAVES:3)
Block(-2,26,5,LEAVES:3)
Block(-2,30,-4,17:15)
Block(-2,31,-11,LEAVES:3)
Block(-2,31,-9,LEAVES:3)
Block(-2,31,-8,LEAVES:3)
Block(-2,31,-7,17:15)
Block(-2,31,-6,LEAVES:3)
Block(-2,31,-2,LEAVES:3)
Block(-2,32,-10,LEAVES:3)
Block(-2,32,-9,LEAVES:3)
Block(-2,32,-8,LEAVES:3)
Block(-2,32,-7,LEAVES:3)
Block(-2,32,-6,LEAVES:3)
Block(-2,32,-4,LEAVES:3)
Block(-2,32,-3,LEAVES:3)
Block(-2,32,-2,17:15)
Block(-2,32,-1,LEAVES:3)
Block(-2,32,0,LEAVES:3)
Block(-2,32,1,LEAVES:3)
Block(-2,33,-17,LEAVES:3)
Block(-2,33,-15,LEAVES:3)
Block(-2,33,-14,LEAVES:3)
Block(-2,33,-13,LEAVES:3)
Block(-2,33,-9,LEAVES:3)
Block(-2,33,-8,LEAVES:3)
Block(-2,33,-7,LEAVES:3)
Block(-2,33,-3,LEAVES:3)
Block(-2,33,-2,LEAVES:3)
Block(-2,34,-18,LEAVES:3)
Block(-2,34,-17,LEAVES:3)
Block(-2,34,-16,LEAVES:3)
Block(-2,34,-15,LEAVES:3)
Block(-2,35,-17,LEAVES:3)
Block(-2,37,6,17:15)
Block(-2,37,7,LEAVES:3)
Block(-2,38,-1,17:15)
Block(-2,38,0,17:15)
Block(-2,38,4,17:15)
Block(-2,39,-8,17:15)
Block(-2,39,-7,17:15)
Block(-2,39,-1,17:15)
Block(-2,40,-9,17:15)
Block(-2,40,-6,LEAVES:3)
Block(-2,40,-2,17:15)
Block(-2,40,-1,17:15)
Block(-2,41,-9,LEAVES:3)
Block(-2,41,-2,LEAVES:3)
Block(-2,47,6,17:15)
Block(-2,47,8,17:15)
Block(-2,48,3,LEAVES:3)
Block(-2,48,4,LEAVES:3)
Block(-2,48,5,LEAVES:3)
Block(-2,48,6,LEAVES:3)
Block(-2,48,8,17:15)
Block(-2,48,9,17:15)
Block(-2,48,10,17:15)
Block(-2,49,4,LEAVES:3)
Block(-2,49,5,LEAVES:3)
Block(-2,49,7,LEAVES:3)
Block(-2,49,8,LEAVES:3)
Block(-2,49,9,LEAVES:3)
Block(-2,49,10,17:15)
Block(-2,49,11,LEAVES:3)
Block(-2,50,5,LEAVES:3)
Block(-2,50,9,LEAVES:3)
Block(-2,50,10,LEAVES:3)
Block(-2,50,14,LEAVES:3)
Block(-2,50,15,LEAVES:3)
Block(-2,50,16,LEAVES:3)
Block(-2,50,18,LEAVES:3)
Block(-2,51,16,LEAVES:3)
Block(-2,51,17,LEAVES:3)
Block(-2,51,18,LEAVES:3)
Block(-2,51,19,LEAVES:3)
Block(-2,52,18,LEAVES:3)
Block(-2,55,-7,LEAVES:3)
Block(-2,55,-3,LEAVES:3)
Block(-2,56,-13,LEAVES:3)
Block(-2,56,-10,LEAVES:3)
Block(-2,56,-9,17:15)
Block(-2,56,-8,LEAVES:3)
Block(-2,56,-6,LEAVES:3)
Block(-2,56,-5,17:15)
Block(-2,56,-4,LEAVES:3)
Block(-2,56,0,LEAVES:3)
Block(-2,56,1,17:15)
Block(-2,56,3,17:15)
Block(-2,56,4,17:15)
Block(-2,57,-12,LEAVES:3)
Block(-2,57,-11,LEAVES:3)
Block(-2,57,-10,LEAVES:3)
Block(-2,57,-9,LEAVES:3)
Block(-2,57,-8,LEAVES:3)
Block(-2,57,-5,LEAVES:3)
Block(-2,57,-4,17:15)
Block(-2,57,-3,LEAVES:3)
Block(-2,57,-2,LEAVES:3)
Block(-2,57,-1,LEAVES:3)
Block(-2,57,1,17:15)
Block(-2,57,3,LEAVES:3)
Block(-2,58,-5,LEAVES:3)
Block(-2,58,-4,LEAVES:3)
Block(-2,58,3,LEAVES:3)
Block(-2,64,0,17:15)
Block(-2,64,1,17:15)
Block(-2,64,2,17:15)
Block(-2,65,0,17:15)
Block(-2,66,-3,LEAVES:3)
Block(-2,66,9,LEAVES:3)
Block(-2,67,-5,LEAVES:3)
Block(-2,67,-4,17:15)
Block(-2,67,-3,LEAVES:3)
Block(-2,67,7,LEAVES:3)
Block(-2,67,8,LEAVES:3)
Block(-2,67,9,17:15)
Block(-2,67,10,LEAVES:3)
Block(-2,68,-13,LEAVES:3)
Block(-2,68,-11,LEAVES:3)
Block(-2,68,-10,LEAVES:3)
Block(-2,68,-9,LEAVES:3)
Block(-2,68,-1,LEAVES:3)
Block(-2,68,1,LEAVES:3)
Block(-2,68,2,LEAVES:3)
Block(-2,68,7,LEAVES:3)
Block(-2,68,9,LEAVES:3)
Block(-2,68,11,LEAVES:3)
Block(-2,68,12,LEAVES:3)
Block(-2,68,13,LEAVES:3)
Block(-2,69,-14,LEAVES:3)
Block(-2,69,-13,LEAVES:3)
Block(-2,69,-12,LEAVES:3)
Block(-2,69,-11,LEAVES:3)
Block(-2,69,-1,LEAVES:3)
Block(-2,69,0,LEAVES:3)
Block(-2,69,1,LEAVES:3)
Block(-2,69,9,LEAVES:3)
Block(-2,70,-13,LEAVES:3)
Block(-2,70,0,LEAVES:3)
Block(-2,75,-5,LEAVES:3)
Block(-2,76,-4,LEAVES:3)
Block(-2,76,-2,LEAVES:3)
Block(-2,77,-6,LEAVES:3)
Block(-2,77,-5,LEAVES:3)
Block(-2,77,-4,LEAVES:3)
Block(-2,77,-3,17:15)
Block(-2,77,-2,LEAVES:3)
Block(-2,77,0,LEAVES:3)
Block(-2,77,2,LEAVES:3)
Block(-2,77,4,LEAVES:3)
Block(-2,78,-5,LEAVES:3)
Block(-2,78,-4,LEAVES:3)
Block(-2,78,-3,LEAVES:3)
Block(-2,78,1,LEAVES:3)
Block(-2,78,2,17:15)
Block(-2,78,3,LEAVES:3)
Block(-2,78,4,LEAVES:3)
Block(-2,79,-3,LEAVES:3)
Block(-2,79,1,LEAVES:3)
Block(-2,79,2,LEAVES:3)
Block(-2,79,3,LEAVES:3)
Block(-2,80,2,LEAVES:3)
Block(-1,-4,0,17:15)
Block(-1,-4,3,17:15)
Block(-1,-3,-1,17:15)
Block(-1,-3,0,17:15)
Block(-1,-3,3,17:15)
Block(-1,-2,-1,17:15)
Block(-1,-2,3,17:15)
Block(-1,-2,4,17:15)
Block(-1,-1,2,17:15)
Block(-1,-1,3,17:15)
Block(-1,0,-1,17:15)
Block(-1,0,0,17:15)
Block(-1,0,1,17:15)
Block(-1,1,-1,17:15)
Block(-1,1,0,17:15)
Block(-1,1,1,17:15)
Block(-1,1,3,17:15)
Block(-1,1,4,17:15)
Block(-1,2,-1,17:15)
Block(-1,2,0,17:15)
Block(-1,2,1,17:15)
Block(-1,2,3,17:15)
Block(-1,3,0,17:15)
Block(-1,3,1,17:15)
Block(-1,3,3,17:15)
Block(-1,4,0,17:15)
Block(-1,4,1,17:15)
Block(-1,4,2,17:15)
Block(-1,5,0,17:15)
Block(-1,5,1,17:15)
Block(-1,5,2,17:15)
Block(-1,6,0,17:15)
Block(-1,6,1,17:15)
Block(-1,6,2,17:15)
Block(-1,7,0,17:15)
Block(-1,7,1,17:15)
Block(-1,7,2,17:15)
Block(-1,8,0,17:15)
Block(-1,8,1,17:15)
Block(-1,8,2,17:15)
Block(-1,9,0,17:15)
Block(-1,9,1,17:15)
Block(-1,9,2,17:15)
Block(-1,10,0,17:15)
Block(-1,10,1,17:15)
Block(-1,10,2,17:15)
Block(-1,11,0,17:15)
Block(-1,11,1,17:15)
Block(-1,11,2,17:15)
Block(-1,12,0,17:15)
Block(-1,12,1,17:15)
Block(-1,13,0,17:15)
Block(-1,13,1,17:15)
Block(-1,14,0,17:15)
Block(-1,14,1,17:15)
Block(-1,15,0,17:15)
Block(-1,15,1,17:15)
Block(-1,16,0,17:15)
Block(-1,16,1,17:15)
Block(-1,17,0,17:15)
Block(-1,17,1,17:15)
Block(-1,18,0,17:15)
Block(-1,18,1,17:15)
Block(-1,19,0,17:15)
Block(-1,19,1,17:15)
Block(-1,20,0,17:15)
Block(-1,20,1,17:15)
Block(-1,21,-3,LEAVES:3)
Block(-1,21,0,17:15)
Block(-1,21,1,17:15)
Block(-1,22,-6,LEAVES:3)
Block(-1,22,-4,LEAVES:3)
Block(-1,22,0,17:15)
Block(-1,22,1,17:15)
Block(-1,22,8,LEAVES:3)
Block(-1,23,-5,LEAVES:3)
Block(-1,23,-4,LEAVES:3)
Block(-1,23,-3,LEAVES:3)
Block(-1,23,0,17:15)
Block(-1,23,1,17:15)
Block(-1,23,4,LEAVES:3)
Block(-1,23,6,LEAVES:3)
Block(-1,24,-5,LEAVES:3)
Block(-1,24,-4,LEAVES:3)
Block(-1,24,-3,LEAVES:3)
Block(-1,24,0,17:15)
Block(-1,24,1,17:15)
Block(-1,24,5,LEAVES:3)
Block(-1,24,6,17:15)
Block(-1,24,7,LEAVES:3)
Block(-1,24,8,LEAVES:3)
Block(-1,24,9,LEAVES:3)
Block(-1,25,-4,LEAVES:3)
Block(-1,25,0,17:15)
Block(-1,25,1,17:15)
Block(-1,25,5,LEAVES:3)
Block(-1,25,6,LEAVES:3)
Block(-1,25,7,LEAVES:3)
Block(-1,25,8,LEAVES:3)
Block(-1,26,1,17:15)
Block(-1,26,7,LEAVES:3)
Block(-1,27,1,17:15)
Block(-1,28,1,17:15)
Block(-1,29,1,17:15)
Block(-1,30,-7,LEAVES:3)
Block(-1,30,-4,17:15)
Block(-1,30,1,17:15)
Block(-1,31,-7,17:15)
Block(-1,31,-6,17:15)
Block(-1,31,-5,17:15)
Block(-1,31,-4,17:15)
Block(-1,31,1,LEAVES:3)
Block(-1,32,-15,LEAVES:3)
Block(-1,32,-12,LEAVES:3)
Block(-1,32,-11,LEAVES:3)
Block(-1,32,-10,LEAVES:3)
Block(-1,32,-9,LEAVES:3)
Block(-1,32,-8,17:15)
Block(-1,32,-7,17:15)
Block(-1,32,-6,LEAVES:3)
Block(-1,32,-5,LEAVES:3)
Block(-1,32,-3,LEAVES:3)
Block(-1,32,-2,LEAVES:3)
Block(-1,32,-1,17:15)
Block(-1,32,0,LEAVES:3)
Block(-1,32,1,LEAVES:3)
Block(-1,33,-19,LEAVES:3)
Block(-1,33,-15,17:15)
Block(-1,33,-14,LEAVES:3)
Block(-1,33,-13,LEAVES:3)
Block(-1,33,-12,LEAVES:3)
Block(-1,33,-10,LEAVES:3)
Block(-1,33,-9,LEAVES:3)
Block(-1,33,-8,LEAVES:3)
Block(-1,33,-7,LEAVES:3)
Block(-1,33,-6,LEAVES:3)
Block(-1,33,-1,LEAVES:3)
Block(-1,33,0,LEAVES:3)
Block(-1,33,1,17:15)
Block(-1,34,-19,LEAVES:3)
Block(-1,34,-18,LEAVES:3)
Block(-1,34,-17,LEAVES:3)
Block(-1,34,-16,17:15)
Block(-1,34,-15,LEAVES:3)
Block(-1,34,-14,LEAVES:3)
Block(-1,34,-13,LEAVES:3)
Block(-1,34,-9,LEAVES:3)
Block(-1,34,-7,LEAVES:3)
Block(-1,34,1,17:15)
Block(-1,35,-18,LEAVES:3)
Block(-1,35,-17,LEAVES:3)
Block(-1,35,-16,LEAVES:3)
Block(-1,35,-15,LEAVES:3)
Block(-1,35,1,17:15)
Block(-1,36,-16,LEAVES:3)
Block(-1,36,1,17:15)
Block(-1,37,0,17:15)
Block(-1,37,1,17:15)
Block(-1,37,4,17:15)
Block(-1,37,6,17:15)
Block(-1,38,0,17:15)
Block(-1,38,1,17:15)
Block(-1,38,6,17:15)
Block(-1,38,7,17:15)
Block(-1,38,8,LEAVES:3)
Block(-1,38,9,LEAVES:3)
Block(-1,39,0,17:15)
Block(-1,39,1,17:15)
Block(-1,39,6,LEAVES:3)
Block(-1,39,8,LEAVES:3)
Block(-1,40,-9,LEAVES:3)
Block(-1,40,-7,17:15)
Block(-1,40,-3,17:15)
Block(-1,40,-2,17:15)
Block(-1,40,1,17:15)
Block(-1,41,-3,17:15)
Block(-1,41,1,17:15)
Block(-1,42,-3,LEAVES:3)
Block(-1,42,1,17:15)
Block(-1,43,1,17:15)
Block(-1,44,1,17:15)
Block(-1,45,1,17:15)
Block(-1,46,1,17:15)
Block(-1,47,1,17:15)
Block(-1,47,3,LEAVES:3)
Block(-1,47,5,LEAVES:3)
Block(-1,47,6,17:15)
Block(-1,47,7,17:15)
Block(-1,47,8,LEAVES:3)
Block(-1,47,11,LEAVES:3)
Block(-1,48,1,17:15)
Block(-1,48,4,LEAVES:3)
Block(-1,48,5,LEAVES:3)
Block(-1,48,6,17:15)
Block(-1,48,7,17:15)
Block(-1,48,8,17:15)
Block(-1,48,10,LEAVES:3)
Block(-1,49,1,17:15)
Block(-1,49,6,LEAVES:3)
Block(-1,49,7,LEAVES:3)
Block(-1,49,8,LEAVES:3)
Block(-1,49,9,LEAVES:3)
Block(-1,49,10,LEAVES:3)
Block(-1,49,11,17:15)
Block(-1,49,12,LEAVES:3)
Block(-1,49,15,LEAVES:3)
Block(-1,50,1,17:15)
Block(-1,50,11,LEAVES:3)
Block(-1,50,13,LEAVES:3)
Block(-1,50,14,LEAVES:3)
Block(-1,50,16,LEAVES:3)
Block(-1,50,17,LEAVES:3)
Block(-1,51,1,17:15)
Block(-1,51,13,LEAVES:3)
Block(-1,51,18,LEAVES:3)
Block(-1,52,1,17:15)
Block(-1,53,1,17:15)
Block(-1,54,-8,LEAVES:3)
Block(-1,54,-6,LEAVES:3)
Block(-1,54,1,17:15)
Block(-1,54,2,17:15)
Block(-1,55,-9,LEAVES:3)
Block(-1,55,-8,17:15)
Block(-1,55,-7,17:15)
Block(-1,55,-6,17:15)
Block(-1,55,2,17:15)
Block(-1,55,7,17:15)
Block(-1,56,-12,LEAVES:3)
Block(-1,56,-11,LEAVES:3)
Block(-1,56,-10,LEAVES:3)
Block(-1,56,-9,LEAVES:3)
Block(-1,56,-8,17:15)
Block(-1,56,-7,LEAVES:3)
Block(-1,56,-6,17:15)
Block(-1,56,-5,17:15)
Block(-1,56,-4,LEAVES:3)
Block(-1,56,-3,LEAVES:3)
Block(-1,56,2,17:15)
Block(-1,56,3,17:15)
Block(-1,56,8,17:15)
Block(-1,56,9,LEAVES:3)
Block(-1,56,10,LEAVES:3)
Block(-1,57,-13,LEAVES:3)
Block(-1,57,-12,LEAVES:3)
Block(-1,57,-11,17:15)
Block(-1,57,-10,LEAVES:3)
Block(-1,57,-9,LEAVES:3)
Block(-1,57,-8,LEAVES:3)
Block(-1,57,-5,LEAVES:3)
Block(-1,57,9,LEAVES:3)
Block(-1,58,-12,LEAVES:3)
Block(-1,58,-11,LEAVES:3)
Block(-1,58,-9,LEAVES:3)
Block(-1,59,-11,LEAVES:3)
Block(-1,63,1,17:15)
Block(-1,64,0,17:15)
Block(-1,64,1,17:15)
Block(-1,67,-10,LEAVES:3)
Block(-1,67,0,LEAVES:3)
Block(-1,67,8,LEAVES:3)
Block(-1,67,13,LEAVES:3)
Block(-1,68,-12,LEAVES:3)
Block(-1,68,-11,LEAVES:3)
Block(-1,68,-4,17:15)
Block(-1,68,-2,LEAVES:3)
Block(-1,68,6,LEAVES:3)
Block(-1,68,7,LEAVES:3)
Block(-1,68,8,LEAVES:3)
Block(-1,68,9,17:15)
Block(-1,68,10,LEAVES:3)
Block(-1,68,11,LEAVES:3)
Block(-1,68,12,LEAVES:3)
Block(-1,69,-13,LEAVES:3)
Block(-1,69,-3,LEAVES:3)
Block(-1,69,0,LEAVES:3)
Block(-1,69,7,LEAVES:3)
Block(-1,69,8,LEAVES:3)
Block(-1,69,9,LEAVES:3)
Block(-1,70,9,LEAVES:3)
Block(-1,76,-6,LEAVES:3)
Block(-1,77,-5,LEAVES:3)
Block(-1,77,-4,LEAVES:3)
Block(-1,77,-3,LEAVES:3)
Block(-1,77,-2,17:15)
Block(-1,77,-1,17:15)
Block(-1,77,6,LEAVES:3)
Block(-1,78,-2,LEAVES:3)
Block(-1,78,-1,LEAVES:3)
Block(-1,78,0,LEAVES:3)
Block(-1,78,1,17:15)
Block(-1,78,3,LEAVES:3)
Block(-1,78,4,LEAVES:3)
Block(-1,78,5,LEAVES:3)
Block(-1,79,1,LEAVES:3)
Block(-1,79,2,LEAVES:3)
Block(-1,79,4,LEAVES:3)
Block(0,-5,-4,17:15)
Block(0,-5,4,17:15)
Block(0,-5,5,17:15)
Block(0,-4,-4,17:15)
Block(0,-4,4,17:15)
Block(0,-4,5,17:15)
Block(0,-3,-3,17:15)
Block(0,-3,4,17:15)
Block(0,-2,-3,17:15)
Block(0,-2,-2,17:15)
Block(0,-2,-1,17:15)
Block(0,-2,3,17:15)
Block(0,-2,4,17:15)
Block(0,-1,-3,17:15)
Block(0,-1,-2,17:15)
Block(0,-1,-1,17:15)
Block(0,-1,2,17:15)
Block(0,-1,3,17:15)
Block(0,0,-2,17:15)
Block(0,0,-1,17:15)
Block(0,0,0,17:15)
Block(0,0,1,17:15)
Block(0,0,2,17:15)
Block(0,0,3,17:15)
Block(0,1,-1,17:15)
Block(0,1,0,17:15)
Block(0,1,1,17:15)
Block(0,1,2,17:15)
Block(0,2,-1,17:15)
Block(0,2,0,17:15)
Block(0,2,1,17:15)
Block(0,2,2,17:15)
Block(0,2,3,17:15)
Block(0,3,-1,17:15)
Block(0,3,0,17:15)
Block(0,3,1,17:15)
Block(0,3,2,17:15)
Block(0,3,3,17:15)
Block(0,4,-1,17:15)
Block(0,4,0,17:15)
Block(0,4,1,17:15)
Block(0,4,2,17:15)
Block(0,4,3,17:15)
Block(0,5,-1,17:15)
Block(0,5,0,17:15)
Block(0,5,1,17:15)
Block(0,5,2,17:15)
Block(0,6,-1,17:15)
Block(0,6,0,17:15)
Block(0,6,1,17:15)
Block(0,6,2,17:15)
Block(0,7,-1,17:15)
Block(0,7,0,17:15)
Block(0,7,1,17:15)
Block(0,7,2,17:15)
Block(0,8,-1,17:15)
Block(0,8,0,17:15)
Block(0,8,1,17:15)
Block(0,8,2,17:15)
Block(0,9,-1,17:15)
Block(0,9,0,17:15)
Block(0,9,1,17:15)
Block(0,9,2,17:15)
Block(0,10,-1,17:15)
Block(0,10,0,17:15)
Block(0,10,1,17:15)
Block(0,10,2,17:15)
Block(0,11,-1,17:15)
Block(0,11,0,17:15)
Block(0,11,1,17:15)
Block(0,11,2,17:15)
Block(0,12,-1,17:15)
Block(0,12,0,17:15)
Block(0,12,1,17:15)
Block(0,12,2,17:15)
Block(0,13,-1,17:15)
Block(0,13,0,17:15)
Block(0,13,1,17:15)
Block(0,13,2,17:15)
Block(0,14,-1,17:15)
Block(0,14,0,17:15)
Block(0,14,1,17:15)
Block(0,14,2,17:15)
Block(0,15,-1,17:15)
Block(0,15,0,17:15)
Block(0,15,1,17:15)
Block(0,15,2,17:15)
Block(0,16,-1,17:15)
Block(0,16,0,17:15)
Block(0,16,1,17:15)
Block(0,16,2,17:15)
Block(0,17,-1,17:15)
Block(0,17,0,17:15)
Block(0,17,1,17:15)
Block(0,17,2,17:15)
Block(0,18,0,17:15)
Block(0,18,1,17:15)
Block(0,18,2,17:15)
Block(0,19,0,17:15)
Block(0,19,1,17:15)
Block(0,19,2,17:15)
Block(0,20,0,17:15)
Block(0,20,1,17:15)
Block(0,20,2,17:15)
Block(0,21,0,17:15)
Block(0,21,1,17:15)
Block(0,21,2,17:15)
Block(0,22,0,17:15)
Block(0,22,1,17:15)
Block(0,22,2,17:15)
Block(0,22,6,LEAVES:3)
Block(0,23,-5,LEAVES:3)
Block(0,23,-4,LEAVES:3)
Block(0,23,-3,LEAVES:3)
Block(0,23,0,17:15)
Block(0,23,1,17:15)
Block(0,23,2,17:15)
Block(0,23,5,LEAVES:3)
Block(0,23,7,LEAVES:3)
Block(0,23,9,LEAVES:3)
Block(0,24,-4,LEAVES:3)
Block(0,24,0,17:15)
Block(0,24,1,17:15)
Block(0,24,2,17:15)
Block(0,24,5,LEAVES:3)
Block(0,24,6,LEAVES:3)
Block(0,24,7,LEAVES:3)
Block(0,24,8,LEAVES:3)
Block(0,25,0,17:15)
Block(0,25,1,17:15)
Block(0,25,2,17:15)
Block(0,25,6,LEAVES:3)
Block(0,25,7,LEAVES:3)
Block(0,26,0,17:15)
Block(0,26,1,17:15)
Block(0,26,2,17:15)
Block(0,27,0,17:15)
Block(0,27,1,17:15)
Block(0,27,2,17:15)
Block(0,28,0,17:15)
Block(0,28,1,17:15)
Block(0,28,2,17:15)
Block(0,29,-1,17:15)
Block(0,29,0,17:15)
Block(0,29,1,17:15)
Block(0,29,2,17:15)
Block(0,30,-3,17:15)
Block(0,30,-1,17:15)
Block(0,30,0,17:15)
Block(0,30,1,17:15)
Block(0,30,2,17:15)
Block(0,31,-9,LEAVES:3)
Block(0,31,-6,17:15)
Block(0,31,-3,LEAVES:3)
Block(0,31,-1,LEAVES:3)
Block(0,31,0,17:15)
Block(0,31,1,17:15)
Block(0,31,2,17:15)
Block(0,32,-14,LEAVES:3)
Block(0,32,-12,LEAVES:3)
Block(0,32,-10,LEAVES:3)
Block(0,32,-9,17:15)
Block(0,32,-8,LEAVES:3)
Block(0,32,-7,LEAVES:3)
Block(0,32,-6,LEAVES:3)
Block(0,32,-2,LEAVES:3)
Block(0,32,-1,LEAVES:3)
Block(0,32,0,LEAVES:3)
Block(0,32,1,17:15)
Block(0,32,2,17:15)
Block(0,33,-18,LEAVES:3)
Block(0,33,-16,LEAVES:3)
Block(0,33,-15,LEAVES:3)
Block(0,33,-14,17:15)
Block(0,33,-13,17:15)
Block(0,33,-12,LEAVES:3)
Block(0,33,-11,LEAVES:3)
Block(0,33,-10,LEAVES:3)
Block(0,33,-9,LEAVES:3)
Block(0,33,-8,LEAVES:3)
Block(0,33,-7,LEAVES:3)
Block(0,33,-2,LEAVES:3)
Block(0,33,-1,LEAVES:3)
Block(0,33,0,17:15)
Block(0,33,1,17:15)
Block(0,33,2,17:15)
Block(0,34,-18,LEAVES:3)
Block(0,34,-17,LEAVES:3)
Block(0,34,-16,LEAVES:3)
Block(0,34,-15,LEAVES:3)
Block(0,34,-14,LEAVES:3)
Block(0,34,-13,LEAVES:3)
Block(0,34,-3,LEAVES:3)
Block(0,34,0,17:15)
Block(0,34,1,17:15)
Block(0,34,2,17:15)
Block(0,35,-16,LEAVES:3)
Block(0,35,-14,LEAVES:3)
Block(0,35,0,17:15)
Block(0,35,1,17:15)
Block(0,35,2,17:15)
Block(0,35,3,17:15)
Block(0,36,0,17:15)
Block(0,36,1,17:15)
Block(0,36,2,17:15)
Block(0,36,3,17:15)
Block(0,37,0,17:15)
Block(0,37,1,17:15)
Block(0,37,2,17:15)
Block(0,37,3,17:15)
Block(0,37,4,17:15)
Block(0,37,5,17:15)
Block(0,38,0,17:15)
Block(0,38,1,17:15)
Block(0,38,2,17:15)
Block(0,38,4,LEAVES:3)
Block(0,38,8,17:15)
Block(0,39,0,17:15)
Block(0,39,1,17:15)
Block(0,39,2,17:15)
Block(0,40,-7,LEAVES:3)
Block(0,40,0,17:15)
Block(0,40,1,17:15)
Block(0,40,2,17:15)
Block(0,41,-5,17:15)
Block(0,41,-4,17:15)
Block(0,41,1,17:15)
Block(0,41,2,17:15)
Block(0,42,-4,LEAVES:3)
Block(0,42,1,17:15)
Block(0,42,2,17:15)
Block(0,43,1,17:15)
Block(0,43,2,17:15)
Block(0,44,1,17:15)
Block(0,44,2,17:15)
Block(0,45,1,17:15)
Block(0,45,2,17:15)
Block(0,46,1,17:15)
Block(0,46,2,17:15)
Block(0,46,4,17:15)
Block(0,47,1,17:15)
Block(0,47,2,17:15)
Block(0,47,4,17:15)
Block(0,47,5,17:15)
Block(0,47,6,17:15)
Block(0,47,10,LEAVES:3)
Block(0,47,16,LEAVES:3)
Block(0,48,1,17:15)
Block(0,48,2,17:15)
Block(0,48,5,LEAVES:3)
Block(0,48,6,LEAVES:3)
Block(0,48,7,LEAVES:3)
Block(0,48,8,LEAVES:3)
Block(0,48,9,LEAVES:3)
Block(0,48,10,LEAVES:3)
Block(0,48,11,LEAVES:3)
Block(0,48,15,LEAVES:3)
Block(0,48,18,LEAVES:3)
Block(0,49,1,17:15)
Block(0,49,2,17:15)
Block(0,49,5,LEAVES:3)
Block(0,49,6,LEAVES:3)
Block(0,49,7,LEAVES:3)
Block(0,49,10,LEAVES:3)
Block(0,49,12,17:15)
Block(0,49,17,LEAVES:3)
Block(0,50,1,17:15)
Block(0,50,2,17:15)
Block(0,50,6,LEAVES:3)
Block(0,50,12,LEAVES:3)
Block(0,50,13,17:15)
Block(0,50,14,LEAVES:3)
Block(0,50,15,LEAVES:3)
Block(0,51,1,17:15)
Block(0,51,2,17:15)
Block(0,51,13,LEAVES:3)
Block(0,51,14,LEAVES:3)
Block(0,52,1,17:15)
Block(0,52,2,17:15)
Block(0,52,13,LEAVES:3)
Block(0,53,-7,LEAVES:3)
Block(0,53,-2,LEAVES:3)
Block(0,53,1,17:15)
Block(0,53,2,17:15)
Block(0,54,-7,17:15)
Block(0,54,-6,17:15)
Block(0,54,-5,LEAVES:3)
Block(0,54,1,17:15)
Block(0,54,2,17:15)
Block(0,55,-7,17:15)
Block(0,55,-5,LEAVES:3)
Block(0,55,-2,LEAVES:3)
Block(0,55,1,17:15)
Block(0,55,2,17:15)
Block(0,55,6,17:15)
Block(0,56,-14,LEAVES:3)
Block(0,56,-10,LEAVES:3)
Block(0,56,-9,LEAVES:3)
Block(0,56,-8,LEAVES:3)
Block(0,56,-5,LEAVES:3)
Block(0,56,-4,17:15)
Block(0,56,-3,LEAVES:3)
Block(0,56,-2,LEAVES:3)
Block(0,56,1,17:15)
Block(0,56,2,17:15)
Block(0,56,6,LEAVES:3)
Block(0,56,9,LEAVES:3)
Block(0,57,-21,LEAVES:3)
Block(0,57,-14,LEAVES:3)
Block(0,57,-13,LEAVES:3)
Block(0,57,-12,LEAVES:3)
Block(0,57,-11,17:15)
Block(0,57,-9,LEAVES:3)
Block(0,57,-4,LEAVES:3)
Block(0,57,-3,LEAVES:3)
Block(0,57,1,17:15)
Block(0,57,2,17:15)
Block(0,58,-20,LEAVES:3)
Block(0,58,-13,LEAVES:3)
Block(0,58,-11,LEAVES:3)
Block(0,58,1,17:15)
Block(0,59,1,17:15)
Block(0,60,1,17:15)
Block(0,61,1,17:15)
Block(0,62,1,17:15)
Block(0,63,1,17:15)
Block(0,64,1,17:15)
Block(0,65,1,17:15)
Block(0,66,1,17:15)
Block(0,67,1,17:15)
Block(0,67,9,LEAVES:3)
Block(0,67,11,LEAVES:3)
Block(0,68,-4,17:15)
Block(0,68,-3,17:15)
Block(0,68,-2,LEAVES:3)
Block(0,68,-1,LEAVES:3)
Block(0,68,1,17:15)
Block(0,68,7,LEAVES:3)
Block(0,68,8,LEAVES:3)
Block(0,68,9,LEAVES:3)
Block(0,68,10,17:15)
Block(0,68,11,LEAVES:3)
Block(0,68,12,LEAVES:3)
Block(0,69,-4,LEAVES:3)
Block(0,69,-3,17:15)
Block(0,69,-2,LEAVES:3)
Block(0,69,1,17:15)
Block(0,69,8,LEAVES:3)
Block(0,69,10,LEAVES:3)
Block(0,69,11,LEAVES:3)
Block(0,70,-3,LEAVES:3)
Block(0,70,-2,LEAVES:3)
Block(0,70,1,17:15)
Block(0,71,1,17:15)
Block(0,72,1,17:15)
Block(0,73,1,17:15)
Block(0,74,1,17:15)
Block(0,75,1,17:15)
Block(0,76,-4,LEAVES:3)
Block(0,76,0,17:15)
Block(0,76,1,17:15)
Block(0,77,-6,LEAVES:3)
Block(0,77,-4,LEAVES:3)
Block(0,77,-3,17:15)
Block(0,77,-2,LEAVES:3)
Block(0,77,-1,17:15)
Block(0,77,0,17:15)
Block(0,77,1,17:15)
Block(0,77,2,17:15)
Block(0,77,3,LEAVES:3)
Block(0,77,5,LEAVES:3)
Block(0,78,-6,LEAVES:3)
Block(0,78,-5,LEAVES:3)
Block(0,78,-4,LEAVES:3)
Block(0,78,-3,LEAVES:3)
Block(0,78,-2,LEAVES:3)
Block(0,78,-1,LEAVES:3)
Block(0,78,0,LEAVES:3)
Block(0,78,1,LEAVES:3)
Block(0,78,2,LEAVES:3)
Block(0,78,3,17:15)
Block(0,78,4,LEAVES:3)
Block(0,78,5,LEAVES:3)
Block(0,78,6,LEAVES:3)
Block(0,79,-1,LEAVES:3)
Block(0,79,1,LEAVES:3)
Block(0,79,3,LEAVES:3)
Block(0,79,4,LEAVES:3)
Block(0,79,5,LEAVES:3)
Block(0,80,4,LEAVES:3)
Block(1,-5,2,17:15)
Block(1,-5,4,17:15)
Block(1,-4,-2,17:15)
Block(1,-4,1,17:15)
Block(1,-4,2,17:15)
Block(1,-3,-2,17:15)
Block(1,-3,1,17:15)
Block(1,-2,-2,17:15)
Block(1,-2,5,17:15)
Block(1,-1,4,17:15)
Block(1,-1,5,17:15)
Block(1,0,2,17:15)
Block(1,0,4,17:15)
Block(1,1,1,17:15)
Block(1,1,2,17:15)
Block(1,1,3,17:15)
Block(1,1,4,17:15)
Block(1,2,-1,17:15)
Block(1,2,0,17:15)
Block(1,2,1,17:15)
Block(1,2,2,17:15)
Block(1,2,3,17:15)
Block(1,2,4,17:15)
Block(1,3,-1,17:15)
Block(1,3,0,17:15)
Block(1,3,1,17:15)
Block(1,3,2,17:15)
Block(1,3,3,17:15)
Block(1,4,0,17:15)
Block(1,4,1,17:15)
Block(1,4,2,17:15)
Block(1,4,3,17:15)
Block(1,5,0,17:15)
Block(1,5,1,17:15)
Block(1,5,2,17:15)
Block(1,5,3,17:15)
Block(1,6,0,17:15)
Block(1,6,1,17:15)
Block(1,6,2,17:15)
Block(1,6,3,17:15)
Block(1,7,0,17:15)
Block(1,7,1,17:15)
Block(1,7,2,17:15)
Block(1,7,3,17:15)
Block(1,8,0,17:15)
Block(1,8,1,17:15)
Block(1,8,2,17:15)
Block(1,8,3,17:15)
Block(1,9,0,17:15)
Block(1,9,1,17:15)
Block(1,9,2,17:15)
Block(1,9,3,17:15)
Block(1,10,0,17:15)
Block(1,10,1,17:15)
Block(1,10,2,17:15)
Block(1,10,3,17:15)
Block(1,11,0,17:15)
Block(1,11,1,17:15)
Block(1,11,2,17:15)
Block(1,11,3,17:15)
Block(1,12,0,17:15)
Block(1,12,1,17:15)
Block(1,12,2,17:15)
Block(1,12,3,17:15)
Block(1,13,0,17:15)
Block(1,13,1,17:15)
Block(1,13,2,17:15)
Block(1,13,3,17:15)
Block(1,14,0,17:15)
Block(1,14,1,17:15)
Block(1,14,2,17:15)
Block(1,14,3,17:15)
Block(1,15,0,17:15)
Block(1,15,1,17:15)
Block(1,15,2,17:15)
Block(1,15,3,17:15)
Block(1,16,0,17:15)
Block(1,16,1,17:15)
Block(1,16,2,17:15)
Block(1,16,3,17:15)
Block(1,17,0,17:15)
Block(1,17,1,17:15)
Block(1,17,2,17:15)
Block(1,17,3,17:15)
Block(1,18,0,17:15)
Block(1,18,1,17:15)
Block(1,18,2,17:15)
Block(1,18,3,17:15)
Block(1,19,0,17:15)
Block(1,19,1,17:15)
Block(1,19,2,17:15)
Block(1,19,3,17:15)
Block(1,19,8,LEAVES:3)
Block(1,20,0,17:15)
Block(1,20,1,17:15)
Block(1,20,2,17:15)
Block(1,20,3,17:15)
Block(1,21,0,17:15)
Block(1,21,1,17:15)
Block(1,21,2,17:15)
Block(1,21,3,17:15)
Block(1,21,5,LEAVES:3)
Block(1,22,-3,LEAVES:3)
Block(1,22,0,17:15)
Block(1,22,1,17:15)
Block(1,22,3,17:15)
Block(1,23,-4,LEAVES:3)
Block(1,23,0,17:15)
Block(1,23,1,17:15)
Block(1,23,3,17:15)
Block(1,24,0,17:15)
Block(1,24,1,17:15)
Block(1,24,3,17:15)
Block(1,24,6,LEAVES:3)
Block(1,25,0,17:15)
Block(1,25,1,17:15)
Block(1,25,3,17:15)
Block(1,26,0,17:15)
Block(1,26,1,17:15)
Block(1,26,3,17:15)
Block(1,27,0,17:15)
Block(1,27,1,17:15)
Block(1,27,3,17:15)
Block(1,28,0,17:15)
Block(1,28,1,17:15)
Block(1,28,3,17:15)
Block(1,29,-3,17:15)
Block(1,29,-2,17:15)
Block(1,29,-1,17:15)
Block(1,29,0,17:15)
Block(1,29,1,17:15)
Block(1,29,3,17:15)
Block(1,30,-4,17:15)
Block(1,30,-3,17:15)
Block(1,30,-2,17:15)
Block(1,30,-1,17:15)
Block(1,30,0,17:15)
Block(1,30,1,17:15)
Block(1,30,3,17:15)
Block(1,31,-7,LEAVES:3)
Block(1,31,-6,LEAVES:3)
Block(1,31,-5,LEAVES:3)
Block(1,31,0,17:15)
Block(1,31,1,17:15)
Block(1,31,3,17:15)
Block(1,32,-16,LEAVES:3)
Block(1,32,-12,17:15)
Block(1,32,-11,17:15)
Block(1,32,-9,LEAVES:3)
Block(1,32,-8,LEAVES:3)
Block(1,32,-7,LEAVES:3)
Block(1,32,-6,LEAVES:3)
Block(1,32,0,17:15)
Block(1,32,1,17:15)
Block(1,32,3,17:15)
Block(1,33,-16,LEAVES:3)
Block(1,33,-15,LEAVES:3)
Block(1,33,-14,LEAVES:3)
Block(1,33,-13,LEAVES:3)
Block(1,33,-12,LEAVES:3)
Block(1,33,-11,LEAVES:3)
Block(1,33,-10,17:15)
Block(1,33,-9,LEAVES:3)
Block(1,33,-8,LEAVES:3)
Block(1,33,-7,LEAVES:3)
Block(1,33,-5,LEAVES:3)
Block(1,33,-1,LEAVES:3)
Block(1,33,0,17:15)
Block(1,33,1,17:15)
Block(1,33,3,17:15)
Block(1,34,-16,LEAVES:3)
Block(1,34,-15,LEAVES:3)
Block(1,34,-14,LEAVES:3)
Block(1,34,-12,LEAVES:3)
Block(1,34,-11,LEAVES:3)
Block(1,34,-10,LEAVES:3)
Block(1,34,-9,LEAVES:3)
Block(1,34,-4,LEAVES:3)
Block(1,34,-3,LEAVES:3)
Block(1,34,-2,LEAVES:3)
Block(1,34,0,17:15)
Block(1,34,1,17:15)
Block(1,34,3,17:15)
Block(1,35,-10,LEAVES:3)
Block(1,35,-3,LEAVES:3)
Block(1,35,0,17:15)
Block(1,35,1,17:15)
Block(1,35,3,17:15)
Block(1,36,0,17:15)
Block(1,36,1,17:15)
Block(1,36,3,17:15)
Block(1,37,0,17:15)
Block(1,37,1,17:15)
Block(1,37,3,17:15)
Block(1,37,5,17:15)
Block(1,38,0,17:15)
Block(1,38,1,17:15)
Block(1,38,3,17:15)
Block(1,38,5,LEAVES:3)
Block(1,38,6,LEAVES:3)
Block(1,39,0,17:15)
Block(1,39,1,17:15)
Block(1,39,3,17:15)
Block(1,39,5,LEAVES:3)
Block(1,39,9,17:15)
Block(1,39,10,LEAVES:3)
Block(1,40,0,17:15)
Block(1,40,1,17:15)
Block(1,40,3,17:15)
Block(1,40,9,LEAVES:3)
Block(1,41,-8,LEAVES:3)
Block(1,41,-7,LEAVES:3)
Block(1,41,-6,17:15)
Block(1,41,-4,LEAVES:3)
Block(1,41,-3,LEAVES:3)
Block(1,41,0,17:15)
Block(1,41,1,17:15)
Block(1,41,3,17:15)
Block(1,42,-6,LEAVES:3)
Block(1,42,0,17:15)
Block(1,42,1,17:15)
Block(1,42,3,17:15)
Block(1,43,0,17:15)
Block(1,43,1,17:15)
Block(1,43,3,17:15)
Block(1,44,0,17:15)
Block(1,44,1,17:15)
Block(1,44,3,17:15)
Block(1,45,0,17:15)
Block(1,45,1,17:15)
Block(1,45,3,17:15)
Block(1,46,0,17:15)
Block(1,46,1,17:15)
Block(1,46,3,17:15)
Block(1,46,4,17:15)
Block(1,46,7,17:15)
Block(1,46,8,17:15)
Block(1,47,0,17:15)
Block(1,47,1,17:15)
Block(1,47,3,17:15)
Block(1,47,4,LEAVES:3)
Block(1,47,7,17:15)
Block(1,47,8,17:15)
Block(1,47,12,LEAVES:3)
Block(1,47,13,LEAVES:3)
Block(1,47,15,LEAVES:3)
Block(1,48,0,17:15)
Block(1,48,1,17:15)
Block(1,48,2,17:15)
Block(1,48,3,17:15)
Block(1,48,5,LEAVES:3)
Block(1,48,6,LEAVES:3)
Block(1,48,7,LEAVES:3)
Block(1,48,8,LEAVES:3)
Block(1,48,9,LEAVES:3)
Block(1,48,10,LEAVES:3)
Block(1,48,11,LEAVES:3)
Block(1,48,12,LEAVES:3)
Block(1,48,14,LEAVES:3)
Block(1,48,15,LEAVES:3)
Block(1,48,16,LEAVES:3)
Block(1,49,0,17:15)
Block(1,49,1,17:15)
Block(1,49,2,17:15)
Block(1,49,3,17:15)
Block(1,49,6,LEAVES:3)
Block(1,49,8,LEAVES:3)
Block(1,49,10,LEAVES:3)
Block(1,49,11,LEAVES:3)
Block(1,49,12,LEAVES:3)
Block(1,49,15,LEAVES:3)
Block(1,49,16,LEAVES:3)
Block(1,49,17,LEAVES:3)
Block(1,49,18,LEAVES:3)
Block(1,50,0,17:15)
Block(1,50,1,17:15)
Block(1,50,2,17:15)
Block(1,50,3,17:15)
Block(1,50,13,LEAVES:3)
Block(1,50,14,LEAVES:3)
Block(1,50,17,LEAVES:3)
Block(1,51,0,17:15)
Block(1,51,1,17:15)
Block(1,51,2,17:15)
Block(1,51,3,17:15)
Block(1,52,-1,17:15)
Block(1,52,0,17:15)
Block(1,52,1,17:15)
Block(1,52,2,17:15)
Block(1,53,-5,LEAVES:3)
Block(1,53,-3,LEAVES:3)
Block(1,53,-2,17:15)
Block(1,53,0,17:15)
Block(1,53,1,17:15)
Block(1,53,2,17:15)
Block(1,53,3,17:15)
Block(1,54,-6,17:15)
Block(1,54,-5,17:15)
Block(1,54,0,17:15)
Block(1,54,1,17:15)
Block(1,54,2,17:15)
Block(1,54,3,17:15)
Block(1,55,-4,LEAVES:3)
Block(1,55,0,17:15)
Block(1,55,1,17:15)
Block(1,55,2,17:15)
Block(1,55,3,17:15)
Block(1,55,4,17:15)
Block(1,55,5,17:15)
Block(1,56,-12,LEAVES:3)
Block(1,56,-10,LEAVES:3)
Block(1,56,-9,LEAVES:3)
Block(1,56,-4,LEAVES:3)
Block(1,56,-3,LEAVES:3)
Block(1,56,0,17:15)
Block(1,56,1,17:15)
Block(1,56,2,17:15)
Block(1,56,5,17:15)
Block(1,57,-19,LEAVES:3)
Block(1,57,-15,LEAVES:3)
Block(1,57,-14,LEAVES:3)
Block(1,57,-13,LEAVES:3)
Block(1,57,-12,17:15)
Block(1,57,-10,LEAVES:3)
Block(1,57,-6,LEAVES:3)
Block(1,57,-5,LEAVES:3)
Block(1,57,-4,17:15)
Block(1,57,-3,LEAVES:3)
Block(1,57,0,17:15)
Block(1,57,1,17:15)
Block(1,57,2,17:15)
Block(1,58,-21,LEAVES:3)
Block(1,58,-20,LEAVES:3)
Block(1,58,-19,LEAVES:3)
Block(1,58,-16,LEAVES:3)
Block(1,58,-14,LEAVES:3)
Block(1,58,-13,LEAVES:3)
Block(1,58,-11,LEAVES:3)
Block(1,58,-5,LEAVES:3)
Block(1,58,-4,LEAVES:3)
Block(1,58,0,17:15)
Block(1,58,1,17:15)
Block(1,58,2,17:15)
Block(1,59,-20,LEAVES:3)
Block(1,59,-13,LEAVES:3)
Block(1,59,-4,LEAVES:3)
Block(1,59,0,17:15)
Block(1,59,1,17:15)
Block(1,59,2,17:15)
Block(1,60,0,17:15)
Block(1,60,1,17:15)
Block(1,60,2,17:15)
Block(1,61,0,17:15)
Block(1,61,1,17:15)
Block(1,61,2,17:15)
Block(1,62,1,17:15)
Block(1,62,2,17:15)
Block(1,63,1,17:15)
Block(1,63,2,17:15)
Block(1,64,1,17:15)
Block(1,64,2,17:15)
Block(1,65,1,17:15)
Block(1,65,2,17:15)
Block(1,66,1,17:15)
Block(1,66,2,17:15)
Block(1,67,-1,17:15)
Block(1,67,1,17:15)
Block(1,67,2,17:15)
Block(1,67,9,LEAVES:3)
Block(1,67,12,LEAVES:3)
Block(1,68,-3,17:15)
Block(1,68,-2,17:15)
Block(1,68,-1,17:15)
Block(1,68,2,17:15)
Block(1,68,8,LEAVES:3)
Block(1,68,9,LEAVES:3)
Block(1,68,10,LEAVES:3)
Block(1,68,11,LEAVES:3)
Block(1,69,-3,17:15)
Block(1,69,-2,17:15)
Block(1,69,-1,LEAVES:3)
Block(1,69,2,17:15)
Block(1,69,10,LEAVES:3)
Block(1,70,-4,LEAVES:3)
Block(1,70,-3,LEAVES:3)
Block(1,70,-2,LEAVES:3)
Block(1,70,2,17:15)
Block(1,71,-6,LEAVES:3)
Block(1,71,-3,LEAVES:3)
Block(1,71,-2,LEAVES:3)
Block(1,71,2,17:15)
Block(1,72,2,17:15)
Block(1,73,2,17:15)
Block(1,74,1,17:15)
Block(1,74,2,17:15)
Block(1,75,-1,LEAVES:3)
Block(1,75,0,17:15)
Block(1,75,1,17:15)
Block(1,75,2,17:15)
Block(1,76,-6,LEAVES:3)
Block(1,76,0,LEAVES:3)
Block(1,76,2,17:15)
Block(1,77,-7,LEAVES:3)
Block(1,77,-4,LEAVES:3)
Block(1,77,-3,LEAVES:3)
Block(1,77,-2,LEAVES:3)
Block(1,77,-1,LEAVES:3)
Block(1,77,0,LEAVES:3)
Block(1,77,1,LEAVES:3)
Block(1,77,2,17:15)
Block(1,78,-7,LEAVES:3)
Block(1,78,-6,LEAVES:3)
Block(1,78,-5,LEAVES:3)
Block(1,78,-4,17:15)
Block(1,78,-3,LEAVES:3)
Block(1,78,-1,LEAVES:3)
Block(1,78,1,LEAVES:3)
Block(1,78,2,LEAVES:3)
Block(1,78,3,17:15)
Block(1,78,4,LEAVES:3)
Block(1,78,7,LEAVES:3)
Block(1,79,-6,LEAVES:3)
Block(1,79,-5,LEAVES:3)
Block(1,79,-4,LEAVES:3)
Block(1,79,-3,LEAVES:3)
Block(1,79,2,LEAVES:3)
Block(1,79,3,LEAVES:3)
Block(1,79,4,LEAVES:3)
Block(1,79,5,LEAVES:3)
Block(1,79,6,LEAVES:3)
Block(1,79,7,LEAVES:3)
Block(1,80,-4,LEAVES:3)
Block(1,80,2,17:15)
Block(1,80,3,LEAVES:3)
Block(1,80,5,LEAVES:3)
Block(2,-5,-3,17:15)
Block(2,-5,-2,17:15)
Block(2,-5,6,17:15)
Block(2,-4,-3,17:15)
Block(2,-4,6,17:15)
Block(2,-3,-3,17:15)
Block(2,-3,1,17:15)
Block(2,-3,5,17:15)
Block(2,-3,6,17:15)
Block(2,-2,1,17:15)
Block(2,-2,3,17:15)
Block(2,-2,5,17:15)
Block(2,-1,-3,17:15)
Block(2,-1,3,17:15)
Block(2,0,-3,17:15)
Block(2,0,-2,17:15)
Block(2,0,0,17:15)
Block(2,0,2,17:15)
Block(2,0,3,17:15)
Block(2,1,-2,17:15)
Block(2,1,0,17:15)
Block(2,1,1,17:15)
Block(2,1,2,17:15)
Block(2,1,3,17:15)
Block(2,2,-2,17:15)
Block(2,2,-1,17:15)
Block(2,2,0,17:15)
Block(2,2,1,17:15)
Block(2,2,2,17:15)
Block(2,2,3,17:15)
Block(2,3,0,17:15)
Block(2,3,1,17:15)
Block(2,3,2,17:15)
Block(2,3,3,17:15)
Block(2,4,0,17:15)
Block(2,4,1,17:15)
Block(2,4,2,17:15)
Block(2,4,3,17:15)
Block(2,5,0,17:15)
Block(2,5,1,17:15)
Block(2,5,2,17:15)
Block(2,5,3,17:15)
Block(2,6,0,17:15)
Block(2,6,1,17:15)
Block(2,6,2,17:15)
Block(2,6,3,17:15)
Block(2,7,0,17:15)
Block(2,7,1,17:15)
Block(2,7,2,17:15)
Block(2,7,3,17:15)
Block(2,8,0,17:15)
Block(2,8,1,17:15)
Block(2,8,2,17:15)
Block(2,8,3,17:15)
Block(2,9,0,17:15)
Block(2,9,1,17:15)
Block(2,9,2,17:15)
Block(2,9,3,17:15)
Block(2,10,0,17:15)
Block(2,10,1,17:15)
Block(2,10,2,17:15)
Block(2,10,3,17:15)
Block(2,11,0,17:15)
Block(2,11,1,17:15)
Block(2,11,2,17:15)
Block(2,11,3,17:15)
Block(2,12,0,17:15)
Block(2,12,1,17:15)
Block(2,12,2,17:15)
Block(2,12,3,17:15)
Block(2,13,0,17:15)
Block(2,13,1,17:15)
Block(2,13,2,17:15)
Block(2,13,3,17:15)
Block(2,14,0,17:15)
Block(2,14,1,17:15)
Block(2,14,2,17:15)
Block(2,14,3,17:15)
Block(2,15,0,17:15)
Block(2,15,1,17:15)
Block(2,15,2,17:15)
Block(2,15,3,17:15)
Block(2,16,0,17:15)
Block(2,16,1,17:15)
Block(2,16,2,17:15)
Block(2,16,3,17:15)
Block(2,17,0,17:15)
Block(2,17,1,17:15)
Block(2,17,2,17:15)
Block(2,17,3,17:15)
Block(2,18,0,17:15)
Block(2,18,1,17:15)
Block(2,18,2,17:15)
Block(2,18,3,17:15)
Block(2,19,0,17:15)
Block(2,19,1,17:15)
Block(2,19,2,17:15)
Block(2,19,3,17:15)
Block(2,19,8,LEAVES:3)
Block(2,20,0,17:15)
Block(2,20,1,17:15)
Block(2,20,2,17:15)
Block(2,20,3,17:15)
Block(2,20,8,LEAVES:3)
Block(2,20,9,17:15)
Block(2,20,10,LEAVES:3)
Block(2,21,1,17:15)
Block(2,21,2,17:15)
Block(2,21,5,17:15)
Block(2,21,6,LEAVES:3)
Block(2,22,1,17:15)
Block(2,22,2,17:15)
Block(2,23,1,17:15)
Block(2,23,2,17:15)
Block(2,24,1,17:15)
Block(2,24,2,17:15)
Block(2,25,1,17:15)
Block(2,25,2,17:15)
Block(2,26,1,17:15)
Block(2,26,2,17:15)
Block(2,27,1,17:15)
Block(2,27,2,17:15)
Block(2,28,1,17:15)
Block(2,28,2,17:15)
Block(2,29,-4,17:15)
Block(2,29,1,17:15)
Block(2,29,2,17:15)
Block(2,30,-7,LEAVES:3)
Block(2,30,-5,17:15)
Block(2,30,-4,17:15)
Block(2,30,1,17:15)
Block(2,30,2,17:15)
Block(2,31,-8,17:15)
Block(2,31,-6,LEAVES:3)
Block(2,31,1,17:15)
Block(2,31,2,17:15)
Block(2,32,-14,LEAVES:3)
Block(2,32,-13,LEAVES:3)
Block(2,32,-11,17:15)
Block(2,32,-10,17:15)
Block(2,32,-9,17:15)
Block(2,32,-8,17:15)
Block(2,32,-7,LEAVES:3)
Block(2,32,-4,LEAVES:3)
Block(2,32,1,17:15)
Block(2,32,2,17:15)
Block(2,33,-15,LEAVES:3)
Block(2,33,-14,LEAVES:3)
Block(2,33,-13,LEAVES:3)
Block(2,33,-12,LEAVES:3)
Block(2,33,-11,LEAVES:3)
Block(2,33,-10,LEAVES:3)
Block(2,33,-9,LEAVES:3)
Block(2,33,-8,LEAVES:3)
Block(2,33,-7,LEAVES:3)
Block(2,33,-6,LEAVES:3)
Block(2,33,-5,LEAVES:3)
Block(2,33,-4,LEAVES:3)
Block(2,33,-3,LEAVES:3)
Block(2,33,1,17:15)
Block(2,33,2,17:15)
Block(2,34,-14,LEAVES:3)
Block(2,34,-11,LEAVES:3)
Block(2,34,-8,LEAVES:3)
Block(2,34,-5,LEAVES:3)
Block(2,34,-4,LEAVES:3)
Block(2,34,-3,17:15)
Block(2,34,-2,LEAVES:3)
Block(2,34,-1,LEAVES:3)
Block(2,34,1,17:15)
Block(2,34,2,17:15)
Block(2,35,-4,LEAVES:3)
Block(2,35,-3,LEAVES:3)
Block(2,35,-2,LEAVES:3)
Block(2,35,1,17:15)
Block(2,35,2,17:15)
Block(2,36,1,17:15)
Block(2,36,2,17:15)
Block(2,37,1,17:15)
Block(2,37,2,17:15)
Block(2,37,6,17:15)
Block(2,37,7,LEAVES:3)
Block(2,38,1,17:15)
Block(2,38,2,17:15)
Block(2,39,1,17:15)
Block(2,39,2,17:15)
Block(2,39,9,LEAVES:3)
Block(2,40,1,17:15)
Block(2,40,2,17:15)
Block(2,41,-6,LEAVES:3)
Block(2,41,-4,LEAVES:3)
Block(2,41,1,17:15)
Block(2,41,2,17:15)
Block(2,42,1,17:15)
Block(2,42,2,17:15)
Block(2,43,1,17:15)
Block(2,43,2,17:15)
Block(2,44,1,17:15)
Block(2,44,2,17:15)
Block(2,45,1,17:15)
Block(2,45,2,17:15)
Block(2,46,1,17:15)
Block(2,46,2,17:15)
Block(2,46,9,17:15)
Block(2,47,1,17:15)
Block(2,47,2,17:15)
Block(2,47,8,17:15)
Block(2,47,10,LEAVES:3)
Block(2,48,1,17:15)
Block(2,48,2,17:15)
Block(2,48,5,LEAVES:3)
Block(2,48,6,LEAVES:3)
Block(2,48,8,LEAVES:3)
Block(2,48,9,17:15)
Block(2,48,10,17:15)
Block(2,48,11,LEAVES:3)
Block(2,48,12,LEAVES:3)
Block(2,48,14,LEAVES:3)
Block(2,48,15,17:15)
Block(2,48,17,LEAVES:3)
Block(2,48,19,LEAVES:3)
Block(2,49,1,17:15)
Block(2,49,2,17:15)
Block(2,49,9,LEAVES:3)
Block(2,49,10,LEAVES:3)
Block(2,49,11,LEAVES:3)
Block(2,49,12,LEAVES:3)
Block(2,49,13,LEAVES:3)
Block(2,49,14,LEAVES:3)
Block(2,49,15,LEAVES:3)
Block(2,49,16,17:15)
Block(2,49,17,LEAVES:3)
Block(2,49,18,LEAVES:3)
Block(2,49,19,LEAVES:3)
Block(2,50,1,17:15)
Block(2,50,2,17:15)
Block(2,50,10,LEAVES:3)
Block(2,50,12,LEAVES:3)
Block(2,50,15,LEAVES:3)
Block(2,50,16,LEAVES:3)
Block(2,50,17,LEAVES:3)
Block(2,50,18,LEAVES:3)
Block(2,51,1,17:15)
Block(2,51,2,17:15)
Block(2,51,16,LEAVES:3)
Block(2,52,-3,17:15)
Block(2,52,-2,17:15)
Block(2,52,-1,17:15)
Block(2,52,1,17:15)
Block(2,52,2,17:15)
Block(2,53,-5,17:15)
Block(2,53,-4,17:15)
Block(2,53,-3,17:15)
Block(2,53,-2,17:15)
Block(2,53,1,17:15)
Block(2,53,2,17:15)
Block(2,54,-5,17:15)
Block(2,54,-4,17:15)
Block(2,54,1,17:15)
Block(2,54,2,17:15)
Block(2,55,-12,LEAVES:3)
Block(2,55,-9,LEAVES:3)
Block(2,55,-8,LEAVES:3)
Block(2,55,-7,LEAVES:3)
Block(2,55,-2,LEAVES:3)
Block(2,55,1,17:15)
Block(2,55,2,17:15)
Block(2,55,3,17:15)
Block(2,56,-11,LEAVES:3)
Block(2,56,-10,17:15)
Block(2,56,-9,LEAVES:3)
Block(2,56,-8,LEAVES:3)
Block(2,56,-6,LEAVES:3)
Block(2,56,-3,LEAVES:3)
Block(2,56,1,17:15)
Block(2,56,2,17:15)
Block(2,56,6,17:15)
Block(2,57,-21,LEAVES:3)
Block(2,57,-20,LEAVES:3)
Block(2,57,-18,LEAVES:3)
Block(2,57,-17,LEAVES:3)
Block(2,57,-14,LEAVES:3)
Block(2,57,-13,LEAVES:3)
Block(2,57,-12,LEAVES:3)
Block(2,57,-11,17:15)
Block(2,57,-10,LEAVES:3)
Block(2,57,-9,LEAVES:3)
Block(2,57,-5,LEAVES:3)
Block(2,57,-4,17:15)
Block(2,57,-3,LEAVES:3)
Block(2,57,-2,LEAVES:3)
Block(2,57,1,17:15)
Block(2,57,2,17:15)
Block(2,57,8,LEAVES:3)
Block(2,58,-22,LEAVES:3)
Block(2,58,-21,LEAVES:3)
Block(2,58,-20,17:15)
Block(2,58,-19,LEAVES:3)
Block(2,58,-18,LEAVES:3)
Block(2,58,-17,LEAVES:3)
Block(2,58,-16,LEAVES:3)
Block(2,58,-15,LEAVES:3)
Block(2,58,-13,LEAVES:3)
Block(2,58,-12,LEAVES:3)
Block(2,58,-11,LEAVES:3)
Block(2,58,-10,LEAVES:3)
Block(2,58,-4,LEAVES:3)
Block(2,58,-3,LEAVES:3)
Block(2,58,1,17:15)
Block(2,58,2,17:15)
Block(2,59,-21,LEAVES:3)
Block(2,59,-20,LEAVES:3)
Block(2,59,-16,LEAVES:3)
Block(2,59,-11,LEAVES:3)
Block(2,59,1,17:15)
Block(2,59,2,17:15)
Block(2,60,1,17:15)
Block(2,60,2,17:15)
Block(2,61,1,17:15)
Block(2,61,2,17:15)
Block(2,62,1,17:15)
Block(2,62,2,17:15)
Block(2,63,1,17:15)
Block(2,63,2,17:15)
Block(2,64,1,17:15)
Block(2,64,2,17:15)
Block(2,65,1,17:15)
Block(2,65,2,17:15)
Block(2,66,0,17:15)
Block(2,66,1,17:15)
Block(2,66,2,17:15)
Block(2,67,0,17:15)
Block(2,67,2,17:15)
Block(2,67,10,LEAVES:3)
Block(2,68,-3,LEAVES:3)
Block(2,68,2,17:15)
Block(2,68,10,LEAVES:3)
Block(2,69,-4,LEAVES:3)
Block(2,69,-3,17:15)
Block(2,69,-1,LEAVES:3)
Block(2,69,2,17:15)
Block(2,70,-5,LEAVES:3)
Block(2,70,-4,LEAVES:3)
Block(2,70,-3,LEAVES:3)
Block(2,70,-2,17:15)
Block(2,70,-1,17:15)
Block(2,70,0,LEAVES:3)
Block(2,70,2,17:15)
Block(2,71,-7,LEAVES:3)
Block(2,71,-6,LEAVES:3)
Block(2,71,-5,LEAVES:3)
Block(2,71,-4,LEAVES:3)
Block(2,71,-2,LEAVES:3)
Block(2,71,-1,LEAVES:3)
Block(2,72,-6,LEAVES:3)
Block(2,72,-2,LEAVES:3)
Block(2,74,2,LEAVES:3)
Block(2,75,-2,LEAVES:3)
Block(2,75,-1,17:15)
Block(2,75,0,17:15)
Block(2,75,1,LEAVES:3)
Block(2,76,-2,LEAVES:3)
Block(2,76,-1,17:15)
Block(2,76,0,LEAVES:3)
Block(2,77,-6,LEAVES:3)
Block(2,77,-2,LEAVES:3)
Block(2,77,-1,LEAVES:3)
Block(2,77,0,LEAVES:3)
Block(2,77,4,LEAVES:3)
Block(2,78,-6,LEAVES:3)
Block(2,78,-5,LEAVES:3)
Block(2,78,-4,LEAVES:3)
Block(2,78,-3,LEAVES:3)
Block(2,78,-1,LEAVES:3)
Block(2,78,1,LEAVES:3)
Block(2,78,2,LEAVES:3)
Block(2,78,3,LEAVES:3)
Block(2,78,4,17:15)
Block(2,78,6,LEAVES:3)
Block(2,79,-4,LEAVES:3)
Block(2,79,2,LEAVES:3)
Block(2,79,3,LEAVES:3)
Block(2,79,4,LEAVES:3)
Block(2,79,5,17:15)
Block(2,79,6,LEAVES:3)
Block(2,79,7,LEAVES:3)
Block(2,79,8,LEAVES:3)
Block(2,80,4,LEAVES:3)
Block(2,80,5,LEAVES:3)
Block(2,80,6,LEAVES:3)
Block(2,80,7,LEAVES:3)
Block(2,81,5,LEAVES:3)
Block(3,-5,-2,17:15)
Block(3,-5,6,17:15)
Block(3,-4,-2,17:15)
Block(3,-3,-2,17:15)
Block(3,-3,3,17:15)
Block(3,-2,-3,17:15)
Block(3,-2,-2,17:15)
Block(3,-2,-1,17:15)
Block(3,-2,1,17:15)
Block(3,-2,3,17:15)
Block(3,-1,-3,17:15)
Block(3,-1,-1,17:15)
Block(3,-1,1,17:15)
Block(3,0,-1,17:15)
Block(3,0,0,17:15)
Block(3,0,1,17:15)
Block(3,1,0,17:15)
Block(3,1,1,17:15)
Block(3,2,0,17:15)
Block(3,2,1,17:15)
Block(3,3,0,17:15)
Block(3,3,1,17:15)
Block(3,4,1,17:15)
Block(3,5,1,17:15)
Block(3,6,1,17:15)
Block(3,7,1,17:15)
Block(3,8,1,17:15)
Block(3,9,1,17:15)
Block(3,10,1,17:15)
Block(3,11,1,17:15)
Block(3,12,1,17:15)
Block(3,13,1,17:15)
Block(3,14,1,17:15)
Block(3,14,2,17:15)
Block(3,15,1,17:15)
Block(3,15,2,17:15)
Block(3,16,1,17:15)
Block(3,16,2,17:15)
Block(3,17,1,17:15)
Block(3,17,2,17:15)
Block(3,18,1,17:15)
Block(3,18,2,17:15)
Block(3,19,1,17:15)
Block(3,19,7,17:15)
Block(3,19,8,17:15)
Block(3,20,1,17:15)
Block(3,20,5,17:15)
Block(3,21,1,17:15)
Block(3,22,1,17:15)
Block(3,23,1,17:15)
Block(3,24,1,17:15)
Block(3,25,1,17:15)
Block(3,26,1,17:15)
Block(3,27,1,17:15)
Block(3,28,1,17:15)
Block(3,29,1,17:15)
Block(3,30,-5,17:15)
Block(3,30,1,17:15)
Block(3,31,-7,17:15)
Block(3,31,-6,17:15)
Block(3,31,-5,17:15)
Block(3,31,-4,LEAVES:3)
Block(3,31,1,17:15)
Block(3,32,-15,LEAVES:3)
Block(3,32,-12,LEAVES:3)
Block(3,32,-10,LEAVES:3)
Block(3,32,-9,LEAVES:3)
Block(3,32,-8,LEAVES:3)
Block(3,32,-6,LEAVES:3)
Block(3,32,1,17:15)
Block(3,33,-14,LEAVES:3)
Block(3,33,-11,LEAVES:3)
Block(3,33,-9,LEAVES:3)
Block(3,33,-8,LEAVES:3)
Block(3,33,-7,LEAVES:3)
Block(3,33,-6,LEAVES:3)
Block(3,33,-5,LEAVES:3)
Block(3,33,-2,LEAVES:3)
Block(3,33,1,17:15)
Block(3,34,-6,LEAVES:3)
Block(3,34,-5,LEAVES:3)
Block(3,34,-4,17:15)
Block(3,34,-3,LEAVES:3)
Block(3,34,-2,LEAVES:3)
Block(3,34,1,17:15)
Block(3,35,-4,LEAVES:3)
Block(3,35,1,17:15)
Block(3,36,-4,LEAVES:3)
Block(3,36,1,17:15)
Block(3,38,-6,LEAVES:3)
Block(3,38,6,17:15)
Block(3,39,-5,LEAVES:3)
Block(3,40,4,LEAVES:3)
Block(3,41,5,LEAVES:3)
Block(3,46,5,LEAVES:3)
Block(3,47,7,17:15)
Block(3,47,8,17:15)
Block(3,47,11,LEAVES:3)
Block(3,47,12,17:15)
Block(3,47,13,17:15)
Block(3,48,4,LEAVES:3)
Block(3,48,5,LEAVES:3)
Block(3,48,6,17:15)
Block(3,48,7,LEAVES:3)
Block(3,48,8,LEAVES:3)
Block(3,48,9,LEAVES:3)
Block(3,48,10,LEAVES:3)
Block(3,48,11,17:15)
Block(3,48,13,LEAVES:3)
Block(3,48,14,17:15)
Block(3,48,15,LEAVES:3)
Block(3,49,5,LEAVES:3)
Block(3,49,6,LEAVES:3)
Block(3,49,7,LEAVES:3)
Block(3,49,9,LEAVES:3)
Block(3,49,10,LEAVES:3)
Block(3,49,11,LEAVES:3)
Block(3,49,12,17:15)
Block(3,49,13,LEAVES:3)
Block(3,49,14,LEAVES:3)
Block(3,49,15,LEAVES:3)
Block(3,49,16,LEAVES:3)
Block(3,49,17,LEAVES:3)
Block(3,49,18,LEAVES:3)
Block(3,50,6,LEAVES:3)
Block(3,50,11,LEAVES:3)
Block(3,50,12,LEAVES:3)
Block(3,50,13,LEAVES:3)
Block(3,50,14,LEAVES:3)
Block(3,50,16,LEAVES:3)
Block(3,51,12,LEAVES:3)
Block(3,53,-4,17:15)
Block(3,53,-3,17:15)
Block(3,54,-4,17:15)
Block(3,55,-9,LEAVES:3)
Block(3,55,-8,LEAVES:3)
Block(3,55,-7,LEAVES:3)
Block(3,55,2,17:15)
Block(3,56,-21,LEAVES:3)
Block(3,56,-14,LEAVES:3)
Block(3,56,-10,17:15)
Block(3,56,-8,LEAVES:3)
Block(3,56,-7,LEAVES:3)
Block(3,56,-2,LEAVES:3)
Block(3,56,2,17:15)
Block(3,56,7,17:15)
Block(3,57,-22,LEAVES:3)
Block(3,57,-19,LEAVES:3)
Block(3,57,-16,LEAVES:3)
Block(3,57,-15,LEAVES:3)
Block(3,57,-12,LEAVES:3)
Block(3,57,-11,LEAVES:3)
Block(3,57,-10,LEAVES:3)
Block(3,57,-8,LEAVES:3)
Block(3,57,-5,LEAVES:3)
Block(3,57,-4,LEAVES:3)
Block(3,57,-3,LEAVES:3)
Block(3,57,8,17:15)
Block(3,57,9,LEAVES:3)
Block(3,57,10,LEAVES:3)
Block(3,58,-21,LEAVES:3)
Block(3,58,-20,LEAVES:3)
Block(3,58,-19,LEAVES:3)
Block(3,58,-18,LEAVES:3)
Block(3,58,-17,LEAVES:3)
Block(3,58,-16,17:15)
Block(3,58,-15,LEAVES:3)
Block(3,58,-11,LEAVES:3)
Block(3,58,-9,LEAVES:3)
Block(3,58,-4,LEAVES:3)
Block(3,58,5,17:15)
Block(3,58,6,LEAVES:3)
Block(3,58,9,LEAVES:3)
Block(3,59,-19,17:15)
Block(3,59,-18,LEAVES:3)
Block(3,59,-16,LEAVES:3)
Block(3,59,5,LEAVES:3)
Block(3,60,-19,LEAVES:3)
Block(3,69,-4,17:15)
Block(3,69,-2,LEAVES:3)
Block(3,69,1,LEAVES:3)
Block(3,70,-6,LEAVES:3)
Block(3,70,-5,LEAVES:3)
Block(3,70,-4,17:15)
Block(3,70,-3,LEAVES:3)
Block(3,70,-2,LEAVES:3)
Block(3,70,-1,LEAVES:3)
Block(3,70,0,17:15)
Block(3,70,1,LEAVES:3)
Block(3,71,-8,LEAVES:3)
Block(3,71,-7,LEAVES:3)
Block(3,71,-6,LEAVES:3)
Block(3,71,-4,LEAVES:3)
Block(3,71,-3,LEAVES:3)
Block(3,71,-2,LEAVES:3)
Block(3,71,-1,LEAVES:3)
Block(3,71,0,LEAVES:3)
Block(3,72,-7,LEAVES:3)
Block(3,72,-6,LEAVES:3)
Block(3,72,-3,LEAVES:3)
Block(3,74,1,LEAVES:3)
Block(3,75,-5,LEAVES:3)
Block(3,75,0,LEAVES:3)
Block(3,75,1,17:15)
Block(3,75,2,LEAVES:3)
Block(3,76,-5,LEAVES:3)
Block(3,76,-4,LEAVES:3)
Block(3,76,-3,LEAVES:3)
Block(3,76,-2,17:15)
Block(3,76,-1,17:15)
Block(3,77,-4,LEAVES:3)
Block(3,77,-2,LEAVES:3)
Block(3,77,-1,LEAVES:3)
Block(3,77,1,LEAVES:3)
Block(3,77,3,LEAVES:3)
Block(3,78,-4,LEAVES:3)
Block(3,78,2,LEAVES:3)
Block(3,78,4,LEAVES:3)
Block(3,78,5,LEAVES:3)
Block(3,78,8,LEAVES:3)
Block(3,79,4,LEAVES:3)
Block(3,79,5,LEAVES:3)
Block(3,79,6,LEAVES:3)
Block(3,79,7,LEAVES:3)
Block(3,80,6,LEAVES:3)
Block(4,-5,4,17:15)
Block(4,-4,4,17:15)
Block(4,-3,0,17:15)
Block(4,-3,4,17:15)
Block(4,-2,-1,17:15)
Block(4,-2,0,17:15)
Block(4,-1,0,17:15)
Block(4,18,2,17:15)
Block(4,18,3,17:15)
Block(4,19,3,17:15)
Block(4,19,6,17:15)
Block(4,20,3,LEAVES:3)
Block(4,20,4,17:15)
Block(4,21,3,LEAVES:3)
Block(4,30,-4,17:15)
Block(4,30,-2,LEAVES:3)
Block(4,31,-7,17:15)
Block(4,31,-6,17:15)
Block(4,31,-3,LEAVES:3)
Block(4,31,-2,LEAVES:3)
Block(4,32,-15,LEAVES:3)
Block(4,32,-11,LEAVES:3)
Block(4,32,-9,LEAVES:3)
Block(4,32,-8,LEAVES:3)
Block(4,32,-6,17:15)
Block(4,32,-5,LEAVES:3)
Block(4,32,-3,LEAVES:3)
Block(4,33,-14,LEAVES:3)
Block(4,33,-13,LEAVES:3)
Block(4,33,-12,LEAVES:3)
Block(4,33,-11,LEAVES:3)
Block(4,33,-6,LEAVES:3)
Block(4,33,-5,17:15)
Block(4,33,-3,LEAVES:3)
Block(4,34,-13,LEAVES:3)
Block(4,34,-5,LEAVES:3)
Block(4,34,-4,LEAVES:3)
Block(4,35,-5,LEAVES:3)
Block(4,36,0,17:15)
Block(4,36,1,17:15)
Block(4,38,-4,LEAVES:3)
Block(4,38,6,LEAVES:3)
Block(4,39,-6,LEAVES:3)
Block(4,39,-5,LEAVES:3)
Block(4,39,-4,LEAVES:3)
Block(4,39,6,LEAVES:3)
Block(4,40,-5,LEAVES:3)
Block(4,40,6,LEAVES:3)
Block(4,41,4,LEAVES:3)
Block(4,41,5,LEAVES:3)
Block(4,41,6,LEAVES:3)
Block(4,42,5,LEAVES:3)
Block(4,46,7,LEAVES:3)
Block(4,47,4,LEAVES:3)
Block(4,47,6,LEAVES:3)
Block(4,47,7,17:15)
Block(4,47,8,LEAVES:3)
Block(4,47,14,LEAVES:3)
Block(4,48,4,LEAVES:3)
Block(4,48,5,LEAVES:3)
Block(4,48,6,LEAVES:3)
Block(4,48,7,LEAVES:3)
Block(4,48,9,LEAVES:3)
Block(4,48,10,LEAVES:3)
Block(4,48,11,LEAVES:3)
Block(4,48,12,LEAVES:3)
Block(4,48,13,LEAVES:3)
Block(4,48,14,17:15)
Block(4,48,15,LEAVES:3)
Block(4,48,16,LEAVES:3)
Block(4,48,17,LEAVES:3)
Block(4,49,6,LEAVES:3)
Block(4,49,11,LEAVES:3)
Block(4,49,12,LEAVES:3)
Block(4,49,13,LEAVES:3)
Block(4,49,14,LEAVES:3)
Block(4,50,13,LEAVES:3)
Block(4,54,-6,17:15)
Block(4,54,-5,17:15)
Block(4,54,-4,17:15)
Block(4,55,-12,LEAVES:3)
Block(4,55,-10,17:15)
Block(4,55,-9,17:15)
Block(4,55,-8,17:15)
Block(4,55,-7,17:15)
Block(4,55,-6,17:15)
Block(4,56,-17,LEAVES:3)
Block(4,56,-15,LEAVES:3)
Block(4,56,-13,17:15)
Block(4,56,-12,17:15)
Block(4,56,-11,17:15)
Block(4,56,-10,17:15)
Block(4,56,-9,LEAVES:3)
Block(4,56,-7,LEAVES:3)
Block(4,56,-4,LEAVES:3)
Block(4,56,-3,LEAVES:3)
Block(4,56,1,LEAVES:3)
Block(4,56,2,17:15)
Block(4,56,3,17:15)
Block(4,56,7,LEAVES:3)
Block(4,57,-20,LEAVES:3)
Block(4,57,-18,LEAVES:3)
Block(4,57,-17,17:15)
Block(4,57,-16,17:15)
Block(4,57,-15,LEAVES:3)
Block(4,57,-14,LEAVES:3)
Block(4,57,-13,LEAVES:3)
Block(4,57,-12,17:15)
Block(4,57,-4,LEAVES:3)
Block(4,57,2,LEAVES:3)
Block(4,57,4,17:15)
Block(4,57,5,LEAVES:3)
Block(4,57,7,LEAVES:3)
Block(4,58,-21,LEAVES:3)
Block(4,58,-20,LEAVES:3)
Block(4,58,-19,LEAVES:3)
Block(4,58,-18,17:15)
Block(4,58,-17,LEAVES:3)
Block(4,58,-16,LEAVES:3)
Block(4,58,-15,LEAVES:3)
Block(4,58,-12,LEAVES:3)
Block(4,58,-10,LEAVES:3)
Block(4,58,-9,LEAVES:3)
Block(4,58,-8,LEAVES:3)
Block(4,59,-20,LEAVES:3)
Block(4,59,-19,LEAVES:3)
Block(4,59,-18,LEAVES:3)
Block(4,59,-17,LEAVES:3)
Block(4,59,-9,LEAVES:3)
Block(4,60,-19,LEAVES:3)
Block(4,69,-5,LEAVES:3)
Block(4,69,-3,LEAVES:3)
Block(4,69,0,LEAVES:3)
Block(4,70,-8,LEAVES:3)
Block(4,70,-7,LEAVES:3)
Block(4,70,-5,17:15)
Block(4,70,-3,LEAVES:3)
Block(4,70,-2,LEAVES:3)
Block(4,70,-1,LEAVES:3)
Block(4,70,0,17:15)
Block(4,70,1,LEAVES:3)
Block(4,71,-8,LEAVES:3)
Block(4,71,-7,LEAVES:3)
Block(4,71,-6,17:15)
Block(4,71,-5,LEAVES:3)
Block(4,71,-3,LEAVES:3)
Block(4,71,0,LEAVES:3)
Block(4,71,1,LEAVES:3)
Block(4,72,-6,LEAVES:3)
Block(4,72,-5,LEAVES:3)
Block(4,73,-6,LEAVES:3)
Block(4,74,3,LEAVES:3)
Block(4,75,-3,LEAVES:3)
Block(4,75,1,17:15)
Block(4,75,2,LEAVES:3)
Block(4,75,3,LEAVES:3)
Block(4,76,-6,LEAVES:3)
Block(4,76,-5,LEAVES:3)
Block(4,76,-4,LEAVES:3)
Block(4,76,-3,17:15)
Block(4,76,-2,LEAVES:3)
Block(4,76,-1,LEAVES:3)
Block(4,76,0,LEAVES:3)
Block(4,76,1,LEAVES:3)
Block(4,76,2,LEAVES:3)
Block(4,77,-5,LEAVES:3)
Block(4,77,-4,LEAVES:3)
Block(4,77,-3,LEAVES:3)
Block(4,77,-1,LEAVES:3)
Block(4,77,1,LEAVES:3)
Block(4,77,4,LEAVES:3)
Block(4,78,-4,LEAVES:3)
Block(4,78,4,LEAVES:3)
Block(4,78,6,LEAVES:3)
Block(4,79,6,LEAVES:3)
Block(5,-4,0,17:15)
Block(5,-4,1,17:15)
Block(5,-3,0,17:15)
Block(5,-3,1,17:15)
Block(5,-2,1,17:15)
Block(5,18,1,17:15)
Block(5,18,2,17:15)
Block(5,18,3,17:15)
Block(5,18,4,17:15)
Block(5,19,1,LEAVES:3)
Block(5,19,5,17:15)
Block(5,20,6,17:15)
Block(5,20,7,LEAVES:3)
Block(5,30,-7,LEAVES:3)
Block(5,31,-10,LEAVES:3)
Block(5,31,-8,17:15)
Block(5,31,-7,17:15)
Block(5,31,-4,17:15)
Block(5,31,-3,LEAVES:3)
Block(5,31,-2,LEAVES:3)
Block(5,31,-1,LEAVES:3)
Block(5,32,-13,LEAVES:3)
Block(5,32,-9,LEAVES:3)
Block(5,32,-8,17:15)
Block(5,32,-7,LEAVES:3)
Block(5,32,-6,LEAVES:3)
Block(5,32,-5,LEAVES:3)
Block(5,32,-4,LEAVES:3)
Block(5,32,-3,LEAVES:3)
Block(5,32,-2,LEAVES:3)
Block(5,33,-15,LEAVES:3)
Block(5,33,-14,LEAVES:3)
Block(5,33,-13,LEAVES:3)
Block(5,33,-12,17:15)
Block(5,33,-11,LEAVES:3)
Block(5,33,-10,LEAVES:3)
Block(5,33,-9,LEAVES:3)
Block(5,33,-7,LEAVES:3)
Block(5,33,-6,LEAVES:3)
Block(5,33,-5,LEAVES:3)
Block(5,33,-3,LEAVES:3)
Block(5,34,-14,LEAVES:3)
Block(5,34,-13,LEAVES:3)
Block(5,34,-12,LEAVES:3)
Block(5,34,-10,LEAVES:3)
Block(5,34,-6,LEAVES:3)
Block(5,34,-5,LEAVES:3)
Block(5,35,-13,LEAVES:3)
Block(5,36,0,17:15)
Block(5,37,0,17:15)
Block(5,37,1,17:15)
Block(5,37,2,LEAVES:3)
Block(5,38,-6,LEAVES:3)
Block(5,38,-5,LEAVES:3)
Block(5,38,-3,LEAVES:3)
Block(5,38,6,LEAVES:3)
Block(5,39,-8,LEAVES:3)
Block(5,39,-6,LEAVES:3)
Block(5,39,-5,LEAVES:3)
Block(5,39,-4,LEAVES:3)
Block(5,39,-3,LEAVES:3)
Block(5,39,0,LEAVES:3)
Block(5,39,2,LEAVES:3)
Block(5,40,-7,LEAVES:3)
Block(5,40,-6,LEAVES:3)
Block(5,40,-5,LEAVES:3)
Block(5,40,-4,LEAVES:3)
Block(5,40,-1,LEAVES:3)
Block(5,40,2,LEAVES:3)
Block(5,40,5,LEAVES:3)
Block(5,41,-5,LEAVES:3)
Block(5,41,0,LEAVES:3)
Block(5,41,4,LEAVES:3)
Block(5,41,5,LEAVES:3)
Block(5,41,6,LEAVES:3)
Block(5,41,7,LEAVES:3)
Block(5,42,5,LEAVES:3)
Block(5,42,6,LEAVES:3)
Block(5,47,10,LEAVES:3)
Block(5,47,17,LEAVES:3)
Block(5,48,6,LEAVES:3)
Block(5,48,7,17:15)
Block(5,48,8,LEAVES:3)
Block(5,48,11,LEAVES:3)
Block(5,48,12,LEAVES:3)
Block(5,48,13,LEAVES:3)
Block(5,48,14,LEAVES:3)
Block(5,48,15,17:15)
Block(5,48,16,LEAVES:3)
Block(5,48,17,LEAVES:3)
Block(5,49,6,LEAVES:3)
Block(5,49,13,LEAVES:3)
Block(5,49,15,LEAVES:3)
Block(5,49,16,LEAVES:3)
Block(5,54,-5,17:15)
Block(5,54,-2,LEAVES:3)
Block(5,55,-12,LEAVES:3)
Block(5,55,-7,17:15)
Block(5,55,-6,LEAVES:3)
Block(5,55,-3,LEAVES:3)
Block(5,55,-2,LEAVES:3)
Block(5,56,-17,LEAVES:3)
Block(5,56,-15,17:15)
Block(5,56,-14,17:15)
Block(5,56,-13,17:15)
Block(5,56,-12,LEAVES:3)
Block(5,56,-10,LEAVES:3)
Block(5,56,-9,LEAVES:3)
Block(5,56,-7,17:15)
Block(5,56,-6,LEAVES:3)
Block(5,56,3,17:15)
Block(5,56,7,LEAVES:3)
Block(5,57,-21,LEAVES:3)
Block(5,57,-16,17:15)
Block(5,57,-15,17:15)
Block(5,57,-14,LEAVES:3)
Block(5,57,-7,LEAVES:3)
Block(5,57,3,17:15)
Block(5,58,-20,LEAVES:3)
Block(5,58,-19,LEAVES:3)
Block(5,58,-18,LEAVES:3)
Block(5,58,-17,LEAVES:3)
Block(5,58,-16,LEAVES:3)
Block(5,58,-15,LEAVES:3)
Block(5,58,-14,LEAVES:3)
Block(5,58,-13,LEAVES:3)
Block(5,58,-12,17:15)
Block(5,58,-11,LEAVES:3)
Block(5,58,-10,LEAVES:3)
Block(5,58,-9,17:15)
Block(5,58,-8,LEAVES:3)
Block(5,59,-19,LEAVES:3)
Block(5,59,-16,LEAVES:3)
Block(5,59,-12,LEAVES:3)
Block(5,59,-9,LEAVES:3)
Block(5,59,-8,LEAVES:3)
Block(5,60,-12,LEAVES:3)
Block(5,60,-9,LEAVES:3)
Block(5,69,-3,LEAVES:3)
Block(5,69,1,LEAVES:3)
Block(5,70,-9,LEAVES:3)
Block(5,70,-5,LEAVES:3)
Block(5,70,-4,17:15)
Block(5,70,-3,LEAVES:3)
Block(5,70,-1,LEAVES:3)
Block(5,70,0,LEAVES:3)
Block(5,70,1,LEAVES:3)
Block(5,70,2,LEAVES:3)
Block(5,71,-9,LEAVES:3)
Block(5,71,-8,LEAVES:3)
Block(5,71,-7,17:15)
Block(5,71,-6,LEAVES:3)
Block(5,71,-4,LEAVES:3)
Block(5,71,0,LEAVES:3)
Block(5,71,1,LEAVES:3)
Block(5,72,-8,LEAVES:3)
Block(5,72,-7,LEAVES:3)
Block(5,72,-4,LEAVES:3)
Block(5,74,-3,LEAVES:3)
Block(5,74,0,LEAVES:3)
Block(5,74,4,LEAVES:3)
Block(5,75,-6,LEAVES:3)
Block(5,75,-4,LEAVES:3)
Block(5,75,0,LEAVES:3)
Block(5,75,1,LEAVES:3)
Block(5,75,2,17:15)
Block(5,75,3,LEAVES:3)
Block(5,75,4,LEAVES:3)
Block(5,76,-5,LEAVES:3)
Block(5,76,-4,LEAVES:3)
Block(5,76,-3,LEAVES:3)
Block(5,76,-2,LEAVES:3)
Block(5,76,-1,LEAVES:3)
Block(5,76,2,LEAVES:3)
Block(5,76,3,LEAVES:3)
Block(5,77,-3,LEAVES:3)
Block(6,-5,0,17:15)
Block(6,-5,2,17:15)
Block(6,-4,0,17:15)
Block(6,-4,2,17:15)
Block(6,-3,0,17:15)
Block(6,18,1,17:15)
Block(6,18,3,17:15)
Block(6,19,-2,LEAVES:3)
Block(6,19,-1,LEAVES:3)
Block(6,19,0,17:15)
Block(6,19,1,17:15)
Block(6,19,3,17:15)
Block(6,20,-1,LEAVES:3)
Block(6,20,2,LEAVES:3)
Block(6,20,3,LEAVES:3)
Block(6,20,7,17:15)
Block(6,20,8,LEAVES:3)
Block(6,20,9,LEAVES:3)
Block(6,21,3,LEAVES:3)
Block(6,21,7,LEAVES:3)
Block(6,30,-1,LEAVES:3)
Block(6,31,-12,LEAVES:3)
Block(6,31,-8,LEAVES:3)
Block(6,31,-3,17:15)
Block(6,31,-2,LEAVES:3)
Block(6,32,-14,LEAVES:3)
Block(6,32,-11,LEAVES:3)
Block(6,32,-10,17:15)
Block(6,32,-9,17:15)
Block(6,32,-8,LEAVES:3)
Block(6,32,-7,LEAVES:3)
Block(6,32,-6,LEAVES:3)
Block(6,32,-5,LEAVES:3)
Block(6,32,-4,LEAVES:3)
Block(6,32,-3,LEAVES:3)
Block(6,32,-2,LEAVES:3)
Block(6,33,-14,LEAVES:3)
Block(6,33,-13,LEAVES:3)
Block(6,33,-12,LEAVES:3)
Block(6,33,-11,17:15)
Block(6,33,-10,LEAVES:3)
Block(6,33,-9,LEAVES:3)
Block(6,33,-6,LEAVES:3)
Block(6,34,-11,LEAVES:3)
Block(6,34,-10,LEAVES:3)
Block(6,36,0,17:15)
Block(6,37,-1,17:15)
Block(6,37,0,17:15)
Block(6,37,1,LEAVES:3)
Block(6,38,-7,LEAVES:3)
Block(6,38,-4,LEAVES:3)
Block(6,39,-7,LEAVES:3)
Block(6,39,-5,17:15)
Block(6,39,-4,LEAVES:3)
Block(6,39,-3,LEAVES:3)
Block(6,39,4,LEAVES:3)
Block(6,40,-8,LEAVES:3)
Block(6,40,-7,LEAVES:3)
Block(6,40,-6,17:15)
Block(6,40,-5,LEAVES:3)
Block(6,40,-4,LEAVES:3)
Block(6,40,-2,LEAVES:3)
Block(6,40,0,LEAVES:3)
Block(6,40,1,LEAVES:3)
Block(6,40,2,LEAVES:3)
Block(6,40,3,LEAVES:3)
Block(6,40,5,LEAVES:3)
Block(6,40,7,LEAVES:3)
Block(6,41,-7,LEAVES:3)
Block(6,41,-6,LEAVES:3)
Block(6,41,-1,LEAVES:3)
Block(6,41,0,LEAVES:3)
Block(6,41,1,LEAVES:3)
Block(6,41,2,LEAVES:3)
Block(6,41,4,LEAVES:3)
Block(6,41,5,17:15)
Block(6,41,6,LEAVES:3)
Block(6,42,0,LEAVES:3)
Block(6,42,5,LEAVES:3)
Block(6,43,5,LEAVES:3)
Block(6,47,13,LEAVES:3)
Block(6,47,15,LEAVES:3)
Block(6,48,4,LEAVES:3)
Block(6,48,7,17:15)
Block(6,48,9,LEAVES:3)
Block(6,48,14,LEAVES:3)
Block(6,48,15,LEAVES:3)
Block(6,48,16,LEAVES:3)
Block(6,49,5,LEAVES:3)
Block(6,49,6,LEAVES:3)
Block(6,49,7,LEAVES:3)
Block(6,49,14,LEAVES:3)
Block(6,49,15,LEAVES:3)
Block(6,50,6,LEAVES:3)
Block(6,54,-3,LEAVES:3)
Block(6,54,-1,LEAVES:3)
Block(6,55,-5,17:15)
Block(6,55,-4,LEAVES:3)
Block(6,55,-3,LEAVES:3)
Block(6,55,-2,LEAVES:3)
Block(6,55,-1,LEAVES:3)
Block(6,56,-14,LEAVES:3)
Block(6,56,-7,17:15)
Block(6,56,-6,LEAVES:3)
Block(6,56,-5,LEAVES:3)
Block(6,56,-3,LEAVES:3)
Block(6,56,-2,LEAVES:3)
Block(6,56,3,17:15)
Block(6,57,-20,LEAVES:3)
Block(6,57,-17,LEAVES:3)
Block(6,57,-16,17:15)
Block(6,57,-15,LEAVES:3)
Block(6,57,-14,LEAVES:3)
Block(6,57,-12,LEAVES:3)
Block(6,57,-11,LEAVES:3)
Block(6,57,-10,17:15)
Block(6,57,-9,17:15)
Block(6,57,-8,LEAVES:3)
Block(6,57,-7,LEAVES:3)
Block(6,57,-6,LEAVES:3)
Block(6,57,4,17:15)
Block(6,58,-19,LEAVES:3)
Block(6,58,-17,LEAVES:3)
Block(6,58,-16,LEAVES:3)
Block(6,58,-14,LEAVES:3)
Block(6,58,-13,LEAVES:3)
Block(6,58,-12,LEAVES:3)
Block(6,58,-11,LEAVES:3)
Block(6,58,-10,LEAVES:3)
Block(6,58,-9,LEAVES:3)
Block(6,58,-7,LEAVES:3)
Block(6,59,-17,LEAVES:3)
Block(6,59,-13,LEAVES:3)
Block(6,59,-12,LEAVES:3)
Block(6,69,0,LEAVES:3)
Block(6,70,-7,LEAVES:3)
Block(6,70,-4,LEAVES:3)
Block(6,70,-1,LEAVES:3)
Block(6,70,0,LEAVES:3)
Block(6,70,1,LEAVES:3)
Block(6,71,-8,LEAVES:3)
Block(6,71,-7,LEAVES:3)
Block(6,71,-6,LEAVES:3)
Block(6,71,-5,LEAVES:3)
Block(6,71,-4,17:15)
Block(6,71,-3,LEAVES:3)
Block(6,71,-2,LEAVES:3)
Block(6,71,0,LEAVES:3)
Block(6,72,-7,LEAVES:3)
Block(6,72,-4,LEAVES:3)
Block(6,72,-3,LEAVES:3)
Block(6,73,-4,LEAVES:3)
Block(6,73,3,LEAVES:3)
Block(6,74,2,LEAVES:3)
Block(6,75,-2,LEAVES:3)
Block(6,75,1,LEAVES:3)
Block(6,75,2,LEAVES:3)
Block(6,75,3,LEAVES:3)
Block(6,76,-3,LEAVES:3)
Block(6,76,2,LEAVES:3)
Block(7,19,0,17:15)
Block(7,19,3,17:15)
Block(7,19,4,17:15)
Block(7,20,-1,17:15)
Block(7,30,-3,LEAVES:3)
Block(7,31,-7,LEAVES:3)
Block(7,31,-4,LEAVES:3)
Block(7,31,-3,17:15)
Block(7,31,-1,LEAVES:3)
Block(7,32,-13,LEAVES:3)
Block(7,32,-9,17:15)
Block(7,32,-6,LEAVES:3)
Block(7,32,-5,LEAVES:3)
Block(7,32,-4,LEAVES:3)
Block(7,32,-3,17:15)
Block(7,32,-2,LEAVES:3)
Block(7,32,-1,LEAVES:3)
Block(7,33,-12,LEAVES:3)
Block(7,33,-11,LEAVES:3)
Block(7,33,-10,LEAVES:3)
Block(7,33,-9,17:15)
Block(7,33,-7,LEAVES:3)
Block(7,33,-3,LEAVES:3)
Block(7,33,-2,LEAVES:3)
Block(7,34,-11,LEAVES:3)
Block(7,34,-9,LEAVES:3)
Block(7,37,-1,17:15)
Block(7,37,0,17:15)
Block(7,38,-2,17:15)
Block(7,38,-1,17:15)
Block(7,38,0,17:15)
Block(7,39,-8,LEAVES:3)
Block(7,39,-6,LEAVES:3)
Block(7,39,-5,17:15)
Block(7,39,-4,LEAVES:3)
Block(7,39,1,LEAVES:3)
Block(7,40,-8,LEAVES:3)
Block(7,40,-7,LEAVES:3)
Block(7,40,-6,LEAVES:3)
Block(7,40,-5,LEAVES:3)
Block(7,40,-2,LEAVES:3)
Block(7,40,1,LEAVES:3)
Block(7,40,2,17:15)
Block(7,40,3,LEAVES:3)
Block(7,40,4,LEAVES:3)
Block(7,40,5,LEAVES:3)
Block(7,41,-2,LEAVES:3)
Block(7,41,-1,LEAVES:3)
Block(7,41,0,17:15)
Block(7,41,1,17:15)
Block(7,41,2,LEAVES:3)
Block(7,41,4,17:15)
Block(7,41,5,LEAVES:3)
Block(7,42,-1,LEAVES:3)
Block(7,42,0,LEAVES:3)
Block(7,42,1,LEAVES:3)
Block(7,42,4,LEAVES:3)
Block(7,42,5,LEAVES:3)
Block(7,43,1,LEAVES:3)
Block(7,48,6,LEAVES:3)
Block(7,49,4,LEAVES:3)
Block(7,49,5,LEAVES:3)
Block(7,49,6,17:15)
Block(7,49,7,17:15)
Block(7,49,8,LEAVES:3)
Block(7,49,9,LEAVES:3)
Block(7,50,4,LEAVES:3)
Block(7,50,6,LEAVES:3)
Block(7,50,7,LEAVES:3)
Block(7,50,8,LEAVES:3)
Block(7,54,-2,LEAVES:3)
Block(7,55,-5,LEAVES:3)
Block(7,55,-4,17:15)
Block(7,55,-3,17:15)
Block(7,55,-2,LEAVES:3)
Block(7,55,-1,LEAVES:3)
Block(7,55,0,LEAVES:3)
Block(7,56,-16,LEAVES:3)
Block(7,56,-9,LEAVES:3)
Block(7,56,-8,17:15)
Block(7,56,-7,LEAVES:3)
Block(7,56,-6,LEAVES:3)
Block(7,56,-4,LEAVES:3)
Block(7,56,-3,LEAVES:3)
Block(7,56,-2,LEAVES:3)
Block(7,56,-1,LEAVES:3)
Block(7,56,2,17:15)
Block(7,57,-16,LEAVES:3)
Block(7,57,-15,LEAVES:3)
Block(7,57,-14,LEAVES:3)
Block(7,57,-10,LEAVES:3)
Block(7,57,-9,LEAVES:3)
Block(7,57,-8,17:15)
Block(7,57,-7,LEAVES:3)
Block(7,57,-2,LEAVES:3)
Block(7,57,4,LEAVES:3)
Block(7,57,5,17:15)
Block(7,58,-20,LEAVES:3)
Block(7,58,-18,LEAVES:3)
Block(7,58,-17,17:15)
Block(7,58,-16,LEAVES:3)
Block(7,58,-15,LEAVES:3)
Block(7,58,-13,LEAVES:3)
Block(7,58,-12,LEAVES:3)
Block(7,58,-11,LEAVES:3)
Block(7,58,-9,LEAVES:3)
Block(7,58,-8,LEAVES:3)
Block(7,58,-7,LEAVES:3)
Block(7,59,-19,LEAVES:3)
Block(7,59,-18,LEAVES:3)
Block(7,59,-17,LEAVES:3)
Block(7,59,-12,LEAVES:3)
Block(7,59,-8,LEAVES:3)
Block(7,60,-17,LEAVES:3)
Block(7,69,-1,LEAVES:3)
Block(7,70,-8,LEAVES:3)
Block(7,70,-2,LEAVES:3)
Block(7,70,0,LEAVES:3)
Block(7,71,-7,LEAVES:3)
Block(7,71,-6,LEAVES:3)
Block(7,71,-5,LEAVES:3)
Block(7,71,-4,LEAVES:3)
Block(7,71,-3,LEAVES:3)
Block(7,71,-2,LEAVES:3)
Block(7,72,-4,LEAVES:3)
Block(7,74,1,LEAVES:3)
Block(7,75,2,LEAVES:3)
Block(8,19,0,17:15)
Block(8,19,4,17:15)
Block(8,19,5,17:15)
Block(8,20,-2,17:15)
Block(8,20,0,LEAVES:3)
Block(8,20,4,17:15)
Block(8,21,-2,LEAVES:3)
Block(8,21,3,LEAVES:3)
Block(8,21,4,LEAVES:3)
Block(8,22,4,LEAVES:3)
Block(8,31,-3,LEAVES:3)
Block(8,32,-11,LEAVES:3)
Block(8,32,-3,17:15)
Block(8,32,-2,LEAVES:3)
Block(8,33,-11,LEAVES:3)
Block(8,33,-10,LEAVES:3)
Block(8,33,-9,17:15)
Block(8,33,-8,17:15)
Block(8,33,-7,LEAVES:3)
Block(8,33,-6,LEAVES:3)
Block(8,33,-4,LEAVES:3)
Block(8,34,-10,LEAVES:3)
Block(8,34,-9,LEAVES:3)
Block(8,34,-8,LEAVES:3)
Block(8,34,-7,LEAVES:3)
Block(8,35,-9,LEAVES:3)
Block(8,37,0,17:15)
Block(8,37,1,LEAVES:3)
Block(8,38,-3,17:15)
Block(8,38,-2,17:15)
Block(8,38,0,17:15)
Block(8,38,1,17:15)
Block(8,38,2,LEAVES:3)
Block(8,39,-5,LEAVES:3)
Block(8,39,-4,17:15)
Block(8,39,2,LEAVES:3)
Block(8,39,6,LEAVES:3)
Block(8,40,-4,LEAVES:3)
Block(8,40,2,LEAVES:3)
Block(8,40,3,17:15)
Block(8,40,4,17:15)
Block(8,40,5,LEAVES:3)
Block(8,40,6,LEAVES:3)
Block(8,41,-1,LEAVES:3)
Block(8,41,0,LEAVES:3)
Block(8,41,1,LEAVES:3)
Block(8,41,3,LEAVES:3)
Block(8,41,4,LEAVES:3)
Block(8,41,5,LEAVES:3)
Block(8,42,-10,LEAVES:3)
Block(8,42,1,LEAVES:3)
Block(8,42,4,LEAVES:3)
Block(8,43,-11,LEAVES:3)
Block(8,48,4,LEAVES:3)
Block(8,48,9,LEAVES:3)
Block(8,49,4,LEAVES:3)
Block(8,49,5,17:15)
Block(8,49,6,LEAVES:3)
Block(8,49,8,17:15)
Block(8,49,9,LEAVES:3)
Block(8,49,10,LEAVES:3)
Block(8,50,4,LEAVES:3)
Block(8,50,5,LEAVES:3)
Block(8,50,7,LEAVES:3)
Block(8,50,8,LEAVES:3)
Block(8,50,9,LEAVES:3)
Block(8,51,8,LEAVES:3)
Block(8,54,-2,LEAVES:3)
Block(8,54,0,LEAVES:3)
Block(8,55,-6,LEAVES:3)
Block(8,55,-4,LEAVES:3)
Block(8,55,-2,LEAVES:3)
Block(8,55,-1,LEAVES:3)
Block(8,56,-15,LEAVES:3)
Block(8,56,-10,LEAVES:3)
Block(8,56,-8,LEAVES:3)
Block(8,56,-6,LEAVES:3)
Block(8,56,-4,LEAVES:3)
Block(8,56,-3,17:15)
Block(8,56,-2,LEAVES:3)
Block(8,56,1,LEAVES:3)
Block(8,56,2,17:15)
Block(8,57,-19,LEAVES:3)
Block(8,57,-17,LEAVES:3)
Block(8,57,-16,LEAVES:3)
Block(8,57,-15,LEAVES:3)
Block(8,57,-13,LEAVES:3)
Block(8,57,-12,LEAVES:3)
Block(8,57,-11,LEAVES:3)
Block(8,57,-10,LEAVES:3)
Block(8,57,-9,17:15)
Block(8,57,-8,17:15)
Block(8,57,-7,LEAVES:3)
Block(8,57,-3,LEAVES:3)
Block(8,58,-20,LEAVES:3)
Block(8,58,-19,LEAVES:3)
Block(8,58,-18,17:15)
Block(8,58,-17,LEAVES:3)
Block(8,58,-16,LEAVES:3)
Block(8,58,-12,LEAVES:3)
Block(8,58,-10,LEAVES:3)
Block(8,58,-8,LEAVES:3)
Block(8,58,5,17:15)
Block(8,58,6,LEAVES:3)
Block(8,59,-19,LEAVES:3)
Block(8,59,-18,LEAVES:3)
Block(8,59,-10,LEAVES:3)
Block(8,59,5,LEAVES:3)
Block(8,70,-6,LEAVES:3)
Block(8,70,-4,LEAVES:3)
Block(8,71,-5,LEAVES:3)
Block(8,71,-4,LEAVES:3)
Block(8,71,-3,LEAVES:3)
Block(8,72,-4,LEAVES:3)
Block(9,19,1,17:15)
Block(9,19,5,17:15)
Block(9,19,6,17:15)
Block(9,20,-4,LEAVES:3)
Block(9,20,-3,17:15)
Block(9,20,-2,LEAVES:3)
Block(9,20,4,LEAVES:3)
Block(9,20,6,17:15)
Block(9,20,7,17:15)
Block(9,20,9,LEAVES:3)
Block(9,20,10,17:15)
Block(9,20,11,LEAVES:3)
Block(9,21,7,LEAVES:3)
Block(9,21,10,LEAVES:3)
Block(9,32,-9,LEAVES:3)
Block(9,32,-6,LEAVES:3)
Block(9,32,-3,17:15)
Block(9,32,-1,LEAVES:3)
Block(9,33,-12,LEAVES:3)
Block(9,33,-11,17:15)
Block(9,33,-10,17:15)
Block(9,33,-9,17:15)
Block(9,33,-7,LEAVES:3)
Block(9,33,-5,LEAVES:3)
Block(9,33,-4,LEAVES:3)
Block(9,33,-3,LEAVES:3)
Block(9,34,-13,LEAVES:3)
Block(9,34,-12,LEAVES:3)
Block(9,34,-11,LEAVES:3)
Block(9,34,-10,LEAVES:3)
Block(9,34,-9,17:15)
Block(9,34,-8,LEAVES:3)
Block(9,34,-7,LEAVES:3)
Block(9,34,-4,LEAVES:3)
Block(9,35,-10,LEAVES:3)
Block(9,35,-9,LEAVES:3)
Block(9,35,-8,LEAVES:3)
Block(9,36,-9,LEAVES:3)
Block(9,38,-2,17:15)
Block(9,38,1,17:15)
Block(9,38,2,17:15)
Block(9,38,3,LEAVES:3)
Block(9,39,-6,LEAVES:3)
Block(9,39,-3,LEAVES:3)
Block(9,39,-2,17:15)
Block(9,39,3,17:15)
Block(9,40,-6,LEAVES:3)
Block(9,40,-5,LEAVES:3)
Block(9,40,-4,LEAVES:3)
Block(9,40,-3,LEAVES:3)
Block(9,40,0,LEAVES:3)
Block(9,40,3,17:15)
Block(9,40,4,LEAVES:3)
Block(9,40,5,LEAVES:3)
Block(9,41,-8,LEAVES:3)
Block(9,41,-4,LEAVES:3)
Block(9,41,1,LEAVES:3)
Block(9,42,-12,LEAVES:3)
Block(9,42,-8,LEAVES:3)
Block(9,43,-12,LEAVES:3)
Block(9,43,-11,LEAVES:3)
Block(9,43,-10,LEAVES:3)
Block(9,44,-11,LEAVES:3)
Block(9,48,10,LEAVES:3)
Block(9,49,4,LEAVES:3)
Block(9,49,5,LEAVES:3)
Block(9,49,6,LEAVES:3)
Block(9,49,9,LEAVES:3)
Block(9,50,5,LEAVES:3)
Block(9,50,7,LEAVES:3)
Block(9,50,8,17:15)
Block(9,50,9,LEAVES:3)
Block(9,51,7,LEAVES:3)
Block(9,51,8,LEAVES:3)
Block(9,52,8,LEAVES:3)
Block(9,54,-3,LEAVES:3)
Block(9,55,-3,LEAVES:3)
Block(9,56,-17,LEAVES:3)
Block(9,56,-11,LEAVES:3)
Block(9,56,-4,LEAVES:3)
Block(9,56,-3,LEAVES:3)
Block(9,56,-2,LEAVES:3)
Block(9,57,-16,LEAVES:3)
Block(9,57,-10,LEAVES:3)
Block(9,57,-9,17:15)
Block(9,57,-8,LEAVES:3)
Block(9,57,-3,LEAVES:3)
Block(9,57,2,17:15)
Block(9,58,-19,LEAVES:3)
Block(9,58,-18,LEAVES:3)
Block(9,58,-17,LEAVES:3)
Block(9,58,-12,LEAVES:3)
Block(9,58,-9,17:15)
Block(9,58,-8,LEAVES:3)
