#######################################################################
# +-----------------------------------------------------------------+ #
# |                            BO3 object                           | #
# +-----------------------------------------------------------------+ #
#######################################################################

# The descriptions in this file are accurate only for TerrainControl and OTG.
# For MCW and OTG+ these descriptions are only accurate if the BO3 is used as a CustomObject.
# MCW and OTG+ completely reimplemented CustomStructure, check the MCW/OTG+ documentation for more information.

# This is the config file of a custom object.
# If you add this object correctly to your BiomeConfigs, it will spawn in the world.

# This is the creator of this BO3 object
Author: Unknown

# A short description of this BO3 object
Description: This BO3 was converted from a schematic using OTGEdit. The author and description information of the schematic could not be found. If you know who the author of the schematic is then please add this information.

# The BO3 version, don't change this! It can be used by external applications to do a version check.
Version: 3

# The settings mode, WriteAll, WriteWithoutComments or WriteDisable. See WorldConfig.
SettingsMode: WriteDisable

#######################################################################
# +-----------------------------------------------------------------+ #
# |                          Main settings                          | #
# +-----------------------------------------------------------------+ #
#######################################################################

# This needs to be set to true to spawn the object in the Tree and Sapling resources.
Tree: true

# The frequency of the BO3 from 1 to 200. Tries this many times to spawn this BO3 when using the CustomObject(...) resource.
# Ignored by Tree(..), Sapling(..) and CustomStructure(..)
Frequency: 1

# The rarity of the BO3 from 0 to 100. Each spawn attempt has rarity% chance to succeed when using the CustomObject(...) resource.
# Ignored by Tree(..), Sapling(..) and CustomStructure(..)
Rarity: 100.0

# If you set this to true, the BO3 will be placed with a random rotation.
RotateRandomly: false

# The spawn height of the BO3 - randomY, highestBlock or highestSolidBlock.
SpawnHeight: highestBlock

# The height limits for the BO3.
MinHeight: 64

MaxHeight: 80

# Objects can have other objects attached to it: branches. Branches can also
# have branches attached to it, which can also have branches, etc. This is the
# maximum branch depth for this objects.
MaxBranchDepth: 10

# When spawned with the UseWorld keyword, this BO3 should NOT spawn in the following biomes.
# If you writer.write the BO3 name directly in the BiomeConfigs, this will be ignored.
ExcludedBiomes: All

# To optimise this BO3 for faster loading times you can use Notepad++ to find/replace comments and abbreviate things.
# Notepad++ find/replace with regex:
# Find: ^[#;].* replace to nothing removes all lines starting with # 
# Find: ^\s*$ replace to nothing removes most empty lines 
# Notepad++ find/replace without regex:
# *Warning: This will only work for OTG 1.10.2 v21 / OTG 1.11.2 v6 or higher. B( is not recognised by lower versions.
# Find: Block( replace to B(

#######################################################################
# +-----------------------------------------------------------------+ #
# |                      Source block settings                      | #
# +-----------------------------------------------------------------+ #
#######################################################################

# The block(s) the BO3 should spawn in.
SourceBlocks: STONE:1,STONE:3,STONE:5,DIRT:1,DIRT,SAND,GRASS,DIRT:2,STATIONARY_WATER,HARD_CLAY,STAINED_CLAY,CLAY,SANDSTONE,SAND:1,AIR,STONE,GRAVEL,LONG_GRASS,LONG_GRASS:1,LONG_GRASS:2,DEAD_BUSH,YELLOW_FLOWER,RED_ROSE,BROWN_MUSHROOM,RED_MUSHROOM

# The maximum percentage of the BO3 that can be outside the SourceBlock.
# The BO3 won't be placed on a location with more blocks outside the SourceBlock than this percentage.
MaxPercentageOutsideSourceBlock: 0

# What to do when a block is about to be placed outside the SourceBlock? (dontPlace, placeAnyway)
OutsideSourceBlock: placeAnyway

#######################################################################
# +-----------------------------------------------------------------+ #
# |                              Blocks                             | #
# +-----------------------------------------------------------------+ #
#######################################################################

# All the blocks used in the BO3 are listed here. Possible blocks:
# Block(x,y,z,id[.data][,nbtfile.nbt) or B(x,y,z,id[.data][,nbtfile.nbt)
# RandomBlock(x,y,z,id[:data][,nbtfile.nbt],chance[,id[:data][,nbtfile.nbt],chance[,...]])
# So RandomBlock(0,0,0,CHEST,chest.nbt,50,CHEST,anotherchest.nbt,100) will spawn a chest at
# the BO3 origin, and give it a 50% chance to have the contents of chest.nbt, or, if that
# fails, a 100% percent chance to have the contents of anotherchest.nbt.

Block(-16,11,-2,LEAVES:3)
Block(-16,11,1,LEAVES:3)
Block(-16,11,3,17:15)
Block(-16,11,4,LEAVES:3)
Block(-16,12,-2,LEAVES:3)
Block(-16,12,-1,LEAVES:3)
Block(-16,12,0,LEAVES:3)
Block(-16,12,2,LEAVES:3)
Block(-16,12,3,LEAVES:3)
Block(-16,12,4,LEAVES:3)
Block(-16,12,5,LEAVES:3)
Block(-16,13,-1,LEAVES:3)
Block(-16,13,3,LEAVES:3)
Block(-16,13,4,LEAVES:3)
Block(-16,13,9,LEAVES:3)
Block(-16,14,9,LEAVES:3)
Block(-15,11,-4,LEAVES:3)
Block(-15,11,2,17:15)
Block(-15,11,3,17:15)
Block(-15,12,-3,LEAVES:3)
Block(-15,12,-2,LEAVES:3)
Block(-15,12,-1,LEAVES:3)
Block(-15,12,0,LEAVES:3)
Block(-15,12,2,LEAVES:3)
Block(-15,12,6,LEAVES:3)
Block(-15,13,-2,LEAVES:3)
Block(-15,13,-1,LEAVES:3)
Block(-15,13,0,LEAVES:3)
Block(-15,13,3,LEAVES:3)
Block(-15,13,4,LEAVES:3)
Block(-15,13,5,LEAVES:3)
Block(-15,13,11,LEAVES:3)
Block(-15,14,-1,LEAVES:3)
Block(-15,14,4,LEAVES:3)
Block(-15,14,8,LEAVES:3)
Block(-15,14,9,LEAVES:3)
Block(-15,14,10,LEAVES:3)
Block(-15,15,9,LEAVES:3)
Block(-14,10,0,LEAVES:3)
Block(-14,10,2,LEAVES:3)
Block(-14,10,3,LEAVES:3)
Block(-14,11,-3,LEAVES:3)
Block(-14,11,-1,LEAVES:3)
Block(-14,11,2,17:15)
Block(-14,11,3,LEAVES:3)
Block(-14,12,-4,LEAVES:3)
Block(-14,12,-3,LEAVES:3)
Block(-14,12,-2,LEAVES:3)
Block(-14,12,-1,17:15)
Block(-14,12,0,LEAVES:3)
Block(-14,12,1,LEAVES:3)
Block(-14,12,2,17:15)
Block(-14,12,4,LEAVES:3)
Block(-14,12,6,LEAVES:3)
Block(-14,12,11,LEAVES:3)
Block(-14,13,-3,LEAVES:3)
Block(-14,13,0,LEAVES:3)
Block(-14,13,2,LEAVES:3)
Block(-14,13,3,17:15)
Block(-14,13,4,LEAVES:3)
Block(-14,13,5,LEAVES:3)
Block(-14,13,6,LEAVES:3)
Block(-14,13,7,LEAVES:3)
Block(-14,13,10,LEAVES:3)
Block(-14,14,3,LEAVES:3)
Block(-14,14,4,LEAVES:3)
Block(-14,14,5,LEAVES:3)
Block(-14,14,8,LEAVES:3)
Block(-14,14,9,17:15)
Block(-14,14,10,LEAVES:3)
Block(-14,14,11,LEAVES:3)
Block(-14,15,3,LEAVES:3)
Block(-14,15,9,LEAVES:3)
Block(-14,15,10,LEAVES:3)
Block(-13,11,-6,LEAVES:3)
Block(-13,11,-3,LEAVES:3)
Block(-13,11,0,LEAVES:3)
Block(-13,11,2,17:15)
Block(-13,11,7,LEAVES:3)
Block(-13,12,-6,LEAVES:3)
Block(-13,12,-4,LEAVES:3)
Block(-13,12,-3,17:15)
Block(-13,12,-2,17:15)
Block(-13,12,0,17:15)
Block(-13,12,1,LEAVES:3)
Block(-13,12,4,LEAVES:3)
Block(-13,12,6,LEAVES:3)
Block(-13,13,-3,LEAVES:3)
Block(-13,13,-2,LEAVES:3)
Block(-13,13,-1,LEAVES:3)
Block(-13,13,0,LEAVES:3)
Block(-13,13,1,LEAVES:3)
Block(-13,13,3,LEAVES:3)
Block(-13,13,4,LEAVES:3)
Block(-13,13,5,LEAVES:3)
Block(-13,13,9,LEAVES:3)
Block(-13,13,10,LEAVES:3)
Block(-13,14,-3,LEAVES:3)
Block(-13,14,0,LEAVES:3)
Block(-13,14,7,LEAVES:3)
Block(-13,14,8,LEAVES:3)
Block(-13,14,9,17:15)
Block(-13,14,10,LEAVES:3)
Block(-13,15,8,LEAVES:3)
Block(-13,15,9,LEAVES:3)
Block(-13,16,9,LEAVES:3)
Block(-12,10,2,17:15)
Block(-12,11,-8,LEAVES:3)
Block(-12,11,-5,LEAVES:3)
Block(-12,11,-4,LEAVES:3)
Block(-12,11,-3,LEAVES:3)
Block(-12,11,-2,LEAVES:3)
Block(-12,11,-1,LEAVES:3)
Block(-12,11,0,17:15)
Block(-12,11,1,17:15)
Block(-12,11,2,17:15)
Block(-12,11,3,LEAVES:3)
Block(-12,11,6,LEAVES:3)
Block(-12,12,-7,LEAVES:3)
Block(-12,12,-6,LEAVES:3)
Block(-12,12,-5,LEAVES:3)
Block(-12,12,-4,LEAVES:3)
Block(-12,12,-3,LEAVES:3)
Block(-12,12,-1,LEAVES:3)
Block(-12,12,0,LEAVES:3)
Block(-12,12,1,LEAVES:3)
Block(-12,12,4,17:15)
Block(-12,12,5,LEAVES:3)
Block(-12,12,6,LEAVES:3)
Block(-12,12,7,LEAVES:3)
Block(-12,12,8,LEAVES:3)
Block(-12,12,11,LEAVES:3)
Block(-12,13,-6,LEAVES:3)
Block(-12,13,0,LEAVES:3)
Block(-12,13,2,LEAVES:3)
Block(-12,13,3,LEAVES:3)
Block(-12,13,4,LEAVES:3)
Block(-12,13,6,LEAVES:3)
Block(-12,13,8,LEAVES:3)
Block(-12,13,9,17:15)
Block(-12,13,10,LEAVES:3)
Block(-12,13,11,LEAVES:3)
Block(-12,14,6,LEAVES:3)
Block(-12,14,9,LEAVES:3)
Block(-12,14,10,LEAVES:3)
Block(-11,10,-3,LEAVES:3)
Block(-11,10,0,LEAVES:3)
Block(-11,10,1,LEAVES:3)
Block(-11,10,2,17:15)
Block(-11,11,-6,LEAVES:3)
Block(-11,11,-5,LEAVES:3)
Block(-11,11,-4,17:15)
Block(-11,11,-3,LEAVES:3)
Block(-11,11,-2,LEAVES:3)
Block(-11,11,-1,LEAVES:3)
Block(-11,11,0,LEAVES:3)
Block(-11,11,2,LEAVES:3)
Block(-11,11,3,LEAVES:3)
Block(-11,11,5,LEAVES:3)
Block(-11,12,-8,LEAVES:3)
Block(-11,12,-7,LEAVES:3)
Block(-11,12,-6,LEAVES:3)
Block(-11,12,-5,17:15)
Block(-11,12,-4,LEAVES:3)
Block(-11,12,-3,LEAVES:3)
Block(-11,12,-2,LEAVES:3)
Block(-11,12,0,LEAVES:3)
Block(-11,12,4,17:15)
Block(-11,12,5,LEAVES:3)
Block(-11,12,6,17:15)
Block(-11,12,7,17:15)
Block(-11,13,-7,LEAVES:3)
Block(-11,13,-6,LEAVES:3)
Block(-11,13,-5,LEAVES:3)
Block(-11,13,-3,LEAVES:3)
Block(-11,13,1,LEAVES:3)
Block(-11,13,2,LEAVES:3)
Block(-11,13,3,17:15)
Block(-11,13,4,LEAVES:3)
Block(-11,13,5,LEAVES:3)
Block(-11,13,7,17:15)
Block(-11,13,8,17:15)
Block(-11,13,9,LEAVES:3)
Block(-11,13,10,LEAVES:3)
Block(-11,14,2,LEAVES:3)
Block(-11,14,3,LEAVES:3)
Block(-11,14,8,LEAVES:3)
Block(-11,15,3,LEAVES:3)
Block(-11,23,-3,LEAVES:3)
Block(-11,24,-4,LEAVES:3)
Block(-10,9,-3,LEAVES:3)
Block(-10,10,-6,LEAVES:3)
Block(-10,10,-3,17:15)
Block(-10,10,0,LEAVES:3)
Block(-10,10,1,LEAVES:3)
Block(-10,10,2,17:15)
Block(-10,11,-7,LEAVES:3)
Block(-10,11,-4,LEAVES:3)
Block(-10,11,-3,17:15)
Block(-10,11,-2,LEAVES:3)
Block(-10,11,0,LEAVES:3)
Block(-10,11,1,LEAVES:3)
Block(-10,11,5,17:15)
Block(-10,11,6,LEAVES:3)
Block(-10,12,-7,LEAVES:3)
Block(-10,12,-6,LEAVES:3)
Block(-10,12,-5,LEAVES:3)
Block(-10,12,-4,LEAVES:3)
Block(-10,12,-3,LEAVES:3)
Block(-10,12,1,LEAVES:3)
Block(-10,12,4,LEAVES:3)
Block(-10,12,5,17:15)
Block(-10,12,6,17:15)
Block(-10,12,7,LEAVES:3)
Block(-10,12,10,LEAVES:3)
Block(-10,13,2,LEAVES:3)
Block(-10,13,3,LEAVES:3)
Block(-10,13,5,LEAVES:3)
Block(-10,13,6,LEAVES:3)
Block(-10,13,7,LEAVES:3)
Block(-10,13,8,17:15)
Block(-10,13,9,LEAVES:3)
Block(-10,13,13,LEAVES:3)
Block(-10,14,3,LEAVES:3)
Block(-10,14,5,LEAVES:3)
Block(-10,14,8,LEAVES:3)
Block(-10,14,9,17:15)
Block(-10,14,10,LEAVES:3)
Block(-10,14,11,LEAVES:3)
Block(-10,14,12,LEAVES:3)
Block(-10,15,8,LEAVES:3)
Block(-10,15,9,LEAVES:3)
Block(-10,22,-3,LEAVES:3)
Block(-10,23,-6,LEAVES:3)
Block(-10,23,-4,LEAVES:3)
Block(-10,23,-1,LEAVES:3)
Block(-10,24,-5,LEAVES:3)
Block(-10,24,-4,LEAVES:3)
Block(-10,24,-3,LEAVES:3)
Block(-10,24,-2,LEAVES:3)
Block(-10,25,-4,LEAVES:3)
Block(-9,8,-2,LEAVES:3)
Block(-9,9,-2,17:15)
Block(-9,10,-4,LEAVES:3)
Block(-9,10,-3,17:15)
Block(-9,10,-2,17:15)
Block(-9,10,0,LEAVES:3)
Block(-9,10,1,LEAVES:3)
Block(-9,10,2,17:15)
Block(-9,10,3,17:15)
Block(-9,11,-5,LEAVES:3)
Block(-9,11,-3,LEAVES:3)
Block(-9,11,1,LEAVES:3)
Block(-9,11,2,LEAVES:3)
Block(-9,11,3,17:15)
Block(-9,11,4,17:15)
Block(-9,11,5,LEAVES:3)
Block(-9,12,3,LEAVES:3)
Block(-9,12,4,LEAVES:3)
Block(-9,12,5,LEAVES:3)
Block(-9,12,6,LEAVES:3)
Block(-9,13,4,LEAVES:3)
Block(-9,13,5,LEAVES:3)
Block(-9,13,7,LEAVES:3)
Block(-9,13,8,LEAVES:3)
Block(-9,13,9,LEAVES:3)
Block(-9,13,10,LEAVES:3)
Block(-9,13,11,LEAVES:3)
Block(-9,14,8,LEAVES:3)
Block(-9,14,9,LEAVES:3)
Block(-9,14,10,17:15)
Block(-9,14,11,LEAVES:3)
Block(-9,14,12,LEAVES:3)
Block(-9,14,13,LEAVES:3)
Block(-9,15,9,LEAVES:3)
Block(-9,15,10,LEAVES:3)
Block(-9,15,11,LEAVES:3)
Block(-9,15,12,LEAVES:3)
Block(-9,16,10,LEAVES:3)
Block(-9,23,-4,LEAVES:3)
Block(-9,23,-2,LEAVES:3)
Block(-9,23,0,LEAVES:3)
Block(-9,24,-6,LEAVES:3)
Block(-9,24,-5,LEAVES:3)
Block(-9,24,-4,17:15)
Block(-9,24,-3,LEAVES:3)
Block(-9,24,-2,LEAVES:3)
Block(-9,24,-1,LEAVES:3)
Block(-9,24,1,LEAVES:3)
Block(-9,24,2,LEAVES:3)
Block(-9,25,-5,LEAVES:3)
Block(-9,25,-4,LEAVES:3)
Block(-9,25,-2,LEAVES:3)
Block(-8,9,-3,LEAVES:3)
Block(-8,9,-2,17:15)
Block(-8,9,-1,17:15)
Block(-8,9,2,17:15)
Block(-8,10,-3,17:15)
Block(-8,10,2,17:15)
Block(-8,10,3,LEAVES:3)
Block(-8,10,6,LEAVES:3)
Block(-8,11,-5,LEAVES:3)
Block(-8,11,-4,LEAVES:3)
Block(-8,11,-3,17:15)
Block(-8,11,0,LEAVES:3)
Block(-8,11,3,LEAVES:3)
Block(-8,11,4,LEAVES:3)
Block(-8,11,5,LEAVES:3)
Block(-8,11,6,LEAVES:3)
Block(-8,12,-1,LEAVES:3)
Block(-8,12,4,LEAVES:3)
Block(-8,12,8,LEAVES:3)
Block(-8,13,8,LEAVES:3)
Block(-8,13,12,LEAVES:3)
Block(-8,14,10,LEAVES:3)
Block(-8,14,11,LEAVES:3)
Block(-8,14,12,LEAVES:3)
Block(-8,15,11,LEAVES:3)
Block(-8,23,-5,LEAVES:3)
Block(-8,23,-3,LEAVES:3)
Block(-8,23,2,LEAVES:3)
Block(-8,24,-5,LEAVES:3)
Block(-8,24,-4,LEAVES:3)
Block(-8,24,-3,LEAVES:3)
Block(-8,24,-2,LEAVES:3)
Block(-8,24,-1,LEAVES:3)
Block(-8,24,0,LEAVES:3)
Block(-8,24,2,LEAVES:3)
Block(-8,24,3,LEAVES:3)
Block(-8,25,-3,17:15)
Block(-8,25,-2,LEAVES:3)
Block(-8,25,-1,LEAVES:3)
Block(-8,25,1,LEAVES:3)
Block(-8,25,2,LEAVES:3)
Block(-8,26,-3,LEAVES:3)
Block(-8,26,-2,LEAVES:3)
Block(-8,39,-3,LEAVES:3)
Block(-8,40,-4,LEAVES:3)
Block(-7,8,-1,LEAVES:3)
Block(-7,8,0,17:15)
Block(-7,9,-2,LEAVES:3)
Block(-7,9,-1,17:15)
Block(-7,9,0,17:15)
Block(-7,9,2,17:15)
Block(-7,9,3,17:15)
Block(-7,10,-6,LEAVES:3)
Block(-7,10,-2,LEAVES:3)
Block(-7,10,4,17:15)
Block(-7,10,5,LEAVES:3)
Block(-7,11,-6,LEAVES:3)
Block(-7,11,-5,LEAVES:3)
Block(-7,11,-4,17:15)
Block(-7,11,-3,17:15)
Block(-7,11,-2,LEAVES:3)
Block(-7,11,4,LEAVES:3)
Block(-7,12,-5,LEAVES:3)
Block(-7,12,-4,LEAVES:3)
Block(-7,12,-3,LEAVES:3)
Block(-7,12,-1,LEAVES:3)
Block(-7,12,0,LEAVES:3)
Block(-7,12,1,LEAVES:3)
Block(-7,13,-4,LEAVES:3)
Block(-7,13,-1,LEAVES:3)
Block(-7,13,10,LEAVES:3)
Block(-7,14,11,LEAVES:3)
Block(-7,23,-4,LEAVES:3)
Block(-7,23,-2,LEAVES:3)
Block(-7,24,-4,LEAVES:3)
Block(-7,24,-3,LEAVES:3)
Block(-7,24,-2,17:15)
Block(-7,24,-1,LEAVES:3)
Block(-7,24,1,LEAVES:3)
Block(-7,24,2,17:15)
Block(-7,24,3,LEAVES:3)
Block(-7,24,4,LEAVES:3)
Block(-7,25,-3,LEAVES:3)
Block(-7,25,-2,LEAVES:3)
Block(-7,25,1,LEAVES:3)
Block(-7,25,2,LEAVES:3)
Block(-7,25,3,LEAVES:3)
Block(-7,38,-3,LEAVES:3)
Block(-7,39,-6,LEAVES:3)
Block(-7,39,-4,LEAVES:3)
Block(-7,39,-1,LEAVES:3)
Block(-7,40,-5,LEAVES:3)
Block(-7,40,-4,LEAVES:3)
Block(-7,40,-3,LEAVES:3)
Block(-7,40,-2,LEAVES:3)
Block(-7,41,-4,LEAVES:3)
Block(-6,8,0,17:15)
Block(-6,8,1,17:15)
Block(-6,9,0,17:15)
Block(-6,9,1,17:15)
Block(-6,9,2,17:15)
Block(-6,10,-1,LEAVES:3)
Block(-6,10,4,LEAVES:3)
Block(-6,10,5,17:15)
Block(-6,10,6,LEAVES:3)
Block(-6,10,8,LEAVES:3)
Block(-6,11,-5,LEAVES:3)
Block(-6,11,-4,LEAVES:3)
Block(-6,11,-3,LEAVES:3)
Block(-6,11,-2,17:15)
Block(-6,11,-1,LEAVES:3)
Block(-6,11,2,LEAVES:3)
Block(-6,11,5,LEAVES:3)
Block(-6,11,6,LEAVES:3)
Block(-6,11,7,LEAVES:3)
Block(-6,11,8,LEAVES:3)
Block(-6,12,-5,LEAVES:3)
Block(-6,12,-4,17:15)
Block(-6,12,-2,LEAVES:3)
Block(-6,12,-1,17:15)
Block(-6,12,0,17:15)
Block(-6,12,1,LEAVES:3)
Block(-6,12,2,LEAVES:3)
Block(-6,13,-5,LEAVES:3)
Block(-6,13,-4,LEAVES:3)
Block(-6,13,-1,LEAVES:3)
Block(-6,13,0,LEAVES:3)
Block(-6,13,1,LEAVES:3)
Block(-6,14,-1,LEAVES:3)
Block(-6,22,-2,LEAVES:3)
Block(-6,22,-1,LEAVES:3)
Block(-6,22,3,LEAVES:3)
Block(-6,23,-4,LEAVES:3)
Block(-6,23,-2,17:15)
Block(-6,23,0,LEAVES:3)
Block(-6,23,2,LEAVES:3)
Block(-6,23,4,LEAVES:3)
Block(-6,24,-4,LEAVES:3)
Block(-6,24,-3,LEAVES:3)
Block(-6,24,-2,LEAVES:3)
Block(-6,24,-1,LEAVES:3)
Block(-6,24,0,LEAVES:3)
Block(-6,24,1,17:15)
Block(-6,24,2,LEAVES:3)
Block(-6,24,3,LEAVES:3)
Block(-6,25,-2,LEAVES:3)
Block(-6,25,0,LEAVES:3)
Block(-6,25,1,LEAVES:3)
Block(-6,26,1,LEAVES:3)
Block(-6,30,-9,LEAVES:3)
Block(-6,31,-9,LEAVES:3)
Block(-6,39,-4,LEAVES:3)
Block(-6,39,-2,LEAVES:3)
Block(-6,39,0,LEAVES:3)
Block(-6,40,-6,LEAVES:3)
Block(-6,40,-5,LEAVES:3)
Block(-6,40,-4,17:15)
Block(-6,40,-3,LEAVES:3)
Block(-6,40,-2,LEAVES:3)
Block(-6,40,-1,LEAVES:3)
Block(-6,40,1,LEAVES:3)
Block(-6,40,2,LEAVES:3)
Block(-6,41,-5,LEAVES:3)
Block(-6,41,-4,LEAVES:3)
Block(-6,41,-2,LEAVES:3)
Block(-6,50,-2,LEAVES:3)
Block(-6,51,-2,LEAVES:3)
Block(-5,-3,-1,17:15)
Block(-5,-3,1,17:15)
Block(-5,7,0,17:15)
Block(-5,8,-1,LEAVES:3)
Block(-5,8,0,17:15)
Block(-5,8,1,17:15)
Block(-5,9,4,LEAVES:3)
Block(-5,9,7,LEAVES:3)
Block(-5,10,-4,LEAVES:3)
Block(-5,10,3,LEAVES:3)
Block(-5,10,4,LEAVES:3)
Block(-5,10,5,17:15)
Block(-5,10,7,LEAVES:3)
Block(-5,11,-7,LEAVES:3)
Block(-5,11,-5,LEAVES:3)
Block(-5,11,-3,LEAVES:3)
Block(-5,11,-2,LEAVES:3)
Block(-5,11,-1,LEAVES:3)
Block(-5,11,0,LEAVES:3)
Block(-5,11,2,LEAVES:3)
Block(-5,11,4,LEAVES:3)
Block(-5,11,5,LEAVES:3)
Block(-5,11,6,17:15)
Block(-5,11,7,LEAVES:3)
Block(-5,11,8,LEAVES:3)
Block(-5,12,-6,LEAVES:3)
Block(-5,12,-5,17:15)
Block(-5,12,-4,LEAVES:3)
Block(-5,12,-2,LEAVES:3)
Block(-5,12,-1,LEAVES:3)
Block(-5,12,0,LEAVES:3)
Block(-5,12,1,LEAVES:3)
Block(-5,12,6,LEAVES:3)
Block(-5,12,7,LEAVES:3)
Block(-5,13,-5,LEAVES:3)
Block(-5,13,0,LEAVES:3)
Block(-5,14,-5,LEAVES:3)
Block(-5,22,1,LEAVES:3)
Block(-5,22,9,LEAVES:3)
Block(-5,23,-3,LEAVES:3)
Block(-5,23,-2,17:15)
Block(-5,23,-1,17:15)
Block(-5,23,0,17:15)
Block(-5,23,1,LEAVES:3)
Block(-5,23,2,LEAVES:3)
Block(-5,23,3,LEAVES:3)
Block(-5,24,-5,LEAVES:3)
Block(-5,24,-4,LEAVES:3)
Block(-5,24,-3,17:15)
Block(-5,24,-2,LEAVES:3)
Block(-5,24,-1,LEAVES:3)
Block(-5,24,0,LEAVES:3)
Block(-5,24,1,LEAVES:3)
Block(-5,24,2,LEAVES:3)
Block(-5,25,-4,LEAVES:3)
Block(-5,25,-3,LEAVES:3)
Block(-5,25,-1,LEAVES:3)
Block(-5,30,-11,LEAVES:3)
Block(-5,30,-8,LEAVES:3)
Block(-5,31,-10,LEAVES:3)
Block(-5,31,-9,LEAVES:3)
Block(-5,31,-8,LEAVES:3)
Block(-5,31,-7,LEAVES:3)
Block(-5,32,-9,LEAVES:3)
Block(-5,33,6,LEAVES:3)
Block(-5,34,6,LEAVES:3)
Block(-5,39,-5,LEAVES:3)
Block(-5,39,-3,LEAVES:3)
Block(-5,39,2,LEAVES:3)
Block(-5,40,-5,LEAVES:3)
Block(-5,40,-4,LEAVES:3)
Block(-5,40,-3,LEAVES:3)
Block(-5,40,-2,LEAVES:3)
Block(-5,40,-1,LEAVES:3)
Block(-5,40,0,LEAVES:3)
Block(-5,40,2,LEAVES:3)
Block(-5,40,3,LEAVES:3)
Block(-5,41,-3,17:15)
Block(-5,41,-2,LEAVES:3)
Block(-5,41,-1,LEAVES:3)
Block(-5,41,1,LEAVES:3)
Block(-5,41,2,LEAVES:3)
Block(-5,42,-3,LEAVES:3)
Block(-5,42,-2,LEAVES:3)
Block(-5,51,-3,LEAVES:3)
Block(-5,51,-2,LEAVES:3)
Block(-5,51,-1,LEAVES:3)
Block(-5,52,-2,LEAVES:3)
Block(-5,52,-1,LEAVES:3)
Block(-4,-3,-4,17:15)
Block(-4,-3,-1,17:15)
Block(-4,-3,1,17:15)
Block(-4,-3,2,17:15)
Block(-4,-2,-1,17:15)
Block(-4,-2,1,17:15)
Block(-4,-1,-1,17:15)
Block(-4,7,0,17:15)
Block(-4,8,-2,LEAVES:3)
Block(-4,8,-1,17:15)
Block(-4,8,0,17:15)
Block(-4,9,3,LEAVES:3)
Block(-4,9,5,LEAVES:3)
Block(-4,9,6,LEAVES:3)
Block(-4,10,-2,LEAVES:3)
Block(-4,10,0,LEAVES:3)
Block(-4,10,3,LEAVES:3)
Block(-4,10,4,LEAVES:3)
Block(-4,10,5,LEAVES:3)
Block(-4,10,6,LEAVES:3)
Block(-4,10,8,LEAVES:3)
Block(-4,11,-12,LEAVES:3)
Block(-4,11,-5,LEAVES:3)
Block(-4,11,-2,LEAVES:3)
Block(-4,11,1,LEAVES:3)
Block(-4,11,4,LEAVES:3)
Block(-4,11,5,LEAVES:3)
Block(-4,11,6,LEAVES:3)
Block(-4,11,7,LEAVES:3)
Block(-4,12,-7,LEAVES:3)
Block(-4,12,-6,LEAVES:3)
Block(-4,12,-5,LEAVES:3)
Block(-4,12,-4,LEAVES:3)
Block(-4,12,0,LEAVES:3)
Block(-4,12,5,LEAVES:3)
Block(-4,13,-6,LEAVES:3)
Block(-4,13,-5,LEAVES:3)
Block(-4,21,7,LEAVES:3)
Block(-4,21,10,LEAVES:3)
Block(-4,22,-2,LEAVES:3)
Block(-4,22,-1,17:15)
Block(-4,22,2,LEAVES:3)
Block(-4,22,8,LEAVES:3)
Block(-4,22,9,LEAVES:3)
Block(-4,22,10,LEAVES:3)
Block(-4,23,-5,LEAVES:3)
Block(-4,23,-3,LEAVES:3)
Block(-4,23,-2,LEAVES:3)
Block(-4,23,-1,17:15)
Block(-4,23,0,LEAVES:3)
Block(-4,23,1,LEAVES:3)
Block(-4,23,2,LEAVES:3)
Block(-4,23,9,LEAVES:3)
Block(-4,24,-4,LEAVES:3)
Block(-4,24,-3,LEAVES:3)
Block(-4,24,-2,LEAVES:3)
Block(-4,24,-1,LEAVES:3)
Block(-4,24,1,LEAVES:3)
Block(-4,30,-10,LEAVES:3)
Block(-4,30,-8,LEAVES:3)
Block(-4,31,-11,LEAVES:3)
Block(-4,31,-10,LEAVES:3)
Block(-4,31,-9,17:15)
Block(-4,31,-8,LEAVES:3)
Block(-4,31,-7,LEAVES:3)
Block(-4,31,-6,LEAVES:3)
Block(-4,32,-10,LEAVES:3)
Block(-4,32,-9,LEAVES:3)
Block(-4,32,-7,LEAVES:3)
Block(-4,33,5,LEAVES:3)
Block(-4,33,8,LEAVES:3)
Block(-4,34,4,LEAVES:3)
Block(-4,34,5,LEAVES:3)
Block(-4,34,6,LEAVES:3)
Block(-4,34,7,LEAVES:3)
Block(-4,35,6,LEAVES:3)
Block(-4,39,-4,LEAVES:3)
Block(-4,39,-2,LEAVES:3)
Block(-4,40,-4,LEAVES:3)
Block(-4,40,-3,LEAVES:3)
Block(-4,40,-2,17:15)
Block(-4,40,-1,LEAVES:3)
Block(-4,40,1,LEAVES:3)
Block(-4,40,2,17:15)
Block(-4,40,3,LEAVES:3)
Block(-4,41,-3,LEAVES:3)
Block(-4,41,-2,LEAVES:3)
Block(-4,41,1,LEAVES:3)
Block(-4,41,2,LEAVES:3)
Block(-4,41,3,LEAVES:3)
Block(-4,44,3,LEAVES:3)
Block(-4,45,3,LEAVES:3)
Block(-4,46,-6,LEAVES:3)
Block(-4,47,-6,LEAVES:3)
Block(-4,47,-4,LEAVES:3)
Block(-4,48,-5,LEAVES:3)
Block(-4,50,-3,LEAVES:3)
Block(-4,50,-1,LEAVES:3)
Block(-4,50,1,LEAVES:3)
Block(-4,51,-3,LEAVES:3)
Block(-4,51,-2,LEAVES:3)
Block(-4,51,-1,17:15)
Block(-4,51,0,LEAVES:3)
Block(-4,51,1,LEAVES:3)
Block(-4,52,-2,LEAVES:3)
Block(-4,52,-1,LEAVES:3)
Block(-4,52,0,LEAVES:3)
Block(-4,53,-1,LEAVES:3)
Block(-3,-3,-5,17:15)
Block(-3,-3,-4,17:15)
Block(-3,-3,-3,17:15)
Block(-3,-3,3,17:15)
Block(-3,-2,-4,17:15)
Block(-3,-2,-3,17:15)
Block(-3,-2,-1,17:15)
Block(-3,-2,1,17:15)
Block(-3,-2,3,17:15)
Block(-3,-1,-3,17:15)
Block(-3,-1,-2,17:15)
Block(-3,-1,-1,17:15)
Block(-3,-1,1,17:15)
Block(-3,0,-2,17:15)
Block(-3,0,-1,17:15)
Block(-3,0,1,17:15)
Block(-3,1,-2,17:15)
Block(-3,1,1,17:15)
Block(-3,2,-2,17:15)
Block(-3,2,1,17:15)
Block(-3,3,1,17:15)
Block(-3,7,-1,17:15)
Block(-3,7,0,17:15)
Block(-3,9,4,LEAVES:3)
Block(-3,10,-13,LEAVES:3)
Block(-3,10,-10,LEAVES:3)
Block(-3,10,4,LEAVES:3)
Block(-3,10,5,LEAVES:3)
Block(-3,10,6,LEAVES:3)
Block(-3,11,-13,LEAVES:3)
Block(-3,11,-12,LEAVES:3)
Block(-3,11,-11,LEAVES:3)
Block(-3,11,-6,LEAVES:3)
Block(-3,11,5,LEAVES:3)
Block(-3,12,-12,LEAVES:3)
Block(-3,12,-6,LEAVES:3)
Block(-3,12,-5,LEAVES:3)
Block(-3,12,-4,LEAVES:3)
Block(-3,13,-5,LEAVES:3)
Block(-3,20,8,LEAVES:3)
Block(-3,21,-13,LEAVES:3)
Block(-3,21,6,LEAVES:3)
Block(-3,21,7,LEAVES:3)
Block(-3,21,9,LEAVES:3)
Block(-3,21,12,LEAVES:3)
Block(-3,22,-3,LEAVES:3)
Block(-3,22,-1,17:15)
Block(-3,22,0,LEAVES:3)
Block(-3,22,7,LEAVES:3)
Block(-3,22,8,17:15)
Block(-3,22,9,LEAVES:3)
Block(-3,22,10,LEAVES:3)
Block(-3,22,11,LEAVES:3)
Block(-3,23,-2,LEAVES:3)
Block(-3,23,-1,LEAVES:3)
Block(-3,23,0,LEAVES:3)
Block(-3,23,1,LEAVES:3)
Block(-3,23,8,LEAVES:3)
Block(-3,23,9,LEAVES:3)
Block(-3,23,10,LEAVES:3)
Block(-3,24,-1,LEAVES:3)
Block(-3,24,9,LEAVES:3)
Block(-3,30,-12,LEAVES:3)
Block(-3,30,-7,LEAVES:3)
Block(-3,31,-11,LEAVES:3)
Block(-3,31,-10,LEAVES:3)
Block(-3,31,-9,LEAVES:3)
Block(-3,31,-8,17:15)
Block(-3,31,-7,LEAVES:3)
Block(-3,31,-6,LEAVES:3)
Block(-3,31,-5,LEAVES:3)
Block(-3,32,-8,LEAVES:3)
Block(-3,32,-7,LEAVES:3)
Block(-3,32,-6,LEAVES:3)
Block(-3,33,-8,LEAVES:3)
Block(-3,33,5,LEAVES:3)
Block(-3,33,7,LEAVES:3)
Block(-3,34,3,LEAVES:3)
Block(-3,34,4,LEAVES:3)
Block(-3,34,5,LEAVES:3)
Block(-3,34,6,17:15)
Block(-3,34,7,LEAVES:3)
Block(-3,34,8,LEAVES:3)
Block(-3,35,4,LEAVES:3)
Block(-3,35,6,LEAVES:3)
Block(-3,35,7,LEAVES:3)
Block(-3,38,-2,LEAVES:3)
Block(-3,38,-1,LEAVES:3)
Block(-3,38,3,LEAVES:3)
Block(-3,39,-4,LEAVES:3)
Block(-3,39,-2,17:15)
Block(-3,39,0,LEAVES:3)
Block(-3,39,2,LEAVES:3)
Block(-3,40,-4,LEAVES:3)
Block(-3,40,-3,LEAVES:3)
Block(-3,40,-2,LEAVES:3)
Block(-3,40,-1,LEAVES:3)
Block(-3,40,0,LEAVES:3)
Block(-3,40,1,17:15)
Block(-3,40,2,LEAVES:3)
Block(-3,40,3,LEAVES:3)
Block(-3,41,-2,LEAVES:3)
Block(-3,41,0,LEAVES:3)
Block(-3,41,1,LEAVES:3)
Block(-3,42,1,LEAVES:3)
Block(-3,44,5,LEAVES:3)
Block(-3,45,2,LEAVES:3)
Block(-3,45,3,LEAVES:3)
Block(-3,45,4,LEAVES:3)
Block(-3,45,5,LEAVES:3)
Block(-3,46,3,LEAVES:3)
Block(-3,46,4,LEAVES:3)
Block(-3,47,-5,LEAVES:3)
Block(-3,48,-8,LEAVES:3)
Block(-3,48,-6,LEAVES:3)
Block(-3,48,-5,LEAVES:3)
Block(-3,48,-4,LEAVES:3)
Block(-3,49,-7,LEAVES:3)
Block(-3,49,-5,LEAVES:3)
Block(-3,49,-4,LEAVES:3)
Block(-3,50,3,LEAVES:3)
Block(-3,51,-2,LEAVES:3)
Block(-3,51,-1,LEAVES:3)
Block(-3,51,0,17:15)
Block(-3,51,1,LEAVES:3)
Block(-3,51,2,LEAVES:3)
Block(-3,52,-1,LEAVES:3)
Block(-3,52,0,LEAVES:3)
Block(-3,53,2,LEAVES:3)
Block(-3,54,-2,LEAVES:3)
Block(-2,-2,3,17:15)
Block(-2,-1,2,17:15)
Block(-2,-1,3,17:15)
Block(-2,0,-2,17:15)
Block(-2,0,1,17:15)
Block(-2,0,2,17:15)
Block(-2,0,3,17:15)
Block(-2,1,-2,17:15)
Block(-2,1,1,17:15)
Block(-2,1,2,17:15)
Block(-2,1,3,17:15)
Block(-2,2,-2,17:15)
Block(-2,2,-1,17:15)
Block(-2,2,1,17:15)
Block(-2,2,2,17:15)
Block(-2,3,-2,17:15)
Block(-2,3,-1,17:15)
Block(-2,3,1,17:15)
Block(-2,3,2,17:15)
Block(-2,4,-2,17:15)
Block(-2,4,-1,17:15)
Block(-2,4,1,17:15)
Block(-2,5,-1,17:15)
Block(-2,6,-1,17:15)
Block(-2,7,-1,17:15)
Block(-2,8,-1,17:15)
Block(-2,9,-11,LEAVES:3)
Block(-2,9,-1,17:15)
Block(-2,9,6,LEAVES:3)
Block(-2,10,-15,LEAVES:3)
Block(-2,10,-12,LEAVES:3)
Block(-2,10,-10,LEAVES:3)
Block(-2,10,-9,LEAVES:3)
Block(-2,10,-1,17:15)
Block(-2,10,5,LEAVES:3)
Block(-2,11,-14,LEAVES:3)
Block(-2,11,-13,LEAVES:3)
Block(-2,11,-12,LEAVES:3)
Block(-2,11,-11,17:15)
Block(-2,11,-10,LEAVES:3)
Block(-2,11,-4,LEAVES:3)
Block(-2,11,-1,17:15)
Block(-2,12,-13,LEAVES:3)
Block(-2,12,-12,LEAVES:3)
Block(-2,12,-11,LEAVES:3)
Block(-2,12,-5,LEAVES:3)
Block(-2,12,-1,17:15)
Block(-2,13,-12,LEAVES:3)
Block(-2,13,-1,17:15)
Block(-2,14,-1,17:15)
Block(-2,15,-1,17:15)
Block(-2,16,-1,17:15)
Block(-2,17,-1,17:15)
Block(-2,19,8,LEAVES:3)
Block(-2,20,-13,LEAVES:3)
Block(-2,20,-11,LEAVES:3)
Block(-2,20,3,LEAVES:3)
Block(-2,20,7,LEAVES:3)
Block(-2,21,-14,LEAVES:3)
Block(-2,21,-13,LEAVES:3)
Block(-2,21,-12,LEAVES:3)
Block(-2,21,-11,LEAVES:3)
Block(-2,21,5,LEAVES:3)
Block(-2,21,6,LEAVES:3)
Block(-2,21,7,17:15)
Block(-2,21,10,LEAVES:3)
Block(-2,22,-13,LEAVES:3)
Block(-2,22,-12,LEAVES:3)
Block(-2,22,-1,17:15)
Block(-2,22,7,LEAVES:3)
Block(-2,22,8,LEAVES:3)
Block(-2,22,9,LEAVES:3)
Block(-2,22,10,LEAVES:3)
Block(-2,22,11,LEAVES:3)
Block(-2,23,8,LEAVES:3)
Block(-2,23,9,LEAVES:3)
Block(-2,29,-8,LEAVES:3)
Block(-2,30,-9,LEAVES:3)
Block(-2,30,-8,17:15)
Block(-2,30,-7,LEAVES:3)
Block(-2,30,-6,LEAVES:3)
Block(-2,31,-12,LEAVES:3)
Block(-2,31,-11,LEAVES:3)
Block(-2,31,-10,LEAVES:3)
Block(-2,31,-8,LEAVES:3)
Block(-2,31,-6,LEAVES:3)
Block(-2,32,-8,LEAVES:3)
Block(-2,33,4,LEAVES:3)
Block(-2,33,9,LEAVES:3)
Block(-2,34,2,LEAVES:3)
Block(-2,34,3,LEAVES:3)
Block(-2,34,4,LEAVES:3)
Block(-2,34,5,17:15)
Block(-2,34,6,LEAVES:3)
Block(-2,34,7,LEAVES:3)
Block(-2,34,8,LEAVES:3)
Block(-2,35,-7,LEAVES:3)
Block(-2,35,3,LEAVES:3)
Block(-2,35,4,LEAVES:3)
Block(-2,35,5,LEAVES:3)
Block(-2,36,-8,LEAVES:3)
Block(-2,36,5,LEAVES:3)
Block(-2,38,1,LEAVES:3)
Block(-2,39,-3,LEAVES:3)
Block(-2,39,-2,17:15)
Block(-2,39,-1,17:15)
Block(-2,39,0,17:15)
Block(-2,39,1,LEAVES:3)
Block(-2,39,2,LEAVES:3)
Block(-2,39,3,LEAVES:3)
Block(-2,40,-5,LEAVES:3)
Block(-2,40,-4,LEAVES:3)
Block(-2,40,-3,17:15)
Block(-2,40,-2,LEAVES:3)
Block(-2,40,-1,LEAVES:3)
Block(-2,40,0,LEAVES:3)
Block(-2,40,1,LEAVES:3)
Block(-2,40,2,LEAVES:3)
Block(-2,41,-4,LEAVES:3)
Block(-2,41,-3,LEAVES:3)
Block(-2,41,-1,LEAVES:3)
Block(-2,44,3,LEAVES:3)
Block(-2,45,2,LEAVES:3)
Block(-2,45,3,17:15)
Block(-2,45,4,LEAVES:3)
Block(-2,45,5,LEAVES:3)
Block(-2,45,6,LEAVES:3)
Block(-2,46,3,LEAVES:3)
Block(-2,46,4,LEAVES:3)
Block(-2,46,5,LEAVES:3)
Block(-2,47,-6,LEAVES:3)
Block(-2,47,4,LEAVES:3)
Block(-2,48,-6,LEAVES:3)
Block(-2,48,-5,17:15)
Block(-2,48,-4,LEAVES:3)
Block(-2,49,-8,LEAVES:3)
Block(-2,49,-7,LEAVES:3)
Block(-2,49,-6,17:15)
Block(-2,49,-5,LEAVES:3)
Block(-2,49,-4,LEAVES:3)
Block(-2,49,-3,LEAVES:3)
Block(-2,50,-7,LEAVES:3)
Block(-2,50,-6,LEAVES:3)
Block(-2,50,-4,LEAVES:3)
Block(-2,50,0,17:15)
Block(-2,50,1,LEAVES:3)
Block(-2,51,-1,LEAVES:3)
Block(-2,51,0,LEAVES:3)
Block(-2,51,1,17:15)
Block(-2,51,2,LEAVES:3)
Block(-2,51,3,LEAVES:3)
Block(-2,52,0,LEAVES:3)
Block(-2,52,1,LEAVES:3)
Block(-2,52,2,LEAVES:3)
Block(-2,53,1,LEAVES:3)
Block(-2,53,2,LEAVES:3)
Block(-2,53,3,LEAVES:3)
Block(-2,54,-2,LEAVES:3)
Block(-2,54,-1,LEAVES:3)
Block(-2,54,2,LEAVES:3)
Block(-2,55,-2,LEAVES:3)
Block(-1,-3,-3,17:15)
Block(-1,-3,-1,17:15)
Block(-1,-3,0,17:15)
Block(-1,-3,4,17:15)
Block(-1,-2,-3,17:15)
Block(-1,-2,-2,17:15)
Block(-1,-2,-1,17:15)
Block(-1,-2,0,17:15)
Block(-1,-2,4,17:15)
Block(-1,-1,-3,17:15)
Block(-1,-1,-2,17:15)
Block(-1,-1,-1,17:15)
Block(-1,-1,4,17:15)
Block(-1,0,-2,17:15)
Block(-1,0,0,17:15)
Block(-1,1,-2,17:15)
Block(-1,1,0,17:15)
Block(-1,1,1,17:15)
Block(-1,2,-2,17:15)
Block(-1,2,0,17:15)
Block(-1,2,1,17:15)
Block(-1,3,-2,17:15)
Block(-1,3,-1,17:15)
Block(-1,3,0,17:15)
Block(-1,3,1,17:15)
Block(-1,4,-2,17:15)
Block(-1,4,-1,17:15)
Block(-1,4,0,17:15)
Block(-1,4,1,17:15)
Block(-1,5,-2,17:15)
Block(-1,5,-1,17:15)
Block(-1,5,0,17:15)
Block(-1,5,1,17:15)
Block(-1,6,-2,17:15)
Block(-1,6,-1,17:15)
Block(-1,6,0,17:15)
Block(-1,6,1,17:15)
Block(-1,7,-2,17:15)
Block(-1,7,-1,17:15)
Block(-1,7,0,17:15)
Block(-1,7,1,17:15)
Block(-1,8,-11,LEAVES:3)
Block(-1,8,-2,17:15)
Block(-1,8,-1,17:15)
Block(-1,8,0,17:15)
Block(-1,9,-10,LEAVES:3)
Block(-1,9,-6,LEAVES:3)
Block(-1,9,-2,17:15)
Block(-1,9,-1,17:15)
Block(-1,9,0,17:15)
Block(-1,10,-13,LEAVES:3)
Block(-1,10,-10,17:15)
Block(-1,10,-9,LEAVES:3)
Block(-1,10,-8,LEAVES:3)
Block(-1,10,-2,17:15)
Block(-1,10,-1,17:15)
Block(-1,10,0,17:15)
Block(-1,11,-14,LEAVES:3)
Block(-1,11,-13,LEAVES:3)
Block(-1,11,-12,LEAVES:3)
Block(-1,11,-11,LEAVES:3)
Block(-1,11,-10,LEAVES:3)
Block(-1,11,-2,17:15)
Block(-1,11,-1,17:15)
Block(-1,11,0,17:15)
Block(-1,12,-12,LEAVES:3)
Block(-1,12,-11,LEAVES:3)
Block(-1,12,-2,17:15)
Block(-1,12,-1,17:15)
Block(-1,12,0,17:15)
Block(-1,13,-2,17:15)
Block(-1,13,-1,17:15)
Block(-1,13,0,17:15)
Block(-1,14,-2,17:15)
Block(-1,14,-1,17:15)
Block(-1,14,0,17:15)
Block(-1,15,-2,17:15)
Block(-1,15,-1,17:15)
Block(-1,15,0,17:15)
Block(-1,16,-2,17:15)
Block(-1,16,-1,17:15)
Block(-1,16,0,17:15)
Block(-1,17,-2,17:15)
Block(-1,17,-1,17:15)
Block(-1,17,0,17:15)
Block(-1,18,-2,17:15)
Block(-1,18,-1,17:15)
Block(-1,18,0,LEAVES:3)
Block(-1,19,-2,17:15)
Block(-1,19,-1,17:15)
Block(-1,19,0,17:15)
Block(-1,19,1,LEAVES:3)
Block(-1,20,-14,LEAVES:3)
Block(-1,20,-12,LEAVES:3)
Block(-1,20,-2,17:15)
Block(-1,20,-1,17:15)
Block(-1,20,0,17:15)
Block(-1,20,2,LEAVES:3)
Block(-1,20,3,LEAVES:3)
Block(-1,20,4,LEAVES:3)
Block(-1,21,-15,LEAVES:3)
Block(-1,21,-14,LEAVES:3)
Block(-1,21,-13,LEAVES:3)
Block(-1,21,-12,17:15)
Block(-1,21,-11,17:15)
Block(-1,21,-10,LEAVES:3)
Block(-1,21,-2,17:15)
Block(-1,21,-1,17:15)
Block(-1,21,0,17:15)
Block(-1,21,3,LEAVES:3)
Block(-1,21,4,LEAVES:3)
Block(-1,21,5,LEAVES:3)
Block(-1,21,6,17:15)
Block(-1,21,7,LEAVES:3)
Block(-1,21,8,LEAVES:3)
Block(-1,22,-14,LEAVES:3)
Block(-1,22,-13,LEAVES:3)
Block(-1,22,-12,LEAVES:3)
Block(-1,22,-11,LEAVES:3)
Block(-1,22,-2,17:15)
Block(-1,22,-1,17:15)
Block(-1,22,0,17:15)
Block(-1,22,5,LEAVES:3)
Block(-1,22,6,LEAVES:3)
Block(-1,22,10,LEAVES:3)
Block(-1,23,-2,17:15)
Block(-1,23,-1,17:15)
Block(-1,23,0,17:15)
Block(-1,24,-2,17:15)
Block(-1,24,-1,17:15)
Block(-1,24,0,17:15)
Block(-1,25,-2,17:15)
Block(-1,25,-1,17:15)
Block(-1,25,0,17:15)
Block(-1,26,-2,17:15)
Block(-1,26,-1,17:15)
Block(-1,26,0,17:15)
Block(-1,27,-2,17:15)
Block(-1,27,-1,17:15)
Block(-1,27,0,17:15)
Block(-1,28,-4,17:15)
Block(-1,28,-3,17:15)
Block(-1,28,-2,17:15)
Block(-1,28,-1,17:15)
Block(-1,28,0,17:15)
Block(-1,29,-7,17:15)
Block(-1,29,-6,LEAVES:3)
Block(-1,29,-4,LEAVES:3)
Block(-1,29,-2,17:15)
Block(-1,29,-1,17:15)
Block(-1,30,-12,LEAVES:3)
Block(-1,30,-10,LEAVES:3)
Block(-1,30,-9,17:15)
Block(-1,30,-7,17:15)
Block(-1,30,-6,LEAVES:3)
Block(-1,30,-5,LEAVES:3)
Block(-1,30,-2,17:15)
Block(-1,30,-1,17:15)
Block(-1,31,-13,LEAVES:3)
Block(-1,31,-12,LEAVES:3)
Block(-1,31,-11,LEAVES:3)
Block(-1,31,-10,17:15)
Block(-1,31,-9,LEAVES:3)
Block(-1,31,-7,LEAVES:3)
Block(-1,31,-6,LEAVES:3)
Block(-1,31,-1,17:15)
Block(-1,32,-12,LEAVES:3)
Block(-1,32,-11,LEAVES:3)
Block(-1,32,-10,LEAVES:3)
Block(-1,32,-9,LEAVES:3)
Block(-1,32,-1,17:15)
Block(-1,32,5,LEAVES:3)
Block(-1,33,-10,LEAVES:3)
Block(-1,33,-1,17:15)
Block(-1,33,3,LEAVES:3)
Block(-1,33,4,LEAVES:3)
Block(-1,33,5,17:15)
Block(-1,33,6,LEAVES:3)
Block(-1,34,-9,LEAVES:3)
Block(-1,34,-1,17:15)
Block(-1,34,3,LEAVES:3)
Block(-1,34,5,LEAVES:3)
Block(-1,34,7,LEAVES:3)
Block(-1,34,8,LEAVES:3)
Block(-1,34,9,LEAVES:3)
Block(-1,35,-9,LEAVES:3)
Block(-1,35,-1,17:15)
Block(-1,35,5,LEAVES:3)
Block(-1,36,-9,LEAVES:3)
Block(-1,36,-8,LEAVES:3)
Block(-1,36,-7,LEAVES:3)
Block(-1,36,-1,17:15)
Block(-1,37,-8,LEAVES:3)
Block(-1,37,-1,17:15)
Block(-1,38,-2,LEAVES:3)
Block(-1,38,-1,17:15)
Block(-1,38,2,LEAVES:3)
Block(-1,39,-5,LEAVES:3)
Block(-1,39,-3,LEAVES:3)
Block(-1,39,-2,LEAVES:3)
Block(-1,39,-1,17:15)
Block(-1,39,0,LEAVES:3)
Block(-1,39,1,LEAVES:3)
Block(-1,39,2,LEAVES:3)
Block(-1,40,-4,LEAVES:3)
Block(-1,40,-3,LEAVES:3)
Block(-1,40,-2,LEAVES:3)
Block(-1,40,-1,LEAVES:3)
Block(-1,40,1,LEAVES:3)
Block(-1,43,5,LEAVES:3)
Block(-1,44,4,LEAVES:3)
Block(-1,44,6,LEAVES:3)
Block(-1,45,1,LEAVES:3)
Block(-1,45,2,17:15)
Block(-1,45,3,LEAVES:3)
Block(-1,45,4,LEAVES:3)
Block(-1,45,5,LEAVES:3)
Block(-1,46,2,LEAVES:3)
Block(-1,47,-5,LEAVES:3)
Block(-1,48,-7,LEAVES:3)
Block(-1,48,-4,17:15)
Block(-1,49,-7,LEAVES:3)
Block(-1,49,-6,LEAVES:3)
Block(-1,49,-5,LEAVES:3)
Block(-1,49,-4,LEAVES:3)
Block(-1,49,-3,LEAVES:3)
Block(-1,50,-4,LEAVES:3)
Block(-1,50,-1,17:15)
Block(-1,50,0,LEAVES:3)
Block(-1,50,2,LEAVES:3)
Block(-1,51,-2,LEAVES:3)
Block(-1,51,-1,LEAVES:3)
Block(-1,51,0,LEAVES:3)
Block(-1,51,1,LEAVES:3)
Block(-1,51,2,LEAVES:3)
Block(-1,52,-2,LEAVES:3)
Block(-1,52,-1,LEAVES:3)
Block(-1,52,0,LEAVES:3)
Block(-1,53,-4,LEAVES:3)
Block(-1,53,-3,LEAVES:3)
Block(-1,53,-2,LEAVES:3)
Block(-1,53,1,LEAVES:3)
Block(-1,53,2,17:15)
Block(-1,53,3,LEAVES:3)
Block(-1,54,-3,LEAVES:3)
Block(-1,54,-2,17:15)
Block(-1,54,-1,LEAVES:3)
Block(-1,54,2,LEAVES:3)
Block(-1,55,-2,LEAVES:3)
Block(0,-3,-3,17:15)
Block(0,-2,-1,17:15)
Block(0,-1,-4,17:15)
Block(0,0,-4,17:15)
Block(0,0,0,17:15)
Block(0,1,-4,17:15)
Block(0,1,-3,17:15)
Block(0,1,0,17:15)
Block(0,2,-4,17:15)
Block(0,2,-3,17:15)
Block(0,2,-1,17:15)
Block(0,2,0,17:15)
Block(0,3,-4,17:15)
Block(0,3,-3,17:15)
Block(0,3,-2,17:15)
Block(0,3,-1,17:15)
Block(0,3,0,17:15)
Block(0,4,-3,17:15)
Block(0,4,-2,17:15)
Block(0,4,-1,17:15)
Block(0,4,0,17:15)
Block(0,4,1,17:15)
Block(0,5,-3,17:15)
Block(0,5,-2,17:15)
Block(0,5,-1,17:15)
Block(0,5,0,17:15)
Block(0,5,1,17:15)
Block(0,6,-3,17:15)
Block(0,6,-2,17:15)
Block(0,6,-1,17:15)
Block(0,6,0,17:15)
Block(0,6,1,17:15)
Block(0,7,-3,LEAVES:3)
Block(0,7,-2,17:15)
Block(0,7,-1,17:15)
Block(0,7,0,17:15)
Block(0,7,1,17:15)
Block(0,8,-4,LEAVES:3)
Block(0,8,-3,17:15)
Block(0,8,-2,17:15)
Block(0,8,-1,17:15)
Block(0,8,0,17:15)
Block(0,8,1,17:15)
Block(0,9,-7,LEAVES:3)
Block(0,9,-6,LEAVES:3)
Block(0,9,-5,LEAVES:3)
Block(0,9,-3,17:15)
Block(0,9,-2,17:15)
Block(0,9,-1,17:15)
Block(0,9,0,17:15)
Block(0,9,1,17:15)
Block(0,10,-11,LEAVES:3)
Block(0,10,-10,LEAVES:3)
Block(0,10,-9,17:15)
Block(0,10,-8,LEAVES:3)
Block(0,10,-7,LEAVES:3)
Block(0,10,-6,LEAVES:3)
Block(0,10,-3,17:15)
Block(0,10,-2,17:15)
Block(0,10,-1,17:15)
Block(0,10,0,17:15)
Block(0,10,1,17:15)
Block(0,11,-13,LEAVES:3)
Block(0,11,-9,LEAVES:3)
Block(0,11,-8,LEAVES:3)
Block(0,11,-3,17:15)
Block(0,11,-2,17:15)
Block(0,11,-1,17:15)
Block(0,11,0,17:15)
Block(0,11,1,17:15)
Block(0,12,-3,17:15)
Block(0,12,-2,17:15)
Block(0,12,-1,17:15)
Block(0,12,0,17:15)
Block(0,12,1,17:15)
Block(0,13,-3,17:15)
Block(0,13,-2,17:15)
Block(0,13,-1,17:15)
Block(0,13,0,17:15)
Block(0,13,1,17:15)
Block(0,14,-3,17:15)
Block(0,14,-2,17:15)
Block(0,14,-1,17:15)
Block(0,14,0,17:15)
Block(0,14,1,17:15)
Block(0,15,-3,17:15)
Block(0,15,-2,17:15)
Block(0,15,-1,17:15)
Block(0,15,0,17:15)
Block(0,15,1,17:15)
Block(0,16,-3,17:15)
Block(0,16,-2,17:15)
Block(0,16,-1,17:15)
Block(0,16,0,17:15)
Block(0,16,1,17:15)
Block(0,17,-3,17:15)
Block(0,17,-2,17:15)
Block(0,17,-1,17:15)
Block(0,17,0,17:15)
Block(0,17,1,17:15)
Block(0,18,-3,17:15)
Block(0,18,-2,17:15)
Block(0,18,-1,17:15)
Block(0,18,0,17:15)
Block(0,19,-8,LEAVES:3)
Block(0,19,-3,17:15)
Block(0,19,-2,17:15)
Block(0,19,-1,17:15)
Block(0,19,0,17:15)
Block(0,19,1,17:15)
Block(0,19,3,LEAVES:3)
Block(0,20,-15,LEAVES:3)
Block(0,20,-10,LEAVES:3)
Block(0,20,-9,LEAVES:3)
Block(0,20,-3,17:15)
Block(0,20,-2,17:15)
Block(0,20,-1,17:15)
Block(0,20,0,17:15)
Block(0,20,1,LEAVES:3)
Block(0,20,2,LEAVES:3)
Block(0,20,3,LEAVES:3)
Block(0,20,4,LEAVES:3)
Block(0,20,7,LEAVES:3)
Block(0,21,-14,LEAVES:3)
Block(0,21,-13,LEAVES:3)
Block(0,21,-12,LEAVES:3)
Block(0,21,-11,LEAVES:3)
Block(0,21,-10,17:15)
Block(0,21,-3,17:15)
Block(0,21,-2,17:15)
Block(0,21,-1,17:15)
Block(0,21,0,17:15)
Block(0,21,4,LEAVES:3)
Block(0,21,5,LEAVES:3)
Block(0,21,6,17:15)
Block(0,21,7,LEAVES:3)
Block(0,21,8,LEAVES:3)
Block(0,21,13,LEAVES:3)
Block(0,22,-11,LEAVES:3)
Block(0,22,-10,LEAVES:3)
Block(0,22,-2,17:15)
Block(0,22,-1,17:15)
Block(0,22,0,17:15)
Block(0,22,5,LEAVES:3)
Block(0,22,6,LEAVES:3)
Block(0,22,7,LEAVES:3)
Block(0,22,8,LEAVES:3)
Block(0,22,9,LEAVES:3)
Block(0,22,10,LEAVES:3)
Block(0,22,11,LEAVES:3)
Block(0,22,12,LEAVES:3)
Block(0,23,-2,17:15)
Block(0,23,-1,17:15)
Block(0,23,0,17:15)
Block(0,23,5,LEAVES:3)
Block(0,23,6,LEAVES:3)
Block(0,23,7,LEAVES:3)
Block(0,23,10,LEAVES:3)
Block(0,24,-2,17:15)
Block(0,24,-1,17:15)
Block(0,24,0,17:15)
Block(0,24,6,LEAVES:3)
Block(0,25,-2,17:15)
Block(0,25,-1,17:15)
Block(0,25,0,17:15)
Block(0,26,-2,17:15)
Block(0,26,-1,17:15)
Block(0,26,0,17:15)
Block(0,27,-2,17:15)
Block(0,27,-1,17:15)
Block(0,27,0,17:15)
Block(0,28,-6,LEAVES:3)
Block(0,28,-4,17:15)
Block(0,28,-2,17:15)
Block(0,28,-1,17:15)
Block(0,28,0,17:15)
Block(0,29,-9,LEAVES:3)
Block(0,29,-8,LEAVES:3)
Block(0,29,-6,17:15)
Block(0,29,-5,17:15)
Block(0,29,-4,17:15)
Block(0,29,-3,LEAVES:3)
Block(0,29,-2,17:15)
Block(0,29,-1,17:15)
Block(0,29,0,17:15)
Block(0,30,-9,LEAVES:3)
Block(0,30,-8,LEAVES:3)
Block(0,30,-7,LEAVES:3)
Block(0,30,-6,LEAVES:3)
Block(0,30,-5,LEAVES:3)
Block(0,30,-4,LEAVES:3)
Block(0,30,-2,17:15)
Block(0,30,-1,17:15)
Block(0,30,0,17:15)
Block(0,31,-12,LEAVES:3)
Block(0,31,-11,LEAVES:3)
Block(0,31,-10,LEAVES:3)
Block(0,31,-8,LEAVES:3)
Block(0,31,-7,LEAVES:3)
Block(0,31,-5,LEAVES:3)
Block(0,31,-2,17:15)
Block(0,31,-1,17:15)
Block(0,31,0,17:15)
Block(0,31,1,17:15)
Block(0,32,-10,LEAVES:3)
Block(0,32,-7,LEAVES:3)
Block(0,32,-2,17:15)
Block(0,32,-1,17:15)
Block(0,32,0,17:15)
Block(0,32,1,LEAVES:3)
Block(0,32,3,LEAVES:3)
Block(0,32,4,17:15)
Block(0,33,-2,17:15)
Block(0,33,-1,17:15)
Block(0,33,0,17:15)
Block(0,33,2,LEAVES:3)
Block(0,33,3,LEAVES:3)
Block(0,33,4,17:15)
Block(0,33,6,17:15)
Block(0,33,7,LEAVES:3)
Block(0,33,9,LEAVES:3)
Block(0,34,-2,17:15)
Block(0,34,-1,17:15)
Block(0,34,0,17:15)
Block(0,34,3,LEAVES:3)
Block(0,34,4,LEAVES:3)
Block(0,34,6,LEAVES:3)
Block(0,34,7,17:15)
Block(0,34,8,LEAVES:3)
Block(0,34,9,LEAVES:3)
Block(0,34,10,LEAVES:3)
Block(0,35,-8,LEAVES:3)
Block(0,35,-6,LEAVES:3)
Block(0,35,-1,17:15)
Block(0,35,0,17:15)
Block(0,35,6,LEAVES:3)
Block(0,35,7,LEAVES:3)
Block(0,35,8,LEAVES:3)
Block(0,35,9,LEAVES:3)
Block(0,36,-9,LEAVES:3)
Block(0,36,-8,17:15)
Block(0,36,-7,LEAVES:3)
Block(0,36,-1,17:15)
Block(0,36,0,17:15)
Block(0,36,7,LEAVES:3)
Block(0,37,-9,LEAVES:3)
Block(0,37,-8,LEAVES:3)
Block(0,37,-1,17:15)
Block(0,37,0,17:15)
Block(0,38,-8,LEAVES:3)
Block(0,38,-1,17:15)
Block(0,38,0,17:15)
Block(0,39,-1,17:15)
Block(0,39,0,17:15)
Block(0,40,-1,17:15)
Block(0,40,0,17:15)
Block(0,41,-1,17:15)
Block(0,41,0,17:15)
Block(0,42,-1,17:15)
Block(0,42,0,17:15)
Block(0,43,-1,17:15)
Block(0,43,0,17:15)
Block(0,44,-1,17:15)
Block(0,44,0,17:15)
Block(0,44,1,17:15)
Block(0,44,2,17:15)
Block(0,44,3,17:15)
Block(0,44,5,LEAVES:3)
Block(0,45,-1,17:15)
Block(0,45,0,17:15)
Block(0,45,1,LEAVES:3)
Block(0,45,2,LEAVES:3)
Block(0,45,3,LEAVES:3)
Block(0,45,4,LEAVES:3)
Block(0,46,-2,17:15)
Block(0,46,-1,17:15)
Block(0,46,0,17:15)
Block(0,47,-3,17:15)
Block(0,47,-2,17:15)
Block(0,47,-1,17:15)
Block(0,47,0,17:15)
Block(0,48,-4,LEAVES:3)
Block(0,48,-3,17:15)
Block(0,48,-1,17:15)
Block(0,49,-5,LEAVES:3)
Block(0,49,-4,LEAVES:3)
Block(0,49,-3,LEAVES:3)
Block(0,49,-2,LEAVES:3)
Block(0,49,-1,17:15)
Block(0,49,0,LEAVES:3)
Block(0,50,-4,LEAVES:3)
Block(0,50,-1,17:15)
Block(0,50,0,LEAVES:3)
Block(0,51,-1,17:15)
Block(0,51,0,LEAVES:3)
Block(0,52,-3,LEAVES:3)
Block(0,52,-2,17:15)
Block(0,52,-1,17:15)
Block(0,52,0,17:15)
Block(0,52,1,LEAVES:3)
Block(0,52,2,LEAVES:3)
Block(0,53,-5,LEAVES:3)
Block(0,53,-4,LEAVES:3)
Block(0,53,-3,LEAVES:3)
Block(0,53,-2,17:15)
Block(0,53,-1,LEAVES:3)
Block(0,53,0,LEAVES:3)
Block(0,53,1,17:15)
Block(0,53,2,LEAVES:3)
Block(0,53,3,LEAVES:3)
Block(0,53,4,LEAVES:3)
Block(0,54,-4,LEAVES:3)
Block(0,54,-3,LEAVES:3)
Block(0,54,-2,LEAVES:3)
Block(0,54,1,LEAVES:3)
Block(0,54,2,LEAVES:3)
Block(0,54,3,LEAVES:3)
Block(0,55,-3,LEAVES:3)
Block(0,55,2,LEAVES:3)
Block(1,-3,-5,17:15)
Block(1,-3,-1,17:15)
Block(1,-3,3,17:15)
Block(1,-2,-5,17:15)
Block(1,-2,-4,17:15)
Block(1,-2,-1,17:15)
Block(1,-2,2,17:15)
Block(1,-2,3,17:15)
Block(1,-1,-5,17:15)
Block(1,-1,-4,17:15)
Block(1,-1,1,17:15)
Block(1,-1,2,17:15)
Block(1,0,-4,17:15)
Block(1,0,1,17:15)
Block(1,0,2,17:15)
Block(1,1,-4,17:15)
Block(1,1,-1,17:15)
Block(1,1,0,17:15)
Block(1,1,1,17:15)
Block(1,1,2,17:15)
Block(1,2,-2,17:15)
Block(1,2,-1,17:15)
Block(1,2,0,17:15)
Block(1,2,1,17:15)
Block(1,2,2,17:15)
Block(1,3,-2,17:15)
Block(1,3,-1,17:15)
Block(1,3,0,17:15)
Block(1,3,1,17:15)
Block(1,3,2,17:15)
Block(1,4,-2,17:15)
Block(1,4,-1,17:15)
Block(1,4,0,17:15)
Block(1,4,1,17:15)
Block(1,5,-2,17:15)
Block(1,5,-1,17:15)
Block(1,5,0,17:15)
Block(1,5,1,17:15)
Block(1,6,-2,17:15)
Block(1,6,-1,17:15)
Block(1,6,0,17:15)
Block(1,6,1,17:15)
Block(1,7,-3,17:15)
Block(1,7,-2,17:15)
Block(1,7,-1,17:15)
Block(1,7,0,17:15)
Block(1,8,-6,LEAVES:3)
Block(1,8,-4,17:15)
Block(1,8,-3,17:15)
Block(1,8,-2,17:15)
Block(1,8,-1,17:15)
Block(1,8,0,17:15)
Block(1,9,-10,LEAVES:3)
Block(1,9,-7,LEAVES:3)
Block(1,9,-6,LEAVES:3)
Block(1,9,-5,LEAVES:3)
Block(1,9,-4,LEAVES:3)
Block(1,9,-2,17:15)
Block(1,9,-1,17:15)
Block(1,9,0,17:15)
Block(1,10,-16,LEAVES:3)
Block(1,10,-11,LEAVES:3)
Block(1,10,-10,LEAVES:3)
Block(1,10,-9,17:15)
Block(1,10,-8,LEAVES:3)
Block(1,10,-7,LEAVES:3)
Block(1,10,-2,17:15)
Block(1,10,-1,17:15)
Block(1,10,0,17:15)
Block(1,11,-15,LEAVES:3)
Block(1,11,-14,LEAVES:3)
Block(1,11,-13,LEAVES:3)
Block(1,11,-12,LEAVES:3)
Block(1,11,-11,LEAVES:3)
Block(1,11,-10,LEAVES:3)
Block(1,11,-9,LEAVES:3)
Block(1,11,-8,LEAVES:3)
Block(1,11,-2,17:15)
Block(1,11,-1,17:15)
Block(1,11,0,17:15)
Block(1,12,-13,LEAVES:3)
Block(1,12,-10,LEAVES:3)
Block(1,12,-9,LEAVES:3)
Block(1,12,-8,LEAVES:3)
Block(1,12,-2,17:15)
Block(1,12,-1,17:15)
Block(1,12,0,17:15)
Block(1,13,-9,LEAVES:3)
Block(1,13,-2,17:15)
Block(1,13,-1,17:15)
Block(1,13,0,17:15)
Block(1,14,-2,17:15)
Block(1,14,-1,17:15)
Block(1,14,0,17:15)
Block(1,15,-2,17:15)
Block(1,15,-1,17:15)
Block(1,15,0,17:15)
Block(1,16,-2,17:15)
Block(1,16,-1,17:15)
Block(1,16,0,17:15)
Block(1,17,-3,17:15)
Block(1,17,-2,17:15)
Block(1,17,-1,17:15)
Block(1,17,0,17:15)
Block(1,18,-4,17:15)
Block(1,18,-3,17:15)
Block(1,18,-2,17:15)
Block(1,18,-1,17:15)
Block(1,18,0,17:15)
Block(1,19,-8,LEAVES:3)
Block(1,19,-7,LEAVES:3)
Block(1,19,-5,LEAVES:3)
Block(1,19,-4,LEAVES:3)
Block(1,19,-3,LEAVES:3)
Block(1,19,-2,17:15)
Block(1,19,-1,17:15)
Block(1,19,0,17:15)
Block(1,19,1,17:15)
Block(1,19,2,17:15)
Block(1,19,3,17:15)
Block(1,20,-11,LEAVES:3)
Block(1,20,-9,17:15)
Block(1,20,-8,LEAVES:3)
Block(1,20,-4,LEAVES:3)
Block(1,20,-2,17:15)
Block(1,20,-1,17:15)
Block(1,20,0,17:15)
Block(1,20,1,LEAVES:3)
Block(1,20,2,LEAVES:3)
Block(1,20,3,17:15)
Block(1,20,4,LEAVES:3)
Block(1,20,9,LEAVES:3)
Block(1,21,-15,LEAVES:3)
Block(1,21,-12,LEAVES:3)
Block(1,21,-11,LEAVES:3)
Block(1,21,-10,17:15)
Block(1,21,-9,LEAVES:3)
Block(1,21,-8,LEAVES:3)
Block(1,21,-2,17:15)
Block(1,21,-1,17:15)
Block(1,21,2,LEAVES:3)
Block(1,21,3,LEAVES:3)
Block(1,21,4,LEAVES:3)
Block(1,21,5,17:15)
Block(1,21,6,LEAVES:3)
Block(1,21,8,LEAVES:3)
Block(1,21,9,17:15)
Block(1,21,11,LEAVES:3)
Block(1,22,-15,LEAVES:3)
Block(1,22,-14,LEAVES:3)
Block(1,22,-11,LEAVES:3)
Block(1,22,-10,LEAVES:3)
Block(1,22,-9,LEAVES:3)
Block(1,22,-2,17:15)
Block(1,22,-1,17:15)
Block(1,22,4,LEAVES:3)
Block(1,22,5,LEAVES:3)
Block(1,22,6,LEAVES:3)
Block(1,22,7,LEAVES:3)
Block(1,22,9,LEAVES:3)
Block(1,22,10,17:15)
Block(1,22,11,17:15)
Block(1,22,12,LEAVES:3)
Block(1,22,13,LEAVES:3)
Block(1,23,-10,LEAVES:3)
Block(1,23,-2,17:15)
Block(1,23,-1,17:15)
Block(1,23,6,LEAVES:3)
Block(1,23,10,LEAVES:3)
Block(1,23,11,LEAVES:3)
Block(1,23,12,LEAVES:3)
Block(1,24,-2,17:15)
Block(1,24,-1,17:15)
Block(1,25,-2,17:15)
Block(1,25,-1,17:15)
Block(1,25,0,LEAVES:3)
Block(1,25,1,LEAVES:3)
Block(1,26,-1,17:15)
Block(1,27,-1,17:15)
Block(1,28,-4,LEAVES:3)
Block(1,28,-3,LEAVES:3)
Block(1,28,-1,17:15)
Block(1,29,-7,LEAVES:3)
Block(1,29,-5,17:15)
Block(1,29,-4,LEAVES:3)
Block(1,29,-1,17:15)
Block(1,30,-11,LEAVES:3)
Block(1,30,-8,LEAVES:3)
Block(1,30,-7,LEAVES:3)
Block(1,30,-6,17:15)
Block(1,30,-5,LEAVES:3)
Block(1,30,-4,LEAVES:3)
Block(1,30,-1,17:15)
Block(1,31,-11,LEAVES:3)
Block(1,31,-10,LEAVES:3)
Block(1,31,-7,LEAVES:3)
Block(1,31,-6,LEAVES:3)
Block(1,31,-5,LEAVES:3)
Block(1,31,-2,17:15)
Block(1,31,-1,17:15)
Block(1,31,1,17:15)
Block(1,31,3,LEAVES:3)
Block(1,32,-6,LEAVES:3)
Block(1,32,-2,17:15)
Block(1,32,-1,17:15)
Block(1,32,0,LEAVES:3)
Block(1,32,1,17:15)
Block(1,32,2,17:15)
Block(1,32,3,17:15)
Block(1,32,5,LEAVES:3)
Block(1,32,6,LEAVES:3)
Block(1,33,-2,17:15)
Block(1,33,-1,17:15)
Block(1,33,1,LEAVES:3)
Block(1,33,2,LEAVES:3)
Block(1,33,3,LEAVES:3)
Block(1,33,4,LEAVES:3)
Block(1,33,5,LEAVES:3)
Block(1,33,6,LEAVES:3)
Block(1,34,-6,LEAVES:3)
Block(1,34,-2,LEAVES:3)
Block(1,34,-1,17:15)
Block(1,34,2,LEAVES:3)
Block(1,34,4,LEAVES:3)
Block(1,34,5,LEAVES:3)
Block(1,34,7,LEAVES:3)
Block(1,34,8,LEAVES:3)
Block(1,34,9,LEAVES:3)
Block(1,35,-9,LEAVES:3)
Block(1,35,-6,17:15)
Block(1,35,-5,LEAVES:3)
Block(1,35,-4,LEAVES:3)
Block(1,35,-1,17:15)
Block(1,35,4,LEAVES:3)
Block(1,35,7,LEAVES:3)
Block(1,36,-8,LEAVES:3)
Block(1,36,-7,17:15)
Block(1,36,-6,LEAVES:3)
Block(1,36,-1,17:15)
Block(1,37,-8,LEAVES:3)
Block(1,37,-7,LEAVES:3)
Block(1,37,-1,17:15)
Block(1,38,-1,17:15)
Block(1,38,0,17:15)
Block(1,39,-2,17:15)
Block(1,39,-1,17:15)
Block(1,39,1,17:15)
Block(1,40,-1,17:15)
Block(1,41,-1,17:15)
Block(1,42,-1,17:15)
Block(1,43,-1,17:15)
Block(1,43,4,LEAVES:3)
Block(1,43,6,LEAVES:3)
Block(1,44,-1,17:15)
Block(1,44,2,LEAVES:3)
Block(1,44,4,17:15)
Block(1,44,5,LEAVES:3)
Block(1,44,6,LEAVES:3)
Block(1,45,2,LEAVES:3)
Block(1,45,3,LEAVES:3)
Block(1,45,4,LEAVES:3)
Block(1,45,5,LEAVES:3)
Block(1,46,4,LEAVES:3)
Block(1,47,-2,LEAVES:3)
Block(1,48,-6,LEAVES:3)
Block(1,48,-3,LEAVES:3)
Block(1,48,-1,17:15)
Block(1,49,-6,LEAVES:3)
Block(1,49,-5,LEAVES:3)
Block(1,49,-4,17:15)
Block(1,49,-3,LEAVES:3)
Block(1,49,-2,LEAVES:3)
Block(1,49,-1,17:15)
Block(1,49,0,LEAVES:3)
Block(1,50,-5,LEAVES:3)
Block(1,50,-4,LEAVES:3)
Block(1,50,-3,LEAVES:3)
Block(1,51,-4,LEAVES:3)
Block(1,51,-1,LEAVES:3)
Block(1,52,-5,LEAVES:3)
Block(1,52,-2,LEAVES:3)
Block(1,52,-1,LEAVES:3)
Block(1,52,0,LEAVES:3)
Block(1,53,-4,LEAVES:3)
Block(1,53,-3,LEAVES:3)
Block(1,53,-2,LEAVES:3)
Block(1,53,-1,LEAVES:3)
Block(1,53,1,LEAVES:3)
Block(1,53,2,LEAVES:3)
Block(1,53,3,LEAVES:3)
Block(1,54,-3,LEAVES:3)
Block(1,54,2,LEAVES:3)
Block(2,-3,-3,17:15)
Block(2,-3,-1,17:15)
Block(2,-3,2,17:15)
Block(2,-3,3,17:15)
Block(2,-2,-3,17:15)
Block(2,-2,2,17:15)
Block(2,-1,-3,17:15)
Block(2,-1,-2,17:15)
Block(2,-1,2,17:15)
Block(2,0,-3,17:15)
Block(2,0,-2,17:15)
Block(2,0,-1,17:15)
Block(2,1,-3,17:15)
Block(2,1,-2,17:15)
Block(2,1,-1,17:15)
Block(2,2,-3,17:15)
Block(2,2,-2,17:15)
Block(2,2,-1,17:15)
Block(2,3,-2,17:15)
Block(2,3,-1,17:15)
Block(2,4,-2,17:15)
Block(2,4,-1,17:15)
Block(2,5,-2,17:15)
Block(2,5,-1,17:15)
Block(2,6,-2,17:15)
Block(2,6,-1,17:15)
Block(2,7,-2,17:15)
Block(2,7,-1,17:15)
Block(2,8,-6,17:15)
Block(2,8,-5,17:15)
Block(2,8,-4,17:15)
Block(2,8,-1,17:15)
Block(2,9,-12,LEAVES:3)
Block(2,9,-7,LEAVES:3)
Block(2,9,-6,17:15)
Block(2,9,-5,LEAVES:3)
Block(2,9,-4,LEAVES:3)
Block(2,9,-1,17:15)
Block(2,10,-14,LEAVES:3)
Block(2,10,-12,17:15)
Block(2,10,-11,LEAVES:3)
Block(2,10,-9,LEAVES:3)
Block(2,10,-8,17:15)
Block(2,10,-7,LEAVES:3)
Block(2,10,-6,LEAVES:3)
Block(2,10,-5,LEAVES:3)
Block(2,10,-1,17:15)
Block(2,11,-16,LEAVES:3)
Block(2,11,-15,LEAVES:3)
Block(2,11,-14,17:15)
Block(2,11,-13,17:15)
Block(2,11,-12,LEAVES:3)
Block(2,11,-10,LEAVES:3)
Block(2,11,-9,LEAVES:3)
Block(2,11,-8,LEAVES:3)
Block(2,11,-7,LEAVES:3)
Block(2,12,-15,LEAVES:3)
Block(2,12,-14,LEAVES:3)
Block(2,12,-13,LEAVES:3)
Block(2,12,-9,LEAVES:3)
Block(2,12,0,17:15)
Block(2,13,0,17:15)
Block(2,13,1,17:15)
Block(2,14,1,LEAVES:3)
Block(2,17,-2,LEAVES:3)
Block(2,18,-5,17:15)
Block(2,18,-4,17:15)
Block(2,18,-3,LEAVES:3)
Block(2,18,-2,LEAVES:3)
Block(2,19,-10,LEAVES:3)
Block(2,19,-8,17:15)
Block(2,19,-6,LEAVES:3)
Block(2,19,-5,17:15)
Block(2,19,-4,LEAVES:3)
Block(2,19,-3,LEAVES:3)
Block(2,19,3,LEAVES:3)
Block(2,19,6,LEAVES:3)
Block(2,20,-13,LEAVES:3)
Block(2,20,-12,LEAVES:3)
Block(2,20,-10,17:15)
Block(2,20,-9,17:15)
Block(2,20,-8,17:15)
Block(2,20,-7,LEAVES:3)
Block(2,20,-5,LEAVES:3)
Block(2,20,-4,LEAVES:3)
Block(2,20,-3,LEAVES:3)
Block(2,20,2,LEAVES:3)
Block(2,20,3,17:15)
Block(2,20,4,17:15)
Block(2,20,5,17:15)
Block(2,20,6,LEAVES:3)
Block(2,20,8,LEAVES:3)
Block(2,20,9,LEAVES:3)
Block(2,21,-13,LEAVES:3)
Block(2,21,-12,LEAVES:3)
Block(2,21,-11,LEAVES:3)
Block(2,21,-10,LEAVES:3)
Block(2,21,-9,LEAVES:3)
Block(2,21,-8,LEAVES:3)
Block(2,21,-4,LEAVES:3)
Block(2,21,3,LEAVES:3)
Block(2,21,4,LEAVES:3)
Block(2,21,5,LEAVES:3)
Block(2,21,6,LEAVES:3)
Block(2,21,8,17:15)
Block(2,21,11,LEAVES:3)
Block(2,22,-16,LEAVES:3)
Block(2,22,-15,LEAVES:3)
Block(2,22,-14,LEAVES:3)
Block(2,22,-12,LEAVES:3)
Block(2,22,-11,LEAVES:3)
Block(2,22,-9,LEAVES:3)
Block(2,22,5,LEAVES:3)
Block(2,22,8,LEAVES:3)
Block(2,22,9,LEAVES:3)
Block(2,22,10,LEAVES:3)
Block(2,22,11,LEAVES:3)
Block(2,22,12,LEAVES:3)
Block(2,23,-14,LEAVES:3)
Block(2,23,-11,LEAVES:3)
Block(2,24,-1,17:15)
Block(2,25,-1,17:15)
Block(2,25,0,LEAVES:3)
Block(2,25,1,LEAVES:3)
Block(2,25,2,LEAVES:3)
Block(2,26,1,LEAVES:3)
Block(2,28,-4,LEAVES:3)
Block(2,29,-11,LEAVES:3)
Block(2,29,-6,LEAVES:3)
Block(2,29,-5,LEAVES:3)
Block(2,30,-10,LEAVES:3)
Block(2,30,-9,LEAVES:3)
Block(2,30,-8,LEAVES:3)
Block(2,30,-7,LEAVES:3)
Block(2,30,-6,17:15)
Block(2,31,-7,LEAVES:3)
Block(2,31,-6,LEAVES:3)
Block(2,31,0,LEAVES:3)
Block(2,31,1,LEAVES:3)
Block(2,32,-2,17:15)
Block(2,32,-1,17:15)
Block(2,32,1,LEAVES:3)
Block(2,32,2,17:15)
Block(2,32,4,LEAVES:3)
Block(2,33,-2,17:15)
Block(2,33,1,LEAVES:3)
Block(2,33,2,LEAVES:3)
Block(2,33,3,17:15)
Block(2,33,4,LEAVES:3)
Block(2,33,5,LEAVES:3)
Block(2,33,8,LEAVES:3)
Block(2,34,-3,LEAVES:3)
Block(2,34,-2,LEAVES:3)
Block(2,34,-1,LEAVES:3)
Block(2,34,2,LEAVES:3)
Block(2,34,3,LEAVES:3)
Block(2,34,4,LEAVES:3)
Block(2,34,7,LEAVES:3)
Block(2,34,8,LEAVES:3)
Block(2,35,-8,LEAVES:3)
Block(2,35,-7,LEAVES:3)
Block(2,35,-6,LEAVES:3)
Block(2,35,-5,17:15)
Block(2,35,-4,LEAVES:3)
Block(2,35,-2,LEAVES:3)
Block(2,35,3,LEAVES:3)
Block(2,36,-7,LEAVES:3)
Block(2,36,-6,LEAVES:3)
Block(2,36,-5,LEAVES:3)
Block(2,37,-6,LEAVES:3)
Block(2,39,-3,17:15)
Block(2,39,-2,17:15)
Block(2,39,2,17:15)
Block(2,39,3,LEAVES:3)
Block(2,39,4,LEAVES:3)
Block(2,40,-3,17:15)
Block(2,40,-1,17:15)
Block(2,40,3,LEAVES:3)
Block(2,41,-6,LEAVES:3)
Block(2,41,-5,LEAVES:3)
Block(2,41,-4,17:15)
Block(2,42,-5,LEAVES:3)
Block(2,44,3,LEAVES:3)
Block(2,44,5,LEAVES:3)
Block(2,44,8,LEAVES:3)
Block(2,45,4,LEAVES:3)
Block(2,45,5,17:15)
Block(2,45,6,LEAVES:3)
Block(2,45,7,LEAVES:3)
Block(2,45,8,LEAVES:3)
Block(2,46,4,LEAVES:3)
Block(2,46,5,LEAVES:3)
Block(2,46,6,LEAVES:3)
Block(2,46,7,LEAVES:3)
Block(2,47,5,LEAVES:3)
Block(2,48,-4,LEAVES:3)
Block(2,49,-5,LEAVES:3)
Block(2,49,-4,LEAVES:3)
Block(2,49,-2,LEAVES:3)
Block(2,49,-1,17:15)
Block(2,50,-4,LEAVES:3)
Block(2,50,-1,17:15)
Block(2,51,-1,LEAVES:3)
Block(2,51,0,LEAVES:3)
Block(2,52,-3,LEAVES:3)
Block(2,52,-1,LEAVES:3)
Block(2,53,-3,LEAVES:3)
Block(3,-3,-3,17:15)
Block(3,-3,-1,17:15)
Block(3,-3,2,17:15)
Block(3,-2,-3,17:15)
Block(3,-2,2,17:15)
Block(3,-1,-3,17:15)
Block(3,-1,-1,17:15)
Block(3,-1,0,17:15)
Block(3,0,-3,17:15)
Block(3,0,-1,17:15)
Block(3,0,0,17:15)
Block(3,1,-1,17:15)
Block(3,2,-1,17:15)
Block(3,8,-9,LEAVES:3)
Block(3,8,-6,LEAVES:3)
Block(3,9,-12,LEAVES:3)
Block(3,9,-11,LEAVES:3)
Block(3,9,-9,LEAVES:3)
Block(3,9,-8,17:15)
Block(3,9,-7,17:15)
Block(3,9,-6,17:15)
Block(3,9,-5,LEAVES:3)
Block(3,10,-14,LEAVES:3)
Block(3,10,-11,17:15)
Block(3,10,-9,LEAVES:3)
Block(3,10,-8,LEAVES:3)
Block(3,10,-7,LEAVES:3)
Block(3,10,-6,LEAVES:3)
Block(3,11,-15,LEAVES:3)
Block(3,11,-14,LEAVES:3)
Block(3,11,-13,LEAVES:3)
Block(3,11,-12,LEAVES:3)
Block(3,11,-11,LEAVES:3)
Block(3,11,-8,LEAVES:3)
Block(3,13,1,17:15)
Block(3,13,2,LEAVES:3)
Block(3,14,1,LEAVES:3)
Block(3,15,1,LEAVES:3)
Block(3,18,-5,17:15)
Block(3,18,-4,LEAVES:3)
Block(3,19,-8,17:15)
Block(3,19,-7,17:15)
Block(3,19,-6,17:15)
Block(3,19,-5,LEAVES:3)
Block(3,19,-4,LEAVES:3)
Block(3,19,-3,LEAVES:3)
Block(3,19,-2,LEAVES:3)
Block(3,19,3,LEAVES:3)
Block(3,20,-11,17:15)
Block(3,20,-10,LEAVES:3)
Block(3,20,-8,LEAVES:3)
Block(3,20,-6,LEAVES:3)
Block(3,20,-4,LEAVES:3)
Block(3,20,3,LEAVES:3)
Block(3,20,4,LEAVES:3)
Block(3,20,5,17:15)
Block(3,20,6,17:15)
Block(3,20,7,LEAVES:3)
Block(3,21,-16,LEAVES:3)
Block(3,21,-14,LEAVES:3)
Block(3,21,-13,17:15)
Block(3,21,-11,17:15)
Block(3,21,-10,LEAVES:3)
Block(3,21,-9,LEAVES:3)
Block(3,21,4,LEAVES:3)
Block(3,21,5,LEAVES:3)
Block(3,21,6,17:15)
Block(3,21,7,17:15)
Block(3,21,8,17:15)
Block(3,21,9,LEAVES:3)
Block(3,21,10,LEAVES:3)
Block(3,21,12,LEAVES:3)
Block(3,22,-17,LEAVES:3)
Block(3,22,-16,LEAVES:3)
Block(3,22,-15,LEAVES:3)
Block(3,22,-14,17:15)
Block(3,22,-13,LEAVES:3)
Block(3,22,-11,LEAVES:3)
Block(3,22,-10,LEAVES:3)
Block(3,22,4,LEAVES:3)
Block(3,22,5,LEAVES:3)
Block(3,22,6,LEAVES:3)
Block(3,22,7,LEAVES:3)
Block(3,22,8,LEAVES:3)
Block(3,22,9,LEAVES:3)
Block(3,22,10,LEAVES:3)
Block(3,22,11,LEAVES:3)
Block(3,23,-16,LEAVES:3)
Block(3,23,-15,LEAVES:3)
Block(3,23,-14,LEAVES:3)
Block(3,23,-13,LEAVES:3)
Block(3,23,5,LEAVES:3)
Block(3,23,9,LEAVES:3)
Block(3,24,-14,LEAVES:3)
Block(3,24,1,LEAVES:3)
Block(3,25,-2,LEAVES:3)
Block(3,25,-1,17:15)
Block(3,25,0,17:15)
Block(3,25,1,LEAVES:3)
Block(3,25,3,LEAVES:3)
Block(3,26,-1,LEAVES:3)
Block(3,26,1,LEAVES:3)
Block(3,26,2,LEAVES:3)
Block(3,26,3,LEAVES:3)
Block(3,27,-2,LEAVES:3)
Block(3,27,1,LEAVES:3)
Block(3,29,-10,LEAVES:3)
Block(3,29,-8,LEAVES:3)
Block(3,30,-11,LEAVES:3)
Block(3,30,-10,LEAVES:3)
Block(3,30,-9,LEAVES:3)
Block(3,30,-8,17:15)
Block(3,30,-7,17:15)
Block(3,30,-6,LEAVES:3)
Block(3,31,-10,LEAVES:3)
Block(3,31,-9,LEAVES:3)
Block(3,31,-8,LEAVES:3)
Block(3,31,-7,LEAVES:3)
Block(3,31,1,LEAVES:3)
Block(3,32,-2,17:15)
Block(3,32,2,LEAVES:3)
Block(3,32,3,LEAVES:3)
Block(3,32,8,LEAVES:3)
Block(3,33,-3,17:15)
Block(3,33,-2,17:15)
Block(3,33,-1,LEAVES:3)
Block(3,33,0,LEAVES:3)
Block(3,33,3,17:15)
Block(3,33,4,LEAVES:3)
Block(3,33,5,LEAVES:3)
Block(3,33,6,LEAVES:3)
Block(3,33,7,LEAVES:3)
Block(3,34,-7,LEAVES:3)
Block(3,34,-3,LEAVES:3)
Block(3,34,-2,LEAVES:3)
Block(3,34,3,LEAVES:3)
Block(3,34,4,LEAVES:3)
Block(3,35,-7,LEAVES:3)
Block(3,35,-6,LEAVES:3)
Block(3,35,-5,LEAVES:3)
Block(3,35,-4,17:15)
Block(3,36,-6,LEAVES:3)
Block(3,36,-4,LEAVES:3)
Block(3,39,3,LEAVES:3)
Block(3,40,-3,17:15)
Block(3,40,0,17:15)
Block(3,44,4,LEAVES:3)
Block(3,44,7,LEAVES:3)
Block(3,45,5,LEAVES:3)
Block(3,45,6,17:15)
Block(3,45,7,LEAVES:3)
Block(3,45,8,LEAVES:3)
Block(3,45,9,LEAVES:3)
Block(3,46,5,LEAVES:3)
Block(3,46,6,LEAVES:3)
Block(3,46,7,LEAVES:3)
Block(3,46,8,LEAVES:3)
Block(3,49,-1,LEAVES:3)
Block(3,50,-2,LEAVES:3)
Block(3,50,-1,17:15)
Block(3,51,-2,LEAVES:3)
Block(3,51,-1,LEAVES:3)
Block(3,51,0,17:15)
Block(3,51,1,LEAVES:3)
Block(3,51,2,LEAVES:3)
Block(3,52,0,LEAVES:3)
Block(4,-3,-3,17:15)
Block(4,-3,0,17:15)
Block(4,-3,1,17:15)
Block(4,-3,2,17:15)
Block(4,-2,-3,17:15)
Block(4,-2,0,17:15)
Block(4,-2,1,17:15)
Block(4,-1,0,17:15)
Block(4,8,-6,LEAVES:3)
Block(4,9,-10,LEAVES:3)
Block(4,9,-9,17:15)
Block(4,9,-8,17:15)
Block(4,9,-7,LEAVES:3)
Block(4,9,-6,LEAVES:3)
Block(4,10,-15,LEAVES:3)
Block(4,10,-13,LEAVES:3)
Block(4,10,-12,LEAVES:3)
Block(4,10,-11,17:15)
Block(4,10,-10,17:15)
Block(4,10,-9,17:15)
Block(4,10,-8,LEAVES:3)
Block(4,10,-7,LEAVES:3)
Block(4,11,-14,LEAVES:3)
Block(4,11,-13,LEAVES:3)
Block(4,11,-12,LEAVES:3)
Block(4,11,-11,LEAVES:3)
Block(4,11,-10,LEAVES:3)
Block(4,11,-9,LEAVES:3)
Block(4,11,-8,LEAVES:3)
Block(4,11,-7,LEAVES:3)
Block(4,12,-12,LEAVES:3)
Block(4,12,-8,LEAVES:3)
Block(4,13,1,17:15)
Block(4,13,2,17:15)
Block(4,13,3,LEAVES:3)
Block(4,14,0,LEAVES:3)
Block(4,14,3,LEAVES:3)
Block(4,15,1,LEAVES:3)
Block(4,18,-6,LEAVES:3)
Block(4,18,-5,17:15)
Block(4,19,-5,LEAVES:3)
Block(4,19,-4,LEAVES:3)
Block(4,19,-3,LEAVES:3)
Block(4,19,4,LEAVES:3)
Block(4,19,5,17:15)
Block(4,20,-12,LEAVES:3)
Block(4,20,-3,LEAVES:3)
Block(4,20,-2,LEAVES:3)
Block(4,20,3,LEAVES:3)
Block(4,20,4,LEAVES:3)
Block(4,20,5,17:15)
Block(4,20,6,LEAVES:3)
Block(4,20,9,LEAVES:3)
Block(4,21,-13,LEAVES:3)
Block(4,21,-12,17:15)
Block(4,21,-11,LEAVES:3)
Block(4,21,-10,LEAVES:3)
Block(4,21,4,LEAVES:3)
Block(4,21,5,LEAVES:3)
Block(4,21,6,LEAVES:3)
Block(4,21,7,LEAVES:3)
Block(4,21,8,17:15)
Block(4,21,9,17:15)
Block(4,21,12,LEAVES:3)
Block(4,22,-16,LEAVES:3)
Block(4,22,-15,LEAVES:3)
Block(4,22,-14,LEAVES:3)
Block(4,22,-12,LEAVES:3)
Block(4,22,-10,LEAVES:3)
Block(4,22,6,LEAVES:3)
Block(4,22,8,LEAVES:3)
Block(4,22,9,LEAVES:3)
Block(4,22,11,LEAVES:3)
Block(4,22,12,LEAVES:3)
Block(4,22,13,LEAVES:3)
Block(4,23,-12,LEAVES:3)
Block(4,23,11,LEAVES:3)
Block(4,25,-2,17:15)
Block(4,25,-1,LEAVES:3)
Block(4,25,1,17:15)
Block(4,25,2,LEAVES:3)
Block(4,26,-3,LEAVES:3)
Block(4,26,-2,17:15)
Block(4,26,-1,LEAVES:3)
Block(4,26,0,LEAVES:3)
Block(4,26,1,LEAVES:3)
Block(4,26,2,LEAVES:3)
Block(4,26,3,LEAVES:3)
Block(4,27,-3,LEAVES:3)
Block(4,27,-2,LEAVES:3)
Block(4,27,2,LEAVES:3)
Block(4,28,-2,LEAVES:3)
Block(4,29,-9,LEAVES:3)
Block(4,29,-7,LEAVES:3)
Block(4,30,-10,LEAVES:3)
Block(4,30,-9,LEAVES:3)
Block(4,30,-8,LEAVES:3)
Block(4,30,-7,LEAVES:3)
Block(4,31,-9,LEAVES:3)
Block(4,31,-8,LEAVES:3)
Block(4,32,5,LEAVES:3)
Block(4,32,7,LEAVES:3)
Block(4,33,-4,LEAVES:3)
Block(4,33,-3,17:15)
Block(4,33,-2,LEAVES:3)
Block(4,33,-1,17:15)
Block(4,33,0,LEAVES:3)
Block(4,33,1,LEAVES:3)
Block(4,33,3,LEAVES:3)
Block(4,33,4,17:15)
Block(4,33,5,17:15)
Block(4,33,6,LEAVES:3)
Block(4,33,7,LEAVES:3)
Block(4,33,8,LEAVES:3)
Block(4,34,-5,LEAVES:3)
Block(4,34,-4,17:15)
Block(4,34,-3,17:15)
Block(4,34,-2,LEAVES:3)
Block(4,34,-1,LEAVES:3)
Block(4,34,0,LEAVES:3)
Block(4,34,4,LEAVES:3)
Block(4,34,5,LEAVES:3)
Block(4,34,6,LEAVES:3)
Block(4,34,7,LEAVES:3)
Block(4,35,-4,LEAVES:3)
Block(4,35,-3,LEAVES:3)
Block(4,36,-3,LEAVES:3)
Block(4,40,-5,LEAVES:3)
Block(4,40,-4,17:15)
Block(4,40,1,17:15)
Block(4,41,-2,LEAVES:3)
Block(4,41,-1,17:15)
Block(4,44,9,LEAVES:3)
Block(4,45,5,LEAVES:3)
Block(4,45,6,LEAVES:3)
Block(4,45,7,LEAVES:3)
Block(4,45,8,LEAVES:3)
Block(4,46,6,LEAVES:3)
Block(4,46,7,LEAVES:3)
Block(4,50,-3,LEAVES:3)
Block(4,50,-1,17:15)
Block(4,50,1,LEAVES:3)
Block(4,50,3,LEAVES:3)
Block(4,51,-2,LEAVES:3)
Block(4,51,-1,LEAVES:3)
Block(4,51,0,LEAVES:3)
Block(4,51,1,17:15)
Block(4,51,2,LEAVES:3)
Block(4,51,3,LEAVES:3)
Block(4,52,1,LEAVES:3)
Block(4,52,2,LEAVES:3)
Block(5,8,-8,17:15)
Block(5,8,-7,LEAVES:3)
Block(5,9,-12,LEAVES:3)
Block(5,9,-9,LEAVES:3)
Block(5,9,-8,17:15)
Block(5,9,-7,LEAVES:3)
Block(5,9,-6,LEAVES:3)
Block(5,10,-15,LEAVES:3)
Block(5,10,-12,17:15)
Block(5,10,-11,17:15)
Block(5,10,-10,LEAVES:3)
Block(5,10,-9,LEAVES:3)
Block(5,10,-8,LEAVES:3)
Block(5,10,-7,LEAVES:3)
Block(5,11,-16,LEAVES:3)
Block(5,11,-15,LEAVES:3)
Block(5,11,-14,LEAVES:3)
Block(5,11,-12,LEAVES:3)
Block(5,11,-11,LEAVES:3)
Block(5,11,-9,LEAVES:3)
Block(5,12,-14,LEAVES:3)
Block(5,13,2,17:15)
Block(5,14,2,17:15)
Block(5,14,3,LEAVES:3)
Block(5,14,4,LEAVES:3)
Block(5,15,0,LEAVES:3)
Block(5,15,1,LEAVES:3)
Block(5,15,2,LEAVES:3)
Block(5,15,3,LEAVES:3)
Block(5,16,1,LEAVES:3)
Block(5,19,-6,LEAVES:3)
Block(5,19,-5,17:15)
Block(5,19,-4,17:15)
Block(5,19,-3,LEAVES:3)
Block(5,19,-2,LEAVES:3)
Block(5,19,3,LEAVES:3)
Block(5,19,5,17:15)
Block(5,20,-5,LEAVES:3)
Block(5,20,-3,LEAVES:3)
Block(5,20,-2,LEAVES:3)
Block(5,20,-1,LEAVES:3)
Block(5,20,4,LEAVES:3)
Block(5,20,5,LEAVES:3)
Block(5,20,7,LEAVES:3)
Block(5,20,8,LEAVES:3)
Block(5,21,-16,LEAVES:3)
Block(5,21,-11,LEAVES:3)
Block(5,21,-3,LEAVES:3)
Block(5,21,-2,LEAVES:3)
Block(5,21,6,LEAVES:3)
Block(5,21,7,LEAVES:3)
Block(5,21,8,LEAVES:3)
Block(5,21,9,LEAVES:3)
Block(5,21,10,17:15)
Block(5,21,11,LEAVES:3)
Block(5,21,14,LEAVES:3)
Block(5,22,-15,LEAVES:3)
Block(5,22,-14,LEAVES:3)
Block(5,22,-13,LEAVES:3)
Block(5,22,-12,17:15)
Block(5,22,-11,LEAVES:3)
Block(5,22,-10,LEAVES:3)
Block(5,22,-9,LEAVES:3)
Block(5,22,8,LEAVES:3)
Block(5,22,10,LEAVES:3)
Block(5,22,11,17:15)
Block(5,22,12,LEAVES:3)
Block(5,22,13,LEAVES:3)
Block(5,22,14,LEAVES:3)
Block(5,23,-12,LEAVES:3)
Block(5,23,-11,LEAVES:3)
Block(5,23,-10,LEAVES:3)
Block(5,23,7,LEAVES:3)
Block(5,23,8,LEAVES:3)
Block(5,23,11,LEAVES:3)
Block(5,23,12,LEAVES:3)
Block(5,23,13,LEAVES:3)
Block(5,24,-12,LEAVES:3)
Block(5,24,0,LEAVES:3)
Block(5,25,0,LEAVES:3)
Block(5,25,1,LEAVES:3)
Block(5,25,3,LEAVES:3)
Block(5,26,-6,LEAVES:3)
Block(5,26,-5,LEAVES:3)
Block(5,26,-4,LEAVES:3)
Block(5,26,-3,17:15)
Block(5,26,-2,LEAVES:3)
Block(5,26,-1,LEAVES:3)
Block(5,26,1,LEAVES:3)
Block(5,26,2,17:15)
Block(5,26,3,LEAVES:3)
Block(5,26,4,LEAVES:3)
Block(5,27,-5,LEAVES:3)
Block(5,27,-3,LEAVES:3)
Block(5,27,1,LEAVES:3)
Block(5,27,2,LEAVES:3)
Block(5,27,3,LEAVES:3)
Block(5,28,2,LEAVES:3)
Block(5,30,-9,LEAVES:3)
Block(5,32,4,LEAVES:3)
Block(5,32,6,LEAVES:3)
Block(5,33,2,LEAVES:3)
Block(5,33,4,LEAVES:3)
Block(5,33,5,LEAVES:3)
Block(5,33,6,LEAVES:3)
Block(5,33,7,LEAVES:3)
Block(5,34,-7,LEAVES:3)
Block(5,34,-5,17:15)
Block(5,34,-4,17:15)
Block(5,34,-3,LEAVES:3)
Block(5,34,-2,LEAVES:3)
Block(5,34,-1,17:15)
Block(5,34,0,LEAVES:3)
Block(5,34,1,LEAVES:3)
Block(5,34,5,LEAVES:3)
Block(5,34,6,LEAVES:3)
Block(5,35,-6,LEAVES:3)
Block(5,35,-4,LEAVES:3)
Block(5,35,-3,LEAVES:3)
Block(5,35,-1,LEAVES:3)
Block(5,35,1,LEAVES:3)
Block(5,40,-4,LEAVES:3)
Block(5,40,1,17:15)
Block(5,40,2,LEAVES:3)
Block(5,41,-4,LEAVES:3)
Block(5,41,-1,LEAVES:3)
Block(5,44,6,LEAVES:3)
Block(5,45,6,LEAVES:3)
Block(5,49,-2,LEAVES:3)
Block(5,50,-4,LEAVES:3)
Block(5,50,-2,17:15)
Block(5,50,0,LEAVES:3)
Block(5,51,-3,LEAVES:3)
Block(5,51,-2,LEAVES:3)
Block(5,51,-1,LEAVES:3)
Block(5,51,0,LEAVES:3)
Block(5,51,1,LEAVES:3)
Block(5,51,2,LEAVES:3)
Block(5,52,-3,LEAVES:3)
Block(5,52,-2,LEAVES:3)
Block(5,52,1,LEAVES:3)
Block(5,52,2,LEAVES:3)
Block(5,53,1,LEAVES:3)
Block(6,8,-8,17:15)
Block(6,8,-6,LEAVES:3)
Block(6,9,-11,LEAVES:3)
Block(6,9,-10,LEAVES:3)
Block(6,9,-8,LEAVES:3)
Block(6,9,-7,LEAVES:3)
Block(6,10,-17,LEAVES:3)
Block(6,10,-14,LEAVES:3)
Block(6,10,-13,17:15)
Block(6,10,-12,LEAVES:3)
Block(6,10,-11,LEAVES:3)
Block(6,10,-10,LEAVES:3)
Block(6,10,-9,LEAVES:3)
Block(6,11,-17,LEAVES:3)
Block(6,11,-16,LEAVES:3)
Block(6,11,-15,LEAVES:3)
Block(6,11,-14,17:15)
Block(6,11,-13,LEAVES:3)
Block(6,11,-11,LEAVES:3)
Block(6,12,-16,LEAVES:3)
Block(6,12,-15,LEAVES:3)
Block(6,12,-14,LEAVES:3)
Block(6,12,-11,LEAVES:3)
Block(6,12,-10,LEAVES:3)
Block(6,13,2,17:15)
Block(6,13,5,LEAVES:3)
Block(6,14,-1,LEAVES:3)
Block(6,14,1,LEAVES:3)
Block(6,14,2,17:15)
Block(6,14,3,17:15)
Block(6,14,4,LEAVES:3)
Block(6,15,-2,LEAVES:3)
Block(6,15,-1,LEAVES:3)
Block(6,15,0,17:15)
Block(6,15,1,17:15)
Block(6,15,2,LEAVES:3)
Block(6,15,3,LEAVES:3)
Block(6,15,6,LEAVES:3)
Block(6,16,0,LEAVES:3)
Block(6,16,1,LEAVES:3)
Block(6,16,3,LEAVES:3)
Block(6,17,2,LEAVES:3)
Block(6,18,-8,LEAVES:3)
Block(6,18,-5,LEAVES:3)
Block(6,18,-3,LEAVES:3)
Block(6,18,4,LEAVES:3)
Block(6,19,-7,LEAVES:3)
Block(6,19,-6,17:15)
Block(6,19,-5,LEAVES:3)
Block(6,19,-4,LEAVES:3)
Block(6,19,-3,17:15)
Block(6,19,-1,LEAVES:3)
Block(6,19,4,LEAVES:3)
Block(6,19,5,17:15)
Block(6,19,6,LEAVES:3)
Block(6,20,-7,LEAVES:3)
Block(6,20,-6,LEAVES:3)
Block(6,20,-5,LEAVES:3)
Block(6,20,-4,LEAVES:3)
Block(6,20,-3,LEAVES:3)
Block(6,20,-2,LEAVES:3)
Block(6,20,4,LEAVES:3)
Block(6,20,5,LEAVES:3)
Block(6,20,6,LEAVES:3)
Block(6,20,8,LEAVES:3)
Block(6,20,10,LEAVES:3)
Block(6,21,-14,LEAVES:3)
Block(6,21,-12,LEAVES:3)
Block(6,21,-6,LEAVES:3)
Block(6,21,5,LEAVES:3)
Block(6,21,6,LEAVES:3)
Block(6,21,7,LEAVES:3)
Block(6,21,8,LEAVES:3)
Block(6,21,9,LEAVES:3)
Block(6,21,10,LEAVES:3)
Block(6,21,12,LEAVES:3)
Block(6,22,-15,LEAVES:3)
Block(6,22,-14,LEAVES:3)
Block(6,22,-13,17:15)
Block(6,22,-12,LEAVES:3)
Block(6,22,-11,LEAVES:3)
Block(6,22,-10,LEAVES:3)
Block(6,22,8,LEAVES:3)
Block(6,22,11,LEAVES:3)
Block(6,22,12,LEAVES:3)
Block(6,22,13,LEAVES:3)
Block(6,23,-14,LEAVES:3)
Block(6,23,-13,LEAVES:3)
Block(6,23,-11,LEAVES:3)
Block(6,23,12,LEAVES:3)
Block(6,23,13,LEAVES:3)
Block(6,24,4,LEAVES:3)
Block(6,25,4,LEAVES:3)
Block(6,26,-7,LEAVES:3)
Block(6,26,-6,LEAVES:3)
Block(6,26,-5,17:15)
Block(6,26,-4,17:15)
Block(6,26,-2,17:15)
Block(6,26,-1,LEAVES:3)
Block(6,26,0,LEAVES:3)
Block(6,26,1,LEAVES:3)
Block(6,26,2,17:15)
Block(6,26,3,LEAVES:3)
Block(6,27,-6,LEAVES:3)
Block(6,27,-5,LEAVES:3)
Block(6,27,-4,LEAVES:3)
Block(6,27,-3,LEAVES:3)
Block(6,27,-2,LEAVES:3)
Block(6,27,-1,LEAVES:3)
Block(6,27,2,LEAVES:3)
Block(6,28,-5,LEAVES:3)
Block(6,32,1,LEAVES:3)
Block(6,33,-3,LEAVES:3)
Block(6,33,-1,LEAVES:3)
Block(6,33,1,LEAVES:3)
Block(6,33,6,LEAVES:3)
Block(6,34,-8,LEAVES:3)
Block(6,34,-7,LEAVES:3)
Block(6,34,-6,17:15)
Block(6,34,-5,17:15)
Block(6,34,-3,LEAVES:3)
Block(6,34,-2,LEAVES:3)
Block(6,34,-1,LEAVES:3)
Block(6,34,0,17:15)
Block(6,34,1,LEAVES:3)
Block(6,35,-7,LEAVES:3)
Block(6,35,-6,17:15)
Block(6,35,-5,LEAVES:3)
Block(6,35,-2,LEAVES:3)
Block(6,35,-1,LEAVES:3)
Block(6,35,0,LEAVES:3)
Block(6,35,1,LEAVES:3)
Block(6,36,-7,LEAVES:3)
Block(6,36,-6,LEAVES:3)
Block(6,36,-1,LEAVES:3)
Block(6,40,-4,LEAVES:3)
Block(6,40,1,LEAVES:3)
Block(6,49,0,LEAVES:3)
Block(6,50,-3,LEAVES:3)
Block(6,50,-2,LEAVES:3)
Block(6,50,-1,LEAVES:3)
Block(6,50,2,LEAVES:3)
Block(6,51,-5,LEAVES:3)
Block(6,51,-4,LEAVES:3)
Block(6,51,-3,17:15)
Block(6,51,-2,LEAVES:3)
Block(6,51,0,LEAVES:3)
Block(6,51,1,LEAVES:3)
Block(6,51,2,LEAVES:3)
Block(6,52,-4,LEAVES:3)
Block(6,52,-3,LEAVES:3)
Block(6,52,1,LEAVES:3)
Block(6,53,-3,LEAVES:3)
Block(7,7,-7,LEAVES:3)
Block(7,8,-9,LEAVES:3)
Block(7,8,-8,17:15)
Block(7,8,-7,LEAVES:3)
Block(7,9,-13,LEAVES:3)
Block(7,9,-11,LEAVES:3)
Block(7,9,-9,LEAVES:3)
Block(7,9,-8,LEAVES:3)
Block(7,9,-7,LEAVES:3)
Block(7,10,-15,LEAVES:3)
Block(7,10,-13,LEAVES:3)
Block(7,10,-12,LEAVES:3)
Block(7,10,-11,LEAVES:3)
Block(7,10,-10,LEAVES:3)
Block(7,10,-9,LEAVES:3)
Block(7,10,-8,LEAVES:3)
Block(7,11,-16,LEAVES:3)
Block(7,11,-15,LEAVES:3)
Block(7,11,-14,LEAVES:3)
Block(7,11,-11,LEAVES:3)
Block(7,12,-16,LEAVES:3)
Block(7,12,-15,LEAVES:3)
Block(7,14,-3,LEAVES:3)
Block(7,14,3,17:15)
Block(7,15,-3,LEAVES:3)
Block(7,15,-2,LEAVES:3)
Block(7,15,-1,17:15)
Block(7,15,0,LEAVES:3)
Block(7,15,1,LEAVES:3)
Block(7,15,3,LEAVES:3)
Block(7,15,4,LEAVES:3)
Block(7,15,5,LEAVES:3)
Block(7,16,-2,LEAVES:3)
Block(7,16,-1,LEAVES:3)
Block(7,16,0,LEAVES:3)
Block(7,16,1,LEAVES:3)
Block(7,16,2,LEAVES:3)
Block(7,16,3,LEAVES:3)
Block(7,16,4,LEAVES:3)
Block(7,16,5,LEAVES:3)
Block(7,16,6,LEAVES:3)
Block(7,17,-1,LEAVES:3)
Block(7,17,2,LEAVES:3)
Block(7,17,3,LEAVES:3)
Block(7,17,4,LEAVES:3)
Block(7,17,6,LEAVES:3)
Block(7,18,-10,LEAVES:3)
Block(7,18,-6,LEAVES:3)
Block(7,18,3,LEAVES:3)
Block(7,19,-9,LEAVES:3)
Block(7,19,-8,LEAVES:3)
Block(7,19,-6,17:15)
Block(7,19,-5,LEAVES:3)
Block(7,19,2,LEAVES:3)
Block(7,19,4,17:15)
Block(7,19,7,LEAVES:3)
Block(7,20,-7,LEAVES:3)
Block(7,20,-6,LEAVES:3)
Block(7,20,-5,LEAVES:3)
Block(7,20,-3,17:15)
Block(7,20,-2,LEAVES:3)
Block(7,20,3,LEAVES:3)
Block(7,20,4,LEAVES:3)
Block(7,20,5,LEAVES:3)
Block(7,20,6,LEAVES:3)
Block(7,20,7,LEAVES:3)
Block(7,21,-15,LEAVES:3)
Block(7,21,-12,LEAVES:3)
Block(7,21,-3,LEAVES:3)
Block(7,21,4,LEAVES:3)
Block(7,21,6,LEAVES:3)
Block(7,21,8,LEAVES:3)
Block(7,21,11,LEAVES:3)
Block(7,22,-14,LEAVES:3)
Block(7,22,-13,LEAVES:3)
Block(7,22,-12,LEAVES:3)
Block(7,22,-11,LEAVES:3)
Block(7,22,12,LEAVES:3)
Block(7,23,-13,LEAVES:3)
Block(7,25,0,LEAVES:3)
Block(7,25,3,LEAVES:3)
Block(7,26,-6,LEAVES:3)
Block(7,26,-5,LEAVES:3)
Block(7,26,-4,LEAVES:3)
Block(7,26,-3,LEAVES:3)
Block(7,26,-2,17:15)
Block(7,26,-1,LEAVES:3)
Block(7,26,0,LEAVES:3)
Block(7,26,1,LEAVES:3)
Block(7,26,2,LEAVES:3)
Block(7,26,3,17:15)
Block(7,26,4,LEAVES:3)
Block(7,27,-5,LEAVES:3)
Block(7,27,-4,LEAVES:3)
Block(7,27,-1,LEAVES:3)
Block(7,27,0,LEAVES:3)
Block(7,27,2,LEAVES:3)
Block(7,27,3,LEAVES:3)
Block(7,28,-1,LEAVES:3)
Block(7,32,0,LEAVES:3)
Block(7,33,3,LEAVES:3)
Block(7,34,-2,LEAVES:3)
Block(7,34,-1,LEAVES:3)
Block(7,34,0,LEAVES:3)
Block(7,34,1,17:15)
Block(7,34,2,LEAVES:3)
Block(7,35,-8,LEAVES:3)
Block(7,35,-7,17:15)
Block(7,35,-6,17:15)
Block(7,35,-1,LEAVES:3)
Block(7,35,1,LEAVES:3)
Block(7,35,2,LEAVES:3)
Block(7,36,-7,LEAVES:3)
Block(7,36,-6,LEAVES:3)
Block(7,36,-5,LEAVES:3)
Block(7,36,1,LEAVES:3)
Block(7,37,-7,LEAVES:3)
Block(7,37,-6,LEAVES:3)
Block(7,37,-3,LEAVES:3)
Block(7,49,-2,LEAVES:3)
Block(7,50,-6,LEAVES:3)
Block(7,50,-2,LEAVES:3)
Block(7,50,0,LEAVES:3)
Block(7,51,-6,LEAVES:3)
Block(7,51,-5,LEAVES:3)
Block(7,51,-4,17:15)
Block(7,51,-3,LEAVES:3)
Block(7,51,1,LEAVES:3)
Block(7,52,-5,LEAVES:3)
Block(7,52,-4,LEAVES:3)
Block(7,52,-3,LEAVES:3)
Block(8,8,-10,LEAVES:3)
Block(8,8,-7,17:15)
Block(8,8,-5,LEAVES:3)
Block(8,9,-10,LEAVES:3)
Block(8,9,-9,LEAVES:3)
Block(8,9,-8,LEAVES:3)
Block(8,9,-7,LEAVES:3)
Block(8,9,-6,LEAVES:3)
Block(8,10,-14,LEAVES:3)
Block(8,10,-11,LEAVES:3)
Block(8,10,-9,LEAVES:3)
Block(8,10,-7,LEAVES:3)
Block(8,11,-15,LEAVES:3)
Block(8,14,-1,LEAVES:3)
Block(8,14,2,17:15)
Block(8,14,3,17:15)
Block(8,14,4,17:15)
Block(8,15,-2,LEAVES:3)
Block(8,15,-1,LEAVES:3)
Block(8,15,0,LEAVES:3)
Block(8,15,2,LEAVES:3)
Block(8,15,3,LEAVES:3)
Block(8,15,4,17:15)
Block(8,15,5,17:15)
Block(8,15,6,LEAVES:3)
Block(8,15,8,LEAVES:3)
Block(8,15,10,LEAVES:3)
Block(8,16,-1,LEAVES:3)
Block(8,16,2,LEAVES:3)
Block(8,16,3,LEAVES:3)
Block(8,16,4,LEAVES:3)
Block(8,16,5,LEAVES:3)
Block(8,16,6,17:15)
Block(8,16,7,LEAVES:3)
Block(8,16,8,LEAVES:3)
Block(8,16,9,LEAVES:3)
Block(8,17,3,LEAVES:3)
Block(8,17,5,LEAVES:3)
Block(8,17,6,LEAVES:3)
Block(8,17,7,LEAVES:3)
Block(8,17,8,LEAVES:3)
Block(8,18,-8,LEAVES:3)
Block(8,18,6,LEAVES:3)
Block(8,19,-10,LEAVES:3)
Block(8,19,-9,LEAVES:3)
Block(8,19,-8,LEAVES:3)
Block(8,19,-7,17:15)
Block(8,19,-6,LEAVES:3)
Block(8,19,-4,LEAVES:3)
Block(8,19,-1,LEAVES:3)
Block(8,19,3,LEAVES:3)
Block(8,20,-9,LEAVES:3)
Block(8,20,-8,LEAVES:3)
Block(8,20,-7,LEAVES:3)
Block(8,20,-6,LEAVES:3)
Block(8,20,-4,LEAVES:3)
Block(8,20,-3,LEAVES:3)
Block(8,20,-2,LEAVES:3)
Block(8,20,-1,LEAVES:3)
Block(8,20,2,LEAVES:3)
Block(8,20,3,LEAVES:3)
Block(8,20,4,17:15)
Block(8,20,5,LEAVES:3)
Block(8,20,6,LEAVES:3)
Block(8,21,-13,LEAVES:3)
Block(8,21,-3,LEAVES:3)
Block(8,21,-2,LEAVES:3)
Block(8,21,3,LEAVES:3)
Block(8,21,4,LEAVES:3)
Block(8,21,5,LEAVES:3)
Block(8,22,-13,LEAVES:3)
Block(8,22,4,LEAVES:3)
Block(8,25,-3,LEAVES:3)
Block(8,26,-4,LEAVES:3)
Block(8,26,-3,LEAVES:3)
Block(8,26,-1,LEAVES:3)
Block(8,26,0,LEAVES:3)
Block(8,26,2,LEAVES:3)
Block(8,26,3,LEAVES:3)
Block(8,26,4,LEAVES:3)
Block(8,27,-2,17:15)
Block(8,27,-1,LEAVES:3)
Block(8,27,3,LEAVES:3)
Block(8,27,4,LEAVES:3)
Block(8,28,-2,LEAVES:3)
Block(8,33,-1,LEAVES:3)
Block(8,33,1,LEAVES:3)
Block(8,34,-6,LEAVES:3)
Block(8,34,0,LEAVES:3)
Block(8,34,1,LEAVES:3)
Block(8,34,2,LEAVES:3)
Block(8,34,3,LEAVES:3)
Block(8,35,-8,LEAVES:3)
Block(8,35,-6,17:15)
Block(8,35,-5,LEAVES:3)
Block(8,35,1,LEAVES:3)
Block(8,35,2,LEAVES:3)
Block(8,36,-9,LEAVES:3)
Block(8,36,-8,17:15)
Block(8,36,-7,17:15)
Block(8,36,-6,LEAVES:3)
Block(8,36,-5,LEAVES:3)
Block(8,36,-4,LEAVES:3)
Block(8,37,-8,LEAVES:3)
Block(8,37,-7,LEAVES:3)
Block(8,37,-5,LEAVES:3)
Block(8,37,-4,LEAVES:3)
Block(8,37,-3,LEAVES:3)
Block(8,37,-2,LEAVES:3)
Block(8,38,-7,LEAVES:3)
Block(8,38,-3,LEAVES:3)
Block(8,50,-4,LEAVES:3)
Block(8,51,-5,LEAVES:3)
Block(8,51,-4,LEAVES:3)
Block(8,51,-3,LEAVES:3)
Block(8,52,-5,LEAVES:3)
Block(8,52,-4,LEAVES:3)
Block(8,52,-3,LEAVES:3)
Block(9,8,-6,LEAVES:3)
Block(9,9,-9,LEAVES:3)
Block(9,9,-8,LEAVES:3)
Block(9,9,-7,17:15)
Block(9,9,-6,LEAVES:3)
Block(9,9,-5,LEAVES:3)
Block(9,10,-8,LEAVES:3)
Block(9,10,-7,LEAVES:3)
Block(9,10,-6,LEAVES:3)
Block(9,11,-7,LEAVES:3)
Block(9,14,-2,LEAVES:3)
Block(9,14,2,17:15)
Block(9,14,4,17:15)
Block(9,14,5,LEAVES:3)
Block(9,15,-1,LEAVES:3)
Block(9,15,0,LEAVES:3)
Block(9,15,1,17:15)
Block(9,15,2,LEAVES:3)
Block(9,15,9,LEAVES:3)
Block(9,16,-1,LEAVES:3)
Block(9,16,0,LEAVES:3)
Block(9,16,1,LEAVES:3)
Block(9,16,3,LEAVES:3)
Block(9,16,4,LEAVES:3)
Block(9,16,5,LEAVES:3)
Block(9,16,6,LEAVES:3)
Block(9,16,7,17:15)
Block(9,16,8,LEAVES:3)
Block(9,16,9,LEAVES:3)
Block(9,16,10,LEAVES:3)
Block(9,17,-1,LEAVES:3)
Block(9,17,5,LEAVES:3)
Block(9,17,7,LEAVES:3)
Block(9,17,8,LEAVES:3)
Block(9,17,9,LEAVES:3)
Block(9,18,-9,LEAVES:3)
Block(9,18,-7,LEAVES:3)
Block(9,18,8,LEAVES:3)
Block(9,19,-9,LEAVES:3)
Block(9,19,-8,LEAVES:3)
Block(9,19,-7,LEAVES:3)
Block(9,19,4,LEAVES:3)
Block(9,19,6,LEAVES:3)
Block(9,20,-8,LEAVES:3)
Block(9,20,-7,LEAVES:3)
Block(9,20,-4,LEAVES:3)
Block(9,20,-3,LEAVES:3)
Block(9,20,-2,LEAVES:3)
Block(9,20,3,LEAVES:3)
Block(9,20,4,LEAVES:3)
Block(9,20,5,LEAVES:3)
Block(9,21,-4,LEAVES:3)
Block(9,21,-3,LEAVES:3)
Block(9,21,-2,LEAVES:3)
Block(9,21,4,LEAVES:3)
Block(9,22,-3,LEAVES:3)
Block(9,25,0,LEAVES:3)
Block(9,26,-2,LEAVES:3)
Block(9,26,3,LEAVES:3)
Block(9,27,-3,LEAVES:3)
Block(9,27,-2,LEAVES:3)
Block(9,27,-1,LEAVES:3)
Block(9,28,-2,LEAVES:3)
Block(9,33,2,LEAVES:3)
Block(9,34,1,LEAVES:3)
Block(9,34,2,LEAVES:3)
Block(9,35,-10,LEAVES:3)
Block(9,35,-7,LEAVES:3)
Block(9,35,-5,17:15)
Block(9,36,-10,LEAVES:3)
Block(9,36,-9,17:15)
Block(9,36,-8,LEAVES:3)
Block(9,36,-7,LEAVES:3)
Block(9,36,-6,LEAVES:3)
Block(9,36,-5,17:15)
Block(9,36,-4,LEAVES:3)
Block(9,36,-3,LEAVES:3)
Block(9,37,-9,LEAVES:3)
Block(9,37,-8,LEAVES:3)
Block(9,37,-7,LEAVES:3)
Block(9,37,-6,LEAVES:3)
Block(9,37,-5,LEAVES:3)
Block(9,37,-3,LEAVES:3)
Block(9,37,-2,LEAVES:3)
Block(9,37,-1,LEAVES:3)
Block(9,38,-6,LEAVES:3)
Block(9,38,-3,LEAVES:3)
Block(9,38,-2,LEAVES:3)
Block(9,50,-3,LEAVES:3)
Block(9,51,-5,LEAVES:3)
Block(9,51,-4,LEAVES:3)
Block(9,51,-3,LEAVES:3)
Block(9,52,-4,LEAVES:3)
Block(10,8,-9,LEAVES:3)
Block(10,8,-7,LEAVES:3)
Block(10,9,-8,LEAVES:3)
Block(10,9,-7,LEAVES:3)
Block(10,9,-6,LEAVES:3)
Block(10,10,-7,LEAVES:3)
Block(10,14,1,LEAVES:3)
Block(10,14,3,LEAVES:3)
Block(10,14,4,17:15)
Block(10,14,6,LEAVES:3)
Block(10,14,9,LEAVES:3)
Block(10,15,-2,LEAVES:3)
Block(10,15,0,17:15)
Block(10,15,1,LEAVES:3)
Block(10,15,2,LEAVES:3)
Block(10,15,4,LEAVES:3)
Block(10,15,6,LEAVES:3)
Block(10,15,7,LEAVES:3)
Block(10,16,-2,LEAVES:3)
Block(10,16,-1,17:15)
Block(10,16,0,LEAVES:3)
Block(10,16,1,LEAVES:3)
Block(10,16,2,LEAVES:3)
Block(10,16,5,LEAVES:3)
Block(10,16,6,LEAVES:3)
Block(10,16,7,LEAVES:3)
Block(10,16,8,LEAVES:3)
Block(10,16,9,LEAVES:3)
Block(10,17,-2,LEAVES:3)
Block(10,17,-1,LEAVES:3)
Block(10,17,1,LEAVES:3)
Block(10,17,7,LEAVES:3)
Block(10,17,8,LEAVES:3)
Block(10,18,-1,LEAVES:3)
Block(10,18,4,LEAVES:3)
Block(10,19,-8,LEAVES:3)
Block(10,19,-4,LEAVES:3)
Block(10,19,2,LEAVES:3)
Block(10,20,-4,LEAVES:3)
Block(10,20,-3,LEAVES:3)
Block(10,20,3,LEAVES:3)
Block(10,20,4,LEAVES:3)
Block(10,20,5,LEAVES:3)
Block(10,21,-3,LEAVES:3)
Block(10,21,4,LEAVES:3)
Block(10,25,-3,LEAVES:3)
Block(10,26,-3,LEAVES:3)
Block(10,27,-2,LEAVES:3)
Block(10,35,-9,LEAVES:3)
Block(10,35,-6,LEAVES:3)
Block(10,35,-4,LEAVES:3)
Block(10,36,-10,LEAVES:3)
Block(10,36,-9,17:15)
Block(10,36,-8,LEAVES:3)
Block(10,36,-7,LEAVES:3)
Block(10,36,-6,LEAVES:3)
Block(10,36,-4,17:15)
Block(10,36,-2,LEAVES:3)
Block(10,36,-1,LEAVES:3)
Block(10,37,-10,LEAVES:3)
Block(10,37,-9,LEAVES:3)
Block(10,37,-6,LEAVES:3)
Block(10,37,-4,LEAVES:3)
Block(10,37,-3,17:15)
Block(10,37,-2,LEAVES:3)
Block(10,37,-1,LEAVES:3)
Block(10,38,-4,LEAVES:3)
Block(10,38,-3,LEAVES:3)
Block(10,39,-3,LEAVES:3)
Block(10,50,-5,LEAVES:3)
Block(10,51,-4,LEAVES:3)
Block(11,7,-7,LEAVES:3)
Block(11,8,-5,LEAVES:3)
Block(11,9,-8,LEAVES:3)
Block(11,9,-7,LEAVES:3)
Block(11,9,-6,LEAVES:3)
Block(11,10,-7,LEAVES:3)
Block(11,13,3,LEAVES:3)
Block(11,14,4,17:15)
Block(11,15,-1,LEAVES:3)
Block(11,15,0,LEAVES:3)
Block(11,15,1,LEAVES:3)
Block(11,15,3,LEAVES:3)
Block(11,15,4,17:15)
Block(11,15,5,17:15)
Block(11,15,6,LEAVES:3)
Block(11,15,7,LEAVES:3)
Block(11,15,8,LEAVES:3)
Block(11,16,-3,LEAVES:3)
Block(11,16,-2,LEAVES:3)
Block(11,16,-1,LEAVES:3)
Block(11,16,0,LEAVES:3)
Block(11,16,1,LEAVES:3)
Block(11,16,4,LEAVES:3)
Block(11,16,5,LEAVES:3)
Block(11,16,6,LEAVES:3)
Block(11,16,7,LEAVES:3)
Block(11,16,8,LEAVES:3)
Block(11,17,-2,LEAVES:3)
Block(11,17,-1,LEAVES:3)
Block(11,17,6,LEAVES:3)
Block(11,19,4,LEAVES:3)
Block(11,20,4,LEAVES:3)
Block(11,35,-10,LEAVES:3)
Block(11,35,-6,LEAVES:3)
Block(11,36,-11,LEAVES:3)
Block(11,36,-10,LEAVES:3)
Block(11,36,-9,LEAVES:3)
Block(11,36,-8,LEAVES:3)
Block(11,36,-6,LEAVES:3)
Block(11,36,-5,17:15)
Block(11,36,-4,LEAVES:3)
Block(11,36,0,LEAVES:3)
Block(11,37,-10,LEAVES:3)
Block(11,37,-9,LEAVES:3)
Block(11,37,-5,LEAVES:3)
Block(11,37,-3,LEAVES:3)
Block(11,37,-2,17:15)
Block(11,37,-1,LEAVES:3)
Block(11,37,0,LEAVES:3)
Block(11,38,-5,LEAVES:3)
Block(11,38,-2,LEAVES:3)
Block(11,38,-1,LEAVES:3)
Block(12,8,-7,LEAVES:3)
Block(12,9,-7,LEAVES:3)
Block(12,14,0,LEAVES:3)
Block(12,15,-3,LEAVES:3)
Block(12,15,3,LEAVES:3)
Block(12,15,5,17:15)
Block(12,15,6,LEAVES:3)
Block(12,15,7,LEAVES:3)
Block(12,16,-2,LEAVES:3)
Block(12,16,-1,LEAVES:3)
Block(12,16,0,LEAVES:3)
Block(12,16,2,LEAVES:3)
Block(12,16,3,17:15)
Block(12,16,4,LEAVES:3)
Block(12,16,5,LEAVES:3)
Block(12,16,6,LEAVES:3)
Block(12,17,-1,LEAVES:3)
Block(12,17,3,LEAVES:3)
Block(12,17,4,LEAVES:3)
Block(12,18,3,LEAVES:3)
Block(12,35,-9,LEAVES:3)
Block(12,36,-10,LEAVES:3)
Block(12,36,-9,LEAVES:3)
Block(12,36,-8,LEAVES:3)
Block(12,36,-5,LEAVES:3)
Block(12,36,-2,LEAVES:3)
Block(12,37,-9,LEAVES:3)
Block(12,37,-7,LEAVES:3)
Block(12,37,-6,LEAVES:3)
Block(12,37,-5,17:15)
Block(12,37,-4,LEAVES:3)
Block(12,37,-3,LEAVES:3)
Block(12,37,-2,LEAVES:3)
Block(12,37,-1,LEAVES:3)
Block(12,38,-6,LEAVES:3)
Block(12,38,-5,LEAVES:3)
Block(12,38,-2,LEAVES:3)
Block(12,39,-5,LEAVES:3)
Block(13,14,3,LEAVES:3)
Block(13,14,5,LEAVES:3)
Block(13,15,2,LEAVES:3)
Block(13,15,4,LEAVES:3)
Block(13,15,5,17:15)
Block(13,15,6,LEAVES:3)
Block(13,15,7,LEAVES:3)
Block(13,16,-1,LEAVES:3)
Block(13,16,1,LEAVES:3)
Block(13,16,2,17:15)
Block(13,16,3,LEAVES:3)
Block(13,16,5,LEAVES:3)
Block(13,16,6,LEAVES:3)
Block(13,17,2,LEAVES:3)
Block(13,17,3,LEAVES:3)
Block(13,17,5,LEAVES:3)
Block(13,35,-8,LEAVES:3)
Block(13,36,-9,LEAVES:3)
Block(13,36,-7,LEAVES:3)
Block(13,36,-1,LEAVES:3)
Block(13,37,-7,LEAVES:3)
Block(13,37,-6,LEAVES:3)
Block(13,37,-5,LEAVES:3)
Block(13,37,-4,LEAVES:3)
Block(13,37,-3,LEAVES:3)
Block(13,37,-2,LEAVES:3)
Block(13,38,-5,LEAVES:3)
Block(14,14,7,LEAVES:3)
Block(14,15,5,LEAVES:3)
Block(14,15,6,17:15)
Block(14,15,7,LEAVES:3)
Block(14,15,8,LEAVES:3)
Block(14,16,1,LEAVES:3)
Block(14,16,2,LEAVES:3)
Block(14,16,3,LEAVES:3)
Block(14,16,5,LEAVES:3)
Block(14,16,6,LEAVES:3)
Block(14,16,7,LEAVES:3)
Block(14,17,2,LEAVES:3)
Block(14,36,-5,LEAVES:3)
Block(14,36,-3,LEAVES:3)
Block(14,37,-6,LEAVES:3)
Block(14,37,-5,LEAVES:3)
Block(14,37,-4,LEAVES:3)
Block(14,38,-5,LEAVES:3)
Block(15,14,6,LEAVES:3)
Block(15,14,8,LEAVES:3)
Block(15,15,1,LEAVES:3)
Block(15,15,3,LEAVES:3)
Block(15,15,6,LEAVES:3)
Block(15,15,7,LEAVES:3)
Block(15,15,8,LEAVES:3)
Block(15,16,2,LEAVES:3)
Block(15,16,5,LEAVES:3)
Block(15,16,6,17:15)
Block(15,16,7,LEAVES:3)
Block(15,17,6,LEAVES:3)
Block(15,37,-5,LEAVES:3)
Block(16,15,4,LEAVES:3)
Block(16,16,4,LEAVES:3)
Block(16,16,5,LEAVES:3)
Block(16,16,6,LEAVES:3)
Block(16,16,7,LEAVES:3)
Block(16,17,6,LEAVES:3)
Block(17,15,5,LEAVES:3)
Block(17,15,7,LEAVES:3)
Block(17,16,6,LEAVES:3)


#######################################################################
# +-----------------------------------------------------------------+ #
# |                             Entities                            | #
# +-----------------------------------------------------------------+ #
#######################################################################

# Entity() spawns an entity instead of a block. The entity is spawned only once when the BO3 is spawned.
# Entities are persistent by default so they don't de-spawn when no player is near, they are only unloaded.
# Usage: Entity(x,y,z,mobName,groupSize,NameTagOrNBTFileName) or Entity(x,y,z,mobName,groupSize)
# Use /tc entities or /otg entities to get a list of entities that can be used as mobName, this includes entities added by other mods.
# NameTagOrNBTFileName can be either a nametag for the mob or an nbt file (such as mymobinfo.nbt or mymobinfo.txt).
# When using a text file you can use the same mob spawning parameters used with the /summon command to equip the
# entity and give it custom attributes etc. You can copy the DATA part of a summon command including surrounding
# curly braces to a .txt file, for instance for: "/summon Skeleton x y z {DATA}"

#######################################################################
# +-----------------------------------------------------------------+ #
# |                            BO3 checks                           | #
# +-----------------------------------------------------------------+ #
#######################################################################

# Require a condition at a certain location in order for the BO3 to be spawned.
# BlockCheck(x,y,z,BlockName[,BlockName[,...]]) - one of the blocks must be at the location
# BlockCheckNot(x,y,z,BlockName[,BlockName[,...]]) - all the blocks must not be at the location
# LightCheck(x,y,z,minLightLevel,maxLightLevel) - light must be between min and max (inclusive)

# You can use "Solid" as a BlockName for matching all solid blocks or "All" to match all blocks that aren't air.

# Examples:
#   BlockCheck(0,-1,0,GRASS,DIRT)  Require grass or dirt just below the object
#   BlockCheck(0,-1,0,Solid)       Require any solid block just below the object
#   BlockCheck(0,-1,0,WOOL)        Require any type of wool just below the object
#   BlockCheck(0,-1,0,WOOL:0)      Require white wool just below the object
#   BlockCheckNot(0,-1,0,WOOL:0)   Require that there is no white wool below the object
#   LightCheck(0,0,0,0,LEAVES:3)          Require almost complete darkness just below the object

