#######################################################################
# +-----------------------------------------------------------------+ #
# |                            BO3 object                           | #
# +-----------------------------------------------------------------+ #
#######################################################################

# The descriptions in this file are accurate only for TerrainControl and OTG.
# For MCW and OTG+ these descriptions are only accurate if the BO3 is used as a CustomObject.
# MCW and OTG+ completely reimplemented CustomStructure, check the MCW/OTG+ documentation for more information.

# This is the config file of a custom object.
# If you add this object correctly to your BiomeConfigs, it will spawn in the world.

# This is the creator of this BO3 object
Author: Unknown

# A short description of this BO3 object
Description: This BO3 was converted from a schematic using OTGEdit. The author and description information of the schematic could not be found. If you know who the author of the schematic is then please add this information.

# The BO3 version, don't change this! It can be used by external applications to do a version check.
Version: 3

# The settings mode, WriteAll, WriteWithoutComments or WriteDisable. See WorldConfig.
SettingsMode: WriteDisable

#######################################################################
# +-----------------------------------------------------------------+ #
# |                          Main settings                          | #
# +-----------------------------------------------------------------+ #
#######################################################################

# This needs to be set to true to spawn the object in the Tree and Sapling resources.
Tree: true

# The frequency of the BO3 from 1 to 200. Tries this many times to spawn this BO3 when using the CustomObject(...) resource.
# Ignored by Tree(..), Sapling(..) and CustomStructure(..)
Frequency: 1

# The rarity of the BO3 from 0 to 100. Each spawn attempt has rarity% chance to succeed when using the CustomObject(...) resource.
# Ignored by Tree(..), Sapling(..) and CustomStructure(..)
Rarity: 100.0

# If you set this to true, the BO3 will be placed with a random rotation.
RotateRandomly: false

# The spawn height of the BO3 - randomY, highestBlock or highestSolidBlock.
SpawnHeight: highestBlock

# The height limits for the BO3.
MinHeight: 64

MaxHeight: 80

# Objects can have other objects attached to it: branches. Branches can also
# have branches attached to it, which can also have branches, etc. This is the
# maximum branch depth for this objects.
MaxBranchDepth: 10

# When spawned with the UseWorld keyword, this BO3 should NOT spawn in the following biomes.
# If you writer.write the BO3 name directly in the BiomeConfigs, this will be ignored.
ExcludedBiomes: All

# To optimise this BO3 for faster loading times you can use Notepad++ to find/replace comments and abbreviate things.
# Notepad++ find/replace with regex:
# Find: ^[#;].* replace to nothing removes all lines starting with # 
# Find: ^\s*$ replace to nothing removes most empty lines 
# Notepad++ find/replace without regex:
# *Warning: This will only work for OTG 1.10.2 v21 / OTG 1.11.2 v6 or higher. B( is not recognised by lower versions.
# Find: Block( replace to B(

#######################################################################
# +-----------------------------------------------------------------+ #
# |                      Source block settings                      | #
# +-----------------------------------------------------------------+ #
#######################################################################

# The block(s) the BO3 should spawn in.
SourceBlocks: STONE:1,STONE:3,STONE:5,DIRT:1,DIRT,SAND,GRASS,DIRT:2,STATIONARY_WATER,HARD_CLAY,STAINED_CLAY,CLAY,SANDSTONE,SAND:1,AIR,STONE,GRAVEL,LONG_GRASS,LONG_GRASS:1,LONG_GRASS:2,DEAD_BUSH,YELLOW_FLOWER,RED_ROSE,BROWN_MUSHROOM,RED_MUSHROOM

# The maximum percentage of the BO3 that can be outside the SourceBlock.
# The BO3 won't be placed on a location with more blocks outside the SourceBlock than this percentage.
MaxPercentageOutsideSourceBlock: 0

# What to do when a block is about to be placed outside the SourceBlock? (dontPlace, placeAnyway)
OutsideSourceBlock: placeAnyway

#######################################################################
# +-----------------------------------------------------------------+ #
# |                              Blocks                             | #
# +-----------------------------------------------------------------+ #
#######################################################################

# All the blocks used in the BO3 are listed here. Possible blocks:
# Block(x,y,z,id[.data][,nbtfile.nbt) or B(x,y,z,id[.data][,nbtfile.nbt)
# RandomBlock(x,y,z,id[:data][,nbtfile.nbt],chance[,id[:data][,nbtfile.nbt],chance[,...]])
# So RandomBlock(0,0,0,CHEST,chest.nbt,50,CHEST,anotherchest.nbt,100) will spawn a chest at
# the BO3 origin, and give it a 50% chance to have the contents of chest.nbt, or, if that
# fails, a 100% percent chance to have the contents of anotherchest.nbt.

Block(-12,30,2,LEAVES:3)
Block(-12,31,1,LEAVES:3)
Block(-11,30,0,LEAVES:3)
Block(-11,31,0,LEAVES:3)
Block(-11,31,1,LEAVES:3)
Block(-11,31,2,LEAVES:3)
Block(-11,32,1,LEAVES:3)
Block(-10,29,-2,LEAVES:3)
Block(-10,30,-1,LEAVES:3)
Block(-10,30,2,LEAVES:3)
Block(-10,31,0,LEAVES:3)
Block(-10,31,1,LEAVES:3)
Block(-10,31,2,LEAVES:3)
Block(-10,31,3,LEAVES:3)
Block(-10,32,1,LEAVES:3)
Block(-10,32,2,LEAVES:3)
Block(-9,29,-4,LEAVES:3)
Block(-9,30,-4,LEAVES:3)
Block(-9,30,-2,LEAVES:3)
Block(-9,30,-1,LEAVES:3)
Block(-9,30,0,LEAVES:3)
Block(-9,31,-1,LEAVES:3)
Block(-9,31,0,LEAVES:3)
Block(-9,31,1,17:15)
Block(-9,31,2,LEAVES:3)
Block(-9,32,1,LEAVES:3)
Block(-9,33,1,LEAVES:3)
Block(-8,29,-2,LEAVES:3)
Block(-8,29,0,LEAVES:3)
Block(-8,29,2,LEAVES:3)
Block(-8,30,-5,LEAVES:3)
Block(-8,30,-4,LEAVES:3)
Block(-8,30,-3,LEAVES:3)
Block(-8,30,-2,LEAVES:3)
Block(-8,30,-1,LEAVES:3)
Block(-8,30,0,17:15)
Block(-8,30,1,LEAVES:3)
Block(-8,30,2,LEAVES:3)
Block(-8,31,-4,LEAVES:3)
Block(-8,31,-2,LEAVES:3)
Block(-8,31,-1,LEAVES:3)
Block(-8,31,0,LEAVES:3)
Block(-8,31,1,LEAVES:3)
Block(-8,32,-1,LEAVES:3)
Block(-8,32,1,LEAVES:3)
Block(-8,34,1,LEAVES:3)
Block(-8,35,0,LEAVES:3)
Block(-7,29,-5,LEAVES:3)
Block(-7,29,-3,LEAVES:3)
Block(-7,29,-2,LEAVES:3)
Block(-7,30,-6,LEAVES:3)
Block(-7,30,-5,LEAVES:3)
Block(-7,30,-4,17:15)
Block(-7,30,-2,LEAVES:3)
Block(-7,30,-1,17:15)
Block(-7,30,0,LEAVES:3)
Block(-7,30,1,LEAVES:3)
Block(-7,31,-5,LEAVES:3)
Block(-7,31,-4,LEAVES:3)
Block(-7,31,-3,LEAVES:3)
Block(-7,31,-1,LEAVES:3)
Block(-7,32,-4,LEAVES:3)
Block(-7,33,-9,LEAVES:3)
Block(-7,34,-1,LEAVES:3)
Block(-7,35,-1,LEAVES:3)
Block(-7,35,0,LEAVES:3)
Block(-7,35,1,LEAVES:3)
Block(-7,36,0,LEAVES:3)
Block(-6,28,-1,LEAVES:3)
Block(-6,28,2,LEAVES:3)
Block(-6,29,-4,LEAVES:3)
Block(-6,29,-3,17:15)
Block(-6,29,-2,17:15)
Block(-6,29,-1,17:15)
Block(-6,29,1,LEAVES:3)
Block(-6,30,-5,LEAVES:3)
Block(-6,30,-4,LEAVES:3)
Block(-6,30,-3,LEAVES:3)
Block(-6,30,-2,LEAVES:3)
Block(-6,30,-1,17:15)
Block(-6,30,0,LEAVES:3)
Block(-6,30,1,LEAVES:3)
Block(-6,31,-2,LEAVES:3)
Block(-6,31,-1,LEAVES:3)
Block(-6,31,0,LEAVES:3)
Block(-6,32,-9,LEAVES:3)
Block(-6,32,-7,LEAVES:3)
Block(-6,32,-1,LEAVES:3)
Block(-6,33,-10,LEAVES:3)
Block(-6,33,-9,LEAVES:3)
Block(-6,33,-8,LEAVES:3)
Block(-6,33,-7,LEAVES:3)
Block(-6,33,3,LEAVES:3)
Block(-6,33,5,LEAVES:3)
Block(-6,34,-9,LEAVES:3)
Block(-6,34,-8,LEAVES:3)
Block(-6,34,0,LEAVES:3)
Block(-6,34,3,LEAVES:3)
Block(-6,34,6,LEAVES:3)
Block(-6,35,-2,LEAVES:3)
Block(-6,35,-1,LEAVES:3)
Block(-6,35,0,LEAVES:3)
Block(-6,35,1,LEAVES:3)
Block(-6,35,5,LEAVES:3)
Block(-6,36,-1,LEAVES:3)
Block(-6,36,0,LEAVES:3)
Block(-5,15,-7,LEAVES:3)
Block(-5,16,-9,LEAVES:3)
Block(-5,16,-6,LEAVES:3)
Block(-5,17,-8,LEAVES:3)
Block(-5,18,5,LEAVES:3)
Block(-5,18,7,LEAVES:3)
Block(-5,19,6,LEAVES:3)
Block(-5,19,7,LEAVES:3)
Block(-5,19,8,LEAVES:3)
Block(-5,20,6,LEAVES:3)
Block(-5,20,7,LEAVES:3)
Block(-5,29,-2,LEAVES:3)
Block(-5,29,-1,17:15)
Block(-5,29,0,17:15)
Block(-5,29,1,LEAVES:3)
Block(-5,29,2,LEAVES:3)
Block(-5,30,-2,LEAVES:3)
Block(-5,30,-1,LEAVES:3)
Block(-5,30,0,LEAVES:3)
Block(-5,30,1,LEAVES:3)
Block(-5,30,8,LEAVES:3)
Block(-5,31,-1,LEAVES:3)
Block(-5,31,8,LEAVES:3)
Block(-5,32,-10,LEAVES:3)
Block(-5,32,-8,LEAVES:3)
Block(-5,33,-11,LEAVES:3)
Block(-5,33,-10,LEAVES:3)
Block(-5,33,-9,LEAVES:3)
Block(-5,33,-8,17:15)
Block(-5,33,-7,17:15)
Block(-5,33,-6,LEAVES:3)
Block(-5,33,1,LEAVES:3)
Block(-5,34,-10,LEAVES:3)
Block(-5,34,-9,LEAVES:3)
Block(-5,34,-8,LEAVES:3)
Block(-5,34,-7,LEAVES:3)
Block(-5,34,-2,LEAVES:3)
Block(-5,34,0,LEAVES:3)
Block(-5,34,2,LEAVES:3)
Block(-5,34,3,LEAVES:3)
Block(-5,34,4,LEAVES:3)
Block(-5,34,5,LEAVES:3)
Block(-5,35,-1,LEAVES:3)
Block(-5,35,0,17:15)
Block(-5,35,1,LEAVES:3)
Block(-5,35,3,LEAVES:3)
Block(-5,35,4,LEAVES:3)
Block(-5,35,5,LEAVES:3)
Block(-5,35,6,LEAVES:3)
Block(-5,36,0,LEAVES:3)
Block(-5,36,5,LEAVES:3)
Block(-5,37,0,LEAVES:3)
Block(-4,-4,-2,17:15)
Block(-4,-4,2,17:15)
Block(-4,-3,-2,17:15)
Block(-4,-3,2,17:15)
Block(-4,-2,2,17:15)
Block(-4,15,-6,LEAVES:3)
Block(-4,15,-4,LEAVES:3)
Block(-4,16,-7,LEAVES:3)
Block(-4,16,-6,LEAVES:3)
Block(-4,16,-5,LEAVES:3)
Block(-4,17,-9,LEAVES:3)
Block(-4,17,-8,LEAVES:3)
Block(-4,17,-7,LEAVES:3)
Block(-4,17,-6,LEAVES:3)
Block(-4,18,-8,LEAVES:3)
Block(-4,18,9,LEAVES:3)
Block(-4,19,5,LEAVES:3)
Block(-4,19,6,LEAVES:3)
Block(-4,19,7,17:15)
Block(-4,19,8,LEAVES:3)
Block(-4,19,9,LEAVES:3)
Block(-4,20,7,LEAVES:3)
Block(-4,20,8,LEAVES:3)
Block(-4,29,-1,17:15)
Block(-4,29,1,LEAVES:3)
Block(-4,30,-1,LEAVES:3)
Block(-4,30,7,LEAVES:3)
Block(-4,30,10,LEAVES:3)
Block(-4,31,-4,LEAVES:3)
Block(-4,31,3,17:15)
Block(-4,31,6,LEAVES:3)
Block(-4,31,7,LEAVES:3)
Block(-4,31,8,LEAVES:3)
Block(-4,31,9,LEAVES:3)
Block(-4,32,-11,LEAVES:3)
Block(-4,32,-6,LEAVES:3)
Block(-4,32,-5,LEAVES:3)
Block(-4,32,8,LEAVES:3)
Block(-4,33,-10,LEAVES:3)
Block(-4,33,-9,LEAVES:3)
Block(-4,33,-8,LEAVES:3)
Block(-4,33,-7,LEAVES:3)
Block(-4,33,-6,17:15)
Block(-4,34,-7,LEAVES:3)
Block(-4,34,-6,LEAVES:3)
Block(-4,34,0,LEAVES:3)
Block(-4,34,1,LEAVES:3)
Block(-4,34,2,LEAVES:3)
Block(-4,34,3,17:15)
Block(-4,34,4,LEAVES:3)
Block(-4,34,7,LEAVES:3)
Block(-4,35,0,LEAVES:3)
Block(-4,35,1,17:15)
Block(-4,35,3,LEAVES:3)
Block(-4,35,4,17:15)
Block(-4,35,5,17:15)
Block(-4,35,6,LEAVES:3)
Block(-4,35,7,LEAVES:3)
Block(-4,36,-1,LEAVES:3)
Block(-4,36,0,LEAVES:3)
Block(-4,36,1,LEAVES:3)
Block(-4,36,4,LEAVES:3)
Block(-4,36,5,LEAVES:3)
Block(-4,36,6,LEAVES:3)
Block(-4,37,4,LEAVES:3)
Block(-3,-4,3,17:15)
Block(-3,-3,-2,17:15)
Block(-3,-3,1,17:15)
Block(-3,-3,3,17:15)
Block(-3,-2,-2,17:15)
Block(-3,-2,1,17:15)
Block(-3,-1,1,17:15)
Block(-3,16,-10,LEAVES:3)
Block(-3,16,-8,LEAVES:3)
Block(-3,16,-6,17:15)
Block(-3,16,-5,LEAVES:3)
Block(-3,17,-10,LEAVES:3)
Block(-3,17,-9,LEAVES:3)
Block(-3,17,-8,LEAVES:3)
Block(-3,17,-7,17:15)
Block(-3,17,-6,LEAVES:3)
Block(-3,17,-5,LEAVES:3)
Block(-3,18,-9,LEAVES:3)
Block(-3,18,-8,LEAVES:3)
Block(-3,18,-7,LEAVES:3)
Block(-3,18,-6,LEAVES:3)
Block(-3,18,6,LEAVES:3)
Block(-3,19,-7,LEAVES:3)
Block(-3,19,4,LEAVES:3)
Block(-3,19,5,LEAVES:3)
Block(-3,19,6,17:15)
Block(-3,19,7,LEAVES:3)
Block(-3,19,8,LEAVES:3)
Block(-3,19,9,LEAVES:3)
Block(-3,20,5,LEAVES:3)
Block(-3,20,6,LEAVES:3)
Block(-3,29,-1,17:15)
Block(-3,29,2,17:15)
Block(-3,30,2,17:15)
Block(-3,30,7,LEAVES:3)
Block(-3,30,9,LEAVES:3)
Block(-3,31,-4,LEAVES:3)
Block(-3,31,-3,LEAVES:3)
Block(-3,31,5,LEAVES:3)
Block(-3,31,6,LEAVES:3)
Block(-3,31,7,LEAVES:3)
Block(-3,31,8,17:15)
Block(-3,31,9,LEAVES:3)
Block(-3,31,10,LEAVES:3)
Block(-3,32,-7,LEAVES:3)
Block(-3,32,-5,17:15)
Block(-3,32,-4,LEAVES:3)
Block(-3,32,6,LEAVES:3)
Block(-3,32,8,LEAVES:3)
Block(-3,32,9,LEAVES:3)
Block(-3,33,-11,LEAVES:3)
Block(-3,33,-8,LEAVES:3)
Block(-3,33,-7,LEAVES:3)
Block(-3,33,-6,17:15)
Block(-3,33,-5,LEAVES:3)
Block(-3,33,-4,LEAVES:3)
Block(-3,33,-1,LEAVES:3)
Block(-3,33,3,LEAVES:3)
Block(-3,34,-11,LEAVES:3)
Block(-3,34,-10,LEAVES:3)
Block(-3,34,-7,LEAVES:3)
Block(-3,34,-6,LEAVES:3)
Block(-3,34,-5,LEAVES:3)
Block(-3,34,-1,LEAVES:3)
Block(-3,34,0,LEAVES:3)
Block(-3,34,1,17:15)
Block(-3,34,2,17:15)
Block(-3,34,3,LEAVES:3)
Block(-3,35,-6,LEAVES:3)
Block(-3,35,-1,LEAVES:3)
Block(-3,35,0,LEAVES:3)
Block(-3,35,1,LEAVES:3)
Block(-3,35,2,LEAVES:3)
Block(-3,35,4,LEAVES:3)
Block(-3,35,5,LEAVES:3)
Block(-3,35,6,LEAVES:3)
Block(-3,36,-2,LEAVES:3)
Block(-3,36,-1,LEAVES:3)
Block(-3,36,0,LEAVES:3)
Block(-3,36,1,LEAVES:3)
Block(-3,36,4,LEAVES:3)
Block(-3,37,-1,LEAVES:3)
Block(-2,-3,3,17:15)
Block(-2,-2,-2,17:15)
Block(-2,-2,3,17:15)
Block(-2,-1,-2,17:15)
Block(-2,-1,-1,17:15)
Block(-2,-1,1,17:15)
Block(-2,0,-1,17:15)
Block(-2,0,1,17:15)
Block(-2,1,-1,17:15)
Block(-2,2,-1,17:15)
Block(-2,15,-4,17:15)
Block(-2,15,-3,17:15)
Block(-2,16,-5,17:15)
Block(-2,16,-4,LEAVES:3)
Block(-2,17,-9,LEAVES:3)
Block(-2,17,-8,LEAVES:3)
Block(-2,17,-7,LEAVES:3)
Block(-2,17,-6,LEAVES:3)
Block(-2,17,-5,LEAVES:3)
Block(-2,17,3,17:15)
Block(-2,18,-7,LEAVES:3)
Block(-2,18,4,17:15)
Block(-2,18,5,17:15)
Block(-2,19,5,LEAVES:3)
Block(-2,19,6,17:15)
Block(-2,20,6,LEAVES:3)
Block(-2,20,7,LEAVES:3)
Block(-2,20,8,LEAVES:3)
Block(-2,20,9,LEAVES:3)
Block(-2,20,10,LEAVES:3)
Block(-2,21,8,LEAVES:3)
Block(-2,28,-1,17:15)
Block(-2,28,1,17:15)
Block(-2,29,-1,17:15)
Block(-2,30,6,LEAVES:3)
Block(-2,30,11,LEAVES:3)
Block(-2,31,-6,LEAVES:3)
Block(-2,31,-4,17:15)
Block(-2,31,4,LEAVES:3)
Block(-2,31,5,LEAVES:3)
Block(-2,31,6,LEAVES:3)
Block(-2,31,7,17:15)
Block(-2,31,8,LEAVES:3)
Block(-2,31,9,LEAVES:3)
Block(-2,31,10,LEAVES:3)
Block(-2,32,-9,LEAVES:3)
Block(-2,32,-8,LEAVES:3)
Block(-2,32,-7,17:15)
Block(-2,32,-6,17:15)
Block(-2,32,-5,17:15)
Block(-2,32,-4,17:15)
Block(-2,32,-3,LEAVES:3)
Block(-2,32,5,LEAVES:3)
Block(-2,32,6,LEAVES:3)
Block(-2,32,7,LEAVES:3)
Block(-2,33,-9,LEAVES:3)
Block(-2,33,-8,LEAVES:3)
Block(-2,33,-7,LEAVES:3)
Block(-2,33,-6,LEAVES:3)
Block(-2,33,-5,LEAVES:3)
Block(-2,33,-4,LEAVES:3)
Block(-2,33,2,17:15)
Block(-2,33,3,17:15)
Block(-2,33,7,LEAVES:3)
Block(-2,34,-12,LEAVES:3)
Block(-2,34,-11,LEAVES:3)
Block(-2,34,-10,LEAVES:3)
Block(-2,34,-8,LEAVES:3)
Block(-2,34,-7,LEAVES:3)
Block(-2,34,-5,LEAVES:3)
Block(-2,34,0,LEAVES:3)
Block(-2,34,1,LEAVES:3)
Block(-2,34,2,17:15)
Block(-2,34,5,LEAVES:3)
Block(-2,35,-10,LEAVES:3)
Block(-2,35,-7,LEAVES:3)
Block(-2,35,-3,LEAVES:3)
Block(-2,35,0,LEAVES:3)
Block(-2,35,4,LEAVES:3)
Block(-2,36,-3,LEAVES:3)
Block(-2,36,-2,LEAVES:3)
Block(-2,36,-1,17:15)
Block(-2,36,0,LEAVES:3)
Block(-2,37,-2,LEAVES:3)
Block(-2,37,-1,LEAVES:3)
Block(-2,38,-1,LEAVES:3)
Block(-1,-4,-4,17:15)
Block(-1,-4,0,17:15)
Block(-1,-4,4,17:15)
Block(-1,-3,-4,17:15)
Block(-1,-3,-3,17:15)
Block(-1,-3,0,17:15)
Block(-1,-3,4,17:15)
Block(-1,-2,-3,17:15)
Block(-1,-2,-2,17:15)
Block(-1,-2,2,17:15)
Block(-1,-2,3,17:15)
Block(-1,-1,-3,17:15)
Block(-1,-1,-2,17:15)
Block(-1,-1,1,17:15)
Block(-1,-1,2,17:15)
Block(-1,-1,3,17:15)
Block(-1,0,-2,17:15)
Block(-1,0,-1,17:15)
Block(-1,0,1,17:15)
Block(-1,0,2,17:15)
Block(-1,1,-1,17:15)
Block(-1,1,0,17:15)
Block(-1,1,1,17:15)
Block(-1,2,-1,17:15)
Block(-1,2,0,17:15)
Block(-1,3,-1,17:15)
Block(-1,3,0,17:15)
Block(-1,4,-1,17:15)
Block(-1,4,0,17:15)
Block(-1,5,-1,17:15)
Block(-1,5,0,17:15)
Block(-1,6,-1,17:15)
Block(-1,6,0,17:15)
Block(-1,7,-1,17:15)
Block(-1,7,0,17:15)
Block(-1,8,-1,17:15)
Block(-1,8,0,17:15)
Block(-1,9,-1,17:15)
Block(-1,9,0,17:15)
Block(-1,10,0,17:15)
Block(-1,11,0,17:15)
Block(-1,12,0,17:15)
Block(-1,13,-1,17:15)
Block(-1,13,0,17:15)
Block(-1,14,-2,17:15)
Block(-1,14,-1,17:15)
Block(-1,14,0,17:15)
Block(-1,15,-5,LEAVES:3)
Block(-1,15,0,17:15)
Block(-1,16,-8,LEAVES:3)
Block(-1,16,-7,LEAVES:3)
Block(-1,16,-6,LEAVES:3)
Block(-1,16,-5,17:15)
Block(-1,16,-4,LEAVES:3)
Block(-1,16,-3,LEAVES:3)
Block(-1,16,0,17:15)
Block(-1,17,-5,LEAVES:3)
Block(-1,17,-4,LEAVES:3)
Block(-1,17,0,17:15)
Block(-1,17,2,17:15)
Block(-1,18,0,17:15)
Block(-1,19,0,17:15)
Block(-1,19,6,LEAVES:3)
Block(-1,19,7,17:15)
Block(-1,19,9,LEAVES:3)
Block(-1,19,11,LEAVES:3)
Block(-1,20,6,LEAVES:3)
Block(-1,20,7,LEAVES:3)
Block(-1,20,8,17:15)
Block(-1,20,9,LEAVES:3)
Block(-1,20,10,LEAVES:3)
Block(-1,20,11,LEAVES:3)
Block(-1,21,7,LEAVES:3)
Block(-1,21,8,LEAVES:3)
Block(-1,21,9,LEAVES:3)
Block(-1,21,10,LEAVES:3)
Block(-1,22,8,LEAVES:3)
Block(-1,27,0,17:15)
Block(-1,28,0,17:15)
Block(-1,29,7,LEAVES:3)
Block(-1,30,5,LEAVES:3)
Block(-1,30,6,LEAVES:3)
Block(-1,30,7,17:15)
Block(-1,30,8,LEAVES:3)
Block(-1,31,-5,17:15)
Block(-1,31,-4,17:15)
Block(-1,31,-3,17:15)
Block(-1,31,5,LEAVES:3)
Block(-1,31,7,LEAVES:3)
Block(-1,31,9,LEAVES:3)
Block(-1,31,10,LEAVES:3)
Block(-1,31,11,LEAVES:3)
Block(-1,32,-7,17:15)
Block(-1,32,-6,LEAVES:3)
Block(-1,32,-4,LEAVES:3)
Block(-1,32,0,17:15)
Block(-1,32,7,LEAVES:3)
Block(-1,33,-12,LEAVES:3)
Block(-1,33,-10,LEAVES:3)
Block(-1,33,-9,17:15)
Block(-1,33,-7,17:15)
Block(-1,33,-6,LEAVES:3)
Block(-1,33,-5,LEAVES:3)
Block(-1,33,1,17:15)
Block(-1,34,-13,LEAVES:3)
Block(-1,34,-12,LEAVES:3)
Block(-1,34,-11,LEAVES:3)
Block(-1,34,-10,17:15)
Block(-1,34,-9,LEAVES:3)
Block(-1,34,-7,LEAVES:3)
Block(-1,34,-6,LEAVES:3)
Block(-1,35,-12,LEAVES:3)
Block(-1,35,-11,LEAVES:3)
Block(-1,35,-10,LEAVES:3)
Block(-1,35,-9,LEAVES:3)
Block(-1,35,-1,LEAVES:3)
Block(-1,35,0,17:15)
Block(-1,36,-10,LEAVES:3)
Block(-1,36,-2,LEAVES:3)
Block(-1,36,0,LEAVES:3)
Block(-1,37,-1,LEAVES:3)
Block(0,-4,0,17:15)
Block(0,-4,3,17:15)
Block(0,-3,0,17:15)
Block(0,-3,3,17:15)
Block(0,-2,0,17:15)
Block(0,-2,3,17:15)
Block(0,-1,-3,17:15)
Block(0,-1,0,17:15)
Block(0,0,-3,17:15)
Block(0,0,-2,17:15)
Block(0,0,0,17:15)
Block(0,0,1,17:15)
Block(0,1,-3,17:15)
Block(0,1,-2,17:15)
Block(0,1,-1,17:15)
Block(0,1,0,17:15)
Block(0,1,1,17:15)
Block(0,2,-2,17:15)
Block(0,2,-1,17:15)
Block(0,2,0,17:15)
Block(0,2,1,17:15)
Block(0,3,-2,17:15)
Block(0,3,-1,17:15)
Block(0,3,0,17:15)
Block(0,3,1,17:15)
Block(0,4,-2,17:15)
Block(0,4,-1,17:15)
Block(0,4,0,17:15)
Block(0,4,1,17:15)
Block(0,5,-2,17:15)
Block(0,5,-1,17:15)
Block(0,5,0,17:15)
Block(0,5,1,17:15)
Block(0,6,-1,17:15)
Block(0,6,0,17:15)
Block(0,6,1,17:15)
Block(0,7,-1,17:15)
Block(0,7,0,17:15)
Block(0,7,1,17:15)
Block(0,8,-1,17:15)
Block(0,8,0,17:15)
Block(0,8,1,17:15)
Block(0,9,-1,17:15)
Block(0,9,0,17:15)
Block(0,9,1,17:15)
Block(0,10,-1,17:15)
Block(0,10,0,17:15)
Block(0,10,1,17:15)
Block(0,11,-1,17:15)
Block(0,11,0,17:15)
Block(0,11,1,17:15)
Block(0,12,-1,17:15)
Block(0,12,0,17:15)
Block(0,12,1,17:15)
Block(0,13,-1,17:15)
Block(0,13,0,17:15)
Block(0,14,-1,17:15)
Block(0,14,0,17:15)
Block(0,15,-8,LEAVES:3)
Block(0,15,-1,17:15)
Block(0,15,0,17:15)
Block(0,16,-8,LEAVES:3)
Block(0,16,-7,LEAVES:3)
Block(0,16,-6,17:15)
Block(0,16,-5,LEAVES:3)
Block(0,16,-4,LEAVES:3)
Block(0,16,-1,17:15)
Block(0,16,0,17:15)
Block(0,16,1,17:15)
Block(0,17,-7,LEAVES:3)
Block(0,17,-6,LEAVES:3)
Block(0,17,-1,17:15)
Block(0,17,0,17:15)
Block(0,17,1,17:15)
Block(0,18,-1,17:15)
Block(0,18,0,17:15)
Block(0,18,2,17:15)
Block(0,18,5,LEAVES:3)
Block(0,18,7,LEAVES:3)
Block(0,19,-1,17:15)
Block(0,19,0,17:15)
Block(0,19,6,LEAVES:3)
Block(0,19,7,LEAVES:3)
Block(0,19,8,LEAVES:3)
Block(0,20,-1,17:15)
Block(0,20,0,17:15)
Block(0,20,7,LEAVES:3)
Block(0,20,8,LEAVES:3)
Block(0,20,9,LEAVES:3)
Block(0,20,10,LEAVES:3)
Block(0,21,-1,17:15)
Block(0,21,0,17:15)
Block(0,21,9,LEAVES:3)
Block(0,22,-1,17:15)
Block(0,22,0,17:15)
Block(0,23,-1,17:15)
Block(0,23,0,17:15)
Block(0,24,0,17:15)
Block(0,25,0,17:15)
Block(0,26,0,17:15)
Block(0,26,1,17:15)
Block(0,27,0,17:15)
Block(0,27,1,17:15)
Block(0,27,2,17:15)
Block(0,28,0,17:15)
Block(0,28,2,17:15)
Block(0,28,3,17:15)
Block(0,29,-1,17:15)
Block(0,29,0,17:15)
Block(0,29,3,LEAVES:3)
Block(0,29,5,LEAVES:3)
Block(0,29,6,17:15)
Block(0,30,-2,17:15)
Block(0,30,-1,17:15)
Block(0,30,0,17:15)
Block(0,30,4,LEAVES:3)
Block(0,30,5,LEAVES:3)
Block(0,30,6,17:15)
Block(0,30,8,17:15)
Block(0,30,9,LEAVES:3)
Block(0,30,11,LEAVES:3)
Block(0,31,-3,17:15)
Block(0,31,0,17:15)
Block(0,31,1,17:15)
Block(0,31,5,LEAVES:3)
Block(0,31,6,LEAVES:3)
Block(0,31,8,LEAVES:3)
Block(0,31,9,17:15)
Block(0,31,10,LEAVES:3)
Block(0,31,11,LEAVES:3)
Block(0,31,12,LEAVES:3)
Block(0,32,-8,LEAVES:3)
Block(0,32,0,17:15)
Block(0,32,8,LEAVES:3)
Block(0,32,9,LEAVES:3)
Block(0,32,10,LEAVES:3)
Block(0,32,11,LEAVES:3)
Block(0,33,-9,LEAVES:3)
Block(0,33,-8,17:15)
Block(0,33,-7,LEAVES:3)
Block(0,33,-6,LEAVES:3)
Block(0,33,0,17:15)
Block(0,33,9,LEAVES:3)
Block(0,34,-12,LEAVES:3)
Block(0,34,-11,LEAVES:3)
Block(0,34,-10,LEAVES:3)
Block(0,34,-8,LEAVES:3)
Block(0,34,-6,LEAVES:3)
Block(0,35,-8,LEAVES:3)
Block(0,35,-4,LEAVES:3)
Block(0,35,-2,LEAVES:3)
Block(0,35,-1,LEAVES:3)
Block(0,35,0,17:15)
Block(0,35,1,LEAVES:3)
Block(0,36,-3,LEAVES:3)
Block(0,36,-2,LEAVES:3)
Block(0,36,-1,LEAVES:3)
Block(0,36,0,LEAVES:3)
Block(0,36,1,LEAVES:3)
Block(0,37,-2,LEAVES:3)
Block(0,37,0,LEAVES:3)
Block(1,-4,-5,17:15)
Block(1,-3,-5,17:15)
Block(1,-3,-4,17:15)
Block(1,-2,-4,17:15)
Block(1,-2,-3,17:15)
Block(1,-2,2,17:15)
Block(1,-1,-3,17:15)
Block(1,-1,-1,17:15)
Block(1,-1,1,17:15)
Block(1,-1,2,17:15)
Block(1,0,-3,17:15)
Block(1,0,-1,17:15)
Block(1,0,0,17:15)
Block(1,0,1,17:15)
Block(1,0,2,17:15)
Block(1,1,-1,17:15)
Block(1,1,0,17:15)
Block(1,1,1,17:15)
Block(1,2,-1,17:15)
Block(1,2,0,17:15)
Block(1,2,1,17:15)
Block(1,3,-1,17:15)
Block(1,3,0,17:15)
Block(1,3,1,17:15)
Block(1,4,0,17:15)
Block(1,4,1,17:15)
Block(1,5,0,17:15)
Block(1,6,0,17:15)
Block(1,7,0,17:15)
Block(1,8,0,17:15)
Block(1,9,0,17:15)
Block(1,15,-6,LEAVES:3)
Block(1,16,-7,LEAVES:3)
Block(1,16,-6,LEAVES:3)
Block(1,16,-5,LEAVES:3)
Block(1,17,-6,LEAVES:3)
Block(1,17,-5,LEAVES:3)
Block(1,17,2,LEAVES:3)
Block(1,18,2,LEAVES:3)
Block(1,18,3,17:15)
Block(1,18,5,LEAVES:3)
Block(1,18,8,LEAVES:3)
Block(1,19,5,LEAVES:3)
Block(1,19,7,LEAVES:3)
Block(1,19,10,LEAVES:3)
Block(1,20,9,LEAVES:3)
Block(1,28,0,17:15)
Block(1,28,3,17:15)
Block(1,28,5,LEAVES:3)
Block(1,29,0,17:15)
Block(1,29,2,LEAVES:3)
Block(1,29,3,17:15)
Block(1,29,4,17:15)
Block(1,29,5,17:15)
Block(1,29,7,LEAVES:3)
Block(1,29,8,LEAVES:3)
Block(1,30,3,LEAVES:3)
Block(1,30,4,LEAVES:3)
Block(1,30,5,LEAVES:3)
Block(1,30,6,LEAVES:3)
Block(1,30,7,LEAVES:3)
Block(1,30,8,LEAVES:3)
Block(1,31,1,17:15)
Block(1,31,4,LEAVES:3)
Block(1,31,6,LEAVES:3)
Block(1,31,7,LEAVES:3)
Block(1,31,9,LEAVES:3)
Block(1,31,10,LEAVES:3)
Block(1,31,11,LEAVES:3)
Block(1,32,6,LEAVES:3)
Block(1,32,9,LEAVES:3)
Block(1,33,-12,LEAVES:3)
Block(1,33,-7,LEAVES:3)
Block(1,34,-11,LEAVES:3)
Block(1,34,-10,LEAVES:3)
Block(1,34,-9,LEAVES:3)
Block(1,34,-8,17:15)
Block(1,34,-7,LEAVES:3)
Block(1,34,-6,LEAVES:3)
Block(1,34,-5,LEAVES:3)
Block(1,34,-1,17:15)
Block(1,34,0,LEAVES:3)
Block(1,35,-8,LEAVES:3)
Block(1,35,-7,LEAVES:3)
Block(1,35,-6,LEAVES:3)
Block(1,35,-1,17:15)
Block(1,35,0,17:15)
Block(1,35,1,17:15)
Block(1,35,2,17:15)
Block(1,36,-8,LEAVES:3)
Block(1,36,-4,LEAVES:3)
Block(1,36,-3,LEAVES:3)
Block(1,36,-2,LEAVES:3)
Block(1,36,-1,17:15)
Block(1,36,0,17:15)
Block(1,36,1,LEAVES:3)
Block(1,36,2,LEAVES:3)
Block(1,37,-3,LEAVES:3)
Block(1,37,-2,LEAVES:3)
Block(1,37,-1,LEAVES:3)
Block(1,37,0,LEAVES:3)
Block(1,37,1,LEAVES:3)
Block(1,38,-2,LEAVES:3)
Block(1,38,0,LEAVES:3)
Block(2,-4,-2,17:15)
Block(2,-3,-2,17:15)
Block(2,-3,-1,17:15)
Block(2,-3,2,17:15)
Block(2,-2,-2,17:15)
Block(2,-2,-1,17:15)
Block(2,-2,2,17:15)
Block(2,-1,-1,17:15)
Block(2,-1,0,17:15)
Block(2,0,-1,17:15)
Block(2,0,0,17:15)
Block(2,0,1,17:15)
Block(2,1,-1,17:15)
Block(2,1,0,17:15)
Block(2,1,1,17:15)
Block(2,2,0,17:15)
Block(2,18,1,LEAVES:3)
Block(2,18,2,LEAVES:3)
Block(2,18,3,17:15)
Block(2,18,4,LEAVES:3)
Block(2,19,2,LEAVES:3)
Block(2,19,3,LEAVES:3)
Block(2,19,4,LEAVES:3)
Block(2,19,5,LEAVES:3)
Block(2,19,6,LEAVES:3)
Block(2,20,5,LEAVES:3)
Block(2,28,2,LEAVES:3)
Block(2,28,3,LEAVES:3)
Block(2,29,-1,LEAVES:3)
Block(2,29,1,17:15)
Block(2,29,3,LEAVES:3)
Block(2,29,4,17:15)
Block(2,29,5,17:15)
Block(2,29,6,LEAVES:3)
Block(2,30,0,LEAVES:3)
Block(2,30,3,LEAVES:3)
Block(2,30,4,LEAVES:3)
Block(2,30,5,17:15)
Block(2,30,6,LEAVES:3)
Block(2,30,7,LEAVES:3)
Block(2,30,10,LEAVES:3)
Block(2,31,4,LEAVES:3)
Block(2,31,5,LEAVES:3)
Block(2,31,6,LEAVES:3)
Block(2,31,9,LEAVES:3)
Block(2,31,10,LEAVES:3)
Block(2,32,2,17:15)
Block(2,32,3,17:15)
Block(2,32,5,LEAVES:3)
Block(2,33,-10,LEAVES:3)
Block(2,33,-8,LEAVES:3)
Block(2,33,3,17:15)
Block(2,34,-11,LEAVES:3)
Block(2,34,-10,LEAVES:3)
Block(2,34,-9,17:15)
Block(2,34,-8,LEAVES:3)
Block(2,34,-7,LEAVES:3)
Block(2,34,-6,LEAVES:3)
Block(2,34,4,LEAVES:3)
Block(2,35,-10,LEAVES:3)
Block(2,35,-9,LEAVES:3)
Block(2,35,-7,LEAVES:3)
Block(2,35,-2,LEAVES:3)
Block(2,35,1,17:15)
Block(2,36,-5,LEAVES:3)
Block(2,36,-3,LEAVES:3)
Block(2,36,-2,17:15)
Block(2,36,-1,LEAVES:3)
Block(2,36,0,LEAVES:3)
Block(2,36,1,LEAVES:3)
Block(2,37,-5,LEAVES:3)
Block(2,37,-4,LEAVES:3)
Block(2,37,-3,LEAVES:3)
Block(2,37,-2,LEAVES:3)
Block(2,37,0,LEAVES:3)
Block(3,-4,2,17:15)
Block(3,-3,2,17:15)
Block(3,-2,0,17:15)
Block(3,-2,1,17:15)
Block(3,-1,0,17:15)
Block(3,17,1,LEAVES:3)
Block(3,17,4,LEAVES:3)
Block(3,18,2,LEAVES:3)
Block(3,18,3,LEAVES:3)
Block(3,18,4,17:15)
Block(3,18,7,LEAVES:3)
Block(3,19,4,LEAVES:3)
Block(3,19,5,17:15)
Block(3,19,6,LEAVES:3)
Block(3,28,3,LEAVES:3)
Block(3,29,1,LEAVES:3)
Block(3,29,4,LEAVES:3)
Block(3,29,5,LEAVES:3)
Block(3,29,10,LEAVES:3)
Block(3,30,-1,LEAVES:3)
Block(3,30,0,LEAVES:3)
Block(3,30,1,LEAVES:3)
Block(3,30,5,17:15)
Block(3,30,6,LEAVES:3)
Block(3,30,7,LEAVES:3)
Block(3,30,8,LEAVES:3)
Block(3,30,9,LEAVES:3)
Block(3,31,0,LEAVES:3)
Block(3,31,5,LEAVES:3)
Block(3,31,6,LEAVES:3)
Block(3,33,-11,LEAVES:3)
Block(3,33,-8,LEAVES:3)
Block(3,33,1,LEAVES:3)
Block(3,33,3,17:15)
Block(3,33,6,LEAVES:3)
Block(3,34,-10,LEAVES:3)
Block(3,34,-9,LEAVES:3)
Block(3,34,-8,LEAVES:3)
Block(3,34,-7,LEAVES:3)
Block(3,34,3,LEAVES:3)
Block(3,34,4,LEAVES:3)
Block(3,34,5,LEAVES:3)
Block(3,35,-9,LEAVES:3)
Block(3,35,0,LEAVES:3)
Block(3,35,1,LEAVES:3)
Block(3,35,2,LEAVES:3)
Block(3,35,4,LEAVES:3)
Block(3,36,-2,LEAVES:3)
Block(3,36,-1,LEAVES:3)
Block(3,36,0,LEAVES:3)
Block(3,36,1,LEAVES:3)
Block(3,37,-6,LEAVES:3)
Block(3,37,-5,LEAVES:3)
Block(3,37,-4,LEAVES:3)
Block(3,37,-3,17:15)
Block(3,37,-2,LEAVES:3)
Block(3,38,-5,LEAVES:3)
Block(3,38,-4,LEAVES:3)
Block(3,38,-3,LEAVES:3)
Block(3,38,-2,LEAVES:3)
Block(3,39,-3,LEAVES:3)
Block(4,-4,0,17:15)
Block(4,-3,0,17:15)
Block(4,-2,0,17:15)
Block(4,18,3,LEAVES:3)
Block(4,18,4,LEAVES:3)
Block(4,18,5,LEAVES:3)
Block(4,19,4,LEAVES:3)
Block(4,19,5,LEAVES:3)
Block(4,19,6,17:15)
Block(4,19,7,LEAVES:3)
Block(4,20,5,LEAVES:3)
Block(4,20,6,LEAVES:3)
Block(4,21,6,LEAVES:3)
Block(4,29,0,17:15)
Block(4,29,7,LEAVES:3)
Block(4,29,9,LEAVES:3)
Block(4,30,-2,LEAVES:3)
Block(4,30,-1,LEAVES:3)
Block(4,30,0,17:15)
Block(4,30,1,17:15)
Block(4,30,5,LEAVES:3)
Block(4,30,6,17:15)
Block(4,30,7,17:15)
Block(4,30,8,LEAVES:3)
Block(4,30,9,LEAVES:3)
Block(4,30,10,LEAVES:3)
Block(4,31,0,LEAVES:3)
Block(4,31,6,LEAVES:3)
Block(4,31,7,LEAVES:3)
Block(4,31,8,LEAVES:3)
Block(4,31,9,LEAVES:3)
Block(4,33,-9,LEAVES:3)
Block(4,33,4,LEAVES:3)
Block(4,34,-9,LEAVES:3)
Block(4,34,0,LEAVES:3)
Block(4,34,1,LEAVES:3)
Block(4,34,2,LEAVES:3)
Block(4,34,3,17:15)
Block(4,34,4,17:15)
Block(4,34,5,LEAVES:3)
Block(4,34,6,LEAVES:3)
Block(4,35,-2,LEAVES:3)
Block(4,35,1,LEAVES:3)
Block(4,35,2,LEAVES:3)
Block(4,35,3,LEAVES:3)
Block(4,35,4,LEAVES:3)
Block(4,35,6,LEAVES:3)
Block(4,36,-6,LEAVES:3)
Block(4,36,-4,LEAVES:3)
Block(4,36,-2,LEAVES:3)
Block(4,37,-5,LEAVES:3)
Block(4,37,-4,LEAVES:3)
Block(4,37,-3,LEAVES:3)
Block(4,38,-4,LEAVES:3)
Block(5,17,4,LEAVES:3)
Block(5,18,4,LEAVES:3)
Block(5,18,8,LEAVES:3)
Block(5,19,5,LEAVES:3)
Block(5,19,6,LEAVES:3)
Block(5,19,7,LEAVES:3)
Block(5,19,8,LEAVES:3)
Block(5,20,6,LEAVES:3)
Block(5,20,7,LEAVES:3)
Block(5,29,-3,LEAVES:3)
Block(5,29,-1,LEAVES:3)
Block(5,29,0,17:15)
Block(5,29,6,LEAVES:3)
Block(5,29,8,LEAVES:3)
Block(5,30,-3,LEAVES:3)
Block(5,30,-2,LEAVES:3)
Block(5,30,-1,17:15)
Block(5,30,0,LEAVES:3)
Block(5,30,6,LEAVES:3)
Block(5,30,7,LEAVES:3)
Block(5,30,8,LEAVES:3)
Block(5,30,9,LEAVES:3)
Block(5,31,-2,LEAVES:3)
Block(5,31,-1,LEAVES:3)
Block(5,31,0,LEAVES:3)
Block(5,31,7,LEAVES:3)
Block(5,31,8,LEAVES:3)
Block(5,33,1,LEAVES:3)
Block(5,33,6,LEAVES:3)
Block(5,34,0,LEAVES:3)
Block(5,34,1,LEAVES:3)
Block(5,34,2,17:15)
Block(5,34,4,LEAVES:3)
Block(5,34,5,17:15)
Block(5,34,6,LEAVES:3)
Block(5,35,1,LEAVES:3)
Block(5,35,2,LEAVES:3)
Block(5,35,3,LEAVES:3)
Block(5,35,5,LEAVES:3)
Block(5,35,6,LEAVES:3)
Block(5,36,2,LEAVES:3)
Block(5,37,-4,LEAVES:3)
Block(6,18,6,LEAVES:3)
Block(6,19,5,LEAVES:3)
Block(6,19,6,LEAVES:3)
Block(6,19,7,LEAVES:3)
Block(6,20,6,LEAVES:3)
Block(6,30,-2,LEAVES:3)
Block(6,30,1,LEAVES:3)
Block(6,30,8,LEAVES:3)
Block(6,31,-4,LEAVES:3)
Block(6,31,-3,LEAVES:3)
Block(6,31,-2,LEAVES:3)
Block(6,31,-1,17:15)
Block(6,31,0,LEAVES:3)
Block(6,31,1,LEAVES:3)
Block(6,32,-2,LEAVES:3)
Block(6,32,0,LEAVES:3)
Block(6,33,0,LEAVES:3)
Block(6,34,1,LEAVES:3)
Block(6,34,4,LEAVES:3)
Block(6,34,5,LEAVES:3)
Block(6,34,6,LEAVES:3)
Block(6,35,1,LEAVES:3)
Block(6,35,2,17:15)
Block(6,35,3,LEAVES:3)
Block(6,35,5,LEAVES:3)
Block(6,36,2,LEAVES:3)
Block(6,36,3,LEAVES:3)
Block(6,37,2,LEAVES:3)
Block(7,18,7,LEAVES:3)
Block(7,19,6,LEAVES:3)
Block(7,30,-4,LEAVES:3)
Block(7,31,-5,LEAVES:3)
Block(7,31,-4,LEAVES:3)
Block(7,31,-3,LEAVES:3)
Block(7,31,-2,17:15)
Block(7,31,-1,LEAVES:3)
Block(7,31,0,LEAVES:3)
Block(7,32,-4,LEAVES:3)
Block(7,32,-3,LEAVES:3)
Block(7,32,-2,LEAVES:3)
Block(7,33,-2,LEAVES:3)
Block(7,33,5,LEAVES:3)
Block(7,34,2,LEAVES:3)
Block(7,34,4,LEAVES:3)
Block(7,34,5,LEAVES:3)
Block(7,35,0,LEAVES:3)
Block(7,35,1,LEAVES:3)
Block(7,35,2,LEAVES:3)
Block(7,35,3,LEAVES:3)
Block(7,36,1,LEAVES:3)
Block(7,36,2,LEAVES:3)
Block(8,30,-5,LEAVES:3)
Block(8,30,-1,LEAVES:3)
Block(8,31,-4,LEAVES:3)
Block(8,31,-3,LEAVES:3)
Block(8,31,-2,LEAVES:3)
Block(8,32,-3,LEAVES:3)
Block(8,34,0,LEAVES:3)
Block(8,35,1,LEAVES:3)
Block(8,35,2,LEAVES:3)
Block(8,35,3,LEAVES:3)
Block(8,36,2,LEAVES:3)
Block(9,30,-3,LEAVES:3)
Block(9,31,-3,LEAVES:3)
Block(9,34,2,LEAVES:3)
Block(9,35,2,LEAVES:3)


#######################################################################
# +-----------------------------------------------------------------+ #
# |                             Entities                            | #
# +-----------------------------------------------------------------+ #
#######################################################################

# Entity() spawns an entity instead of a block. The entity is spawned only once when the BO3 is spawned.
# Entities are persistent by default so they don't de-spawn when no player is near, they are only unloaded.
# Usage: Entity(x,y,z,mobName,groupSize,NameTagOrNBTFileName) or Entity(x,y,z,mobName,groupSize)
# Use /tc entities or /otg entities to get a list of entities that can be used as mobName, this includes entities added by other mods.
# NameTagOrNBTFileName can be either a nametag for the mob or an nbt file (such as mymobinfo.nbt or mymobinfo.txt).
# When using a text file you can use the same mob spawning parameters used with the /summon command to equip the
# entity and give it custom attributes etc. You can copy the DATA part of a summon command including surrounding
# curly braces to a .txt file, for instance for: "/summon Skeleton x y z {DATA}"

#######################################################################
# +-----------------------------------------------------------------+ #
# |                            BO3 checks                           | #
# +-----------------------------------------------------------------+ #
#######################################################################

# Require a condition at a certain location in order for the BO3 to be spawned.
# BlockCheck(x,y,z,BlockName[,BlockName[,...]]) - one of the blocks must be at the location
# BlockCheckNot(x,y,z,BlockName[,BlockName[,...]]) - all the blocks must not be at the location
# LightCheck(x,y,z,minLightLevel,maxLightLevel) - light must be between min and max (inclusive)

# You can use "Solid" as a BlockName for matching all solid blocks or "All" to match all blocks that aren't air.

# Examples:
#   BlockCheck(0,-1,0,GRASS,DIRT)  Require grass or dirt just below the object
#   BlockCheck(0,-1,0,Solid)       Require any solid block just below the object
#   BlockCheck(0,-1,0,WOOL)        Require any type of wool just below the object
#   BlockCheck(0,-1,0,WOOL:0)      Require white wool just below the object
#   BlockCheckNot(0,-1,0,WOOL:0)   Require that there is no white wool below the object
#   LightCheck(0,0,0,0,LEAVES:3)          Require almost complete darkness just below the object

