#######################################################################
# +-----------------------------------------------------------------+ #
# |                            BO3 object                           | #
# +-----------------------------------------------------------------+ #
#######################################################################

# The descriptions in this file are accurate only for TerrainControl and OTG.
# For MCW and OTG+ these descriptions are only accurate if the BO3 is used as a CustomObject.
# MCW and OTG+ completely reimplemented CustomStructure, check the MCW/OTG+ documentation for more information.

# This is the config file of a custom object.
# If you add this object correctly to your BiomeConfigs, it will spawn in the world.

# This is the creator of this BO3 object
Author: Unknown

# A short description of this BO3 object
Description: This BO3 was converted from a schematic using OTGEdit. The author and description information of the schematic could not be found. If you know who the author of the schematic is then please add this information.

# The BO3 version, don't change this! It can be used by external applications to do a version check.
Version: 3

# The settings mode, WriteAll, WriteWithoutComments or WriteDisable. See WorldConfig.
SettingsMode: WriteDisable

#######################################################################
# +-----------------------------------------------------------------+ #
# |                          Main settings                          | #
# +-----------------------------------------------------------------+ #
#######################################################################

# This needs to be set to true to spawn the object in the Tree and Sapling resources.
Tree: true

# The frequency of the BO3 from 1 to 200. Tries this many times to spawn this BO3 when using the CustomObject(...) resource.
# Ignored by Tree(..), Sapling(..) and CustomStructure(..)
Frequency: 1

# The rarity of the BO3 from 0 to 100. Each spawn attempt has rarity% chance to succeed when using the CustomObject(...) resource.
# Ignored by Tree(..), Sapling(..) and CustomStructure(..)
Rarity: 100.0

# If you set this to true, the BO3 will be placed with a random rotation.
RotateRandomly: false

# The spawn height of the BO3 - randomY, highestBlock or highestSolidBlock.
SpawnHeight: highestBlock

# The height limits for the BO3.
MinHeight: 64

MaxHeight: 80

# Objects can have other objects attached to it: branches. Branches can also
# have branches attached to it, which can also have branches, etc. This is the
# maximum branch depth for this objects.
MaxBranchDepth: 10

# When spawned with the UseWorld keyword, this BO3 should NOT spawn in the following biomes.
# If you writer.write the BO3 name directly in the BiomeConfigs, this will be ignored.
ExcludedBiomes: All

# To optimise this BO3 for faster loading times you can use Notepad++ to find/replace comments and abbreviate things.
# Notepad++ find/replace with regex:
# Find: ^[#;].* replace to nothing removes all lines starting with # 
# Find: ^\s*$ replace to nothing removes most empty lines 
# Notepad++ find/replace without regex:
# *Warning: This will only work for OTG 1.10.2 v21 / OTG 1.11.2 v6 or higher. B( is not recognised by lower versions.
# Find: Block( replace to B(

#######################################################################
# +-----------------------------------------------------------------+ #
# |                      Source block settings                      | #
# +-----------------------------------------------------------------+ #
#######################################################################

# The block(s) the BO3 should spawn in.
SourceBlocks: STONE:1,STONE:3,STONE:5,DIRT:1,DIRT,SAND,GRASS,DIRT:2,STATIONARY_WATER,HARD_CLAY,STAINED_CLAY,CLAY,SANDSTONE,SAND:1,AIR,STONE,GRAVEL,LONG_GRASS,LONG_GRASS:1,LONG_GRASS:2,DEAD_BUSH,YELLOW_FLOWER,RED_ROSE,BROWN_MUSHROOM,RED_MUSHROOM

# The maximum percentage of the BO3 that can be outside the SourceBlock.
# The BO3 won't be placed on a location with more blocks outside the SourceBlock than this percentage.
MaxPercentageOutsideSourceBlock: 0

# What to do when a block is about to be placed outside the SourceBlock? (dontPlace, placeAnyway)
OutsideSourceBlock: placeAnyway

#######################################################################
# +-----------------------------------------------------------------+ #
# |                              Blocks                             | #
# +-----------------------------------------------------------------+ #
#######################################################################

# All the blocks used in the BO3 are listed here. Possible blocks:
# Block(x,y,z,id[.data][,nbtfile.nbt) or B(x,y,z,id[.data][,nbtfile.nbt)
# RandomBlock(x,y,z,id[:data][,nbtfile.nbt],chance[,id[:data][,nbtfile.nbt],chance[,...]])
# So RandomBlock(0,0,0,CHEST,chest.nbt,50,CHEST,anotherchest.nbt,100) will spawn a chest at
# the BO3 origin, and give it a 50% chance to have the contents of chest.nbt, or, if that
# fails, a 100% percent chance to have the contents of anotherchest.nbt.

Block(-12,32,-1,LEAVES:3)
Block(-12,33,0,LEAVES:3)
Block(-12,39,6,LEAVES:3)
Block(-12,40,6,LEAVES:3)
Block(-12,41,-3,LEAVES:3)
Block(-11,32,1,LEAVES:3)
Block(-11,33,-1,LEAVES:3)
Block(-11,33,0,LEAVES:3)
Block(-11,33,1,LEAVES:3)
Block(-11,34,0,LEAVES:3)
Block(-11,38,6,LEAVES:3)
Block(-11,39,4,LEAVES:3)
Block(-11,40,-3,LEAVES:3)
Block(-11,40,-1,LEAVES:3)
Block(-11,40,5,LEAVES:3)
Block(-11,40,6,LEAVES:3)
Block(-11,40,7,LEAVES:3)
Block(-11,41,-4,LEAVES:3)
Block(-11,41,-3,LEAVES:3)
Block(-11,41,-2,LEAVES:3)
Block(-11,41,6,LEAVES:3)
Block(-11,42,-3,LEAVES:3)
Block(-10,31,3,LEAVES:3)
Block(-10,32,-1,LEAVES:3)
Block(-10,32,2,LEAVES:3)
Block(-10,33,-2,LEAVES:3)
Block(-10,33,-1,LEAVES:3)
Block(-10,33,0,LEAVES:3)
Block(-10,33,1,LEAVES:3)
Block(-10,34,-1,LEAVES:3)
Block(-10,34,0,LEAVES:3)
Block(-10,39,-6,LEAVES:3)
Block(-10,39,6,LEAVES:3)
Block(-10,39,8,LEAVES:3)
Block(-10,40,-7,LEAVES:3)
Block(-10,40,-5,LEAVES:3)
Block(-10,40,1,LEAVES:3)
Block(-10,40,5,LEAVES:3)
Block(-10,40,6,LEAVES:3)
Block(-10,40,7,LEAVES:3)
Block(-10,41,-5,LEAVES:3)
Block(-10,41,-4,LEAVES:3)
Block(-10,41,-3,LEAVES:3)
Block(-10,41,-2,LEAVES:3)
Block(-10,41,-1,LEAVES:3)
Block(-10,41,0,LEAVES:3)
Block(-10,41,6,LEAVES:3)
Block(-10,42,-3,LEAVES:3)
Block(-9,31,5,LEAVES:3)
Block(-9,32,1,LEAVES:3)
Block(-9,32,2,LEAVES:3)
Block(-9,32,3,LEAVES:3)
Block(-9,32,5,LEAVES:3)
Block(-9,33,-1,LEAVES:3)
Block(-9,33,0,17:15)
Block(-9,33,1,LEAVES:3)
Block(-9,33,2,LEAVES:3)
Block(-9,34,0,LEAVES:3)
Block(-9,35,0,LEAVES:3)
Block(-9,39,-7,LEAVES:3)
Block(-9,39,5,LEAVES:3)
Block(-9,40,-8,LEAVES:3)
Block(-9,40,-7,LEAVES:3)
Block(-9,40,-6,LEAVES:3)
Block(-9,40,-3,LEAVES:3)
Block(-9,40,0,LEAVES:3)
Block(-9,40,4,LEAVES:3)
Block(-9,40,5,LEAVES:3)
Block(-9,40,6,17:15)
Block(-9,40,7,LEAVES:3)
Block(-9,40,8,LEAVES:3)
Block(-9,41,-7,LEAVES:3)
Block(-9,41,-5,LEAVES:3)
Block(-9,41,-4,LEAVES:3)
Block(-9,41,-3,17:15)
Block(-9,41,-2,LEAVES:3)
Block(-9,41,-1,LEAVES:3)
Block(-9,41,0,LEAVES:3)
Block(-9,41,1,LEAVES:3)
Block(-9,41,5,LEAVES:3)
Block(-9,41,6,LEAVES:3)
Block(-9,41,7,LEAVES:3)
Block(-9,42,-4,LEAVES:3)
Block(-9,42,-3,LEAVES:3)
Block(-9,42,0,LEAVES:3)
Block(-9,42,6,LEAVES:3)
Block(-9,43,-3,LEAVES:3)
Block(-8,31,-1,LEAVES:3)
Block(-8,31,1,LEAVES:3)
Block(-8,31,3,LEAVES:3)
Block(-8,32,-1,LEAVES:3)
Block(-8,32,0,LEAVES:3)
Block(-8,32,1,17:15)
Block(-8,32,2,LEAVES:3)
Block(-8,32,3,LEAVES:3)
Block(-8,32,4,LEAVES:3)
Block(-8,32,5,LEAVES:3)
Block(-8,32,6,LEAVES:3)
Block(-8,33,0,LEAVES:3)
Block(-8,33,1,LEAVES:3)
Block(-8,33,2,LEAVES:3)
Block(-8,33,3,LEAVES:3)
Block(-8,33,5,LEAVES:3)
Block(-8,34,0,LEAVES:3)
Block(-8,34,2,LEAVES:3)
Block(-8,39,-8,LEAVES:3)
Block(-8,39,-4,LEAVES:3)
Block(-8,39,4,LEAVES:3)
Block(-8,39,6,17:15)
Block(-8,39,9,LEAVES:3)
Block(-8,40,-9,LEAVES:3)
Block(-8,40,-8,LEAVES:3)
Block(-8,40,-7,LEAVES:3)
Block(-8,40,-6,LEAVES:3)
Block(-8,40,-4,LEAVES:3)
Block(-8,40,-3,17:15)
Block(-8,40,-2,LEAVES:3)
Block(-8,40,2,LEAVES:3)
Block(-8,40,5,LEAVES:3)
Block(-8,40,6,LEAVES:3)
Block(-8,40,7,LEAVES:3)
Block(-8,40,8,LEAVES:3)
Block(-8,40,9,LEAVES:3)
Block(-8,41,-8,LEAVES:3)
Block(-8,41,-7,LEAVES:3)
Block(-8,41,-3,LEAVES:3)
Block(-8,41,-1,LEAVES:3)
Block(-8,41,0,17:15)
Block(-8,41,1,LEAVES:3)
Block(-8,41,2,LEAVES:3)
Block(-8,41,6,LEAVES:3)
Block(-8,41,8,LEAVES:3)
Block(-8,41,10,LEAVES:3)
Block(-8,41,13,LEAVES:3)
Block(-8,42,-3,LEAVES:3)
Block(-8,42,0,LEAVES:3)
Block(-8,42,1,LEAVES:3)
Block(-8,42,14,LEAVES:3)
Block(-7,31,3,LEAVES:3)
Block(-7,31,4,LEAVES:3)
Block(-7,31,6,LEAVES:3)
Block(-7,32,0,LEAVES:3)
Block(-7,32,1,LEAVES:3)
Block(-7,32,2,17:15)
Block(-7,32,3,LEAVES:3)
Block(-7,32,5,17:15)
Block(-7,32,6,LEAVES:3)
Block(-7,32,7,LEAVES:3)
Block(-7,33,2,LEAVES:3)
Block(-7,33,4,LEAVES:3)
Block(-7,33,5,LEAVES:3)
Block(-7,33,6,LEAVES:3)
Block(-7,34,5,LEAVES:3)
Block(-7,36,-11,LEAVES:3)
Block(-7,38,6,LEAVES:3)
Block(-7,39,-7,LEAVES:3)
Block(-7,39,-4,LEAVES:3)
Block(-7,39,-2,LEAVES:3)
Block(-7,39,6,LEAVES:3)
Block(-7,39,7,17:15)
Block(-7,39,8,LEAVES:3)
Block(-7,40,-8,LEAVES:3)
Block(-7,40,-7,17:15)
Block(-7,40,-6,LEAVES:3)
Block(-7,40,-5,LEAVES:3)
Block(-7,40,-4,LEAVES:3)
Block(-7,40,-2,17:15)
Block(-7,40,0,LEAVES:3)
Block(-7,40,1,LEAVES:3)
Block(-7,40,6,LEAVES:3)
Block(-7,40,7,LEAVES:3)
Block(-7,40,8,LEAVES:3)
Block(-7,40,10,LEAVES:3)
Block(-7,40,12,LEAVES:3)
Block(-7,41,-8,LEAVES:3)
Block(-7,41,-7,LEAVES:3)
Block(-7,41,-4,LEAVES:3)
Block(-7,41,-2,LEAVES:3)
Block(-7,41,-1,17:15)
Block(-7,41,0,LEAVES:3)
Block(-7,41,1,LEAVES:3)
Block(-7,41,7,LEAVES:3)
Block(-7,41,8,LEAVES:3)
Block(-7,41,9,LEAVES:3)
Block(-7,41,10,LEAVES:3)
Block(-7,41,11,LEAVES:3)
Block(-7,41,12,LEAVES:3)
Block(-7,41,14,LEAVES:3)
Block(-7,42,-2,LEAVES:3)
Block(-7,42,-1,LEAVES:3)
Block(-7,42,10,LEAVES:3)
Block(-7,42,13,LEAVES:3)
Block(-7,42,14,LEAVES:3)
Block(-7,42,15,LEAVES:3)
Block(-7,43,-1,LEAVES:3)
Block(-7,43,14,LEAVES:3)
Block(-7,43,15,LEAVES:3)
Block(-6,30,-1,LEAVES:3)
Block(-6,30,2,LEAVES:3)
Block(-6,31,0,LEAVES:3)
Block(-6,31,2,17:15)
Block(-6,31,3,17:15)
Block(-6,31,4,17:15)
Block(-6,31,5,LEAVES:3)
Block(-6,32,0,LEAVES:3)
Block(-6,32,1,LEAVES:3)
Block(-6,32,2,17:15)
Block(-6,32,3,LEAVES:3)
Block(-6,32,4,LEAVES:3)
Block(-6,32,5,LEAVES:3)
Block(-6,32,6,LEAVES:3)
Block(-6,33,-7,LEAVES:3)
Block(-6,33,1,LEAVES:3)
Block(-6,33,2,LEAVES:3)
Block(-6,33,3,LEAVES:3)
Block(-6,34,-9,LEAVES:3)
Block(-6,34,-6,LEAVES:3)
Block(-6,34,2,LEAVES:3)
Block(-6,35,-13,LEAVES:3)
Block(-6,35,-11,LEAVES:3)
Block(-6,35,-9,LEAVES:3)
Block(-6,36,-12,LEAVES:3)
Block(-6,36,-11,LEAVES:3)
Block(-6,36,-10,LEAVES:3)
Block(-6,37,-11,LEAVES:3)
Block(-6,38,1,17:15)
Block(-6,39,-8,LEAVES:3)
Block(-6,39,-5,LEAVES:3)
Block(-6,39,-3,17:15)
Block(-6,39,5,LEAVES:3)
Block(-6,39,7,17:15)
Block(-6,40,-8,LEAVES:3)
Block(-6,40,-7,17:15)
Block(-6,40,-6,LEAVES:3)
Block(-6,40,-5,LEAVES:3)
Block(-6,40,-4,LEAVES:3)
Block(-6,40,-3,17:15)
Block(-6,40,-2,LEAVES:3)
Block(-6,40,-1,LEAVES:3)
Block(-6,40,6,LEAVES:3)
Block(-6,40,7,LEAVES:3)
Block(-6,40,9,LEAVES:3)
Block(-6,40,10,LEAVES:3)
Block(-6,41,-7,LEAVES:3)
Block(-6,41,-6,LEAVES:3)
Block(-6,41,-5,LEAVES:3)
Block(-6,41,-4,LEAVES:3)
Block(-6,41,-3,LEAVES:3)
Block(-6,41,-1,LEAVES:3)
Block(-6,41,0,LEAVES:3)
Block(-6,41,1,LEAVES:3)
Block(-6,41,8,LEAVES:3)
Block(-6,41,9,LEAVES:3)
Block(-6,41,10,LEAVES:3)
Block(-6,41,11,LEAVES:3)
Block(-6,41,12,17:15)
Block(-6,41,13,LEAVES:3)
Block(-6,41,16,LEAVES:3)
Block(-6,42,-4,LEAVES:3)
Block(-6,42,-1,LEAVES:3)
Block(-6,42,0,LEAVES:3)
Block(-6,42,10,LEAVES:3)
Block(-6,42,12,LEAVES:3)
Block(-6,42,13,17:15)
Block(-6,42,14,LEAVES:3)
Block(-6,42,15,LEAVES:3)
Block(-6,42,16,LEAVES:3)
Block(-6,43,9,LEAVES:3)
Block(-6,43,10,LEAVES:3)
Block(-6,43,13,LEAVES:3)
Block(-6,43,14,LEAVES:3)
Block(-6,43,15,LEAVES:3)
Block(-5,23,-11,LEAVES:3)
Block(-5,31,-1,LEAVES:3)
Block(-5,31,0,LEAVES:3)
Block(-5,31,1,17:15)
Block(-5,31,2,17:15)
Block(-5,31,3,LEAVES:3)
Block(-5,31,4,17:15)
Block(-5,32,0,LEAVES:3)
Block(-5,32,1,LEAVES:3)
Block(-5,32,2,LEAVES:3)
Block(-5,32,3,LEAVES:3)
Block(-5,33,2,LEAVES:3)
Block(-5,34,-7,LEAVES:3)
Block(-5,34,-6,LEAVES:3)
Block(-5,34,-5,LEAVES:3)
Block(-5,35,-9,LEAVES:3)
Block(-5,35,-8,LEAVES:3)
Block(-5,35,-7,LEAVES:3)
Block(-5,35,-6,LEAVES:3)
Block(-5,36,-13,LEAVES:3)
Block(-5,36,-12,LEAVES:3)
Block(-5,36,-11,LEAVES:3)
Block(-5,36,-10,17:15)
Block(-5,36,-9,LEAVES:3)
Block(-5,37,-12,LEAVES:3)
Block(-5,37,-11,LEAVES:3)
Block(-5,37,-10,LEAVES:3)
Block(-5,37,-9,LEAVES:3)
Block(-5,37,1,17:15)
Block(-5,38,-10,LEAVES:3)
Block(-5,38,-4,LEAVES:3)
Block(-5,39,-6,LEAVES:3)
Block(-5,39,-4,17:15)
Block(-5,39,-3,LEAVES:3)
Block(-5,39,6,LEAVES:3)
Block(-5,39,7,17:15)
Block(-5,40,-7,LEAVES:3)
Block(-5,40,-6,17:15)
Block(-5,40,-5,17:15)
Block(-5,40,-4,LEAVES:3)
Block(-5,40,-3,LEAVES:3)
Block(-5,40,-2,LEAVES:3)
Block(-5,40,5,LEAVES:3)
Block(-5,40,6,LEAVES:3)
Block(-5,40,7,17:15)
Block(-5,40,8,LEAVES:3)
Block(-5,40,11,LEAVES:3)
Block(-5,41,-6,LEAVES:3)
Block(-5,41,-5,LEAVES:3)
Block(-5,41,-3,LEAVES:3)
Block(-5,41,-2,LEAVES:3)
Block(-5,41,-1,LEAVES:3)
Block(-5,41,0,LEAVES:3)
Block(-5,41,6,LEAVES:3)
Block(-5,41,7,LEAVES:3)
Block(-5,41,8,LEAVES:3)
Block(-5,41,9,LEAVES:3)
Block(-5,41,10,17:15)
Block(-5,41,11,17:15)
Block(-5,41,14,LEAVES:3)
Block(-5,42,-5,LEAVES:3)
Block(-5,42,-1,LEAVES:3)
Block(-5,42,8,LEAVES:3)
Block(-5,42,10,LEAVES:3)
Block(-5,42,11,LEAVES:3)
Block(-5,42,13,LEAVES:3)
Block(-5,42,14,LEAVES:3)
Block(-5,42,15,LEAVES:3)
Block(-5,43,13,LEAVES:3)
Block(-4,-5,-2,17:15)
Block(-4,-4,-2,17:15)
Block(-4,-3,-2,17:15)
Block(-4,-2,-2,17:15)
Block(-4,22,-12,LEAVES:3)
Block(-4,22,-9,LEAVES:3)
Block(-4,23,-12,LEAVES:3)
Block(-4,23,-11,LEAVES:3)
Block(-4,23,-10,LEAVES:3)
Block(-4,24,-11,LEAVES:3)
Block(-4,31,0,LEAVES:3)
Block(-4,31,2,17:15)
Block(-4,31,3,17:15)
Block(-4,32,2,LEAVES:3)
Block(-4,34,-9,LEAVES:3)
Block(-4,34,-6,17:15)
Block(-4,35,-12,LEAVES:3)
Block(-4,35,-10,LEAVES:3)
Block(-4,35,-9,17:15)
Block(-4,35,-8,LEAVES:3)
Block(-4,35,-7,LEAVES:3)
Block(-4,35,-6,LEAVES:3)
Block(-4,36,-12,LEAVES:3)
Block(-4,36,-11,LEAVES:3)
Block(-4,36,-10,LEAVES:3)
Block(-4,36,-9,LEAVES:3)
Block(-4,36,-7,LEAVES:3)
Block(-4,37,1,17:15)
Block(-4,38,-4,17:15)
Block(-4,39,-6,LEAVES:3)
Block(-4,39,-5,17:15)
Block(-4,39,-4,17:15)
Block(-4,39,5,LEAVES:3)
Block(-4,40,-5,LEAVES:3)
Block(-4,40,-4,LEAVES:3)
Block(-4,40,-3,LEAVES:3)
Block(-4,40,5,LEAVES:3)
Block(-4,40,6,LEAVES:3)
Block(-4,40,7,17:15)
Block(-4,40,8,17:15)
Block(-4,40,9,LEAVES:3)
Block(-4,41,-5,LEAVES:3)
Block(-4,41,-4,LEAVES:3)
Block(-4,41,-2,17:15)
Block(-4,41,-1,LEAVES:3)
Block(-4,41,6,LEAVES:3)
Block(-4,41,7,LEAVES:3)
Block(-4,41,8,17:15)
Block(-4,41,9,17:15)
Block(-4,41,10,17:15)
Block(-4,41,11,LEAVES:3)
Block(-4,41,12,LEAVES:3)
Block(-4,41,14,LEAVES:3)
Block(-4,42,6,LEAVES:3)
Block(-4,42,7,LEAVES:3)
Block(-4,42,8,LEAVES:3)
Block(-4,42,9,LEAVES:3)
Block(-4,42,10,LEAVES:3)
Block(-4,42,11,LEAVES:3)
Block(-4,42,12,LEAVES:3)
Block(-4,42,13,LEAVES:3)
Block(-4,43,-3,LEAVES:3)
Block(-4,43,7,LEAVES:3)
Block(-4,43,11,LEAVES:3)
Block(-3,-5,-5,17:15)
Block(-3,-5,-1,17:15)
Block(-3,-4,-5,17:15)
Block(-3,-4,-4,17:15)
Block(-3,-4,-1,17:15)
Block(-3,-3,-4,17:15)
Block(-3,-3,-2,17:15)
Block(-3,-3,-1,17:15)
Block(-3,-2,-4,17:15)
Block(-3,-2,-3,17:15)
Block(-3,-2,-1,17:15)
Block(-3,-1,-3,17:15)
Block(-3,-1,-2,17:15)
Block(-3,-1,-1,17:15)
Block(-3,0,-2,17:15)
Block(-3,21,-10,LEAVES:3)
Block(-3,22,-14,LEAVES:3)
Block(-3,22,-11,LEAVES:3)
Block(-3,22,-9,LEAVES:3)
Block(-3,22,-8,LEAVES:3)
Block(-3,23,-13,LEAVES:3)
Block(-3,23,-12,LEAVES:3)
Block(-3,23,-11,LEAVES:3)
Block(-3,23,-10,17:15)
Block(-3,23,-9,LEAVES:3)
Block(-3,24,-12,LEAVES:3)
Block(-3,24,-11,LEAVES:3)
Block(-3,24,-10,LEAVES:3)
Block(-3,25,-11,LEAVES:3)
Block(-3,29,3,LEAVES:3)
Block(-3,29,5,LEAVES:3)
Block(-3,30,2,17:15)
Block(-3,30,4,LEAVES:3)
Block(-3,30,5,LEAVES:3)
Block(-3,30,6,LEAVES:3)
Block(-3,31,4,LEAVES:3)
Block(-3,31,5,LEAVES:3)
Block(-3,33,-7,LEAVES:3)
Block(-3,34,-7,17:15)
Block(-3,34,-6,17:15)
Block(-3,34,-5,17:15)
Block(-3,35,-11,LEAVES:3)
Block(-3,35,-10,LEAVES:3)
Block(-3,35,-9,LEAVES:3)
Block(-3,35,-8,17:15)
Block(-3,35,-7,17:15)
Block(-3,35,-6,LEAVES:3)
Block(-3,35,-5,LEAVES:3)
Block(-3,36,-10,LEAVES:3)
Block(-3,36,-9,LEAVES:3)
Block(-3,36,-8,LEAVES:3)
Block(-3,36,-7,LEAVES:3)
Block(-3,36,-6,LEAVES:3)
Block(-3,37,-9,LEAVES:3)
Block(-3,37,-7,LEAVES:3)
Block(-3,37,0,17:15)
Block(-3,38,-6,LEAVES:3)
Block(-3,38,-5,LEAVES:3)
Block(-3,38,-4,17:15)
Block(-3,38,-3,17:15)
Block(-3,39,-5,LEAVES:3)
Block(-3,39,-4,17:15)
Block(-3,39,-3,LEAVES:3)
Block(-3,39,5,LEAVES:3)
Block(-3,39,8,LEAVES:3)
Block(-3,40,-8,LEAVES:3)
Block(-3,40,-5,LEAVES:3)
Block(-3,40,-4,LEAVES:3)
Block(-3,40,-2,17:15)
Block(-3,40,1,LEAVES:3)
Block(-3,40,4,LEAVES:3)
Block(-3,40,5,17:15)
Block(-3,40,6,17:15)
Block(-3,40,7,17:15)
Block(-3,40,8,LEAVES:3)
Block(-3,40,10,LEAVES:3)
Block(-3,40,11,LEAVES:3)
Block(-3,41,-8,LEAVES:3)
Block(-3,41,-1,LEAVES:3)
Block(-3,41,2,LEAVES:3)
Block(-3,41,5,LEAVES:3)
Block(-3,41,6,LEAVES:3)
Block(-3,41,7,LEAVES:3)
Block(-3,41,8,LEAVES:3)
Block(-3,41,10,17:15)
Block(-3,41,13,LEAVES:3)
Block(-3,42,-5,LEAVES:3)
Block(-3,42,-3,LEAVES:3)
Block(-3,42,-1,LEAVES:3)
Block(-3,42,7,LEAVES:3)
Block(-3,42,10,LEAVES:3)
Block(-3,42,11,LEAVES:3)
Block(-3,42,12,LEAVES:3)
Block(-3,42,13,LEAVES:3)
Block(-3,42,14,LEAVES:3)
Block(-3,43,-4,LEAVES:3)
Block(-3,43,-3,LEAVES:3)
Block(-3,43,-2,LEAVES:3)
Block(-3,44,-3,LEAVES:3)
Block(-2,-5,1,17:15)
Block(-2,-4,-5,17:15)
Block(-2,-4,1,17:15)
Block(-2,-3,-5,17:15)
Block(-2,-3,-4,17:15)
Block(-2,-3,1,17:15)
Block(-2,-3,2,17:15)
Block(-2,-2,-5,17:15)
Block(-2,-2,1,17:15)
Block(-2,-2,2,17:15)
Block(-2,-1,-5,17:15)
Block(-2,-1,-2,17:15)
Block(-2,-1,0,17:15)
Block(-2,-1,1,17:15)
Block(-2,0,-2,17:15)
Block(-2,0,0,17:15)
Block(-2,1,-2,17:15)
Block(-2,1,0,17:15)
Block(-2,20,-10,LEAVES:3)
Block(-2,21,-9,LEAVES:3)
Block(-2,21,-5,LEAVES:3)
Block(-2,22,-12,LEAVES:3)
Block(-2,22,-9,17:15)
Block(-2,22,-8,LEAVES:3)
Block(-2,22,-7,LEAVES:3)
Block(-2,23,-13,LEAVES:3)
Block(-2,23,-12,LEAVES:3)
Block(-2,23,-11,LEAVES:3)
Block(-2,23,-10,LEAVES:3)
Block(-2,23,-9,LEAVES:3)
Block(-2,24,-11,LEAVES:3)
Block(-2,24,-10,LEAVES:3)
Block(-2,29,7,LEAVES:3)
Block(-2,30,1,17:15)
Block(-2,30,3,LEAVES:3)
Block(-2,30,4,LEAVES:3)
Block(-2,30,5,17:15)
Block(-2,30,6,LEAVES:3)
Block(-2,30,7,LEAVES:3)
Block(-2,31,5,LEAVES:3)
Block(-2,31,6,LEAVES:3)
Block(-2,33,-3,17:15)
Block(-2,34,-11,LEAVES:3)
Block(-2,34,-9,LEAVES:3)
Block(-2,34,-8,LEAVES:3)
Block(-2,34,-7,17:15)
Block(-2,34,-6,LEAVES:3)
Block(-2,34,-4,17:15)
Block(-2,34,-3,17:15)
Block(-2,35,-10,LEAVES:3)
Block(-2,35,-9,LEAVES:3)
Block(-2,35,-8,LEAVES:3)
Block(-2,35,-7,LEAVES:3)
Block(-2,35,-6,LEAVES:3)
Block(-2,35,0,17:15)
Block(-2,36,-9,LEAVES:3)
Block(-2,36,-7,LEAVES:3)
Block(-2,36,0,17:15)
Block(-2,37,-3,17:15)
Block(-2,38,-5,LEAVES:3)
Block(-2,38,-3,17:15)
Block(-2,39,-4,LEAVES:3)
Block(-2,39,3,17:15)
Block(-2,39,4,17:15)
Block(-2,39,5,17:15)
Block(-2,40,-10,LEAVES:3)
Block(-2,40,-6,LEAVES:3)
Block(-2,40,-1,17:15)
Block(-2,40,3,LEAVES:3)
Block(-2,40,4,LEAVES:3)
Block(-2,40,5,17:15)
Block(-2,40,6,LEAVES:3)
Block(-2,40,11,LEAVES:3)
Block(-2,41,-9,LEAVES:3)
Block(-2,41,-8,LEAVES:3)
Block(-2,41,-7,LEAVES:3)
Block(-2,41,-1,17:15)
Block(-2,41,1,LEAVES:3)
Block(-2,41,2,LEAVES:3)
Block(-2,41,3,LEAVES:3)
Block(-2,41,4,LEAVES:3)
Block(-2,41,5,LEAVES:3)
Block(-2,41,6,LEAVES:3)
Block(-2,41,7,17:15)
Block(-2,41,8,LEAVES:3)
Block(-2,41,10,LEAVES:3)
Block(-2,41,11,17:15)
Block(-2,41,13,LEAVES:3)
Block(-2,42,-8,LEAVES:3)
Block(-2,42,-1,LEAVES:3)
Block(-2,42,0,LEAVES:3)
Block(-2,42,1,LEAVES:3)
Block(-2,42,2,LEAVES:3)
Block(-2,42,6,LEAVES:3)
Block(-2,42,7,LEAVES:3)
Block(-2,42,8,LEAVES:3)
Block(-2,42,9,LEAVES:3)
Block(-2,42,11,LEAVES:3)
Block(-2,42,12,17:15)
Block(-2,42,13,17:15)
Block(-2,42,14,LEAVES:3)
Block(-2,42,15,LEAVES:3)
Block(-2,43,-5,LEAVES:3)
Block(-2,43,-4,LEAVES:3)
Block(-2,43,-3,LEAVES:3)
Block(-2,43,-2,17:15)
Block(-2,43,-1,LEAVES:3)
Block(-2,43,8,LEAVES:3)
Block(-2,43,12,LEAVES:3)
Block(-2,43,13,LEAVES:3)
Block(-2,43,14,LEAVES:3)
Block(-2,44,-4,LEAVES:3)
Block(-2,44,-3,LEAVES:3)
Block(-2,44,-2,LEAVES:3)
Block(-2,44,-1,LEAVES:3)
Block(-2,45,-2,LEAVES:3)
Block(-1,-5,-5,17:15)
Block(-1,-5,2,17:15)
Block(-1,-4,-5,17:15)
Block(-1,-4,2,17:15)
Block(-1,-3,2,17:15)
Block(-1,-2,-4,17:15)
Block(-1,-1,-4,17:15)
Block(-1,-1,2,17:15)
Block(-1,0,-4,17:15)
Block(-1,0,-3,17:15)
Block(-1,0,-2,17:15)
Block(-1,0,0,17:15)
Block(-1,1,-3,17:15)
Block(-1,1,-2,17:15)
Block(-1,1,-1,17:15)
Block(-1,1,0,17:15)
Block(-1,1,1,17:15)
Block(-1,2,-2,17:15)
Block(-1,2,-1,17:15)
Block(-1,2,0,17:15)
Block(-1,2,1,17:15)
Block(-1,3,-1,17:15)
Block(-1,3,0,17:15)
Block(-1,4,-1,17:15)
Block(-1,4,0,17:15)
Block(-1,5,-1,17:15)
Block(-1,5,0,17:15)
Block(-1,6,-1,17:15)
Block(-1,7,-1,17:15)
Block(-1,8,-1,17:15)
Block(-1,9,-1,17:15)
Block(-1,10,-1,17:15)
Block(-1,11,-1,17:15)
Block(-1,12,-1,17:15)
Block(-1,13,-1,17:15)
Block(-1,14,-1,17:15)
Block(-1,15,-1,17:15)
Block(-1,16,-1,17:15)
Block(-1,17,-1,17:15)
Block(-1,18,-1,17:15)
Block(-1,19,-2,LEAVES:3)
Block(-1,19,-1,17:15)
Block(-1,20,-3,LEAVES:3)
Block(-1,20,-1,17:15)
Block(-1,21,-6,LEAVES:3)
Block(-1,21,-5,LEAVES:3)
Block(-1,21,-4,LEAVES:3)
Block(-1,21,-1,17:15)
Block(-1,22,-10,LEAVES:3)
Block(-1,22,-9,LEAVES:3)
Block(-1,22,-8,17:15)
Block(-1,22,-7,LEAVES:3)
Block(-1,22,-6,LEAVES:3)
Block(-1,22,-5,LEAVES:3)
Block(-1,23,-12,LEAVES:3)
Block(-1,23,-8,LEAVES:3)
Block(-1,23,-7,LEAVES:3)
Block(-1,29,1,17:15)
Block(-1,29,2,17:15)
Block(-1,29,4,LEAVES:3)
Block(-1,30,2,LEAVES:3)
Block(-1,30,3,LEAVES:3)
Block(-1,30,4,17:15)
Block(-1,30,5,LEAVES:3)
Block(-1,30,6,LEAVES:3)
Block(-1,30,7,LEAVES:3)
Block(-1,31,-8,17:15)
Block(-1,31,3,LEAVES:3)
Block(-1,31,4,LEAVES:3)
Block(-1,32,-2,17:15)
Block(-1,33,-2,17:15)
Block(-1,34,-8,LEAVES:3)
Block(-1,34,-7,17:15)
Block(-1,35,-9,LEAVES:3)
Block(-1,35,-7,LEAVES:3)
Block(-1,35,-1,17:15)
Block(-1,36,-8,LEAVES:3)
Block(-1,36,-2,17:15)
Block(-1,36,-1,17:15)
Block(-1,37,-2,17:15)
Block(-1,38,1,17:15)
Block(-1,38,2,17:15)
Block(-1,39,-1,17:15)
Block(-1,39,2,17:15)
Block(-1,39,3,17:15)
Block(-1,39,5,LEAVES:3)
Block(-1,40,-9,LEAVES:3)
Block(-1,40,3,LEAVES:3)
Block(-1,40,4,LEAVES:3)
Block(-1,40,5,LEAVES:3)
Block(-1,40,6,LEAVES:3)
Block(-1,40,9,LEAVES:3)
Block(-1,41,-10,LEAVES:3)
Block(-1,41,-9,LEAVES:3)
Block(-1,41,-8,LEAVES:3)
Block(-1,41,-7,17:15)
Block(-1,41,-6,LEAVES:3)
Block(-1,41,-5,LEAVES:3)
Block(-1,41,-1,LEAVES:3)
Block(-1,41,0,17:15)
Block(-1,41,2,17:15)
Block(-1,41,6,LEAVES:3)
Block(-1,41,7,LEAVES:3)
Block(-1,41,8,17:15)
Block(-1,41,9,LEAVES:3)
Block(-1,41,10,LEAVES:3)
Block(-1,41,15,LEAVES:3)
Block(-1,42,-9,LEAVES:3)
Block(-1,42,-8,LEAVES:3)
Block(-1,42,-7,LEAVES:3)
Block(-1,42,-4,LEAVES:3)
Block(-1,42,-2,LEAVES:3)
Block(-1,42,-1,17:15)
Block(-1,42,0,LEAVES:3)
Block(-1,42,1,LEAVES:3)
Block(-1,42,2,LEAVES:3)
Block(-1,42,7,LEAVES:3)
Block(-1,42,8,LEAVES:3)
Block(-1,42,9,LEAVES:3)
Block(-1,42,10,LEAVES:3)
Block(-1,42,11,LEAVES:3)
Block(-1,42,12,LEAVES:3)
Block(-1,42,13,LEAVES:3)
Block(-1,42,14,LEAVES:3)
Block(-1,43,-7,LEAVES:3)
Block(-1,43,-4,LEAVES:3)
Block(-1,43,-3,LEAVES:3)
Block(-1,43,-2,LEAVES:3)
Block(-1,43,-1,LEAVES:3)
Block(-1,43,1,LEAVES:3)
Block(-1,43,7,LEAVES:3)
Block(-1,43,8,LEAVES:3)
Block(-1,43,9,LEAVES:3)
Block(-1,43,12,LEAVES:3)
Block(-1,44,8,LEAVES:3)
Block(0,-4,-3,17:15)
Block(0,-3,-3,17:15)
Block(0,-3,-2,17:15)
Block(0,-3,-1,17:15)
Block(0,-3,3,17:15)
Block(0,-2,-2,17:15)
Block(0,-2,-1,17:15)
Block(0,-2,3,17:15)
Block(0,-1,-1,17:15)
Block(0,-1,2,17:15)
Block(0,-1,3,17:15)
Block(0,0,-1,17:15)
Block(0,0,0,17:15)
Block(0,0,1,17:15)
Block(0,0,2,17:15)
Block(0,1,-1,17:15)
Block(0,1,0,17:15)
Block(0,1,1,17:15)
Block(0,2,-2,17:15)
Block(0,2,-1,17:15)
Block(0,2,0,17:15)
Block(0,2,1,17:15)
Block(0,3,-2,17:15)
Block(0,3,-1,17:15)
Block(0,3,0,17:15)
Block(0,3,1,17:15)
Block(0,4,-2,17:15)
Block(0,4,-1,17:15)
Block(0,4,0,17:15)
Block(0,5,-2,17:15)
Block(0,5,-1,17:15)
Block(0,5,0,17:15)
Block(0,6,-2,17:15)
Block(0,6,-1,17:15)
Block(0,6,0,17:15)
Block(0,7,-2,17:15)
Block(0,7,-1,17:15)
Block(0,7,0,17:15)
Block(0,8,-2,17:15)
Block(0,8,-1,17:15)
Block(0,8,0,17:15)
Block(0,9,-2,17:15)
Block(0,9,-1,17:15)
Block(0,9,0,17:15)
Block(0,10,-2,17:15)
Block(0,10,-1,17:15)
Block(0,10,0,17:15)
Block(0,11,-2,17:15)
Block(0,11,-1,17:15)
Block(0,11,0,17:15)
Block(0,12,-2,17:15)
Block(0,12,-1,17:15)
Block(0,12,0,17:15)
Block(0,13,-2,17:15)
Block(0,13,-1,17:15)
Block(0,13,0,17:15)
Block(0,14,-2,17:15)
Block(0,14,-1,17:15)
Block(0,14,0,17:15)
Block(0,15,-2,17:15)
Block(0,15,-1,17:15)
Block(0,15,0,17:15)
Block(0,16,-2,17:15)
Block(0,16,-1,17:15)
Block(0,16,0,17:15)
Block(0,17,-2,17:15)
Block(0,17,-1,17:15)
Block(0,17,0,17:15)
Block(0,18,-2,17:15)
Block(0,18,-1,17:15)
Block(0,18,0,17:15)
Block(0,19,-2,17:15)
Block(0,19,-1,17:15)
Block(0,20,-5,LEAVES:3)
Block(0,20,-3,17:15)
Block(0,20,-2,17:15)
Block(0,20,-1,17:15)
Block(0,21,-9,LEAVES:3)
Block(0,21,-6,LEAVES:3)
Block(0,21,-5,LEAVES:3)
Block(0,21,-4,LEAVES:3)
Block(0,21,-3,LEAVES:3)
Block(0,21,-2,17:15)
Block(0,21,-1,17:15)
Block(0,22,-15,LEAVES:3)
Block(0,22,-10,LEAVES:3)
Block(0,22,-9,LEAVES:3)
Block(0,22,-8,17:15)
Block(0,22,-7,LEAVES:3)
Block(0,22,-6,LEAVES:3)
Block(0,22,-2,17:15)
Block(0,22,-1,17:15)
Block(0,23,-14,LEAVES:3)
Block(0,23,-13,LEAVES:3)
Block(0,23,-12,LEAVES:3)
Block(0,23,-11,LEAVES:3)
Block(0,23,-10,LEAVES:3)
Block(0,23,-9,LEAVES:3)
Block(0,23,-8,LEAVES:3)
Block(0,23,-7,LEAVES:3)
Block(0,23,-2,17:15)
Block(0,23,-1,17:15)
Block(0,24,-12,LEAVES:3)
Block(0,24,-9,LEAVES:3)
Block(0,24,-8,LEAVES:3)
Block(0,24,-7,LEAVES:3)
Block(0,24,-2,17:15)
Block(0,24,-1,17:15)
Block(0,25,-8,LEAVES:3)
Block(0,25,-2,17:15)
Block(0,25,-1,17:15)
Block(0,26,-2,17:15)
Block(0,26,-1,17:15)
Block(0,27,-2,17:15)
Block(0,27,-1,17:15)
Block(0,28,-2,17:15)
Block(0,28,-1,17:15)
Block(0,28,0,17:15)
Block(0,29,-2,17:15)
Block(0,29,-1,17:15)
Block(0,29,0,17:15)
Block(0,29,2,17:15)
Block(0,29,3,17:15)
Block(0,30,-2,17:15)
Block(0,30,-1,17:15)
Block(0,30,3,LEAVES:3)
Block(0,30,4,17:15)
Block(0,31,-7,17:15)
Block(0,31,-2,17:15)
Block(0,31,-1,17:15)
Block(0,31,4,LEAVES:3)
Block(0,31,5,LEAVES:3)
Block(0,31,6,LEAVES:3)
Block(0,31,7,LEAVES:3)
Block(0,31,8,LEAVES:3)
Block(0,32,-6,17:15)
Block(0,32,-3,17:15)
Block(0,32,-2,17:15)
Block(0,32,-1,17:15)
Block(0,32,6,LEAVES:3)
Block(0,33,-1,17:15)
Block(0,34,-10,LEAVES:3)
Block(0,34,-7,LEAVES:3)
Block(0,34,-1,17:15)
Block(0,35,-10,LEAVES:3)
Block(0,35,-9,LEAVES:3)
Block(0,35,-8,17:15)
Block(0,35,-7,LEAVES:3)
Block(0,35,-1,17:15)
Block(0,36,-9,LEAVES:3)
Block(0,36,-8,LEAVES:3)
Block(0,36,-1,17:15)
Block(0,37,-8,LEAVES:3)
Block(0,37,-1,17:15)
Block(0,37,0,17:15)
Block(0,37,1,17:15)
Block(0,38,-1,17:15)
Block(0,38,1,17:15)
Block(0,38,2,LEAVES:3)
Block(0,38,4,LEAVES:3)
Block(0,38,6,LEAVES:3)
Block(0,39,3,LEAVES:3)
Block(0,39,5,LEAVES:3)
Block(0,39,6,LEAVES:3)
Block(0,39,7,LEAVES:3)
Block(0,40,-7,LEAVES:3)
Block(0,40,-4,LEAVES:3)
Block(0,40,1,LEAVES:3)
Block(0,40,4,LEAVES:3)
Block(0,40,5,LEAVES:3)
Block(0,40,6,LEAVES:3)
Block(0,41,-9,LEAVES:3)
Block(0,41,-8,LEAVES:3)
Block(0,41,-7,LEAVES:3)
Block(0,41,-6,17:15)
Block(0,41,-5,LEAVES:3)
Block(0,41,-4,LEAVES:3)
Block(0,41,1,17:15)
Block(0,41,2,17:15)
Block(0,41,3,17:15)
Block(0,41,5,LEAVES:3)
Block(0,41,6,LEAVES:3)
Block(0,41,7,LEAVES:3)
Block(0,41,8,17:15)
Block(0,41,9,LEAVES:3)
Block(0,41,10,LEAVES:3)
Block(0,42,-7,LEAVES:3)
Block(0,42,-5,LEAVES:3)
Block(0,42,-3,LEAVES:3)
Block(0,42,-2,LEAVES:3)
Block(0,42,-1,LEAVES:3)
Block(0,42,0,17:15)
Block(0,42,1,17:15)
Block(0,42,2,LEAVES:3)
Block(0,42,3,LEAVES:3)
Block(0,42,7,LEAVES:3)
Block(0,42,8,LEAVES:3)
Block(0,42,12,LEAVES:3)
Block(0,43,-2,LEAVES:3)
Block(0,43,-1,LEAVES:3)
Block(0,43,0,LEAVES:3)
Block(0,43,1,LEAVES:3)
Block(0,43,2,LEAVES:3)
Block(0,44,-1,LEAVES:3)
Block(0,44,1,LEAVES:3)
Block(1,-5,-3,17:15)
Block(1,-5,3,17:15)
Block(1,-4,-3,17:15)
Block(1,-4,3,17:15)
Block(1,-3,-1,17:15)
Block(1,-3,3,17:15)
Block(1,-2,-1,17:15)
Block(1,-2,1,17:15)
Block(1,-1,-1,17:15)
Block(1,-1,1,17:15)
Block(1,0,-3,17:15)
Block(1,0,-1,17:15)
Block(1,0,0,17:15)
Block(1,0,1,17:15)
Block(1,1,-3,17:15)
Block(1,1,-2,17:15)
Block(1,1,0,17:15)
Block(1,1,1,17:15)
Block(1,2,-3,17:15)
Block(1,2,-2,17:15)
Block(1,2,-1,17:15)
Block(1,2,0,17:15)
Block(1,3,-3,17:15)
Block(1,3,-2,17:15)
Block(1,3,-1,17:15)
Block(1,3,0,17:15)
Block(1,4,-2,17:15)
Block(1,4,-1,17:15)
Block(1,4,0,17:15)
Block(1,5,-2,17:15)
Block(1,5,-1,17:15)
Block(1,6,-2,17:15)
Block(1,6,-1,17:15)
Block(1,7,-2,17:15)
Block(1,7,-1,17:15)
Block(1,8,-2,17:15)
Block(1,8,-1,17:15)
Block(1,9,-2,17:15)
Block(1,9,-1,17:15)
Block(1,10,-2,17:15)
Block(1,10,-1,17:15)
Block(1,11,-2,17:15)
Block(1,11,-1,17:15)
Block(1,12,-2,17:15)
Block(1,12,-1,17:15)
Block(1,13,-2,17:15)
Block(1,13,-1,17:15)
Block(1,14,-2,17:15)
Block(1,14,-1,17:15)
Block(1,15,-2,17:15)
Block(1,15,-1,17:15)
Block(1,16,-2,17:15)
Block(1,16,-1,17:15)
Block(1,17,-2,17:15)
Block(1,17,-1,17:15)
Block(1,18,-3,17:15)
Block(1,18,-2,17:15)
Block(1,18,-1,17:15)
Block(1,19,-3,17:15)
Block(1,19,-1,17:15)
Block(1,20,-5,17:15)
Block(1,20,-4,17:15)
Block(1,20,-3,17:15)
Block(1,20,-1,17:15)
Block(1,21,-11,LEAVES:3)
Block(1,21,-6,LEAVES:3)
Block(1,21,-5,17:15)
Block(1,21,-4,LEAVES:3)
Block(1,21,-3,LEAVES:3)
Block(1,21,-1,17:15)
Block(1,22,-13,LEAVES:3)
Block(1,22,-11,17:15)
Block(1,22,-10,LEAVES:3)
Block(1,22,-8,LEAVES:3)
Block(1,22,-7,17:15)
Block(1,22,-6,LEAVES:3)
Block(1,22,-5,LEAVES:3)
Block(1,22,-4,LEAVES:3)
Block(1,22,-1,17:15)
Block(1,23,-15,LEAVES:3)
Block(1,23,-14,LEAVES:3)
Block(1,23,-13,17:15)
Block(1,23,-12,17:15)
Block(1,23,-11,LEAVES:3)
Block(1,23,-9,LEAVES:3)
Block(1,23,-8,LEAVES:3)
Block(1,23,-7,LEAVES:3)
Block(1,23,-6,LEAVES:3)
Block(1,23,-1,17:15)
Block(1,24,-14,LEAVES:3)
Block(1,24,-13,LEAVES:3)
Block(1,24,-12,LEAVES:3)
Block(1,24,-8,LEAVES:3)
Block(1,24,-1,17:15)
Block(1,25,-1,17:15)
Block(1,26,-1,17:15)
Block(1,27,-1,17:15)
Block(1,28,-1,17:15)
Block(1,29,-1,17:15)
Block(1,30,-1,17:15)
Block(1,30,4,LEAVES:3)
Block(1,30,5,17:15)
Block(1,30,6,17:15)
Block(1,30,7,LEAVES:3)
Block(1,30,9,LEAVES:3)
Block(1,31,-1,17:15)
Block(1,31,4,LEAVES:3)
Block(1,31,5,LEAVES:3)
Block(1,31,6,17:15)
Block(1,31,7,LEAVES:3)
Block(1,31,8,LEAVES:3)
Block(1,31,9,LEAVES:3)
Block(1,32,-5,17:15)
Block(1,32,-4,17:15)
Block(1,32,-1,17:15)
Block(1,32,5,LEAVES:3)
Block(1,32,6,LEAVES:3)
Block(1,32,7,LEAVES:3)
Block(1,32,8,LEAVES:3)
Block(1,33,-1,17:15)
Block(1,33,6,LEAVES:3)
Block(1,34,-8,LEAVES:3)
Block(1,35,-9,LEAVES:3)
Block(1,35,-8,LEAVES:3)
Block(1,35,-7,LEAVES:3)
Block(1,36,-8,LEAVES:3)
Block(1,37,-10,LEAVES:3)
Block(1,37,-7,LEAVES:3)
Block(1,37,1,17:15)
Block(1,38,-9,LEAVES:3)
Block(1,38,-2,17:15)
Block(1,38,8,LEAVES:3)
Block(1,39,-8,LEAVES:3)
Block(1,39,-6,LEAVES:3)
Block(1,39,-2,17:15)
Block(1,39,4,LEAVES:3)
Block(1,39,5,LEAVES:3)
Block(1,39,6,17:15)
Block(1,39,7,LEAVES:3)
Block(1,39,8,LEAVES:3)
Block(1,39,10,LEAVES:3)
Block(1,40,-8,LEAVES:3)
Block(1,40,-7,LEAVES:3)
Block(1,40,-6,17:15)
Block(1,40,-5,LEAVES:3)
Block(1,40,-1,17:15)
Block(1,40,5,LEAVES:3)
Block(1,40,6,LEAVES:3)
Block(1,40,7,LEAVES:3)
Block(1,40,9,LEAVES:3)
Block(1,41,-7,LEAVES:3)
Block(1,41,-6,LEAVES:3)
Block(1,41,-5,LEAVES:3)
Block(1,41,-3,LEAVES:3)
Block(1,41,-1,LEAVES:3)
Block(1,41,0,LEAVES:3)
Block(1,41,1,17:15)
Block(1,41,2,LEAVES:3)
Block(1,41,3,LEAVES:3)
Block(1,41,7,LEAVES:3)
Block(1,41,8,LEAVES:3)
Block(1,41,9,17:15)
Block(1,41,12,LEAVES:3)
Block(1,42,-2,LEAVES:3)
Block(1,42,-1,LEAVES:3)
Block(1,42,0,LEAVES:3)
Block(1,42,1,LEAVES:3)
Block(1,42,2,LEAVES:3)
Block(1,42,3,LEAVES:3)
Block(1,42,4,LEAVES:3)
Block(1,42,9,LEAVES:3)
Block(1,42,10,LEAVES:3)
Block(1,42,11,LEAVES:3)
Block(1,42,12,LEAVES:3)
Block(1,42,13,LEAVES:3)
Block(1,43,-1,LEAVES:3)
Block(1,43,1,LEAVES:3)
Block(1,43,2,LEAVES:3)
Block(1,43,3,LEAVES:3)
Block(1,43,10,LEAVES:3)
Block(1,43,11,LEAVES:3)
Block(2,-5,-5,17:15)
Block(2,-5,1,17:15)
Block(2,-4,-5,17:15)
Block(2,-4,-1,17:15)
Block(2,-4,1,17:15)
Block(2,-3,-5,17:15)
Block(2,-3,-1,17:15)
Block(2,-3,1,17:15)
Block(2,-2,-5,17:15)
Block(2,-2,-4,17:15)
Block(2,-2,-1,17:15)
Block(2,-2,1,17:15)
Block(2,-1,-4,17:15)
Block(2,-1,-3,17:15)
Block(2,-1,-2,17:15)
Block(2,-1,1,17:15)
Block(2,0,-3,17:15)
Block(2,0,-2,17:15)
Block(2,1,-2,17:15)
Block(2,1,-1,17:15)
Block(2,2,-1,17:15)
Block(2,3,-1,17:15)
Block(2,4,-1,17:15)
Block(2,5,-1,17:15)
Block(2,6,-1,17:15)
Block(2,7,-1,17:15)
Block(2,8,-1,17:15)
Block(2,9,-1,17:15)
Block(2,10,-1,17:15)
Block(2,11,-2,17:15)
Block(2,11,-1,17:15)
Block(2,12,-7,LEAVES:3)
Block(2,12,-1,17:15)
Block(2,13,-9,LEAVES:3)
Block(2,13,-6,LEAVES:3)
Block(2,14,-8,LEAVES:3)
Block(2,20,-8,LEAVES:3)
Block(2,20,-5,LEAVES:3)
Block(2,21,-11,LEAVES:3)
Block(2,21,-10,LEAVES:3)
Block(2,21,-8,LEAVES:3)
Block(2,21,-7,17:15)
Block(2,21,-6,17:15)
Block(2,21,-5,17:15)
Block(2,21,-4,LEAVES:3)
Block(2,22,-13,LEAVES:3)
Block(2,22,-10,17:15)
Block(2,22,-8,LEAVES:3)
Block(2,22,-7,LEAVES:3)
Block(2,22,-6,LEAVES:3)
Block(2,22,-5,LEAVES:3)
Block(2,23,-14,LEAVES:3)
Block(2,23,-13,LEAVES:3)
Block(2,23,-12,LEAVES:3)
Block(2,23,-11,LEAVES:3)
Block(2,23,-10,LEAVES:3)
Block(2,23,-7,LEAVES:3)
Block(2,29,3,LEAVES:3)
Block(2,29,5,LEAVES:3)
Block(2,30,4,LEAVES:3)
Block(2,30,5,LEAVES:3)
Block(2,30,6,LEAVES:3)
Block(2,31,5,LEAVES:3)
Block(2,31,6,LEAVES:3)
Block(2,31,7,LEAVES:3)
Block(2,31,8,LEAVES:3)
Block(2,32,7,LEAVES:3)
Block(2,33,-6,17:15)
Block(2,33,-5,17:15)
Block(2,33,-1,17:15)
Block(2,34,-1,17:15)
Block(2,35,-8,LEAVES:3)
Block(2,36,-7,LEAVES:3)
Block(2,36,-5,LEAVES:3)
Block(2,37,-8,LEAVES:3)
Block(2,37,-7,LEAVES:3)
Block(2,37,-6,LEAVES:3)
Block(2,38,-10,LEAVES:3)
Block(2,38,-9,LEAVES:3)
Block(2,38,-8,LEAVES:3)
Block(2,38,-7,LEAVES:3)
Block(2,38,2,17:15)
Block(2,38,3,17:15)
Block(2,38,5,LEAVES:3)
Block(2,39,-9,LEAVES:3)
Block(2,39,-3,17:15)
Block(2,39,3,LEAVES:3)
Block(2,39,4,LEAVES:3)
Block(2,39,5,17:15)
Block(2,39,6,LEAVES:3)
Block(2,39,7,LEAVES:3)
Block(2,39,8,LEAVES:3)
Block(2,40,-7,LEAVES:3)
Block(2,40,-6,LEAVES:3)
Block(2,40,-5,17:15)
Block(2,40,-4,17:15)
Block(2,40,0,17:15)
Block(2,40,4,LEAVES:3)
Block(2,40,5,LEAVES:3)
Block(2,40,10,LEAVES:3)
Block(2,41,-5,LEAVES:3)
Block(2,41,0,LEAVES:3)
Block(2,41,1,17:15)
Block(2,41,5,LEAVES:3)
Block(2,41,8,LEAVES:3)
Block(2,41,9,LEAVES:3)
Block(2,41,11,LEAVES:3)
Block(2,41,14,LEAVES:3)
Block(2,42,-1,LEAVES:3)
Block(2,42,1,LEAVES:3)
Block(2,42,2,LEAVES:3)
Block(2,42,3,17:15)
Block(2,42,4,LEAVES:3)
Block(2,42,5,LEAVES:3)
Block(2,42,9,LEAVES:3)
Block(2,42,10,17:15)
Block(2,42,11,LEAVES:3)
Block(2,42,12,LEAVES:3)
Block(2,42,13,LEAVES:3)
Block(2,43,0,LEAVES:3)
Block(2,43,3,LEAVES:3)
Block(2,43,4,LEAVES:3)
Block(2,43,10,LEAVES:3)
Block(2,43,11,LEAVES:3)
Block(2,43,12,LEAVES:3)
Block(2,44,11,LEAVES:3)
Block(3,-5,0,17:15)
Block(3,-4,-3,17:15)
Block(3,-4,0,17:15)
Block(3,-4,1,17:15)
Block(3,-3,-3,17:15)
Block(3,-2,-3,17:15)
Block(3,-2,-2,17:15)
Block(3,-1,-2,17:15)
Block(3,-1,0,17:15)
Block(3,0,-2,17:15)
Block(3,0,-1,17:15)
Block(3,0,0,17:15)
Block(3,1,-1,17:15)
Block(3,1,0,17:15)
Block(3,2,-1,17:15)
Block(3,12,-6,LEAVES:3)
Block(3,12,-4,LEAVES:3)
Block(3,12,-3,17:15)
Block(3,12,-1,17:15)
Block(3,12,0,17:15)
Block(3,12,2,LEAVES:3)
Block(3,13,-7,LEAVES:3)
Block(3,13,-6,LEAVES:3)
Block(3,13,-5,LEAVES:3)
Block(3,13,0,17:15)
Block(3,13,1,LEAVES:3)
Block(3,14,-9,LEAVES:3)
Block(3,14,-8,LEAVES:3)
Block(3,14,-7,LEAVES:3)
Block(3,14,-6,LEAVES:3)
Block(3,15,-8,LEAVES:3)
Block(3,20,-5,LEAVES:3)
Block(3,21,-9,LEAVES:3)
Block(3,21,-8,17:15)
Block(3,21,-7,17:15)
Block(3,21,-6,LEAVES:3)
Block(3,21,-5,LEAVES:3)
Block(3,22,-14,LEAVES:3)
Block(3,22,-12,LEAVES:3)
Block(3,22,-11,LEAVES:3)
Block(3,22,-10,17:15)
Block(3,22,-9,17:15)
Block(3,22,-8,17:15)
Block(3,22,-7,LEAVES:3)
Block(3,22,-6,LEAVES:3)
Block(3,23,-13,LEAVES:3)
Block(3,23,-12,LEAVES:3)
Block(3,23,-11,LEAVES:3)
Block(3,23,-10,LEAVES:3)
Block(3,23,-9,LEAVES:3)
Block(3,23,-8,LEAVES:3)
Block(3,23,-7,LEAVES:3)
Block(3,23,-6,LEAVES:3)
Block(3,24,-11,LEAVES:3)
Block(3,24,-7,LEAVES:3)
Block(3,29,6,LEAVES:3)
Block(3,30,5,LEAVES:3)
Block(3,30,8,LEAVES:3)
Block(3,31,7,LEAVES:3)
Block(3,34,-8,17:15)
Block(3,34,-7,17:15)
Block(3,34,-1,17:15)
Block(3,37,-11,LEAVES:3)
Block(3,37,-9,LEAVES:3)
Block(3,37,-7,17:15)
Block(3,37,-6,LEAVES:3)
Block(3,38,-11,LEAVES:3)
Block(3,38,-10,LEAVES:3)
Block(3,38,-9,LEAVES:3)
Block(3,38,-8,17:15)
Block(3,38,-7,LEAVES:3)
Block(3,38,-6,LEAVES:3)
Block(3,38,3,17:15)
Block(3,38,4,17:15)
Block(3,39,-10,LEAVES:3)
Block(3,39,-9,LEAVES:3)
Block(3,39,-8,LEAVES:3)
Block(3,39,-7,LEAVES:3)
Block(3,39,-4,LEAVES:3)
Block(3,39,-3,17:15)
Block(3,39,4,LEAVES:3)
Block(3,39,5,17:15)
Block(3,40,-8,LEAVES:3)
Block(3,40,-6,LEAVES:3)
Block(3,40,-5,LEAVES:3)
Block(3,40,-4,LEAVES:3)
Block(3,40,1,17:15)
Block(3,40,5,LEAVES:3)
Block(3,40,6,LEAVES:3)
Block(3,40,7,LEAVES:3)
Block(3,40,8,LEAVES:3)
Block(3,40,9,LEAVES:3)
Block(3,41,-5,LEAVES:3)
Block(3,41,-2,LEAVES:3)
Block(3,41,1,LEAVES:3)
Block(3,41,2,LEAVES:3)
Block(3,41,7,LEAVES:3)
Block(3,41,9,LEAVES:3)
Block(3,41,12,LEAVES:3)
Block(3,42,-2,LEAVES:3)
Block(3,42,-1,LEAVES:3)
Block(3,42,0,17:15)
Block(3,42,1,LEAVES:3)
Block(3,42,2,17:15)
Block(3,42,3,LEAVES:3)
Block(3,42,4,LEAVES:3)
Block(3,42,5,LEAVES:3)
Block(3,42,10,LEAVES:3)
Block(3,42,11,LEAVES:3)
Block(3,42,12,LEAVES:3)
Block(3,43,-1,LEAVES:3)
Block(3,43,0,LEAVES:3)
Block(3,43,1,LEAVES:3)
Block(3,43,2,LEAVES:3)
Block(3,43,11,LEAVES:3)
Block(3,44,0,LEAVES:3)
Block(4,-5,-3,17:15)
Block(4,-4,-3,17:15)
Block(4,-3,-2,17:15)
Block(4,-2,-2,17:15)
Block(4,-2,0,17:15)
Block(4,-1,0,17:15)
Block(4,12,-3,17:15)
Block(4,12,0,17:15)
Block(4,12,1,17:15)
Block(4,12,2,LEAVES:3)
Block(4,12,3,LEAVES:3)
Block(4,13,-10,LEAVES:3)
Block(4,13,-8,LEAVES:3)
Block(4,13,-6,17:15)
Block(4,13,-5,LEAVES:3)
Block(4,13,0,LEAVES:3)
Block(4,13,1,17:15)
Block(4,13,2,LEAVES:3)
Block(4,14,-10,LEAVES:3)
Block(4,14,-9,LEAVES:3)
Block(4,14,-8,LEAVES:3)
Block(4,14,-7,17:15)
Block(4,14,-6,LEAVES:3)
Block(4,14,-5,LEAVES:3)
Block(4,14,1,LEAVES:3)
Block(4,14,2,LEAVES:3)
Block(4,15,-9,LEAVES:3)
Block(4,15,-8,LEAVES:3)
Block(4,15,-7,LEAVES:3)
Block(4,15,-6,LEAVES:3)
Block(4,16,-7,LEAVES:3)
Block(4,20,-7,17:15)
Block(4,20,-6,LEAVES:3)
Block(4,21,-11,LEAVES:3)
Block(4,21,-8,LEAVES:3)
Block(4,21,-7,17:15)
Block(4,21,-6,LEAVES:3)
Block(4,21,-5,LEAVES:3)
Block(4,22,-14,LEAVES:3)
Block(4,22,-11,17:15)
Block(4,22,-10,17:15)
Block(4,22,-9,LEAVES:3)
Block(4,22,-8,LEAVES:3)
Block(4,22,-7,LEAVES:3)
Block(4,22,-6,LEAVES:3)
Block(4,23,-15,LEAVES:3)
Block(4,23,-14,LEAVES:3)
Block(4,23,-13,LEAVES:3)
Block(4,23,-11,LEAVES:3)
Block(4,23,-10,LEAVES:3)
Block(4,23,-8,LEAVES:3)
Block(4,24,-13,LEAVES:3)
Block(4,34,-2,LEAVES:3)
Block(4,35,-3,17:15)
Block(4,35,-2,LEAVES:3)
Block(4,35,-1,17:15)
Block(4,35,1,LEAVES:3)
Block(4,36,-5,17:15)
Block(4,36,-4,17:15)
Block(4,36,1,LEAVES:3)
Block(4,37,-6,17:15)
Block(4,37,-5,LEAVES:3)
Block(4,38,-10,LEAVES:3)
Block(4,38,-9,LEAVES:3)
Block(4,38,-8,LEAVES:3)
Block(4,38,-7,LEAVES:3)
Block(4,38,-6,LEAVES:3)
Block(4,39,-8,LEAVES:3)
Block(4,39,-6,LEAVES:3)
Block(4,39,5,LEAVES:3)
Block(4,39,6,17:15)
Block(4,39,8,LEAVES:3)
Block(4,39,10,LEAVES:3)
Block(4,40,-5,LEAVES:3)
Block(4,40,-3,17:15)
Block(4,40,5,LEAVES:3)
Block(4,40,6,LEAVES:3)
Block(4,40,7,17:15)
Block(4,40,8,LEAVES:3)
Block(4,40,9,LEAVES:3)
Block(4,40,10,LEAVES:3)
Block(4,41,0,LEAVES:3)
Block(4,41,1,17:15)
Block(4,41,6,LEAVES:3)
Block(4,41,7,LEAVES:3)
Block(4,41,8,LEAVES:3)
Block(4,41,9,LEAVES:3)
Block(4,42,-1,LEAVES:3)
Block(4,42,0,LEAVES:3)
Block(4,42,1,LEAVES:3)
Block(4,42,2,17:15)
Block(4,42,7,LEAVES:3)
Block(4,42,11,LEAVES:3)
Block(4,43,0,LEAVES:3)
Block(4,43,2,LEAVES:3)
Block(4,43,3,LEAVES:3)
Block(4,43,4,LEAVES:3)
Block(4,43,5,LEAVES:3)
Block(4,43,6,LEAVES:3)
Block(4,44,4,LEAVES:3)
Block(5,-5,-1,17:15)
Block(5,-4,-1,17:15)
Block(5,-4,0,17:15)
Block(5,-3,0,17:15)
Block(5,-2,0,17:15)
Block(5,12,-4,17:15)
Block(5,12,-3,17:15)
Block(5,13,-5,17:15)
Block(5,13,-4,LEAVES:3)
Block(5,13,1,17:15)
Block(5,13,2,17:15)
Block(5,13,3,LEAVES:3)
Block(5,14,-9,LEAVES:3)
Block(5,14,-8,LEAVES:3)
Block(5,14,-7,LEAVES:3)
Block(5,14,-6,LEAVES:3)
Block(5,14,-5,LEAVES:3)
Block(5,14,0,LEAVES:3)
Block(5,14,1,LEAVES:3)
Block(5,14,2,LEAVES:3)
Block(5,15,-7,LEAVES:3)
Block(5,15,-2,LEAVES:3)
Block(5,15,1,LEAVES:3)
Block(5,15,2,LEAVES:3)
Block(5,20,-7,17:15)
Block(5,20,-5,LEAVES:3)
Block(5,21,-10,LEAVES:3)
Block(5,21,-9,LEAVES:3)
Block(5,21,-7,LEAVES:3)
Block(5,21,-6,LEAVES:3)
Block(5,22,-16,LEAVES:3)
Block(5,22,-13,LEAVES:3)
Block(5,22,-12,17:15)
Block(5,22,-11,LEAVES:3)
Block(5,22,-10,LEAVES:3)
Block(5,22,-9,LEAVES:3)
Block(5,22,-8,LEAVES:3)
Block(5,23,-16,LEAVES:3)
Block(5,23,-15,LEAVES:3)
Block(5,23,-14,LEAVES:3)
Block(5,23,-13,17:15)
Block(5,23,-12,LEAVES:3)
Block(5,23,-10,LEAVES:3)
Block(5,24,-15,LEAVES:3)
Block(5,24,-14,LEAVES:3)
Block(5,24,-13,LEAVES:3)
Block(5,24,-10,LEAVES:3)
Block(5,24,-9,LEAVES:3)
Block(5,35,-3,LEAVES:3)
Block(5,35,-2,LEAVES:3)
Block(5,35,-1,17:15)
Block(5,35,0,LEAVES:3)
Block(5,36,-6,LEAVES:3)
Block(5,36,-2,LEAVES:3)
Block(5,36,-1,LEAVES:3)
Block(5,36,0,LEAVES:3)
Block(5,36,1,LEAVES:3)
Block(5,36,2,LEAVES:3)
Block(5,37,-9,LEAVES:3)
Block(5,37,-8,LEAVES:3)
Block(5,37,-7,LEAVES:3)
Block(5,37,-6,17:15)
Block(5,37,-5,LEAVES:3)
Block(5,37,-4,LEAVES:3)
Block(5,37,1,LEAVES:3)
Block(5,38,-6,LEAVES:3)
Block(5,38,-5,LEAVES:3)
Block(5,38,4,LEAVES:3)
Block(5,38,6,LEAVES:3)
Block(5,39,5,LEAVES:3)
Block(5,39,6,LEAVES:3)
Block(5,39,7,LEAVES:3)
Block(5,40,-5,LEAVES:3)
Block(5,40,-3,17:15)
Block(5,40,6,LEAVES:3)
Block(5,40,7,LEAVES:3)
Block(5,40,8,LEAVES:3)
Block(5,40,9,LEAVES:3)
Block(5,41,-3,LEAVES:3)
Block(5,41,8,LEAVES:3)
Block(5,42,0,LEAVES:3)
Block(5,42,2,LEAVES:3)
Block(5,42,3,17:15)
Block(5,42,5,LEAVES:3)
Block(5,42,7,LEAVES:3)
Block(5,43,2,LEAVES:3)
Block(5,43,3,LEAVES:3)
Block(5,43,4,17:15)
Block(5,43,5,LEAVES:3)
Block(5,43,6,LEAVES:3)
Block(5,43,7,LEAVES:3)
Block(5,44,3,LEAVES:3)
Block(5,44,4,LEAVES:3)
Block(5,44,5,LEAVES:3)
Block(5,44,6,LEAVES:3)
Block(5,45,4,LEAVES:3)
Block(6,12,-5,LEAVES:3)
Block(6,12,1,LEAVES:3)
Block(6,13,-8,LEAVES:3)
Block(6,13,-7,LEAVES:3)
Block(6,13,-6,LEAVES:3)
Block(6,13,-5,17:15)
Block(6,13,-4,LEAVES:3)
Block(6,13,-3,LEAVES:3)
Block(6,13,0,LEAVES:3)
Block(6,13,1,17:15)
Block(6,13,3,LEAVES:3)
Block(6,14,-5,LEAVES:3)
Block(6,14,-4,LEAVES:3)
Block(6,14,-1,LEAVES:3)
Block(6,14,0,LEAVES:3)
Block(6,14,1,LEAVES:3)
Block(6,14,2,17:15)
Block(6,14,3,17:15)
Block(6,14,4,LEAVES:3)
Block(6,15,-3,LEAVES:3)
Block(6,15,-2,LEAVES:3)
Block(6,15,-1,LEAVES:3)
Block(6,15,0,LEAVES:3)
Block(6,15,2,LEAVES:3)
Block(6,15,3,LEAVES:3)
Block(6,16,-2,LEAVES:3)
Block(6,16,2,LEAVES:3)
Block(6,19,-6,LEAVES:3)
Block(6,20,-8,LEAVES:3)
Block(6,20,-7,17:15)
Block(6,20,-6,LEAVES:3)
Block(6,21,-12,LEAVES:3)
Block(6,21,-10,LEAVES:3)
Block(6,21,-8,LEAVES:3)
Block(6,21,-7,LEAVES:3)
Block(6,21,-6,LEAVES:3)
Block(6,22,-14,LEAVES:3)
Block(6,22,-12,LEAVES:3)
Block(6,22,-11,LEAVES:3)
Block(6,22,-10,LEAVES:3)
Block(6,22,-9,LEAVES:3)
Block(6,22,-8,LEAVES:3)
Block(6,22,-7,LEAVES:3)
Block(6,23,-15,LEAVES:3)
Block(6,23,-14,LEAVES:3)
Block(6,23,-13,LEAVES:3)
Block(6,23,-10,LEAVES:3)
Block(6,24,-15,LEAVES:3)
Block(6,24,-14,LEAVES:3)
Block(6,34,-3,LEAVES:3)
Block(6,34,0,LEAVES:3)
Block(6,35,-2,LEAVES:3)
Block(6,35,-1,LEAVES:3)
Block(6,35,0,17:15)
Block(6,35,3,LEAVES:3)
Block(6,36,-9,LEAVES:3)
Block(6,36,0,LEAVES:3)
Block(6,36,1,17:15)
Block(6,36,2,LEAVES:3)
Block(6,37,-9,LEAVES:3)
Block(6,37,-8,LEAVES:3)
Block(6,37,-7,17:15)
Block(6,37,-6,LEAVES:3)
Block(6,37,-5,LEAVES:3)
Block(6,38,-8,LEAVES:3)
Block(6,38,-7,LEAVES:3)
Block(6,38,7,LEAVES:3)
Block(6,39,6,LEAVES:3)
Block(6,39,9,LEAVES:3)
Block(6,40,-6,LEAVES:3)
Block(6,40,-5,LEAVES:3)
Block(6,40,-4,17:15)
Block(6,40,-3,17:15)
Block(6,40,-2,LEAVES:3)
Block(6,40,8,LEAVES:3)
Block(6,41,-5,LEAVES:3)
Block(6,41,-4,LEAVES:3)
Block(6,41,-3,LEAVES:3)
Block(6,41,-2,LEAVES:3)
Block(6,41,1,LEAVES:3)
Block(6,41,3,LEAVES:3)
Block(6,42,-3,LEAVES:3)
Block(6,42,2,LEAVES:3)
Block(6,42,3,LEAVES:3)
Block(6,42,4,LEAVES:3)
Block(6,43,3,LEAVES:3)
Block(6,43,4,LEAVES:3)
Block(6,43,5,LEAVES:3)
Block(6,43,6,LEAVES:3)
Block(6,44,5,LEAVES:3)
Block(7,12,-8,LEAVES:3)
Block(7,13,-8,LEAVES:3)
Block(7,13,-7,LEAVES:3)
Block(7,13,-6,17:15)
Block(7,13,-5,LEAVES:3)
Block(7,13,-4,LEAVES:3)
Block(7,13,0,17:15)
Block(7,13,2,LEAVES:3)
Block(7,13,5,LEAVES:3)
Block(7,14,-7,LEAVES:3)
Block(7,14,-6,LEAVES:3)
Block(7,14,-2,LEAVES:3)
Block(7,14,-1,LEAVES:3)
Block(7,14,0,17:15)
Block(7,14,1,LEAVES:3)
Block(7,14,2,LEAVES:3)
Block(7,14,3,LEAVES:3)
Block(7,14,4,17:15)
Block(7,14,5,LEAVES:3)
Block(7,15,-4,LEAVES:3)
Block(7,15,-3,LEAVES:3)
Block(7,15,-2,LEAVES:3)
Block(7,15,0,LEAVES:3)
Block(7,15,1,LEAVES:3)
Block(7,15,2,LEAVES:3)
Block(7,15,3,LEAVES:3)
Block(7,15,4,LEAVES:3)
Block(7,16,-3,LEAVES:3)
Block(7,16,-2,LEAVES:3)
Block(7,16,1,LEAVES:3)
Block(7,20,-9,LEAVES:3)
Block(7,20,-6,17:15)
Block(7,20,-4,LEAVES:3)
Block(7,21,-9,LEAVES:3)
Block(7,21,-8,LEAVES:3)
Block(7,21,-7,LEAVES:3)
Block(7,21,-6,LEAVES:3)
Block(7,21,-5,LEAVES:3)
Block(7,22,-13,LEAVES:3)
Block(7,22,-10,LEAVES:3)
Block(7,22,-8,LEAVES:3)
Block(7,22,-6,LEAVES:3)
Block(7,23,-14,LEAVES:3)
Block(7,35,-1,LEAVES:3)
Block(7,35,0,LEAVES:3)
Block(7,35,1,LEAVES:3)
Block(7,36,-7,LEAVES:3)
Block(7,36,-5,LEAVES:3)
Block(7,36,0,LEAVES:3)
Block(7,36,1,LEAVES:3)
Block(7,36,2,17:15)
Block(7,36,3,LEAVES:3)
Block(7,37,-8,LEAVES:3)
Block(7,37,-7,LEAVES:3)
Block(7,37,-6,LEAVES:3)
Block(7,37,1,LEAVES:3)
Block(7,37,2,LEAVES:3)
Block(7,38,-7,LEAVES:3)
Block(7,38,-6,LEAVES:3)
Block(7,38,2,LEAVES:3)
Block(7,39,-6,LEAVES:3)
Block(7,39,-3,LEAVES:3)
Block(7,40,-5,LEAVES:3)
Block(7,40,-3,17:15)
Block(7,40,-2,17:15)
Block(7,40,-1,17:15)
Block(7,40,0,LEAVES:3)
Block(7,41,-5,LEAVES:3)
Block(7,41,-4,LEAVES:3)
Block(7,41,-3,17:15)
Block(7,41,-2,LEAVES:3)
Block(7,41,-1,LEAVES:3)
Block(7,41,0,LEAVES:3)
Block(7,41,1,LEAVES:3)
Block(7,41,4,LEAVES:3)
Block(7,42,-4,LEAVES:3)
Block(7,42,-3,LEAVES:3)
Block(7,42,-2,LEAVES:3)
Block(7,42,3,LEAVES:3)
Block(7,42,6,LEAVES:3)
Block(7,43,-3,LEAVES:3)
Block(7,43,5,LEAVES:3)
Block(8,12,-6,LEAVES:3)
Block(8,12,-4,LEAVES:3)
Block(8,13,-7,LEAVES:3)
Block(8,13,-6,LEAVES:3)
Block(8,13,-5,LEAVES:3)
Block(8,13,-1,LEAVES:3)
Block(8,13,1,LEAVES:3)
Block(8,13,4,LEAVES:3)
Block(8,14,-6,LEAVES:3)
Block(8,14,-5,LEAVES:3)
Block(8,14,-4,LEAVES:3)
Block(8,14,-3,LEAVES:3)
Block(8,14,-1,17:15)
Block(8,14,1,LEAVES:3)
Block(8,14,2,LEAVES:3)
Block(8,14,3,LEAVES:3)
Block(8,14,4,17:15)
Block(8,14,5,LEAVES:3)
Block(8,15,-4,LEAVES:3)
Block(8,15,-3,LEAVES:3)
Block(8,15,-2,17:15)
Block(8,15,-1,LEAVES:3)
Block(8,15,1,LEAVES:3)
Block(8,15,4,LEAVES:3)
Block(8,15,5,LEAVES:3)
Block(8,16,-2,LEAVES:3)
Block(8,16,-1,LEAVES:3)
Block(8,17,-2,LEAVES:3)
Block(8,20,-5,LEAVES:3)
Block(8,21,-8,LEAVES:3)
Block(8,21,-7,LEAVES:3)
Block(8,21,-6,17:15)
Block(8,21,-5,LEAVES:3)
Block(8,21,-4,LEAVES:3)
Block(8,22,-7,LEAVES:3)
Block(8,22,-6,LEAVES:3)
Block(8,22,-5,LEAVES:3)
Block(8,23,-6,LEAVES:3)
Block(8,34,0,LEAVES:3)
Block(8,35,0,LEAVES:3)
Block(8,35,4,LEAVES:3)
Block(8,36,1,LEAVES:3)
Block(8,36,2,LEAVES:3)
Block(8,36,3,LEAVES:3)
Block(8,36,4,LEAVES:3)
Block(8,37,2,LEAVES:3)
Block(8,37,3,LEAVES:3)
Block(8,40,-2,LEAVES:3)
Block(8,40,-1,LEAVES:3)
Block(8,40,1,LEAVES:3)
Block(8,41,-5,LEAVES:3)
Block(8,41,-4,LEAVES:3)
Block(8,41,-3,17:15)
Block(8,41,-2,LEAVES:3)
Block(8,41,0,17:15)
Block(8,41,1,LEAVES:3)
Block(8,41,2,LEAVES:3)
Block(8,42,-3,LEAVES:3)
Block(8,42,-1,LEAVES:3)
Block(8,42,0,LEAVES:3)
Block(8,42,1,LEAVES:3)
Block(8,43,0,LEAVES:3)
Block(9,13,1,LEAVES:3)
Block(9,13,5,LEAVES:3)
Block(9,14,-5,LEAVES:3)
Block(9,14,-1,LEAVES:3)
Block(9,14,0,17:15)
Block(9,14,1,LEAVES:3)
Block(9,14,3,LEAVES:3)
Block(9,14,4,LEAVES:3)
Block(9,14,5,LEAVES:3)
Block(9,14,6,LEAVES:3)
Block(9,15,-5,LEAVES:3)
Block(9,15,-4,LEAVES:3)
Block(9,15,-3,17:15)
Block(9,15,-2,LEAVES:3)
Block(9,15,0,LEAVES:3)
Block(9,15,4,LEAVES:3)
Block(9,15,5,LEAVES:3)
Block(9,16,-4,LEAVES:3)
Block(9,16,-3,LEAVES:3)
Block(9,16,0,LEAVES:3)
Block(9,20,-8,LEAVES:3)
Block(9,20,-6,LEAVES:3)
Block(9,21,-7,LEAVES:3)
Block(9,21,-6,LEAVES:3)
Block(9,21,-5,LEAVES:3)
Block(9,22,-6,LEAVES:3)
Block(9,35,2,LEAVES:3)
Block(9,36,1,LEAVES:3)
Block(9,36,2,LEAVES:3)
Block(9,36,3,LEAVES:3)
Block(9,37,2,LEAVES:3)
Block(9,40,-6,LEAVES:3)
Block(9,40,-4,LEAVES:3)
Block(9,40,-2,LEAVES:3)
Block(9,41,-6,LEAVES:3)
Block(9,41,-5,LEAVES:3)
Block(9,41,-4,17:15)
Block(9,41,-3,LEAVES:3)
Block(9,41,-2,LEAVES:3)
Block(9,41,-1,LEAVES:3)
Block(9,41,0,LEAVES:3)
Block(9,41,1,LEAVES:3)
Block(9,42,-5,LEAVES:3)
Block(9,42,-4,LEAVES:3)
Block(9,42,-3,LEAVES:3)
Block(9,42,-2,LEAVES:3)
Block(9,42,0,LEAVES:3)
Block(9,43,-5,LEAVES:3)
Block(9,43,-3,LEAVES:3)
Block(10,13,4,LEAVES:3)
Block(10,14,-3,LEAVES:3)
Block(10,14,0,LEAVES:3)
Block(10,14,3,LEAVES:3)
Block(10,14,4,LEAVES:3)
Block(10,14,5,LEAVES:3)
Block(10,15,-4,LEAVES:3)
Block(10,15,-3,LEAVES:3)
Block(10,15,-2,LEAVES:3)
Block(10,15,-1,LEAVES:3)
Block(10,15,0,17:15)
Block(10,15,1,LEAVES:3)
Block(10,15,2,LEAVES:3)
Block(10,15,4,LEAVES:3)
Block(10,16,-3,LEAVES:3)
Block(10,16,0,LEAVES:3)
Block(10,16,1,LEAVES:3)
Block(10,17,0,LEAVES:3)
Block(10,19,-6,LEAVES:3)
Block(10,20,-4,LEAVES:3)
Block(10,21,-7,LEAVES:3)
Block(10,21,-6,LEAVES:3)
Block(10,21,-5,LEAVES:3)
Block(10,22,-6,LEAVES:3)
Block(10,35,3,LEAVES:3)
Block(10,36,2,LEAVES:3)
Block(10,40,0,LEAVES:3)
Block(10,41,-4,LEAVES:3)
Block(10,41,-3,LEAVES:3)
Block(10,41,-2,LEAVES:3)
Block(10,41,0,LEAVES:3)
Block(10,42,-6,LEAVES:3)
Block(10,42,-5,17:15)
Block(10,42,-4,LEAVES:3)
Block(10,42,-3,LEAVES:3)
Block(10,43,-5,LEAVES:3)
Block(10,44,-5,LEAVES:3)
Block(11,13,3,LEAVES:3)
Block(11,14,-4,LEAVES:3)
Block(11,14,2,LEAVES:3)
Block(11,14,4,LEAVES:3)
Block(11,15,-3,LEAVES:3)
Block(11,15,-2,LEAVES:3)
Block(11,15,-1,LEAVES:3)
Block(11,15,0,LEAVES:3)
Block(11,15,1,LEAVES:3)
Block(11,15,2,LEAVES:3)
Block(11,16,0,LEAVES:3)
Block(11,20,-6,LEAVES:3)
Block(11,21,-6,LEAVES:3)
Block(11,40,-2,LEAVES:3)
Block(11,41,-6,LEAVES:3)
Block(11,41,-3,LEAVES:3)
Block(11,42,-7,LEAVES:3)
Block(11,42,-6,LEAVES:3)
Block(11,42,-5,LEAVES:3)
Block(11,42,-4,LEAVES:3)
Block(11,43,-6,LEAVES:3)
Block(11,43,-5,LEAVES:3)
Block(12,14,-2,LEAVES:3)
Block(12,14,0,LEAVES:3)
Block(12,15,-1,LEAVES:3)
Block(12,15,0,LEAVES:3)
Block(12,15,1,LEAVES:3)
Block(12,16,0,LEAVES:3)
Block(12,41,-4,LEAVES:3)
Block(12,42,-6,LEAVES:3)
Block(12,42,-5,LEAVES:3)
Block(12,42,-4,LEAVES:3)
Block(12,43,-5,LEAVES:3)
Block(13,15,0,LEAVES:3)
Block(13,41,-6,LEAVES:3)
Block(13,42,-5,LEAVES:3)


#######################################################################
# +-----------------------------------------------------------------+ #
# |                             Entities                            | #
# +-----------------------------------------------------------------+ #
#######################################################################

# Entity() spawns an entity instead of a block. The entity is spawned only once when the BO3 is spawned.
# Entities are persistent by default so they don't de-spawn when no player is near, they are only unloaded.
# Usage: Entity(x,y,z,mobName,groupSize,NameTagOrNBTFileName) or Entity(x,y,z,mobName,groupSize)
# Use /tc entities or /otg entities to get a list of entities that can be used as mobName, this includes entities added by other mods.
# NameTagOrNBTFileName can be either a nametag for the mob or an nbt file (such as mymobinfo.nbt or mymobinfo.txt).
# When using a text file you can use the same mob spawning parameters used with the /summon command to equip the
# entity and give it custom attributes etc. You can copy the DATA part of a summon command including surrounding
# curly braces to a .txt file, for instance for: "/summon Skeleton x y z {DATA}"

#######################################################################
# +-----------------------------------------------------------------+ #
# |                            BO3 checks                           | #
# +-----------------------------------------------------------------+ #
#######################################################################

# Require a condition at a certain location in order for the BO3 to be spawned.
# BlockCheck(x,y,z,BlockName[,BlockName[,...]]) - one of the blocks must be at the location
# BlockCheckNot(x,y,z,BlockName[,BlockName[,...]]) - all the blocks must not be at the location
# LightCheck(x,y,z,minLightLevel,maxLightLevel) - light must be between min and max (inclusive)

# You can use "Solid" as a BlockName for matching all solid blocks or "All" to match all blocks that aren't air.

# Examples:
#   BlockCheck(0,-1,0,GRASS,DIRT)  Require grass or dirt just below the object
#   BlockCheck(0,-1,0,Solid)       Require any solid block just below the object
#   BlockCheck(0,-1,0,WOOL)        Require any type of wool just below the object
#   BlockCheck(0,-1,0,WOOL:0)      Require white wool just below the object
#   BlockCheckNot(0,-1,0,WOOL:0)   Require that there is no white wool below the object
#   LightCheck(0,0,0,0,LEAVES:3)          Require almost complete darkness just below the object

