#######################################################################
# +-----------------------------------------------------------------+ #
# |                            BO3 object                           | #
# +-----------------------------------------------------------------+ #
#######################################################################

# The descriptions in this file are accurate only for TerrainControl and OTG.
# For MCW and OTG+ these descriptions are only accurate if the BO3 is used as a CustomObject.
# MCW and OTG+ completely reimplemented CustomStructure, check the MCW/OTG+ documentation for more information.

# This is the config file of a custom object.
# If you add this object correctly to your BiomeConfigs, it will spawn in the world.

# This is the creator of this BO3 object
Author: Unknown

# A short description of this BO3 object
Description: This BO3 was converted from a schematic using OTGEdit. The author and description information of the schematic could not be found. If you know who the author of the schematic is then please add this information.

# The BO3 version, don't change this! It can be used by external applications to do a version check.
Version: 3

# The settings mode, WriteAll, WriteWithoutComments or WriteDisable. See WorldConfig.
SettingsMode: WriteDisable

#######################################################################
# +-----------------------------------------------------------------+ #
# |                          Main settings                          | #
# +-----------------------------------------------------------------+ #
#######################################################################

# This needs to be set to true to spawn the object in the Tree and Sapling resources.
Tree: true

# The frequency of the BO3 from 1 to 200. Tries this many times to spawn this BO3 when using the CustomObject(...) resource.
# Ignored by Tree(..), Sapling(..) and CustomStructure(..)
Frequency: 1

# The rarity of the BO3 from 0 to 100. Each spawn attempt has rarity% chance to succeed when using the CustomObject(...) resource.
# Ignored by Tree(..), Sapling(..) and CustomStructure(..)
Rarity: 100.0

# If you set this to true, the BO3 will be placed with a random rotation.
RotateRandomly: false

# The spawn height of the BO3 - randomY, highestBlock or highestSolidBlock.
SpawnHeight: highestBlock

# The height limits for the BO3.
MinHeight: 64

MaxHeight: 80

# Objects can have other objects attached to it: branches. Branches can also
# have branches attached to it, which can also have branches, etc. This is the
# maximum branch depth for this objects.
MaxBranchDepth: 10

# When spawned with the UseWorld keyword, this BO3 should NOT spawn in the following biomes.
# If you writer.write the BO3 name directly in the BiomeConfigs, this will be ignored.
ExcludedBiomes: All

# To optimise this BO3 for faster loading times you can use Notepad++ to find/replace comments and abbreviate things.
# Notepad++ find/replace with regex:
# Find: ^[#;].* replace to nothing removes all lines starting with # 
# Find: ^\s*$ replace to nothing removes most empty lines 
# Notepad++ find/replace without regex:
# *Warning: This will only work for OTG 1.10.2 v21 / OTG 1.11.2 v6 or higher. B( is not recognised by lower versions.
# Find: Block( replace to B(

#######################################################################
# +-----------------------------------------------------------------+ #
# |                      Source block settings                      | #
# +-----------------------------------------------------------------+ #
#######################################################################

# The block(s) the BO3 should spawn in.
SourceBlocks: STONE:1,STONE:3,STONE:5,DIRT:1,DIRT,SAND,GRASS,DIRT:2,STATIONARY_WATER,HARD_CLAY,STAINED_CLAY,CLAY,SANDSTONE,SAND:1,AIR,STONE,GRAVEL,LONG_GRASS,LONG_GRASS:1,LONG_GRASS:2,DEAD_BUSH,YELLOW_FLOWER,RED_ROSE,BROWN_MUSHROOM,RED_MUSHROOM

# The maximum percentage of the BO3 that can be outside the SourceBlock.
# The BO3 won't be placed on a location with more blocks outside the SourceBlock than this percentage.
MaxPercentageOutsideSourceBlock: 0

# What to do when a block is about to be placed outside the SourceBlock? (dontPlace, placeAnyway)
OutsideSourceBlock: placeAnyway

#######################################################################
# +-----------------------------------------------------------------+ #
# |                              Blocks                             | #
# +-----------------------------------------------------------------+ #
#######################################################################

# All the blocks used in the BO3 are listed here. Possible blocks:
# Block(x,y,z,id[.data][,nbtfile.nbt) or B(x,y,z,id[.data][,nbtfile.nbt)
# RandomBlock(x,y,z,id[:data][,nbtfile.nbt],chance[,id[:data][,nbtfile.nbt],chance[,...]])
# So RandomBlock(0,0,0,CHEST,chest.nbt,50,CHEST,anotherchest.nbt,100) will spawn a chest at
# the BO3 origin, and give it a 50% chance to have the contents of chest.nbt, or, if that
# fails, a 100% percent chance to have the contents of anotherchest.nbt.

Block(-20,50,-5,LEAVES:3)
Block(-20,51,-6,LEAVES:3)
Block(-19,49,-5,LEAVES:3)
Block(-19,50,-8,LEAVES:3)
Block(-19,50,-6,LEAVES:3)
Block(-19,50,-3,LEAVES:3)
Block(-19,51,-7,LEAVES:3)
Block(-19,51,-6,LEAVES:3)
Block(-19,51,-5,LEAVES:3)
Block(-19,51,-4,LEAVES:3)
Block(-19,52,-6,LEAVES:3)
Block(-18,50,-6,LEAVES:3)
Block(-18,50,-4,LEAVES:3)
Block(-18,50,-2,LEAVES:3)
Block(-18,51,-8,LEAVES:3)
Block(-18,51,-7,LEAVES:3)
Block(-18,51,-6,17:15)
Block(-18,51,-5,LEAVES:3)
Block(-18,51,-4,LEAVES:3)
Block(-18,51,-3,LEAVES:3)
Block(-18,51,-1,LEAVES:3)
Block(-18,51,0,LEAVES:3)
Block(-18,52,-7,LEAVES:3)
Block(-18,52,-6,LEAVES:3)
Block(-18,52,-4,LEAVES:3)
Block(-17,50,-7,LEAVES:3)
Block(-17,50,-5,LEAVES:3)
Block(-17,50,0,LEAVES:3)
Block(-17,51,-7,LEAVES:3)
Block(-17,51,-6,LEAVES:3)
Block(-17,51,-5,LEAVES:3)
Block(-17,51,-4,LEAVES:3)
Block(-17,51,-3,LEAVES:3)
Block(-17,51,-2,LEAVES:3)
Block(-17,51,0,LEAVES:3)
Block(-17,51,1,LEAVES:3)
Block(-17,52,-5,17:15)
Block(-17,52,-4,LEAVES:3)
Block(-17,52,-3,LEAVES:3)
Block(-17,52,-1,LEAVES:3)
Block(-17,52,0,LEAVES:3)
Block(-17,53,-5,LEAVES:3)
Block(-17,53,-4,LEAVES:3)
Block(-16,50,-6,LEAVES:3)
Block(-16,50,-4,LEAVES:3)
Block(-16,51,-6,LEAVES:3)
Block(-16,51,-5,LEAVES:3)
Block(-16,51,-4,17:15)
Block(-16,51,-3,LEAVES:3)
Block(-16,51,-1,LEAVES:3)
Block(-16,51,0,17:15)
Block(-16,51,1,LEAVES:3)
Block(-16,51,2,LEAVES:3)
Block(-16,52,-5,LEAVES:3)
Block(-16,52,-4,LEAVES:3)
Block(-16,52,-1,LEAVES:3)
Block(-16,52,0,LEAVES:3)
Block(-16,52,1,LEAVES:3)
Block(-15,49,-4,LEAVES:3)
Block(-15,49,-3,LEAVES:3)
Block(-15,49,1,LEAVES:3)
Block(-15,49,8,LEAVES:3)
Block(-15,50,-6,LEAVES:3)
Block(-15,50,-4,17:15)
Block(-15,50,-2,LEAVES:3)
Block(-15,50,0,LEAVES:3)
Block(-15,50,2,LEAVES:3)
Block(-15,50,7,LEAVES:3)
Block(-15,51,-6,LEAVES:3)
Block(-15,51,-5,LEAVES:3)
Block(-15,51,-4,LEAVES:3)
Block(-15,51,-3,LEAVES:3)
Block(-15,51,-2,LEAVES:3)
Block(-15,51,-1,17:15)
Block(-15,51,0,LEAVES:3)
Block(-15,51,1,LEAVES:3)
Block(-15,52,-4,LEAVES:3)
Block(-15,52,-2,LEAVES:3)
Block(-15,52,-1,LEAVES:3)
Block(-15,53,-1,LEAVES:3)
Block(-14,49,-1,LEAVES:3)
Block(-14,49,6,LEAVES:3)
Block(-14,50,-5,LEAVES:3)
Block(-14,50,-4,17:15)
Block(-14,50,-3,17:15)
Block(-14,50,-2,17:15)
Block(-14,50,-1,LEAVES:3)
Block(-14,50,0,LEAVES:3)
Block(-14,50,1,LEAVES:3)
Block(-14,50,6,LEAVES:3)
Block(-14,50,7,LEAVES:3)
Block(-14,50,8,LEAVES:3)
Block(-14,51,-7,LEAVES:3)
Block(-14,51,-6,LEAVES:3)
Block(-14,51,-5,17:15)
Block(-14,51,-4,LEAVES:3)
Block(-14,51,-3,LEAVES:3)
Block(-14,51,-2,LEAVES:3)
Block(-14,51,-1,LEAVES:3)
Block(-14,51,0,LEAVES:3)
Block(-14,51,7,LEAVES:3)
Block(-14,52,-6,LEAVES:3)
Block(-14,52,-5,LEAVES:3)
Block(-14,52,-3,LEAVES:3)
Block(-13,48,4,LEAVES:3)
Block(-13,49,-4,LEAVES:3)
Block(-13,49,-3,17:15)
Block(-13,49,0,LEAVES:3)
Block(-13,49,5,LEAVES:3)
Block(-13,49,8,LEAVES:3)
Block(-13,50,-5,LEAVES:3)
Block(-13,50,-4,LEAVES:3)
Block(-13,50,-3,17:15)
Block(-13,50,-2,LEAVES:3)
Block(-13,50,-1,LEAVES:3)
Block(-13,50,0,LEAVES:3)
Block(-13,50,6,LEAVES:3)
Block(-13,50,7,LEAVES:3)
Block(-13,50,8,LEAVES:3)
Block(-13,50,9,LEAVES:3)
Block(-13,51,-6,LEAVES:3)
Block(-13,51,-5,LEAVES:3)
Block(-13,51,-4,LEAVES:3)
Block(-13,51,-3,LEAVES:3)
Block(-13,51,-1,LEAVES:3)
Block(-13,51,7,LEAVES:3)
Block(-13,51,8,LEAVES:3)
Block(-12,48,2,LEAVES:3)
Block(-12,49,-5,LEAVES:3)
Block(-12,49,-3,17:15)
Block(-12,49,-2,LEAVES:3)
Block(-12,49,2,LEAVES:3)
Block(-12,49,4,LEAVES:3)
Block(-12,49,5,LEAVES:3)
Block(-12,49,6,LEAVES:3)
Block(-12,50,-4,LEAVES:3)
Block(-12,50,-3,LEAVES:3)
Block(-12,50,-2,LEAVES:3)
Block(-12,50,-1,LEAVES:3)
Block(-12,50,5,LEAVES:3)
Block(-12,50,6,LEAVES:3)
Block(-12,50,7,17:15)
Block(-12,50,8,LEAVES:3)
Block(-12,51,-3,LEAVES:3)
Block(-12,51,7,LEAVES:3)
Block(-12,52,7,LEAVES:3)
Block(-11,34,-4,LEAVES:3)
Block(-11,35,-4,LEAVES:3)
Block(-11,48,4,LEAVES:3)
Block(-11,48,6,LEAVES:3)
Block(-11,48,8,LEAVES:3)
Block(-11,49,-3,17:15)
Block(-11,49,1,LEAVES:3)
Block(-11,49,2,LEAVES:3)
Block(-11,49,3,LEAVES:3)
Block(-11,49,4,LEAVES:3)
Block(-11,49,5,LEAVES:3)
Block(-11,49,6,17:15)
Block(-11,49,7,LEAVES:3)
Block(-11,49,8,LEAVES:3)
Block(-11,50,-3,LEAVES:3)
Block(-11,50,-2,LEAVES:3)
Block(-11,50,2,LEAVES:3)
Block(-11,50,4,LEAVES:3)
Block(-11,50,5,LEAVES:3)
Block(-11,50,6,LEAVES:3)
Block(-11,50,7,LEAVES:3)
Block(-11,51,-4,LEAVES:3)
Block(-11,51,-3,LEAVES:3)
Block(-11,51,-2,LEAVES:3)
Block(-11,51,5,LEAVES:3)
Block(-11,51,7,LEAVES:3)
Block(-11,52,-3,LEAVES:3)
Block(-10,34,-6,LEAVES:3)
Block(-10,35,-5,LEAVES:3)
Block(-10,35,-4,LEAVES:3)
Block(-10,35,-3,LEAVES:3)
Block(-10,36,-4,LEAVES:3)
Block(-10,48,1,LEAVES:3)
Block(-10,48,3,LEAVES:3)
Block(-10,48,4,LEAVES:3)
Block(-10,48,6,LEAVES:3)
Block(-10,48,19,LEAVES:3)
Block(-10,49,-8,LEAVES:3)
Block(-10,49,-6,LEAVES:3)
Block(-10,49,-3,17:15)
Block(-10,49,0,LEAVES:3)
Block(-10,49,1,LEAVES:3)
Block(-10,49,2,17:15)
Block(-10,49,4,LEAVES:3)
Block(-10,49,5,17:15)
Block(-10,49,6,LEAVES:3)
Block(-10,49,7,LEAVES:3)
Block(-10,49,18,LEAVES:3)
Block(-10,50,-9,LEAVES:3)
Block(-10,50,-6,LEAVES:3)
Block(-10,50,-3,LEAVES:3)
Block(-10,50,1,LEAVES:3)
Block(-10,50,2,LEAVES:3)
Block(-10,50,3,LEAVES:3)
Block(-10,50,5,LEAVES:3)
Block(-10,51,-8,LEAVES:3)
Block(-10,51,-4,LEAVES:3)
Block(-10,51,-3,LEAVES:3)
Block(-10,51,-2,LEAVES:3)
Block(-10,51,-1,LEAVES:3)
Block(-10,51,2,LEAVES:3)
Block(-10,52,-3,LEAVES:3)
Block(-10,52,-2,LEAVES:3)
Block(-9,33,-6,LEAVES:3)
Block(-9,34,-5,LEAVES:3)
Block(-9,34,-3,LEAVES:3)
Block(-9,35,-6,LEAVES:3)
Block(-9,35,-5,LEAVES:3)
Block(-9,35,-4,LEAVES:3)
Block(-9,35,-3,LEAVES:3)
Block(-9,36,-5,LEAVES:3)
Block(-9,36,-4,LEAVES:3)
Block(-9,47,5,LEAVES:3)
Block(-9,47,8,LEAVES:3)
Block(-9,48,-2,17:15)
Block(-9,48,2,LEAVES:3)
Block(-9,48,3,17:15)
Block(-9,48,4,17:15)
Block(-9,48,5,17:15)
Block(-9,48,7,LEAVES:3)
Block(-9,48,8,LEAVES:3)
Block(-9,48,13,LEAVES:3)
Block(-9,48,17,LEAVES:3)
Block(-9,49,-4,LEAVES:3)
Block(-9,49,1,LEAVES:3)
Block(-9,49,2,LEAVES:3)
Block(-9,49,3,LEAVES:3)
Block(-9,49,4,LEAVES:3)
Block(-9,49,5,17:15)
Block(-9,49,6,LEAVES:3)
Block(-9,49,7,LEAVES:3)
Block(-9,49,14,LEAVES:3)
Block(-9,49,17,LEAVES:3)
Block(-9,49,18,LEAVES:3)
Block(-9,49,19,LEAVES:3)
Block(-9,50,-8,LEAVES:3)
Block(-9,50,-7,LEAVES:3)
Block(-9,50,-6,LEAVES:3)
Block(-9,50,-5,LEAVES:3)
Block(-9,50,-3,LEAVES:3)
Block(-9,50,-1,LEAVES:3)
Block(-9,50,4,LEAVES:3)
Block(-9,50,5,LEAVES:3)
Block(-9,50,6,LEAVES:3)
Block(-9,50,18,LEAVES:3)
Block(-9,51,-9,LEAVES:3)
Block(-9,51,-8,LEAVES:3)
Block(-9,51,-7,LEAVES:3)
Block(-9,51,-6,LEAVES:3)
Block(-9,51,-4,LEAVES:3)
Block(-9,51,-3,17:15)
Block(-9,51,-2,LEAVES:3)
Block(-9,51,5,LEAVES:3)
Block(-9,52,-8,LEAVES:3)
Block(-9,52,-3,LEAVES:3)
Block(-9,53,-3,LEAVES:3)
Block(-8,33,-3,LEAVES:3)
Block(-8,34,-6,LEAVES:3)
Block(-8,34,-4,LEAVES:3)
Block(-8,35,-5,LEAVES:3)
Block(-8,35,-4,17:15)
Block(-8,35,-3,LEAVES:3)
Block(-8,35,-2,LEAVES:3)
Block(-8,36,-4,LEAVES:3)
Block(-8,36,-3,LEAVES:3)
Block(-8,45,-12,LEAVES:3)
Block(-8,46,-13,LEAVES:3)
Block(-8,47,5,17:15)
Block(-8,47,8,LEAVES:3)
Block(-8,48,-2,17:15)
Block(-8,48,4,LEAVES:3)
Block(-8,48,5,17:15)
Block(-8,48,6,17:15)
Block(-8,48,7,LEAVES:3)
Block(-8,48,8,LEAVES:3)
Block(-8,48,15,LEAVES:3)
Block(-8,48,16,LEAVES:3)
Block(-8,48,18,LEAVES:3)
Block(-8,48,19,LEAVES:3)
Block(-8,49,4,LEAVES:3)
Block(-8,49,5,LEAVES:3)
Block(-8,49,6,LEAVES:3)
Block(-8,49,7,LEAVES:3)
Block(-8,49,8,LEAVES:3)
Block(-8,49,13,LEAVES:3)
Block(-8,49,14,LEAVES:3)
Block(-8,49,15,LEAVES:3)
Block(-8,49,16,LEAVES:3)
Block(-8,49,17,LEAVES:3)
Block(-8,49,18,17:15)
Block(-8,49,19,LEAVES:3)
Block(-8,49,20,LEAVES:3)
Block(-8,50,-10,LEAVES:3)
Block(-8,50,-7,LEAVES:3)
Block(-8,50,-6,17:15)
Block(-8,50,-5,LEAVES:3)
Block(-8,50,-4,LEAVES:3)
Block(-8,50,-3,LEAVES:3)
Block(-8,50,5,LEAVES:3)
Block(-8,50,6,LEAVES:3)
Block(-8,50,7,LEAVES:3)
Block(-8,50,14,LEAVES:3)
Block(-8,50,18,LEAVES:3)
Block(-8,50,19,LEAVES:3)
Block(-8,51,-10,LEAVES:3)
Block(-8,51,-9,LEAVES:3)
Block(-8,51,-8,17:15)
Block(-8,51,-7,17:15)
Block(-8,51,-6,LEAVES:3)
Block(-8,51,-4,17:15)
Block(-8,51,-3,LEAVES:3)
Block(-8,52,-9,LEAVES:3)
Block(-8,52,-8,LEAVES:3)
Block(-8,52,-7,LEAVES:3)
Block(-8,52,-4,LEAVES:3)
Block(-8,52,-3,LEAVES:3)
Block(-8,53,-7,LEAVES:3)
Block(-7,32,-5,LEAVES:3)
Block(-7,34,-7,LEAVES:3)
Block(-7,34,-6,LEAVES:3)
Block(-7,34,-5,LEAVES:3)
Block(-7,34,-4,17:15)
Block(-7,34,-3,LEAVES:3)
Block(-7,34,-1,LEAVES:3)
Block(-7,35,-4,LEAVES:3)
Block(-7,35,-3,LEAVES:3)
Block(-7,35,-2,LEAVES:3)
Block(-7,44,-12,LEAVES:3)
Block(-7,45,-11,LEAVES:3)
Block(-7,46,-14,LEAVES:3)
Block(-7,46,-13,LEAVES:3)
Block(-7,46,-12,LEAVES:3)
Block(-7,46,4,17:15)
Block(-7,47,-13,LEAVES:3)
Block(-7,47,-1,17:15)
Block(-7,47,12,LEAVES:3)
Block(-7,47,19,LEAVES:3)
Block(-7,48,5,17:15)
Block(-7,48,6,LEAVES:3)
Block(-7,48,7,LEAVES:3)
Block(-7,48,13,LEAVES:3)
Block(-7,48,14,LEAVES:3)
Block(-7,48,17,LEAVES:3)
Block(-7,48,20,LEAVES:3)
Block(-7,49,-6,LEAVES:3)
Block(-7,49,-2,LEAVES:3)
Block(-7,49,4,LEAVES:3)
Block(-7,49,5,LEAVES:3)
Block(-7,49,6,17:15)
Block(-7,49,7,LEAVES:3)
Block(-7,49,13,LEAVES:3)
Block(-7,49,14,17:15)
Block(-7,49,15,LEAVES:3)
Block(-7,49,16,LEAVES:3)
Block(-7,49,17,LEAVES:3)
Block(-7,49,18,LEAVES:3)
Block(-7,49,19,LEAVES:3)
Block(-7,50,-6,LEAVES:3)
Block(-7,50,-5,17:15)
Block(-7,50,-4,17:15)
Block(-7,50,-3,LEAVES:3)
Block(-7,50,-2,LEAVES:3)
Block(-7,50,-1,LEAVES:3)
Block(-7,50,5,LEAVES:3)
Block(-7,50,6,LEAVES:3)
Block(-7,50,14,LEAVES:3)
Block(-7,50,16,LEAVES:3)
Block(-7,50,17,17:15)
Block(-7,51,-9,LEAVES:3)
Block(-7,51,-8,LEAVES:3)
Block(-7,51,-7,LEAVES:3)
Block(-7,51,-5,LEAVES:3)
Block(-7,51,-4,LEAVES:3)
Block(-7,51,-3,LEAVES:3)
Block(-7,51,-2,LEAVES:3)
Block(-7,51,6,LEAVES:3)
Block(-7,51,17,LEAVES:3)
Block(-7,52,-7,LEAVES:3)
Block(-7,52,-4,LEAVES:3)
Block(-7,54,2,LEAVES:3)
Block(-7,55,3,LEAVES:3)
Block(-6,-6,-1,17:15)
Block(-6,-6,1,17:15)
Block(-6,-5,-1,17:15)
Block(-6,-5,1,17:15)
Block(-6,-4,-1,17:15)
Block(-6,33,-6,LEAVES:3)
Block(-6,33,-2,LEAVES:3)
Block(-6,34,-8,LEAVES:3)
Block(-6,34,-7,LEAVES:3)
Block(-6,34,-6,17:15)
Block(-6,34,-5,LEAVES:3)
Block(-6,34,-4,LEAVES:3)
Block(-6,34,-3,17:15)
Block(-6,34,-2,LEAVES:3)
Block(-6,35,-7,LEAVES:3)
Block(-6,35,-6,LEAVES:3)
Block(-6,35,-5,LEAVES:3)
Block(-6,35,-4,LEAVES:3)
Block(-6,35,-3,LEAVES:3)
Block(-6,35,-2,LEAVES:3)
Block(-6,36,-3,LEAVES:3)
Block(-6,44,-10,LEAVES:3)
Block(-6,45,-14,LEAVES:3)
Block(-6,45,-12,LEAVES:3)
Block(-6,45,-11,LEAVES:3)
Block(-6,45,-10,LEAVES:3)
Block(-6,46,-15,LEAVES:3)
Block(-6,46,-14,LEAVES:3)
Block(-6,46,-13,17:15)
Block(-6,46,-12,LEAVES:3)
Block(-6,46,-11,LEAVES:3)
Block(-6,46,4,17:15)
Block(-6,47,-14,LEAVES:3)
Block(-6,47,-13,LEAVES:3)
Block(-6,47,-1,17:15)
Block(-6,47,4,17:15)
Block(-6,47,5,LEAVES:3)
Block(-6,47,8,LEAVES:3)
Block(-6,47,13,LEAVES:3)
Block(-6,47,15,LEAVES:3)
Block(-6,48,5,LEAVES:3)
Block(-6,48,6,17:15)
Block(-6,48,7,LEAVES:3)
Block(-6,48,8,LEAVES:3)
Block(-6,48,12,LEAVES:3)
Block(-6,48,13,LEAVES:3)
Block(-6,48,14,17:15)
Block(-6,48,15,17:15)
Block(-6,48,16,LEAVES:3)
Block(-6,48,18,LEAVES:3)
Block(-6,49,-5,17:15)
Block(-6,49,1,LEAVES:3)
Block(-6,49,6,LEAVES:3)
Block(-6,49,7,LEAVES:3)
Block(-6,49,13,LEAVES:3)
Block(-6,49,14,LEAVES:3)
Block(-6,49,15,LEAVES:3)
Block(-6,49,16,17:15)
Block(-6,49,17,LEAVES:3)
Block(-6,49,18,LEAVES:3)
Block(-6,49,19,LEAVES:3)
Block(-6,50,-8,LEAVES:3)
Block(-6,50,-5,17:15)
Block(-6,50,-4,LEAVES:3)
Block(-6,50,-3,LEAVES:3)
Block(-6,50,1,LEAVES:3)
Block(-6,50,15,LEAVES:3)
Block(-6,50,16,LEAVES:3)
Block(-6,50,17,LEAVES:3)
Block(-6,50,18,LEAVES:3)
Block(-6,51,-7,LEAVES:3)
Block(-6,51,-3,LEAVES:3)
Block(-6,51,-2,LEAVES:3)
Block(-6,51,-1,LEAVES:3)
Block(-6,51,17,LEAVES:3)
Block(-6,52,-2,LEAVES:3)
Block(-6,54,4,LEAVES:3)
Block(-6,55,2,LEAVES:3)
Block(-6,55,3,LEAVES:3)
Block(-6,55,4,LEAVES:3)
Block(-6,56,3,LEAVES:3)
Block(-5,-5,1,17:15)
Block(-5,-4,0,17:15)
Block(-5,-4,1,17:15)
Block(-5,-3,0,17:15)
Block(-5,-2,0,17:15)
Block(-5,33,-8,LEAVES:3)
Block(-5,33,-5,LEAVES:3)
Block(-5,33,-4,17:15)
Block(-5,33,-3,17:15)
Block(-5,33,-1,LEAVES:3)
Block(-5,34,-7,LEAVES:3)
Block(-5,34,-6,LEAVES:3)
Block(-5,34,-5,17:15)
Block(-5,34,-4,LEAVES:3)
Block(-5,34,-3,LEAVES:3)
Block(-5,34,-2,LEAVES:3)
Block(-5,34,-1,LEAVES:3)
Block(-5,35,-6,LEAVES:3)
Block(-5,35,-5,LEAVES:3)
Block(-5,35,-4,LEAVES:3)
Block(-5,35,-3,LEAVES:3)
Block(-5,35,-2,LEAVES:3)
Block(-5,36,-5,LEAVES:3)
Block(-5,44,-11,LEAVES:3)
Block(-5,45,-11,LEAVES:3)
Block(-5,45,-10,LEAVES:3)
Block(-5,45,-9,LEAVES:3)
Block(-5,45,3,17:15)
Block(-5,46,-15,LEAVES:3)
Block(-5,46,-13,LEAVES:3)
Block(-5,46,-12,17:15)
Block(-5,46,-11,LEAVES:3)
Block(-5,46,-10,LEAVES:3)
Block(-5,46,0,17:15)
Block(-5,47,-14,LEAVES:3)
Block(-5,47,-13,LEAVES:3)
Block(-5,47,-12,LEAVES:3)
Block(-5,47,4,17:15)
Block(-5,47,10,17:15)
Block(-5,47,11,17:15)
Block(-5,47,12,17:15)
Block(-5,47,13,17:15)
Block(-5,47,15,LEAVES:3)
Block(-5,48,-12,LEAVES:3)
Block(-5,48,4,17:15)
Block(-5,48,5,17:15)
Block(-5,48,6,LEAVES:3)
Block(-5,48,7,LEAVES:3)
Block(-5,48,11,LEAVES:3)
Block(-5,48,12,LEAVES:3)
Block(-5,48,13,17:15)
Block(-5,48,14,17:15)
Block(-5,48,19,LEAVES:3)
Block(-5,49,-4,17:15)
Block(-5,49,5,LEAVES:3)
Block(-5,49,12,LEAVES:3)
Block(-5,49,13,LEAVES:3)
Block(-5,49,14,LEAVES:3)
Block(-5,49,15,LEAVES:3)
Block(-5,49,16,LEAVES:3)
Block(-5,49,17,LEAVES:3)
Block(-5,49,18,LEAVES:3)
Block(-5,50,-2,LEAVES:3)
Block(-5,50,-1,LEAVES:3)
Block(-5,50,0,LEAVES:3)
Block(-5,50,1,LEAVES:3)
Block(-5,50,2,LEAVES:3)
Block(-5,50,14,LEAVES:3)
Block(-5,50,17,LEAVES:3)
Block(-5,51,-4,LEAVES:3)
Block(-5,51,-3,LEAVES:3)
Block(-5,51,-2,LEAVES:3)
Block(-5,51,-1,17:15)
Block(-5,51,0,LEAVES:3)
Block(-5,51,1,LEAVES:3)
Block(-5,52,-3,LEAVES:3)
Block(-5,52,-2,LEAVES:3)
Block(-5,52,-1,LEAVES:3)
Block(-5,52,0,LEAVES:3)
Block(-5,53,-1,LEAVES:3)
Block(-5,53,6,LEAVES:3)
Block(-5,54,1,LEAVES:3)
Block(-5,54,3,LEAVES:3)
Block(-5,54,5,LEAVES:3)
Block(-5,55,1,LEAVES:3)
Block(-5,55,2,LEAVES:3)
Block(-5,55,3,LEAVES:3)
Block(-5,55,4,LEAVES:3)
Block(-5,56,2,LEAVES:3)
Block(-5,56,3,LEAVES:3)
Block(-4,-6,-2,17:15)
Block(-4,-6,2,17:15)
Block(-4,-5,-2,17:15)
Block(-4,-5,2,17:15)
Block(-4,-4,-2,17:15)
Block(-4,-3,0,17:15)
Block(-4,-2,0,17:15)
Block(-4,-1,0,17:15)
Block(-4,32,-2,LEAVES:3)
Block(-4,32,-1,LEAVES:3)
Block(-4,33,-6,LEAVES:3)
Block(-4,33,-3,17:15)
Block(-4,33,-1,LEAVES:3)
Block(-4,34,-6,LEAVES:3)
Block(-4,34,-5,LEAVES:3)
Block(-4,34,-3,LEAVES:3)
Block(-4,34,-2,LEAVES:3)
Block(-4,35,-5,LEAVES:3)
Block(-4,35,-4,LEAVES:3)
Block(-4,44,-9,LEAVES:3)
Block(-4,45,-15,LEAVES:3)
Block(-4,45,-12,LEAVES:3)
Block(-4,45,-11,17:15)
Block(-4,45,-10,LEAVES:3)
Block(-4,45,-9,LEAVES:3)
Block(-4,45,1,17:15)
Block(-4,45,2,17:15)
Block(-4,46,-14,LEAVES:3)
Block(-4,46,-12,LEAVES:3)
Block(-4,46,-11,LEAVES:3)
Block(-4,46,1,17:15)
Block(-4,46,7,17:15)
Block(-4,46,8,17:15)
Block(-4,47,-12,LEAVES:3)
Block(-4,47,7,LEAVES:3)
Block(-4,47,9,17:15)
Block(-4,47,12,LEAVES:3)
Block(-4,48,-4,17:15)
Block(-4,48,4,17:15)
Block(-4,48,5,17:15)
Block(-4,48,6,LEAVES:3)
Block(-4,48,10,LEAVES:3)
Block(-4,48,12,LEAVES:3)
Block(-4,48,13,LEAVES:3)
Block(-4,48,14,17:15)
Block(-4,48,15,LEAVES:3)
Block(-4,48,18,LEAVES:3)
Block(-4,49,-1,LEAVES:3)
Block(-4,49,5,LEAVES:3)
Block(-4,49,6,17:15)
Block(-4,49,7,LEAVES:3)
Block(-4,49,8,LEAVES:3)
Block(-4,49,9,LEAVES:3)
Block(-4,49,14,LEAVES:3)
Block(-4,49,15,LEAVES:3)
Block(-4,49,17,LEAVES:3)
Block(-4,50,-4,LEAVES:3)
Block(-4,50,0,LEAVES:3)
Block(-4,50,1,17:15)
Block(-4,50,2,LEAVES:3)
Block(-4,50,5,LEAVES:3)
Block(-4,50,6,LEAVES:3)
Block(-4,50,15,LEAVES:3)
Block(-4,51,-14,LEAVES:3)
Block(-4,51,-3,LEAVES:3)
Block(-4,51,-2,LEAVES:3)
Block(-4,51,-1,LEAVES:3)
Block(-4,51,0,17:15)
Block(-4,51,1,LEAVES:3)
Block(-4,52,0,LEAVES:3)
Block(-4,52,1,LEAVES:3)
Block(-4,53,5,LEAVES:3)
Block(-4,54,2,LEAVES:3)
Block(-4,54,5,LEAVES:3)
Block(-4,54,6,LEAVES:3)
Block(-4,55,2,LEAVES:3)
Block(-4,55,3,17:15)
Block(-4,55,4,LEAVES:3)
Block(-4,55,5,LEAVES:3)
Block(-4,56,3,LEAVES:3)
Block(-4,56,4,LEAVES:3)
Block(-4,57,3,LEAVES:3)
Block(-3,-6,-1,17:15)
Block(-3,-5,-1,17:15)
Block(-3,-5,2,17:15)
Block(-3,-4,-1,17:15)
Block(-3,-4,2,17:15)
Block(-3,-3,-1,17:15)
Block(-3,-3,2,17:15)
Block(-3,-2,-1,17:15)
Block(-3,-1,0,17:15)
Block(-3,0,0,17:15)
Block(-3,1,0,17:15)
Block(-3,32,-3,LEAVES:3)
Block(-3,32,0,LEAVES:3)
Block(-3,33,-3,LEAVES:3)
Block(-3,33,-2,17:15)
Block(-3,33,-1,LEAVES:3)
Block(-3,34,-7,LEAVES:3)
Block(-3,34,-6,LEAVES:3)
Block(-3,34,-5,LEAVES:3)
Block(-3,34,-4,LEAVES:3)
Block(-3,34,-3,17:15)
Block(-3,34,-2,LEAVES:3)
Block(-3,35,-6,LEAVES:3)
Block(-3,35,-5,LEAVES:3)
Block(-3,35,-3,LEAVES:3)
Block(-3,36,-6,LEAVES:3)
Block(-3,44,-12,LEAVES:3)
Block(-3,44,-10,17:15)
Block(-3,44,-9,17:15)
Block(-3,44,-8,17:15)
Block(-3,44,-7,17:15)
Block(-3,44,1,17:15)
Block(-3,45,-16,LEAVES:3)
Block(-3,45,-11,17:15)
Block(-3,45,-10,17:15)
Block(-3,45,-9,LEAVES:3)
Block(-3,45,-8,LEAVES:3)
Block(-3,45,1,17:15)
Block(-3,45,5,17:15)
Block(-3,46,-15,LEAVES:3)
Block(-3,46,-14,LEAVES:3)
Block(-3,46,-13,LEAVES:3)
Block(-3,46,-12,LEAVES:3)
Block(-3,46,-11,LEAVES:3)
Block(-3,46,-10,LEAVES:3)
Block(-3,46,-9,LEAVES:3)
Block(-3,46,6,17:15)
Block(-3,47,-14,LEAVES:3)
Block(-3,47,-11,LEAVES:3)
Block(-3,47,14,LEAVES:3)
Block(-3,48,-3,17:15)
Block(-3,48,3,17:15)
Block(-3,48,4,17:15)
Block(-3,48,5,LEAVES:3)
Block(-3,48,6,LEAVES:3)
Block(-3,48,7,LEAVES:3)
Block(-3,48,8,LEAVES:3)
Block(-3,48,12,LEAVES:3)
Block(-3,48,13,LEAVES:3)
Block(-3,48,14,LEAVES:3)
Block(-3,49,2,17:15)
Block(-3,49,5,LEAVES:3)
Block(-3,49,6,LEAVES:3)
Block(-3,49,7,17:15)
Block(-3,49,8,LEAVES:3)
Block(-3,49,9,LEAVES:3)
Block(-3,49,10,LEAVES:3)
Block(-3,49,13,LEAVES:3)
Block(-3,49,14,LEAVES:3)
Block(-3,49,15,17:15)
Block(-3,49,16,LEAVES:3)
Block(-3,49,18,LEAVES:3)
Block(-3,50,-15,LEAVES:3)
Block(-3,50,-12,LEAVES:3)
Block(-3,50,-1,LEAVES:3)
Block(-3,50,0,LEAVES:3)
Block(-3,50,1,17:15)
Block(-3,50,2,17:15)
Block(-3,50,6,LEAVES:3)
Block(-3,50,7,LEAVES:3)
Block(-3,50,8,LEAVES:3)
Block(-3,50,9,LEAVES:3)
Block(-3,50,15,LEAVES:3)
Block(-3,50,16,LEAVES:3)
Block(-3,50,17,LEAVES:3)
Block(-3,51,-15,LEAVES:3)
Block(-3,51,-14,LEAVES:3)
Block(-3,51,-13,LEAVES:3)
Block(-3,51,1,LEAVES:3)
Block(-3,51,7,LEAVES:3)
Block(-3,51,15,LEAVES:3)
Block(-3,52,-14,LEAVES:3)
Block(-3,53,1,LEAVES:3)
Block(-3,53,3,LEAVES:3)
Block(-3,53,7,LEAVES:3)
Block(-3,54,1,LEAVES:3)
Block(-3,54,2,LEAVES:3)
Block(-3,54,3,17:15)
Block(-3,54,4,LEAVES:3)
Block(-3,54,5,LEAVES:3)
Block(-3,54,6,LEAVES:3)
Block(-3,54,7,LEAVES:3)
Block(-3,55,2,LEAVES:3)
Block(-3,55,3,LEAVES:3)
Block(-3,55,4,LEAVES:3)
Block(-3,55,5,LEAVES:3)
Block(-3,55,6,LEAVES:3)
Block(-3,56,3,LEAVES:3)
Block(-3,56,5,LEAVES:3)
Block(-2,-6,-3,17:15)
Block(-2,-6,1,17:15)
Block(-2,-6,6,17:15)
Block(-2,-5,-3,17:15)
Block(-2,-5,-2,17:15)
Block(-2,-5,-1,17:15)
Block(-2,-5,1,17:15)
Block(-2,-5,6,17:15)
Block(-2,-4,-3,17:15)
Block(-2,-4,-2,17:15)
Block(-2,-4,-1,17:15)
Block(-2,-4,1,17:15)
Block(-2,-4,2,17:15)
Block(-2,-3,-3,17:15)
Block(-2,-3,-2,17:15)
Block(-2,-3,-1,17:15)
Block(-2,-3,2,17:15)
Block(-2,-2,-2,17:15)
Block(-2,-2,-1,17:15)
Block(-2,-2,2,17:15)
Block(-2,-1,-2,17:15)
Block(-2,-1,-1,17:15)
Block(-2,-1,2,17:15)
Block(-2,0,-1,17:15)
Block(-2,0,0,17:15)
Block(-2,0,2,17:15)
Block(-2,1,-1,17:15)
Block(-2,1,0,17:15)
Block(-2,2,-1,17:15)
Block(-2,2,0,17:15)
Block(-2,3,0,17:15)
Block(-2,4,0,17:15)
Block(-2,5,0,17:15)
Block(-2,6,0,17:15)
Block(-2,7,0,17:15)
Block(-2,32,-4,LEAVES:3)
Block(-2,32,-1,17:15)
Block(-2,33,-2,LEAVES:3)
Block(-2,33,-1,17:15)
Block(-2,34,-8,LEAVES:3)
Block(-2,34,-6,LEAVES:3)
Block(-2,34,-5,17:15)
Block(-2,34,-4,17:15)
Block(-2,34,-3,LEAVES:3)
Block(-2,35,-8,LEAVES:3)
Block(-2,35,-7,LEAVES:3)
Block(-2,35,-6,17:15)
Block(-2,35,-5,LEAVES:3)
Block(-2,35,-4,LEAVES:3)
Block(-2,35,-3,LEAVES:3)
Block(-2,36,-7,LEAVES:3)
Block(-2,36,-6,LEAVES:3)
Block(-2,37,-6,LEAVES:3)
Block(-2,42,2,17:15)
Block(-2,43,-5,17:15)
Block(-2,43,-4,17:15)
Block(-2,43,2,17:15)
Block(-2,44,-12,LEAVES:3)
Block(-2,44,-10,LEAVES:3)
Block(-2,44,-6,17:15)
Block(-2,44,2,17:15)
Block(-2,44,3,17:15)
Block(-2,45,-15,LEAVES:3)
Block(-2,45,-13,LEAVES:3)
Block(-2,45,-12,17:15)
Block(-2,45,-11,17:15)
Block(-2,45,-10,LEAVES:3)
Block(-2,45,-9,LEAVES:3)
Block(-2,45,3,17:15)
Block(-2,45,4,17:15)
Block(-2,46,-16,LEAVES:3)
Block(-2,46,-15,LEAVES:3)
Block(-2,46,-14,LEAVES:3)
Block(-2,46,-13,17:15)
Block(-2,46,-12,LEAVES:3)
Block(-2,46,-11,LEAVES:3)
Block(-2,46,-10,LEAVES:3)
Block(-2,47,-15,LEAVES:3)
Block(-2,47,-14,LEAVES:3)
Block(-2,47,-13,LEAVES:3)
Block(-2,47,-12,LEAVES:3)
Block(-2,47,-2,17:15)
Block(-2,47,5,LEAVES:3)
Block(-2,47,13,LEAVES:3)
Block(-2,48,-14,LEAVES:3)
Block(-2,48,4,17:15)
Block(-2,48,5,LEAVES:3)
Block(-2,48,9,LEAVES:3)
Block(-2,48,13,LEAVES:3)
Block(-2,48,14,LEAVES:3)
Block(-2,48,15,LEAVES:3)
Block(-2,48,17,LEAVES:3)
Block(-2,49,-13,LEAVES:3)
Block(-2,49,-2,LEAVES:3)
Block(-2,49,1,LEAVES:3)
Block(-2,49,7,LEAVES:3)
Block(-2,49,8,LEAVES:3)
Block(-2,49,9,LEAVES:3)
Block(-2,49,14,LEAVES:3)
Block(-2,49,15,LEAVES:3)
Block(-2,49,16,17:15)
Block(-2,49,17,LEAVES:3)
Block(-2,49,18,LEAVES:3)
Block(-2,50,-17,LEAVES:3)
Block(-2,50,-14,LEAVES:3)
Block(-2,50,-12,LEAVES:3)
Block(-2,50,-11,LEAVES:3)
Block(-2,50,-2,LEAVES:3)
Block(-2,50,-1,LEAVES:3)
Block(-2,50,0,17:15)
Block(-2,50,1,LEAVES:3)
Block(-2,50,8,LEAVES:3)
Block(-2,50,16,LEAVES:3)
Block(-2,50,17,LEAVES:3)
Block(-2,51,-16,LEAVES:3)
Block(-2,51,-15,LEAVES:3)
Block(-2,51,-14,LEAVES:3)
Block(-2,51,-13,17:15)
Block(-2,51,-12,LEAVES:3)
Block(-2,51,-1,LEAVES:3)
Block(-2,51,0,LEAVES:3)
Block(-2,52,-15,LEAVES:3)
Block(-2,52,-14,LEAVES:3)
Block(-2,52,-13,LEAVES:3)
Block(-2,53,-14,LEAVES:3)
Block(-2,53,2,LEAVES:3)
Block(-2,53,5,LEAVES:3)
Block(-2,53,8,LEAVES:3)
Block(-2,54,3,LEAVES:3)
Block(-2,54,4,17:15)
Block(-2,54,5,17:15)
Block(-2,54,6,LEAVES:3)
Block(-2,54,7,LEAVES:3)
Block(-2,54,8,LEAVES:3)
Block(-2,55,3,LEAVES:3)
Block(-2,55,4,LEAVES:3)
Block(-2,55,5,LEAVES:3)
Block(-2,55,7,LEAVES:3)
Block(-2,56,4,LEAVES:3)
Block(-1,-6,5,17:15)
Block(-1,-5,5,17:15)
Block(-1,-4,3,17:15)
Block(-1,-4,5,17:15)
Block(-1,-3,1,17:15)
Block(-1,-3,3,17:15)
Block(-1,-3,5,17:15)
Block(-1,-2,0,17:15)
Block(-1,-2,1,17:15)
Block(-1,-2,3,17:15)
Block(-1,-1,-1,17:15)
Block(-1,-1,0,17:15)
Block(-1,-1,1,17:15)
Block(-1,0,-1,17:15)
Block(-1,0,1,17:15)
Block(-1,1,-1,17:15)
Block(-1,1,0,17:15)
Block(-1,1,1,17:15)
Block(-1,2,-1,17:15)
Block(-1,2,0,17:15)
Block(-1,2,1,17:15)
Block(-1,3,-1,17:15)
Block(-1,3,0,17:15)
Block(-1,3,1,17:15)
Block(-1,4,-1,17:15)
Block(-1,4,0,17:15)
Block(-1,4,1,17:15)
Block(-1,5,-1,17:15)
Block(-1,5,0,17:15)
Block(-1,5,1,17:15)
Block(-1,6,-1,17:15)
Block(-1,6,0,17:15)
Block(-1,6,1,17:15)
Block(-1,7,-1,17:15)
Block(-1,7,0,17:15)
Block(-1,7,1,17:15)
Block(-1,8,-1,17:15)
Block(-1,8,0,17:15)
Block(-1,8,1,17:15)
Block(-1,9,-1,17:15)
Block(-1,9,0,17:15)
Block(-1,9,1,17:15)
Block(-1,10,-1,17:15)
Block(-1,10,0,17:15)
Block(-1,10,1,17:15)
Block(-1,11,-1,17:15)
Block(-1,11,0,17:15)
Block(-1,11,1,17:15)
Block(-1,12,-1,17:15)
Block(-1,12,0,17:15)
Block(-1,12,1,17:15)
Block(-1,13,-1,17:15)
Block(-1,13,0,17:15)
Block(-1,13,1,17:15)
Block(-1,14,-1,17:15)
Block(-1,14,0,17:15)
Block(-1,14,1,17:15)
Block(-1,15,0,17:15)
Block(-1,15,1,17:15)
Block(-1,16,0,17:15)
Block(-1,16,1,17:15)
Block(-1,17,0,17:15)
Block(-1,17,1,17:15)
Block(-1,18,0,17:15)
Block(-1,18,1,17:15)
Block(-1,19,0,17:15)
Block(-1,19,1,17:15)
Block(-1,20,0,17:15)
Block(-1,20,1,17:15)
Block(-1,21,0,17:15)
Block(-1,21,1,17:15)
Block(-1,22,0,17:15)
Block(-1,22,1,17:15)
Block(-1,23,0,17:15)
Block(-1,23,1,17:15)
Block(-1,24,0,17:15)
Block(-1,24,1,17:15)
Block(-1,25,0,17:15)
Block(-1,25,1,17:15)
Block(-1,26,0,17:15)
Block(-1,26,1,17:15)
Block(-1,27,1,17:15)
Block(-1,28,1,17:15)
Block(-1,29,1,17:15)
Block(-1,30,1,17:15)
Block(-1,31,0,17:15)
Block(-1,31,1,17:15)
Block(-1,32,-1,17:15)
Block(-1,32,0,17:15)
Block(-1,32,1,17:15)
Block(-1,33,-5,LEAVES:3)
Block(-1,33,-4,LEAVES:3)
Block(-1,33,-2,LEAVES:3)
Block(-1,33,-1,LEAVES:3)
Block(-1,33,1,17:15)
Block(-1,34,-9,LEAVES:3)
Block(-1,34,-5,LEAVES:3)
Block(-1,34,-4,LEAVES:3)
Block(-1,34,-3,LEAVES:3)
Block(-1,34,1,17:15)
Block(-1,35,-9,LEAVES:3)
Block(-1,35,-8,LEAVES:3)
Block(-1,35,-7,17:15)
Block(-1,35,-6,LEAVES:3)
Block(-1,35,-4,LEAVES:3)
Block(-1,35,1,17:15)
Block(-1,36,-8,LEAVES:3)
Block(-1,36,-7,LEAVES:3)
Block(-1,36,1,17:15)
Block(-1,37,1,17:15)
Block(-1,38,1,17:15)
Block(-1,39,1,17:15)
Block(-1,40,1,17:15)
Block(-1,40,2,17:15)
Block(-1,41,1,17:15)
Block(-1,41,2,17:15)
Block(-1,42,1,17:15)
Block(-1,42,2,17:15)
Block(-1,43,-3,17:15)
Block(-1,43,1,17:15)
Block(-1,44,-16,LEAVES:3)
Block(-1,44,-9,LEAVES:3)
Block(-1,45,-17,LEAVES:3)
Block(-1,45,-14,LEAVES:3)
Block(-1,45,-11,LEAVES:3)
Block(-1,45,-10,LEAVES:3)
Block(-1,46,-16,LEAVES:3)
Block(-1,46,-15,LEAVES:3)
Block(-1,46,-14,LEAVES:3)
Block(-1,46,-13,LEAVES:3)
Block(-1,46,-12,LEAVES:3)
Block(-1,46,-11,17:15)
Block(-1,46,-10,LEAVES:3)
Block(-1,46,-1,17:15)
Block(-1,47,-14,17:15)
Block(-1,47,-13,LEAVES:3)
Block(-1,47,-11,LEAVES:3)
Block(-1,47,-1,17:15)
Block(-1,47,15,LEAVES:3)
Block(-1,48,-14,LEAVES:3)
Block(-1,48,-13,LEAVES:3)
Block(-1,48,7,LEAVES:3)
Block(-1,48,12,17:15)
Block(-1,48,14,LEAVES:3)
Block(-1,49,-12,LEAVES:3)
Block(-1,49,-8,LEAVES:3)
Block(-1,49,4,17:15)
Block(-1,49,8,LEAVES:3)
Block(-1,49,15,LEAVES:3)
Block(-1,49,16,LEAVES:3)
Block(-1,49,17,LEAVES:3)
Block(-1,50,-15,LEAVES:3)
Block(-1,50,-12,17:15)
Block(-1,50,-11,LEAVES:3)
Block(-1,50,-10,LEAVES:3)
Block(-1,50,-1,LEAVES:3)
Block(-1,50,0,LEAVES:3)
Block(-1,50,16,LEAVES:3)
Block(-1,51,-16,LEAVES:3)
Block(-1,51,-15,LEAVES:3)
Block(-1,51,-14,LEAVES:3)
Block(-1,51,-13,LEAVES:3)
Block(-1,51,-12,LEAVES:3)
Block(-1,51,-1,LEAVES:3)
Block(-1,51,0,17:15)
Block(-1,51,1,LEAVES:3)
Block(-1,51,2,LEAVES:3)
Block(-1,52,-14,LEAVES:3)
Block(-1,52,-13,LEAVES:3)
Block(-1,52,0,LEAVES:3)
Block(-1,52,1,LEAVES:3)
Block(-1,53,0,LEAVES:3)
Block(-1,53,5,17:15)
Block(-1,53,7,LEAVES:3)
Block(-1,54,2,LEAVES:3)
Block(-1,54,3,LEAVES:3)
Block(-1,54,4,LEAVES:3)
Block(-1,54,5,LEAVES:3)
Block(-1,54,7,17:15)
Block(-1,54,8,LEAVES:3)
Block(-1,54,9,LEAVES:3)
Block(-1,55,3,LEAVES:3)
Block(-1,55,4,LEAVES:3)
Block(-1,55,6,LEAVES:3)
Block(-1,55,7,LEAVES:3)
Block(-1,55,8,LEAVES:3)
Block(-1,56,7,LEAVES:3)
Block(0,-6,-3,17:15)
Block(0,-6,0,17:15)
Block(0,-5,-3,17:15)
Block(0,-5,0,17:15)
Block(0,-4,-3,17:15)
Block(0,-4,-2,17:15)
Block(0,-4,4,17:15)
Block(0,-3,-3,17:15)
Block(0,-3,-2,17:15)
Block(0,-3,1,17:15)
Block(0,-3,3,17:15)
Block(0,-3,4,17:15)
Block(0,-2,-2,17:15)
Block(0,-2,1,17:15)
Block(0,-2,3,17:15)
Block(0,-2,4,17:15)
Block(0,-1,-2,17:15)
Block(0,-1,1,17:15)
Block(0,-1,2,17:15)
Block(0,-1,3,17:15)
Block(0,0,-2,17:15)
Block(0,0,-1,17:15)
Block(0,0,0,17:15)
Block(0,0,1,17:15)
Block(0,0,2,17:15)
Block(0,0,3,17:15)
Block(0,1,-2,17:15)
Block(0,1,-1,17:15)
Block(0,1,1,17:15)
Block(0,1,2,17:15)
Block(0,2,-2,17:15)
Block(0,2,-1,17:15)
Block(0,2,0,17:15)
Block(0,2,1,17:15)
Block(0,2,2,17:15)
Block(0,3,-2,17:15)
Block(0,3,-1,17:15)
Block(0,3,0,17:15)
Block(0,3,1,17:15)
Block(0,3,2,17:15)
Block(0,4,-2,17:15)
Block(0,4,-1,17:15)
Block(0,4,0,17:15)
Block(0,4,1,17:15)
Block(0,4,2,17:15)
Block(0,5,-2,17:15)
Block(0,5,-1,17:15)
Block(0,5,0,17:15)
Block(0,5,1,17:15)
Block(0,5,2,17:15)
Block(0,6,-2,17:15)
Block(0,6,-1,17:15)
Block(0,6,0,17:15)
Block(0,6,1,17:15)
Block(0,6,2,17:15)
Block(0,7,-2,17:15)
Block(0,7,-1,17:15)
Block(0,7,0,17:15)
Block(0,7,1,17:15)
Block(0,7,2,17:15)
Block(0,8,-2,17:15)
Block(0,8,-1,17:15)
Block(0,8,0,17:15)
Block(0,8,1,17:15)
Block(0,8,2,17:15)
Block(0,9,-2,17:15)
Block(0,9,-1,17:15)
Block(0,9,0,17:15)
Block(0,9,1,17:15)
Block(0,9,2,17:15)
Block(0,10,-1,17:15)
Block(0,10,0,17:15)
Block(0,10,1,17:15)
Block(0,10,2,17:15)
Block(0,11,-1,17:15)
Block(0,11,0,17:15)
Block(0,11,1,17:15)
Block(0,11,2,17:15)
Block(0,12,-1,17:15)
Block(0,12,0,17:15)
Block(0,12,1,17:15)
Block(0,12,2,17:15)
Block(0,13,-1,17:15)
Block(0,13,0,17:15)
Block(0,13,1,17:15)
Block(0,13,2,17:15)
Block(0,14,-1,17:15)
Block(0,14,0,17:15)
Block(0,14,1,17:15)
Block(0,14,2,17:15)
Block(0,15,-1,17:15)
Block(0,15,0,17:15)
Block(0,15,1,17:15)
Block(0,15,2,17:15)
Block(0,16,-1,17:15)
Block(0,16,0,17:15)
Block(0,16,1,17:15)
Block(0,16,2,17:15)
Block(0,17,-1,17:15)
Block(0,17,0,17:15)
Block(0,17,1,17:15)
Block(0,17,2,17:15)
Block(0,18,-1,17:15)
Block(0,18,0,17:15)
Block(0,18,1,17:15)
Block(0,18,2,17:15)
Block(0,19,-1,17:15)
Block(0,19,0,17:15)
Block(0,19,1,17:15)
Block(0,19,2,17:15)
Block(0,20,-1,17:15)
Block(0,20,0,17:15)
Block(0,20,1,17:15)
Block(0,20,2,17:15)
Block(0,21,-1,17:15)
Block(0,21,0,17:15)
Block(0,21,1,17:15)
Block(0,21,2,17:15)
Block(0,22,-1,17:15)
Block(0,22,0,17:15)
Block(0,22,1,17:15)
Block(0,22,2,17:15)
Block(0,23,-1,17:15)
Block(0,23,0,17:15)
Block(0,23,1,17:15)
Block(0,23,2,17:15)
Block(0,24,-1,17:15)
Block(0,24,0,17:15)
Block(0,24,1,17:15)
Block(0,24,2,17:15)
Block(0,25,0,17:15)
Block(0,25,1,17:15)
Block(0,25,2,17:15)
Block(0,26,0,17:15)
Block(0,26,1,17:15)
Block(0,26,2,17:15)
Block(0,27,0,17:15)
Block(0,27,1,17:15)
Block(0,27,2,17:15)
Block(0,28,0,17:15)
Block(0,28,1,17:15)
Block(0,28,2,17:15)
Block(0,29,0,17:15)
Block(0,29,1,17:15)
Block(0,29,2,17:15)
Block(0,30,0,17:15)
Block(0,30,1,17:15)
Block(0,30,2,17:15)
Block(0,31,0,17:15)
Block(0,31,1,17:15)
Block(0,31,2,17:15)
Block(0,32,-2,LEAVES:3)
Block(0,32,-1,LEAVES:3)
Block(0,32,0,LEAVES:3)
Block(0,32,1,17:15)
Block(0,32,2,17:15)
Block(0,33,-6,LEAVES:3)
Block(0,33,-3,LEAVES:3)
Block(0,33,-2,LEAVES:3)
Block(0,33,-1,LEAVES:3)
Block(0,33,0,LEAVES:3)
Block(0,33,1,17:15)
Block(0,33,2,17:15)
Block(0,34,-8,LEAVES:3)
Block(0,34,-6,LEAVES:3)
Block(0,34,-4,LEAVES:3)
Block(0,34,-2,LEAVES:3)
Block(0,34,-1,LEAVES:3)
Block(0,34,1,17:15)
Block(0,34,2,17:15)
Block(0,35,-8,LEAVES:3)
Block(0,35,-7,LEAVES:3)
Block(0,35,-1,LEAVES:3)
Block(0,35,1,17:15)
Block(0,35,2,17:15)
Block(0,36,1,17:15)
Block(0,36,2,17:15)
Block(0,37,1,17:15)
Block(0,37,2,17:15)
Block(0,38,1,17:15)
Block(0,38,2,17:15)
Block(0,39,1,17:15)
Block(0,39,2,17:15)
Block(0,40,0,17:15)
Block(0,40,1,17:15)
Block(0,41,-1,17:15)
Block(0,41,0,17:15)
Block(0,41,1,17:15)
Block(0,42,-2,17:15)
Block(0,42,-1,17:15)
Block(0,42,1,17:15)
Block(0,43,1,17:15)
Block(0,44,1,17:15)
Block(0,45,-16,LEAVES:3)
Block(0,45,-15,LEAVES:3)
Block(0,45,-13,LEAVES:3)
Block(0,45,-12,LEAVES:3)
Block(0,45,0,17:15)
Block(0,45,1,17:15)
Block(0,46,-17,LEAVES:3)
Block(0,46,-16,LEAVES:3)
Block(0,46,-15,17:15)
Block(0,46,-14,LEAVES:3)
Block(0,46,-13,LEAVES:3)
Block(0,46,-12,LEAVES:3)
Block(0,46,-11,LEAVES:3)
Block(0,46,-10,LEAVES:3)
Block(0,46,-4,17:15)
Block(0,46,0,17:15)
Block(0,47,-16,LEAVES:3)
Block(0,47,-15,LEAVES:3)
Block(0,47,-11,LEAVES:3)
Block(0,47,-5,LEAVES:3)
Block(0,47,-4,17:15)
Block(0,47,9,17:15)
Block(0,47,10,17:15)
Block(0,48,-6,LEAVES:3)
Block(0,48,11,17:15)
Block(0,48,15,LEAVES:3)
Block(0,49,-9,LEAVES:3)
Block(0,49,-8,LEAVES:3)
Block(0,49,-7,LEAVES:3)
Block(0,49,-2,LEAVES:3)
Block(0,49,9,LEAVES:3)
Block(0,49,10,LEAVES:3)
Block(0,49,11,17:15)
Block(0,49,14,LEAVES:3)
Block(0,49,16,LEAVES:3)
Block(0,50,-13,LEAVES:3)
Block(0,50,-12,LEAVES:3)
Block(0,50,-11,17:15)
Block(0,50,-10,LEAVES:3)
Block(0,50,-9,LEAVES:3)
Block(0,50,-8,LEAVES:3)
Block(0,50,-1,LEAVES:3)
Block(0,50,2,LEAVES:3)
Block(0,50,5,17:15)
Block(0,50,13,LEAVES:3)
Block(0,51,-15,LEAVES:3)
Block(0,51,-11,LEAVES:3)
Block(0,51,-10,LEAVES:3)
Block(0,51,-2,LEAVES:3)
Block(0,51,-1,LEAVES:3)
Block(0,51,0,17:15)
Block(0,51,1,LEAVES:3)
Block(0,52,-1,LEAVES:3)
Block(0,52,0,LEAVES:3)
Block(0,52,5,17:15)
Block(0,53,2,LEAVES:3)
Block(0,53,4,LEAVES:3)
Block(0,53,5,17:15)
Block(0,53,9,LEAVES:3)
Block(0,54,3,LEAVES:3)
Block(0,54,4,LEAVES:3)
Block(0,54,5,LEAVES:3)
Block(0,54,6,17:15)
Block(0,54,7,LEAVES:3)
Block(0,54,8,LEAVES:3)
Block(0,55,5,LEAVES:3)
Block(0,55,6,LEAVES:3)
Block(0,55,7,LEAVES:3)
Block(1,-6,-5,17:15)
Block(1,-6,-4,17:15)
Block(1,-6,-3,17:15)
Block(1,-6,2,17:15)
Block(1,-5,-4,17:15)
Block(1,-5,-3,17:15)
Block(1,-5,1,17:15)
Block(1,-5,2,17:15)
Block(1,-5,4,17:15)
Block(1,-4,-4,17:15)
Block(1,-4,-3,17:15)
Block(1,-4,-1,17:15)
Block(1,-4,0,17:15)
Block(1,-4,1,17:15)
Block(1,-4,2,17:15)
Block(1,-4,4,17:15)
Block(1,-3,-3,17:15)
Block(1,-3,-2,17:15)
Block(1,-3,-1,17:15)
Block(1,-3,2,17:15)
Block(1,-3,4,17:15)
Block(1,-2,-3,17:15)
Block(1,-2,-2,17:15)
Block(1,-1,-2,17:15)
Block(1,0,-2,17:15)
Block(1,0,0,17:15)
Block(1,0,1,17:15)
Block(1,1,-1,17:15)
Block(1,1,0,17:15)
Block(1,1,1,17:15)
Block(1,2,-1,17:15)
Block(1,2,0,17:15)
Block(1,2,1,17:15)
Block(1,3,-1,17:15)
Block(1,3,0,17:15)
Block(1,3,1,17:15)
Block(1,4,-1,17:15)
Block(1,4,0,17:15)
Block(1,4,1,17:15)
Block(1,5,-1,17:15)
Block(1,5,0,17:15)
Block(1,5,1,17:15)
Block(1,6,-1,17:15)
Block(1,6,0,17:15)
Block(1,6,1,17:15)
Block(1,7,-1,17:15)
Block(1,7,0,17:15)
Block(1,7,1,17:15)
Block(1,8,-1,17:15)
Block(1,8,0,17:15)
Block(1,8,1,17:15)
Block(1,9,-1,17:15)
Block(1,9,0,17:15)
Block(1,9,1,17:15)
Block(1,10,-1,17:15)
Block(1,10,0,17:15)
Block(1,10,1,17:15)
Block(1,11,-1,17:15)
Block(1,11,0,17:15)
Block(1,11,1,17:15)
Block(1,12,-1,17:15)
Block(1,12,0,17:15)
Block(1,12,1,17:15)
Block(1,13,-1,17:15)
Block(1,13,0,17:15)
Block(1,13,1,17:15)
Block(1,14,-1,17:15)
Block(1,14,0,17:15)
Block(1,14,1,17:15)
Block(1,15,-1,17:15)
Block(1,15,0,17:15)
Block(1,15,1,17:15)
Block(1,16,-1,17:15)
Block(1,16,0,17:15)
Block(1,16,1,17:15)
Block(1,17,-1,17:15)
Block(1,17,0,17:15)
Block(1,17,1,17:15)
Block(1,18,-1,17:15)
Block(1,18,0,17:15)
Block(1,18,1,17:15)
Block(1,19,-1,17:15)
Block(1,19,0,17:15)
Block(1,19,1,17:15)
Block(1,20,0,17:15)
Block(1,20,1,17:15)
Block(1,21,0,17:15)
Block(1,21,1,17:15)
Block(1,22,-1,17:15)
Block(1,22,0,17:15)
Block(1,22,1,17:15)
Block(1,23,-1,17:15)
Block(1,23,0,17:15)
Block(1,23,1,17:15)
Block(1,24,0,17:15)
Block(1,24,1,17:15)
Block(1,25,0,17:15)
Block(1,25,1,17:15)
Block(1,26,0,17:15)
Block(1,26,1,17:15)
Block(1,27,0,17:15)
Block(1,27,1,17:15)
Block(1,28,1,17:15)
Block(1,29,1,17:15)
Block(1,30,1,17:15)
Block(1,31,-2,LEAVES:3)
Block(1,31,1,17:15)
Block(1,32,-1,LEAVES:3)
Block(1,32,0,LEAVES:3)
Block(1,32,1,17:15)
Block(1,33,-2,LEAVES:3)
Block(1,33,-1,LEAVES:3)
Block(1,33,1,17:15)
Block(1,34,-1,LEAVES:3)
Block(1,34,1,17:15)
Block(1,35,1,17:15)
Block(1,36,1,17:15)
Block(1,38,3,17:15)
Block(1,39,2,17:15)
Block(1,39,3,17:15)
Block(1,40,2,17:15)
Block(1,40,3,17:15)
Block(1,41,3,17:15)
Block(1,42,-1,17:15)
Block(1,42,3,17:15)
Block(1,43,-1,17:15)
Block(1,45,-14,LEAVES:3)
Block(1,45,-10,LEAVES:3)
Block(1,46,-16,LEAVES:3)
Block(1,46,-15,LEAVES:3)
Block(1,46,-14,LEAVES:3)
Block(1,46,-11,LEAVES:3)
Block(1,46,-2,17:15)
Block(1,46,-1,17:15)
Block(1,46,7,17:15)
Block(1,46,8,17:15)
Block(1,47,-15,LEAVES:3)
Block(1,47,-5,17:15)
Block(1,47,-4,17:15)
Block(1,47,-3,17:15)
Block(1,48,-8,LEAVES:3)
Block(1,48,-6,17:15)
Block(1,48,-5,17:15)
Block(1,48,8,LEAVES:3)
Block(1,48,12,LEAVES:3)
Block(1,49,-12,LEAVES:3)
Block(1,49,-9,LEAVES:3)
Block(1,49,-8,LEAVES:3)
Block(1,49,-7,LEAVES:3)
Block(1,49,-6,LEAVES:3)
Block(1,49,8,LEAVES:3)
Block(1,49,9,LEAVES:3)
Block(1,49,10,17:15)
Block(1,49,11,17:15)
Block(1,49,12,LEAVES:3)
Block(1,50,-18,LEAVES:3)
Block(1,50,-13,LEAVES:3)
Block(1,50,-12,LEAVES:3)
Block(1,50,-11,17:15)
Block(1,50,-10,LEAVES:3)
Block(1,50,-9,LEAVES:3)
Block(1,50,-2,LEAVES:3)
Block(1,50,9,LEAVES:3)
Block(1,50,10,LEAVES:3)
Block(1,50,11,LEAVES:3)
Block(1,50,13,LEAVES:3)
Block(1,50,14,LEAVES:3)
Block(1,50,15,LEAVES:3)
Block(1,51,-17,LEAVES:3)
Block(1,51,-16,LEAVES:3)
Block(1,51,-15,LEAVES:3)
Block(1,51,-14,LEAVES:3)
Block(1,51,-13,LEAVES:3)
Block(1,51,-12,LEAVES:3)
Block(1,51,-11,LEAVES:3)
Block(1,51,-10,LEAVES:3)
Block(1,51,-1,LEAVES:3)
Block(1,51,0,LEAVES:3)
Block(1,51,1,LEAVES:3)
Block(1,51,5,17:15)
Block(1,51,10,LEAVES:3)
Block(1,51,13,LEAVES:3)
Block(1,52,-15,LEAVES:3)
Block(1,52,-12,LEAVES:3)
Block(1,52,-11,LEAVES:3)
Block(1,52,-10,LEAVES:3)
Block(1,52,0,LEAVES:3)
Block(1,52,3,LEAVES:3)
Block(1,52,4,LEAVES:3)
Block(1,52,5,17:15)
Block(1,52,8,LEAVES:3)
Block(1,53,-11,LEAVES:3)
Block(1,53,7,LEAVES:3)
Block(1,54,6,LEAVES:3)
Block(2,-6,-4,17:15)
Block(2,-6,5,17:15)
Block(2,-5,-4,17:15)
Block(2,-5,5,17:15)
Block(2,-4,5,17:15)
Block(2,-2,0,17:15)
Block(2,-2,1,17:15)
Block(2,-1,-1,17:15)
Block(2,-1,0,17:15)
Block(2,-1,1,17:15)
Block(2,0,-1,17:15)
Block(2,0,0,17:15)
Block(2,0,1,17:15)
Block(2,1,0,17:15)
Block(2,1,1,17:15)
Block(2,2,0,17:15)
Block(2,2,1,17:15)
Block(2,3,0,17:15)
Block(2,3,1,17:15)
Block(2,4,0,17:15)
Block(2,4,1,17:15)
Block(2,5,0,17:15)
Block(2,6,0,17:15)
Block(2,7,0,17:15)
Block(2,8,0,17:15)
Block(2,9,0,17:15)
Block(2,10,0,17:15)
Block(2,11,0,17:15)
Block(2,12,0,17:15)
Block(2,13,0,17:15)
Block(2,14,0,17:15)
Block(2,15,0,17:15)
Block(2,23,0,17:15)
Block(2,24,0,17:15)
Block(2,25,0,LEAVES:3)
Block(2,26,-1,LEAVES:3)
Block(2,26,0,LEAVES:3)
Block(2,27,0,LEAVES:3)
Block(2,31,0,LEAVES:3)
Block(2,32,-1,LEAVES:3)
Block(2,41,3,17:15)
Block(2,42,3,17:15)
Block(2,42,4,17:15)
Block(2,43,-2,17:15)
Block(2,43,4,17:15)
Block(2,44,-3,17:15)
Block(2,44,4,17:15)
Block(2,45,-16,LEAVES:3)
Block(2,45,6,17:15)
Block(2,46,-15,LEAVES:3)
Block(2,46,6,17:15)
Block(2,48,-8,17:15)
Block(2,48,-7,17:15)
Block(2,48,-6,17:15)
Block(2,49,-14,LEAVES:3)
Block(2,49,-9,LEAVES:3)
Block(2,49,-8,17:15)
Block(2,49,-7,LEAVES:3)
Block(2,49,-6,LEAVES:3)
Block(2,49,9,LEAVES:3)
Block(2,49,10,LEAVES:3)
Block(2,49,11,LEAVES:3)
Block(2,49,12,17:15)
Block(2,49,13,LEAVES:3)
Block(2,49,16,LEAVES:3)
Block(2,50,-16,LEAVES:3)
Block(2,50,-14,17:15)
Block(2,50,-13,LEAVES:3)
Block(2,50,-11,LEAVES:3)
Block(2,50,-10,17:15)
Block(2,50,-9,LEAVES:3)
Block(2,50,-8,LEAVES:3)
Block(2,50,-7,LEAVES:3)
Block(2,50,0,LEAVES:3)
Block(2,50,9,LEAVES:3)
Block(2,50,10,17:15)
Block(2,50,12,LEAVES:3)
Block(2,50,13,17:15)
Block(2,50,14,17:15)
Block(2,50,15,LEAVES:3)
Block(2,50,16,LEAVES:3)
Block(2,51,-18,LEAVES:3)
Block(2,51,-17,LEAVES:3)
Block(2,51,-16,17:15)
Block(2,51,-15,17:15)
Block(2,51,-14,LEAVES:3)
Block(2,51,-12,LEAVES:3)
Block(2,51,-11,LEAVES:3)
Block(2,51,-10,LEAVES:3)
Block(2,51,-9,LEAVES:3)
Block(2,51,0,LEAVES:3)
Block(2,51,2,LEAVES:3)
Block(2,51,6,LEAVES:3)
Block(2,51,9,LEAVES:3)
Block(2,51,10,LEAVES:3)
Block(2,51,13,LEAVES:3)
Block(2,51,14,LEAVES:3)
Block(2,51,15,LEAVES:3)
Block(2,52,-17,LEAVES:3)
Block(2,52,-16,LEAVES:3)
Block(2,52,-15,LEAVES:3)
Block(2,52,-11,LEAVES:3)
Block(2,52,2,LEAVES:3)
Block(2,52,3,LEAVES:3)
Block(2,52,4,17:15)
Block(2,52,5,17:15)
Block(2,52,6,LEAVES:3)
Block(2,52,13,LEAVES:3)
Block(2,53,3,LEAVES:3)
Block(2,53,4,LEAVES:3)
Block(2,53,5,LEAVES:3)
Block(2,53,7,LEAVES:3)
Block(2,53,8,LEAVES:3)
Block(2,53,9,LEAVES:3)
Block(2,54,4,LEAVES:3)
Block(2,54,7,LEAVES:3)
Block(3,-4,-1,17:15)
Block(3,-4,2,17:15)
Block(3,-3,-1,17:15)
Block(3,-3,1,17:15)
Block(3,-3,2,17:15)
Block(3,-2,-1,17:15)
Block(3,-2,0,17:15)
Block(3,-2,1,17:15)
Block(3,-2,2,17:15)
Block(3,-1,-1,17:15)
Block(3,-1,0,17:15)
Block(3,-1,1,17:15)
Block(3,0,0,17:15)
Block(3,1,0,17:15)
Block(3,24,-2,LEAVES:3)
Block(3,24,0,17:15)
Block(3,24,1,17:15)
Block(3,24,5,LEAVES:3)
Block(3,25,-1,LEAVES:3)
Block(3,25,0,LEAVES:3)
Block(3,25,1,17:15)
Block(3,25,3,LEAVES:3)
Block(3,25,5,LEAVES:3)
Block(3,26,-2,LEAVES:3)
Block(3,26,-1,LEAVES:3)
Block(3,26,0,LEAVES:3)
Block(3,26,1,LEAVES:3)
Block(3,26,3,LEAVES:3)
Block(3,26,4,LEAVES:3)
Block(3,27,-1,LEAVES:3)
Block(3,27,0,LEAVES:3)
Block(3,27,1,LEAVES:3)
Block(3,27,3,LEAVES:3)
Block(3,28,0,LEAVES:3)
Block(3,43,4,17:15)
Block(3,44,-4,17:15)
Block(3,44,4,17:15)
Block(3,44,5,17:15)
Block(3,45,4,17:15)
Block(3,45,5,17:15)
Block(3,46,3,17:15)
Block(3,46,4,17:15)
Block(3,47,3,17:15)
Block(3,48,-11,LEAVES:3)
Block(3,48,-8,LEAVES:3)
Block(3,48,10,LEAVES:3)
Block(3,49,-14,LEAVES:3)
Block(3,49,-13,LEAVES:3)
Block(3,49,-11,LEAVES:3)
Block(3,49,-10,17:15)
Block(3,49,-9,17:15)
Block(3,49,-8,17:15)
Block(3,49,-7,LEAVES:3)
Block(3,49,7,LEAVES:3)
Block(3,49,9,LEAVES:3)
Block(3,49,11,LEAVES:3)
Block(3,49,12,LEAVES:3)
Block(3,49,13,LEAVES:3)
Block(3,49,14,LEAVES:3)
Block(3,50,-16,LEAVES:3)
Block(3,50,-13,17:15)
Block(3,50,-11,LEAVES:3)
Block(3,50,-10,LEAVES:3)
Block(3,50,-9,LEAVES:3)
Block(3,50,-8,LEAVES:3)
Block(3,50,8,LEAVES:3)
Block(3,50,9,17:15)
Block(3,50,10,LEAVES:3)
Block(3,50,12,LEAVES:3)
Block(3,50,13,LEAVES:3)
Block(3,50,14,LEAVES:3)
Block(3,50,15,LEAVES:3)
Block(3,51,-17,LEAVES:3)
Block(3,51,-16,LEAVES:3)
Block(3,51,-15,LEAVES:3)
Block(3,51,-14,LEAVES:3)
Block(3,51,-13,LEAVES:3)
Block(3,51,-10,LEAVES:3)
Block(3,51,9,LEAVES:3)
Block(3,51,14,LEAVES:3)
Block(3,52,3,LEAVES:3)
Block(3,52,4,LEAVES:3)
Block(3,52,5,LEAVES:3)
Block(3,52,6,17:15)
Block(3,52,7,LEAVES:3)
Block(3,52,9,LEAVES:3)
Block(3,52,10,LEAVES:3)
Block(3,53,3,LEAVES:3)
Block(3,53,4,17:15)
Block(3,53,6,LEAVES:3)
Block(3,53,7,17:15)
Block(3,53,8,17:15)
Block(3,53,9,LEAVES:3)
Block(3,53,10,LEAVES:3)
Block(3,54,3,LEAVES:3)
Block(3,54,4,LEAVES:3)
Block(3,54,7,LEAVES:3)
Block(3,54,8,LEAVES:3)
Block(3,54,9,LEAVES:3)
Block(3,55,7,LEAVES:3)
Block(4,-6,-2,17:15)
Block(4,-6,3,17:15)
Block(4,-5,-2,17:15)
Block(4,-5,0,17:15)
Block(4,-5,2,17:15)
Block(4,-5,3,17:15)
Block(4,-4,-2,17:15)
Block(4,-4,-1,17:15)
Block(4,-4,0,17:15)
Block(4,-4,2,17:15)
Block(4,-4,3,17:15)
Block(4,-3,-1,17:15)
Block(4,-3,0,17:15)
Block(4,-3,2,17:15)
Block(4,-2,0,17:15)
Block(4,24,-4,LEAVES:3)
Block(4,24,-1,17:15)
Block(4,24,3,LEAVES:3)
Block(4,25,-3,LEAVES:3)
Block(4,25,-2,LEAVES:3)
Block(4,25,-1,LEAVES:3)
Block(4,25,0,LEAVES:3)
Block(4,25,1,LEAVES:3)
Block(4,25,2,17:15)
Block(4,25,4,LEAVES:3)
Block(4,26,-1,LEAVES:3)
Block(4,26,0,LEAVES:3)
Block(4,26,2,17:15)
Block(4,26,3,LEAVES:3)
Block(4,26,4,LEAVES:3)
Block(4,26,5,LEAVES:3)
Block(4,27,2,LEAVES:3)
Block(4,27,3,LEAVES:3)
Block(4,27,4,LEAVES:3)
Block(4,28,3,LEAVES:3)
Block(4,44,-5,17:15)
Block(4,44,5,17:15)
Block(4,45,-7,17:15)
Block(4,45,-6,LEAVES:3)
Block(4,46,-7,LEAVES:3)
Block(4,47,2,17:15)
Block(4,48,-8,LEAVES:3)
Block(4,48,1,17:15)
Block(4,48,12,LEAVES:3)
Block(4,48,14,LEAVES:3)
Block(4,49,-12,LEAVES:3)
Block(4,49,-11,17:15)
Block(4,49,-10,17:15)
Block(4,49,-9,LEAVES:3)
Block(4,49,-8,LEAVES:3)
Block(4,49,9,LEAVES:3)
Block(4,49,12,LEAVES:3)
Block(4,49,15,LEAVES:3)
Block(4,50,-17,LEAVES:3)
Block(4,50,-15,LEAVES:3)
Block(4,50,-14,LEAVES:3)
Block(4,50,-13,17:15)
Block(4,50,-12,17:15)
Block(4,50,-11,17:15)
Block(4,50,-10,LEAVES:3)
Block(4,50,-9,LEAVES:3)
Block(4,50,7,LEAVES:3)
Block(4,50,8,LEAVES:3)
Block(4,50,9,LEAVES:3)
Block(4,50,10,LEAVES:3)
Block(4,50,13,LEAVES:3)
Block(4,50,14,LEAVES:3)
Block(4,50,16,LEAVES:3)
Block(4,51,-16,LEAVES:3)
Block(4,51,-15,LEAVES:3)
Block(4,51,-14,LEAVES:3)
Block(4,51,-13,LEAVES:3)
Block(4,51,-12,LEAVES:3)
Block(4,51,-11,LEAVES:3)
Block(4,51,-10,LEAVES:3)
Block(4,51,-9,LEAVES:3)
Block(4,51,4,LEAVES:3)
Block(4,51,8,LEAVES:3)
Block(4,51,9,LEAVES:3)
Block(4,51,12,LEAVES:3)
Block(4,51,13,LEAVES:3)
Block(4,51,14,LEAVES:3)
Block(4,51,15,LEAVES:3)
Block(4,52,-14,LEAVES:3)
Block(4,52,-10,LEAVES:3)
Block(4,52,1,LEAVES:3)
Block(4,52,3,LEAVES:3)
Block(4,52,5,LEAVES:3)
Block(4,52,6,LEAVES:3)
Block(4,52,7,LEAVES:3)
Block(4,52,8,LEAVES:3)
Block(4,52,14,LEAVES:3)
Block(4,53,2,LEAVES:3)
Block(4,53,3,17:15)
Block(4,53,4,LEAVES:3)
Block(4,53,6,LEAVES:3)
Block(4,53,7,LEAVES:3)
Block(4,53,8,LEAVES:3)
Block(4,53,9,LEAVES:3)
Block(4,54,3,LEAVES:3)
Block(4,54,8,LEAVES:3)
Block(4,55,3,LEAVES:3)
Block(5,-6,-3,17:15)
Block(5,-6,0,17:15)
Block(5,-5,-3,17:15)
Block(5,-5,0,17:15)
Block(5,-4,-3,17:15)
Block(5,-4,0,17:15)
Block(5,24,-3,LEAVES:3)
Block(5,25,-4,LEAVES:3)
Block(5,25,-3,LEAVES:3)
Block(5,25,-2,17:15)
Block(5,25,0,LEAVES:3)
Block(5,25,5,LEAVES:3)
Block(5,26,-3,LEAVES:3)
Block(5,26,-2,LEAVES:3)
Block(5,26,3,17:15)
Block(5,26,4,LEAVES:3)
Block(5,26,5,LEAVES:3)
Block(5,27,3,LEAVES:3)
Block(5,44,-6,LEAVES:3)
Block(5,44,4,17:15)
Block(5,44,5,17:15)
Block(5,45,-8,17:15)
Block(5,45,-5,LEAVES:3)
Block(5,45,5,17:15)
Block(5,46,-8,LEAVES:3)
Block(5,46,-7,LEAVES:3)
Block(5,46,-6,LEAVES:3)
Block(5,47,-7,LEAVES:3)
Block(5,48,-10,17:15)
Block(5,48,-9,LEAVES:3)
Block(5,48,-1,17:15)
Block(5,48,0,17:15)
Block(5,49,-14,LEAVES:3)
Block(5,49,-11,LEAVES:3)
Block(5,49,-10,17:15)
Block(5,49,-9,LEAVES:3)
Block(5,49,-8,LEAVES:3)
Block(5,49,-2,17:15)
Block(5,49,8,LEAVES:3)
Block(5,50,-17,LEAVES:3)
Block(5,50,-14,17:15)
Block(5,50,-13,17:15)
Block(5,50,-12,LEAVES:3)
Block(5,50,-11,LEAVES:3)
Block(5,50,-10,LEAVES:3)
Block(5,50,-9,LEAVES:3)
Block(5,50,-4,LEAVES:3)
Block(5,50,8,LEAVES:3)
Block(5,50,9,LEAVES:3)
Block(5,50,10,LEAVES:3)
Block(5,50,13,LEAVES:3)
Block(5,50,15,LEAVES:3)
Block(5,51,-18,LEAVES:3)
Block(5,51,-17,LEAVES:3)
Block(5,51,-16,LEAVES:3)
Block(5,51,-14,LEAVES:3)
Block(5,51,-13,LEAVES:3)
Block(5,51,-11,LEAVES:3)
Block(5,51,-3,LEAVES:3)
Block(5,51,6,LEAVES:3)
Block(5,51,8,LEAVES:3)
Block(5,51,9,LEAVES:3)
Block(5,51,11,LEAVES:3)
Block(5,51,12,LEAVES:3)
Block(5,51,13,LEAVES:3)
Block(5,51,14,17:15)
Block(5,51,15,LEAVES:3)
Block(5,51,16,LEAVES:3)
Block(5,52,-16,LEAVES:3)
Block(5,52,3,LEAVES:3)
Block(5,52,6,LEAVES:3)
Block(5,52,9,LEAVES:3)
Block(5,52,12,LEAVES:3)
Block(5,52,14,LEAVES:3)
Block(5,52,15,LEAVES:3)
Block(5,53,1,LEAVES:3)
Block(5,53,2,LEAVES:3)
Block(5,53,3,LEAVES:3)
Block(5,53,4,LEAVES:3)
Block(5,53,8,LEAVES:3)
Block(5,54,2,LEAVES:3)
Block(5,54,3,LEAVES:3)
Block(6,24,-5,LEAVES:3)
Block(6,25,-5,LEAVES:3)
Block(6,25,-4,LEAVES:3)
Block(6,25,-3,LEAVES:3)
Block(6,25,-2,17:15)
Block(6,25,4,LEAVES:3)
Block(6,26,-4,LEAVES:3)
Block(6,26,-2,LEAVES:3)
Block(6,26,3,LEAVES:3)
Block(6,26,4,17:15)
Block(6,26,6,LEAVES:3)
Block(6,27,0,LEAVES:3)
Block(6,27,1,LEAVES:3)
Block(6,27,2,LEAVES:3)
Block(6,27,3,17:15)
Block(6,27,4,LEAVES:3)
Block(6,27,5,LEAVES:3)
Block(6,27,6,LEAVES:3)
Block(6,28,1,LEAVES:3)
Block(6,28,5,LEAVES:3)
Block(6,43,3,17:15)
Block(6,43,4,17:15)
Block(6,44,-4,LEAVES:3)
Block(6,45,-8,LEAVES:3)
Block(6,45,-6,LEAVES:3)
Block(6,45,-5,LEAVES:3)
Block(6,45,-4,LEAVES:3)
Block(6,45,6,17:15)
Block(6,46,-9,LEAVES:3)
Block(6,46,-8,LEAVES:3)
Block(6,46,-7,17:15)
Block(6,46,-6,LEAVES:3)
Block(6,46,-5,LEAVES:3)
Block(6,46,6,17:15)
Block(6,47,-8,LEAVES:3)
Block(6,47,-7,LEAVES:3)
Block(6,48,-10,17:15)
Block(6,48,-8,LEAVES:3)
Block(6,49,-13,LEAVES:3)
Block(6,49,-12,LEAVES:3)
Block(6,49,-10,LEAVES:3)
Block(6,49,-9,LEAVES:3)
Block(6,49,-2,17:15)
Block(6,49,10,LEAVES:3)
Block(6,50,-19,LEAVES:3)
Block(6,50,-16,LEAVES:3)
Block(6,50,-15,17:15)
Block(6,50,-14,LEAVES:3)
Block(6,50,-13,LEAVES:3)
Block(6,50,-12,LEAVES:3)
Block(6,50,-11,LEAVES:3)
Block(6,50,-6,LEAVES:3)
Block(6,50,-2,17:15)
Block(6,50,-1,LEAVES:3)
Block(6,50,1,LEAVES:3)
Block(6,50,9,LEAVES:3)
Block(6,50,12,LEAVES:3)
Block(6,50,17,LEAVES:3)
Block(6,51,-19,LEAVES:3)
Block(6,51,-18,LEAVES:3)
Block(6,51,-17,LEAVES:3)
Block(6,51,-16,17:15)
Block(6,51,-15,LEAVES:3)
Block(6,51,-13,LEAVES:3)
Block(6,51,-5,LEAVES:3)
Block(6,51,-4,LEAVES:3)
Block(6,51,-3,17:15)
Block(6,51,-2,LEAVES:3)
Block(6,51,-1,LEAVES:3)
Block(6,51,0,LEAVES:3)
Block(6,51,10,LEAVES:3)
Block(6,51,11,LEAVES:3)
Block(6,51,12,LEAVES:3)
Block(6,51,13,17:15)
Block(6,51,14,LEAVES:3)
Block(6,51,15,LEAVES:3)
Block(6,51,16,LEAVES:3)
Block(6,52,-18,LEAVES:3)
Block(6,52,-17,LEAVES:3)
Block(6,52,-16,LEAVES:3)
Block(6,52,-13,LEAVES:3)
Block(6,52,-12,LEAVES:3)
Block(6,52,-4,LEAVES:3)
Block(6,52,-3,LEAVES:3)
Block(6,52,-2,LEAVES:3)
Block(6,52,2,LEAVES:3)
Block(6,52,11,LEAVES:3)
Block(6,52,12,LEAVES:3)
Block(6,52,13,LEAVES:3)
Block(6,53,2,LEAVES:3)
Block(6,53,3,LEAVES:3)
Block(6,53,4,LEAVES:3)
Block(6,53,13,LEAVES:3)
Block(6,54,3,LEAVES:3)
Block(7,23,-5,LEAVES:3)
Block(7,24,-3,LEAVES:3)
Block(7,25,-6,LEAVES:3)
Block(7,25,-5,LEAVES:3)
Block(7,25,-4,LEAVES:3)
Block(7,25,-3,17:15)
Block(7,25,-1,LEAVES:3)
Block(7,25,3,LEAVES:3)
Block(7,25,5,LEAVES:3)
Block(7,26,-5,LEAVES:3)
Block(7,26,-4,LEAVES:3)
Block(7,26,-3,LEAVES:3)
Block(7,26,-2,LEAVES:3)
Block(7,26,1,LEAVES:3)
Block(7,26,6,LEAVES:3)
Block(7,27,-4,LEAVES:3)
Block(7,27,-1,LEAVES:3)
Block(7,27,0,LEAVES:3)
Block(7,27,1,LEAVES:3)
Block(7,27,2,17:15)
Block(7,27,4,17:15)
Block(7,27,5,LEAVES:3)
Block(7,27,6,LEAVES:3)
Block(7,27,7,LEAVES:3)
Block(7,28,0,LEAVES:3)
Block(7,28,1,LEAVES:3)
Block(7,28,2,LEAVES:3)
Block(7,28,4,LEAVES:3)
Block(7,28,5,LEAVES:3)
Block(7,28,6,LEAVES:3)
Block(7,29,1,LEAVES:3)
Block(7,29,5,LEAVES:3)
Block(7,43,2,17:15)
Block(7,44,-5,LEAVES:3)
Block(7,45,-5,LEAVES:3)
Block(7,45,-4,LEAVES:3)
Block(7,45,-3,LEAVES:3)
Block(7,46,-9,LEAVES:3)
Block(7,46,-7,LEAVES:3)
Block(7,46,-6,17:15)
Block(7,46,-5,LEAVES:3)
Block(7,46,-4,LEAVES:3)
Block(7,46,7,17:15)
Block(7,47,-9,LEAVES:3)
Block(7,47,-8,LEAVES:3)
Block(7,47,-7,LEAVES:3)
Block(7,47,-6,LEAVES:3)
Block(7,47,7,17:15)
Block(7,47,8,17:15)
Block(7,48,-11,LEAVES:3)
Block(7,48,-10,17:15)
Block(7,48,-9,LEAVES:3)
Block(7,48,-6,LEAVES:3)
Block(7,48,9,17:15)
Block(7,49,-15,LEAVES:3)
Block(7,49,-13,LEAVES:3)
Block(7,49,-11,LEAVES:3)
Block(7,49,-10,LEAVES:3)
Block(7,49,-9,LEAVES:3)
Block(7,49,13,LEAVES:3)
Block(7,50,-17,LEAVES:3)
Block(7,50,-15,LEAVES:3)
Block(7,50,-14,LEAVES:3)
Block(7,50,-13,LEAVES:3)
Block(7,50,-12,LEAVES:3)
Block(7,50,-11,LEAVES:3)
Block(7,50,-10,LEAVES:3)
Block(7,50,-4,LEAVES:3)
Block(7,50,-2,17:15)
Block(7,50,11,LEAVES:3)
Block(7,50,12,LEAVES:3)
Block(7,50,13,17:15)
Block(7,50,14,LEAVES:3)
Block(7,51,-18,LEAVES:3)
Block(7,51,-17,LEAVES:3)
Block(7,51,-16,LEAVES:3)
Block(7,51,-13,LEAVES:3)
Block(7,51,-6,LEAVES:3)
Block(7,51,-5,LEAVES:3)
Block(7,51,-4,17:15)
Block(7,51,-2,LEAVES:3)
Block(7,51,-1,LEAVES:3)
Block(7,51,0,LEAVES:3)
Block(7,51,1,LEAVES:3)
Block(7,51,11,LEAVES:3)
Block(7,51,13,LEAVES:3)
Block(7,51,15,LEAVES:3)
Block(7,51,16,LEAVES:3)
Block(7,51,17,LEAVES:3)
Block(7,52,-18,LEAVES:3)
Block(7,52,-17,LEAVES:3)
Block(7,52,-5,LEAVES:3)
Block(7,52,-4,LEAVES:3)
Block(7,52,-3,LEAVES:3)
Block(7,52,-1,LEAVES:3)
Block(7,52,0,LEAVES:3)
Block(7,52,4,LEAVES:3)
Block(7,52,13,LEAVES:3)
Block(7,53,-4,LEAVES:3)
Block(7,53,3,LEAVES:3)
Block(8,24,-6,LEAVES:3)
Block(8,25,-5,LEAVES:3)
Block(8,25,-4,LEAVES:3)
Block(8,26,-4,LEAVES:3)
Block(8,26,-3,17:15)
Block(8,26,-2,LEAVES:3)
Block(8,26,4,LEAVES:3)
Block(8,26,7,LEAVES:3)
Block(8,27,-2,LEAVES:3)
Block(8,27,-1,LEAVES:3)
Block(8,27,0,17:15)
Block(8,27,1,17:15)
Block(8,27,2,LEAVES:3)
Block(8,27,4,LEAVES:3)
Block(8,27,5,17:15)
Block(8,27,6,LEAVES:3)
Block(8,28,0,LEAVES:3)
Block(8,28,1,LEAVES:3)
Block(8,28,5,LEAVES:3)
Block(8,44,-3,LEAVES:3)
Block(8,44,1,17:15)
Block(8,45,-9,LEAVES:3)
Block(8,45,-6,LEAVES:3)
Block(8,45,-5,17:15)
Block(8,45,-4,LEAVES:3)
Block(8,45,-3,LEAVES:3)
Block(8,45,-1,LEAVES:3)
Block(8,45,0,LEAVES:3)
Block(8,45,1,17:15)
Block(8,45,4,LEAVES:3)
Block(8,46,-8,LEAVES:3)
Block(8,46,-6,LEAVES:3)
Block(8,46,-5,LEAVES:3)
Block(8,46,3,LEAVES:3)
Block(8,46,7,17:15)
Block(8,47,-6,LEAVES:3)
Block(8,48,-12,LEAVES:3)
Block(8,48,-9,17:15)
Block(8,48,-7,LEAVES:3)
Block(8,48,8,17:15)
Block(8,48,9,17:15)
Block(8,48,10,17:15)
Block(8,48,11,17:15)
Block(8,49,-12,LEAVES:3)
Block(8,49,-11,LEAVES:3)
Block(8,49,-10,LEAVES:3)
Block(8,49,-9,LEAVES:3)
Block(8,49,-8,LEAVES:3)
Block(8,49,9,LEAVES:3)
Block(8,49,11,LEAVES:3)
Block(8,49,12,17:15)
Block(8,50,-16,LEAVES:3)
Block(8,50,-13,LEAVES:3)
Block(8,50,-11,LEAVES:3)
Block(8,50,-9,LEAVES:3)
Block(8,50,-5,LEAVES:3)
Block(8,50,-2,LEAVES:3)
Block(8,50,1,LEAVES:3)
Block(8,50,10,LEAVES:3)
Block(8,50,11,LEAVES:3)
Block(8,50,12,17:15)
Block(8,50,14,17:15)
Block(8,50,15,LEAVES:3)
Block(8,50,17,LEAVES:3)
Block(8,51,-17,LEAVES:3)
Block(8,51,-5,LEAVES:3)
Block(8,51,-4,LEAVES:3)
Block(8,51,-3,LEAVES:3)
Block(8,51,-2,17:15)
Block(8,51,-1,17:15)
Block(8,51,0,LEAVES:3)
Block(8,51,11,LEAVES:3)
Block(8,51,12,LEAVES:3)
Block(8,51,14,LEAVES:3)
Block(8,51,15,17:15)
Block(8,51,16,LEAVES:3)
Block(8,51,17,LEAVES:3)
Block(8,51,18,LEAVES:3)
Block(8,52,-4,LEAVES:3)
Block(8,52,-3,LEAVES:3)
Block(8,52,-2,LEAVES:3)
Block(8,52,-1,LEAVES:3)
Block(8,52,0,LEAVES:3)
Block(8,52,14,LEAVES:3)
Block(8,52,15,LEAVES:3)
Block(8,52,16,LEAVES:3)
Block(8,52,17,LEAVES:3)
Block(8,53,-1,LEAVES:3)
Block(8,53,15,LEAVES:3)
Block(9,24,-5,LEAVES:3)
Block(9,25,-6,LEAVES:3)
Block(9,25,-2,LEAVES:3)
Block(9,25,-1,LEAVES:3)
Block(9,26,-5,LEAVES:3)
Block(9,26,-4,17:15)
Block(9,26,-3,LEAVES:3)
Block(9,26,0,LEAVES:3)
Block(9,26,5,LEAVES:3)
Block(9,27,-5,LEAVES:3)
Block(9,27,-4,LEAVES:3)
Block(9,27,-3,LEAVES:3)
Block(9,27,-2,LEAVES:3)
Block(9,27,-1,17:15)
Block(9,27,0,LEAVES:3)
Block(9,27,1,17:15)
Block(9,27,3,LEAVES:3)
Block(9,27,4,LEAVES:3)
Block(9,27,5,17:15)
Block(9,27,7,LEAVES:3)
Block(9,27,9,LEAVES:3)
Block(9,28,-4,LEAVES:3)
Block(9,28,-2,LEAVES:3)
Block(9,28,-1,LEAVES:3)
Block(9,28,0,LEAVES:3)
Block(9,28,1,LEAVES:3)
Block(9,28,2,LEAVES:3)
Block(9,28,3,LEAVES:3)
Block(9,28,5,LEAVES:3)
Block(9,28,6,LEAVES:3)
Block(9,28,7,LEAVES:3)
Block(9,28,8,LEAVES:3)
Block(9,29,0,LEAVES:3)
Block(9,29,1,LEAVES:3)
Block(9,29,7,LEAVES:3)
Block(9,44,-6,LEAVES:3)
Block(9,44,-4,17:15)
Block(9,44,-3,17:15)
Block(9,44,-2,LEAVES:3)
Block(9,44,-1,17:15)
Block(9,44,0,17:15)
Block(9,44,2,LEAVES:3)
Block(9,45,-10,LEAVES:3)
Block(9,45,-5,17:15)
Block(9,45,-4,17:15)
Block(9,45,-3,LEAVES:3)
Block(9,45,-2,LEAVES:3)
Block(9,45,-1,LEAVES:3)
Block(9,45,0,17:15)
Block(9,45,1,17:15)
Block(9,45,2,LEAVES:3)
Block(9,46,-9,LEAVES:3)
Block(9,46,-8,LEAVES:3)
Block(9,46,-7,LEAVES:3)
Block(9,46,-6,LEAVES:3)
Block(9,46,-5,LEAVES:3)
Block(9,46,-4,LEAVES:3)
Block(9,46,-3,LEAVES:3)
Block(9,46,-1,LEAVES:3)
Block(9,46,0,LEAVES:3)
Block(9,46,1,LEAVES:3)
Block(9,46,3,LEAVES:3)
Block(9,46,4,LEAVES:3)
Block(9,46,5,LEAVES:3)
Block(9,47,-8,LEAVES:3)
Block(9,47,-5,LEAVES:3)
Block(9,47,0,LEAVES:3)
Block(9,47,3,LEAVES:3)
Block(9,47,6,17:15)
Block(9,48,-8,LEAVES:3)
Block(9,48,9,17:15)
Block(9,48,11,LEAVES:3)
Block(9,49,-11,LEAVES:3)
Block(9,49,-10,LEAVES:3)
Block(9,49,-9,17:15)
Block(9,49,-8,LEAVES:3)
Block(9,49,-7,LEAVES:3)
Block(9,49,8,LEAVES:3)
Block(9,49,9,17:15)
Block(9,49,10,17:15)
Block(9,49,11,17:15)
Block(9,49,13,LEAVES:3)
Block(9,49,14,LEAVES:3)
Block(9,50,-10,LEAVES:3)
Block(9,50,-9,LEAVES:3)
Block(9,50,-8,LEAVES:3)
Block(9,50,-4,LEAVES:3)
Block(9,50,0,LEAVES:3)
Block(9,50,2,LEAVES:3)
Block(9,50,9,LEAVES:3)
Block(9,50,10,LEAVES:3)
Block(9,50,11,LEAVES:3)
Block(9,50,12,LEAVES:3)
Block(9,50,13,LEAVES:3)
Block(9,50,14,LEAVES:3)
Block(9,51,-9,LEAVES:3)
Block(9,51,-4,LEAVES:3)
Block(9,51,-3,LEAVES:3)
Block(9,51,-2,LEAVES:3)
Block(9,51,-1,LEAVES:3)
Block(9,51,0,17:15)
Block(9,51,1,LEAVES:3)
Block(9,51,2,LEAVES:3)
Block(9,51,10,LEAVES:3)
Block(9,51,12,LEAVES:3)
Block(9,51,13,LEAVES:3)
Block(9,51,15,LEAVES:3)
Block(9,51,16,LEAVES:3)
Block(9,51,17,LEAVES:3)
Block(9,52,-3,LEAVES:3)
Block(9,52,-2,LEAVES:3)
Block(9,52,-1,LEAVES:3)
Block(9,52,0,LEAVES:3)
Block(9,52,1,LEAVES:3)
Block(9,52,12,LEAVES:3)
Block(9,52,15,LEAVES:3)
Block(9,53,-2,LEAVES:3)
Block(9,53,0,LEAVES:3)
Block(10,25,-4,LEAVES:3)
Block(10,25,-3,LEAVES:3)
Block(10,26,-6,LEAVES:3)
Block(10,26,-5,LEAVES:3)
Block(10,26,-4,LEAVES:3)
Block(10,26,-3,LEAVES:3)
Block(10,26,-1,LEAVES:3)
Block(10,26,9,LEAVES:3)
Block(10,27,-5,LEAVES:3)
Block(10,27,-4,LEAVES:3)
Block(10,27,-2,LEAVES:3)
Block(10,27,-1,LEAVES:3)
Block(10,27,4,LEAVES:3)
Block(10,27,8,LEAVES:3)
Block(10,28,-1,LEAVES:3)
Block(10,28,0,LEAVES:3)
Block(10,28,1,17:15)
Block(10,28,2,LEAVES:3)
Block(10,28,3,LEAVES:3)
Block(10,28,5,LEAVES:3)
Block(10,28,6,17:15)
Block(10,28,7,LEAVES:3)
Block(10,28,8,LEAVES:3)
Block(10,28,9,LEAVES:3)
Block(10,29,0,LEAVES:3)
Block(10,29,1,LEAVES:3)
Block(10,29,2,LEAVES:3)
Block(10,29,6,LEAVES:3)
Block(10,29,7,LEAVES:3)
Block(10,29,8,LEAVES:3)
Block(10,30,1,LEAVES:3)
Block(10,30,7,LEAVES:3)
Block(10,44,-6,LEAVES:3)
Block(10,44,-4,LEAVES:3)
Block(10,45,-9,LEAVES:3)
Block(10,45,-7,LEAVES:3)
Block(10,45,-6,17:15)
Block(10,45,-5,17:15)
Block(10,45,-4,LEAVES:3)
Block(10,45,-3,LEAVES:3)
Block(10,45,-1,LEAVES:3)
Block(10,45,0,LEAVES:3)
Block(10,45,1,LEAVES:3)
Block(10,45,2,17:15)
Block(10,45,3,LEAVES:3)
Block(10,45,6,LEAVES:3)
Block(10,46,-10,LEAVES:3)
Block(10,46,-9,LEAVES:3)
Block(10,46,-8,LEAVES:3)
Block(10,46,-7,17:15)
Block(10,46,-6,LEAVES:3)
Block(10,46,-5,LEAVES:3)
Block(10,46,-4,LEAVES:3)
Block(10,46,-1,LEAVES:3)
Block(10,46,0,17:15)
Block(10,46,2,LEAVES:3)
Block(10,46,3,17:15)
Block(10,46,4,17:15)
Block(10,46,5,LEAVES:3)
Block(10,46,6,LEAVES:3)
Block(10,47,-9,LEAVES:3)
Block(10,47,-8,LEAVES:3)
Block(10,47,-7,LEAVES:3)
Block(10,47,-6,LEAVES:3)
Block(10,47,-1,LEAVES:3)
Block(10,47,0,LEAVES:3)
Block(10,47,3,LEAVES:3)
Block(10,47,4,LEAVES:3)
Block(10,47,5,LEAVES:3)
Block(10,48,-11,LEAVES:3)
Block(10,48,-9,LEAVES:3)
Block(10,48,-8,LEAVES:3)
Block(10,48,3,LEAVES:3)
Block(10,48,8,LEAVES:3)
Block(10,48,9,LEAVES:3)
Block(10,49,-10,LEAVES:3)
Block(10,49,-9,LEAVES:3)
Block(10,49,-8,LEAVES:3)
Block(10,49,9,LEAVES:3)
Block(10,49,10,17:15)
Block(10,49,12,LEAVES:3)
Block(10,50,-9,LEAVES:3)
Block(10,50,-2,LEAVES:3)
Block(10,50,9,LEAVES:3)
Block(10,50,10,LEAVES:3)
Block(10,50,11,17:15)
Block(10,50,12,LEAVES:3)
Block(10,50,13,LEAVES:3)
Block(10,50,16,LEAVES:3)
Block(10,51,-3,LEAVES:3)
Block(10,51,-2,LEAVES:3)
Block(10,51,1,LEAVES:3)
Block(10,51,10,LEAVES:3)
Block(10,51,11,LEAVES:3)
Block(10,51,12,LEAVES:3)
Block(10,51,15,LEAVES:3)
Block(10,51,16,LEAVES:3)
Block(10,52,-2,LEAVES:3)
Block(10,52,-1,LEAVES:3)
Block(10,52,0,17:15)
Block(10,52,1,LEAVES:3)
Block(10,52,11,LEAVES:3)
Block(10,53,-1,LEAVES:3)
Block(10,53,0,LEAVES:3)
Block(10,54,0,LEAVES:3)
Block(11,24,-6,LEAVES:3)
Block(11,24,-4,LEAVES:3)
Block(11,25,-6,LEAVES:3)
Block(11,25,-4,LEAVES:3)
Block(11,25,-1,LEAVES:3)
Block(11,26,-5,LEAVES:3)
Block(11,26,-4,LEAVES:3)
Block(11,26,-3,LEAVES:3)
Block(11,26,-2,LEAVES:3)
Block(11,26,2,LEAVES:3)
Block(11,26,6,LEAVES:3)
Block(11,27,-4,LEAVES:3)
Block(11,27,-1,LEAVES:3)
Block(11,27,0,LEAVES:3)
Block(11,27,3,LEAVES:3)
Block(11,27,7,LEAVES:3)
Block(11,28,-1,LEAVES:3)
Block(11,28,0,17:15)
Block(11,28,1,LEAVES:3)
Block(11,28,2,LEAVES:3)
Block(11,28,3,LEAVES:3)
Block(11,28,5,LEAVES:3)
Block(11,28,6,LEAVES:3)
Block(11,28,7,LEAVES:3)
Block(11,28,8,LEAVES:3)
Block(11,29,0,LEAVES:3)
Block(11,29,1,LEAVES:3)
Block(11,29,2,LEAVES:3)
Block(11,29,6,LEAVES:3)
Block(11,44,-10,LEAVES:3)
Block(11,44,-3,LEAVES:3)
Block(11,44,0,LEAVES:3)
Block(11,45,-11,LEAVES:3)
Block(11,45,-8,LEAVES:3)
Block(11,45,-5,LEAVES:3)
Block(11,45,-4,LEAVES:3)
Block(11,45,-3,LEAVES:3)
Block(11,45,-1,LEAVES:3)
Block(11,45,1,LEAVES:3)
Block(11,45,2,LEAVES:3)
Block(11,45,3,LEAVES:3)
Block(11,45,4,LEAVES:3)
Block(11,46,-10,LEAVES:3)
Block(11,46,-9,LEAVES:3)
Block(11,46,-8,LEAVES:3)
Block(11,46,-7,LEAVES:3)
Block(11,46,-6,LEAVES:3)
Block(11,46,-5,17:15)
Block(11,46,-4,LEAVES:3)
Block(11,46,-2,LEAVES:3)
Block(11,46,-1,17:15)
Block(11,46,0,LEAVES:3)
Block(11,46,2,LEAVES:3)
Block(11,46,3,LEAVES:3)
Block(11,46,4,LEAVES:3)
Block(11,46,5,LEAVES:3)
Block(11,47,-9,LEAVES:3)
Block(11,47,-8,17:15)
Block(11,47,-7,LEAVES:3)
Block(11,47,-5,LEAVES:3)
Block(11,47,-1,LEAVES:3)
Block(11,47,4,LEAVES:3)
Block(11,47,5,17:15)
Block(11,48,-8,LEAVES:3)
Block(11,48,-7,LEAVES:3)
Block(11,48,-1,LEAVES:3)
Block(11,48,9,LEAVES:3)
Block(11,49,-10,LEAVES:3)
Block(11,49,-9,LEAVES:3)
Block(11,49,-8,LEAVES:3)
Block(11,49,10,LEAVES:3)
Block(11,49,11,LEAVES:3)
Block(11,49,16,LEAVES:3)
Block(11,50,-9,LEAVES:3)
Block(11,50,-3,LEAVES:3)
Block(11,50,11,17:15)
Block(11,50,12,LEAVES:3)
Block(11,50,13,LEAVES:3)
Block(11,50,14,LEAVES:3)
Block(11,50,15,LEAVES:3)
Block(11,51,-2,LEAVES:3)
Block(11,51,0,LEAVES:3)
Block(11,51,2,LEAVES:3)
Block(11,51,11,LEAVES:3)
Block(11,51,12,LEAVES:3)
Block(11,52,-1,LEAVES:3)
Block(11,52,0,LEAVES:3)
Block(11,52,1,LEAVES:3)
Block(11,52,2,LEAVES:3)
Block(11,53,0,LEAVES:3)
Block(11,53,1,LEAVES:3)
Block(12,25,-5,LEAVES:3)
Block(12,25,-3,LEAVES:3)
Block(12,26,-4,LEAVES:3)
Block(12,27,1,LEAVES:3)
Block(12,27,5,LEAVES:3)
Block(12,28,-1,LEAVES:3)
Block(12,28,0,LEAVES:3)
Block(12,28,1,LEAVES:3)
Block(12,28,2,LEAVES:3)
Block(12,28,6,LEAVES:3)
Block(12,29,0,LEAVES:3)
Block(12,44,2,LEAVES:3)
Block(12,44,4,LEAVES:3)
Block(12,45,-10,LEAVES:3)
Block(12,45,-9,LEAVES:3)
Block(12,45,-7,LEAVES:3)
Block(12,45,-6,LEAVES:3)
Block(12,45,-1,LEAVES:3)
Block(12,45,2,LEAVES:3)
Block(12,45,5,LEAVES:3)
Block(12,46,-11,LEAVES:3)
Block(12,46,-10,LEAVES:3)
Block(12,46,-9,17:15)
Block(12,46,-8,LEAVES:3)
Block(12,46,-7,LEAVES:3)
Block(12,46,-6,LEAVES:3)
Block(12,46,-5,LEAVES:3)
Block(12,46,-4,LEAVES:3)
Block(12,46,-3,LEAVES:3)
Block(12,46,-2,LEAVES:3)
Block(12,46,-1,LEAVES:3)
Block(12,46,0,LEAVES:3)
Block(12,46,4,LEAVES:3)
Block(12,47,-10,LEAVES:3)
Block(12,47,-9,LEAVES:3)
Block(12,47,-5,LEAVES:3)
Block(12,47,-2,LEAVES:3)
Block(12,47,-1,LEAVES:3)
Block(12,48,-9,LEAVES:3)
Block(12,48,5,17:15)
Block(12,49,-9,LEAVES:3)
Block(12,49,13,LEAVES:3)
Block(12,49,15,LEAVES:3)
Block(12,50,11,LEAVES:3)
Block(12,50,12,17:15)
Block(12,50,13,17:15)
Block(12,50,14,LEAVES:3)
Block(12,50,15,LEAVES:3)
Block(12,50,16,LEAVES:3)
Block(12,51,-1,LEAVES:3)
Block(12,51,12,LEAVES:3)
Block(12,51,13,LEAVES:3)
Block(12,51,14,LEAVES:3)
Block(12,51,15,LEAVES:3)
Block(12,52,-1,LEAVES:3)
Block(12,52,0,LEAVES:3)
Block(12,52,1,LEAVES:3)
Block(12,53,0,LEAVES:3)
Block(13,27,-1,LEAVES:3)
Block(13,28,0,LEAVES:3)
Block(13,45,-8,LEAVES:3)
Block(13,45,-4,LEAVES:3)
Block(13,45,-2,LEAVES:3)
Block(13,46,-10,LEAVES:3)
Block(13,46,-9,LEAVES:3)
Block(13,46,-8,LEAVES:3)
Block(13,46,-5,LEAVES:3)
Block(13,46,-2,LEAVES:3)
Block(13,46,-1,LEAVES:3)
Block(13,46,0,LEAVES:3)
Block(13,47,-9,LEAVES:3)
Block(13,47,-1,LEAVES:3)
Block(13,48,4,17:15)
Block(13,49,12,LEAVES:3)
Block(13,49,14,LEAVES:3)
Block(13,50,12,LEAVES:3)
Block(13,50,13,LEAVES:3)
Block(13,50,14,LEAVES:3)
Block(13,50,15,LEAVES:3)
Block(13,51,1,LEAVES:3)
Block(13,51,13,LEAVES:3)
Block(13,51,14,LEAVES:3)
Block(13,52,0,LEAVES:3)
Block(14,45,-10,LEAVES:3)
Block(14,45,0,LEAVES:3)
Block(14,46,-9,LEAVES:3)
Block(14,46,-1,LEAVES:3)
Block(14,48,4,17:15)
Block(14,49,4,LEAVES:3)
Block(14,50,14,LEAVES:3)
Block(15,48,3,LEAVES:3)
Block(15,48,4,17:15)
Block(15,48,6,LEAVES:3)
Block(15,49,2,LEAVES:3)
Block(15,49,3,LEAVES:3)
Block(15,49,4,LEAVES:3)
Block(15,49,5,LEAVES:3)
Block(15,50,4,LEAVES:3)
Block(16,48,1,LEAVES:3)
Block(16,48,4,17:15)
Block(16,48,5,LEAVES:3)
Block(16,49,1,LEAVES:3)
Block(16,49,2,LEAVES:3)
Block(16,49,3,LEAVES:3)
Block(16,49,4,17:15)
Block(16,49,5,LEAVES:3)
Block(16,49,6,LEAVES:3)
Block(16,49,8,LEAVES:3)
Block(16,50,2,LEAVES:3)
Block(16,50,4,LEAVES:3)
Block(16,50,5,LEAVES:3)
Block(16,50,6,LEAVES:3)
Block(16,50,7,LEAVES:3)
Block(17,48,2,LEAVES:3)
Block(17,49,0,LEAVES:3)
Block(17,49,1,LEAVES:3)
Block(17,49,2,LEAVES:3)
Block(17,49,3,17:15)
Block(17,49,4,17:15)
Block(17,49,5,17:15)
Block(17,49,6,LEAVES:3)
Block(17,50,1,LEAVES:3)
Block(17,50,2,LEAVES:3)
Block(17,50,3,LEAVES:3)
Block(17,50,4,LEAVES:3)
Block(17,50,5,LEAVES:3)
Block(17,50,6,17:15)
Block(17,50,7,LEAVES:3)
Block(17,50,8,LEAVES:3)
Block(17,51,4,LEAVES:3)
Block(17,51,6,LEAVES:3)
Block(17,51,7,LEAVES:3)
Block(18,48,0,LEAVES:3)
Block(18,48,4,LEAVES:3)
Block(18,48,5,LEAVES:3)
Block(18,49,-1,LEAVES:3)
Block(18,49,1,LEAVES:3)
Block(18,49,3,LEAVES:3)
Block(18,49,5,17:15)
Block(18,49,7,LEAVES:3)
Block(18,50,0,LEAVES:3)
Block(18,50,1,LEAVES:3)
Block(18,50,2,17:15)
Block(18,50,3,LEAVES:3)
Block(18,50,4,LEAVES:3)
Block(18,50,5,LEAVES:3)
Block(18,50,6,LEAVES:3)
Block(18,50,7,LEAVES:3)
Block(18,51,2,LEAVES:3)
Block(18,51,3,LEAVES:3)
Block(18,51,5,LEAVES:3)
Block(18,52,2,LEAVES:3)
Block(19,49,5,LEAVES:3)
Block(19,49,7,LEAVES:3)
Block(19,50,-1,LEAVES:3)
Block(19,50,0,LEAVES:3)
Block(19,50,1,17:15)
Block(19,50,2,LEAVES:3)
Block(19,50,3,LEAVES:3)
Block(19,50,4,LEAVES:3)
Block(19,50,5,17:15)
Block(19,50,6,LEAVES:3)
Block(19,50,7,LEAVES:3)
Block(19,51,0,LEAVES:3)
Block(19,51,1,LEAVES:3)
Block(19,51,2,LEAVES:3)
Block(19,51,5,LEAVES:3)
Block(19,51,6,LEAVES:3)
Block(20,49,1,LEAVES:3)
Block(20,49,6,LEAVES:3)
Block(20,49,8,LEAVES:3)
Block(20,50,0,LEAVES:3)
Block(20,50,1,LEAVES:3)
Block(20,50,3,LEAVES:3)
Block(20,50,4,LEAVES:3)
Block(20,50,5,LEAVES:3)
Block(20,50,6,LEAVES:3)
Block(20,50,7,LEAVES:3)
Block(20,50,8,LEAVES:3)
Block(20,51,1,LEAVES:3)
Block(20,51,2,LEAVES:3)
Block(20,51,4,LEAVES:3)
Block(20,51,5,LEAVES:3)
Block(20,51,6,17:15)
Block(20,52,5,LEAVES:3)
Block(20,52,6,LEAVES:3)
Block(21,49,3,LEAVES:3)
Block(21,49,5,LEAVES:3)
Block(21,49,7,LEAVES:3)
Block(21,50,1,LEAVES:3)
Block(21,50,2,LEAVES:3)
Block(21,50,4,LEAVES:3)
Block(21,50,5,LEAVES:3)
Block(21,50,6,LEAVES:3)
Block(21,50,7,17:15)
Block(21,50,8,LEAVES:3)
Block(21,50,9,LEAVES:3)
Block(21,51,5,LEAVES:3)
Block(21,51,7,LEAVES:3)
Block(21,51,8,LEAVES:3)
Block(22,48,6,LEAVES:3)
Block(22,49,4,LEAVES:3)
Block(22,49,7,LEAVES:3)
Block(22,49,9,LEAVES:3)
Block(22,50,5,LEAVES:3)
Block(22,50,6,LEAVES:3)
Block(22,50,7,LEAVES:3)
Block(22,50,8,LEAVES:3)
Block(22,51,7,LEAVES:3)
Block(23,49,6,LEAVES:3)
Block(23,50,7,LEAVES:3)


#######################################################################
# +-----------------------------------------------------------------+ #
# |                             Entities                            | #
# +-----------------------------------------------------------------+ #
#######################################################################

# Entity() spawns an entity instead of a block. The entity is spawned only once when the BO3 is spawned.
# Entities are persistent by default so they don't de-spawn when no player is near, they are only unloaded.
# Usage: Entity(x,y,z,mobName,groupSize,NameTagOrNBTFileName) or Entity(x,y,z,mobName,groupSize)
# Use /tc entities or /otg entities to get a list of entities that can be used as mobName, this includes entities added by other mods.
# NameTagOrNBTFileName can be either a nametag for the mob or an nbt file (such as mymobinfo.nbt or mymobinfo.txt).
# When using a text file you can use the same mob spawning parameters used with the /summon command to equip the
# entity and give it custom attributes etc. You can copy the DATA part of a summon command including surrounding
# curly braces to a .txt file, for instance for: "/summon Skeleton x y z {DATA}"

#######################################################################
# +-----------------------------------------------------------------+ #
# |                            BO3 checks                           | #
# +-----------------------------------------------------------------+ #
#######################################################################

# Require a condition at a certain location in order for the BO3 to be spawned.
# BlockCheck(x,y,z,BlockName[,BlockName[,...]]) - one of the blocks must be at the location
# BlockCheckNot(x,y,z,BlockName[,BlockName[,...]]) - all the blocks must not be at the location
# LightCheck(x,y,z,minLightLevel,maxLightLevel) - light must be between min and max (inclusive)

# You can use "Solid" as a BlockName for matching all solid blocks or "All" to match all blocks that aren't air.

# Examples:
#   BlockCheck(0,-1,0,GRASS,DIRT)  Require grass or dirt just below the object
#   BlockCheck(0,-1,0,Solid)       Require any solid block just below the object
#   BlockCheck(0,-1,0,WOOL)        Require any type of wool just below the object
#   BlockCheck(0,-1,0,WOOL:0)      Require white wool just below the object
#   BlockCheckNot(0,-1,0,WOOL:0)   Require that there is no white wool below the object
#   LightCheck(0,0,0,0,LEAVES:3)          Require almost complete darkness just below the object

