#######################################################################
# +-----------------------------------------------------------------+ #
# |                            BO3 object                           | #
# +-----------------------------------------------------------------+ #
#######################################################################

# The descriptions in this file are accurate only for TerrainControl and OTG.
# For MCW and OTG+ these descriptions are only accurate if the BO3 is used as a CustomObject.
# MCW and OTG+ completely reimplemented CustomStructure, check the MCW/OTG+ documentation for more information.

# This is the config file of a custom object.
# If you add this object correctly to your BiomeConfigs, it will spawn in the world.

# This is the creator of this BO3 object
Author: Unknown

# A short description of this BO3 object
Description: This BO3 was converted from a schematic using OTGEdit. The author and description information of the schematic could not be found. If you know who the author of the schematic is then please add this information.

# The BO3 version, don't change this! It can be used by external applications to do a version check.
Version: 3

# The settings mode, WriteAll, WriteWithoutComments or WriteDisable. See WorldConfig.
SettingsMode: WriteDisable

#######################################################################
# +-----------------------------------------------------------------+ #
# |                          Main settings                          | #
# +-----------------------------------------------------------------+ #
#######################################################################

# This needs to be set to true to spawn the object in the Tree and Sapling resources.
Tree: true

# The frequency of the BO3 from 1 to 200. Tries this many times to spawn this BO3 when using the CustomObject(...) resource.
# Ignored by Tree(..), Sapling(..) and CustomStructure(..)
Frequency: 1

# The rarity of the BO3 from 0 to 100. Each spawn attempt has rarity% chance to succeed when using the CustomObject(...) resource.
# Ignored by Tree(..), Sapling(..) and CustomStructure(..)
Rarity: 100.0

# If you set this to true, the BO3 will be placed with a random rotation.
RotateRandomly: false

# The spawn height of the BO3 - randomY, highestBlock or highestSolidBlock.
SpawnHeight: highestBlock

# The height limits for the BO3.
MinHeight: 64

MaxHeight: 80

# Objects can have other objects attached to it: branches. Branches can also
# have branches attached to it, which can also have branches, etc. This is the
# maximum branch depth for this objects.
MaxBranchDepth: 10

# When spawned with the UseWorld keyword, this BO3 should NOT spawn in the following biomes.
# If you writer.write the BO3 name directly in the BiomeConfigs, this will be ignored.
ExcludedBiomes: All

# To optimise this BO3 for faster loading times you can use Notepad++ to find/replace comments and abbreviate things.
# Notepad++ find/replace with regex:
# Find: ^[#;].* replace to nothing removes all lines starting with # 
# Find: ^\s*$ replace to nothing removes most empty lines 
# Notepad++ find/replace without regex:
# *Warning: This will only work for OTG 1.10.2 v21 / OTG 1.11.2 v6 or higher. B( is not recognised by lower versions.
# Find: Block( replace to B(

#######################################################################
# +-----------------------------------------------------------------+ #
# |                      Source block settings                      | #
# +-----------------------------------------------------------------+ #
#######################################################################

# The block(s) the BO3 should spawn in.
SourceBlocks: STONE:1,STONE:3,STONE:5,DIRT:1,DIRT,SAND,GRASS,DIRT:2,STATIONARY_WATER,HARD_CLAY,STAINED_CLAY,CLAY,SANDSTONE,SAND:1,AIR,STONE,GRAVEL,LONG_GRASS,LONG_GRASS:1,LONG_GRASS:2,DEAD_BUSH,YELLOW_FLOWER,RED_ROSE,BROWN_MUSHROOM,RED_MUSHROOM

# The maximum percentage of the BO3 that can be outside the SourceBlock.
# The BO3 won't be placed on a location with more blocks outside the SourceBlock than this percentage.
MaxPercentageOutsideSourceBlock: 0

# What to do when a block is about to be placed outside the SourceBlock? (dontPlace, placeAnyway)
OutsideSourceBlock: placeAnyway

#######################################################################
# +-----------------------------------------------------------------+ #
# |                              Blocks                             | #
# +-----------------------------------------------------------------+ #
#######################################################################

# All the blocks used in the BO3 are listed here. Possible blocks:
# Block(x,y,z,id[.data][,nbtfile.nbt) or B(x,y,z,id[.data][,nbtfile.nbt)
# RandomBlock(x,y,z,id[:data][,nbtfile.nbt],chance[,id[:data][,nbtfile.nbt],chance[,...]])
# So RandomBlock(0,0,0,CHEST,chest.nbt,50,CHEST,anotherchest.nbt,100) will spawn a chest at
# the BO3 origin, and give it a 50% chance to have the contents of chest.nbt, or, if that
# fails, a 100% percent chance to have the contents of anotherchest.nbt.

Block(-21,32,4,LEAVES:3)
Block(-21,33,4,LEAVES:3)
Block(-20,32,3,LEAVES:3)
Block(-20,33,3,LEAVES:3)
Block(-20,33,4,LEAVES:3)
Block(-20,33,5,LEAVES:3)
Block(-20,34,4,LEAVES:3)
Block(-19,32,5,LEAVES:3)
Block(-19,33,3,LEAVES:3)
Block(-19,33,4,LEAVES:3)
Block(-19,33,5,LEAVES:3)
Block(-19,33,6,LEAVES:3)
Block(-19,34,4,LEAVES:3)
Block(-19,34,5,LEAVES:3)
Block(-18,31,2,LEAVES:3)
Block(-18,32,2,LEAVES:3)
Block(-18,32,3,LEAVES:3)
Block(-18,32,6,LEAVES:3)
Block(-18,33,2,LEAVES:3)
Block(-18,33,3,LEAVES:3)
Block(-18,33,4,17:15)
Block(-18,33,5,LEAVES:3)
Block(-18,34,3,LEAVES:3)
Block(-18,34,4,LEAVES:3)
Block(-18,35,4,LEAVES:3)
Block(-17,31,-1,LEAVES:3)
Block(-17,31,0,LEAVES:3)
Block(-17,31,4,LEAVES:3)
Block(-17,32,-2,LEAVES:3)
Block(-17,32,1,LEAVES:3)
Block(-17,32,2,LEAVES:3)
Block(-17,32,3,LEAVES:3)
Block(-17,32,4,17:15)
Block(-17,32,5,LEAVES:3)
Block(-17,32,6,LEAVES:3)
Block(-17,33,2,LEAVES:3)
Block(-17,33,3,LEAVES:3)
Block(-17,33,4,LEAVES:3)
Block(-17,33,5,LEAVES:3)
Block(-17,34,4,LEAVES:3)
Block(-17,79,-2,LEAVES:3)
Block(-17,80,-2,LEAVES:3)
Block(-16,31,-3,LEAVES:3)
Block(-16,31,1,LEAVES:3)
Block(-16,31,3,LEAVES:3)
Block(-16,31,6,LEAVES:3)
Block(-16,32,-3,LEAVES:3)
Block(-16,32,-2,LEAVES:3)
Block(-16,32,-1,LEAVES:3)
Block(-16,32,0,LEAVES:3)
Block(-16,32,1,LEAVES:3)
Block(-16,32,2,LEAVES:3)
Block(-16,32,3,17:15)
Block(-16,32,4,LEAVES:3)
Block(-16,32,5,LEAVES:3)
Block(-16,33,-7,LEAVES:3)
Block(-16,33,-2,LEAVES:3)
Block(-16,33,1,LEAVES:3)
Block(-16,33,2,LEAVES:3)
Block(-16,33,3,LEAVES:3)
Block(-16,33,4,LEAVES:3)
Block(-16,34,3,LEAVES:3)
Block(-16,79,-4,LEAVES:3)
Block(-16,80,-3,LEAVES:3)
Block(-16,80,-2,LEAVES:3)
Block(-16,80,-1,LEAVES:3)
Block(-16,81,-2,LEAVES:3)
Block(-15,31,-4,LEAVES:3)
Block(-15,31,-2,LEAVES:3)
Block(-15,31,1,LEAVES:3)
Block(-15,31,10,LEAVES:3)
Block(-15,32,-7,LEAVES:3)
Block(-15,32,-3,LEAVES:3)
Block(-15,32,-2,LEAVES:3)
Block(-15,32,-1,LEAVES:3)
Block(-15,32,1,LEAVES:3)
Block(-15,32,2,LEAVES:3)
Block(-15,32,3,17:15)
Block(-15,32,4,LEAVES:3)
Block(-15,32,5,LEAVES:3)
Block(-15,32,9,LEAVES:3)
Block(-15,33,-8,LEAVES:3)
Block(-15,33,-7,LEAVES:3)
Block(-15,33,-6,LEAVES:3)
Block(-15,33,-2,LEAVES:3)
Block(-15,33,-1,LEAVES:3)
Block(-15,33,3,LEAVES:3)
Block(-15,33,4,LEAVES:3)
Block(-15,34,-7,LEAVES:3)
Block(-15,34,-2,LEAVES:3)
Block(-15,48,5,LEAVES:3)
Block(-15,49,6,LEAVES:3)
Block(-15,67,-2,LEAVES:3)
Block(-15,78,1,LEAVES:3)
Block(-15,79,-2,LEAVES:3)
Block(-15,79,0,LEAVES:3)
Block(-15,79,1,LEAVES:3)
Block(-15,79,6,LEAVES:3)
Block(-15,80,-4,LEAVES:3)
Block(-15,80,-3,LEAVES:3)
Block(-15,80,-2,LEAVES:3)
Block(-15,80,-1,LEAVES:3)
Block(-15,80,7,LEAVES:3)
Block(-15,81,-3,LEAVES:3)
Block(-15,81,-2,LEAVES:3)
Block(-14,30,-3,LEAVES:3)
Block(-14,30,6,LEAVES:3)
Block(-14,30,8,LEAVES:3)
Block(-14,31,0,LEAVES:3)
Block(-14,31,2,17:15)
Block(-14,31,3,LEAVES:3)
Block(-14,31,4,LEAVES:3)
Block(-14,31,6,LEAVES:3)
Block(-14,31,8,LEAVES:3)
Block(-14,31,9,LEAVES:3)
Block(-14,32,-9,LEAVES:3)
Block(-14,32,-6,LEAVES:3)
Block(-14,32,-4,LEAVES:3)
Block(-14,32,-3,LEAVES:3)
Block(-14,32,-2,17:15)
Block(-14,32,-1,LEAVES:3)
Block(-14,32,1,LEAVES:3)
Block(-14,32,2,LEAVES:3)
Block(-14,32,3,LEAVES:3)
Block(-14,32,4,LEAVES:3)
Block(-14,32,9,LEAVES:3)
Block(-14,32,10,LEAVES:3)
Block(-14,33,-9,LEAVES:3)
Block(-14,33,-8,LEAVES:3)
Block(-14,33,-7,17:15)
Block(-14,33,-6,LEAVES:3)
Block(-14,33,-2,LEAVES:3)
Block(-14,33,2,LEAVES:3)
Block(-14,33,9,LEAVES:3)
Block(-14,34,-8,LEAVES:3)
Block(-14,34,-7,LEAVES:3)
Block(-14,35,-7,LEAVES:3)
Block(-14,48,7,LEAVES:3)
Block(-14,49,5,LEAVES:3)
Block(-14,49,6,LEAVES:3)
Block(-14,49,7,LEAVES:3)
Block(-14,50,6,LEAVES:3)
Block(-14,67,-2,LEAVES:3)
Block(-14,68,-2,LEAVES:3)
Block(-14,78,-4,LEAVES:3)
Block(-14,79,-3,LEAVES:3)
Block(-14,79,0,LEAVES:3)
Block(-14,79,1,LEAVES:3)
Block(-14,79,2,LEAVES:3)
Block(-14,79,8,LEAVES:3)
Block(-14,80,-3,LEAVES:3)
Block(-14,80,-2,17:15)
Block(-14,80,-1,LEAVES:3)
Block(-14,80,1,LEAVES:3)
Block(-14,80,2,LEAVES:3)
Block(-14,80,6,LEAVES:3)
Block(-14,80,7,LEAVES:3)
Block(-14,80,8,LEAVES:3)
Block(-14,81,-2,LEAVES:3)
Block(-14,81,-1,LEAVES:3)
Block(-14,81,7,LEAVES:3)
Block(-14,82,-2,LEAVES:3)
Block(-13,30,5,LEAVES:3)
Block(-13,31,-5,LEAVES:3)
Block(-13,31,-3,LEAVES:3)
Block(-13,31,-1,LEAVES:3)
Block(-13,31,1,17:15)
Block(-13,31,2,17:15)
Block(-13,31,4,LEAVES:3)
Block(-13,31,6,LEAVES:3)
Block(-13,31,7,LEAVES:3)
Block(-13,31,8,17:15)
Block(-13,31,11,LEAVES:3)
Block(-13,32,-7,LEAVES:3)
Block(-13,32,-6,17:15)
Block(-13,32,-5,LEAVES:3)
Block(-13,32,-4,LEAVES:3)
Block(-13,32,-3,17:15)
Block(-13,32,-2,LEAVES:3)
Block(-13,32,-1,LEAVES:3)
Block(-13,32,0,LEAVES:3)
Block(-13,32,1,LEAVES:3)
Block(-13,32,2,LEAVES:3)
Block(-13,32,3,LEAVES:3)
Block(-13,32,6,LEAVES:3)
Block(-13,32,8,LEAVES:3)
Block(-13,32,9,17:15)
Block(-13,32,10,LEAVES:3)
Block(-13,32,11,LEAVES:3)
Block(-13,33,-8,LEAVES:3)
Block(-13,33,-6,LEAVES:3)
Block(-13,33,-4,LEAVES:3)
Block(-13,33,-3,LEAVES:3)
Block(-13,33,1,LEAVES:3)
Block(-13,33,2,LEAVES:3)
Block(-13,33,9,LEAVES:3)
Block(-13,33,10,LEAVES:3)
Block(-13,34,-7,LEAVES:3)
Block(-13,48,6,LEAVES:3)
Block(-13,49,5,LEAVES:3)
Block(-13,49,6,LEAVES:3)
Block(-13,49,7,LEAVES:3)
Block(-13,50,5,LEAVES:3)
Block(-13,50,6,LEAVES:3)
Block(-13,50,7,LEAVES:3)
Block(-13,67,-3,LEAVES:3)
Block(-13,67,-2,17:15)
Block(-13,78,-3,LEAVES:3)
Block(-13,78,2,LEAVES:3)
Block(-13,79,-4,LEAVES:3)
Block(-13,79,-3,LEAVES:3)
Block(-13,79,-2,17:15)
Block(-13,79,0,LEAVES:3)
Block(-13,79,1,17:15)
Block(-13,79,2,LEAVES:3)
Block(-13,79,4,LEAVES:3)
Block(-13,79,6,LEAVES:3)
Block(-13,80,-3,LEAVES:3)
Block(-13,80,-2,LEAVES:3)
Block(-13,80,-1,LEAVES:3)
Block(-13,80,0,LEAVES:3)
Block(-13,80,1,LEAVES:3)
Block(-13,80,2,LEAVES:3)
Block(-13,80,3,LEAVES:3)
Block(-13,80,7,17:15)
Block(-13,80,8,LEAVES:3)
Block(-13,80,9,LEAVES:3)
Block(-13,81,-2,LEAVES:3)
Block(-13,81,-1,LEAVES:3)
Block(-13,81,2,LEAVES:3)
Block(-13,81,6,LEAVES:3)
Block(-13,81,7,LEAVES:3)
Block(-13,81,8,LEAVES:3)
Block(-12,29,6,LEAVES:3)
Block(-12,30,-2,LEAVES:3)
Block(-12,30,7,LEAVES:3)
Block(-12,31,-3,17:15)
Block(-12,31,0,LEAVES:3)
Block(-12,31,1,17:15)
Block(-12,31,3,LEAVES:3)
Block(-12,31,4,LEAVES:3)
Block(-12,31,5,LEAVES:3)
Block(-12,31,6,17:15)
Block(-12,31,7,LEAVES:3)
Block(-12,31,8,17:15)
Block(-12,31,9,LEAVES:3)
Block(-12,32,-10,LEAVES:3)
Block(-12,32,-8,LEAVES:3)
Block(-12,32,-7,LEAVES:3)
Block(-12,32,-6,17:15)
Block(-12,32,-5,LEAVES:3)
Block(-12,32,-4,LEAVES:3)
Block(-12,32,-3,LEAVES:3)
Block(-12,32,-2,LEAVES:3)
Block(-12,32,1,LEAVES:3)
Block(-12,32,2,17:15)
Block(-12,32,3,LEAVES:3)
Block(-12,32,4,LEAVES:3)
Block(-12,32,6,LEAVES:3)
Block(-12,32,8,LEAVES:3)
Block(-12,32,9,LEAVES:3)
Block(-12,32,10,LEAVES:3)
Block(-12,33,-9,LEAVES:3)
Block(-12,33,-8,LEAVES:3)
Block(-12,33,-7,LEAVES:3)
Block(-12,33,-6,LEAVES:3)
Block(-12,33,-5,LEAVES:3)
Block(-12,33,-3,LEAVES:3)
Block(-12,33,-2,LEAVES:3)
Block(-12,33,2,LEAVES:3)
Block(-12,34,-8,LEAVES:3)
Block(-12,34,-6,LEAVES:3)
Block(-12,34,2,LEAVES:3)
Block(-12,47,8,LEAVES:3)
Block(-12,48,4,LEAVES:3)
Block(-12,48,8,LEAVES:3)
Block(-12,48,10,LEAVES:3)
Block(-12,49,4,LEAVES:3)
Block(-12,49,5,LEAVES:3)
Block(-12,49,6,17:15)
Block(-12,49,7,LEAVES:3)
Block(-12,49,11,LEAVES:3)
Block(-12,50,5,LEAVES:3)
Block(-12,50,6,LEAVES:3)
Block(-12,50,7,LEAVES:3)
Block(-12,51,-4,LEAVES:3)
Block(-12,52,-4,LEAVES:3)
Block(-12,67,-4,LEAVES:3)
Block(-12,67,-3,LEAVES:3)
Block(-12,67,-2,17:15)
Block(-12,67,-1,LEAVES:3)
Block(-12,67,2,LEAVES:3)
Block(-12,68,-3,LEAVES:3)
Block(-12,78,0,LEAVES:3)
Block(-12,79,-3,LEAVES:3)
Block(-12,79,-2,LEAVES:3)
Block(-12,79,-1,17:15)
Block(-12,79,0,17:15)
Block(-12,79,1,LEAVES:3)
Block(-12,79,2,LEAVES:3)
Block(-12,79,4,LEAVES:3)
Block(-12,79,7,LEAVES:3)
Block(-12,79,9,LEAVES:3)
Block(-12,80,-2,LEAVES:3)
Block(-12,80,-1,LEAVES:3)
Block(-12,80,0,LEAVES:3)
Block(-12,80,1,LEAVES:3)
Block(-12,80,2,LEAVES:3)
Block(-12,80,3,17:15)
Block(-12,80,4,LEAVES:3)
Block(-12,80,5,LEAVES:3)
Block(-12,80,6,17:15)
Block(-12,80,7,LEAVES:3)
Block(-12,80,8,LEAVES:3)
Block(-12,81,-2,LEAVES:3)
Block(-12,81,-1,LEAVES:3)
Block(-12,81,0,LEAVES:3)
Block(-12,81,1,LEAVES:3)
Block(-12,81,2,LEAVES:3)
Block(-12,81,3,LEAVES:3)
Block(-12,81,5,LEAVES:3)
Block(-12,81,6,LEAVES:3)
Block(-12,81,7,LEAVES:3)
Block(-12,82,-1,LEAVES:3)
Block(-12,82,2,LEAVES:3)
Block(-12,82,6,LEAVES:3)
Block(-11,30,3,LEAVES:3)
Block(-11,30,5,LEAVES:3)
Block(-11,30,9,LEAVES:3)
Block(-11,31,-6,LEAVES:3)
Block(-11,31,-4,17:15)
Block(-11,31,-3,17:15)
Block(-11,31,-2,LEAVES:3)
Block(-11,31,-1,LEAVES:3)
Block(-11,31,0,LEAVES:3)
Block(-11,31,1,17:15)
Block(-11,31,2,LEAVES:3)
Block(-11,31,3,17:15)
Block(-11,31,4,LEAVES:3)
Block(-11,31,5,LEAVES:3)
Block(-11,31,6,LEAVES:3)
Block(-11,31,7,17:15)
Block(-11,31,8,LEAVES:3)
Block(-11,32,-6,17:15)
Block(-11,32,-5,17:15)
Block(-11,32,-4,17:15)
Block(-11,32,-3,LEAVES:3)
Block(-11,32,-2,LEAVES:3)
Block(-11,32,0,LEAVES:3)
Block(-11,32,1,LEAVES:3)
Block(-11,32,2,LEAVES:3)
Block(-11,32,3,LEAVES:3)
Block(-11,32,4,LEAVES:3)
Block(-11,32,5,LEAVES:3)
Block(-11,32,6,LEAVES:3)
Block(-11,32,7,LEAVES:3)
Block(-11,32,8,LEAVES:3)
Block(-11,33,-10,LEAVES:3)
Block(-11,33,-9,LEAVES:3)
Block(-11,33,-8,LEAVES:3)
Block(-11,33,-7,17:15)
Block(-11,33,-6,17:15)
Block(-11,33,-5,LEAVES:3)
Block(-11,33,-4,LEAVES:3)
Block(-11,33,2,LEAVES:3)
Block(-11,33,4,LEAVES:3)
Block(-11,33,7,LEAVES:3)
Block(-11,34,-9,LEAVES:3)
Block(-11,34,-8,LEAVES:3)
Block(-11,34,-7,LEAVES:3)
Block(-11,34,-6,LEAVES:3)
Block(-11,34,-5,LEAVES:3)
Block(-11,35,-8,LEAVES:3)
Block(-11,35,-6,LEAVES:3)
Block(-11,47,10,LEAVES:3)
Block(-11,48,7,LEAVES:3)
Block(-11,48,8,LEAVES:3)
Block(-11,48,9,LEAVES:3)
Block(-11,48,12,LEAVES:3)
Block(-11,49,5,LEAVES:3)
Block(-11,49,6,LEAVES:3)
Block(-11,49,7,17:15)
Block(-11,49,8,LEAVES:3)
Block(-11,49,10,LEAVES:3)
Block(-11,49,11,LEAVES:3)
Block(-11,49,12,LEAVES:3)
Block(-11,50,6,LEAVES:3)
Block(-11,50,7,LEAVES:3)
Block(-11,50,11,LEAVES:3)
Block(-11,51,-6,LEAVES:3)
Block(-11,51,7,LEAVES:3)
Block(-11,52,-5,LEAVES:3)
Block(-11,52,-4,LEAVES:3)
Block(-11,52,-3,LEAVES:3)
Block(-11,53,-4,LEAVES:3)
Block(-11,66,-2,17:15)
Block(-11,67,2,LEAVES:3)
Block(-11,67,3,LEAVES:3)
Block(-11,68,2,LEAVES:3)
Block(-11,78,-3,LEAVES:3)
Block(-11,78,-1,17:15)
Block(-11,78,2,LEAVES:3)
Block(-11,79,-4,LEAVES:3)
Block(-11,79,-1,LEAVES:3)
Block(-11,79,0,LEAVES:3)
Block(-11,79,1,LEAVES:3)
Block(-11,79,2,LEAVES:3)
Block(-11,79,4,17:15)
Block(-11,79,5,17:15)
Block(-11,79,6,LEAVES:3)
Block(-11,80,-3,LEAVES:3)
Block(-11,80,0,LEAVES:3)
Block(-11,80,1,LEAVES:3)
Block(-11,80,2,LEAVES:3)
Block(-11,80,3,LEAVES:3)
Block(-11,80,4,LEAVES:3)
Block(-11,80,5,LEAVES:3)
Block(-11,80,6,LEAVES:3)
Block(-11,80,7,LEAVES:3)
Block(-11,81,-2,LEAVES:3)
Block(-11,81,-1,LEAVES:3)
Block(-11,81,0,LEAVES:3)
Block(-11,81,1,LEAVES:3)
Block(-11,81,4,LEAVES:3)
Block(-11,81,6,LEAVES:3)
Block(-11,82,-1,LEAVES:3)
Block(-11,82,0,LEAVES:3)
Block(-10,30,-3,LEAVES:3)
Block(-10,30,-2,17:15)
Block(-10,30,1,17:15)
Block(-10,30,5,LEAVES:3)
Block(-10,30,6,LEAVES:3)
Block(-10,30,8,LEAVES:3)
Block(-10,30,11,LEAVES:3)
Block(-10,31,-3,LEAVES:3)
Block(-10,31,-2,17:15)
Block(-10,31,-1,LEAVES:3)
Block(-10,31,0,LEAVES:3)
Block(-10,31,1,17:15)
Block(-10,31,2,LEAVES:3)
Block(-10,31,3,LEAVES:3)
Block(-10,31,4,17:15)
Block(-10,31,5,LEAVES:3)
Block(-10,31,6,17:15)
Block(-10,31,7,17:15)
Block(-10,31,8,LEAVES:3)
Block(-10,31,9,LEAVES:3)
Block(-10,31,10,LEAVES:3)
Block(-10,31,13,LEAVES:3)
Block(-10,32,-8,LEAVES:3)
Block(-10,32,-5,17:15)
Block(-10,32,0,LEAVES:3)
Block(-10,32,1,LEAVES:3)
Block(-10,32,4,LEAVES:3)
Block(-10,32,6,LEAVES:3)
Block(-10,32,7,LEAVES:3)
Block(-10,32,8,LEAVES:3)
Block(-10,32,12,LEAVES:3)
Block(-10,33,-11,LEAVES:3)
Block(-10,33,-9,LEAVES:3)
Block(-10,33,-8,17:15)
Block(-10,33,-7,LEAVES:3)
Block(-10,33,-6,LEAVES:3)
Block(-10,33,-5,LEAVES:3)
Block(-10,33,1,LEAVES:3)
Block(-10,33,7,LEAVES:3)
Block(-10,34,-11,LEAVES:3)
Block(-10,34,-10,LEAVES:3)
Block(-10,34,-9,LEAVES:3)
Block(-10,34,-8,LEAVES:3)
Block(-10,34,-6,LEAVES:3)
Block(-10,47,4,LEAVES:3)
Block(-10,47,8,LEAVES:3)
Block(-10,48,6,LEAVES:3)
Block(-10,48,8,17:15)
Block(-10,48,10,LEAVES:3)
Block(-10,49,7,LEAVES:3)
Block(-10,49,8,LEAVES:3)
Block(-10,49,9,LEAVES:3)
Block(-10,49,10,LEAVES:3)
Block(-10,49,11,LEAVES:3)
Block(-10,49,12,LEAVES:3)
Block(-10,50,-1,LEAVES:3)
Block(-10,50,7,LEAVES:3)
Block(-10,50,8,LEAVES:3)
Block(-10,50,11,LEAVES:3)
Block(-10,50,12,LEAVES:3)
Block(-10,51,-4,LEAVES:3)
Block(-10,51,-2,LEAVES:3)
Block(-10,51,-1,LEAVES:3)
Block(-10,51,11,LEAVES:3)
Block(-10,52,-6,LEAVES:3)
Block(-10,52,-5,LEAVES:3)
Block(-10,52,-4,LEAVES:3)
Block(-10,52,-3,LEAVES:3)
Block(-10,53,-5,LEAVES:3)
Block(-10,53,-4,LEAVES:3)
Block(-10,61,9,LEAVES:3)
Block(-10,62,8,LEAVES:3)
Block(-10,66,-5,LEAVES:3)
Block(-10,66,-4,LEAVES:3)
Block(-10,66,-3,17:15)
Block(-10,67,-4,LEAVES:3)
Block(-10,67,2,17:15)
Block(-10,73,7,LEAVES:3)
Block(-10,78,-1,17:15)
Block(-10,78,4,LEAVES:3)
Block(-10,78,5,17:15)
Block(-10,79,-6,LEAVES:3)
Block(-10,79,0,LEAVES:3)
Block(-10,79,5,17:15)
Block(-10,79,6,LEAVES:3)
Block(-10,79,7,LEAVES:3)
Block(-10,80,-6,LEAVES:3)
Block(-10,80,-4,LEAVES:3)
Block(-10,80,-3,LEAVES:3)
Block(-10,80,-2,LEAVES:3)
Block(-10,80,4,LEAVES:3)
Block(-10,80,5,LEAVES:3)
Block(-10,80,6,LEAVES:3)
Block(-10,80,9,LEAVES:3)
Block(-10,81,-3,LEAVES:3)
Block(-10,81,-2,LEAVES:3)
Block(-10,81,-1,17:15)
Block(-10,81,0,LEAVES:3)
Block(-10,81,8,LEAVES:3)
Block(-10,82,-1,LEAVES:3)
Block(-10,83,-1,LEAVES:3)
Block(-9,29,-2,LEAVES:3)
Block(-9,29,1,LEAVES:3)
Block(-9,29,4,LEAVES:3)
Block(-9,30,-4,LEAVES:3)
Block(-9,30,-2,17:15)
Block(-9,30,-1,17:15)
Block(-9,30,0,17:15)
Block(-9,30,2,LEAVES:3)
Block(-9,30,4,17:15)
Block(-9,30,5,17:15)
Block(-9,30,6,17:15)
Block(-9,30,7,LEAVES:3)
Block(-9,30,8,LEAVES:3)
Block(-9,30,10,LEAVES:3)
Block(-9,31,-3,LEAVES:3)
Block(-9,31,-2,LEAVES:3)
Block(-9,31,1,LEAVES:3)
Block(-9,31,2,LEAVES:3)
Block(-9,31,3,LEAVES:3)
Block(-9,31,4,17:15)
Block(-9,31,5,LEAVES:3)
Block(-9,31,6,LEAVES:3)
Block(-9,31,7,LEAVES:3)
Block(-9,31,8,LEAVES:3)
Block(-9,31,9,LEAVES:3)
Block(-9,31,10,LEAVES:3)
Block(-9,31,11,LEAVES:3)
Block(-9,32,-6,LEAVES:3)
Block(-9,32,-5,LEAVES:3)
Block(-9,32,-4,LEAVES:3)
Block(-9,32,-2,LEAVES:3)
Block(-9,32,0,LEAVES:3)
Block(-9,32,1,LEAVES:3)
Block(-9,32,3,LEAVES:3)
Block(-9,32,4,LEAVES:3)
Block(-9,32,5,LEAVES:3)
Block(-9,32,10,LEAVES:3)
Block(-9,32,11,LEAVES:3)
Block(-9,32,12,LEAVES:3)
Block(-9,32,13,LEAVES:3)
Block(-9,33,-8,LEAVES:3)
Block(-9,33,-7,LEAVES:3)
Block(-9,33,-6,LEAVES:3)
Block(-9,33,-5,LEAVES:3)
Block(-9,33,4,LEAVES:3)
Block(-9,33,12,LEAVES:3)
Block(-9,34,-12,LEAVES:3)
Block(-9,34,-11,LEAVES:3)
Block(-9,34,-10,LEAVES:3)
Block(-9,34,-9,17:15)
Block(-9,34,-8,LEAVES:3)
Block(-9,35,-11,LEAVES:3)
Block(-9,35,-10,LEAVES:3)
Block(-9,35,-9,LEAVES:3)
Block(-9,35,-8,LEAVES:3)
Block(-9,36,-9,LEAVES:3)
Block(-9,47,4,LEAVES:3)
Block(-9,48,7,LEAVES:3)
Block(-9,48,9,17:15)
Block(-9,48,11,LEAVES:3)
Block(-9,48,13,LEAVES:3)
Block(-9,49,8,LEAVES:3)
Block(-9,49,9,LEAVES:3)
Block(-9,49,10,LEAVES:3)
Block(-9,49,11,17:15)
Block(-9,49,12,LEAVES:3)
Block(-9,49,13,LEAVES:3)
Block(-9,50,-6,LEAVES:3)
Block(-9,50,11,LEAVES:3)
Block(-9,50,12,LEAVES:3)
Block(-9,51,-5,LEAVES:3)
Block(-9,51,-2,LEAVES:3)
Block(-9,51,-1,LEAVES:3)
Block(-9,51,0,LEAVES:3)
Block(-9,52,-5,LEAVES:3)
Block(-9,52,-4,17:15)
Block(-9,52,-3,LEAVES:3)
Block(-9,52,-1,LEAVES:3)
Block(-9,53,-4,LEAVES:3)
Block(-9,53,-3,LEAVES:3)
Block(-9,54,-4,LEAVES:3)
Block(-9,59,2,LEAVES:3)
Block(-9,60,3,LEAVES:3)
Block(-9,61,8,LEAVES:3)
Block(-9,62,7,LEAVES:3)
Block(-9,62,8,LEAVES:3)
Block(-9,62,9,LEAVES:3)
Block(-9,63,8,LEAVES:3)
Block(-9,64,8,LEAVES:3)
Block(-9,66,-4,17:15)
Block(-9,66,-2,LEAVES:3)
Block(-9,66,-1,LEAVES:3)
Block(-9,66,0,17:15)
Block(-9,66,3,LEAVES:3)
Block(-9,67,-2,LEAVES:3)
Block(-9,67,1,17:15)
Block(-9,72,7,LEAVES:3)
Block(-9,72,9,LEAVES:3)
Block(-9,73,6,LEAVES:3)
Block(-9,73,7,LEAVES:3)
Block(-9,73,8,LEAVES:3)
Block(-9,74,7,LEAVES:3)
Block(-9,78,-2,17:15)
Block(-9,78,5,17:15)
Block(-9,79,-4,LEAVES:3)
Block(-9,79,-2,LEAVES:3)
Block(-9,79,0,LEAVES:3)
Block(-9,79,2,LEAVES:3)
Block(-9,79,4,LEAVES:3)
Block(-9,79,5,17:15)
Block(-9,79,6,LEAVES:3)
Block(-9,80,-7,LEAVES:3)
Block(-9,80,-6,LEAVES:3)
Block(-9,80,-5,LEAVES:3)
Block(-9,80,-4,LEAVES:3)
Block(-9,80,-3,LEAVES:3)
Block(-9,80,-2,17:15)
Block(-9,80,-1,LEAVES:3)
Block(-9,80,0,LEAVES:3)
Block(-9,80,5,LEAVES:3)
Block(-9,81,-6,LEAVES:3)
Block(-9,81,-4,LEAVES:3)
Block(-9,81,-3,LEAVES:3)
Block(-9,81,-2,LEAVES:3)
Block(-9,81,-1,LEAVES:3)
Block(-9,81,7,LEAVES:3)
Block(-9,81,8,LEAVES:3)
Block(-9,81,9,LEAVES:3)
Block(-9,82,-3,LEAVES:3)
Block(-9,82,-1,LEAVES:3)
Block(-9,82,8,LEAVES:3)
Block(-8,-6,5,17:15)
Block(-8,-5,5,17:15)
Block(-8,-4,5,17:15)
Block(-8,-3,5,17:15)
Block(-8,-2,5,17:15)
Block(-8,-1,5,17:15)
Block(-8,30,-1,17:15)
Block(-8,30,0,17:15)
Block(-8,30,1,LEAVES:3)
Block(-8,30,2,LEAVES:3)
Block(-8,30,3,17:15)
Block(-8,30,4,17:15)
Block(-8,30,5,LEAVES:3)
Block(-8,31,-8,LEAVES:3)
Block(-8,31,-6,LEAVES:3)
Block(-8,31,-4,LEAVES:3)
Block(-8,31,-3,LEAVES:3)
Block(-8,31,-2,LEAVES:3)
Block(-8,31,-1,17:15)
Block(-8,31,0,LEAVES:3)
Block(-8,31,2,LEAVES:3)
Block(-8,31,3,LEAVES:3)
Block(-8,31,4,LEAVES:3)
Block(-8,31,5,LEAVES:3)
Block(-8,31,9,LEAVES:3)
Block(-8,31,10,17:15)
Block(-8,31,12,LEAVES:3)
Block(-8,31,14,LEAVES:3)
Block(-8,32,-9,LEAVES:3)
Block(-8,32,-8,LEAVES:3)
Block(-8,32,-7,LEAVES:3)
Block(-8,32,-5,LEAVES:3)
Block(-8,32,-3,LEAVES:3)
Block(-8,32,-2,LEAVES:3)
Block(-8,32,-1,LEAVES:3)
Block(-8,32,0,LEAVES:3)
Block(-8,32,1,LEAVES:3)
Block(-8,32,4,LEAVES:3)
Block(-8,32,9,LEAVES:3)
Block(-8,32,10,LEAVES:3)
Block(-8,32,11,17:15)
Block(-8,32,12,LEAVES:3)
Block(-8,32,13,LEAVES:3)
Block(-8,32,14,LEAVES:3)
Block(-8,33,-12,LEAVES:3)
Block(-8,33,-10,LEAVES:3)
Block(-8,33,-8,LEAVES:3)
Block(-8,33,-7,LEAVES:3)
Block(-8,33,-2,LEAVES:3)
Block(-8,33,0,LEAVES:3)
Block(-8,33,10,LEAVES:3)
Block(-8,33,11,LEAVES:3)
Block(-8,33,12,LEAVES:3)
Block(-8,33,13,LEAVES:3)
Block(-8,34,-11,LEAVES:3)
Block(-8,34,-10,LEAVES:3)
Block(-8,34,-9,LEAVES:3)
Block(-8,34,11,LEAVES:3)
Block(-8,35,-10,LEAVES:3)
Block(-8,47,3,LEAVES:3)
Block(-8,47,4,17:15)
Block(-8,48,4,LEAVES:3)
Block(-8,48,8,LEAVES:3)
Block(-8,48,9,17:15)
Block(-8,49,8,LEAVES:3)
Block(-8,49,9,LEAVES:3)
Block(-8,49,10,17:15)
Block(-8,49,11,LEAVES:3)
Block(-8,49,12,LEAVES:3)
Block(-8,50,-5,LEAVES:3)
Block(-8,50,0,LEAVES:3)
Block(-8,50,10,LEAVES:3)
Block(-8,51,-6,LEAVES:3)
Block(-8,51,-5,LEAVES:3)
Block(-8,51,-4,17:15)
Block(-8,51,-2,LEAVES:3)
Block(-8,51,-1,17:15)
Block(-8,51,0,LEAVES:3)
Block(-8,52,-5,LEAVES:3)
Block(-8,52,-4,LEAVES:3)
Block(-8,52,-3,LEAVES:3)
Block(-8,52,-1,LEAVES:3)
Block(-8,52,0,LEAVES:3)
Block(-8,53,-4,LEAVES:3)
Block(-8,59,4,LEAVES:3)
Block(-8,60,1,LEAVES:3)
Block(-8,60,2,LEAVES:3)
Block(-8,60,3,LEAVES:3)
Block(-8,60,4,LEAVES:3)
Block(-8,61,2,LEAVES:3)
Block(-8,61,3,LEAVES:3)
Block(-8,61,9,LEAVES:3)
Block(-8,62,7,LEAVES:3)
Block(-8,62,8,LEAVES:3)
Block(-8,62,9,LEAVES:3)
Block(-8,63,7,LEAVES:3)
Block(-8,63,8,LEAVES:3)
Block(-8,63,9,LEAVES:3)
Block(-8,63,13,LEAVES:3)
Block(-8,66,-5,17:15)
Block(-8,66,-3,17:15)
Block(-8,66,-2,17:15)
Block(-8,66,-1,17:15)
Block(-8,66,3,17:15)
Block(-8,66,4,LEAVES:3)
Block(-8,67,-8,LEAVES:3)
Block(-8,67,-7,LEAVES:3)
Block(-8,67,-6,17:15)
Block(-8,67,-1,LEAVES:3)
Block(-8,67,3,LEAVES:3)
Block(-8,68,-6,LEAVES:3)
Block(-8,68,-1,LEAVES:3)
Block(-8,71,4,LEAVES:3)
Block(-8,72,3,LEAVES:3)
Block(-8,72,5,LEAVES:3)
Block(-8,72,11,LEAVES:3)
Block(-8,73,5,LEAVES:3)
Block(-8,73,6,LEAVES:3)
Block(-8,73,7,LEAVES:3)
Block(-8,73,8,LEAVES:3)
Block(-8,73,9,LEAVES:3)
Block(-8,73,10,LEAVES:3)
Block(-8,74,7,LEAVES:3)
Block(-8,78,-2,17:15)
Block(-8,79,-7,LEAVES:3)
Block(-8,79,-5,LEAVES:3)
Block(-8,79,-4,LEAVES:3)
Block(-8,79,3,LEAVES:3)
Block(-8,79,4,17:15)
Block(-8,79,5,LEAVES:3)
Block(-8,80,-8,LEAVES:3)
Block(-8,80,-7,LEAVES:3)
Block(-8,80,-6,17:15)
Block(-8,80,-4,LEAVES:3)
Block(-8,80,-3,17:15)
Block(-8,80,-2,LEAVES:3)
Block(-8,80,-1,LEAVES:3)
Block(-8,80,2,LEAVES:3)
Block(-8,80,4,LEAVES:3)
Block(-8,80,7,LEAVES:3)
Block(-8,80,9,LEAVES:3)
Block(-8,81,-7,LEAVES:3)
Block(-8,81,-6,LEAVES:3)
Block(-8,81,-5,LEAVES:3)
Block(-8,81,-3,LEAVES:3)
Block(-8,81,7,LEAVES:3)
Block(-8,81,8,LEAVES:3)
Block(-8,81,9,LEAVES:3)
Block(-8,81,10,LEAVES:3)
Block(-8,82,-6,LEAVES:3)
Block(-8,82,8,LEAVES:3)
Block(-8,82,9,LEAVES:3)
Block(-8,83,8,LEAVES:3)
Block(-7,-6,0,17:15)
Block(-7,-6,3,17:15)
Block(-7,-6,4,17:15)
Block(-7,-5,0,17:15)
Block(-7,-5,3,17:15)
Block(-7,-4,0,17:15)
Block(-7,-4,3,17:15)
Block(-7,-4,4,17:15)
Block(-7,-3,0,17:15)
Block(-7,-3,2,17:15)
Block(-7,-3,3,17:15)
Block(-7,-3,4,17:15)
Block(-7,-2,0,17:15)
Block(-7,-2,2,17:15)
Block(-7,-2,3,17:15)
Block(-7,-2,4,17:15)
Block(-7,-1,2,17:15)
Block(-7,-1,3,17:15)
Block(-7,-1,4,17:15)
Block(-7,0,2,17:15)
Block(-7,0,4,17:15)
Block(-7,1,2,17:15)
Block(-7,29,0,17:15)
Block(-7,29,1,17:15)
Block(-7,29,6,17:15)
Block(-7,30,0,17:15)
Block(-7,30,2,LEAVES:3)
Block(-7,30,4,17:15)
Block(-7,30,7,17:15)
Block(-7,30,8,17:15)
Block(-7,31,-10,LEAVES:3)
Block(-7,31,-4,LEAVES:3)
Block(-7,31,-3,LEAVES:3)
Block(-7,31,-2,LEAVES:3)
Block(-7,31,-1,LEAVES:3)
Block(-7,31,4,LEAVES:3)
Block(-7,31,8,LEAVES:3)
Block(-7,31,9,17:15)
Block(-7,32,-10,LEAVES:3)
Block(-7,32,-9,LEAVES:3)
Block(-7,32,-8,17:15)
Block(-7,32,-7,LEAVES:3)
Block(-7,32,-6,LEAVES:3)
Block(-7,32,-2,LEAVES:3)
Block(-7,32,-1,17:15)
Block(-7,32,0,LEAVES:3)
Block(-7,32,1,LEAVES:3)
Block(-7,32,2,LEAVES:3)
Block(-7,32,9,LEAVES:3)
Block(-7,32,10,LEAVES:3)
Block(-7,32,11,LEAVES:3)
Block(-7,32,12,LEAVES:3)
Block(-7,32,13,LEAVES:3)
Block(-7,33,-9,LEAVES:3)
Block(-7,33,-8,LEAVES:3)
Block(-7,33,-2,LEAVES:3)
Block(-7,33,-1,LEAVES:3)
Block(-7,33,0,LEAVES:3)
Block(-7,33,1,LEAVES:3)
Block(-7,33,11,LEAVES:3)
Block(-7,34,-10,LEAVES:3)
Block(-7,34,-1,LEAVES:3)
Block(-7,46,4,17:15)
Block(-7,47,6,LEAVES:3)
Block(-7,47,7,LEAVES:3)
Block(-7,47,8,17:15)
Block(-7,47,9,17:15)
Block(-7,48,7,LEAVES:3)
Block(-7,48,9,17:15)
Block(-7,49,9,LEAVES:3)
Block(-7,49,10,LEAVES:3)
Block(-7,49,14,LEAVES:3)
Block(-7,50,-2,LEAVES:3)
Block(-7,51,-5,LEAVES:3)
Block(-7,51,-4,LEAVES:3)
Block(-7,51,-3,17:15)
Block(-7,51,-2,17:15)
Block(-7,51,-1,LEAVES:3)
Block(-7,51,0,LEAVES:3)
Block(-7,52,-4,LEAVES:3)
Block(-7,52,-3,LEAVES:3)
Block(-7,52,-2,LEAVES:3)
Block(-7,52,0,LEAVES:3)
Block(-7,59,2,LEAVES:3)
Block(-7,60,0,LEAVES:3)
Block(-7,60,1,LEAVES:3)
Block(-7,60,2,LEAVES:3)
Block(-7,60,3,17:15)
Block(-7,60,4,LEAVES:3)
Block(-7,60,7,LEAVES:3)
Block(-7,60,9,LEAVES:3)
Block(-7,61,1,LEAVES:3)
Block(-7,61,2,LEAVES:3)
Block(-7,61,3,LEAVES:3)
Block(-7,61,4,LEAVES:3)
Block(-7,61,6,LEAVES:3)
Block(-7,61,7,LEAVES:3)
Block(-7,61,10,LEAVES:3)
Block(-7,62,2,LEAVES:3)
Block(-7,62,7,LEAVES:3)
Block(-7,62,8,17:15)
Block(-7,62,9,LEAVES:3)
Block(-7,62,10,LEAVES:3)
Block(-7,62,11,LEAVES:3)
Block(-7,62,13,LEAVES:3)
Block(-7,62,15,LEAVES:3)
Block(-7,63,8,LEAVES:3)
Block(-7,63,9,LEAVES:3)
Block(-7,63,12,LEAVES:3)
Block(-7,63,13,LEAVES:3)
Block(-7,63,14,LEAVES:3)
Block(-7,64,12,LEAVES:3)
Block(-7,64,13,LEAVES:3)
Block(-7,64,14,LEAVES:3)
Block(-7,65,-2,17:15)
Block(-7,65,2,17:15)
Block(-7,66,-2,17:15)
Block(-7,67,-7,LEAVES:3)
Block(-7,69,-1,LEAVES:3)
Block(-7,71,3,LEAVES:3)
Block(-7,72,2,LEAVES:3)
Block(-7,72,3,LEAVES:3)
Block(-7,72,4,LEAVES:3)
Block(-7,72,7,LEAVES:3)
Block(-7,72,10,LEAVES:3)
Block(-7,73,3,LEAVES:3)
Block(-7,73,5,LEAVES:3)
Block(-7,73,6,LEAVES:3)
Block(-7,73,7,17:15)
Block(-7,73,8,LEAVES:3)
Block(-7,73,9,LEAVES:3)
Block(-7,73,10,LEAVES:3)
Block(-7,73,11,LEAVES:3)
Block(-7,74,6,LEAVES:3)
Block(-7,74,7,LEAVES:3)
Block(-7,74,10,LEAVES:3)
Block(-7,75,7,LEAVES:3)
Block(-7,77,-2,17:15)
Block(-7,78,-3,LEAVES:3)
Block(-7,78,0,LEAVES:3)
Block(-7,78,2,LEAVES:3)
Block(-7,78,12,LEAVES:3)
Block(-7,79,-6,LEAVES:3)
Block(-7,79,-5,17:15)
Block(-7,79,-4,17:15)
Block(-7,79,-3,17:15)
Block(-7,79,-1,LEAVES:3)
Block(-7,79,1,LEAVES:3)
Block(-7,79,3,LEAVES:3)
Block(-7,79,4,17:15)
Block(-7,79,5,LEAVES:3)
Block(-7,80,-7,LEAVES:3)
Block(-7,80,-6,LEAVES:3)
Block(-7,80,-5,LEAVES:3)
Block(-7,80,-4,LEAVES:3)
Block(-7,80,-3,17:15)
Block(-7,80,-2,LEAVES:3)
Block(-7,80,-1,LEAVES:3)
Block(-7,80,1,LEAVES:3)
Block(-7,80,2,LEAVES:3)
Block(-7,80,3,LEAVES:3)
Block(-7,80,4,LEAVES:3)
Block(-7,80,5,LEAVES:3)
Block(-7,81,-4,LEAVES:3)
Block(-7,81,-3,LEAVES:3)
Block(-7,81,-2,LEAVES:3)
Block(-7,81,2,LEAVES:3)
Block(-7,81,4,LEAVES:3)
Block(-7,81,7,LEAVES:3)
Block(-7,81,8,17:15)
Block(-7,81,9,LEAVES:3)
Block(-7,82,-3,LEAVES:3)
Block(-7,82,8,LEAVES:3)
Block(-6,-6,7,17:15)
Block(-6,-5,6,17:15)
Block(-6,-5,7,17:15)
Block(-6,-4,0,17:15)
Block(-6,-4,6,17:15)
Block(-6,-4,7,17:15)
Block(-6,-3,0,17:15)
Block(-6,-3,1,17:15)
Block(-6,-3,6,17:15)
Block(-6,-3,7,17:15)
Block(-6,-2,0,17:15)
Block(-6,-2,2,17:15)
Block(-6,-2,4,17:15)
Block(-6,-2,6,17:15)
Block(-6,-2,7,17:15)
Block(-6,-1,0,17:15)
Block(-6,-1,1,17:15)
Block(-6,-1,2,17:15)
Block(-6,-1,4,17:15)
Block(-6,-1,6,17:15)
Block(-6,0,0,17:15)
Block(-6,0,2,17:15)
Block(-6,0,3,17:15)
Block(-6,0,4,17:15)
Block(-6,1,0,17:15)
Block(-6,1,2,17:15)
Block(-6,1,3,17:15)
Block(-6,1,4,17:15)
Block(-6,2,2,17:15)
Block(-6,2,3,17:15)
Block(-6,2,4,17:15)
Block(-6,3,3,17:15)
Block(-6,28,1,17:15)
Block(-6,29,-1,17:15)
Block(-6,29,1,17:15)
Block(-6,29,2,17:15)
Block(-6,29,4,17:15)
Block(-6,29,5,17:15)
Block(-6,30,-4,LEAVES:3)
Block(-6,30,-2,17:15)
Block(-6,30,0,LEAVES:3)
Block(-6,30,4,17:15)
Block(-6,30,6,17:15)
Block(-6,30,9,LEAVES:3)
Block(-6,31,-7,LEAVES:3)
Block(-6,31,-4,LEAVES:3)
Block(-6,31,-3,LEAVES:3)
Block(-6,31,-2,LEAVES:3)
Block(-6,31,1,LEAVES:3)
Block(-6,31,5,LEAVES:3)
Block(-6,31,7,LEAVES:3)
Block(-6,31,8,LEAVES:3)
Block(-6,31,9,17:15)
Block(-6,31,10,LEAVES:3)
Block(-6,31,11,LEAVES:3)
Block(-6,31,12,LEAVES:3)
Block(-6,32,-10,LEAVES:3)
Block(-6,32,-9,LEAVES:3)
Block(-6,32,-8,LEAVES:3)
Block(-6,32,-7,17:15)
Block(-6,32,-6,LEAVES:3)
Block(-6,32,-5,LEAVES:3)
Block(-6,32,1,LEAVES:3)
Block(-6,32,8,LEAVES:3)
Block(-6,32,9,LEAVES:3)
Block(-6,33,-7,LEAVES:3)
Block(-6,33,-6,LEAVES:3)
Block(-6,33,-1,LEAVES:3)
Block(-6,33,0,17:15)
Block(-6,33,1,LEAVES:3)
Block(-6,33,2,LEAVES:3)
Block(-6,34,0,LEAVES:3)
Block(-6,34,1,LEAVES:3)
Block(-6,35,0,LEAVES:3)
Block(-6,46,5,17:15)
Block(-6,47,7,17:15)
Block(-6,47,8,17:15)
Block(-6,49,-11,LEAVES:3)
Block(-6,49,-9,LEAVES:3)
Block(-6,49,12,17:15)
Block(-6,49,13,17:15)
Block(-6,49,14,LEAVES:3)
Block(-6,49,15,LEAVES:3)
Block(-6,50,-12,LEAVES:3)
Block(-6,50,-11,LEAVES:3)
Block(-6,50,-10,LEAVES:3)
Block(-6,50,-5,LEAVES:3)
Block(-6,50,-3,17:15)
Block(-6,50,0,LEAVES:3)
Block(-6,50,13,LEAVES:3)
Block(-6,51,-11,LEAVES:3)
Block(-6,51,-10,LEAVES:3)
Block(-6,51,-3,LEAVES:3)
Block(-6,51,-2,LEAVES:3)
Block(-6,51,-1,LEAVES:3)
Block(-6,52,-2,LEAVES:3)
Block(-6,58,2,LEAVES:3)
Block(-6,59,0,LEAVES:3)
Block(-6,59,5,LEAVES:3)
Block(-6,60,1,LEAVES:3)
Block(-6,60,2,LEAVES:3)
Block(-6,60,3,LEAVES:3)
Block(-6,60,4,17:15)
Block(-6,60,5,LEAVES:3)
Block(-6,61,2,LEAVES:3)
Block(-6,61,3,LEAVES:3)
Block(-6,61,4,LEAVES:3)
Block(-6,61,5,LEAVES:3)
Block(-6,61,6,LEAVES:3)
Block(-6,61,7,LEAVES:3)
Block(-6,61,8,17:15)
Block(-6,61,14,LEAVES:3)
Block(-6,62,4,LEAVES:3)
Block(-6,62,6,LEAVES:3)
Block(-6,62,7,LEAVES:3)
Block(-6,62,8,LEAVES:3)
Block(-6,62,9,LEAVES:3)
Block(-6,62,10,LEAVES:3)
Block(-6,62,11,LEAVES:3)
Block(-6,63,7,LEAVES:3)
Block(-6,63,10,LEAVES:3)
Block(-6,63,12,17:15)
Block(-6,63,13,LEAVES:3)
Block(-6,63,14,LEAVES:3)
Block(-6,63,15,LEAVES:3)
Block(-6,64,11,LEAVES:3)
Block(-6,64,12,LEAVES:3)
Block(-6,64,13,LEAVES:3)
Block(-6,65,-4,LEAVES:3)
Block(-6,65,-3,LEAVES:3)
Block(-6,65,-2,17:15)
Block(-6,65,-1,17:15)
Block(-6,65,2,17:15)
Block(-6,65,3,17:15)
Block(-6,65,5,LEAVES:3)
Block(-6,65,12,LEAVES:3)
Block(-6,66,-3,LEAVES:3)
Block(-6,66,0,LEAVES:3)
Block(-6,66,2,LEAVES:3)
Block(-6,69,-3,LEAVES:3)
Block(-6,69,-2,LEAVES:3)
Block(-6,69,-1,17:15)
Block(-6,70,-2,LEAVES:3)
Block(-6,71,2,LEAVES:3)
Block(-6,71,6,LEAVES:3)
Block(-6,72,1,LEAVES:3)
Block(-6,72,2,LEAVES:3)
Block(-6,72,3,LEAVES:3)
Block(-6,72,4,LEAVES:3)
Block(-6,72,6,LEAVES:3)
Block(-6,72,7,17:15)
Block(-6,72,8,LEAVES:3)
Block(-6,72,12,LEAVES:3)
Block(-6,73,2,LEAVES:3)
Block(-6,73,3,LEAVES:3)
Block(-6,73,7,LEAVES:3)
Block(-6,73,9,LEAVES:3)
Block(-6,73,10,17:15)
Block(-6,73,11,LEAVES:3)
Block(-6,73,12,LEAVES:3)
Block(-6,74,7,LEAVES:3)
Block(-6,74,10,LEAVES:3)
Block(-6,74,11,LEAVES:3)
Block(-6,77,-2,17:15)
Block(-6,77,-1,17:15)
Block(-6,77,10,LEAVES:3)
Block(-6,77,12,LEAVES:3)
Block(-6,78,10,LEAVES:3)
Block(-6,78,11,LEAVES:3)
Block(-6,78,12,LEAVES:3)
Block(-6,78,13,LEAVES:3)
Block(-6,79,-4,LEAVES:3)
Block(-6,79,-3,17:15)
Block(-6,79,-2,17:15)
Block(-6,79,-1,LEAVES:3)
Block(-6,79,0,LEAVES:3)
Block(-6,79,2,LEAVES:3)
Block(-6,79,3,17:15)
Block(-6,79,4,LEAVES:3)
Block(-6,79,6,LEAVES:3)
Block(-6,79,11,LEAVES:3)
Block(-6,79,12,LEAVES:3)
Block(-6,80,-4,LEAVES:3)
Block(-6,80,-3,LEAVES:3)
Block(-6,80,-2,LEAVES:3)
Block(-6,80,-1,LEAVES:3)
Block(-6,80,0,LEAVES:3)
Block(-6,80,1,LEAVES:3)
Block(-6,80,2,17:15)
Block(-6,80,3,LEAVES:3)
Block(-6,80,4,LEAVES:3)
Block(-6,80,7,17:15)
Block(-6,80,8,LEAVES:3)
Block(-6,80,9,LEAVES:3)
Block(-6,81,-3,LEAVES:3)
Block(-6,81,1,LEAVES:3)
Block(-6,81,2,LEAVES:3)
Block(-6,81,6,LEAVES:3)
Block(-6,81,7,LEAVES:3)
Block(-6,81,8,LEAVES:3)
Block(-6,82,7,LEAVES:3)
Block(-5,-6,3,17:15)
Block(-5,-5,3,17:15)
Block(-5,-4,-1,17:15)
Block(-5,-4,2,17:15)
Block(-5,-4,3,17:15)
Block(-5,-4,6,17:15)
Block(-5,-3,-1,17:15)
Block(-5,-3,1,17:15)
Block(-5,-3,2,17:15)
Block(-5,-3,3,17:15)
Block(-5,-3,6,17:15)
Block(-5,-2,-1,17:15)
Block(-5,-2,1,17:15)
Block(-5,-2,2,17:15)
Block(-5,-2,6,17:15)
Block(-5,-1,-1,17:15)
Block(-5,-1,1,17:15)
Block(-5,-1,2,17:15)
Block(-5,-1,6,17:15)
Block(-5,0,-1,17:15)
Block(-5,0,1,17:15)
Block(-5,0,4,17:15)
Block(-5,0,6,17:15)
Block(-5,1,1,17:15)
Block(-5,1,3,17:15)
Block(-5,1,4,17:15)
Block(-5,2,3,17:15)
Block(-5,2,4,17:15)
Block(-5,3,3,17:15)
Block(-5,3,4,17:15)
Block(-5,4,3,17:15)
Block(-5,28,2,17:15)
Block(-5,29,-4,LEAVES:3)
Block(-5,29,2,17:15)
Block(-5,29,3,17:15)
Block(-5,30,-5,LEAVES:3)
Block(-5,30,-4,17:15)
Block(-5,30,-3,17:15)
Block(-5,30,-2,LEAVES:3)
Block(-5,30,-1,LEAVES:3)
Block(-5,30,3,LEAVES:3)
Block(-5,30,6,17:15)
Block(-5,30,8,LEAVES:3)
Block(-5,30,12,LEAVES:3)
Block(-5,31,-6,17:15)
Block(-5,31,-5,17:15)
Block(-5,31,-4,17:15)
Block(-5,31,-3,LEAVES:3)
Block(-5,31,-2,LEAVES:3)
Block(-5,31,-1,LEAVES:3)
Block(-5,31,4,LEAVES:3)
Block(-5,31,5,LEAVES:3)
Block(-5,31,6,LEAVES:3)
Block(-5,31,8,LEAVES:3)
Block(-5,31,9,LEAVES:3)
Block(-5,31,10,17:15)
Block(-5,31,11,LEAVES:3)
Block(-5,31,12,LEAVES:3)
Block(-5,32,-7,17:15)
Block(-5,32,-6,LEAVES:3)
Block(-5,32,-4,LEAVES:3)
Block(-5,32,-2,LEAVES:3)
Block(-5,32,-1,LEAVES:3)
Block(-5,32,1,LEAVES:3)
Block(-5,32,5,LEAVES:3)
Block(-5,32,10,LEAVES:3)
Block(-5,32,11,LEAVES:3)
Block(-5,33,-11,LEAVES:3)
Block(-5,33,-10,LEAVES:3)
Block(-5,33,-9,LEAVES:3)
Block(-5,33,-8,LEAVES:3)
Block(-5,33,-7,LEAVES:3)
Block(-5,33,0,LEAVES:3)
Block(-5,33,1,17:15)
Block(-5,33,2,LEAVES:3)
Block(-5,33,3,LEAVES:3)
Block(-5,34,-9,LEAVES:3)
Block(-5,34,1,LEAVES:3)
Block(-5,34,2,LEAVES:3)
Block(-5,46,4,LEAVES:3)
Block(-5,46,6,17:15)
Block(-5,47,6,17:15)
Block(-5,47,7,17:15)
Block(-5,48,6,LEAVES:3)
Block(-5,48,11,17:15)
Block(-5,49,-13,LEAVES:3)
Block(-5,49,-6,LEAVES:3)
Block(-5,50,-13,LEAVES:3)
Block(-5,50,-12,LEAVES:3)
Block(-5,50,-11,17:15)
Block(-5,50,-10,LEAVES:3)
Block(-5,50,-9,LEAVES:3)
Block(-5,50,-8,LEAVES:3)
Block(-5,50,-7,LEAVES:3)
Block(-5,50,-4,LEAVES:3)
Block(-5,50,-3,17:15)
Block(-5,50,-2,LEAVES:3)
Block(-5,51,-12,LEAVES:3)
Block(-5,51,-11,LEAVES:3)
Block(-5,51,-9,LEAVES:3)
Block(-5,51,-2,LEAVES:3)
Block(-5,59,3,LEAVES:3)
Block(-5,59,4,17:15)
Block(-5,60,4,LEAVES:3)
Block(-5,60,5,LEAVES:3)
Block(-5,60,9,LEAVES:3)
Block(-5,61,4,LEAVES:3)
Block(-5,61,6,LEAVES:3)
Block(-5,61,7,LEAVES:3)
Block(-5,61,8,17:15)
Block(-5,61,9,LEAVES:3)
Block(-5,61,13,LEAVES:3)
Block(-5,62,7,LEAVES:3)
Block(-5,62,8,LEAVES:3)
Block(-5,62,10,17:15)
Block(-5,62,11,17:15)
Block(-5,62,12,LEAVES:3)
Block(-5,62,14,LEAVES:3)
Block(-5,63,10,LEAVES:3)
Block(-5,63,11,LEAVES:3)
Block(-5,63,12,LEAVES:3)
Block(-5,63,13,LEAVES:3)
Block(-5,63,14,LEAVES:3)
Block(-5,64,0,17:15)
Block(-5,64,1,17:15)
Block(-5,64,12,LEAVES:3)
Block(-5,65,-1,17:15)
Block(-5,65,0,17:15)
Block(-5,65,4,17:15)
Block(-5,65,5,17:15)
Block(-5,65,6,LEAVES:3)
Block(-5,65,7,LEAVES:3)
Block(-5,66,0,LEAVES:3)
Block(-5,66,1,LEAVES:3)
Block(-5,66,4,LEAVES:3)
Block(-5,66,6,LEAVES:3)
Block(-5,67,0,LEAVES:3)
Block(-5,68,-1,17:15)
Block(-5,68,3,17:15)
Block(-5,71,3,LEAVES:3)
Block(-5,71,6,LEAVES:3)
Block(-5,71,8,LEAVES:3)
Block(-5,72,2,LEAVES:3)
Block(-5,72,3,17:15)
Block(-5,72,4,LEAVES:3)
Block(-5,72,5,LEAVES:3)
Block(-5,72,6,LEAVES:3)
Block(-5,72,8,17:15)
Block(-5,72,10,LEAVES:3)
Block(-5,72,11,LEAVES:3)
Block(-5,73,2,LEAVES:3)
Block(-5,73,3,LEAVES:3)
Block(-5,73,6,LEAVES:3)
Block(-5,73,8,LEAVES:3)
Block(-5,73,9,17:15)
Block(-5,73,10,LEAVES:3)
Block(-5,73,11,LEAVES:3)
Block(-5,74,8,LEAVES:3)
Block(-5,74,9,LEAVES:3)
Block(-5,75,9,LEAVES:3)
Block(-5,77,-1,17:15)
Block(-5,77,11,LEAVES:3)
Block(-5,77,13,LEAVES:3)
Block(-5,78,-9,LEAVES:3)
Block(-5,78,-6,LEAVES:3)
Block(-5,78,-3,17:15)
Block(-5,78,2,17:15)
Block(-5,78,3,17:15)
Block(-5,78,4,17:15)
Block(-5,78,9,LEAVES:3)
Block(-5,78,10,17:15)
Block(-5,78,11,17:15)
Block(-5,78,12,LEAVES:3)
Block(-5,78,13,LEAVES:3)
Block(-5,78,14,LEAVES:3)
Block(-5,79,-8,LEAVES:3)
Block(-5,79,-3,17:15)
Block(-5,79,-1,LEAVES:3)
Block(-5,79,1,LEAVES:3)
Block(-5,79,3,LEAVES:3)
Block(-5,79,4,17:15)
Block(-5,79,5,17:15)
Block(-5,79,6,17:15)
Block(-5,79,10,LEAVES:3)
Block(-5,79,11,LEAVES:3)
Block(-5,79,12,LEAVES:3)
Block(-5,79,13,LEAVES:3)
Block(-5,80,-3,LEAVES:3)
Block(-5,80,1,LEAVES:3)
Block(-5,80,2,LEAVES:3)
Block(-5,80,6,17:15)
Block(-5,80,7,17:15)
Block(-5,81,6,LEAVES:3)
Block(-5,81,7,LEAVES:3)
Block(-5,81,8,LEAVES:3)
Block(-5,82,8,LEAVES:3)
Block(-4,-6,-2,17:15)
Block(-4,-6,2,17:15)
Block(-4,-6,4,17:15)
Block(-4,-5,-2,17:15)
Block(-4,-5,-1,17:15)
Block(-4,-5,2,17:15)
Block(-4,-5,4,17:15)
Block(-4,-4,-2,17:15)
Block(-4,-4,-1,17:15)
Block(-4,-4,2,17:15)
Block(-4,-4,4,17:15)
Block(-4,-3,-2,17:15)
Block(-4,-3,-1,17:15)
Block(-4,-3,2,17:15)
Block(-4,-3,4,17:15)
Block(-4,-3,5,17:15)
Block(-4,-3,6,17:15)
Block(-4,-2,-2,17:15)
Block(-4,-2,-1,17:15)
Block(-4,-2,1,17:15)
Block(-4,-2,2,17:15)
Block(-4,-2,5,17:15)
Block(-4,-2,6,17:15)
Block(-4,-1,-1,17:15)
Block(-4,-1,1,17:15)
Block(-4,-1,5,17:15)
Block(-4,-1,6,17:15)
Block(-4,0,1,17:15)
Block(-4,0,5,17:15)
Block(-4,0,6,17:15)
Block(-4,1,1,17:15)
Block(-4,1,2,17:15)
Block(-4,1,3,17:15)
Block(-4,1,5,17:15)
Block(-4,1,6,17:15)
Block(-4,2,1,17:15)
Block(-4,2,2,17:15)
Block(-4,2,3,17:15)
Block(-4,2,5,17:15)
Block(-4,3,1,17:15)
Block(-4,3,2,17:15)
Block(-4,3,3,17:15)
Block(-4,4,1,17:15)
Block(-4,4,2,17:15)
Block(-4,4,3,17:15)
Block(-4,5,2,17:15)
Block(-4,5,3,17:15)
Block(-4,6,2,17:15)
Block(-4,6,3,17:15)
Block(-4,7,2,17:15)
Block(-4,8,2,17:15)
Block(-4,9,2,17:15)
Block(-4,10,2,17:15)
Block(-4,11,2,17:15)
Block(-4,12,2,17:15)
Block(-4,28,2,17:15)
Block(-4,29,-1,LEAVES:3)
Block(-4,29,2,17:15)
Block(-4,30,-3,LEAVES:3)
Block(-4,30,-2,LEAVES:3)
Block(-4,30,-1,LEAVES:3)
Block(-4,30,5,LEAVES:3)
Block(-4,30,8,LEAVES:3)
Block(-4,30,10,LEAVES:3)
Block(-4,31,-5,LEAVES:3)
Block(-4,31,-4,LEAVES:3)
Block(-4,31,-3,LEAVES:3)
Block(-4,31,-2,LEAVES:3)
Block(-4,31,3,LEAVES:3)
Block(-4,31,4,LEAVES:3)
Block(-4,31,5,17:15)
Block(-4,31,6,17:15)
Block(-4,31,7,LEAVES:3)
Block(-4,31,8,LEAVES:3)
Block(-4,31,9,LEAVES:3)
Block(-4,31,10,LEAVES:3)
Block(-4,31,11,LEAVES:3)
Block(-4,32,-12,LEAVES:3)
Block(-4,32,-10,LEAVES:3)
Block(-4,32,-8,17:15)
Block(-4,32,-7,LEAVES:3)
Block(-4,32,-4,LEAVES:3)
Block(-4,32,0,LEAVES:3)
Block(-4,32,3,LEAVES:3)
Block(-4,32,5,LEAVES:3)
Block(-4,32,6,LEAVES:3)
Block(-4,32,7,LEAVES:3)
Block(-4,32,9,LEAVES:3)
Block(-4,32,10,LEAVES:3)
Block(-4,33,-12,LEAVES:3)
Block(-4,33,-11,LEAVES:3)
Block(-4,33,-10,LEAVES:3)
Block(-4,33,-9,17:15)
Block(-4,33,-8,LEAVES:3)
Block(-4,33,-7,LEAVES:3)
Block(-4,33,0,LEAVES:3)
Block(-4,33,1,LEAVES:3)
Block(-4,33,2,LEAVES:3)
Block(-4,34,-11,LEAVES:3)
Block(-4,34,-10,LEAVES:3)
Block(-4,34,-9,LEAVES:3)
Block(-4,34,-8,LEAVES:3)
Block(-4,34,1,LEAVES:3)
Block(-4,35,-9,LEAVES:3)
Block(-4,46,4,LEAVES:3)
Block(-4,46,5,17:15)
Block(-4,46,6,17:15)
Block(-4,47,4,LEAVES:3)
Block(-4,47,7,17:15)
Block(-4,47,8,17:15)
Block(-4,47,9,17:15)
Block(-4,48,-3,LEAVES:3)
Block(-4,48,7,17:15)
Block(-4,48,11,17:15)
Block(-4,48,12,LEAVES:3)
Block(-4,49,-10,LEAVES:3)
Block(-4,49,-4,LEAVES:3)
Block(-4,49,-3,17:15)
Block(-4,49,-2,LEAVES:3)
Block(-4,49,0,LEAVES:3)
Block(-4,49,7,LEAVES:3)
Block(-4,50,-13,LEAVES:3)
Block(-4,50,-12,LEAVES:3)
Block(-4,50,-11,LEAVES:3)
Block(-4,50,-10,17:15)
Block(-4,50,-9,LEAVES:3)
Block(-4,50,-8,LEAVES:3)
Block(-4,50,-7,LEAVES:3)
Block(-4,50,-6,LEAVES:3)
Block(-4,50,-5,LEAVES:3)
Block(-4,50,-3,LEAVES:3)
Block(-4,50,-2,LEAVES:3)
Block(-4,50,-1,LEAVES:3)
Block(-4,50,0,LEAVES:3)
Block(-4,51,-10,LEAVES:3)
Block(-4,51,-9,LEAVES:3)
Block(-4,51,-8,LEAVES:3)
Block(-4,51,-7,LEAVES:3)
Block(-4,51,-2,LEAVES:3)
Block(-4,52,-9,LEAVES:3)
Block(-4,59,4,LEAVES:3)
Block(-4,59,5,17:15)
Block(-4,60,4,LEAVES:3)
Block(-4,60,5,LEAVES:3)
Block(-4,60,6,LEAVES:3)
Block(-4,61,5,LEAVES:3)
Block(-4,61,7,LEAVES:3)
Block(-4,61,8,LEAVES:3)
Block(-4,61,9,17:15)
Block(-4,61,10,17:15)
Block(-4,62,9,LEAVES:3)
Block(-4,62,10,17:15)
Block(-4,62,11,LEAVES:3)
Block(-4,62,12,LEAVES:3)
Block(-4,63,10,LEAVES:3)
Block(-4,63,11,LEAVES:3)
Block(-4,63,12,LEAVES:3)
Block(-4,64,0,17:15)
Block(-4,64,11,LEAVES:3)
Block(-4,65,-3,17:15)
Block(-4,65,-2,17:15)
Block(-4,65,0,17:15)
Block(-4,66,-3,17:15)
Block(-4,66,1,17:15)
Block(-4,66,6,17:15)
Block(-4,67,0,17:15)
Block(-4,67,2,17:15)
Block(-4,71,2,LEAVES:3)
Block(-4,71,5,LEAVES:3)
Block(-4,71,7,17:15)
Block(-4,72,2,LEAVES:3)
Block(-4,72,3,17:15)
Block(-4,72,4,LEAVES:3)
Block(-4,72,5,LEAVES:3)
Block(-4,72,6,LEAVES:3)
Block(-4,72,7,17:15)
Block(-4,72,8,LEAVES:3)
Block(-4,72,9,LEAVES:3)
Block(-4,73,3,LEAVES:3)
Block(-4,73,4,LEAVES:3)
Block(-4,73,5,LEAVES:3)
Block(-4,73,6,LEAVES:3)
Block(-4,73,7,LEAVES:3)
Block(-4,73,9,LEAVES:3)
Block(-4,73,10,LEAVES:3)
Block(-4,73,11,LEAVES:3)
Block(-4,74,6,LEAVES:3)
Block(-4,74,9,LEAVES:3)
Block(-4,74,10,LEAVES:3)
Block(-4,76,7,LEAVES:3)
Block(-4,77,-1,17:15)
Block(-4,77,0,17:15)
Block(-4,77,8,LEAVES:3)
Block(-4,77,9,LEAVES:3)
Block(-4,77,14,LEAVES:3)
Block(-4,78,-8,LEAVES:3)
Block(-4,78,-3,17:15)
Block(-4,78,-2,17:15)
Block(-4,78,1,17:15)
Block(-4,78,3,17:15)
Block(-4,78,9,17:15)
Block(-4,78,10,LEAVES:3)
Block(-4,78,11,LEAVES:3)
Block(-4,78,12,LEAVES:3)
Block(-4,78,13,LEAVES:3)
Block(-4,79,-9,LEAVES:3)
Block(-4,79,-8,LEAVES:3)
Block(-4,79,-7,LEAVES:3)
Block(-4,79,-6,LEAVES:3)
Block(-4,79,2,LEAVES:3)
Block(-4,79,6,17:15)
Block(-4,79,9,LEAVES:3)
Block(-4,79,10,LEAVES:3)
Block(-4,80,-8,LEAVES:3)
Block(-4,80,5,LEAVES:3)
Block(-4,80,6,LEAVES:3)
Block(-4,80,7,LEAVES:3)
Block(-4,80,9,LEAVES:3)
Block(-4,80,11,LEAVES:3)
Block(-4,81,6,LEAVES:3)
Block(-4,81,7,LEAVES:3)
Block(-4,81,8,17:15)
Block(-4,81,10,LEAVES:3)
Block(-4,82,7,LEAVES:3)
Block(-4,82,8,LEAVES:3)
Block(-4,82,9,LEAVES:3)
Block(-4,83,8,LEAVES:3)
Block(-3,-5,1,17:15)
Block(-3,-5,4,17:15)
Block(-3,-4,0,17:15)
Block(-3,-4,1,17:15)
Block(-3,-4,4,17:15)
Block(-3,-3,0,17:15)
Block(-3,-3,1,17:15)
Block(-3,-3,4,17:15)
Block(-3,-3,5,17:15)
Block(-3,-2,0,17:15)
Block(-3,-2,1,17:15)
Block(-3,-2,3,17:15)
Block(-3,-2,4,17:15)
Block(-3,-1,0,17:15)
Block(-3,-1,1,17:15)
Block(-3,-1,2,17:15)
Block(-3,-1,4,17:15)
Block(-3,-1,5,17:15)
Block(-3,0,0,17:15)
Block(-3,0,1,17:15)
Block(-3,0,2,17:15)
Block(-3,0,3,17:15)
Block(-3,0,4,17:15)
Block(-3,0,5,17:15)
Block(-3,1,0,17:15)
Block(-3,1,1,17:15)
Block(-3,1,2,17:15)
Block(-3,1,4,17:15)
Block(-3,2,0,17:15)
Block(-3,2,1,17:15)
Block(-3,2,2,17:15)
Block(-3,2,4,17:15)
Block(-3,2,5,17:15)
Block(-3,3,0,17:15)
Block(-3,3,1,17:15)
Block(-3,3,2,17:15)
Block(-3,3,3,17:15)
Block(-3,3,4,17:15)
Block(-3,4,1,17:15)
Block(-3,4,2,17:15)
Block(-3,4,3,17:15)
Block(-3,4,4,17:15)
Block(-3,5,1,17:15)
Block(-3,5,2,17:15)
Block(-3,5,3,17:15)
Block(-3,6,1,17:15)
Block(-3,6,2,17:15)
Block(-3,6,3,17:15)
Block(-3,7,1,17:15)
Block(-3,7,2,17:15)
Block(-3,7,3,17:15)
Block(-3,8,1,17:15)
Block(-3,8,2,17:15)
Block(-3,8,3,17:15)
Block(-3,9,1,17:15)
Block(-3,9,2,17:15)
Block(-3,9,3,17:15)
Block(-3,10,1,17:15)
Block(-3,10,2,17:15)
Block(-3,10,3,17:15)
Block(-3,11,1,17:15)
Block(-3,11,2,17:15)
Block(-3,11,3,17:15)
Block(-3,12,1,17:15)
Block(-3,12,2,17:15)
Block(-3,12,3,17:15)
Block(-3,13,1,17:15)
Block(-3,13,2,17:15)
Block(-3,13,3,17:15)
Block(-3,14,1,17:15)
Block(-3,14,2,17:15)
Block(-3,15,1,17:15)
Block(-3,15,2,17:15)
Block(-3,16,1,17:15)
Block(-3,16,2,17:15)
Block(-3,17,1,17:15)
Block(-3,17,2,17:15)
Block(-3,18,1,17:15)
Block(-3,18,2,17:15)
Block(-3,19,1,17:15)
Block(-3,19,2,17:15)
Block(-3,20,1,17:15)
Block(-3,20,2,17:15)
Block(-3,21,1,17:15)
Block(-3,21,2,17:15)
Block(-3,22,1,17:15)
Block(-3,22,2,17:15)
Block(-3,23,1,17:15)
Block(-3,23,2,17:15)
Block(-3,24,1,17:15)
Block(-3,24,2,17:15)
Block(-3,25,1,17:15)
Block(-3,25,2,17:15)
Block(-3,26,2,17:15)
Block(-3,27,2,17:15)
Block(-3,28,2,17:15)
Block(-3,28,3,17:15)
Block(-3,28,6,LEAVES:3)
Block(-3,29,-3,LEAVES:3)
Block(-3,29,2,17:15)
Block(-3,29,3,17:15)
Block(-3,30,-4,LEAVES:3)
Block(-3,30,-2,LEAVES:3)
Block(-3,30,2,17:15)
Block(-3,30,3,LEAVES:3)
Block(-3,30,8,LEAVES:3)
Block(-3,31,-8,LEAVES:3)
Block(-3,31,-6,LEAVES:3)
Block(-3,31,-4,LEAVES:3)
Block(-3,31,2,17:15)
Block(-3,31,3,LEAVES:3)
Block(-3,31,4,17:15)
Block(-3,31,5,LEAVES:3)
Block(-3,31,7,17:15)
Block(-3,31,8,LEAVES:3)
Block(-3,31,9,LEAVES:3)
Block(-3,32,-9,LEAVES:3)
Block(-3,32,-8,LEAVES:3)
Block(-3,32,-7,LEAVES:3)
Block(-3,32,2,LEAVES:3)
Block(-3,32,3,LEAVES:3)
Block(-3,32,4,LEAVES:3)
Block(-3,32,6,LEAVES:3)
Block(-3,32,7,LEAVES:3)
Block(-3,32,8,LEAVES:3)
Block(-3,33,-11,LEAVES:3)
Block(-3,33,-10,LEAVES:3)
Block(-3,33,-9,LEAVES:3)
Block(-3,33,-8,LEAVES:3)
Block(-3,33,1,LEAVES:3)
Block(-3,33,2,17:15)
Block(-3,33,7,LEAVES:3)
Block(-3,34,-10,LEAVES:3)
Block(-3,34,2,17:15)
Block(-3,35,2,17:15)
Block(-3,36,2,17:15)
Block(-3,37,2,17:15)
Block(-3,38,2,17:15)
Block(-3,39,2,17:15)
Block(-3,40,2,17:15)
Block(-3,41,2,17:15)
Block(-3,42,2,17:15)
Block(-3,43,2,17:15)
Block(-3,44,2,17:15)
Block(-3,45,2,17:15)
Block(-3,45,4,17:15)
Block(-3,45,5,17:15)
Block(-3,46,2,17:15)
Block(-3,46,5,17:15)
Block(-3,47,2,17:15)
Block(-3,47,9,17:15)
Block(-3,47,10,17:15)
Block(-3,48,-1,LEAVES:3)
Block(-3,48,2,17:15)
Block(-3,48,7,17:15)
Block(-3,48,9,LEAVES:3)
Block(-3,48,10,17:15)
Block(-3,48,11,17:15)
Block(-3,48,12,17:15)
Block(-3,48,14,LEAVES:3)
Block(-3,49,-9,17:15)
Block(-3,49,-8,17:15)
Block(-3,49,-7,LEAVES:3)
Block(-3,49,-4,17:15)
Block(-3,49,-3,17:15)
Block(-3,49,2,17:15)
Block(-3,49,10,LEAVES:3)
Block(-3,49,13,LEAVES:3)
Block(-3,50,-11,LEAVES:3)
Block(-3,50,-10,17:15)
Block(-3,50,-9,LEAVES:3)
Block(-3,50,-7,17:15)
Block(-3,50,-6,LEAVES:3)
Block(-3,50,-5,LEAVES:3)
Block(-3,50,-4,LEAVES:3)
Block(-3,50,-3,LEAVES:3)
Block(-3,50,-2,17:15)
Block(-3,50,-1,LEAVES:3)
Block(-3,50,0,LEAVES:3)
Block(-3,50,2,17:15)
Block(-3,50,10,LEAVES:3)
Block(-3,51,-14,LEAVES:3)
Block(-3,51,-13,LEAVES:3)
Block(-3,51,-12,LEAVES:3)
Block(-3,51,-11,LEAVES:3)
Block(-3,51,-10,LEAVES:3)
Block(-3,51,-9,LEAVES:3)
Block(-3,51,-8,17:15)
Block(-3,51,-7,LEAVES:3)
Block(-3,51,-6,LEAVES:3)
Block(-3,51,-5,LEAVES:3)
Block(-3,51,-3,LEAVES:3)
Block(-3,51,-2,LEAVES:3)
Block(-3,51,-1,LEAVES:3)
Block(-3,51,2,17:15)
Block(-3,52,-12,LEAVES:3)
Block(-3,52,-10,LEAVES:3)
Block(-3,52,-9,LEAVES:3)
Block(-3,52,-8,LEAVES:3)
Block(-3,52,-7,LEAVES:3)
Block(-3,52,-2,LEAVES:3)
Block(-3,52,2,17:15)
Block(-3,53,-8,LEAVES:3)
Block(-3,53,2,17:15)
Block(-3,54,2,17:15)
Block(-3,55,2,17:15)
Block(-3,56,2,17:15)
Block(-3,57,2,17:15)
Block(-3,57,3,17:15)
Block(-3,57,4,17:15)
Block(-3,58,2,17:15)
Block(-3,58,4,17:15)
Block(-3,58,5,17:15)
Block(-3,59,2,17:15)
Block(-3,59,3,LEAVES:3)
Block(-3,59,5,17:15)
Block(-3,60,2,17:15)
Block(-3,60,4,LEAVES:3)
Block(-3,60,5,LEAVES:3)
Block(-3,60,11,LEAVES:3)
Block(-3,61,2,17:15)
Block(-3,61,6,LEAVES:3)
Block(-3,61,7,LEAVES:3)
Block(-3,61,8,LEAVES:3)
Block(-3,61,9,17:15)
Block(-3,61,11,LEAVES:3)
Block(-3,61,12,LEAVES:3)
Block(-3,62,7,LEAVES:3)
Block(-3,62,10,LEAVES:3)
Block(-3,62,11,LEAVES:3)
Block(-3,62,12,LEAVES:3)
Block(-3,63,11,LEAVES:3)
Block(-3,64,0,17:15)
Block(-3,64,1,17:15)
Block(-3,65,-2,LEAVES:3)
Block(-3,65,1,17:15)
Block(-3,66,-4,17:15)
Block(-3,66,6,LEAVES:3)
Block(-3,66,7,LEAVES:3)
Block(-3,67,-1,LEAVES:3)
Block(-3,67,0,LEAVES:3)
Block(-3,67,6,LEAVES:3)
Block(-3,68,0,LEAVES:3)
Block(-3,69,-7,LEAVES:3)
Block(-3,70,-7,LEAVES:3)
Block(-3,70,6,LEAVES:3)
Block(-3,71,4,LEAVES:3)
Block(-3,71,6,17:15)
Block(-3,71,7,LEAVES:3)
Block(-3,72,3,LEAVES:3)
Block(-3,72,4,17:15)
Block(-3,72,5,17:15)
Block(-3,72,6,LEAVES:3)
Block(-3,72,7,LEAVES:3)
Block(-3,72,8,LEAVES:3)
Block(-3,73,4,LEAVES:3)
Block(-3,73,5,LEAVES:3)
Block(-3,73,7,LEAVES:3)
Block(-3,73,8,LEAVES:3)
Block(-3,73,9,LEAVES:3)
Block(-3,73,10,LEAVES:3)
Block(-3,74,5,LEAVES:3)
Block(-3,74,9,LEAVES:3)
Block(-3,76,6,LEAVES:3)
Block(-3,76,7,LEAVES:3)
Block(-3,77,0,17:15)
Block(-3,77,1,17:15)
Block(-3,77,7,LEAVES:3)
Block(-3,77,8,17:15)
Block(-3,77,10,LEAVES:3)
Block(-3,78,-10,LEAVES:3)
Block(-3,78,-6,17:15)
Block(-3,78,-5,17:15)
Block(-3,78,-4,17:15)
Block(-3,78,-3,LEAVES:3)
Block(-3,78,-1,17:15)
Block(-3,78,0,LEAVES:3)
Block(-3,78,7,LEAVES:3)
Block(-3,78,8,LEAVES:3)
Block(-3,78,9,17:15)
Block(-3,78,10,LEAVES:3)
Block(-3,78,11,LEAVES:3)
Block(-3,78,14,LEAVES:3)
Block(-3,79,-10,LEAVES:3)
Block(-3,79,-9,LEAVES:3)
Block(-3,79,-8,LEAVES:3)
Block(-3,79,-7,LEAVES:3)
Block(-3,79,-6,LEAVES:3)
Block(-3,79,-5,LEAVES:3)
Block(-3,79,-3,LEAVES:3)
Block(-3,79,1,LEAVES:3)
Block(-3,79,2,LEAVES:3)
Block(-3,79,3,17:15)
Block(-3,79,8,LEAVES:3)
Block(-3,79,9,LEAVES:3)
Block(-3,79,10,LEAVES:3)
Block(-3,79,13,LEAVES:3)
Block(-3,79,14,LEAVES:3)
Block(-3,80,-10,LEAVES:3)
Block(-3,80,-9,LEAVES:3)
Block(-3,80,-8,LEAVES:3)
Block(-3,80,-6,LEAVES:3)
Block(-3,80,2,LEAVES:3)
Block(-3,80,3,LEAVES:3)
Block(-3,80,6,LEAVES:3)
Block(-3,80,8,LEAVES:3)
Block(-3,80,9,LEAVES:3)
Block(-3,81,3,LEAVES:3)
Block(-3,81,7,LEAVES:3)
Block(-3,81,8,LEAVES:3)
Block(-3,81,9,17:15)
Block(-3,81,10,LEAVES:3)
Block(-3,81,11,LEAVES:3)
Block(-3,82,8,LEAVES:3)
Block(-3,82,9,LEAVES:3)
Block(-3,82,10,LEAVES:3)
Block(-2,-6,-3,17:15)
Block(-2,-6,5,17:15)
Block(-2,-6,6,17:15)
Block(-2,-5,-3,17:15)
Block(-2,-5,5,17:15)
Block(-2,-5,6,17:15)
Block(-2,-4,-3,17:15)
Block(-2,-4,-2,17:15)
Block(-2,-4,5,17:15)
Block(-2,-4,6,17:15)
Block(-2,-3,-3,17:15)
Block(-2,-3,-2,17:15)
Block(-2,-3,-1,17:15)
Block(-2,-3,0,17:15)
Block(-2,-3,4,17:15)
Block(-2,-3,5,17:15)
Block(-2,-3,6,17:15)
Block(-2,-2,-2,17:15)
Block(-2,-2,-1,17:15)
Block(-2,-2,0,17:15)
Block(-2,-2,3,17:15)
Block(-2,-2,4,17:15)
Block(-2,-2,5,17:15)
Block(-2,-1,-2,17:15)
Block(-2,-1,-1,17:15)
Block(-2,-1,0,17:15)
Block(-2,-1,2,17:15)
Block(-2,-1,3,17:15)
Block(-2,-1,4,17:15)
Block(-2,-1,5,17:15)
Block(-2,0,-2,17:15)
Block(-2,0,-1,17:15)
Block(-2,0,0,17:15)
Block(-2,0,1,17:15)
Block(-2,0,2,17:15)
Block(-2,0,3,17:15)
Block(-2,0,4,17:15)
Block(-2,1,-1,17:15)
Block(-2,1,0,17:15)
Block(-2,1,1,17:15)
Block(-2,1,2,17:15)
Block(-2,1,3,17:15)
Block(-2,1,4,17:15)
Block(-2,2,0,17:15)
Block(-2,2,1,17:15)
Block(-2,2,2,17:15)
Block(-2,2,3,17:15)
Block(-2,2,4,17:15)
Block(-2,3,0,17:15)
Block(-2,3,1,17:15)
Block(-2,3,2,17:15)
Block(-2,3,3,17:15)
Block(-2,3,4,17:15)
Block(-2,4,0,17:15)
Block(-2,4,1,17:15)
Block(-2,4,2,17:15)
Block(-2,4,3,17:15)
Block(-2,4,4,17:15)
Block(-2,5,0,17:15)
Block(-2,5,1,17:15)
Block(-2,5,2,17:15)
Block(-2,5,3,17:15)
Block(-2,5,4,17:15)
Block(-2,6,0,17:15)
Block(-2,6,1,17:15)
Block(-2,6,2,17:15)
Block(-2,6,3,17:15)
Block(-2,7,0,17:15)
Block(-2,7,1,17:15)
Block(-2,7,2,17:15)
Block(-2,7,3,17:15)
Block(-2,8,0,17:15)
Block(-2,8,1,17:15)
Block(-2,8,2,17:15)
Block(-2,8,3,17:15)
Block(-2,9,0,17:15)
Block(-2,9,1,17:15)
Block(-2,9,2,17:15)
Block(-2,9,3,17:15)
Block(-2,10,0,17:15)
Block(-2,10,1,17:15)
Block(-2,10,2,17:15)
Block(-2,10,3,17:15)
Block(-2,11,0,17:15)
Block(-2,11,1,17:15)
Block(-2,11,2,17:15)
Block(-2,11,3,17:15)
Block(-2,12,0,17:15)
Block(-2,12,1,17:15)
Block(-2,12,2,17:15)
Block(-2,12,3,17:15)
Block(-2,13,0,17:15)
Block(-2,13,1,17:15)
Block(-2,13,2,17:15)
Block(-2,13,3,17:15)
Block(-2,14,0,17:15)
Block(-2,14,1,17:15)
Block(-2,14,2,17:15)
Block(-2,14,3,17:15)
Block(-2,15,0,17:15)
Block(-2,15,1,17:15)
Block(-2,15,2,17:15)
Block(-2,15,3,17:15)
Block(-2,16,0,17:15)
Block(-2,16,1,17:15)
Block(-2,16,2,17:15)
Block(-2,16,3,17:15)
Block(-2,17,0,17:15)
Block(-2,17,1,17:15)
Block(-2,17,2,17:15)
Block(-2,17,3,17:15)
Block(-2,18,1,17:15)
Block(-2,18,2,17:15)
Block(-2,18,3,17:15)
Block(-2,19,1,17:15)
Block(-2,19,2,17:15)
Block(-2,19,3,17:15)
Block(-2,20,1,17:15)
Block(-2,20,2,17:15)
Block(-2,20,3,17:15)
Block(-2,21,1,17:15)
Block(-2,21,2,17:15)
Block(-2,21,3,17:15)
Block(-2,22,1,17:15)
Block(-2,22,2,17:15)
Block(-2,22,3,17:15)
Block(-2,23,1,17:15)
Block(-2,23,2,17:15)
Block(-2,23,3,17:15)
Block(-2,24,1,17:15)
Block(-2,24,2,17:15)
Block(-2,24,3,17:15)
Block(-2,25,1,17:15)
Block(-2,25,2,17:15)
Block(-2,25,3,17:15)
Block(-2,26,1,17:15)
Block(-2,26,2,17:15)
Block(-2,26,3,17:15)
Block(-2,27,1,17:15)
Block(-2,27,2,17:15)
Block(-2,27,3,17:15)
Block(-2,28,1,17:15)
Block(-2,28,2,17:15)
Block(-2,28,3,17:15)
Block(-2,28,6,LEAVES:3)
Block(-2,28,7,LEAVES:3)
Block(-2,29,1,17:15)
Block(-2,29,2,17:15)
Block(-2,29,3,17:15)
Block(-2,30,1,17:15)
Block(-2,30,2,17:15)
Block(-2,30,3,17:15)
Block(-2,30,9,LEAVES:3)
Block(-2,31,-9,LEAVES:3)
Block(-2,31,1,17:15)
Block(-2,31,2,17:15)
Block(-2,31,3,LEAVES:3)
Block(-2,31,4,LEAVES:3)
Block(-2,31,5,LEAVES:3)
Block(-2,31,8,LEAVES:3)
Block(-2,32,-11,LEAVES:3)
Block(-2,32,-8,LEAVES:3)
Block(-2,32,1,17:15)
Block(-2,32,2,17:15)
Block(-2,32,3,17:15)
Block(-2,32,4,LEAVES:3)
Block(-2,32,6,LEAVES:3)
Block(-2,32,7,17:15)
Block(-2,32,8,LEAVES:3)
Block(-2,33,-10,LEAVES:3)
Block(-2,33,1,17:15)
Block(-2,33,2,17:15)
Block(-2,33,3,17:15)
Block(-2,33,6,LEAVES:3)
Block(-2,33,7,LEAVES:3)
Block(-2,34,1,17:15)
Block(-2,34,2,17:15)
Block(-2,34,3,17:15)
Block(-2,34,7,LEAVES:3)
Block(-2,35,1,17:15)
Block(-2,35,2,17:15)
Block(-2,35,3,17:15)
Block(-2,36,1,17:15)
Block(-2,36,2,17:15)
Block(-2,36,3,17:15)
Block(-2,37,1,17:15)
Block(-2,37,2,17:15)
Block(-2,37,3,17:15)
Block(-2,38,1,17:15)
Block(-2,38,2,17:15)
Block(-2,38,3,17:15)
Block(-2,39,1,17:15)
Block(-2,39,2,17:15)
Block(-2,39,3,17:15)
Block(-2,40,1,17:15)
Block(-2,40,2,17:15)
Block(-2,40,3,17:15)
Block(-2,41,1,17:15)
Block(-2,41,2,17:15)
Block(-2,41,3,17:15)
Block(-2,42,1,17:15)
Block(-2,42,2,17:15)
Block(-2,42,3,17:15)
Block(-2,43,1,17:15)
Block(-2,43,2,17:15)
Block(-2,43,3,17:15)
Block(-2,44,1,17:15)
Block(-2,44,2,17:15)
Block(-2,44,3,17:15)
Block(-2,44,4,17:15)
Block(-2,45,1,17:15)
Block(-2,45,2,17:15)
Block(-2,45,3,17:15)
Block(-2,45,4,17:15)
Block(-2,46,1,17:15)
Block(-2,46,2,17:15)
Block(-2,46,3,17:15)
Block(-2,46,6,17:15)
Block(-2,47,1,17:15)
Block(-2,47,2,17:15)
Block(-2,47,3,17:15)
Block(-2,48,-5,17:15)
Block(-2,48,2,17:15)
Block(-2,48,3,17:15)
Block(-2,48,12,17:15)
Block(-2,48,13,17:15)
Block(-2,48,14,LEAVES:3)
Block(-2,48,15,LEAVES:3)
Block(-2,49,-6,LEAVES:3)
Block(-2,49,-4,17:15)
Block(-2,49,2,17:15)
Block(-2,49,3,17:15)
Block(-2,49,8,17:15)
Block(-2,49,12,LEAVES:3)
Block(-2,49,13,17:15)
Block(-2,49,14,LEAVES:3)
Block(-2,50,-15,LEAVES:3)
Block(-2,50,-13,LEAVES:3)
Block(-2,50,-11,17:15)
Block(-2,50,-10,LEAVES:3)
Block(-2,50,-8,LEAVES:3)
Block(-2,50,-7,LEAVES:3)
Block(-2,50,-6,17:15)
Block(-2,50,-5,17:15)
Block(-2,50,-4,LEAVES:3)
Block(-2,50,-2,LEAVES:3)
Block(-2,50,-1,LEAVES:3)
Block(-2,50,2,17:15)
Block(-2,50,3,17:15)
Block(-2,50,13,LEAVES:3)
Block(-2,50,14,LEAVES:3)
Block(-2,51,-15,LEAVES:3)
Block(-2,51,-14,LEAVES:3)
Block(-2,51,-13,LEAVES:3)
Block(-2,51,-12,17:15)
Block(-2,51,-11,LEAVES:3)
Block(-2,51,-10,LEAVES:3)
Block(-2,51,-9,LEAVES:3)
Block(-2,51,-8,LEAVES:3)
Block(-2,51,-7,LEAVES:3)
Block(-2,51,-6,LEAVES:3)
Block(-2,51,-5,LEAVES:3)
Block(-2,51,2,17:15)
Block(-2,51,3,17:15)
Block(-2,52,-14,LEAVES:3)
Block(-2,52,-13,LEAVES:3)
Block(-2,52,-12,LEAVES:3)
Block(-2,52,-11,LEAVES:3)
Block(-2,52,-8,LEAVES:3)
Block(-2,52,-6,LEAVES:3)
Block(-2,52,2,17:15)
Block(-2,52,3,17:15)
Block(-2,53,-12,LEAVES:3)
Block(-2,53,2,17:15)
Block(-2,53,3,17:15)
Block(-2,54,2,17:15)
Block(-2,54,3,17:15)
Block(-2,55,2,17:15)
Block(-2,55,3,17:15)
Block(-2,56,2,17:15)
Block(-2,57,2,17:15)
Block(-2,57,3,17:15)
Block(-2,58,2,17:15)
Block(-2,58,3,17:15)
Block(-2,58,4,17:15)
Block(-2,59,2,17:15)
Block(-2,59,5,17:15)
Block(-2,59,6,17:15)
Block(-2,59,7,17:15)
Block(-2,60,2,17:15)
Block(-2,60,5,LEAVES:3)
Block(-2,60,7,17:15)
Block(-2,61,2,17:15)
Block(-2,61,5,LEAVES:3)
Block(-2,61,6,LEAVES:3)
Block(-2,61,7,LEAVES:3)
Block(-2,61,8,17:15)
Block(-2,61,9,LEAVES:3)
Block(-2,62,1,17:15)
Block(-2,62,2,17:15)
Block(-2,62,7,LEAVES:3)
Block(-2,62,8,LEAVES:3)
Block(-2,62,11,LEAVES:3)
Block(-2,63,1,17:15)
Block(-2,63,2,17:15)
Block(-2,63,7,LEAVES:3)
Block(-2,64,1,17:15)
Block(-2,64,2,17:15)
Block(-2,65,-5,LEAVES:3)
Block(-2,65,-2,LEAVES:3)
Block(-2,65,2,17:15)
Block(-2,66,-7,LEAVES:3)
Block(-2,66,-6,LEAVES:3)
Block(-2,66,-5,17:15)
Block(-2,66,2,17:15)
Block(-2,66,6,LEAVES:3)
Block(-2,67,2,17:15)
Block(-2,68,2,17:15)
Block(-2,69,-9,LEAVES:3)
Block(-2,69,-6,LEAVES:3)
Block(-2,69,2,17:15)
Block(-2,70,-8,LEAVES:3)
Block(-2,70,-7,LEAVES:3)
Block(-2,70,-6,LEAVES:3)
Block(-2,70,-5,LEAVES:3)
Block(-2,70,2,17:15)
Block(-2,70,6,17:15)
Block(-2,71,-7,LEAVES:3)
Block(-2,71,2,17:15)
Block(-2,71,4,LEAVES:3)
Block(-2,71,5,17:15)
Block(-2,71,6,17:15)
Block(-2,72,2,17:15)
Block(-2,72,5,LEAVES:3)
Block(-2,72,6,LEAVES:3)
Block(-2,72,7,LEAVES:3)
Block(-2,73,2,17:15)
Block(-2,73,5,LEAVES:3)
Block(-2,73,6,LEAVES:3)
Block(-2,73,9,LEAVES:3)
Block(-2,74,2,17:15)
Block(-2,75,2,17:15)
Block(-2,76,1,17:15)
Block(-2,76,2,17:15)
Block(-2,76,7,17:15)
Block(-2,76,9,LEAVES:3)
Block(-2,77,-2,17:15)
Block(-2,77,-1,17:15)
Block(-2,77,1,17:15)
Block(-2,77,2,17:15)
Block(-2,77,6,LEAVES:3)
Block(-2,77,7,17:15)
Block(-2,77,8,17:15)
Block(-2,77,9,17:15)
Block(-2,77,11,LEAVES:3)
Block(-2,77,12,LEAVES:3)
Block(-2,78,-8,LEAVES:3)
Block(-2,78,-4,LEAVES:3)
Block(-2,78,-3,17:15)
Block(-2,78,-2,LEAVES:3)
Block(-2,78,-1,17:15)
Block(-2,78,0,LEAVES:3)
Block(-2,78,1,LEAVES:3)
Block(-2,78,2,17:15)
Block(-2,78,7,LEAVES:3)
Block(-2,78,8,LEAVES:3)
Block(-2,78,9,LEAVES:3)
Block(-2,78,10,LEAVES:3)
Block(-2,78,11,LEAVES:3)
Block(-2,78,12,LEAVES:3)
Block(-2,79,-12,LEAVES:3)
Block(-2,79,-10,LEAVES:3)
Block(-2,79,-9,LEAVES:3)
Block(-2,79,-8,17:15)
Block(-2,79,-7,17:15)
Block(-2,79,-6,LEAVES:3)
Block(-2,79,-3,LEAVES:3)
Block(-2,79,-2,LEAVES:3)
Block(-2,79,-1,LEAVES:3)
Block(-2,79,0,LEAVES:3)
Block(-2,79,2,17:15)
Block(-2,79,8,LEAVES:3)
Block(-2,79,10,LEAVES:3)
Block(-2,79,11,LEAVES:3)
Block(-2,79,13,LEAVES:3)
Block(-2,79,14,LEAVES:3)
Block(-2,79,15,LEAVES:3)
Block(-2,80,-12,LEAVES:3)
Block(-2,80,-11,LEAVES:3)
Block(-2,80,-10,LEAVES:3)
Block(-2,80,-9,LEAVES:3)
Block(-2,80,-8,LEAVES:3)
Block(-2,80,-7,LEAVES:3)
Block(-2,80,-3,LEAVES:3)
Block(-2,80,1,LEAVES:3)
Block(-2,80,2,LEAVES:3)
Block(-2,80,3,17:15)
Block(-2,80,4,LEAVES:3)
Block(-2,80,10,LEAVES:3)
Block(-2,80,13,LEAVES:3)
Block(-2,81,-10,LEAVES:3)
Block(-2,81,-8,LEAVES:3)
Block(-2,81,2,LEAVES:3)
Block(-2,81,3,LEAVES:3)
Block(-2,81,4,LEAVES:3)
Block(-2,81,8,LEAVES:3)
Block(-2,81,9,LEAVES:3)
Block(-2,81,10,LEAVES:3)
Block(-2,82,3,LEAVES:3)
Block(-2,82,9,LEAVES:3)
Block(-1,-6,3,17:15)
Block(-1,-6,5,17:15)
Block(-1,-5,-1,17:15)
Block(-1,-5,2,17:15)
Block(-1,-5,3,17:15)
Block(-1,-4,-1,17:15)
Block(-1,-4,2,17:15)
Block(-1,-4,3,17:15)
Block(-1,-4,5,17:15)
Block(-1,-3,-1,17:15)
Block(-1,-3,2,17:15)
Block(-1,-3,3,17:15)
Block(-1,-3,6,17:15)
Block(-1,-2,-1,17:15)
Block(-1,-2,2,17:15)
Block(-1,-2,5,17:15)
Block(-1,-2,6,17:15)
Block(-1,-1,-1,17:15)
Block(-1,-1,3,17:15)
Block(-1,-1,5,17:15)
Block(-1,-1,6,17:15)
Block(-1,0,2,17:15)
Block(-1,0,3,17:15)
Block(-1,0,4,17:15)
Block(-1,0,5,17:15)
Block(-1,0,6,17:15)
Block(-1,1,0,17:15)
Block(-1,1,1,17:15)
Block(-1,1,2,17:15)
Block(-1,1,3,17:15)
Block(-1,1,4,17:15)
Block(-1,1,5,17:15)
Block(-1,2,0,17:15)
Block(-1,2,1,17:15)
Block(-1,2,2,17:15)
Block(-1,2,3,17:15)
Block(-1,2,4,17:15)
Block(-1,2,5,17:15)
Block(-1,3,0,17:15)
Block(-1,3,1,17:15)
Block(-1,3,2,17:15)
Block(-1,3,3,17:15)
Block(-1,3,4,17:15)
Block(-1,3,5,17:15)
Block(-1,4,0,17:15)
Block(-1,4,1,17:15)
Block(-1,4,2,17:15)
Block(-1,4,3,17:15)
Block(-1,4,4,17:15)
Block(-1,5,1,17:15)
Block(-1,5,2,17:15)
Block(-1,5,3,17:15)
Block(-1,5,4,17:15)
Block(-1,6,1,17:15)
Block(-1,6,2,17:15)
Block(-1,6,3,17:15)
Block(-1,6,4,17:15)
Block(-1,7,1,17:15)
Block(-1,7,2,17:15)
Block(-1,7,3,17:15)
Block(-1,7,4,17:15)
Block(-1,8,1,17:15)
Block(-1,8,2,17:15)
Block(-1,8,3,17:15)
Block(-1,8,4,17:15)
Block(-1,9,1,17:15)
Block(-1,9,2,17:15)
Block(-1,9,3,17:15)
Block(-1,9,4,17:15)
Block(-1,10,1,17:15)
Block(-1,10,2,17:15)
Block(-1,10,3,17:15)
Block(-1,10,4,17:15)
Block(-1,11,1,17:15)
Block(-1,11,2,17:15)
Block(-1,11,3,17:15)
Block(-1,11,4,17:15)
Block(-1,12,1,17:15)
Block(-1,12,2,17:15)
Block(-1,12,3,17:15)
Block(-1,12,4,17:15)
Block(-1,13,1,17:15)
Block(-1,13,2,17:15)
Block(-1,13,3,17:15)
Block(-1,13,4,17:15)
Block(-1,14,1,17:15)
Block(-1,14,2,17:15)
Block(-1,14,3,17:15)
Block(-1,14,4,17:15)
Block(-1,15,1,17:15)
Block(-1,15,2,17:15)
Block(-1,15,3,17:15)
Block(-1,15,4,17:15)
Block(-1,16,1,17:15)
Block(-1,16,2,17:15)
Block(-1,16,3,17:15)
Block(-1,17,1,17:15)
Block(-1,17,2,17:15)
Block(-1,17,3,17:15)
Block(-1,18,1,17:15)
Block(-1,18,2,17:15)
Block(-1,18,3,17:15)
Block(-1,19,1,17:15)
Block(-1,19,2,17:15)
Block(-1,19,3,17:15)
Block(-1,20,1,17:15)
Block(-1,20,2,17:15)
Block(-1,20,3,17:15)
Block(-1,21,1,17:15)
Block(-1,21,2,17:15)
Block(-1,21,3,17:15)
Block(-1,22,1,17:15)
Block(-1,22,2,17:15)
Block(-1,23,1,17:15)
Block(-1,23,2,17:15)
Block(-1,24,1,17:15)
Block(-1,24,2,17:15)
Block(-1,25,1,17:15)
Block(-1,25,2,17:15)
Block(-1,26,1,17:15)
Block(-1,26,2,17:15)
Block(-1,27,1,17:15)
Block(-1,27,2,17:15)
Block(-1,27,3,LEAVES:3)
Block(-1,28,1,17:15)
Block(-1,28,2,17:15)
Block(-1,28,6,17:15)
Block(-1,29,1,17:15)
Block(-1,29,2,17:15)
Block(-1,29,6,LEAVES:3)
Block(-1,30,1,17:15)
Block(-1,30,2,17:15)
Block(-1,30,4,LEAVES:3)
Block(-1,31,1,17:15)
Block(-1,31,2,17:15)
Block(-1,31,4,LEAVES:3)
Block(-1,31,5,LEAVES:3)
Block(-1,31,7,LEAVES:3)
Block(-1,32,1,17:15)
Block(-1,32,2,17:15)
Block(-1,32,6,LEAVES:3)
Block(-1,32,7,LEAVES:3)
Block(-1,32,8,LEAVES:3)
Block(-1,32,9,LEAVES:3)
Block(-1,33,1,17:15)
Block(-1,33,2,17:15)
Block(-1,33,7,LEAVES:3)
Block(-1,33,8,LEAVES:3)
Block(-1,34,1,17:15)
Block(-1,34,2,17:15)
Block(-1,35,1,17:15)
Block(-1,35,2,17:15)
Block(-1,36,1,17:15)
Block(-1,36,2,17:15)
Block(-1,36,3,17:15)
Block(-1,37,1,17:15)
Block(-1,37,2,17:15)
Block(-1,38,1,17:15)
Block(-1,38,2,17:15)
Block(-1,39,1,17:15)
Block(-1,39,2,17:15)
Block(-1,40,1,17:15)
Block(-1,40,2,17:15)
Block(-1,41,1,17:15)
Block(-1,41,2,17:15)
Block(-1,42,1,17:15)
Block(-1,42,2,17:15)
Block(-1,43,1,17:15)
Block(-1,43,2,17:15)
Block(-1,44,1,17:15)
Block(-1,44,2,17:15)
Block(-1,45,1,17:15)
Block(-1,45,2,17:15)
Block(-1,46,1,17:15)
Block(-1,46,2,17:15)
Block(-1,47,1,17:15)
Block(-1,47,2,17:15)
Block(-1,47,4,LEAVES:3)
Block(-1,47,5,LEAVES:3)
Block(-1,47,6,17:15)
Block(-1,48,-4,17:15)
Block(-1,48,-3,17:15)
Block(-1,48,0,17:15)
Block(-1,48,1,17:15)
Block(-1,48,2,17:15)
Block(-1,48,5,LEAVES:3)
Block(-1,49,-11,LEAVES:3)
Block(-1,49,-9,LEAVES:3)
Block(-1,49,-8,LEAVES:3)
Block(-1,49,-4,17:15)
Block(-1,49,-3,17:15)
Block(-1,49,0,LEAVES:3)
Block(-1,49,1,17:15)
Block(-1,49,2,17:15)
Block(-1,49,9,17:15)
Block(-1,49,13,17:15)
Block(-1,49,14,17:15)
Block(-1,49,15,LEAVES:3)
Block(-1,50,-12,LEAVES:3)
Block(-1,50,-11,LEAVES:3)
Block(-1,50,-10,LEAVES:3)
Block(-1,50,-8,LEAVES:3)
Block(-1,50,-7,LEAVES:3)
Block(-1,50,-6,LEAVES:3)
Block(-1,50,-5,LEAVES:3)
Block(-1,50,-4,LEAVES:3)
Block(-1,50,-3,LEAVES:3)
Block(-1,50,-2,LEAVES:3)
Block(-1,50,-1,LEAVES:3)
Block(-1,50,1,17:15)
Block(-1,50,2,17:15)
Block(-1,50,9,LEAVES:3)
Block(-1,50,12,LEAVES:3)
Block(-1,50,13,LEAVES:3)
Block(-1,50,14,LEAVES:3)
Block(-1,51,-14,LEAVES:3)
Block(-1,51,-13,LEAVES:3)
Block(-1,51,-12,LEAVES:3)
Block(-1,51,-11,LEAVES:3)
Block(-1,51,-8,LEAVES:3)
Block(-1,51,-7,LEAVES:3)
Block(-1,51,-6,LEAVES:3)
Block(-1,51,-4,LEAVES:3)
Block(-1,51,-2,LEAVES:3)
Block(-1,51,1,17:15)
Block(-1,51,2,17:15)
Block(-1,51,10,LEAVES:3)
Block(-1,51,13,LEAVES:3)
Block(-1,51,14,LEAVES:3)
Block(-1,52,-13,LEAVES:3)
Block(-1,52,-10,LEAVES:3)
Block(-1,52,-9,LEAVES:3)
Block(-1,52,1,17:15)
Block(-1,52,2,17:15)
Block(-1,53,1,17:15)
Block(-1,53,2,17:15)
Block(-1,54,1,17:15)
Block(-1,54,2,17:15)
Block(-1,55,1,17:15)
Block(-1,55,2,17:15)
Block(-1,56,1,17:15)
Block(-1,56,2,17:15)
Block(-1,57,1,17:15)
Block(-1,57,2,17:15)
Block(-1,58,1,17:15)
Block(-1,58,2,17:15)
Block(-1,59,1,17:15)
Block(-1,59,2,17:15)
Block(-1,59,5,17:15)
Block(-1,60,1,17:15)
Block(-1,60,2,17:15)
Block(-1,60,4,LEAVES:3)
Block(-1,60,5,LEAVES:3)
Block(-1,60,6,LEAVES:3)
Block(-1,60,7,17:15)
Block(-1,60,8,17:15)
Block(-1,61,1,17:15)
Block(-1,61,2,17:15)
Block(-1,61,4,LEAVES:3)
Block(-1,61,5,LEAVES:3)
Block(-1,61,6,LEAVES:3)
Block(-1,61,7,LEAVES:3)
Block(-1,61,11,LEAVES:3)
Block(-1,62,1,17:15)
Block(-1,62,2,17:15)
Block(-1,62,7,LEAVES:3)
Block(-1,62,9,LEAVES:3)
Block(-1,62,10,LEAVES:3)
Block(-1,63,1,17:15)
Block(-1,63,2,17:15)
Block(-1,63,9,LEAVES:3)
Block(-1,64,1,17:15)
Block(-1,64,2,17:15)
Block(-1,65,1,17:15)
Block(-1,65,2,17:15)
Block(-1,66,-6,LEAVES:3)
Block(-1,66,1,17:15)
Block(-1,66,2,17:15)
Block(-1,67,1,17:15)
Block(-1,67,2,17:15)
Block(-1,68,1,17:15)
Block(-1,68,2,17:15)
Block(-1,69,-8,LEAVES:3)
Block(-1,69,-6,LEAVES:3)
Block(-1,69,2,17:15)
Block(-1,70,-9,LEAVES:3)
Block(-1,70,-8,LEAVES:3)
Block(-1,70,-7,17:15)
Block(-1,70,-6,LEAVES:3)
Block(-1,70,-5,LEAVES:3)
Block(-1,70,-4,LEAVES:3)
Block(-1,70,2,17:15)
Block(-1,70,4,LEAVES:3)
Block(-1,70,5,LEAVES:3)
Block(-1,70,6,17:15)
Block(-1,70,7,17:15)
Block(-1,71,-8,LEAVES:3)
Block(-1,71,-7,LEAVES:3)
Block(-1,71,-5,LEAVES:3)
Block(-1,71,2,17:15)
Block(-1,71,5,LEAVES:3)
Block(-1,71,6,17:15)
Block(-1,71,7,LEAVES:3)
Block(-1,72,2,17:15)
Block(-1,72,5,LEAVES:3)
Block(-1,72,6,LEAVES:3)
Block(-1,73,2,17:15)
Block(-1,74,2,17:15)
Block(-1,75,2,17:15)
Block(-1,75,5,17:15)
Block(-1,76,1,17:15)
Block(-1,76,2,17:15)
Block(-1,76,6,LEAVES:3)
Block(-1,76,7,17:15)
Block(-1,77,7,LEAVES:3)
Block(-1,77,9,LEAVES:3)
Block(-1,77,10,17:15)
Block(-1,78,-9,LEAVES:3)
Block(-1,78,-6,LEAVES:3)
Block(-1,78,-4,LEAVES:3)
Block(-1,78,-3,LEAVES:3)
Block(-1,78,-2,LEAVES:3)
Block(-1,78,-1,17:15)
Block(-1,78,0,LEAVES:3)
Block(-1,78,8,LEAVES:3)
Block(-1,78,9,LEAVES:3)
Block(-1,78,10,17:15)
Block(-1,78,12,17:15)
Block(-1,78,13,LEAVES:3)
Block(-1,78,15,LEAVES:3)
Block(-1,79,-13,LEAVES:3)
Block(-1,79,-9,17:15)
Block(-1,79,-8,LEAVES:3)
Block(-1,79,-7,LEAVES:3)
Block(-1,79,-6,LEAVES:3)
Block(-1,79,-3,LEAVES:3)
Block(-1,79,-2,LEAVES:3)
Block(-1,79,9,LEAVES:3)
Block(-1,79,10,LEAVES:3)
Block(-1,79,12,LEAVES:3)
Block(-1,79,13,17:15)
Block(-1,79,14,LEAVES:3)
Block(-1,79,15,LEAVES:3)
Block(-1,79,16,LEAVES:3)
Block(-1,80,-13,LEAVES:3)
Block(-1,80,-12,LEAVES:3)
Block(-1,80,-11,LEAVES:3)
Block(-1,80,-10,17:15)
Block(-1,80,-9,LEAVES:3)
Block(-1,80,-8,LEAVES:3)
Block(-1,80,-7,LEAVES:3)
Block(-1,80,0,LEAVES:3)
Block(-1,80,1,LEAVES:3)
Block(-1,80,2,17:15)
Block(-1,80,3,LEAVES:3)
Block(-1,80,4,LEAVES:3)
Block(-1,80,8,LEAVES:3)
Block(-1,80,12,LEAVES:3)
Block(-1,80,13,LEAVES:3)
Block(-1,80,14,LEAVES:3)
Block(-1,80,15,LEAVES:3)
Block(-1,81,-12,LEAVES:3)
Block(-1,81,-11,LEAVES:3)
Block(-1,81,-10,LEAVES:3)
Block(-1,81,-9,LEAVES:3)
Block(-1,81,1,LEAVES:3)
Block(-1,81,2,LEAVES:3)
Block(-1,81,3,LEAVES:3)
Block(-1,81,9,LEAVES:3)
Block(-1,81,13,LEAVES:3)
Block(-1,82,-10,LEAVES:3)
Block(0,-6,-2,17:15)
Block(0,-6,-1,17:15)
Block(0,-6,7,17:15)
Block(0,-5,-2,17:15)
Block(0,-5,7,17:15)
Block(0,-4,-2,17:15)
Block(0,-4,-1,17:15)
Block(0,-4,2,17:15)
Block(0,-4,6,17:15)
Block(0,-4,7,17:15)
Block(0,-3,-2,17:15)
Block(0,-3,2,17:15)
Block(0,-3,4,17:15)
Block(0,-3,6,17:15)
Block(0,-3,7,17:15)
Block(0,-2,-2,17:15)
Block(0,-2,2,17:15)
Block(0,-2,4,17:15)
Block(0,-2,6,17:15)
Block(0,-2,7,17:15)
Block(0,-1,-2,17:15)
Block(0,-1,-1,17:15)
Block(0,-1,1,17:15)
Block(0,-1,2,17:15)
Block(0,-1,3,17:15)
Block(0,-1,4,17:15)
Block(0,-1,6,17:15)
Block(0,0,-2,17:15)
Block(0,0,-1,17:15)
Block(0,0,0,17:15)
Block(0,0,1,17:15)
Block(0,0,2,17:15)
Block(0,0,3,17:15)
Block(0,0,4,17:15)
Block(0,1,-2,17:15)
Block(0,1,-1,17:15)
Block(0,1,0,17:15)
Block(0,1,1,17:15)
Block(0,1,2,17:15)
Block(0,1,3,17:15)
Block(0,1,4,17:15)
Block(0,2,-1,17:15)
Block(0,2,1,17:15)
Block(0,2,2,17:15)
Block(0,2,3,17:15)
Block(0,3,-1,17:15)
Block(0,3,0,17:15)
Block(0,3,1,17:15)
Block(0,3,2,17:15)
Block(0,3,3,17:15)
Block(0,4,1,17:15)
Block(0,4,2,17:15)
Block(0,4,3,17:15)
Block(0,5,1,17:15)
Block(0,5,2,17:15)
Block(0,5,3,17:15)
Block(0,6,1,17:15)
Block(0,6,2,17:15)
Block(0,6,3,17:15)
Block(0,7,1,17:15)
Block(0,7,2,17:15)
Block(0,7,3,17:15)
Block(0,8,1,17:15)
Block(0,8,2,17:15)
Block(0,8,3,17:15)
Block(0,9,1,17:15)
Block(0,9,2,17:15)
Block(0,9,3,17:15)
Block(0,10,1,17:15)
Block(0,10,2,17:15)
Block(0,10,3,17:15)
Block(0,11,1,17:15)
Block(0,11,2,17:15)
Block(0,11,3,17:15)
Block(0,12,1,17:15)
Block(0,12,2,17:15)
Block(0,12,3,17:15)
Block(0,13,1,17:15)
Block(0,13,2,17:15)
Block(0,13,3,17:15)
Block(0,14,1,17:15)
Block(0,14,2,17:15)
Block(0,14,3,17:15)
Block(0,15,1,17:15)
Block(0,15,2,17:15)
Block(0,15,3,17:15)
Block(0,16,1,17:15)
Block(0,16,2,17:15)
Block(0,16,3,17:15)
Block(0,17,1,17:15)
Block(0,17,2,17:15)
Block(0,17,3,17:15)
Block(0,18,1,17:15)
Block(0,18,2,17:15)
Block(0,18,3,17:15)
Block(0,19,1,17:15)
Block(0,19,2,17:15)
Block(0,20,1,17:15)
Block(0,20,2,17:15)
Block(0,21,2,17:15)
Block(0,22,2,17:15)
Block(0,23,2,17:15)
Block(0,24,1,17:15)
Block(0,24,2,17:15)
Block(0,25,1,17:15)
Block(0,25,2,17:15)
Block(0,27,2,LEAVES:3)
Block(0,27,3,17:15)
Block(0,27,6,17:15)
Block(0,27,7,LEAVES:3)
Block(0,28,-9,LEAVES:3)
Block(0,28,6,LEAVES:3)
Block(0,29,-11,LEAVES:3)
Block(0,31,9,LEAVES:3)
Block(0,32,6,LEAVES:3)
Block(0,32,7,LEAVES:3)
Block(0,32,8,LEAVES:3)
Block(0,33,7,LEAVES:3)
Block(0,36,2,17:15)
Block(0,37,2,17:15)
Block(0,39,-5,LEAVES:3)
Block(0,40,-4,LEAVES:3)
Block(0,41,5,LEAVES:3)
Block(0,42,6,LEAVES:3)
Block(0,47,6,17:15)
Block(0,48,0,17:15)
Block(0,48,13,LEAVES:3)
Block(0,49,-12,LEAVES:3)
Block(0,49,-6,LEAVES:3)
Block(0,49,-2,17:15)
Block(0,49,-1,17:15)
Block(0,49,0,17:15)
Block(0,49,9,LEAVES:3)
Block(0,49,12,LEAVES:3)
Block(0,49,13,17:15)
Block(0,49,15,LEAVES:3)
Block(0,50,-14,LEAVES:3)
Block(0,50,-11,LEAVES:3)
Block(0,50,-7,LEAVES:3)
Block(0,50,-6,LEAVES:3)
Block(0,50,-5,LEAVES:3)
Block(0,50,-4,LEAVES:3)
Block(0,50,-3,LEAVES:3)
Block(0,50,-2,LEAVES:3)
Block(0,50,-1,LEAVES:3)
Block(0,50,11,LEAVES:3)
Block(0,50,12,LEAVES:3)
Block(0,50,13,LEAVES:3)
Block(0,50,14,17:15)
Block(0,50,15,17:15)
Block(0,50,16,LEAVES:3)
Block(0,51,-13,LEAVES:3)
Block(0,51,-8,17:15)
Block(0,51,-6,LEAVES:3)
Block(0,51,-3,LEAVES:3)
Block(0,51,-2,LEAVES:3)
Block(0,51,-1,LEAVES:3)
Block(0,51,9,LEAVES:3)
Block(0,51,10,LEAVES:3)
Block(0,51,11,LEAVES:3)
Block(0,51,12,LEAVES:3)
Block(0,51,14,LEAVES:3)
Block(0,51,15,LEAVES:3)
Block(0,52,-11,LEAVES:3)
Block(0,52,-10,LEAVES:3)
Block(0,52,-9,17:15)
Block(0,52,-8,LEAVES:3)
Block(0,52,-2,LEAVES:3)
Block(0,52,10,LEAVES:3)
Block(0,52,14,LEAVES:3)
Block(0,53,-10,LEAVES:3)
Block(0,53,-9,LEAVES:3)
Block(0,54,-9,LEAVES:3)
Block(0,59,3,LEAVES:3)
Block(0,60,3,LEAVES:3)
Block(0,60,4,LEAVES:3)
Block(0,60,5,17:15)
Block(0,60,8,17:15)
Block(0,60,9,17:15)
Block(0,60,10,LEAVES:3)
Block(0,61,4,LEAVES:3)
Block(0,61,5,LEAVES:3)
Block(0,61,7,LEAVES:3)
Block(0,61,8,LEAVES:3)
Block(0,61,9,17:15)
Block(0,61,13,LEAVES:3)
Block(0,62,8,LEAVES:3)
Block(0,62,9,LEAVES:3)
Block(0,62,10,LEAVES:3)
Block(0,62,11,LEAVES:3)
Block(0,62,12,LEAVES:3)
Block(0,63,8,LEAVES:3)
Block(0,63,9,LEAVES:3)
Block(0,63,10,LEAVES:3)
Block(0,64,9,LEAVES:3)
Block(0,65,2,17:15)
Block(0,66,2,17:15)
Block(0,66,3,17:15)
Block(0,69,-10,LEAVES:3)
Block(0,69,-5,LEAVES:3)
Block(0,69,3,LEAVES:3)
Block(0,69,13,LEAVES:3)
Block(0,70,-9,LEAVES:3)
Block(0,70,-8,LEAVES:3)
Block(0,70,-7,LEAVES:3)
Block(0,70,-6,17:15)
Block(0,70,-5,LEAVES:3)
Block(0,70,-4,LEAVES:3)
Block(0,70,-3,LEAVES:3)
Block(0,70,5,LEAVES:3)
Block(0,70,7,17:15)
Block(0,70,14,LEAVES:3)
Block(0,70,15,LEAVES:3)
Block(0,71,-6,LEAVES:3)
Block(0,71,-5,LEAVES:3)
Block(0,71,-4,LEAVES:3)
Block(0,71,3,LEAVES:3)
Block(0,71,6,LEAVES:3)
Block(0,71,16,LEAVES:3)
Block(0,72,-6,LEAVES:3)
Block(0,75,2,17:15)
Block(0,75,3,17:15)
Block(0,75,4,17:15)
Block(0,76,-3,LEAVES:3)
Block(0,76,2,17:15)
Block(0,77,-6,LEAVES:3)
Block(0,77,-4,LEAVES:3)
Block(0,77,-2,LEAVES:3)
Block(0,77,-1,LEAVES:3)
Block(0,77,6,LEAVES:3)
Block(0,77,7,LEAVES:3)
Block(0,77,8,LEAVES:3)
Block(0,77,11,LEAVES:3)
Block(0,78,-5,LEAVES:3)
Block(0,78,-4,LEAVES:3)
Block(0,78,-3,LEAVES:3)
Block(0,78,-2,LEAVES:3)
Block(0,78,-1,LEAVES:3)
Block(0,78,7,LEAVES:3)
Block(0,78,9,LEAVES:3)
Block(0,78,10,LEAVES:3)
Block(0,78,11,17:15)
Block(0,78,12,LEAVES:3)
Block(0,79,-11,LEAVES:3)
Block(0,79,-9,LEAVES:3)
Block(0,79,-8,LEAVES:3)
Block(0,79,-7,LEAVES:3)
Block(0,79,-4,LEAVES:3)
Block(0,79,-3,LEAVES:3)
Block(0,79,1,LEAVES:3)
Block(0,79,3,LEAVES:3)
Block(0,79,4,LEAVES:3)
Block(0,79,9,LEAVES:3)
Block(0,79,11,LEAVES:3)
Block(0,79,13,LEAVES:3)
Block(0,79,14,LEAVES:3)
Block(0,79,15,LEAVES:3)
Block(0,80,-12,LEAVES:3)
Block(0,80,-11,LEAVES:3)
Block(0,80,-10,LEAVES:3)
Block(0,80,-9,LEAVES:3)
Block(0,80,1,LEAVES:3)
Block(0,80,2,LEAVES:3)
Block(0,80,3,LEAVES:3)
Block(0,80,11,LEAVES:3)
Block(0,81,-11,LEAVES:3)
Block(0,81,2,LEAVES:3)
Block(1,-6,-1,17:15)
Block(1,-6,7,17:15)
Block(1,-5,-1,17:15)
Block(1,-4,-1,17:15)
Block(1,-4,4,17:15)
Block(1,-4,7,17:15)
Block(1,-3,-2,17:15)
Block(1,-3,-1,17:15)
Block(1,-3,0,17:15)
Block(1,-3,2,17:15)
Block(1,-3,4,17:15)
Block(1,-2,-2,17:15)
Block(1,-2,-1,17:15)
Block(1,-2,0,17:15)
Block(1,-2,2,17:15)
Block(1,-2,4,17:15)
Block(1,-1,-2,17:15)
Block(1,-1,-1,17:15)
Block(1,-1,0,17:15)
Block(1,-1,1,17:15)
Block(1,-1,2,17:15)
Block(1,-1,4,17:15)
Block(1,0,-2,17:15)
Block(1,0,0,17:15)
Block(1,0,1,17:15)
Block(1,0,2,17:15)
Block(1,1,0,17:15)
Block(1,1,1,17:15)
Block(1,1,2,17:15)
Block(1,2,1,17:15)
Block(1,2,2,17:15)
Block(1,3,1,17:15)
Block(1,3,2,17:15)
Block(1,4,1,17:15)
Block(1,4,2,17:15)
Block(1,5,2,17:15)
Block(1,6,2,17:15)
Block(1,7,2,17:15)
Block(1,8,2,17:15)
Block(1,9,2,17:15)
Block(1,10,2,17:15)
Block(1,11,2,17:15)
Block(1,12,2,17:15)
Block(1,24,1,17:15)
Block(1,25,1,17:15)
Block(1,26,-3,LEAVES:3)
Block(1,27,-5,LEAVES:3)
Block(1,27,4,17:15)
Block(1,27,5,17:15)
Block(1,27,9,LEAVES:3)
Block(1,28,-9,17:15)
Block(1,29,-12,LEAVES:3)
Block(1,29,-11,LEAVES:3)
Block(1,29,-10,17:15)
Block(1,29,-9,LEAVES:3)
Block(1,29,0,LEAVES:3)
Block(1,30,-10,LEAVES:3)
Block(1,31,7,LEAVES:3)
Block(1,32,7,LEAVES:3)
Block(1,37,1,17:15)
Block(1,37,2,17:15)
Block(1,39,-3,LEAVES:3)
Block(1,40,-5,LEAVES:3)
Block(1,40,-4,LEAVES:3)
Block(1,40,-3,LEAVES:3)
Block(1,41,-4,LEAVES:3)
Block(1,41,7,LEAVES:3)
Block(1,42,5,LEAVES:3)
Block(1,42,6,LEAVES:3)
Block(1,42,7,LEAVES:3)
Block(1,43,6,LEAVES:3)
Block(1,47,7,17:15)
Block(1,48,5,17:15)
Block(1,49,-7,LEAVES:3)
Block(1,49,-4,LEAVES:3)
Block(1,49,-3,17:15)
Block(1,49,-2,17:15)
Block(1,49,-1,LEAVES:3)
Block(1,49,1,LEAVES:3)
Block(1,49,5,LEAVES:3)
Block(1,49,12,17:15)
Block(1,49,14,LEAVES:3)
Block(1,49,17,LEAVES:3)
Block(1,50,-6,LEAVES:3)
Block(1,50,-4,17:15)
Block(1,50,-3,17:15)
Block(1,50,-2,17:15)
Block(1,50,-1,LEAVES:3)
Block(1,50,0,LEAVES:3)
Block(1,50,10,LEAVES:3)
Block(1,50,11,LEAVES:3)
Block(1,50,12,17:15)
Block(1,50,13,LEAVES:3)
Block(1,50,14,LEAVES:3)
Block(1,50,15,LEAVES:3)
Block(1,50,16,17:15)
Block(1,50,17,LEAVES:3)
Block(1,51,-11,LEAVES:3)
Block(1,51,-8,LEAVES:3)
Block(1,51,-7,17:15)
Block(1,51,-6,LEAVES:3)
Block(1,51,-5,LEAVES:3)
Block(1,51,-4,LEAVES:3)
Block(1,51,-3,LEAVES:3)
Block(1,51,-2,LEAVES:3)
Block(1,51,8,LEAVES:3)
Block(1,51,9,LEAVES:3)
Block(1,51,10,LEAVES:3)
Block(1,51,12,LEAVES:3)
Block(1,51,13,LEAVES:3)
Block(1,51,14,LEAVES:3)
Block(1,51,15,LEAVES:3)
Block(1,51,16,LEAVES:3)
Block(1,52,-13,LEAVES:3)
Block(1,52,-12,LEAVES:3)
Block(1,52,-10,LEAVES:3)
Block(1,52,-9,LEAVES:3)
Block(1,52,-7,LEAVES:3)
Block(1,52,9,LEAVES:3)
Block(1,52,10,LEAVES:3)
Block(1,52,13,LEAVES:3)
Block(1,53,-14,LEAVES:3)
Block(1,53,-9,LEAVES:3)
Block(1,59,8,LEAVES:3)
Block(1,60,2,LEAVES:3)
Block(1,60,5,17:15)
Block(1,60,8,LEAVES:3)
Block(1,60,9,17:15)
Block(1,60,12,LEAVES:3)
Block(1,61,3,LEAVES:3)
Block(1,61,6,LEAVES:3)
Block(1,61,7,LEAVES:3)
Block(1,61,8,LEAVES:3)
Block(1,61,9,17:15)
Block(1,61,10,17:15)
Block(1,61,12,LEAVES:3)
Block(1,62,3,LEAVES:3)
Block(1,62,7,LEAVES:3)
Block(1,62,8,LEAVES:3)
Block(1,62,9,LEAVES:3)
Block(1,62,10,LEAVES:3)
Block(1,62,11,LEAVES:3)
Block(1,62,12,LEAVES:3)
Block(1,62,13,LEAVES:3)
Block(1,63,8,LEAVES:3)
Block(1,63,9,LEAVES:3)
Block(1,63,12,LEAVES:3)
Block(1,66,1,17:15)
Block(1,66,2,17:15)
Block(1,66,3,17:15)
Block(1,67,3,17:15)
Block(1,68,-6,LEAVES:3)
Block(1,68,6,LEAVES:3)
Block(1,69,-7,LEAVES:3)
Block(1,69,-6,17:15)
Block(1,69,-5,LEAVES:3)
Block(1,69,-4,LEAVES:3)
Block(1,69,6,LEAVES:3)
Block(1,69,7,17:15)
Block(1,69,8,LEAVES:3)
Block(1,70,-10,LEAVES:3)
Block(1,70,-9,LEAVES:3)
Block(1,70,-8,LEAVES:3)
Block(1,70,-6,LEAVES:3)
Block(1,70,-4,LEAVES:3)
Block(1,70,1,LEAVES:3)
Block(1,70,2,LEAVES:3)
Block(1,70,4,LEAVES:3)
Block(1,70,12,LEAVES:3)
Block(1,70,13,LEAVES:3)
Block(1,70,14,LEAVES:3)
Block(1,70,16,LEAVES:3)
Block(1,71,-6,LEAVES:3)
Block(1,71,2,LEAVES:3)
Block(1,71,3,LEAVES:3)
Block(1,71,4,LEAVES:3)
Block(1,71,14,LEAVES:3)
Block(1,71,15,LEAVES:3)
Block(1,71,16,LEAVES:3)
Block(1,71,17,LEAVES:3)
Block(1,72,3,LEAVES:3)
Block(1,72,16,LEAVES:3)
Block(1,74,3,17:15)
Block(1,75,2,17:15)
Block(1,75,3,17:15)
Block(1,75,6,LEAVES:3)
Block(1,76,-5,LEAVES:3)
Block(1,76,7,LEAVES:3)
Block(1,76,9,LEAVES:3)
Block(1,77,-3,LEAVES:3)
Block(1,77,-1,LEAVES:3)
Block(1,77,6,LEAVES:3)
Block(1,77,7,LEAVES:3)
Block(1,77,8,LEAVES:3)
Block(1,78,-8,LEAVES:3)
Block(1,78,-6,LEAVES:3)
Block(1,78,-5,LEAVES:3)
Block(1,78,-4,LEAVES:3)
Block(1,78,-3,17:15)
Block(1,78,-2,LEAVES:3)
Block(1,78,2,LEAVES:3)
Block(1,78,6,LEAVES:3)
Block(1,78,7,LEAVES:3)
Block(1,78,8,LEAVES:3)
Block(1,78,10,LEAVES:3)
Block(1,78,15,LEAVES:3)
Block(1,79,-10,LEAVES:3)
Block(1,79,-9,LEAVES:3)
Block(1,79,-5,LEAVES:3)
Block(1,79,-4,LEAVES:3)
Block(1,79,-3,LEAVES:3)
Block(1,79,-2,LEAVES:3)
Block(1,79,0,LEAVES:3)
Block(1,79,7,LEAVES:3)
Block(1,79,8,LEAVES:3)
Block(1,79,9,LEAVES:3)
Block(1,79,10,LEAVES:3)
Block(1,79,11,17:15)
Block(1,79,12,LEAVES:3)
Block(1,79,13,LEAVES:3)
Block(1,79,14,LEAVES:3)
Block(1,80,-11,LEAVES:3)
Block(1,80,-4,LEAVES:3)
Block(1,80,-1,LEAVES:3)
Block(1,80,2,LEAVES:3)
Block(1,80,9,LEAVES:3)
Block(1,80,10,LEAVES:3)
Block(1,80,11,LEAVES:3)
Block(1,81,11,LEAVES:3)
Block(2,-6,5,17:15)
Block(2,-5,5,17:15)
Block(2,-4,1,17:15)
Block(2,-4,5,17:15)
Block(2,-3,0,17:15)
Block(2,-3,1,17:15)
Block(2,-3,5,17:15)
Block(2,-2,1,17:15)
Block(2,-2,5,17:15)
Block(2,-1,0,17:15)
Block(2,-1,1,17:15)
Block(2,0,1,17:15)
Block(2,24,1,17:15)
Block(2,25,1,17:15)
Block(2,25,2,17:15)
Block(2,26,-5,17:15)
Block(2,26,-4,17:15)
Block(2,26,-3,LEAVES:3)
Block(2,26,5,17:15)
Block(2,27,-7,17:15)
Block(2,27,-6,17:15)
Block(2,27,-5,17:15)
Block(2,27,-3,LEAVES:3)
Block(2,27,4,LEAVES:3)
Block(2,27,9,17:15)
Block(2,27,10,LEAVES:3)
Block(2,28,-8,17:15)
Block(2,29,0,17:15)
Block(2,29,1,LEAVES:3)
Block(2,37,1,17:15)
Block(2,38,1,17:15)
Block(2,38,2,17:15)
Block(2,38,3,LEAVES:3)
Block(2,39,-5,LEAVES:3)
Block(2,39,-4,LEAVES:3)
Block(2,39,-2,LEAVES:3)
Block(2,40,-7,LEAVES:3)
Block(2,40,-5,LEAVES:3)
Block(2,40,-4,LEAVES:3)
Block(2,40,-3,LEAVES:3)
Block(2,40,-2,LEAVES:3)
Block(2,40,1,LEAVES:3)
Block(2,40,3,LEAVES:3)
Block(2,41,-6,LEAVES:3)
Block(2,41,-5,LEAVES:3)
Block(2,41,-4,LEAVES:3)
Block(2,41,-3,LEAVES:3)
Block(2,41,0,LEAVES:3)
Block(2,41,3,LEAVES:3)
Block(2,41,6,LEAVES:3)
Block(2,42,-4,LEAVES:3)
Block(2,42,1,LEAVES:3)
Block(2,42,5,LEAVES:3)
Block(2,42,6,LEAVES:3)
Block(2,42,7,LEAVES:3)
Block(2,42,8,LEAVES:3)
Block(2,43,6,LEAVES:3)
Block(2,43,7,LEAVES:3)
Block(2,47,7,LEAVES:3)
Block(2,47,8,17:15)
Block(2,48,3,LEAVES:3)
Block(2,48,4,17:15)
Block(2,48,7,LEAVES:3)
Block(2,48,9,17:15)
Block(2,48,10,LEAVES:3)
Block(2,49,-4,17:15)
Block(2,49,-2,17:15)
Block(2,49,11,LEAVES:3)
Block(2,49,13,LEAVES:3)
Block(2,49,16,LEAVES:3)
Block(2,50,-6,17:15)
Block(2,50,-5,17:15)
Block(2,50,-4,17:15)
Block(2,50,-2,LEAVES:3)
Block(2,50,-1,LEAVES:3)
Block(2,50,0,LEAVES:3)
Block(2,50,1,LEAVES:3)
Block(2,50,8,LEAVES:3)
Block(2,50,9,LEAVES:3)
Block(2,50,11,17:15)
Block(2,50,13,LEAVES:3)
Block(2,50,14,LEAVES:3)
Block(2,50,15,LEAVES:3)
Block(2,50,16,17:15)
Block(2,50,17,LEAVES:3)
Block(2,51,-7,LEAVES:3)
Block(2,51,-6,17:15)
Block(2,51,-5,LEAVES:3)
Block(2,51,-4,LEAVES:3)
Block(2,51,-3,LEAVES:3)
Block(2,51,-1,LEAVES:3)
Block(2,51,0,LEAVES:3)
Block(2,51,8,LEAVES:3)
Block(2,51,9,LEAVES:3)
Block(2,51,10,17:15)
Block(2,51,11,LEAVES:3)
Block(2,51,13,LEAVES:3)
Block(2,51,16,LEAVES:3)
Block(2,51,17,LEAVES:3)
Block(2,52,-14,LEAVES:3)
Block(2,52,-12,LEAVES:3)
Block(2,52,-11,LEAVES:3)
Block(2,52,-10,LEAVES:3)
Block(2,52,-6,LEAVES:3)
Block(2,52,-5,LEAVES:3)
Block(2,52,-1,LEAVES:3)
Block(2,52,10,LEAVES:3)
Block(2,52,11,LEAVES:3)
Block(2,53,-15,LEAVES:3)
Block(2,53,-14,LEAVES:3)
Block(2,53,-13,LEAVES:3)
Block(2,53,-12,LEAVES:3)
Block(2,53,10,LEAVES:3)
Block(2,54,-14,LEAVES:3)
Block(2,60,1,LEAVES:3)
Block(2,60,4,17:15)
Block(2,60,5,LEAVES:3)
Block(2,60,7,LEAVES:3)
Block(2,61,1,LEAVES:3)
Block(2,61,2,LEAVES:3)
Block(2,61,3,17:15)
Block(2,61,4,LEAVES:3)
Block(2,61,7,LEAVES:3)
Block(2,61,8,LEAVES:3)
Block(2,61,9,LEAVES:3)
Block(2,61,10,17:15)
Block(2,61,11,17:15)
Block(2,61,13,LEAVES:3)
Block(2,62,2,LEAVES:3)
Block(2,62,3,LEAVES:3)
Block(2,62,4,LEAVES:3)
Block(2,62,9,LEAVES:3)
Block(2,62,11,17:15)
Block(2,62,12,LEAVES:3)
Block(2,62,13,LEAVES:3)
Block(2,62,14,LEAVES:3)
Block(2,62,15,LEAVES:3)
Block(2,63,3,LEAVES:3)
Block(2,63,12,LEAVES:3)
Block(2,63,13,LEAVES:3)
Block(2,66,0,17:15)
Block(2,66,3,17:15)
Block(2,67,-2,17:15)
Block(2,67,-1,17:15)
Block(2,67,3,17:15)
Block(2,67,4,17:15)
Block(2,68,-5,17:15)
Block(2,68,-4,LEAVES:3)
Block(2,68,-2,LEAVES:3)
Block(2,69,-10,LEAVES:3)
Block(2,69,-8,LEAVES:3)
Block(2,69,-7,17:15)
Block(2,69,-5,17:15)
Block(2,69,-4,LEAVES:3)
Block(2,69,-3,LEAVES:3)
Block(2,69,5,LEAVES:3)
Block(2,69,6,17:15)
Block(2,69,7,LEAVES:3)
Block(2,69,8,LEAVES:3)
Block(2,69,9,LEAVES:3)
Block(2,69,11,LEAVES:3)
Block(2,69,14,LEAVES:3)
Block(2,70,-11,LEAVES:3)
Block(2,70,-10,LEAVES:3)
Block(2,70,-9,LEAVES:3)
Block(2,70,-8,17:15)
Block(2,70,-7,LEAVES:3)
Block(2,70,-5,LEAVES:3)
Block(2,70,-4,LEAVES:3)
Block(2,70,7,LEAVES:3)
Block(2,70,8,LEAVES:3)
Block(2,70,11,LEAVES:3)
Block(2,70,12,LEAVES:3)
Block(2,70,13,LEAVES:3)
Block(2,70,14,17:15)
Block(2,70,18,LEAVES:3)
Block(2,71,-10,LEAVES:3)
Block(2,71,-9,LEAVES:3)
Block(2,71,-8,LEAVES:3)
Block(2,71,-7,LEAVES:3)
Block(2,71,-3,LEAVES:3)
Block(2,71,1,LEAVES:3)
Block(2,71,2,LEAVES:3)
Block(2,71,3,17:15)
Block(2,71,4,LEAVES:3)
Block(2,71,5,LEAVES:3)
Block(2,71,12,LEAVES:3)
Block(2,71,13,LEAVES:3)
Block(2,71,14,LEAVES:3)
Block(2,71,15,17:15)
Block(2,71,16,LEAVES:3)
Block(2,71,17,LEAVES:3)
Block(2,71,18,LEAVES:3)
Block(2,72,-8,LEAVES:3)
Block(2,72,-4,LEAVES:3)
Block(2,72,2,LEAVES:3)
Block(2,72,3,LEAVES:3)
Block(2,72,4,LEAVES:3)
Block(2,72,14,LEAVES:3)
Block(2,72,15,LEAVES:3)
Block(2,72,16,LEAVES:3)
Block(2,72,17,LEAVES:3)
Block(2,73,15,LEAVES:3)
Block(2,74,2,17:15)
Block(2,74,3,17:15)
Block(2,75,2,17:15)
Block(2,75,3,17:15)
Block(2,76,0,LEAVES:3)
Block(2,76,3,LEAVES:3)
Block(2,76,5,LEAVES:3)
Block(2,77,-5,LEAVES:3)
Block(2,77,0,LEAVES:3)
Block(2,77,6,LEAVES:3)
Block(2,77,7,17:15)
Block(2,77,8,LEAVES:3)
Block(2,77,9,LEAVES:3)
Block(2,78,-5,LEAVES:3)
Block(2,78,-4,LEAVES:3)
Block(2,78,-3,LEAVES:3)
Block(2,78,-2,17:15)
Block(2,78,-1,LEAVES:3)
Block(2,78,6,LEAVES:3)
Block(2,78,7,LEAVES:3)
Block(2,78,8,LEAVES:3)
Block(2,78,11,LEAVES:3)
Block(2,78,13,LEAVES:3)
Block(2,79,-4,LEAVES:3)
Block(2,79,-3,LEAVES:3)
Block(2,79,-2,LEAVES:3)
Block(2,79,-1,LEAVES:3)
Block(2,79,0,LEAVES:3)
Block(2,79,1,LEAVES:3)
Block(2,79,9,LEAVES:3)
Block(2,79,10,LEAVES:3)
Block(2,79,11,LEAVES:3)
Block(2,79,12,17:15)
Block(2,79,13,LEAVES:3)
Block(2,79,14,LEAVES:3)
Block(2,80,-2,LEAVES:3)
Block(2,80,-1,17:15)
Block(2,80,0,LEAVES:3)
Block(2,80,10,LEAVES:3)
Block(2,80,12,LEAVES:3)
Block(2,80,13,LEAVES:3)
Block(2,81,-1,LEAVES:3)
Block(2,81,0,LEAVES:3)
Block(3,-5,1,17:15)
Block(3,-5,2,17:15)
Block(3,-4,1,17:15)
Block(3,-4,2,17:15)
Block(3,-3,1,17:15)
Block(3,-3,2,17:15)
Block(3,-2,1,17:15)
Block(3,-2,2,17:15)
Block(3,-1,2,17:15)
Block(3,24,0,17:15)
Block(3,25,-2,17:15)
Block(3,25,0,17:15)
Block(3,25,1,17:15)
Block(3,25,3,17:15)
Block(3,25,4,17:15)
Block(3,26,-3,17:15)
Block(3,26,3,17:15)
Block(3,26,5,17:15)
Block(3,27,7,LEAVES:3)
Block(3,27,8,17:15)
Block(3,28,-8,17:15)
Block(3,28,-7,LEAVES:3)
Block(3,29,-1,17:15)
Block(3,30,-1,LEAVES:3)
Block(3,37,1,17:15)
Block(3,38,0,17:15)
Block(3,38,1,17:15)
Block(3,38,2,LEAVES:3)
Block(3,39,-6,LEAVES:3)
Block(3,39,-3,LEAVES:3)
Block(3,40,-6,LEAVES:3)
Block(3,40,-4,17:15)
Block(3,40,-3,LEAVES:3)
Block(3,40,-2,LEAVES:3)
Block(3,40,5,LEAVES:3)
Block(3,41,-7,LEAVES:3)
Block(3,41,-6,LEAVES:3)
Block(3,41,-5,17:15)
Block(3,41,-4,LEAVES:3)
Block(3,41,-3,LEAVES:3)
Block(3,41,-1,LEAVES:3)
Block(3,41,1,LEAVES:3)
Block(3,41,2,LEAVES:3)
Block(3,41,3,LEAVES:3)
Block(3,41,4,LEAVES:3)
Block(3,41,6,LEAVES:3)
Block(3,41,8,LEAVES:3)
Block(3,42,-6,LEAVES:3)
Block(3,42,-5,LEAVES:3)
Block(3,42,0,LEAVES:3)
Block(3,42,1,LEAVES:3)
Block(3,42,2,LEAVES:3)
Block(3,42,3,LEAVES:3)
Block(3,42,5,LEAVES:3)
Block(3,42,6,17:15)
Block(3,42,7,LEAVES:3)
Block(3,43,1,LEAVES:3)
Block(3,43,6,LEAVES:3)
Block(3,44,6,LEAVES:3)
Block(3,47,7,LEAVES:3)
Block(3,48,4,17:15)
Block(3,48,9,LEAVES:3)
Block(3,49,-3,17:15)
Block(3,49,0,LEAVES:3)
Block(3,49,4,LEAVES:3)
Block(3,49,13,LEAVES:3)
Block(3,49,17,LEAVES:3)
Block(3,50,-7,17:15)
Block(3,50,-6,LEAVES:3)
Block(3,50,-3,LEAVES:3)
Block(3,50,-1,LEAVES:3)
Block(3,50,0,LEAVES:3)
Block(3,50,7,LEAVES:3)
Block(3,50,11,LEAVES:3)
Block(3,50,12,17:15)
Block(3,50,13,LEAVES:3)
Block(3,50,15,LEAVES:3)
Block(3,50,16,LEAVES:3)
Block(3,50,17,LEAVES:3)
Block(3,50,18,LEAVES:3)
Block(3,51,-12,LEAVES:3)
Block(3,51,-9,LEAVES:3)
Block(3,51,-8,LEAVES:3)
Block(3,51,-7,17:15)
Block(3,51,-6,LEAVES:3)
Block(3,51,-5,LEAVES:3)
Block(3,51,-4,LEAVES:3)
Block(3,51,-1,LEAVES:3)
Block(3,51,7,LEAVES:3)
Block(3,51,8,LEAVES:3)
Block(3,51,9,17:15)
Block(3,51,10,LEAVES:3)
Block(3,51,12,LEAVES:3)
Block(3,51,16,LEAVES:3)
Block(3,51,17,LEAVES:3)
Block(3,52,-16,LEAVES:3)
Block(3,52,-12,17:15)
Block(3,52,-11,LEAVES:3)
Block(3,52,-10,LEAVES:3)
Block(3,52,-9,LEAVES:3)
Block(3,52,-7,LEAVES:3)
Block(3,52,-5,LEAVES:3)
Block(3,52,-4,LEAVES:3)
Block(3,52,8,LEAVES:3)
Block(3,52,9,LEAVES:3)
Block(3,52,12,LEAVES:3)
Block(3,53,-16,LEAVES:3)
Block(3,53,-15,LEAVES:3)
Block(3,53,-14,LEAVES:3)
Block(3,53,-13,17:15)
Block(3,53,-12,LEAVES:3)
Block(3,53,-11,LEAVES:3)
Block(3,53,-10,LEAVES:3)
Block(3,53,-5,LEAVES:3)
Block(3,54,-15,LEAVES:3)
Block(3,54,-14,LEAVES:3)
Block(3,54,-13,LEAVES:3)
Block(3,54,-12,LEAVES:3)
Block(3,55,-13,LEAVES:3)
Block(3,59,1,LEAVES:3)
Block(3,60,2,LEAVES:3)
Block(3,60,8,LEAVES:3)
Block(3,60,10,LEAVES:3)
Block(3,60,15,LEAVES:3)
Block(3,61,0,LEAVES:3)
Block(3,61,1,LEAVES:3)
Block(3,61,2,17:15)
Block(3,61,3,LEAVES:3)
Block(3,61,9,LEAVES:3)
Block(3,61,10,LEAVES:3)
Block(3,61,16,LEAVES:3)
Block(3,62,1,LEAVES:3)
Block(3,62,2,LEAVES:3)
Block(3,62,3,LEAVES:3)
Block(3,62,10,LEAVES:3)
Block(3,62,11,17:15)
Block(3,62,12,17:15)
Block(3,62,13,17:15)
Block(3,62,14,LEAVES:3)
Block(3,62,15,LEAVES:3)
Block(3,62,16,LEAVES:3)
Block(3,63,11,LEAVES:3)
Block(3,63,12,LEAVES:3)
Block(3,63,13,LEAVES:3)
Block(3,63,14,LEAVES:3)
Block(3,63,15,LEAVES:3)
Block(3,64,13,LEAVES:3)
Block(3,67,-4,LEAVES:3)
Block(3,67,-2,17:15)
Block(3,67,4,17:15)
Block(3,68,-7,LEAVES:3)
Block(3,68,-6,LEAVES:3)
Block(3,68,-4,17:15)
Block(3,68,-3,17:15)
Block(3,68,-2,17:15)
Block(3,68,-1,LEAVES:3)
Block(3,68,4,17:15)
Block(3,68,6,17:15)
Block(3,68,7,17:15)
Block(3,69,-7,LEAVES:3)
Block(3,69,-6,LEAVES:3)
Block(3,69,-5,LEAVES:3)
Block(3,69,-4,LEAVES:3)
Block(3,69,-3,LEAVES:3)
Block(3,69,-2,LEAVES:3)
Block(3,69,4,LEAVES:3)
Block(3,69,5,LEAVES:3)
Block(3,69,6,17:15)
Block(3,69,7,LEAVES:3)
Block(3,69,8,17:15)
Block(3,69,9,LEAVES:3)
Block(3,69,13,LEAVES:3)
Block(3,70,-10,LEAVES:3)
Block(3,70,-9,LEAVES:3)
Block(3,70,-8,LEAVES:3)
Block(3,70,-6,LEAVES:3)
Block(3,70,-5,LEAVES:3)
Block(3,70,-3,LEAVES:3)
Block(3,70,5,LEAVES:3)
Block(3,70,6,LEAVES:3)
Block(3,70,7,LEAVES:3)
Block(3,70,8,LEAVES:3)
Block(3,70,11,LEAVES:3)
Block(3,70,12,17:15)
Block(3,70,13,17:15)
Block(3,70,14,LEAVES:3)
Block(3,70,15,LEAVES:3)
Block(3,70,17,LEAVES:3)
Block(3,71,-8,LEAVES:3)
Block(3,71,-5,LEAVES:3)
Block(3,71,1,LEAVES:3)
Block(3,71,2,17:15)
Block(3,71,3,LEAVES:3)
Block(3,71,4,LEAVES:3)
Block(3,71,8,LEAVES:3)
Block(3,71,12,LEAVES:3)
Block(3,71,13,LEAVES:3)
Block(3,71,14,LEAVES:3)
Block(3,71,15,LEAVES:3)
Block(3,71,16,LEAVES:3)
Block(3,71,17,LEAVES:3)
Block(3,72,-5,LEAVES:3)
Block(3,72,-4,LEAVES:3)
Block(3,72,-3,LEAVES:3)
Block(3,72,1,LEAVES:3)
Block(3,72,2,LEAVES:3)
Block(3,72,3,LEAVES:3)
Block(3,72,13,LEAVES:3)
Block(3,72,15,LEAVES:3)
Block(3,73,-4,LEAVES:3)
Block(3,73,2,LEAVES:3)
Block(3,74,3,17:15)
Block(3,75,2,17:15)
Block(3,75,3,17:15)
Block(3,76,4,LEAVES:3)
Block(3,76,5,17:15)
Block(3,76,8,LEAVES:3)
Block(3,77,-4,LEAVES:3)
Block(3,77,-2,17:15)
Block(3,77,0,LEAVES:3)
Block(3,77,1,LEAVES:3)
Block(3,77,3,LEAVES:3)
Block(3,77,4,LEAVES:3)
Block(3,77,5,LEAVES:3)
Block(3,77,6,17:15)
Block(3,77,7,LEAVES:3)
Block(3,77,8,LEAVES:3)
Block(3,78,-4,LEAVES:3)
Block(3,78,-2,LEAVES:3)
Block(3,78,0,LEAVES:3)
Block(3,78,1,LEAVES:3)
Block(3,78,5,LEAVES:3)
Block(3,78,6,LEAVES:3)
Block(3,78,7,LEAVES:3)
Block(3,78,11,LEAVES:3)
Block(3,78,14,LEAVES:3)
Block(3,79,-2,LEAVES:3)
Block(3,79,-1,17:15)
Block(3,79,6,LEAVES:3)
Block(3,79,10,LEAVES:3)
Block(3,79,11,LEAVES:3)
Block(3,79,12,LEAVES:3)
Block(3,79,13,LEAVES:3)
Block(3,80,-1,17:15)
Block(3,80,0,17:15)
Block(3,80,1,LEAVES:3)
Block(3,80,12,LEAVES:3)
Block(3,81,-2,LEAVES:3)
Block(3,81,-1,LEAVES:3)
Block(3,81,0,LEAVES:3)
Block(3,82,-4,LEAVES:3)
Block(3,82,-1,LEAVES:3)
Block(3,82,0,LEAVES:3)
Block(4,-6,1,17:15)
Block(4,-6,3,17:15)
Block(4,-5,1,17:15)
Block(4,-5,3,17:15)
Block(4,-4,1,17:15)
Block(4,-4,3,17:15)
Block(4,-3,1,17:15)
Block(4,-3,3,17:15)
Block(4,-2,1,17:15)
Block(4,25,-1,17:15)
Block(4,25,0,17:15)
Block(4,25,5,17:15)
Block(4,26,-1,17:15)
Block(4,26,3,17:15)
Block(4,26,6,17:15)
Block(4,26,7,17:15)
Block(4,27,8,17:15)
Block(4,28,-10,LEAVES:3)
Block(4,28,-9,17:15)
Block(4,28,-2,17:15)
Block(4,28,-1,LEAVES:3)
Block(4,28,0,LEAVES:3)
Block(4,29,-2,LEAVES:3)
Block(4,38,0,17:15)
Block(4,38,1,17:15)
Block(4,39,-1,17:15)
Block(4,39,0,17:15)
Block(4,39,1,17:15)
Block(4,40,-7,LEAVES:3)
Block(4,40,-5,LEAVES:3)
Block(4,40,-4,17:15)
Block(4,40,-3,LEAVES:3)
Block(4,40,2,LEAVES:3)
Block(4,41,-7,LEAVES:3)
Block(4,41,-6,LEAVES:3)
Block(4,41,-5,LEAVES:3)
Block(4,41,-4,LEAVES:3)
Block(4,41,-1,LEAVES:3)
Block(4,41,2,LEAVES:3)
Block(4,41,3,17:15)
Block(4,41,4,LEAVES:3)
Block(4,41,5,LEAVES:3)
Block(4,41,6,LEAVES:3)
Block(4,42,-1,LEAVES:3)
Block(4,42,0,LEAVES:3)
Block(4,42,1,17:15)
Block(4,42,2,17:15)
Block(4,42,3,LEAVES:3)
Block(4,42,5,17:15)
Block(4,42,6,LEAVES:3)
Block(4,43,0,LEAVES:3)
Block(4,43,1,LEAVES:3)
Block(4,43,2,LEAVES:3)
Block(4,43,5,LEAVES:3)
Block(4,43,6,LEAVES:3)
Block(4,44,2,LEAVES:3)
Block(4,48,4,LEAVES:3)
Block(4,48,5,LEAVES:3)
Block(4,49,16,LEAVES:3)
Block(4,50,-5,LEAVES:3)
Block(4,50,-3,17:15)
Block(4,50,-2,17:15)
Block(4,50,9,LEAVES:3)
Block(4,50,12,LEAVES:3)
Block(4,50,15,LEAVES:3)
Block(4,50,16,LEAVES:3)
Block(4,50,17,LEAVES:3)
Block(4,51,-11,LEAVES:3)
Block(4,51,-8,17:15)
Block(4,51,-7,17:15)
Block(4,51,-6,LEAVES:3)
Block(4,51,-5,LEAVES:3)
Block(4,51,-4,LEAVES:3)
Block(4,51,-3,LEAVES:3)
Block(4,51,-2,LEAVES:3)
Block(4,51,-1,LEAVES:3)
Block(4,51,0,LEAVES:3)
Block(4,51,8,LEAVES:3)
Block(4,51,9,LEAVES:3)
Block(4,51,10,LEAVES:3)
Block(4,51,11,LEAVES:3)
Block(4,51,12,17:15)
Block(4,51,13,LEAVES:3)
Block(4,51,14,LEAVES:3)
Block(4,51,16,LEAVES:3)
Block(4,52,-15,LEAVES:3)
Block(4,52,-13,LEAVES:3)
Block(4,52,-12,LEAVES:3)
Block(4,52,-11,17:15)
Block(4,52,-10,17:15)
Block(4,52,-9,LEAVES:3)
Block(4,52,-8,LEAVES:3)
Block(4,52,-7,LEAVES:3)
Block(4,52,-6,LEAVES:3)
Block(4,52,-5,LEAVES:3)
Block(4,52,-2,LEAVES:3)
Block(4,52,9,LEAVES:3)
Block(4,52,12,LEAVES:3)
Block(4,52,13,LEAVES:3)
Block(4,53,-15,LEAVES:3)
Block(4,53,-14,LEAVES:3)
Block(4,53,-13,LEAVES:3)
Block(4,53,-12,LEAVES:3)
Block(4,53,-11,LEAVES:3)
Block(4,53,-10,LEAVES:3)
Block(4,53,-7,LEAVES:3)
Block(4,53,12,LEAVES:3)
Block(4,54,-13,LEAVES:3)
Block(4,54,-11,LEAVES:3)
Block(4,60,1,LEAVES:3)
Block(4,60,4,LEAVES:3)
Block(4,61,1,LEAVES:3)
Block(4,61,2,LEAVES:3)
Block(4,61,3,LEAVES:3)
Block(4,61,4,LEAVES:3)
Block(4,61,12,LEAVES:3)
Block(4,61,14,LEAVES:3)
Block(4,62,1,LEAVES:3)
Block(4,62,2,LEAVES:3)
Block(4,62,3,LEAVES:3)
Block(4,62,10,LEAVES:3)
Block(4,62,11,LEAVES:3)
Block(4,62,12,LEAVES:3)
Block(4,62,13,LEAVES:3)
Block(4,62,14,LEAVES:3)
Block(4,62,15,LEAVES:3)
Block(4,63,2,LEAVES:3)
Block(4,63,11,LEAVES:3)
Block(4,63,14,LEAVES:3)
Block(4,67,-2,LEAVES:3)
Block(4,67,-1,LEAVES:3)
Block(4,68,-5,LEAVES:3)
Block(4,68,-3,17:15)
Block(4,68,-2,LEAVES:3)
Block(4,68,4,17:15)
Block(4,68,5,17:15)
Block(4,69,-9,LEAVES:3)
Block(4,69,-6,LEAVES:3)
Block(4,69,-5,LEAVES:3)
Block(4,69,-4,17:15)
Block(4,69,-3,LEAVES:3)
Block(4,69,-2,LEAVES:3)
Block(4,69,5,LEAVES:3)
Block(4,69,6,17:15)
Block(4,69,8,LEAVES:3)
Block(4,69,9,17:15)
Block(4,69,10,17:15)
Block(4,69,11,17:15)
Block(4,69,15,LEAVES:3)
Block(4,70,-9,LEAVES:3)
Block(4,70,-8,LEAVES:3)
Block(4,70,-5,LEAVES:3)
Block(4,70,-4,LEAVES:3)
Block(4,70,-3,LEAVES:3)
Block(4,70,2,17:15)
Block(4,70,3,LEAVES:3)
Block(4,70,4,LEAVES:3)
Block(4,70,8,LEAVES:3)
Block(4,70,10,LEAVES:3)
Block(4,70,11,LEAVES:3)
Block(4,70,12,LEAVES:3)
Block(4,70,13,LEAVES:3)
Block(4,70,14,LEAVES:3)
Block(4,70,15,LEAVES:3)
Block(4,71,-4,LEAVES:3)
Block(4,71,-3,LEAVES:3)
Block(4,71,-1,LEAVES:3)
Block(4,71,2,LEAVES:3)
Block(4,71,3,LEAVES:3)
Block(4,71,11,LEAVES:3)
Block(4,71,13,LEAVES:3)
Block(4,71,14,LEAVES:3)
Block(4,71,15,LEAVES:3)
Block(4,72,-6,LEAVES:3)
Block(4,72,-5,LEAVES:3)
Block(4,72,-4,17:15)
Block(4,72,-3,LEAVES:3)
Block(4,72,-2,LEAVES:3)
Block(4,72,2,LEAVES:3)
Block(4,73,-5,LEAVES:3)
Block(4,73,-4,LEAVES:3)
Block(4,73,-3,LEAVES:3)
Block(4,75,3,17:15)
Block(4,76,1,17:15)
Block(4,76,2,17:15)
Block(4,76,3,17:15)
Block(4,76,4,17:15)
Block(4,76,6,LEAVES:3)
Block(4,77,-2,LEAVES:3)
Block(4,77,-1,17:15)
Block(4,77,0,17:15)
Block(4,77,1,LEAVES:3)
Block(4,77,2,LEAVES:3)
Block(4,77,3,LEAVES:3)
Block(4,77,4,LEAVES:3)
Block(4,77,5,LEAVES:3)
Block(4,77,6,LEAVES:3)
Block(4,78,0,LEAVES:3)
Block(4,78,1,LEAVES:3)
Block(4,78,2,LEAVES:3)
Block(4,78,4,LEAVES:3)
Block(4,78,6,LEAVES:3)
Block(4,78,12,LEAVES:3)
Block(4,79,-1,LEAVES:3)
Block(4,79,12,LEAVES:3)
Block(4,80,-2,LEAVES:3)
Block(4,80,-1,17:15)
Block(4,80,1,LEAVES:3)
Block(4,81,-3,LEAVES:3)
Block(4,81,-2,LEAVES:3)
Block(4,81,-1,LEAVES:3)
Block(4,81,0,17:15)
Block(4,81,1,17:15)
Block(4,81,2,LEAVES:3)
Block(4,82,-5,LEAVES:3)
Block(4,82,-4,LEAVES:3)
Block(4,82,-3,LEAVES:3)
Block(4,82,-2,LEAVES:3)
Block(4,82,0,LEAVES:3)
Block(4,82,1,LEAVES:3)
Block(4,83,-4,LEAVES:3)
Block(4,83,0,LEAVES:3)
Block(5,26,-2,17:15)
Block(5,26,-1,17:15)
Block(5,26,1,LEAVES:3)
Block(5,26,2,17:15)
Block(5,26,3,17:15)
Block(5,27,-4,LEAVES:3)
Block(5,27,-3,LEAVES:3)
Block(5,27,-2,17:15)
Block(5,27,3,LEAVES:3)
Block(5,27,9,17:15)
Block(5,28,-3,LEAVES:3)
Block(5,28,-1,LEAVES:3)
Block(5,28,9,LEAVES:3)
Block(5,28,10,17:15)
Block(5,28,11,LEAVES:3)
Block(5,28,12,LEAVES:3)
Block(5,29,10,LEAVES:3)
Block(5,30,-11,LEAVES:3)
Block(5,38,1,17:15)
Block(5,38,2,LEAVES:3)
Block(5,39,-2,17:15)
Block(5,39,-1,17:15)
Block(5,39,1,17:15)
Block(5,39,2,17:15)
Block(5,39,3,LEAVES:3)
Block(5,40,-4,LEAVES:3)
Block(5,40,-3,17:15)
Block(5,40,3,LEAVES:3)
Block(5,40,7,LEAVES:3)
Block(5,41,-3,LEAVES:3)
Block(5,41,3,LEAVES:3)
Block(5,41,4,17:15)
Block(5,41,5,17:15)
Block(5,41,6,LEAVES:3)
Block(5,41,7,LEAVES:3)
Block(5,42,0,LEAVES:3)
Block(5,42,1,LEAVES:3)
Block(5,42,2,LEAVES:3)
Block(5,42,4,LEAVES:3)
Block(5,42,5,LEAVES:3)
Block(5,42,6,LEAVES:3)
Block(5,43,-9,LEAVES:3)
Block(5,43,2,LEAVES:3)
Block(5,43,5,LEAVES:3)
Block(5,44,-10,LEAVES:3)
Block(5,48,4,LEAVES:3)
Block(5,49,2,LEAVES:3)
Block(5,49,15,LEAVES:3)
Block(5,50,-6,LEAVES:3)
Block(5,50,-3,17:15)
Block(5,50,-2,LEAVES:3)
Block(5,50,-1,17:15)
Block(5,50,1,LEAVES:3)
Block(5,50,8,LEAVES:3)
Block(5,50,14,LEAVES:3)
Block(5,50,16,LEAVES:3)
Block(5,51,-13,LEAVES:3)
Block(5,51,-9,17:15)
Block(5,51,-8,17:15)
Block(5,51,-6,LEAVES:3)
Block(5,51,-5,LEAVES:3)
Block(5,51,-2,LEAVES:3)
Block(5,51,-1,LEAVES:3)
Block(5,51,0,17:15)
Block(5,51,1,LEAVES:3)
Block(5,51,2,LEAVES:3)
Block(5,51,9,LEAVES:3)
Block(5,51,10,LEAVES:3)
Block(5,51,11,LEAVES:3)
Block(5,51,12,LEAVES:3)
Block(5,51,13,LEAVES:3)
Block(5,51,14,LEAVES:3)
Block(5,52,-13,LEAVES:3)
Block(5,52,-12,LEAVES:3)
Block(5,52,-11,LEAVES:3)
Block(5,52,-10,LEAVES:3)
Block(5,52,-9,LEAVES:3)
Block(5,52,-8,LEAVES:3)
Block(5,52,-7,LEAVES:3)
Block(5,52,0,LEAVES:3)
Block(5,52,1,LEAVES:3)
Block(5,52,12,LEAVES:3)
Block(5,53,-13,LEAVES:3)
Block(5,53,-12,LEAVES:3)
Block(5,53,-11,LEAVES:3)
Block(5,53,-9,LEAVES:3)
Block(5,59,2,LEAVES:3)
Block(5,60,3,LEAVES:3)
Block(5,61,1,LEAVES:3)
Block(5,61,2,LEAVES:3)
Block(5,61,3,LEAVES:3)
Block(5,61,10,LEAVES:3)
Block(5,61,15,LEAVES:3)
Block(5,62,2,LEAVES:3)
Block(5,62,11,LEAVES:3)
Block(5,62,14,LEAVES:3)
Block(5,67,-2,LEAVES:3)
Block(5,68,-9,LEAVES:3)
Block(5,68,-4,LEAVES:3)
Block(5,68,-3,LEAVES:3)
Block(5,68,5,17:15)
Block(5,68,6,17:15)
Block(5,69,-8,LEAVES:3)
Block(5,69,-7,LEAVES:3)
Block(5,69,-6,LEAVES:3)
Block(5,69,-5,LEAVES:3)
Block(5,69,-4,17:15)
Block(5,69,2,17:15)
Block(5,69,4,17:15)
Block(5,69,7,17:15)
Block(5,69,8,17:15)
Block(5,69,13,LEAVES:3)
Block(5,70,-5,LEAVES:3)
Block(5,70,-4,LEAVES:3)
Block(5,70,-1,17:15)
Block(5,70,3,LEAVES:3)
Block(5,70,11,LEAVES:3)
Block(5,70,12,LEAVES:3)
Block(5,70,13,LEAVES:3)
Block(5,70,14,LEAVES:3)
Block(5,71,-6,LEAVES:3)
Block(5,71,-4,LEAVES:3)
Block(5,71,-2,LEAVES:3)
Block(5,71,-1,LEAVES:3)
Block(5,71,0,LEAVES:3)
Block(5,71,13,LEAVES:3)
Block(5,72,-5,LEAVES:3)
Block(5,72,-3,17:15)
Block(5,72,-2,LEAVES:3)
Block(5,72,-1,LEAVES:3)
Block(5,73,-4,LEAVES:3)
Block(5,73,-3,LEAVES:3)
Block(5,73,-2,LEAVES:3)
Block(5,74,-3,LEAVES:3)
Block(5,76,2,17:15)
Block(5,77,1,LEAVES:3)
Block(5,77,4,LEAVES:3)
Block(5,78,-1,LEAVES:3)
Block(5,78,1,LEAVES:3)
Block(5,78,2,LEAVES:3)
Block(5,78,3,LEAVES:3)
Block(5,78,5,LEAVES:3)
Block(5,78,6,LEAVES:3)
Block(5,78,7,LEAVES:3)
Block(5,79,6,LEAVES:3)
Block(5,80,-2,17:15)
Block(5,80,0,LEAVES:3)
Block(5,80,3,LEAVES:3)
Block(5,81,-4,LEAVES:3)
Block(5,81,-3,LEAVES:3)
Block(5,81,-2,17:15)
Block(5,81,-1,LEAVES:3)
Block(5,81,0,LEAVES:3)
Block(5,81,1,LEAVES:3)
Block(5,81,2,17:15)
Block(5,81,3,LEAVES:3)
Block(5,82,-6,LEAVES:3)
Block(5,82,-5,LEAVES:3)
Block(5,82,-4,LEAVES:3)
Block(5,82,-2,LEAVES:3)
Block(5,82,-1,LEAVES:3)
Block(5,82,0,LEAVES:3)
Block(5,82,1,LEAVES:3)
Block(5,82,2,LEAVES:3)
Block(5,83,-5,LEAVES:3)
Block(5,83,-4,LEAVES:3)
Block(5,83,-1,LEAVES:3)
Block(6,26,-3,17:15)
Block(6,26,-2,17:15)
Block(6,26,-1,17:15)
Block(6,26,3,17:15)
Block(6,26,4,17:15)
Block(6,26,5,17:15)
Block(6,27,2,LEAVES:3)
Block(6,27,3,17:15)
Block(6,27,4,LEAVES:3)
Block(6,27,9,LEAVES:3)
Block(6,28,-6,LEAVES:3)
Block(6,28,3,LEAVES:3)
Block(6,28,11,LEAVES:3)
Block(6,29,-9,LEAVES:3)
Block(6,30,-12,LEAVES:3)
Block(6,30,-11,LEAVES:3)
