#######################################################################
# +-----------------------------------------------------------------+ #
# |                            BO3 object                           | #
# +-----------------------------------------------------------------+ #
#######################################################################

# The descriptions in this file are accurate only for TerrainControl and OTG.
# For MCW and OTG+ these descriptions are only accurate if the BO3 is used as a CustomObject.
# MCW and OTG+ completely reimplemented CustomStructure, check the MCW/OTG+ documentation for more information.

# This is the config file of a custom object.
# If you add this object correctly to your BiomeConfigs, it will spawn in the world.

# This is the creator of this BO3 object
Author: Unknown

# A short description of this BO3 object
Description: This BO3 was converted from a schematic using OTGEdit. The author and description information of the schematic could not be found. If you know who the author of the schematic is then please add this information.

# The BO3 version, don't change this! It can be used by external applications to do a version check.
Version: 3

# The settings mode, WriteAll, WriteWithoutComments or WriteDisable. See WorldConfig.
SettingsMode: WriteDisable

#######################################################################
# +-----------------------------------------------------------------+ #
# |                          Main settings                          | #
# +-----------------------------------------------------------------+ #
#######################################################################

# This needs to be set to true to spawn the object in the Tree and Sapling resources.
Tree: true

# The frequency of the BO3 from 1 to 200. Tries this many times to spawn this BO3 when using the CustomObject(...) resource.
# Ignored by Tree(..), Sapling(..) and CustomStructure(..)
Frequency: 1

# The rarity of the BO3 from 0 to 100. Each spawn attempt has rarity% chance to succeed when using the CustomObject(...) resource.
# Ignored by Tree(..), Sapling(..) and CustomStructure(..)
Rarity: 100.0

# If you set this to true, the BO3 will be placed with a random rotation.
RotateRandomly: false

# The spawn height of the BO3 - randomY, highestBlock or highestSolidBlock.
SpawnHeight: highestBlock

# The height limits for the BO3.
MinHeight: 64

MaxHeight: 80

# Objects can have other objects attached to it: branches. Branches can also
# have branches attached to it, which can also have branches, etc. This is the
# maximum branch depth for this objects.
MaxBranchDepth: 10

# When spawned with the UseWorld keyword, this BO3 should NOT spawn in the following biomes.
# If you writer.write the BO3 name directly in the BiomeConfigs, this will be ignored.
ExcludedBiomes: All

# To optimise this BO3 for faster loading times you can use Notepad++ to find/replace comments and abbreviate things.
# Notepad++ find/replace with regex:
# Find: ^[#;].* replace to nothing removes all lines starting with # 
# Find: ^\s*$ replace to nothing removes most empty lines 
# Notepad++ find/replace without regex:
# *Warning: This will only work for OTG 1.10.2 v21 / OTG 1.11.2 v6 or higher. B( is not recognised by lower versions.
# Find: Block( replace to B(

#######################################################################
# +-----------------------------------------------------------------+ #
# |                      Source block settings                      | #
# +-----------------------------------------------------------------+ #
#######################################################################

# The block(s) the BO3 should spawn in.
SourceBlocks: STONE:1,STONE:3,STONE:5,DIRT:1,DIRT,SAND,GRASS,DIRT:2,STATIONARY_WATER,HARD_CLAY,STAINED_CLAY,CLAY,SANDSTONE,SAND:1,AIR,STONE,GRAVEL,LONG_GRASS,LONG_GRASS:1,LONG_GRASS:2,DEAD_BUSH,YELLOW_FLOWER,RED_ROSE,BROWN_MUSHROOM,RED_MUSHROOM

# The maximum percentage of the BO3 that can be outside the SourceBlock.
# The BO3 won't be placed on a location with more blocks outside the SourceBlock than this percentage.
MaxPercentageOutsideSourceBlock: 0

# What to do when a block is about to be placed outside the SourceBlock? (dontPlace, placeAnyway)
OutsideSourceBlock: placeAnyway

#######################################################################
# +-----------------------------------------------------------------+ #
# |                              Blocks                             | #
# +-----------------------------------------------------------------+ #
#######################################################################

# All the blocks used in the BO3 are listed here. Possible blocks:
# Block(x,y,z,id[.data][,nbtfile.nbt) or B(x,y,z,id[.data][,nbtfile.nbt)
# RandomBlock(x,y,z,id[:data][,nbtfile.nbt],chance[,id[:data][,nbtfile.nbt],chance[,...]])
# So RandomBlock(0,0,0,CHEST,chest.nbt,50,CHEST,anotherchest.nbt,100) will spawn a chest at
# the BO3 origin, and give it a 50% chance to have the contents of chest.nbt, or, if that
# fails, a 100% percent chance to have the contents of anotherchest.nbt.

Block(-9,13,-2,LEAVES:3)
Block(-9,14,-3,LEAVES:3)
Block(-8,12,-2,LEAVES:3)
Block(-8,13,-5,LEAVES:3)
Block(-8,13,-3,LEAVES:3)
Block(-8,13,0,LEAVES:3)
Block(-8,14,-4,LEAVES:3)
Block(-8,14,-3,LEAVES:3)
Block(-8,14,-2,LEAVES:3)
Block(-8,14,-1,LEAVES:3)
Block(-8,15,-3,LEAVES:3)
Block(-7,13,-3,LEAVES:3)
Block(-7,13,-1,LEAVES:3)
Block(-7,13,1,LEAVES:3)
Block(-7,14,-5,LEAVES:3)
Block(-7,14,-4,LEAVES:3)
Block(-7,14,-3,17:15)
Block(-7,14,-2,LEAVES:3)
Block(-7,14,-1,LEAVES:3)
Block(-7,14,0,LEAVES:3)
Block(-7,14,2,LEAVES:3)
Block(-7,14,3,LEAVES:3)
Block(-7,15,-4,LEAVES:3)
Block(-7,15,-3,LEAVES:3)
Block(-7,15,-1,LEAVES:3)
Block(-6,13,-4,LEAVES:3)
Block(-6,13,-2,LEAVES:3)
Block(-6,13,3,LEAVES:3)
Block(-6,14,-4,LEAVES:3)
Block(-6,14,-3,LEAVES:3)
Block(-6,14,-2,LEAVES:3)
Block(-6,14,-1,LEAVES:3)
Block(-6,14,0,LEAVES:3)
Block(-6,14,1,LEAVES:3)
Block(-6,14,3,LEAVES:3)
Block(-6,14,4,LEAVES:3)
Block(-6,15,-2,17:15)
Block(-6,15,-1,LEAVES:3)
Block(-6,15,0,LEAVES:3)
Block(-6,15,2,LEAVES:3)
Block(-6,15,3,LEAVES:3)
Block(-6,16,-2,LEAVES:3)
Block(-6,16,-1,LEAVES:3)
Block(-6,24,-5,LEAVES:3)
Block(-6,25,-4,LEAVES:3)
Block(-5,13,-3,LEAVES:3)
Block(-5,13,-1,LEAVES:3)
Block(-5,14,-3,LEAVES:3)
Block(-5,14,-2,LEAVES:3)
Block(-5,14,-1,17:15)
Block(-5,14,0,LEAVES:3)
Block(-5,14,2,LEAVES:3)
Block(-5,14,3,17:15)
Block(-5,14,4,LEAVES:3)
Block(-5,14,5,LEAVES:3)
Block(-5,15,-2,LEAVES:3)
Block(-5,15,-1,LEAVES:3)
Block(-5,15,2,LEAVES:3)
Block(-5,15,3,LEAVES:3)
Block(-5,15,4,LEAVES:3)
Block(-5,24,-4,LEAVES:3)
Block(-5,25,-5,LEAVES:3)
Block(-5,25,-4,LEAVES:3)
Block(-5,25,-3,LEAVES:3)
Block(-5,26,-4,LEAVES:3)
Block(-4,-5,-4,17:15)
Block(-4,-4,-4,17:15)
Block(-4,-3,-4,17:15)
Block(-4,12,-1,LEAVES:3)
Block(-4,12,0,LEAVES:3)
Block(-4,12,4,LEAVES:3)
Block(-4,13,-3,LEAVES:3)
Block(-4,13,-1,17:15)
Block(-4,13,1,LEAVES:3)
Block(-4,13,3,LEAVES:3)
Block(-4,13,5,LEAVES:3)
Block(-4,14,-3,LEAVES:3)
Block(-4,14,-2,LEAVES:3)
Block(-4,14,-1,LEAVES:3)
Block(-4,14,0,LEAVES:3)
Block(-4,14,1,LEAVES:3)
Block(-4,14,2,17:15)
Block(-4,14,3,LEAVES:3)
Block(-4,14,4,LEAVES:3)
Block(-4,15,-1,LEAVES:3)
Block(-4,15,1,LEAVES:3)
Block(-4,15,2,LEAVES:3)
Block(-4,16,2,LEAVES:3)
Block(-4,23,-2,LEAVES:3)
Block(-4,24,-6,LEAVES:3)
Block(-4,24,-2,LEAVES:3)
Block(-4,25,-6,LEAVES:3)
Block(-4,25,-5,LEAVES:3)
Block(-4,25,-4,LEAVES:3)
Block(-4,25,-3,LEAVES:3)
Block(-4,26,-5,LEAVES:3)
Block(-4,26,-4,LEAVES:3)
Block(-3,-4,-3,17:15)
Block(-3,-3,-3,17:15)
Block(-3,-2,-3,17:15)
Block(-3,-2,-2,17:15)
Block(-3,-1,-2,17:15)
Block(-3,11,-3,LEAVES:3)
Block(-3,12,-4,LEAVES:3)
Block(-3,12,2,LEAVES:3)
Block(-3,13,-2,LEAVES:3)
Block(-3,13,-1,17:15)
Block(-3,13,0,17:15)
Block(-3,13,1,17:15)
Block(-3,13,2,LEAVES:3)
Block(-3,13,3,LEAVES:3)
Block(-3,13,4,LEAVES:3)
Block(-3,14,-4,LEAVES:3)
Block(-3,14,-3,LEAVES:3)
Block(-3,14,-2,17:15)
Block(-3,14,-1,LEAVES:3)
Block(-3,14,0,LEAVES:3)
Block(-3,14,1,LEAVES:3)
Block(-3,14,2,LEAVES:3)
Block(-3,14,3,LEAVES:3)
Block(-3,15,-3,LEAVES:3)
Block(-3,15,-2,LEAVES:3)
Block(-3,15,0,LEAVES:3)
Block(-3,21,6,LEAVES:3)
Block(-3,24,-3,LEAVES:3)
Block(-3,24,-2,LEAVES:3)
Block(-3,24,-1,LEAVES:3)
Block(-3,25,-5,LEAVES:3)
Block(-3,25,-4,17:15)
Block(-3,25,-3,LEAVES:3)
Block(-3,25,-2,LEAVES:3)
Block(-3,26,-4,LEAVES:3)
Block(-3,26,-3,LEAVES:3)
Block(-3,27,-4,LEAVES:3)
Block(-3,31,-4,LEAVES:3)
Block(-2,-5,1,17:15)
Block(-2,-5,2,17:15)
Block(-2,-4,0,17:15)
Block(-2,-4,1,17:15)
Block(-2,-4,2,17:15)
Block(-2,-3,0,17:15)
Block(-2,-3,1,17:15)
Block(-2,-2,0,17:15)
Block(-2,-1,-2,17:15)
Block(-2,0,-2,17:15)
Block(-2,1,-2,17:15)
Block(-2,9,7,LEAVES:3)
Block(-2,11,-5,LEAVES:3)
Block(-2,12,-5,LEAVES:3)
Block(-2,12,-4,LEAVES:3)
Block(-2,12,-3,LEAVES:3)
Block(-2,12,-1,LEAVES:3)
Block(-2,12,0,17:15)
Block(-2,12,3,LEAVES:3)
Block(-2,13,-4,LEAVES:3)
Block(-2,13,-2,LEAVES:3)
Block(-2,13,-1,LEAVES:3)
Block(-2,13,0,17:15)
Block(-2,13,1,LEAVES:3)
Block(-2,13,2,LEAVES:3)
Block(-2,13,3,LEAVES:3)
Block(-2,14,-3,LEAVES:3)
Block(-2,14,-2,LEAVES:3)
Block(-2,14,-1,LEAVES:3)
Block(-2,14,0,LEAVES:3)
Block(-2,14,2,LEAVES:3)
Block(-2,18,2,LEAVES:3)
Block(-2,19,1,LEAVES:3)
Block(-2,19,4,LEAVES:3)
Block(-2,20,4,LEAVES:3)
Block(-2,20,6,LEAVES:3)
Block(-2,20,8,LEAVES:3)
Block(-2,21,5,LEAVES:3)
Block(-2,21,6,LEAVES:3)
Block(-2,21,7,LEAVES:3)
Block(-2,22,6,LEAVES:3)
Block(-2,23,-2,LEAVES:3)
Block(-2,23,1,LEAVES:3)
Block(-2,24,-5,LEAVES:3)
Block(-2,24,-2,17:15)
Block(-2,24,-1,LEAVES:3)
Block(-2,24,0,LEAVES:3)
Block(-2,25,-4,LEAVES:3)
Block(-2,25,-3,17:15)
Block(-2,25,-2,LEAVES:3)
Block(-2,30,-4,LEAVES:3)
Block(-2,31,-5,LEAVES:3)
Block(-2,31,-4,LEAVES:3)
Block(-2,31,-3,LEAVES:3)
Block(-2,32,-4,LEAVES:3)
Block(-2,34,3,LEAVES:3)
Block(-2,35,3,LEAVES:3)
Block(-1,-2,0,17:15)
Block(-1,-2,1,17:15)
Block(-1,-1,0,17:15)
Block(-1,0,-2,17:15)
Block(-1,0,0,17:15)
Block(-1,1,-2,17:15)
Block(-1,1,-1,17:15)
Block(-1,1,0,17:15)
Block(-1,2,-1,17:15)
Block(-1,3,-1,17:15)
Block(-1,6,3,LEAVES:3)
Block(-1,7,2,LEAVES:3)
Block(-1,7,5,LEAVES:3)
Block(-1,8,5,LEAVES:3)
Block(-1,8,7,LEAVES:3)
Block(-1,8,9,LEAVES:3)
Block(-1,9,6,LEAVES:3)
Block(-1,9,7,LEAVES:3)
Block(-1,9,8,LEAVES:3)
Block(-1,10,7,LEAVES:3)
Block(-1,11,-6,LEAVES:3)
Block(-1,11,-4,LEAVES:3)
Block(-1,11,-2,LEAVES:3)
Block(-1,12,-6,LEAVES:3)
Block(-1,12,-5,LEAVES:3)
Block(-1,12,-4,17:15)
Block(-1,12,-3,LEAVES:3)
Block(-1,12,-2,LEAVES:3)
Block(-1,12,0,17:15)
Block(-1,12,1,LEAVES:3)
Block(-1,13,-5,LEAVES:3)
Block(-1,13,-4,LEAVES:3)
Block(-1,13,-3,LEAVES:3)
Block(-1,13,-1,LEAVES:3)
Block(-1,13,0,LEAVES:3)
Block(-1,13,1,LEAVES:3)
Block(-1,13,2,LEAVES:3)
Block(-1,14,-4,LEAVES:3)
Block(-1,14,0,LEAVES:3)
Block(-1,19,0,LEAVES:3)
Block(-1,19,1,LEAVES:3)
Block(-1,19,2,LEAVES:3)
Block(-1,20,1,LEAVES:3)
Block(-1,20,2,LEAVES:3)
Block(-1,20,3,LEAVES:3)
Block(-1,20,4,LEAVES:3)
Block(-1,21,4,LEAVES:3)
Block(-1,21,5,17:15)
Block(-1,21,6,LEAVES:3)
Block(-1,21,7,LEAVES:3)
Block(-1,21,8,LEAVES:3)
Block(-1,22,4,LEAVES:3)
Block(-1,22,5,LEAVES:3)
Block(-1,22,6,LEAVES:3)
Block(-1,22,7,LEAVES:3)
Block(-1,23,5,LEAVES:3)
Block(-1,24,-2,LEAVES:3)
Block(-1,24,-1,17:15)
Block(-1,24,0,LEAVES:3)
Block(-1,24,1,LEAVES:3)
Block(-1,25,-4,LEAVES:3)
Block(-1,25,-3,LEAVES:3)
Block(-1,25,-2,LEAVES:3)
Block(-1,25,-1,LEAVES:3)
Block(-1,25,0,LEAVES:3)
Block(-1,26,-3,LEAVES:3)
Block(-1,30,-6,LEAVES:3)
Block(-1,30,-3,LEAVES:3)
Block(-1,31,-6,LEAVES:3)
Block(-1,31,-5,LEAVES:3)
Block(-1,31,-4,17:15)
Block(-1,31,-3,LEAVES:3)
Block(-1,32,-5,LEAVES:3)
Block(-1,32,-4,LEAVES:3)
Block(-1,33,-4,LEAVES:3)
Block(-1,34,5,LEAVES:3)
Block(-1,35,2,LEAVES:3)
Block(-1,35,3,LEAVES:3)
Block(-1,35,4,LEAVES:3)
Block(-1,35,5,LEAVES:3)
Block(-1,36,3,LEAVES:3)
Block(-1,36,4,LEAVES:3)
Block(-1,39,-1,LEAVES:3)
Block(-1,40,-1,LEAVES:3)
Block(0,-5,-5,17:15)
Block(0,-5,-2,17:15)
Block(0,-5,2,17:15)
Block(0,-5,3,17:15)
Block(0,-4,-5,17:15)
Block(0,-4,-2,17:15)
Block(0,-4,-1,17:15)
Block(0,-4,2,17:15)
Block(0,-4,3,17:15)
Block(0,-3,-5,17:15)
Block(0,-3,-4,17:15)
Block(0,-3,-1,17:15)
Block(0,-3,1,17:15)
Block(0,-3,2,17:15)
Block(0,-2,-5,17:15)
Block(0,-2,-4,17:15)
Block(0,-2,-1,17:15)
Block(0,-2,1,17:15)
Block(0,-2,2,17:15)
Block(0,-1,-4,17:15)
Block(0,-1,1,17:15)
Block(0,0,0,17:15)
Block(0,0,1,17:15)
Block(0,1,-2,17:15)
Block(0,1,0,17:15)
Block(0,1,1,17:15)
Block(0,2,-2,17:15)
Block(0,2,-1,17:15)
Block(0,2,0,17:15)
Block(0,2,1,17:15)
Block(0,3,-1,17:15)
Block(0,3,0,17:15)
Block(0,4,-1,17:15)
Block(0,4,0,17:15)
Block(0,5,-1,17:15)
Block(0,5,0,17:15)
Block(0,6,-1,17:15)
Block(0,6,0,17:15)
Block(0,7,-1,17:15)
Block(0,7,0,17:15)
Block(0,7,1,LEAVES:3)
Block(0,7,2,LEAVES:3)
Block(0,7,3,LEAVES:3)
Block(0,8,-1,17:15)
Block(0,8,2,LEAVES:3)
Block(0,8,3,LEAVES:3)
Block(0,8,4,LEAVES:3)
Block(0,8,5,LEAVES:3)
Block(0,9,-1,17:15)
Block(0,9,5,LEAVES:3)
Block(0,9,6,17:15)
Block(0,9,7,LEAVES:3)
Block(0,9,8,LEAVES:3)
Block(0,9,9,LEAVES:3)
Block(0,10,-1,17:15)
Block(0,10,5,LEAVES:3)
Block(0,10,6,LEAVES:3)
Block(0,10,7,LEAVES:3)
Block(0,10,8,LEAVES:3)
Block(0,11,-8,LEAVES:3)
Block(0,11,-1,17:15)
Block(0,11,6,LEAVES:3)
Block(0,12,-7,LEAVES:3)
Block(0,12,-6,LEAVES:3)
Block(0,12,-5,LEAVES:3)
Block(0,12,-3,17:15)
Block(0,12,-2,LEAVES:3)
Block(0,12,0,17:15)
Block(0,13,-6,LEAVES:3)
Block(0,13,-4,LEAVES:3)
Block(0,13,-3,LEAVES:3)
Block(0,13,0,LEAVES:3)
Block(0,17,-4,LEAVES:3)
Block(0,18,-3,LEAVES:3)
Block(0,19,1,17:15)
Block(0,19,4,LEAVES:3)
Block(0,20,1,LEAVES:3)
Block(0,20,2,LEAVES:3)
Block(0,20,3,LEAVES:3)
Block(0,20,4,17:15)
Block(0,20,5,LEAVES:3)
Block(0,20,7,LEAVES:3)
Block(0,21,2,LEAVES:3)
Block(0,21,4,LEAVES:3)
Block(0,21,5,LEAVES:3)
Block(0,21,6,LEAVES:3)
Block(0,21,7,LEAVES:3)
Block(0,23,0,LEAVES:3)
Block(0,24,-3,LEAVES:3)
Block(0,24,-1,17:15)
Block(0,24,0,LEAVES:3)
Block(0,25,-3,LEAVES:3)
Block(0,30,-4,LEAVES:3)
Block(0,30,-3,17:15)
Block(0,31,-5,LEAVES:3)
Block(0,31,-3,LEAVES:3)
Block(0,32,-4,LEAVES:3)
Block(0,34,3,LEAVES:3)
Block(0,35,2,LEAVES:3)
Block(0,35,3,17:15)
Block(0,35,4,LEAVES:3)
Block(0,35,5,LEAVES:3)
Block(0,35,6,LEAVES:3)
Block(0,36,3,LEAVES:3)
Block(0,36,4,LEAVES:3)
Block(0,36,5,LEAVES:3)
Block(0,37,4,LEAVES:3)
Block(0,39,-2,LEAVES:3)
Block(0,39,1,LEAVES:3)
Block(0,40,-2,LEAVES:3)
Block(0,40,-1,LEAVES:3)
Block(0,40,0,LEAVES:3)
Block(0,41,-1,LEAVES:3)
Block(1,-2,-4,17:15)
Block(1,-2,-1,17:15)
Block(1,-2,0,17:15)
Block(1,-1,-4,17:15)
Block(1,-1,-3,17:15)
Block(1,-1,-1,17:15)
Block(1,-1,0,17:15)
Block(1,-1,1,17:15)
Block(1,0,-4,17:15)
Block(1,0,-3,17:15)
Block(1,0,-1,17:15)
Block(1,0,0,17:15)
Block(1,0,1,17:15)
Block(1,1,-3,17:15)
Block(1,1,-2,17:15)
Block(1,1,-1,17:15)
Block(1,1,0,17:15)
Block(1,2,-2,17:15)
Block(1,2,-1,17:15)
Block(1,2,0,17:15)
Block(1,3,-2,17:15)
Block(1,3,-1,17:15)
Block(1,3,0,17:15)
Block(1,4,-1,17:15)
Block(1,4,0,17:15)
Block(1,5,-1,17:15)
Block(1,5,0,17:15)
Block(1,6,-1,17:15)
Block(1,6,0,17:15)
Block(1,7,-1,17:15)
Block(1,7,0,17:15)
Block(1,7,2,17:15)
Block(1,7,5,LEAVES:3)
Block(1,8,-1,17:15)
Block(1,8,0,17:15)
Block(1,8,2,LEAVES:3)
Block(1,8,3,LEAVES:3)
Block(1,8,4,LEAVES:3)
Block(1,8,5,17:15)
Block(1,8,6,LEAVES:3)
Block(1,8,8,LEAVES:3)
Block(1,9,-1,17:15)
Block(1,9,0,17:15)
Block(1,9,3,LEAVES:3)
Block(1,9,5,LEAVES:3)
Block(1,9,6,LEAVES:3)
Block(1,9,7,LEAVES:3)
Block(1,9,8,LEAVES:3)
Block(1,10,-3,17:15)
Block(1,10,-2,17:15)
Block(1,10,-1,17:15)
Block(1,10,0,17:15)
Block(1,11,-7,LEAVES:3)
Block(1,11,-5,LEAVES:3)
Block(1,11,-4,17:15)
Block(1,11,-3,17:15)
Block(1,11,-1,17:15)
Block(1,11,0,17:15)
Block(1,12,-8,LEAVES:3)
Block(1,12,-7,LEAVES:3)
Block(1,12,-6,LEAVES:3)
Block(1,12,-5,17:15)
Block(1,12,-4,LEAVES:3)
Block(1,12,-3,LEAVES:3)
Block(1,12,-1,17:15)
Block(1,12,0,17:15)
Block(1,13,-7,LEAVES:3)
Block(1,13,-6,LEAVES:3)
Block(1,13,-5,LEAVES:3)
Block(1,13,-3,LEAVES:3)
Block(1,13,-1,17:15)
Block(1,13,0,17:15)
Block(1,14,-6,LEAVES:3)
Block(1,14,-1,17:15)
Block(1,14,0,17:15)
Block(1,15,-1,17:15)
Block(1,15,0,17:15)
Block(1,16,-1,17:15)
Block(1,16,0,17:15)
Block(1,17,-2,LEAVES:3)
Block(1,17,-1,17:15)
Block(1,17,0,17:15)
Block(1,18,-4,LEAVES:3)
Block(1,18,-3,LEAVES:3)
Block(1,18,-2,LEAVES:3)
Block(1,18,-1,17:15)
Block(1,18,0,17:15)
Block(1,18,2,LEAVES:3)
Block(1,19,-3,LEAVES:3)
Block(1,19,-1,17:15)
Block(1,19,0,17:15)
Block(1,19,1,17:15)
Block(1,19,2,17:15)
Block(1,20,-1,17:15)
Block(1,20,0,LEAVES:3)
Block(1,20,1,LEAVES:3)
Block(1,20,2,17:15)
Block(1,20,3,17:15)
Block(1,20,4,LEAVES:3)
Block(1,20,5,LEAVES:3)
Block(1,20,6,LEAVES:3)
Block(1,21,-1,17:15)
Block(1,21,1,LEAVES:3)
Block(1,21,2,LEAVES:3)
Block(1,21,3,LEAVES:3)
Block(1,21,4,LEAVES:3)
Block(1,21,5,LEAVES:3)
Block(1,22,-1,17:15)
Block(1,22,2,LEAVES:3)
Block(1,22,4,LEAVES:3)
Block(1,23,-1,17:15)
Block(1,24,-1,17:15)
Block(1,25,-1,17:15)
Block(1,26,-1,17:15)
Block(1,27,-1,17:15)
Block(1,28,-1,17:15)
Block(1,30,-7,LEAVES:3)
Block(1,30,-5,LEAVES:3)
Block(1,30,-4,LEAVES:3)
Block(1,30,-3,17:15)
Block(1,30,-2,LEAVES:3)
Block(1,31,-6,LEAVES:3)
Block(1,31,-5,LEAVES:3)
Block(1,31,-4,LEAVES:3)
Block(1,31,-3,LEAVES:3)
Block(1,31,-2,LEAVES:3)
Block(1,32,-5,LEAVES:3)
Block(1,32,-3,LEAVES:3)
Block(1,33,5,LEAVES:3)
Block(1,34,4,LEAVES:3)
Block(1,34,6,LEAVES:3)
Block(1,35,1,LEAVES:3)
Block(1,35,2,17:15)
Block(1,35,3,LEAVES:3)
Block(1,35,4,LEAVES:3)
Block(1,35,5,LEAVES:3)
Block(1,36,2,LEAVES:3)
Block(1,38,0,LEAVES:3)
Block(1,39,0,LEAVES:3)
Block(1,39,1,LEAVES:3)
Block(1,39,2,LEAVES:3)
Block(1,39,3,LEAVES:3)
Block(1,40,-2,LEAVES:3)
Block(1,40,-1,17:15)
Block(1,40,0,LEAVES:3)
Block(1,40,1,LEAVES:3)
Block(1,40,2,LEAVES:3)
Block(1,41,-1,LEAVES:3)
Block(1,41,0,LEAVES:3)
Block(2,-4,0,17:15)
Block(2,-3,-3,17:15)
Block(2,-3,0,17:15)
Block(2,-2,-3,17:15)
Block(2,-1,-3,17:15)
Block(2,-1,0,17:15)
Block(2,0,-1,17:15)
Block(2,0,0,17:15)
Block(2,1,-1,17:15)
Block(2,1,0,17:15)
Block(2,2,-1,17:15)
Block(2,2,0,17:15)
Block(2,3,-1,17:15)
Block(2,4,-1,17:15)
Block(2,5,-1,17:15)
Block(2,6,-1,17:15)
Block(2,6,0,17:15)
Block(2,6,3,LEAVES:3)
Block(2,7,0,17:15)
Block(2,7,1,17:15)
Block(2,7,2,17:15)
Block(2,7,3,17:15)
Block(2,8,0,17:15)
Block(2,8,1,LEAVES:3)
Block(2,8,2,LEAVES:3)
Block(2,8,3,17:15)
Block(2,8,4,17:15)
Block(2,8,5,LEAVES:3)
Block(2,8,6,LEAVES:3)
Block(2,8,7,LEAVES:3)
Block(2,9,0,17:15)
Block(2,9,2,LEAVES:3)
Block(2,9,3,LEAVES:3)
Block(2,9,4,LEAVES:3)
Block(2,9,5,LEAVES:3)
Block(2,9,6,LEAVES:3)
Block(2,10,-2,17:15)
Block(2,10,0,17:15)
Block(2,10,3,LEAVES:3)
Block(2,10,5,LEAVES:3)
Block(2,11,-4,LEAVES:3)
Block(2,11,-3,LEAVES:3)
Block(2,11,-2,17:15)
Block(2,11,0,17:15)
Block(2,11,1,LEAVES:3)
Block(2,12,-9,LEAVES:3)
Block(2,12,-6,LEAVES:3)
Block(2,12,-5,17:15)
Block(2,12,-4,LEAVES:3)
Block(2,12,-3,LEAVES:3)
Block(2,12,0,LEAVES:3)
Block(2,13,-9,LEAVES:3)
Block(2,13,-8,LEAVES:3)
Block(2,13,-7,LEAVES:3)
Block(2,13,-6,LEAVES:3)
Block(2,13,-5,LEAVES:3)
Block(2,13,-4,LEAVES:3)
Block(2,13,0,17:15)
Block(2,14,-7,LEAVES:3)
Block(2,14,-5,LEAVES:3)
Block(2,14,0,17:15)
Block(2,15,0,17:15)
Block(2,16,0,17:15)
Block(2,17,0,17:15)
Block(2,18,-5,LEAVES:3)
Block(2,18,-4,LEAVES:3)
Block(2,18,-3,17:15)
Block(2,18,-2,17:15)
Block(2,18,-1,17:15)
Block(2,18,0,17:15)
Block(2,19,-3,LEAVES:3)
Block(2,19,-1,17:15)
Block(2,19,0,17:15)
Block(2,19,1,LEAVES:3)
Block(2,19,2,17:15)
Block(2,19,3,LEAVES:3)
Block(2,19,4,LEAVES:3)
Block(2,19,6,LEAVES:3)
Block(2,20,-1,17:15)
Block(2,20,0,17:15)
Block(2,20,1,LEAVES:3)
Block(2,20,2,LEAVES:3)
Block(2,20,3,LEAVES:3)
Block(2,20,4,LEAVES:3)
Block(2,20,5,LEAVES:3)
Block(2,21,-1,17:15)
Block(2,21,0,17:15)
Block(2,21,2,LEAVES:3)
Block(2,21,4,LEAVES:3)
Block(2,22,-1,17:15)
Block(2,22,0,17:15)
Block(2,23,-2,LEAVES:3)
Block(2,23,-1,17:15)
Block(2,23,0,17:15)
Block(2,24,-1,17:15)
Block(2,24,0,17:15)
Block(2,25,-1,17:15)
Block(2,25,0,17:15)
Block(2,26,-1,17:15)
Block(2,26,0,17:15)
Block(2,27,-1,17:15)
Block(2,27,0,17:15)
Block(2,28,-1,17:15)
Block(2,28,0,17:15)
Block(2,29,-3,LEAVES:3)
Block(2,29,-1,17:15)
Block(2,29,0,17:15)
Block(2,30,-3,17:15)
Block(2,30,-2,17:15)
Block(2,30,-1,17:15)
Block(2,30,0,17:15)
Block(2,31,-7,LEAVES:3)
Block(2,31,-6,LEAVES:3)
Block(2,31,-5,LEAVES:3)
Block(2,31,-4,17:15)
Block(2,31,-3,17:15)
Block(2,31,-2,LEAVES:3)
Block(2,31,-1,LEAVES:3)
Block(2,31,0,17:15)
Block(2,32,-6,LEAVES:3)
Block(2,32,-5,LEAVES:3)
Block(2,32,-4,LEAVES:3)
Block(2,32,-3,LEAVES:3)
Block(2,32,-2,LEAVES:3)
Block(2,32,0,17:15)
Block(2,33,-5,LEAVES:3)
Block(2,33,-3,LEAVES:3)
Block(2,33,0,17:15)
Block(2,34,0,17:15)
Block(2,34,1,17:15)
Block(2,34,2,17:15)
Block(2,34,3,17:15)
Block(2,34,5,LEAVES:3)
Block(2,35,0,17:15)
Block(2,35,1,LEAVES:3)
Block(2,35,2,LEAVES:3)
Block(2,35,3,LEAVES:3)
Block(2,35,4,LEAVES:3)
Block(2,36,0,17:15)
Block(2,37,0,17:15)
Block(2,37,1,LEAVES:3)
Block(2,38,0,17:15)
Block(2,38,2,LEAVES:3)
Block(2,39,-2,LEAVES:3)
Block(2,39,-1,LEAVES:3)
Block(2,39,0,17:15)
Block(2,39,1,17:15)
Block(2,39,2,LEAVES:3)
Block(2,39,3,LEAVES:3)
Block(2,39,4,LEAVES:3)
Block(2,40,-1,LEAVES:3)
Block(2,40,0,17:15)
Block(2,40,2,LEAVES:3)
Block(2,40,3,LEAVES:3)
Block(2,41,-1,LEAVES:3)
Block(2,41,0,LEAVES:3)
Block(2,41,1,LEAVES:3)
Block(2,41,2,LEAVES:3)
Block(2,42,0,LEAVES:3)
Block(3,-5,-3,17:15)
Block(3,-5,0,17:15)
Block(3,-4,-3,17:15)
Block(3,-4,0,17:15)
Block(3,-3,-3,17:15)
Block(3,-3,0,17:15)
Block(3,-3,2,17:15)
Block(3,-2,0,17:15)
Block(3,-2,1,17:15)
Block(3,-2,2,17:15)
Block(3,-1,1,17:15)
Block(3,7,2,LEAVES:3)
Block(3,7,3,17:15)
Block(3,7,4,LEAVES:3)
Block(3,7,5,LEAVES:3)
Block(3,7,7,LEAVES:3)
Block(3,8,2,LEAVES:3)
Block(3,8,3,LEAVES:3)
Block(3,8,4,LEAVES:3)
Block(3,8,5,LEAVES:3)
Block(3,8,6,LEAVES:3)
Block(3,9,3,LEAVES:3)
Block(3,9,5,LEAVES:3)
Block(3,10,-5,LEAVES:3)
Block(3,10,-1,LEAVES:3)
Block(3,11,-6,LEAVES:3)
Block(3,11,-5,LEAVES:3)
Block(3,11,-4,LEAVES:3)
Block(3,11,-3,17:15)
Block(3,11,-2,17:15)
Block(3,11,-1,LEAVES:3)
Block(3,12,-8,LEAVES:3)
Block(3,12,-6,17:15)
Block(3,12,-5,LEAVES:3)
Block(3,12,-4,LEAVES:3)
Block(3,12,-3,LEAVES:3)
Block(3,12,-2,LEAVES:3)
Block(3,12,0,LEAVES:3)
Block(3,12,1,LEAVES:3)
Block(3,12,2,LEAVES:3)
Block(3,13,-10,LEAVES:3)
Block(3,13,-9,LEAVES:3)
Block(3,13,-8,LEAVES:3)
Block(3,13,-7,17:15)
Block(3,13,-6,LEAVES:3)
Block(3,13,-5,LEAVES:3)
Block(3,13,-4,LEAVES:3)
Block(3,13,-3,LEAVES:3)
Block(3,13,0,LEAVES:3)
Block(3,14,-9,LEAVES:3)
Block(3,14,-8,LEAVES:3)
Block(3,14,-7,LEAVES:3)
Block(3,14,-6,LEAVES:3)
Block(3,15,-7,LEAVES:3)
Block(3,17,-6,LEAVES:3)
Block(3,17,-4,LEAVES:3)
Block(3,18,-6,LEAVES:3)
Block(3,18,-5,LEAVES:3)
Block(3,18,-4,17:15)
Block(3,18,-3,LEAVES:3)
Block(3,19,-5,LEAVES:3)
Block(3,19,-4,LEAVES:3)
Block(3,19,-3,LEAVES:3)
Block(3,19,2,17:15)
Block(3,19,3,LEAVES:3)
Block(3,20,2,LEAVES:3)
Block(3,20,4,LEAVES:3)
Block(3,21,3,LEAVES:3)
Block(3,22,-1,17:15)
Block(3,22,0,LEAVES:3)
Block(3,23,-3,LEAVES:3)
Block(3,23,-2,LEAVES:3)
Block(3,23,-1,17:15)
Block(3,24,-2,LEAVES:3)
Block(3,24,-1,LEAVES:3)
Block(3,24,0,LEAVES:3)
Block(3,30,-5,LEAVES:3)
Block(3,30,-2,17:15)
Block(3,31,-8,LEAVES:3)
Block(3,31,-6,LEAVES:3)
Block(3,31,-5,17:15)
Block(3,31,-4,LEAVES:3)
Block(3,31,-3,LEAVES:3)
Block(3,31,-2,LEAVES:3)
Block(3,32,-8,LEAVES:3)
Block(3,32,-7,LEAVES:3)
Block(3,32,-6,LEAVES:3)
Block(3,32,-5,LEAVES:3)
Block(3,32,-3,LEAVES:3)
Block(3,33,4,LEAVES:3)
Block(3,33,6,LEAVES:3)
Block(3,34,2,LEAVES:3)
Block(3,34,4,17:15)
Block(3,34,5,LEAVES:3)
Block(3,34,6,LEAVES:3)
Block(3,35,2,LEAVES:3)
Block(3,35,3,LEAVES:3)
Block(3,35,4,LEAVES:3)
Block(3,35,5,LEAVES:3)
Block(3,36,4,LEAVES:3)
Block(3,37,-1,LEAVES:3)
Block(3,38,-3,LEAVES:3)
Block(3,38,-2,LEAVES:3)
Block(3,38,-1,17:15)
Block(3,38,0,17:15)
Block(3,38,1,LEAVES:3)
Block(3,38,3,LEAVES:3)
Block(3,39,-2,LEAVES:3)
Block(3,39,-1,LEAVES:3)
Block(3,39,1,LEAVES:3)
Block(3,39,2,LEAVES:3)
Block(3,39,3,LEAVES:3)
Block(3,40,0,LEAVES:3)
Block(3,40,2,LEAVES:3)
Block(3,41,0,LEAVES:3)
Block(4,-5,3,17:15)
Block(4,-4,2,17:15)
Block(4,-4,3,17:15)
Block(4,-3,2,17:15)
Block(4,7,3,17:15)
Block(4,7,4,LEAVES:3)
Block(4,8,3,LEAVES:3)
Block(4,8,5,LEAVES:3)
Block(4,9,4,LEAVES:3)
Block(4,11,-5,LEAVES:3)
Block(4,11,-4,LEAVES:3)
Block(4,11,-3,LEAVES:3)
Block(4,11,-2,LEAVES:3)
Block(4,11,-1,17:15)
Block(4,11,0,LEAVES:3)
Block(4,11,3,LEAVES:3)
Block(4,12,-10,LEAVES:3)
Block(4,12,-7,LEAVES:3)
Block(4,12,-6,LEAVES:3)
Block(4,12,-4,LEAVES:3)
Block(4,12,-3,17:15)
Block(4,12,-1,LEAVES:3)
Block(4,12,0,17:15)
Block(4,12,1,17:15)
Block(4,12,2,LEAVES:3)
Block(4,12,3,LEAVES:3)
Block(4,13,-9,LEAVES:3)
Block(4,13,-8,LEAVES:3)
Block(4,13,-7,LEAVES:3)
Block(4,13,-6,LEAVES:3)
Block(4,13,-4,LEAVES:3)
Block(4,13,-3,LEAVES:3)
Block(4,13,0,LEAVES:3)
Block(4,13,1,LEAVES:3)
Block(4,13,2,LEAVES:3)
Block(4,14,-8,LEAVES:3)
Block(4,14,0,LEAVES:3)
Block(4,18,-5,LEAVES:3)
Block(4,18,-2,LEAVES:3)
Block(4,19,-7,LEAVES:3)
Block(4,19,-6,LEAVES:3)
Block(4,19,-5,LEAVES:3)
Block(4,19,-4,17:15)
Block(4,19,-3,LEAVES:3)
Block(4,19,-2,LEAVES:3)
Block(4,19,2,LEAVES:3)
Block(4,19,5,LEAVES:3)
Block(4,20,-5,LEAVES:3)
Block(4,20,-3,LEAVES:3)
Block(4,20,2,LEAVES:3)
Block(4,20,3,17:15)
Block(4,20,4,LEAVES:3)
Block(4,20,5,LEAVES:3)
Block(4,21,3,LEAVES:3)
Block(4,21,4,LEAVES:3)
Block(4,22,3,LEAVES:3)
Block(4,23,-2,LEAVES:3)
Block(4,23,-1,17:15)
Block(4,23,0,17:15)
Block(4,23,2,LEAVES:3)
Block(4,24,-3,LEAVES:3)
Block(4,24,-2,LEAVES:3)
Block(4,24,-1,LEAVES:3)
Block(4,24,0,LEAVES:3)
Block(4,24,1,LEAVES:3)
Block(4,24,2,LEAVES:3)
Block(4,24,3,LEAVES:3)
Block(4,25,-2,LEAVES:3)
Block(4,25,0,LEAVES:3)
Block(4,30,-3,LEAVES:3)
Block(4,30,-2,LEAVES:3)
Block(4,30,-1,LEAVES:3)
Block(4,31,-5,LEAVES:3)
Block(4,31,-4,LEAVES:3)
Block(4,31,-3,LEAVES:3)
Block(4,31,-2,LEAVES:3)
Block(4,32,-9,LEAVES:3)
Block(4,32,-8,LEAVES:3)
Block(4,32,-7,LEAVES:3)
Block(4,32,-6,17:15)
Block(4,32,-5,LEAVES:3)
Block(4,33,-8,LEAVES:3)
Block(4,33,-7,LEAVES:3)
Block(4,33,-6,LEAVES:3)
Block(4,33,-5,LEAVES:3)
Block(4,34,-6,LEAVES:3)
Block(4,34,3,LEAVES:3)
Block(4,34,5,LEAVES:3)
Block(4,34,8,LEAVES:3)
Block(4,35,4,LEAVES:3)
Block(4,35,5,17:15)
Block(4,35,6,LEAVES:3)
Block(4,35,7,LEAVES:3)
Block(4,35,8,LEAVES:3)
Block(4,36,4,LEAVES:3)
Block(4,36,5,LEAVES:3)
Block(4,36,6,LEAVES:3)
Block(4,36,7,LEAVES:3)
Block(4,37,5,LEAVES:3)
Block(4,38,-1,LEAVES:3)
Block(4,38,0,LEAVES:3)
Block(4,38,1,LEAVES:3)
Block(4,39,-3,LEAVES:3)
Block(4,39,-2,LEAVES:3)
Block(4,39,-1,17:15)
Block(4,39,0,LEAVES:3)
Block(4,39,3,LEAVES:3)
Block(4,40,-2,LEAVES:3)
Block(4,40,-1,LEAVES:3)
Block(5,7,3,LEAVES:3)
Block(5,7,6,LEAVES:3)
Block(5,8,3,LEAVES:3)
Block(5,8,4,17:15)
Block(5,8,5,LEAVES:3)
Block(5,8,6,LEAVES:3)
Block(5,9,4,LEAVES:3)
Block(5,9,5,LEAVES:3)
Block(5,10,-3,LEAVES:3)
Block(5,10,4,LEAVES:3)
Block(5,11,-6,LEAVES:3)
Block(5,11,-4,LEAVES:3)
Block(5,11,-2,LEAVES:3)
Block(5,11,-1,LEAVES:3)
Block(5,11,0,LEAVES:3)
Block(5,11,1,LEAVES:3)
Block(5,12,-8,LEAVES:3)
Block(5,12,-6,LEAVES:3)
Block(5,12,-5,LEAVES:3)
Block(5,12,-4,17:15)
Block(5,12,-3,LEAVES:3)
Block(5,12,-1,LEAVES:3)
Block(5,12,0,LEAVES:3)
Block(5,12,1,LEAVES:3)
Block(5,12,2,LEAVES:3)
Block(5,13,-8,LEAVES:3)
Block(5,13,-4,LEAVES:3)
Block(5,13,1,LEAVES:3)
Block(5,14,-4,LEAVES:3)
Block(5,18,-7,LEAVES:3)
Block(5,19,-8,LEAVES:3)
Block(5,19,-7,LEAVES:3)
Block(5,19,-6,LEAVES:3)
Block(5,19,-5,17:15)
Block(5,19,-4,LEAVES:3)
Block(5,19,-3,LEAVES:3)
Block(5,19,3,LEAVES:3)
Block(5,20,-7,LEAVES:3)
Block(5,20,-6,LEAVES:3)
Block(5,20,-5,LEAVES:3)
Block(5,20,2,LEAVES:3)
Block(5,20,3,LEAVES:3)
Block(5,20,4,LEAVES:3)
Block(5,21,-5,LEAVES:3)
Block(5,21,3,LEAVES:3)
Block(5,23,-5,LEAVES:3)
Block(5,23,-3,LEAVES:3)
Block(5,23,0,LEAVES:3)
Block(5,24,-4,LEAVES:3)
Block(5,24,-3,LEAVES:3)
Block(5,24,-2,17:15)
Block(5,24,-1,LEAVES:3)
Block(5,24,0,LEAVES:3)
Block(5,24,1,17:15)
Block(5,24,2,LEAVES:3)
Block(5,24,3,LEAVES:3)
Block(5,24,4,LEAVES:3)
Block(5,25,-3,LEAVES:3)
Block(5,25,-2,LEAVES:3)
Block(5,25,-1,LEAVES:3)
Block(5,25,1,LEAVES:3)
Block(5,25,2,LEAVES:3)
Block(5,25,3,LEAVES:3)
Block(5,26,-2,LEAVES:3)
Block(5,26,2,LEAVES:3)
Block(5,29,-3,LEAVES:3)
Block(5,30,-5,LEAVES:3)
Block(5,30,-2,LEAVES:3)
Block(5,31,-9,LEAVES:3)
Block(5,31,-7,LEAVES:3)
Block(5,31,-5,LEAVES:3)
Block(5,32,-8,LEAVES:3)
Block(5,32,-7,LEAVES:3)
Block(5,32,-6,LEAVES:3)
Block(5,33,-7,LEAVES:3)
Block(5,34,4,LEAVES:3)
Block(5,34,7,LEAVES:3)
Block(5,35,5,LEAVES:3)
Block(5,35,6,17:15)
Block(5,35,7,LEAVES:3)
Block(5,35,8,LEAVES:3)
Block(5,35,9,LEAVES:3)
Block(5,36,5,LEAVES:3)
Block(5,36,6,LEAVES:3)
Block(5,36,7,LEAVES:3)
Block(5,36,8,LEAVES:3)
Block(5,37,1,LEAVES:3)
Block(5,38,-3,LEAVES:3)
Block(5,38,0,LEAVES:3)
Block(5,39,-3,LEAVES:3)
Block(5,39,-2,LEAVES:3)
Block(5,39,-1,LEAVES:3)
Block(5,39,0,LEAVES:3)
Block(5,40,-2,LEAVES:3)
Block(5,40,-1,LEAVES:3)
Block(5,40,0,LEAVES:3)
Block(5,41,-1,LEAVES:3)
Block(6,7,4,LEAVES:3)
Block(6,8,3,LEAVES:3)
Block(6,8,4,LEAVES:3)
Block(6,8,5,LEAVES:3)
Block(6,9,4,LEAVES:3)
Block(6,10,-1,LEAVES:3)
Block(6,10,1,LEAVES:3)
Block(6,11,-4,LEAVES:3)
Block(6,11,-1,LEAVES:3)
Block(6,11,2,LEAVES:3)
Block(6,12,-6,LEAVES:3)
Block(6,12,-5,LEAVES:3)
Block(6,12,-4,LEAVES:3)
Block(6,12,-3,LEAVES:3)
Block(6,12,1,LEAVES:3)
Block(6,13,-5,LEAVES:3)
Block(6,13,-4,LEAVES:3)
Block(6,18,-8,LEAVES:3)
Block(6,18,-4,LEAVES:3)
Block(6,19,-7,LEAVES:3)
Block(6,19,-6,LEAVES:3)
Block(6,19,-5,LEAVES:3)
Block(6,20,-6,LEAVES:3)
Block(6,20,3,LEAVES:3)
Block(6,23,-2,LEAVES:3)
Block(6,23,0,LEAVES:3)
Block(6,23,2,LEAVES:3)
Block(6,23,4,LEAVES:3)
Block(6,24,-5,LEAVES:3)
Block(6,24,-4,LEAVES:3)
Block(6,24,-3,17:15)
Block(6,24,1,LEAVES:3)
Block(6,24,2,LEAVES:3)
Block(6,24,3,LEAVES:3)
Block(6,25,-4,LEAVES:3)
Block(6,25,-3,LEAVES:3)
Block(6,25,-2,LEAVES:3)
Block(6,25,2,LEAVES:3)
Block(6,32,-7,LEAVES:3)
Block(6,34,9,LEAVES:3)
Block(6,35,5,LEAVES:3)
Block(6,35,6,LEAVES:3)
Block(6,35,7,LEAVES:3)
Block(6,35,8,LEAVES:3)
Block(6,36,6,LEAVES:3)
Block(6,36,7,LEAVES:3)
Block(6,38,-2,LEAVES:3)
Block(6,39,-2,LEAVES:3)
Block(6,39,-1,LEAVES:3)
Block(6,39,0,LEAVES:3)
Block(6,40,-1,LEAVES:3)
Block(7,8,4,LEAVES:3)
Block(7,11,-5,LEAVES:3)
Block(7,12,-5,LEAVES:3)
Block(7,12,-4,LEAVES:3)
Block(7,12,-3,LEAVES:3)
Block(7,13,-4,LEAVES:3)
Block(7,18,-6,LEAVES:3)
Block(7,19,-6,LEAVES:3)
Block(7,23,-4,LEAVES:3)
Block(7,24,-4,LEAVES:3)
Block(7,24,-3,LEAVES:3)
Block(7,24,-2,LEAVES:3)
Block(7,24,2,LEAVES:3)
Block(7,25,-3,LEAVES:3)
Block(7,34,6,LEAVES:3)
Block(7,35,6,LEAVES:3)
Block(7,38,0,LEAVES:3)
Block(7,39,-1,LEAVES:3)
Block(8,11,-3,LEAVES:3)
Block(8,12,-4,LEAVES:3)
Block(8,23,-2,LEAVES:3)
Block(8,24,-3,LEAVES:3)


#######################################################################
# +-----------------------------------------------------------------+ #
# |                             Entities                            | #
# +-----------------------------------------------------------------+ #
#######################################################################

# Entity() spawns an entity instead of a block. The entity is spawned only once when the BO3 is spawned.
# Entities are persistent by default so they don't de-spawn when no player is near, they are only unloaded.
# Usage: Entity(x,y,z,mobName,groupSize,NameTagOrNBTFileName) or Entity(x,y,z,mobName,groupSize)
# Use /tc entities or /otg entities to get a list of entities that can be used as mobName, this includes entities added by other mods.
# NameTagOrNBTFileName can be either a nametag for the mob or an nbt file (such as mymobinfo.nbt or mymobinfo.txt).
# When using a text file you can use the same mob spawning parameters used with the /summon command to equip the
# entity and give it custom attributes etc. You can copy the DATA part of a summon command including surrounding
# curly braces to a .txt file, for instance for: "/summon Skeleton x y z {DATA}"

#######################################################################
# +-----------------------------------------------------------------+ #
# |                            BO3 checks                           | #
# +-----------------------------------------------------------------+ #
#######################################################################

# Require a condition at a certain location in order for the BO3 to be spawned.
# BlockCheck(x,y,z,BlockName[,BlockName[,...]]) - one of the blocks must be at the location
# BlockCheckNot(x,y,z,BlockName[,BlockName[,...]]) - all the blocks must not be at the location
# LightCheck(x,y,z,minLightLevel,maxLightLevel) - light must be between min and max (inclusive)

# You can use "Solid" as a BlockName for matching all solid blocks or "All" to match all blocks that aren't air.

# Examples:
#   BlockCheck(0,-1,0,GRASS,DIRT)  Require grass or dirt just below the object
#   BlockCheck(0,-1,0,Solid)       Require any solid block just below the object
#   BlockCheck(0,-1,0,WOOL)        Require any type of wool just below the object
#   BlockCheck(0,-1,0,WOOL:0)      Require white wool just below the object
#   BlockCheckNot(0,-1,0,WOOL:0)   Require that there is no white wool below the object
#   LightCheck(0,0,0,0,LEAVES:3)          Require almost complete darkness just below the object

