#######################################################################
# +-----------------------------------------------------------------+ #
# |                            BO3 object                           | #
# +-----------------------------------------------------------------+ #
#######################################################################

# The descriptions in this file are accurate only for TerrainControl and OTG.
# For MCW and OTG+ these descriptions are only accurate if the BO3 is used as a CustomObject.
# MCW and OTG+ completely reimplemented CustomStructure, check the MCW/OTG+ documentation for more information.

# This is the config file of a custom object.
# If you add this object correctly to your BiomeConfigs, it will spawn in the world.

# This is the creator of this BO3 object
Author: Unknown

# A short description of this BO3 object
Description: This BO3 was converted from a schematic using OTGEdit. The author and description information of the schematic could not be found. If you know who the author of the schematic is then please add this information.

# The BO3 version, don't change this! It can be used by external applications to do a version check.
Version: 3

# The settings mode, WriteAll, WriteWithoutComments or WriteDisable. See WorldConfig.
SettingsMode: WriteDisable

#######################################################################
# +-----------------------------------------------------------------+ #
# |                          Main settings                          | #
# +-----------------------------------------------------------------+ #
#######################################################################

# This needs to be set to true to spawn the object in the Tree and Sapling resources.
Tree: true

# The frequency of the BO3 from 1 to 200. Tries this many times to spawn this BO3 when using the CustomObject(...) resource.
# Ignored by Tree(..), Sapling(..) and CustomStructure(..)
Frequency: 40

# The rarity of the BO3 from 0 to 100. Each spawn attempt has rarity% chance to succeed when using the CustomObject(...) resource.
# Ignored by Tree(..), Sapling(..) and CustomStructure(..)
Rarity: 100.0

# If you set this to true, the BO3 will be placed with a random rotation.
RotateRandomly: true

# The spawn height of the BO3 - randomY, highestBlock or highestSolidBlock.
SpawnHeight: randomY

# The height limits for the BO3.
MinHeight: 63

MaxHeight: 256

# Objects can have other objects attached to it: branches. Branches can also
# have branches attached to it, which can also have branches, etc. This is the
# maximum branch depth for this objects.
MaxBranchDepth: 10

# When spawned with the UseWorld keyword, this BO3 should NOT spawn in the following biomes.
# If you writer.write the BO3 name directly in the BiomeConfigs, this will be ignored.
ExcludedBiomes: All

# To optimise this BO3 for faster loading times you can use Notepad++ to find/replace comments and abbreviate things.
# Notepad++ find/replace with regex:
# Find: ^[#;].* replace to nothing removes all lines starting with # 
# Find: ^\s*$ replace to nothing removes most empty lines 
# Notepad++ find/replace without regex:
# *Warning: This will only work for OTG 1.10.2 v21 / OTG 1.11.2 v6 or higher. B( is not recognised by lower versions.
# Find: Block( replace to B(

#######################################################################
# +-----------------------------------------------------------------+ #
# |                      Source block settings                      | #
# +-----------------------------------------------------------------+ #
#######################################################################

# The block(s) the BO3 should spawn in.
SourceBlocks: AIR,GRASS,DIRT

# The maximum percentage of the BO3 that can be outside the SourceBlock.
# The BO3 won't be placed on a location with more blocks outside the SourceBlock than this percentage.
MaxPercentageOutsideSourceBlock: 5

# What to do when a block is about to be placed outside the SourceBlock? (dontPlace, placeAnyway)
OutsideSourceBlock: dontPlace

#######################################################################
# +-----------------------------------------------------------------+ #
# |                              Blocks                             | #
# +-----------------------------------------------------------------+ #
#######################################################################

# All the blocks used in the BO3 are listed here. Possible blocks:
# Block(x,y,z,id[.data][,nbtfile.nbt) or B(x,y,z,id[.data][,nbtfile.nbt)
# RandomBlock(x,y,z,id[:data][,nbtfile.nbt],chance[,id[:data][,nbtfile.nbt],chance[,...]])
# So RandomBlock(0,0,0,CHEST,chest.nbt,50,CHEST,anotherchest.nbt,100) will spawn a chest at
# the BO3 origin, and give it a 50% chance to have the contents of chest.nbt, or, if that
# fails, a 100% percent chance to have the contents of anotherchest.nbt.

Block(-16,18,9,18:3)
Block(-16,19,9,18:3)
Block(-16,20,9,18:3)
Block(-16,21,9,18:3)
Block(-16,22,9,18:3)
Block(-16,22,10,18:3)
Block(-16,23,7,18:3)
Block(-16,23,8,18:3)
Block(-16,23,9,18:3)
Block(-16,23,10,18:3)
Block(-16,23,11,18:3)
Block(-16,23,12,18:3)
Block(-16,24,8,18:3)
Block(-16,24,9,18:3)
Block(-16,24,10,18:3)
Block(-15,20,13,18:3)
Block(-15,21,13,18:3)
Block(-15,22,6,18:3)
Block(-15,22,7,18:3)
Block(-15,22,8,18:3)
Block(-15,22,10,18:3)
Block(-15,22,11,18:3)
Block(-15,22,13,18:3)
Block(-15,23,5,18:3)
Block(-15,23,7,18:3)
Block(-15,23,8,18:3)
Block(-15,23,9,18:3)
Block(-15,23,10,18:3)
Block(-15,23,11,18:3)
Block(-15,23,12,18:3)
Block(-15,23,13,18:3)
Block(-15,24,6,18:3)
Block(-15,24,7,18:3)
Block(-15,24,8,18:3)
Block(-15,24,9,18:3)
Block(-15,24,10,18:3)
Block(-15,24,11,18:3)
Block(-15,25,8,18:3)
Block(-15,25,9,18:3)
Block(-14,19,6,18:3)
Block(-14,20,6,18:3)
Block(-14,21,6,18:3)
Block(-14,22,5,18:3)
Block(-14,22,6,18:3)
Block(-14,22,7,18:3)
Block(-14,22,12,18:3)
Block(-14,23,5,18:3)
Block(-14,23,6,18:3)
Block(-14,23,7,18:3)
Block(-14,23,8,18:3)
Block(-14,23,9,18:3)
Block(-14,23,11,18:3)
Block(-14,23,12,18:3)
Block(-14,23,13,18:3)
Block(-14,23,14,18:3)
Block(-14,24,5,18:3)
Block(-14,24,6,18:3)
Block(-14,24,7,18:3)
Block(-14,24,8,18:3)
Block(-14,24,9,18:3)
Block(-14,24,10,18:3)
Block(-14,24,11,18:3)
Block(-14,24,13,18:3)
Block(-14,24,14,18:3)
Block(-14,25,6,18:3)
Block(-14,25,7,18:3)
Block(-14,25,8,18:3)
Block(-14,25,10,18:3)
Block(-14,25,13,18:3)
Block(-14,26,10,18:3)
Block(-14,26,11,18:3)
Block(-13,22,6,18:3)
Block(-13,22,13,18:3)
Block(-13,23,5,18:3)
Block(-13,23,6,18:3)
Block(-13,23,7,18:3)
Block(-13,23,8,18:3)
Block(-13,23,12,18:3)
Block(-13,23,13,18:3)
Block(-13,23,14,18:3)
Block(-13,23,15,18:3)
Block(-13,24,5,18:3)
Block(-13,24,6,18:3)
Block(-13,24,8,18:3)
Block(-13,24,9,18:3)
Block(-13,24,11,18:3)
Block(-13,24,12,18:3)
Block(-13,24,13,18:3)
Block(-13,24,14,18:3)
Block(-13,24,15,18:3)
Block(-13,25,6,18:3)
Block(-13,25,8,18:3)
Block(-13,25,9,18:3)
Block(-13,25,10,18:3)
Block(-13,25,11,18:3)
Block(-13,25,12,18:3)
Block(-13,25,13,18:3)
Block(-13,25,14,18:3)
Block(-13,26,8,18:3)
Block(-13,26,9,18:3)
Block(-13,26,12,18:3)
Block(-13,26,13,18:3)
Block(-12,19,15,18:3)
Block(-12,20,15,18:3)
Block(-12,21,15,18:3)
Block(-12,22,5,18:3)
Block(-12,22,6,18:3)
Block(-12,22,13,18:3)
Block(-12,22,14,18:3)
Block(-12,22,15,18:3)
Block(-12,23,-8,18:3)
Block(-12,23,5,18:3)
Block(-12,23,6,18:3)
Block(-12,23,7,18:3)
Block(-12,23,14,18:3)
Block(-12,23,15,18:3)
Block(-12,23,16,18:3)
Block(-12,24,-8,18:3)
Block(-12,24,5,18:3)
Block(-12,24,6,18:3)
Block(-12,24,7,18:3)
Block(-12,24,8,18:3)
Block(-12,24,9,18:3)
Block(-12,24,11,18:3)
Block(-12,24,13,18:3)
Block(-12,24,14,18:3)
Block(-12,24,15,18:3)
Block(-12,25,-8,18:3)
Block(-12,25,6,18:3)
Block(-12,25,7,18:3)
Block(-12,25,8,18:3)
Block(-12,25,9,18:3)
Block(-12,25,10,18:3)
Block(-12,25,11,18:3)
Block(-12,25,12,18:3)
Block(-12,25,13,18:3)
Block(-12,25,14,18:3)
Block(-12,25,15,18:3)
Block(-12,26,-9,18:3)
Block(-12,26,-8,18:3)
Block(-12,26,7,18:3)
Block(-12,26,9,18:3)
Block(-12,26,10,18:3)
Block(-12,26,11,18:3)
Block(-12,26,12,18:3)
Block(-12,26,14,18:3)
Block(-12,27,-10,18:3)
Block(-12,27,-9,18:3)
Block(-12,27,-8,18:3)
Block(-12,27,10,18:3)
Block(-12,27,11,18:3)
Block(-12,28,-11,18:3)
Block(-12,28,-10,18:3)
Block(-12,28,-9,18:3)
Block(-12,28,-8,18:3)
Block(-12,28,-7,18:3)
Block(-12,29,-9,18:3)
Block(-11,16,5,18:3)
Block(-11,17,5,18:3)
Block(-11,18,5,18:3)
Block(-11,19,5,18:3)
Block(-11,19,8,18:3)
Block(-11,20,5,18:3)
Block(-11,20,8,18:3)
Block(-11,21,5,18:3)
Block(-11,21,8,18:3)
Block(-11,22,5,18:3)
Block(-11,22,6,18:3)
Block(-11,22,8,18:3)
Block(-11,22,11,18:3)
Block(-11,22,16,18:3)
Block(-11,23,4,18:3)
Block(-11,23,5,18:3)
Block(-11,23,6,18:3)
Block(-11,23,7,18:3)
Block(-11,23,8,18:3)
Block(-11,23,9,18:3)
Block(-11,23,11,18:3)
Block(-11,23,13,18:3)
Block(-11,23,14,18:3)
Block(-11,23,15,18:3)
Block(-11,23,16,18:3)
Block(-11,24,-10,18:3)
Block(-11,24,-6,18:3)
Block(-11,24,5,18:3)
Block(-11,24,6,18:3)
Block(-11,24,7,18:3)
Block(-11,24,8,18:3)
Block(-11,24,9,18:3)
Block(-11,24,10,18:3)
Block(-11,24,11,18:3)
Block(-11,24,12,18:3)
Block(-11,24,13,18:3)
Block(-11,24,14,18:3)
Block(-11,24,15,18:3)
Block(-11,24,16,18:3)
Block(-11,25,-10,18:3)
Block(-11,25,-6,18:3)
Block(-11,25,5,18:3)
Block(-11,25,8,18:3)
Block(-11,25,9,18:3)
Block(-11,25,10,18:3)
Block(-11,25,11,18:3)
Block(-11,25,13,18:3)
Block(-11,25,14,18:3)
Block(-11,26,-10,18:3)
Block(-11,26,-6,18:3)
Block(-11,26,7,18:3)
Block(-11,26,8,18:3)
Block(-11,26,9,18:3)
Block(-11,26,10,18:3)
Block(-11,26,11,18:3)
Block(-11,26,12,18:3)
Block(-11,26,13,18:3)
Block(-11,27,-11,18:3)
Block(-11,27,-10,18:3)
Block(-11,27,-9,18:3)
Block(-11,27,-6,18:3)
Block(-11,27,9,18:3)
Block(-11,27,10,18:3)
Block(-11,27,11,18:3)
Block(-11,27,12,18:3)
Block(-11,28,-12,18:3)
Block(-11,28,-11,18:3)
Block(-11,28,-10,18:3)
Block(-11,28,-9,18:3)
Block(-11,28,-8,18:3)
Block(-11,28,-7,18:3)
Block(-11,28,-6,18:3)
Block(-11,29,-11,18:3)
Block(-11,29,-10,18:3)
Block(-11,29,-9,18:3)
Block(-11,29,-8,18:3)
Block(-11,29,-7,18:3)
Block(-11,30,-10,18:3)
Block(-11,30,-8,18:3)
Block(-10,20,4,18:3)
Block(-10,20,5,17:3)
Block(-10,20,6,17:3)
Block(-10,20,16,18:3)
Block(-10,21,6,17:3)
Block(-10,21,7,17:3)
Block(-10,21,8,17:3)
Block(-10,21,16,18:3)
Block(-10,22,4,18:3)
Block(-10,22,5,18:3)
Block(-10,22,6,18:3)
Block(-10,22,7,17:3)
Block(-10,22,8,17:3)
Block(-10,22,9,17:3)
Block(-10,22,11,18:3)
Block(-10,22,16,18:3)
Block(-10,23,4,18:3)
Block(-10,23,5,18:3)
Block(-10,23,6,18:3)
Block(-10,23,7,18:3)
Block(-10,23,8,18:3)
Block(-10,23,9,18:3)
Block(-10,23,10,18:3)
Block(-10,23,11,18:3)
Block(-10,23,15,18:3)
Block(-10,23,16,18:3)
Block(-10,24,4,18:3)
Block(-10,24,5,18:3)
Block(-10,24,6,18:3)
Block(-10,24,7,18:3)
Block(-10,24,8,18:3)
Block(-10,24,9,17:3)
Block(-10,24,10,18:3)
Block(-10,24,11,18:3)
Block(-10,24,12,18:3)
Block(-10,24,13,17:3)
Block(-10,24,14,18:3)
Block(-10,24,15,18:3)
Block(-10,24,16,18:3)
Block(-10,25,6,18:3)
Block(-10,25,7,18:3)
Block(-10,25,8,18:3)
Block(-10,25,9,18:3)
Block(-10,25,10,18:3)
Block(-10,25,11,18:3)
Block(-10,25,12,18:3)
Block(-10,25,13,18:3)
Block(-10,25,14,18:3)
Block(-10,25,15,18:3)
Block(-10,26,6,18:3)
Block(-10,26,7,18:3)
Block(-10,26,8,18:3)
Block(-10,26,10,18:3)
Block(-10,26,11,18:3)
Block(-10,26,13,18:3)
Block(-10,26,14,18:3)
Block(-10,27,-12,18:3)
Block(-10,27,-11,18:3)
Block(-10,27,-10,18:3)
Block(-10,27,-8,18:3)
Block(-10,27,-7,18:3)
Block(-10,27,-6,18:3)
Block(-10,27,8,18:3)
Block(-10,27,11,18:3)
Block(-10,27,13,18:3)
Block(-10,28,-13,18:3)
Block(-10,28,-12,18:3)
Block(-10,28,-11,18:3)
Block(-10,28,-10,18:3)
Block(-10,28,-9,18:3)
Block(-10,28,-8,18:3)
Block(-10,28,-7,18:3)
Block(-10,28,-6,18:3)
Block(-10,28,-5,18:3)
Block(-10,29,-12,18:3)
Block(-10,29,-11,18:3)
Block(-10,29,-10,18:3)
Block(-10,29,-9,18:3)
Block(-10,29,-8,18:3)
Block(-10,29,-7,18:3)
Block(-10,29,-6,18:3)
Block(-10,30,-11,18:3)
Block(-10,30,-10,18:3)
Block(-10,30,-9,18:3)
Block(-10,35,3,18:3)
Block(-10,35,4,18:3)
Block(-10,35,5,18:3)
Block(-10,36,2,18:3)
Block(-10,36,3,18:3)
Block(-10,36,4,18:3)
Block(-10,36,5,18:3)
Block(-10,36,6,18:3)
Block(-10,37,3,18:3)
Block(-10,37,5,18:3)
Block(-9,19,4,18:3)
Block(-9,19,5,17:3)
Block(-9,19,6,17:3)
Block(-9,20,3,18:3)
Block(-9,20,4,17:3)
Block(-9,20,5,17:3)
Block(-9,20,6,17:3)
Block(-9,20,7,17:3)
Block(-9,20,8,17:3)
Block(-9,21,4,18:3)
Block(-9,21,5,17:3)
Block(-9,21,6,17:3)
Block(-9,21,7,17:3)
Block(-9,21,8,17:3)
Block(-9,21,9,17:3)
Block(-9,22,5,18:3)
Block(-9,22,6,17:3)
Block(-9,22,7,17:3)
Block(-9,22,8,17:3)
Block(-9,22,9,17:3)
Block(-9,22,10,17:3)
Block(-9,22,15,18:3)
Block(-9,23,4,18:3)
Block(-9,23,5,18:3)
Block(-9,23,6,18:3)
Block(-9,23,7,18:3)
Block(-9,23,8,18:3)
Block(-9,23,9,18:3)
Block(-9,23,10,17:3)
Block(-9,23,11,17:3)
Block(-9,23,14,18:3)
Block(-9,23,15,18:3)
Block(-9,23,16,18:3)
Block(-9,24,4,18:3)
Block(-9,24,5,18:3)
Block(-9,24,6,18:3)
Block(-9,24,7,18:3)
Block(-9,24,8,17:3)
Block(-9,24,9,17:3)
Block(-9,24,10,17:3)
Block(-9,24,11,18:3)
Block(-9,24,12,17:3)
Block(-9,24,13,17:3)
Block(-9,24,15,18:3)
Block(-9,24,16,18:3)
Block(-9,25,4,18:3)
Block(-9,25,5,18:3)
Block(-9,25,7,18:3)
Block(-9,25,8,18:3)
Block(-9,25,9,18:3)
Block(-9,25,10,18:3)
Block(-9,25,11,18:3)
Block(-9,25,12,18:3)
Block(-9,25,13,18:3)
Block(-9,25,15,18:3)
Block(-9,26,6,18:3)
Block(-9,26,7,18:3)
Block(-9,26,8,18:3)
Block(-9,26,9,18:3)
Block(-9,26,10,18:3)
Block(-9,26,11,18:3)
Block(-9,26,12,18:3)
Block(-9,26,13,18:3)
Block(-9,26,14,18:3)
Block(-9,27,-11,18:3)
Block(-9,27,-8,18:3)
Block(-9,27,-6,18:3)
Block(-9,27,8,18:3)
Block(-9,27,10,18:3)
Block(-9,27,13,18:3)
Block(-9,28,-13,18:3)
Block(-9,28,-12,18:3)
Block(-9,28,-10,18:3)
Block(-9,28,-8,17:3)
Block(-9,28,-7,17:3)
Block(-9,28,-6,18:3)
Block(-9,28,-5,18:3)
Block(-9,28,-4,18:3)
Block(-9,29,-12,18:3)
Block(-9,29,-11,18:3)
Block(-9,29,-10,18:3)
Block(-9,29,-9,18:3)
Block(-9,29,-8,18:3)
Block(-9,29,-7,17:3)
Block(-9,29,-6,18:3)
Block(-9,30,-12,18:3)
Block(-9,30,-11,18:3)
Block(-9,30,-10,18:3)
Block(-9,30,-9,18:3)
Block(-9,30,-8,18:3)
Block(-9,30,-7,18:3)
Block(-9,31,-11,18:3)
Block(-9,31,-9,18:3)
Block(-9,31,6,18:3)
Block(-9,32,-1,18:3)
Block(-9,32,6,18:3)
Block(-9,33,-1,18:3)
Block(-9,33,1,18:3)
Block(-9,33,6,18:3)
Block(-9,34,-1,18:3)
Block(-9,34,1,18:3)
Block(-9,34,6,18:3)
Block(-9,35,-1,18:3)
Block(-9,35,0,18:3)
Block(-9,35,1,18:3)
Block(-9,35,2,18:3)
Block(-9,35,4,18:3)
Block(-9,35,5,18:3)
Block(-9,35,6,18:3)
Block(-9,35,7,18:3)
Block(-9,36,-1,18:3)
Block(-9,36,0,18:3)
Block(-9,36,1,18:3)
Block(-9,36,2,18:3)
Block(-9,36,3,18:3)
Block(-9,36,4,18:3)
Block(-9,36,5,18:3)
Block(-9,36,6,18:3)
Block(-9,36,7,18:3)
Block(-9,36,8,18:3)
Block(-9,37,0,18:3)
Block(-9,37,1,18:3)
Block(-9,37,2,18:3)
Block(-9,37,4,18:3)
Block(-9,37,6,18:3)
Block(-9,37,7,18:3)
Block(-9,38,2,18:3)
Block(-8,18,5,18:3)
Block(-8,19,4,17:3)
Block(-8,19,5,17:3)
Block(-8,19,6,17:3)
Block(-8,20,3,17:3)
Block(-8,20,4,17:3)
Block(-8,20,5,17:3)
Block(-8,20,6,17:3)
Block(-8,20,7,17:3)
Block(-8,21,4,17:3)
Block(-8,21,5,17:3)
Block(-8,21,6,17:3)
Block(-8,21,7,17:3)
Block(-8,21,8,17:3)
Block(-8,22,-12,18:3)
Block(-8,22,4,18:3)
Block(-8,22,5,18:3)
Block(-8,22,6,18:3)
Block(-8,22,7,17:3)
Block(-8,22,8,17:3)
Block(-8,22,9,17:3)
Block(-8,22,14,18:3)
Block(-8,22,15,18:3)
Block(-8,22,16,18:3)
Block(-8,23,-12,18:3)
Block(-8,23,4,18:3)
Block(-8,23,5,18:3)
Block(-8,23,6,18:3)
Block(-8,23,7,18:3)
Block(-8,23,8,18:3)
Block(-8,23,9,17:3)
Block(-8,23,13,18:3)
Block(-8,23,14,18:3)
Block(-8,23,15,18:3)
Block(-8,23,16,18:3)
Block(-8,24,-12,18:3)
Block(-8,24,-5,18:3)
Block(-8,24,4,18:3)
Block(-8,24,5,18:3)
Block(-8,24,6,18:3)
Block(-8,24,7,18:3)
Block(-8,24,8,18:3)
Block(-8,24,9,17:3)
Block(-8,24,10,18:3)
Block(-8,24,11,18:3)
Block(-8,24,12,18:3)
Block(-8,24,13,18:3)
Block(-8,24,14,18:3)
Block(-8,24,15,18:3)
Block(-8,25,-12,18:3)
Block(-8,25,-7,18:3)
Block(-8,25,-5,18:3)
Block(-8,25,6,18:3)
Block(-8,25,7,18:3)
Block(-8,25,8,18:3)
Block(-8,25,9,18:3)
Block(-8,25,10,18:3)
Block(-8,25,11,18:3)
Block(-8,25,12,18:3)
Block(-8,25,14,18:3)
Block(-8,26,-12,18:3)
Block(-8,26,-8,17:3)
Block(-8,26,-7,18:3)
Block(-8,26,-5,18:3)
Block(-8,26,7,18:3)
Block(-8,26,9,18:3)
Block(-8,26,10,18:3)
Block(-8,26,11,18:3)
Block(-8,26,13,18:3)
Block(-8,27,-12,18:3)
Block(-8,27,-9,17:3)
Block(-8,27,-8,17:3)
Block(-8,27,-5,18:3)
Block(-8,27,9,18:3)
Block(-8,27,10,18:3)
Block(-8,28,-14,18:3)
Block(-8,28,-13,18:3)
Block(-8,28,-12,18:3)
Block(-8,28,-10,17:3)
Block(-8,28,-9,17:3)
Block(-8,28,-8,18:3)
Block(-8,28,-7,18:3)
Block(-8,28,-6,18:3)
Block(-8,28,-5,18:3)
Block(-8,28,-4,18:3)
Block(-8,29,-14,18:3)
Block(-8,29,-13,18:3)
Block(-8,29,-12,18:3)
Block(-8,29,-11,18:3)
Block(-8,29,-10,18:3)
Block(-8,29,-9,18:3)
Block(-8,29,-8,18:3)
Block(-8,29,-7,18:3)
Block(-8,29,-5,18:3)
Block(-8,30,-13,18:3)
Block(-8,30,-12,18:3)
Block(-8,30,-11,18:3)
Block(-8,30,-10,18:3)
Block(-8,30,-9,18:3)
Block(-8,30,-8,18:3)
Block(-8,30,-7,18:3)
Block(-8,30,-6,18:3)
Block(-8,30,4,18:3)
Block(-8,31,-12,18:3)
Block(-8,31,-11,18:3)
Block(-8,31,-10,18:3)
Block(-8,31,-9,18:3)
Block(-8,31,-8,18:3)
Block(-8,31,4,18:3)
Block(-8,32,4,18:3)
Block(-8,33,4,18:3)
Block(-8,34,4,18:3)
Block(-8,35,-3,18:3)
Block(-8,35,-2,18:3)
Block(-8,35,-1,18:3)
Block(-8,35,0,18:3)
Block(-8,35,1,18:3)
Block(-8,35,2,18:3)
Block(-8,35,3,18:3)
Block(-8,35,4,18:3)
Block(-8,35,5,18:3)
Block(-8,35,6,18:3)
Block(-8,35,8,18:3)
Block(-8,36,-4,18:3)
Block(-8,36,-3,18:3)
Block(-8,36,-2,18:3)
Block(-8,36,-1,18:3)
Block(-8,36,0,18:3)
Block(-8,36,1,18:3)
Block(-8,36,2,18:3)
Block(-8,36,4,18:3)
Block(-8,36,5,18:3)
Block(-8,36,6,18:3)
Block(-8,36,7,18:3)
Block(-8,36,8,18:3)
Block(-8,36,9,18:3)
Block(-8,37,-1,18:3)
Block(-8,37,0,18:3)
Block(-8,37,1,18:3)
Block(-8,37,2,18:3)
Block(-8,37,3,18:3)
Block(-8,37,4,18:3)
Block(-8,37,5,18:3)
Block(-8,37,6,18:3)
Block(-8,37,7,18:3)
Block(-8,37,8,18:3)
Block(-8,38,0,18:3)
Block(-8,38,4,18:3)
Block(-8,38,5,18:3)
Block(-8,38,7,18:3)
Block(-7,18,5,18:3)
Block(-7,19,3,17:3)
Block(-7,19,4,17:3)
Block(-7,19,5,17:3)
Block(-7,19,6,18:3)
Block(-7,19,15,18:3)
Block(-7,20,2,17:3)
Block(-7,20,3,17:3)
Block(-7,20,4,17:3)
Block(-7,20,5,17:3)
Block(-7,20,6,17:3)
Block(-7,20,7,18:3)
Block(-7,20,12,18:3)
Block(-7,20,15,18:3)
Block(-7,21,3,17:3)
Block(-7,21,4,17:3)
Block(-7,21,5,17:3)
Block(-7,21,6,18:3)
Block(-7,21,12,18:3)
Block(-7,21,15,18:3)
Block(-7,22,5,18:3)
Block(-7,22,12,18:3)
Block(-7,22,14,18:3)
Block(-7,22,15,18:3)
Block(-7,23,-8,18:3)
Block(-7,23,4,18:3)
Block(-7,23,5,18:3)
Block(-7,23,8,17:3)
Block(-7,23,12,18:3)
Block(-7,23,14,18:3)
Block(-7,23,15,18:3)
Block(-7,24,-8,17:3)
Block(-7,24,-7,18:3)
Block(-7,24,5,18:3)
Block(-7,24,6,18:3)
Block(-7,24,7,18:3)
Block(-7,24,8,18:3)
Block(-7,24,9,18:3)
Block(-7,24,10,18:3)
Block(-7,24,11,18:3)
Block(-7,24,12,18:3)
Block(-7,24,14,18:3)
Block(-7,24,15,18:3)
Block(-7,25,-9,17:3)
Block(-7,25,-8,17:3)
Block(-7,25,-7,17:3)
Block(-7,25,6,18:3)
Block(-7,25,8,18:3)
Block(-7,25,9,18:3)
Block(-7,25,10,18:3)
Block(-7,25,11,18:3)
Block(-7,25,13,18:3)
Block(-7,25,14,18:3)
Block(-7,26,-10,17:3)
Block(-7,26,-9,17:3)
Block(-7,26,-8,17:3)
Block(-7,26,-7,17:3)
Block(-7,26,8,18:3)
Block(-7,26,9,18:3)
Block(-7,26,11,18:3)
Block(-7,26,12,18:3)
Block(-7,26,13,18:3)
Block(-7,27,-13,18:3)
Block(-7,27,-10,17:3)
Block(-7,27,-9,17:3)
Block(-7,27,-8,17:3)
Block(-7,27,-7,17:3)
Block(-7,27,-5,18:3)
Block(-7,27,-4,18:3)
Block(-7,27,2,18:3)
Block(-7,27,10,18:3)
Block(-7,27,11,18:3)
Block(-7,28,-14,18:3)
Block(-7,28,-13,18:3)
Block(-7,28,-12,17:3)
Block(-7,28,-11,17:3)
Block(-7,28,-10,17:3)
Block(-7,28,-9,17:3)
Block(-7,28,-8,17:3)
Block(-7,28,-7,18:3)
Block(-7,28,-5,18:3)
Block(-7,28,-4,18:3)
Block(-7,28,2,18:3)
Block(-7,29,-14,18:3)
Block(-7,29,-13,18:3)
Block(-7,29,-12,18:3)
Block(-7,29,-11,18:3)
Block(-7,29,-10,18:3)
Block(-7,29,-9,17:3)
Block(-7,29,-8,17:3)
Block(-7,29,-7,18:3)
Block(-7,29,-6,18:3)
Block(-7,29,-5,18:3)
Block(-7,29,2,18:3)
Block(-7,30,-13,18:3)
Block(-7,30,-12,18:3)
Block(-7,30,-11,18:3)
Block(-7,30,-10,18:3)
Block(-7,30,-9,18:3)
Block(-7,30,-8,18:3)
Block(-7,30,-7,18:3)
Block(-7,30,-6,18:3)
Block(-7,30,-5,18:3)
Block(-7,30,2,18:3)
Block(-7,31,-12,18:3)
Block(-7,31,-10,18:3)
Block(-7,31,-8,18:3)
Block(-7,31,-7,18:3)
Block(-7,31,2,18:3)
Block(-7,31,8,18:3)
Block(-7,32,-3,18:3)
Block(-7,32,2,18:3)
Block(-7,32,8,18:3)
Block(-7,33,-3,18:3)
Block(-7,33,2,18:3)
Block(-7,33,8,18:3)
Block(-7,34,-3,18:3)
Block(-7,34,2,18:3)
Block(-7,34,8,18:3)
Block(-7,35,-4,18:3)
Block(-7,35,-3,18:3)
Block(-7,35,-2,18:3)
Block(-7,35,-1,18:3)
Block(-7,35,2,18:3)
Block(-7,35,3,18:3)
Block(-7,35,5,18:3)
Block(-7,35,6,18:3)
Block(-7,35,7,18:3)
Block(-7,35,8,18:3)
Block(-7,35,9,18:3)
Block(-7,36,-5,18:3)
Block(-7,36,-4,18:3)
Block(-7,36,-3,18:3)
Block(-7,36,-2,18:3)
Block(-7,36,-1,18:3)
Block(-7,36,0,18:3)
Block(-7,36,1,18:3)
Block(-7,36,3,18:3)
Block(-7,36,4,18:3)
Block(-7,36,5,18:3)
Block(-7,36,6,18:3)
Block(-7,36,7,18:3)
Block(-7,36,8,18:3)
Block(-7,37,-4,18:3)
Block(-7,37,-3,18:3)
Block(-7,37,-2,18:3)
Block(-7,37,-1,18:3)
Block(-7,37,0,18:3)
Block(-7,37,1,18:3)
Block(-7,37,2,18:3)
Block(-7,37,3,18:3)
Block(-7,37,4,18:3)
Block(-7,37,5,18:3)
Block(-7,37,6,18:3)
Block(-7,37,7,18:3)
Block(-7,37,8,18:3)
Block(-7,37,9,18:3)
Block(-7,38,-3,18:3)
Block(-7,38,0,18:3)
Block(-7,38,1,18:3)
Block(-7,38,2,18:3)
Block(-7,38,3,18:3)
Block(-7,38,4,18:3)
Block(-7,38,8,18:3)
Block(-6,18,3,17:3)
Block(-6,19,2,17:3)
Block(-6,19,3,17:3)
Block(-6,19,4,17:3)
Block(-6,20,2,17:3)
Block(-6,20,3,17:3)
Block(-6,20,4,17:3)
Block(-6,20,5,17:3)
Block(-6,21,3,17:3)
Block(-6,21,4,17:3)
Block(-6,22,4,18:3)
Block(-6,22,5,18:3)
Block(-6,22,12,18:3)
Block(-6,22,13,18:3)
Block(-6,22,14,18:3)
Block(-6,22,15,18:3)
Block(-6,23,-9,18:3)
Block(-6,23,-8,17:3)
Block(-6,23,5,18:3)
Block(-6,23,6,18:3)
Block(-6,23,8,17:3)
Block(-6,23,10,18:3)
Block(-6,23,11,18:3)
Block(-6,23,12,18:3)
Block(-6,23,13,18:3)
Block(-6,23,14,18:3)
Block(-6,23,15,18:3)
Block(-6,24,-14,18:3)
Block(-6,24,-10,18:3)
Block(-6,24,-9,17:3)
Block(-6,24,-8,17:3)
Block(-6,24,-7,17:3)
Block(-6,24,5,18:3)
Block(-6,24,6,18:3)
Block(-6,24,7,18:3)
Block(-6,24,8,18:3)
Block(-6,24,9,18:3)
Block(-6,24,10,18:3)
Block(-6,24,11,18:3)
Block(-6,24,12,18:3)
Block(-6,24,13,18:3)
Block(-6,24,14,18:3)
Block(-6,24,15,18:3)
Block(-6,25,-14,18:3)
Block(-6,25,-10,17:3)
Block(-6,25,-9,17:3)
Block(-6,25,-8,17:3)
Block(-6,25,-7,17:3)
Block(-6,25,7,18:3)
Block(-6,25,8,18:3)
Block(-6,25,9,18:3)
Block(-6,25,10,18:3)
Block(-6,25,11,18:3)
Block(-6,25,12,18:3)
Block(-6,25,13,18:3)
Block(-6,26,-14,18:3)
Block(-6,26,-10,17:3)
Block(-6,26,-9,17:3)
Block(-6,26,-8,17:3)
Block(-6,26,-7,17:3)
Block(-6,26,8,18:3)
Block(-6,26,9,18:3)
Block(-6,26,10,18:3)
Block(-6,26,11,18:3)
Block(-6,26,12,18:3)
Block(-6,27,-14,18:3)
Block(-6,27,-13,18:3)
Block(-6,27,-10,17:3)
Block(-6,27,-9,17:3)
Block(-6,27,-8,17:3)
Block(-6,27,-7,18:3)
Block(-6,27,-5,18:3)
Block(-6,27,-4,18:3)
Block(-6,27,9,18:3)
Block(-6,28,-14,18:3)
Block(-6,28,-13,17:3)
Block(-6,28,-12,17:3)
Block(-6,28,-10,18:3)
Block(-6,28,-9,18:3)
Block(-6,28,-8,18:3)
Block(-6,28,-7,18:3)
Block(-6,28,-6,18:3)
Block(-6,28,-4,18:3)
Block(-6,29,-14,18:3)
Block(-6,29,-13,18:3)
Block(-6,29,-12,18:3)
Block(-6,29,-11,18:3)
Block(-6,29,-10,18:3)
Block(-6,29,-9,17:3)
Block(-6,29,-8,18:3)
Block(-6,29,-7,18:3)
Block(-6,29,-6,18:3)
Block(-6,29,-5,18:3)
Block(-6,29,-4,18:3)
Block(-6,30,-13,18:3)
Block(-6,30,-11,18:3)
Block(-6,30,-10,18:3)
Block(-6,30,-9,18:3)
Block(-6,30,-8,18:3)
Block(-6,30,-7,18:3)
Block(-6,30,10,18:3)
Block(-6,31,-12,18:3)
Block(-6,31,-9,18:3)
Block(-6,31,-8,18:3)
Block(-6,31,10,18:3)
Block(-6,32,10,18:3)
Block(-6,33,10,18:3)
Block(-6,33,11,18:3)
Block(-6,34,7,18:3)
Block(-6,34,8,18:3)
Block(-6,34,9,18:3)
Block(-6,34,10,18:3)
Block(-6,34,11,18:3)
Block(-6,34,12,18:3)
Block(-6,35,-5,18:3)
Block(-6,35,-4,18:3)
Block(-6,35,-3,18:3)
Block(-6,35,7,18:3)
Block(-6,35,8,18:3)
Block(-6,35,9,18:3)
Block(-6,35,10,18:3)
Block(-6,35,11,18:3)
Block(-6,36,-5,18:3)
Block(-6,36,-4,18:3)
Block(-6,36,-3,18:3)
Block(-6,36,-2,18:3)
Block(-6,36,0,18:3)
Block(-6,36,1,18:3)
Block(-6,36,2,18:3)
Block(-6,36,3,18:3)
Block(-6,36,4,18:3)
Block(-6,36,5,18:3)
Block(-6,36,6,18:3)
Block(-6,36,7,18:3)
Block(-6,36,8,18:3)
Block(-6,36,9,18:3)
Block(-6,36,10,18:3)
Block(-6,37,-5,18:3)
Block(-6,37,-4,18:3)
Block(-6,37,-3,18:3)
Block(-6,37,-2,18:3)
Block(-6,37,-1,18:3)
Block(-6,37,0,18:3)
Block(-6,37,1,18:3)
Block(-6,37,2,18:3)
Block(-6,37,3,18:3)
Block(-6,37,4,18:3)
Block(-6,37,5,18:3)
Block(-6,37,6,18:3)
Block(-6,37,7,18:3)
Block(-6,37,8,18:3)
Block(-6,37,9,18:3)
Block(-6,38,-4,18:3)
Block(-6,38,-2,18:3)
Block(-6,38,-1,18:3)
Block(-6,38,0,18:3)
Block(-6,38,1,18:3)
Block(-6,38,2,18:3)
Block(-6,38,3,18:3)
Block(-6,38,4,18:3)
Block(-6,38,5,18:3)
Block(-6,38,6,18:3)
Block(-6,38,8,18:3)
Block(-6,38,9,18:3)
Block(-6,39,1,18:3)
Block(-6,39,3,18:3)
Block(-5,16,14,18:3)
Block(-5,17,1,17:3)
Block(-5,17,2,18:3)
Block(-5,17,14,18:3)
Block(-5,18,0,17:3)
Block(-5,18,1,17:3)
Block(-5,18,2,17:3)
Block(-5,18,3,17:3)
Block(-5,18,14,18:3)
Block(-5,19,1,17:3)
Block(-5,19,2,17:3)
Block(-5,19,3,17:3)
Block(-5,19,14,18:3)
Block(-5,20,2,17:3)
Block(-5,20,3,17:3)
Block(-5,20,4,17:3)
Block(-5,20,14,18:3)
Block(-5,21,3,17:3)
Block(-5,21,14,18:3)
Block(-5,22,-8,17:3)
Block(-5,22,-7,17:3)
Block(-5,22,6,18:3)
Block(-5,22,7,18:3)
Block(-5,22,9,18:3)
Block(-5,22,10,18:3)
Block(-5,22,13,18:3)
Block(-5,22,14,18:3)
Block(-5,23,-9,17:3)
Block(-5,23,-8,17:3)
Block(-5,23,-7,17:3)
Block(-5,23,-6,17:3)
Block(-5,23,5,18:3)
Block(-5,23,6,18:3)
Block(-5,23,7,18:3)
Block(-5,23,8,17:3)
Block(-5,23,9,17:3)
Block(-5,23,10,18:3)
Block(-5,23,11,18:3)
Block(-5,23,12,18:3)
Block(-5,23,14,18:3)
Block(-5,23,15,18:3)
Block(-5,24,-9,17:3)
Block(-5,24,-8,17:3)
Block(-5,24,-7,17:3)
Block(-5,24,7,18:3)
Block(-5,24,8,18:3)
Block(-5,24,10,18:3)
Block(-5,24,11,18:3)
Block(-5,24,12,18:3)
Block(-5,24,13,18:3)
Block(-5,25,-10,18:3)
Block(-5,25,-9,17:3)
Block(-5,25,-8,17:3)
Block(-5,25,-7,17:3)
Block(-5,25,-5,18:3)
Block(-5,25,7,18:3)
Block(-5,25,9,18:3)
Block(-5,25,10,18:3)
Block(-5,25,12,18:3)
Block(-5,26,-11,18:3)
Block(-5,26,-10,17:3)
Block(-5,26,-9,17:3)
Block(-5,26,-8,17:3)
Block(-5,26,-5,18:3)
Block(-5,26,9,18:3)
Block(-5,26,10,18:3)
Block(-5,27,-13,18:3)
Block(-5,27,-11,18:3)
Block(-5,27,-10,18:3)
Block(-5,27,-9,17:3)
Block(-5,27,-7,18:3)
Block(-5,27,-5,18:3)
Block(-5,28,-14,18:3)
Block(-5,28,-12,18:3)
Block(-5,28,-11,18:3)
Block(-5,28,-10,18:3)
Block(-5,28,-9,18:3)
Block(-5,28,-8,18:3)
Block(-5,28,-7,18:3)
Block(-5,28,-6,18:3)
Block(-5,28,-5,18:3)
Block(-5,28,-4,18:3)
Block(-5,29,-13,18:3)
Block(-5,29,-12,18:3)
Block(-5,29,-11,18:3)
Block(-5,29,-10,18:3)
Block(-5,29,-9,18:3)
Block(-5,29,-8,18:3)
Block(-5,29,-7,18:3)
Block(-5,29,-6,18:3)
Block(-5,29,-5,18:3)
Block(-5,30,-13,18:3)
Block(-5,30,-12,18:3)
Block(-5,30,-11,18:3)
Block(-5,30,-10,18:3)
Block(-5,30,-9,18:3)
Block(-5,30,-8,18:3)
Block(-5,30,-7,18:3)
Block(-5,30,-6,18:3)
Block(-5,31,-11,18:3)
Block(-5,31,-10,18:3)
Block(-5,31,-9,18:3)
Block(-5,31,-8,18:3)
Block(-5,31,12,18:3)
Block(-5,32,12,18:3)
Block(-5,33,11,18:3)
Block(-5,33,12,18:3)
Block(-5,34,8,18:3)
Block(-5,34,9,18:3)
Block(-5,34,10,18:3)
Block(-5,34,11,18:3)
Block(-5,34,12,18:3)
Block(-5,35,-6,18:3)
Block(-5,35,-4,18:3)
Block(-5,35,7,18:3)
Block(-5,35,8,18:3)
Block(-5,35,9,18:3)
Block(-5,35,10,18:3)
Block(-5,35,11,18:3)
Block(-5,35,12,18:3)
Block(-5,36,-7,18:3)
Block(-5,36,-6,18:3)
Block(-5,36,-5,18:3)
Block(-5,36,-4,18:3)
Block(-5,36,-3,18:3)
Block(-5,36,-2,18:3)
Block(-5,36,2,18:3)
Block(-5,36,3,18:3)
Block(-5,36,4,18:3)
Block(-5,36,5,18:3)
Block(-5,36,6,18:3)
Block(-5,36,7,18:3)
Block(-5,36,8,18:3)
Block(-5,36,9,18:3)
Block(-5,36,10,18:3)
Block(-5,36,11,18:3)
Block(-5,37,-6,18:3)
Block(-5,37,-5,18:3)
Block(-5,37,-4,18:3)
Block(-5,37,-3,18:3)
Block(-5,37,-2,18:3)
Block(-5,37,-1,18:3)
Block(-5,37,0,17:3)
Block(-5,37,1,18:3)
Block(-5,37,2,18:3)
Block(-5,37,3,18:3)
Block(-5,37,4,18:3)
Block(-5,37,5,18:3)
Block(-5,37,6,18:3)
Block(-5,37,7,18:3)
Block(-5,37,8,18:3)
Block(-5,37,9,18:3)
Block(-5,37,10,18:3)
Block(-5,38,-4,18:3)
Block(-5,38,-3,18:3)
Block(-5,38,-2,18:3)
Block(-5,38,-1,18:3)
Block(-5,38,0,18:3)
Block(-5,38,1,18:3)
Block(-5,38,2,18:3)
Block(-5,38,3,18:3)
Block(-5,38,4,18:3)
Block(-5,38,5,18:3)
Block(-5,38,6,18:3)
Block(-5,38,7,18:3)
Block(-5,38,8,18:3)
Block(-5,39,-2,18:3)
Block(-5,39,-1,18:3)
Block(-5,39,0,18:3)
Block(-5,39,1,18:3)
Block(-5,39,2,18:3)
Block(-5,39,3,18:3)
Block(-5,39,7,18:3)
Block(-5,40,1,18:3)
Block(-5,40,2,18:3)
Block(-4,4,-1,18:3)
Block(-4,5,-1,18:3)
Block(-4,6,0,18:3)
Block(-4,7,1,18:3)
Block(-4,13,-1,18:3)
Block(-4,14,-2,18:3)
Block(-4,16,1,17:3)
Block(-4,16,2,18:3)
Block(-4,17,0,17:3)
Block(-4,17,1,17:3)
Block(-4,17,2,17:3)
Block(-4,18,0,17:3)
Block(-4,18,1,17:3)
Block(-4,18,2,17:3)
Block(-4,18,3,17:3)
Block(-4,19,0,17:3)
Block(-4,19,1,17:3)
Block(-4,19,2,17:3)
Block(-4,19,3,17:3)
Block(-4,20,1,17:3)
Block(-4,20,2,17:3)
Block(-4,20,3,17:3)
Block(-4,21,-7,17:3)
Block(-4,22,-9,17:3)
Block(-4,22,-8,17:3)
Block(-4,22,-7,17:3)
Block(-4,22,-6,17:3)
Block(-4,22,6,18:3)
Block(-4,22,7,18:3)
Block(-4,22,8,18:3)
Block(-4,22,9,18:3)
Block(-4,22,12,18:3)
Block(-4,23,-9,17:3)
Block(-4,23,-8,17:3)
Block(-4,23,-7,17:3)
Block(-4,23,-6,17:3)
Block(-4,23,6,18:3)
Block(-4,23,7,18:3)
Block(-4,23,8,18:3)
Block(-4,23,9,18:3)
Block(-4,23,10,18:3)
Block(-4,23,11,18:3)
Block(-4,23,12,18:3)
Block(-4,23,13,18:3)
Block(-4,23,14,18:3)
Block(-4,24,-9,17:3)
Block(-4,24,-8,17:3)
Block(-4,24,-7,17:3)
Block(-4,24,-6,17:3)
Block(-4,24,6,18:3)
Block(-4,24,7,18:3)
Block(-4,24,8,18:3)
Block(-4,24,9,18:3)
Block(-4,24,10,18:3)
Block(-4,24,11,18:3)
Block(-4,24,12,18:3)
Block(-4,25,-12,18:3)
Block(-4,25,-9,17:3)
Block(-4,25,-8,17:3)
Block(-4,25,8,18:3)
Block(-4,25,9,18:3)
Block(-4,25,10,18:3)
Block(-4,25,11,18:3)
Block(-4,26,-12,18:3)
Block(-4,27,-13,18:3)
Block(-4,27,-12,18:3)
Block(-4,27,-9,18:3)
Block(-4,27,-8,18:3)
Block(-4,27,-7,18:3)
Block(-4,27,-6,18:3)
Block(-4,28,-13,18:3)
Block(-4,28,-12,18:3)
Block(-4,28,-11,18:3)
Block(-4,28,-10,18:3)
Block(-4,28,-9,18:3)
Block(-4,28,-8,18:3)
Block(-4,28,-7,18:3)
Block(-4,28,-6,18:3)
Block(-4,28,-5,18:3)
Block(-4,29,-12,18:3)
Block(-4,29,-11,18:3)
Block(-4,29,-10,18:3)
Block(-4,29,-9,18:3)
Block(-4,29,-7,18:3)
Block(-4,29,-6,18:3)
Block(-4,30,-12,18:3)
Block(-4,30,-11,18:3)
Block(-4,30,-10,18:3)
Block(-4,30,-9,18:3)
Block(-4,30,-7,18:3)
Block(-4,31,-11,18:3)
Block(-4,31,-9,18:3)
Block(-4,31,7,18:3)
Block(-4,32,-5,18:3)
Block(-4,32,7,18:3)
Block(-4,33,-5,18:3)
Block(-4,33,2,18:3)
Block(-4,33,7,18:3)
Block(-4,33,12,18:3)
Block(-4,33,13,18:3)
Block(-4,34,-5,18:3)
Block(-4,34,2,18:3)
Block(-4,34,7,18:3)
Block(-4,34,10,18:3)
Block(-4,34,11,18:3)
Block(-4,34,12,18:3)
Block(-4,34,13,18:3)
Block(-4,34,14,18:3)
Block(-4,35,-7,18:3)
Block(-4,35,-6,18:3)
Block(-4,35,-5,18:3)
Block(-4,35,2,18:3)
Block(-4,35,7,18:3)
Block(-4,35,8,18:3)
Block(-4,35,9,17:3)
Block(-4,35,10,18:3)
Block(-4,35,11,18:3)
Block(-4,35,13,18:3)
Block(-4,36,-7,18:3)
Block(-4,36,-6,18:3)
Block(-4,36,-5,18:3)
Block(-4,36,-4,18:3)
Block(-4,36,2,18:3)
Block(-4,36,5,18:3)
Block(-4,36,6,18:3)
Block(-4,36,7,18:3)
Block(-4,36,8,18:3)
Block(-4,36,9,18:3)
Block(-4,36,10,18:3)
Block(-4,36,11,18:3)
Block(-4,37,-7,18:3)
Block(-4,37,-6,18:3)
Block(-4,37,-5,18:3)
Block(-4,37,-4,18:3)
Block(-4,37,-3,18:3)
Block(-4,37,-2,18:3)
Block(-4,37,-1,18:3)
Block(-4,37,0,17:3)
Block(-4,37,1,17:3)
Block(-4,37,2,18:3)
Block(-4,37,3,18:3)
Block(-4,37,4,18:3)
Block(-4,37,5,18:3)
Block(-4,37,6,18:3)
Block(-4,37,7,18:3)
Block(-4,37,8,18:3)
Block(-4,37,9,18:3)
Block(-4,37,10,18:3)
Block(-4,37,11,18:3)
Block(-4,38,-6,18:3)
Block(-4,38,-5,18:3)
Block(-4,38,-4,18:3)
Block(-4,38,-3,18:3)
Block(-4,38,-2,18:3)
Block(-4,38,-1,18:3)
Block(-4,38,0,18:3)
Block(-4,38,1,18:3)
Block(-4,38,2,18:3)
Block(-4,38,3,18:3)
Block(-4,38,5,18:3)
Block(-4,38,6,18:3)
Block(-4,38,7,18:3)
Block(-4,38,8,18:3)
Block(-4,38,9,18:3)
Block(-4,39,-3,18:3)
Block(-4,39,-2,18:3)
Block(-4,39,-1,18:3)
Block(-4,39,0,18:3)
Block(-4,39,1,18:3)
Block(-4,39,2,18:3)
Block(-4,39,3,18:3)
Block(-4,39,4,18:3)
Block(-4,39,5,18:3)
Block(-4,39,6,18:3)
Block(-4,39,7,18:3)
Block(-4,40,-1,18:3)
Block(-4,40,0,18:3)
Block(-4,40,1,18:3)
Block(-4,40,3,18:3)
Block(-4,40,4,18:3)
Block(-3,0,-1,17:3)
Block(-3,0,0,17:3)
Block(-3,0,2,17:3)
Block(-3,0,3,18:3)
Block(-3,1,0,17:3)
Block(-3,1,1,17:3)
Block(-3,1,2,17:3)
Block(-3,1,3,18:3)
Block(-3,2,0,17:3)
Block(-3,2,1,17:3)
Block(-3,2,2,17:3)
Block(-3,3,-1,18:3)
Block(-3,3,0,17:3)
Block(-3,3,1,17:3)
Block(-3,3,2,17:3)
Block(-3,4,-1,17:3)
Block(-3,4,0,17:3)
Block(-3,4,1,17:3)
Block(-3,5,-1,17:3)
Block(-3,5,0,17:3)
Block(-3,5,1,17:3)
Block(-3,6,-1,17:3)
Block(-3,6,0,17:3)
Block(-3,6,1,17:3)
Block(-3,7,-2,17:3)
Block(-3,7,-1,17:3)
Block(-3,7,0,17:3)
Block(-3,7,1,17:3)
Block(-3,8,-2,17:3)
Block(-3,8,-1,17:3)
Block(-3,8,0,17:3)
Block(-3,8,1,18:3)
Block(-3,9,-2,17:3)
Block(-3,9,-1,17:3)
Block(-3,9,0,17:3)
Block(-3,9,1,18:3)
Block(-3,10,-3,17:3)
Block(-3,10,-2,17:3)
Block(-3,10,-1,17:3)
Block(-3,10,0,17:3)
Block(-3,11,-3,17:3)
Block(-3,11,-2,17:3)
Block(-3,11,-1,17:3)
Block(-3,11,0,18:3)
Block(-3,12,-3,17:3)
Block(-3,12,-2,17:3)
Block(-3,12,-1,18:3)
Block(-3,12,0,18:3)
Block(-3,13,-3,17:3)
Block(-3,13,-2,17:3)
Block(-3,13,-1,18:3)
Block(-3,14,-3,18:3)
Block(-3,14,-2,17:3)
Block(-3,14,-1,17:3)
Block(-3,15,-3,18:3)
Block(-3,15,-2,17:3)
Block(-3,15,-1,17:3)
Block(-3,16,-4,18:3)
Block(-3,16,-2,17:3)
Block(-3,16,-1,17:3)
Block(-3,16,0,17:3)
Block(-3,16,1,17:3)
Block(-3,16,2,18:3)
Block(-3,17,-4,18:3)
Block(-3,17,-1,17:3)
Block(-3,17,0,17:3)
Block(-3,17,1,17:3)
Block(-3,17,2,17:3)
Block(-3,18,0,17:3)
Block(-3,18,1,17:3)
Block(-3,18,2,17:3)
Block(-3,19,0,17:3)
Block(-3,19,1,17:3)
Block(-3,19,2,17:3)
Block(-3,19,3,17:3)
Block(-3,19,8,18:3)
Block(-3,19,11,18:3)
Block(-3,20,-7,18:3)
Block(-3,20,-6,17:3)
Block(-3,20,8,18:3)
Block(-3,20,11,18:3)
Block(-3,21,-8,17:3)
Block(-3,21,-7,17:3)
Block(-3,21,-6,17:3)
Block(-3,21,-5,17:3)
Block(-3,21,8,18:3)
Block(-3,21,11,18:3)
Block(-3,22,-8,17:3)
Block(-3,22,-7,17:3)
Block(-3,22,-6,17:3)
Block(-3,22,7,18:3)
Block(-3,22,8,18:3)
Block(-3,22,9,18:3)
Block(-3,22,10,18:3)
Block(-3,22,11,18:3)
Block(-3,23,-9,17:3)
Block(-3,23,-8,17:3)
Block(-3,23,-7,17:3)
Block(-3,23,-6,17:3)
Block(-3,23,6,18:3)
Block(-3,23,7,18:3)
Block(-3,23,8,18:3)
Block(-3,23,10,18:3)
Block(-3,23,11,18:3)
Block(-3,23,12,18:3)
Block(-3,24,-9,17:3)
Block(-3,24,-8,17:3)
Block(-3,24,-7,17:3)
Block(-3,24,7,18:3)
Block(-3,24,8,18:3)
Block(-3,24,9,18:3)
Block(-3,24,10,18:3)
Block(-3,25,-8,17:3)
Block(-3,27,-11,18:3)
Block(-3,27,-9,18:3)
Block(-3,28,-12,18:3)
Block(-3,28,-11,18:3)
Block(-3,28,-10,18:3)
Block(-3,28,-9,18:3)
Block(-3,28,-8,18:3)
Block(-3,28,-7,18:3)
Block(-3,28,-6,18:3)
Block(-3,29,-12,18:3)
Block(-3,29,-11,18:3)
Block(-3,29,-10,18:3)
Block(-3,29,-9,18:3)
Block(-3,29,-8,18:3)
Block(-3,29,-7,18:3)
Block(-3,30,-9,18:3)
Block(-3,31,14,18:3)
Block(-3,32,14,18:3)
Block(-3,33,12,18:3)
Block(-3,33,13,18:3)
Block(-3,33,14,18:3)
Block(-3,34,12,18:3)
Block(-3,34,13,18:3)
Block(-3,34,14,18:3)
Block(-3,35,-7,18:3)
Block(-3,35,-6,18:3)
Block(-3,35,6,18:3)
Block(-3,35,7,18:3)
Block(-3,35,8,18:3)
Block(-3,35,9,17:3)
Block(-3,35,10,18:3)
Block(-3,35,11,18:3)
Block(-3,35,12,18:3)
Block(-3,35,13,18:3)
Block(-3,35,14,18:3)
Block(-3,36,-8,18:3)
Block(-3,36,-7,18:3)
Block(-3,36,-6,18:3)
Block(-3,36,-5,18:3)
Block(-3,36,-4,18:3)
Block(-3,36,-3,18:3)
Block(-3,36,4,18:3)
Block(-3,36,5,18:3)
Block(-3,36,6,18:3)
Block(-3,36,7,18:3)
Block(-3,36,8,18:3)
Block(-3,36,9,18:3)
Block(-3,36,10,18:3)
Block(-3,36,11,18:3)
Block(-3,36,12,18:3)
Block(-3,37,-7,18:3)
Block(-3,37,-6,18:3)
Block(-3,37,-5,18:3)
Block(-3,37,-4,18:3)
Block(-3,37,-3,18:3)
Block(-3,37,-2,18:3)
Block(-3,37,-1,18:3)
Block(-3,37,0,18:3)
Block(-3,37,1,17:3)
Block(-3,37,3,18:3)
Block(-3,37,4,18:3)
Block(-3,37,5,18:3)
Block(-3,37,6,18:3)
Block(-3,37,7,18:3)
Block(-3,37,8,18:3)
Block(-3,37,9,18:3)
Block(-3,37,10,18:3)
Block(-3,38,-5,18:3)
Block(-3,38,-4,18:3)
Block(-3,38,-3,18:3)
Block(-3,38,-2,18:3)
Block(-3,38,-1,18:3)
Block(-3,38,0,18:3)
Block(-3,38,1,18:3)
Block(-3,38,2,18:3)
Block(-3,38,3,18:3)
Block(-3,38,4,18:3)
Block(-3,38,5,18:3)
Block(-3,38,6,18:3)
Block(-3,38,7,18:3)
Block(-3,38,8,18:3)
Block(-3,38,9,18:3)
Block(-3,38,10,18:3)
Block(-3,39,-3,18:3)
Block(-3,39,-2,18:3)
Block(-3,39,-1,18:3)
Block(-3,39,0,18:3)
Block(-3,39,1,18:3)
Block(-3,39,2,18:3)
Block(-3,39,3,18:3)
Block(-3,39,4,18:3)
Block(-3,39,5,18:3)
Block(-3,39,6,18:3)
Block(-3,39,8,18:3)
Block(-3,40,-4,18:3)
Block(-3,40,-3,18:3)
Block(-3,40,-2,18:3)
Block(-3,40,-1,18:3)
Block(-3,40,0,18:3)
Block(-3,40,2,18:3)
Block(-3,40,3,18:3)
Block(-3,40,5,18:3)
Block(-3,40,6,18:3)
Block(-3,40,7,18:3)
Block(-2,0,-2,17:3)
Block(-2,0,-1,17:3)
Block(-2,0,0,17:3)
Block(-2,0,1,17:3)
Block(-2,0,2,17:3)
Block(-2,0,3,17:3)
Block(-2,1,-2,18:3)
Block(-2,1,-1,17:3)
Block(-2,1,0,17:3)
Block(-2,1,1,17:3)
Block(-2,1,2,17:3)
Block(-2,1,3,17:3)
Block(-2,2,-2,18:3)
Block(-2,2,-1,17:3)
Block(-2,2,0,17:3)
Block(-2,2,1,17:3)
Block(-2,2,2,17:3)
Block(-2,2,3,18:3)
Block(-2,3,-1,17:3)
Block(-2,3,0,17:3)
Block(-2,3,1,17:3)
Block(-2,3,2,17:3)
Block(-2,3,3,18:3)
Block(-2,4,-1,17:3)
Block(-2,4,0,17:3)
Block(-2,4,1,17:3)
Block(-2,4,2,17:3)
Block(-2,5,-2,17:3)
Block(-2,5,-1,17:3)
Block(-2,5,0,17:3)
Block(-2,5,1,17:3)
Block(-2,6,-2,17:3)
Block(-2,6,-1,17:3)
Block(-2,6,0,17:3)
Block(-2,6,1,17:3)
Block(-2,7,-3,17:3)
Block(-2,7,-2,17:3)
Block(-2,7,-1,17:3)
Block(-2,7,0,17:3)
Block(-2,7,1,17:3)
Block(-2,8,-3,17:3)
Block(-2,8,-2,17:3)
Block(-2,8,-1,17:3)
Block(-2,8,0,17:3)
Block(-2,8,1,17:3)
Block(-2,9,-3,17:3)
Block(-2,9,-2,17:3)
Block(-2,9,-1,17:3)
Block(-2,9,0,17:3)
Block(-2,9,1,17:3)
Block(-2,10,-3,17:3)
Block(-2,10,-2,17:3)
Block(-2,10,-1,17:3)
Block(-2,10,0,17:3)
Block(-2,10,1,18:3)
Block(-2,11,-3,17:3)
Block(-2,11,-2,17:3)
Block(-2,11,-1,17:3)
Block(-2,11,0,17:3)
Block(-2,12,-3,17:3)
Block(-2,12,-2,17:3)
Block(-2,12,-1,17:3)
Block(-2,13,-3,17:3)
Block(-2,13,-2,17:3)
Block(-2,13,-1,17:3)
Block(-2,14,-4,17:3)
Block(-2,14,-3,17:3)
Block(-2,14,-2,17:3)
Block(-2,14,-1,17:3)
Block(-2,15,-4,17:3)
Block(-2,15,-3,17:3)
Block(-2,15,-2,17:3)
Block(-2,15,-1,17:3)
Block(-2,15,0,17:3)
Block(-2,16,-4,17:3)
Block(-2,16,-3,17:3)
Block(-2,16,-2,17:3)
Block(-2,16,-1,17:3)
Block(-2,16,0,17:3)
Block(-2,16,1,17:3)
Block(-2,17,-4,17:3)
Block(-2,17,-3,17:3)
Block(-2,17,-2,17:3)
Block(-2,17,-1,17:3)
Block(-2,17,0,17:3)
Block(-2,17,1,17:3)
Block(-2,17,2,17:3)
Block(-2,17,3,18:3)
Block(-2,18,-5,18:3)
Block(-2,18,-3,17:3)
Block(-2,18,-2,17:3)
Block(-2,18,-1,17:3)
Block(-2,18,0,17:3)
Block(-2,18,1,17:3)
Block(-2,18,2,17:3)
Block(-2,19,-6,18:3)
Block(-2,19,-5,18:3)
Block(-2,19,-1,17:3)
Block(-2,19,0,17:3)
Block(-2,19,1,17:3)
Block(-2,20,-7,17:3)
Block(-2,20,-6,17:3)
Block(-2,20,-5,17:3)
Block(-2,21,-8,18:3)
Block(-2,21,-7,17:3)
Block(-2,21,-6,17:3)
Block(-2,21,-5,17:3)
Block(-2,21,-4,17:3)
Block(-2,22,-9,18:3)
Block(-2,22,-8,17:3)
Block(-2,22,-7,17:3)
Block(-2,22,-6,17:3)
Block(-2,22,-5,17:3)
Block(-2,22,9,18:3)
Block(-2,23,-8,17:3)
Block(-2,23,-7,17:3)
Block(-2,23,-6,17:3)
Block(-2,23,8,18:3)
Block(-2,23,9,18:3)
Block(-2,23,10,18:3)
Block(-2,24,-10,18:3)
Block(-2,24,9,18:3)
Block(-2,25,-10,18:3)
Block(-2,26,-10,18:3)
Block(-2,26,-7,18:3)
Block(-2,27,-10,18:3)
Block(-2,27,-8,18:3)
Block(-2,27,-7,18:3)
Block(-2,28,-11,18:3)
Block(-2,28,-10,18:3)
Block(-2,28,-9,18:3)
Block(-2,28,-8,18:3)
Block(-2,29,-10,18:3)
Block(-2,32,5,18:3)
Block(-2,33,-8,18:3)
Block(-2,33,-3,18:3)
Block(-2,33,5,18:3)
Block(-2,33,12,18:3)
Block(-2,33,13,18:3)
Block(-2,33,14,18:3)
Block(-2,34,-8,18:3)
Block(-2,34,-3,18:3)
Block(-2,34,5,18:3)
Block(-2,34,8,18:3)
Block(-2,34,11,18:3)
Block(-2,34,12,18:3)
Block(-2,34,13,18:3)
Block(-2,34,14,18:3)
Block(-2,34,15,18:3)
Block(-2,35,-8,18:3)
Block(-2,35,-7,18:3)
Block(-2,35,-6,18:3)
Block(-2,35,-3,18:3)
Block(-2,35,5,18:3)
Block(-2,35,6,18:3)
Block(-2,35,7,18:3)
Block(-2,35,8,17:3)
Block(-2,35,9,17:3)
Block(-2,35,10,18:3)
Block(-2,35,11,18:3)
Block(-2,35,12,18:3)
Block(-2,35,13,18:3)
Block(-2,35,14,18:3)
Block(-2,36,-8,18:3)
Block(-2,36,-7,18:3)
Block(-2,36,-6,18:3)
Block(-2,36,-5,18:3)
Block(-2,36,-4,18:3)
Block(-2,36,-3,18:3)
Block(-2,36,4,18:3)
Block(-2,36,5,18:3)
Block(-2,36,6,18:3)
Block(-2,36,7,18:3)
Block(-2,36,8,18:3)
Block(-2,36,9,18:3)
Block(-2,36,10,18:3)
Block(-2,36,11,18:3)
Block(-2,36,12,18:3)
Block(-2,36,13,18:3)
Block(-2,37,-8,18:3)
Block(-2,37,-7,18:3)
Block(-2,37,-6,18:3)
Block(-2,37,-5,18:3)
Block(-2,37,-4,18:3)
Block(-2,37,-3,18:3)
Block(-2,37,-2,18:3)
Block(-2,37,-1,18:3)
Block(-2,37,1,17:3)
Block(-2,37,2,18:3)
Block(-2,37,3,18:3)
Block(-2,37,4,18:3)
Block(-2,37,5,18:3)
Block(-2,37,6,18:3)
Block(-2,37,7,18:3)
Block(-2,37,8,18:3)
Block(-2,37,9,18:3)
Block(-2,37,10,18:3)
Block(-2,37,11,18:3)
Block(-2,37,12,18:3)
Block(-2,38,-6,18:3)
Block(-2,38,-5,18:3)
Block(-2,38,-4,18:3)
Block(-2,38,-3,18:3)
Block(-2,38,-2,18:3)
Block(-2,38,-1,18:3)
Block(-2,38,0,18:3)
Block(-2,38,1,18:3)
Block(-2,38,2,18:3)
Block(-2,38,3,18:3)
Block(-2,38,4,18:3)
Block(-2,38,5,18:3)
Block(-2,38,6,18:3)
Block(-2,38,7,18:3)
Block(-2,38,8,18:3)
Block(-2,38,9,18:3)
Block(-2,38,11,18:3)
Block(-2,39,-5,18:3)
Block(-2,39,-4,18:3)
Block(-2,39,-3,18:3)
Block(-2,39,-2,18:3)
Block(-2,39,-1,18:3)
Block(-2,39,0,18:3)
Block(-2,39,1,18:3)
Block(-2,39,2,18:3)
Block(-2,39,3,18:3)
Block(-2,39,4,18:3)
Block(-2,39,5,18:3)
Block(-2,39,6,18:3)
Block(-2,39,7,18:3)
Block(-2,39,8,18:3)
Block(-2,40,-4,18:3)
Block(-2,40,-2,18:3)
Block(-2,40,-1,18:3)
Block(-2,40,0,18:3)
Block(-2,40,1,18:3)
Block(-2,40,2,18:3)
Block(-2,40,3,18:3)
Block(-2,40,4,18:3)
Block(-2,40,7,18:3)
Block(-2,41,1,18:3)
Block(-1,0,-3,18:3)
Block(-1,0,-2,17:3)
Block(-1,0,-1,17:3)
Block(-1,0,0,17:3)
Block(-1,0,1,17:3)
Block(-1,0,2,17:3)
Block(-1,1,-2,17:3)
Block(-1,1,-1,17:3)
Block(-1,1,0,17:3)
Block(-1,1,1,17:3)
Block(-1,1,2,17:3)
Block(-1,1,3,17:3)
Block(-1,2,-2,17:3)
Block(-1,2,-1,17:3)
Block(-1,2,0,17:3)
Block(-1,2,1,17:3)
Block(-1,2,2,17:3)
Block(-1,2,3,17:3)
Block(-1,3,-3,17:3)
Block(-1,3,-2,17:3)
Block(-1,3,-1,17:3)
Block(-1,3,0,17:3)
Block(-1,3,1,17:3)
Block(-1,3,2,17:3)
Block(-1,3,3,17:3)
Block(-1,4,-3,17:3)
Block(-1,4,-2,17:3)
Block(-1,4,-1,17:3)
Block(-1,4,0,17:3)
Block(-1,4,1,17:3)
Block(-1,4,2,17:3)
Block(-1,4,3,18:3)
Block(-1,5,-3,17:3)
Block(-1,5,-2,17:3)
Block(-1,5,-1,17:3)
Block(-1,5,0,17:3)
Block(-1,5,1,17:3)
Block(-1,5,2,17:3)
Block(-1,5,3,18:3)
Block(-1,6,-3,17:3)
Block(-1,6,-2,17:3)
Block(-1,6,-1,17:3)
Block(-1,6,0,17:3)
Block(-1,6,1,17:3)
Block(-1,6,2,17:3)
Block(-1,7,-3,17:3)
Block(-1,7,-2,17:3)
Block(-1,7,-1,17:3)
Block(-1,7,0,17:3)
Block(-1,7,1,17:3)
Block(-1,7,2,17:3)
Block(-1,8,-3,17:3)
Block(-1,8,-2,17:3)
Block(-1,8,-1,17:3)
Block(-1,8,0,17:3)
Block(-1,8,1,17:3)
Block(-1,8,2,17:3)
Block(-1,9,-3,17:3)
Block(-1,9,-2,17:3)
Block(-1,9,-1,17:3)
Block(-1,9,0,17:3)
Block(-1,9,1,17:3)
Block(-1,10,-4,17:3)
Block(-1,10,-3,17:3)
Block(-1,10,-2,17:3)
Block(-1,10,-1,17:3)
Block(-1,10,0,17:3)
Block(-1,10,1,17:3)
Block(-1,11,-4,17:3)
Block(-1,11,-3,17:3)
Block(-1,11,-2,17:3)
Block(-1,11,-1,17:3)
Block(-1,11,0,17:3)
Block(-1,12,-4,17:3)
Block(-1,12,-3,17:3)
Block(-1,12,-2,17:3)
Block(-1,12,-1,17:3)
Block(-1,12,0,17:3)
Block(-1,13,-4,17:3)
Block(-1,13,-3,17:3)
Block(-1,13,-2,17:3)
Block(-1,13,-1,17:3)
Block(-1,13,0,17:3)
Block(-1,14,-4,17:3)
Block(-1,14,-3,17:3)
Block(-1,14,-2,17:3)
Block(-1,14,-1,17:3)
Block(-1,14,0,17:3)
Block(-1,15,-5,17:3)
Block(-1,15,-4,17:3)
Block(-1,15,-3,17:3)
Block(-1,15,-2,17:3)
Block(-1,15,-1,17:3)
Block(-1,15,0,17:3)
Block(-1,16,-5,17:3)
Block(-1,16,-4,17:3)
Block(-1,16,-3,17:3)
Block(-1,16,-2,17:3)
Block(-1,16,-1,17:3)
Block(-1,16,0,17:3)
Block(-1,17,-5,17:3)
Block(-1,17,-4,17:3)
Block(-1,17,-3,17:3)
Block(-1,17,-2,17:3)
Block(-1,17,-1,17:3)
Block(-1,17,0,17:3)
Block(-1,17,1,17:3)
Block(-1,18,-5,17:3)
Block(-1,18,-4,17:3)
Block(-1,18,-3,17:3)
Block(-1,18,-2,17:3)
Block(-1,18,-1,17:3)
Block(-1,18,0,17:3)
Block(-1,18,2,18:3)
Block(-1,19,-5,17:3)
Block(-1,19,-4,17:3)
Block(-1,19,-3,17:3)
Block(-1,19,-2,17:3)
Block(-1,19,-1,17:3)
Block(-1,19,0,17:3)
Block(-1,19,1,18:3)
Block(-1,20,-7,17:3)
Block(-1,20,-6,17:3)
Block(-1,20,-5,17:3)
Block(-1,20,-4,17:3)
Block(-1,20,-3,17:3)
Block(-1,20,-2,17:3)
Block(-1,20,0,18:3)
Block(-1,21,-7,17:3)
Block(-1,21,-6,17:3)
Block(-1,21,-5,17:3)
Block(-1,21,-4,17:3)
Block(-1,21,-3,17:3)
Block(-1,22,-8,17:3)
Block(-1,22,-7,17:3)
Block(-1,22,-6,17:3)
Block(-1,22,-5,17:3)
Block(-1,22,-4,17:3)
Block(-1,23,-8,18:3)
Block(-1,23,-7,17:3)
Block(-1,23,-6,18:3)
Block(-1,23,-5,18:3)
Block(-1,24,-4,18:3)
Block(-1,25,-3,18:3)
Block(-1,30,7,18:3)
Block(-1,30,16,18:3)
Block(-1,31,7,18:3)
Block(-1,31,16,18:3)
Block(-1,32,7,18:3)
Block(-1,32,16,18:3)
Block(-1,33,8,18:3)
Block(-1,33,13,18:3)
Block(-1,33,14,18:3)
Block(-1,33,15,18:3)
Block(-1,33,16,18:3)
Block(-1,34,8,17:3)
Block(-1,34,9,18:3)
Block(-1,34,12,18:3)
Block(-1,34,13,18:3)
Block(-1,34,14,18:3)
Block(-1,34,15,18:3)
Block(-1,35,-7,18:3)
Block(-1,35,5,18:3)
Block(-1,35,6,18:3)
Block(-1,35,7,17:3)
Block(-1,35,8,17:3)
Block(-1,35,9,18:3)
Block(-1,35,10,18:3)
Block(-1,35,11,18:3)
Block(-1,35,12,18:3)
Block(-1,35,13,18:3)
Block(-1,35,14,18:3)
Block(-1,35,15,18:3)
Block(-1,36,-8,18:3)
Block(-1,36,-7,18:3)
Block(-1,36,-6,18:3)
Block(-1,36,-5,18:3)
Block(-1,36,3,18:3)
Block(-1,36,4,18:3)
Block(-1,36,5,18:3)
Block(-1,36,6,18:3)
Block(-1,36,7,18:3)
Block(-1,36,8,18:3)
Block(-1,36,9,18:3)
Block(-1,36,11,18:3)
Block(-1,36,12,18:3)
Block(-1,36,14,18:3)
Block(-1,37,-8,18:3)
Block(-1,37,-7,18:3)
Block(-1,37,-6,18:3)
Block(-1,37,-5,18:3)
Block(-1,37,-4,17:3)
Block(-1,37,-3,17:3)
Block(-1,37,-2,18:3)
Block(-1,37,-1,18:3)
Block(-1,37,0,17:3)
Block(-1,37,1,17:3)
Block(-1,37,2,18:3)
Block(-1,37,3,18:3)
Block(-1,37,4,18:3)
Block(-1,37,5,18:3)
Block(-1,37,6,18:3)
Block(-1,37,7,18:3)
Block(-1,37,8,18:3)
Block(-1,37,9,18:3)
Block(-1,37,10,18:3)
Block(-1,37,11,18:3)
Block(-1,37,12,18:3)
Block(-1,38,-7,18:3)
Block(-1,38,-6,18:3)
Block(-1,38,-5,18:3)
Block(-1,38,-4,18:3)
Block(-1,38,-3,18:3)
Block(-1,38,-2,18:3)
Block(-1,38,-1,18:3)
Block(-1,38,0,18:3)
Block(-1,38,1,18:3)
Block(-1,38,2,18:3)
Block(-1,38,3,18:3)
Block(-1,38,4,18:3)
Block(-1,38,5,18:3)
Block(-1,38,6,18:3)
Block(-1,38,7,18:3)
Block(-1,38,9,18:3)
Block(-1,38,10,18:3)
Block(-1,38,11,18:3)
Block(-1,38,12,18:3)
Block(-1,39,-6,18:3)
Block(-1,39,-5,18:3)
Block(-1,39,-4,18:3)
Block(-1,39,-3,18:3)
Block(-1,39,-2,18:3)
Block(-1,39,-1,18:3)
Block(-1,39,0,18:3)
Block(-1,39,1,18:3)
Block(-1,39,2,18:3)
Block(-1,39,3,18:3)
Block(-1,39,4,18:3)
Block(-1,39,5,18:3)
Block(-1,39,6,18:3)
Block(-1,39,7,18:3)
Block(-1,39,8,18:3)
Block(-1,39,9,18:3)
Block(-1,40,-5,18:3)
Block(-1,40,-4,18:3)
Block(-1,40,-3,18:3)
Block(-1,40,-2,18:3)
Block(-1,40,-1,18:3)
Block(-1,40,0,18:3)
Block(-1,40,1,18:3)
Block(-1,40,2,18:3)
Block(-1,40,3,18:3)
Block(-1,40,4,18:3)
Block(-1,40,5,18:3)
Block(-1,40,6,18:3)
Block(-1,40,8,18:3)
Block(-1,41,-1,18:3)
Block(-1,41,0,18:3)
Block(-1,41,1,18:3)
Block(-1,41,2,18:3)
Block(-1,41,4,18:3)
Block(0,0,-3,17:3)
Block(0,0,-2,17:3)
Block(0,0,-1,17:3)
Block(0,0,0,17:3)
Block(0,0,1,17:3)
Block(0,0,2,17:3)
Block(0,1,-2,17:3)
Block(0,1,-1,17:3)
Block(0,1,0,17:3)
Block(0,1,1,17:3)
Block(0,1,2,17:3)
Block(0,1,3,17:3)
Block(0,2,-2,17:3)
Block(0,2,-1,17:3)
Block(0,2,0,17:3)
Block(0,2,1,17:3)
Block(0,2,2,17:3)
Block(0,2,3,17:3)
Block(0,3,-2,17:3)
Block(0,3,-1,17:3)
Block(0,3,0,17:3)
Block(0,3,1,17:3)
Block(0,3,2,17:3)
Block(0,3,3,17:3)
Block(0,4,-2,17:3)
Block(0,4,-1,17:3)
Block(0,4,0,17:3)
Block(0,4,1,17:3)
Block(0,4,2,17:3)
Block(0,4,3,17:3)
Block(0,5,-3,17:3)
Block(0,5,-2,17:3)
Block(0,5,-1,17:3)
Block(0,5,0,17:3)
Block(0,5,1,17:3)
Block(0,5,2,17:3)
Block(0,6,-3,17:3)
Block(0,6,-2,17:3)
Block(0,6,-1,17:3)
Block(0,6,0,17:3)
Block(0,6,1,17:3)
Block(0,6,2,17:3)
Block(0,6,3,18:3)
Block(0,7,-3,17:3)
Block(0,7,-2,17:3)
Block(0,7,-1,17:3)
Block(0,7,0,17:3)
Block(0,7,1,17:3)
Block(0,7,2,17:3)
Block(0,8,-4,17:3)
Block(0,8,-3,17:3)
Block(0,8,-2,17:3)
Block(0,8,-1,17:3)
Block(0,8,0,17:3)
Block(0,8,1,17:3)
Block(0,9,-4,17:3)
Block(0,9,-3,17:3)
Block(0,9,-2,17:3)
Block(0,9,-1,17:3)
Block(0,9,0,17:3)
Block(0,9,1,17:3)
Block(0,10,-4,17:3)
Block(0,10,-3,17:3)
Block(0,10,-2,17:3)
Block(0,10,-1,17:3)
Block(0,10,0,17:3)
Block(0,10,1,17:3)
Block(0,11,-4,17:3)
Block(0,11,-3,17:3)
Block(0,11,-2,17:3)
Block(0,11,-1,17:3)
Block(0,11,0,17:3)
Block(0,11,1,17:3)
Block(0,12,-4,17:3)
Block(0,12,-3,17:3)
Block(0,12,-2,17:3)
Block(0,12,-1,17:3)
Block(0,12,0,17:3)
Block(0,12,1,17:3)
Block(0,13,-5,17:3)
Block(0,13,-4,17:3)
Block(0,13,-3,17:3)
Block(0,13,-2,17:3)
Block(0,13,-1,17:3)
Block(0,13,0,17:3)
Block(0,13,1,17:3)
Block(0,14,-5,17:3)
Block(0,14,-4,17:3)
Block(0,14,-3,17:3)
Block(0,14,-2,17:3)
Block(0,14,-1,17:3)
Block(0,14,0,17:3)
Block(0,15,-5,17:3)
Block(0,15,-4,17:3)
Block(0,15,-3,17:3)
Block(0,15,-2,17:3)
Block(0,15,-1,17:3)
Block(0,15,0,17:3)
Block(0,16,-5,17:3)
Block(0,16,-4,17:3)
Block(0,16,-3,17:3)
Block(0,16,-2,17:3)
Block(0,16,-1,17:3)
Block(0,16,0,17:3)
Block(0,17,-6,17:3)
Block(0,17,-5,17:3)
Block(0,17,-4,17:3)
Block(0,17,-3,17:3)
Block(0,17,-2,17:3)
Block(0,17,-1,17:3)
Block(0,17,0,17:3)
Block(0,18,-6,17:3)
Block(0,18,-5,17:3)
Block(0,18,-4,17:3)
Block(0,18,-3,17:3)
Block(0,18,-2,17:3)
Block(0,18,-1,17:3)
Block(0,18,0,17:3)
Block(0,19,-6,17:3)
Block(0,19,-5,17:3)
Block(0,19,-4,17:3)
Block(0,19,-3,17:3)
Block(0,19,-2,17:3)
Block(0,19,-1,17:3)
Block(0,20,-6,17:3)
Block(0,20,-5,17:3)
Block(0,20,-4,17:3)
Block(0,20,-3,17:3)
Block(0,20,-2,17:3)
Block(0,20,-1,17:3)
Block(0,20,0,18:3)
Block(0,21,-7,18:3)
Block(0,21,-6,17:3)
Block(0,21,-5,17:3)
Block(0,21,-4,17:3)
Block(0,21,-3,17:3)
Block(0,21,-2,17:3)
Block(0,21,-1,18:3)
Block(0,22,-7,18:3)
Block(0,22,-5,17:3)
Block(0,22,-4,17:3)
Block(0,22,-3,17:3)
Block(0,22,-2,17:3)
Block(0,23,-5,17:3)
Block(0,23,-4,17:3)
Block(0,23,-3,17:3)
Block(0,23,-2,17:3)
Block(0,23,-1,17:3)
Block(0,24,-5,18:3)
Block(0,24,-4,17:3)
Block(0,24,-3,17:3)
Block(0,24,-2,17:3)
Block(0,24,-1,17:3)
Block(0,25,-3,17:3)
Block(0,25,-2,17:3)
Block(0,25,-1,17:3)
Block(0,26,-3,18:3)
Block(0,26,-2,17:3)
Block(0,26,-1,17:3)
Block(0,27,-3,18:3)
Block(0,27,-2,17:3)
Block(0,27,2,18:3)
Block(0,27,5,17:3)
Block(0,28,-2,18:3)
Block(0,28,2,18:3)
Block(0,28,4,17:3)
Block(0,28,5,17:3)
Block(0,28,6,17:3)
Block(0,29,-2,18:3)
Block(0,29,5,17:3)
Block(0,29,6,17:3)
Block(0,29,7,17:3)
Block(0,29,8,18:3)
Block(0,30,-1,18:3)
Block(0,30,5,17:3)
Block(0,30,6,17:3)
Block(0,30,7,17:3)
Block(0,30,8,17:3)
Block(0,31,0,18:3)
Block(0,31,6,17:3)
Block(0,31,7,17:3)
Block(0,31,8,17:3)
Block(0,32,0,18:3)
Block(0,32,1,18:3)
Block(0,32,6,17:3)
Block(0,32,7,17:3)
Block(0,32,8,17:3)
Block(0,33,1,18:3)
Block(0,33,7,17:3)
Block(0,33,8,17:3)
Block(0,33,14,18:3)
Block(0,33,15,18:3)
Block(0,33,16,18:3)
Block(0,34,7,17:3)
Block(0,34,8,17:3)
Block(0,34,9,17:3)
Block(0,34,13,18:3)
Block(0,34,14,18:3)
Block(0,34,15,18:3)
Block(0,34,16,18:3)
Block(0,35,-8,18:3)
Block(0,35,2,18:3)
Block(0,35,5,18:3)
Block(0,35,6,18:3)
Block(0,35,7,18:3)
Block(0,35,8,17:3)
Block(0,35,11,18:3)
Block(0,35,12,17:3)
Block(0,35,13,18:3)
Block(0,35,14,18:3)
Block(0,35,15,18:3)
Block(0,36,-9,18:3)
Block(0,36,-8,18:3)
Block(0,36,-7,18:3)
Block(0,36,-6,18:3)
Block(0,36,-5,18:3)
Block(0,36,-3,17:3)
Block(0,36,0,17:3)
Block(0,36,1,17:3)
Block(0,36,2,17:3)
Block(0,36,3,18:3)
Block(0,36,4,18:3)
Block(0,36,5,18:3)
Block(0,36,6,18:3)
Block(0,36,8,18:3)
Block(0,36,11,18:3)
Block(0,36,13,18:3)
Block(0,36,14,18:3)
Block(0,36,15,18:3)
Block(0,37,-8,18:3)
Block(0,37,-7,18:3)
Block(0,37,-5,18:3)
Block(0,37,-4,18:3)
Block(0,37,-3,18:3)
Block(0,37,-2,18:3)
Block(0,37,-1,18:3)
Block(0,37,0,18:3)
Block(0,37,1,18:3)
Block(0,37,3,18:3)
Block(0,37,4,18:3)
Block(0,37,5,18:3)
Block(0,37,6,18:3)
Block(0,37,7,18:3)
Block(0,37,8,18:3)
Block(0,37,9,18:3)
Block(0,37,10,18:3)
Block(0,37,11,18:3)
Block(0,37,12,18:3)
Block(0,37,13,18:3)
Block(0,38,-8,18:3)
Block(0,38,-7,18:3)
Block(0,38,-6,18:3)
Block(0,38,-5,18:3)
Block(0,38,-4,18:3)
Block(0,38,-3,18:3)
Block(0,38,-2,18:3)
Block(0,38,-1,18:3)
Block(0,38,0,18:3)
Block(0,38,1,18:3)
Block(0,38,2,18:3)
Block(0,38,3,18:3)
Block(0,38,4,18:3)
Block(0,38,5,18:3)
Block(0,38,6,18:3)
Block(0,38,7,18:3)
Block(0,38,8,18:3)
Block(0,38,9,18:3)
Block(0,38,10,18:3)
Block(0,39,-6,18:3)
Block(0,39,-5,18:3)
Block(0,39,-4,18:3)
Block(0,39,-3,18:3)
Block(0,39,-2,18:3)
Block(0,39,-1,18:3)
Block(0,39,0,18:3)
Block(0,39,1,18:3)
Block(0,39,2,18:3)
Block(0,39,3,18:3)
Block(0,39,4,18:3)
Block(0,39,5,18:3)
Block(0,39,6,18:3)
Block(0,39,7,18:3)
Block(0,39,8,18:3)
Block(0,40,-6,18:3)
Block(0,40,-5,18:3)
Block(0,40,-4,18:3)
Block(0,40,-3,18:3)
Block(0,40,-2,18:3)
Block(0,40,-1,18:3)
Block(0,40,0,18:3)
Block(0,40,1,18:3)
Block(0,40,2,18:3)
Block(0,40,3,18:3)
Block(0,40,4,18:3)
Block(0,40,5,18:3)
Block(0,40,6,18:3)
Block(0,40,7,18:3)
Block(0,40,8,18:3)
Block(0,41,-2,18:3)
Block(0,41,-1,18:3)
Block(0,41,0,18:3)
Block(0,41,1,18:3)
Block(0,41,2,18:3)
Block(0,41,3,18:3)
Block(0,41,4,18:3)
Block(0,41,5,18:3)
Block(1,0,-3,17:3)
Block(1,0,-2,17:3)
Block(1,0,-1,17:3)
Block(1,0,0,17:3)
Block(1,0,1,17:3)
Block(1,0,2,17:3)
Block(1,0,3,17:3)
Block(1,1,-2,17:3)
Block(1,1,-1,17:3)
Block(1,1,0,17:3)
Block(1,1,1,17:3)
Block(1,1,2,17:3)
Block(1,1,3,17:3)
Block(1,2,-1,17:3)
Block(1,2,0,17:3)
Block(1,2,1,17:3)
Block(1,2,2,17:3)
Block(1,3,-1,17:3)
Block(1,3,0,17:3)
Block(1,3,1,17:3)
Block(1,3,2,17:3)
Block(1,4,-2,17:3)
Block(1,4,-1,17:3)
Block(1,4,0,17:3)
Block(1,4,1,17:3)
Block(1,5,-2,17:3)
Block(1,5,-1,17:3)
Block(1,5,0,17:3)
Block(1,5,1,17:3)
Block(1,6,-3,17:3)
Block(1,6,-2,17:3)
Block(1,6,-1,17:3)
Block(1,6,0,17:3)
Block(1,6,1,17:3)
Block(1,7,-3,17:3)
Block(1,7,-2,17:3)
Block(1,7,-1,17:3)
Block(1,7,0,17:3)
Block(1,7,1,17:3)
Block(1,7,2,18:3)
Block(1,8,-3,17:3)
Block(1,8,-2,17:3)
Block(1,8,-1,17:3)
Block(1,8,0,17:3)
Block(1,8,1,17:3)
Block(1,8,2,18:3)
Block(1,9,-3,17:3)
Block(1,9,-2,17:3)
Block(1,9,-1,17:3)
Block(1,9,0,17:3)
Block(1,9,1,18:3)
Block(1,10,-3,17:3)
Block(1,10,-2,17:3)
Block(1,10,-1,17:3)
Block(1,10,0,17:3)
Block(1,11,-4,17:3)
Block(1,11,-3,17:3)
Block(1,11,-2,17:3)
Block(1,11,-1,17:3)
Block(1,11,0,17:3)
Block(1,12,-4,17:3)
Block(1,12,-3,17:3)
Block(1,12,-2,17:3)
Block(1,12,-1,17:3)
Block(1,12,0,17:3)
Block(1,13,-4,17:3)
Block(1,13,-3,17:3)
Block(1,13,-2,17:3)
Block(1,13,-1,17:3)
Block(1,13,0,17:3)
Block(1,14,-4,17:3)
Block(1,14,-3,17:3)
Block(1,14,-2,17:3)
Block(1,14,-1,17:3)
Block(1,14,0,17:3)
Block(1,15,-4,17:3)
Block(1,15,-3,17:3)
Block(1,15,-2,17:3)
Block(1,15,-1,17:3)
Block(1,15,0,17:3)
Block(1,16,-5,17:3)
Block(1,16,-4,17:3)
Block(1,16,-3,17:3)
Block(1,16,-2,17:3)
Block(1,16,-1,17:3)
Block(1,17,-5,17:3)
Block(1,17,-4,17:3)
Block(1,17,-3,17:3)
Block(1,17,-2,17:3)
Block(1,17,-1,17:3)
Block(1,18,-5,17:3)
Block(1,18,-4,17:3)
Block(1,18,-3,17:3)
Block(1,18,-2,17:3)
Block(1,18,-1,17:3)
Block(1,19,-6,17:3)
Block(1,19,-5,17:3)
Block(1,19,-4,17:3)
Block(1,19,-3,17:3)
Block(1,19,-2,17:3)
Block(1,19,-1,17:3)
Block(1,20,-7,18:3)
Block(1,20,-6,17:3)
Block(1,20,-5,17:3)
Block(1,20,-4,17:3)
Block(1,20,-3,17:3)
Block(1,20,-2,17:3)
Block(1,20,-1,17:3)
Block(1,21,-5,17:3)
Block(1,21,-4,17:3)
Block(1,21,-3,17:3)
Block(1,21,-2,17:3)
Block(1,21,-1,17:3)
Block(1,22,-5,17:3)
Block(1,22,-4,17:3)
Block(1,22,-3,17:3)
Block(1,22,-2,17:3)
Block(1,22,-1,17:3)
Block(1,23,-5,17:3)
Block(1,23,-4,17:3)
Block(1,23,-3,17:3)
Block(1,23,-2,17:3)
Block(1,23,-1,17:3)
Block(1,23,0,17:3)
Block(1,24,-5,17:3)
Block(1,24,-4,17:3)
Block(1,24,-3,17:3)
Block(1,24,-2,17:3)
Block(1,24,-1,17:3)
Block(1,24,0,17:3)
Block(1,25,-5,18:3)
Block(1,25,-4,17:3)
Block(1,25,-3,17:3)
Block(1,25,-2,17:3)
Block(1,25,-1,17:3)
Block(1,25,0,17:3)
Block(1,25,1,17:3)
Block(1,26,-4,17:3)
Block(1,26,-3,17:3)
Block(1,26,-2,17:3)
Block(1,26,-1,17:3)
Block(1,26,0,17:3)
Block(1,26,1,17:3)
Block(1,26,2,18:3)
Block(1,27,-3,17:3)
Block(1,27,-2,17:3)
Block(1,27,-1,17:3)
Block(1,27,0,17:3)
Block(1,27,1,17:3)
Block(1,27,2,17:3)
Block(1,27,3,17:3)
Block(1,27,4,17:3)
Block(1,27,5,17:3)
Block(1,27,6,17:3)
Block(1,28,-3,17:3)
Block(1,28,-2,17:3)
Block(1,28,-1,17:3)
Block(1,28,0,17:3)
Block(1,28,1,17:3)
Block(1,28,2,17:3)
Block(1,28,3,17:3)
Block(1,28,4,17:3)
Block(1,28,5,17:3)
Block(1,28,6,17:3)
Block(1,28,7,17:3)
Block(1,28,8,18:3)
Block(1,28,15,18:3)
Block(1,29,-3,17:3)
Block(1,29,-2,17:3)
Block(1,29,-1,17:3)
Block(1,29,0,17:3)
Block(1,29,1,17:3)
Block(1,29,2,18:3)
Block(1,29,4,17:3)
Block(1,29,5,17:3)
Block(1,29,6,17:3)
Block(1,29,7,17:3)
Block(1,29,8,17:3)
Block(1,29,15,18:3)
Block(1,30,-2,17:3)
Block(1,30,-1,17:3)
Block(1,30,0,17:3)
Block(1,30,1,18:3)
Block(1,30,5,17:3)
Block(1,30,6,17:3)
Block(1,30,7,17:3)
Block(1,30,8,17:3)
Block(1,30,15,18:3)
Block(1,31,-2,17:3)
Block(1,31,-1,17:3)
Block(1,31,0,17:3)
Block(1,31,1,18:3)
Block(1,31,5,17:3)
Block(1,31,6,17:3)
Block(1,31,7,17:3)
Block(1,31,8,17:3)
Block(1,31,9,17:3)
Block(1,31,15,18:3)
Block(1,32,-9,18:3)
Block(1,32,-1,17:3)
Block(1,32,0,17:3)
Block(1,32,1,17:3)
Block(1,32,6,17:3)
Block(1,32,7,17:3)
Block(1,32,8,17:3)
Block(1,32,9,17:3)
Block(1,32,15,18:3)
Block(1,33,-9,18:3)
Block(1,33,-1,17:3)
Block(1,33,0,17:3)
Block(1,33,1,17:3)
Block(1,33,6,17:3)
Block(1,33,7,17:3)
Block(1,33,8,17:3)
Block(1,33,9,17:3)
Block(1,33,13,18:3)
Block(1,33,14,18:3)
Block(1,33,15,18:3)
Block(1,34,-9,18:3)
Block(1,34,0,17:3)
Block(1,34,1,17:3)
Block(1,34,2,18:3)
Block(1,34,7,17:3)
Block(1,34,8,17:3)
Block(1,34,9,17:3)
Block(1,34,12,18:3)
Block(1,34,13,18:3)
Block(1,34,14,18:3)
Block(1,34,15,18:3)
Block(1,34,16,18:3)
Block(1,35,-9,18:3)
Block(1,35,-8,18:3)
Block(1,35,0,17:3)
Block(1,35,1,17:3)
Block(1,35,2,17:3)
Block(1,35,3,18:3)
Block(1,35,6,18:3)
Block(1,35,7,18:3)
Block(1,35,8,18:3)
Block(1,35,9,17:3)
Block(1,35,10,17:3)
Block(1,35,11,17:3)
Block(1,35,12,17:3)
Block(1,35,13,18:3)
Block(1,35,14,18:3)
Block(1,35,15,18:3)
Block(1,35,16,18:3)
Block(1,36,-9,18:3)
Block(1,36,-8,18:3)
Block(1,36,-7,17:3)
Block(1,36,-6,17:3)
Block(1,36,-5,18:3)
Block(1,36,-3,17:3)
Block(1,36,-2,17:3)
Block(1,36,-1,17:3)
Block(1,36,0,18:3)
Block(1,36,1,17:3)
Block(1,36,2,18:3)
Block(1,36,3,17:3)
Block(1,36,4,18:3)
Block(1,36,5,18:3)
Block(1,36,6,18:3)
Block(1,36,7,18:3)
Block(1,36,8,18:3)
Block(1,36,9,18:3)
Block(1,36,10,18:3)
Block(1,36,11,18:3)
Block(1,36,12,18:3)
Block(1,36,13,18:3)
Block(1,36,14,18:3)
Block(1,37,-9,18:3)
Block(1,37,-8,18:3)
Block(1,37,-7,18:3)
Block(1,37,-6,18:3)
Block(1,37,-5,18:3)
Block(1,37,-4,18:3)
Block(1,37,-3,18:3)
Block(1,37,-2,18:3)
Block(1,37,-1,18:3)
Block(1,37,0,18:3)
Block(1,37,1,18:3)
Block(1,37,2,18:3)
Block(1,37,3,18:3)
Block(1,37,4,18:3)
Block(1,37,5,18:3)
Block(1,37,6,18:3)
Block(1,37,7,18:3)
Block(1,37,8,18:3)
Block(1,37,9,18:3)
Block(1,37,10,18:3)
Block(1,37,11,18:3)
Block(1,37,12,18:3)
Block(1,37,13,18:3)
Block(1,37,14,18:3)
Block(1,38,-8,18:3)
Block(1,38,-7,18:3)
Block(1,38,-6,18:3)
Block(1,38,-5,18:3)
Block(1,38,-4,18:3)
Block(1,38,-3,18:3)
Block(1,38,-2,18:3)
Block(1,38,-1,18:3)
Block(1,38,0,18:3)
Block(1,38,1,18:3)
Block(1,38,2,18:3)
Block(1,38,3,18:3)
Block(1,38,4,18:3)
Block(1,38,5,18:3)
Block(1,38,6,18:3)
Block(1,38,7,18:3)
Block(1,38,8,18:3)
Block(1,38,9,18:3)
Block(1,38,10,18:3)
Block(1,38,12,18:3)
Block(1,39,-7,18:3)
Block(1,39,-6,18:3)
Block(1,39,-5,18:3)
Block(1,39,-4,18:3)
Block(1,39,-3,18:3)
Block(1,39,-2,18:3)
Block(1,39,-1,18:3)
Block(1,39,0,18:3)
Block(1,39,1,18:3)
Block(1,39,2,18:3)
Block(1,39,3,18:3)
Block(1,39,4,18:3)
Block(1,39,5,18:3)
Block(1,39,6,18:3)
Block(1,39,7,18:3)
Block(1,39,8,18:3)
Block(1,39,9,18:3)
Block(1,40,-5,18:3)
Block(1,40,-4,18:3)
Block(1,40,-3,18:3)
Block(1,40,-2,18:3)
Block(1,40,-1,18:3)
Block(1,40,0,18:3)
Block(1,40,1,18:3)
Block(1,40,2,18:3)
Block(1,40,3,18:3)
Block(1,40,4,18:3)
Block(1,40,5,18:3)
Block(1,40,6,18:3)
Block(1,40,7,18:3)
Block(1,40,8,18:3)
Block(1,41,-2,18:3)
Block(1,41,-1,18:3)
Block(1,41,1,18:3)
Block(1,41,2,18:3)
Block(1,41,3,18:3)
Block(1,41,4,18:3)
Block(1,41,5,18:3)
Block(2,0,-2,17:3)
Block(2,0,-1,17:3)
Block(2,0,0,17:3)
Block(2,0,1,17:3)
Block(2,0,2,17:3)
Block(2,1,-1,17:3)
Block(2,1,0,17:3)
Block(2,1,1,17:3)
Block(2,2,-1,17:3)
Block(2,2,0,17:3)
Block(2,2,1,17:3)
Block(2,3,-1,17:3)
Block(2,3,0,17:3)
Block(2,4,-1,17:3)
Block(2,4,0,17:3)
Block(2,5,-2,17:3)
Block(2,5,-1,17:3)
Block(2,5,0,17:3)
Block(2,5,1,17:3)
Block(2,6,-2,17:3)
Block(2,6,-1,17:3)
Block(2,6,0,17:3)
Block(2,6,1,17:3)
Block(2,6,2,18:3)
Block(2,7,-2,17:3)
Block(2,7,-1,17:3)
Block(2,7,0,17:3)
Block(2,7,1,17:3)
Block(2,8,-2,17:3)
Block(2,8,-1,17:3)
Block(2,8,0,17:3)
Block(2,9,-2,17:3)
Block(2,9,-1,17:3)
Block(2,9,0,18:3)
Block(2,10,-2,17:3)
Block(2,10,-1,17:3)
Block(2,10,0,18:3)
Block(2,11,-2,17:3)
Block(2,11,-1,17:3)
Block(2,12,-2,17:3)
Block(2,12,-1,17:3)
Block(2,13,-3,17:3)
Block(2,13,-2,17:3)
Block(2,13,-1,17:3)
Block(2,14,-4,18:3)
Block(2,14,-3,17:3)
Block(2,14,-2,17:3)
Block(2,14,-1,17:3)
Block(2,15,-4,18:3)
Block(2,15,-3,17:3)
Block(2,15,-2,17:3)
Block(2,15,-1,17:3)
Block(2,16,-5,18:3)
Block(2,16,-4,17:3)
Block(2,16,-3,17:3)
Block(2,16,-2,17:3)
Block(2,16,-1,17:3)
Block(2,17,-5,18:3)
Block(2,17,-4,17:3)
Block(2,17,-3,17:3)
Block(2,17,-2,17:3)
Block(2,18,-6,18:3)
Block(2,18,-5,17:3)
Block(2,18,-4,17:3)
Block(2,18,-3,17:3)
Block(2,18,-2,17:3)
Block(2,19,-6,18:3)
Block(2,19,-5,17:3)
Block(2,19,-4,17:3)
Block(2,19,-3,17:3)
Block(2,19,-2,17:3)
Block(2,19,-1,17:3)
Block(2,20,-5,17:3)
Block(2,20,-4,17:3)
Block(2,20,-3,17:3)
Block(2,20,-2,17:3)
Block(2,20,-1,17:3)
Block(2,21,-5,17:3)
Block(2,21,-4,17:3)
Block(2,21,-3,17:3)
Block(2,21,-2,17:3)
Block(2,21,-1,17:3)
Block(2,22,-5,17:3)
Block(2,22,-4,17:3)
Block(2,22,-3,17:3)
Block(2,22,-2,17:3)
Block(2,22,-1,17:3)
Block(2,22,0,17:3)
Block(2,23,-5,17:3)
Block(2,23,-4,17:3)
Block(2,23,-3,17:3)
Block(2,23,-2,17:3)
Block(2,23,-1,17:3)
Block(2,23,0,17:3)
Block(2,24,-5,17:3)
Block(2,24,-4,17:3)
Block(2,24,-3,17:3)
Block(2,24,-2,17:3)
Block(2,24,-1,17:3)
Block(2,24,0,17:3)
Block(2,24,1,17:3)
Block(2,25,-5,17:3)
Block(2,25,-4,17:3)
Block(2,25,-3,17:3)
Block(2,25,-2,17:3)
Block(2,25,-1,17:3)
Block(2,25,0,17:3)
Block(2,25,1,17:3)
Block(2,25,2,17:3)
Block(2,25,3,18:3)
Block(2,26,-5,18:3)
Block(2,26,-4,17:3)
Block(2,26,-3,17:3)
Block(2,26,-2,17:3)
Block(2,26,-1,17:3)
Block(2,26,0,17:3)
Block(2,26,1,17:3)
Block(2,26,2,17:3)
Block(2,26,3,17:3)
Block(2,26,4,17:3)
Block(2,27,-4,17:3)
Block(2,27,-3,17:3)
Block(2,27,-2,17:3)
Block(2,27,-1,17:3)
Block(2,27,0,17:3)
Block(2,27,1,17:3)
Block(2,27,2,17:3)
Block(2,27,3,17:3)
Block(2,27,4,17:3)
Block(2,27,5,17:3)
Block(2,28,-4,17:3)
Block(2,28,-3,17:3)
Block(2,28,-2,17:3)
Block(2,28,-1,17:3)
Block(2,28,0,17:3)
Block(2,28,1,17:3)
Block(2,28,2,17:3)
Block(2,28,3,17:3)
Block(2,28,4,17:3)
Block(2,28,5,17:3)
Block(2,28,6,17:3)
Block(2,28,7,18:3)
Block(2,29,-3,17:3)
Block(2,29,-2,17:3)
Block(2,29,-1,17:3)
Block(2,29,0,17:3)
Block(2,29,1,17:3)
Block(2,29,2,17:3)
Block(2,29,3,17:3)
Block(2,29,4,17:3)
Block(2,29,5,17:3)
Block(2,29,6,17:3)
Block(2,29,7,17:3)
Block(2,30,-3,17:3)
Block(2,30,-2,17:3)
Block(2,30,-1,17:3)
Block(2,30,0,17:3)
Block(2,30,1,17:3)
Block(2,30,2,17:3)
Block(2,30,6,17:3)
Block(2,30,7,17:3)
Block(2,30,8,17:3)
Block(2,31,-3,17:3)
Block(2,31,-2,17:3)
Block(2,31,-1,17:3)
Block(2,31,0,17:3)
Block(2,31,1,17:3)
Block(2,31,2,17:3)
Block(2,31,6,17:3)
Block(2,31,7,17:3)
Block(2,31,8,17:3)
Block(2,32,-3,17:3)
Block(2,32,-2,17:3)
Block(2,32,-1,17:3)
Block(2,32,0,17:3)
Block(2,32,1,17:3)
Block(2,32,2,17:3)
Block(2,32,7,17:3)
Block(2,32,8,17:3)
Block(2,33,-2,17:3)
Block(2,33,-1,17:3)
Block(2,33,0,17:3)
Block(2,33,1,17:3)
Block(2,33,2,17:3)
Block(2,33,7,17:3)
Block(2,33,8,17:3)
Block(2,33,9,17:3)
Block(2,33,14,18:3)
Block(2,33,15,18:3)
Block(2,33,16,18:3)
Block(2,34,-2,17:3)
Block(2,34,-1,17:3)
Block(2,34,0,17:3)
Block(2,34,1,17:3)
Block(2,34,2,17:3)
Block(2,34,7,17:3)
Block(2,34,8,17:3)
Block(2,34,9,17:3)
Block(2,34,14,18:3)
Block(2,34,15,18:3)
Block(2,35,-8,18:3)
Block(2,35,-2,17:3)
Block(2,35,-1,17:3)
Block(2,35,0,17:3)
Block(2,35,1,17:3)
Block(2,35,2,17:3)
Block(2,35,3,17:3)
Block(2,35,6,18:3)
Block(2,35,7,18:3)
Block(2,35,8,18:3)
Block(2,35,9,18:3)
Block(2,35,10,18:3)
Block(2,35,11,18:3)
Block(2,35,12,18:3)
Block(2,35,13,18:3)
Block(2,35,14,18:3)
Block(2,35,16,18:3)
Block(2,36,-9,18:3)
Block(2,36,-7,18:3)
Block(2,36,-6,17:3)
Block(2,36,-5,17:3)
Block(2,36,-4,17:3)
Block(2,36,-3,17:3)
Block(2,36,-2,18:3)
Block(2,36,-1,18:3)
Block(2,36,0,18:3)
Block(2,36,1,18:3)
Block(2,36,2,18:3)
Block(2,36,3,18:3)
Block(2,36,4,17:3)
Block(2,36,5,17:3)
Block(2,36,6,18:3)
Block(2,36,7,18:3)
Block(2,36,8,18:3)
Block(2,36,9,18:3)
Block(2,36,10,18:3)
Block(2,36,11,18:3)
Block(2,36,12,18:3)
Block(2,36,13,18:3)
Block(2,36,14,18:3)
Block(2,36,15,18:3)
Block(2,37,-9,18:3)
Block(2,37,-8,18:3)
Block(2,37,-7,18:3)
Block(2,37,-6,18:3)
Block(2,37,-4,18:3)
Block(2,37,-3,18:3)
Block(2,37,-2,18:3)
Block(2,37,-1,18:3)
Block(2,37,0,18:3)
Block(2,37,1,18:3)
Block(2,37,2,18:3)
Block(2,37,3,18:3)
Block(2,37,4,18:3)
Block(2,37,5,18:3)
Block(2,37,6,18:3)
Block(2,37,7,18:3)
Block(2,37,8,18:3)
Block(2,37,9,18:3)
Block(2,37,10,18:3)
Block(2,37,11,18:3)
Block(2,37,12,18:3)
Block(2,37,14,18:3)
Block(2,38,-9,18:3)
Block(2,38,-8,18:3)
Block(2,38,-7,18:3)
Block(2,38,-6,18:3)
Block(2,38,-5,18:3)
Block(2,38,-4,18:3)
Block(2,38,-3,18:3)
Block(2,38,-2,18:3)
Block(2,38,-1,18:3)
Block(2,38,0,18:3)
Block(2,38,1,18:3)
Block(2,38,2,18:3)
Block(2,38,3,18:3)
Block(2,38,4,18:3)
Block(2,38,5,18:3)
Block(2,38,6,18:3)
Block(2,38,7,18:3)
Block(2,38,8,18:3)
Block(2,38,9,18:3)
Block(2,38,10,18:3)
Block(2,38,11,18:3)
Block(2,39,-7,18:3)
Block(2,39,-5,18:3)
Block(2,39,-4,18:3)
Block(2,39,-3,18:3)
Block(2,39,-2,18:3)
Block(2,39,-1,18:3)
Block(2,39,0,18:3)
Block(2,39,1,18:3)
Block(2,39,2,18:3)
Block(2,39,3,18:3)
Block(2,39,4,18:3)
Block(2,39,5,18:3)
Block(2,39,6,18:3)
Block(2,39,7,18:3)
Block(2,39,8,18:3)
Block(2,39,9,18:3)
Block(2,40,-3,18:3)
Block(2,40,-2,18:3)
Block(2,40,-1,18:3)
Block(2,40,0,18:3)
Block(2,40,1,18:3)
Block(2,40,2,18:3)
Block(2,40,3,18:3)
Block(2,40,4,18:3)
Block(2,40,5,18:3)
Block(2,40,6,18:3)
Block(2,40,7,18:3)
Block(2,40,8,18:3)
Block(2,41,-3,18:3)
Block(2,41,-2,18:3)
Block(2,41,-1,18:3)
Block(2,41,0,18:3)
Block(2,41,1,18:3)
Block(2,41,2,18:3)
Block(2,41,3,18:3)
Block(2,41,4,18:3)
Block(2,41,5,18:3)
Block(2,41,6,18:3)
Block(3,0,-1,17:3)
Block(3,0,0,17:3)
Block(3,0,1,17:3)
Block(3,1,-1,17:3)
Block(3,1,0,17:3)
Block(3,4,-1,17:3)
Block(3,4,0,18:3)
Block(3,5,-1,17:3)
Block(3,5,0,17:3)
Block(3,5,1,18:3)
Block(3,6,-2,17:3)
Block(3,6,-1,17:3)
Block(3,6,0,17:3)
Block(3,6,1,17:3)
Block(3,7,-2,17:3)
Block(3,7,-1,17:3)
Block(3,7,0,17:3)
Block(3,7,1,17:3)
Block(3,8,-2,17:3)
Block(3,8,-1,17:3)
Block(3,8,0,17:3)
Block(3,9,-1,17:3)
Block(3,11,-1,18:3)
Block(3,12,-2,18:3)
Block(3,13,-3,18:3)
Block(3,16,-4,18:3)
Block(3,17,-3,18:3)
Block(3,18,-3,17:3)
Block(3,18,-2,18:3)
Block(3,19,-4,17:3)
Block(3,19,-3,17:3)
Block(3,19,-2,18:3)
Block(3,20,-4,17:3)
Block(3,20,-3,17:3)
Block(3,20,-2,17:3)
Block(3,20,-1,18:3)
Block(3,21,-4,17:3)
Block(3,21,-3,17:3)
Block(3,21,-2,17:3)
Block(3,21,-1,17:3)
Block(3,21,0,18:3)
Block(3,22,-4,17:3)
Block(3,22,-3,17:3)
Block(3,22,-2,17:3)
Block(3,22,-1,17:3)
Block(3,22,0,18:3)
Block(3,23,-5,17:3)
Block(3,23,-4,17:3)
Block(3,23,-3,17:3)
Block(3,23,-2,17:3)
Block(3,23,-1,17:3)
Block(3,23,1,18:3)
Block(3,24,-5,17:3)
Block(3,24,-4,17:3)
Block(3,24,-3,17:3)
Block(3,24,-2,17:3)
Block(3,24,-1,17:3)
Block(3,24,0,17:3)
Block(3,24,1,18:3)
Block(3,25,-5,17:3)
Block(3,25,-4,17:3)
Block(3,25,-3,17:3)
Block(3,25,-2,17:3)
Block(3,25,-1,17:3)
Block(3,25,0,17:3)
Block(3,25,2,18:3)
Block(3,26,-5,17:3)
Block(3,26,-4,17:3)
Block(3,26,-3,17:3)
Block(3,26,-2,17:3)
Block(3,26,-1,17:3)
Block(3,26,0,17:3)
Block(3,26,1,17:3)
Block(3,26,2,17:3)
Block(3,27,-5,18:3)
Block(3,27,-4,17:3)
Block(3,27,-3,17:3)
Block(3,27,-2,17:3)
Block(3,27,-1,17:3)
Block(3,27,0,17:3)
Block(3,27,1,17:3)
Block(3,27,2,17:3)
Block(3,27,3,17:3)
Block(3,27,4,17:3)
Block(3,28,-4,17:3)
Block(3,28,-3,17:3)
Block(3,28,-2,17:3)
Block(3,28,-1,17:3)
Block(3,28,0,17:3)
Block(3,28,1,17:3)
Block(3,28,2,17:3)
Block(3,28,3,17:3)
Block(3,28,4,17:3)
Block(3,28,5,17:3)
Block(3,29,-4,17:3)
Block(3,29,-3,17:3)
Block(3,29,-2,17:3)
Block(3,29,-1,17:3)
Block(3,29,0,17:3)
Block(3,29,1,17:3)
Block(3,29,2,17:3)
Block(3,29,3,17:3)
Block(3,29,4,17:3)
Block(3,29,5,18:3)
Block(3,29,7,18:3)
Block(3,30,-9,18:3)
Block(3,30,-3,17:3)
Block(3,30,-2,17:3)
Block(3,30,-1,17:3)
Block(3,30,0,17:3)
Block(3,30,1,17:3)
Block(3,30,2,17:3)
Block(3,30,3,17:3)
Block(3,30,6,18:3)
Block(3,30,16,18:3)
Block(3,31,-9,18:3)
Block(3,31,-3,17:3)
Block(3,31,-2,17:3)
Block(3,31,-1,17:3)
Block(3,31,0,17:3)
Block(3,31,1,17:3)
Block(3,31,2,17:3)
Block(3,31,7,18:3)
Block(3,31,16,18:3)
Block(3,32,-9,18:3)
Block(3,32,-3,17:3)
Block(3,32,-2,17:3)
Block(3,32,-1,17:3)
Block(3,32,0,17:3)
Block(3,32,1,17:3)
Block(3,32,2,17:3)
Block(3,32,7,18:3)
Block(3,32,8,18:3)
Block(3,32,16,18:3)
Block(3,33,-9,18:3)
Block(3,33,-3,17:3)
Block(3,33,-2,17:3)
Block(3,33,-1,17:3)
Block(3,33,0,17:3)
Block(3,33,1,17:3)
Block(3,33,2,17:3)
Block(3,33,8,18:3)
Block(3,33,13,18:3)
Block(3,33,14,18:3)
Block(3,33,15,18:3)
Block(3,33,16,18:3)
Block(3,34,-9,18:3)
Block(3,34,-3,17:3)
Block(3,34,-2,17:3)
Block(3,34,-1,17:3)
Block(3,34,0,17:3)
Block(3,34,1,17:3)
Block(3,34,2,17:3)
Block(3,34,3,18:3)
Block(3,34,8,17:3)
Block(3,34,9,18:3)
Block(3,34,11,18:3)
Block(3,34,12,18:3)
Block(3,34,13,18:3)
Block(3,34,14,18:3)
Block(3,34,15,18:3)
Block(3,34,16,18:3)
Block(3,35,-9,18:3)
Block(3,35,-8,18:3)
Block(3,35,-7,18:3)
Block(3,35,-2,17:3)
Block(3,35,-1,17:3)
Block(3,35,0,17:3)
Block(3,35,1,17:3)
Block(3,35,2,17:3)
Block(3,35,3,17:3)
Block(3,35,4,18:3)
Block(3,35,6,18:3)
Block(3,35,7,18:3)
Block(3,35,8,18:3)
Block(3,35,9,18:3)
Block(3,35,10,18:3)
Block(3,35,11,18:3)
Block(3,35,12,18:3)
Block(3,35,13,18:3)
Block(3,35,14,18:3)
Block(3,35,15,18:3)
Block(3,35,16,18:3)
Block(3,36,-9,18:3)
Block(3,36,-8,18:3)
Block(3,36,-7,18:3)
Block(3,36,-6,18:3)
Block(3,36,-3,17:3)
Block(3,36,-2,18:3)
Block(3,36,-1,18:3)
Block(3,36,0,18:3)
Block(3,36,1,18:3)
Block(3,36,2,18:3)
Block(3,36,4,18:3)
Block(3,36,5,18:3)
Block(3,36,6,18:3)
Block(3,36,7,18:3)
Block(3,36,9,18:3)
Block(3,36,10,18:3)
Block(3,36,11,18:3)
Block(3,36,12,18:3)
Block(3,36,13,18:3)
Block(3,36,14,18:3)
Block(3,37,-9,18:3)
Block(3,37,-8,18:3)
Block(3,37,-7,18:3)
Block(3,37,-6,18:3)
Block(3,37,-5,18:3)
Block(3,37,-4,18:3)
Block(3,37,-3,18:3)
Block(3,37,-2,18:3)
Block(3,37,-1,18:3)
Block(3,37,0,18:3)
Block(3,37,1,18:3)
Block(3,37,2,18:3)
Block(3,37,3,18:3)
Block(3,37,4,18:3)
Block(3,37,5,18:3)
Block(3,37,6,18:3)
Block(3,37,7,18:3)
Block(3,37,8,18:3)
Block(3,37,9,18:3)
Block(3,37,10,18:3)
Block(3,37,11,18:3)
Block(3,37,12,18:3)
Block(3,37,13,18:3)
Block(3,38,-8,18:3)
Block(3,38,-7,18:3)
Block(3,38,-6,18:3)
Block(3,38,-5,18:3)
Block(3,38,-4,18:3)
Block(3,38,-3,18:3)
Block(3,38,-2,18:3)
Block(3,38,-1,18:3)
Block(3,38,0,18:3)
Block(3,38,1,18:3)
Block(3,38,2,18:3)
Block(3,38,3,18:3)
Block(3,38,4,18:3)
Block(3,38,5,18:3)
Block(3,38,6,18:3)
Block(3,38,7,18:3)
Block(3,38,8,18:3)
Block(3,38,9,18:3)
Block(3,38,10,18:3)
Block(3,38,11,18:3)
Block(3,39,-6,18:3)
Block(3,39,-5,18:3)
Block(3,39,-4,18:3)
Block(3,39,-3,18:3)
Block(3,39,-2,18:3)
Block(3,39,-1,18:3)
Block(3,39,0,18:3)
Block(3,39,1,18:3)
Block(3,39,2,18:3)
Block(3,39,3,18:3)
Block(3,39,4,18:3)
Block(3,39,5,18:3)
Block(3,39,6,18:3)
Block(3,39,7,18:3)
Block(3,39,8,18:3)
Block(3,39,9,18:3)
Block(3,39,10,18:3)
Block(3,40,-5,18:3)
Block(3,40,-3,18:3)
Block(3,40,-2,18:3)
Block(3,40,-1,18:3)
Block(3,40,0,18:3)
Block(3,40,1,18:3)
Block(3,40,2,18:3)
Block(3,40,3,18:3)
Block(3,40,4,18:3)
Block(3,40,5,18:3)
Block(3,40,6,18:3)
Block(3,40,7,18:3)
Block(3,40,8,18:3)
Block(3,41,-2,18:3)
Block(3,41,-1,18:3)
Block(3,41,0,18:3)
Block(3,41,1,18:3)
Block(3,41,2,18:3)
Block(3,41,3,18:3)
Block(3,41,4,18:3)
Block(3,41,5,18:3)
Block(3,41,7,18:3)
Block(4,4,-1,18:3)
Block(4,5,-2,18:3)
Block(4,5,-1,17:3)
Block(4,5,0,17:3)
Block(4,6,-2,17:3)
Block(4,6,-1,17:3)
Block(4,6,0,17:3)
Block(4,6,1,17:3)
Block(4,7,-2,17:3)
Block(4,7,-1,17:3)
Block(4,7,0,17:3)
Block(4,7,1,17:3)
Block(4,7,2,17:3)
Block(4,8,-1,17:3)
Block(4,8,0,17:3)
Block(4,8,1,17:3)
Block(4,21,-3,17:3)
Block(4,22,-3,17:3)
Block(4,22,-2,17:3)
Block(4,23,-4,17:3)
Block(4,23,-3,17:3)
Block(4,23,-2,17:3)
Block(4,23,-1,17:3)
Block(4,24,-4,17:3)
Block(4,24,-3,17:3)
Block(4,24,-2,17:3)
Block(4,24,-1,17:3)
Block(4,25,-4,17:3)
Block(4,25,-3,17:3)
Block(4,25,-2,17:3)
Block(4,25,-1,17:3)
Block(4,25,0,17:3)
Block(4,26,-4,17:3)
Block(4,26,-3,17:3)
Block(4,26,-2,17:3)
Block(4,26,-1,17:3)
Block(4,26,0,17:3)
Block(4,26,1,17:3)
Block(4,26,2,18:3)
Block(4,27,-4,17:3)
Block(4,27,-3,17:3)
Block(4,27,-2,17:3)
Block(4,27,-1,17:3)
Block(4,27,0,17:3)
Block(4,27,1,17:3)
Block(4,27,2,18:3)
Block(4,28,-4,18:3)
Block(4,28,-3,17:3)
Block(4,28,-2,17:3)
Block(4,28,-1,17:3)
Block(4,28,0,17:3)
Block(4,28,1,17:3)
Block(4,28,2,17:3)
Block(4,28,3,18:3)
Block(4,29,-4,18:3)
Block(4,29,-3,17:3)
Block(4,29,-2,17:3)
Block(4,29,-1,17:3)
Block(4,29,0,17:3)
Block(4,29,1,17:3)
Block(4,29,2,17:3)
Block(4,29,4,18:3)
Block(4,30,-3,17:3)
Block(4,30,-2,17:3)
Block(4,30,-1,17:3)
Block(4,30,0,17:3)
Block(4,30,1,17:3)
Block(4,30,2,17:3)
Block(4,31,-2,17:3)
Block(4,31,-1,17:3)
Block(4,31,0,17:3)
Block(4,31,1,17:3)
Block(4,31,2,17:3)
Block(4,32,-2,17:3)
Block(4,32,-1,17:3)
Block(4,32,0,17:3)
Block(4,32,1,17:3)
Block(4,32,2,17:3)
Block(4,33,-2,17:3)
Block(4,33,-1,17:3)
Block(4,33,0,17:3)
Block(4,33,1,17:3)
Block(4,33,2,17:3)
Block(4,33,11,18:3)
Block(4,33,12,18:3)
Block(4,33,13,18:3)
Block(4,33,14,18:3)
Block(4,34,-2,17:3)
Block(4,34,-1,17:3)
Block(4,34,0,17:3)
Block(4,34,1,17:3)
Block(4,34,2,17:3)
Block(4,34,3,18:3)
Block(4,34,4,18:3)
Block(4,34,10,18:3)
Block(4,34,11,18:3)
Block(4,34,12,18:3)
Block(4,34,14,18:3)
Block(4,34,15,18:3)
Block(4,34,16,18:3)
Block(4,35,-8,18:3)
Block(4,35,-2,17:3)
Block(4,35,-1,17:3)
Block(4,35,0,17:3)
Block(4,35,1,17:3)
Block(4,35,2,17:3)
Block(4,35,3,17:3)
Block(4,35,4,18:3)
Block(4,35,7,18:3)
Block(4,35,8,18:3)
Block(4,35,9,18:3)
Block(4,35,10,18:3)
Block(4,35,11,18:3)
Block(4,35,12,18:3)
Block(4,35,13,18:3)
Block(4,35,14,18:3)
Block(4,35,15,18:3)
Block(4,36,-9,18:3)
Block(4,36,-8,18:3)
Block(4,36,-7,18:3)
Block(4,36,-6,18:3)
Block(4,36,-3,17:3)
Block(4,36,-2,18:3)
Block(4,36,-1,18:3)
Block(4,36,0,18:3)
Block(4,36,1,18:3)
Block(4,36,2,18:3)
Block(4,36,3,18:3)
Block(4,36,4,18:3)
Block(4,36,6,18:3)
Block(4,36,7,18:3)
Block(4,36,8,18:3)
Block(4,36,9,18:3)
Block(4,36,10,18:3)
Block(4,36,11,18:3)
Block(4,36,12,18:3)
Block(4,36,13,18:3)
Block(4,37,-8,18:3)
Block(4,37,-7,18:3)
Block(4,37,-6,18:3)
Block(4,37,-5,18:3)
Block(4,37,-4,18:3)
Block(4,37,-3,18:3)
Block(4,37,-2,18:3)
Block(4,37,-1,18:3)
Block(4,37,0,18:3)
Block(4,37,1,18:3)
Block(4,37,2,18:3)
Block(4,37,3,18:3)
Block(4,37,4,18:3)
Block(4,37,5,18:3)
Block(4,37,6,18:3)
Block(4,37,7,18:3)
Block(4,37,8,18:3)
Block(4,37,9,18:3)
Block(4,37,10,18:3)
Block(4,37,11,18:3)
Block(4,37,12,18:3)
Block(4,38,-7,18:3)
Block(4,38,-6,18:3)
Block(4,38,-5,18:3)
Block(4,38,-4,18:3)
Block(4,38,-3,18:3)
Block(4,38,-2,18:3)
Block(4,38,-1,18:3)
Block(4,38,0,18:3)
Block(4,38,1,18:3)
Block(4,38,2,18:3)
Block(4,38,3,18:3)
Block(4,38,4,18:3)
Block(4,38,5,18:3)
Block(4,38,6,18:3)
Block(4,38,7,18:3)
Block(4,38,8,18:3)
Block(4,38,9,18:3)
Block(4,38,11,18:3)
Block(4,38,12,18:3)
Block(4,39,-7,18:3)
Block(4,39,-5,18:3)
Block(4,39,-3,18:3)
Block(4,39,-2,18:3)
Block(4,39,-1,18:3)
Block(4,39,0,18:3)
Block(4,39,1,18:3)
Block(4,39,2,18:3)
Block(4,39,4,18:3)
Block(4,39,5,18:3)
Block(4,39,6,18:3)
Block(4,39,7,18:3)
Block(4,39,8,18:3)
Block(4,40,-5,18:3)
Block(4,40,-3,18:3)
Block(4,40,-2,18:3)
Block(4,40,-1,18:3)
Block(4,40,0,18:3)
Block(4,40,1,18:3)
Block(4,40,2,18:3)
Block(4,40,3,18:3)
Block(4,40,4,18:3)
Block(4,40,5,18:3)
Block(4,40,7,18:3)
Block(4,41,-2,18:3)
Block(4,41,-1,18:3)
Block(4,41,2,18:3)
Block(4,41,3,18:3)
Block(4,41,4,18:3)
Block(4,41,5,18:3)
Block(5,5,-1,17:3)
Block(5,6,-2,18:3)
Block(5,6,-1,17:3)
Block(5,6,0,17:3)
Block(5,6,1,17:3)
Block(5,7,-2,17:3)
Block(5,7,-1,17:3)
Block(5,7,0,17:3)
Block(5,7,1,17:3)
Block(5,7,2,17:3)
Block(5,8,-1,17:3)
Block(5,8,0,17:3)
Block(5,8,1,17:3)
Block(5,8,2,17:3)
Block(5,9,0,17:3)
Block(5,13,1,18:3)
Block(5,13,2,18:3)
Block(5,23,-3,17:3)
Block(5,24,-3,17:3)
Block(5,24,-2,17:3)
Block(5,25,-3,17:3)
Block(5,25,-2,17:3)
Block(5,26,-3,17:3)
Block(5,26,-2,17:3)
Block(5,27,-3,17:3)
Block(5,27,-2,17:3)
Block(5,27,-1,17:3)
Block(5,28,-3,17:3)
Block(5,28,-2,17:3)
Block(5,28,-1,17:3)
Block(5,29,-2,17:3)
Block(5,29,-1,17:3)
Block(5,29,0,17:3)
Block(5,29,13,18:3)
Block(5,30,-3,18:3)
Block(5,30,-2,17:3)
Block(5,30,-1,17:3)
Block(5,30,0,17:3)
Block(5,30,13,18:3)
Block(5,31,-3,18:3)
Block(5,31,-2,17:3)
Block(5,31,-1,17:3)
Block(5,31,0,17:3)
Block(5,31,13,18:3)
Block(5,32,-2,18:3)
Block(5,32,-1,17:3)
Block(5,32,0,17:3)
Block(5,32,1,17:3)
Block(5,32,7,18:3)
Block(5,32,13,18:3)
Block(5,33,-8,18:3)
Block(5,33,-1,17:3)
Block(5,33,0,17:3)
Block(5,33,1,17:3)
Block(5,33,3,18:3)
Block(5,33,7,18:3)
Block(5,33,12,18:3)
Block(5,33,13,18:3)
Block(5,34,-8,18:3)
Block(5,34,-1,17:3)
Block(5,34,0,17:3)
Block(5,34,1,17:3)
Block(5,34,3,18:3)
Block(5,34,7,18:3)
Block(5,34,11,18:3)
Block(5,34,13,18:3)
Block(5,34,14,18:3)
Block(5,35,-9,18:3)
Block(5,35,-8,18:3)
Block(5,35,-7,18:3)
Block(5,35,-1,17:3)
Block(5,35,0,17:3)
Block(5,35,1,17:3)
Block(5,35,2,17:3)
Block(5,35,3,17:3)
Block(5,35,4,18:3)
Block(5,35,7,18:3)
Block(5,35,10,18:3)
Block(5,35,11,18:3)
Block(5,35,12,18:3)
Block(5,35,13,18:3)
Block(5,35,14,18:3)
Block(5,36,-9,18:3)
Block(5,36,-8,18:3)
Block(5,36,-7,18:3)
Block(5,36,-6,18:3)
Block(5,36,-5,18:3)
Block(5,36,-2,17:3)
Block(5,36,-1,17:3)
Block(5,36,0,18:3)
Block(5,36,1,18:3)
Block(5,36,2,18:3)
Block(5,36,3,18:3)
Block(5,36,4,18:3)
Block(5,36,7,18:3)
Block(5,36,8,18:3)
Block(5,36,9,18:3)
Block(5,36,10,18:3)
Block(5,36,11,18:3)
Block(5,36,12,18:3)
Block(5,36,13,18:3)
Block(5,36,14,18:3)
Block(5,37,-9,18:3)
Block(5,37,-8,18:3)
Block(5,37,-7,18:3)
Block(5,37,-6,18:3)
Block(5,37,-5,18:3)
Block(5,37,-4,18:3)
Block(5,37,-3,18:3)
Block(5,37,-2,18:3)
Block(5,37,-1,18:3)
Block(5,37,0,18:3)
Block(5,37,2,18:3)
Block(5,37,3,18:3)
Block(5,37,4,18:3)
Block(5,37,5,18:3)
Block(5,37,6,18:3)
Block(5,37,7,18:3)
Block(5,37,8,18:3)
Block(5,37,9,18:3)
Block(5,37,10,18:3)
Block(5,37,11,18:3)
Block(5,37,12,18:3)
Block(5,37,13,18:3)
Block(5,38,-8,18:3)
Block(5,38,-7,18:3)
Block(5,38,-6,18:3)
Block(5,38,-5,18:3)
Block(5,38,-4,18:3)
Block(5,38,-3,18:3)
Block(5,38,-2,18:3)
Block(5,38,-1,18:3)
Block(5,38,0,18:3)
Block(5,38,1,18:3)
Block(5,38,2,18:3)
Block(5,38,4,18:3)
Block(5,38,5,18:3)
Block(5,38,6,18:3)
Block(5,38,7,18:3)
Block(5,38,8,18:3)
Block(5,38,10,18:3)
Block(5,38,11,18:3)
Block(5,39,-7,18:3)
Block(5,39,-6,18:3)
Block(5,39,-5,18:3)
Block(5,39,-4,18:3)
Block(5,39,-3,18:3)
Block(5,39,-2,18:3)
Block(5,39,-1,18:3)
Block(5,39,0,18:3)
Block(5,39,1,18:3)
Block(5,39,2,18:3)
Block(5,39,4,18:3)
Block(5,39,5,18:3)
Block(5,39,6,18:3)
Block(5,39,7,18:3)
Block(5,39,8,18:3)
Block(5,39,10,18:3)
Block(5,40,-4,18:3)
Block(5,40,-3,18:3)
Block(5,40,-2,18:3)
Block(5,40,-1,18:3)
Block(5,40,0,18:3)
Block(5,40,1,18:3)
Block(5,40,2,18:3)
Block(5,40,3,18:3)
Block(5,40,4,18:3)
Block(5,40,5,18:3)
Block(5,40,6,18:3)
Block(5,40,7,18:3)
Block(5,41,-3,18:3)
Block(5,41,-1,18:3)
Block(5,41,0,18:3)
Block(5,41,1,18:3)
Block(5,41,4,18:3)
Block(5,41,6,18:3)
Block(6,6,0,17:3)
Block(6,7,-2,18:3)
Block(6,7,-1,17:3)
Block(6,7,0,17:3)
Block(6,7,1,17:3)
Block(6,7,2,17:3)
Block(6,8,-2,18:3)
Block(6,8,-1,17:3)
Block(6,8,0,17:3)
Block(6,8,1,17:3)
Block(6,8,2,17:3)
Block(6,9,-1,18:3)
Block(6,9,0,17:3)
Block(6,9,1,17:3)
Block(6,11,1,18:3)
Block(6,11,2,18:3)
Block(6,11,3,18:3)
Block(6,12,-1,18:3)
Block(6,12,0,18:3)
Block(6,12,2,18:3)
Block(6,12,3,18:3)
Block(6,12,4,18:3)
Block(6,13,0,18:3)
Block(6,13,1,18:3)
Block(6,13,2,18:3)
Block(6,13,3,18:3)
Block(6,33,-5,18:3)
Block(6,33,-2,18:3)
Block(6,34,-5,18:3)
Block(6,34,-1,18:3)
Block(6,34,0,17:3)
Block(6,34,10,18:3)
Block(6,34,11,18:3)
Block(6,34,12,18:3)
Block(6,35,-8,18:3)
Block(6,35,-5,18:3)
Block(6,35,0,17:3)
Block(6,35,10,18:3)
Block(6,35,11,18:3)
Block(6,35,12,18:3)
Block(6,35,13,18:3)
Block(6,35,14,18:3)
Block(6,36,-9,18:3)
Block(6,36,-8,18:3)
Block(6,36,-7,18:3)
Block(6,36,-6,18:3)
Block(6,36,-5,18:3)
Block(6,36,1,18:3)
Block(6,36,2,18:3)
Block(6,36,3,17:3)
Block(6,36,4,17:3)
Block(6,36,5,17:3)
Block(6,36,8,18:3)
Block(6,36,9,18:3)
Block(6,36,10,18:3)
Block(6,36,11,18:3)
Block(6,36,12,18:3)
Block(6,36,13,18:3)
Block(6,37,-8,18:3)
Block(6,37,-7,18:3)
Block(6,37,-6,18:3)
Block(6,37,-5,18:3)
Block(6,37,-4,18:3)
Block(6,37,-3,18:3)
Block(6,37,-2,18:3)
Block(6,37,1,18:3)
Block(6,37,2,18:3)
Block(6,37,3,18:3)
Block(6,37,4,18:3)
Block(6,37,5,18:3)
Block(6,37,6,18:3)
Block(6,37,7,18:3)
Block(6,37,8,18:3)
Block(6,37,10,18:3)
Block(6,37,11,18:3)
Block(6,37,12,18:3)
Block(6,38,-7,18:3)
Block(6,38,-6,18:3)
Block(6,38,-5,18:3)
Block(6,38,-4,18:3)
Block(6,38,-3,18:3)
Block(6,38,-2,18:3)
Block(6,38,-1,18:3)
Block(6,38,1,18:3)
Block(6,38,2,18:3)
Block(6,38,3,18:3)
Block(6,38,4,18:3)
Block(6,38,5,18:3)
Block(6,38,6,18:3)
Block(6,38,7,18:3)
Block(6,38,8,18:3)
Block(6,38,10,18:3)
Block(6,38,11,18:3)
Block(6,39,-6,18:3)
Block(6,39,-4,18:3)
Block(6,39,-3,18:3)
Block(6,39,-2,18:3)
Block(6,39,-1,18:3)
Block(6,39,0,18:3)
Block(6,39,1,18:3)
Block(6,39,2,18:3)
Block(6,39,3,18:3)
Block(6,39,4,18:3)
Block(6,39,5,18:3)
Block(6,39,6,18:3)
Block(6,39,7,18:3)
Block(6,39,8,18:3)
Block(6,39,9,18:3)
Block(6,39,10,18:3)
Block(6,40,-3,18:3)
Block(6,40,-2,18:3)
Block(6,40,-1,18:3)
Block(6,40,0,18:3)
Block(6,40,1,18:3)
Block(6,40,2,18:3)
Block(6,40,3,18:3)
Block(6,40,4,18:3)
Block(6,40,5,18:3)
Block(6,40,6,18:3)
Block(6,40,7,18:3)
Block(6,40,8,18:3)
Block(6,41,-2,18:3)
Block(6,41,1,18:3)
Block(6,41,3,18:3)
Block(6,41,4,18:3)
Block(6,41,5,18:3)
Block(7,7,0,17:3)
Block(7,7,1,17:3)
Block(7,7,4,18:3)
Block(7,8,-1,17:3)
Block(7,8,0,17:3)
Block(7,8,1,17:3)
Block(7,8,2,17:3)
Block(7,8,4,18:3)
Block(7,9,-2,18:3)
Block(7,9,-1,17:3)
Block(7,9,0,17:3)
Block(7,9,1,17:3)
Block(7,9,2,17:3)
Block(7,9,4,18:3)
Block(7,10,-2,18:3)
Block(7,10,-1,18:3)
Block(7,10,1,17:3)
Block(7,10,4,18:3)
Block(7,11,-1,18:3)
Block(7,11,0,18:3)
Block(7,11,1,18:3)
Block(7,11,2,18:3)
Block(7,11,4,18:3)
Block(7,12,-2,18:3)
Block(7,12,0,18:3)
Block(7,12,1,18:3)
Block(7,12,2,18:3)
Block(7,12,3,18:3)
Block(7,13,-1,18:3)
Block(7,13,0,18:3)
Block(7,13,1,18:3)
Block(7,13,2,18:3)
Block(7,13,3,18:3)
Block(7,13,4,18:3)
Block(7,14,0,18:3)
Block(7,14,1,18:3)
Block(7,14,2,18:3)
Block(7,31,11,18:3)
Block(7,32,11,18:3)
Block(7,33,11,18:3)
Block(7,34,11,18:3)
Block(7,34,12,18:3)
Block(7,35,-7,18:3)
Block(7,35,-6,18:3)
Block(7,35,0,17:3)
Block(7,35,10,18:3)
Block(7,35,11,18:3)
Block(7,35,12,18:3)
Block(7,35,13,18:3)
Block(7,36,-8,18:3)
Block(7,36,-7,18:3)
Block(7,36,-6,18:3)
Block(7,36,-5,18:3)
Block(7,36,-4,18:3)
Block(7,36,-2,18:3)
Block(7,36,0,17:3)
Block(7,36,1,18:3)
Block(7,36,7,17:3)
Block(7,36,8,18:3)
Block(7,36,9,18:3)
Block(7,36,10,18:3)
Block(7,36,11,18:3)
Block(7,36,12,18:3)
Block(7,37,-7,18:3)
Block(7,37,-6,18:3)
Block(7,37,-5,18:3)
Block(7,37,-4,18:3)
Block(7,37,-3,18:3)
Block(7,37,-2,18:3)
Block(7,37,-1,18:3)
Block(7,37,1,18:3)
Block(7,37,2,18:3)
Block(7,37,3,18:3)
Block(7,37,4,18:3)
Block(7,37,5,17:3)
Block(7,37,6,17:3)
Block(7,37,8,18:3)
Block(7,37,9,18:3)
Block(7,37,10,18:3)
Block(7,37,11,18:3)
Block(7,37,12,18:3)
Block(7,38,-7,18:3)
Block(7,38,-6,18:3)
Block(7,38,-5,18:3)
Block(7,38,-4,18:3)
Block(7,38,-3,18:3)
Block(7,38,-2,18:3)
Block(7,38,-1,18:3)
Block(7,38,1,18:3)
Block(7,38,2,18:3)
Block(7,38,4,18:3)
Block(7,38,5,18:3)
Block(7,38,6,18:3)
Block(7,38,7,18:3)
Block(7,38,8,18:3)
Block(7,38,9,18:3)
Block(7,38,10,18:3)
Block(7,39,-6,18:3)
Block(7,39,-5,18:3)
Block(7,39,-4,18:3)
Block(7,39,-3,18:3)
Block(7,39,-2,18:3)
Block(7,39,-1,18:3)
Block(7,39,1,18:3)
Block(7,39,2,18:3)
Block(7,39,3,18:3)
Block(7,39,4,18:3)
Block(7,39,5,18:3)
Block(7,39,6,18:3)
Block(7,39,7,18:3)
Block(7,39,8,18:3)
Block(7,39,9,18:3)
Block(7,40,-3,18:3)
Block(7,40,-2,18:3)
Block(7,40,-1,18:3)
Block(7,40,0,18:3)
Block(7,40,1,18:3)
Block(7,40,2,18:3)
Block(7,40,4,18:3)
Block(7,40,5,18:3)
Block(7,40,6,18:3)
Block(7,40,7,18:3)
Block(7,41,-1,18:3)
Block(7,41,0,18:3)
Block(7,41,1,18:3)
Block(7,41,2,18:3)
Block(8,7,0,17:3)
Block(8,7,1,17:3)
Block(8,8,-1,18:3)
Block(8,8,0,17:3)
Block(8,8,1,17:3)
Block(8,9,-1,17:3)
Block(8,9,0,17:3)
Block(8,9,1,17:3)
Block(8,9,2,17:3)
Block(8,10,0,17:3)
Block(8,10,1,17:3)
Block(8,10,2,17:3)
Block(8,11,-2,18:3)
Block(8,11,1,18:3)
Block(8,11,4,18:3)
Block(8,12,-3,18:3)
Block(8,12,-2,18:3)
Block(8,12,-1,18:3)
Block(8,12,0,18:3)
Block(8,12,1,18:3)
Block(8,12,3,18:3)
Block(8,12,4,18:3)
Block(8,12,5,18:3)
Block(8,13,-2,18:3)
Block(8,13,-1,18:3)
Block(8,13,0,18:3)
Block(8,13,1,18:3)
Block(8,13,2,18:3)
Block(8,13,3,18:3)
Block(8,13,4,18:3)
Block(8,14,-1,18:3)
Block(8,14,0,18:3)
Block(8,14,1,18:3)
Block(8,14,3,18:3)
Block(8,15,0,18:3)
Block(8,15,1,18:3)
Block(8,32,-7,18:3)
Block(8,33,-7,18:3)
Block(8,33,-1,18:3)
Block(8,34,-7,18:3)
Block(8,34,-1,18:3)
Block(8,35,-8,18:3)
Block(8,35,-7,18:3)
Block(8,35,-6,18:3)
Block(8,35,-5,18:3)
Block(8,35,-1,18:3)
Block(8,35,9,18:3)
Block(8,35,11,18:3)
Block(8,36,-7,18:3)
Block(8,36,-6,18:3)
Block(8,36,-5,18:3)
Block(8,36,-4,18:3)
Block(8,36,-3,18:3)
Block(8,36,-2,18:3)
Block(8,36,-1,18:3)
Block(8,36,0,17:3)
Block(8,36,1,17:3)
Block(8,36,5,18:3)
Block(8,36,6,18:3)
Block(8,36,7,18:3)
Block(8,36,8,18:3)
Block(8,36,9,18:3)
Block(8,36,10,18:3)
Block(8,36,12,18:3)
Block(8,37,-8,18:3)
Block(8,37,-7,18:3)
Block(8,37,-6,18:3)
Block(8,37,-5,18:3)
Block(8,37,-4,18:3)
Block(8,37,-3,18:3)
Block(8,37,-2,18:3)
Block(8,37,-1,18:3)
Block(8,37,0,18:3)
Block(8,37,1,18:3)
Block(8,37,2,18:3)
Block(8,37,3,18:3)
Block(8,37,4,18:3)
Block(8,37,5,18:3)
Block(8,37,6,18:3)
Block(8,37,7,18:3)
Block(8,37,8,18:3)
Block(8,37,9,18:3)
Block(8,37,10,18:3)
Block(8,37,11,18:3)
Block(8,38,-6,18:3)
Block(8,38,-5,18:3)
Block(8,38,-4,18:3)
Block(8,38,-3,18:3)
Block(8,38,-2,18:3)
Block(8,38,-1,18:3)
Block(8,38,1,18:3)
Block(8,38,2,18:3)
Block(8,38,3,18:3)
Block(8,38,4,18:3)
Block(8,38,5,18:3)
Block(8,38,6,18:3)
Block(8,38,7,18:3)
Block(8,38,8,18:3)
Block(8,38,9,18:3)
Block(8,38,10,18:3)
Block(8,39,-5,18:3)
Block(8,39,-3,18:3)
Block(8,39,-2,18:3)
Block(8,39,-1,18:3)
Block(8,39,1,18:3)
Block(8,39,2,18:3)
Block(8,39,3,18:3)
Block(8,39,4,18:3)
Block(8,39,5,18:3)
Block(8,39,6,18:3)
Block(8,39,7,18:3)
Block(8,40,-1,18:3)
Block(8,40,1,18:3)
Block(8,40,2,18:3)
Block(8,40,3,18:3)
Block(8,40,4,18:3)
Block(8,40,5,18:3)
Block(8,41,0,18:3)
Block(9,7,0,18:3)
Block(9,7,1,18:3)
Block(9,8,1,17:3)
Block(9,8,2,18:3)
Block(9,9,0,17:3)
Block(9,9,1,17:3)
Block(9,9,2,17:3)
Block(9,10,0,17:3)
Block(9,10,1,17:3)
Block(9,10,2,17:3)
Block(9,11,0,17:3)
Block(9,11,1,17:3)
Block(9,11,5,18:3)
Block(9,12,-3,18:3)
Block(9,12,-2,18:3)
Block(9,12,1,17:3)
Block(9,12,2,18:3)
Block(9,12,4,18:3)
Block(9,12,5,18:3)
Block(9,13,-2,18:3)
Block(9,13,-1,18:3)
Block(9,13,0,18:3)
Block(9,13,1,17:3)
Block(9,13,2,18:3)
Block(9,13,4,18:3)
Block(9,13,5,18:3)
Block(9,14,-1,18:3)
Block(9,14,1,18:3)
Block(9,14,2,18:3)
Block(9,14,3,18:3)
Block(9,14,4,18:3)
Block(9,15,-1,18:3)
Block(9,15,1,18:3)
Block(9,15,2,18:3)
Block(9,15,3,18:3)
Block(9,15,4,18:3)
Block(9,33,6,18:3)
Block(9,34,6,18:3)
Block(9,35,-7,18:3)
Block(9,35,-6,18:3)
Block(9,35,-4,18:3)
Block(9,35,6,18:3)
Block(9,35,8,18:3)
Block(9,35,9,18:3)
Block(9,35,10,18:3)
Block(9,36,-8,18:3)
Block(9,36,-7,18:3)
Block(9,36,-6,18:3)
Block(9,36,-5,18:3)
Block(9,36,-4,18:3)
Block(9,36,-3,18:3)
Block(9,36,-2,18:3)
Block(9,36,-1,18:3)
Block(9,36,0,18:3)
Block(9,36,1,17:3)
Block(9,36,3,18:3)
Block(9,36,4,18:3)
Block(9,36,5,18:3)
Block(9,36,6,18:3)
Block(9,36,7,18:3)
Block(9,36,8,18:3)
Block(9,36,9,18:3)
Block(9,36,10,18:3)
Block(9,37,-7,18:3)
Block(9,37,-6,18:3)
Block(9,37,-5,18:3)
Block(9,37,-4,18:3)
Block(9,37,-3,18:3)
Block(9,37,-2,18:3)
Block(9,37,-1,18:3)
Block(9,37,0,18:3)
Block(9,37,1,18:3)
Block(9,37,2,18:3)
Block(9,37,3,18:3)
Block(9,37,4,18:3)
Block(9,37,5,18:3)
Block(9,37,6,18:3)
Block(9,37,7,18:3)
Block(9,37,8,18:3)
Block(9,37,9,18:3)
Block(9,37,10,18:3)
Block(9,38,-5,18:3)
Block(9,38,-4,18:3)
Block(9,38,-3,18:3)
Block(9,38,-1,18:3)
Block(9,38,0,18:3)
Block(9,38,1,18:3)
Block(9,38,2,18:3)
Block(9,38,4,18:3)
Block(9,38,5,18:3)
Block(9,38,7,18:3)
Block(9,38,9,18:3)
Block(9,39,-4,18:3)
Block(9,39,-1,18:3)
Block(9,39,1,18:3)
Block(9,39,2,18:3)
Block(9,39,3,18:3)
Block(9,39,4,18:3)
Block(9,39,5,18:3)
Block(9,39,7,18:3)
Block(9,40,2,18:3)
Block(9,40,4,18:3)
Block(10,8,-3,18:3)
Block(10,9,-3,18:3)
Block(10,9,1,17:3)
Block(10,9,2,18:3)
Block(10,9,5,18:3)
Block(10,10,-3,18:3)
Block(10,10,0,17:3)
Block(10,10,1,17:3)
Block(10,10,2,17:3)
Block(10,10,3,18:3)
Block(10,10,5,18:3)
Block(10,11,-3,18:3)
Block(10,11,0,17:3)
Block(10,11,1,17:3)
Block(10,11,2,17:3)
Block(10,11,5,18:3)
Block(10,12,-3,18:3)
Block(10,12,0,17:3)
Block(10,12,1,17:3)
Block(10,12,2,17:3)
Block(10,12,3,17:3)
Block(10,12,5,18:3)
Block(10,12,6,18:3)
Block(10,13,-3,18:3)
Block(10,13,-2,18:3)
Block(10,13,-1,17:3)
Block(10,13,0,17:3)
Block(10,13,1,17:3)
Block(10,13,2,17:3)
Block(10,13,3,18:3)
Block(10,13,4,17:3)
Block(10,13,5,18:3)
Block(10,14,-2,18:3)
Block(10,14,-1,18:3)
Block(10,14,0,18:3)
Block(10,14,1,18:3)
Block(10,14,2,18:3)
Block(10,14,3,18:3)
Block(10,14,4,18:3)
Block(10,14,5,18:3)
Block(10,15,-1,18:3)
Block(10,15,2,18:3)
Block(10,15,3,18:3)
Block(10,28,9,18:3)
Block(10,29,9,18:3)
Block(10,30,9,18:3)
Block(10,31,9,18:3)
Block(10,32,-4,18:3)
Block(10,32,9,18:3)
Block(10,33,-4,18:3)
Block(10,33,9,18:3)
Block(10,34,-4,18:3)
Block(10,34,9,18:3)
Block(10,35,-5,18:3)
Block(10,35,-4,18:3)
Block(10,35,-3,18:3)
Block(10,35,-2,18:3)
Block(10,35,7,18:3)
Block(10,35,8,18:3)
Block(10,35,9,18:3)
Block(10,36,-5,18:3)
Block(10,36,-4,18:3)
Block(10,36,-3,18:3)
Block(10,36,-2,18:3)
Block(10,36,-1,18:3)
Block(10,36,0,18:3)
Block(10,36,1,17:3)
Block(10,36,2,18:3)
Block(10,36,3,18:3)
Block(10,36,4,18:3)
Block(10,36,5,18:3)
Block(10,36,6,18:3)
Block(10,36,7,18:3)
Block(10,36,8,18:3)
Block(10,36,9,18:3)
Block(10,36,10,18:3)
Block(10,37,-5,18:3)
Block(10,37,-4,18:3)
Block(10,37,-3,18:3)
Block(10,37,-2,18:3)
Block(10,37,-1,18:3)
Block(10,37,0,18:3)
Block(10,37,1,18:3)
Block(10,37,2,18:3)
Block(10,37,3,18:3)
Block(10,37,4,18:3)
Block(10,37,5,18:3)
Block(10,37,6,18:3)
Block(10,37,7,18:3)
Block(10,37,8,18:3)
Block(10,37,9,18:3)
Block(10,38,-4,18:3)
Block(10,38,-3,18:3)
Block(10,38,-2,18:3)
Block(10,38,-1,18:3)
Block(10,38,0,18:3)
Block(10,38,2,18:3)
Block(10,38,3,18:3)
Block(10,38,4,18:3)
Block(10,38,6,18:3)
Block(10,38,7,18:3)
Block(10,38,8,18:3)
Block(10,39,0,18:3)
Block(10,39,2,18:3)
Block(10,39,3,18:3)
Block(10,39,4,18:3)
Block(10,39,6,18:3)
Block(11,11,1,17:3)
Block(11,11,2,17:3)
Block(11,11,3,18:3)
Block(11,11,6,18:3)
Block(11,12,-3,18:3)
Block(11,12,-2,18:3)
Block(11,12,1,17:3)
Block(11,12,2,18:3)
Block(11,12,3,18:3)
Block(11,12,4,18:3)
Block(11,12,5,18:3)
Block(11,12,6,18:3)
Block(11,13,-3,18:3)
Block(11,13,-2,18:3)
Block(11,13,-1,18:3)
Block(11,13,0,18:3)
Block(11,13,1,17:3)
Block(11,13,2,18:3)
Block(11,13,3,18:3)
Block(11,13,4,18:3)
Block(11,13,5,18:3)
Block(11,13,6,18:3)
Block(11,14,-1,18:3)
Block(11,14,1,18:3)
Block(11,14,2,18:3)
Block(11,14,3,18:3)
Block(11,14,5,18:3)
Block(11,15,0,18:3)
Block(11,15,1,18:3)
Block(11,15,3,18:3)
Block(11,29,6,18:3)
Block(11,30,6,18:3)
Block(11,31,2,18:3)
Block(11,31,6,18:3)
Block(11,32,2,18:3)
Block(11,32,6,18:3)
Block(11,33,2,18:3)
Block(11,33,6,18:3)
Block(11,34,2,18:3)
Block(11,34,6,18:3)
Block(11,35,-4,18:3)
Block(11,35,-3,18:3)
Block(11,35,-2,18:3)
Block(11,35,-1,18:3)
Block(11,35,0,18:3)
Block(11,35,2,18:3)
Block(11,35,6,18:3)
Block(11,35,7,18:3)
Block(11,35,8,18:3)
Block(11,36,-5,18:3)
Block(11,36,-4,18:3)
Block(11,36,-3,18:3)
Block(11,36,-2,18:3)
Block(11,36,-1,18:3)
Block(11,36,0,18:3)
Block(11,36,1,17:3)
Block(11,36,2,18:3)
Block(11,36,3,18:3)
Block(11,36,4,18:3)
Block(11,36,5,18:3)
Block(11,36,6,18:3)
Block(11,36,7,18:3)
Block(11,36,8,18:3)
Block(11,36,9,18:3)
Block(11,37,-4,18:3)
Block(11,37,-3,18:3)
Block(11,37,-2,18:3)
Block(11,37,-1,18:3)
Block(11,37,0,18:3)
Block(11,37,1,18:3)
Block(11,37,2,18:3)
Block(11,37,3,18:3)
Block(11,37,4,18:3)
Block(11,37,5,18:3)
Block(11,37,6,18:3)
Block(11,37,7,18:3)
Block(11,37,8,18:3)
Block(11,38,-2,18:3)
Block(11,38,-1,18:3)
Block(11,38,1,18:3)
Block(11,38,2,18:3)
Block(11,38,3,18:3)
Block(11,38,4,18:3)
Block(11,38,5,18:3)
Block(11,38,7,18:3)
Block(11,39,3,18:3)
Block(11,39,4,18:3)
Block(12,11,1,17:3)
Block(12,11,5,18:3)
Block(12,12,-3,18:3)
Block(12,12,-2,18:3)
Block(12,12,1,18:3)
Block(12,12,2,18:3)
Block(12,12,3,18:3)
Block(12,12,4,18:3)
Block(12,12,5,18:3)
Block(12,12,6,18:3)
Block(12,13,-2,18:3)
Block(12,13,-1,18:3)
Block(12,13,0,18:3)
Block(12,13,1,18:3)
Block(12,13,2,18:3)
Block(12,13,3,18:3)
Block(12,13,4,18:3)
Block(12,13,5,18:3)
Block(12,14,-2,18:3)
Block(12,14,0,18:3)
Block(12,14,1,18:3)
Block(12,14,2,18:3)
Block(12,14,3,18:3)
Block(12,14,4,18:3)
Block(12,15,1,18:3)
Block(12,15,2,18:3)
Block(12,32,-2,18:3)
Block(12,33,-2,18:3)
Block(12,34,-2,18:3)
Block(12,35,-2,18:3)
Block(12,35,-1,18:3)
Block(12,35,0,18:3)
Block(12,35,1,18:3)
Block(12,35,2,18:3)
Block(12,35,3,18:3)
Block(12,35,5,18:3)
Block(12,35,6,18:3)
Block(12,36,-3,18:3)
Block(12,36,-2,18:3)
Block(12,36,-1,18:3)
Block(12,36,0,18:3)
Block(12,36,1,18:3)
Block(12,36,2,18:3)
Block(12,36,3,18:3)
Block(12,36,4,18:3)
Block(12,36,5,18:3)
Block(12,36,6,18:3)
Block(12,36,7,18:3)
Block(12,37,-2,18:3)
Block(12,37,-1,18:3)
Block(12,37,0,18:3)
Block(12,37,1,18:3)
Block(12,37,2,18:3)
Block(12,37,3,18:3)
Block(12,37,4,18:3)
Block(12,37,5,18:3)
Block(12,37,6,18:3)
Block(12,37,7,18:3)
Block(12,38,0,18:3)
Block(12,38,2,18:3)
Block(12,38,3,18:3)
Block(12,38,4,18:3)
Block(12,38,5,18:3)
Block(12,38,6,18:3)
Block(12,39,4,18:3)
Block(13,9,-2,18:3)
Block(13,9,4,18:3)
Block(13,10,-2,18:3)
Block(13,10,4,18:3)
Block(13,11,-2,18:3)
Block(13,11,3,18:3)
Block(13,11,4,18:3)
Block(13,12,-2,18:3)
Block(13,12,-1,18:3)
Block(13,12,0,18:3)
Block(13,12,1,17:3)
Block(13,12,2,18:3)
Block(13,12,3,18:3)
Block(13,12,4,18:3)
Block(13,13,-2,18:3)
Block(13,13,-1,18:3)
Block(13,13,0,18:3)
Block(13,13,1,18:3)
Block(13,13,2,18:3)
Block(13,13,3,18:3)
Block(13,13,4,18:3)
Block(13,14,-1,18:3)
Block(13,14,1,18:3)
Block(13,14,2,18:3)
Block(13,15,1,18:3)
Block(13,31,4,18:3)
Block(13,32,4,18:3)
Block(13,33,2,18:3)
Block(13,33,4,18:3)
Block(13,34,2,18:3)
Block(13,34,4,18:3)
Block(13,35,0,18:3)
Block(13,35,2,18:3)
Block(13,35,3,18:3)
Block(13,35,4,18:3)
Block(13,35,6,18:3)
Block(13,36,-1,18:3)
Block(13,36,0,18:3)
Block(13,36,1,18:3)
Block(13,36,2,18:3)
Block(13,36,3,18:3)
Block(13,36,4,18:3)
Block(13,36,5,18:3)
Block(13,36,6,18:3)
Block(13,36,7,18:3)
Block(13,37,0,18:3)
Block(13,37,2,18:3)
Block(13,37,3,18:3)
Block(13,37,4,18:3)
Block(13,37,5,18:3)
Block(13,37,6,18:3)
Block(13,38,3,18:3)
Block(13,38,4,18:3)
Block(14,10,1,18:3)
Block(14,11,0,18:3)
Block(14,11,1,18:3)
Block(14,11,3,18:3)
Block(14,12,-1,18:3)
Block(14,12,0,18:3)
Block(14,12,1,18:3)
Block(14,12,2,18:3)
Block(14,12,3,18:3)
Block(14,12,4,18:3)
Block(14,13,1,18:3)
Block(14,13,2,18:3)
Block(14,13,3,18:3)
Block(14,35,3,18:3)
Block(14,36,2,18:3)
Block(14,36,3,18:3)
Block(14,36,4,18:3)
Block(14,36,5,18:3)
Block(14,37,3,18:3)
Block(14,37,4,18:3)
Block(14,37,5,18:3)
Block(15,8,1,18:3)
Block(15,9,1,18:3)
Block(15,10,1,18:3)
Block(15,11,1,18:3)
Block(15,12,1,18:3)


#######################################################################
# +-----------------------------------------------------------------+ #
# |                             Entities                            | #
# +-----------------------------------------------------------------+ #
#######################################################################

# Entity() spawns an entity instead of a block. The entity is spawned only once when the BO3 is spawned.
# Entities are persistent by default so they don't de-spawn when no player is near, they are only unloaded.
# Usage: Entity(x,y,z,mobName,groupSize,NameTagOrNBTFileName) or Entity(x,y,z,mobName,groupSize)
# Use /tc entities or /otg entities to get a list of entities that can be used as mobName, this includes entities added by other mods.
# NameTagOrNBTFileName can be either a nametag for the mob or an nbt file (such as mymobinfo.nbt or mymobinfo.txt).
# When using a text file you can use the same mob spawning parameters used with the /summon command to equip the
# entity and give it custom attributes etc. You can copy the DATA part of a summon command including surrounding
# curly braces to a .txt file, for instance for: "/summon Skeleton x y z {DATA}"

#######################################################################
# +-----------------------------------------------------------------+ #
# |                            BO3 checks                           | #
# +-----------------------------------------------------------------+ #
#######################################################################

# Require a condition at a certain location in order for the BO3 to be spawned.
# BlockCheck(x,y,z,BlockName[,BlockName[,...]]) - one of the blocks must be at the location
# BlockCheckNot(x,y,z,BlockName[,BlockName[,...]]) - all the blocks must not be at the location
# LightCheck(x,y,z,minLightLevel,maxLightLevel) - light must be between min and max (inclusive)

# You can use "Solid" as a BlockName for matching all solid blocks or "All" to match all blocks that aren't air.

# Examples:
#   BlockCheck(0,-1,0,GRASS,DIRT)  Require grass or dirt just below the object
#   BlockCheck(0,-1,0,Solid)       Require any solid block just below the object
#   BlockCheck(0,-1,0,WOOL)        Require any type of wool just below the object
#   BlockCheck(0,-1,0,WOOL:0)      Require white wool just below the object
#   BlockCheckNot(0,-1,0,WOOL:0)   Require that there is no white wool below the object
#   LightCheck(0,0,0,0,1)          Require almost complete darkness just below the object
BlockCheck(0,-1,0,GRASS,DIRT)
BlockCheck(1,-1,0,Solid)
BlockCheck(1,-1,-1,Solid)
BlockCheck(1,-1,1,Solid)
BlockCheck(0,-1,1,Solid)
BlockCheck(0,-1,-1,Solid)
BlockCheck(-1,-1,1,Solid)
BlockCheck(-1,-1,0,Solid)
BlockCheck(-1,-1,-1,Solid)
BlockCheck(2,-1,2,Solid)
BlockCheck(2,-1,1,Solid)
BlockCheck(2,-1,0,Solid)
BlockCheck(2,-1,-1,Solid)
BlockCheck(2,-1,-2,Solid)
BlockCheck(1,-1,2,Solid)
BlockCheck(1,-1,-2,Solid)
BlockCheck(0,-1,2,Solid)
BlockCheck(0,-1,-2,Solid)
BlockCheck(-1,-1,2,Solid)
BlockCheck(-1,-1,-2,Solid)
BlockCheck(-2,-1,2,Solid)
BlockCheck(-2,-1,1,Solid)
BlockCheck(-2,-1,0,Solid)
BlockCheck(-2,-1,-1,Solid)
BlockCheck(-2,-1,-2,Solid)

