#######################################################################
# +-----------------------------------------------------------------+ #
# |                            BO3 object                           | #
# +-----------------------------------------------------------------+ #
#######################################################################

# The descriptions in this file are accurate only for TerrainControl and OTG.
# For MCW and OTG+ these descriptions are only accurate if the BO3 is used as a CustomObject.
# MCW and OTG+ completely reimplemented CustomStructure, check the MCW/OTG+ documentation for more information.

# This is the config file of a custom object.
# If you add this object correctly to your BiomeConfigs, it will spawn in the world.

# This is the creator of this BO3 object
Author: Unknown

# A short description of this BO3 object
Description: This BO3 was converted from a schematic using OTGEdit. The author and description information of the schematic could not be found. If you know who the author of the schematic is then please add this information.

# The BO3 version, don't change this! It can be used by external applications to do a version check.
Version: 3

# The settings mode, WriteAll, WriteWithoutComments or WriteDisable. See WorldConfig.
SettingsMode: WriteDisable

#######################################################################
# +-----------------------------------------------------------------+ #
# |                          Main settings                          | #
# +-----------------------------------------------------------------+ #
#######################################################################

# This needs to be set to true to spawn the object in the Tree and Sapling resources.
Tree: true

# The frequency of the BO3 from 1 to 200. Tries this many times to spawn this BO3 when using the CustomObject(...) resource.
# Ignored by Tree(..), Sapling(..) and CustomStructure(..)
Frequency: 40

# The rarity of the BO3 from 0 to 100. Each spawn attempt has rarity% chance to succeed when using the CustomObject(...) resource.
# Ignored by Tree(..), Sapling(..) and CustomStructure(..)
Rarity: 100.0

# If you set this to true, the BO3 will be placed with a random rotation.
RotateRandomly: true

# The spawn height of the BO3 - randomY, highestBlock or highestSolidBlock.
SpawnHeight: randomY

# The height limits for the BO3.
MinHeight: 63

MaxHeight: 256

# Objects can have other objects attached to it: branches. Branches can also
# have branches attached to it, which can also have branches, etc. This is the
# maximum branch depth for this objects.
MaxBranchDepth: 10

# When spawned with the UseWorld keyword, this BO3 should NOT spawn in the following biomes.
# If you writer.write the BO3 name directly in the BiomeConfigs, this will be ignored.
ExcludedBiomes: All

# To optimise this BO3 for faster loading times you can use Notepad++ to find/replace comments and abbreviate things.
# Notepad++ find/replace with regex:
# Find: ^[#;].* replace to nothing removes all lines starting with # 
# Find: ^\s*$ replace to nothing removes most empty lines 
# Notepad++ find/replace without regex:
# *Warning: This will only work for OTG 1.10.2 v21 / OTG 1.11.2 v6 or higher. B( is not recognised by lower versions.
# Find: Block( replace to B(

#######################################################################
# +-----------------------------------------------------------------+ #
# |                      Source block settings                      | #
# +-----------------------------------------------------------------+ #
#######################################################################

# The block(s) the BO3 should spawn in.
SourceBlocks: AIR,GRASS,DIRT

# The maximum percentage of the BO3 that can be outside the SourceBlock.
# The BO3 won't be placed on a location with more blocks outside the SourceBlock than this percentage.
MaxPercentageOutsideSourceBlock: 5

# What to do when a block is about to be placed outside the SourceBlock? (dontPlace, placeAnyway)
OutsideSourceBlock: dontPlace

#######################################################################
# +-----------------------------------------------------------------+ #
# |                              Blocks                             | #
# +-----------------------------------------------------------------+ #
#######################################################################

# All the blocks used in the BO3 are listed here. Possible blocks:
# Block(x,y,z,id[.data][,nbtfile.nbt) or B(x,y,z,id[.data][,nbtfile.nbt)
# RandomBlock(x,y,z,id[:data][,nbtfile.nbt],chance[,id[:data][,nbtfile.nbt],chance[,...]])
# So RandomBlock(0,0,0,CHEST,chest.nbt,50,CHEST,anotherchest.nbt,100) will spawn a chest at
# the BO3 origin, and give it a 50% chance to have the contents of chest.nbt, or, if that
# fails, a 100% percent chance to have the contents of anotherchest.nbt.

Block(-15,26,-1,161)
Block(-15,26,0,161)
Block(-14,25,-1,161)
Block(-14,25,1,161)
Block(-14,26,-2,161)
Block(-14,26,-1,161)
Block(-14,26,0,161)
Block(-14,27,-1,161)
Block(-14,27,0,161)
Block(-13,14,1,161)
Block(-13,14,3,161)
Block(-13,15,0,161)
Block(-13,15,2,161)
Block(-13,15,3,161)
Block(-13,15,4,161)
Block(-13,16,1,161)
Block(-13,25,-8,161)
Block(-13,25,-2,161)
Block(-13,25,-1,161)
Block(-13,25,0,161)
Block(-13,25,1,161)
Block(-13,25,2,161)
Block(-13,26,-2,161)
Block(-13,26,-1,161)
Block(-13,26,0,161)
Block(-13,27,-2,161)
Block(-13,27,-1,161)
Block(-13,27,0,161)
Block(-12,14,1,161)
Block(-12,14,2,161)
Block(-12,14,4,161)
Block(-12,15,0,161)
Block(-12,15,2,161)
Block(-12,15,3,161)
Block(-12,15,4,161)
Block(-12,16,1,161)
Block(-12,16,2,161)
Block(-12,16,3,161)
Block(-12,16,4,161)
Block(-12,24,-9,161)
Block(-12,24,-8,161)
Block(-12,24,-7,161)
Block(-12,25,-10,161)
Block(-12,25,-9,161)
Block(-12,25,-8,161)
Block(-12,25,-6,161)
Block(-12,25,-1,161)
Block(-12,25,0,161)
Block(-12,25,1,161)
Block(-12,26,-2,161)
Block(-12,26,-1,161)
Block(-12,26,0,162:12)
Block(-12,26,2,161)
Block(-12,27,-1,161)
Block(-12,27,0,161)
Block(-11,13,0,161)
Block(-11,14,0,161)
Block(-11,14,1,161)
Block(-11,14,2,161)
Block(-11,14,3,161)
Block(-11,15,0,161)
Block(-11,15,1,161)
Block(-11,15,2,162:12)
Block(-11,15,3,161)
Block(-11,15,4,161)
Block(-11,16,0,161)
Block(-11,16,1,161)
Block(-11,16,2,161)
Block(-11,24,-6,161)
Block(-11,25,-11,161)
Block(-11,25,-10,161)
Block(-11,25,-9,161)
Block(-11,25,-8,161)
Block(-11,25,-7,161)
Block(-11,25,-6,161)
Block(-11,25,-5,161)
Block(-11,25,-2,161)
Block(-11,25,-1,161)
Block(-11,25,0,162:12)
Block(-11,25,2,161)
Block(-11,26,-9,161)
Block(-11,26,-8,161)
Block(-11,26,-6,161)
Block(-11,26,0,161)
Block(-11,26,1,161)
Block(-11,26,2,161)
Block(-11,26,3,161)
Block(-11,27,-2,161)
Block(-11,27,-1,161)
Block(-11,27,0,161)
Block(-11,27,1,161)
Block(-11,27,2,161)
Block(-10,14,2,161)
Block(-10,15,1,162:12)
Block(-10,15,2,161)
Block(-10,15,3,161)
Block(-10,15,4,161)
Block(-10,15,5,161)
Block(-10,15,8,161)
Block(-10,15,9,161)
Block(-10,16,-3,161)
Block(-10,16,0,161)
Block(-10,16,1,161)
Block(-10,16,2,161)
Block(-10,24,-11,161)
Block(-10,24,-10,161)
Block(-10,24,-9,161)
Block(-10,24,-8,161)
Block(-10,24,-1,162:12)
Block(-10,24,0,162:12)
Block(-10,25,-10,161)
Block(-10,25,-9,161)
Block(-10,25,-8,162:12)
Block(-10,25,-7,161)
Block(-10,25,-6,161)
Block(-10,25,-5,161)
Block(-10,25,-1,161)
Block(-10,25,1,161)
Block(-10,26,-9,161)
Block(-10,26,-8,161)
Block(-10,26,-7,161)
Block(-10,26,-1,161)
Block(-10,26,0,161)
Block(-10,26,1,161)
Block(-10,26,2,161)
Block(-9,14,1,162:12)
Block(-9,14,4,161)
Block(-9,14,7,161)
Block(-9,14,9,161)
Block(-9,15,-5,161)
Block(-9,15,-3,162:12)
Block(-9,15,1,162:12)
Block(-9,15,3,161)
Block(-9,15,4,161)
Block(-9,15,5,161)
Block(-9,15,6,161)
Block(-9,15,7,161)
Block(-9,15,8,161)
Block(-9,15,9,161)
Block(-9,16,-5,161)
Block(-9,16,-4,161)
Block(-9,16,-3,161)
Block(-9,16,-2,161)
Block(-9,16,0,161)
Block(-9,16,1,161)
Block(-9,16,4,161)
Block(-9,16,8,161)
Block(-9,23,-8,161)
Block(-9,23,-7,162:12)
Block(-9,23,-2,162:12)
Block(-9,24,-10,161)
Block(-9,24,-8,161)
Block(-9,24,-7,162:12)
Block(-9,24,-6,161)
Block(-9,24,-1,162:12)
Block(-9,25,-10,161)
Block(-9,25,-9,161)
Block(-9,25,-8,161)
Block(-9,25,-7,161)
Block(-9,25,-6,161)
Block(-9,26,-8,161)
Block(-8,14,-4,161)
Block(-8,14,-3,161)
Block(-8,14,-2,162:12)
Block(-8,14,0,162:12)
Block(-8,14,3,161)
Block(-8,14,7,161)
Block(-8,14,9,161)
Block(-8,14,10,161)
Block(-8,15,-3,161)
Block(-8,15,-2,162:12)
Block(-8,15,2,161)
Block(-8,15,3,161)
Block(-8,15,4,162:12)
Block(-8,15,5,161)
Block(-8,15,6,161)
Block(-8,15,7,161)
Block(-8,15,8,161)
Block(-8,15,9,161)
Block(-8,15,10,161)
Block(-8,16,-4,161)
Block(-8,16,-3,161)
Block(-8,16,-2,161)
Block(-8,16,1,161)
Block(-8,16,3,161)
Block(-8,16,5,161)
Block(-8,16,7,161)
Block(-8,16,9,161)
Block(-8,17,1,161)
Block(-8,17,3,161)
Block(-8,22,-3,162:12)
Block(-8,23,-7,162:12)
Block(-8,23,-6,162:12)
Block(-8,23,-3,162:12)
Block(-8,24,-8,161)
Block(-8,24,-6,161)
Block(-8,25,-10,161)
Block(-8,25,-9,161)
Block(-8,25,-8,161)
Block(-8,25,-7,161)
Block(-8,26,-9,161)
Block(-7,12,-1,162:12)
Block(-7,13,-1,162:12)
Block(-7,14,-3,161)
Block(-7,14,-1,162:12)
Block(-7,14,7,162:12)
Block(-7,15,3,161)
Block(-7,15,4,161)
Block(-7,15,5,162:12)
Block(-7,15,7,161)
Block(-7,15,8,162:12)
Block(-7,15,10,161)
Block(-7,16,3,161)
Block(-7,16,8,161)
Block(-7,16,9,161)
Block(-7,16,10,161)
Block(-7,21,-3,162:12)
Block(-7,22,-5,162:12)
Block(-7,22,-4,162:12)
Block(-7,22,-3,162:12)
Block(-7,23,-6,162:12)
Block(-7,23,-5,162:12)
Block(-7,24,-8,161)
Block(-7,25,-9,161)
Block(-6,10,0,162:12)
Block(-6,11,0,162:12)
Block(-6,12,0,162:12)
Block(-6,14,6,162:12)
Block(-6,14,8,161)
Block(-6,15,5,162:12)
Block(-6,15,7,161)
Block(-6,15,8,161)
Block(-6,15,9,161)
Block(-6,15,10,161)
Block(-6,16,3,161)
Block(-6,16,8,161)
Block(-6,20,-3,162:12)
Block(-6,21,-3,162:12)
Block(-6,22,-5,162:12)
Block(-6,24,3,161)
Block(-6,25,-5,161)
Block(-6,25,3,161)
Block(-6,25,4,161)
Block(-6,25,5,161)
Block(-6,26,-6,161)
Block(-6,26,-5,161)
Block(-6,26,3,161)
Block(-5,8,0,162:12)
Block(-5,9,0,162:12)
Block(-5,10,0,162:12)
Block(-5,14,5,162:12)
Block(-5,15,8,161)
Block(-5,15,9,161)
Block(-5,17,-3,162:12)
Block(-5,18,-3,162:12)
Block(-5,19,-3,162:12)
Block(-5,20,-3,162:12)
Block(-5,20,-2,162:12)
Block(-5,21,-2,162:12)
Block(-5,21,-1,162:12)
Block(-5,22,-1,162:12)
Block(-5,22,0,162:12)
Block(-5,22,1,162:12)
Block(-5,23,-8,161)
Block(-5,23,-5,162:12)
Block(-5,24,-8,161)
Block(-5,24,-7,161)
Block(-5,24,-5,161)
Block(-5,24,-4,161)
Block(-5,24,-3,161)
Block(-5,24,4,161)
Block(-5,25,-7,161)
Block(-5,25,-6,161)
Block(-5,25,-5,161)
Block(-5,25,-4,161)
Block(-5,25,4,161)
Block(-5,25,5,161)
Block(-5,26,-8,161)
Block(-5,26,-7,161)
Block(-5,26,-6,161)
Block(-5,26,-5,161)
Block(-5,26,3,161)
Block(-5,26,4,161)
Block(-5,26,5,161)
Block(-4,7,0,162:12)
Block(-4,8,0,162:12)
Block(-4,9,2,162:12)
Block(-4,10,2,162:12)
Block(-4,11,2,162:12)
Block(-4,11,3,162:12)
Block(-4,12,3,162:12)
Block(-4,13,4,162:12)
Block(-4,13,5,162:12)
Block(-4,14,-2,162:12)
Block(-4,15,-2,162:12)
Block(-4,16,-2,162:12)
Block(-4,17,-2,162:12)
Block(-4,19,-3,162:12)
Block(-4,20,-4,162:12)
Block(-4,20,-3,162:12)
Block(-4,21,-3,162:12)
Block(-4,21,-2,162:12)
Block(-4,22,1,162:12)
Block(-4,23,-7,161)
Block(-4,23,1,162:12)
Block(-4,23,2,162:12)
Block(-4,24,-8,161)
Block(-4,24,-7,161)
Block(-4,24,-6,162:12)
Block(-4,24,-4,161)
Block(-4,24,2,161)
Block(-4,24,3,162:12)
Block(-4,24,5,161)
Block(-4,24,6,161)
Block(-4,25,-7,162:12)
Block(-4,25,-6,161)
Block(-4,25,2,161)
Block(-4,25,3,162:12)
Block(-4,25,4,161)
Block(-4,25,5,161)
Block(-4,25,6,161)
Block(-4,25,7,161)
Block(-4,26,-5,161)
Block(-4,26,2,161)
Block(-4,26,3,161)
Block(-4,26,4,161)
Block(-4,26,5,161)
Block(-4,26,6,161)
Block(-3,0,-2,162:12)
Block(-3,0,1,162:12)
Block(-3,6,0,162:12)
Block(-3,7,0,162:12)
Block(-3,7,1,162:12)
Block(-3,8,1,162:12)
Block(-3,8,2,162:12)
Block(-3,11,-2,162:12)
Block(-3,12,-2,162:12)
Block(-3,13,-2,162:12)
Block(-3,13,3,162:12)
Block(-3,14,-2,162:12)
Block(-3,14,5,162:12)
Block(-3,15,5,161)
Block(-3,15,6,162:12)
Block(-3,15,7,161)
Block(-3,16,7,161)
Block(-3,20,-4,162:12)
Block(-3,21,-6,162:12)
Block(-3,21,-5,162:12)
Block(-3,21,-3,162:12)
Block(-3,22,-7,162:12)
Block(-3,22,5,161)
Block(-3,22,6,161)
Block(-3,22,7,161)
Block(-3,23,-8,161)
Block(-3,23,-6,161)
Block(-3,23,6,161)
Block(-3,23,7,161)
Block(-3,24,-9,161)
Block(-3,24,-8,161)
Block(-3,24,-7,161)
Block(-3,24,-6,161)
Block(-3,24,-5,161)
Block(-3,24,1,161)
Block(-3,24,5,161)
Block(-3,25,-8,161)
Block(-3,25,-7,161)
Block(-3,25,-6,161)
Block(-3,25,-5,161)
Block(-3,25,-4,161)
Block(-3,25,2,161)
Block(-3,25,3,161)
Block(-3,25,5,161)
Block(-3,25,6,161)
Block(-3,26,4,161)
Block(-2,0,-1,162:12)
Block(-2,0,2,162:12)
Block(-2,1,0,162:12)
Block(-2,2,0,162:12)
Block(-2,3,0,162:12)
Block(-2,4,-1,162:12)
Block(-2,4,0,162:12)
Block(-2,5,-1,162:12)
Block(-2,5,0,162:12)
Block(-2,5,1,162:12)
Block(-2,6,-1,162:12)
Block(-2,6,0,162:12)
Block(-2,6,1,162:12)
Block(-2,7,-2,162:12)
Block(-2,7,-1,162:12)
Block(-2,7,0,162:12)
Block(-2,7,1,162:12)
Block(-2,8,-2,162:12)
Block(-2,8,-1,162:12)
Block(-2,8,0,162:12)
Block(-2,9,-2,162:12)
Block(-2,9,-1,162:12)
Block(-2,10,-2,162:12)
Block(-2,10,-1,162:12)
Block(-2,11,-2,162:12)
Block(-2,12,-2,162:12)
Block(-2,15,5,161)
Block(-2,15,6,162:12)
Block(-2,15,7,161)
Block(-2,15,8,161)
Block(-2,16,6,161)
Block(-2,16,7,161)
Block(-2,16,8,161)
Block(-2,17,7,161)
Block(-2,21,-3,162:12)
Block(-2,21,5,161)
Block(-2,21,6,161)
Block(-2,21,7,161)
Block(-2,21,8,161)
Block(-2,22,-7,161)
Block(-2,22,-6,161)
Block(-2,22,4,161)
Block(-2,22,5,161)
Block(-2,22,6,161)
Block(-2,22,7,161)
Block(-2,22,9,161)
Block(-2,23,-9,161)
Block(-2,23,-8,161)
Block(-2,23,-7,161)
Block(-2,23,0,161)
Block(-2,23,5,161)
Block(-2,23,6,161)
Block(-2,23,7,161)
Block(-2,24,-6,161)
Block(-2,24,1,161)
Block(-2,24,4,161)
Block(-2,24,6,161)
Block(-2,25,-6,161)
Block(-2,25,-5,161)
Block(-2,25,3,161)
Block(-2,25,4,161)
Block(-2,25,5,161)
Block(-2,26,-6,161)
Block(-2,26,4,161)
Block(-1,0,-1,162:12)
Block(-1,0,0,162:12)
Block(-1,0,1,162:12)
Block(-1,1,0,162:12)
Block(-1,1,1,162:12)
Block(-1,2,-1,162:12)
Block(-1,2,0,162:12)
Block(-1,2,1,162:12)
Block(-1,3,-1,162:12)
Block(-1,3,0,162:12)
Block(-1,3,1,162:12)
Block(-1,4,-1,162:12)
Block(-1,4,0,162:12)
Block(-1,5,-1,162:12)
Block(-1,5,0,162:12)
Block(-1,6,-1,162:12)
Block(-1,6,0,162:12)
Block(-1,7,-1,162:12)
Block(-1,8,-1,162:12)
Block(-1,9,-1,162:12)
Block(-1,9,0,162:12)
Block(-1,10,-1,162:12)
Block(-1,10,0,162:12)
Block(-1,11,0,162:12)
Block(-1,14,8,161)
Block(-1,15,5,161)
Block(-1,15,6,161)
Block(-1,15,8,161)
Block(-1,16,5,161)
Block(-1,16,6,161)
Block(-1,16,7,162:12)
Block(-1,16,8,161)
Block(-1,16,9,161)
Block(-1,17,6,161)
Block(-1,17,7,161)
Block(-1,21,-8,161)
Block(-1,21,-3,162:12)
Block(-1,21,5,161)
Block(-1,21,6,161)
Block(-1,21,8,161)
Block(-1,21,9,161)
Block(-1,22,-8,161)
Block(-1,22,-7,161)
Block(-1,22,-3,162:12)
Block(-1,22,0,161)
Block(-1,22,2,161)
Block(-1,22,4,161)
Block(-1,22,5,162:12)
Block(-1,22,8,161)
Block(-1,22,9,161)
Block(-1,22,10,161)
Block(-1,23,0,161)
Block(-1,23,1,162:12)
Block(-1,23,2,161)
Block(-1,23,4,161)
Block(-1,23,5,161)
Block(-1,23,7,161)
Block(-1,24,-6,161)
Block(-1,24,-5,161)
Block(-1,24,0,161)
Block(-1,24,1,161)
Block(-1,24,2,161)
Block(-1,24,4,161)
Block(-1,24,5,161)
Block(-1,24,8,161)
Block(-1,25,-6,161)
Block(0,0,-1,162:12)
Block(0,0,0,162:12)
Block(0,0,1,162:12)
Block(0,0,2,162:12)
Block(0,1,-1,162:12)
Block(0,1,0,162:12)
Block(0,1,1,162:12)
Block(0,2,-1,162:12)
Block(0,2,0,162:12)
Block(0,2,1,162:12)
Block(0,3,-1,162:12)
Block(0,3,0,162:12)
Block(0,4,-1,162:12)
Block(0,4,0,162:12)
Block(0,5,-1,162:12)
Block(0,5,0,162:12)
Block(0,6,-1,162:12)
Block(0,10,0,162:12)
Block(0,11,0,162:12)
Block(0,12,0,162:12)
Block(0,13,0,162:12)
Block(0,14,0,162:12)
Block(0,15,5,161)
Block(0,15,7,161)
Block(0,15,9,161)
Block(0,16,4,161)
Block(0,16,5,161)
Block(0,16,6,161)
Block(0,16,7,161)
Block(0,16,8,161)
Block(0,16,9,161)
Block(0,17,7,161)
Block(0,17,8,161)
Block(0,17,9,161)
Block(0,21,-7,161)
Block(0,21,1,162:12)
Block(0,21,8,161)
Block(0,21,9,161)
Block(0,21,10,161)
Block(0,22,-8,161)
Block(0,22,-7,161)
Block(0,22,-3,162:12)
Block(0,22,-2,161)
Block(0,22,1,162:12)
Block(0,22,4,161)
Block(0,22,6,162:12)
Block(0,22,7,162:12)
Block(0,22,8,161)
Block(0,23,-7,161)
Block(0,23,-3,161)
Block(0,23,-1,161)
Block(0,23,0,161)
Block(0,23,1,161)
Block(0,23,2,161)
Block(0,23,4,161)
Block(0,23,7,161)
Block(0,23,8,162:12)
Block(0,23,9,161)
Block(0,24,-6,161)
Block(0,24,-2,161)
Block(0,24,1,161)
Block(0,24,8,161)
Block(1,0,-2,162:12)
Block(1,0,-1,162:12)
Block(1,0,0,162:12)
Block(1,0,1,162:12)
Block(1,0,2,162:12)
Block(1,0,3,162:12)
Block(1,1,0,162:12)
Block(1,1,1,162:12)
Block(1,14,0,162:12)
Block(1,15,0,162:12)
Block(1,15,1,162:12)
Block(1,15,6,161)
Block(1,15,7,161)
Block(1,15,8,161)
Block(1,16,1,162:12)
Block(1,16,5,161)
Block(1,16,6,161)
Block(1,16,7,161)
Block(1,16,8,161)
Block(1,16,9,161)
Block(1,17,1,162:12)
Block(1,21,1,162:12)
Block(1,21,2,162:12)
Block(1,21,5,162:12)
Block(1,21,6,162:12)
Block(1,21,9,161)
Block(1,22,-7,161)
Block(1,22,-5,161)
Block(1,22,-3,162:12)
Block(1,22,-1,161)
Block(1,22,8,161)
Block(1,22,9,161)
Block(1,22,10,161)
Block(1,23,-5,161)
Block(1,23,-4,161)
Block(1,23,-3,161)
Block(1,23,-2,162:12)
Block(1,23,-1,161)
Block(1,23,1,161)
Block(1,23,7,161)
Block(1,23,8,161)
Block(1,24,-5,161)
Block(1,24,-2,161)
Block(1,24,-1,161)
Block(1,24,8,161)
Block(2,0,-1,162:12)
Block(2,0,0,162:12)
Block(2,15,7,161)
Block(2,16,6,161)
Block(2,16,7,161)
Block(2,16,8,161)
Block(2,17,1,162:12)
Block(2,17,7,161)
Block(2,18,1,162:12)
Block(2,18,2,162:12)
Block(2,19,2,162:12)
Block(2,20,2,162:12)
Block(2,20,3,162:12)
Block(2,20,4,162:12)
Block(2,21,2,162:12)
Block(2,21,4,162:12)
Block(2,21,5,162:12)
Block(2,22,-5,161)
Block(2,22,-4,161)
Block(2,22,-3,162:12)
Block(2,22,8,161)
Block(2,23,-6,161)
Block(2,23,-5,161)
Block(2,23,-4,161)
Block(2,23,-1,161)
Block(2,24,-6,161)
Block(2,24,-5,161)
Block(2,24,-4,161)
Block(2,24,-2,161)
Block(3,0,1,162:12)
Block(3,20,0,162:12)
Block(3,20,1,162:12)
Block(3,20,3,162:12)
Block(3,21,0,162:12)
Block(3,22,-3,161)
Block(3,23,-6,161)
Block(3,23,-5,161)
Block(3,23,-4,162:12)
Block(3,23,-3,161)
Block(3,24,-5,161)
Block(3,24,-4,161)
Block(3,24,-3,161)
Block(4,20,3,162:12)
Block(4,21,-1,162:12)
Block(4,21,0,162:12)
Block(4,22,-4,161)
Block(4,22,6,161)
Block(4,23,-4,161)
Block(4,23,-3,161)
Block(4,23,6,161)
Block(4,24,-4,161)
Block(5,20,3,162:12)
Block(5,21,3,162:12)
Block(5,21,4,162:12)
Block(5,21,7,161)
Block(5,22,-5,161)
Block(5,22,-4,161)
Block(5,22,-2,161)
Block(5,22,-1,162:12)
Block(5,22,6,161)
Block(5,22,7,161)
Block(5,23,-5,161)
Block(5,23,-4,161)
Block(5,23,-2,161)
Block(5,23,5,161)
Block(5,23,6,161)
Block(5,23,7,161)
Block(5,24,-2,161)
Block(6,21,4,162:12)
Block(6,21,5,162:12)
Block(6,21,8,161)
Block(6,22,-5,161)
Block(6,22,-4,161)
Block(6,22,-3,161)
Block(6,22,5,161)
Block(6,22,6,162:12)
Block(6,22,7,161)
Block(6,22,8,161)
Block(6,23,-6,161)
Block(6,23,-5,161)
Block(6,23,-4,161)
Block(6,23,-3,161)
Block(6,23,-2,162:12)
Block(6,23,-1,161)
Block(6,23,6,161)
Block(6,23,7,161)
Block(6,23,8,161)
Block(6,23,9,161)
Block(6,24,-5,161)
Block(6,24,-4,161)
Block(6,24,-3,161)
Block(6,24,-2,161)
Block(6,24,-1,161)
Block(7,21,3,162:12)
Block(7,21,4,162:12)
Block(7,21,6,161)
Block(7,21,7,161)
Block(7,21,8,161)
Block(7,21,9,161)
Block(7,22,-4,161)
Block(7,22,-2,161)
Block(7,22,6,161)
Block(7,22,7,162:12)
Block(7,22,8,161)
Block(7,22,9,161)
Block(7,23,-5,161)
Block(7,23,-4,161)
Block(7,23,-3,161)
Block(7,23,-2,161)
Block(7,23,-1,161)
Block(7,23,7,161)
Block(7,23,8,161)
Block(7,24,-3,161)
Block(7,24,-2,161)
Block(8,20,8,161)
Block(8,21,3,162:12)
Block(8,21,6,161)
Block(8,21,7,161)
Block(8,21,8,161)
Block(8,22,2,162:12)
Block(8,22,3,162:12)
Block(8,22,7,161)
Block(8,22,8,161)
Block(8,23,-4,161)
Block(8,23,1,161)
Block(8,23,2,161)
Block(8,23,3,161)
Block(8,23,6,161)
Block(8,23,7,161)
Block(8,24,-3,161)
Block(9,21,6,161)
Block(9,22,1,161)
Block(9,22,2,162:12)
Block(9,22,5,161)
Block(9,22,6,161)
Block(9,22,7,161)
Block(9,22,8,161)
Block(9,23,0,161)
Block(9,23,1,161)
Block(9,23,2,161)
Block(9,23,3,161)
Block(9,23,6,161)
Block(9,23,8,161)
Block(9,24,2,161)
Block(10,22,2,161)
Block(10,22,6,161)
Block(10,22,7,161)
Block(10,23,0,161)
Block(10,23,1,161)
Block(10,23,2,162:12)
Block(10,24,1,161)
Block(10,24,2,161)
Block(10,24,3,161)
Block(11,22,0,161)
Block(11,22,1,161)
Block(11,22,2,161)
Block(11,22,3,161)
Block(11,22,4,161)
Block(11,23,-1,161)
Block(11,23,0,161)
Block(11,23,3,161)
Block(11,24,0,161)
Block(11,24,1,161)
Block(11,24,2,161)
Block(12,22,1,161)
Block(12,22,2,161)
Block(12,22,3,161)
Block(12,23,0,161)
Block(12,23,2,161)
Block(12,24,2,161)
Block(12,24,3,161)
Block(13,22,2,161)


#######################################################################
# +-----------------------------------------------------------------+ #
# |                             Entities                            | #
# +-----------------------------------------------------------------+ #
#######################################################################

# Entity() spawns an entity instead of a block. The entity is spawned only once when the BO3 is spawned.
# Entities are persistent by default so they don't de-spawn when no player is near, they are only unloaded.
# Usage: Entity(x,y,z,mobName,groupSize,NameTagOrNBTFileName) or Entity(x,y,z,mobName,groupSize)
# Use /tc entities or /otg entities to get a list of entities that can be used as mobName, this includes entities added by other mods.
# NameTagOrNBTFileName can be either a nametag for the mob or an nbt file (such as mymobinfo.nbt or mymobinfo.txt).
# When using a text file you can use the same mob spawning parameters used with the /summon command to equip the
# entity and give it custom attributes etc. You can copy the DATA part of a summon command including surrounding
# curly braces to a .txt file, for instance for: "/summon Skeleton x y z {DATA}"

#######################################################################
# +-----------------------------------------------------------------+ #
# |                            BO3 checks                           | #
# +-----------------------------------------------------------------+ #
#######################################################################

# Require a condition at a certain location in order for the BO3 to be spawned.
# BlockCheck(x,y,z,BlockName[,BlockName[,...]]) - one of the blocks must be at the location
# BlockCheckNot(x,y,z,BlockName[,BlockName[,...]]) - all the blocks must not be at the location
# LightCheck(x,y,z,minLightLevel,maxLightLevel) - light must be between min and max (inclusive)

# You can use "Solid" as a BlockName for matching all solid blocks or "All" to match all blocks that aren't air.

# Examples:
#   BlockCheck(0,-1,0,GRASS,DIRT)  Require grass or dirt just below the object
#   BlockCheck(0,-1,0,Solid)       Require any solid block just below the object
#   BlockCheck(0,-1,0,WOOL)        Require any type of wool just below the object
#   BlockCheck(0,-1,0,WOOL:0)      Require white wool just below the object
#   BlockCheckNot(0,-1,0,WOOL:0)   Require that there is no white wool below the object
#   LightCheck(0,0,0,0,1)          Require almost complete darkness just below the object
BlockCheck(0,-1,0,GRASS,DIRT)
BlockCheck(1,-1,0,Solid)
BlockCheck(1,-1,-1,Solid)
BlockCheck(1,-1,1,Solid)
BlockCheck(0,-1,1,Solid)
BlockCheck(0,-1,-1,Solid)
BlockCheck(-1,-1,1,Solid)
BlockCheck(-1,-1,0,Solid)
BlockCheck(-1,-1,-1,Solid)
BlockCheck(2,-1,2,Solid)
BlockCheck(2,-1,1,Solid)
BlockCheck(2,-1,0,Solid)
BlockCheck(2,-1,-1,Solid)
BlockCheck(2,-1,-2,Solid)
BlockCheck(1,-1,2,Solid)
BlockCheck(1,-1,-2,Solid)
BlockCheck(0,-1,2,Solid)
BlockCheck(0,-1,-2,Solid)
BlockCheck(-1,-1,2,Solid)
BlockCheck(-1,-1,-2,Solid)
BlockCheck(-2,-1,2,Solid)
BlockCheck(-2,-1,1,Solid)
BlockCheck(-2,-1,0,Solid)
BlockCheck(-2,-1,-1,Solid)
BlockCheck(-2,-1,-2,Solid)

