#######################################################################
# +-----------------------------------------------------------------+ #
# |                            BO3 object                           | #
# +-----------------------------------------------------------------+ #
#######################################################################

# The descriptions in this file are accurate only for TerrainControl and OTG.
# For MCW and OTG+ these descriptions are only accurate if the BO3 is used as a CustomObject.
# MCW and OTG+ completely reimplemented CustomStructure, check the MCW/OTG+ documentation for more information.

# This is the config file of a custom object.
# If you add this object correctly to your BiomeConfigs, it will spawn in the world.

# This is the creator of this BO3 object
Author: Unknown

# A short description of this BO3 object
Description: This BO3 was converted from a schematic using OTGEdit. The author and description information of the schematic could not be found. If you know who the author of the schematic is then please add this information.

# The BO3 version, don't change this! It can be used by external applications to do a version check.
Version: 3

# The settings mode, WriteAll, WriteWithoutComments or WriteDisable. See WorldConfig.
SettingsMode: WriteDisable

#######################################################################
# +-----------------------------------------------------------------+ #
# |                          Main settings                          | #
# +-----------------------------------------------------------------+ #
#######################################################################

# This needs to be set to true to spawn the object in the Tree and Sapling resources.
Tree: true

# The frequency of the BO3 from 1 to 200. Tries this many times to spawn this BO3 when using the CustomObject(...) resource.
# Ignored by Tree(..), Sapling(..) and CustomStructure(..)
Frequency: 40

# The rarity of the BO3 from 0 to 100. Each spawn attempt has rarity% chance to succeed when using the CustomObject(...) resource.
# Ignored by Tree(..), Sapling(..) and CustomStructure(..)
Rarity: 100.0

# If you set this to true, the BO3 will be placed with a random rotation.
RotateRandomly: true

# The spawn height of the BO3 - randomY, highestBlock or highestSolidBlock.
SpawnHeight: randomY

# The height limits for the BO3.
MinHeight: 63

MaxHeight: 256

# Objects can have other objects attached to it: branches. Branches can also
# have branches attached to it, which can also have branches, etc. This is the
# maximum branch depth for this objects.
MaxBranchDepth: 10

# When spawned with the UseWorld keyword, this BO3 should NOT spawn in the following biomes.
# If you writer.write the BO3 name directly in the BiomeConfigs, this will be ignored.
ExcludedBiomes: All

# To optimise this BO3 for faster loading times you can use Notepad++ to find/replace comments and abbreviate things.
# Notepad++ find/replace with regex:
# Find: ^[#;].* replace to nothing removes all lines starting with # 
# Find: ^\s*$ replace to nothing removes most empty lines 
# Notepad++ find/replace without regex:
# *Warning: This will only work for OTG 1.10.2 v21 / OTG 1.11.2 v6 or higher. B( is not recognised by lower versions.
# Find: Block( replace to B(

#######################################################################
# +-----------------------------------------------------------------+ #
# |                      Source block settings                      | #
# +-----------------------------------------------------------------+ #
#######################################################################

# The block(s) the BO3 should spawn in.
SourceBlocks: AIR,GRASS,DIRT

# The maximum percentage of the BO3 that can be outside the SourceBlock.
# The BO3 won't be placed on a location with more blocks outside the SourceBlock than this percentage.
MaxPercentageOutsideSourceBlock: 5

# What to do when a block is about to be placed outside the SourceBlock? (dontPlace, placeAnyway)
OutsideSourceBlock: dontPlace

#######################################################################
# +-----------------------------------------------------------------+ #
# |                              Blocks                             | #
# +-----------------------------------------------------------------+ #
#######################################################################

# All the blocks used in the BO3 are listed here. Possible blocks:
# Block(x,y,z,id[.data][,nbtfile.nbt) or B(x,y,z,id[.data][,nbtfile.nbt)
# RandomBlock(x,y,z,id[:data][,nbtfile.nbt],chance[,id[:data][,nbtfile.nbt],chance[,...]])
# So RandomBlock(0,0,0,CHEST,chest.nbt,50,CHEST,anotherchest.nbt,100) will spawn a chest at
# the BO3 origin, and give it a 50% chance to have the contents of chest.nbt, or, if that
# fails, a 100% percent chance to have the contents of anotherchest.nbt.

Block(-9,23,-2,161)
Block(-9,24,-3,161)
Block(-9,24,-2,161)
Block(-9,24,-1,161)
Block(-9,25,-2,161)
Block(-8,22,-2,161)
Block(-8,23,-3,161)
Block(-8,23,-2,161)
Block(-8,23,-1,161)
Block(-8,24,-4,161)
Block(-8,24,-3,161)
Block(-8,24,-2,161)
Block(-8,24,-1,161)
Block(-8,25,-3,161)
Block(-8,25,-2,161)
Block(-8,25,-1,161)
Block(-7,23,-11,161)
Block(-7,23,-9,161)
Block(-7,23,-4,161)
Block(-7,23,-3,161)
Block(-7,23,-2,161)
Block(-7,24,-12,161)
Block(-7,24,-11,161)
Block(-7,24,-10,161)
Block(-7,24,-9,161)
Block(-7,24,-8,161)
Block(-7,24,-5,161)
Block(-7,24,-4,161)
Block(-7,24,-3,161)
Block(-7,24,-2,161)
Block(-7,24,-1,161)
Block(-7,25,-11,161)
Block(-7,25,-9,161)
Block(-7,25,-4,161)
Block(-7,25,-3,161)
Block(-7,25,-2,161)
Block(-6,22,-11,161)
Block(-6,22,7,161)
Block(-6,23,-12,161)
Block(-6,23,-11,161)
Block(-6,23,-10,161)
Block(-6,23,-9,161)
Block(-6,23,-8,161)
Block(-6,23,-5,161)
Block(-6,23,-4,161)
Block(-6,23,-3,161)
Block(-6,23,-2,161)
Block(-6,23,-1,161)
Block(-6,24,-12,161)
Block(-6,24,-11,161)
Block(-6,24,-10,161)
Block(-6,24,-9,162:12)
Block(-6,24,-8,161)
Block(-6,24,-5,161)
Block(-6,24,-4,161)
Block(-6,24,-3,161)
Block(-6,24,-2,162:12)
Block(-6,24,-1,161)
Block(-6,25,-12,161)
Block(-6,25,-11,161)
Block(-6,25,-10,161)
Block(-6,25,-9,161)
Block(-6,25,-8,161)
Block(-6,25,-5,161)
Block(-6,25,-4,161)
Block(-6,25,-3,161)
Block(-6,25,-2,161)
Block(-6,25,-1,161)
Block(-5,11,1,161)
Block(-5,11,2,161)
Block(-5,11,3,161)
Block(-5,12,0,161)
Block(-5,12,1,161)
Block(-5,12,2,161)
Block(-5,12,3,161)
Block(-5,12,4,161)
Block(-5,13,1,161)
Block(-5,13,3,161)
Block(-5,21,1,161)
Block(-5,21,6,161)
Block(-5,21,7,161)
Block(-5,22,0,161)
Block(-5,22,1,161)
Block(-5,22,2,161)
Block(-5,22,6,161)
Block(-5,22,7,161)
Block(-5,22,8,161)
Block(-5,23,-11,161)
Block(-5,23,-10,161)
Block(-5,23,-9,161)
Block(-5,23,-8,162:12)
Block(-5,23,-4,161)
Block(-5,23,-3,162:12)
Block(-5,23,-2,162:12)
Block(-5,23,1,161)
Block(-5,23,7,161)
Block(-5,24,-12,161)
Block(-5,24,-11,161)
Block(-5,24,-10,161)
Block(-5,24,-9,161)
Block(-5,24,-8,161)
Block(-5,24,-5,161)
Block(-5,24,-4,161)
Block(-5,24,-3,161)
Block(-5,24,-2,161)
Block(-5,24,-1,161)
Block(-5,25,-11,161)
Block(-5,25,-10,161)
Block(-5,25,-9,161)
Block(-5,25,-4,161)
Block(-5,25,-2,161)
Block(-4,11,0,161)
Block(-4,11,1,161)
Block(-4,11,2,161)
Block(-4,11,3,161)
Block(-4,11,4,161)
Block(-4,12,0,161)
Block(-4,12,1,161)
Block(-4,12,2,161)
Block(-4,12,3,161)
Block(-4,12,4,161)
Block(-4,12,5,161)
Block(-4,13,0,161)
Block(-4,13,1,161)
Block(-4,13,2,161)
Block(-4,13,3,161)
Block(-4,13,4,161)
Block(-4,21,0,161)
Block(-4,21,1,161)
Block(-4,21,2,161)
Block(-4,21,6,161)
Block(-4,21,7,161)
Block(-4,21,8,161)
Block(-4,22,-3,162:12)
Block(-4,22,-1,161)
Block(-4,22,0,161)
Block(-4,22,1,161)
Block(-4,22,2,161)
Block(-4,22,3,161)
Block(-4,22,5,161)
Block(-4,22,6,161)
Block(-4,22,7,161)
Block(-4,22,8,161)
Block(-4,22,9,161)
Block(-4,23,-10,161)
Block(-4,23,-8,162:12)
Block(-4,23,-7,162:12)
Block(-4,23,-3,162:12)
Block(-4,23,0,161)
Block(-4,23,1,161)
Block(-4,23,2,161)
Block(-4,23,6,161)
Block(-4,23,7,161)
Block(-4,23,8,161)
Block(-4,24,-11,161)
Block(-4,24,-10,161)
Block(-4,24,-9,161)
Block(-4,25,-10,161)
Block(-3,0,1,162:12)
Block(-3,11,1,161)
Block(-3,11,2,161)
Block(-3,11,3,161)
Block(-3,11,4,161)
Block(-3,11,5,161)
Block(-3,12,0,161)
Block(-3,12,1,161)
Block(-3,12,2,162:12)
Block(-3,12,3,161)
Block(-3,12,4,161)
Block(-3,12,5,161)
Block(-3,13,1,161)
Block(-3,13,2,161)
Block(-3,13,3,161)
Block(-3,13,4,161)
Block(-3,13,5,161)
Block(-3,21,-4,162:12)
Block(-3,21,-1,161)
Block(-3,21,0,161)
Block(-3,21,1,161)
Block(-3,21,2,161)
Block(-3,21,3,161)
Block(-3,21,5,161)
Block(-3,21,6,161)
Block(-3,21,7,161)
Block(-3,21,8,161)
Block(-3,21,9,161)
Block(-3,22,-7,162:12)
Block(-3,22,-4,162:12)
Block(-3,22,-3,162:12)
Block(-3,22,-1,161)
Block(-3,22,0,162:12)
Block(-3,22,1,161)
Block(-3,22,2,161)
Block(-3,22,3,161)
Block(-3,22,5,161)
Block(-3,22,6,161)
Block(-3,22,7,161)
Block(-3,22,8,161)
Block(-3,22,9,161)
Block(-3,22,10,161)
Block(-3,23,-7,162:12)
Block(-3,23,-1,161)
Block(-3,23,0,161)
Block(-3,23,1,161)
Block(-3,23,2,161)
Block(-3,23,3,161)
Block(-3,23,5,161)
Block(-3,23,6,161)
Block(-3,23,7,161)
Block(-3,23,8,161)
Block(-3,23,9,161)
Block(-2,0,-2,162:12)
Block(-2,0,0,162:12)
Block(-2,11,1,162:12)
Block(-2,11,2,162:12)
Block(-2,11,4,161)
Block(-2,12,1,161)
Block(-2,12,2,161)
Block(-2,12,3,161)
Block(-2,12,4,161)
Block(-2,12,5,161)
Block(-2,13,2,161)
Block(-2,13,4,161)
Block(-2,15,-9,161)
Block(-2,15,-8,161)
Block(-2,15,-4,162:12)
Block(-2,16,-10,161)
Block(-2,16,-9,161)
Block(-2,16,-8,161)
Block(-2,16,-4,162:12)
Block(-2,17,-9,161)
Block(-2,17,-5,162:12)
Block(-2,17,-4,162:12)
Block(-2,18,-5,162:12)
Block(-2,19,-5,162:12)
Block(-2,20,-5,162:12)
Block(-2,21,-6,162:12)
Block(-2,21,-5,162:12)
Block(-2,21,-4,162:12)
Block(-2,21,0,161)
Block(-2,21,1,161)
Block(-2,21,2,161)
Block(-2,21,6,161)
Block(-2,21,7,161)
Block(-2,21,8,161)
Block(-2,21,9,161)
Block(-2,21,10,161)
Block(-2,22,-12,161)
Block(-2,22,-11,161)
Block(-2,22,-7,162:12)
Block(-2,22,-4,162:12)
Block(-2,22,-1,161)
Block(-2,22,0,161)
Block(-2,22,1,162:12)
Block(-2,22,2,161)
Block(-2,22,3,161)
Block(-2,22,5,161)
Block(-2,22,6,161)
Block(-2,22,7,162:12)
Block(-2,22,8,161)
Block(-2,22,9,161)
Block(-2,22,10,161)
Block(-2,23,-12,161)
Block(-2,23,-11,161)
Block(-2,23,-10,161)
Block(-2,23,0,161)
Block(-2,23,1,161)
Block(-2,23,2,161)
Block(-2,23,6,161)
Block(-2,23,7,161)
Block(-2,23,8,161)
Block(-2,23,9,161)
Block(-2,23,10,161)
Block(-2,24,-11,161)
Block(-1,0,-3,162:12)
Block(-1,0,-2,162:12)
Block(-1,0,-1,162:12)
Block(-1,0,0,162:12)
Block(-1,0,1,162:12)
Block(-1,1,-1,162:12)
Block(-1,1,0,162:12)
Block(-1,2,0,162:12)
Block(-1,10,0,162:12)
Block(-1,11,0,162:12)
Block(-1,12,-3,162:12)
Block(-1,13,-4,162:12)
Block(-1,13,-3,162:12)
Block(-1,14,-8,161)
Block(-1,14,-4,162:12)
Block(-1,15,-10,161)
Block(-1,15,-9,161)
Block(-1,15,-8,161)
Block(-1,15,-7,161)
Block(-1,15,-4,162:12)
Block(-1,16,-11,161)
Block(-1,16,-10,161)
Block(-1,16,-9,161)
Block(-1,16,-8,161)
Block(-1,17,-10,161)
Block(-1,17,-9,161)
Block(-1,17,-8,161)
Block(-1,20,-5,162:12)
Block(-1,20,7,161)
Block(-1,20,8,161)
Block(-1,21,-5,162:12)
Block(-1,21,1,162:12)
Block(-1,21,2,161)
Block(-1,21,3,161)
Block(-1,21,6,162:12)
Block(-1,21,7,161)
Block(-1,21,8,161)
Block(-1,21,9,161)
Block(-1,22,-12,161)
Block(-1,22,-11,161)
Block(-1,22,-10,161)
Block(-1,22,-9,162:12)
Block(-1,22,-8,162:12)
Block(-1,22,0,161)
Block(-1,22,1,161)
Block(-1,22,2,161)
Block(-1,22,3,161)
Block(-1,22,6,161)
Block(-1,22,7,161)
Block(-1,22,8,161)
Block(-1,22,9,161)
Block(-1,22,10,161)
Block(-1,23,-13,161)
Block(-1,23,-12,161)
Block(-1,23,-11,161)
Block(-1,23,-10,162:12)
Block(-1,23,1,161)
Block(-1,23,2,161)
Block(-1,23,3,161)
Block(-1,23,7,161)
Block(-1,23,9,161)
Block(-1,24,-12,161)
Block(-1,24,-11,161)
Block(-1,24,-10,161)
Block(0,0,-2,162:12)
Block(0,0,-1,162:12)
Block(0,0,0,162:12)
Block(0,1,-2,162:12)
Block(0,1,-1,162:12)
Block(0,1,0,162:12)
Block(0,1,1,162:12)
Block(0,2,-1,162:12)
Block(0,2,0,162:12)
Block(0,2,1,162:12)
Block(0,3,-1,162:12)
Block(0,3,0,162:12)
Block(0,3,1,162:12)
Block(0,4,1,162:12)
Block(0,5,1,162:12)
Block(0,6,0,162:12)
Block(0,6,1,162:12)
Block(0,7,1,162:12)
Block(0,9,-2,162:12)
Block(0,9,-1,162:12)
Block(0,10,-3,162:12)
Block(0,10,-2,162:12)
Block(0,10,-1,162:12)
Block(0,11,-3,162:12)
Block(0,11,-2,162:12)
Block(0,12,-3,162:12)
Block(0,14,-9,161)
Block(0,14,-8,161)
Block(0,14,-7,161)
Block(0,15,-11,161)
Block(0,15,-10,161)
Block(0,15,-9,162:12)
Block(0,15,-8,162:12)
Block(0,15,-7,161)
Block(0,16,-11,161)
Block(0,16,-10,162:12)
Block(0,16,-9,161)
Block(0,16,-8,161)
Block(0,16,-7,161)
Block(0,17,-11,161)
Block(0,17,-10,161)
Block(0,17,-9,161)
Block(0,18,-2,161)
Block(0,18,-1,161)
Block(0,19,7,161)
Block(0,19,8,161)
Block(0,20,7,161)
Block(0,20,8,161)
Block(0,21,-13,161)
Block(0,21,-5,162:12)
Block(0,21,-4,161)
Block(0,21,-3,161)
Block(0,21,1,162:12)
Block(0,21,2,162:12)
Block(0,21,6,162:12)
Block(0,21,7,161)
Block(0,21,8,161)
Block(0,21,9,161)
Block(0,22,-13,161)
Block(0,22,-12,161)
Block(0,22,-11,161)
Block(0,22,-10,161)
Block(0,22,-6,162:12)
Block(0,22,-5,162:12)
Block(0,22,-4,161)
Block(0,22,-3,161)
Block(0,22,-2,161)
Block(0,22,1,161)
Block(0,22,2,161)
Block(0,22,3,161)
Block(0,23,-13,161)
Block(0,23,-12,161)
Block(0,23,-11,162:12)
Block(0,23,-10,162:12)
Block(0,23,-4,161)
Block(0,23,-3,161)
Block(0,23,2,161)
Block(0,24,-13,161)
Block(0,24,-12,161)
Block(0,24,-11,161)
Block(0,24,-10,161)
Block(1,0,-1,162:12)
Block(1,0,0,162:12)
Block(1,0,1,162:12)
Block(1,0,2,162:12)
Block(1,1,-1,162:12)
Block(1,1,0,162:12)
Block(1,1,1,162:12)
Block(1,2,-1,162:12)
Block(1,2,0,162:12)
Block(1,2,1,162:12)
Block(1,3,-1,162:12)
Block(1,3,0,162:12)
Block(1,3,1,162:12)
Block(1,4,-1,162:12)
Block(1,4,0,162:12)
Block(1,4,1,162:12)
Block(1,5,-1,162:12)
Block(1,5,0,162:12)
Block(1,5,1,162:12)
Block(1,6,-2,162:12)
Block(1,6,-1,162:12)
Block(1,6,0,162:12)
Block(1,6,1,162:12)
Block(1,7,-2,162:12)
Block(1,7,-1,162:12)
Block(1,7,1,162:12)
Block(1,8,-2,162:12)
Block(1,8,-1,162:12)
Block(1,9,-2,162:12)
Block(1,9,-1,162:12)
Block(1,10,-3,162:12)
Block(1,10,-2,162:12)
Block(1,14,-8,161)
Block(1,15,-11,161)
Block(1,15,-10,161)
Block(1,15,-9,161)
Block(1,15,-8,162:12)
Block(1,15,-7,162:12)
Block(1,16,-11,161)
Block(1,16,-10,161)
Block(1,16,-9,161)
Block(1,16,-8,161)
Block(1,17,-10,161)
Block(1,17,0,161)
Block(1,18,-3,161)
Block(1,18,-2,161)
Block(1,18,-1,161)
Block(1,18,0,161)
Block(1,19,-2,161)
Block(1,19,-1,161)
Block(1,19,8,161)
Block(1,19,9,161)
Block(1,19,10,161)
Block(1,20,2,162:12)
Block(1,20,5,162:12)
Block(1,20,6,162:12)
Block(1,20,7,161)
Block(1,20,8,161)
Block(1,20,9,161)
Block(1,20,10,161)
Block(1,21,-5,161)
Block(1,21,-4,161)
Block(1,21,-3,161)
Block(1,21,-2,161)
Block(1,21,2,162:12)
Block(1,21,6,162:12)
Block(1,21,8,161)
Block(1,21,9,161)
Block(1,22,-12,161)
Block(1,22,-11,161)
Block(1,22,-10,161)
Block(1,22,-6,162:12)
Block(1,22,-5,161)
Block(1,22,-4,162:12)
Block(1,22,-3,161)
Block(1,22,-2,161)
Block(1,23,-13,161)
Block(1,23,-12,161)
Block(1,23,-11,161)
Block(1,23,-10,161)
Block(1,23,-5,161)
Block(1,23,-4,161)
Block(1,23,-3,161)
Block(1,23,-2,161)
Block(1,24,-12,161)
Block(1,24,-11,161)
Block(1,24,-10,161)
Block(2,0,-1,162:12)
Block(2,0,0,161)
Block(2,0,1,162:12)
Block(2,1,-1,162:12)
Block(2,1,0,162:12)
Block(2,2,0,162:12)
Block(2,2,1,162:12)
Block(2,3,0,162:12)
Block(2,3,1,162:12)
Block(2,4,0,162:12)
Block(2,5,0,162:12)
Block(2,6,0,162:12)
Block(2,6,1,162:12)
Block(2,7,0,162:12)
Block(2,7,1,162:12)
Block(2,7,2,162:12)
Block(2,8,0,162:12)
Block(2,8,1,162:12)
Block(2,8,2,162:12)
Block(2,9,2,162:12)
Block(2,10,-3,162:12)
Block(2,10,2,162:12)
Block(2,11,-3,162:12)
Block(2,12,-4,162:12)
Block(2,12,-3,162:12)
Block(2,13,-5,162:12)
Block(2,13,-4,162:12)
Block(2,14,-7,162:12)
Block(2,15,-7,162:12)
Block(2,17,-1,161)
Block(2,18,-1,162:12)
Block(2,18,0,161)
Block(2,19,-1,161)
Block(2,19,5,162:12)
Block(2,19,7,161)
Block(2,19,8,161)
Block(2,19,9,161)
Block(2,19,10,161)
Block(2,20,2,162:12)
Block(2,20,5,162:12)
Block(2,20,7,161)
Block(2,20,8,161)
Block(2,20,9,161)
Block(2,20,10,161)
Block(2,20,11,161)
Block(2,21,-11,161)
Block(2,21,-5,161)
Block(2,21,-4,161)
Block(2,21,-3,161)
Block(2,21,7,161)
Block(2,21,8,161)
Block(2,21,9,161)
Block(2,21,10,161)
Block(2,22,-11,161)
Block(2,22,-8,161)
Block(2,22,-5,161)
Block(2,22,-4,161)
Block(2,22,-3,161)
Block(2,22,-2,161)
Block(2,23,-12,161)
Block(2,23,-11,161)
Block(2,23,-10,161)
Block(2,23,-9,161)
Block(2,23,-8,161)
Block(2,23,-7,162:12)
Block(2,23,-5,161)
Block(2,23,-4,161)
Block(2,23,-3,161)
Block(2,24,-11,161)
Block(2,24,-8,161)
Block(3,0,-2,162:12)
Block(3,0,2,162:12)
Block(3,8,1,162:12)
Block(3,9,1,162:12)
Block(3,9,2,162:12)
Block(3,10,1,162:12)
Block(3,10,2,162:12)
Block(3,10,3,162:12)
Block(3,11,2,162:12)
Block(3,11,3,162:12)
Block(3,12,-3,162:12)
Block(3,12,3,162:12)
Block(3,13,-6,162:12)
Block(3,13,-5,162:12)
Block(3,13,-3,162:12)
Block(3,13,-2,162:12)
Block(3,13,3,162:12)
Block(3,13,4,162:12)
Block(3,14,-7,162:12)
Block(3,14,-6,162:12)
Block(3,14,-2,162:12)
Block(3,14,3,162:12)
Block(3,14,4,162:12)
Block(3,15,4,162:12)
Block(3,16,4,162:12)
Block(3,17,-4,161)
Block(3,17,-2,162:12)
Block(3,18,-5,161)
Block(3,18,-4,161)
Block(3,18,-3,161)
Block(3,18,-1,162:12)
Block(3,18,9,161)
Block(3,19,-4,161)
Block(3,19,2,162:12)
Block(3,19,3,162:12)
Block(3,19,4,162:12)
Block(3,19,7,161)
Block(3,19,8,161)
Block(3,19,9,161)
Block(3,19,10,161)
Block(3,19,11,161)
Block(3,20,1,162:12)
Block(3,20,2,162:12)
Block(3,20,7,161)
Block(3,20,8,162:12)
Block(3,20,9,161)
Block(3,20,10,161)
Block(3,20,11,161)
Block(3,21,-4,161)
Block(3,21,1,162:12)
Block(3,21,7,161)
Block(3,21,8,161)
Block(3,21,9,161)
Block(3,21,10,161)
Block(3,21,11,161)
Block(3,22,-9,161)
Block(3,22,-8,161)
Block(3,22,-7,161)
Block(3,22,-5,161)
Block(3,22,-4,161)
Block(3,22,-3,161)
Block(3,23,-10,161)
Block(3,23,-9,161)
Block(3,23,-8,162:12)
Block(3,23,-7,161)
Block(3,23,-6,161)
Block(3,23,-4,161)
Block(3,24,-9,161)
Block(3,24,-8,161)
Block(3,24,-7,161)
Block(4,13,-5,162:12)
Block(4,14,-8,162:12)
Block(4,14,-7,162:12)
Block(4,14,-2,162:12)
Block(4,15,-2,162:12)
Block(4,15,4,162:12)
Block(4,16,-2,162:12)
Block(4,16,4,162:12)
Block(4,17,-5,161)
Block(4,17,-4,161)
Block(4,17,-3,162:12)
Block(4,17,-2,162:12)
Block(4,17,4,162:12)
Block(4,18,-6,161)
Block(4,18,-5,161)
Block(4,18,-4,162:12)
Block(4,18,-3,161)
Block(4,18,4,162:12)
Block(4,19,-5,161)
Block(4,19,-4,161)
Block(4,19,-3,161)
Block(4,19,4,162:12)
Block(4,19,5,162:12)
Block(4,19,6,162:12)
Block(4,19,8,161)
Block(4,19,9,161)
Block(4,19,10,161)
Block(4,20,6,162:12)
Block(4,20,7,162:12)
Block(4,20,8,161)
Block(4,20,9,161)
Block(4,20,10,161)
Block(4,20,11,161)
Block(4,21,-1,161)
Block(4,21,0,162:12)
Block(4,21,1,162:12)
Block(4,21,8,161)
Block(4,21,9,161)
Block(4,21,10,161)
Block(4,22,-10,161)
Block(4,22,-9,161)
Block(4,22,-8,161)
Block(4,22,-7,161)
Block(4,22,-6,161)
Block(4,22,-2,161)
Block(4,22,-1,161)
Block(4,22,0,161)
Block(4,23,-10,161)
Block(4,23,-9,161)
Block(4,23,-8,161)
Block(4,23,-7,161)
Block(4,23,-6,161)
Block(4,23,-3,161)
Block(4,23,-2,161)
Block(4,23,-1,161)
Block(4,24,-10,161)
Block(4,24,-9,161)
Block(4,24,-8,161)
Block(4,24,-7,161)
Block(4,24,-6,161)
Block(4,24,-2,161)
Block(5,13,-5,162:12)
Block(5,13,-4,161)
Block(5,14,-8,162:12)
Block(5,14,-6,161)
Block(5,14,-5,162:12)
Block(5,14,-4,161)
Block(5,14,-3,161)
Block(5,15,-10,161)
Block(5,15,-8,162:12)
Block(5,15,-5,161)
Block(5,15,-4,161)
Block(5,16,-11,161)
Block(5,16,-10,161)
Block(5,16,-9,161)
Block(5,17,-10,161)
Block(5,17,-6,161)
Block(5,17,-5,161)
Block(5,17,-4,161)
Block(5,17,-2,162:12)
Block(5,17,-1,162:12)
Block(5,17,1,161)
Block(5,18,-6,161)
Block(5,18,-5,161)
Block(5,18,-4,161)
Block(5,18,-3,161)
Block(5,18,-1,162:12)
Block(5,18,0,161)
Block(5,18,1,161)
Block(5,18,2,161)
Block(5,18,4,162:12)
Block(5,19,-6,161)
Block(5,19,-5,161)
Block(5,19,-4,161)
Block(5,19,1,161)
Block(5,19,9,161)
Block(5,20,8,161)
Block(5,20,9,161)
Block(5,20,10,161)
Block(5,21,-2,161)
Block(5,21,-1,161)
Block(5,21,0,161)
Block(5,21,9,161)
Block(5,22,-9,161)
Block(5,22,-8,161)
Block(5,22,-7,161)
Block(5,22,-3,161)
Block(5,22,-2,161)
Block(5,22,-1,162:12)
Block(5,22,0,162:12)
Block(5,23,-10,161)
Block(5,23,-9,161)
Block(5,23,-8,161)
Block(5,23,-7,161)
Block(5,23,-6,161)
Block(5,23,-3,161)
Block(5,23,-2,161)
Block(5,23,-1,161)
Block(5,23,0,161)
Block(5,24,-9,161)
Block(5,24,-8,161)
Block(5,24,-7,161)
Block(5,24,-3,161)
Block(5,24,-2,161)
Block(5,24,-1,161)
Block(6,13,-6,161)
Block(6,13,-5,161)
Block(6,13,-4,161)
Block(6,13,-3,161)
Block(6,14,-11,161)
Block(6,14,-7,161)
Block(6,14,-6,161)
Block(6,14,-5,162:12)
Block(6,14,-4,161)
Block(6,14,-3,161)
Block(6,15,-11,161)
Block(6,15,-10,161)
Block(6,15,-9,161)
Block(6,15,-8,162:12)
Block(6,15,-6,161)
Block(6,15,-5,161)
Block(6,15,-4,161)
Block(6,15,-3,161)
Block(6,16,-11,161)
Block(6,16,-10,161)
Block(6,16,-9,161)
Block(6,16,-8,161)
Block(6,16,-5,161)
Block(6,17,-11,161)
Block(6,17,-10,161)
Block(6,17,-9,161)
Block(6,17,-5,161)
Block(6,17,-1,161)
Block(6,17,0,161)
Block(6,17,1,161)
Block(6,17,2,161)
Block(6,18,-6,161)
Block(6,18,-5,161)
Block(6,18,-4,161)
Block(6,18,-2,161)
Block(6,18,-1,162:12)
Block(6,18,0,161)
Block(6,18,1,161)
Block(6,18,2,161)
Block(6,18,4,162:12)
Block(6,19,-5,161)
Block(6,19,-1,161)
Block(6,19,0,161)
Block(6,19,1,161)
Block(6,19,2,161)
Block(6,19,4,162:12)
Block(6,20,9,161)
Block(6,21,-1,161)
Block(6,22,-8,161)
Block(6,22,-2,161)
Block(6,22,-1,161)
Block(6,22,0,161)
Block(6,23,-9,161)
Block(6,23,-8,161)
Block(6,23,-7,161)
Block(6,23,-3,161)
Block(6,23,-2,161)
Block(6,23,-1,161)
Block(6,24,-8,161)
Block(6,24,-2,161)
Block(7,13,-7,161)
Block(7,13,-6,161)
Block(7,13,-5,161)
Block(7,13,-4,161)
Block(7,14,-7,161)
Block(7,14,-6,161)
Block(7,14,-5,161)
Block(7,14,-4,161)
Block(7,14,-3,161)
Block(7,15,-11,161)
Block(7,15,-10,161)
Block(7,15,-9,161)
Block(7,15,-8,161)
Block(7,15,-7,161)
Block(7,15,-6,161)
Block(7,15,-5,161)
Block(7,15,-4,161)
Block(7,16,-11,161)
Block(7,16,-10,161)
Block(7,16,-9,162:12)
Block(7,16,-8,161)
Block(7,16,-6,161)
Block(7,16,-5,161)
Block(7,16,-4,161)
Block(7,16,1,161)
Block(7,17,-10,161)
Block(7,17,-9,161)
Block(7,17,-8,161)
Block(7,17,-2,161)
Block(7,17,-1,161)
Block(7,17,0,161)
Block(7,17,1,161)
Block(7,18,-2,161)
Block(7,18,-1,161)
Block(7,18,0,162:12)
Block(7,18,1,161)
Block(7,18,2,161)
Block(7,19,-2,161)
Block(7,19,-1,161)
Block(7,19,0,161)
Block(7,19,1,161)
Block(7,19,4,162:12)
Block(7,20,4,162:12)
Block(7,20,5,162:12)
Block(8,13,-6,161)
Block(8,14,-7,161)
Block(8,14,-6,161)
Block(8,14,-5,161)
Block(8,14,-4,161)
Block(8,15,-10,161)
Block(8,15,-9,161)
Block(8,15,-8,161)
Block(8,15,-6,161)
Block(8,15,-5,161)
Block(8,15,-4,161)
Block(8,16,-10,161)
Block(8,16,-9,161)
Block(8,16,-8,161)
Block(8,16,-5,161)
Block(8,16,0,161)
Block(8,17,-10,161)
Block(8,17,-9,161)
Block(8,17,-8,161)
Block(8,17,-2,161)
Block(8,17,-1,161)
Block(8,17,0,161)
Block(8,18,-2,161)
Block(8,18,-1,161)
Block(8,18,0,161)
Block(8,18,1,161)
Block(8,19,-2,161)
Block(8,19,-1,161)
Block(8,19,0,161)
Block(8,20,2,161)
Block(8,20,3,162:12)
Block(8,20,5,162:12)
Block(8,20,6,162:12)
Block(8,21,1,161)
Block(8,21,2,162:12)
Block(8,21,3,161)
Block(8,22,2,161)
Block(8,22,9,161)
Block(8,23,8,161)
Block(8,23,9,161)
Block(8,23,10,161)
Block(8,24,9,161)
Block(9,14,-5,161)
Block(9,15,-9,161)
Block(9,15,-5,161)
Block(9,16,-10,161)
Block(9,16,-9,161)
Block(9,16,-8,161)
Block(9,17,-9,161)
Block(9,17,-1,161)
Block(9,18,-2,161)
Block(9,18,-1,161)
Block(9,18,0,161)
Block(9,19,-1,161)
Block(9,20,1,161)
Block(9,20,2,161)
Block(9,20,3,161)
Block(9,20,6,162:12)
Block(9,20,7,162:12)
Block(9,21,0,161)
Block(9,21,1,161)
Block(9,21,2,162:12)
Block(9,21,3,161)
Block(9,21,4,161)
Block(9,21,7,162:12)
Block(9,21,8,162:12)
Block(9,22,-1,161)
Block(9,22,0,161)
Block(9,22,1,161)
Block(9,22,2,161)
Block(9,22,3,161)
Block(9,22,8,162:12)
Block(9,22,9,161)
Block(9,22,10,161)
Block(9,23,0,161)
Block(9,23,7,161)
Block(9,23,8,161)
Block(9,23,9,161)
Block(9,23,10,161)
Block(9,23,11,161)
Block(9,24,8,161)
Block(9,24,9,161)
Block(9,24,10,161)
Block(10,14,-5,161)
Block(10,20,0,161)
Block(10,20,1,161)
Block(10,20,2,161)
Block(10,20,3,161)
Block(10,20,4,161)
Block(10,21,-1,161)
Block(10,21,0,161)
Block(10,21,1,161)
Block(10,21,2,161)
Block(10,21,3,161)
Block(10,21,4,161)
Block(10,21,9,161)
Block(10,21,10,161)
Block(10,22,0,161)
Block(10,22,1,161)
Block(10,22,2,161)
Block(10,22,3,161)
Block(10,22,4,161)
Block(10,22,7,161)
Block(10,22,8,161)
Block(10,22,9,162:12)
Block(10,22,10,161)
Block(10,22,11,161)
Block(10,23,1,161)
Block(10,23,7,161)
Block(10,23,8,161)
Block(10,23,9,162:12)
Block(10,23,10,161)
Block(10,23,11,161)
Block(10,24,7,161)
Block(10,24,8,161)
Block(10,24,9,161)
Block(10,24,10,161)
Block(10,24,11,161)
Block(11,19,3,161)
Block(11,20,1,161)
Block(11,20,2,161)
Block(11,20,3,161)
Block(11,20,4,161)
Block(11,21,0,161)
Block(11,21,1,161)
Block(11,21,2,161)
Block(11,21,3,161)
Block(11,21,4,161)
Block(11,21,10,161)
Block(11,22,1,161)
Block(11,22,2,161)
Block(11,22,3,161)
Block(11,22,8,161)
Block(11,22,9,161)
Block(11,22,10,161)
Block(11,23,7,161)
Block(11,23,8,161)
Block(11,23,9,161)
Block(11,23,10,161)
Block(11,23,11,161)
Block(11,24,8,161)
Block(11,24,9,161)
Block(11,24,10,161)
Block(12,20,2,161)
Block(12,21,1,161)
Block(12,21,2,161)
Block(12,21,9,161)
Block(12,22,9,161)
Block(12,23,8,161)
Block(12,23,9,161)
Block(12,23,10,161)
Block(12,24,9,161)


#######################################################################
# +-----------------------------------------------------------------+ #
# |                             Entities                            | #
# +-----------------------------------------------------------------+ #
#######################################################################

# Entity() spawns an entity instead of a block. The entity is spawned only once when the BO3 is spawned.
# Entities are persistent by default so they don't de-spawn when no player is near, they are only unloaded.
# Usage: Entity(x,y,z,mobName,groupSize,NameTagOrNBTFileName) or Entity(x,y,z,mobName,groupSize)
# Use /tc entities or /otg entities to get a list of entities that can be used as mobName, this includes entities added by other mods.
# NameTagOrNBTFileName can be either a nametag for the mob or an nbt file (such as mymobinfo.nbt or mymobinfo.txt).
# When using a text file you can use the same mob spawning parameters used with the /summon command to equip the
# entity and give it custom attributes etc. You can copy the DATA part of a summon command including surrounding
# curly braces to a .txt file, for instance for: "/summon Skeleton x y z {DATA}"

#######################################################################
# +-----------------------------------------------------------------+ #
# |                            BO3 checks                           | #
# +-----------------------------------------------------------------+ #
#######################################################################

# Require a condition at a certain location in order for the BO3 to be spawned.
# BlockCheck(x,y,z,BlockName[,BlockName[,...]]) - one of the blocks must be at the location
# BlockCheckNot(x,y,z,BlockName[,BlockName[,...]]) - all the blocks must not be at the location
# LightCheck(x,y,z,minLightLevel,maxLightLevel) - light must be between min and max (inclusive)

# You can use "Solid" as a BlockName for matching all solid blocks or "All" to match all blocks that aren't air.

# Examples:
#   BlockCheck(0,-1,0,GRASS,DIRT)  Require grass or dirt just below the object
#   BlockCheck(0,-1,0,Solid)       Require any solid block just below the object
#   BlockCheck(0,-1,0,WOOL)        Require any type of wool just below the object
#   BlockCheck(0,-1,0,WOOL:0)      Require white wool just below the object
#   BlockCheckNot(0,-1,0,WOOL:0)   Require that there is no white wool below the object
#   LightCheck(0,0,0,0,1)          Require almost complete darkness just below the object
BlockCheck(0,-1,0,GRASS,DIRT)
BlockCheck(1,-1,0,Solid)
BlockCheck(1,-1,-1,Solid)
BlockCheck(1,-1,1,Solid)
BlockCheck(0,-1,1,Solid)
BlockCheck(0,-1,-1,Solid)
BlockCheck(-1,-1,1,Solid)
BlockCheck(-1,-1,0,Solid)
BlockCheck(-1,-1,-1,Solid)
BlockCheck(2,-1,2,Solid)
BlockCheck(2,-1,1,Solid)
BlockCheck(2,-1,0,Solid)
BlockCheck(2,-1,-1,Solid)
BlockCheck(2,-1,-2,Solid)
BlockCheck(1,-1,2,Solid)
BlockCheck(1,-1,-2,Solid)
BlockCheck(0,-1,2,Solid)
BlockCheck(0,-1,-2,Solid)
BlockCheck(-1,-1,2,Solid)
BlockCheck(-1,-1,-2,Solid)
BlockCheck(-2,-1,2,Solid)
BlockCheck(-2,-1,1,Solid)
BlockCheck(-2,-1,0,Solid)
BlockCheck(-2,-1,-1,Solid)
BlockCheck(-2,-1,-2,Solid)

