#######################################################################
# +-----------------------------------------------------------------+ #
# |                            BO3 object                           | #
# +-----------------------------------------------------------------+ #
#######################################################################

# The descriptions in this file are accurate only for TerrainControl and OTG.
# For MCW and OTG+ these descriptions are only accurate if the BO3 is used as a CustomObject.
# MCW and OTG+ completely reimplemented CustomStructure, check the MCW/OTG+ documentation for more information.

# This is the config file of a custom object.
# If you add this object correctly to your BiomeConfigs, it will spawn in the world.

# This is the creator of this BO3 object
Author: Unknown

# A short description of this BO3 object
Description: This BO3 was converted from a schematic using OTGEdit. The author and description information of the schematic could not be found. If you know who the author of the schematic is then please add this information.

# The BO3 version, don't change this! It can be used by external applications to do a version check.
Version: 3

# The settings mode, WriteAll, WriteWithoutComments or WriteDisable. See WorldConfig.
SettingsMode: WriteDisable

#######################################################################
# +-----------------------------------------------------------------+ #
# |                          Main settings                          | #
# +-----------------------------------------------------------------+ #
#######################################################################

# This needs to be set to true to spawn the object in the Tree and Sapling resources.
Tree: false

# The frequency of the BO3 from 1 to 200. Tries this many times to spawn this BO3 when using the CustomObject(...) resource.
# Ignored by Tree(..), Sapling(..) and CustomStructure(..)
Frequency: 1

# The rarity of the BO3 from 0 to 100. Each spawn attempt has rarity% chance to succeed when using the CustomObject(...) resource.
# Ignored by Tree(..), Sapling(..) and CustomStructure(..)
Rarity: 10.0

# If you set this to true, the BO3 will be placed with a random rotation.
RotateRandomly: true

# The spawn height of the BO3 - randomY, highestBlock or highestSolidBlock.
SpawnHeight: highestSolidBlock

# The height limits for the BO3.
MinHeight: 60

MaxHeight: 75

# Objects can have other objects attached to it: branches. Branches can also
# have branches attached to it, which can also have branches, etc. This is the
# maximum branch depth for this objects.
MaxBranchDepth: 10

# When spawned with the UseWorld keyword, this BO3 should NOT spawn in the following biomes.
# If you writer.write the BO3 name directly in the BiomeConfigs, this will be ignored.
ExcludedBiomes: All

# To optimise this BO3 for faster loading times you can use Notepad++ to find/replace comments and abbreviate things.
# Notepad++ find/replace with regex:
# Find: ^[#;].* replace to nothing removes all lines starting with # 
# Find: ^\s*$ replace to nothing removes most empty lines 
# Notepad++ find/replace without regex:
# *Warning: This will only work for OTG 1.10.2 v21 / OTG 1.11.2 v6 or higher. B( is not recognised by lower versions.
# Find: Block( replace to B(

#######################################################################
# +-----------------------------------------------------------------+ #
# |                      Source block settings                      | #
# +-----------------------------------------------------------------+ #
#######################################################################

# The block(s) the BO3 should spawn in.
SourceBlocks: STONE:1,STONE:3,STONE:5,DIRT:1,DIRT,SAND,GRASS,DIRT:2,STATIONARY_WATER,HARD_CLAY,STAINED_CLAY,CLAY,SANDSTONE,SAND:1,AIR,STONE,GRAVEL,LONG_GRASS,LONG_GRASS:1,LONG_GRASS:2,DEAD_BUSH,YELLOW_FLOWER,RED_ROSE,BROWN_MUSHROOM,RED_MUSHROOM

# The maximum percentage of the BO3 that can be outside the SourceBlock.
# The BO3 won't be placed on a location with more blocks outside the SourceBlock than this percentage.
MaxPercentageOutsideSourceBlock: 0

# What to do when a block is about to be placed outside the SourceBlock? (dontPlace, placeAnyway)
OutsideSourceBlock: placeAnyway

#######################################################################
# +-----------------------------------------------------------------+ #
# |                              Blocks                             | #
# +-----------------------------------------------------------------+ #
#######################################################################

# All the blocks used in the BO3 are listed here. Possible blocks:
# Block(x,y,z,id[.data][,nbtfile.nbt) or B(x,y,z,id[.data][,nbtfile.nbt)
# RandomBlock(x,y,z,id[:data][,nbtfile.nbt],chance[,id[:data][,nbtfile.nbt],chance[,...]])
# So RandomBlock(0,0,0,CHEST,chest.nbt,50,CHEST,anotherchest.nbt,100) will spawn a chest at
# the BO3 origin, and give it a 50% chance to have the contents of chest.nbt, or, if that
# fails, a 100% percent chance to have the contents of anotherchest.nbt.

Block(-13,24,1,LEAVES:3)
Block(-13,25,-2,LEAVES:3)
Block(-12,24,1,LEAVES:3)
Block(-12,25,-1,LEAVES:3)
Block(-12,25,4,LEAVES:3)
Block(-12,25,6,LEAVES:3)
Block(-12,26,-10,LEAVES:3)
Block(-12,27,-13,LEAVES:3)
Block(-11,23,2,LEAVES:3)
Block(-11,23,5,LEAVES:3)
Block(-11,24,1,LEAVES:3)
Block(-11,24,2,LEAVES:3)
Block(-11,25,-1,LEAVES:3)
Block(-11,25,0,LEAVES:3)
Block(-11,25,1,LEAVES:3)
Block(-11,25,3,LEAVES:3)
Block(-11,25,6,LEAVES:3)
Block(-11,26,-10,LEAVES:3)
Block(-11,26,1,LEAVES:3)
Block(-11,27,-12,LEAVES:3)
Block(-11,27,-7,LEAVES:3)
Block(-11,27,-5,LEAVES:3)
Block(-10,23,5,LEAVES:3)
Block(-10,24,2,LEAVES:3)
Block(-10,24,7,LEAVES:3)
Block(-10,25,-9,LEAVES:3)
Block(-10,25,-6,LEAVES:3)
Block(-10,25,2,LEAVES:3)
Block(-10,25,3,LEAVES:3)
Block(-10,25,4,LEAVES:3)
Block(-10,25,5,LEAVES:3)
Block(-10,26,-10,LEAVES:3)
Block(-10,26,-9,LEAVES:3)
Block(-10,26,-3,LEAVES:3)
Block(-10,26,-2,LEAVES:3)
Block(-10,27,-12,LEAVES:3)
Block(-10,27,-11,LEAVES:3)
Block(-10,27,-10,LEAVES:3)
Block(-10,27,-8,LEAVES:3)
Block(-10,27,-5,LEAVES:3)
Block(-10,28,-10,LEAVES:3)
Block(-9,23,-1,LEAVES:3)
Block(-9,24,-4,LEAVES:3)
Block(-9,24,-3,LEAVES:3)
Block(-9,24,-2,LEAVES:3)
Block(-9,24,-1,LEAVES:3)
Block(-9,24,5,LEAVES:3)
Block(-9,24,6,LEAVES:3)
Block(-9,25,-6,LEAVES:3)
Block(-9,25,2,LEAVES:3)
Block(-9,25,5,LEAVES:3)
Block(-9,25,6,LEAVES:3)
Block(-9,26,-9,LEAVES:3)
Block(-9,26,-4,LEAVES:3)
Block(-9,26,-1,LEAVES:3)
Block(-9,26,2,LEAVES:3)
Block(-9,27,-9,LEAVES:3)
Block(-9,27,-8,LEAVES:3)
Block(-9,27,-7,LEAVES:3)
Block(-9,27,-6,LEAVES:3)
Block(-9,28,-14,LEAVES:3)
Block(-9,28,-13,LEAVES:3)
Block(-8,24,-1,LEAVES:3)
Block(-8,24,0,LEAVES:3)
Block(-8,24,2,17:15)
Block(-8,24,3,LEAVES:3)
Block(-8,24,4,LEAVES:3)
Block(-8,25,-12,LEAVES:3)
Block(-8,25,0,LEAVES:3)
Block(-8,25,1,LEAVES:3)
Block(-8,25,2,LEAVES:3)
Block(-8,25,3,LEAVES:3)
Block(-8,25,6,LEAVES:3)
Block(-8,26,-15,LEAVES:3)
Block(-8,26,-14,LEAVES:3)
Block(-8,26,-13,LEAVES:3)
Block(-8,26,-12,LEAVES:3)
Block(-8,26,-6,LEAVES:3)
Block(-8,26,-5,LEAVES:3)
Block(-8,26,-1,LEAVES:3)
Block(-8,26,0,LEAVES:3)
Block(-8,26,3,LEAVES:3)
Block(-8,27,-9,LEAVES:3)
Block(-8,27,-6,LEAVES:3)
Block(-8,27,-5,LEAVES:3)
Block(-8,28,-12,LEAVES:3)
Block(-8,28,-9,LEAVES:3)
Block(-7,23,5,LEAVES:3)
Block(-7,24,-3,LEAVES:3)
Block(-7,24,1,LEAVES:3)
Block(-7,24,2,17:15)
Block(-7,24,4,LEAVES:3)
Block(-7,24,5,LEAVES:3)
Block(-7,24,6,LEAVES:3)
Block(-7,25,-4,LEAVES:3)
Block(-7,25,-3,LEAVES:3)
Block(-7,25,1,LEAVES:3)
Block(-7,25,2,LEAVES:3)
Block(-7,25,4,LEAVES:3)
Block(-7,26,-12,LEAVES:3)
Block(-7,26,-11,LEAVES:3)
Block(-7,26,-9,17:15)
Block(-7,26,-8,17:15)
Block(-7,26,-7,17:15)
Block(-7,26,1,LEAVES:3)
Block(-7,26,2,LEAVES:3)
Block(-7,26,5,LEAVES:3)
Block(-7,26,8,LEAVES:3)
Block(-7,27,-11,LEAVES:3)
Block(-7,27,-10,LEAVES:3)
Block(-7,27,-9,LEAVES:3)
Block(-7,27,-8,LEAVES:3)
Block(-7,27,-5,LEAVES:3)
Block(-7,27,5,LEAVES:3)
Block(-7,28,-12,LEAVES:3)
Block(-7,28,-11,LEAVES:3)
Block(-7,28,-8,LEAVES:3)
Block(-6,24,-1,LEAVES:3)
Block(-6,24,0,LEAVES:3)
Block(-6,24,2,17:15)
Block(-6,25,-6,LEAVES:3)
Block(-6,25,-2,LEAVES:3)
Block(-6,25,0,LEAVES:3)
Block(-6,25,1,17:15)
Block(-6,25,2,17:15)
Block(-6,26,-14,LEAVES:3)
Block(-6,26,-10,LEAVES:3)
Block(-6,26,-7,17:15)
Block(-6,26,-6,17:15)
Block(-6,26,-5,LEAVES:3)
Block(-6,26,3,LEAVES:3)
Block(-6,26,8,LEAVES:3)
Block(-6,27,-15,LEAVES:3)
Block(-6,27,-14,LEAVES:3)
Block(-6,27,-10,LEAVES:3)
Block(-6,27,-9,LEAVES:3)
Block(-6,27,-7,LEAVES:3)
Block(-6,27,6,LEAVES:3)
Block(-6,27,11,LEAVES:3)
Block(-6,27,13,LEAVES:3)
Block(-6,28,-10,LEAVES:3)
Block(-6,28,-9,LEAVES:3)
Block(-6,28,-6,LEAVES:3)
Block(-5,23,-1,LEAVES:3)
Block(-5,23,2,LEAVES:3)
Block(-5,24,-1,LEAVES:3)
Block(-5,24,2,LEAVES:3)
Block(-5,24,5,LEAVES:3)
Block(-5,24,6,LEAVES:3)
Block(-5,25,-6,17:15)
Block(-5,25,-5,17:15)
Block(-5,25,1,17:15)
Block(-5,25,2,LEAVES:3)
Block(-5,25,3,LEAVES:3)
Block(-5,25,9,LEAVES:3)
Block(-5,25,12,LEAVES:3)
Block(-5,26,-12,LEAVES:3)
Block(-5,26,-11,LEAVES:3)
Block(-5,26,-9,LEAVES:3)
Block(-5,26,-6,17:15)
Block(-5,26,1,LEAVES:3)
Block(-5,26,3,LEAVES:3)
Block(-5,26,4,LEAVES:3)
Block(-5,26,8,LEAVES:3)
Block(-5,26,9,LEAVES:3)
Block(-5,27,-13,LEAVES:3)
Block(-5,27,-11,LEAVES:3)
Block(-5,27,-10,LEAVES:3)
Block(-5,27,2,LEAVES:3)
Block(-5,27,6,LEAVES:3)
Block(-5,27,7,LEAVES:3)
Block(-5,27,8,LEAVES:3)
Block(-5,27,10,LEAVES:3)
Block(-5,27,13,LEAVES:3)
Block(-5,28,-8,LEAVES:3)
Block(-5,28,-1,LEAVES:3)
Block(-5,28,8,LEAVES:3)
Block(-4,24,-2,LEAVES:3)
Block(-4,24,-1,LEAVES:3)
Block(-4,24,2,LEAVES:3)
Block(-4,24,3,LEAVES:3)
Block(-4,24,4,LEAVES:3)
Block(-4,25,-12,LEAVES:3)
Block(-4,25,-9,LEAVES:3)
Block(-4,25,-5,17:15)
Block(-4,25,-4,17:15)
Block(-4,25,0,17:15)
Block(-4,25,1,17:15)
Block(-4,25,12,LEAVES:3)
Block(-4,26,-12,LEAVES:3)
Block(-4,26,-9,LEAVES:3)
Block(-4,26,-6,LEAVES:3)
Block(-4,26,-5,LEAVES:3)
Block(-4,26,1,LEAVES:3)
Block(-4,26,4,LEAVES:3)
Block(-4,26,5,LEAVES:3)
Block(-4,26,6,LEAVES:3)
Block(-4,26,9,LEAVES:3)
Block(-4,26,14,LEAVES:3)
Block(-4,27,-10,LEAVES:3)
Block(-4,27,-9,LEAVES:3)
Block(-4,27,-8,LEAVES:3)
Block(-4,27,2,LEAVES:3)
Block(-4,27,9,LEAVES:3)
Block(-4,27,10,LEAVES:3)
Block(-4,27,11,LEAVES:3)
Block(-4,27,12,LEAVES:3)
Block(-4,28,-10,LEAVES:3)
Block(-4,28,-8,LEAVES:3)
Block(-4,28,-7,LEAVES:3)
Block(-4,28,0,LEAVES:3)
Block(-4,28,4,LEAVES:3)
Block(-4,28,5,LEAVES:3)
Block(-4,28,7,LEAVES:3)
Block(-3,24,-2,LEAVES:3)
Block(-3,24,-1,17:15)
Block(-3,24,0,17:15)
Block(-3,24,1,LEAVES:3)
Block(-3,24,3,LEAVES:3)
Block(-3,25,-4,17:15)
Block(-3,25,-3,17:15)
Block(-3,25,0,17:15)
Block(-3,25,6,LEAVES:3)
Block(-3,26,-13,LEAVES:3)
Block(-3,26,-12,LEAVES:3)
Block(-3,26,-9,LEAVES:3)
Block(-3,26,-8,LEAVES:3)
Block(-3,26,-7,LEAVES:3)
Block(-3,26,-6,LEAVES:3)
Block(-3,26,1,LEAVES:3)
Block(-3,26,2,LEAVES:3)
Block(-3,26,3,LEAVES:3)
Block(-3,26,4,LEAVES:3)
Block(-3,26,5,LEAVES:3)
Block(-3,26,6,LEAVES:3)
Block(-3,26,12,LEAVES:3)
Block(-3,26,13,LEAVES:3)
Block(-3,27,-9,LEAVES:3)
Block(-3,27,2,LEAVES:3)
Block(-3,27,3,LEAVES:3)
Block(-3,27,9,LEAVES:3)
Block(-3,27,12,LEAVES:3)
Block(-3,27,13,LEAVES:3)
Block(-3,28,-10,LEAVES:3)
Block(-3,28,-7,LEAVES:3)
Block(-3,28,-6,LEAVES:3)
Block(-3,28,-5,LEAVES:3)
Block(-3,28,0,LEAVES:3)
Block(-3,28,1,LEAVES:3)
Block(-3,28,2,LEAVES:3)
Block(-3,28,4,LEAVES:3)
Block(-3,28,6,LEAVES:3)
Block(-3,28,7,LEAVES:3)
Block(-3,28,9,LEAVES:3)
Block(-3,29,2,LEAVES:3)
Block(-2,23,3,LEAVES:3)
Block(-2,24,-3,17:15)
Block(-2,24,-2,17:15)
Block(-2,24,-1,17:15)
Block(-2,24,0,LEAVES:3)
Block(-2,24,3,LEAVES:3)
Block(-2,24,4,LEAVES:3)
Block(-2,25,-3,17:15)
Block(-2,26,-13,LEAVES:3)
Block(-2,26,-10,LEAVES:3)
Block(-2,26,-8,LEAVES:3)
Block(-2,26,-6,LEAVES:3)
Block(-2,26,2,LEAVES:3)
Block(-2,26,6,LEAVES:3)
Block(-2,26,7,17:15)
Block(-2,26,8,17:15)
Block(-2,26,9,17:15)
Block(-2,26,10,LEAVES:3)
Block(-2,26,11,LEAVES:3)
Block(-2,27,-8,LEAVES:3)
Block(-2,27,-3,LEAVES:3)
Block(-2,27,-1,LEAVES:3)
Block(-2,27,3,LEAVES:3)
Block(-2,27,7,LEAVES:3)
Block(-2,27,8,LEAVES:3)
Block(-2,27,9,LEAVES:3)
Block(-2,27,10,LEAVES:3)
Block(-2,27,13,LEAVES:3)
Block(-2,28,-10,LEAVES:3)
Block(-2,28,-9,LEAVES:3)
Block(-2,28,3,LEAVES:3)
Block(-2,28,4,LEAVES:3)
Block(-2,28,5,LEAVES:3)
Block(-2,28,6,LEAVES:3)
Block(-2,28,7,LEAVES:3)
Block(-2,28,10,LEAVES:3)
Block(-2,29,-2,LEAVES:3)
Block(-2,29,-1,LEAVES:3)
Block(-1,0,0,17:15)
Block(-1,1,0,17:15)
Block(-1,24,-2,17:15)
Block(-1,25,-8,LEAVES:3)
Block(-1,25,-5,LEAVES:3)
Block(-1,25,-2,LEAVES:3)
Block(-1,25,6,17:15)
Block(-1,25,7,17:15)
Block(-1,25,12,LEAVES:3)
Block(-1,26,-11,LEAVES:3)
Block(-1,26,-8,LEAVES:3)
Block(-1,26,-7,LEAVES:3)
Block(-1,26,-6,LEAVES:3)
Block(-1,26,-5,LEAVES:3)
Block(-1,26,0,LEAVES:3)
Block(-1,26,2,LEAVES:3)
Block(-1,26,4,LEAVES:3)
Block(-1,26,7,17:15)
Block(-1,26,8,LEAVES:3)
Block(-1,26,11,LEAVES:3)
Block(-1,26,12,LEAVES:3)
Block(-1,26,13,LEAVES:3)
Block(-1,27,-8,LEAVES:3)
Block(-1,27,-7,LEAVES:3)
Block(-1,27,-6,LEAVES:3)
Block(-1,27,-4,LEAVES:3)
Block(-1,27,-3,LEAVES:3)
Block(-1,27,-2,LEAVES:3)
Block(-1,27,-1,LEAVES:3)
Block(-1,27,0,LEAVES:3)
Block(-1,27,3,17:15)
Block(-1,27,4,LEAVES:3)
Block(-1,27,6,LEAVES:3)
Block(-1,27,7,LEAVES:3)
Block(-1,27,8,LEAVES:3)
Block(-1,27,9,LEAVES:3)
Block(-1,27,11,LEAVES:3)
Block(-1,28,-9,LEAVES:3)
Block(-1,28,-6,LEAVES:3)
Block(-1,28,3,LEAVES:3)
Block(-1,28,6,LEAVES:3)
Block(-1,28,7,LEAVES:3)
Block(-1,28,8,LEAVES:3)
Block(-1,28,9,LEAVES:3)
Block(-1,28,12,LEAVES:3)
Block(-1,29,0,LEAVES:3)
Block(-1,29,3,LEAVES:3)
Block(0,0,-1,17:15)
Block(0,0,0,17:15)
Block(0,0,1,17:3)
Block(0,1,0,17:15)
Block(0,1,1,17:15)
Block(0,2,0,17:15)
Block(0,2,1,17:15)
Block(0,3,0,17:15)
Block(0,4,0,17:15)
Block(0,5,0,17:15)
Block(0,6,0,17:15)
Block(0,7,0,17:15)
Block(0,8,0,17:15)
Block(0,9,0,17:15)
Block(0,10,0,17:15)
Block(0,23,-1,17:15)
Block(0,24,-2,17:15)
Block(0,24,-1,17:15)
Block(0,25,-2,LEAVES:3)
Block(0,25,6,17:15)
Block(0,26,-5,LEAVES:3)
Block(0,26,0,LEAVES:3)
Block(0,26,6,LEAVES:3)
Block(0,26,7,LEAVES:3)
Block(0,26,9,LEAVES:3)
Block(0,27,-5,LEAVES:3)
Block(0,27,-4,LEAVES:3)
Block(0,27,-3,LEAVES:3)
Block(0,27,-2,LEAVES:3)
Block(0,27,0,LEAVES:3)
Block(0,27,1,LEAVES:3)
Block(0,27,2,17:15)
Block(0,27,3,17:15)
Block(0,27,4,LEAVES:3)
Block(0,27,5,LEAVES:3)
Block(0,27,7,LEAVES:3)
Block(0,27,8,LEAVES:3)
Block(0,28,-10,LEAVES:3)
Block(0,28,-9,LEAVES:3)
Block(0,28,1,LEAVES:3)
Block(0,28,2,LEAVES:3)
Block(0,28,3,LEAVES:3)
Block(0,28,4,LEAVES:3)
Block(0,28,7,LEAVES:3)
Block(0,28,10,LEAVES:3)
Block(0,29,0,LEAVES:3)
Block(0,29,1,LEAVES:3)
Block(0,29,4,LEAVES:3)
Block(1,0,-1,17:15)
Block(1,0,0,17:15)
Block(1,0,1,17:15)
Block(1,1,-1,17:15)
Block(1,1,0,17:15)
Block(1,2,-1,17:15)
Block(1,2,0,17:15)
Block(1,3,-1,17:15)
Block(1,3,0,17:15)
Block(1,4,0,17:15)
Block(1,5,0,17:15)
Block(1,6,0,17:15)
Block(1,7,0,17:15)
Block(1,7,1,17:15)
Block(1,8,0,17:15)
Block(1,8,1,17:15)
Block(1,9,0,17:15)
Block(1,9,1,17:15)
Block(1,10,0,17:15)
Block(1,10,1,17:15)
Block(1,11,0,17:15)
Block(1,11,1,17:15)
Block(1,12,0,17:15)
Block(1,12,1,17:15)
Block(1,13,0,17:15)
Block(1,13,1,17:15)
Block(1,14,0,17:15)
Block(1,14,1,17:15)
Block(1,15,0,17:15)
Block(1,15,1,17:15)
Block(1,16,0,17:15)
Block(1,17,0,17:15)
Block(1,18,0,17:15)
Block(1,19,0,17:15)
Block(1,20,0,17:15)
Block(1,21,0,17:15)
Block(1,22,-1,17:15)
Block(1,22,0,17:15)
Block(1,23,-1,17:15)
Block(1,25,-8,LEAVES:3)
Block(1,25,5,17:15)
Block(1,25,6,17:15)
Block(1,25,9,LEAVES:3)
Block(1,26,-11,LEAVES:3)
Block(1,26,-10,LEAVES:3)
Block(1,26,-9,LEAVES:3)
Block(1,26,-8,LEAVES:3)
Block(1,26,-2,LEAVES:3)
Block(1,26,-1,LEAVES:3)
Block(1,26,2,17:15)
Block(1,26,6,LEAVES:3)
Block(1,26,9,LEAVES:3)
Block(1,26,12,LEAVES:3)
Block(1,26,13,LEAVES:3)
Block(1,27,-13,LEAVES:3)
Block(1,27,-5,LEAVES:3)
Block(1,27,-2,LEAVES:3)
Block(1,27,-1,LEAVES:3)
Block(1,27,2,17:15)
Block(1,27,5,LEAVES:3)
Block(1,27,6,LEAVES:3)
Block(1,27,7,LEAVES:3)
Block(1,27,8,LEAVES:3)
Block(1,27,9,LEAVES:3)
Block(1,27,10,LEAVES:3)
Block(1,28,-8,LEAVES:3)
Block(1,28,-5,LEAVES:3)
Block(1,28,-3,LEAVES:3)
Block(1,28,-2,LEAVES:3)
Block(1,28,2,LEAVES:3)
Block(1,28,3,LEAVES:3)
Block(1,28,5,LEAVES:3)
Block(1,28,8,LEAVES:3)
Block(1,28,10,LEAVES:3)
Block(1,28,11,LEAVES:3)
Block(1,29,2,LEAVES:3)
Block(1,29,3,LEAVES:3)
Block(1,29,6,LEAVES:3)
Block(2,0,0,17:15)
Block(2,1,0,17:15)
Block(2,10,0,17:15)
Block(2,11,0,17:15)
Block(2,12,0,17:15)
Block(2,13,0,17:15)
Block(2,14,0,17:15)
Block(2,15,0,17:15)
Block(2,16,0,17:15)
Block(2,17,-1,17:15)
Block(2,17,0,17:15)
Block(2,18,-1,17:15)
Block(2,18,0,17:15)
Block(2,19,-1,17:15)
Block(2,19,0,17:15)
Block(2,19,1,17:15)
Block(2,20,0,17:15)
Block(2,20,1,17:15)
Block(2,21,0,17:15)
Block(2,21,1,17:15)
Block(2,24,5,17:15)
Block(2,25,2,17:15)
Block(2,25,5,17:15)
Block(2,26,-10,LEAVES:3)
Block(2,26,-8,LEAVES:3)
Block(2,26,-7,LEAVES:3)
Block(2,26,-5,17:15)
Block(2,26,-4,17:15)
Block(2,26,-3,LEAVES:3)
Block(2,26,2,17:15)
Block(2,26,5,LEAVES:3)
Block(2,26,6,LEAVES:3)
Block(2,26,9,LEAVES:3)
Block(2,26,10,LEAVES:3)
Block(2,26,11,LEAVES:3)
Block(2,27,-12,LEAVES:3)
Block(2,27,-7,LEAVES:3)
Block(2,27,-6,LEAVES:3)
Block(2,27,-5,LEAVES:3)
Block(2,27,-4,LEAVES:3)
Block(2,27,-1,LEAVES:3)
Block(2,27,0,LEAVES:3)
Block(2,27,1,LEAVES:3)
Block(2,27,3,LEAVES:3)
Block(2,27,7,LEAVES:3)
Block(2,28,-8,LEAVES:3)
Block(2,28,-7,LEAVES:3)
Block(2,28,-4,LEAVES:3)
Block(2,28,-1,LEAVES:3)
Block(2,28,1,LEAVES:3)
Block(2,28,2,LEAVES:3)
Block(2,28,8,LEAVES:3)
Block(2,28,11,LEAVES:3)
Block(2,28,12,LEAVES:3)
Block(2,28,13,LEAVES:3)
Block(2,29,4,LEAVES:3)
Block(3,16,0,17:15)
Block(3,17,0,17:15)
Block(3,18,0,17:15)
Block(3,18,1,17:15)
Block(3,19,1,17:15)
Block(3,20,1,17:15)
Block(3,21,1,17:15)
Block(3,22,1,17:15)
Block(3,23,0,17:15)
Block(3,23,1,17:15)
Block(3,23,2,17:15)
Block(3,24,-1,17:15)
Block(3,24,2,17:15)
Block(3,24,4,17:15)
Block(3,24,5,17:15)
Block(3,25,-9,LEAVES:3)
Block(3,25,-6,LEAVES:3)
Block(3,25,-2,17:15)
Block(3,25,-1,17:15)
Block(3,25,2,17:15)
Block(3,26,-10,LEAVES:3)
Block(3,26,-9,LEAVES:3)
Block(3,26,-6,LEAVES:3)
Block(3,26,-4,17:15)
Block(3,26,-3,17:15)
Block(3,26,-2,17:15)
Block(3,26,-1,LEAVES:3)
Block(3,26,0,LEAVES:3)
Block(3,26,3,LEAVES:3)
Block(3,26,5,LEAVES:3)
Block(3,26,8,LEAVES:3)
Block(3,26,10,LEAVES:3)
Block(3,27,-12,LEAVES:3)
Block(3,27,-11,LEAVES:3)
Block(3,27,-10,LEAVES:3)
Block(3,27,-8,LEAVES:3)
Block(3,27,-6,LEAVES:3)
Block(3,27,-5,LEAVES:3)
Block(3,27,-3,LEAVES:3)
Block(3,27,0,LEAVES:3)
Block(3,27,3,LEAVES:3)
Block(3,27,6,LEAVES:3)
Block(3,27,7,LEAVES:3)
Block(3,27,8,LEAVES:3)
Block(3,27,13,LEAVES:3)
Block(3,27,15,LEAVES:3)
Block(3,28,-10,LEAVES:3)
Block(3,28,-6,LEAVES:3)
Block(3,28,-5,LEAVES:3)
Block(3,28,-2,LEAVES:3)
Block(3,28,2,LEAVES:3)
Block(3,28,3,LEAVES:3)
Block(3,28,4,LEAVES:3)
Block(3,28,8,LEAVES:3)
Block(3,28,9,LEAVES:3)
Block(3,29,2,LEAVES:3)
Block(3,29,4,LEAVES:3)
Block(3,29,5,LEAVES:3)
Block(4,22,2,17:15)
Block(4,23,-1,17:15)
Block(4,23,0,17:15)
Block(4,23,2,17:15)
Block(4,23,3,17:15)
Block(4,24,-1,17:15)
Block(4,24,4,17:15)
Block(4,25,-6,LEAVES:3)
Block(4,25,10,LEAVES:3)
Block(4,25,11,LEAVES:3)
Block(4,25,14,LEAVES:3)
Block(4,26,-9,LEAVES:3)
Block(4,26,-8,LEAVES:3)
Block(4,26,-7,LEAVES:3)
Block(4,26,-5,LEAVES:3)
Block(4,26,-4,LEAVES:3)
Block(4,26,7,LEAVES:3)
Block(4,26,10,LEAVES:3)
Block(4,26,11,LEAVES:3)
Block(4,27,-9,LEAVES:3)
Block(4,27,-8,LEAVES:3)
Block(4,27,-7,LEAVES:3)
Block(4,27,-6,LEAVES:3)
Block(4,27,-1,LEAVES:3)
Block(4,27,0,LEAVES:3)
Block(4,27,3,LEAVES:3)
Block(4,27,4,LEAVES:3)
Block(4,27,5,LEAVES:3)
Block(4,27,8,LEAVES:3)
Block(4,27,9,LEAVES:3)
Block(4,27,10,LEAVES:3)
Block(4,27,12,LEAVES:3)
Block(4,27,15,LEAVES:3)
Block(4,28,-14,LEAVES:3)
Block(4,28,-13,LEAVES:3)
Block(4,28,-4,LEAVES:3)
Block(4,28,9,LEAVES:3)
Block(4,28,10,LEAVES:3)
Block(4,29,2,LEAVES:3)
Block(4,29,5,LEAVES:3)
Block(4,29,6,LEAVES:3)
Block(4,29,7,LEAVES:3)
Block(5,22,3,17:15)
Block(5,23,3,17:15)
Block(5,24,-3,17:15)
Block(5,24,-2,17:15)
Block(5,24,-1,17:15)
Block(5,24,3,17:15)
Block(5,24,4,17:15)
Block(5,24,5,17:15)
Block(5,25,-12,LEAVES:3)
Block(5,25,-8,LEAVES:3)
Block(5,25,-5,LEAVES:3)
Block(5,25,-3,17:15)
Block(5,25,5,17:15)
Block(5,25,6,17:15)
Block(5,25,7,17:15)
Block(5,25,14,LEAVES:3)
Block(5,26,-15,LEAVES:3)
Block(5,26,-14,LEAVES:3)
Block(5,26,-13,LEAVES:3)
Block(5,26,-12,LEAVES:3)
Block(5,26,-9,17:15)
Block(5,26,-8,17:15)
Block(5,26,-6,LEAVES:3)
Block(5,26,-5,LEAVES:3)
Block(5,26,-2,LEAVES:3)
Block(5,26,-1,LEAVES:3)
Block(5,26,7,17:15)
Block(5,26,11,LEAVES:3)
Block(5,26,16,LEAVES:3)
Block(5,27,-9,LEAVES:3)
Block(5,27,-6,LEAVES:3)
Block(5,27,-5,LEAVES:3)
Block(5,27,-4,LEAVES:3)
Block(5,27,-1,LEAVES:3)
Block(5,27,2,LEAVES:3)
Block(5,27,4,LEAVES:3)
Block(5,27,11,LEAVES:3)
Block(5,27,12,LEAVES:3)
Block(5,27,13,LEAVES:3)
Block(5,27,14,LEAVES:3)
Block(5,28,-12,LEAVES:3)
Block(5,28,-9,LEAVES:3)
Block(5,28,-6,LEAVES:3)
Block(5,28,-4,LEAVES:3)
Block(5,28,-3,LEAVES:3)
Block(5,28,6,LEAVES:3)
Block(5,28,7,LEAVES:3)
Block(5,28,9,LEAVES:3)
Block(5,29,2,LEAVES:3)
Block(5,29,3,LEAVES:3)
Block(6,24,4,17:15)
Block(6,25,-6,17:15)
Block(6,25,-5,17:15)
Block(6,25,-4,17:15)
Block(6,25,-3,17:15)
Block(6,25,8,LEAVES:3)
Block(6,26,-12,LEAVES:3)
Block(6,26,-11,LEAVES:3)
Block(6,26,-9,LEAVES:3)
Block(6,26,-8,17:15)
Block(6,26,-7,17:15)
Block(6,26,-6,17:15)
Block(6,26,-5,LEAVES:3)
Block(6,26,-4,LEAVES:3)
Block(6,26,-3,LEAVES:3)
Block(6,26,4,LEAVES:3)
Block(6,26,5,LEAVES:3)
Block(6,26,6,LEAVES:3)
Block(6,26,7,17:15)
Block(6,26,8,17:15)
Block(6,26,9,17:15)
Block(6,26,10,17:15)
Block(6,26,14,LEAVES:3)
Block(6,26,15,LEAVES:3)
Block(6,27,-11,LEAVES:3)
Block(6,27,-10,LEAVES:3)
Block(6,27,-9,LEAVES:3)
Block(6,27,-8,LEAVES:3)
Block(6,27,-5,LEAVES:3)
Block(6,27,1,LEAVES:3)
Block(6,27,4,LEAVES:3)
Block(6,27,5,LEAVES:3)
Block(6,27,11,LEAVES:3)
Block(6,27,14,LEAVES:3)
Block(6,27,15,LEAVES:3)
Block(6,28,-12,LEAVES:3)
Block(6,28,-11,LEAVES:3)
Block(6,28,-8,LEAVES:3)
Block(6,28,-6,LEAVES:3)
Block(6,28,-3,LEAVES:3)
Block(6,28,-2,LEAVES:3)
Block(6,28,-1,LEAVES:3)
Block(6,28,8,LEAVES:3)
Block(6,28,11,LEAVES:3)
Block(6,29,3,LEAVES:3)
Block(7,24,4,17:15)
Block(7,25,-6,LEAVES:3)
Block(7,25,-4,17:15)
Block(7,25,4,17:15)
Block(7,26,-14,LEAVES:3)
Block(7,26,-10,LEAVES:3)
Block(7,26,-9,LEAVES:3)
Block(7,26,-7,LEAVES:3)
Block(7,26,-6,LEAVES:3)
Block(7,26,-5,LEAVES:3)
Block(7,26,-4,LEAVES:3)
Block(7,26,8,LEAVES:3)
Block(7,26,9,LEAVES:3)
Block(7,26,10,17:15)
Block(7,26,11,17:15)
Block(7,26,12,17:15)
Block(7,26,13,LEAVES:3)
Block(7,27,-15,LEAVES:3)
Block(7,27,-14,LEAVES:3)
Block(7,27,-10,LEAVES:3)
Block(7,27,-9,LEAVES:3)
Block(7,27,-8,LEAVES:3)
Block(7,27,-7,LEAVES:3)
Block(7,27,-3,LEAVES:3)
Block(7,27,-1,LEAVES:3)
Block(7,27,9,LEAVES:3)
Block(7,27,10,LEAVES:3)
Block(7,27,11,LEAVES:3)
Block(7,27,12,LEAVES:3)
Block(7,27,15,LEAVES:3)
Block(7,28,-10,LEAVES:3)
Block(7,28,-9,LEAVES:3)
Block(7,28,-6,LEAVES:3)
Block(7,28,-5,LEAVES:3)
Block(7,28,8,LEAVES:3)
Block(7,28,9,LEAVES:3)
Block(7,28,12,LEAVES:3)
Block(7,29,3,LEAVES:3)
Block(8,25,-5,17:15)
Block(8,25,-4,17:15)
Block(8,25,-2,LEAVES:3)
Block(8,25,0,LEAVES:3)
Block(8,25,3,17:15)
Block(8,25,4,17:15)
Block(8,25,14,LEAVES:3)
Block(8,26,-12,LEAVES:3)
Block(8,26,-11,LEAVES:3)
Block(8,26,-9,LEAVES:3)
Block(8,26,-7,LEAVES:3)
Block(8,26,-6,LEAVES:3)
Block(8,26,-5,LEAVES:3)
Block(8,26,-4,LEAVES:3)
Block(8,26,-3,LEAVES:3)
Block(8,26,6,LEAVES:3)
Block(8,26,10,LEAVES:3)
Block(8,26,13,LEAVES:3)
Block(8,26,14,LEAVES:3)
Block(8,26,15,LEAVES:3)
Block(8,27,-13,LEAVES:3)
Block(8,27,-11,LEAVES:3)
Block(8,27,-10,LEAVES:3)
Block(8,27,-8,LEAVES:3)
Block(8,27,-7,LEAVES:3)
Block(8,27,-6,LEAVES:3)
Block(8,27,-4,LEAVES:3)
Block(8,27,-1,LEAVES:3)
Block(8,27,5,LEAVES:3)
Block(8,27,6,LEAVES:3)
Block(8,27,10,LEAVES:3)
Block(8,27,11,LEAVES:3)
Block(8,27,13,LEAVES:3)
Block(8,28,-8,LEAVES:3)
Block(8,28,-6,LEAVES:3)
Block(8,28,-5,LEAVES:3)
Block(8,28,10,LEAVES:3)
Block(8,28,11,LEAVES:3)
Block(8,28,14,LEAVES:3)
Block(9,25,-12,LEAVES:3)
Block(9,25,-9,LEAVES:3)
Block(9,25,-5,17:15)
Block(9,25,-2,LEAVES:3)
Block(9,25,0,LEAVES:3)
Block(9,25,2,17:15)
Block(9,25,3,17:15)
Block(9,26,-12,LEAVES:3)
Block(9,26,-9,LEAVES:3)
Block(9,26,-6,LEAVES:3)
Block(9,26,-5,17:15)
Block(9,26,-2,LEAVES:3)
Block(9,26,0,LEAVES:3)
Block(9,26,3,LEAVES:3)
Block(9,26,5,LEAVES:3)
Block(9,26,8,LEAVES:3)
Block(9,26,9,LEAVES:3)
Block(9,26,11,LEAVES:3)
Block(9,27,-10,LEAVES:3)
Block(9,27,-9,LEAVES:3)
Block(9,27,-8,LEAVES:3)
Block(9,27,-5,LEAVES:3)
Block(9,27,-4,LEAVES:3)
Block(9,27,-3,LEAVES:3)
Block(9,27,-2,LEAVES:3)
Block(9,27,7,LEAVES:3)
Block(9,27,9,LEAVES:3)
Block(9,27,10,LEAVES:3)
Block(9,28,-10,LEAVES:3)
Block(9,28,-9,LEAVES:3)
Block(9,28,-8,LEAVES:3)
Block(9,28,-7,LEAVES:3)
Block(9,28,-5,LEAVES:3)
Block(9,28,12,LEAVES:3)
Block(10,24,1,LEAVES:3)
Block(10,24,4,LEAVES:3)
Block(10,25,-8,LEAVES:3)
Block(10,25,0,LEAVES:3)
Block(10,25,1,LEAVES:3)
Block(10,25,2,17:15)
Block(10,25,8,LEAVES:3)
Block(10,25,11,LEAVES:3)
Block(10,26,-13,LEAVES:3)
Block(10,26,-12,LEAVES:3)
Block(10,26,-11,LEAVES:3)
Block(10,26,-10,LEAVES:3)
Block(10,26,-9,LEAVES:3)
Block(10,26,-8,LEAVES:3)
Block(10,26,-7,LEAVES:3)
Block(10,26,-5,17:15)
Block(10,26,-2,LEAVES:3)
Block(10,26,-1,LEAVES:3)
Block(10,26,0,LEAVES:3)
Block(10,26,2,LEAVES:3)
Block(10,26,5,LEAVES:3)
Block(10,26,8,LEAVES:3)
Block(10,26,11,LEAVES:3)
Block(10,26,14,LEAVES:3)
Block(10,26,15,LEAVES:3)
Block(10,27,-5,LEAVES:3)
Block(10,27,-2,LEAVES:3)
Block(10,27,-1,LEAVES:3)
Block(10,27,0,LEAVES:3)
Block(10,27,10,LEAVES:3)
Block(10,27,11,LEAVES:3)
Block(10,27,12,LEAVES:3)
Block(10,28,-10,LEAVES:3)
Block(10,28,-8,LEAVES:3)
Block(10,28,-7,LEAVES:3)
Block(10,28,-6,LEAVES:3)
Block(10,28,-5,LEAVES:3)
Block(10,28,10,LEAVES:3)
Block(10,28,12,LEAVES:3)
Block(10,28,13,LEAVES:3)
Block(11,24,4,LEAVES:3)
Block(11,25,1,17:15)
Block(11,25,2,17:15)
Block(11,25,6,LEAVES:3)
Block(11,26,-13,LEAVES:3)
Block(11,26,-10,LEAVES:3)
Block(11,26,-8,LEAVES:3)
Block(11,26,-7,LEAVES:3)
Block(11,26,-5,17:15)
Block(11,26,-4,LEAVES:3)
Block(11,26,-3,LEAVES:3)
Block(11,26,1,LEAVES:3)
Block(11,26,2,LEAVES:3)
Block(11,26,3,LEAVES:3)
Block(11,26,4,LEAVES:3)
Block(11,26,7,LEAVES:3)
Block(11,26,8,LEAVES:3)
Block(11,26,11,LEAVES:3)
Block(11,26,12,LEAVES:3)
Block(11,26,13,LEAVES:3)
Block(11,27,-7,LEAVES:3)
Block(11,27,-6,LEAVES:3)
Block(11,27,-5,LEAVES:3)
Block(11,27,-4,LEAVES:3)
Block(11,27,-3,LEAVES:3)
Block(11,27,-1,LEAVES:3)
Block(11,28,-10,LEAVES:3)
Block(11,28,-9,LEAVES:3)
Block(11,28,-8,LEAVES:3)
Block(11,28,-7,LEAVES:3)
Block(11,28,-4,LEAVES:3)
Block(11,28,10,LEAVES:3)
Block(11,28,13,LEAVES:3)
Block(11,28,14,LEAVES:3)
Block(11,28,15,LEAVES:3)
Block(12,24,-2,LEAVES:3)
Block(12,25,-8,LEAVES:3)
Block(12,25,-5,LEAVES:3)
Block(12,25,-4,LEAVES:3)
Block(12,25,-3,LEAVES:3)
Block(12,25,-2,LEAVES:3)
Block(12,25,1,17:15)
Block(12,25,4,LEAVES:3)
Block(12,25,5,LEAVES:3)
Block(12,26,-11,LEAVES:3)
Block(12,26,-10,LEAVES:3)
Block(12,26,-8,LEAVES:3)
Block(12,26,-7,LEAVES:3)
Block(12,26,-6,LEAVES:3)
Block(12,26,-3,LEAVES:3)
Block(12,26,-2,LEAVES:3)
Block(12,26,-1,LEAVES:3)
Block(12,26,1,LEAVES:3)
Block(12,26,4,LEAVES:3)
Block(12,26,5,LEAVES:3)
Block(12,26,7,LEAVES:3)
Block(12,26,10,LEAVES:3)
Block(12,26,12,LEAVES:3)
Block(12,27,-11,LEAVES:3)
Block(12,27,-10,LEAVES:3)
Block(12,27,-6,LEAVES:3)
Block(12,27,-5,LEAVES:3)
Block(12,27,-3,LEAVES:3)
Block(12,27,-2,LEAVES:3)
Block(12,27,1,LEAVES:3)
Block(12,28,-9,LEAVES:3)
Block(12,28,-6,LEAVES:3)
Block(12,28,-5,LEAVES:3)
Block(12,28,-2,LEAVES:3)
Block(12,28,10,LEAVES:3)
Block(12,28,11,LEAVES:3)
Block(13,25,-2,LEAVES:3)
Block(13,25,-1,LEAVES:3)
Block(13,25,1,17:15)
Block(13,25,2,LEAVES:3)
Block(13,25,3,LEAVES:3)
Block(13,25,12,LEAVES:3)
Block(13,26,-8,LEAVES:3)
Block(13,26,-7,LEAVES:3)
Block(13,26,-5,LEAVES:3)
Block(13,26,-1,LEAVES:3)
Block(13,26,0,LEAVES:3)
Block(13,26,1,LEAVES:3)
Block(13,26,2,LEAVES:3)
Block(13,26,5,LEAVES:3)
Block(13,26,9,LEAVES:3)
Block(13,26,12,LEAVES:3)
Block(13,26,13,LEAVES:3)
Block(13,27,-9,LEAVES:3)
Block(13,27,-7,LEAVES:3)
Block(13,27,-6,LEAVES:3)
Block(13,27,-2,LEAVES:3)
Block(13,27,-1,LEAVES:3)
Block(13,27,2,LEAVES:3)
Block(13,28,-9,LEAVES:3)
Block(13,28,-4,LEAVES:3)
Block(13,28,11,LEAVES:3)
Block(14,24,4,LEAVES:3)
Block(14,25,-8,LEAVES:3)
Block(14,25,-5,LEAVES:3)
Block(14,25,-4,LEAVES:3)
Block(14,25,0,LEAVES:3)
Block(14,25,3,LEAVES:3)
Block(14,25,4,LEAVES:3)
Block(14,25,5,LEAVES:3)
Block(14,26,-8,LEAVES:3)
Block(14,26,-5,LEAVES:3)
Block(14,26,-4,LEAVES:3)
Block(14,26,-2,LEAVES:3)
Block(14,26,-1,LEAVES:3)
Block(14,26,0,LEAVES:3)
Block(14,26,1,LEAVES:3)
Block(14,26,3,LEAVES:3)
Block(14,27,-6,LEAVES:3)
Block(14,27,-5,LEAVES:3)
Block(14,27,-4,LEAVES:3)
Block(14,27,0,LEAVES:3)
Block(14,27,1,LEAVES:3)
Block(14,27,4,LEAVES:3)
Block(14,28,-6,LEAVES:3)
Block(14,28,-4,LEAVES:3)
Block(14,28,-3,LEAVES:3)
Block(14,28,11,LEAVES:3)
Block(15,25,-2,LEAVES:3)
Block(15,25,-1,LEAVES:3)
Block(15,25,1,LEAVES:3)
Block(15,26,-9,LEAVES:3)
Block(15,26,-8,LEAVES:3)
Block(15,26,-5,LEAVES:3)
Block(15,26,-4,LEAVES:3)
Block(15,26,-3,LEAVES:3)
Block(15,26,-1,LEAVES:3)
Block(15,26,0,LEAVES:3)
Block(15,27,2,LEAVES:3)
Block(15,28,-6,LEAVES:3)
Block(15,28,-3,LEAVES:3)
Block(15,28,-2,LEAVES:3)
Block(15,28,-1,LEAVES:3)
Block(16,24,-2,LEAVES:3)
Block(16,24,1,LEAVES:3)
Block(16,25,-2,LEAVES:3)
Block(16,25,1,LEAVES:3)
Block(16,25,4,LEAVES:3)
Block(16,25,5,LEAVES:3)
Block(16,26,-9,LEAVES:3)
Block(16,26,-6,LEAVES:3)
Block(16,26,-4,LEAVES:3)
Block(16,26,0,LEAVES:3)
Block(16,26,1,LEAVES:3)
Block(16,26,2,LEAVES:3)
Block(16,27,0,LEAVES:3)
Block(16,27,2,LEAVES:3)
Block(16,27,3,LEAVES:3)
Block(16,28,-6,LEAVES:3)
Block(16,28,-5,LEAVES:3)
Block(17,25,-4,LEAVES:3)
Block(17,25,-3,LEAVES:3)
Block(17,25,-2,LEAVES:3)
Block(17,25,1,LEAVES:3)
Block(17,25,2,LEAVES:3)
Block(17,25,3,LEAVES:3)
Block(17,26,-7,LEAVES:3)
Block(17,26,-4,LEAVES:3)
Block(17,26,-3,LEAVES:3)
Block(17,27,0,LEAVES:3)
Block(17,27,3,LEAVES:3)
Block(17,27,4,LEAVES:3)
Block(17,27,5,LEAVES:3)
Block(17,28,-5,LEAVES:3)
Block(18,25,-3,LEAVES:3)
Block(18,25,0,LEAVES:3)
Block(18,25,2,LEAVES:3)
Block(18,27,0,LEAVES:3)
Block(18,27,1,LEAVES:3)
Block(18,28,-5,LEAVES:3)
Block(19,24,2,LEAVES:3)
Block(19,25,-1,LEAVES:3)
Block(19,25,2,LEAVES:3)
Block(19,25,3,LEAVES:3)
Block(19,27,1,LEAVES:3)
Block(20,27,1,LEAVES:3)


#######################################################################
# +-----------------------------------------------------------------+ #
# |                             Entities                            | #
# +-----------------------------------------------------------------+ #
#######################################################################

# Entity() spawns an entity instead of a block. The entity is spawned only once when the BO3 is spawned.
# Entities are persistent by default so they don't de-spawn when no player is near, they are only unloaded.
# Usage: Entity(x,y,z,mobName,groupSize,NameTagOrNBTFileName) or Entity(x,y,z,mobName,groupSize)
# Use /tc entities or /otg entities to get a list of entities that can be used as mobName, this includes entities added by other mods.
# NameTagOrNBTFileName can be either a nametag for the mob or an nbt file (such as mymobinfo.nbt or mymobinfo.txt).
# When using a text file you can use the same mob spawning parameters used with the /summon command to equip the
# entity and give it custom attributes etc. You can copy the DATA part of a summon command including surrounding
# curly braces to a .txt file, for instance for: "/summon Skeleton x y z {DATA}"

#######################################################################
# +-----------------------------------------------------------------+ #
# |                            BO3 checks                           | #
# +-----------------------------------------------------------------+ #
#######################################################################

# Require a condition at a certain location in order for the BO3 to be spawned.
# BlockCheck(x,y,z,BlockName[,BlockName[,...]]) - one of the blocks must be at the location
# BlockCheckNot(x,y,z,BlockName[,BlockName[,...]]) - all the blocks must not be at the location
# LightCheck(x,y,z,minLightLevel,maxLightLevel) - light must be between min and max (inclusive)

# You can use "Solid" as a BlockName for matching all solid blocks or "All" to match all blocks that aren't air.

# Examples:
#   BlockCheck(0,-1,0,GRASS,DIRT)  Require grass or dirt just below the object
#   BlockCheck(0,-1,0,Solid)       Require any solid block just below the object
#   BlockCheck(0,-1,0,WOOL)        Require any type of wool just below the object
#   BlockCheck(0,-1,0,WOOL:0)      Require white wool just below the object
#   BlockCheckNot(0,-1,0,WOOL:0)   Require that there is no white wool below the object
#   LightCheck(0,0,0,0,LEAVES:3)          Require almost complete darkness just below the object

BlockCheck(0,-1,0,GRASS,DIRT)
