#######################################################################
# +-----------------------------------------------------------------+ #
# |                            BO3 object                           | #
# +-----------------------------------------------------------------+ #
#######################################################################

# The descriptions in this file are accurate only for TerrainControl and OTG.
# For MCW and OTG+ these descriptions are only accurate if the BO3 is used as a CustomObject.
# MCW and OTG+ completely reimplemented CustomStructure, check the MCW/OTG+ documentation for more information.

# This is the config file of a custom object.
# If you add this object correctly to your BiomeConfigs, it will spawn in the world.

# This is the creator of this BO3 object
Author: Unknown

# A short description of this BO3 object
Description: This BO3 was converted from a schematic using OTGEdit. The author and description information of the schematic could not be found. If you know who the author of the schematic is then please add this information.

# The BO3 version, don't change this! It can be used by external applications to do a version check.
Version: 3

# The settings mode, WriteAll, WriteWithoutComments or WriteDisable. See WorldConfig.
SettingsMode: WriteDisable

#######################################################################
# +-----------------------------------------------------------------+ #
# |                          Main settings                          | #
# +-----------------------------------------------------------------+ #
#######################################################################

# This needs to be set to true to spawn the object in the Tree and Sapling resources.
Tree: false

# The frequency of the BO3 from 1 to 200. Tries this many times to spawn this BO3 when using the CustomObject(...) resource.
# Ignored by Tree(..), Sapling(..) and CustomStructure(..)
Frequency: 1

# The rarity of the BO3 from 0 to 100. Each spawn attempt has rarity% chance to succeed when using the CustomObject(...) resource.
# Ignored by Tree(..), Sapling(..) and CustomStructure(..)
Rarity: 10.0

# If you set this to true, the BO3 will be placed with a random rotation.
RotateRandomly: true

# The spawn height of the BO3 - randomY, highestBlock or highestSolidBlock.
SpawnHeight: highestSolidBlock

# The height limits for the BO3.
MinHeight: 60

MaxHeight: 75

# Objects can have other objects attached to it: branches. Branches can also
# have branches attached to it, which can also have branches, etc. This is the
# maximum branch depth for this objects.
MaxBranchDepth: 10

# When spawned with the UseWorld keyword, this BO3 should NOT spawn in the following biomes.
# If you writer.write the BO3 name directly in the BiomeConfigs, this will be ignored.
ExcludedBiomes: All

# To optimise this BO3 for faster loading times you can use Notepad++ to find/replace comments and abbreviate things.
# Notepad++ find/replace with regex:
# Find: ^[#;].* replace to nothing removes all lines starting with # 
# Find: ^\s*$ replace to nothing removes most empty lines 
# Notepad++ find/replace without regex:
# *Warning: This will only work for OTG 1.10.2 v21 / OTG 1.11.2 v6 or higher. B( is not recognised by lower versions.
# Find: Block( replace to B(

#######################################################################
# +-----------------------------------------------------------------+ #
# |                      Source block settings                      | #
# +-----------------------------------------------------------------+ #
#######################################################################

# The block(s) the BO3 should spawn in.
STONE:1,STONE:3,STONE:5,DIRT:1,DIRT,SAND,GRASS,DIRT:2,STATIONARY_WATER,HARD_CLAY,STAINED_CLAY,CLAY,SANDSTONE,SAND:1,AIR,STONE,GRAVEL,LONG_GRASS,LONG_GRASS:1,LONG_GRASS:2,DEAD_BUSH,YELLOW_FLOWER,RED_ROSE,BROWN_MUSHROOM,RED_MUSHROOM

# The maximum percentage of the BO3 that can be outside the SourceBlock.
# The BO3 won't be placed on a location with more blocks outside the SourceBlock than this percentage.
MaxPercentageOutsideSourceBlock: 0

# What to do when a block is about to be placed outside the SourceBlock? (dontPlace, placeAnyway)
OutsideSourceBlock: placeAnyway

#######################################################################
# +-----------------------------------------------------------------+ #
# |                              Blocks                             | #
# +-----------------------------------------------------------------+ #
#######################################################################

# All the blocks used in the BO3 are listed here. Possible blocks:
# Block(x,y,z,id[.data][,nbtfile.nbt) or B(x,y,z,id[.data][,nbtfile.nbt)
# RandomBlock(x,y,z,id[:data][,nbtfile.nbt],chance[,id[:data][,nbtfile.nbt],chance[,...]])
# So RandomBlock(0,0,0,CHEST,chest.nbt,50,CHEST,anotherchest.nbt,100) will spawn a chest at
# the BO3 origin, and give it a 50% chance to have the contents of chest.nbt, or, if that
# fails, a 100% percent chance to have the contents of anotherchest.nbt.

Block(-15,20,-1,LEAVES:3)
Block(-15,21,-3,LEAVES:3)
Block(-15,21,2,LEAVES:3)
Block(-15,21,4,LEAVES:3)
Block(-15,22,10,LEAVES:3)
Block(-15,23,7,LEAVES:3)
Block(-14,19,0,LEAVES:3)
Block(-14,19,3,LEAVES:3)
Block(-14,20,-1,LEAVES:3)
Block(-14,20,0,LEAVES:3)
Block(-14,21,-3,LEAVES:3)
Block(-14,21,-2,LEAVES:3)
Block(-14,21,-1,LEAVES:3)
Block(-14,21,1,LEAVES:3)
Block(-14,21,4,LEAVES:3)
Block(-14,22,-1,LEAVES:3)
Block(-14,22,10,LEAVES:3)
Block(-14,23,8,LEAVES:3)
Block(-14,23,13,LEAVES:3)
Block(-14,23,15,LEAVES:3)
Block(-13,19,3,LEAVES:3)
Block(-13,20,0,LEAVES:3)
Block(-13,20,5,LEAVES:3)
Block(-13,21,0,LEAVES:3)
Block(-13,21,1,LEAVES:3)
Block(-13,21,2,LEAVES:3)
Block(-13,21,3,LEAVES:3)
Block(-13,21,11,LEAVES:3)
Block(-13,21,14,LEAVES:3)
Block(-13,22,-10,LEAVES:3)
Block(-13,22,-5,LEAVES:3)
Block(-13,22,-4,LEAVES:3)
Block(-13,22,10,LEAVES:3)
Block(-13,22,11,LEAVES:3)
Block(-13,23,-13,LEAVES:3)
Block(-13,23,8,LEAVES:3)
Block(-13,23,9,LEAVES:3)
Block(-13,23,10,LEAVES:3)
Block(-13,23,12,LEAVES:3)
Block(-13,23,15,LEAVES:3)
Block(-13,24,10,LEAVES:3)
Block(-12,19,-3,LEAVES:3)
Block(-12,20,-6,LEAVES:3)
Block(-12,20,-5,LEAVES:3)
Block(-12,20,-4,LEAVES:3)
Block(-12,20,-3,LEAVES:3)
Block(-12,20,3,LEAVES:3)
Block(-12,20,4,LEAVES:3)
Block(-12,21,0,LEAVES:3)
Block(-12,21,3,LEAVES:3)
Block(-12,21,4,LEAVES:3)
Block(-12,21,14,LEAVES:3)
Block(-12,22,-10,LEAVES:3)
Block(-12,22,-3,LEAVES:3)
Block(-12,22,0,LEAVES:3)
Block(-12,22,11,LEAVES:3)
Block(-12,22,16,LEAVES:3)
Block(-12,23,-12,LEAVES:3)
Block(-12,23,-7,LEAVES:3)
Block(-12,23,-5,LEAVES:3)
Block(-12,23,11,LEAVES:3)
Block(-12,23,12,LEAVES:3)
Block(-12,23,13,LEAVES:3)
Block(-12,23,14,LEAVES:3)
Block(-12,24,6,LEAVES:3)
Block(-12,24,7,LEAVES:3)
Block(-11,20,-3,LEAVES:3)
Block(-11,20,-2,LEAVES:3)
Block(-11,20,0,17:15)
Block(-11,20,1,LEAVES:3)
Block(-11,20,2,LEAVES:3)
Block(-11,21,-9,LEAVES:3)
Block(-11,21,-6,LEAVES:3)
Block(-11,21,-2,LEAVES:3)
Block(-11,21,-1,LEAVES:3)
Block(-11,21,0,LEAVES:3)
Block(-11,21,1,LEAVES:3)
Block(-11,21,4,LEAVES:3)
Block(-11,21,8,LEAVES:3)
Block(-11,22,-10,LEAVES:3)
Block(-11,22,-9,LEAVES:3)
Block(-11,22,-3,LEAVES:3)
Block(-11,22,-2,LEAVES:3)
Block(-11,22,1,LEAVES:3)
Block(-11,22,5,LEAVES:3)
Block(-11,22,6,LEAVES:3)
Block(-11,22,7,LEAVES:3)
Block(-11,22,8,LEAVES:3)
Block(-11,22,14,LEAVES:3)
Block(-11,22,15,LEAVES:3)
Block(-11,23,-12,LEAVES:3)
Block(-11,23,-11,LEAVES:3)
Block(-11,23,-10,LEAVES:3)
Block(-11,23,-8,LEAVES:3)
Block(-11,23,-5,LEAVES:3)
Block(-11,23,11,LEAVES:3)
Block(-11,23,14,LEAVES:3)
Block(-11,23,15,LEAVES:3)
Block(-11,24,-10,LEAVES:3)
Block(-11,24,8,LEAVES:3)
Block(-11,24,11,LEAVES:3)
Block(-10,19,3,LEAVES:3)
Block(-10,20,-5,LEAVES:3)
Block(-10,20,-1,LEAVES:3)
Block(-10,20,0,17:15)
Block(-10,20,2,LEAVES:3)
Block(-10,20,3,LEAVES:3)
Block(-10,20,4,LEAVES:3)
Block(-10,21,-6,LEAVES:3)
Block(-10,21,-5,LEAVES:3)
Block(-10,21,-1,LEAVES:3)
Block(-10,21,0,LEAVES:3)
Block(-10,21,2,LEAVES:3)
Block(-10,22,-9,LEAVES:3)
Block(-10,22,-4,LEAVES:3)
Block(-10,22,-1,LEAVES:3)
Block(-10,22,0,LEAVES:3)
Block(-10,22,3,LEAVES:3)
Block(-10,22,8,LEAVES:3)
Block(-10,22,9,17:15)
Block(-10,22,10,17:15)
Block(-10,22,11,17:15)
Block(-10,22,12,LEAVES:3)
Block(-10,22,13,LEAVES:3)
Block(-10,23,-9,LEAVES:3)
Block(-10,23,-8,LEAVES:3)
Block(-10,23,-7,LEAVES:3)
Block(-10,23,-6,LEAVES:3)
Block(-10,23,9,LEAVES:3)
Block(-10,23,10,LEAVES:3)
Block(-10,23,11,LEAVES:3)
Block(-10,23,12,LEAVES:3)
Block(-10,23,15,LEAVES:3)
Block(-10,24,-14,LEAVES:3)
Block(-10,24,-13,LEAVES:3)
Block(-10,24,8,LEAVES:3)
Block(-10,24,9,LEAVES:3)
Block(-10,24,12,LEAVES:3)
Block(-9,20,-3,LEAVES:3)
Block(-9,20,-2,LEAVES:3)
Block(-9,20,0,17:15)
Block(-9,21,-12,LEAVES:3)
Block(-9,21,-4,LEAVES:3)
Block(-9,21,-2,LEAVES:3)
Block(-9,21,-1,LEAVES:3)
Block(-9,21,14,LEAVES:3)
Block(-9,22,-15,LEAVES:3)
Block(-9,22,-14,LEAVES:3)
Block(-9,22,-13,LEAVES:3)
Block(-9,22,-12,LEAVES:3)
Block(-9,22,-6,LEAVES:3)
Block(-9,22,-5,LEAVES:3)
Block(-9,22,1,LEAVES:3)
Block(-9,22,6,LEAVES:3)
Block(-9,22,7,17:15)
Block(-9,22,8,17:15)
Block(-9,22,9,17:15)
Block(-9,22,10,LEAVES:3)
Block(-9,22,13,LEAVES:3)
Block(-9,22,14,LEAVES:3)
Block(-9,22,15,LEAVES:3)
Block(-9,23,-9,LEAVES:3)
Block(-9,23,-6,LEAVES:3)
Block(-9,23,-5,LEAVES:3)
Block(-9,23,5,LEAVES:3)
Block(-9,23,6,LEAVES:3)
Block(-9,23,10,LEAVES:3)
Block(-9,23,11,LEAVES:3)
Block(-9,23,13,LEAVES:3)
Block(-9,24,-12,LEAVES:3)
Block(-9,24,-9,LEAVES:3)
Block(-9,24,10,LEAVES:3)
Block(-9,24,11,LEAVES:3)
Block(-9,24,14,LEAVES:3)
Block(-8,19,-3,LEAVES:3)
Block(-8,19,0,LEAVES:3)
Block(-8,20,-3,LEAVES:3)
Block(-8,20,0,17:15)
Block(-8,20,3,LEAVES:3)
Block(-8,20,4,LEAVES:3)
Block(-8,21,-1,LEAVES:3)
Block(-8,21,0,17:15)
Block(-8,21,1,LEAVES:3)
Block(-8,21,6,17:15)
Block(-8,22,-12,LEAVES:3)
Block(-8,22,-11,LEAVES:3)
Block(-8,22,-9,17:15)
Block(-8,22,-8,17:15)
Block(-8,22,-7,LEAVES:3)
Block(-8,22,-1,LEAVES:3)
Block(-8,22,1,LEAVES:3)
Block(-8,22,2,LEAVES:3)
Block(-8,22,6,17:15)
Block(-8,22,7,17:15)
Block(-8,22,8,LEAVES:3)
Block(-8,22,9,LEAVES:3)
Block(-8,22,11,LEAVES:3)
Block(-8,23,-11,LEAVES:3)
Block(-8,23,-10,LEAVES:3)
Block(-8,23,-9,LEAVES:3)
Block(-8,23,-8,LEAVES:3)
Block(-8,23,-5,LEAVES:3)
Block(-8,23,7,LEAVES:3)
Block(-8,23,9,LEAVES:3)
Block(-8,23,10,LEAVES:3)
Block(-8,24,-12,LEAVES:3)
Block(-8,24,-11,LEAVES:3)
Block(-8,24,-8,LEAVES:3)
Block(-8,24,12,LEAVES:3)
Block(-7,20,-4,LEAVES:3)
Block(-7,20,-3,LEAVES:3)
Block(-7,20,0,LEAVES:3)
Block(-7,20,1,LEAVES:3)
Block(-7,20,2,LEAVES:3)
Block(-7,21,-6,LEAVES:3)
Block(-7,21,0,17:15)
Block(-7,21,1,17:15)
Block(-7,21,6,17:15)
Block(-7,21,8,LEAVES:3)
Block(-7,21,11,LEAVES:3)
Block(-7,22,-14,LEAVES:3)
Block(-7,22,-10,LEAVES:3)
Block(-7,22,-8,17:15)
Block(-7,22,-7,17:15)
Block(-7,22,-6,17:15)
Block(-7,22,-5,LEAVES:3)
Block(-7,22,-1,LEAVES:3)
Block(-7,22,2,LEAVES:3)
Block(-7,22,3,LEAVES:3)
Block(-7,22,4,LEAVES:3)
Block(-7,22,8,LEAVES:3)
Block(-7,22,11,LEAVES:3)
Block(-7,22,14,LEAVES:3)
Block(-7,22,15,LEAVES:3)
Block(-7,23,-15,LEAVES:3)
Block(-7,23,-14,LEAVES:3)
Block(-7,23,-10,LEAVES:3)
Block(-7,23,-9,LEAVES:3)
Block(-7,23,-7,LEAVES:3)
Block(-7,23,10,LEAVES:3)
Block(-7,23,11,LEAVES:3)
Block(-7,23,12,LEAVES:3)
Block(-7,24,-10,LEAVES:3)
Block(-7,24,-9,LEAVES:3)
Block(-7,24,-6,LEAVES:3)
Block(-7,24,10,LEAVES:3)
Block(-7,24,12,LEAVES:3)
Block(-7,24,13,LEAVES:3)
Block(-6,20,-4,LEAVES:3)
Block(-6,20,-1,LEAVES:3)
Block(-6,20,1,LEAVES:3)
Block(-6,21,1,17:15)
Block(-6,21,5,17:15)
Block(-6,21,6,17:15)
Block(-6,22,-12,LEAVES:3)
Block(-6,22,-11,LEAVES:3)
Block(-6,22,-9,LEAVES:3)
Block(-6,22,-6,17:15)
Block(-6,22,-5,17:15)
Block(-6,22,-4,17:15)
Block(-6,22,-1,LEAVES:3)
Block(-6,22,0,LEAVES:3)
Block(-6,22,7,LEAVES:3)
Block(-6,22,8,LEAVES:3)
Block(-6,22,11,LEAVES:3)
Block(-6,22,12,LEAVES:3)
Block(-6,22,13,LEAVES:3)
Block(-6,23,-13,LEAVES:3)
Block(-6,23,-11,LEAVES:3)
Block(-6,23,-10,LEAVES:3)
Block(-6,23,5,LEAVES:3)
Block(-6,24,-13,LEAVES:3)
Block(-6,24,-8,LEAVES:3)
Block(-6,24,10,LEAVES:3)
Block(-6,24,13,LEAVES:3)
Block(-6,24,14,LEAVES:3)
Block(-6,24,15,LEAVES:3)
Block(-5,19,1,LEAVES:3)
Block(-5,20,-2,LEAVES:3)
Block(-5,20,1,LEAVES:3)
Block(-5,20,2,LEAVES:3)
Block(-5,21,-12,LEAVES:3)
Block(-5,21,-9,LEAVES:3)
Block(-5,21,-3,17:15)
Block(-5,21,1,17:15)
Block(-5,21,4,17:15)
Block(-5,21,5,17:15)
Block(-5,22,-12,LEAVES:3)
Block(-5,22,-9,LEAVES:3)
Block(-5,22,-6,LEAVES:3)
Block(-5,22,-5,LEAVES:3)
Block(-5,22,-4,17:15)
Block(-5,22,-3,17:15)
Block(-5,22,0,LEAVES:3)
Block(-5,22,7,LEAVES:3)
Block(-5,22,8,LEAVES:3)
Block(-5,22,10,LEAVES:3)
Block(-5,22,12,LEAVES:3)
Block(-5,23,-10,LEAVES:3)
Block(-5,23,-9,LEAVES:3)
Block(-5,23,-8,LEAVES:3)
Block(-5,23,6,LEAVES:3)
Block(-5,23,11,LEAVES:3)
Block(-5,23,13,LEAVES:3)
Block(-5,24,-12,LEAVES:3)
Block(-5,24,-10,LEAVES:3)
Block(-5,24,-8,LEAVES:3)
Block(-5,24,-7,LEAVES:3)
Block(-5,24,-5,LEAVES:3)
Block(-5,24,10,LEAVES:3)
Block(-5,24,11,LEAVES:3)
Block(-4,20,1,17:15)
Block(-4,20,3,17:15)
Block(-4,21,-3,17:15)
Block(-4,21,1,17:15)
Block(-4,21,4,17:15)
Block(-4,21,5,17:15)
Block(-4,21,6,17:15)
Block(-4,21,7,17:15)
Block(-4,21,9,LEAVES:3)
Block(-4,21,12,LEAVES:3)
Block(-4,22,-13,LEAVES:3)
Block(-4,22,-12,LEAVES:3)
Block(-4,22,-9,LEAVES:3)
Block(-4,22,-8,LEAVES:3)
Block(-4,22,-7,LEAVES:3)
Block(-4,22,-6,LEAVES:3)
Block(-4,22,0,LEAVES:3)
Block(-4,22,7,17:15)
Block(-4,22,8,LEAVES:3)
Block(-4,22,9,LEAVES:3)
Block(-4,22,12,LEAVES:3)
Block(-4,22,13,LEAVES:3)
Block(-4,23,-10,LEAVES:3)
Block(-4,23,-9,LEAVES:3)
Block(-4,23,2,LEAVES:3)
Block(-4,23,6,LEAVES:3)
Block(-4,23,7,LEAVES:3)
Block(-4,23,8,LEAVES:3)
Block(-4,23,10,LEAVES:3)
Block(-4,23,13,LEAVES:3)
Block(-4,24,-12,LEAVES:3)
Block(-4,24,-11,LEAVES:3)
Block(-4,24,-10,LEAVES:3)
Block(-4,24,-8,LEAVES:3)
Block(-4,24,-7,LEAVES:3)
Block(-4,24,-6,LEAVES:3)
Block(-4,24,-5,LEAVES:3)
Block(-4,24,-1,LEAVES:3)
Block(-4,24,8,LEAVES:3)
Block(-4,24,11,LEAVES:3)
Block(-4,25,-10,LEAVES:3)
Block(-4,25,-9,LEAVES:3)
Block(-3,20,-2,17:15)
Block(-3,20,1,17:15)
Block(-3,20,2,17:15)
Block(-3,20,3,17:15)
Block(-3,21,-5,17:15)
Block(-3,21,-4,17:15)
Block(-3,21,-3,17:15)
Block(-3,21,-2,17:15)
Block(-3,21,12,LEAVES:3)
Block(-3,22,-13,LEAVES:3)
Block(-3,22,-10,LEAVES:3)
Block(-3,22,-8,LEAVES:3)
Block(-3,22,-6,17:15)
Block(-3,22,-5,17:15)
Block(-3,22,7,17:15)
Block(-3,22,8,17:15)
Block(-3,22,9,LEAVES:3)
Block(-3,22,14,LEAVES:3)
Block(-3,23,-9,LEAVES:3)
Block(-3,23,-4,LEAVES:3)
Block(-3,23,2,LEAVES:3)
Block(-3,23,9,LEAVES:3)
Block(-3,23,10,LEAVES:3)
Block(-3,23,11,LEAVES:3)
Block(-3,23,12,LEAVES:3)
Block(-3,24,-10,LEAVES:3)
Block(-3,24,-9,LEAVES:3)
Block(-3,24,-8,LEAVES:3)
Block(-3,24,-7,LEAVES:3)
Block(-3,24,-6,LEAVES:3)
Block(-3,24,0,LEAVES:3)
Block(-3,24,4,LEAVES:3)
Block(-3,24,5,LEAVES:3)
Block(-3,24,7,LEAVES:3)
Block(-3,24,11,LEAVES:3)
Block(-3,25,-14,LEAVES:3)
Block(-3,25,-13,LEAVES:3)
Block(-3,25,-8,LEAVES:3)
Block(-3,25,-3,LEAVES:3)
Block(-3,25,-1,LEAVES:3)
Block(-2,13,1,17:15)
Block(-2,14,1,17:15)
Block(-2,15,1,17:15)
Block(-2,16,1,17:15)
Block(-2,17,1,17:15)
Block(-2,18,0,17:15)
Block(-2,18,1,17:15)
Block(-2,19,-1,17:15)
Block(-2,19,0,17:15)
Block(-2,19,1,17:15)
Block(-2,20,-2,17:15)
Block(-2,20,-1,17:15)
Block(-2,20,1,17:15)
Block(-2,21,-8,LEAVES:3)
Block(-2,21,-2,17:15)
Block(-2,21,6,LEAVES:3)
Block(-2,22,-12,LEAVES:3)
Block(-2,22,-11,LEAVES:3)
Block(-2,22,-8,17:15)
Block(-2,22,-7,17:15)
Block(-2,22,-6,17:15)
Block(-2,22,3,LEAVES:3)
Block(-2,22,4,LEAVES:3)
Block(-2,22,5,LEAVES:3)
Block(-2,22,6,LEAVES:3)
Block(-2,22,8,17:15)
Block(-2,22,9,17:15)
Block(-2,22,12,LEAVES:3)
Block(-2,22,13,LEAVES:3)
Block(-2,23,-15,LEAVES:3)
Block(-2,23,-14,LEAVES:3)
Block(-2,23,-13,LEAVES:3)
Block(-2,23,-12,LEAVES:3)
Block(-2,23,-9,17:15)
Block(-2,23,-8,17:15)
Block(-2,23,-6,LEAVES:3)
Block(-2,23,-5,LEAVES:3)
Block(-2,23,-2,LEAVES:3)
Block(-2,23,2,LEAVES:3)
Block(-2,23,3,LEAVES:3)
Block(-2,23,9,LEAVES:3)
Block(-2,23,12,LEAVES:3)
Block(-2,23,13,LEAVES:3)
Block(-2,24,-9,LEAVES:3)
Block(-2,24,-6,LEAVES:3)
Block(-2,24,-5,LEAVES:3)
Block(-2,24,0,LEAVES:3)
Block(-2,24,1,LEAVES:3)
Block(-2,24,2,LEAVES:3)
Block(-2,24,4,LEAVES:3)
Block(-2,24,6,LEAVES:3)
Block(-2,24,7,LEAVES:3)
Block(-2,24,9,LEAVES:3)
Block(-2,25,-12,LEAVES:3)
Block(-2,25,-9,LEAVES:3)
Block(-2,25,-8,LEAVES:3)
Block(-2,25,-7,LEAVES:3)
Block(-2,25,-6,LEAVES:3)
Block(-2,25,-4,LEAVES:3)
Block(-2,25,-1,LEAVES:3)
Block(-2,25,2,LEAVES:3)
Block(-2,26,-6,LEAVES:3)
Block(-1,0,0,17:15)
Block(-1,1,0,17:15)
Block(-1,2,-1,17:15)
Block(-1,2,0,17:15)
Block(-1,3,-1,17:15)
Block(-1,3,0,17:15)
Block(-1,4,-1,17:15)
Block(-1,4,0,17:15)
Block(-1,5,-1,17:15)
Block(-1,5,0,17:15)
Block(-1,6,-1,17:15)
Block(-1,6,0,17:15)
Block(-1,7,-1,17:15)
Block(-1,7,0,17:15)
Block(-1,8,-1,17:15)
Block(-1,8,0,17:15)
Block(-1,9,-1,17:15)
Block(-1,9,0,17:15)
Block(-1,10,-1,17:15)
Block(-1,10,0,17:15)
Block(-1,11,0,17:15)
Block(-1,11,1,17:15)
Block(-1,12,0,17:15)
Block(-1,12,1,17:15)
Block(-1,13,0,17:15)
Block(-1,13,1,17:15)
Block(-1,14,0,17:15)
Block(-1,14,1,17:15)
Block(-1,15,0,17:15)
Block(-1,15,1,17:15)
Block(-1,16,0,17:15)
Block(-1,16,1,17:15)
Block(-1,17,0,17:15)
Block(-1,17,1,17:15)
Block(-1,18,0,17:15)
Block(-1,18,1,17:15)
Block(-1,19,0,17:15)
Block(-1,21,-2,17:15)
Block(-1,22,-2,17:15)
Block(-1,22,6,LEAVES:3)
Block(-1,22,7,LEAVES:3)
Block(-1,22,9,17:15)
Block(-1,22,10,LEAVES:3)
Block(-1,22,11,LEAVES:3)
Block(-1,23,-12,LEAVES:3)
Block(-1,23,-11,LEAVES:3)
Block(-1,23,-10,17:15)
Block(-1,23,-9,17:15)
Block(-1,23,-8,LEAVES:3)
Block(-1,23,-7,LEAVES:3)
Block(-1,23,-3,17:15)
Block(-1,23,-2,17:15)
Block(-1,23,3,LEAVES:3)
Block(-1,23,7,LEAVES:3)
Block(-1,23,8,LEAVES:3)
Block(-1,23,9,LEAVES:3)
Block(-1,23,10,LEAVES:3)
Block(-1,23,13,LEAVES:3)
Block(-1,24,-11,LEAVES:3)
Block(-1,24,-10,LEAVES:3)
Block(-1,24,-9,LEAVES:3)
Block(-1,24,-8,LEAVES:3)
Block(-1,24,-5,LEAVES:3)
Block(-1,24,0,LEAVES:3)
Block(-1,24,3,LEAVES:3)
Block(-1,24,4,LEAVES:3)
Block(-1,24,5,LEAVES:3)
Block(-1,24,6,LEAVES:3)
Block(-1,24,7,LEAVES:3)
Block(-1,24,10,LEAVES:3)
Block(-1,25,-12,LEAVES:3)
Block(-1,25,-11,LEAVES:3)
Block(-1,25,-8,LEAVES:3)
Block(-1,25,-5,LEAVES:3)
Block(-1,25,-4,LEAVES:3)
Block(-1,25,-3,LEAVES:3)
Block(-1,25,-2,LEAVES:3)
Block(-1,25,-1,LEAVES:3)
Block(-1,26,-10,LEAVES:3)
Block(-1,26,-9,LEAVES:3)
Block(0,0,-1,17:15)
Block(0,0,0,17:15)
Block(0,0,1,17:15)
Block(0,1,-1,17:15)
Block(0,1,0,17:15)
Block(0,2,-1,17:15)
Block(0,2,0,17:15)
Block(0,3,0,17:15)
Block(0,4,0,17:15)
Block(0,5,0,17:15)
Block(0,6,0,17:15)
Block(0,7,0,17:15)
Block(0,8,0,17:15)
Block(0,9,0,17:15)
Block(0,10,0,17:15)
Block(0,11,0,17:15)
Block(0,12,0,17:15)
Block(0,17,0,17:15)
Block(0,18,-1,17:15)
Block(0,18,0,17:15)
Block(0,18,1,17:15)
Block(0,19,-1,17:15)
Block(0,19,1,17:15)
Block(0,20,1,17:15)
Block(0,21,1,17:15)
Block(0,21,2,17:15)
Block(0,21,12,LEAVES:3)
Block(0,22,-6,LEAVES:3)
Block(0,22,0,LEAVES:3)
Block(0,22,2,17:15)
Block(0,22,4,LEAVES:3)
Block(0,22,8,LEAVES:3)
Block(0,22,11,LEAVES:3)
Block(0,22,12,LEAVES:3)
Block(0,22,13,LEAVES:3)
Block(0,23,-14,LEAVES:3)
Block(0,23,-10,LEAVES:3)
Block(0,23,-8,LEAVES:3)
Block(0,23,-7,LEAVES:3)
Block(0,23,-6,LEAVES:3)
Block(0,23,-5,LEAVES:3)
Block(0,23,-3,17:15)
Block(0,23,-2,LEAVES:3)
Block(0,23,-1,LEAVES:3)
Block(0,23,0,LEAVES:3)
Block(0,23,2,17:15)
Block(0,23,3,17:15)
Block(0,23,4,LEAVES:3)
Block(0,23,6,LEAVES:3)
Block(0,23,7,LEAVES:3)
Block(0,23,8,LEAVES:3)
Block(0,23,9,LEAVES:3)
Block(0,23,11,LEAVES:3)
Block(0,24,-15,LEAVES:3)
Block(0,24,-14,LEAVES:3)
Block(0,24,-11,LEAVES:3)
Block(0,24,-10,LEAVES:3)
Block(0,24,-9,LEAVES:3)
Block(0,24,-8,LEAVES:3)
Block(0,24,-7,LEAVES:3)
Block(0,24,-4,17:15)
Block(0,24,-3,17:15)
Block(0,24,-2,LEAVES:3)
Block(0,24,-1,LEAVES:3)
Block(0,24,3,LEAVES:3)
Block(0,24,6,LEAVES:3)
Block(0,24,7,LEAVES:3)
Block(0,24,8,LEAVES:3)
Block(0,24,9,LEAVES:3)
Block(0,24,12,LEAVES:3)
Block(0,25,-10,LEAVES:3)
Block(0,25,-9,LEAVES:3)
Block(0,25,-6,LEAVES:3)
Block(0,25,-5,LEAVES:3)
Block(0,25,-2,LEAVES:3)
Block(0,25,-1,LEAVES:3)
Block(0,25,0,LEAVES:3)
Block(0,25,3,LEAVES:3)
Block(0,26,-8,LEAVES:3)
Block(0,26,-5,LEAVES:3)
Block(1,0,0,17:3)
Block(1,1,0,17:15)
Block(1,19,-2,17:15)
Block(1,19,-1,17:15)
Block(1,20,-3,17:15)
Block(1,20,-2,17:15)
Block(1,22,6,LEAVES:3)
Block(1,22,7,LEAVES:3)
Block(1,22,9,LEAVES:3)
Block(1,23,-12,LEAVES:3)
Block(1,23,-11,LEAVES:3)
Block(1,23,-9,LEAVES:3)
Block(1,23,0,LEAVES:3)
Block(1,23,1,LEAVES:3)
Block(1,23,3,17:15)
Block(1,23,4,17:15)
Block(1,23,5,LEAVES:3)
Block(1,23,7,LEAVES:3)
Block(1,23,8,LEAVES:3)
Block(1,24,-13,LEAVES:3)
Block(1,24,-11,LEAVES:3)
Block(1,24,-10,LEAVES:3)
Block(1,24,-8,LEAVES:3)
Block(1,24,-7,LEAVES:3)
Block(1,24,-5,17:15)
Block(1,24,-4,17:15)
Block(1,24,-3,LEAVES:3)
Block(1,24,1,LEAVES:3)
Block(1,24,2,LEAVES:3)
Block(1,24,3,LEAVES:3)
Block(1,24,4,LEAVES:3)
Block(1,24,7,LEAVES:3)
Block(1,24,10,LEAVES:3)
Block(1,25,-8,LEAVES:3)
Block(1,25,-7,LEAVES:3)
Block(1,25,-6,LEAVES:3)
Block(1,25,-5,LEAVES:3)
Block(1,25,-4,LEAVES:3)
Block(1,25,-1,LEAVES:3)
Block(1,25,0,LEAVES:3)
Block(1,25,1,LEAVES:3)
Block(1,25,4,LEAVES:3)
Block(1,26,-8,LEAVES:3)
Block(1,26,-7,LEAVES:3)
Block(1,26,-4,LEAVES:3)
Block(2,20,-5,17:15)
Block(2,20,-4,17:15)
Block(2,20,-3,17:15)
Block(2,21,6,LEAVES:3)
Block(2,21,9,LEAVES:3)
Block(2,22,-12,LEAVES:3)
Block(2,22,-9,LEAVES:3)
Block(2,22,6,LEAVES:3)
Block(2,22,9,LEAVES:3)
Block(2,22,12,LEAVES:3)
Block(2,22,13,LEAVES:3)
Block(2,23,-12,LEAVES:3)
Block(2,23,-9,LEAVES:3)
Block(2,23,-6,LEAVES:3)
Block(2,23,-5,LEAVES:3)
Block(2,23,-2,LEAVES:3)
Block(2,23,2,LEAVES:3)
Block(2,23,5,LEAVES:3)
Block(2,23,6,LEAVES:3)
Block(2,23,7,LEAVES:3)
Block(2,23,8,LEAVES:3)
Block(2,23,9,LEAVES:3)
Block(2,23,10,LEAVES:3)
Block(2,24,-10,LEAVES:3)
Block(2,24,-9,LEAVES:3)
Block(2,24,-8,LEAVES:3)
Block(2,24,-6,LEAVES:3)
Block(2,24,-3,LEAVES:3)
Block(2,24,-2,LEAVES:3)
Block(2,24,-1,LEAVES:3)
Block(2,24,2,LEAVES:3)
Block(2,24,3,LEAVES:3)
Block(2,24,5,LEAVES:3)
Block(2,24,8,LEAVES:3)
Block(2,24,10,LEAVES:3)
Block(2,24,11,LEAVES:3)
Block(2,25,-11,LEAVES:3)
Block(2,25,-10,LEAVES:3)
Block(2,25,-8,LEAVES:3)
Block(2,25,-7,LEAVES:3)
Block(2,25,-6,LEAVES:3)
Block(2,25,-5,LEAVES:3)
Block(2,25,-3,LEAVES:3)
Block(2,25,2,LEAVES:3)
Block(2,25,3,LEAVES:3)
Block(2,25,6,LEAVES:3)
Block(2,26,-6,LEAVES:3)
Block(2,26,-5,LEAVES:3)
Block(2,26,-2,LEAVES:3)
Block(3,20,-5,17:15)
Block(3,21,-6,17:15)
Block(3,21,-5,17:15)
Block(3,21,-4,17:15)
Block(3,22,-14,LEAVES:3)
Block(3,22,5,LEAVES:3)
Block(3,22,6,LEAVES:3)
Block(3,22,9,LEAVES:3)
Block(3,22,10,LEAVES:3)
Block(3,22,11,LEAVES:3)
Block(3,23,-17,LEAVES:3)
Block(3,23,-13,LEAVES:3)
Block(3,23,-12,LEAVES:3)
Block(3,23,-9,LEAVES:3)
Block(3,23,-8,LEAVES:3)
Block(3,23,-7,LEAVES:3)
Block(3,23,0,LEAVES:3)
Block(3,23,1,LEAVES:3)
Block(3,23,3,LEAVES:3)
Block(3,24,-8,LEAVES:3)
Block(3,24,-7,LEAVES:3)
Block(3,24,-5,LEAVES:3)
Block(3,24,-1,LEAVES:3)
Block(3,24,1,LEAVES:3)
Block(3,24,2,LEAVES:3)
Block(3,24,8,LEAVES:3)
Block(3,24,11,LEAVES:3)
Block(3,24,12,LEAVES:3)
Block(3,24,13,LEAVES:3)
Block(3,25,-10,LEAVES:3)
Block(3,25,-9,LEAVES:3)
Block(3,25,-7,LEAVES:3)
Block(3,25,-6,LEAVES:3)
Block(3,25,-5,LEAVES:3)
Block(3,25,4,LEAVES:3)
Block(3,26,-4,LEAVES:3)
Block(4,21,-7,17:15)
Block(4,21,-6,17:15)
Block(4,21,-4,17:15)
Block(4,21,-3,17:15)
Block(4,21,-2,17:15)
Block(4,21,-1,17:15)
Block(4,21,0,17:15)
Block(4,22,-14,LEAVES:3)
Block(4,22,0,17:15)
Block(4,22,3,LEAVES:3)
Block(4,22,5,LEAVES:3)
Block(4,22,8,LEAVES:3)
Block(4,22,10,LEAVES:3)
Block(4,23,-16,LEAVES:3)
Block(4,23,-13,LEAVES:3)
Block(4,23,-11,LEAVES:3)
Block(4,23,-10,LEAVES:3)
Block(4,23,-9,LEAVES:3)
Block(4,23,-8,LEAVES:3)
Block(4,23,-5,LEAVES:3)
Block(4,23,0,LEAVES:3)
Block(4,23,3,LEAVES:3)
Block(4,23,6,LEAVES:3)
Block(4,23,7,LEAVES:3)
Block(4,24,-8,LEAVES:3)
Block(4,24,-5,LEAVES:3)
Block(4,24,-2,LEAVES:3)
Block(4,24,-1,LEAVES:3)
Block(4,24,2,LEAVES:3)
Block(4,24,3,LEAVES:3)
Block(4,24,4,LEAVES:3)
Block(4,24,8,LEAVES:3)
Block(4,24,9,LEAVES:3)
Block(4,25,-10,LEAVES:3)
Block(4,25,-9,LEAVES:3)
Block(4,25,-6,LEAVES:3)
Block(4,25,-5,LEAVES:3)
Block(4,25,-4,LEAVES:3)
Block(4,25,2,LEAVES:3)
Block(4,25,4,LEAVES:3)
Block(4,25,5,LEAVES:3)
Block(4,26,-6,LEAVES:3)
Block(4,26,-4,LEAVES:3)
Block(4,26,-3,LEAVES:3)
Block(5,21,-13,LEAVES:3)
Block(5,21,-10,LEAVES:3)
Block(5,21,-8,17:15)
Block(5,21,-7,17:15)
Block(5,21,-3,17:15)
Block(5,21,10,LEAVES:3)
Block(5,22,-14,LEAVES:3)
Block(5,22,-13,LEAVES:3)
Block(5,22,-8,LEAVES:3)
Block(5,22,-3,17:15)
Block(5,22,0,17:15)
Block(5,22,1,17:15)
Block(5,22,2,17:15)
Block(5,22,7,LEAVES:3)
Block(5,22,10,LEAVES:3)
Block(5,22,11,LEAVES:3)
Block(5,23,-16,LEAVES:3)
Block(5,23,-15,LEAVES:3)
Block(5,23,-14,LEAVES:3)
Block(5,23,-12,LEAVES:3)
Block(5,23,-11,LEAVES:3)
Block(5,23,-9,LEAVES:3)
Block(5,23,-8,LEAVES:3)
Block(5,23,-7,LEAVES:3)
Block(5,23,-1,LEAVES:3)
Block(5,23,0,LEAVES:3)
Block(5,23,3,LEAVES:3)
Block(5,23,4,LEAVES:3)
Block(5,23,5,LEAVES:3)
Block(5,24,-14,LEAVES:3)
Block(5,24,-9,LEAVES:3)
Block(5,24,-8,LEAVES:3)
Block(5,24,-5,LEAVES:3)
Block(5,24,-4,LEAVES:3)
Block(5,24,-3,LEAVES:3)
Block(5,24,9,LEAVES:3)
Block(5,25,-9,LEAVES:3)
Block(5,25,2,LEAVES:3)
Block(5,25,5,LEAVES:3)
Block(5,25,6,LEAVES:3)
Block(5,25,7,LEAVES:3)
Block(5,26,-6,LEAVES:3)
Block(5,26,-3,LEAVES:3)
Block(5,26,-2,LEAVES:3)
Block(5,26,-1,LEAVES:3)
Block(6,21,-10,17:15)
Block(6,21,-9,17:15)
Block(6,21,-8,17:15)
Block(6,22,-13,LEAVES:3)
Block(6,22,-12,17:15)
Block(6,22,-11,17:15)
Block(6,22,-10,17:15)
Block(6,22,-8,LEAVES:3)
Block(6,22,-4,LEAVES:3)
Block(6,22,-3,17:15)
Block(6,22,-2,17:15)
Block(6,22,2,17:15)
Block(6,22,3,17:15)
Block(6,22,4,17:15)
Block(6,23,-13,LEAVES:3)
Block(6,23,-12,LEAVES:3)
Block(6,23,-11,LEAVES:3)
Block(6,23,-10,LEAVES:3)
Block(6,23,-7,LEAVES:3)
Block(6,23,-1,LEAVES:3)
Block(6,23,2,LEAVES:3)
Block(6,23,4,LEAVES:3)
Block(6,24,-18,LEAVES:3)
Block(6,24,-17,LEAVES:3)
Block(6,24,-9,LEAVES:3)
Block(6,24,-6,LEAVES:3)
Block(6,24,-4,LEAVES:3)
Block(6,24,9,LEAVES:3)
Block(6,25,-9,LEAVES:3)
Block(6,25,2,LEAVES:3)
Block(6,25,3,LEAVES:3)
Block(6,26,-6,LEAVES:3)
Block(6,26,-5,LEAVES:3)
Block(7,21,-16,LEAVES:3)
Block(7,22,-19,LEAVES:3)
Block(7,22,-18,LEAVES:3)
Block(7,22,-17,LEAVES:3)
Block(7,22,-16,LEAVES:3)
Block(7,22,-13,17:15)
Block(7,22,-12,17:15)
Block(7,22,-10,LEAVES:3)
Block(7,22,-9,LEAVES:3)
Block(7,22,-4,LEAVES:3)
Block(7,22,-2,17:15)
Block(7,22,4,LEAVES:3)
Block(7,23,-13,LEAVES:3)
Block(7,23,-10,LEAVES:3)
Block(7,23,-9,LEAVES:3)
Block(7,23,-6,LEAVES:3)
Block(7,23,-4,LEAVES:3)
Block(7,23,-1,LEAVES:3)
Block(7,23,1,LEAVES:3)
Block(7,23,4,LEAVES:3)
Block(7,23,5,LEAVES:3)
Block(7,24,-16,LEAVES:3)
Block(7,24,-13,LEAVES:3)
Block(7,24,-7,LEAVES:3)
Block(7,24,-4,LEAVES:3)
Block(7,24,-3,LEAVES:3)
Block(7,25,3,LEAVES:3)
Block(7,26,-5,LEAVES:3)
Block(8,21,-3,LEAVES:3)
Block(8,21,0,LEAVES:3)
Block(8,22,-16,LEAVES:3)
Block(8,22,-15,LEAVES:3)
Block(8,22,-13,17:15)
Block(8,22,-12,LEAVES:3)
Block(8,22,-11,LEAVES:3)
Block(8,22,-4,LEAVES:3)
Block(8,22,-3,LEAVES:3)
Block(8,22,-2,17:15)
Block(8,23,-15,LEAVES:3)
Block(8,23,-14,LEAVES:3)
Block(8,23,-13,LEAVES:3)
Block(8,23,-12,LEAVES:3)
Block(8,23,-9,LEAVES:3)
Block(8,23,-6,LEAVES:3)
Block(8,23,-5,LEAVES:3)
Block(8,23,-4,LEAVES:3)
Block(8,23,-2,LEAVES:3)
Block(8,23,1,LEAVES:3)
Block(8,24,-16,LEAVES:3)
Block(8,24,-15,LEAVES:3)
Block(8,24,-12,LEAVES:3)
Block(8,24,-4,LEAVES:3)
Block(8,25,3,LEAVES:3)
Block(8,26,-5,LEAVES:3)
Block(9,21,-10,LEAVES:3)
Block(9,21,0,LEAVES:3)
Block(9,22,-18,LEAVES:3)
Block(9,22,-14,LEAVES:3)
Block(9,22,-11,LEAVES:3)
Block(9,22,-10,LEAVES:3)
Block(9,22,-9,LEAVES:3)
Block(9,22,-3,17:15)
Block(9,22,-2,17:15)
Block(9,22,2,LEAVES:3)
Block(9,23,-19,LEAVES:3)
Block(9,23,-18,LEAVES:3)
Block(9,23,-14,LEAVES:3)
Block(9,23,-13,LEAVES:3)
Block(9,23,-11,LEAVES:3)
Block(9,23,-3,LEAVES:3)
Block(9,23,-2,LEAVES:3)
Block(9,23,-1,LEAVES:3)
Block(9,23,0,LEAVES:3)
Block(9,24,-14,LEAVES:3)
Block(9,24,-13,LEAVES:3)
Block(9,24,-10,LEAVES:3)
Block(9,24,-8,LEAVES:3)
Block(9,24,-7,LEAVES:3)
Block(10,21,-6,LEAVES:3)
Block(10,22,-16,LEAVES:3)
Block(10,22,-15,LEAVES:3)
Block(10,22,-13,LEAVES:3)
Block(10,22,-9,LEAVES:3)
Block(10,22,-8,LEAVES:3)
Block(10,22,-7,LEAVES:3)
Block(10,22,-6,LEAVES:3)
Block(10,22,-3,17:15)
Block(10,22,0,LEAVES:3)
Block(10,22,1,LEAVES:3)
Block(10,23,-17,LEAVES:3)
Block(10,23,-15,LEAVES:3)
Block(10,23,-14,LEAVES:3)
Block(10,23,-3,LEAVES:3)
Block(10,23,0,LEAVES:3)
Block(10,23,1,LEAVES:3)
Block(10,24,-12,LEAVES:3)
Block(10,24,-6,LEAVES:3)
Block(10,24,-3,LEAVES:3)
Block(11,21,-16,LEAVES:3)
Block(11,21,-13,LEAVES:3)
Block(11,22,-16,LEAVES:3)
Block(11,22,-13,LEAVES:3)
Block(11,22,-10,LEAVES:3)
Block(11,22,-9,LEAVES:3)
Block(11,22,-6,LEAVES:3)
Block(11,22,-5,LEAVES:3)
Block(11,22,-3,17:15)
Block(11,22,-2,LEAVES:3)
Block(11,22,-1,LEAVES:3)
Block(11,23,-14,LEAVES:3)
Block(11,23,-13,LEAVES:3)
Block(11,23,-12,LEAVES:3)
Block(11,23,-5,LEAVES:3)
Block(11,23,-4,LEAVES:3)
Block(11,23,-3,LEAVES:3)
Block(11,23,-2,LEAVES:3)
Block(11,23,1,LEAVES:3)
Block(11,24,-14,LEAVES:3)
Block(11,24,-12,LEAVES:3)
Block(11,24,-11,LEAVES:3)
Block(11,24,-6,LEAVES:3)
Block(11,24,-5,LEAVES:3)
Block(11,24,-2,LEAVES:3)
Block(12,21,0,LEAVES:3)
Block(12,22,-17,LEAVES:3)
Block(12,22,-16,LEAVES:3)
Block(12,22,-13,LEAVES:3)
Block(12,22,-12,LEAVES:3)
Block(12,22,-11,LEAVES:3)
Block(12,22,-8,LEAVES:3)
Block(12,22,-4,LEAVES:3)
Block(12,22,-1,LEAVES:3)
Block(12,22,0,LEAVES:3)
Block(12,22,1,LEAVES:3)
Block(12,23,-9,LEAVES:3)
Block(12,23,-8,LEAVES:3)
Block(12,23,-4,LEAVES:3)
Block(12,23,-3,LEAVES:3)
Block(12,23,-1,LEAVES:3)
Block(12,24,-14,LEAVES:3)
Block(12,24,-11,LEAVES:3)
Block(12,24,-10,LEAVES:3)
Block(12,24,-9,LEAVES:3)
Block(12,24,-4,LEAVES:3)
Block(12,24,-3,LEAVES:3)
Block(12,24,0,LEAVES:3)
Block(13,22,-17,LEAVES:3)
Block(13,22,-14,LEAVES:3)
Block(13,22,-12,LEAVES:3)
Block(13,22,-6,LEAVES:3)
Block(13,22,-5,LEAVES:3)
Block(13,22,-3,LEAVES:3)
Block(13,23,-7,LEAVES:3)
Block(13,23,-5,LEAVES:3)
Block(13,23,-4,LEAVES:3)
Block(13,24,-14,LEAVES:3)
Block(13,24,-13,LEAVES:3)
Block(13,24,-2,LEAVES:3)
Block(14,21,-12,LEAVES:3)
Block(14,21,-6,LEAVES:3)
Block(14,21,-3,LEAVES:3)
Block(14,22,-15,LEAVES:3)
Block(14,22,-12,LEAVES:3)
Block(14,22,-11,LEAVES:3)
Block(14,22,-6,LEAVES:3)
Block(14,22,-3,LEAVES:3)
Block(14,22,0,LEAVES:3)
Block(14,22,1,LEAVES:3)
Block(14,23,-4,LEAVES:3)
Block(14,23,-3,LEAVES:3)
Block(14,23,-2,LEAVES:3)
Block(14,24,-13,LEAVES:3)
Block(14,24,-4,LEAVES:3)
Block(14,24,-2,LEAVES:3)
Block(14,24,-1,LEAVES:3)
Block(15,22,-7,LEAVES:3)
Block(15,22,-6,LEAVES:3)
Block(15,22,-3,LEAVES:3)
Block(15,22,-2,LEAVES:3)
Block(15,22,-1,LEAVES:3)
Block(15,24,-13,LEAVES:3)
Block(15,24,-4,LEAVES:3)
Block(15,24,-1,LEAVES:3)
Block(15,24,0,LEAVES:3)
Block(15,24,1,LEAVES:3)
Block(16,22,-7,LEAVES:3)
Block(16,22,-4,LEAVES:3)
Block(16,22,-2,LEAVES:3)
Block(16,24,-4,LEAVES:3)
Block(16,24,-3,LEAVES:3)
Block(17,21,-2,LEAVES:3)
Block(17,22,-5,LEAVES:3)
Block(17,22,-2,LEAVES:3)
Block(17,22,-1,LEAVES:3)
Block(17,24,-3,LEAVES:3)
Block(18,24,-3,LEAVES:3)


#######################################################################
# +-----------------------------------------------------------------+ #
# |                             Entities                            | #
# +-----------------------------------------------------------------+ #
#######################################################################

# Entity() spawns an entity instead of a block. The entity is spawned only once when the BO3 is spawned.
# Entities are persistent by default so they don't de-spawn when no player is near, they are only unloaded.
# Usage: Entity(x,y,z,mobName,groupSize,NameTagOrNBTFileName) or Entity(x,y,z,mobName,groupSize)
# Use /tc entities or /otg entities to get a list of entities that can be used as mobName, this includes entities added by other mods.
# NameTagOrNBTFileName can be either a nametag for the mob or an nbt file (such as mymobinfo.nbt or mymobinfo.txt).
# When using a text file you can use the same mob spawning parameters used with the /summon command to equip the
# entity and give it custom attributes etc. You can copy the DATA part of a summon command including surrounding
# curly braces to a .txt file, for instance for: "/summon Skeleton x y z {DATA}"

#######################################################################
# +-----------------------------------------------------------------+ #
# |                            BO3 checks                           | #
# +-----------------------------------------------------------------+ #
#######################################################################

# Require a condition at a certain location in order for the BO3 to be spawned.
# BlockCheck(x,y,z,BlockName[,BlockName[,...]]) - one of the blocks must be at the location
# BlockCheckNot(x,y,z,BlockName[,BlockName[,...]]) - all the blocks must not be at the location
# LightCheck(x,y,z,minLightLevel,maxLightLevel) - light must be between min and max (inclusive)

# You can use "Solid" as a BlockName for matching all solid blocks or "All" to match all blocks that aren't air.

# Examples:
#   BlockCheck(0,-1,0,GRASS,DIRT)  Require grass or dirt just below the object
#   BlockCheck(0,-1,0,Solid)       Require any solid block just below the object
#   BlockCheck(0,-1,0,WOOL)        Require any type of wool just below the object
#   BlockCheck(0,-1,0,WOOL:0)      Require white wool just below the object
#   BlockCheckNot(0,-1,0,WOOL:0)   Require that there is no white wool below the object
#   LightCheck(0,0,0,0,LEAVES:3)          Require almost complete darkness just below the object

BlockCheck(0,-1,0,GRASS,DIRT)
