
#######################################################################
# +-----------------------------------------------------------------+ #
# |                            BO3 object                           | #
# +-----------------------------------------------------------------+ #
#######################################################################

# This is the config file of a custom object.
# If you add this object correctly to your BiomeConfigs, it will spawn in the world.

# This is the creator of this BO3 object
Author: Unknown

# A short description of this BO3 object
Description: No description given

# The BO3 version, don't change this! It can be used by external applications to do a version check.
Version: 3

# The settings mode, WriteAll, WriteWithoutComments or WriteDisable. See WorldConfig.
SettingsMode: WriteAll


#######################################################################
# +-----------------------------------------------------------------+ #
# |                          Main settings                          | #
# +-----------------------------------------------------------------+ #
#######################################################################

# This needs to be set to true to spawn the object in the Tree and Sapling resources.
Tree: false

# The frequency of the BO3 from 1 to 200. Tries this many times to spawn this BO3 when using the CustomObject(...) resource.
# Ignored by Tree(..), Sapling(..) and CustomStructure(..)
Frequency: 10

# The rarity of the BO3 from 0 to 100. Each spawn attempt has rarity% chance to succeed when using the CustomObject(...) resource.
# Ignored by Tree(..), Sapling(..) and CustomStructure(..)
Rarity: 33.0

# If you set this to true, the BO3 will be placed with a random rotation.
RotateRandomly: true

# The spawn height of the BO3: randomY, highestBlock or highestSolidBlock.
SpawnHeight: highestSolidBlock

# The offset from the spawn height to spawn this BO3
# Ex. SpawnHeight = highestSolidBlock, SpawnHeightOffset = 3; This object will spawn 3 blocks above the highest solid block
SpawnHeightOffset: -120

# A random amount to offset the spawn location from the spawn offset height
# Ex. SpawnHeightOffset = 3, SpawnHeightVariance = 3; This object will spawn 3 to 6 blocks above the original spot it would have spawned
SpawnHeightVariance: 0

##############################
# Height Limits for the BO3. #
##############################

# When in randomY mode used as the minimum Y or in atMinY mode as the actual Y to spawn this BO3 at.
MinHeight: 32

# When in randomY mode used as the maximum Y to spawn this BO3 at.
MaxHeight: 255

######################
# Extrusion settings #
######################

# The style of extrusion you wish to use - BottomDown, TopUp, None (Default)
ExtrudeMode: BottomDown

# The blocks to extrude your BO3 through
ExtrudeThroughBlocks: AIR,GRASS

# Objects can have other objects attacthed to it: branches. Branches can also
# have branches attached to it, which can also have branches, etc. This is the
# maximum branch depth for this objects.
MaxBranchDepth: 10

# When spawned with the UseWorld keyword, this BO3 should NOT spawn in the following biomes.
# If you write the BO3 name directly in the BiomeConfigs, this will be ignored.
ExcludedBiomes: All


#######################################################################
# +-----------------------------------------------------------------+ #
# |                      Source block settings                      | #
# +-----------------------------------------------------------------+ #
#######################################################################

# The block(s) the BO3 should spawn in.
SourceBlocks: AIR

# The maximum percentage of the BO3 that can be outside the SourceBlock.
# The BO3 won't be placed on a location with more blocks outside the SourceBlock than this percentage.
MaxPercentageOutsideSourceBlock: 100

# What to do when a block is about to be placed outside the SourceBlock? (dontPlace, placeAnyway)
OutsideSourceBlock: placeAnyway

# Disable doReplaceBlocks to make this BO3 ignore any ReplacedBlocks settings in biome configs, improves performance.
DoReplaceBlocks: true

# OTG+ settings #
# Legacy setting, rename this file to .BO4 instead. Set this to true to enable the advanced customstructure features of OTG+.
IsOTGPlus: false


#######################################################################
# +-----------------------------------------------------------------+ #
# |                              Blocks                             | #
# +-----------------------------------------------------------------+ #
#######################################################################

# All the blocks used in the BO3 are listed here. Possible blocks:
# Block(x,y,z,id[.data][,nbtfile.nbt)
# RandomBlock(x,y,z,id[:data][,nbtfile.nbt],chance[,id[:data][,nbtfile.nbt],chance[,...]])
#  So RandomBlock(0,0,0,CHEST,chest.nbt,50,CHEST,anotherchest.nbt,100) will spawn a chest at
#  the BO3 origin, and give it a 50% chance to have the contents of chest.nbt, or, if that
#  fails, a 100% percent chance to have the contents of anotherchest.nbt.
# *Note: Unlike Entity() and Spawner(), for Block() .txt files don't work, only .nbt files work.
# MinecraftObject(x,y,z,name) (TODO: This may not work anymore and needs to be tested.
#  Spawns an object in the Mojang NBT structure format. For example, 
#  MinecraftObject(0,0,0,minecraft:igloo/igloo_bottom)
#  spawns the bottom part of an igloo.
Block(-10,0,-3,STONE:0)
Block(-10,0,0,STONE:0)
Block(-10,0,3,STONE:0)
Block(-10,0,6,STONE:0)
Block(-10,1,-3,STONE:0)
Block(-10,1,3,STONE:0)
Block(-10,1,6,STONE:0)
Block(-10,2,-3,STONE:0)
Block(-10,2,6,STONE:0)
Block(-10,3,-3,STONE:0)
Block(-9,0,-4,STONE:0)
Block(-9,0,-3,STONE:0)
Block(-9,0,-2,STONE:0)
Block(-9,0,-1,STONE:0)
Block(-9,0,0,STONE:0)
Block(-9,0,1,STONE:0)
Block(-9,0,2,STONE:0)
Block(-9,0,3,STONE:0)
Block(-9,0,4,STONE:0)
Block(-9,0,5,STONE:0)
Block(-9,0,6,STONE:0)
Block(-9,0,7,STONE:0)
Block(-9,1,-4,STONE:0)
Block(-9,1,-3,STONE:0)
Block(-9,1,-2,STONE:0)
Block(-9,1,-1,STONE:0)
Block(-9,1,0,STONE:0)
Block(-9,1,1,STONE:0)
Block(-9,1,2,STONE:0)
Block(-9,1,3,STONE:0)
Block(-9,1,4,STONE:0)
Block(-9,1,5,STONE:0)
Block(-9,1,6,STONE:0)
Block(-9,1,7,STONE:0)
Block(-9,2,-3,STONE:0)
Block(-9,2,-2,STONE:0)
Block(-9,2,-1,STONE:0)
Block(-9,2,0,STONE:0)
Block(-9,2,2,STONE:0)
Block(-9,2,3,STONE:0)
Block(-9,2,4,STONE:0)
Block(-9,2,5,STONE:0)
Block(-9,2,6,STONE:0)
Block(-9,3,-3,STONE:0)
Block(-9,3,-2,STONE:0)
Block(-9,3,-1,STONE:0)
Block(-9,3,2,STONE:0)
Block(-9,3,3,STONE:0)
Block(-9,3,4,STONE:0)
Block(-9,3,6,STONE:0)
Block(-9,4,-3,STONE:0)
Block(-9,4,-2,STONE:0)
Block(-9,4,2,STONE:0)
Block(-9,4,6,STONE:0)
Block(-9,5,-3,STONE:0)
Block(-9,5,-2,STONE:0)
Block(-9,5,2,STONE:0)
Block(-9,5,6,STONE:0)
Block(-9,6,-3,STONE:0)
Block(-9,6,-2,STONE:0)
Block(-9,6,2,STONE:0)
Block(-9,6,6,STONE:0)
Block(-9,7,-3,STONE:0)
Block(-9,7,6,STONE:0)
Block(-9,8,-3,STONE:0)
Block(-9,8,6,STONE:0)
Block(-9,9,-3,STONE:0)
Block(-9,9,6,STONE:0)
Block(-9,10,-3,STONE:0)
Block(-8,0,-10,STONE:0)
Block(-8,0,-9,STONE:0)
Block(-8,0,-8,STONE:0)
Block(-8,0,-7,STONE:0)
Block(-8,0,-6,STONE:0)
Block(-8,0,-5,STONE:0)
Block(-8,0,-4,STONE:0)
Block(-8,0,-3,STONE:0)
Block(-8,0,-2,STONE:0)
Block(-8,0,-1,STONE:0)
Block(-8,0,0,STONE:0)
Block(-8,0,1,STONE:0)
Block(-8,0,2,STONE:0)
Block(-8,0,3,STONE:0)
Block(-8,0,4,STONE:0)
Block(-8,0,5,STONE:0)
Block(-8,0,6,STONE:0)
Block(-8,0,7,STONE:0)
Block(-8,0,8,STONE:0)
Block(-8,1,-9,STONE:0)
Block(-8,1,-8,STONE:0)
Block(-8,1,-7,STONE:0)
Block(-8,1,-6,STONE:0)
Block(-8,1,-5,STONE:0)
Block(-8,1,-4,STONE:0)
Block(-8,1,-3,STONE:0)
Block(-8,1,-2,STONE:0)
Block(-8,1,-1,STONE:0)
Block(-8,1,0,STONE:0)
Block(-8,1,1,STONE:0)
Block(-8,1,2,STONE:0)
Block(-8,1,3,STONE:0)
Block(-8,1,4,STONE:0)
Block(-8,1,5,STONE:0)
Block(-8,1,6,STONE:0)
Block(-8,1,7,STONE:0)
Block(-8,1,8,STONE:0)
Block(-8,2,-9,STONE:0)
Block(-8,2,-8,STONE:0)
Block(-8,2,-7,STONE:0)
Block(-8,2,-6,STONE:0)
Block(-8,2,-5,STONE:0)
Block(-8,2,-4,STONE:0)
Block(-8,2,-3,STONE:0)
Block(-8,2,-2,STONE:0)
Block(-8,2,-1,STONE:0)
Block(-8,2,0,STONE:0)
Block(-8,2,1,STONE:0)
Block(-8,2,2,STONE:0)
Block(-8,2,3,STONE:0)
Block(-8,2,4,STONE:0)
Block(-8,2,5,STONE:0)
Block(-8,2,6,STONE:0)
Block(-8,2,7,STONE:0)
Block(-8,2,8,STONE:0)
Block(-8,3,-9,STONE:0)
Block(-8,3,-8,STONE:0)
Block(-8,3,-7,STONE:0)
Block(-8,3,-6,STONE:0)
Block(-8,3,-5,STONE:0)
Block(-8,3,-4,STONE:0)
Block(-8,3,-3,STONE:0)
Block(-8,3,-2,STONE:0)
Block(-8,3,-1,STONE:0)
Block(-8,3,0,STONE:0)
Block(-8,3,1,STONE:0)
Block(-8,3,2,STONE:0)
Block(-8,3,3,STONE:0)
Block(-8,3,4,STONE:0)
Block(-8,3,5,STONE:0)
Block(-8,3,6,STONE:0)
Block(-8,3,7,STONE:0)
Block(-8,4,-8,STONE:0)
Block(-8,4,-5,STONE:0)
Block(-8,4,-4,STONE:0)
Block(-8,4,-3,STONE:0)
Block(-8,4,-2,STONE:0)
Block(-8,4,-1,STONE:0)
Block(-8,4,0,STONE:0)
Block(-8,4,1,STONE:0)
Block(-8,4,2,STONE:0)
Block(-8,4,3,STONE:0)
Block(-8,4,4,STONE:0)
Block(-8,4,5,STONE:0)
Block(-8,4,6,STONE:0)
Block(-8,5,-4,STONE:0)
Block(-8,5,-3,STONE:0)
Block(-8,5,-2,STONE:0)
Block(-8,5,-1,STONE:0)
Block(-8,5,0,STONE:0)
Block(-8,5,1,STONE:0)
Block(-8,5,2,STONE:0)
Block(-8,5,3,STONE:0)
Block(-8,5,4,STONE:0)
Block(-8,5,5,STONE:0)
Block(-8,5,6,STONE:0)
Block(-8,6,-4,STONE:0)
Block(-8,6,-3,STONE:0)
Block(-8,6,-2,STONE:0)
Block(-8,6,-1,STONE:0)
Block(-8,6,0,STONE:0)
Block(-8,6,1,STONE:0)
Block(-8,6,2,STONE:0)
Block(-8,6,3,STONE:0)
Block(-8,6,4,STONE:0)
Block(-8,6,5,STONE:0)
Block(-8,6,6,STONE:0)
Block(-8,7,-3,STONE:0)
Block(-8,7,-2,STONE:0)
Block(-8,7,-1,STONE:0)
Block(-8,7,1,STONE:0)
Block(-8,7,2,STONE:0)
Block(-8,7,3,STONE:0)
Block(-8,7,4,STONE:0)
Block(-8,7,5,STONE:0)
Block(-8,7,6,STONE:0)
Block(-8,8,-3,STONE:0)
Block(-8,8,-2,STONE:0)
Block(-8,8,-1,STONE:0)
Block(-8,8,1,STONE:0)
Block(-8,8,2,STONE:0)
Block(-8,8,3,STONE:0)
Block(-8,8,4,STONE:0)
Block(-8,8,5,STONE:0)
Block(-8,8,6,STONE:0)
Block(-8,9,-3,STONE:0)
Block(-8,9,-2,STONE:0)
Block(-8,9,-1,STONE:0)
Block(-8,9,1,STONE:0)
Block(-8,9,2,STONE:0)
Block(-8,9,3,STONE:0)
Block(-8,9,4,STONE:0)
Block(-8,9,5,STONE:0)
Block(-8,9,6,STONE:0)
Block(-8,10,-3,STONE:0)
Block(-8,10,-2,STONE:0)
Block(-8,10,-1,STONE:0)
Block(-8,10,1,STONE:0)
Block(-8,10,2,STONE:0)
Block(-8,10,3,STONE:0)
Block(-8,10,4,STONE:0)
Block(-8,10,5,STONE:0)
Block(-8,10,6,STONE:0)
Block(-8,11,-3,STONE:0)
Block(-8,11,-2,STONE:0)
Block(-8,11,-1,STONE:0)
Block(-8,11,2,STONE:0)
Block(-8,11,3,STONE:0)
Block(-8,11,4,STONE:0)
Block(-8,12,-3,STONE:0)
Block(-8,12,-2,STONE:0)
Block(-8,12,-1,STONE:0)
Block(-8,12,2,STONE:0)
Block(-8,12,3,STONE:0)
Block(-8,12,4,STONE:0)
Block(-8,13,-3,STONE:0)
Block(-8,13,-2,STONE:0)
Block(-8,13,2,STONE:0)
Block(-8,13,3,STONE:0)
Block(-8,14,-3,STONE:0)
Block(-8,14,-2,STONE:0)
Block(-8,14,2,STONE:0)
Block(-8,14,3,STONE:0)
Block(-8,15,-3,STONE:0)
Block(-8,15,-2,STONE:0)
Block(-8,15,2,STONE:0)
Block(-8,16,-3,STONE:0)
Block(-8,17,-3,STONE:0)
Block(-8,18,-3,STONE:0)
Block(-8,19,-3,STONE:0)
Block(-8,20,-3,STONE:0)
Block(-8,21,-3,STONE:0)
Block(-8,22,-3,STONE:0)
Block(-8,23,-3,STONE:0)
Block(-8,24,-3,STONE:0)
Block(-8,25,-3,STONE:0)
Block(-8,26,-3,STONE:0)
Block(-7,0,-11,STONE:0)
Block(-7,0,-10,STONE:0)
Block(-7,0,-9,STONE:0)
Block(-7,0,-8,STONE:0)
Block(-7,0,-7,STONE:0)
Block(-7,0,-6,STONE:0)
Block(-7,0,-5,STONE:0)
Block(-7,0,-4,STONE:0)
Block(-7,0,-3,STONE:0)
Block(-7,0,-2,STONE:0)
Block(-7,0,-1,STONE:0)
Block(-7,0,0,STONE:0)
Block(-7,0,1,STONE:0)
Block(-7,0,2,STONE:0)
Block(-7,0,3,STONE:0)
Block(-7,0,4,STONE:0)
Block(-7,0,5,STONE:0)
Block(-7,0,6,STONE:0)
Block(-7,0,7,STONE:0)
Block(-7,0,8,STONE:0)
Block(-7,0,9,STONE:0)
Block(-7,1,-10,STONE:0)
Block(-7,1,-9,STONE:0)
Block(-7,1,-8,STONE:0)
Block(-7,1,-7,STONE:0)
Block(-7,1,-6,STONE:0)
Block(-7,1,-5,STONE:0)
Block(-7,1,-4,STONE:0)
Block(-7,1,-3,STONE:0)
Block(-7,1,-2,STONE:0)
Block(-7,1,-1,STONE:0)
Block(-7,1,0,STONE:0)
Block(-7,1,1,STONE:0)
Block(-7,1,2,STONE:0)
Block(-7,1,3,STONE:0)
Block(-7,1,4,STONE:0)
Block(-7,1,5,STONE:0)
Block(-7,1,6,STONE:0)
Block(-7,1,7,STONE:0)
Block(-7,1,8,STONE:0)
Block(-7,1,9,STONE:0)
Block(-7,2,-10,STONE:0)
Block(-7,2,-9,STONE:0)
Block(-7,2,-8,STONE:0)
Block(-7,2,-7,STONE:0)
Block(-7,2,-6,STONE:0)
Block(-7,2,-5,STONE:0)
Block(-7,2,-4,STONE:0)
Block(-7,2,-3,STONE:0)
Block(-7,2,-2,STONE:0)
Block(-7,2,-1,STONE:0)
Block(-7,2,0,STONE:0)
Block(-7,2,1,STONE:0)
Block(-7,2,2,STONE:0)
Block(-7,2,3,STONE:0)
Block(-7,2,4,STONE:0)
Block(-7,2,5,STONE:0)
Block(-7,2,6,STONE:0)
Block(-7,2,7,STONE:0)
Block(-7,2,8,STONE:0)
Block(-7,3,-9,STONE:0)
Block(-7,3,-8,STONE:0)
Block(-7,3,-7,STONE:0)
Block(-7,3,-6,STONE:0)
Block(-7,3,-5,STONE:0)
Block(-7,3,-4,STONE:0)
Block(-7,3,-3,STONE:0)
Block(-7,3,-2,STONE:0)
Block(-7,3,-1,STONE:0)
Block(-7,3,0,STONE:0)
Block(-7,3,1,STONE:0)
Block(-7,3,2,STONE:0)
Block(-7,3,3,STONE:0)
Block(-7,3,4,STONE:0)
Block(-7,3,5,STONE:0)
Block(-7,3,6,STONE:0)
Block(-7,3,7,STONE:0)
Block(-7,3,8,STONE:0)
Block(-7,4,-9,STONE:0)
Block(-7,4,-8,STONE:0)
Block(-7,4,-7,STONE:0)
Block(-7,4,-6,STONE:0)
Block(-7,4,-5,STONE:0)
Block(-7,4,-4,STONE:0)
Block(-7,4,-3,STONE:0)
Block(-7,4,-2,STONE:0)
Block(-7,4,-1,STONE:0)
Block(-7,4,0,STONE:0)
Block(-7,4,1,STONE:0)
Block(-7,4,2,STONE:0)
Block(-7,4,3,STONE:0)
Block(-7,4,4,STONE:0)
Block(-7,4,5,STONE:0)
Block(-7,4,6,STONE:0)
Block(-7,4,7,STONE:0)
Block(-7,4,8,STONE:0)
Block(-7,5,-9,STONE:0)
Block(-7,5,-8,STONE:0)
Block(-7,5,-7,STONE:0)
Block(-7,5,-6,STONE:0)
Block(-7,5,-5,STONE:0)
Block(-7,5,-4,STONE:0)
Block(-7,5,-3,STONE:0)
Block(-7,5,-2,STONE:0)
Block(-7,5,-1,STONE:0)
Block(-7,5,0,STONE:0)
Block(-7,5,1,STONE:0)
Block(-7,5,2,STONE:0)
Block(-7,5,3,STONE:0)
Block(-7,5,4,STONE:0)
Block(-7,5,5,STONE:0)
Block(-7,5,6,STONE:0)
Block(-7,5,7,STONE:0)
Block(-7,5,8,STONE:0)
Block(-7,6,-9,STONE:0)
Block(-7,6,-8,STONE:0)
Block(-7,6,-7,STONE:0)
Block(-7,6,-6,STONE:0)
Block(-7,6,-5,STONE:0)
Block(-7,6,-4,STONE:0)
Block(-7,6,-3,STONE:0)
Block(-7,6,-2,STONE:0)
Block(-7,6,-1,STONE:0)
Block(-7,6,0,STONE:0)
Block(-7,6,1,STONE:0)
Block(-7,6,2,STONE:0)
Block(-7,6,3,STONE:0)
Block(-7,6,4,STONE:0)
Block(-7,6,5,STONE:0)
Block(-7,6,6,STONE:0)
Block(-7,6,7,STONE:0)
Block(-7,6,8,STONE:0)
Block(-7,7,-8,STONE:0)
Block(-7,7,-7,STONE:0)
Block(-7,7,-6,STONE:0)
Block(-7,7,-5,STONE:0)
Block(-7,7,-4,STONE:0)
Block(-7,7,-3,STONE:0)
Block(-7,7,-2,STONE:0)
Block(-7,7,-1,STONE:0)
Block(-7,7,0,STONE:0)
Block(-7,7,1,STONE:0)
Block(-7,7,2,STONE:0)
Block(-7,7,3,STONE:0)
Block(-7,7,4,STONE:0)
Block(-7,7,5,STONE:0)
Block(-7,7,6,STONE:0)
Block(-7,7,7,STONE:0)
Block(-7,7,8,STONE:0)
Block(-7,8,-8,STONE:0)
Block(-7,8,-7,STONE:0)
Block(-7,8,-6,STONE:0)
Block(-7,8,-5,STONE:0)
Block(-7,8,-4,STONE:0)
Block(-7,8,-3,STONE:0)
Block(-7,8,-2,STONE:0)
Block(-7,8,-1,STONE:0)
Block(-7,8,0,STONE:0)
Block(-7,8,1,STONE:0)
Block(-7,8,2,STONE:0)
Block(-7,8,3,STONE:0)
Block(-7,8,4,STONE:0)
Block(-7,8,5,STONE:0)
Block(-7,8,6,STONE:0)
Block(-7,8,7,STONE:0)
Block(-7,8,8,STONE:0)
Block(-7,9,-8,STONE:0)
Block(-7,9,-7,STONE:0)
Block(-7,9,-6,STONE:0)
Block(-7,9,-5,STONE:0)
Block(-7,9,-4,STONE:0)
Block(-7,9,-3,STONE:0)
Block(-7,9,-2,STONE:0)
Block(-7,9,-1,STONE:0)
Block(-7,9,0,STONE:0)
Block(-7,9,1,STONE:0)
Block(-7,9,2,STONE:0)
Block(-7,9,3,STONE:0)
Block(-7,9,4,STONE:0)
Block(-7,9,5,STONE:0)
Block(-7,9,6,STONE:0)
Block(-7,9,7,STONE:0)
Block(-7,9,8,STONE:0)
Block(-7,10,-6,STONE:0)
Block(-7,10,-5,STONE:0)
Block(-7,10,-4,STONE:0)
Block(-7,10,-3,STONE:0)
Block(-7,10,-2,STONE:0)
Block(-7,10,-1,STONE:0)
Block(-7,10,0,STONE:0)
Block(-7,10,1,STONE:0)
Block(-7,10,2,STONE:0)
Block(-7,10,3,STONE:0)
Block(-7,10,4,STONE:0)
Block(-7,10,5,STONE:0)
Block(-7,10,6,STONE:0)
Block(-7,10,7,STONE:0)
Block(-7,10,8,STONE:0)
Block(-7,11,-6,STONE:0)
Block(-7,11,-5,STONE:0)
Block(-7,11,-4,STONE:0)
Block(-7,11,-3,STONE:0)
Block(-7,11,-2,STONE:0)
Block(-7,11,-1,STONE:0)
Block(-7,11,0,STONE:0)
Block(-7,11,1,STONE:0)
Block(-7,11,2,STONE:0)
Block(-7,11,3,STONE:0)
Block(-7,11,4,STONE:0)
Block(-7,11,5,STONE:0)
Block(-7,11,6,STONE:0)
Block(-7,11,7,STONE:0)
Block(-7,12,-5,STONE:0)
Block(-7,12,-4,STONE:0)
Block(-7,12,-3,STONE:0)
Block(-7,12,-2,STONE:0)
Block(-7,12,-1,STONE:0)
Block(-7,12,0,STONE:0)
Block(-7,12,1,STONE:0)
Block(-7,12,2,STONE:0)
Block(-7,12,3,STONE:0)
Block(-7,12,4,STONE:0)
Block(-7,12,5,STONE:0)
Block(-7,12,6,STONE:0)
Block(-7,13,-5,STONE:0)
Block(-7,13,-4,STONE:0)
Block(-7,13,-3,STONE:0)
Block(-7,13,-2,STONE:0)
Block(-7,13,-1,STONE:0)
Block(-7,13,0,STONE:0)
Block(-7,13,1,STONE:0)
Block(-7,13,2,STONE:0)
Block(-7,13,3,STONE:0)
Block(-7,13,4,STONE:0)
Block(-7,13,5,STONE:0)
Block(-7,13,6,STONE:0)
Block(-7,14,-5,STONE:0)
Block(-7,14,-4,STONE:0)
Block(-7,14,-3,STONE:0)
Block(-7,14,-2,STONE:0)
Block(-7,14,-1,STONE:0)
Block(-7,14,0,STONE:0)
Block(-7,14,1,STONE:0)
Block(-7,14,2,STONE:0)
Block(-7,14,3,STONE:0)
Block(-7,14,4,STONE:0)
Block(-7,14,5,STONE:0)
Block(-7,14,6,STONE:0)
Block(-7,15,-5,STONE:0)
Block(-7,15,-4,STONE:0)
Block(-7,15,-3,STONE:0)
Block(-7,15,-2,STONE:0)
Block(-7,15,-1,STONE:0)
Block(-7,15,0,STONE:0)
Block(-7,15,1,STONE:0)
Block(-7,15,2,STONE:0)
Block(-7,15,3,STONE:0)
Block(-7,15,4,STONE:0)
Block(-7,15,5,STONE:0)
Block(-7,15,6,STONE:0)
Block(-7,16,-5,STONE:0)
Block(-7,16,-4,STONE:0)
Block(-7,16,-3,STONE:0)
Block(-7,16,-2,STONE:0)
Block(-7,16,-1,STONE:0)
Block(-7,16,0,STONE:0)
Block(-7,16,1,STONE:0)
Block(-7,16,2,STONE:0)
Block(-7,16,3,STONE:0)
Block(-7,16,4,STONE:0)
Block(-7,16,5,STONE:0)
Block(-7,16,6,STONE:0)
Block(-7,17,-5,STONE:0)
Block(-7,17,-4,STONE:0)
Block(-7,17,-3,STONE:0)
Block(-7,17,-2,STONE:0)
Block(-7,17,-1,STONE:0)
Block(-7,17,0,STONE:0)
Block(-7,17,1,STONE:0)
Block(-7,17,2,STONE:0)
Block(-7,17,3,STONE:0)
Block(-7,17,4,STONE:0)
Block(-7,17,5,STONE:0)
Block(-7,17,6,STONE:0)
Block(-7,18,-5,STONE:0)
Block(-7,18,-4,STONE:0)
Block(-7,18,-3,STONE:0)
Block(-7,18,-2,STONE:0)
Block(-7,18,-1,STONE:0)
Block(-7,18,0,STONE:0)
Block(-7,18,1,STONE:0)
Block(-7,18,2,STONE:0)
Block(-7,18,3,STONE:0)
Block(-7,18,4,STONE:0)
Block(-7,18,5,STONE:0)
Block(-7,18,6,STONE:0)
Block(-7,19,-5,STONE:0)
Block(-7,19,-4,STONE:0)
Block(-7,19,-3,STONE:0)
Block(-7,19,-2,STONE:0)
Block(-7,19,-1,STONE:0)
Block(-7,19,0,STONE:0)
Block(-7,19,1,STONE:0)
Block(-7,19,2,STONE:0)
Block(-7,19,3,STONE:0)
Block(-7,19,4,STONE:0)
Block(-7,19,5,STONE:0)
Block(-7,19,6,STONE:0)
Block(-7,20,-5,STONE:0)
Block(-7,20,-4,STONE:0)
Block(-7,20,-3,STONE:0)
Block(-7,20,-2,STONE:0)
Block(-7,20,-1,STONE:0)
Block(-7,20,0,STONE:0)
Block(-7,20,1,STONE:0)
Block(-7,20,2,STONE:0)
Block(-7,20,3,STONE:0)
Block(-7,20,4,STONE:0)
Block(-7,20,5,STONE:0)
Block(-7,20,6,STONE:0)
Block(-7,21,-5,STONE:0)
Block(-7,21,-4,STONE:0)
Block(-7,21,-3,STONE:0)
Block(-7,21,-2,STONE:0)
Block(-7,21,-1,STONE:0)
Block(-7,21,0,STONE:0)
Block(-7,21,1,STONE:0)
Block(-7,21,2,STONE:0)
Block(-7,21,3,STONE:0)
Block(-7,21,4,STONE:0)
Block(-7,21,5,STONE:0)
Block(-7,21,6,STONE:0)
Block(-7,22,-5,STONE:0)
Block(-7,22,-4,STONE:0)
Block(-7,22,-3,STONE:0)
Block(-7,22,-2,STONE:0)
Block(-7,22,-1,STONE:0)
Block(-7,22,0,STONE:0)
Block(-7,22,1,STONE:0)
Block(-7,22,2,STONE:0)
Block(-7,22,3,STONE:0)
Block(-7,22,4,STONE:0)
Block(-7,22,5,STONE:0)
Block(-7,22,6,STONE:0)
Block(-7,23,-5,STONE:0)
Block(-7,23,-4,STONE:0)
Block(-7,23,-3,STONE:0)
Block(-7,23,-2,STONE:0)
Block(-7,23,-1,STONE:0)
Block(-7,23,0,STONE:0)
Block(-7,23,1,STONE:0)
Block(-7,23,2,STONE:0)
Block(-7,23,3,STONE:0)
Block(-7,23,4,STONE:0)
Block(-7,23,5,STONE:0)
Block(-7,23,6,STONE:0)
Block(-7,24,-5,STONE:0)
Block(-7,24,-4,STONE:0)
Block(-7,24,-3,STONE:0)
Block(-7,24,-2,STONE:0)
Block(-7,24,-1,STONE:0)
Block(-7,24,0,STONE:0)
Block(-7,24,1,STONE:0)
Block(-7,24,2,STONE:0)
Block(-7,24,3,STONE:0)
Block(-7,24,4,STONE:0)
Block(-7,24,5,STONE:0)
Block(-7,24,6,STONE:0)
Block(-7,25,-5,STONE:0)
Block(-7,25,-4,STONE:0)
Block(-7,25,-3,STONE:0)
Block(-7,25,-2,STONE:0)
Block(-7,25,-1,STONE:0)
Block(-7,25,0,STONE:0)
Block(-7,25,1,STONE:0)
Block(-7,25,2,STONE:0)
Block(-7,25,3,STONE:0)
Block(-7,25,4,STONE:0)
Block(-7,25,5,STONE:0)
Block(-7,25,6,STONE:0)
Block(-7,26,-4,STONE:0)
Block(-7,26,-3,STONE:0)
Block(-7,26,-2,STONE:0)
Block(-7,26,-1,STONE:0)
Block(-7,26,0,STONE:0)
Block(-7,26,1,STONE:0)
Block(-7,26,2,STONE:0)
Block(-7,26,3,STONE:0)
Block(-7,26,4,STONE:0)
Block(-7,26,5,STONE:0)
Block(-7,26,6,STONE:0)
Block(-7,27,-3,STONE:0)
Block(-7,27,-2,STONE:0)
Block(-7,27,-1,STONE:0)
Block(-7,27,0,STONE:0)
Block(-7,27,1,STONE:0)
Block(-7,27,2,STONE:0)
Block(-7,27,3,STONE:0)
Block(-7,27,4,STONE:0)
Block(-7,27,5,STONE:0)
Block(-7,27,6,STONE:0)
Block(-7,28,-3,STONE:0)
Block(-7,28,-2,STONE:0)
Block(-7,28,-1,STONE:0)
Block(-7,28,0,STONE:0)
Block(-7,28,1,STONE:0)
Block(-7,28,2,STONE:0)
Block(-7,28,3,STONE:0)
Block(-7,28,4,STONE:0)
Block(-7,28,5,STONE:0)
Block(-7,29,-3,STONE:0)
Block(-7,29,-1,STONE:0)
Block(-7,29,0,STONE:0)
Block(-7,29,1,STONE:0)
Block(-7,29,3,STONE:0)
Block(-7,29,4,STONE:0)
Block(-7,29,5,STONE:0)
Block(-7,30,-3,STONE:0)
Block(-7,30,-1,STONE:0)
Block(-7,30,0,STONE:0)
Block(-7,30,1,STONE:0)
Block(-7,30,4,STONE:0)
Block(-7,31,-3,STONE:0)
Block(-7,31,-1,STONE:0)
Block(-7,31,0,STONE:0)
Block(-7,31,4,STONE:0)
Block(-7,32,-3,STONE:0)
Block(-7,32,-1,STONE:0)
Block(-7,32,0,STONE:0)
Block(-7,32,4,STONE:0)
Block(-7,33,-3,STONE:0)
Block(-7,33,-1,STONE:0)
Block(-7,33,0,STONE:0)
Block(-7,34,-1,STONE:0)
Block(-7,35,-1,STONE:0)
Block(-7,36,-1,STONE:0)
Block(-7,37,-1,STONE:0)
Block(-7,38,-1,STONE:0)
Block(-6,0,-11,STONE:0)
Block(-6,0,-10,STONE:0)
Block(-6,0,-9,STONE:0)
Block(-6,0,-8,STONE:0)
Block(-6,0,-7,STONE:0)
Block(-6,0,-6,STONE:0)
Block(-6,0,-5,STONE:0)
Block(-6,0,-4,STONE:0)
Block(-6,0,-3,STONE:0)
Block(-6,0,-2,STONE:0)
Block(-6,0,-1,STONE:0)
Block(-6,0,0,STONE:0)
Block(-6,0,1,STONE:0)
Block(-6,0,2,STONE:0)
Block(-6,0,3,STONE:0)
Block(-6,0,4,STONE:0)
Block(-6,0,5,STONE:0)
Block(-6,0,6,STONE:0)
Block(-6,0,7,STONE:0)
Block(-6,0,8,STONE:0)
Block(-6,0,9,STONE:0)
Block(-6,1,-11,STONE:0)
Block(-6,1,-10,STONE:0)
Block(-6,1,-9,STONE:0)
Block(-6,1,-8,STONE:0)
Block(-6,1,-7,STONE:0)
Block(-6,1,-6,STONE:0)
Block(-6,1,-5,STONE:0)
Block(-6,1,-4,STONE:0)
Block(-6,1,-3,STONE:0)
Block(-6,1,-2,STONE:0)
Block(-6,1,-1,STONE:0)
Block(-6,1,0,STONE:0)
Block(-6,1,1,STONE:0)
Block(-6,1,2,STONE:0)
Block(-6,1,3,STONE:0)
Block(-6,1,4,STONE:0)
Block(-6,1,5,STONE:0)
Block(-6,1,6,STONE:0)
Block(-6,1,7,STONE:0)
Block(-6,1,8,STONE:0)
Block(-6,1,9,STONE:0)
Block(-6,2,-10,STONE:0)
Block(-6,2,-9,STONE:0)
Block(-6,2,-8,STONE:0)
Block(-6,2,-7,STONE:0)
Block(-6,2,-6,STONE:0)
Block(-6,2,-5,STONE:0)
Block(-6,2,-4,STONE:0)
Block(-6,2,-3,STONE:0)
Block(-6,2,-2,STONE:0)
Block(-6,2,-1,STONE:0)
Block(-6,2,0,STONE:0)
Block(-6,2,1,STONE:0)
Block(-6,2,2,STONE:0)
Block(-6,2,3,STONE:0)
Block(-6,2,4,STONE:0)
Block(-6,2,5,STONE:0)
Block(-6,2,6,STONE:0)
Block(-6,2,7,STONE:0)
Block(-6,2,8,STONE:0)
Block(-6,2,9,STONE:0)
Block(-6,3,-10,STONE:0)
Block(-6,3,-9,STONE:0)
Block(-6,3,-8,STONE:0)
Block(-6,3,-7,STONE:0)
Block(-6,3,-6,STONE:0)
Block(-6,3,-5,STONE:0)
Block(-6,3,-4,STONE:0)
Block(-6,3,-3,STONE:0)
Block(-6,3,-2,STONE:0)
Block(-6,3,-1,STONE:0)
Block(-6,3,0,STONE:0)
Block(-6,3,1,STONE:0)
Block(-6,3,2,STONE:0)
Block(-6,3,3,STONE:0)
Block(-6,3,4,STONE:0)
Block(-6,3,5,STONE:0)
Block(-6,3,6,STONE:0)
Block(-6,3,7,STONE:0)
Block(-6,3,8,STONE:0)
Block(-6,3,9,STONE:0)
Block(-6,4,-9,STONE:0)
Block(-6,4,-8,STONE:0)
Block(-6,4,-7,STONE:0)
Block(-6,4,-6,STONE:0)
Block(-6,4,-5,STONE:0)
Block(-6,4,-4,STONE:0)
Block(-6,4,-3,STONE:0)
Block(-6,4,-2,STONE:0)
Block(-6,4,-1,STONE:0)
Block(-6,4,0,STONE:0)
Block(-6,4,1,STONE:0)
Block(-6,4,2,STONE:0)
Block(-6,4,3,STONE:0)
Block(-6,4,4,STONE:0)
Block(-6,4,5,STONE:0)
Block(-6,4,6,STONE:0)
Block(-6,4,7,STONE:0)
Block(-6,4,8,STONE:0)
Block(-6,4,9,STONE:0)
Block(-6,5,-9,STONE:0)
Block(-6,5,-8,STONE:0)
Block(-6,5,-7,STONE:0)
Block(-6,5,-6,STONE:0)
Block(-6,5,-5,STONE:0)
Block(-6,5,-4,STONE:0)
Block(-6,5,-3,STONE:0)
Block(-6,5,-2,STONE:0)
Block(-6,5,-1,STONE:0)
Block(-6,5,0,STONE:0)
Block(-6,5,1,STONE:0)
Block(-6,5,2,STONE:0)
Block(-6,5,3,STONE:0)
Block(-6,5,4,STONE:0)
Block(-6,5,5,STONE:0)
Block(-6,5,6,STONE:0)
Block(-6,5,7,STONE:0)
Block(-6,5,8,STONE:0)
Block(-6,6,-9,STONE:0)
Block(-6,6,-8,STONE:0)
Block(-6,6,-7,STONE:0)
Block(-6,6,-6,STONE:0)
Block(-6,6,-5,STONE:0)
Block(-6,6,-4,STONE:0)
Block(-6,6,-3,STONE:0)
Block(-6,6,-2,STONE:0)
Block(-6,6,-1,STONE:0)
Block(-6,6,0,STONE:0)
Block(-6,6,1,STONE:0)
Block(-6,6,2,STONE:0)
Block(-6,6,3,STONE:0)
Block(-6,6,4,STONE:0)
Block(-6,6,5,STONE:0)
Block(-6,6,6,STONE:0)
Block(-6,6,7,STONE:0)
Block(-6,6,8,STONE:0)
Block(-6,7,-9,STONE:0)
Block(-6,7,-8,STONE:0)
Block(-6,7,-7,STONE:0)
Block(-6,7,-6,STONE:0)
Block(-6,7,-5,STONE:0)
Block(-6,7,-4,STONE:0)
Block(-6,7,-3,STONE:0)
Block(-6,7,-2,STONE:0)
Block(-6,7,-1,STONE:0)
Block(-6,7,0,STONE:0)
Block(-6,7,1,STONE:0)
Block(-6,7,2,STONE:0)
Block(-6,7,3,STONE:0)
Block(-6,7,4,STONE:0)
Block(-6,7,5,STONE:0)
Block(-6,7,6,STONE:0)
Block(-6,7,7,STONE:0)
Block(-6,7,8,STONE:0)
Block(-6,8,-9,STONE:0)
Block(-6,8,-8,STONE:0)
Block(-6,8,-7,STONE:0)
Block(-6,8,-6,STONE:0)
Block(-6,8,-5,STONE:0)
Block(-6,8,-4,STONE:0)
Block(-6,8,-3,STONE:0)
Block(-6,8,-2,STONE:0)
Block(-6,8,-1,STONE:0)
Block(-6,8,0,STONE:0)
Block(-6,8,1,STONE:0)
Block(-6,8,2,STONE:0)
Block(-6,8,3,STONE:0)
Block(-6,8,4,STONE:0)
Block(-6,8,5,STONE:0)
Block(-6,8,6,STONE:0)
Block(-6,8,7,STONE:0)
Block(-6,8,8,STONE:0)
Block(-6,9,-9,STONE:0)
Block(-6,9,-8,STONE:0)
Block(-6,9,-7,STONE:0)
Block(-6,9,-6,STONE:0)
Block(-6,9,-5,STONE:0)
Block(-6,9,-4,STONE:0)
Block(-6,9,-3,STONE:0)
Block(-6,9,-2,STONE:0)
Block(-6,9,-1,STONE:0)
Block(-6,9,0,STONE:0)
Block(-6,9,1,STONE:0)
Block(-6,9,2,STONE:0)
Block(-6,9,3,STONE:0)
Block(-6,9,4,STONE:0)
Block(-6,9,5,STONE:0)
Block(-6,9,6,STONE:0)
Block(-6,9,7,STONE:0)
Block(-6,9,8,STONE:0)
Block(-6,10,-8,STONE:0)
Block(-6,10,-7,STONE:0)
Block(-6,10,-6,STONE:0)
Block(-6,10,-5,STONE:0)
Block(-6,10,-4,STONE:0)
Block(-6,10,-3,STONE:0)
Block(-6,10,-2,STONE:0)
Block(-6,10,-1,STONE:0)
Block(-6,10,0,STONE:0)
Block(-6,10,1,STONE:0)
Block(-6,10,2,STONE:0)
Block(-6,10,3,STONE:0)
Block(-6,10,4,STONE:0)
Block(-6,10,5,STONE:0)
Block(-6,10,6,STONE:0)
Block(-6,10,7,STONE:0)
Block(-6,10,8,STONE:0)
Block(-6,11,-8,STONE:0)
Block(-6,11,-7,STONE:0)
Block(-6,11,-6,STONE:0)
Block(-6,11,-5,STONE:0)
Block(-6,11,-4,STONE:0)
Block(-6,11,-3,STONE:0)
Block(-6,11,-2,STONE:0)
Block(-6,11,-1,STONE:0)
Block(-6,11,0,STONE:0)
Block(-6,11,1,STONE:0)
Block(-6,11,2,STONE:0)
Block(-6,11,3,STONE:0)
Block(-6,11,4,STONE:0)
Block(-6,11,5,STONE:0)
Block(-6,11,6,STONE:0)
Block(-6,11,7,STONE:0)
Block(-6,11,8,STONE:0)
Block(-6,12,-8,STONE:0)
Block(-6,12,-7,STONE:0)
Block(-6,12,-6,STONE:0)
Block(-6,12,-5,STONE:0)
Block(-6,12,-4,STONE:0)
Block(-6,12,-3,STONE:0)
Block(-6,12,-2,STONE:0)
Block(-6,12,-1,STONE:0)
Block(-6,12,0,STONE:0)
Block(-6,12,1,STONE:0)
Block(-6,12,2,STONE:0)
Block(-6,12,3,STONE:0)
Block(-6,12,4,STONE:0)
Block(-6,12,5,STONE:0)
Block(-6,12,6,STONE:0)
Block(-6,12,7,STONE:0)
Block(-6,12,8,STONE:0)
Block(-6,13,-8,STONE:0)
Block(-6,13,-7,STONE:0)
Block(-6,13,-6,STONE:0)
Block(-6,13,-5,STONE:0)
Block(-6,13,-4,STONE:0)
Block(-6,13,-3,STONE:0)
Block(-6,13,-2,STONE:0)
Block(-6,13,-1,STONE:0)
Block(-6,13,0,STONE:0)
Block(-6,13,1,STONE:0)
Block(-6,13,2,STONE:0)
Block(-6,13,3,STONE:0)
Block(-6,13,4,STONE:0)
Block(-6,13,5,STONE:0)
Block(-6,13,6,STONE:0)
Block(-6,13,7,STONE:0)
Block(-6,13,8,STONE:0)
Block(-6,14,-8,STONE:0)
Block(-6,14,-7,STONE:0)
Block(-6,14,-6,STONE:0)
Block(-6,14,-5,STONE:0)
Block(-6,14,-4,STONE:0)
Block(-6,14,-3,STONE:0)
Block(-6,14,-2,STONE:0)
Block(-6,14,-1,STONE:0)
Block(-6,14,0,STONE:0)
Block(-6,14,1,STONE:0)
Block(-6,14,2,STONE:0)
Block(-6,14,3,STONE:0)
Block(-6,14,4,STONE:0)
Block(-6,14,5,STONE:0)
Block(-6,14,6,STONE:0)
Block(-6,14,7,STONE:0)
Block(-6,14,8,STONE:0)
Block(-6,15,-8,STONE:0)
Block(-6,15,-7,STONE:0)
Block(-6,15,-6,STONE:0)
Block(-6,15,-5,STONE:0)
Block(-6,15,-4,STONE:0)
Block(-6,15,-3,STONE:0)
Block(-6,15,-2,STONE:0)
Block(-6,15,-1,STONE:0)
Block(-6,15,0,STONE:0)
Block(-6,15,1,STONE:0)
Block(-6,15,2,STONE:0)
Block(-6,15,3,STONE:0)
Block(-6,15,4,STONE:0)
Block(-6,15,5,STONE:0)
Block(-6,15,6,STONE:0)
Block(-6,15,7,STONE:0)
Block(-6,15,8,STONE:0)
Block(-6,16,-8,STONE:0)
Block(-6,16,-7,STONE:0)
Block(-6,16,-6,STONE:0)
Block(-6,16,-5,STONE:0)
Block(-6,16,-4,STONE:0)
Block(-6,16,-3,STONE:0)
Block(-6,16,-2,STONE:0)
Block(-6,16,-1,STONE:0)
Block(-6,16,0,STONE:0)
Block(-6,16,1,STONE:0)
Block(-6,16,2,STONE:0)
Block(-6,16,3,STONE:0)
Block(-6,16,4,STONE:0)
Block(-6,16,5,STONE:0)
Block(-6,16,6,STONE:0)
Block(-6,16,7,STONE:0)
Block(-6,17,-8,STONE:0)
Block(-6,17,-7,STONE:0)
Block(-6,17,-6,STONE:0)
Block(-6,17,-5,STONE:0)
Block(-6,17,-4,STONE:0)
Block(-6,17,-3,STONE:0)
Block(-6,17,-2,STONE:0)
Block(-6,17,-1,STONE:0)
Block(-6,17,0,STONE:0)
Block(-6,17,1,STONE:0)
Block(-6,17,2,STONE:0)
Block(-6,17,3,STONE:0)
Block(-6,17,4,STONE:0)
Block(-6,17,5,STONE:0)
Block(-6,17,6,STONE:0)
Block(-6,17,7,STONE:0)
Block(-6,18,-8,STONE:0)
Block(-6,18,-7,STONE:0)
Block(-6,18,-6,STONE:0)
Block(-6,18,-5,STONE:0)
Block(-6,18,-4,STONE:0)
Block(-6,18,-3,STONE:0)
Block(-6,18,-2,STONE:0)
Block(-6,18,-1,STONE:0)
Block(-6,18,0,STONE:0)
Block(-6,18,1,STONE:0)
Block(-6,18,2,STONE:0)
Block(-6,18,3,STONE:0)
Block(-6,18,4,STONE:0)
Block(-6,18,5,STONE:0)
Block(-6,18,6,STONE:0)
Block(-6,18,7,STONE:0)
Block(-6,19,-7,STONE:0)
Block(-6,19,-6,STONE:0)
Block(-6,19,-5,STONE:0)
Block(-6,19,-4,STONE:0)
Block(-6,19,-3,STONE:0)
Block(-6,19,-2,STONE:0)
Block(-6,19,-1,STONE:0)
Block(-6,19,0,STONE:0)
Block(-6,19,1,STONE:0)
Block(-6,19,2,STONE:0)
Block(-6,19,3,STONE:0)
Block(-6,19,4,STONE:0)
Block(-6,19,5,STONE:0)
Block(-6,19,6,STONE:0)
Block(-6,19,7,STONE:0)
Block(-6,20,-7,STONE:0)
Block(-6,20,-6,STONE:0)
Block(-6,20,-5,STONE:0)
Block(-6,20,-4,STONE:0)
Block(-6,20,-3,STONE:0)
Block(-6,20,-2,STONE:0)
Block(-6,20,-1,STONE:0)
Block(-6,20,0,STONE:0)
Block(-6,20,1,STONE:0)
Block(-6,20,2,STONE:0)
Block(-6,20,3,STONE:0)
Block(-6,20,4,STONE:0)
Block(-6,20,5,STONE:0)
Block(-6,20,6,STONE:0)
Block(-6,20,7,STONE:0)
Block(-6,21,-7,STONE:0)
Block(-6,21,-6,STONE:0)
Block(-6,21,-5,STONE:0)
Block(-6,21,-4,STONE:0)
Block(-6,21,-3,STONE:0)
Block(-6,21,-2,STONE:0)
Block(-6,21,-1,STONE:0)
Block(-6,21,0,STONE:0)
Block(-6,21,1,STONE:0)
Block(-6,21,2,STONE:0)
Block(-6,21,3,STONE:0)
Block(-6,21,4,STONE:0)
Block(-6,21,5,STONE:0)
Block(-6,21,6,STONE:0)
Block(-6,21,7,STONE:0)
Block(-6,22,-7,STONE:0)
Block(-6,22,-6,STONE:0)
Block(-6,22,-5,STONE:0)
Block(-6,22,-4,STONE:0)
Block(-6,22,-3,STONE:0)
Block(-6,22,-2,STONE:0)
Block(-6,22,-1,STONE:0)
Block(-6,22,0,STONE:0)
Block(-6,22,1,STONE:0)
Block(-6,22,2,STONE:0)
Block(-6,22,3,STONE:0)
Block(-6,22,4,STONE:0)
Block(-6,22,5,STONE:0)
Block(-6,22,6,STONE:0)
Block(-6,23,-7,STONE:0)
Block(-6,23,-6,STONE:0)
Block(-6,23,-5,STONE:0)
Block(-6,23,-4,STONE:0)
Block(-6,23,-3,STONE:0)
Block(-6,23,-2,STONE:0)
Block(-6,23,-1,STONE:0)
Block(-6,23,0,STONE:0)
Block(-6,23,1,STONE:0)
Block(-6,23,2,STONE:0)
Block(-6,23,3,STONE:0)
Block(-6,23,4,STONE:0)
Block(-6,23,5,STONE:0)
Block(-6,23,6,STONE:0)
Block(-6,24,-7,STONE:0)
Block(-6,24,-6,STONE:0)
Block(-6,24,-5,STONE:0)
Block(-6,24,-4,STONE:0)
Block(-6,24,-3,STONE:0)
Block(-6,24,-2,STONE:0)
Block(-6,24,-1,STONE:0)
Block(-6,24,0,STONE:0)
Block(-6,24,1,STONE:0)
Block(-6,24,2,STONE:0)
Block(-6,24,3,STONE:0)
Block(-6,24,4,STONE:0)
Block(-6,24,5,STONE:0)
Block(-6,24,6,STONE:0)
Block(-6,25,-7,STONE:0)
Block(-6,25,-6,STONE:0)
Block(-6,25,-5,STONE:0)
Block(-6,25,-4,STONE:0)
Block(-6,25,-3,STONE:0)
Block(-6,25,-2,STONE:0)
Block(-6,25,-1,STONE:0)
Block(-6,25,0,STONE:0)
Block(-6,25,1,STONE:0)
Block(-6,25,2,STONE:0)
Block(-6,25,3,STONE:0)
Block(-6,25,4,STONE:0)
Block(-6,25,5,STONE:0)
Block(-6,25,6,STONE:0)
Block(-6,26,-7,STONE:0)
Block(-6,26,-6,STONE:0)
Block(-6,26,-5,STONE:0)
Block(-6,26,-4,STONE:0)
Block(-6,26,-3,STONE:0)
Block(-6,26,-2,STONE:0)
Block(-6,26,-1,STONE:0)
Block(-6,26,0,STONE:0)
Block(-6,26,1,STONE:0)
Block(-6,26,2,STONE:0)
Block(-6,26,3,STONE:0)
Block(-6,26,4,STONE:0)
Block(-6,26,5,STONE:0)
Block(-6,26,6,STONE:0)
Block(-6,27,-7,STONE:0)
Block(-6,27,-6,STONE:0)
Block(-6,27,-5,STONE:0)
Block(-6,27,-4,STONE:0)
Block(-6,27,-3,STONE:0)
Block(-6,27,-2,STONE:0)
Block(-6,27,-1,STONE:0)
Block(-6,27,0,STONE:0)
Block(-6,27,1,STONE:0)
Block(-6,27,2,STONE:0)
Block(-6,27,3,STONE:0)
Block(-6,27,4,STONE:0)
Block(-6,27,5,STONE:0)
Block(-6,27,6,STONE:0)
Block(-6,28,-7,STONE:0)
Block(-6,28,-6,STONE:0)
Block(-6,28,-5,STONE:0)
Block(-6,28,-4,STONE:0)
Block(-6,28,-3,STONE:0)
Block(-6,28,-2,STONE:0)
Block(-6,28,-1,STONE:0)
Block(-6,28,0,STONE:0)
Block(-6,28,1,STONE:0)
Block(-6,28,2,STONE:0)
Block(-6,28,3,STONE:0)
Block(-6,28,4,STONE:0)
Block(-6,28,5,STONE:0)
Block(-6,28,6,STONE:0)
Block(-6,29,-7,STONE:0)
Block(-6,29,-6,STONE:0)
Block(-6,29,-5,STONE:0)
Block(-6,29,-4,STONE:0)
Block(-6,29,-3,STONE:0)
Block(-6,29,-2,STONE:0)
Block(-6,29,-1,STONE:0)
Block(-6,29,0,STONE:0)
Block(-6,29,1,STONE:0)
Block(-6,29,2,STONE:0)
Block(-6,29,3,STONE:0)
Block(-6,29,4,STONE:0)
Block(-6,29,5,STONE:0)
Block(-6,29,6,STONE:0)
Block(-6,30,-6,STONE:0)
Block(-6,30,-5,STONE:0)
Block(-6,30,-4,STONE:0)
Block(-6,30,-3,STONE:0)
Block(-6,30,-2,STONE:0)
Block(-6,30,-1,STONE:0)
Block(-6,30,0,STONE:0)
Block(-6,30,1,STONE:0)
Block(-6,30,2,STONE:0)
Block(-6,30,3,STONE:0)
Block(-6,30,4,STONE:0)
Block(-6,30,5,STONE:0)
Block(-6,30,6,STONE:0)
Block(-6,31,-5,STONE:0)
Block(-6,31,-4,STONE:0)
Block(-6,31,-3,STONE:0)
Block(-6,31,-2,STONE:0)
Block(-6,31,-1,STONE:0)
Block(-6,31,0,STONE:0)
Block(-6,31,1,STONE:0)
Block(-6,31,2,STONE:0)
Block(-6,31,3,STONE:0)
Block(-6,31,4,STONE:0)
Block(-6,31,5,STONE:0)
Block(-6,31,6,STONE:0)
Block(-6,32,-5,STONE:0)
Block(-6,32,-4,STONE:0)
Block(-6,32,-3,STONE:0)
Block(-6,32,-2,STONE:0)
Block(-6,32,-1,STONE:0)
Block(-6,32,0,STONE:0)
Block(-6,32,1,STONE:0)
Block(-6,32,2,STONE:0)
Block(-6,32,3,STONE:0)
Block(-6,32,4,STONE:0)
Block(-6,32,5,STONE:0)
Block(-6,32,6,STONE:0)
Block(-6,33,-5,STONE:0)
Block(-6,33,-4,STONE:0)
Block(-6,33,-3,STONE:0)
Block(-6,33,-2,STONE:0)
Block(-6,33,-1,STONE:0)
Block(-6,33,0,STONE:0)
Block(-6,33,1,STONE:0)
Block(-6,33,2,STONE:0)
Block(-6,33,3,STONE:0)
Block(-6,33,4,STONE:0)
Block(-6,33,5,STONE:0)
Block(-6,33,6,STONE:0)
Block(-6,34,-4,STONE:0)
Block(-6,34,-3,STONE:0)
Block(-6,34,-2,STONE:0)
Block(-6,34,-1,STONE:0)
Block(-6,34,0,STONE:0)
Block(-6,34,1,STONE:0)
Block(-6,34,2,STONE:0)
Block(-6,34,3,STONE:0)
Block(-6,34,4,STONE:0)
Block(-6,34,5,STONE:0)
Block(-6,34,6,STONE:0)
Block(-6,35,-4,STONE:0)
Block(-6,35,-3,STONE:0)
Block(-6,35,-2,STONE:0)
Block(-6,35,-1,STONE:0)
Block(-6,35,0,STONE:0)
Block(-6,35,1,STONE:0)
Block(-6,35,2,STONE:0)
Block(-6,35,3,STONE:0)
Block(-6,35,4,STONE:0)
Block(-6,35,5,STONE:0)
Block(-6,35,6,STONE:0)
Block(-6,36,-4,STONE:0)
Block(-6,36,-3,STONE:0)
Block(-6,36,-2,STONE:0)
Block(-6,36,-1,STONE:0)
Block(-6,36,0,STONE:0)
Block(-6,36,1,STONE:0)
Block(-6,36,2,STONE:0)
Block(-6,36,3,STONE:0)
Block(-6,36,4,STONE:0)
Block(-6,36,5,STONE:0)
Block(-6,36,6,STONE:0)
Block(-6,37,-4,STONE:0)
Block(-6,37,-3,STONE:0)
Block(-6,37,-2,STONE:0)
Block(-6,37,-1,STONE:0)
Block(-6,37,0,STONE:0)
Block(-6,37,1,STONE:0)
Block(-6,37,2,STONE:0)
Block(-6,37,3,STONE:0)
Block(-6,37,4,STONE:0)
Block(-6,37,5,STONE:0)
Block(-6,37,6,STONE:0)
Block(-6,38,-4,STONE:0)
Block(-6,38,-3,STONE:0)
Block(-6,38,-2,STONE:0)
Block(-6,38,-1,STONE:0)
Block(-6,38,0,STONE:0)
Block(-6,38,1,STONE:0)
Block(-6,38,2,STONE:0)
Block(-6,38,4,STONE:0)
Block(-6,38,5,STONE:0)
Block(-6,38,6,STONE:0)
Block(-6,39,-4,STONE:0)
Block(-6,39,-3,STONE:0)
Block(-6,39,-2,STONE:0)
Block(-6,39,-1,STONE:0)
Block(-6,39,0,STONE:0)
Block(-6,39,1,STONE:0)
Block(-6,39,2,STONE:0)
Block(-6,39,4,STONE:0)
Block(-6,39,5,STONE:0)
Block(-6,39,6,STONE:0)
Block(-6,40,-3,STONE:0)
Block(-6,40,-2,STONE:0)
Block(-6,40,-1,STONE:0)
Block(-6,40,0,STONE:0)
Block(-6,40,1,STONE:0)
Block(-6,40,2,STONE:0)
Block(-6,40,4,STONE:0)
Block(-6,40,5,STONE:0)
Block(-6,41,-3,STONE:0)
Block(-6,41,-1,STONE:0)
Block(-6,41,0,STONE:0)
Block(-6,41,1,STONE:0)
Block(-6,41,2,STONE:0)
Block(-6,41,4,STONE:0)
Block(-6,41,5,STONE:0)
Block(-6,42,-1,STONE:0)
Block(-6,42,0,STONE:0)
Block(-6,42,1,STONE:0)
Block(-6,42,2,STONE:0)
Block(-6,42,4,STONE:0)
Block(-6,42,5,STONE:0)
Block(-6,43,-1,STONE:0)
Block(-6,43,0,STONE:0)
Block(-6,43,1,STONE:0)
Block(-6,43,4,STONE:0)
Block(-6,43,5,STONE:0)
Block(-6,44,-1,STONE:0)
Block(-6,44,0,STONE:0)
Block(-6,44,4,STONE:0)
Block(-6,44,5,STONE:0)
Block(-6,45,-1,STONE:0)
Block(-6,45,0,STONE:0)
Block(-6,45,4,STONE:0)
Block(-6,45,5,STONE:0)
Block(-6,46,-1,STONE:0)
Block(-6,46,0,STONE:0)
Block(-6,46,4,STONE:0)
Block(-6,46,5,STONE:0)
Block(-6,47,-1,STONE:0)
Block(-6,47,0,STONE:0)
Block(-6,47,4,STONE:0)
Block(-6,47,5,STONE:0)
Block(-6,48,-1,STONE:0)
Block(-6,48,0,STONE:0)
Block(-6,48,4,STONE:0)
Block(-6,48,5,STONE:0)
Block(-6,49,-1,STONE:0)
Block(-6,49,0,STONE:0)
Block(-6,49,4,STONE:0)
Block(-6,49,5,STONE:0)
Block(-6,50,-1,STONE:0)
Block(-6,50,0,STONE:0)
Block(-6,50,4,STONE:0)
Block(-6,51,-1,STONE:0)
Block(-6,51,0,STONE:0)
Block(-6,51,4,STONE:0)
Block(-6,52,-1,STONE:0)
Block(-6,52,0,STONE:0)
Block(-6,52,4,STONE:0)
Block(-6,53,-1,STONE:0)
Block(-6,53,0,STONE:0)
Block(-6,53,4,STONE:0)
Block(-6,54,-1,STONE:0)
Block(-6,54,0,STONE:0)
Block(-6,55,-1,STONE:0)
Block(-6,55,0,STONE:0)
Block(-6,56,-1,STONE:0)
Block(-6,56,0,STONE:0)
Block(-6,57,-1,STONE:0)
Block(-6,57,0,STONE:0)
Block(-6,58,0,STONE:0)
Block(-5,0,-11,STONE:0)
Block(-5,0,-10,STONE:0)
Block(-5,0,-9,STONE:0)
Block(-5,0,-8,STONE:0)
Block(-5,0,-7,STONE:0)
Block(-5,0,-6,STONE:0)
Block(-5,0,-5,STONE:0)
Block(-5,0,-4,STONE:0)
Block(-5,0,-3,STONE:0)
Block(-5,0,-2,STONE:0)
Block(-5,0,-1,STONE:0)
Block(-5,0,0,STONE:0)
Block(-5,0,1,STONE:0)
Block(-5,0,2,STONE:0)
Block(-5,0,3,STONE:0)
Block(-5,0,4,STONE:0)
Block(-5,0,5,STONE:0)
Block(-5,0,6,STONE:0)
Block(-5,0,7,STONE:0)
Block(-5,0,8,STONE:0)
Block(-5,0,9,STONE:0)
Block(-5,0,10,STONE:0)
Block(-5,1,-10,STONE:0)
Block(-5,1,-9,STONE:0)
Block(-5,1,-8,STONE:0)
Block(-5,1,-7,STONE:0)
Block(-5,1,-6,STONE:0)
Block(-5,1,-5,STONE:0)
Block(-5,1,-4,STONE:0)
Block(-5,1,-3,STONE:0)
Block(-5,1,-2,STONE:0)
Block(-5,1,-1,STONE:0)
Block(-5,1,0,STONE:0)
Block(-5,1,1,STONE:0)
Block(-5,1,2,STONE:0)
Block(-5,1,3,STONE:0)
Block(-5,1,4,STONE:0)
Block(-5,1,5,STONE:0)
Block(-5,1,6,STONE:0)
Block(-5,1,7,STONE:0)
Block(-5,1,8,STONE:0)
Block(-5,1,9,STONE:0)
Block(-5,2,-10,STONE:0)
Block(-5,2,-9,STONE:0)
Block(-5,2,-8,STONE:0)
Block(-5,2,-7,STONE:0)
Block(-5,2,-6,STONE:0)
Block(-5,2,-5,STONE:0)
Block(-5,2,-4,STONE:0)
Block(-5,2,-3,STONE:0)
Block(-5,2,-2,STONE:0)
Block(-5,2,-1,STONE:0)
Block(-5,2,0,STONE:0)
Block(-5,2,1,STONE:0)
Block(-5,2,2,STONE:0)
Block(-5,2,3,STONE:0)
Block(-5,2,4,STONE:0)
Block(-5,2,5,STONE:0)
Block(-5,2,6,STONE:0)
Block(-5,2,7,STONE:0)
Block(-5,2,8,STONE:0)
Block(-5,2,9,STONE:0)
Block(-5,3,-9,STONE:0)
Block(-5,3,-8,STONE:0)
Block(-5,3,-7,STONE:0)
Block(-5,3,-6,STONE:0)
Block(-5,3,-5,STONE:0)
Block(-5,3,-4,STONE:0)
Block(-5,3,-3,STONE:0)
Block(-5,3,-2,STONE:0)
Block(-5,3,-1,STONE:0)
Block(-5,3,0,STONE:0)
Block(-5,3,1,STONE:0)
Block(-5,3,2,STONE:0)
Block(-5,3,3,STONE:0)
Block(-5,3,4,STONE:0)
Block(-5,3,5,STONE:0)
Block(-5,3,6,STONE:0)
Block(-5,3,7,STONE:0)
Block(-5,3,8,STONE:0)
Block(-5,3,9,STONE:0)
Block(-5,4,-9,STONE:0)
Block(-5,4,-8,STONE:0)
Block(-5,4,-7,STONE:0)
Block(-5,4,-6,STONE:0)
Block(-5,4,-5,STONE:0)
Block(-5,4,-4,STONE:0)
Block(-5,4,-3,STONE:0)
Block(-5,4,-2,STONE:0)
Block(-5,4,-1,STONE:0)
Block(-5,4,0,STONE:0)
Block(-5,4,1,STONE:0)
Block(-5,4,2,STONE:0)
Block(-5,4,3,STONE:0)
Block(-5,4,4,STONE:0)
Block(-5,4,5,STONE:0)
Block(-5,4,6,STONE:0)
Block(-5,4,7,STONE:0)
Block(-5,4,8,STONE:0)
Block(-5,4,9,STONE:0)
Block(-5,5,-9,STONE:0)
Block(-5,5,-8,STONE:0)
Block(-5,5,-7,STONE:0)
Block(-5,5,-6,STONE:0)
Block(-5,5,-5,STONE:0)
Block(-5,5,-4,STONE:0)
Block(-5,5,-3,STONE:0)
Block(-5,5,-2,STONE:0)
Block(-5,5,-1,STONE:0)
Block(-5,5,0,STONE:0)
Block(-5,5,1,STONE:0)
Block(-5,5,2,STONE:0)
Block(-5,5,3,STONE:0)
Block(-5,5,4,STONE:0)
Block(-5,5,5,STONE:0)
Block(-5,5,6,STONE:0)
Block(-5,5,7,STONE:0)
Block(-5,5,8,STONE:0)
Block(-5,5,9,STONE:0)
Block(-5,6,-9,STONE:0)
Block(-5,6,-8,STONE:0)
Block(-5,6,-7,STONE:0)
Block(-5,6,-6,STONE:0)
Block(-5,6,-5,STONE:0)
Block(-5,6,-4,STONE:0)
Block(-5,6,-3,STONE:0)
Block(-5,6,-2,STONE:0)
Block(-5,6,-1,STONE:0)
Block(-5,6,0,STONE:0)
Block(-5,6,1,STONE:0)
Block(-5,6,2,STONE:0)
Block(-5,6,3,STONE:0)
Block(-5,6,4,STONE:0)
Block(-5,6,5,STONE:0)
Block(-5,6,6,STONE:0)
Block(-5,6,7,STONE:0)
Block(-5,6,8,STONE:0)
Block(-5,6,9,STONE:0)
Block(-5,7,-9,STONE:0)
Block(-5,7,-8,STONE:0)
Block(-5,7,-7,STONE:0)
Block(-5,7,-6,STONE:0)
Block(-5,7,-5,STONE:0)
Block(-5,7,-4,STONE:0)
Block(-5,7,-3,STONE:0)
Block(-5,7,-2,STONE:0)
Block(-5,7,-1,STONE:0)
Block(-5,7,0,STONE:0)
Block(-5,7,1,STONE:0)
Block(-5,7,2,STONE:0)
Block(-5,7,3,STONE:0)
Block(-5,7,4,STONE:0)
Block(-5,7,5,STONE:0)
Block(-5,7,6,STONE:0)
Block(-5,7,7,STONE:0)
Block(-5,7,8,STONE:0)
Block(-5,7,9,STONE:0)
Block(-5,8,-9,STONE:0)
Block(-5,8,-8,STONE:0)
Block(-5,8,-7,STONE:0)
Block(-5,8,-6,STONE:0)
Block(-5,8,-5,STONE:0)
Block(-5,8,-4,STONE:0)
Block(-5,8,-3,STONE:0)
Block(-5,8,-2,STONE:0)
Block(-5,8,-1,STONE:0)
Block(-5,8,0,STONE:0)
Block(-5,8,1,STONE:0)
Block(-5,8,2,STONE:0)
Block(-5,8,3,STONE:0)
Block(-5,8,4,STONE:0)
Block(-5,8,5,STONE:0)
Block(-5,8,6,STONE:0)
Block(-5,8,7,STONE:0)
Block(-5,8,8,STONE:0)
Block(-5,8,9,STONE:0)
Block(-5,9,-9,STONE:0)
Block(-5,9,-8,STONE:0)
Block(-5,9,-7,STONE:0)
Block(-5,9,-6,STONE:0)
Block(-5,9,-5,STONE:0)
Block(-5,9,-4,STONE:0)
Block(-5,9,-3,STONE:0)
Block(-5,9,-2,STONE:0)
Block(-5,9,-1,STONE:0)
Block(-5,9,0,STONE:0)
Block(-5,9,1,STONE:0)
Block(-5,9,2,STONE:0)
Block(-5,9,3,STONE:0)
Block(-5,9,4,STONE:0)
Block(-5,9,5,STONE:0)
Block(-5,9,6,STONE:0)
Block(-5,9,7,STONE:0)
Block(-5,9,8,STONE:0)
Block(-5,10,-9,STONE:0)
Block(-5,10,-8,STONE:0)
Block(-5,10,-7,STONE:0)
Block(-5,10,-6,STONE:0)
Block(-5,10,-5,STONE:0)
Block(-5,10,-4,STONE:0)
Block(-5,10,-3,STONE:0)
Block(-5,10,-2,STONE:0)
Block(-5,10,-1,STONE:0)
Block(-5,10,0,STONE:0)
Block(-5,10,1,STONE:0)
Block(-5,10,2,STONE:0)
Block(-5,10,3,STONE:0)
Block(-5,10,4,STONE:0)
Block(-5,10,5,STONE:0)
Block(-5,10,6,STONE:0)
Block(-5,10,7,STONE:0)
Block(-5,10,8,STONE:0)
Block(-5,11,-8,STONE:0)
Block(-5,11,-7,STONE:0)
Block(-5,11,-6,STONE:0)
Block(-5,11,-5,STONE:0)
Block(-5,11,-4,STONE:0)
Block(-5,11,-3,STONE:0)
Block(-5,11,-2,STONE:0)
Block(-5,11,-1,STONE:0)
Block(-5,11,0,STONE:0)
Block(-5,11,1,STONE:0)
Block(-5,11,2,STONE:0)
Block(-5,11,3,STONE:0)
Block(-5,11,4,STONE:0)
Block(-5,11,5,STONE:0)
Block(-5,11,6,STONE:0)
Block(-5,11,7,STONE:0)
Block(-5,11,8,STONE:0)
Block(-5,12,-8,STONE:0)
Block(-5,12,-7,STONE:0)
Block(-5,12,-6,STONE:0)
Block(-5,12,-5,STONE:0)
Block(-5,12,-4,STONE:0)
Block(-5,12,-3,STONE:0)
Block(-5,12,-2,STONE:0)
Block(-5,12,-1,STONE:0)
Block(-5,12,0,STONE:0)
Block(-5,12,1,STONE:0)
Block(-5,12,2,STONE:0)
Block(-5,12,3,STONE:0)
Block(-5,12,4,STONE:0)
Block(-5,12,5,STONE:0)
Block(-5,12,6,STONE:0)
Block(-5,12,7,STONE:0)
Block(-5,12,8,STONE:0)
Block(-5,13,-8,STONE:0)
Block(-5,13,-7,STONE:0)
Block(-5,13,-6,STONE:0)
Block(-5,13,-5,STONE:0)
Block(-5,13,-4,STONE:0)
Block(-5,13,-3,STONE:0)
Block(-5,13,-2,STONE:0)
Block(-5,13,-1,STONE:0)
Block(-5,13,0,STONE:0)
Block(-5,13,1,STONE:0)
Block(-5,13,2,STONE:0)
Block(-5,13,3,STONE:0)
Block(-5,13,4,STONE:0)
Block(-5,13,5,STONE:0)
Block(-5,13,6,STONE:0)
Block(-5,13,7,STONE:0)
Block(-5,13,8,STONE:0)
Block(-5,14,-8,STONE:0)
Block(-5,14,-7,STONE:0)
Block(-5,14,-6,STONE:0)
Block(-5,14,-5,STONE:0)
Block(-5,14,-4,STONE:0)
Block(-5,14,-3,STONE:0)
Block(-5,14,-2,STONE:0)
Block(-5,14,-1,STONE:0)
Block(-5,14,0,STONE:0)
Block(-5,14,1,STONE:0)
Block(-5,14,2,STONE:0)
Block(-5,14,3,STONE:0)
Block(-5,14,4,STONE:0)
Block(-5,14,5,STONE:0)
Block(-5,14,6,STONE:0)
Block(-5,14,7,STONE:0)
Block(-5,14,8,STONE:0)
Block(-5,15,-8,STONE:0)
Block(-5,15,-7,STONE:0)
Block(-5,15,-6,STONE:0)
Block(-5,15,-5,STONE:0)
Block(-5,15,-4,STONE:0)
Block(-5,15,-3,STONE:0)
Block(-5,15,-2,STONE:0)
Block(-5,15,-1,STONE:0)
Block(-5,15,0,STONE:0)
Block(-5,15,1,STONE:0)
Block(-5,15,2,STONE:0)
Block(-5,15,3,STONE:0)
Block(-5,15,4,STONE:0)
Block(-5,15,5,STONE:0)
Block(-5,15,6,STONE:0)
Block(-5,15,7,STONE:0)
Block(-5,15,8,STONE:0)
Block(-5,16,-8,STONE:0)
Block(-5,16,-7,STONE:0)
Block(-5,16,-6,STONE:0)
Block(-5,16,-5,STONE:0)
Block(-5,16,-4,STONE:0)
Block(-5,16,-3,STONE:0)
Block(-5,16,-2,STONE:0)
Block(-5,16,-1,STONE:0)
Block(-5,16,0,STONE:0)
Block(-5,16,1,STONE:0)
Block(-5,16,2,STONE:0)
Block(-5,16,3,STONE:0)
Block(-5,16,4,STONE:0)
Block(-5,16,5,STONE:0)
Block(-5,16,6,STONE:0)
Block(-5,16,7,STONE:0)
Block(-5,16,8,STONE:0)
Block(-5,17,-8,STONE:0)
Block(-5,17,-7,STONE:0)
Block(-5,17,-6,STONE:0)
Block(-5,17,-5,STONE:0)
Block(-5,17,-4,STONE:0)
Block(-5,17,-3,STONE:0)
Block(-5,17,-2,STONE:0)
Block(-5,17,-1,STONE:0)
Block(-5,17,0,STONE:0)
Block(-5,17,1,STONE:0)
Block(-5,17,2,STONE:0)
Block(-5,17,3,STONE:0)
Block(-5,17,4,STONE:0)
Block(-5,17,5,STONE:0)
Block(-5,17,6,STONE:0)
Block(-5,17,7,STONE:0)
Block(-5,17,8,STONE:0)
Block(-5,18,-8,STONE:0)
Block(-5,18,-7,STONE:0)
Block(-5,18,-6,STONE:0)
Block(-5,18,-5,STONE:0)
Block(-5,18,-4,STONE:0)
Block(-5,18,-3,STONE:0)
Block(-5,18,-2,STONE:0)
Block(-5,18,-1,STONE:0)
Block(-5,18,0,STONE:0)
Block(-5,18,1,STONE:0)
Block(-5,18,2,STONE:0)
Block(-5,18,3,STONE:0)
Block(-5,18,4,STONE:0)
Block(-5,18,5,STONE:0)
Block(-5,18,6,STONE:0)
Block(-5,18,7,STONE:0)
Block(-5,18,8,STONE:0)
Block(-5,19,-7,STONE:0)
Block(-5,19,-6,STONE:0)
Block(-5,19,-5,STONE:0)
Block(-5,19,-4,STONE:0)
Block(-5,19,-3,STONE:0)
Block(-5,19,-2,STONE:0)
Block(-5,19,-1,STONE:0)
Block(-5,19,0,STONE:0)
Block(-5,19,1,STONE:0)
Block(-5,19,2,STONE:0)
Block(-5,19,3,STONE:0)
Block(-5,19,4,STONE:0)
Block(-5,19,5,STONE:0)
Block(-5,19,6,STONE:0)
Block(-5,19,7,STONE:0)
Block(-5,19,8,STONE:0)
Block(-5,20,-7,STONE:0)
Block(-5,20,-6,STONE:0)
Block(-5,20,-5,STONE:0)
Block(-5,20,-4,STONE:0)
Block(-5,20,-3,STONE:0)
Block(-5,20,-2,STONE:0)
Block(-5,20,-1,STONE:0)
Block(-5,20,0,STONE:0)
Block(-5,20,1,STONE:0)
Block(-5,20,2,STONE:0)
Block(-5,20,3,STONE:0)
Block(-5,20,4,STONE:0)
Block(-5,20,5,STONE:0)
Block(-5,20,6,STONE:0)
Block(-5,20,7,STONE:0)
Block(-5,20,8,STONE:0)
Block(-5,21,-7,STONE:0)
Block(-5,21,-6,STONE:0)
Block(-5,21,-5,STONE:0)
Block(-5,21,-4,STONE:0)
Block(-5,21,-3,STONE:0)
Block(-5,21,-2,STONE:0)
Block(-5,21,-1,STONE:0)
Block(-5,21,0,STONE:0)
Block(-5,21,1,STONE:0)
Block(-5,21,2,STONE:0)
Block(-5,21,3,STONE:0)
Block(-5,21,4,STONE:0)
Block(-5,21,5,STONE:0)
Block(-5,21,6,STONE:0)
Block(-5,21,7,STONE:0)
Block(-5,21,8,STONE:0)
Block(-5,22,-7,STONE:0)
Block(-5,22,-6,STONE:0)
Block(-5,22,-5,STONE:0)
Block(-5,22,-4,STONE:0)
Block(-5,22,-3,STONE:0)
Block(-5,22,-2,STONE:0)
Block(-5,22,-1,STONE:0)
Block(-5,22,0,STONE:0)
Block(-5,22,1,STONE:0)
Block(-5,22,2,STONE:0)
Block(-5,22,3,STONE:0)
Block(-5,22,4,STONE:0)
Block(-5,22,5,STONE:0)
Block(-5,22,6,STONE:0)
Block(-5,22,7,STONE:0)
Block(-5,22,8,STONE:0)
Block(-5,23,-7,STONE:0)
Block(-5,23,-6,STONE:0)
Block(-5,23,-5,STONE:0)
Block(-5,23,-4,STONE:0)
Block(-5,23,-3,STONE:0)
Block(-5,23,-2,STONE:0)
Block(-5,23,-1,STONE:0)
Block(-5,23,0,STONE:0)
Block(-5,23,1,STONE:0)
Block(-5,23,2,STONE:0)
Block(-5,23,3,STONE:0)
Block(-5,23,4,STONE:0)
Block(-5,23,5,STONE:0)
Block(-5,23,6,STONE:0)
Block(-5,23,7,STONE:0)
Block(-5,23,8,STONE:0)
Block(-5,24,-7,STONE:0)
Block(-5,24,-6,STONE:0)
Block(-5,24,-5,STONE:0)
Block(-5,24,-4,STONE:0)
Block(-5,24,-3,STONE:0)
Block(-5,24,-2,STONE:0)
Block(-5,24,-1,STONE:0)
Block(-5,24,0,STONE:0)
Block(-5,24,1,STONE:0)
Block(-5,24,2,STONE:0)
Block(-5,24,3,STONE:0)
Block(-5,24,4,STONE:0)
Block(-5,24,5,STONE:0)
Block(-5,24,6,STONE:0)
Block(-5,24,7,STONE:0)
Block(-5,24,8,STONE:0)
Block(-5,25,-7,STONE:0)
Block(-5,25,-6,STONE:0)
Block(-5,25,-5,STONE:0)
Block(-5,25,-4,STONE:0)
Block(-5,25,-3,STONE:0)
Block(-5,25,-2,STONE:0)
Block(-5,25,-1,STONE:0)
Block(-5,25,0,STONE:0)
Block(-5,25,1,STONE:0)
Block(-5,25,2,STONE:0)
Block(-5,25,3,STONE:0)
Block(-5,25,4,STONE:0)
Block(-5,25,5,STONE:0)
Block(-5,25,6,STONE:0)
Block(-5,25,7,STONE:0)
Block(-5,25,8,STONE:0)
Block(-5,26,-7,STONE:0)
Block(-5,26,-6,STONE:0)
Block(-5,26,-5,STONE:0)
Block(-5,26,-4,STONE:0)
Block(-5,26,-3,STONE:0)
Block(-5,26,-2,STONE:0)
Block(-5,26,-1,STONE:0)
Block(-5,26,0,STONE:0)
Block(-5,26,1,STONE:0)
Block(-5,26,2,STONE:0)
Block(-5,26,3,STONE:0)
Block(-5,26,4,STONE:0)
Block(-5,26,5,STONE:0)
Block(-5,26,6,STONE:0)
Block(-5,26,7,STONE:0)
Block(-5,26,8,STONE:0)
Block(-5,27,-7,STONE:0)
Block(-5,27,-6,STONE:0)
Block(-5,27,-5,STONE:0)
Block(-5,27,-4,STONE:0)
Block(-5,27,-3,STONE:0)
Block(-5,27,-2,STONE:0)
Block(-5,27,-1,STONE:0)
Block(-5,27,0,STONE:0)
Block(-5,27,1,STONE:0)
Block(-5,27,2,STONE:0)
Block(-5,27,3,STONE:0)
Block(-5,27,4,STONE:0)
Block(-5,27,5,STONE:0)
Block(-5,27,6,STONE:0)
Block(-5,27,7,STONE:0)
Block(-5,27,8,STONE:0)
Block(-5,28,-7,STONE:0)
Block(-5,28,-6,STONE:0)
Block(-5,28,-5,STONE:0)
Block(-5,28,-4,STONE:0)
Block(-5,28,-3,STONE:0)
Block(-5,28,-2,STONE:0)
Block(-5,28,-1,STONE:0)
Block(-5,28,0,STONE:0)
Block(-5,28,1,STONE:0)
Block(-5,28,2,STONE:0)
Block(-5,28,3,STONE:0)
Block(-5,28,4,STONE:0)
Block(-5,28,5,STONE:0)
Block(-5,28,6,STONE:0)
Block(-5,28,7,STONE:0)
Block(-5,28,8,STONE:0)
Block(-5,29,-7,STONE:0)
Block(-5,29,-6,STONE:0)
Block(-5,29,-5,STONE:0)
Block(-5,29,-4,STONE:0)
Block(-5,29,-3,STONE:0)
Block(-5,29,-2,STONE:0)
Block(-5,29,-1,STONE:0)
Block(-5,29,0,STONE:0)
Block(-5,29,1,STONE:0)
Block(-5,29,2,STONE:0)
Block(-5,29,3,STONE:0)
Block(-5,29,4,STONE:0)
Block(-5,29,5,STONE:0)
Block(-5,29,6,STONE:0)
Block(-5,29,7,STONE:0)
Block(-5,29,8,STONE:0)
Block(-5,30,-7,STONE:0)
Block(-5,30,-6,STONE:0)
Block(-5,30,-5,STONE:0)
Block(-5,30,-4,STONE:0)
Block(-5,30,-3,STONE:0)
Block(-5,30,-2,STONE:0)
Block(-5,30,-1,STONE:0)
Block(-5,30,0,STONE:0)
Block(-5,30,1,STONE:0)
Block(-5,30,2,STONE:0)
Block(-5,30,3,STONE:0)
Block(-5,30,4,STONE:0)
Block(-5,30,5,STONE:0)
Block(-5,30,6,STONE:0)
Block(-5,30,7,STONE:0)
Block(-5,30,8,STONE:0)
Block(-5,31,-7,STONE:0)
Block(-5,31,-6,STONE:0)
Block(-5,31,-5,STONE:0)
Block(-5,31,-4,STONE:0)
Block(-5,31,-3,STONE:0)
Block(-5,31,-2,STONE:0)
Block(-5,31,-1,STONE:0)
Block(-5,31,0,STONE:0)
Block(-5,31,1,STONE:0)
Block(-5,31,2,STONE:0)
Block(-5,31,3,STONE:0)
Block(-5,31,4,STONE:0)
Block(-5,31,5,STONE:0)
Block(-5,31,6,STONE:0)
Block(-5,31,7,STONE:0)
Block(-5,31,8,STONE:0)
Block(-5,32,-7,STONE:0)
Block(-5,32,-6,STONE:0)
Block(-5,32,-5,STONE:0)
Block(-5,32,-4,STONE:0)
Block(-5,32,-3,STONE:0)
Block(-5,32,-2,STONE:0)
Block(-5,32,-1,STONE:0)
Block(-5,32,0,STONE:0)
Block(-5,32,1,STONE:0)
Block(-5,32,2,STONE:0)
Block(-5,32,3,STONE:0)
Block(-5,32,4,STONE:0)
Block(-5,32,5,STONE:0)
Block(-5,32,6,STONE:0)
Block(-5,32,7,STONE:0)
Block(-5,32,8,STONE:0)
Block(-5,33,-6,STONE:0)
Block(-5,33,-5,STONE:0)
Block(-5,33,-4,STONE:0)
Block(-5,33,-3,STONE:0)
Block(-5,33,-2,STONE:0)
Block(-5,33,-1,STONE:0)
Block(-5,33,0,STONE:0)
Block(-5,33,1,STONE:0)
Block(-5,33,2,STONE:0)
Block(-5,33,3,STONE:0)
Block(-5,33,4,STONE:0)
Block(-5,33,5,STONE:0)
Block(-5,33,6,STONE:0)
Block(-5,33,7,STONE:0)
Block(-5,34,-6,STONE:0)
Block(-5,34,-5,STONE:0)
Block(-5,34,-4,STONE:0)
Block(-5,34,-3,STONE:0)
Block(-5,34,-2,STONE:0)
Block(-5,34,-1,STONE:0)
Block(-5,34,0,STONE:0)
Block(-5,34,1,STONE:0)
Block(-5,34,2,STONE:0)
Block(-5,34,3,STONE:0)
Block(-5,34,4,STONE:0)
Block(-5,34,5,STONE:0)
Block(-5,34,6,STONE:0)
Block(-5,34,7,STONE:0)
Block(-5,35,-6,STONE:0)
Block(-5,35,-5,STONE:0)
Block(-5,35,-4,STONE:0)
Block(-5,35,-3,STONE:0)
Block(-5,35,-2,STONE:0)
Block(-5,35,-1,STONE:0)
Block(-5,35,0,STONE:0)
Block(-5,35,1,STONE:0)
Block(-5,35,2,STONE:0)
Block(-5,35,3,STONE:0)
Block(-5,35,4,STONE:0)
Block(-5,35,5,STONE:0)
Block(-5,35,6,STONE:0)
Block(-5,35,7,STONE:0)
Block(-5,36,-6,STONE:0)
Block(-5,36,-5,STONE:0)
Block(-5,36,-4,STONE:0)
Block(-5,36,-3,STONE:0)
Block(-5,36,-2,STONE:0)
Block(-5,36,-1,STONE:0)
Block(-5,36,0,STONE:0)
Block(-5,36,1,STONE:0)
Block(-5,36,2,STONE:0)
Block(-5,36,3,STONE:0)
Block(-5,36,4,STONE:0)
Block(-5,36,5,STONE:0)
Block(-5,36,6,STONE:0)
Block(-5,36,7,STONE:0)
Block(-5,37,-6,STONE:0)
Block(-5,37,-5,STONE:0)
Block(-5,37,-4,STONE:0)
Block(-5,37,-3,STONE:0)
Block(-5,37,-2,STONE:0)
Block(-5,37,-1,STONE:0)
Block(-5,37,0,STONE:0)
Block(-5,37,1,STONE:0)
Block(-5,37,2,STONE:0)
Block(-5,37,3,STONE:0)
Block(-5,37,4,STONE:0)
Block(-5,37,5,STONE:0)
Block(-5,37,6,STONE:0)
Block(-5,37,7,STONE:0)
Block(-5,38,-6,STONE:0)
Block(-5,38,-5,STONE:0)
Block(-5,38,-4,STONE:0)
Block(-5,38,-3,STONE:0)
Block(-5,38,-2,STONE:0)
Block(-5,38,-1,STONE:0)
Block(-5,38,0,STONE:0)
Block(-5,38,1,STONE:0)
Block(-5,38,2,STONE:0)
Block(-5,38,3,STONE:0)
Block(-5,38,4,STONE:0)
Block(-5,38,5,STONE:0)
Block(-5,38,6,STONE:0)
Block(-5,38,7,STONE:0)
Block(-5,39,-6,STONE:0)
Block(-5,39,-5,STONE:0)
Block(-5,39,-4,STONE:0)
Block(-5,39,-3,STONE:0)
Block(-5,39,-2,STONE:0)
Block(-5,39,-1,STONE:0)
Block(-5,39,0,STONE:0)
Block(-5,39,1,STONE:0)
Block(-5,39,2,STONE:0)
Block(-5,39,3,STONE:0)
Block(-5,39,4,STONE:0)
Block(-5,39,5,STONE:0)
Block(-5,39,6,STONE:0)
Block(-5,39,7,STONE:0)
Block(-5,40,-6,STONE:0)
Block(-5,40,-5,STONE:0)
Block(-5,40,-4,STONE:0)
Block(-5,40,-3,STONE:0)
Block(-5,40,-2,STONE:0)
Block(-5,40,-1,STONE:0)
Block(-5,40,0,STONE:0)
Block(-5,40,1,STONE:0)
Block(-5,40,2,STONE:0)
Block(-5,40,3,STONE:0)
Block(-5,40,4,STONE:0)
Block(-5,40,5,STONE:0)
Block(-5,40,6,STONE:0)
Block(-5,40,7,STONE:0)
Block(-5,41,-5,STONE:0)
Block(-5,41,-4,STONE:0)
Block(-5,41,-3,STONE:0)
Block(-5,41,-2,STONE:0)
Block(-5,41,-1,STONE:0)
Block(-5,41,0,STONE:0)
Block(-5,41,1,STONE:0)
Block(-5,41,2,STONE:0)
Block(-5,41,3,STONE:0)
Block(-5,41,4,STONE:0)
Block(-5,41,5,STONE:0)
Block(-5,41,6,STONE:0)
Block(-5,41,7,STONE:0)
Block(-5,42,-5,STONE:0)
Block(-5,42,-4,STONE:0)
Block(-5,42,-3,STONE:0)
Block(-5,42,-2,STONE:0)
Block(-5,42,-1,STONE:0)
Block(-5,42,0,STONE:0)
Block(-5,42,1,STONE:0)
Block(-5,42,2,STONE:0)
Block(-5,42,3,STONE:0)
Block(-5,42,4,STONE:0)
Block(-5,42,5,STONE:0)
Block(-5,42,6,STONE:0)
Block(-5,42,7,STONE:0)
Block(-5,43,-5,STONE:0)
Block(-5,43,-4,STONE:0)
Block(-5,43,-3,STONE:0)
Block(-5,43,-2,STONE:0)
Block(-5,43,-1,STONE:0)
Block(-5,43,0,STONE:0)
Block(-5,43,1,STONE:0)
Block(-5,43,2,STONE:0)
Block(-5,43,3,STONE:0)
Block(-5,43,4,STONE:0)
Block(-5,43,5,STONE:0)
Block(-5,43,6,STONE:0)
Block(-5,43,7,STONE:0)
Block(-5,44,-5,STONE:0)
Block(-5,44,-4,STONE:0)
Block(-5,44,-3,STONE:0)
Block(-5,44,-2,STONE:0)
Block(-5,44,-1,STONE:0)
Block(-5,44,0,STONE:0)
Block(-5,44,1,STONE:0)
Block(-5,44,2,STONE:0)
Block(-5,44,3,STONE:0)
Block(-5,44,4,STONE:0)
Block(-5,44,5,STONE:0)
Block(-5,44,6,STONE:0)
Block(-5,44,7,STONE:0)
Block(-5,45,-5,STONE:0)
Block(-5,45,-4,STONE:0)
Block(-5,45,-3,STONE:0)
Block(-5,45,-2,STONE:0)
Block(-5,45,-1,STONE:0)
Block(-5,45,0,STONE:0)
Block(-5,45,1,STONE:0)
Block(-5,45,2,STONE:0)
Block(-5,45,3,STONE:0)
Block(-5,45,4,STONE:0)
Block(-5,45,5,STONE:0)
Block(-5,45,6,STONE:0)
Block(-5,45,7,STONE:0)
Block(-5,46,-4,STONE:0)
Block(-5,46,-3,STONE:0)
Block(-5,46,-2,STONE:0)
Block(-5,46,-1,STONE:0)
Block(-5,46,0,STONE:0)
Block(-5,46,1,STONE:0)
Block(-5,46,2,STONE:0)
Block(-5,46,3,STONE:0)
Block(-5,46,4,STONE:0)
Block(-5,46,5,STONE:0)
Block(-5,46,6,STONE:0)
Block(-5,46,7,STONE:0)
Block(-5,47,-4,STONE:0)
Block(-5,47,-3,STONE:0)
Block(-5,47,-2,STONE:0)
Block(-5,47,-1,STONE:0)
Block(-5,47,0,STONE:0)
Block(-5,47,1,STONE:0)
Block(-5,47,2,STONE:0)
Block(-5,47,3,STONE:0)
Block(-5,47,4,STONE:0)
Block(-5,47,5,STONE:0)
Block(-5,47,6,STONE:0)
Block(-5,47,7,STONE:0)
Block(-5,48,-4,STONE:0)
Block(-5,48,-3,STONE:0)
Block(-5,48,-2,STONE:0)
Block(-5,48,-1,STONE:0)
Block(-5,48,0,STONE:0)
Block(-5,48,1,STONE:0)
Block(-5,48,2,STONE:0)
Block(-5,48,3,STONE:0)
Block(-5,48,4,STONE:0)
Block(-5,48,5,STONE:0)
Block(-5,48,6,STONE:0)
Block(-5,48,7,STONE:0)
Block(-5,49,-3,STONE:0)
Block(-5,49,-2,STONE:0)
Block(-5,49,-1,STONE:0)
Block(-5,49,0,STONE:0)
Block(-5,49,1,STONE:0)
Block(-5,49,2,STONE:0)
Block(-5,49,3,STONE:0)
Block(-5,49,4,STONE:0)
Block(-5,49,5,STONE:0)
Block(-5,49,6,STONE:0)
Block(-5,49,7,STONE:0)
Block(-5,50,-3,STONE:0)
Block(-5,50,-2,STONE:0)
Block(-5,50,-1,STONE:0)
Block(-5,50,0,STONE:0)
Block(-5,50,1,STONE:0)
Block(-5,50,2,STONE:0)
Block(-5,50,3,STONE:0)
Block(-5,50,4,STONE:0)
Block(-5,50,5,STONE:0)
Block(-5,50,6,STONE:0)
Block(-5,50,7,STONE:0)
Block(-5,51,-3,STONE:0)
Block(-5,51,-2,STONE:0)
Block(-5,51,-1,STONE:0)
Block(-5,51,0,STONE:0)
Block(-5,51,1,STONE:0)
Block(-5,51,2,STONE:0)
Block(-5,51,3,STONE:0)
Block(-5,51,4,STONE:0)
Block(-5,51,5,STONE:0)
Block(-5,51,6,STONE:0)
Block(-5,52,-3,STONE:0)
Block(-5,52,-2,STONE:0)
Block(-5,52,-1,STONE:0)
Block(-5,52,0,STONE:0)
Block(-5,52,1,STONE:0)
Block(-5,52,2,STONE:0)
Block(-5,52,3,STONE:0)
Block(-5,52,4,STONE:0)
Block(-5,52,5,STONE:0)
Block(-5,52,6,STONE:0)
Block(-5,53,-3,STONE:0)
Block(-5,53,-2,STONE:0)
Block(-5,53,-1,STONE:0)
Block(-5,53,0,STONE:0)
Block(-5,53,1,STONE:0)
Block(-5,53,2,STONE:0)
Block(-5,53,3,STONE:0)
Block(-5,53,4,STONE:0)
Block(-5,53,5,STONE:0)
Block(-5,53,6,STONE:0)
Block(-5,54,-3,STONE:0)
Block(-5,54,-2,STONE:0)
Block(-5,54,-1,STONE:0)
Block(-5,54,0,STONE:0)
Block(-5,54,1,STONE:0)
Block(-5,54,2,STONE:0)
Block(-5,54,3,STONE:0)
Block(-5,54,4,STONE:0)
Block(-5,54,5,STONE:0)
Block(-5,55,-3,STONE:0)
Block(-5,55,-2,STONE:0)
Block(-5,55,-1,STONE:0)
Block(-5,55,0,STONE:0)
Block(-5,55,1,STONE:0)
Block(-5,55,2,STONE:0)
Block(-5,55,3,STONE:0)
Block(-5,55,4,STONE:0)
Block(-5,55,5,STONE:0)
Block(-5,56,-3,STONE:0)
Block(-5,56,-2,STONE:0)
Block(-5,56,-1,STONE:0)
Block(-5,56,0,STONE:0)
Block(-5,56,1,STONE:0)
Block(-5,56,2,STONE:0)
Block(-5,56,4,STONE:0)
Block(-5,56,5,STONE:0)
Block(-5,57,-3,STONE:0)
Block(-5,57,-2,STONE:0)
Block(-5,57,-1,STONE:0)
Block(-5,57,0,STONE:0)
Block(-5,57,1,STONE:0)
Block(-5,57,2,STONE:0)
Block(-5,57,4,STONE:0)
Block(-5,57,5,STONE:0)
Block(-5,58,-3,STONE:0)
Block(-5,58,-2,STONE:0)
Block(-5,58,-1,STONE:0)
Block(-5,58,0,STONE:0)
Block(-5,58,1,STONE:0)
Block(-5,58,4,STONE:0)
Block(-5,58,5,STONE:0)
Block(-5,59,-3,STONE:0)
Block(-5,59,-2,STONE:0)
Block(-5,59,-1,STONE:0)
Block(-5,59,0,STONE:0)
Block(-5,59,1,STONE:0)
Block(-5,59,4,STONE:0)
Block(-5,59,5,STONE:0)
Block(-5,60,-3,STONE:0)
Block(-5,60,-2,STONE:0)
Block(-5,60,-1,STONE:0)
Block(-5,60,0,STONE:0)
Block(-5,60,1,STONE:0)
Block(-5,60,4,STONE:0)
Block(-5,60,5,STONE:0)
Block(-5,61,-3,STONE:0)
Block(-5,61,-2,STONE:0)
Block(-5,61,-1,STONE:0)
Block(-5,61,0,STONE:0)
Block(-5,61,1,STONE:0)
Block(-5,61,4,STONE:0)
Block(-5,61,5,STONE:0)
Block(-5,62,-3,STONE:0)
Block(-5,62,-2,STONE:0)
Block(-5,62,-1,STONE:0)
Block(-5,62,0,STONE:0)
Block(-5,62,1,STONE:0)
Block(-5,62,4,STONE:0)
Block(-5,63,-2,STONE:0)
Block(-5,63,-1,STONE:0)
Block(-5,63,0,STONE:0)
Block(-5,63,1,STONE:0)
Block(-5,64,-2,STONE:0)
Block(-5,64,-1,STONE:0)
Block(-5,64,0,STONE:0)
Block(-5,64,1,STONE:0)
Block(-5,65,-2,STONE:0)
Block(-5,65,-1,STONE:0)
Block(-5,65,0,STONE:0)
Block(-5,65,1,STONE:0)
Block(-5,66,-2,STONE:0)
Block(-5,66,-1,STONE:0)
Block(-5,66,0,STONE:0)
Block(-5,66,1,STONE:0)
Block(-5,67,-2,STONE:0)
Block(-5,67,-1,STONE:0)
Block(-5,67,0,STONE:0)
Block(-5,67,1,STONE:0)
Block(-5,68,-2,STONE:0)
Block(-5,68,-1,STONE:0)
Block(-5,68,0,STONE:0)
Block(-5,68,1,STONE:0)
Block(-5,69,-2,STONE:0)
Block(-5,69,-1,STONE:0)
Block(-5,69,0,STONE:0)
Block(-5,69,1,STONE:0)
Block(-5,70,-1,STONE:0)
Block(-5,70,0,STONE:0)
Block(-5,70,1,STONE:0)
Block(-5,71,-1,STONE:0)
Block(-5,71,0,STONE:0)
Block(-5,71,1,STONE:0)
Block(-5,72,-1,STONE:0)
Block(-5,72,0,STONE:0)
Block(-5,72,1,STONE:0)
Block(-5,73,-1,STONE:0)
Block(-5,73,0,STONE:0)
Block(-5,73,1,STONE:0)
Block(-5,74,-1,STONE:0)
Block(-5,74,0,STONE:0)
Block(-5,74,1,STONE:0)
Block(-5,75,-1,STONE:0)
Block(-5,75,0,STONE:0)
Block(-5,75,1,STONE:0)
Block(-5,76,-1,STONE:0)
Block(-5,76,0,STONE:0)
Block(-5,76,1,STONE:0)
Block(-5,77,-1,STONE:0)
Block(-5,77,0,STONE:0)
Block(-5,77,1,STONE:0)
Block(-5,78,-1,STONE:0)
Block(-5,78,0,STONE:0)
Block(-5,78,1,STONE:0)
Block(-5,79,-1,STONE:0)
Block(-5,80,-1,STONE:0)
Block(-4,0,-10,STONE:0)
Block(-4,0,-9,STONE:0)
Block(-4,0,-8,STONE:0)
Block(-4,0,-7,STONE:0)
Block(-4,0,-6,STONE:0)
Block(-4,0,-5,STONE:0)
Block(-4,0,-4,STONE:0)
Block(-4,0,-3,STONE:0)
Block(-4,0,-2,STONE:0)
Block(-4,0,-1,STONE:0)
Block(-4,0,0,STONE:0)
Block(-4,0,1,STONE:0)
Block(-4,0,2,STONE:0)
Block(-4,0,3,STONE:0)
Block(-4,0,4,STONE:0)
Block(-4,0,5,STONE:0)
Block(-4,0,6,STONE:0)
Block(-4,0,7,STONE:0)
Block(-4,0,8,STONE:0)
Block(-4,0,9,STONE:0)
Block(-4,0,10,STONE:0)
Block(-4,0,11,STONE:0)
Block(-4,1,-9,STONE:0)
Block(-4,1,-8,STONE:0)
Block(-4,1,-7,STONE:0)
Block(-4,1,-6,STONE:0)
Block(-4,1,-5,STONE:0)
Block(-4,1,-4,STONE:0)
Block(-4,1,-3,STONE:0)
Block(-4,1,-2,STONE:0)
Block(-4,1,-1,STONE:0)
Block(-4,1,0,STONE:0)
Block(-4,1,1,STONE:0)
Block(-4,1,2,STONE:0)
Block(-4,1,3,STONE:0)
Block(-4,1,4,STONE:0)
Block(-4,1,5,STONE:0)
Block(-4,1,6,STONE:0)
Block(-4,1,7,STONE:0)
Block(-4,1,8,STONE:0)
Block(-4,1,9,STONE:0)
Block(-4,1,10,STONE:0)
Block(-4,2,-9,STONE:0)
Block(-4,2,-8,STONE:0)
Block(-4,2,-7,STONE:0)
Block(-4,2,-6,STONE:0)
Block(-4,2,-5,STONE:0)
Block(-4,2,-4,STONE:0)
Block(-4,2,-3,STONE:0)
Block(-4,2,-2,STONE:0)
Block(-4,2,-1,STONE:0)
Block(-4,2,0,STONE:0)
Block(-4,2,1,STONE:0)
Block(-4,2,2,STONE:0)
Block(-4,2,3,STONE:0)
Block(-4,2,4,STONE:0)
Block(-4,2,5,STONE:0)
Block(-4,2,6,STONE:0)
Block(-4,2,7,STONE:0)
Block(-4,2,8,STONE:0)
Block(-4,2,9,STONE:0)
Block(-4,2,10,STONE:0)
Block(-4,3,-9,STONE:0)
Block(-4,3,-8,STONE:0)
Block(-4,3,-7,STONE:0)
Block(-4,3,-6,STONE:0)
Block(-4,3,-5,STONE:0)
Block(-4,3,-4,STONE:0)
Block(-4,3,-3,STONE:0)
Block(-4,3,-2,STONE:0)
Block(-4,3,-1,STONE:0)
Block(-4,3,0,STONE:0)
Block(-4,3,1,STONE:0)
Block(-4,3,2,STONE:0)
Block(-4,3,3,STONE:0)
Block(-4,3,4,STONE:0)
Block(-4,3,5,STONE:0)
Block(-4,3,6,STONE:0)
Block(-4,3,7,STONE:0)
Block(-4,3,8,STONE:0)
Block(-4,3,9,STONE:0)
Block(-4,3,10,STONE:0)
Block(-4,4,-9,STONE:0)
Block(-4,4,-8,STONE:0)
Block(-4,4,-7,STONE:0)
Block(-4,4,-6,STONE:0)
Block(-4,4,-5,STONE:0)
Block(-4,4,-4,STONE:0)
Block(-4,4,-3,STONE:0)
Block(-4,4,-2,STONE:0)
Block(-4,4,-1,STONE:0)
Block(-4,4,0,STONE:0)
Block(-4,4,1,STONE:0)
Block(-4,4,2,STONE:0)
Block(-4,4,3,STONE:0)
Block(-4,4,4,STONE:0)
Block(-4,4,5,STONE:0)
Block(-4,4,6,STONE:0)
Block(-4,4,7,STONE:0)
Block(-4,4,8,STONE:0)
Block(-4,4,9,STONE:0)
Block(-4,4,10,STONE:0)
Block(-4,5,-8,STONE:0)
Block(-4,5,-7,STONE:0)
Block(-4,5,-6,STONE:0)
Block(-4,5,-5,STONE:0)
Block(-4,5,-4,STONE:0)
Block(-4,5,-3,STONE:0)
Block(-4,5,-2,STONE:0)
Block(-4,5,-1,STONE:0)
Block(-4,5,0,STONE:0)
Block(-4,5,1,STONE:0)
Block(-4,5,2,STONE:0)
Block(-4,5,3,STONE:0)
Block(-4,5,4,STONE:0)
Block(-4,5,5,STONE:0)
Block(-4,5,6,STONE:0)
Block(-4,5,7,STONE:0)
Block(-4,5,8,STONE:0)
Block(-4,5,9,STONE:0)
Block(-4,5,10,STONE:0)
Block(-4,6,-8,STONE:0)
Block(-4,6,-7,STONE:0)
Block(-4,6,-6,STONE:0)
Block(-4,6,-5,STONE:0)
Block(-4,6,-4,STONE:0)
Block(-4,6,-3,STONE:0)
Block(-4,6,-2,STONE:0)
Block(-4,6,-1,STONE:0)
Block(-4,6,0,STONE:0)
Block(-4,6,1,STONE:0)
Block(-4,6,2,STONE:0)
Block(-4,6,3,STONE:0)
Block(-4,6,4,STONE:0)
Block(-4,6,5,STONE:0)
Block(-4,6,6,STONE:0)
Block(-4,6,7,STONE:0)
Block(-4,6,8,STONE:0)
Block(-4,6,9,STONE:0)
Block(-4,7,-7,STONE:0)
Block(-4,7,-6,STONE:0)
Block(-4,7,-5,STONE:0)
Block(-4,7,-4,STONE:0)
Block(-4,7,-3,STONE:0)
Block(-4,7,-2,STONE:0)
Block(-4,7,-1,STONE:0)
Block(-4,7,0,STONE:0)
Block(-4,7,1,STONE:0)
Block(-4,7,2,STONE:0)
Block(-4,7,3,STONE:0)
Block(-4,7,4,STONE:0)
Block(-4,7,5,STONE:0)
Block(-4,7,6,STONE:0)
Block(-4,7,7,STONE:0)
Block(-4,7,8,STONE:0)
Block(-4,7,9,STONE:0)
Block(-4,8,-7,STONE:0)
Block(-4,8,-6,STONE:0)
Block(-4,8,-5,STONE:0)
Block(-4,8,-4,STONE:0)
Block(-4,8,-3,STONE:0)
Block(-4,8,-2,STONE:0)
Block(-4,8,-1,STONE:0)
Block(-4,8,0,STONE:0)
Block(-4,8,1,STONE:0)
Block(-4,8,2,STONE:0)
Block(-4,8,3,STONE:0)
Block(-4,8,4,STONE:0)
Block(-4,8,5,STONE:0)
Block(-4,8,6,STONE:0)
Block(-4,8,7,STONE:0)
Block(-4,8,8,STONE:0)
Block(-4,8,9,STONE:0)
Block(-4,9,-7,STONE:0)
Block(-4,9,-6,STONE:0)
Block(-4,9,-5,STONE:0)
Block(-4,9,-4,STONE:0)
Block(-4,9,-3,STONE:0)
Block(-4,9,-2,STONE:0)
Block(-4,9,-1,STONE:0)
Block(-4,9,0,STONE:0)
Block(-4,9,1,STONE:0)
Block(-4,9,2,STONE:0)
Block(-4,9,3,STONE:0)
Block(-4,9,4,STONE:0)
Block(-4,9,5,STONE:0)
Block(-4,9,6,STONE:0)
Block(-4,9,7,STONE:0)
Block(-4,9,8,STONE:0)
Block(-4,9,9,STONE:0)
Block(-4,10,-7,STONE:0)
Block(-4,10,-6,STONE:0)
Block(-4,10,-5,STONE:0)
Block(-4,10,-4,STONE:0)
Block(-4,10,-3,STONE:0)
Block(-4,10,-2,STONE:0)
Block(-4,10,-1,STONE:0)
Block(-4,10,0,STONE:0)
Block(-4,10,1,STONE:0)
Block(-4,10,2,STONE:0)
Block(-4,10,3,STONE:0)
Block(-4,10,4,STONE:0)
Block(-4,10,5,STONE:0)
Block(-4,10,6,STONE:0)
Block(-4,10,7,STONE:0)
Block(-4,10,8,STONE:0)
Block(-4,10,9,STONE:0)
Block(-4,11,-7,STONE:0)
Block(-4,11,-6,STONE:0)
Block(-4,11,-5,STONE:0)
Block(-4,11,-4,STONE:0)
Block(-4,11,-3,STONE:0)
Block(-4,11,-2,STONE:0)
Block(-4,11,-1,STONE:0)
Block(-4,11,0,STONE:0)
Block(-4,11,1,STONE:0)
Block(-4,11,2,STONE:0)
Block(-4,11,3,STONE:0)
Block(-4,11,4,STONE:0)
Block(-4,11,5,STONE:0)
Block(-4,11,6,STONE:0)
Block(-4,11,7,STONE:0)
Block(-4,11,8,STONE:0)
Block(-4,11,9,STONE:0)
Block(-4,12,-7,STONE:0)
Block(-4,12,-6,STONE:0)
Block(-4,12,-5,STONE:0)
Block(-4,12,-4,STONE:0)
Block(-4,12,-3,STONE:0)
Block(-4,12,-2,STONE:0)
Block(-4,12,-1,STONE:0)
Block(-4,12,0,STONE:0)
Block(-4,12,1,STONE:0)
Block(-4,12,2,STONE:0)
Block(-4,12,3,STONE:0)
Block(-4,12,4,STONE:0)
Block(-4,12,5,STONE:0)
Block(-4,12,6,STONE:0)
Block(-4,12,7,STONE:0)
Block(-4,12,8,STONE:0)
Block(-4,12,9,STONE:0)
Block(-4,13,-7,STONE:0)
Block(-4,13,-6,STONE:0)
Block(-4,13,-5,STONE:0)
Block(-4,13,-4,STONE:0)
Block(-4,13,-3,STONE:0)
Block(-4,13,-2,STONE:0)
Block(-4,13,-1,STONE:0)
Block(-4,13,0,STONE:0)
Block(-4,13,1,STONE:0)
Block(-4,13,2,STONE:0)
Block(-4,13,3,STONE:0)
Block(-4,13,4,STONE:0)
Block(-4,13,5,STONE:0)
Block(-4,13,6,STONE:0)
Block(-4,13,7,STONE:0)
Block(-4,13,8,STONE:0)
Block(-4,13,9,STONE:0)
Block(-4,14,-7,STONE:0)
Block(-4,14,-6,STONE:0)
Block(-4,14,-5,STONE:0)
Block(-4,14,-4,STONE:0)
Block(-4,14,-3,STONE:0)
Block(-4,14,-2,STONE:0)
Block(-4,14,-1,STONE:0)
Block(-4,14,0,STONE:0)
Block(-4,14,1,STONE:0)
Block(-4,14,2,STONE:0)
Block(-4,14,3,STONE:0)
Block(-4,14,4,STONE:0)
Block(-4,14,5,STONE:0)
Block(-4,14,6,STONE:0)
Block(-4,14,7,STONE:0)
Block(-4,14,8,STONE:0)
Block(-4,15,-7,STONE:0)
Block(-4,15,-6,STONE:0)
Block(-4,15,-5,STONE:0)
Block(-4,15,-4,STONE:0)
Block(-4,15,-3,STONE:0)
Block(-4,15,-2,STONE:0)
Block(-4,15,-1,STONE:0)
Block(-4,15,0,STONE:0)
Block(-4,15,1,STONE:0)
Block(-4,15,2,STONE:0)
Block(-4,15,3,STONE:0)
Block(-4,15,4,STONE:0)
Block(-4,15,5,STONE:0)
Block(-4,15,6,STONE:0)
Block(-4,15,7,STONE:0)
Block(-4,15,8,STONE:0)
Block(-4,16,-7,STONE:0)
Block(-4,16,-6,STONE:0)
Block(-4,16,-5,STONE:0)
Block(-4,16,-4,STONE:0)
Block(-4,16,-3,STONE:0)
Block(-4,16,-2,STONE:0)
Block(-4,16,-1,STONE:0)
Block(-4,16,0,STONE:0)
Block(-4,16,1,STONE:0)
Block(-4,16,2,STONE:0)
Block(-4,16,3,STONE:0)
Block(-4,16,4,STONE:0)
Block(-4,16,5,STONE:0)
Block(-4,16,6,STONE:0)
Block(-4,16,7,STONE:0)
Block(-4,16,8,STONE:0)
Block(-4,17,-7,STONE:0)
Block(-4,17,-6,STONE:0)
Block(-4,17,-5,STONE:0)
Block(-4,17,-4,STONE:0)
Block(-4,17,-3,STONE:0)
Block(-4,17,-2,STONE:0)
Block(-4,17,-1,STONE:0)
Block(-4,17,0,STONE:0)
Block(-4,17,1,STONE:0)
Block(-4,17,2,STONE:0)
Block(-4,17,3,STONE:0)
Block(-4,17,4,STONE:0)
Block(-4,17,5,STONE:0)
Block(-4,17,6,STONE:0)
Block(-4,17,7,STONE:0)
Block(-4,17,8,STONE:0)
Block(-4,18,-6,STONE:0)
Block(-4,18,-5,STONE:0)
Block(-4,18,-4,STONE:0)
Block(-4,18,-3,STONE:0)
Block(-4,18,-2,STONE:0)
Block(-4,18,-1,STONE:0)
Block(-4,18,0,STONE:0)
Block(-4,18,1,STONE:0)
Block(-4,18,2,STONE:0)
Block(-4,18,3,STONE:0)
Block(-4,18,4,STONE:0)
Block(-4,18,5,STONE:0)
Block(-4,18,6,STONE:0)
Block(-4,18,7,STONE:0)
Block(-4,18,8,STONE:0)
Block(-4,19,-6,STONE:0)
Block(-4,19,-5,STONE:0)
Block(-4,19,-4,STONE:0)
Block(-4,19,-3,STONE:0)
Block(-4,19,-2,STONE:0)
Block(-4,19,-1,STONE:0)
Block(-4,19,0,STONE:0)
Block(-4,19,1,STONE:0)
Block(-4,19,2,STONE:0)
Block(-4,19,3,STONE:0)
Block(-4,19,4,STONE:0)
Block(-4,19,5,STONE:0)
Block(-4,19,6,STONE:0)
Block(-4,19,7,STONE:0)
Block(-4,19,8,STONE:0)
Block(-4,20,-6,STONE:0)
Block(-4,20,-5,STONE:0)
Block(-4,20,-4,STONE:0)
Block(-4,20,-3,STONE:0)
Block(-4,20,-2,STONE:0)
Block(-4,20,-1,STONE:0)
Block(-4,20,0,STONE:0)
Block(-4,20,1,STONE:0)
Block(-4,20,2,STONE:0)
Block(-4,20,3,STONE:0)
Block(-4,20,4,STONE:0)
Block(-4,20,5,STONE:0)
Block(-4,20,6,STONE:0)
Block(-4,20,7,STONE:0)
Block(-4,20,8,STONE:0)
Block(-4,21,-6,STONE:0)
Block(-4,21,-5,STONE:0)
Block(-4,21,-4,STONE:0)
Block(-4,21,-3,STONE:0)
Block(-4,21,-2,STONE:0)
Block(-4,21,-1,STONE:0)
Block(-4,21,0,STONE:0)
Block(-4,21,1,STONE:0)
Block(-4,21,2,STONE:0)
Block(-4,21,3,STONE:0)
Block(-4,21,4,STONE:0)
Block(-4,21,5,STONE:0)
Block(-4,21,6,STONE:0)
Block(-4,21,7,STONE:0)
Block(-4,21,8,STONE:0)
Block(-4,22,-6,STONE:0)
Block(-4,22,-5,STONE:0)
Block(-4,22,-4,STONE:0)
Block(-4,22,-3,STONE:0)
Block(-4,22,-2,STONE:0)
Block(-4,22,-1,STONE:0)
Block(-4,22,0,STONE:0)
Block(-4,22,1,STONE:0)
Block(-4,22,2,STONE:0)
Block(-4,22,3,STONE:0)
Block(-4,22,4,STONE:0)
Block(-4,22,5,STONE:0)
Block(-4,22,6,STONE:0)
Block(-4,22,7,STONE:0)
Block(-4,22,8,STONE:0)
Block(-4,23,-6,STONE:0)
Block(-4,23,-5,STONE:0)
Block(-4,23,-4,STONE:0)
Block(-4,23,-3,STONE:0)
Block(-4,23,-2,STONE:0)
Block(-4,23,-1,STONE:0)
Block(-4,23,0,STONE:0)
Block(-4,23,1,STONE:0)
Block(-4,23,2,STONE:0)
Block(-4,23,3,STONE:0)
Block(-4,23,4,STONE:0)
Block(-4,23,5,STONE:0)
Block(-4,23,6,STONE:0)
Block(-4,23,7,STONE:0)
Block(-4,23,8,STONE:0)
Block(-4,24,-6,STONE:0)
Block(-4,24,-5,STONE:0)
Block(-4,24,-4,STONE:0)
Block(-4,24,-3,STONE:0)
Block(-4,24,-2,STONE:0)
Block(-4,24,-1,STONE:0)
Block(-4,24,0,STONE:0)
Block(-4,24,1,STONE:0)
Block(-4,24,2,STONE:0)
Block(-4,24,3,STONE:0)
Block(-4,24,4,STONE:0)
Block(-4,24,5,STONE:0)
Block(-4,24,6,STONE:0)
Block(-4,24,7,STONE:0)
Block(-4,24,8,STONE:0)
Block(-4,25,-6,STONE:0)
Block(-4,25,-5,STONE:0)
Block(-4,25,-4,STONE:0)
Block(-4,25,-3,STONE:0)
Block(-4,25,-2,STONE:0)
Block(-4,25,-1,STONE:0)
Block(-4,25,0,STONE:0)
Block(-4,25,1,STONE:0)
Block(-4,25,2,STONE:0)
Block(-4,25,3,STONE:0)
Block(-4,25,4,STONE:0)
Block(-4,25,5,STONE:0)
Block(-4,25,6,STONE:0)
Block(-4,25,7,STONE:0)
Block(-4,25,8,STONE:0)
Block(-4,26,-6,STONE:0)
Block(-4,26,-5,STONE:0)
Block(-4,26,-4,STONE:0)
Block(-4,26,-3,STONE:0)
Block(-4,26,-2,STONE:0)
Block(-4,26,-1,STONE:0)
Block(-4,26,0,STONE:0)
Block(-4,26,1,STONE:0)
Block(-4,26,2,STONE:0)
Block(-4,26,3,STONE:0)
Block(-4,26,4,STONE:0)
Block(-4,26,5,STONE:0)
Block(-4,26,6,STONE:0)
Block(-4,26,7,STONE:0)
Block(-4,26,8,STONE:0)
Block(-4,27,-6,STONE:0)
Block(-4,27,-5,STONE:0)
Block(-4,27,-4,STONE:0)
Block(-4,27,-3,STONE:0)
Block(-4,27,-2,STONE:0)
Block(-4,27,-1,STONE:0)
Block(-4,27,0,STONE:0)
Block(-4,27,1,STONE:0)
Block(-4,27,2,STONE:0)
Block(-4,27,3,STONE:0)
Block(-4,27,4,STONE:0)
Block(-4,27,5,STONE:0)
Block(-4,27,6,STONE:0)
Block(-4,27,7,STONE:0)
Block(-4,27,8,STONE:0)
Block(-4,28,-6,STONE:0)
Block(-4,28,-5,STONE:0)
Block(-4,28,-4,STONE:0)
Block(-4,28,-3,STONE:0)
Block(-4,28,-2,STONE:0)
Block(-4,28,-1,STONE:0)
Block(-4,28,0,STONE:0)
Block(-4,28,1,STONE:0)
Block(-4,28,2,STONE:0)
Block(-4,28,3,STONE:0)
Block(-4,28,4,STONE:0)
Block(-4,28,5,STONE:0)
Block(-4,28,6,STONE:0)
Block(-4,28,7,STONE:0)
Block(-4,29,-6,STONE:0)
Block(-4,29,-5,STONE:0)
Block(-4,29,-4,STONE:0)
Block(-4,29,-3,STONE:0)
Block(-4,29,-2,STONE:0)
Block(-4,29,-1,STONE:0)
Block(-4,29,0,STONE:0)
Block(-4,29,1,STONE:0)
Block(-4,29,2,STONE:0)
Block(-4,29,3,STONE:0)
Block(-4,29,4,STONE:0)
Block(-4,29,5,STONE:0)
Block(-4,29,6,STONE:0)
Block(-4,29,7,STONE:0)
Block(-4,30,-6,STONE:0)
Block(-4,30,-5,STONE:0)
Block(-4,30,-4,STONE:0)
Block(-4,30,-3,STONE:0)
Block(-4,30,-2,STONE:0)
Block(-4,30,-1,STONE:0)
Block(-4,30,0,STONE:0)
Block(-4,30,1,STONE:0)
Block(-4,30,2,STONE:0)
Block(-4,30,3,STONE:0)
Block(-4,30,4,STONE:0)
Block(-4,30,5,STONE:0)
Block(-4,30,6,STONE:0)
Block(-4,30,7,STONE:0)
Block(-4,31,-6,STONE:0)
Block(-4,31,-5,STONE:0)
Block(-4,31,-4,STONE:0)
Block(-4,31,-3,STONE:0)
Block(-4,31,-2,STONE:0)
Block(-4,31,-1,STONE:0)
Block(-4,31,0,STONE:0)
Block(-4,31,1,STONE:0)
Block(-4,31,2,STONE:0)
Block(-4,31,3,STONE:0)
Block(-4,31,4,STONE:0)
Block(-4,31,5,STONE:0)
Block(-4,31,6,STONE:0)
Block(-4,31,7,STONE:0)
Block(-4,32,-6,STONE:0)
Block(-4,32,-5,STONE:0)
Block(-4,32,-4,STONE:0)
Block(-4,32,-3,STONE:0)
Block(-4,32,-2,STONE:0)
Block(-4,32,-1,STONE:0)
Block(-4,32,0,STONE:0)
Block(-4,32,1,STONE:0)
Block(-4,32,2,STONE:0)
Block(-4,32,3,STONE:0)
Block(-4,32,4,STONE:0)
Block(-4,32,5,STONE:0)
Block(-4,32,6,STONE:0)
Block(-4,32,7,STONE:0)
Block(-4,33,-6,STONE:0)
Block(-4,33,-5,STONE:0)
Block(-4,33,-4,STONE:0)
Block(-4,33,-3,STONE:0)
Block(-4,33,-2,STONE:0)
Block(-4,33,-1,STONE:0)
Block(-4,33,0,STONE:0)
Block(-4,33,1,STONE:0)
Block(-4,33,2,STONE:0)
Block(-4,33,3,STONE:0)
Block(-4,33,4,STONE:0)
Block(-4,33,5,STONE:0)
Block(-4,33,6,STONE:0)
Block(-4,33,7,STONE:0)
Block(-4,34,-6,STONE:0)
Block(-4,34,-5,STONE:0)
Block(-4,34,-4,STONE:0)
Block(-4,34,-3,STONE:0)
Block(-4,34,-2,STONE:0)
Block(-4,34,-1,STONE:0)
Block(-4,34,0,STONE:0)
Block(-4,34,1,STONE:0)
Block(-4,34,2,STONE:0)
Block(-4,34,3,STONE:0)
Block(-4,34,4,STONE:0)
Block(-4,34,5,STONE:0)
Block(-4,34,6,STONE:0)
Block(-4,34,7,STONE:0)
Block(-4,35,-6,STONE:0)
Block(-4,35,-5,STONE:0)
Block(-4,35,-4,STONE:0)
Block(-4,35,-3,STONE:0)
Block(-4,35,-2,STONE:0)
Block(-4,35,-1,STONE:0)
Block(-4,35,0,STONE:0)
Block(-4,35,1,STONE:0)
Block(-4,35,2,STONE:0)
Block(-4,35,3,STONE:0)
Block(-4,35,4,STONE:0)
Block(-4,35,5,STONE:0)
Block(-4,35,6,STONE:0)
Block(-4,35,7,STONE:0)
Block(-4,36,-6,STONE:0)
Block(-4,36,-5,STONE:0)
Block(-4,36,-4,STONE:0)
Block(-4,36,-3,STONE:0)
Block(-4,36,-2,STONE:0)
Block(-4,36,-1,STONE:0)
Block(-4,36,0,STONE:0)
Block(-4,36,1,STONE:0)
Block(-4,36,2,STONE:0)
Block(-4,36,3,STONE:0)
Block(-4,36,4,STONE:0)
Block(-4,36,5,STONE:0)
Block(-4,36,6,STONE:0)
Block(-4,36,7,STONE:0)
Block(-4,37,-6,STONE:0)
Block(-4,37,-5,STONE:0)
Block(-4,37,-4,STONE:0)
Block(-4,37,-3,STONE:0)
Block(-4,37,-2,STONE:0)
Block(-4,37,-1,STONE:0)
Block(-4,37,0,STONE:0)
Block(-4,37,1,STONE:0)
Block(-4,37,2,STONE:0)
Block(-4,37,3,STONE:0)
Block(-4,37,4,STONE:0)
Block(-4,37,5,STONE:0)
Block(-4,37,6,STONE:0)
Block(-4,37,7,STONE:0)
Block(-4,38,-6,STONE:0)
Block(-4,38,-5,STONE:0)
Block(-4,38,-4,STONE:0)
Block(-4,38,-3,STONE:0)
Block(-4,38,-2,STONE:0)
Block(-4,38,-1,STONE:0)
Block(-4,38,0,STONE:0)
Block(-4,38,1,STONE:0)
Block(-4,38,2,STONE:0)
Block(-4,38,3,STONE:0)
Block(-4,38,4,STONE:0)
Block(-4,38,5,STONE:0)
Block(-4,38,6,STONE:0)
Block(-4,38,7,STONE:0)
Block(-4,39,-6,STONE:0)
Block(-4,39,-5,STONE:0)
Block(-4,39,-4,STONE:0)
Block(-4,39,-3,STONE:0)
Block(-4,39,-2,STONE:0)
Block(-4,39,-1,STONE:0)
Block(-4,39,0,STONE:0)
Block(-4,39,1,STONE:0)
Block(-4,39,2,STONE:0)
Block(-4,39,3,STONE:0)
Block(-4,39,4,STONE:0)
Block(-4,39,5,STONE:0)
Block(-4,39,6,STONE:0)
Block(-4,39,7,STONE:0)
Block(-4,40,-6,STONE:0)
Block(-4,40,-5,STONE:0)
Block(-4,40,-4,STONE:0)
Block(-4,40,-3,STONE:0)
Block(-4,40,-2,STONE:0)
Block(-4,40,-1,STONE:0)
Block(-4,40,0,STONE:0)
Block(-4,40,1,STONE:0)
Block(-4,40,2,STONE:0)
Block(-4,40,3,STONE:0)
Block(-4,40,4,STONE:0)
Block(-4,40,5,STONE:0)
Block(-4,40,6,STONE:0)
Block(-4,40,7,STONE:0)
Block(-4,41,-6,STONE:0)
Block(-4,41,-5,STONE:0)
Block(-4,41,-4,STONE:0)
Block(-4,41,-3,STONE:0)
Block(-4,41,-2,STONE:0)
Block(-4,41,-1,STONE:0)
Block(-4,41,0,STONE:0)
Block(-4,41,1,STONE:0)
Block(-4,41,2,STONE:0)
Block(-4,41,3,STONE:0)
Block(-4,41,4,STONE:0)
Block(-4,41,5,STONE:0)
Block(-4,41,6,STONE:0)
Block(-4,41,7,STONE:0)
Block(-4,42,-6,STONE:0)
Block(-4,42,-5,STONE:0)
Block(-4,42,-4,STONE:0)
Block(-4,42,-3,STONE:0)
Block(-4,42,-2,STONE:0)
Block(-4,42,-1,STONE:0)
Block(-4,42,0,STONE:0)
Block(-4,42,1,STONE:0)
Block(-4,42,2,STONE:0)
Block(-4,42,3,STONE:0)
Block(-4,42,4,STONE:0)
Block(-4,42,5,STONE:0)
Block(-4,42,6,STONE:0)
Block(-4,42,7,STONE:0)
Block(-4,43,-5,STONE:0)
Block(-4,43,-4,STONE:0)
Block(-4,43,-3,STONE:0)
Block(-4,43,-2,STONE:0)
Block(-4,43,-1,STONE:0)
Block(-4,43,0,STONE:0)
Block(-4,43,1,STONE:0)
Block(-4,43,2,STONE:0)
Block(-4,43,3,STONE:0)
Block(-4,43,4,STONE:0)
Block(-4,43,5,STONE:0)
Block(-4,43,6,STONE:0)
Block(-4,43,7,STONE:0)
Block(-4,44,-5,STONE:0)
Block(-4,44,-4,STONE:0)
Block(-4,44,-3,STONE:0)
Block(-4,44,-2,STONE:0)
Block(-4,44,-1,STONE:0)
Block(-4,44,0,STONE:0)
Block(-4,44,1,STONE:0)
Block(-4,44,2,STONE:0)
Block(-4,44,3,STONE:0)
Block(-4,44,4,STONE:0)
Block(-4,44,5,STONE:0)
Block(-4,44,6,STONE:0)
Block(-4,44,7,STONE:0)
Block(-4,45,-5,STONE:0)
Block(-4,45,-4,STONE:0)
Block(-4,45,-3,STONE:0)
Block(-4,45,-2,STONE:0)
Block(-4,45,-1,STONE:0)
Block(-4,45,0,STONE:0)
Block(-4,45,1,STONE:0)
Block(-4,45,2,STONE:0)
Block(-4,45,3,STONE:0)
Block(-4,45,4,STONE:0)
Block(-4,45,5,STONE:0)
Block(-4,45,6,STONE:0)
Block(-4,45,7,STONE:0)
Block(-4,46,-5,STONE:0)
Block(-4,46,-4,STONE:0)
Block(-4,46,-3,STONE:0)
Block(-4,46,-2,STONE:0)
Block(-4,46,-1,STONE:0)
Block(-4,46,0,STONE:0)
Block(-4,46,1,STONE:0)
Block(-4,46,2,STONE:0)
Block(-4,46,3,STONE:0)
Block(-4,46,4,STONE:0)
Block(-4,46,5,STONE:0)
Block(-4,46,6,STONE:0)
Block(-4,46,7,STONE:0)
Block(-4,47,-5,STONE:0)
Block(-4,47,-4,STONE:0)
Block(-4,47,-3,STONE:0)
Block(-4,47,-2,STONE:0)
Block(-4,47,-1,STONE:0)
Block(-4,47,0,STONE:0)
Block(-4,47,1,STONE:0)
Block(-4,47,2,STONE:0)
Block(-4,47,3,STONE:0)
Block(-4,47,4,STONE:0)
Block(-4,47,5,STONE:0)
Block(-4,47,6,STONE:0)
Block(-4,47,7,STONE:0)
Block(-4,48,-5,STONE:0)
Block(-4,48,-4,STONE:0)
Block(-4,48,-3,STONE:0)
Block(-4,48,-2,STONE:0)
Block(-4,48,-1,STONE:0)
Block(-4,48,0,STONE:0)
Block(-4,48,1,STONE:0)
Block(-4,48,2,STONE:0)
Block(-4,48,3,STONE:0)
Block(-4,48,4,STONE:0)
Block(-4,48,5,STONE:0)
Block(-4,48,6,STONE:0)
Block(-4,48,7,STONE:0)
Block(-4,49,-5,STONE:0)
Block(-4,49,-4,STONE:0)
Block(-4,49,-3,STONE:0)
Block(-4,49,-2,STONE:0)
Block(-4,49,-1,STONE:0)
Block(-4,49,0,STONE:0)
Block(-4,49,1,STONE:0)
Block(-4,49,2,STONE:0)
Block(-4,49,3,STONE:0)
Block(-4,49,4,STONE:0)
Block(-4,49,5,STONE:0)
Block(-4,49,6,STONE:0)
Block(-4,49,7,STONE:0)
Block(-4,50,-5,STONE:0)
Block(-4,50,-4,STONE:0)
Block(-4,50,-3,STONE:0)
Block(-4,50,-2,STONE:0)
Block(-4,50,-1,STONE:0)
Block(-4,50,0,STONE:0)
Block(-4,50,1,STONE:0)
Block(-4,50,2,STONE:0)
Block(-4,50,3,STONE:0)
Block(-4,50,4,STONE:0)
Block(-4,50,5,STONE:0)
Block(-4,50,6,STONE:0)
Block(-4,51,-5,STONE:0)
Block(-4,51,-4,STONE:0)
Block(-4,51,-3,STONE:0)
Block(-4,51,-2,STONE:0)
Block(-4,51,-1,STONE:0)
Block(-4,51,0,STONE:0)
Block(-4,51,1,STONE:0)
Block(-4,51,2,STONE:0)
Block(-4,51,3,STONE:0)
Block(-4,51,4,STONE:0)
Block(-4,51,5,STONE:0)
Block(-4,51,6,STONE:0)
Block(-4,52,-5,STONE:0)
Block(-4,52,-4,STONE:0)
Block(-4,52,-3,STONE:0)
Block(-4,52,-2,STONE:0)
Block(-4,52,-1,STONE:0)
Block(-4,52,0,STONE:0)
Block(-4,52,1,STONE:0)
Block(-4,52,2,STONE:0)
Block(-4,52,3,STONE:0)
Block(-4,52,4,STONE:0)
Block(-4,52,5,STONE:0)
Block(-4,52,6,STONE:0)
Block(-4,53,-5,STONE:0)
Block(-4,53,-4,STONE:0)
Block(-4,53,-3,STONE:0)
Block(-4,53,-2,STONE:0)
Block(-4,53,-1,STONE:0)
Block(-4,53,0,STONE:0)
Block(-4,53,1,STONE:0)
Block(-4,53,2,STONE:0)
Block(-4,53,3,STONE:0)
Block(-4,53,4,STONE:0)
Block(-4,53,5,STONE:0)
Block(-4,53,6,STONE:0)
Block(-4,54,-5,STONE:0)
Block(-4,54,-4,STONE:0)
Block(-4,54,-3,STONE:0)
Block(-4,54,-2,STONE:0)
Block(-4,54,-1,STONE:0)
Block(-4,54,0,STONE:0)
Block(-4,54,1,STONE:0)
Block(-4,54,2,STONE:0)
Block(-4,54,3,STONE:0)
Block(-4,54,4,STONE:0)
Block(-4,54,5,STONE:0)
Block(-4,54,6,STONE:0)
Block(-4,55,-5,STONE:0)
Block(-4,55,-4,STONE:0)
Block(-4,55,-3,STONE:0)
Block(-4,55,-2,STONE:0)
Block(-4,55,-1,STONE:0)
Block(-4,55,0,STONE:0)
Block(-4,55,1,STONE:0)
Block(-4,55,2,STONE:0)
Block(-4,55,3,STONE:0)
Block(-4,55,4,STONE:0)
Block(-4,55,5,STONE:0)
Block(-4,55,6,STONE:0)
Block(-4,56,-5,STONE:0)
Block(-4,56,-4,STONE:0)
Block(-4,56,-3,STONE:0)
Block(-4,56,-2,STONE:0)
Block(-4,56,-1,STONE:0)
Block(-4,56,0,STONE:0)
Block(-4,56,1,STONE:0)
Block(-4,56,2,STONE:0)
Block(-4,56,3,STONE:0)
Block(-4,56,4,STONE:0)
Block(-4,56,5,STONE:0)
Block(-4,56,6,STONE:0)
Block(-4,57,-5,STONE:0)
Block(-4,57,-4,STONE:0)
Block(-4,57,-3,STONE:0)
Block(-4,57,-2,STONE:0)
Block(-4,57,-1,STONE:0)
Block(-4,57,0,STONE:0)
Block(-4,57,1,STONE:0)
Block(-4,57,2,STONE:0)
Block(-4,57,3,STONE:0)
Block(-4,57,4,STONE:0)
Block(-4,57,6,STONE:0)
Block(-4,58,-5,STONE:0)
Block(-4,58,-4,STONE:0)
Block(-4,58,-3,STONE:0)
Block(-4,58,-2,STONE:0)
Block(-4,58,-1,STONE:0)
Block(-4,58,0,STONE:0)
Block(-4,58,1,STONE:0)
Block(-4,58,2,STONE:0)
Block(-4,58,3,STONE:0)
Block(-4,58,4,STONE:0)
Block(-4,58,6,STONE:0)
Block(-4,59,-5,STONE:0)
Block(-4,59,-4,STONE:0)
Block(-4,59,-3,STONE:0)
Block(-4,59,-2,STONE:0)
Block(-4,59,-1,STONE:0)
Block(-4,59,0,STONE:0)
Block(-4,59,1,STONE:0)
Block(-4,59,2,STONE:0)
Block(-4,59,3,STONE:0)
Block(-4,59,4,STONE:0)
Block(-4,59,6,STONE:0)
Block(-4,60,-5,STONE:0)
Block(-4,60,-4,STONE:0)
Block(-4,60,-3,STONE:0)
Block(-4,60,-2,STONE:0)
Block(-4,60,-1,STONE:0)
Block(-4,60,0,STONE:0)
Block(-4,60,1,STONE:0)
Block(-4,60,2,STONE:0)
Block(-4,60,3,STONE:0)
Block(-4,60,4,STONE:0)
Block(-4,60,6,STONE:0)
Block(-4,61,-4,STONE:0)
Block(-4,61,-3,STONE:0)
Block(-4,61,-2,STONE:0)
Block(-4,61,-1,STONE:0)
Block(-4,61,0,STONE:0)
Block(-4,61,1,STONE:0)
Block(-4,61,2,STONE:0)
Block(-4,61,3,STONE:0)
Block(-4,61,4,STONE:0)
Block(-4,61,6,STONE:0)
Block(-4,62,-4,STONE:0)
Block(-4,62,-3,STONE:0)
Block(-4,62,-2,STONE:0)
Block(-4,62,-1,STONE:0)
Block(-4,62,0,STONE:0)
Block(-4,62,1,STONE:0)
Block(-4,62,2,STONE:0)
Block(-4,62,4,STONE:0)
Block(-4,62,6,STONE:0)
Block(-4,63,-4,STONE:0)
Block(-4,63,-3,STONE:0)
Block(-4,63,-2,STONE:0)
Block(-4,63,-1,STONE:0)
Block(-4,63,0,STONE:0)
Block(-4,63,1,STONE:0)
Block(-4,63,2,STONE:0)
Block(-4,63,4,STONE:0)
Block(-4,63,6,STONE:0)
Block(-4,64,-4,STONE:0)
Block(-4,64,-3,STONE:0)
Block(-4,64,-2,STONE:0)
Block(-4,64,-1,STONE:0)
Block(-4,64,0,STONE:0)
Block(-4,64,1,STONE:0)
Block(-4,64,2,STONE:0)
Block(-4,64,4,STONE:0)
Block(-4,64,6,STONE:0)
Block(-4,65,-4,STONE:0)
Block(-4,65,-3,STONE:0)
Block(-4,65,-2,STONE:0)
Block(-4,65,-1,STONE:0)
Block(-4,65,0,STONE:0)
Block(-4,65,1,STONE:0)
Block(-4,65,2,STONE:0)
Block(-4,65,6,STONE:0)
Block(-4,66,-4,STONE:0)
Block(-4,66,-3,STONE:0)
Block(-4,66,-2,STONE:0)
Block(-4,66,-1,STONE:0)
Block(-4,66,0,STONE:0)
Block(-4,66,1,STONE:0)
Block(-4,66,2,STONE:0)
Block(-4,66,6,STONE:0)
Block(-4,67,-4,STONE:0)
Block(-4,67,-3,STONE:0)
Block(-4,67,-2,STONE:0)
Block(-4,67,-1,STONE:0)
Block(-4,67,0,STONE:0)
Block(-4,67,1,STONE:0)
Block(-4,67,2,STONE:0)
Block(-4,67,6,STONE:0)
Block(-4,68,-4,STONE:0)
Block(-4,68,-3,STONE:0)
Block(-4,68,-2,STONE:0)
Block(-4,68,-1,STONE:0)
Block(-4,68,0,STONE:0)
Block(-4,68,1,STONE:0)
Block(-4,68,2,STONE:0)
Block(-4,69,-4,STONE:0)
Block(-4,69,-3,STONE:0)
Block(-4,69,-2,STONE:0)
Block(-4,69,-1,STONE:0)
Block(-4,69,0,STONE:0)
Block(-4,69,1,STONE:0)
Block(-4,69,2,STONE:0)
Block(-4,70,-4,STONE:0)
Block(-4,70,-3,STONE:0)
Block(-4,70,-2,STONE:0)
Block(-4,70,-1,STONE:0)
Block(-4,70,0,STONE:0)
Block(-4,70,1,STONE:0)
Block(-4,70,2,STONE:0)
Block(-4,71,-4,STONE:0)
Block(-4,71,-3,STONE:0)
Block(-4,71,-2,STONE:0)
Block(-4,71,-1,STONE:0)
Block(-4,71,0,STONE:0)
Block(-4,71,1,STONE:0)
Block(-4,71,2,STONE:0)
Block(-4,72,-4,STONE:0)
Block(-4,72,-3,STONE:0)
Block(-4,72,-2,STONE:0)
Block(-4,72,-1,STONE:0)
Block(-4,72,0,STONE:0)
Block(-4,72,1,STONE:0)
Block(-4,72,2,STONE:0)
Block(-4,73,-4,STONE:0)
Block(-4,73,-3,STONE:0)
Block(-4,73,-2,STONE:0)
Block(-4,73,-1,STONE:0)
Block(-4,73,0,STONE:0)
Block(-4,73,1,STONE:0)
Block(-4,73,2,STONE:0)
Block(-4,74,-4,STONE:0)
Block(-4,74,-3,STONE:0)
Block(-4,74,-2,STONE:0)
Block(-4,74,-1,STONE:0)
Block(-4,74,0,STONE:0)
Block(-4,74,1,STONE:0)
Block(-4,74,2,STONE:0)
Block(-4,75,-3,STONE:0)
Block(-4,75,-2,STONE:0)
Block(-4,75,-1,STONE:0)
Block(-4,75,0,STONE:0)
Block(-4,75,1,STONE:0)
Block(-4,75,2,STONE:0)
Block(-4,76,-3,STONE:0)
Block(-4,76,-2,STONE:0)
Block(-4,76,-1,STONE:0)
Block(-4,76,0,STONE:0)
Block(-4,76,1,STONE:0)
Block(-4,76,2,STONE:0)
Block(-4,77,-3,STONE:0)
Block(-4,77,-2,STONE:0)
Block(-4,77,-1,STONE:0)
Block(-4,77,0,STONE:0)
Block(-4,77,1,STONE:0)
Block(-4,77,2,STONE:0)
Block(-4,78,-3,STONE:0)
Block(-4,78,-2,STONE:0)
Block(-4,78,-1,STONE:0)
Block(-4,78,0,STONE:0)
Block(-4,78,1,STONE:0)
Block(-4,78,2,STONE:0)
Block(-4,79,-3,STONE:0)
Block(-4,79,-2,STONE:0)
Block(-4,79,-1,STONE:0)
Block(-4,79,0,STONE:0)
Block(-4,79,1,STONE:0)
Block(-4,79,2,STONE:0)
Block(-4,80,-3,STONE:0)
Block(-4,80,-2,STONE:0)
Block(-4,80,-1,STONE:0)
Block(-4,80,0,STONE:0)
Block(-4,80,1,STONE:0)
Block(-4,80,2,STONE:0)
Block(-4,81,-3,STONE:0)
Block(-4,81,-2,STONE:0)
Block(-4,81,-1,STONE:0)
Block(-4,81,0,STONE:0)
Block(-4,81,1,STONE:0)
Block(-4,81,2,STONE:0)
Block(-4,82,-3,STONE:0)
Block(-4,82,-2,STONE:0)
Block(-4,82,-1,STONE:0)
Block(-4,82,0,STONE:0)
Block(-4,82,1,STONE:0)
Block(-4,82,2,STONE:0)
Block(-4,83,-3,STONE:0)
Block(-4,83,-2,STONE:0)
Block(-4,83,-1,STONE:0)
Block(-4,83,0,STONE:0)
Block(-4,83,1,STONE:0)
Block(-4,83,2,STONE:0)
Block(-4,84,-3,STONE:0)
Block(-4,84,-2,STONE:0)
Block(-4,84,-1,STONE:0)
Block(-4,84,0,STONE:0)
Block(-4,84,1,STONE:0)
Block(-4,85,-3,STONE:0)
Block(-4,85,-2,STONE:0)
Block(-4,85,-1,STONE:0)
Block(-4,85,0,STONE:0)
Block(-4,85,1,STONE:0)
Block(-4,86,-3,STONE:0)
Block(-4,86,-2,STONE:0)
Block(-4,86,-1,STONE:0)
Block(-4,86,0,STONE:0)
Block(-4,86,1,STONE:0)
Block(-4,87,-3,STONE:0)
Block(-4,87,-2,STONE:0)
Block(-4,87,-1,STONE:0)
Block(-4,87,0,STONE:0)
Block(-4,87,1,STONE:0)
Block(-4,88,-3,STONE:0)
Block(-4,88,-2,STONE:0)
Block(-4,88,-1,STONE:0)
Block(-4,88,0,STONE:0)
Block(-4,88,1,STONE:0)
Block(-4,89,-3,STONE:0)
Block(-4,89,-2,STONE:0)
Block(-4,89,-1,STONE:0)
Block(-4,89,0,STONE:0)
Block(-4,89,1,STONE:0)
Block(-4,90,-3,STONE:0)
Block(-4,90,-2,STONE:0)
Block(-4,90,-1,STONE:0)
Block(-4,90,0,STONE:0)
Block(-4,90,1,STONE:0)
Block(-4,91,-3,STONE:0)
Block(-4,91,-2,STONE:0)
Block(-4,91,-1,STONE:0)
Block(-4,91,0,STONE:0)
Block(-4,91,1,STONE:0)
Block(-4,92,-3,STONE:0)
Block(-4,92,-2,STONE:0)
Block(-4,92,-1,STONE:0)
Block(-4,92,0,STONE:0)
Block(-4,92,1,STONE:0)
Block(-4,93,-3,STONE:0)
Block(-4,93,-2,STONE:0)
Block(-4,93,-1,STONE:0)
Block(-4,93,0,STONE:0)
Block(-4,93,1,STONE:0)
Block(-4,94,-3,STONE:0)
Block(-4,94,-2,STONE:0)
Block(-4,94,-1,STONE:0)
Block(-4,94,0,STONE:0)
Block(-4,94,1,STONE:0)
Block(-4,95,-3,STONE:0)
Block(-4,95,-2,STONE:0)
Block(-4,95,-1,STONE:0)
Block(-4,95,0,STONE:0)
Block(-4,95,1,STONE:0)
Block(-4,96,-3,STONE:0)
Block(-4,96,-2,STONE:0)
Block(-4,96,-1,STONE:0)
Block(-4,96,0,STONE:0)
Block(-4,96,1,STONE:0)
Block(-4,97,-3,STONE:0)
Block(-4,97,-2,STONE:0)
Block(-4,97,-1,STONE:0)
Block(-4,97,0,STONE:0)
Block(-4,97,1,STONE:0)
Block(-4,98,-3,STONE:0)
Block(-4,98,-2,STONE:0)
Block(-4,98,-1,STONE:0)
Block(-4,98,0,STONE:0)
Block(-4,98,1,STONE:0)
Block(-4,99,-3,STONE:0)
Block(-4,99,-2,STONE:0)
Block(-4,99,-1,STONE:0)
Block(-4,99,0,STONE:0)
Block(-4,99,1,STONE:0)
Block(-4,100,-3,STONE:0)
Block(-4,100,-2,STONE:0)
Block(-4,100,-1,STONE:0)
Block(-4,100,0,STONE:0)
Block(-4,100,1,STONE:0)
Block(-4,101,-3,STONE:0)
Block(-4,101,-2,STONE:0)
Block(-4,101,-1,STONE:0)
Block(-4,101,0,STONE:0)
Block(-4,101,1,STONE:0)
Block(-4,102,-3,STONE:0)
Block(-4,102,-1,STONE:0)
Block(-4,102,1,STONE:0)
Block(-4,103,-1,STONE:0)
Block(-4,103,1,STONE:0)
Block(-4,104,-1,STONE:0)
Block(-4,104,1,STONE:0)
Block(-4,105,-1,STONE:0)
Block(-3,0,-9,STONE:0)
Block(-3,0,-8,STONE:0)
Block(-3,0,-7,STONE:0)
Block(-3,0,-6,STONE:0)
Block(-3,0,-5,STONE:0)
Block(-3,0,-4,STONE:0)
Block(-3,0,-3,STONE:0)
Block(-3,0,-2,STONE:0)
Block(-3,0,-1,STONE:0)
Block(-3,0,0,STONE:0)
Block(-3,0,1,STONE:0)
Block(-3,0,2,STONE:0)
Block(-3,0,3,STONE:0)
Block(-3,0,4,STONE:0)
Block(-3,0,5,STONE:0)
Block(-3,0,6,STONE:0)
Block(-3,0,7,STONE:0)
Block(-3,0,8,STONE:0)
Block(-3,0,9,STONE:0)
Block(-3,0,10,STONE:0)
Block(-3,1,-8,STONE:0)
Block(-3,1,-7,STONE:0)
Block(-3,1,-6,STONE:0)
Block(-3,1,-5,STONE:0)
Block(-3,1,-4,STONE:0)
Block(-3,1,-3,STONE:0)
Block(-3,1,-2,STONE:0)
Block(-3,1,-1,STONE:0)
Block(-3,1,0,STONE:0)
Block(-3,1,1,STONE:0)
Block(-3,1,2,STONE:0)
Block(-3,1,3,STONE:0)
Block(-3,1,4,STONE:0)
Block(-3,1,5,STONE:0)
Block(-3,1,6,STONE:0)
Block(-3,1,7,STONE:0)
Block(-3,1,8,STONE:0)
Block(-3,1,9,STONE:0)
Block(-3,1,10,STONE:0)
Block(-3,2,-8,STONE:0)
Block(-3,2,-7,STONE:0)
Block(-3,2,-6,STONE:0)
Block(-3,2,-5,STONE:0)
Block(-3,2,-4,STONE:0)
Block(-3,2,-3,STONE:0)
Block(-3,2,-2,STONE:0)
Block(-3,2,-1,STONE:0)
Block(-3,2,0,STONE:0)
Block(-3,2,1,STONE:0)
Block(-3,2,2,STONE:0)
Block(-3,2,3,STONE:0)
Block(-3,2,4,STONE:0)
Block(-3,2,5,STONE:0)
Block(-3,2,6,STONE:0)
Block(-3,2,7,STONE:0)
Block(-3,2,8,STONE:0)
Block(-3,2,9,STONE:0)
Block(-3,2,10,STONE:0)
Block(-3,3,-8,STONE:0)
Block(-3,3,-7,STONE:0)
Block(-3,3,-6,STONE:0)
Block(-3,3,-5,STONE:0)
Block(-3,3,-4,STONE:0)
Block(-3,3,-3,STONE:0)
Block(-3,3,-2,STONE:0)
Block(-3,3,-1,STONE:0)
Block(-3,3,0,STONE:0)
Block(-3,3,1,STONE:0)
Block(-3,3,2,STONE:0)
Block(-3,3,3,STONE:0)
Block(-3,3,4,STONE:0)
Block(-3,3,5,STONE:0)
Block(-3,3,6,STONE:0)
Block(-3,3,7,STONE:0)
Block(-3,3,8,STONE:0)
Block(-3,3,9,STONE:0)
Block(-3,3,10,STONE:0)
Block(-3,4,-7,STONE:0)
Block(-3,4,-6,STONE:0)
Block(-3,4,-5,STONE:0)
Block(-3,4,-4,STONE:0)
Block(-3,4,-3,STONE:0)
Block(-3,4,-2,STONE:0)
Block(-3,4,-1,STONE:0)
Block(-3,4,0,STONE:0)
Block(-3,4,1,STONE:0)
Block(-3,4,2,STONE:0)
Block(-3,4,3,STONE:0)
Block(-3,4,4,STONE:0)
Block(-3,4,5,STONE:0)
Block(-3,4,6,STONE:0)
Block(-3,4,7,STONE:0)
Block(-3,4,8,STONE:0)
Block(-3,4,9,STONE:0)
Block(-3,4,10,STONE:0)
Block(-3,5,-7,STONE:0)
Block(-3,5,-6,STONE:0)
Block(-3,5,-5,STONE:0)
Block(-3,5,-4,STONE:0)
Block(-3,5,-3,STONE:0)
Block(-3,5,-2,STONE:0)
Block(-3,5,-1,STONE:0)
Block(-3,5,0,STONE:0)
Block(-3,5,1,STONE:0)
Block(-3,5,2,STONE:0)
Block(-3,5,3,STONE:0)
Block(-3,5,4,STONE:0)
Block(-3,5,5,STONE:0)
Block(-3,5,6,STONE:0)
Block(-3,5,7,STONE:0)
Block(-3,5,8,STONE:0)
Block(-3,5,9,STONE:0)
Block(-3,5,10,STONE:0)
Block(-3,6,-7,STONE:0)
Block(-3,6,-6,STONE:0)
Block(-3,6,-5,STONE:0)
Block(-3,6,-4,STONE:0)
Block(-3,6,-3,STONE:0)
Block(-3,6,-2,STONE:0)
Block(-3,6,-1,STONE:0)
Block(-3,6,0,STONE:0)
Block(-3,6,1,STONE:0)
Block(-3,6,2,STONE:0)
Block(-3,6,3,STONE:0)
Block(-3,6,4,STONE:0)
Block(-3,6,5,STONE:0)
Block(-3,6,6,STONE:0)
Block(-3,6,7,STONE:0)
Block(-3,6,8,STONE:0)
Block(-3,6,9,STONE:0)
Block(-3,6,10,STONE:0)
Block(-3,7,-7,STONE:0)
Block(-3,7,-6,STONE:0)
Block(-3,7,-5,STONE:0)
Block(-3,7,-4,STONE:0)
Block(-3,7,-3,STONE:0)
Block(-3,7,-2,STONE:0)
Block(-3,7,-1,STONE:0)
Block(-3,7,0,STONE:0)
Block(-3,7,1,STONE:0)
Block(-3,7,2,STONE:0)
Block(-3,7,3,STONE:0)
Block(-3,7,4,STONE:0)
Block(-3,7,5,STONE:0)
Block(-3,7,6,STONE:0)
Block(-3,7,7,STONE:0)
Block(-3,7,8,STONE:0)
Block(-3,7,9,STONE:0)
Block(-3,7,10,STONE:0)
Block(-3,8,-7,STONE:0)
Block(-3,8,-6,STONE:0)
Block(-3,8,-5,STONE:0)
Block(-3,8,-4,STONE:0)
Block(-3,8,-3,STONE:0)
Block(-3,8,-2,STONE:0)
Block(-3,8,-1,STONE:0)
Block(-3,8,0,STONE:0)
Block(-3,8,1,STONE:0)
Block(-3,8,2,STONE:0)
Block(-3,8,3,STONE:0)
Block(-3,8,4,STONE:0)
Block(-3,8,5,STONE:0)
Block(-3,8,6,STONE:0)
Block(-3,8,7,STONE:0)
Block(-3,8,8,STONE:0)
Block(-3,8,9,STONE:0)
Block(-3,9,-7,STONE:0)
Block(-3,9,-6,STONE:0)
Block(-3,9,-5,STONE:0)
Block(-3,9,-4,STONE:0)
Block(-3,9,-3,STONE:0)
Block(-3,9,-2,STONE:0)
Block(-3,9,-1,STONE:0)
Block(-3,9,0,STONE:0)
Block(-3,9,1,STONE:0)
Block(-3,9,2,STONE:0)
Block(-3,9,3,STONE:0)
Block(-3,9,4,STONE:0)
Block(-3,9,5,STONE:0)
Block(-3,9,6,STONE:0)
Block(-3,9,7,STONE:0)
Block(-3,9,8,STONE:0)
Block(-3,9,9,STONE:0)
Block(-3,10,-7,STONE:0)
Block(-3,10,-6,STONE:0)
Block(-3,10,-5,STONE:0)
Block(-3,10,-4,STONE:0)
Block(-3,10,-3,STONE:0)
Block(-3,10,-2,STONE:0)
Block(-3,10,-1,STONE:0)
Block(-3,10,0,STONE:0)
Block(-3,10,1,STONE:0)
Block(-3,10,2,STONE:0)
Block(-3,10,3,STONE:0)
Block(-3,10,4,STONE:0)
Block(-3,10,5,STONE:0)
Block(-3,10,6,STONE:0)
Block(-3,10,7,STONE:0)
Block(-3,10,8,STONE:0)
Block(-3,10,9,STONE:0)
Block(-3,11,-7,STONE:0)
Block(-3,11,-6,STONE:0)
Block(-3,11,-5,STONE:0)
Block(-3,11,-4,STONE:0)
Block(-3,11,-3,STONE:0)
Block(-3,11,-2,STONE:0)
Block(-3,11,-1,STONE:0)
Block(-3,11,0,STONE:0)
Block(-3,11,1,STONE:0)
Block(-3,11,2,STONE:0)
Block(-3,11,3,STONE:0)
Block(-3,11,4,STONE:0)
Block(-3,11,5,STONE:0)
Block(-3,11,6,STONE:0)
Block(-3,11,7,STONE:0)
Block(-3,11,8,STONE:0)
Block(-3,11,9,STONE:0)
Block(-3,12,-7,STONE:0)
Block(-3,12,-6,STONE:0)
Block(-3,12,-5,STONE:0)
Block(-3,12,-4,STONE:0)
Block(-3,12,-3,STONE:0)
Block(-3,12,-2,STONE:0)
Block(-3,12,-1,STONE:0)
Block(-3,12,0,STONE:0)
Block(-3,12,1,STONE:0)
Block(-3,12,2,STONE:0)
Block(-3,12,3,STONE:0)
Block(-3,12,4,STONE:0)
Block(-3,12,5,STONE:0)
Block(-3,12,6,STONE:0)
Block(-3,12,7,STONE:0)
Block(-3,12,8,STONE:0)
Block(-3,12,9,STONE:0)
Block(-3,13,-7,STONE:0)
Block(-3,13,-6,STONE:0)
Block(-3,13,-5,STONE:0)
Block(-3,13,-4,STONE:0)
Block(-3,13,-3,STONE:0)
Block(-3,13,-2,STONE:0)
Block(-3,13,-1,STONE:0)
Block(-3,13,0,STONE:0)
Block(-3,13,1,STONE:0)
Block(-3,13,2,STONE:0)
Block(-3,13,3,STONE:0)
Block(-3,13,4,STONE:0)
Block(-3,13,5,STONE:0)
Block(-3,13,6,STONE:0)
Block(-3,13,7,STONE:0)
Block(-3,13,8,STONE:0)
Block(-3,13,9,STONE:0)
Block(-3,14,-7,STONE:0)
Block(-3,14,-6,STONE:0)
Block(-3,14,-5,STONE:0)
Block(-3,14,-4,STONE:0)
Block(-3,14,-3,STONE:0)
Block(-3,14,-2,STONE:0)
Block(-3,14,-1,STONE:0)
Block(-3,14,0,STONE:0)
Block(-3,14,1,STONE:0)
Block(-3,14,2,STONE:0)
Block(-3,14,3,STONE:0)
Block(-3,14,4,STONE:0)
Block(-3,14,5,STONE:0)
Block(-3,14,6,STONE:0)
Block(-3,14,7,STONE:0)
Block(-3,14,8,STONE:0)
Block(-3,14,9,STONE:0)
Block(-3,15,-6,STONE:0)
Block(-3,15,-5,STONE:0)
Block(-3,15,-4,STONE:0)
Block(-3,15,-3,STONE:0)
Block(-3,15,-2,STONE:0)
Block(-3,15,-1,STONE:0)
Block(-3,15,0,STONE:0)
Block(-3,15,1,STONE:0)
Block(-3,15,2,STONE:0)
Block(-3,15,3,STONE:0)
Block(-3,15,4,STONE:0)
Block(-3,15,5,STONE:0)
Block(-3,15,6,STONE:0)
Block(-3,15,7,STONE:0)
Block(-3,15,8,STONE:0)
Block(-3,15,9,STONE:0)
Block(-3,16,-6,STONE:0)
Block(-3,16,-5,STONE:0)
Block(-3,16,-4,STONE:0)
Block(-3,16,-3,STONE:0)
Block(-3,16,-2,STONE:0)
Block(-3,16,-1,STONE:0)
Block(-3,16,0,STONE:0)
Block(-3,16,1,STONE:0)
Block(-3,16,2,STONE:0)
Block(-3,16,3,STONE:0)
Block(-3,16,4,STONE:0)
Block(-3,16,5,STONE:0)
Block(-3,16,6,STONE:0)
Block(-3,16,7,STONE:0)
Block(-3,16,8,STONE:0)
Block(-3,16,9,STONE:0)
Block(-3,17,-6,STONE:0)
Block(-3,17,-5,STONE:0)
Block(-3,17,-4,STONE:0)
Block(-3,17,-3,STONE:0)
Block(-3,17,-2,STONE:0)
Block(-3,17,-1,STONE:0)
Block(-3,17,0,STONE:0)
Block(-3,17,1,STONE:0)
Block(-3,17,2,STONE:0)
Block(-3,17,3,STONE:0)
Block(-3,17,4,STONE:0)
Block(-3,17,5,STONE:0)
Block(-3,17,6,STONE:0)
Block(-3,17,7,STONE:0)
Block(-3,17,8,STONE:0)
Block(-3,17,9,STONE:0)
Block(-3,18,-6,STONE:0)
Block(-3,18,-5,STONE:0)
Block(-3,18,-4,STONE:0)
Block(-3,18,-3,STONE:0)
Block(-3,18,-2,STONE:0)
Block(-3,18,-1,STONE:0)
Block(-3,18,0,STONE:0)
Block(-3,18,1,STONE:0)
Block(-3,18,2,STONE:0)
Block(-3,18,3,STONE:0)
Block(-3,18,4,STONE:0)
Block(-3,18,5,STONE:0)
Block(-3,18,6,STONE:0)
Block(-3,18,7,STONE:0)
Block(-3,18,8,STONE:0)
Block(-3,18,9,STONE:0)
Block(-3,19,-6,STONE:0)
Block(-3,19,-5,STONE:0)
Block(-3,19,-4,STONE:0)
Block(-3,19,-3,STONE:0)
Block(-3,19,-2,STONE:0)
Block(-3,19,-1,STONE:0)
Block(-3,19,0,STONE:0)
Block(-3,19,1,STONE:0)
Block(-3,19,2,STONE:0)
Block(-3,19,3,STONE:0)
Block(-3,19,4,STONE:0)
Block(-3,19,5,STONE:0)
Block(-3,19,6,STONE:0)
Block(-3,19,7,STONE:0)
Block(-3,19,8,STONE:0)
Block(-3,19,9,STONE:0)
Block(-3,20,-6,STONE:0)
Block(-3,20,-5,STONE:0)
Block(-3,20,-4,STONE:0)
Block(-3,20,-3,STONE:0)
Block(-3,20,-2,STONE:0)
Block(-3,20,-1,STONE:0)
Block(-3,20,0,STONE:0)
Block(-3,20,1,STONE:0)
Block(-3,20,2,STONE:0)
Block(-3,20,3,STONE:0)
Block(-3,20,4,STONE:0)
Block(-3,20,5,STONE:0)
Block(-3,20,6,STONE:0)
Block(-3,20,7,STONE:0)
Block(-3,20,8,STONE:0)
Block(-3,20,9,STONE:0)
Block(-3,21,-6,STONE:0)
Block(-3,21,-5,STONE:0)
Block(-3,21,-4,STONE:0)
Block(-3,21,-3,STONE:0)
Block(-3,21,-2,STONE:0)
Block(-3,21,-1,STONE:0)
Block(-3,21,0,STONE:0)
Block(-3,21,1,STONE:0)
Block(-3,21,2,STONE:0)
Block(-3,21,3,STONE:0)
Block(-3,21,4,STONE:0)
Block(-3,21,5,STONE:0)
Block(-3,21,6,STONE:0)
Block(-3,21,7,STONE:0)
Block(-3,21,8,STONE:0)
Block(-3,21,9,STONE:0)
Block(-3,22,-6,STONE:0)
Block(-3,22,-5,STONE:0)
Block(-3,22,-4,STONE:0)
Block(-3,22,-3,STONE:0)
Block(-3,22,-2,STONE:0)
Block(-3,22,-1,STONE:0)
Block(-3,22,0,STONE:0)
Block(-3,22,1,STONE:0)
Block(-3,22,2,STONE:0)
Block(-3,22,3,STONE:0)
Block(-3,22,4,STONE:0)
Block(-3,22,5,STONE:0)
Block(-3,22,6,STONE:0)
Block(-3,22,7,STONE:0)
Block(-3,22,8,STONE:0)
Block(-3,22,9,STONE:0)
Block(-3,23,-6,STONE:0)
Block(-3,23,-5,STONE:0)
Block(-3,23,-4,STONE:0)
Block(-3,23,-3,STONE:0)
Block(-3,23,-2,STONE:0)
Block(-3,23,-1,STONE:0)
Block(-3,23,0,STONE:0)
Block(-3,23,1,STONE:0)
Block(-3,23,2,STONE:0)
Block(-3,23,3,STONE:0)
Block(-3,23,4,STONE:0)
Block(-3,23,5,STONE:0)
Block(-3,23,6,STONE:0)
Block(-3,23,7,STONE:0)
Block(-3,23,8,STONE:0)
Block(-3,23,9,STONE:0)
Block(-3,24,-6,STONE:0)
Block(-3,24,-5,STONE:0)
Block(-3,24,-4,STONE:0)
Block(-3,24,-3,STONE:0)
Block(-3,24,-2,STONE:0)
Block(-3,24,-1,STONE:0)
Block(-3,24,0,STONE:0)
Block(-3,24,1,STONE:0)
Block(-3,24,2,STONE:0)
Block(-3,24,3,STONE:0)
Block(-3,24,4,STONE:0)
Block(-3,24,5,STONE:0)
Block(-3,24,6,STONE:0)
Block(-3,24,7,STONE:0)
Block(-3,24,8,STONE:0)
Block(-3,24,9,STONE:0)
Block(-3,25,-6,STONE:0)
Block(-3,25,-5,STONE:0)
Block(-3,25,-4,STONE:0)
Block(-3,25,-3,STONE:0)
Block(-3,25,-2,STONE:0)
Block(-3,25,-1,STONE:0)
Block(-3,25,0,STONE:0)
Block(-3,25,1,STONE:0)
Block(-3,25,2,STONE:0)
Block(-3,25,3,STONE:0)
Block(-3,25,4,STONE:0)
Block(-3,25,5,STONE:0)
Block(-3,25,6,STONE:0)
Block(-3,25,7,STONE:0)
Block(-3,25,8,STONE:0)
Block(-3,25,9,STONE:0)
Block(-3,26,-6,STONE:0)
Block(-3,26,-5,STONE:0)
Block(-3,26,-4,STONE:0)
Block(-3,26,-3,STONE:0)
Block(-3,26,-2,STONE:0)
Block(-3,26,-1,STONE:0)
Block(-3,26,0,STONE:0)
Block(-3,26,1,STONE:0)
Block(-3,26,2,STONE:0)
Block(-3,26,3,STONE:0)
Block(-3,26,4,STONE:0)
Block(-3,26,5,STONE:0)
Block(-3,26,6,STONE:0)
Block(-3,26,7,STONE:0)
Block(-3,26,8,STONE:0)
Block(-3,27,-6,STONE:0)
Block(-3,27,-5,STONE:0)
Block(-3,27,-4,STONE:0)
Block(-3,27,-3,STONE:0)
Block(-3,27,-2,STONE:0)
Block(-3,27,-1,STONE:0)
Block(-3,27,0,STONE:0)
Block(-3,27,1,STONE:0)
Block(-3,27,2,STONE:0)
Block(-3,27,3,STONE:0)
Block(-3,27,4,STONE:0)
Block(-3,27,5,STONE:0)
Block(-3,27,6,STONE:0)
Block(-3,27,7,STONE:0)
Block(-3,27,8,STONE:0)
Block(-3,28,-6,STONE:0)
Block(-3,28,-5,STONE:0)
Block(-3,28,-4,STONE:0)
Block(-3,28,-3,STONE:0)
Block(-3,28,-2,STONE:0)
Block(-3,28,-1,STONE:0)
Block(-3,28,0,STONE:0)
Block(-3,28,1,STONE:0)
Block(-3,28,2,STONE:0)
Block(-3,28,3,STONE:0)
Block(-3,28,4,STONE:0)
Block(-3,28,5,STONE:0)
Block(-3,28,6,STONE:0)
Block(-3,28,7,STONE:0)
Block(-3,28,8,STONE:0)
Block(-3,29,-6,STONE:0)
Block(-3,29,-5,STONE:0)
Block(-3,29,-4,STONE:0)
Block(-3,29,-3,STONE:0)
Block(-3,29,-2,STONE:0)
Block(-3,29,-1,STONE:0)
Block(-3,29,0,STONE:0)
Block(-3,29,1,STONE:0)
Block(-3,29,2,STONE:0)
Block(-3,29,3,STONE:0)
Block(-3,29,4,STONE:0)
Block(-3,29,5,STONE:0)
Block(-3,29,6,STONE:0)
Block(-3,29,7,STONE:0)
Block(-3,30,-6,STONE:0)
Block(-3,30,-5,STONE:0)
Block(-3,30,-4,STONE:0)
Block(-3,30,-3,STONE:0)
Block(-3,30,-2,STONE:0)
Block(-3,30,-1,STONE:0)
Block(-3,30,0,STONE:0)
Block(-3,30,1,STONE:0)
Block(-3,30,2,STONE:0)
Block(-3,30,3,STONE:0)
Block(-3,30,4,STONE:0)
Block(-3,30,5,STONE:0)
Block(-3,30,6,STONE:0)
Block(-3,30,7,STONE:0)
Block(-3,31,-6,STONE:0)
Block(-3,31,-5,STONE:0)
Block(-3,31,-4,STONE:0)
Block(-3,31,-3,STONE:0)
Block(-3,31,-2,STONE:0)
Block(-3,31,-1,STONE:0)
Block(-3,31,0,STONE:0)
Block(-3,31,1,STONE:0)
Block(-3,31,2,STONE:0)
Block(-3,31,3,STONE:0)
Block(-3,31,4,STONE:0)
Block(-3,31,5,STONE:0)
Block(-3,31,6,STONE:0)
Block(-3,31,7,STONE:0)
Block(-3,32,-6,STONE:0)
Block(-3,32,-5,STONE:0)
Block(-3,32,-4,STONE:0)
Block(-3,32,-3,STONE:0)
Block(-3,32,-2,STONE:0)
Block(-3,32,-1,STONE:0)
Block(-3,32,0,STONE:0)
Block(-3,32,1,STONE:0)
Block(-3,32,2,STONE:0)
Block(-3,32,3,STONE:0)
Block(-3,32,4,STONE:0)
Block(-3,32,5,STONE:0)
Block(-3,32,6,STONE:0)
Block(-3,32,7,STONE:0)
Block(-3,33,-6,STONE:0)
Block(-3,33,-5,STONE:0)
Block(-3,33,-4,STONE:0)
Block(-3,33,-3,STONE:0)
Block(-3,33,-2,STONE:0)
Block(-3,33,-1,STONE:0)
Block(-3,33,0,STONE:0)
Block(-3,33,1,STONE:0)
Block(-3,33,2,STONE:0)
Block(-3,33,3,STONE:0)
Block(-3,33,4,STONE:0)
Block(-3,33,5,STONE:0)
Block(-3,33,6,STONE:0)
Block(-3,33,7,STONE:0)
Block(-3,34,-5,STONE:0)
Block(-3,34,-4,STONE:0)
Block(-3,34,-3,STONE:0)
Block(-3,34,-2,STONE:0)
Block(-3,34,-1,STONE:0)
Block(-3,34,0,STONE:0)
Block(-3,34,1,STONE:0)
Block(-3,34,2,STONE:0)
Block(-3,34,3,STONE:0)
Block(-3,34,4,STONE:0)
Block(-3,34,5,STONE:0)
Block(-3,34,6,STONE:0)
Block(-3,34,7,STONE:0)
Block(-3,35,-5,STONE:0)
Block(-3,35,-4,STONE:0)
Block(-3,35,-3,STONE:0)
Block(-3,35,-2,STONE:0)
Block(-3,35,-1,STONE:0)
Block(-3,35,0,STONE:0)
Block(-3,35,1,STONE:0)
Block(-3,35,2,STONE:0)
Block(-3,35,3,STONE:0)
Block(-3,35,4,STONE:0)
Block(-3,35,5,STONE:0)
Block(-3,35,6,STONE:0)
