#######################################################################
# +-----------------------------------------------------------------+ #
# |                            BO3 object                           | #
# +-----------------------------------------------------------------+ #
#######################################################################

# The descriptions in this file are accurate only for TerrainControl and OTG.
# For MCW and OTG+ these descriptions are only accurate if the BO3 is used as a CustomObject.
# MCW and OTG+ completely reimplemented CustomStructure, check the MCW/OTG+ documentation for more information.

# This is the config file of a custom object.
# If you add this object correctly to your BiomeConfigs, it will spawn in the world.

# This is the creator of this BO3 object
Author: Unknown

# A short description of this BO3 object
Description: This BO3 was converted from a schematic using OTGEdit. The author and description information of the schematic could not be found. If you know who the author of the schematic is then please add this information.

# The BO3 version, don't change this! It can be used by external applications to do a version check.
Version: 3

# The settings mode, WriteAll, WriteWithoutComments or WriteDisable. See WorldConfig.
SettingsMode: WriteDisable

#######################################################################
# +-----------------------------------------------------------------+ #
# |                          Main settings                          | #
# +-----------------------------------------------------------------+ #
#######################################################################

# This needs to be set to true to spawn the object in the Tree and Sapling resources.
Tree: true

# The frequency of the BO3 from 1 to 200. Tries this many times to spawn this BO3 when using the CustomObject(...) resource.
# Ignored by Tree(..), Sapling(..) and CustomStructure(..)
Frequency: 40

# The rarity of the BO3 from 0 to 100. Each spawn attempt has rarity% chance to succeed when using the CustomObject(...) resource.
# Ignored by Tree(..), Sapling(..) and CustomStructure(..)
Rarity: 100.0

# If you set this to true, the BO3 will be placed with a random rotation.
RotateRandomly: true

# The spawn height of the BO3 - randomY, highestBlock or highestSolidBlock.
SpawnHeight: highestSolidBlock

SpawnHeightOffset: -2

# The height limits for the BO3.
MinHeight: 63

MaxHeight: 73

######################
# Extrusion settings #
######################

# The style of extrusion you wish to use - BottomDown, TopUp, None (Default)
ExtrudeMode: BottomDown

# The blocks to extrude your BO3 through
ExtrudeThroughBlocks: AIR

# Objects can have other objects attached to it: branches. Branches can also
# have branches attached to it, which can also have branches, etc. This is the
# maximum branch depth for this objects.
MaxBranchDepth: 10

# When spawned with the UseWorld keyword, this BO3 should NOT spawn in the following biomes.
# If you writer.write the BO3 name directly in the BiomeConfigs, this will be ignored.
ExcludedBiomes: All

# To optimise this BO3 for faster loading times you can use Notepad++ to find/replace comments and abbreviate things.
# Notepad++ find/replace with regex:
# Find: ^[#;].* replace to nothing removes all lines starting with # 
# Find: ^\s*$ replace to nothing removes most empty lines 
# Notepad++ find/replace without regex:
# *Warning: This will only work for OTG 1.10.2 v21 / OTG 1.11.2 v6 or higher. B( is not recognised by lower versions.
# Find: Block( replace to B(

#######################################################################
# +-----------------------------------------------------------------+ #
# |                      Source block settings                      | #
# +-----------------------------------------------------------------+ #
#######################################################################

# The block(s) the BO3 should spawn in.
SourceBlocks: STONE:1,STONE:3,STONE:5,DIRT:1,DIRT,SAND,GRASS,DIRT:2,STATIONARY_WATER,HARD_CLAY,STAINED_CLAY,CLAY,SANDSTONE,SAND:1,AIR,STONE,GRAVEL,LONG_GRASS,LONG_GRASS:1,LONG_GRASS:2,DEAD_BUSH,YELLOW_FLOWER,RED_ROSE,BROWN_MUSHROOM,RED_MUSHROOM,SNOW,SNOW_BLOCK

# The maximum percentage of the BO3 that can be outside the SourceBlock.
# The BO3 won't be placed on a location with more blocks outside the SourceBlock than this percentage.
MaxPercentageOutsideSourceBlock: 0

# What to do when a block is about to be placed outside the SourceBlock? (dontPlace, placeAnyway)
OutsideSourceBlock: placeAnyway

#######################################################################
# +-----------------------------------------------------------------+ #
# |                              Blocks                             | #
# +-----------------------------------------------------------------+ #
#######################################################################

# All the blocks used in the BO3 are listed here. Possible blocks:
# Block(x,y,z,id[.data][,nbtfile.nbt) or B(x,y,z,id[.data][,nbtfile.nbt)
# RandomBlock(x,y,z,id[:data][,nbtfile.nbt],chance[,id[:data][,nbtfile.nbt],chance[,...]])
# So RandomBlock(0,0,0,CHEST,chest.nbt,50,CHEST,anotherchest.nbt,100) will spawn a chest at
# the BO3 origin, and give it a 50% chance to have the contents of chest.nbt, or, if that
# fails, a 100% percent chance to have the contents of anotherchest.nbt.

Block(-6,4,-8,LEAVES:1)
Block(-6,5,-8,LEAVES:1)
Block(-6,5,4,LEAVES:1)
Block(-6,6,3,LEAVES:1)
Block(-6,6,4,LEAVES:1)
Block(-6,12,-1,LEAVES:1)
Block(-6,12,2,LEAVES:1)
Block(-6,13,2,LEAVES:1)
Block(-5,5,-8,LEAVES:1)
Block(-5,5,-7,LEAVES:1)
Block(-5,6,-7,LEAVES:1)
Block(-5,6,-6,LEAVES:1)
Block(-5,6,2,LEAVES:1)
Block(-5,6,3,LEAVES:1)
Block(-5,7,-6,LEAVES:1)
Block(-5,7,1,LEAVES:1)
Block(-5,12,-8,LEAVES:1)
Block(-5,12,-7,LEAVES:1)
Block(-5,12,-1,LEAVES:1)
Block(-5,13,-2,LEAVES:1)
Block(-5,13,-1,LEAVES:1)
Block(-5,13,1,LEAVES:1)
Block(-5,13,2,LEAVES:1)
Block(-5,16,-8,LEAVES:1)
Block(-5,16,3,LEAVES:1)
Block(-5,17,3,LEAVES:1)
Block(-5,20,4,LEAVES:1)
Block(-5,21,3,LEAVES:1)
Block(-5,21,4,LEAVES:1)
Block(-5,25,-8,LEAVES:1)
Block(-5,25,3,LEAVES:1)
Block(-5,26,-8,LEAVES:1)
Block(-5,26,-7,LEAVES:1)
Block(-5,26,2,LEAVES:1)
Block(-5,26,3,LEAVES:1)
Block(-5,31,-8,LEAVES:1)
Block(-5,31,2,LEAVES:1)
Block(-5,32,-8,LEAVES:1)
Block(-5,32,1,LEAVES:1)
Block(-5,32,2,LEAVES:1)
Block(-5,35,-8,LEAVES:1)
Block(-5,35,2,LEAVES:1)
Block(-5,36,-8,LEAVES:1)
Block(-5,36,2,LEAVES:1)
Block(-4,6,-6,LEAVES:1)
Block(-4,6,2,LEAVES:1)
Block(-4,6,3,LEAVES:1)
Block(-4,7,-6,LEAVES:1)
Block(-4,7,-5,LEAVES:1)
Block(-4,7,1,LEAVES:1)
Block(-4,7,2,LEAVES:1)
Block(-4,8,-5,LEAVES:1)
Block(-4,8,0,LEAVES:1)
Block(-4,12,-7,LEAVES:1)
Block(-4,12,-6,LEAVES:1)
Block(-4,13,-7,LEAVES:1)
Block(-4,13,-6,LEAVES:1)
Block(-4,13,-2,LEAVES:1)
Block(-4,13,1,LEAVES:1)
Block(-4,14,-6,LEAVES:1)
Block(-4,14,-2,LEAVES:1)
Block(-4,14,-1,LEAVES:1)
Block(-4,14,0,LEAVES:1)
Block(-4,14,1,LEAVES:1)
Block(-4,16,-8,LEAVES:1)
Block(-4,17,-8,LEAVES:1)
Block(-4,17,-7,LEAVES:1)
Block(-4,17,2,LEAVES:1)
Block(-4,17,3,LEAVES:1)
Block(-4,18,-6,LEAVES:1)
Block(-4,18,2,LEAVES:1)
Block(-4,18,3,LEAVES:1)
Block(-4,21,2,LEAVES:1)
Block(-4,21,3,LEAVES:1)
Block(-4,22,-8,LEAVES:1)
Block(-4,22,2,LEAVES:1)
Block(-4,26,-7,LEAVES:1)
Block(-4,26,1,LEAVES:1)
Block(-4,26,2,LEAVES:1)
Block(-4,27,-7,LEAVES:1)
Block(-4,27,-6,LEAVES:1)
Block(-4,27,1,LEAVES:1)
Block(-4,27,2,LEAVES:1)
Block(-4,28,1,LEAVES:1)
Block(-4,29,-5,LEAVES:1)
Block(-4,29,0,LEAVES:1)
Block(-4,32,-8,LEAVES:1)
Block(-4,32,-7,LEAVES:1)
Block(-4,32,1,LEAVES:1)
Block(-4,33,-7,LEAVES:1)
Block(-4,33,-6,LEAVES:1)
Block(-4,33,0,LEAVES:1)
Block(-4,33,1,LEAVES:1)
Block(-4,36,-8,LEAVES:1)
Block(-4,36,-7,LEAVES:1)
Block(-4,36,1,LEAVES:1)
Block(-4,36,2,LEAVES:1)
Block(-4,37,-7,LEAVES:1)
Block(-4,37,-6,LEAVES:1)
Block(-4,37,0,LEAVES:1)
Block(-4,37,1,LEAVES:1)
Block(-4,41,-7,LEAVES:1)
Block(-4,41,2,LEAVES:1)
Block(-4,42,-7,LEAVES:1)
Block(-4,42,-6,LEAVES:1)
Block(-4,42,1,LEAVES:1)
Block(-4,42,2,LEAVES:1)
Block(-4,43,0,LEAVES:1)
Block(-4,46,-6,LEAVES:1)
Block(-3,0,-5,17:13)
Block(-3,0,-4,17:13)
Block(-3,0,-3,17:13)
Block(-3,0,-2,17:13)
Block(-3,0,-1,17:13)
Block(-3,0,0,17:13)
Block(-3,0,1,17:13)
Block(-3,1,-5,17:13)
Block(-3,1,-4,17:13)
Block(-3,1,-3,17:13)
Block(-3,1,-1,17:13)
Block(-3,1,0,17:13)
Block(-3,2,-5,17:13)
Block(-3,2,-4,17:13)
Block(-3,2,-3,17:13)
Block(-3,2,-1,17:13)
Block(-3,2,0,17:13)
Block(-3,3,-4,17:13)
Block(-3,3,-1,17:13)
Block(-3,7,-6,LEAVES:1)
Block(-3,7,-5,LEAVES:1)
Block(-3,7,1,LEAVES:1)
Block(-3,8,-6,LEAVES:1)
Block(-3,8,-5,LEAVES:1)
Block(-3,8,-4,LEAVES:1)
Block(-3,8,-1,LEAVES:1)
Block(-3,8,0,LEAVES:1)
Block(-3,8,1,LEAVES:1)
Block(-3,9,-5,LEAVES:1)
Block(-3,9,-4,LEAVES:1)
Block(-3,9,-1,LEAVES:1)
Block(-3,13,-7,LEAVES:1)
Block(-3,13,-6,LEAVES:1)
Block(-3,14,-6,LEAVES:1)
Block(-3,14,-5,LEAVES:1)
Block(-3,14,-3,LEAVES:1)
Block(-3,14,-2,LEAVES:1)
Block(-3,14,-1,LEAVES:1)
Block(-3,14,0,LEAVES:1)
Block(-3,14,1,LEAVES:1)
Block(-3,14,2,LEAVES:1)
Block(-3,15,-3,LEAVES:1)
Block(-3,15,-2,LEAVES:1)
Block(-3,17,-7,LEAVES:1)
Block(-3,17,1,LEAVES:1)
Block(-3,18,-7,LEAVES:1)
Block(-3,18,-6,LEAVES:1)
Block(-3,18,-5,LEAVES:1)
Block(-3,18,1,LEAVES:1)
Block(-3,18,2,LEAVES:1)
Block(-3,19,-5,LEAVES:1)
Block(-3,19,0,LEAVES:1)
Block(-3,19,1,LEAVES:1)
Block(-3,20,-1,LEAVES:1)
Block(-3,22,-8,LEAVES:1)
Block(-3,22,-7,LEAVES:1)
Block(-3,22,1,LEAVES:1)
Block(-3,22,2,LEAVES:1)
Block(-3,23,-7,LEAVES:1)
Block(-3,23,1,LEAVES:1)
Block(-3,24,0,LEAVES:1)
Block(-3,25,-2,LEAVES:1)
Block(-3,25,-1,LEAVES:1)
Block(-3,27,-7,LEAVES:1)
Block(-3,27,-6,LEAVES:1)
Block(-3,27,0,LEAVES:1)
Block(-3,27,1,LEAVES:1)
Block(-3,28,-6,LEAVES:1)
Block(-3,28,-5,LEAVES:1)
Block(-3,28,0,LEAVES:1)
Block(-3,29,-5,LEAVES:1)
Block(-3,29,-1,LEAVES:1)
Block(-3,29,0,LEAVES:1)
Block(-3,33,-6,LEAVES:1)
Block(-3,33,-5,LEAVES:1)
Block(-3,33,0,LEAVES:1)
Block(-3,33,1,LEAVES:1)
Block(-3,34,-5,LEAVES:1)
Block(-3,34,-4,LEAVES:1)
Block(-3,34,-1,LEAVES:1)
Block(-3,34,0,LEAVES:1)
Block(-3,34,1,LEAVES:1)
Block(-3,37,-6,LEAVES:1)
Block(-3,37,-5,LEAVES:1)
Block(-3,37,0,LEAVES:1)
Block(-3,37,1,LEAVES:1)
Block(-3,38,-5,LEAVES:1)
Block(-3,38,-1,LEAVES:1)
Block(-3,38,0,LEAVES:1)
Block(-3,38,1,LEAVES:1)
Block(-3,42,-6,LEAVES:1)
Block(-3,42,-5,LEAVES:1)
Block(-3,42,1,LEAVES:1)
Block(-3,43,-5,LEAVES:1)
Block(-3,43,-4,LEAVES:1)
Block(-3,43,-1,LEAVES:1)
Block(-3,43,0,LEAVES:1)
Block(-3,45,1,LEAVES:1)
Block(-3,46,-6,LEAVES:1)
Block(-3,46,1,LEAVES:1)
Block(-3,47,-6,LEAVES:1)
Block(-3,47,-5,LEAVES:1)
Block(-3,47,0,LEAVES:1)
Block(-3,48,-4,LEAVES:1)
Block(-2,0,-5,17:13)
Block(-2,0,-4,17:13)
Block(-2,0,-3,17:13)
Block(-2,0,-2,17:13)
Block(-2,0,-1,17:13)
Block(-2,0,0,17:13)
Block(-2,0,1,17:13)
Block(-2,1,-5,17:13)
Block(-2,1,-4,17:13)
Block(-2,1,-3,17:13)
Block(-2,1,-2,17:13)
Block(-2,1,-1,17:13)
Block(-2,1,0,17:13)
Block(-2,1,1,17:13)
Block(-2,2,-5,17:13)
Block(-2,2,-4,17:13)
Block(-2,2,-3,17:13)
Block(-2,2,-2,17:13)
Block(-2,2,-1,17:13)
Block(-2,2,0,17:13)
Block(-2,2,1,17:13)
Block(-2,3,-5,17:13)
Block(-2,3,-4,17:13)
Block(-2,3,-3,17:13)
Block(-2,3,-2,17:13)
Block(-2,3,-1,17:13)
Block(-2,3,0,17:13)
Block(-2,4,-4,17:13)
Block(-2,4,-3,17:13)
Block(-2,4,-2,17:13)
Block(-2,4,-1,17:13)
Block(-2,4,0,17:13)
Block(-2,5,-3,17:13)
Block(-2,5,-2,17:13)
Block(-2,5,-1,17:13)
Block(-2,6,-7,LEAVES:1)
Block(-2,6,-3,17:13)
Block(-2,6,-2,17:13)
Block(-2,7,-3,17:13)
Block(-2,7,-2,17:13)
Block(-2,8,-5,LEAVES:1)
Block(-2,8,-4,LEAVES:1)
Block(-2,8,-3,17:13)
Block(-2,8,0,LEAVES:1)
Block(-2,9,-4,LEAVES:1)
Block(-2,9,-3,LEAVES:1)
Block(-2,9,-1,LEAVES:1)
Block(-2,9,0,LEAVES:1)
Block(-2,10,-4,LEAVES:1)
Block(-2,10,-3,LEAVES:1)
Block(-2,10,-2,LEAVES:1)
Block(-2,10,-1,LEAVES:1)
Block(-2,14,-6,LEAVES:1)
Block(-2,14,-5,LEAVES:1)
Block(-2,14,-3,LEAVES:1)
Block(-2,14,0,LEAVES:1)
Block(-2,15,-5,LEAVES:1)
Block(-2,15,-4,LEAVES:1)
Block(-2,15,-3,LEAVES:1)
Block(-2,15,-2,LEAVES:1)
Block(-2,15,-1,LEAVES:1)
Block(-2,15,0,LEAVES:1)
Block(-2,16,-2,LEAVES:1)
Block(-2,16,-1,LEAVES:1)
Block(-2,16,0,LEAVES:1)
Block(-2,18,-6,LEAVES:1)
Block(-2,18,-5,LEAVES:1)
Block(-2,18,1,LEAVES:1)
Block(-2,19,-5,LEAVES:1)
Block(-2,19,0,LEAVES:1)
Block(-2,19,1,LEAVES:1)
Block(-2,20,-5,LEAVES:1)
Block(-2,20,-3,LEAVES:1)
Block(-2,20,-2,LEAVES:1)
Block(-2,20,-1,LEAVES:1)
Block(-2,20,0,LEAVES:1)
Block(-2,21,-3,LEAVES:1)
Block(-2,21,-1,LEAVES:1)
Block(-2,23,-7,LEAVES:1)
Block(-2,23,-6,LEAVES:1)
Block(-2,23,-5,LEAVES:1)
Block(-2,23,0,LEAVES:1)
Block(-2,23,1,LEAVES:1)
Block(-2,23,2,LEAVES:1)
Block(-2,24,0,LEAVES:1)
Block(-2,24,1,LEAVES:1)
Block(-2,25,-2,LEAVES:1)
Block(-2,25,-1,LEAVES:1)
Block(-2,28,-7,LEAVES:1)
Block(-2,28,-6,LEAVES:1)
Block(-2,28,-2,LEAVES:1)
Block(-2,28,0,LEAVES:1)
Block(-2,29,-6,LEAVES:1)
Block(-2,29,-5,LEAVES:1)
Block(-2,29,-1,LEAVES:1)
Block(-2,29,0,LEAVES:1)
Block(-2,30,-5,LEAVES:1)
Block(-2,30,-4,LEAVES:1)
Block(-2,30,-2,LEAVES:1)
Block(-2,30,-1,LEAVES:1)
Block(-2,30,0,LEAVES:1)
Block(-2,31,-4,LEAVES:1)
Block(-2,31,-3,LEAVES:1)
Block(-2,31,-2,LEAVES:1)
Block(-2,32,-3,LEAVES:1)
Block(-2,33,-6,LEAVES:1)
Block(-2,33,-5,LEAVES:1)
Block(-2,34,-6,LEAVES:1)
Block(-2,34,-5,LEAVES:1)
Block(-2,34,-4,LEAVES:1)
Block(-2,34,-1,LEAVES:1)
Block(-2,34,0,LEAVES:1)
Block(-2,35,-3,LEAVES:1)
Block(-2,35,-2,LEAVES:1)
Block(-2,35,-1,LEAVES:1)
Block(-2,37,-5,LEAVES:1)
Block(-2,38,-6,LEAVES:1)
Block(-2,38,-5,LEAVES:1)
Block(-2,38,-4,LEAVES:1)
Block(-2,38,-2,LEAVES:1)
Block(-2,38,-1,LEAVES:1)
Block(-2,38,0,LEAVES:1)
Block(-2,38,1,LEAVES:1)
Block(-2,39,-1,LEAVES:1)
Block(-2,42,-5,LEAVES:1)
Block(-2,42,0,LEAVES:1)
Block(-2,43,-5,LEAVES:1)
Block(-2,43,-4,LEAVES:1)
Block(-2,43,-2,LEAVES:1)
Block(-2,43,-1,LEAVES:1)
Block(-2,43,0,LEAVES:1)
Block(-2,43,1,LEAVES:1)
Block(-2,44,-3,LEAVES:1)
Block(-2,46,0,LEAVES:1)
Block(-2,46,1,LEAVES:1)
Block(-2,47,-5,LEAVES:1)
Block(-2,47,-1,LEAVES:1)
Block(-2,47,0,LEAVES:1)
Block(-2,48,-4,LEAVES:1)
Block(-2,48,-2,LEAVES:1)
Block(-2,48,-1,LEAVES:1)
Block(-2,50,-5,LEAVES:1)
Block(-2,51,-5,LEAVES:1)
Block(-2,51,-4,LEAVES:1)
Block(-2,51,-1,LEAVES:1)
Block(-2,57,-4,LEAVES:1)
Block(-1,0,-5,17:13)
Block(-1,0,-4,17:13)
Block(-1,0,-3,17:13)
Block(-1,0,-2,17:13)
Block(-1,0,-1,17:13)
Block(-1,0,0,17:13)
Block(-1,0,1,17:13)
Block(-1,0,2,17:13)
Block(-1,1,-4,17:13)
Block(-1,1,-3,17:13)
Block(-1,1,-2,17:13)
Block(-1,1,-1,17:13)
Block(-1,1,0,17:13)
Block(-1,1,1,17:13)
Block(-1,1,2,17:13)
Block(-1,2,-4,17:13)
Block(-1,2,-3,17:13)
Block(-1,2,-2,17:13)
Block(-1,2,-1,17:13)
Block(-1,2,0,17:13)
Block(-1,2,1,17:13)
Block(-1,3,-4,17:13)
Block(-1,3,-3,17:13)
Block(-1,3,-2,17:13)
Block(-1,3,-1,17:13)
Block(-1,3,0,17:13)
Block(-1,3,1,17:13)
Block(-1,4,-4,17:13)
Block(-1,4,-3,17:13)
Block(-1,4,-2,17:13)
Block(-1,4,-1,17:13)
Block(-1,4,0,17:13)
Block(-1,5,-4,17:13)
Block(-1,5,-3,17:13)
Block(-1,5,-2,17:13)
Block(-1,5,-1,17:13)
Block(-1,5,0,17:13)
Block(-1,6,-8,LEAVES:1)
Block(-1,6,-7,LEAVES:1)
Block(-1,6,-4,17:13)
Block(-1,6,-3,17:13)
Block(-1,6,-2,17:13)
Block(-1,6,-1,17:13)
Block(-1,6,0,17:13)
Block(-1,7,-7,LEAVES:1)
Block(-1,7,-6,LEAVES:1)
Block(-1,7,-3,17:13)
Block(-1,7,-2,17:13)
Block(-1,7,-1,17:13)
Block(-1,8,-6,LEAVES:1)
Block(-1,8,-3,17:13)
Block(-1,8,-2,17:13)
Block(-1,8,-1,17:13)
Block(-1,9,-4,LEAVES:1)
Block(-1,9,-3,17:13)
Block(-1,9,-2,17:13)
Block(-1,9,-1,17:13)
Block(-1,9,0,LEAVES:1)
Block(-1,10,-4,LEAVES:1)
Block(-1,10,-3,LEAVES:1)
Block(-1,10,-2,17:13)
Block(-1,10,-1,LEAVES:1)
Block(-1,10,0,LEAVES:1)
Block(-1,11,-4,LEAVES:1)
Block(-1,11,-2,17:13)
Block(-1,11,-1,LEAVES:1)
Block(-1,12,-2,17:13)
Block(-1,13,-2,17:13)
Block(-1,14,-6,LEAVES:1)
Block(-1,14,-3,17:13)
Block(-1,14,-2,17:13)
Block(-1,15,-6,LEAVES:1)
Block(-1,15,-5,LEAVES:1)
Block(-1,15,-4,LEAVES:1)
Block(-1,15,-3,17:13)
Block(-1,15,-2,17:13)
Block(-1,15,-1,LEAVES:1)
Block(-1,16,-4,LEAVES:1)
Block(-1,16,-3,LEAVES:1)
Block(-1,16,-2,17:13)
Block(-1,16,-1,LEAVES:1)
Block(-1,16,0,LEAVES:1)
Block(-1,17,-2,LEAVES:1)
Block(-1,17,-1,LEAVES:1)
Block(-1,18,-6,LEAVES:1)
Block(-1,18,-5,LEAVES:1)
Block(-1,18,-4,LEAVES:1)
Block(-1,19,-5,LEAVES:1)
Block(-1,19,-4,LEAVES:1)
Block(-1,19,-3,LEAVES:1)
Block(-1,19,-1,LEAVES:1)
Block(-1,19,0,LEAVES:1)
Block(-1,20,-4,LEAVES:1)
Block(-1,20,-3,LEAVES:1)
Block(-1,20,-2,LEAVES:1)
Block(-1,20,-1,LEAVES:1)
Block(-1,20,0,LEAVES:1)
Block(-1,21,-3,LEAVES:1)
Block(-1,21,-2,LEAVES:1)
Block(-1,21,-1,LEAVES:1)
Block(-1,22,-3,LEAVES:1)
Block(-1,22,-2,LEAVES:1)
Block(-1,23,-6,LEAVES:1)
Block(-1,23,-5,LEAVES:1)
Block(-1,23,-3,LEAVES:1)
Block(-1,23,-2,LEAVES:1)
Block(-1,24,-5,LEAVES:1)
Block(-1,24,-4,LEAVES:1)
Block(-1,24,-1,LEAVES:1)
Block(-1,24,0,LEAVES:1)
Block(-1,24,1,LEAVES:1)
Block(-1,25,-5,LEAVES:1)
Block(-1,25,-3,LEAVES:1)
Block(-1,25,-2,LEAVES:1)
Block(-1,25,-1,LEAVES:1)
Block(-1,25,0,LEAVES:1)
Block(-1,26,-2,LEAVES:1)
Block(-1,27,-3,LEAVES:1)
Block(-1,28,-2,LEAVES:1)
Block(-1,29,-6,LEAVES:1)
Block(-1,29,-2,LEAVES:1)
Block(-1,29,-1,LEAVES:1)
Block(-1,30,-6,LEAVES:1)
Block(-1,30,-5,LEAVES:1)
Block(-1,30,-4,LEAVES:1)
Block(-1,30,-3,LEAVES:1)
Block(-1,30,-2,LEAVES:1)
Block(-1,30,-1,LEAVES:1)
Block(-1,31,-5,LEAVES:1)
Block(-1,31,-4,LEAVES:1)
Block(-1,31,-3,LEAVES:1)
Block(-1,31,-2,LEAVES:1)
Block(-1,31,-1,LEAVES:1)
Block(-1,31,0,LEAVES:1)
Block(-1,32,-3,LEAVES:1)
Block(-1,32,-2,LEAVES:1)
Block(-1,33,-4,LEAVES:1)
Block(-1,33,-3,LEAVES:1)
Block(-1,34,-5,LEAVES:1)
Block(-1,34,-4,LEAVES:1)
Block(-1,34,-2,LEAVES:1)
Block(-1,34,-1,LEAVES:1)
Block(-1,35,-4,LEAVES:1)
Block(-1,35,-3,LEAVES:1)
Block(-1,35,-2,LEAVES:1)
Block(-1,35,-1,LEAVES:1)
Block(-1,36,-3,LEAVES:1)
Block(-1,36,-2,LEAVES:1)
Block(-1,38,-4,LEAVES:1)
Block(-1,38,-3,LEAVES:1)
Block(-1,38,-1,LEAVES:1)
Block(-1,38,0,LEAVES:1)
Block(-1,39,-4,LEAVES:1)
Block(-1,39,-3,LEAVES:1)
Block(-1,39,-2,LEAVES:1)
Block(-1,39,-1,LEAVES:1)
Block(-1,39,0,LEAVES:1)
Block(-1,40,-3,LEAVES:1)
Block(-1,40,-2,LEAVES:1)
Block(-1,41,-3,LEAVES:1)
Block(-1,42,-3,LEAVES:1)
Block(-1,43,-4,LEAVES:1)
Block(-1,43,-2,LEAVES:1)
Block(-1,43,-1,LEAVES:1)
Block(-1,44,-4,LEAVES:1)
Block(-1,44,-3,LEAVES:1)
Block(-1,44,-2,LEAVES:1)
Block(-1,44,-1,LEAVES:1)
Block(-1,44,0,LEAVES:1)
Block(-1,45,-3,LEAVES:1)
Block(-1,47,-5,LEAVES:1)
Block(-1,47,-4,LEAVES:1)
Block(-1,47,-1,LEAVES:1)
Block(-1,47,0,LEAVES:1)
Block(-1,48,-5,LEAVES:1)
Block(-1,48,-4,LEAVES:1)
Block(-1,48,-3,LEAVES:1)
Block(-1,48,-2,LEAVES:1)
Block(-1,48,-1,LEAVES:1)
Block(-1,49,-2,LEAVES:1)
Block(-1,51,-5,LEAVES:1)
Block(-1,51,-4,LEAVES:1)
Block(-1,51,-2,LEAVES:1)
Block(-1,51,-1,LEAVES:1)
Block(-1,52,-4,LEAVES:1)
Block(-1,52,-3,LEAVES:1)
Block(-1,52,-2,LEAVES:1)
Block(-1,53,0,LEAVES:1)
Block(-1,54,-4,LEAVES:1)
Block(-1,54,-1,LEAVES:1)
Block(-1,54,0,LEAVES:1)
Block(-1,55,-3,LEAVES:1)
Block(-1,57,-4,LEAVES:1)
Block(-1,58,-4,LEAVES:1)
Block(-1,58,-3,LEAVES:1)
Block(0,0,-5,17:13)
Block(0,0,-4,17:13)
Block(0,0,-3,17:13)
Block(0,0,-2,17:13)
Block(0,0,-1,17:13)
Block(0,0,0,LOG:13)
Block(0,0,1,17:13)
Block(0,0,2,17:13)
Block(0,1,-5,17:13)
Block(0,1,-4,17:13)
Block(0,1,-3,17:13)
Block(0,1,-2,17:13)
Block(0,1,-1,17:13)
Block(0,1,0,17:13)
Block(0,1,1,17:13)
Block(0,1,2,17:13)
Block(0,2,-5,17:13)
Block(0,2,-4,17:13)
Block(0,2,-3,17:13)
Block(0,2,-2,17:13)
Block(0,2,-1,17:13)
Block(0,2,0,17:13)
Block(0,2,1,17:13)
Block(0,2,2,17:13)
Block(0,3,-4,17:13)
Block(0,3,-3,17:13)
Block(0,3,-2,17:13)
Block(0,3,-1,17:13)
Block(0,3,0,17:13)
Block(0,3,1,17:13)
Block(0,4,-4,17:13)
Block(0,4,-3,17:13)
Block(0,4,-2,17:13)
Block(0,4,-1,17:13)
Block(0,4,0,17:13)
Block(0,4,1,17:13)
Block(0,5,-4,17:13)
Block(0,5,-3,17:13)
Block(0,5,-2,17:13)
Block(0,5,-1,17:13)
Block(0,5,0,17:13)
Block(0,5,1,17:13)
Block(0,6,-4,17:13)
Block(0,6,-3,17:13)
Block(0,6,-2,17:13)
Block(0,6,-1,17:13)
Block(0,6,0,17:13)
Block(0,7,-6,LEAVES:1)
Block(0,7,-4,17:13)
Block(0,7,-3,17:13)
Block(0,7,-2,17:13)
Block(0,7,-1,17:13)
Block(0,7,0,17:13)
Block(0,8,-6,LEAVES:1)
Block(0,8,-4,17:13)
Block(0,8,-3,17:13)
Block(0,8,-2,17:13)
Block(0,8,-1,17:13)
Block(0,8,0,17:13)
Block(0,9,-6,LEAVES:1)
Block(0,9,-5,LEAVES:1)
Block(0,9,-4,17:13)
Block(0,9,-3,17:13)
Block(0,9,-2,17:13)
Block(0,9,-1,17:13)
Block(0,10,-4,LEAVES:1)
Block(0,10,-3,17:13)
Block(0,10,-2,17:13)
Block(0,10,-1,17:13)
Block(0,11,-4,LEAVES:1)
Block(0,11,-3,17:13)
Block(0,11,-2,17:13)
Block(0,11,-1,17:13)
Block(0,11,1,LEAVES:1)
Block(0,12,-3,17:13)
Block(0,12,-2,17:13)
Block(0,12,-1,17:13)
Block(0,12,0,LEAVES:1)
Block(0,13,-3,17:13)
Block(0,13,-2,17:13)
Block(0,13,-1,17:13)
Block(0,14,-2,17:13)
Block(0,14,-1,17:13)
Block(0,15,-3,17:13)
Block(0,15,-2,17:13)
Block(0,16,-6,LEAVES:1)
Block(0,16,-5,LEAVES:1)
Block(0,16,-4,LEAVES:1)
Block(0,16,-3,17:13)
Block(0,16,-2,17:13)
Block(0,16,-1,17:13)
Block(0,17,-4,LEAVES:1)
Block(0,17,-3,17:13)
Block(0,17,-2,17:13)
Block(0,17,-1,17:13)
Block(0,17,0,LEAVES:1)
Block(0,18,-3,17:13)
Block(0,18,-2,17:13)
Block(0,18,-1,17:13)
Block(0,19,-5,LEAVES:1)
Block(0,19,-4,LEAVES:1)
Block(0,19,-3,17:13)
Block(0,19,-2,17:13)
Block(0,19,-1,17:13)
Block(0,19,0,LEAVES:1)
Block(0,20,-5,LEAVES:1)
Block(0,20,-4,LEAVES:1)
Block(0,20,-3,17:13)
Block(0,20,-2,17:13)
Block(0,20,-1,17:13)
Block(0,20,0,LEAVES:1)
Block(0,20,1,LEAVES:1)
Block(0,21,-4,LEAVES:1)
Block(0,21,-3,17:13)
Block(0,21,-2,17:13)
Block(0,21,-1,LEAVES:1)
Block(0,21,0,LEAVES:1)
Block(0,22,-3,17:13)
Block(0,22,-2,17:13)
Block(0,22,-1,LEAVES:1)
Block(0,23,-3,17:13)
Block(0,23,-2,17:13)
Block(0,24,-4,LEAVES:1)
Block(0,24,-3,LEAVES:1)
Block(0,24,-2,17:13)
Block(0,25,-5,LEAVES:1)
Block(0,25,-4,LEAVES:1)
Block(0,25,-3,17:13)
Block(0,25,-2,17:13)
Block(0,25,-1,LEAVES:1)
Block(0,25,0,LEAVES:1)
Block(0,26,-5,LEAVES:1)
Block(0,26,-4,LEAVES:1)
Block(0,26,-3,17:13)
Block(0,26,-2,17:13)
Block(0,26,-1,LEAVES:1)
Block(0,27,-3,17:13)
Block(0,27,-2,17:13)
Block(0,27,-1,LEAVES:1)
Block(0,28,-4,LEAVES:1)
Block(0,28,-3,17:13)
Block(0,28,-2,17:13)
Block(0,29,-2,17:13)
Block(0,29,-1,LEAVES:1)
Block(0,30,-3,17:13)
Block(0,30,-2,17:13)
Block(0,30,-1,LEAVES:1)
Block(0,31,-6,LEAVES:1)
Block(0,31,-5,LEAVES:1)
Block(0,31,-4,LEAVES:1)
Block(0,31,-3,17:13)
Block(0,31,-2,17:13)
Block(0,31,-1,LEAVES:1)
Block(0,32,-4,LEAVES:1)
Block(0,32,-3,17:13)
Block(0,32,-2,17:13)
Block(0,32,-1,LEAVES:1)
Block(0,32,0,LEAVES:1)
Block(0,33,-3,17:13)
Block(0,33,-2,17:13)
Block(0,34,-3,17:13)
Block(0,34,-2,17:13)
Block(0,34,-1,LEAVES:1)
Block(0,35,-4,LEAVES:1)
Block(0,35,-3,17:13)
Block(0,35,-2,17:13)
Block(0,35,-1,LEAVES:1)
Block(0,36,-4,LEAVES:1)
Block(0,36,-3,LEAVES:1)
Block(0,36,-2,17:13)
Block(0,36,-1,LEAVES:1)
Block(0,37,-4,LEAVES:1)
Block(0,37,-3,LEAVES:1)
Block(0,37,-2,17:13)
Block(0,38,-4,LEAVES:1)
Block(0,38,-3,17:13)
Block(0,38,-2,17:13)
Block(0,39,-4,LEAVES:1)
Block(0,39,-3,17:13)
Block(0,39,-2,17:13)
Block(0,39,-1,LEAVES:1)
Block(0,40,-4,LEAVES:1)
Block(0,40,-3,LEAVES:1)
Block(0,40,-2,17:13)
Block(0,40,-1,LEAVES:1)
Block(0,40,0,LEAVES:1)
Block(0,41,-3,17:13)
Block(0,41,-2,17:13)
Block(0,42,-3,17:13)
Block(0,42,-2,17:13)
Block(0,42,-1,LEAVES:1)
Block(0,43,-3,17:13)
Block(0,43,-2,17:13)
Block(0,44,-4,LEAVES:1)
Block(0,44,-3,17:13)
Block(0,44,-2,17:13)
Block(0,44,-1,LEAVES:1)
Block(0,45,-4,LEAVES:1)
Block(0,45,-3,17:13)
Block(0,45,-2,LEAVES:1)
Block(0,46,-3,17:13)
Block(0,46,-2,17:13)
Block(0,46,-1,LEAVES:1)
Block(0,47,-3,17:13)
Block(0,47,-2,17:13)
Block(0,48,-4,LEAVES:1)
Block(0,48,-3,17:13)
Block(0,48,-2,17:13)
Block(0,48,-1,LEAVES:1)
Block(0,49,-4,LEAVES:1)
Block(0,49,-3,17:13)
Block(0,49,-2,17:13)
Block(0,49,-1,LEAVES:1)
Block(0,50,-2,17:13)
Block(0,51,-3,LEAVES:1)
Block(0,51,-2,17:13)
Block(0,52,-4,LEAVES:1)
Block(0,52,-3,LEAVES:1)
Block(0,52,-2,LEAVES:1)
Block(0,52,-1,LEAVES:1)
Block(0,53,-4,LEAVES:1)
Block(0,53,-3,LEAVES:1)
Block(0,54,-1,LEAVES:1)
Block(0,55,-3,LEAVES:1)
Block(0,55,-2,LEAVES:1)
Block(0,55,-1,LEAVES:1)
Block(0,57,-2,LEAVES:1)
Block(0,57,0,LEAVES:1)
Block(0,57,1,LEAVES:1)
Block(0,58,-3,LEAVES:1)
Block(0,58,-2,LEAVES:1)
Block(0,58,-1,LEAVES:1)
Block(0,58,0,LEAVES:1)
Block(0,59,-3,LEAVES:1)
Block(0,59,-2,LEAVES:1)
Block(0,59,-1,LEAVES:1)
Block(0,60,-2,LEAVES:1)
Block(0,61,-2,LEAVES:1)
Block(0,62,-2,LEAVES:1)
Block(1,0,-5,17:13)
Block(1,0,-4,17:13)
Block(1,0,-3,17:13)
Block(1,0,-2,17:13)
Block(1,0,-1,17:13)
Block(1,0,0,17:13)
Block(1,0,1,17:13)
Block(1,0,2,17:13)
Block(1,1,-5,17:13)
Block(1,1,-4,17:13)
Block(1,1,-3,17:13)
Block(1,1,-2,17:13)
Block(1,1,-1,17:13)
Block(1,1,0,17:13)
Block(1,1,1,17:13)
Block(1,1,2,17:13)
Block(1,2,-5,17:13)
Block(1,2,-4,17:13)
Block(1,2,-3,17:13)
Block(1,2,-2,17:13)
Block(1,2,-1,17:13)
Block(1,2,0,17:13)
Block(1,2,1,17:13)
Block(1,2,2,17:13)
Block(1,3,-5,17:13)
Block(1,3,-4,17:13)
Block(1,3,-3,17:13)
Block(1,3,-2,17:13)
Block(1,3,-1,17:13)
Block(1,3,0,17:13)
Block(1,3,1,17:13)
Block(1,3,2,17:13)
Block(1,4,-5,17:13)
Block(1,4,-4,17:13)
Block(1,4,-3,17:13)
Block(1,4,-2,17:13)
Block(1,4,-1,17:13)
Block(1,4,0,17:13)
Block(1,4,1,17:13)
Block(1,4,2,17:13)
Block(1,5,-4,17:13)
Block(1,5,-3,17:13)
Block(1,5,-2,17:13)
Block(1,5,-1,17:13)
Block(1,5,0,17:13)
Block(1,5,1,17:13)
Block(1,6,-4,17:13)
Block(1,6,-3,17:13)
Block(1,6,-2,17:13)
Block(1,6,-1,17:13)
Block(1,6,0,17:13)
Block(1,6,1,17:13)
Block(1,7,-4,17:13)
Block(1,7,-3,17:13)
Block(1,7,-2,17:13)
Block(1,7,-1,17:13)
Block(1,7,0,17:13)
Block(1,8,-3,17:13)
Block(1,8,-2,17:13)
Block(1,8,-1,17:13)
Block(1,8,0,17:13)
Block(1,9,-5,LEAVES:1)
Block(1,9,-3,17:13)
Block(1,9,-2,17:13)
Block(1,9,-1,17:13)
Block(1,9,0,17:13)
Block(1,10,-5,LEAVES:1)
Block(1,10,-4,LEAVES:1)
Block(1,10,-3,17:13)
Block(1,10,-2,17:13)
Block(1,10,-1,17:13)
Block(1,10,0,LEAVES:1)
Block(1,11,-4,LEAVES:1)
Block(1,11,-3,LEAVES:1)
Block(1,11,-2,17:13)
Block(1,11,-1,LEAVES:1)
Block(1,11,0,LEAVES:1)
Block(1,11,1,LEAVES:1)
Block(1,12,-2,17:13)
Block(1,12,-1,17:13)
Block(1,12,0,LEAVES:1)
Block(1,13,-3,LEAVES:1)
Block(1,13,-2,17:13)
Block(1,13,-1,LEAVES:1)
Block(1,14,-2,17:13)
Block(1,14,-1,17:13)
Block(1,15,-3,LEAVES:1)
Block(1,15,-2,17:13)
Block(1,15,-1,17:13)
Block(1,16,-5,LEAVES:1)
Block(1,16,-4,LEAVES:1)
Block(1,16,-3,LEAVES:1)
Block(1,16,-2,17:13)
Block(1,16,-1,17:13)
Block(1,17,-4,LEAVES:1)
Block(1,17,-3,LEAVES:1)
Block(1,17,-2,17:13)
Block(1,18,-2,17:13)
Block(1,18,-1,17:13)
Block(1,18,0,LEAVES:1)
Block(1,19,-3,LEAVES:1)
Block(1,19,-2,17:13)
Block(1,19,0,LEAVES:1)
Block(1,19,1,LEAVES:1)
Block(1,19,2,LEAVES:1)
Block(1,20,-5,LEAVES:1)
Block(1,20,-4,LEAVES:1)
Block(1,20,-3,LEAVES:1)
Block(1,20,-2,17:13)
Block(1,20,-1,17:13)
Block(1,20,0,LEAVES:1)
Block(1,20,1,LEAVES:1)
Block(1,21,-3,17:13)
Block(1,21,-2,17:13)
Block(1,21,-1,17:13)
Block(1,21,0,LEAVES:1)
Block(1,22,-3,17:13)
Block(1,22,-2,17:13)
Block(1,22,-1,LEAVES:1)
Block(1,23,-3,17:13)
Block(1,23,-2,17:13)
Block(1,23,-1,LEAVES:1)
Block(1,24,-4,LEAVES:1)
Block(1,24,-3,17:13)
Block(1,24,-2,17:13)
Block(1,24,-1,LEAVES:1)
Block(1,24,0,LEAVES:1)
Block(1,25,-4,LEAVES:1)
Block(1,25,-3,17:13)
Block(1,25,-2,17:13)
Block(1,25,-1,LEAVES:1)
Block(1,25,0,LEAVES:1)
Block(1,26,-3,17:13)
Block(1,26,-2,17:13)
Block(1,26,-1,LEAVES:1)
Block(1,27,-4,LEAVES:1)
Block(1,27,-3,17:13)
Block(1,27,-2,17:13)
Block(1,28,-3,17:13)
Block(1,29,-4,LEAVES:1)
Block(1,29,-3,17:13)
Block(1,29,-2,17:13)
Block(1,30,-3,17:13)
Block(1,30,-2,17:13)
Block(1,30,-1,LEAVES:1)
Block(1,30,0,LEAVES:1)
Block(1,31,-4,LEAVES:1)
Block(1,31,-3,17:13)
Block(1,31,-2,17:13)
Block(1,31,-1,LEAVES:1)
Block(1,32,-3,17:13)
Block(1,32,-2,17:13)
Block(1,33,-3,17:13)
Block(1,33,-2,LEAVES:1)
Block(1,33,-1,LEAVES:1)
Block(1,34,-5,LEAVES:1)
Block(1,34,-4,LEAVES:1)
Block(1,34,-3,LEAVES:1)
Block(1,34,-2,17:13)
Block(1,34,-1,LEAVES:1)
Block(1,34,0,LEAVES:1)
Block(1,35,-4,LEAVES:1)
Block(1,35,-3,17:13)
Block(1,35,-2,17:13)
Block(1,35,-1,LEAVES:1)
Block(1,36,-3,17:13)
Block(1,36,-2,17:13)
Block(1,36,-1,LEAVES:1)
Block(1,37,-3,17:13)
Block(1,37,-2,17:13)
Block(1,37,-1,LEAVES:1)
Block(1,38,-3,17:13)
Block(1,38,-2,17:13)
Block(1,39,-4,LEAVES:1)
Block(1,39,-3,17:13)
Block(1,40,-3,LEAVES:1)
Block(1,40,-2,17:13)
Block(1,40,-1,LEAVES:1)
Block(1,40,0,LEAVES:1)
Block(1,41,-4,LEAVES:1)
Block(1,41,-3,17:13)
Block(1,41,-2,17:13)
Block(1,41,-1,LEAVES:1)
Block(1,41,0,LEAVES:1)
Block(1,42,-4,LEAVES:1)
Block(1,42,-3,17:13)
Block(1,42,-2,17:13)
Block(1,43,-4,LEAVES:1)
Block(1,43,-3,17:13)
Block(1,43,-2,17:13)
Block(1,43,-1,LEAVES:1)
Block(1,44,-3,17:13)
Block(1,44,-2,17:13)
Block(1,44,-1,LEAVES:1)
Block(1,45,-2,17:13)
Block(1,45,-1,LEAVES:1)
Block(1,46,-3,17:13)
Block(1,46,-2,17:13)
Block(1,46,-1,LEAVES:1)
Block(1,47,-4,LEAVES:1)
Block(1,47,-3,17:13)
Block(1,47,-2,17:13)
Block(1,48,-6,LEAVES:1)
Block(1,48,-5,LEAVES:1)
Block(1,48,-4,LEAVES:1)
Block(1,48,-3,LEAVES:1)
Block(1,48,-2,17:13)
Block(1,48,-1,LEAVES:1)
Block(1,49,-4,LEAVES:1)
Block(1,49,-3,17:13)
Block(1,49,-2,17:13)
Block(1,49,-1,LEAVES:1)
Block(1,50,-3,17:13)
Block(1,50,-2,17:13)
Block(1,50,-1,LEAVES:1)
Block(1,51,-4,LEAVES:1)
Block(1,51,-3,17:13)
Block(1,51,-2,17:13)
Block(1,52,-3,17:13)
Block(1,52,-2,17:13)
Block(1,52,-1,LEAVES:1)
Block(1,53,-3,LEAVES:1)
Block(1,53,-2,17:13)
Block(1,54,-2,17:13)
Block(1,55,-3,LEAVES:1)
Block(1,55,-2,17:13)
Block(1,55,-1,LEAVES:1)
Block(1,56,-2,17:13)
Block(1,57,-3,LEAVES:1)
Block(1,57,-2,17:13)
Block(1,58,-3,LEAVES:1)
Block(1,58,-2,17:13)
Block(1,58,-1,LEAVES:1)
Block(1,59,-3,LEAVES:1)
Block(1,59,-2,17:13)
Block(1,59,-1,LEAVES:1)
Block(1,60,-3,LEAVES:1)
Block(1,60,-2,17:13)
Block(1,60,-1,LEAVES:1)
Block(1,61,-2,17:13)
Block(1,61,-1,LEAVES:1)
Block(1,62,-2,17:13)
Block(1,63,-2,17:13)
Block(2,0,-6,17:13)
Block(2,0,-5,17:13)
Block(2,0,-4,17:13)
Block(2,0,-3,17:13)
Block(2,0,-2,17:13)
Block(2,0,-1,17:13)
Block(2,0,0,17:13)
Block(2,0,1,17:13)
Block(2,0,2,17:13)
Block(2,1,-5,17:13)
Block(2,1,-4,17:13)
Block(2,1,-3,17:13)
Block(2,1,-2,17:13)
Block(2,1,-1,17:13)
Block(2,1,0,17:13)
Block(2,1,1,17:13)
Block(2,1,2,17:13)
Block(2,2,-5,17:13)
Block(2,2,-4,17:13)
Block(2,2,-3,17:13)
Block(2,2,-2,17:13)
Block(2,2,-1,17:13)
Block(2,2,0,17:13)
Block(2,2,1,17:13)
Block(2,3,-5,17:13)
Block(2,3,-4,17:13)
Block(2,3,-3,17:13)
Block(2,3,-2,17:13)
Block(2,3,-1,17:13)
Block(2,3,0,17:13)
Block(2,3,1,17:13)
Block(2,4,-4,17:13)
Block(2,4,-3,17:13)
Block(2,4,-2,17:13)
Block(2,4,-1,17:13)
Block(2,4,0,17:13)
Block(2,4,1,17:13)
Block(2,5,-4,17:13)
Block(2,5,-3,17:13)
Block(2,5,-2,17:13)
Block(2,5,-1,17:13)
Block(2,5,0,17:13)
Block(2,6,-4,17:13)
Block(2,6,-3,17:13)
Block(2,6,-2,17:13)
Block(2,6,-1,17:13)
Block(2,6,0,17:13)
Block(2,7,-3,17:13)
Block(2,7,-2,17:13)
Block(2,7,-1,17:13)
Block(2,8,-2,17:13)
Block(2,9,-5,LEAVES:1)
Block(2,9,-4,LEAVES:1)
Block(2,9,-3,LEAVES:1)
Block(2,9,-2,17:13)
Block(2,9,-1,LEAVES:1)
Block(2,9,3,LEAVES:1)
Block(2,10,-3,LEAVES:1)
Block(2,10,-2,17:13)
Block(2,10,-1,LEAVES:1)
Block(2,10,0,LEAVES:1)
Block(2,10,1,LEAVES:1)
Block(2,10,2,LEAVES:1)
Block(2,11,-2,17:13)
Block(2,11,-1,LEAVES:1)
Block(2,11,0,LEAVES:1)
Block(2,11,1,LEAVES:1)
Block(2,12,-1,LEAVES:1)
Block(2,13,-2,LEAVES:1)
Block(2,14,-3,LEAVES:1)
Block(2,14,-2,LEAVES:1)
Block(2,15,-3,LEAVES:1)
Block(2,15,-2,LEAVES:1)
Block(2,17,-2,LEAVES:1)
Block(2,17,-1,LEAVES:1)
Block(2,17,2,LEAVES:1)
Block(2,17,3,LEAVES:1)
Block(2,18,-5,LEAVES:1)
Block(2,18,-4,LEAVES:1)
Block(2,18,-3,LEAVES:1)
Block(2,18,-2,LEAVES:1)
Block(2,18,1,LEAVES:1)
Block(2,18,2,LEAVES:1)
Block(2,19,-5,LEAVES:1)
Block(2,19,-4,LEAVES:1)
Block(2,19,-3,LEAVES:1)
Block(2,19,0,LEAVES:1)
Block(2,19,1,LEAVES:1)
Block(2,20,-4,LEAVES:1)
Block(2,20,-3,LEAVES:1)
Block(2,20,-2,LEAVES:1)
Block(2,20,-1,LEAVES:1)
Block(2,20,0,LEAVES:1)
Block(2,21,-2,LEAVES:1)
Block(2,21,-1,LEAVES:1)
Block(2,22,-2,LEAVES:1)
Block(2,23,-2,LEAVES:1)
Block(2,23,0,LEAVES:1)
Block(2,24,-5,LEAVES:1)
Block(2,24,-4,LEAVES:1)
Block(2,24,-3,LEAVES:1)
Block(2,24,-2,LEAVES:1)
Block(2,24,-1,LEAVES:1)
Block(2,24,0,LEAVES:1)
Block(2,24,1,LEAVES:1)
Block(2,24,2,LEAVES:1)
Block(2,25,-3,LEAVES:1)
Block(2,25,-2,LEAVES:1)
Block(2,26,-3,LEAVES:1)
Block(2,28,-3,LEAVES:1)
Block(2,28,2,LEAVES:1)
Block(2,29,-3,LEAVES:1)
Block(2,29,-2,LEAVES:1)
Block(2,29,-1,LEAVES:1)
Block(2,29,0,LEAVES:1)
Block(2,29,1,LEAVES:1)
Block(2,30,-4,LEAVES:1)
Block(2,30,-2,LEAVES:1)
Block(2,30,-1,LEAVES:1)
Block(2,30,0,LEAVES:1)
Block(2,31,-4,LEAVES:1)
Block(2,31,-3,LEAVES:1)
Block(2,33,-4,LEAVES:1)
Block(2,33,-1,LEAVES:1)
Block(2,33,0,LEAVES:1)
Block(2,34,-5,LEAVES:1)
Block(2,34,-4,LEAVES:1)
Block(2,34,-2,LEAVES:1)
Block(2,34,-1,LEAVES:1)
Block(2,34,0,LEAVES:1)
Block(2,35,-3,LEAVES:1)
Block(2,35,-2,LEAVES:1)
Block(2,35,-1,LEAVES:1)
Block(2,36,-2,LEAVES:1)
Block(2,37,-3,LEAVES:1)
Block(2,38,-4,LEAVES:1)
Block(2,38,-1,LEAVES:1)
Block(2,39,-4,LEAVES:1)
Block(2,39,-3,LEAVES:1)
Block(2,39,-2,LEAVES:1)
Block(2,39,-1,LEAVES:1)
Block(2,39,0,LEAVES:1)
Block(2,40,-2,LEAVES:1)
Block(2,40,-1,LEAVES:1)
Block(2,41,-2,LEAVES:1)
Block(2,42,-2,LEAVES:1)
Block(2,42,-1,LEAVES:1)
Block(2,43,-4,LEAVES:1)
Block(2,43,-3,LEAVES:1)
Block(2,43,-1,LEAVES:1)
Block(2,44,-3,LEAVES:1)
Block(2,44,-2,LEAVES:1)
Block(2,44,-1,LEAVES:1)
Block(2,44,0,LEAVES:1)
Block(2,44,1,LEAVES:1)
Block(2,45,-2,LEAVES:1)
Block(2,47,-6,LEAVES:1)
Block(2,47,-5,LEAVES:1)
Block(2,47,-4,LEAVES:1)
Block(2,47,-2,LEAVES:1)
Block(2,47,-1,LEAVES:1)
Block(2,48,-4,LEAVES:1)
Block(2,48,-3,LEAVES:1)
Block(2,48,-2,LEAVES:1)
Block(2,48,-1,LEAVES:1)
Block(2,49,-2,LEAVES:1)
Block(2,51,-5,LEAVES:1)
Block(2,51,-4,LEAVES:1)
Block(2,51,-1,LEAVES:1)
Block(2,52,-4,LEAVES:1)
Block(2,52,-3,LEAVES:1)
Block(2,52,-2,LEAVES:1)
Block(2,52,-1,LEAVES:1)
Block(2,53,-2,LEAVES:1)
Block(2,54,-4,LEAVES:1)
Block(2,54,-3,LEAVES:1)
Block(2,54,-1,LEAVES:1)
Block(2,54,0,LEAVES:1)
Block(2,55,-3,LEAVES:1)
Block(2,55,-2,LEAVES:1)
Block(2,55,-1,LEAVES:1)
Block(2,55,0,LEAVES:1)
Block(2,56,-3,LEAVES:1)
Block(2,56,-2,LEAVES:1)
Block(2,58,-4,LEAVES:1)
Block(2,58,-3,LEAVES:1)
Block(2,58,-1,LEAVES:1)
Block(2,58,0,LEAVES:1)
Block(2,59,-3,LEAVES:1)
Block(2,59,-1,LEAVES:1)
Block(3,0,-5,17:13)
Block(3,0,-4,17:13)
Block(3,0,-3,17:13)
Block(3,0,-2,17:13)
Block(3,0,-1,17:13)
Block(3,0,0,17:13)
Block(3,0,1,17:13)
Block(3,1,-5,17:13)
Block(3,1,-4,17:13)
Block(3,1,-2,17:13)
Block(3,1,-1,17:13)
Block(3,1,0,17:13)
Block(3,1,1,17:13)
Block(3,2,-5,17:13)
Block(3,2,-4,17:13)
Block(3,2,-2,17:13)
Block(3,2,-1,17:13)
Block(3,2,0,17:13)
Block(3,2,1,17:13)
Block(3,3,-4,17:13)
Block(3,3,-1,17:13)
Block(3,3,0,17:13)
Block(3,4,-1,17:13)
Block(3,4,0,17:13)
Block(3,5,0,17:13)
Block(3,7,4,LEAVES:1)
Block(3,8,-5,LEAVES:1)
Block(3,8,-4,LEAVES:1)
Block(3,8,-3,LEAVES:1)
Block(3,8,3,LEAVES:1)
Block(3,8,4,LEAVES:1)
Block(3,9,-4,LEAVES:1)
Block(3,9,-3,LEAVES:1)
Block(3,9,-2,LEAVES:1)
Block(3,9,2,LEAVES:1)
Block(3,9,3,LEAVES:1)
Block(3,10,-2,LEAVES:1)
Block(3,10,1,LEAVES:1)
Block(3,10,2,LEAVES:1)
Block(3,11,-2,LEAVES:1)
Block(3,11,-1,LEAVES:1)
Block(3,12,-4,LEAVES:1)
Block(3,12,-3,LEAVES:1)
Block(3,13,-3,LEAVES:1)
Block(3,14,-3,LEAVES:1)
Block(3,16,-1,LEAVES:1)
Block(3,17,-2,LEAVES:1)
Block(3,17,-1,LEAVES:1)
Block(3,17,2,LEAVES:1)
Block(3,17,3,LEAVES:1)
Block(3,18,-6,LEAVES:1)
Block(3,18,-5,LEAVES:1)
Block(3,18,-4,LEAVES:1)
Block(3,18,-2,LEAVES:1)
Block(3,18,1,LEAVES:1)
Block(3,18,2,LEAVES:1)
Block(3,18,3,LEAVES:1)
Block(3,19,-5,LEAVES:1)
Block(3,19,0,LEAVES:1)
Block(3,23,-6,LEAVES:1)
Block(3,23,-5,LEAVES:1)
Block(3,23,0,LEAVES:1)
Block(3,23,1,LEAVES:1)
Block(3,23,2,LEAVES:1)
Block(3,24,-5,LEAVES:1)
Block(3,24,-4,LEAVES:1)
Block(3,24,-3,LEAVES:1)
Block(3,24,-1,LEAVES:1)
Block(3,24,0,LEAVES:1)
Block(3,28,0,LEAVES:1)
Block(3,28,2,LEAVES:1)
Block(3,29,-5,LEAVES:1)
Block(3,29,-4,LEAVES:1)
Block(3,29,0,LEAVES:1)
Block(3,29,1,LEAVES:1)
Block(3,30,-5,LEAVES:1)
Block(3,30,-4,LEAVES:1)
Block(3,30,-3,LEAVES:1)
Block(3,30,-2,LEAVES:1)
Block(3,30,-1,LEAVES:1)
Block(3,32,-5,LEAVES:1)
Block(3,32,0,LEAVES:1)
Block(3,32,1,LEAVES:1)
Block(3,32,2,LEAVES:1)
Block(3,33,-7,LEAVES:1)
Block(3,33,-6,LEAVES:1)
Block(3,33,-5,LEAVES:1)
Block(3,33,-4,LEAVES:1)
Block(3,33,-1,LEAVES:1)
Block(3,33,0,LEAVES:1)
Block(3,33,1,LEAVES:1)
Block(3,34,-4,LEAVES:1)
Block(3,34,-2,LEAVES:1)
Block(3,34,-1,LEAVES:1)
Block(3,35,-3,LEAVES:1)
Block(3,37,-5,LEAVES:1)
Block(3,37,-3,LEAVES:1)
Block(3,38,-5,LEAVES:1)
Block(3,38,-4,LEAVES:1)
Block(3,38,-2,LEAVES:1)
Block(3,38,-1,LEAVES:1)
Block(3,38,0,LEAVES:1)
Block(3,38,1,LEAVES:1)
Block(3,39,-4,LEAVES:1)
Block(3,39,-3,LEAVES:1)
Block(3,39,-1,LEAVES:1)
Block(3,40,-2,LEAVES:1)
Block(3,41,-2,LEAVES:1)
Block(3,42,-5,LEAVES:1)
Block(3,42,-4,LEAVES:1)
Block(3,42,0,LEAVES:1)
Block(3,43,-5,LEAVES:1)
Block(3,43,-4,LEAVES:1)
Block(3,43,-1,LEAVES:1)
Block(3,43,0,LEAVES:1)
Block(3,44,-4,LEAVES:1)
Block(3,44,-1,LEAVES:1)
Block(3,46,-6,LEAVES:1)
Block(3,46,0,LEAVES:1)
Block(3,46,1,LEAVES:1)
Block(3,47,-6,LEAVES:1)
Block(3,47,-5,LEAVES:1)
Block(3,47,-1,LEAVES:1)
Block(3,47,0,LEAVES:1)
Block(3,48,-1,LEAVES:1)
Block(3,50,-5,LEAVES:1)
Block(3,50,0,LEAVES:1)
Block(3,51,-5,LEAVES:1)
Block(3,51,-1,LEAVES:1)
Block(3,51,0,LEAVES:1)
Block(3,54,-4,LEAVES:1)
Block(3,57,0,LEAVES:1)
Block(3,58,0,LEAVES:1)
Block(4,0,0,17:13)
Block(4,7,-5,LEAVES:1)
Block(4,7,-4,LEAVES:1)
Block(4,7,4,LEAVES:1)
Block(4,7,5,LEAVES:1)
Block(4,8,-5,LEAVES:1)
Block(4,8,-4,LEAVES:1)
Block(4,8,-3,LEAVES:1)
Block(4,8,3,LEAVES:1)
Block(4,8,4,LEAVES:1)
Block(4,9,-4,LEAVES:1)
Block(4,9,-3,LEAVES:1)
Block(4,9,3,LEAVES:1)
Block(4,12,-4,LEAVES:1)
Block(4,12,-3,LEAVES:1)
Block(4,13,-4,LEAVES:1)
Block(4,13,-3,LEAVES:1)
Block(4,16,-1,LEAVES:1)
Block(4,16,0,LEAVES:1)
Block(4,16,3,LEAVES:1)
Block(4,16,4,LEAVES:1)
Block(4,17,-6,LEAVES:1)
Block(4,17,-2,LEAVES:1)
Block(4,17,3,LEAVES:1)
Block(4,18,-6,LEAVES:1)
Block(4,18,-5,LEAVES:1)
Block(4,21,3,LEAVES:1)
Block(4,22,-6,LEAVES:1)
Block(4,22,2,LEAVES:1)
Block(4,22,3,LEAVES:1)
Block(4,23,-6,LEAVES:1)
Block(4,23,-5,LEAVES:1)
Block(4,23,-4,LEAVES:1)
Block(4,23,1,LEAVES:1)
Block(4,23,2,LEAVES:1)
Block(4,24,-4,LEAVES:1)
Block(4,24,0,LEAVES:1)
Block(4,27,2,LEAVES:1)
Block(4,27,3,LEAVES:1)
Block(4,28,-6,LEAVES:1)
Block(4,28,1,LEAVES:1)
Block(4,28,2,LEAVES:1)
Block(4,29,-6,LEAVES:1)
Block(4,29,-5,LEAVES:1)
Block(4,29,1,LEAVES:1)
Block(4,31,1,LEAVES:1)
Block(4,31,2,LEAVES:1)
Block(4,31,3,LEAVES:1)
Block(4,32,-7,LEAVES:1)
Block(4,32,-6,LEAVES:1)
Block(4,32,-5,LEAVES:1)
Block(4,32,1,LEAVES:1)
Block(4,33,-5,LEAVES:1)
Block(4,33,-1,LEAVES:1)
Block(4,33,0,LEAVES:1)
Block(4,37,-6,LEAVES:1)
Block(4,37,-5,LEAVES:1)
Block(4,37,0,LEAVES:1)
Block(4,37,1,LEAVES:1)
Block(4,38,-5,LEAVES:1)
Block(4,38,-1,LEAVES:1)
Block(4,38,0,LEAVES:1)
Block(4,41,-6,LEAVES:1)
Block(4,41,-5,LEAVES:1)
Block(4,42,-6,LEAVES:1)
Block(4,42,-5,LEAVES:1)
Block(4,42,0,LEAVES:1)
Block(4,42,1,LEAVES:1)
Block(4,43,-5,LEAVES:1)
Block(4,43,-4,LEAVES:1)
Block(4,43,-1,LEAVES:1)
Block(4,43,0,LEAVES:1)
Block(4,43,1,LEAVES:1)
Block(4,44,-1,LEAVES:1)
Block(4,45,1,LEAVES:1)
Block(4,46,-6,LEAVES:1)
Block(4,46,1,LEAVES:1)
Block(5,6,5,LEAVES:1)
Block(5,6,6,LEAVES:1)
Block(5,7,-6,LEAVES:1)
Block(5,7,-5,LEAVES:1)
Block(5,7,4,LEAVES:1)
Block(5,7,5,LEAVES:1)
Block(5,8,-4,LEAVES:1)
Block(5,8,5,LEAVES:1)
Block(5,11,-5,LEAVES:1)
Block(5,11,-4,LEAVES:1)
Block(5,12,-4,LEAVES:1)
Block(5,15,-7,LEAVES:1)
Block(5,15,0,LEAVES:1)
Block(5,15,1,LEAVES:1)
Block(5,15,4,LEAVES:1)
Block(5,16,-7,LEAVES:1)
Block(5,16,-6,LEAVES:1)
Block(5,16,-1,LEAVES:1)
Block(5,16,0,LEAVES:1)
Block(5,16,4,LEAVES:1)
Block(5,17,-6,LEAVES:1)
Block(5,21,3,LEAVES:1)
Block(5,21,4,LEAVES:1)
Block(5,22,-7,LEAVES:1)
Block(5,22,-6,LEAVES:1)
Block(5,22,-5,LEAVES:1)
Block(5,22,2,LEAVES:1)
Block(5,23,-5,LEAVES:1)
Block(5,26,3,LEAVES:1)
Block(5,26,4,LEAVES:1)
Block(5,27,-7,LEAVES:1)
Block(5,27,2,LEAVES:1)
Block(5,27,3,LEAVES:1)
Block(5,27,4,LEAVES:1)
Block(5,28,-7,LEAVES:1)
Block(5,28,-6,LEAVES:1)
Block(5,28,-5,LEAVES:1)
Block(5,28,-4,LEAVES:1)
Block(5,30,3,LEAVES:1)
Block(5,31,-7,LEAVES:1)
Block(5,31,-6,LEAVES:1)
Block(5,31,3,LEAVES:1)
Block(5,32,-6,LEAVES:1)
Block(5,36,-7,LEAVES:1)
Block(5,36,-6,LEAVES:1)
Block(5,37,-6,LEAVES:1)
Block(5,37,-5,LEAVES:1)
Block(5,37,1,LEAVES:1)
Block(5,37,2,LEAVES:1)
Block(5,38,0,LEAVES:1)
Block(5,40,1,LEAVES:1)
Block(5,41,-7,LEAVES:1)
Block(5,41,-6,LEAVES:1)
Block(5,41,1,LEAVES:1)
Block(5,41,2,LEAVES:1)
Block(5,42,-6,LEAVES:1)
Block(5,42,1,LEAVES:1)
Block(6,7,-6,LEAVES:1)
Block(6,7,-5,LEAVES:1)
Block(6,7,-4,LEAVES:1)
Block(6,10,-6,LEAVES:1)
Block(6,10,-5,LEAVES:1)
Block(6,11,-5,LEAVES:1)
Block(6,14,-8,LEAVES:1)
Block(6,14,1,LEAVES:1)
Block(6,14,2,LEAVES:1)
Block(6,15,-8,LEAVES:1)
Block(6,15,-7,LEAVES:1)
Block(6,15,1,LEAVES:1)
Block(6,20,4,LEAVES:1)
Block(6,21,-8,LEAVES:1)
Block(6,21,-7,LEAVES:1)
Block(6,21,4,LEAVES:1)
Block(6,22,-7,LEAVES:1)
Block(6,22,-6,LEAVES:1)
Block(6,26,-7,LEAVES:1)
Block(6,27,-7,LEAVES:1)
Block(6,30,-8,LEAVES:1)
Block(6,31,-8,LEAVES:1)
Block(6,31,-7,LEAVES:1)
Block(6,34,-8,LEAVES:1)
Block(6,35,-8,LEAVES:1)
Block(6,35,-7,LEAVES:1)
Block(6,35,2,LEAVES:1)
Block(6,36,-7,LEAVES:1)
Block(6,36,-6,LEAVES:1)
Block(6,36,2,LEAVES:1)
Block(6,37,1,LEAVES:1)
Block(6,40,-7,LEAVES:1)
Block(6,41,-7,LEAVES:1)
Block(6,41,-6,LEAVES:1)
Block(7,6,-7,LEAVES:1)
Block(7,6,-6,LEAVES:1)
Block(7,7,-6,LEAVES:1)
Block(7,7,-5,LEAVES:1)
Block(7,9,-7,LEAVES:1)
Block(7,9,-6,LEAVES:1)
Block(7,10,-6,LEAVES:1)
Block(7,20,-8,LEAVES:1)
Block(7,21,-8,LEAVES:1)
Block(8,5,-7,LEAVES:1)
Block(8,6,-7,LEAVES:1)
Block(8,8,-7,LEAVES:1)
Block(8,9,-7,LEAVES:1)
Block(9,8,-7,LEAVES:1)


#######################################################################
# +-----------------------------------------------------------------+ #
# |                             Entities                            | #
# +-----------------------------------------------------------------+ #
#######################################################################

# Entity() spawns an entity instead of a block. The entity is spawned only once when the BO3 is spawned.
# Entities are persistent by default so they don't de-spawn when no player is near, they are only unloaded.
# Usage: Entity(x,y,z,mobName,groupSize,NameTagOrNBTFileName) or Entity(x,y,z,mobName,groupSize)
# Use /tc entities or /otg entities to get a list of entities that can be used as mobName, this includes entities added by other mods.
# NameTagOrNBTFileName can be either a nametag for the mob or an nbt file (such as mymobinfo.nbt or mymobinfo.txt).
# When using a text file you can use the same mob spawning parameters used with the /summon command to equip the
# entity and give it custom attributes etc. You can copy the DATA part of a summon command including surrounding
# curly braces to a .txt file, for instance for: "/summon Skeleton x y z {DATA}"

#######################################################################
# +-----------------------------------------------------------------+ #
# |                            BO3 checks                           | #
# +-----------------------------------------------------------------+ #
#######################################################################

# Require a condition at a certain location in order for the BO3 to be spawned.
# BlockCheck(x,y,z,BlockName[,BlockName[,...]]) - one of the blocks must be at the location
# BlockCheckNot(x,y,z,BlockName[,BlockName[,...]]) - all the blocks must not be at the location
# LightCheck(x,y,z,minLightLevel,maxLightLevel) - light must be between min and max (inclusive)

# You can use "Solid" as a BlockName for matching all solid blocks or "All" to match all blocks that aren't air.

# Examples:
#   BlockCheck(0,-1,0,GRASS,DIRT)  Require grass or dirt just below the object
#   BlockCheck(0,-1,0,Solid)       Require any solid block just below the object
#   BlockCheck(0,-1,0,WOOL)        Require any type of wool just below the object
#   BlockCheck(0,-1,0,WOOL:0)      Require white wool just below the object
#   BlockCheckNot(0,-1,0,WOOL:0)   Require that there is no white wool below the object
#   LightCheck(0,0,0,0,LEAVES:1)          Require almost complete darkness just below the object

