#######################################################################
# +-----------------------------------------------------------------+ #
# |                            BO3 object                           | #
# +-----------------------------------------------------------------+ #
#######################################################################

# The descriptions in this file are accurate only for TerrainControl and OTG.
# For MCW and OTG+ these descriptions are only accurate if the BO3 is used as a CustomObject.
# MCW and OTG+ completely reimplemented CustomStructure, check the MCW/OTG+ documentation for more information.

# This is the config file of a custom object.
# If you add this object correctly to your BiomeConfigs, it will spawn in the world.

# This is the creator of this BO3 object
Author: Unknown

# A short description of this BO3 object
Description: This BO3 was converted from a schematic using OTGEdit. The author and description information of the schematic could not be found. If you know who the author of the schematic is then please add this information.

# The BO3 version, don't change this! It can be used by external applications to do a version check.
Version: 3

# The settings mode, WriteAll, WriteWithoutComments or WriteDisable. See WorldConfig.
SettingsMode: WriteDisable

#######################################################################
# +-----------------------------------------------------------------+ #
# |                          Main settings                          | #
# +-----------------------------------------------------------------+ #
#######################################################################

# This needs to be set to true to spawn the object in the Tree and Sapling resources.
Tree: true

# The frequency of the BO3 from 1 to 200. Tries this many times to spawn this BO3 when using the CustomObject(...) resource.
# Ignored by Tree(..), Sapling(..) and CustomStructure(..)
Frequency: 1

# The rarity of the BO3 from 0 to 100. Each spawn attempt has rarity% chance to succeed when using the CustomObject(...) resource.
# Ignored by Tree(..), Sapling(..) and CustomStructure(..)
Rarity: 100.0

# If you set this to true, the BO3 will be placed with a random rotation.
RotateRandomly: true

# The spawn height of the BO3 - randomY, highestBlock or highestSolidBlock.
SpawnHeight: highestSolidBlock

SpawnHeightOffset: -5

# The height limits for the BO3.
MinHeight: 55

MaxHeight: 66

# Objects can have other objects attached to it: branches. Branches can also
# have branches attached to it, which can also have branches, etc. This is the
# maximum branch depth for this objects.
MaxBranchDepth: 10

# The style of extrusion you wish to use - BottomDown, TopUp, None (Default)
ExtrudeMode: BottomDown

# The blocks to extrude your BO3 through
ExtrudeThroughBlocks: AIR,STATIONARY_WATER

# When spawned with the UseWorld keyword, this BO3 should NOT spawn in the following biomes.
# If you writer.write the BO3 name directly in the BiomeConfigs, this will be ignored.
ExcludedBiomes: All

# To optimise this BO3 for faster loading times you can use Notepad++ to find/replace comments and abbreviate things.
# Notepad++ find/replace with regex:
# Find: ^[#;].* replace to nothing removes all lines starting with # 
# Find: ^\s*$ replace to nothing removes most empty lines 
# Notepad++ find/replace without regex:
# *Warning: This will only work for OTG 1.10.2 v21 / OTG 1.11.2 v6 or higher. B( is not recognised by lower versions.
# Find: Block( replace to B(

#######################################################################
# +-----------------------------------------------------------------+ #
# |                      Source block settings                      | #
# +-----------------------------------------------------------------+ #
#######################################################################

# The block(s) the BO3 should spawn in.
SourceBlocks: STONE:1,STONE:3,STONE:5,DIRT:1,DIRT,SAND,GRASS,DIRT:2,STATIONARY_WATER,HARD_CLAY,STAINED_CLAY,CLAY,SANDSTONE,SAND:1,AIR,STONE,GRAVEL,LONG_GRASS,LONG_GRASS:1,LONG_GRASS:2,DEAD_BUSH,YELLOW_FLOWER,RED_ROSE,BROWN_MUSHROOM,RED_MUSHROOM

# The maximum percentage of the BO3 that can be outside the SourceBlock.
# The BO3 won't be placed on a location with more blocks outside the SourceBlock than this percentage.
MaxPercentageOutsideSourceBlock: 0

# What to do when a block is about to be placed outside the SourceBlock? (dontPlace, placeAnyway)
OutsideSourceBlock: placeAnyway

#######################################################################
# +-----------------------------------------------------------------+ #
# |                              Blocks                             | #
# +-----------------------------------------------------------------+ #
#######################################################################

# All the blocks used in the BO3 are listed here. Possible blocks:
# Block(x,y,z,id[.data][,nbtfile.nbt) or B(x,y,z,id[.data][,nbtfile.nbt)
# RandomBlock(x,y,z,id[:data][,nbtfile.nbt],chance[,id[:data][,nbtfile.nbt],chance[,...]])
# So RandomBlock(0,0,0,CHEST,chest.nbt,50,CHEST,anotherchest.nbt,100) will spawn a chest at
# the BO3 origin, and give it a 50% chance to have the contents of chest.nbt, or, if that
# fails, a 100% percent chance to have the contents of anotherchest.nbt.

Block(-14,37,-2,LEAVES_2:0)
Block(-14,37,0,LEAVES_2:0)
Block(-14,37,2,LEAVES_2:0)
Block(-14,38,-3,LEAVES_2:0)
Block(-13,35,4,LEAVES_2:0)
Block(-13,36,-4,LEAVES_2:0)
Block(-13,36,-1,LEAVES_2:0)
Block(-13,36,2,LEAVES_2:0)
Block(-13,37,-3,LEAVES_2:0)
Block(-13,37,0,LEAVES_2:0)
Block(-13,37,1,LEAVES_2:0)
Block(-13,37,3,LEAVES_2:0)
Block(-13,38,-4,LEAVES_2:0)
Block(-13,38,-2,LEAVES_2:0)
Block(-13,38,0,LEAVES_2:0)
Block(-13,38,2,LEAVES_2:0)
Block(-13,39,-3,LEAVES_2:0)
Block(-12,34,6,LEAVES_2:0)
Block(-12,35,1,LEAVES_2:0)
Block(-12,35,3,LEAVES_2:0)
Block(-12,35,5,LEAVES_2:0)
Block(-12,35,8,LEAVES_2:0)
Block(-12,36,4,LEAVES_2:0)
Block(-12,37,-4,LEAVES_2:0)
Block(-12,37,-3,LEAVES_2:0)
Block(-12,37,-2,LEAVES_2:0)
Block(-12,37,-1,LEAVES_2:0)
Block(-12,37,0,LEAVES_2:0)
Block(-12,37,1,LEAVES_2:0)
Block(-12,37,2,LEAVES_2:0)
Block(-12,38,-4,LEAVES_2:0)
Block(-12,38,-3,162:12)
Block(-12,38,-2,LEAVES_2:0)
Block(-12,38,-1,LEAVES_2:0)
Block(-12,38,1,LEAVES_2:0)
Block(-12,38,2,162:12)
Block(-12,38,3,LEAVES_2:0)
Block(-12,39,-3,LEAVES_2:0)
Block(-12,39,-1,LEAVES_2:0)
Block(-12,39,2,LEAVES_2:0)
Block(-11,-6,4,3:1)
Block(-11,-6,6,162:12)
Block(-11,34,9,LEAVES_2:0)
Block(-11,35,7,LEAVES_2:0)
Block(-11,35,10,LEAVES_2:0)
Block(-11,36,-5,LEAVES_2:0)
Block(-11,36,-2,LEAVES_2:0)
Block(-11,36,1,LEAVES_2:0)
Block(-11,36,3,LEAVES_2:0)
Block(-11,36,4,162:12)
Block(-11,36,5,LEAVES_2:0)
Block(-11,36,9,LEAVES_2:0)
Block(-11,37,-6,LEAVES_2:0)
Block(-11,37,-5,LEAVES_2:0)
Block(-11,37,-4,LEAVES_2:0)
Block(-11,37,-3,LEAVES_2:0)
Block(-11,37,-2,LEAVES_2:0)
Block(-11,37,-1,LEAVES_2:0)
Block(-11,37,0,LEAVES_2:0)
Block(-11,37,1,LEAVES_2:0)
Block(-11,37,2,LEAVES_2:0)
Block(-11,37,4,LEAVES_2:0)
Block(-11,37,6,LEAVES_2:0)
Block(-11,38,-7,LEAVES_2:0)
Block(-11,38,-3,LEAVES_2:0)
Block(-11,38,-2,162:12)
Block(-11,38,-1,LEAVES_2:0)
Block(-11,38,0,LEAVES_2:0)
Block(-11,38,1,162:12)
Block(-11,38,3,LEAVES_2:0)
Block(-11,39,-2,LEAVES_2:0)
Block(-11,39,1,LEAVES_2:0)
Block(-11,39,2,LEAVES_2:0)
Block(-11,39,4,LEAVES_2:0)
Block(-11,40,3,LEAVES_2:0)
Block(-10,-6,-5,3:1)
Block(-10,-6,-3,3:1)
Block(-10,-6,0,162:12)
Block(-10,-6,2,3:1)
Block(-10,-6,3,162:12)
Block(-10,-6,4,162:12)
Block(-10,-6,5,3:1)
Block(-10,-6,6,3:1)
Block(-10,-6,7,3:1)
Block(-10,-6,8,3:1)
Block(-10,-6,9,3:1)
Block(-10,-5,0,162:12)
Block(-10,-5,2,3:1)
Block(-10,-5,3,3:1)
Block(-10,-5,4,3:1)
Block(-10,-5,5,162:12)
Block(-10,-5,6,3:1)
Block(-10,-5,8,3:1)
Block(-10,-4,3,3:1)
Block(-10,-4,4,3:1)
Block(-10,-4,5,162:12)
Block(-10,-3,3,3:1)
Block(-10,34,8,LEAVES_2:0)
Block(-10,35,1,LEAVES_2:0)
Block(-10,35,4,LEAVES_2:0)
Block(-10,35,9,LEAVES_2:0)
Block(-10,36,-3,LEAVES_2:0)
Block(-10,36,-2,LEAVES_2:0)
Block(-10,36,0,LEAVES_2:0)
Block(-10,36,2,LEAVES_2:0)
Block(-10,36,3,LEAVES_2:0)
Block(-10,36,4,162:12)
Block(-10,36,6,LEAVES_2:0)
Block(-10,36,7,LEAVES_2:0)
Block(-10,36,8,LEAVES_2:0)
Block(-10,36,10,LEAVES_2:0)
Block(-10,37,-7,LEAVES_2:0)
Block(-10,37,-4,LEAVES_2:0)
Block(-10,37,-2,162:12)
Block(-10,37,-1,LEAVES_2:0)
Block(-10,37,0,162:12)
Block(-10,37,1,LEAVES_2:0)
Block(-10,37,4,LEAVES_2:0)
Block(-10,37,5,LEAVES_2:0)
Block(-10,37,9,LEAVES_2:0)
Block(-10,38,-8,LEAVES_2:0)
Block(-10,38,-6,LEAVES_2:0)
Block(-10,38,-3,LEAVES_2:0)
Block(-10,38,-2,LEAVES_2:0)
Block(-10,38,0,LEAVES_2:0)
Block(-10,38,1,LEAVES_2:0)
Block(-10,38,2,LEAVES_2:0)
Block(-10,39,-7,LEAVES_2:0)
Block(-10,39,0,LEAVES_2:0)
Block(-10,39,3,LEAVES_2:0)
Block(-10,40,2,LEAVES_2:0)
Block(-10,40,4,LEAVES_2:0)
Block(-10,41,1,LEAVES_2:0)
Block(-10,41,3,LEAVES_2:0)
Block(-10,41,5,LEAVES_2:0)
Block(-9,-6,-7,3:1)
Block(-9,-6,-6,3:1)
Block(-9,-6,-5,3:1)
Block(-9,-6,-4,3:1)
Block(-9,-6,-3,3:1)
Block(-9,-6,-2,162:12)
Block(-9,-6,-1,3:1)
Block(-9,-6,0,3:1)
Block(-9,-6,1,3:1)
Block(-9,-6,2,162:12)
Block(-9,-6,3,3:1)
Block(-9,-6,4,162:12)
Block(-9,-6,5,3:1)
Block(-9,-6,6,162:12)
Block(-9,-6,7,3:1)
Block(-9,-6,8,3:1)
Block(-9,-6,9,3:1)
Block(-9,-6,10,3:1)
Block(-9,-5,-6,3:1)
Block(-9,-5,-5,3:1)
Block(-9,-5,-4,3:1)
Block(-9,-5,-3,3:1)
Block(-9,-5,-2,162:12)
Block(-9,-5,0,3:1)
Block(-9,-5,1,162:12)
Block(-9,-5,2,3:1)
Block(-9,-5,3,162:12)
Block(-9,-5,4,3:1)
Block(-9,-5,5,3:1)
Block(-9,-5,6,162:12)
Block(-9,-5,7,3:1)
Block(-9,-5,8,3:1)
Block(-9,-5,9,3:1)
Block(-9,-5,10,3:1)
Block(-9,-4,-5,3:1)
Block(-9,-4,1,162:12)
Block(-9,-4,2,3:1)
Block(-9,-4,3,162:12)
Block(-9,-4,4,3:1)
Block(-9,-4,5,3:1)
Block(-9,-4,6,3:1)
Block(-9,-4,7,3:1)
Block(-9,-4,8,3:1)
Block(-9,-3,1,3:1)
Block(-9,-3,2,3:1)
Block(-9,-3,3,3:1)
Block(-9,-3,4,162:12)
Block(-9,-3,5,3:1)
Block(-9,-3,6,3:1)
Block(-9,-2,4,162:12)
Block(-9,34,10,LEAVES_2:0)
Block(-9,35,-2,LEAVES_2:0)
Block(-9,35,0,LEAVES_2:0)
Block(-9,35,5,LEAVES_2:0)
Block(-9,35,6,LEAVES_2:0)
Block(-9,35,7,LEAVES_2:0)
Block(-9,35,9,LEAVES_2:0)
Block(-9,35,11,LEAVES_2:0)
Block(-9,36,-4,LEAVES_2:0)
Block(-9,36,-2,LEAVES_2:0)
Block(-9,36,-1,LEAVES_2:0)
Block(-9,36,1,LEAVES_2:0)
Block(-9,36,3,LEAVES_2:0)
Block(-9,36,4,162:12)
Block(-9,36,5,LEAVES_2:0)
Block(-9,36,8,LEAVES_2:0)
Block(-9,36,9,162:12)
Block(-9,36,10,LEAVES_2:0)
Block(-9,37,-8,LEAVES_2:0)
Block(-9,37,-7,LEAVES_2:0)
Block(-9,37,-6,LEAVES_2:0)
Block(-9,37,-5,LEAVES_2:0)
Block(-9,37,-3,LEAVES_2:0)
Block(-9,37,-2,LEAVES_2:0)
Block(-9,37,-1,162:12)
Block(-9,37,0,162:12)
Block(-9,37,1,LEAVES_2:0)
Block(-9,37,2,LEAVES_2:0)
Block(-9,37,4,LEAVES_2:0)
Block(-9,37,7,LEAVES_2:0)
Block(-9,37,9,LEAVES_2:0)
Block(-9,38,-9,LEAVES_2:0)
Block(-9,38,-7,162:12)
Block(-9,38,-6,LEAVES_2:0)
Block(-9,38,-1,LEAVES_2:0)
Block(-9,38,0,LEAVES_2:0)
Block(-9,38,4,LEAVES_2:0)
Block(-9,38,6,LEAVES_2:0)
Block(-9,39,-8,LEAVES_2:0)
Block(-9,39,-7,LEAVES_2:0)
Block(-9,39,5,LEAVES_2:0)
Block(-9,40,-1,LEAVES_2:0)
Block(-9,40,0,LEAVES_2:0)
Block(-9,40,2,LEAVES_2:0)
Block(-9,40,3,162:12)
Block(-9,40,5,LEAVES_2:0)
Block(-9,41,2,LEAVES_2:0)
Block(-9,41,4,LEAVES_2:0)
Block(-9,42,3,LEAVES_2:0)
Block(-8,-6,-8,3:1)
Block(-8,-6,-7,3:1)
Block(-8,-6,-6,3:1)
Block(-8,-6,-5,3:1)
Block(-8,-6,-4,3:1)
Block(-8,-6,-3,3:1)
Block(-8,-6,-2,3:1)
Block(-8,-6,-1,3:1)
Block(-8,-6,0,3:1)
Block(-8,-6,1,3:1)
Block(-8,-6,2,3:1)
Block(-8,-6,3,3:1)
Block(-8,-6,4,3:1)
Block(-8,-6,5,162:12)
Block(-8,-6,6,162:12)
Block(-8,-6,7,3:1)
Block(-8,-6,8,162:12)
Block(-8,-6,9,162:12)
Block(-8,-6,10,3:1)
Block(-8,-6,11,3:1)
Block(-8,-5,-6,3:1)
Block(-8,-5,-5,3:1)
Block(-8,-5,-4,3:1)
Block(-8,-5,-3,3:1)
Block(-8,-5,-2,3:1)
Block(-8,-5,-1,3:1)
Block(-8,-5,0,3:1)
Block(-8,-5,1,3:1)
Block(-8,-5,2,3:1)
Block(-8,-5,3,3:1)
Block(-8,-5,4,3:1)
Block(-8,-5,5,162:12)
Block(-8,-5,6,3:1)
Block(-8,-5,7,3:1)
Block(-8,-5,8,162:12)
Block(-8,-5,9,3:1)
Block(-8,-5,10,3:1)
Block(-8,-5,11,3:1)
Block(-8,-4,-5,3:1)
Block(-8,-4,-4,3:1)
Block(-8,-4,-3,3:1)
Block(-8,-4,-2,3:1)
Block(-8,-4,-1,162:12)
Block(-8,-4,1,3:1)
Block(-8,-4,2,162:12)
Block(-8,-4,3,3:1)
Block(-8,-4,4,3:1)
Block(-8,-4,5,3:1)
Block(-8,-4,6,162:12)
Block(-8,-4,7,3:1)
Block(-8,-4,8,3:1)
Block(-8,-4,9,3:1)
Block(-8,-4,10,3:1)
Block(-8,-3,1,162:12)
Block(-8,-3,2,3:1)
Block(-8,-3,3,162:12)
Block(-8,-3,4,3:1)
Block(-8,-3,5,3:1)
Block(-8,-2,0,162:12)
Block(-8,-2,3,162:12)
Block(-8,-2,4,3:1)
Block(-8,-2,5,3:1)
Block(-8,-1,4,162:12)
Block(-8,0,4,162:12)
Block(-8,34,5,LEAVES_2:0)
Block(-8,34,7,LEAVES_2:0)
Block(-8,34,12,LEAVES_2:0)
Block(-8,35,1,LEAVES_2:0)
Block(-8,35,4,LEAVES_2:0)
Block(-8,35,6,162:12)
Block(-8,35,8,LEAVES_2:0)
Block(-8,35,9,LEAVES_2:0)
Block(-8,36,-8,LEAVES_2:0)
Block(-8,36,-5,LEAVES_2:0)
Block(-8,36,-2,LEAVES_2:0)
Block(-8,36,-1,LEAVES_2:0)
Block(-8,36,0,162:12)
Block(-8,36,2,LEAVES_2:0)
Block(-8,36,4,LEAVES_2:0)
Block(-8,36,5,162:12)
Block(-8,36,6,LEAVES_2:0)
Block(-8,36,7,162:12)
Block(-8,36,8,162:12)
Block(-8,36,10,LEAVES_2:0)
Block(-8,37,-9,LEAVES_2:0)
Block(-8,37,-7,LEAVES_2:0)
Block(-8,37,-6,LEAVES_2:0)
Block(-8,37,-4,LEAVES_2:0)
Block(-8,37,-3,LEAVES_2:0)
Block(-8,37,0,LEAVES_2:0)
Block(-8,37,1,LEAVES_2:0)
Block(-8,37,2,LEAVES_2:0)
Block(-8,37,3,LEAVES_2:0)
Block(-8,37,4,LEAVES_2:0)
Block(-8,37,5,LEAVES_2:0)
Block(-8,37,7,LEAVES_2:0)
Block(-8,37,8,LEAVES_2:0)
Block(-8,37,9,LEAVES_2:0)
Block(-8,38,-8,LEAVES_2:0)
Block(-8,38,-7,LEAVES_2:0)
Block(-8,38,-6,162:12)
Block(-8,38,-5,LEAVES_2:0)
Block(-8,38,4,LEAVES_2:0)
Block(-8,38,7,LEAVES_2:0)
Block(-8,39,-6,LEAVES_2:0)
Block(-8,39,-2,LEAVES_2:0)
Block(-8,39,-1,LEAVES_2:0)
Block(-8,39,3,LEAVES_2:0)
Block(-8,39,4,LEAVES_2:0)
Block(-8,40,-1,LEAVES_2:0)
Block(-8,40,1,LEAVES_2:0)
Block(-8,40,2,LEAVES_2:0)
Block(-8,40,3,162:12)
Block(-8,40,4,LEAVES_2:0)
Block(-8,40,6,LEAVES_2:0)
Block(-8,41,-4,LEAVES_2:0)
Block(-8,41,0,LEAVES_2:0)
Block(-8,41,3,LEAVES_2:0)
Block(-7,-6,-9,3:1)
Block(-7,-6,-8,3:1)
Block(-7,-6,-7,3:1)
Block(-7,-6,-6,3:1)
Block(-7,-6,-5,3:1)
Block(-7,-6,-4,3:1)
Block(-7,-6,-3,162:12)
Block(-7,-6,-2,3:1)
Block(-7,-6,-1,162:12)
Block(-7,-6,0,162:12)
Block(-7,-6,1,3:1)
Block(-7,-6,2,3:1)
Block(-7,-6,3,3:1)
Block(-7,-6,4,162:12)
Block(-7,-6,5,3:1)
Block(-7,-6,6,3:1)
Block(-7,-6,7,162:12)
Block(-7,-6,8,3:1)
Block(-7,-6,9,3:1)
Block(-7,-6,10,3:1)
Block(-7,-6,11,3:1)
Block(-7,-5,-8,3:1)
Block(-7,-5,-7,3:1)
Block(-7,-5,-6,3:1)
Block(-7,-5,-5,3:1)
Block(-7,-5,-4,3:1)
Block(-7,-5,-3,3:1)
Block(-7,-5,-2,3:1)
Block(-7,-5,-1,3:1)
Block(-7,-5,0,3:1)
Block(-7,-5,1,3:1)
Block(-7,-5,2,3:1)
Block(-7,-5,3,162:12)
Block(-7,-5,4,3:1)
Block(-7,-5,5,3:1)
Block(-7,-5,6,3:1)
Block(-7,-5,7,3:1)
Block(-7,-5,8,3:1)
Block(-7,-5,9,3:1)
Block(-7,-5,10,3:1)
Block(-7,-5,11,3:1)
Block(-7,-4,-6,3:1)
Block(-7,-4,-5,3:1)
Block(-7,-4,-4,3:1)
Block(-7,-4,-3,3:1)
Block(-7,-4,-2,3:1)
Block(-7,-4,-1,3:1)
Block(-7,-4,0,3:1)
Block(-7,-4,1,162:12)
Block(-7,-4,2,3:1)
Block(-7,-4,3,3:1)
Block(-7,-4,4,3:1)
Block(-7,-4,5,3:1)
Block(-7,-4,6,3:1)
Block(-7,-4,7,3:1)
Block(-7,-4,8,162:12)
Block(-7,-4,9,3:1)
Block(-7,-4,10,3:1)
Block(-7,-3,-3,3:1)
Block(-7,-3,-2,3:1)
Block(-7,-3,-1,162:12)
Block(-7,-3,0,3:1)
Block(-7,-3,1,3:1)
Block(-7,-3,2,3:1)
Block(-7,-3,3,3:1)
Block(-7,-3,4,3:1)
Block(-7,-3,5,162:12)
Block(-7,-3,6,162:12)
Block(-7,-3,7,3:1)
Block(-7,-3,8,3:1)
Block(-7,-2,-1,162:12)
Block(-7,-2,2,3:1)
Block(-7,-2,3,3:1)
Block(-7,-2,4,162:12)
Block(-7,-2,5,3:1)
Block(-7,-2,7,162:12)
Block(-7,-1,0,162:12)
Block(-7,-1,4,162:12)
Block(-7,-1,7,162:12)
Block(-7,0,0,162:12)
Block(-7,0,4,162:12)
Block(-7,0,7,162:12)
Block(-7,1,4,162:12)
Block(-7,30,-4,LEAVES_2:0)
Block(-7,34,-4,LEAVES_2:0)
Block(-7,34,-2,LEAVES_2:0)
Block(-7,34,0,LEAVES_2:0)
Block(-7,34,5,LEAVES_2:0)
Block(-7,34,10,LEAVES_2:0)
Block(-7,35,-3,LEAVES_2:0)
Block(-7,35,-1,LEAVES_2:0)
Block(-7,35,3,LEAVES_2:0)
Block(-7,35,4,LEAVES_2:0)
Block(-7,35,5,162:12)
Block(-7,35,6,LEAVES_2:0)
Block(-7,35,7,LEAVES_2:0)
Block(-7,35,11,LEAVES_2:0)
Block(-7,36,-6,LEAVES_2:0)
Block(-7,36,-5,LEAVES_2:0)
Block(-7,36,-2,LEAVES_2:0)
Block(-7,36,0,162:12)
Block(-7,36,1,LEAVES_2:0)
Block(-7,36,2,LEAVES_2:0)
Block(-7,36,3,LEAVES_2:0)
Block(-7,36,5,LEAVES_2:0)
Block(-7,36,7,LEAVES_2:0)
Block(-7,36,8,LEAVES_2:0)
Block(-7,36,9,LEAVES_2:0)
Block(-7,37,-10,LEAVES_2:0)
Block(-7,37,-7,LEAVES_2:0)
Block(-7,37,-5,162:12)
Block(-7,37,-4,LEAVES_2:0)
Block(-7,37,-1,LEAVES_2:0)
Block(-7,37,0,LEAVES_2:0)
Block(-7,37,2,LEAVES_2:0)
Block(-7,37,3,LEAVES_2:0)
Block(-7,37,4,LEAVES_2:0)
Block(-7,38,-9,LEAVES_2:0)
Block(-7,38,-6,LEAVES_2:0)
Block(-7,38,-5,LEAVES_2:0)
Block(-7,38,1,LEAVES_2:0)
Block(-7,38,3,LEAVES_2:0)
Block(-7,38,4,LEAVES_2:0)
Block(-7,38,8,LEAVES_2:0)
Block(-7,39,-7,LEAVES_2:0)
Block(-7,39,-3,LEAVES_2:0)
Block(-7,39,-1,162:12)
Block(-7,39,0,LEAVES_2:0)
Block(-7,39,4,162:12)
Block(-7,39,5,LEAVES_2:0)
Block(-7,39,6,LEAVES_2:0)
Block(-7,39,7,LEAVES_2:0)
Block(-7,40,-2,LEAVES_2:0)
Block(-7,40,-1,LEAVES_2:0)
Block(-7,40,0,162:12)
Block(-7,40,2,LEAVES_2:0)
Block(-7,40,3,LEAVES_2:0)
Block(-7,40,4,LEAVES_2:0)
Block(-7,41,-5,LEAVES_2:0)
Block(-7,41,-3,LEAVES_2:0)
Block(-7,41,0,LEAVES_2:0)
Block(-7,41,1,LEAVES_2:0)
Block(-7,42,-4,LEAVES_2:0)
Block(-7,42,4,LEAVES_2:0)
Block(-6,-6,-10,3:1)
Block(-6,-6,-9,162:12)
Block(-6,-6,-8,3:1)
Block(-6,-6,-7,162:12)
Block(-6,-6,-6,3:1)
Block(-6,-6,-5,3:1)
Block(-6,-6,-4,3:1)
Block(-6,-6,-3,3:1)
Block(-6,-6,-2,3:1)
Block(-6,-6,-1,3:1)
Block(-6,-6,0,3:1)
Block(-6,-6,1,3:1)
Block(-6,-6,2,3:1)
Block(-6,-6,3,3:1)
Block(-6,-6,4,3:1)
Block(-6,-6,5,162:12)
Block(-6,-6,6,3:1)
Block(-6,-6,7,3:1)
Block(-6,-6,8,3:1)
Block(-6,-6,9,3:1)
Block(-6,-6,10,3:1)
Block(-6,-6,11,3:1)
Block(-6,-5,-10,3:1)
Block(-6,-5,-9,3:1)
Block(-6,-5,-8,3:1)
Block(-6,-5,-7,162:12)
Block(-6,-5,-6,3:1)
Block(-6,-5,-5,3:1)
Block(-6,-5,-4,3:1)
Block(-6,-5,-3,162:12)
Block(-6,-5,-2,3:1)
Block(-6,-5,-1,3:1)
Block(-6,-5,0,3:1)
Block(-6,-5,1,3:1)
Block(-6,-5,2,3:1)
Block(-6,-5,3,3:1)
Block(-6,-5,4,3:1)
Block(-6,-5,5,162:12)
Block(-6,-5,6,3:1)
Block(-6,-5,7,3:1)
Block(-6,-5,8,3:1)
Block(-6,-5,9,3:1)
Block(-6,-5,10,3:1)
Block(-6,-5,11,3:1)
Block(-6,-4,-9,3:1)
Block(-6,-4,-8,3:1)
Block(-6,-4,-7,3:1)
Block(-6,-4,-6,3:1)
Block(-6,-4,-5,3:1)
Block(-6,-4,-4,3:1)
Block(-6,-4,-3,3:1)
Block(-6,-4,-2,3:1)
Block(-6,-4,-1,3:1)
Block(-6,-4,0,3:1)
Block(-6,-4,1,162:12)
Block(-6,-4,2,3:1)
Block(-6,-4,3,162:12)
Block(-6,-4,4,3:1)
Block(-6,-4,5,3:1)
Block(-6,-4,6,162:12)
Block(-6,-4,7,3:1)
Block(-6,-4,8,162:12)
Block(-6,-4,9,3:1)
Block(-6,-4,10,3:1)
Block(-6,-3,-6,3:1)
Block(-6,-3,-5,3:1)
Block(-6,-3,-4,3:1)
Block(-6,-3,-3,3:1)
Block(-6,-3,-2,3:1)
Block(-6,-3,-1,3:1)
Block(-6,-3,0,3:1)
Block(-6,-3,1,3:1)
Block(-6,-3,2,162:12)
Block(-6,-3,3,3:1)
Block(-6,-3,4,3:1)
Block(-6,-3,5,3:1)
Block(-6,-3,6,3:1)
Block(-6,-3,8,162:12)
Block(-6,-2,-2,3:1)
Block(-6,-2,-1,3:1)
Block(-6,-2,0,3:1)
Block(-6,-2,1,3:1)
Block(-6,-2,2,3:1)
Block(-6,-2,3,3:1)
Block(-6,-2,4,3:1)
Block(-6,-2,5,3:1)
Block(-6,-2,7,162:12)
Block(-6,-1,7,162:12)
Block(-6,0,1,162:12)
Block(-6,0,6,162:12)
Block(-6,1,3,162:12)
Block(-6,1,6,162:12)
Block(-6,2,5,162:12)
Block(-6,30,-6,LEAVES_2:0)
Block(-6,30,-3,LEAVES_2:0)
Block(-6,31,-5,LEAVES_2:0)
Block(-6,31,-4,LEAVES_2:0)
Block(-6,34,3,LEAVES_2:0)
Block(-6,34,8,LEAVES_2:0)
Block(-6,34,11,LEAVES_2:0)
Block(-6,35,-4,LEAVES_2:0)
Block(-6,35,-3,LEAVES_2:0)
Block(-6,35,-2,162:12)
Block(-6,35,-1,LEAVES_2:0)
Block(-6,35,0,LEAVES_2:0)
Block(-6,35,1,LEAVES_2:0)
Block(-6,35,2,LEAVES_2:0)
Block(-6,35,4,162:12)
Block(-6,35,5,LEAVES_2:0)
Block(-6,35,7,LEAVES_2:0)
Block(-6,35,9,LEAVES_2:0)
Block(-6,35,13,LEAVES_2:0)
Block(-6,36,-3,LEAVES_2:0)
Block(-6,36,-2,LEAVES_2:0)
Block(-6,36,-1,LEAVES_2:0)
Block(-6,36,0,LEAVES_2:0)
Block(-6,36,1,162:12)
Block(-6,36,2,LEAVES_2:0)
Block(-6,36,4,LEAVES_2:0)
Block(-6,36,6,LEAVES_2:0)
Block(-6,36,10,LEAVES_2:0)
Block(-6,36,11,LEAVES_2:0)
Block(-6,36,12,LEAVES_2:0)
Block(-6,37,-6,LEAVES_2:0)
Block(-6,37,-5,LEAVES_2:0)
Block(-6,37,-4,162:12)
Block(-6,37,-3,LEAVES_2:0)
Block(-6,37,1,LEAVES_2:0)
Block(-6,37,3,LEAVES_2:0)
Block(-6,37,7,LEAVES_2:0)
Block(-6,37,8,LEAVES_2:0)
Block(-6,38,-10,LEAVES_2:0)
Block(-6,38,-7,LEAVES_2:0)
Block(-6,38,-5,LEAVES_2:0)
Block(-6,38,-4,LEAVES_2:0)
Block(-6,38,4,162:12)
Block(-6,38,5,LEAVES_2:0)
Block(-6,38,7,LEAVES_2:0)
Block(-6,39,-8,LEAVES_2:0)
Block(-6,39,-7,LEAVES_2:0)
Block(-6,39,-6,LEAVES_2:0)
Block(-6,39,-4,LEAVES_2:0)
Block(-6,39,-3,LEAVES_2:0)
Block(-6,39,-2,162:12)
Block(-6,39,-1,LEAVES_2:0)
Block(-6,39,2,LEAVES_2:0)
Block(-6,39,3,LEAVES_2:0)
Block(-6,39,4,LEAVES_2:0)
Block(-6,39,5,162:12)
Block(-6,39,6,162:12)
Block(-6,39,8,LEAVES_2:0)
Block(-6,40,-4,LEAVES_2:0)
Block(-6,40,-2,LEAVES_2:0)
Block(-6,40,0,LEAVES_2:0)
Block(-6,40,1,LEAVES_2:0)
Block(-6,40,3,LEAVES_2:0)
Block(-6,40,4,LEAVES_2:0)
Block(-6,40,5,LEAVES_2:0)
Block(-6,40,6,LEAVES_2:0)
Block(-6,40,7,LEAVES_2:0)
Block(-6,41,-6,LEAVES_2:0)
Block(-6,41,-5,LEAVES_2:0)
Block(-6,41,-3,LEAVES_2:0)
Block(-6,41,2,LEAVES_2:0)
Block(-6,41,3,LEAVES_2:0)
Block(-6,41,4,LEAVES_2:0)
Block(-6,42,-5,LEAVES_2:0)
Block(-6,42,-3,LEAVES_2:0)
Block(-6,42,-1,LEAVES_2:0)
Block(-6,42,3,LEAVES_2:0)
Block(-6,42,5,LEAVES_2:0)
Block(-6,43,-4,LEAVES_2:0)
Block(-6,43,4,LEAVES_2:0)
Block(-5,-6,-11,3:1)
Block(-5,-6,-10,3:1)
Block(-5,-6,-9,3:1)
Block(-5,-6,-8,3:1)
Block(-5,-6,-7,3:1)
Block(-5,-6,-6,3:1)
Block(-5,-6,-5,3:1)
Block(-5,-6,-4,162:12)
Block(-5,-6,-3,3:1)
Block(-5,-6,-2,3:1)
Block(-5,-6,-1,3:1)
Block(-5,-6,0,3:1)
Block(-5,-6,1,162:12)
Block(-5,-6,2,3:1)
Block(-5,-6,3,3:1)
Block(-5,-6,4,162:12)
Block(-5,-6,5,162:12)
Block(-5,-6,6,3:1)
Block(-5,-6,7,162:12)
Block(-5,-6,8,3:1)
Block(-5,-6,9,3:1)
Block(-5,-6,10,162:12)
Block(-5,-6,11,3:1)
Block(-5,-5,-10,3:1)
Block(-5,-5,-9,162:12)
Block(-5,-5,-8,3:1)
Block(-5,-5,-7,3:1)
Block(-5,-5,-6,3:1)
Block(-5,-5,-5,3:1)
Block(-5,-5,-4,3:1)
Block(-5,-5,-3,3:1)
Block(-5,-5,-2,3:1)
Block(-5,-5,-1,3:1)
Block(-5,-5,0,3:1)
Block(-5,-5,1,162:12)
Block(-5,-5,2,3:1)
Block(-5,-5,3,3:1)
Block(-5,-5,4,162:12)
Block(-5,-5,5,3:1)
Block(-5,-5,6,3:1)
Block(-5,-5,7,162:12)
Block(-5,-5,8,3:1)
Block(-5,-5,9,3:1)
Block(-5,-5,10,162:12)
Block(-5,-4,-9,3:1)
Block(-5,-4,-8,162:12)
Block(-5,-4,-7,3:1)
Block(-5,-4,-6,3:1)
Block(-5,-4,-5,3:1)
Block(-5,-4,-4,3:1)
Block(-5,-4,-3,3:1)
Block(-5,-4,-2,162:12)
Block(-5,-4,-1,3:1)
Block(-5,-4,0,162:12)
Block(-5,-4,1,3:1)
Block(-5,-4,2,3:1)
Block(-5,-4,3,3:1)
Block(-5,-4,4,3:1)
Block(-5,-4,5,3:1)
Block(-5,-4,6,3:1)
Block(-5,-4,7,3:1)
Block(-5,-4,8,3:1)
Block(-5,-4,9,162:12)
Block(-5,-3,-9,3:1)
Block(-5,-3,-6,3:1)
Block(-5,-3,-5,3:1)
Block(-5,-3,-4,3:1)
Block(-5,-3,-3,3:1)
Block(-5,-3,-2,162:12)
Block(-5,-3,-1,3:1)
Block(-5,-3,0,3:1)
Block(-5,-3,1,162:12)
Block(-5,-3,2,3:1)
Block(-5,-3,3,3:1)
Block(-5,-3,4,3:1)
Block(-5,-3,5,3:1)
Block(-5,-3,6,3:1)
Block(-5,-3,9,162:12)
Block(-5,-2,-2,3:1)
Block(-5,-2,-1,3:1)
Block(-5,-2,0,3:1)
Block(-5,-2,1,162:12)
Block(-5,-2,2,3:1)
Block(-5,-2,3,3:1)
Block(-5,-2,4,3:1)
Block(-5,-2,5,3:1)
Block(-5,-2,6,162:12)
Block(-5,-1,0,162:12)
Block(-5,-1,1,3:1)
Block(-5,-1,2,162:12)
Block(-5,-1,3,3:1)
Block(-5,-1,4,3:1)
Block(-5,-1,5,162:12)
Block(-5,0,0,162:12)
Block(-5,0,2,162:12)
Block(-5,0,3,162:12)
Block(-5,0,5,162:12)
Block(-5,1,2,162:12)
Block(-5,1,3,162:12)
Block(-5,1,4,162:12)
Block(-5,2,4,162:12)
Block(-5,2,5,162:12)
Block(-5,29,-6,LEAVES_2:0)
Block(-5,29,-2,LEAVES_2:0)
Block(-5,30,-7,LEAVES_2:0)
Block(-5,30,-5,LEAVES_2:0)
Block(-5,30,-4,LEAVES_2:0)
Block(-5,31,-6,LEAVES_2:0)
Block(-5,31,-5,162:12)
Block(-5,31,-3,LEAVES_2:0)
Block(-5,32,-5,LEAVES_2:0)
Block(-5,32,-4,LEAVES_2:0)
Block(-5,32,-2,LEAVES_2:0)
Block(-5,33,3,LEAVES_2:0)
Block(-5,33,4,LEAVES_2:0)
Block(-5,34,-4,LEAVES_2:0)
Block(-5,34,-2,LEAVES_2:0)
Block(-5,34,0,LEAVES_2:0)
Block(-5,34,1,LEAVES_2:0)
Block(-5,34,2,LEAVES_2:0)
Block(-5,34,3,LEAVES_2:0)
Block(-5,34,5,LEAVES_2:0)
Block(-5,34,6,LEAVES_2:0)
Block(-5,35,-3,LEAVES_2:0)
Block(-5,35,-2,LEAVES_2:0)
Block(-5,35,-1,162:12)
Block(-5,35,1,LEAVES_2:0)
Block(-5,35,3,162:12)
Block(-5,35,4,LEAVES_2:0)
Block(-5,35,8,LEAVES_2:0)
Block(-5,35,9,LEAVES_2:0)
Block(-5,35,10,LEAVES_2:0)
Block(-5,35,12,LEAVES_2:0)
Block(-5,36,-5,LEAVES_2:0)
Block(-5,36,-4,LEAVES_2:0)
Block(-5,36,-1,LEAVES_2:0)
Block(-5,36,0,LEAVES_2:0)
Block(-5,36,1,LEAVES_2:0)
Block(-5,36,2,162:12)
Block(-5,36,3,LEAVES_2:0)
Block(-5,36,6,LEAVES_2:0)
Block(-5,36,7,LEAVES_2:0)
Block(-5,36,8,LEAVES_2:0)
Block(-5,36,9,LEAVES_2:0)
Block(-5,36,11,162:12)
Block(-5,36,13,LEAVES_2:0)
Block(-5,37,-7,LEAVES_2:0)
Block(-5,37,-6,LEAVES_2:0)
Block(-5,37,-4,162:12)
Block(-5,37,-3,LEAVES_2:0)
Block(-5,37,2,LEAVES_2:0)
Block(-5,37,10,LEAVES_2:0)
Block(-5,37,11,LEAVES_2:0)
Block(-5,37,12,LEAVES_2:0)
Block(-5,38,-8,LEAVES_2:0)
Block(-5,38,-6,162:12)
Block(-5,38,-5,162:12)
Block(-5,38,-4,LEAVES_2:0)
Block(-5,38,-1,LEAVES_2:0)
Block(-5,38,0,LEAVES_2:0)
Block(-5,38,2,LEAVES_2:0)
Block(-5,38,3,162:12)
Block(-5,38,4,LEAVES_2:0)
Block(-5,38,10,LEAVES_2:0)
Block(-5,39,-9,LEAVES_2:0)
Block(-5,39,-8,162:12)
Block(-5,39,-7,162:12)
Block(-5,39,-6,LEAVES_2:0)
Block(-5,39,-5,LEAVES_2:0)
Block(-5,39,-3,LEAVES_2:0)
Block(-5,39,-2,162:12)
Block(-5,39,1,LEAVES_2:0)
Block(-5,39,2,LEAVES_2:0)
Block(-5,39,3,LEAVES_2:0)
Block(-5,39,4,LEAVES_2:0)
Block(-5,39,6,LEAVES_2:0)
Block(-5,39,7,LEAVES_2:0)
Block(-5,39,9,LEAVES_2:0)
Block(-5,40,-8,LEAVES_2:0)
Block(-5,40,-7,LEAVES_2:0)
Block(-5,40,-2,LEAVES_2:0)
Block(-5,40,0,LEAVES_2:0)
Block(-5,40,2,LEAVES_2:0)
Block(-5,40,3,LEAVES_2:0)
Block(-5,40,4,LEAVES_2:0)
Block(-5,40,5,LEAVES_2:0)
Block(-5,40,7,162:12)
Block(-5,40,8,LEAVES_2:0)
Block(-5,41,-5,LEAVES_2:0)
Block(-5,41,-4,162:12)
Block(-5,41,-3,LEAVES_2:0)
Block(-5,41,-2,LEAVES_2:0)
Block(-5,41,-1,LEAVES_2:0)
Block(-5,41,2,LEAVES_2:0)
Block(-5,41,3,LEAVES_2:0)
Block(-5,41,4,LEAVES_2:0)
Block(-5,41,6,LEAVES_2:0)
Block(-5,41,7,LEAVES_2:0)
Block(-5,42,-4,LEAVES_2:0)
Block(-5,42,1,LEAVES_2:0)
Block(-5,42,3,LEAVES_2:0)
Block(-5,42,4,162:12)
Block(-5,42,6,LEAVES_2:0)
Block(-5,43,3,LEAVES_2:0)
Block(-5,43,4,LEAVES_2:0)
Block(-5,43,5,LEAVES_2:0)
Block(-4,-6,-11,3:1)
Block(-4,-6,-10,162:12)
Block(-4,-6,-9,3:1)
Block(-4,-6,-8,3:1)
Block(-4,-6,-7,162:12)
Block(-4,-6,-6,3:1)
Block(-4,-6,-5,162:12)
Block(-4,-6,-4,3:1)
Block(-4,-6,-3,3:1)
Block(-4,-6,-2,3:1)
Block(-4,-6,-1,162:12)
Block(-4,-6,0,3:1)
Block(-4,-6,1,3:1)
Block(-4,-6,2,3:1)
Block(-4,-6,3,3:1)
Block(-4,-6,4,3:1)
Block(-4,-6,5,3:1)
Block(-4,-6,6,3:1)
Block(-4,-6,7,162:12)
Block(-4,-6,8,3:1)
Block(-4,-6,9,3:1)
Block(-4,-6,10,162:12)
Block(-4,-5,-10,3:1)
Block(-4,-5,-9,3:1)
Block(-4,-5,-8,3:1)
Block(-4,-5,-7,162:12)
Block(-4,-5,-6,3:1)
Block(-4,-5,-5,162:12)
Block(-4,-5,-4,3:1)
Block(-4,-5,-3,3:1)
Block(-4,-5,-2,3:1)
Block(-4,-5,-1,3:1)
Block(-4,-5,0,3:1)
Block(-4,-5,1,3:1)
Block(-4,-5,2,162:12)
Block(-4,-5,3,3:1)
Block(-4,-5,4,3:1)
Block(-4,-5,5,162:12)
Block(-4,-5,6,3:1)
Block(-4,-5,7,3:1)
Block(-4,-5,8,3:1)
Block(-4,-5,9,3:1)
Block(-4,-5,10,3:1)
Block(-4,-4,-10,3:1)
Block(-4,-4,-9,3:1)
Block(-4,-4,-8,3:1)
Block(-4,-4,-7,3:1)
Block(-4,-4,-6,3:1)
Block(-4,-4,-5,3:1)
Block(-4,-4,-4,3:1)
Block(-4,-4,-3,3:1)
Block(-4,-4,-2,3:1)
Block(-4,-4,-1,3:1)
Block(-4,-4,0,3:1)
Block(-4,-4,1,162:12)
Block(-4,-4,2,162:12)
Block(-4,-4,3,3:1)
Block(-4,-4,4,162:12)
Block(-4,-4,5,3:1)
Block(-4,-4,6,162:12)
Block(-4,-4,7,3:1)
Block(-4,-3,-8,162:12)
Block(-4,-3,-7,3:1)
Block(-4,-3,-6,3:1)
Block(-4,-3,-5,3:1)
Block(-4,-3,-4,3:1)
Block(-4,-3,-3,3:1)
Block(-4,-3,-2,3:1)
Block(-4,-3,-1,162:12)
Block(-4,-3,0,3:1)
Block(-4,-3,1,3:1)
Block(-4,-3,2,3:1)
Block(-4,-3,3,3:1)
Block(-4,-3,4,162:12)
Block(-4,-3,5,3:1)
Block(-4,-3,6,162:12)
Block(-4,-3,7,3:1)
Block(-4,-2,-5,3:1)
Block(-4,-2,-4,3:1)
Block(-4,-2,-3,3:1)
Block(-4,-2,-2,162:12)
Block(-4,-2,-1,3:1)
Block(-4,-2,0,3:1)
Block(-4,-2,1,3:1)
Block(-4,-2,2,3:1)
Block(-4,-2,3,162:12)
Block(-4,-2,4,3:1)
Block(-4,-2,5,3:1)
Block(-4,-2,6,3:1)
Block(-4,-2,8,162:12)
Block(-4,-1,-1,3:1)
Block(-4,-1,0,3:1)
Block(-4,-1,1,3:1)
Block(-4,-1,3,162:12)
Block(-4,-1,4,3:1)
Block(-4,-1,6,3:1)
Block(-4,-1,7,162:12)
Block(-4,0,6,162:12)
Block(-4,1,0,162:12)
Block(-4,1,1,162:12)
Block(-4,1,4,162:12)
Block(-4,1,5,162:12)
Block(-4,29,-4,LEAVES_2:0)
Block(-4,30,-6,LEAVES_2:0)
Block(-4,30,-3,LEAVES_2:0)
Block(-4,30,-1,LEAVES_2:0)
Block(-4,31,-7,LEAVES_2:0)
Block(-4,31,-4,162:12)
Block(-4,31,-3,LEAVES_2:0)
Block(-4,31,-2,LEAVES_2:0)
Block(-4,32,-6,LEAVES_2:0)
Block(-4,32,-5,LEAVES_2:0)
Block(-4,32,-4,LEAVES_2:0)
Block(-4,33,2,LEAVES_2:0)
Block(-4,33,4,LEAVES_2:0)
Block(-4,33,6,LEAVES_2:0)
Block(-4,34,-1,LEAVES_2:0)
Block(-4,34,0,LEAVES_2:0)
Block(-4,34,1,LEAVES_2:0)
Block(-4,34,2,LEAVES_2:0)
Block(-4,34,3,162:12)
Block(-4,34,4,LEAVES_2:0)
Block(-4,34,5,LEAVES_2:0)
Block(-4,34,7,LEAVES_2:0)
Block(-4,34,11,LEAVES_2:0)
Block(-4,35,-3,LEAVES_2:0)
Block(-4,35,-2,LEAVES_2:0)
Block(-4,35,0,162:12)
Block(-4,35,1,LEAVES_2:0)
Block(-4,35,2,LEAVES_2:0)
Block(-4,35,6,LEAVES_2:0)
Block(-4,35,7,LEAVES_2:0)
Block(-4,35,8,LEAVES_2:0)
Block(-4,35,9,LEAVES_2:0)
Block(-4,35,10,LEAVES_2:0)
Block(-4,35,11,LEAVES_2:0)
Block(-4,36,-5,LEAVES_2:0)
Block(-4,36,-3,162:12)
Block(-4,36,-1,LEAVES_2:0)
Block(-4,36,0,LEAVES_2:0)
Block(-4,36,2,LEAVES_2:0)
Block(-4,36,6,LEAVES_2:0)
Block(-4,36,9,162:12)
Block(-4,36,10,162:12)
Block(-4,36,11,LEAVES_2:0)
Block(-4,36,12,LEAVES_2:0)
Block(-4,37,-8,LEAVES_2:0)
Block(-4,37,-6,LEAVES_2:0)
Block(-4,37,-4,LEAVES_2:0)
Block(-4,37,-3,LEAVES_2:0)
Block(-4,37,3,LEAVES_2:0)
Block(-4,37,5,LEAVES_2:0)
Block(-4,37,8,LEAVES_2:0)
Block(-4,37,9,LEAVES_2:0)
Block(-4,37,10,LEAVES_2:0)
Block(-4,38,-7,LEAVES_2:0)
Block(-4,38,-2,LEAVES_2:0)
Block(-4,38,-1,162:12)
Block(-4,38,1,LEAVES_2:0)
Block(-4,38,2,162:12)
Block(-4,38,3,LEAVES_2:0)
Block(-4,38,4,LEAVES_2:0)
Block(-4,38,6,LEAVES_2:0)
Block(-4,39,-8,LEAVES_2:0)
Block(-4,39,-7,LEAVES_2:0)
Block(-4,39,-5,LEAVES_2:0)
Block(-4,39,-1,LEAVES_2:0)
Block(-4,39,0,LEAVES_2:0)
Block(-4,39,2,LEAVES_2:0)
Block(-4,39,4,LEAVES_2:0)
Block(-4,39,5,LEAVES_2:0)
Block(-4,39,6,LEAVES_2:0)
Block(-4,39,7,LEAVES_2:0)
Block(-4,39,9,LEAVES_2:0)
Block(-4,40,-6,LEAVES_2:0)
Block(-4,40,-3,LEAVES_2:0)
Block(-4,40,-2,LEAVES_2:0)
Block(-4,40,-1,LEAVES_2:0)
Block(-4,40,1,LEAVES_2:0)
Block(-4,40,3,LEAVES_2:0)
Block(-4,40,4,LEAVES_2:0)
Block(-4,40,5,LEAVES_2:0)
Block(-4,40,6,LEAVES_2:0)
Block(-4,40,8,LEAVES_2:0)
Block(-4,41,-5,LEAVES_2:0)
Block(-4,41,-3,162:12)
Block(-4,41,0,LEAVES_2:0)
Block(-4,41,2,LEAVES_2:0)
Block(-4,41,4,LEAVES_2:0)
Block(-4,41,5,LEAVES_2:0)
Block(-4,41,7,LEAVES_2:0)
Block(-4,42,-4,LEAVES_2:0)
Block(-4,42,-3,LEAVES_2:0)
Block(-4,42,-2,LEAVES_2:0)
Block(-4,42,2,LEAVES_2:0)
Block(-4,42,3,162:12)
Block(-4,42,5,LEAVES_2:0)
Block(-4,43,2,LEAVES_2:0)
Block(-4,43,4,LEAVES_2:0)
Block(-4,44,3,LEAVES_2:0)
Block(-3,-6,-10,3:1)
Block(-3,-6,-9,3:1)
Block(-3,-6,-8,3:1)
Block(-3,-6,-7,3:1)
Block(-3,-6,-6,3:1)
Block(-3,-6,-5,3:1)
Block(-3,-6,-4,3:1)
Block(-3,-6,-3,162:12)
Block(-3,-6,-2,3:1)
Block(-3,-6,-1,3:1)
Block(-3,-6,0,162:12)
Block(-3,-6,1,3:1)
Block(-3,-6,2,3:1)
Block(-3,-6,3,162:12)
Block(-3,-6,4,3:1)
Block(-3,-6,5,162:12)
Block(-3,-6,6,3:1)
Block(-3,-6,7,3:1)
Block(-3,-6,8,162:12)
Block(-3,-6,9,3:1)
Block(-3,-6,10,3:1)
Block(-3,-6,11,3:1)
Block(-3,-5,-10,3:1)
Block(-3,-5,-9,3:1)
Block(-3,-5,-8,3:1)
Block(-3,-5,-7,3:1)
Block(-3,-5,-6,3:1)
Block(-3,-5,-5,3:1)
Block(-3,-5,-4,3:1)
Block(-3,-5,-3,162:12)
Block(-3,-5,-2,3:1)
Block(-3,-5,-1,162:12)
Block(-3,-5,0,3:1)
Block(-3,-5,1,3:1)
Block(-3,-5,2,3:1)
Block(-3,-5,3,3:1)
Block(-3,-5,4,3:1)
Block(-3,-5,5,3:1)
Block(-3,-5,6,3:1)
Block(-3,-5,7,3:1)
Block(-3,-5,8,3:1)
Block(-3,-5,9,3:1)
Block(-3,-5,10,162:12)
Block(-3,-4,-9,3:1)
Block(-3,-4,-8,3:1)
Block(-3,-4,-7,162:12)
Block(-3,-4,-6,3:1)
Block(-3,-4,-5,3:1)
Block(-3,-4,-4,162:12)
Block(-3,-4,-3,3:1)
Block(-3,-4,-2,162:12)
Block(-3,-4,-1,162:12)
Block(-3,-4,0,3:1)
Block(-3,-4,1,3:1)
Block(-3,-4,2,3:1)
Block(-3,-4,3,3:1)
Block(-3,-4,4,3:1)
Block(-3,-4,5,3:1)
Block(-3,-4,6,3:1)
Block(-3,-4,7,3:1)
Block(-3,-4,8,3:1)
Block(-3,-3,-9,3:1)
Block(-3,-3,-8,162:12)
Block(-3,-3,-7,162:12)
Block(-3,-3,-6,3:1)
Block(-3,-3,-5,3:1)
Block(-3,-3,-4,3:1)
Block(-3,-3,-3,3:1)
Block(-3,-3,-2,3:1)
Block(-3,-3,-1,3:1)
Block(-3,-3,0,162:12)
Block(-3,-3,1,162:12)
Block(-3,-3,2,3:1)
Block(-3,-3,3,3:1)
Block(-3,-3,4,3:1)
Block(-3,-3,5,3:1)
Block(-3,-3,6,162:12)
Block(-3,-3,7,3:1)
Block(-3,-2,-8,162:12)
Block(-3,-2,-7,3:1)
Block(-3,-2,-6,3:1)
Block(-3,-2,-5,3:1)
Block(-3,-2,-4,3:1)
Block(-3,-2,-3,3:1)
Block(-3,-2,-2,3:1)
Block(-3,-2,-1,3:1)
Block(-3,-2,0,3:1)
Block(-3,-2,1,3:1)
Block(-3,-2,2,3:1)
Block(-3,-2,3,3:1)
Block(-3,-2,4,3:1)
Block(-3,-2,5,162:12)
Block(-3,-2,6,3:1)
Block(-3,-2,7,3:1)
Block(-3,-1,-5,3:1)
Block(-3,-1,-3,3:1)
Block(-3,-1,-2,162:12)
Block(-3,-1,-1,3:1)
Block(-3,-1,0,3:1)
Block(-3,-1,1,3:1)
Block(-3,-1,2,3:1)
Block(-3,-1,3,162:12)
Block(-3,-1,4,3:1)
Block(-3,-1,5,162:12)
Block(-3,-1,6,3:1)
Block(-3,0,-2,162:12)
Block(-3,0,-1,3:1)
Block(-3,0,0,162:12)
Block(-3,0,1,3:1)
Block(-3,0,2,3:1)
Block(-3,0,3,162:12)
Block(-3,0,4,3:1)
Block(-3,1,2,162:12)
Block(-3,1,4,162:12)
Block(-3,2,4,162:12)
Block(-3,25,3,162:12)
Block(-3,30,-7,LEAVES_2:0)
Block(-3,30,-5,LEAVES_2:0)
Block(-3,30,-4,LEAVES_2:0)
Block(-3,30,-3,162:12)
Block(-3,30,-2,LEAVES_2:0)
Block(-3,31,-6,LEAVES_2:0)
Block(-3,31,-5,LEAVES_2:0)
Block(-3,31,-4,LEAVES_2:0)
Block(-3,31,-3,162:12)
Block(-3,31,-2,LEAVES_2:0)
Block(-3,32,-3,LEAVES_2:0)
Block(-3,32,4,LEAVES_2:0)
Block(-3,33,3,LEAVES_2:0)
Block(-3,33,4,162:12)
Block(-3,33,5,LEAVES_2:0)
Block(-3,33,7,LEAVES_2:0)
Block(-3,34,0,LEAVES_2:0)
Block(-3,34,1,LEAVES_2:0)
Block(-3,34,2,LEAVES_2:0)
Block(-3,34,3,162:12)
Block(-3,34,5,162:12)
Block(-3,34,6,162:12)
Block(-3,34,8,LEAVES_2:0)
Block(-3,34,9,LEAVES_2:0)
Block(-3,35,-4,LEAVES_2:0)
Block(-3,35,-1,LEAVES_2:0)
Block(-3,35,0,162:12)
Block(-3,35,1,LEAVES_2:0)
Block(-3,35,5,LEAVES_2:0)
Block(-3,35,7,162:12)
Block(-3,35,8,162:12)
Block(-3,35,10,LEAVES_2:0)
Block(-3,36,-7,LEAVES_2:0)
Block(-3,36,-4,LEAVES_2:0)
Block(-3,36,-3,162:12)
Block(-3,36,-2,LEAVES_2:0)
Block(-3,36,0,162:12)
Block(-3,36,2,LEAVES_2:0)
Block(-3,36,5,LEAVES_2:0)
Block(-3,36,7,LEAVES_2:0)
Block(-3,36,8,LEAVES_2:0)
Block(-3,36,9,LEAVES_2:0)
Block(-3,36,11,LEAVES_2:0)
Block(-3,37,-6,LEAVES_2:0)
Block(-3,37,-5,162:12)
Block(-3,37,-4,162:12)
Block(-3,37,-3,LEAVES_2:0)
Block(-3,37,-1,LEAVES_2:0)
Block(-3,37,0,LEAVES_2:0)
Block(-3,37,1,162:12)
Block(-3,37,2,LEAVES_2:0)
Block(-3,37,4,LEAVES_2:0)
Block(-3,37,5,162:12)
Block(-3,37,6,LEAVES_2:0)
Block(-3,37,10,LEAVES_2:0)
Block(-3,38,-9,LEAVES_2:0)
Block(-3,38,-8,LEAVES_2:0)
Block(-3,38,-5,LEAVES_2:0)
Block(-3,38,-4,LEAVES_2:0)
Block(-3,38,-2,LEAVES_2:0)
Block(-3,38,-1,162:12)
Block(-3,38,0,LEAVES_2:0)
Block(-3,38,1,LEAVES_2:0)
Block(-3,38,3,LEAVES_2:0)
Block(-3,38,5,LEAVES_2:0)
Block(-3,38,9,LEAVES_2:0)
Block(-3,39,-7,LEAVES_2:0)
Block(-3,39,-6,LEAVES_2:0)
Block(-3,39,4,LEAVES_2:0)
Block(-3,39,8,LEAVES_2:0)
Block(-3,40,-8,LEAVES_2:0)
Block(-3,40,-5,LEAVES_2:0)
Block(-3,40,-2,162:12)
Block(-3,40,-1,LEAVES_2:0)
Block(-3,40,0,162:12)
Block(-3,40,1,LEAVES_2:0)
Block(-3,40,2,LEAVES_2:0)
Block(-3,40,4,LEAVES_2:0)
Block(-3,40,5,LEAVES_2:0)
Block(-3,40,7,LEAVES_2:0)
Block(-3,41,-4,LEAVES_2:0)
Block(-3,41,-3,LEAVES_2:0)
Block(-3,41,-2,LEAVES_2:0)
Block(-3,41,0,LEAVES_2:0)
Block(-3,41,1,LEAVES_2:0)
Block(-3,41,2,162:12)
Block(-3,41,3,LEAVES_2:0)
Block(-3,41,4,LEAVES_2:0)
Block(-3,42,2,LEAVES_2:0)
Block(-3,42,3,LEAVES_2:0)
Block(-3,42,4,LEAVES_2:0)
Block(-3,43,3,LEAVES_2:0)
Block(-2,-6,-10,162:12)
Block(-2,-6,-9,3:1)
Block(-2,-6,-8,3:1)
Block(-2,-6,-7,162:12)
Block(-2,-6,-6,3:1)
Block(-2,-6,-5,3:1)
Block(-2,-6,-4,3:1)
Block(-2,-6,-3,3:1)
Block(-2,-6,-2,3:1)
Block(-2,-6,-1,3:1)
Block(-2,-6,0,3:1)
Block(-2,-6,1,3:1)
Block(-2,-6,2,162:12)
Block(-2,-6,3,3:1)
Block(-2,-6,4,162:12)
Block(-2,-6,5,3:1)
Block(-2,-6,6,3:1)
Block(-2,-6,7,162:12)
Block(-2,-6,8,3:1)
Block(-2,-6,9,3:1)
Block(-2,-6,10,3:1)
Block(-2,-6,11,3:1)
Block(-2,-5,-10,162:12)
Block(-2,-5,-9,3:1)
Block(-2,-5,-8,3:1)
Block(-2,-5,-7,3:1)
Block(-2,-5,-6,162:12)
Block(-2,-5,-5,3:1)
Block(-2,-5,-4,3:1)
Block(-2,-5,-3,3:1)
Block(-2,-5,-2,3:1)
Block(-2,-5,-1,3:1)
Block(-2,-5,0,3:1)
Block(-2,-5,1,3:1)
Block(-2,-5,2,3:1)
Block(-2,-5,3,3:1)
Block(-2,-5,4,162:12)
Block(-2,-5,5,3:1)
Block(-2,-5,6,3:1)
Block(-2,-5,7,162:12)
Block(-2,-5,8,3:1)
Block(-2,-5,9,3:1)
Block(-2,-4,-9,162:12)
Block(-2,-4,-8,3:1)
Block(-2,-4,-7,3:1)
Block(-2,-4,-6,3:1)
Block(-2,-4,-5,162:12)
Block(-2,-4,-4,3:1)
Block(-2,-4,-3,3:1)
Block(-2,-4,-2,3:1)
Block(-2,-4,-1,3:1)
Block(-2,-4,0,3:1)
Block(-2,-4,1,3:1)
Block(-2,-4,2,3:1)
Block(-2,-4,3,3:1)
Block(-2,-4,4,3:1)
Block(-2,-4,5,3:1)
Block(-2,-4,6,3:1)
Block(-2,-4,7,162:12)
Block(-2,-4,8,3:1)
Block(-2,-4,9,162:12)
Block(-2,-3,-9,162:12)
Block(-2,-3,-7,3:1)
Block(-2,-3,-6,162:12)
Block(-2,-3,-5,3:1)
Block(-2,-3,-4,162:12)
Block(-2,-3,-3,3:1)
Block(-2,-3,-2,3:1)
Block(-2,-3,-1,3:1)
Block(-2,-3,0,3:1)
Block(-2,-3,1,3:1)
Block(-2,-3,2,3:1)
Block(-2,-3,3,3:1)
Block(-2,-3,4,3:1)
Block(-2,-3,5,3:1)
Block(-2,-3,6,3:1)
Block(-2,-3,7,3:1)
Block(-2,-3,8,3:1)
Block(-2,-3,9,162:12)
Block(-2,-2,-7,3:1)
Block(-2,-2,-6,3:1)
Block(-2,-2,-5,3:1)
Block(-2,-2,-4,162:12)
Block(-2,-2,-3,3:1)
Block(-2,-2,-2,3:1)
Block(-2,-2,-1,3:1)
Block(-2,-2,0,162:12)
Block(-2,-2,1,3:1)
Block(-2,-2,2,162:12)
Block(-2,-2,3,3:1)
Block(-2,-2,4,3:1)
Block(-2,-2,5,3:1)
Block(-2,-2,6,3:1)
Block(-2,-2,7,3:1)
Block(-2,-2,8,162:12)
Block(-2,-1,-7,162:12)
Block(-2,-1,-6,3:1)
Block(-2,-1,-5,3:1)
Block(-2,-1,-4,3:1)
Block(-2,-1,-3,3:1)
Block(-2,-1,-2,3:1)
Block(-2,-1,-1,3:1)
Block(-2,-1,0,162:12)
Block(-2,-1,1,3:1)
Block(-2,-1,2,162:12)
Block(-2,-1,3,3:1)
Block(-2,-1,4,3:1)
Block(-2,-1,5,162:12)
Block(-2,-1,6,3:1)
Block(-2,0,-7,162:12)
Block(-2,0,-3,3:1)
Block(-2,0,-2,3:1)
Block(-2,0,-1,162:12)
Block(-2,0,0,3:1)
Block(-2,0,1,3:1)
Block(-2,0,2,162:12)
Block(-2,0,3,162:12)
Block(-2,0,4,3:1)
Block(-2,0,5,162:12)
Block(-2,0,6,3:1)
Block(-2,1,2,3:1)
Block(-2,2,1,162:12)
Block(-2,3,3,162:12)
Block(-2,23,2,162:12)
Block(-2,24,2,162:12)
Block(-2,29,-6,LEAVES_2:0)
Block(-2,29,-2,162:12)
Block(-2,30,-5,LEAVES_2:0)
Block(-2,30,-3,LEAVES_2:0)
Block(-2,30,-2,162:12)
Block(-2,30,-1,LEAVES_2:0)
Block(-2,31,-5,LEAVES_2:0)
Block(-2,31,-4,LEAVES_2:0)
Block(-2,31,-2,LEAVES_2:0)
Block(-2,32,-6,LEAVES_2:0)
Block(-2,32,-3,LEAVES_2:0)
Block(-2,33,2,LEAVES_2:0)
Block(-2,33,3,162:12)
Block(-2,33,9,LEAVES_2:0)
Block(-2,34,0,162:12)
Block(-2,34,1,LEAVES_2:0)
Block(-2,34,7,LEAVES_2:0)
Block(-2,34,8,LEAVES_2:0)
Block(-2,35,-7,LEAVES_2:0)
Block(-2,35,-3,LEAVES_2:0)
Block(-2,35,2,LEAVES_2:0)
Block(-2,35,7,162:12)
Block(-2,35,9,LEAVES_2:0)
Block(-2,35,12,LEAVES_2:0)
Block(-2,36,-10,LEAVES_2:0)
Block(-2,36,-6,LEAVES_2:0)
Block(-2,36,-5,LEAVES_2:0)
Block(-2,36,-4,LEAVES_2:0)
Block(-2,36,-2,162:12)
Block(-2,36,0,LEAVES_2:0)
Block(-2,36,4,LEAVES_2:0)
Block(-2,36,5,LEAVES_2:0)
Block(-2,36,7,LEAVES_2:0)
Block(-2,36,8,LEAVES_2:0)
Block(-2,36,10,LEAVES_2:0)
Block(-2,36,11,LEAVES_2:0)
Block(-2,37,-9,LEAVES_2:0)
Block(-2,37,-8,LEAVES_2:0)
Block(-2,37,-7,LEAVES_2:0)
Block(-2,37,-6,162:12)
Block(-2,37,-4,LEAVES_2:0)
Block(-2,37,-3,LEAVES_2:0)
Block(-2,37,-2,LEAVES_2:0)
Block(-2,37,-1,LEAVES_2:0)
Block(-2,37,0,162:12)
Block(-2,37,1,LEAVES_2:0)
Block(-2,37,2,162:12)
Block(-2,37,3,LEAVES_2:0)
Block(-2,37,5,162:12)
Block(-2,37,6,LEAVES_2:0)
Block(-2,38,-10,LEAVES_2:0)
Block(-2,38,-8,162:12)
Block(-2,38,-7,162:12)
Block(-2,38,-6,LEAVES_2:0)
Block(-2,38,-5,LEAVES_2:0)
Block(-2,38,-3,LEAVES_2:0)
Block(-2,38,-1,LEAVES_2:0)
Block(-2,38,0,LEAVES_2:0)
Block(-2,38,2,LEAVES_2:0)
Block(-2,38,4,LEAVES_2:0)
Block(-2,38,5,LEAVES_2:0)
Block(-2,38,7,LEAVES_2:0)
Block(-2,39,-9,LEAVES_2:0)
Block(-2,39,-8,LEAVES_2:0)
Block(-2,39,-7,LEAVES_2:0)
Block(-2,39,-4,LEAVES_2:0)
Block(-2,39,-3,LEAVES_2:0)
Block(-2,39,-2,162:12)
Block(-2,39,-1,LEAVES_2:0)
Block(-2,39,2,162:12)
Block(-2,39,3,LEAVES_2:0)
Block(-2,39,4,162:12)
Block(-2,39,5,LEAVES_2:0)
Block(-2,39,6,LEAVES_2:0)
Block(-2,40,-6,LEAVES_2:0)
Block(-2,40,-4,LEAVES_2:0)
Block(-2,40,-3,LEAVES_2:0)
Block(-2,40,-2,LEAVES_2:0)
Block(-2,40,-1,LEAVES_2:0)
Block(-2,40,0,LEAVES_2:0)
Block(-2,40,1,162:12)
Block(-2,40,2,LEAVES_2:0)
Block(-2,40,4,LEAVES_2:0)
Block(-2,41,-5,LEAVES_2:0)
Block(-2,41,-4,LEAVES_2:0)
Block(-2,41,-3,LEAVES_2:0)
Block(-2,41,-1,LEAVES_2:0)
Block(-2,41,1,LEAVES_2:0)
Block(-2,41,2,LEAVES_2:0)
Block(-2,41,3,LEAVES_2:0)
Block(-2,42,-3,LEAVES_2:0)
Block(-2,42,-1,LEAVES_2:0)
Block(-2,42,1,LEAVES_2:0)
Block(-2,42,2,LEAVES_2:0)
Block(-2,42,3,LEAVES_2:0)
Block(-2,43,2,LEAVES_2:0)
Block(-1,-6,-9,3:1)
Block(-1,-6,-8,162:12)
Block(-1,-6,-7,3:1)
Block(-1,-6,-6,3:1)
Block(-1,-6,-5,3:1)
Block(-1,-6,-4,3:1)
Block(-1,-6,-3,3:1)
Block(-1,-6,-2,162:12)
Block(-1,-6,-1,3:1)
Block(-1,-6,0,3:1)
Block(-1,-6,1,162:12)
Block(-1,-6,2,162:12)
Block(-1,-6,3,3:1)
Block(-1,-6,4,162:12)
Block(-1,-6,5,162:12)
Block(-1,-6,6,3:1)
Block(-1,-6,7,3:1)
Block(-1,-6,8,3:1)
Block(-1,-6,9,162:12)
Block(-1,-6,10,3:1)
Block(-1,-6,11,3:1)
Block(-1,-5,-8,3:1)
Block(-1,-5,-7,3:1)
Block(-1,-5,-6,3:1)
Block(-1,-5,-5,3:1)
Block(-1,-5,-4,3:1)
Block(-1,-5,-3,3:1)
Block(-1,-5,-2,3:1)
Block(-1,-5,-1,3:1)
Block(-1,-5,0,3:1)
Block(-1,-5,1,3:1)
Block(-1,-5,2,3:1)
Block(-1,-5,3,3:1)
Block(-1,-5,4,162:12)
Block(-1,-5,5,3:1)
Block(-1,-5,6,3:1)
Block(-1,-5,7,3:1)
Block(-1,-5,8,3:1)
Block(-1,-5,9,162:12)
Block(-1,-4,-8,3:1)
Block(-1,-4,-7,162:12)
Block(-1,-4,-6,3:1)
Block(-1,-4,-5,3:1)
Block(-1,-4,-4,3:1)
Block(-1,-4,-3,3:1)
Block(-1,-4,-2,3:1)
Block(-1,-4,-1,3:1)
Block(-1,-4,0,3:1)
Block(-1,-4,1,3:1)
Block(-1,-4,2,3:1)
Block(-1,-4,3,162:12)
Block(-1,-4,4,3:1)
Block(-1,-4,5,3:1)
Block(-1,-4,6,3:1)
Block(-1,-4,7,3:1)
Block(-1,-4,8,3:1)
Block(-1,-3,-8,3:1)
Block(-1,-3,-7,3:1)
Block(-1,-3,-6,3:1)
Block(-1,-3,-5,3:1)
Block(-1,-3,-4,3:1)
Block(-1,-3,-3,3:1)
Block(-1,-3,-2,3:1)
Block(-1,-3,-1,3:1)
Block(-1,-3,0,3:1)
Block(-1,-3,1,3:1)
Block(-1,-3,2,3:1)
Block(-1,-3,3,162:12)
Block(-1,-3,4,3:1)
Block(-1,-3,5,3:1)
Block(-1,-3,6,3:1)
Block(-1,-3,7,162:12)
Block(-1,-3,8,3:1)
Block(-1,-2,-7,3:1)
Block(-1,-2,-6,162:12)
Block(-1,-2,-5,3:1)
Block(-1,-2,-4,3:1)
Block(-1,-2,-3,3:1)
Block(-1,-2,-2,3:1)
Block(-1,-2,-1,3:1)
Block(-1,-2,0,3:1)
Block(-1,-2,1,3:1)
Block(-1,-2,2,162:12)
Block(-1,-2,3,3:1)
Block(-1,-2,4,3:1)
Block(-1,-2,5,3:1)
Block(-1,-2,6,162:12)
Block(-1,-2,7,162:12)
Block(-1,-1,-6,162:12)
Block(-1,-1,-5,3:1)
Block(-1,-1,-4,3:1)
Block(-1,-1,-3,162:12)
Block(-1,-1,-2,3:1)
Block(-1,-1,-1,3:1)
Block(-1,-1,0,162:12)
Block(-1,-1,1,3:1)
Block(-1,-1,2,3:1)
Block(-1,-1,3,3:1)
Block(-1,-1,4,3:1)
Block(-1,-1,5,3:1)
Block(-1,-1,6,162:12)
Block(-1,-1,7,162:12)
Block(-1,0,-6,162:12)
Block(-1,0,-4,3:1)
Block(-1,0,-3,162:12)
Block(-1,0,-2,162:12)
Block(-1,0,-1,3:1)
Block(-1,0,0,162:12)
Block(-1,0,1,3:1)
Block(-1,0,2,3:1)
Block(-1,0,3,3:1)
Block(-1,0,4,162:12)
Block(-1,0,5,3:1)
Block(-1,0,6,162:12)
Block(-1,1,-6,162:12)
Block(-1,1,-3,162:12)
Block(-1,1,-2,3:1)
Block(-1,1,0,162:12)
Block(-1,1,1,3:1)
Block(-1,1,2,3:1)
Block(-1,1,4,3:1)
Block(-1,1,5,3:1)
Block(-1,1,6,3:1)
Block(-1,2,1,162:12)
Block(-1,2,3,162:12)
Block(-1,3,1,162:12)
Block(-1,3,2,162:12)
Block(-1,3,3,162:12)
Block(-1,4,2,162:12)
Block(-1,4,3,162:12)
Block(-1,5,2,162:12)
Block(-1,6,2,162:12)
Block(-1,22,1,162:12)
Block(-1,24,0,162:12)
Block(-1,25,0,162:12)
Block(-1,26,0,162:12)
Block(-1,27,0,162:12)
Block(-1,28,0,162:12)
Block(-1,29,-1,162:12)
Block(-1,29,0,162:12)
Block(-1,29,1,162:12)
Block(-1,30,-4,LEAVES_2:0)
Block(-1,30,0,162:12)
Block(-1,30,1,162:12)
Block(-1,31,-5,LEAVES_2:0)
Block(-1,31,-3,LEAVES_2:0)
Block(-1,31,1,162:12)
Block(-1,32,1,162:12)
Block(-1,32,2,162:12)
Block(-1,33,0,162:12)
Block(-1,33,2,162:12)
Block(-1,34,-1,162:12)
Block(-1,34,0,162:12)
Block(-1,34,1,LEAVES_2:0)
Block(-1,34,2,LEAVES_2:0)
Block(-1,34,8,LEAVES_2:0)
Block(-1,34,9,LEAVES_2:0)
Block(-1,34,11,LEAVES_2:0)
Block(-1,35,-4,LEAVES_2:0)
Block(-1,35,-2,LEAVES_2:0)
Block(-1,35,-1,162:12)
Block(-1,35,0,162:12)
Block(-1,35,1,LEAVES_2:0)
Block(-1,35,3,LEAVES_2:0)
Block(-1,35,4,LEAVES_2:0)
Block(-1,35,5,LEAVES_2:0)
Block(-1,35,7,LEAVES_2:0)
Block(-1,35,8,162:12)
Block(-1,35,9,162:12)
Block(-1,35,10,LEAVES_2:0)
Block(-1,36,-6,LEAVES_2:0)
Block(-1,36,-3,LEAVES_2:0)
Block(-1,36,-1,LEAVES_2:0)
Block(-1,36,0,162:12)
Block(-1,36,1,LEAVES_2:0)
Block(-1,36,3,LEAVES_2:0)
Block(-1,36,4,162:12)
Block(-1,36,6,LEAVES_2:0)
Block(-1,36,8,LEAVES_2:0)
Block(-1,36,9,LEAVES_2:0)
Block(-1,36,10,LEAVES_2:0)
Block(-1,37,-10,LEAVES_2:0)
Block(-1,37,-8,LEAVES_2:0)
Block(-1,37,-7,LEAVES_2:0)
Block(-1,37,-5,LEAVES_2:0)
Block(-1,37,-3,LEAVES_2:0)
Block(-1,37,-2,LEAVES_2:0)
Block(-1,37,-1,LEAVES_2:0)
Block(-1,37,0,162:12)
Block(-1,37,4,LEAVES_2:0)
Block(-1,37,6,LEAVES_2:0)
Block(-1,37,8,LEAVES_2:0)
Block(-1,37,12,LEAVES_2:0)
Block(-1,38,-11,LEAVES_2:0)
Block(-1,38,-10,162:12)
Block(-1,38,-9,162:12)
Block(-1,38,-8,LEAVES_2:0)
Block(-1,38,-6,LEAVES_2:0)
Block(-1,38,-4,LEAVES_2:0)
Block(-1,38,-3,LEAVES_2:0)
Block(-1,38,-2,LEAVES_2:0)
Block(-1,38,0,LEAVES_2:0)
Block(-1,38,1,LEAVES_2:0)
Block(-1,38,2,162:12)
Block(-1,38,5,LEAVES_2:0)
Block(-1,39,-10,LEAVES_2:0)
Block(-1,39,-9,LEAVES_2:0)
Block(-1,39,-7,LEAVES_2:0)
Block(-1,39,-5,LEAVES_2:0)
Block(-1,39,-4,162:12)
Block(-1,39,-3,162:12)
Block(-1,39,-2,LEAVES_2:0)
Block(-1,39,-1,LEAVES_2:0)
Block(-1,39,0,LEAVES_2:0)
Block(-1,39,1,LEAVES_2:0)
Block(-1,39,3,162:12)
Block(-1,39,4,LEAVES_2:0)
Block(-1,40,-8,LEAVES_2:0)
Block(-1,40,-6,LEAVES_2:0)
Block(-1,40,-5,162:12)
Block(-1,40,-4,LEAVES_2:0)
Block(-1,40,-3,LEAVES_2:0)
Block(-1,40,-1,LEAVES_2:0)
Block(-1,40,0,LEAVES_2:0)
Block(-1,40,1,LEAVES_2:0)
Block(-1,40,2,LEAVES_2:0)
Block(-1,40,3,LEAVES_2:0)
Block(-1,41,-5,LEAVES_2:0)
Block(-1,41,-4,LEAVES_2:0)
Block(-1,41,-2,LEAVES_2:0)
Block(-1,41,-1,LEAVES_2:0)
Block(-1,41,0,LEAVES_2:0)
Block(-1,41,1,LEAVES_2:0)
Block(-1,41,2,LEAVES_2:0)
Block(-1,42,0,LEAVES_2:0)
Block(-1,42,2,LEAVES_2:0)
Block(0,-6,-9,3:1)
Block(0,-6,-8,162:12)
Block(0,-6,-7,3:1)
Block(0,-6,-6,3:1)
Block(0,-6,-5,3:1)
Block(0,-6,-4,3:1)
Block(0,-6,-3,3:1)
Block(0,-6,-2,162:12)
Block(0,-6,-1,3:1)
Block(0,-6,0,3:1)
Block(0,-6,1,3:1)
Block(0,-6,2,3:1)
Block(0,-6,3,3:1)
Block(0,-6,4,3:1)
Block(0,-6,5,3:1)
Block(0,-6,6,3:1)
Block(0,-6,7,3:1)
Block(0,-6,8,162:12)
Block(0,-6,9,3:1)
Block(0,-6,10,3:1)
Block(0,-6,11,3:1)
Block(0,-5,-9,162:12)
Block(0,-5,-8,162:12)
Block(0,-5,-7,3:1)
Block(0,-5,-6,3:1)
Block(0,-5,-5,3:1)
Block(0,-5,-4,3:1)
Block(0,-5,-3,162:12)
Block(0,-5,-2,3:1)
Block(0,-5,-1,3:1)
Block(0,-5,0,3:1)
Block(0,-5,1,3:1)
Block(0,-5,2,3:1)
Block(0,-5,3,162:12)
Block(0,-5,4,3:1)
Block(0,-5,5,3:1)
Block(0,-5,6,3:1)
Block(0,-5,7,3:1)
Block(0,-5,8,3:1)
Block(0,-5,9,3:1)
Block(0,-4,-9,3:1)
Block(0,-4,-8,162:12)
Block(0,-4,-7,3:1)
Block(0,-4,-6,3:1)
Block(0,-4,-5,3:1)
Block(0,-4,-4,3:1)
Block(0,-4,-3,162:12)
Block(0,-4,-2,3:1)
Block(0,-4,-1,3:1)
Block(0,-4,0,3:1)
Block(0,-4,1,3:1)
Block(0,-4,2,3:1)
Block(0,-4,3,3:1)
Block(0,-4,4,3:1)
Block(0,-4,5,162:12)
Block(0,-4,6,3:1)
Block(0,-4,7,162:12)
Block(0,-4,8,3:1)
Block(0,-3,-7,162:12)
Block(0,-3,-6,3:1)
Block(0,-3,-5,3:1)
Block(0,-3,-4,3:1)
Block(0,-3,-3,3:1)
Block(0,-3,-2,3:1)
Block(0,-3,-1,3:1)
Block(0,-3,0,3:1)
Block(0,-3,1,162:12)
Block(0,-3,2,3:1)
Block(0,-3,3,3:1)
Block(0,-3,4,162:12)
Block(0,-3,5,3:1)
Block(0,-3,6,3:1)
Block(0,-3,7,162:12)
Block(0,-3,8,3:1)
Block(0,-2,-6,3:1)
Block(0,-2,-5,3:1)
Block(0,-2,-4,3:1)
Block(0,-2,-3,3:1)
Block(0,-2,-2,3:1)
Block(0,-2,-1,3:1)
Block(0,-2,0,162:12)
Block(0,-2,1,162:12)
Block(0,-2,2,3:1)
Block(0,-2,3,3:1)
Block(0,-2,4,3:1)
Block(0,-2,5,3:1)
Block(0,-2,6,3:1)
Block(0,-2,7,3:1)
Block(0,-1,-5,3:1)
Block(0,-1,-4,3:1)
Block(0,-1,-3,3:1)
Block(0,-1,-2,3:1)
Block(0,-1,-1,3:1)
Block(0,-1,0,162:12)
Block(0,-1,1,3:1)
Block(0,-1,2,3:1)
Block(0,-1,3,3:1)
Block(0,-1,4,3:1)
Block(0,-1,5,3:1)
Block(0,-1,6,3:1)
Block(0,-1,7,3:1)
Block(0,0,-4,3:1)
Block(0,0,-3,3:1)
Block(0,0,-2,3:1)
Block(0,0,-1,162:12)
Block(0,0,0,162:12)
Block(0,0,1,3:1)
Block(0,0,2,162:12)
Block(0,0,3,162:12)
Block(0,0,4,3:1)
Block(0,0,5,3:1)
Block(0,0,6,162:12)
Block(0,1,-5,162:12)
Block(0,1,-4,162:12)
Block(0,1,-3,3:1)
Block(0,1,-2,3:1)
Block(0,1,-1,3:1)
Block(0,1,0,3:1)
Block(0,1,1,162:12)
Block(0,1,2,3:1)
Block(0,1,3,3:1)
Block(0,1,4,162:12)
Block(0,1,5,3:1)
Block(0,2,-4,162:12)
Block(0,2,1,162:12)
Block(0,2,4,162:12)
Block(0,3,-1,162:12)
Block(0,3,2,162:12)
Block(0,4,0,162:12)
Block(0,4,1,162:12)
Block(0,4,2,162:12)
Block(0,5,1,162:12)
Block(0,5,2,162:12)
Block(0,5,3,162:12)
Block(0,6,1,162:12)
Block(0,6,2,162:12)
Block(0,6,4,162:12)
Block(0,7,1,162:12)
Block(0,7,2,162:12)
Block(0,7,4,162:12)
Block(0,8,2,162:12)
Block(0,8,5,162:12)
Block(0,9,2,162:12)
Block(0,9,5,162:12)
Block(0,10,2,162:12)
Block(0,10,5,162:12)
Block(0,11,1,162:12)
Block(0,11,2,162:12)
Block(0,12,1,162:12)
Block(0,12,2,162:12)
Block(0,13,1,162:12)
Block(0,13,2,162:12)
Block(0,14,1,162:12)
Block(0,14,2,162:12)
Block(0,15,1,162:12)
Block(0,15,2,162:12)
Block(0,16,1,162:12)
Block(0,16,2,162:12)
Block(0,17,1,162:12)
Block(0,17,2,162:12)
Block(0,18,0,162:12)
Block(0,18,1,162:12)
Block(0,18,2,162:12)
Block(0,19,0,162:12)
Block(0,19,1,162:12)
Block(0,20,0,162:12)
Block(0,20,1,162:12)
Block(0,21,0,162:12)
Block(0,21,1,162:12)
Block(0,22,0,162:12)
Block(0,22,1,162:12)
Block(0,23,0,162:12)
Block(0,23,1,162:12)
Block(0,24,0,162:12)
Block(0,24,1,162:12)
Block(0,25,0,162:12)
Block(0,26,0,162:12)
Block(0,27,0,162:12)
Block(0,28,0,162:12)
Block(0,29,0,162:12)
Block(0,30,0,162:12)
Block(0,30,5,LEAVES_2:0)
Block(0,31,-4,LEAVES_2:0)
Block(0,31,0,162:12)
Block(0,32,0,162:12)
Block(0,33,0,162:12)
Block(0,33,4,LEAVES_2:0)
Block(0,34,-2,LEAVES_2:0)
Block(0,34,-1,LEAVES_2:0)
Block(0,34,0,LEAVES_2:0)
Block(0,34,1,LEAVES_2:0)
Block(0,34,2,LEAVES_2:0)
Block(0,34,3,LEAVES_2:0)
Block(0,34,4,LEAVES_2:0)
Block(0,34,5,LEAVES_2:0)
Block(0,34,6,LEAVES_2:0)
Block(0,34,7,LEAVES_2:0)
Block(0,34,12,LEAVES_2:0)
Block(0,35,-6,LEAVES_2:0)
Block(0,35,-2,162:12)
Block(0,35,-1,LEAVES_2:0)
Block(0,35,0,LEAVES_2:0)
Block(0,35,1,LEAVES_2:0)
Block(0,35,3,162:12)
Block(0,35,4,LEAVES_2:0)
Block(0,35,5,LEAVES_2:0)
Block(0,35,7,LEAVES_2:0)
Block(0,35,8,LEAVES_2:0)
Block(0,35,9,LEAVES_2:0)
Block(0,35,11,LEAVES_2:0)
Block(0,36,-10,LEAVES_2:0)
Block(0,36,-7,LEAVES_2:0)
Block(0,36,-3,LEAVES_2:0)
Block(0,36,-2,LEAVES_2:0)
Block(0,36,2,LEAVES_2:0)
Block(0,36,3,LEAVES_2:0)
Block(0,36,4,162:12)
Block(0,36,5,162:12)
Block(0,36,6,LEAVES_2:0)
Block(0,36,7,LEAVES_2:0)
Block(0,36,10,162:12)
Block(0,36,11,LEAVES_2:0)
Block(0,36,12,LEAVES_2:0)
Block(0,37,-9,LEAVES_2:0)
Block(0,37,-8,LEAVES_2:0)
Block(0,37,-7,LEAVES_2:0)
Block(0,37,-6,LEAVES_2:0)
Block(0,37,-5,LEAVES_2:0)
Block(0,37,-4,LEAVES_2:0)
Block(0,37,0,LEAVES_2:0)
Block(0,37,1,LEAVES_2:0)
Block(0,37,3,LEAVES_2:0)
Block(0,37,4,LEAVES_2:0)
Block(0,37,5,LEAVES_2:0)
Block(0,37,6,162:12)
Block(0,37,7,LEAVES_2:0)
Block(0,37,9,LEAVES_2:0)
Block(0,37,10,LEAVES_2:0)
Block(0,38,-10,LEAVES_2:0)
Block(0,38,-8,LEAVES_2:0)
Block(0,38,-7,LEAVES_2:0)
Block(0,38,-6,LEAVES_2:0)
Block(0,38,-5,LEAVES_2:0)
Block(0,38,-4,LEAVES_2:0)
Block(0,38,-3,LEAVES_2:0)
Block(0,38,-2,LEAVES_2:0)
Block(0,38,-1,LEAVES_2:0)
Block(0,38,0,162:12)
Block(0,38,1,LEAVES_2:0)
Block(0,38,2,LEAVES_2:0)
Block(0,38,3,LEAVES_2:0)
Block(0,38,4,LEAVES_2:0)
Block(0,38,6,LEAVES_2:0)
Block(0,39,-9,LEAVES_2:0)
Block(0,39,-5,LEAVES_2:0)
Block(0,39,-4,LEAVES_2:0)
Block(0,39,-3,LEAVES_2:0)
Block(0,39,-2,LEAVES_2:0)
Block(0,39,0,LEAVES_2:0)
Block(0,39,1,LEAVES_2:0)
Block(0,39,2,LEAVES_2:0)
Block(0,39,3,162:12)
Block(0,39,4,LEAVES_2:0)
Block(0,39,5,LEAVES_2:0)
Block(0,40,-5,LEAVES_2:0)
Block(0,40,-4,LEAVES_2:0)
Block(0,40,-3,162:12)
Block(0,40,-2,LEAVES_2:0)
Block(0,40,1,LEAVES_2:0)
Block(0,40,3,LEAVES_2:0)
Block(0,40,4,LEAVES_2:0)
Block(0,41,-3,LEAVES_2:0)
Block(0,41,-2,162:12)
Block(0,41,0,LEAVES_2:0)
Block(0,41,1,LEAVES_2:0)
Block(0,42,-2,LEAVES_2:0)
Block(0,42,-1,LEAVES_2:0)
Block(0,42,1,LEAVES_2:0)
Block(0,43,-1,LEAVES_2:0)
Block(0,43,0,LEAVES_2:0)
Block(1,-6,-9,162:12)
Block(1,-6,-8,3:1)
Block(1,-6,-7,3:1)
Block(1,-6,-6,162:12)
Block(1,-6,-5,3:1)
Block(1,-6,-4,162:12)
Block(1,-6,-3,3:1)
Block(1,-6,-2,3:1)
Block(1,-6,-1,3:1)
Block(1,-6,0,3:1)
Block(1,-6,1,3:1)
Block(1,-6,2,3:1)
Block(1,-6,3,3:1)
Block(1,-6,4,162:12)
Block(1,-6,5,3:1)
Block(1,-6,6,3:1)
Block(1,-6,7,162:12)
Block(1,-6,8,3:1)
Block(1,-6,9,3:1)
Block(1,-6,10,162:12)
Block(1,-5,-8,3:1)
Block(1,-5,-7,3:1)
Block(1,-5,-6,3:1)
Block(1,-5,-5,3:1)
Block(1,-5,-4,3:1)
Block(1,-5,-3,3:1)
Block(1,-5,-2,3:1)
Block(1,-5,-1,3:1)
Block(1,-5,0,3:1)
Block(1,-5,1,3:1)
Block(1,-5,2,3:1)
Block(1,-5,3,3:1)
Block(1,-5,4,3:1)
Block(1,-5,5,3:1)
Block(1,-5,6,162:12)
Block(1,-5,7,162:12)
Block(1,-5,8,162:12)
Block(1,-5,9,3:1)
Block(1,-5,10,162:12)
Block(1,-4,-7,3:1)
Block(1,-4,-6,3:1)
Block(1,-4,-5,3:1)
Block(1,-4,-4,3:1)
Block(1,-4,-3,3:1)
Block(1,-4,-2,3:1)
Block(1,-4,-1,3:1)
Block(1,-4,0,3:1)
Block(1,-4,1,3:1)
Block(1,-4,2,162:12)
Block(1,-4,3,3:1)
Block(1,-4,4,3:1)
Block(1,-4,5,3:1)
Block(1,-4,6,162:12)
Block(1,-4,7,3:1)
Block(1,-4,8,3:1)
Block(1,-4,9,3:1)
Block(1,-3,-7,3:1)
Block(1,-3,-6,162:12)
Block(1,-3,-5,3:1)
Block(1,-3,-4,162:12)
Block(1,-3,-3,3:1)
Block(1,-3,-2,3:1)
Block(1,-3,-1,3:1)
Block(1,-3,0,162:12)
Block(1,-3,1,3:1)
Block(1,-3,2,3:1)
Block(1,-3,3,3:1)
Block(1,-3,4,3:1)
Block(1,-3,5,3:1)
Block(1,-3,6,3:1)
Block(1,-3,7,3:1)
Block(1,-3,8,3:1)
Block(1,-2,-6,162:12)
Block(1,-2,-5,3:1)
Block(1,-2,-4,3:1)
Block(1,-2,-3,3:1)
Block(1,-2,-2,3:1)
Block(1,-2,-1,3:1)
Block(1,-2,0,3:1)
Block(1,-2,1,3:1)
Block(1,-2,2,3:1)
Block(1,-2,3,3:1)
Block(1,-2,4,162:12)
Block(1,-2,5,3:1)
Block(1,-2,6,3:1)
Block(1,-2,7,3:1)
Block(1,-1,-5,162:12)
Block(1,-1,-4,3:1)
Block(1,-1,-3,162:12)
Block(1,-1,-2,3:1)
Block(1,-1,-1,3:1)
Block(1,-1,0,3:1)
Block(1,-1,1,3:1)
Block(1,-1,2,3:1)
Block(1,-1,3,162:12)
Block(1,-1,4,3:1)
Block(1,-1,5,3:1)
Block(1,-1,6,3:1)
Block(1,-1,7,3:1)
Block(1,0,-5,162:12)
Block(1,0,-3,3:1)
Block(1,0,-2,162:12)
Block(1,0,-1,3:1)
Block(1,0,0,3:1)
Block(1,0,1,162:12)
Block(1,0,2,3:1)
Block(1,0,3,162:12)
Block(1,0,4,3:1)
Block(1,0,5,162:12)
Block(1,0,6,3:1)
Block(1,1,-2,162:12)
Block(1,1,-1,3:1)
Block(1,1,0,3:1)
Block(1,1,1,162:12)
Block(1,1,2,3:1)
Block(1,1,3,3:1)
Block(1,1,4,3:1)
Block(1,1,5,162:12)
Block(1,2,-3,162:12)
Block(1,2,-2,162:12)
Block(1,2,-1,3:1)
Block(1,2,0,3:1)
Block(1,3,-2,162:12)
Block(1,4,2,162:12)
Block(1,5,2,162:12)
Block(1,6,2,162:12)
Block(1,7,2,162:12)
Block(1,8,2,162:12)
Block(1,9,2,162:12)
Block(1,10,2,162:12)
Block(1,11,2,162:12)
Block(1,12,2,162:12)
Block(1,16,2,162:12)
Block(1,22,-1,162:12)
Block(1,28,0,162:12)
Block(1,29,0,162:12)
Block(1,29,4,LEAVES_2:0)
Block(1,29,6,LEAVES_2:0)
Block(1,30,3,LEAVES_2:0)
Block(1,30,4,LEAVES_2:0)
Block(1,31,5,LEAVES_2:0)
Block(1,31,6,LEAVES_2:0)
Block(1,33,1,LEAVES_2:0)
Block(1,33,2,LEAVES_2:0)
Block(1,33,8,LEAVES_2:0)
Block(1,34,-1,LEAVES_2:0)
Block(1,34,0,LEAVES_2:0)
Block(1,34,1,162:12)
Block(1,34,3,LEAVES_2:0)
Block(1,34,4,LEAVES_2:0)
Block(1,34,5,LEAVES_2:0)
Block(1,34,7,LEAVES_2:0)
Block(1,34,9,LEAVES_2:0)
Block(1,35,-3,LEAVES_2:0)
Block(1,35,-2,162:12)
Block(1,35,2,162:12)
Block(1,35,4,LEAVES_2:0)
Block(1,35,6,LEAVES_2:0)
Block(1,35,7,LEAVES_2:0)
Block(1,35,11,LEAVES_2:0)
Block(1,35,12,LEAVES_2:0)
Block(1,36,-5,LEAVES_2:0)
Block(1,36,-4,LEAVES_2:0)
Block(1,36,-2,162:12)
Block(1,36,-1,LEAVES_2:0)
Block(1,36,1,LEAVES_2:0)
Block(1,36,2,LEAVES_2:0)
Block(1,36,3,LEAVES_2:0)
Block(1,36,5,LEAVES_2:0)
Block(1,36,7,LEAVES_2:0)
Block(1,36,8,LEAVES_2:0)
Block(1,36,10,LEAVES_2:0)
Block(1,36,11,162:12)
Block(1,36,13,LEAVES_2:0)
Block(1,37,-10,LEAVES_2:0)
Block(1,37,-9,LEAVES_2:0)
Block(1,37,-8,LEAVES_2:0)
Block(1,37,-7,LEAVES_2:0)
Block(1,37,-6,LEAVES_2:0)
Block(1,37,-5,162:12)
Block(1,37,-4,LEAVES_2:0)
Block(1,37,-3,LEAVES_2:0)
Block(1,37,-2,LEAVES_2:0)
Block(1,37,0,LEAVES_2:0)
Block(1,37,2,LEAVES_2:0)
Block(1,37,3,LEAVES_2:0)
Block(1,37,4,LEAVES_2:0)
Block(1,37,5,LEAVES_2:0)
Block(1,37,6,LEAVES_2:0)
Block(1,37,9,LEAVES_2:0)
Block(1,37,11,LEAVES_2:0)
Block(1,37,12,LEAVES_2:0)
Block(1,38,-9,LEAVES_2:0)
Block(1,38,-8,LEAVES_2:0)
Block(1,38,-6,162:12)
Block(1,38,-5,LEAVES_2:0)
Block(1,38,0,LEAVES_2:0)
Block(1,38,2,LEAVES_2:0)
Block(1,38,3,LEAVES_2:0)
Block(1,38,4,LEAVES_2:0)
Block(1,38,5,LEAVES_2:0)
Block(1,38,10,LEAVES_2:0)
Block(1,39,-7,LEAVES_2:0)
Block(1,39,-6,LEAVES_2:0)
Block(1,39,-4,LEAVES_2:0)
Block(1,39,-2,LEAVES_2:0)
Block(1,39,-1,LEAVES_2:0)
Block(1,39,0,162:12)
Block(1,39,2,LEAVES_2:0)
Block(1,39,3,LEAVES_2:0)
Block(1,39,4,LEAVES_2:0)
Block(1,39,5,LEAVES_2:0)
Block(1,40,-8,LEAVES_2:0)
Block(1,40,-4,LEAVES_2:0)
Block(1,40,-2,LEAVES_2:0)
Block(1,40,0,LEAVES_2:0)
Block(1,40,1,LEAVES_2:0)
Block(1,40,3,LEAVES_2:0)
Block(1,40,4,162:12)
Block(1,40,5,LEAVES_2:0)
Block(1,41,-3,LEAVES_2:0)
Block(1,41,-2,LEAVES_2:0)
Block(1,41,-1,LEAVES_2:0)
Block(1,41,4,LEAVES_2:0)
Block(1,42,-3,LEAVES_2:0)
Block(1,42,-2,LEAVES_2:0)
Block(1,42,-1,162:12)
Block(1,42,0,162:12)
Block(1,42,2,LEAVES_2:0)
Block(1,43,-2,LEAVES_2:0)
Block(1,43,0,LEAVES_2:0)
Block(1,43,1,LEAVES_2:0)
Block(1,44,-1,LEAVES_2:0)
Block(2,-6,-8,3:1)
Block(2,-6,-7,3:1)
Block(2,-6,-6,3:1)
Block(2,-6,-5,3:1)
Block(2,-6,-4,3:1)
Block(2,-6,-3,162:12)
Block(2,-6,-2,162:12)
Block(2,-6,-1,162:12)
Block(2,-6,0,3:1)
Block(2,-6,1,3:1)
Block(2,-6,2,3:1)
Block(2,-6,3,162:12)
Block(2,-6,4,3:1)
Block(2,-6,5,3:1)
Block(2,-6,6,162:12)
Block(2,-6,7,3:1)
Block(2,-6,8,3:1)
Block(2,-6,9,3:1)
Block(2,-6,10,3:1)
Block(2,-5,-7,162:12)
Block(2,-5,-6,3:1)
Block(2,-5,-5,3:1)
Block(2,-5,-4,3:1)
Block(2,-5,-3,162:12)
Block(2,-5,-2,3:1)
Block(2,-5,-1,162:12)
Block(2,-5,0,3:1)
Block(2,-5,1,3:1)
Block(2,-5,2,162:12)
Block(2,-5,3,3:1)
Block(2,-5,4,3:1)
Block(2,-5,5,3:1)
Block(2,-5,6,3:1)
Block(2,-5,7,3:1)
Block(2,-5,8,3:1)
Block(2,-5,9,3:1)
Block(2,-4,-7,162:12)
Block(2,-4,-6,3:1)
Block(2,-4,-5,3:1)
Block(2,-4,-4,3:1)
Block(2,-4,-3,3:1)
Block(2,-4,-2,162:12)
Block(2,-4,-1,3:1)
Block(2,-4,0,162:12)
Block(2,-4,1,3:1)
Block(2,-4,2,3:1)
Block(2,-4,3,3:1)
Block(2,-4,4,3:1)
Block(2,-4,5,3:1)
Block(2,-4,6,3:1)
Block(2,-4,7,3:1)
Block(2,-4,8,3:1)
Block(2,-4,9,162:12)
Block(2,-3,-6,3:1)
Block(2,-3,-5,3:1)
Block(2,-3,-4,3:1)
Block(2,-3,-3,3:1)
Block(2,-3,-2,3:1)
Block(2,-3,-1,3:1)
Block(2,-3,0,3:1)
Block(2,-3,1,3:1)
Block(2,-3,2,3:1)
Block(2,-3,3,3:1)
Block(2,-3,4,3:1)
Block(2,-3,5,162:12)
Block(2,-3,6,3:1)
Block(2,-3,7,3:1)
Block(2,-3,8,162:12)
Block(2,-2,-5,3:1)
Block(2,-2,-4,162:12)
Block(2,-2,-3,3:1)
Block(2,-2,-2,3:1)
Block(2,-2,-1,3:1)
Block(2,-2,0,162:12)
Block(2,-2,1,3:1)
Block(2,-2,2,3:1)
Block(2,-2,3,3:1)
Block(2,-2,4,162:12)
Block(2,-2,5,3:1)
Block(2,-2,6,3:1)
Block(2,-2,7,3:1)
Block(2,-2,8,3:1)
Block(2,-1,-4,162:12)
Block(2,-1,-3,3:1)
Block(2,-1,-2,3:1)
Block(2,-1,-1,3:1)
Block(2,-1,0,3:1)
Block(2,-1,1,3:1)
Block(2,-1,2,3:1)
Block(2,-1,3,3:1)
Block(2,-1,4,162:12)
Block(2,-1,5,3:1)
Block(2,-1,6,3:1)
Block(2,0,-5,162:12)
Block(2,0,-3,3:1)
Block(2,0,-2,3:1)
Block(2,0,-1,3:1)
Block(2,0,0,3:1)
Block(2,0,1,3:1)
Block(2,0,2,3:1)
Block(2,0,3,3:1)
Block(2,0,4,3:1)
Block(2,0,5,3:1)
Block(2,0,6,162:12)
Block(2,1,-3,162:12)
Block(2,1,-2,3:1)
Block(2,1,-1,3:1)
Block(2,1,0,3:1)
Block(2,1,1,3:1)
Block(2,1,2,162:12)
Block(2,1,3,3:1)
Block(2,1,4,162:12)
Block(2,2,1,162:12)
Block(2,2,2,162:12)
Block(2,3,-1,162:12)
Block(2,3,2,162:12)
Block(2,4,2,162:12)
Block(2,17,2,162:12)
Block(2,23,-2,162:12)
Block(2,24,-3,162:12)
Block(2,29,1,162:12)
Block(2,29,3,LEAVES_2:0)
Block(2,30,1,LEAVES_2:0)
Block(2,30,2,LEAVES_2:0)
Block(2,30,3,162:12)
Block(2,30,4,162:12)
Block(2,30,5,LEAVES_2:0)
Block(2,30,6,LEAVES_2:0)
Block(2,31,3,LEAVES_2:0)
Block(2,31,4,LEAVES_2:0)
Block(2,31,5,162:12)
Block(2,31,7,LEAVES_2:0)
Block(2,32,5,LEAVES_2:0)
Block(2,32,6,LEAVES_2:0)
Block(2,33,7,LEAVES_2:0)
Block(2,34,-2,LEAVES_2:0)
Block(2,34,1,LEAVES_2:0)
Block(2,34,2,162:12)
Block(2,34,3,LEAVES_2:0)
Block(2,34,4,LEAVES_2:0)
Block(2,34,5,LEAVES_2:0)
Block(2,34,6,LEAVES_2:0)
Block(2,34,11,LEAVES_2:0)
Block(2,35,-4,LEAVES_2:0)
Block(2,35,-3,LEAVES_2:0)
Block(2,35,-1,LEAVES_2:0)
Block(2,35,0,LEAVES_2:0)
Block(2,35,2,LEAVES_2:0)
Block(2,35,3,LEAVES_2:0)
Block(2,35,5,LEAVES_2:0)
Block(2,35,6,162:12)
Block(2,35,7,LEAVES_2:0)
Block(2,35,9,LEAVES_2:0)
Block(2,35,13,LEAVES_2:0)
Block(2,36,-3,LEAVES_2:0)
Block(2,36,-2,162:12)
Block(2,36,-1,162:12)
Block(2,36,0,LEAVES_2:0)
Block(2,36,4,LEAVES_2:0)
Block(2,36,5,LEAVES_2:0)
Block(2,36,6,LEAVES_2:0)
Block(2,36,7,162:12)
Block(2,36,8,LEAVES_2:0)
Block(2,36,9,LEAVES_2:0)
Block(2,36,11,LEAVES_2:0)
Block(2,36,12,LEAVES_2:0)
Block(2,37,-11,LEAVES_2:0)
Block(2,37,-9,LEAVES_2:0)
Block(2,37,-8,LEAVES_2:0)
Block(2,37,-6,LEAVES_2:0)
Block(2,37,-5,LEAVES_2:0)
Block(2,37,-4,162:12)
Block(2,37,-3,162:12)
Block(2,37,-2,LEAVES_2:0)
Block(2,37,-1,LEAVES_2:0)
Block(2,37,0,LEAVES_2:0)
Block(2,37,5,LEAVES_2:0)
Block(2,37,6,LEAVES_2:0)
Block(2,37,7,LEAVES_2:0)
Block(2,37,10,LEAVES_2:0)
Block(2,38,-10,LEAVES_2:0)
Block(2,38,-8,162:12)
Block(2,38,-7,162:12)
Block(2,38,-6,LEAVES_2:0)
Block(2,38,-4,LEAVES_2:0)
Block(2,38,-3,LEAVES_2:0)
Block(2,38,-1,LEAVES_2:0)
Block(2,38,0,LEAVES_2:0)
Block(2,38,1,LEAVES_2:0)
Block(2,38,5,LEAVES_2:0)
Block(2,39,-9,LEAVES_2:0)
Block(2,39,-8,LEAVES_2:0)
Block(2,39,-7,LEAVES_2:0)
Block(2,39,-5,LEAVES_2:0)
Block(2,39,-2,LEAVES_2:0)
Block(2,39,-1,162:12)
Block(2,39,0,LEAVES_2:0)
Block(2,39,1,162:12)
Block(2,39,2,LEAVES_2:0)
Block(2,39,3,LEAVES_2:0)
Block(2,39,5,LEAVES_2:0)
Block(2,40,-6,LEAVES_2:0)
Block(2,40,-3,LEAVES_2:0)
Block(2,40,-2,LEAVES_2:0)
Block(2,40,-1,LEAVES_2:0)
Block(2,40,0,LEAVES_2:0)
Block(2,40,1,LEAVES_2:0)
Block(2,40,4,LEAVES_2:0)
Block(2,40,5,162:12)
Block(2,40,6,LEAVES_2:0)
Block(2,41,-4,LEAVES_2:0)
Block(2,41,0,LEAVES_2:0)
Block(2,41,3,LEAVES_2:0)
Block(2,41,5,LEAVES_2:0)
Block(2,42,-2,LEAVES_2:0)
Block(2,42,0,LEAVES_2:0)
Block(2,42,1,LEAVES_2:0)
Block(2,42,4,LEAVES_2:0)
Block(2,43,-1,LEAVES_2:0)
Block(3,-6,-8,162:12)
Block(3,-6,-7,3:1)
Block(3,-6,-6,162:12)
Block(3,-6,-5,3:1)
Block(3,-6,-4,3:1)
Block(3,-6,-3,3:1)
Block(3,-6,-2,3:1)
Block(3,-6,-1,3:1)
Block(3,-6,0,3:1)
Block(3,-6,1,162:12)
Block(3,-6,2,3:1)
Block(3,-6,3,3:1)
Block(3,-6,4,162:12)
Block(3,-6,5,162:12)
Block(3,-6,6,3:1)
Block(3,-6,7,3:1)
Block(3,-6,8,162:12)
Block(3,-6,9,162:12)
Block(3,-6,10,3:1)
Block(3,-6,11,3:1)
Block(3,-5,-8,162:12)
Block(3,-5,-7,3:1)
Block(3,-5,-6,3:1)
Block(3,-5,-5,3:1)
Block(3,-5,-4,3:1)
Block(3,-5,-3,3:1)
Block(3,-5,-2,3:1)
Block(3,-5,-1,3:1)
Block(3,-5,0,3:1)
Block(3,-5,1,162:12)
Block(3,-5,2,3:1)
Block(3,-5,3,3:1)
Block(3,-5,4,162:12)
Block(3,-5,5,3:1)
Block(3,-5,6,3:1)
Block(3,-5,7,3:1)
Block(3,-5,8,3:1)
Block(3,-5,9,162:12)
Block(3,-4,-7,3:1)
Block(3,-4,-6,3:1)
Block(3,-4,-5,3:1)
Block(3,-4,-4,3:1)
Block(3,-4,-3,3:1)
Block(3,-4,-2,3:1)
Block(3,-4,-1,3:1)
Block(3,-4,0,3:1)
Block(3,-4,1,3:1)
Block(3,-4,2,3:1)
Block(3,-4,3,3:1)
Block(3,-4,4,3:1)
Block(3,-4,5,3:1)
Block(3,-4,6,3:1)
Block(3,-4,7,3:1)
Block(3,-4,8,3:1)
Block(3,-4,9,3:1)
Block(3,-3,-5,162:12)
Block(3,-3,-4,3:1)
Block(3,-3,-3,3:1)
Block(3,-3,-2,162:12)
Block(3,-3,-1,3:1)
Block(3,-3,0,3:1)
Block(3,-3,1,3:1)
Block(3,-3,2,3:1)
Block(3,-3,3,3:1)
Block(3,-3,4,3:1)
Block(3,-3,5,3:1)
Block(3,-3,6,3:1)
Block(3,-3,7,3:1)
Block(3,-3,8,3:1)
Block(3,-2,-5,162:12)
Block(3,-2,-4,3:1)
Block(3,-2,-3,3:1)
Block(3,-2,-2,3:1)
Block(3,-2,-1,162:12)
Block(3,-2,0,3:1)
Block(3,-2,1,3:1)
Block(3,-2,2,3:1)
Block(3,-2,3,3:1)
Block(3,-2,4,3:1)
Block(3,-2,5,3:1)
Block(3,-2,6,3:1)
Block(3,-2,7,162:12)
Block(3,-2,8,3:1)
Block(3,-1,-4,3:1)
Block(3,-1,-3,3:1)
Block(3,-1,-2,3:1)
Block(3,-1,-1,162:12)
Block(3,-1,0,162:12)
Block(3,-1,1,3:1)
Block(3,-1,2,162:12)
Block(3,-1,3,3:1)
Block(3,-1,4,3:1)
Block(3,-1,5,3:1)
Block(3,-1,6,3:1)
Block(3,-1,7,162:12)
Block(3,0,-3,3:1)
Block(3,0,-2,162:12)
Block(3,0,-1,162:12)
Block(3,0,0,3:1)
Block(3,0,1,3:1)
Block(3,0,2,162:12)
Block(3,0,3,3:1)
Block(3,0,4,3:1)
Block(3,0,5,3:1)
Block(3,0,7,162:12)
Block(3,1,-1,162:12)
Block(3,1,0,162:12)
Block(3,1,1,3:1)
Block(3,1,2,3:1)
Block(3,2,0,162:12)
Block(3,2,1,162:12)
Block(3,2,3,162:12)
Block(3,2,4,162:12)
Block(3,3,0,162:12)
Block(3,3,2,162:12)
Block(3,3,3,162:12)
Block(3,18,3,162:12)
Block(3,19,3,162:12)
Block(3,25,-3,162:12)
Block(3,29,-1,LEAVES_2:0)
Block(3,29,1,LEAVES_2:0)
Block(3,29,2,162:12)
Block(3,29,4,LEAVES_2:0)
Block(3,30,0,LEAVES_2:0)
Block(3,30,2,162:12)
Block(3,30,3,LEAVES_2:0)
Block(3,30,5,LEAVES_2:0)
Block(3,30,7,LEAVES_2:0)
Block(3,31,1,LEAVES_2:0)
Block(3,31,2,LEAVES_2:0)
Block(3,31,3,LEAVES_2:0)
Block(3,31,5,LEAVES_2:0)
Block(3,31,6,LEAVES_2:0)
Block(3,33,1,LEAVES_2:0)
Block(3,33,3,LEAVES_2:0)
Block(3,33,6,LEAVES_2:0)
Block(3,34,0,LEAVES_2:0)
Block(3,34,2,LEAVES_2:0)
Block(3,34,3,162:12)
Block(3,34,5,LEAVES_2:0)
Block(3,34,9,LEAVES_2:0)
Block(3,34,12,LEAVES_2:0)
Block(3,35,-4,LEAVES_2:0)
Block(3,35,-2,LEAVES_2:0)
Block(3,35,-1,LEAVES_2:0)
Block(3,35,1,LEAVES_2:0)
Block(3,35,2,LEAVES_2:0)
Block(3,35,3,LEAVES_2:0)
Block(3,35,4,162:12)
Block(3,35,5,162:12)
Block(3,35,6,LEAVES_2:0)
Block(3,35,7,LEAVES_2:0)
Block(3,35,8,LEAVES_2:0)
Block(3,35,11,LEAVES_2:0)
Block(3,36,-9,LEAVES_2:0)
Block(3,36,-5,LEAVES_2:0)
Block(3,36,-3,LEAVES_2:0)
Block(3,36,-2,162:12)
Block(3,36,0,LEAVES_2:0)
Block(3,36,4,LEAVES_2:0)
Block(3,36,5,LEAVES_2:0)
Block(3,36,6,LEAVES_2:0)
Block(3,36,8,162:12)
Block(3,36,9,LEAVES_2:0)
Block(3,36,10,LEAVES_2:0)
Block(3,37,-10,LEAVES_2:0)
Block(3,37,-7,LEAVES_2:0)
Block(3,37,-5,LEAVES_2:0)
Block(3,37,-4,LEAVES_2:0)
Block(3,37,-2,LEAVES_2:0)
Block(3,37,-1,LEAVES_2:0)
Block(3,37,0,162:12)
Block(3,37,1,LEAVES_2:0)
Block(3,37,7,LEAVES_2:0)
Block(3,37,8,LEAVES_2:0)
Block(3,38,-9,LEAVES_2:0)
Block(3,38,-8,LEAVES_2:0)
Block(3,38,-6,LEAVES_2:0)
Block(3,38,-5,LEAVES_2:0)
Block(3,38,-3,LEAVES_2:0)
Block(3,38,0,LEAVES_2:0)
Block(3,38,3,LEAVES_2:0)
Block(3,38,4,LEAVES_2:0)
Block(3,38,6,LEAVES_2:0)
Block(3,39,-7,LEAVES_2:0)
Block(3,39,-5,LEAVES_2:0)
Block(3,39,-3,LEAVES_2:0)
Block(3,39,-2,LEAVES_2:0)
Block(3,39,-1,LEAVES_2:0)
Block(3,39,1,LEAVES_2:0)
Block(3,39,2,162:12)
Block(3,39,3,162:12)
Block(3,39,5,LEAVES_2:0)
Block(3,40,-4,LEAVES_2:0)
Block(3,40,-3,LEAVES_2:0)
Block(3,40,-2,162:12)
Block(3,40,0,LEAVES_2:0)
Block(3,40,1,LEAVES_2:0)
Block(3,40,2,LEAVES_2:0)
Block(3,40,3,LEAVES_2:0)
Block(3,40,4,LEAVES_2:0)
Block(3,40,6,LEAVES_2:0)
Block(3,41,-2,LEAVES_2:0)
Block(3,41,-1,LEAVES_2:0)
Block(3,41,5,LEAVES_2:0)
Block(3,42,-1,LEAVES_2:0)
Block(4,-6,-8,3:1)
Block(4,-6,-7,3:1)
Block(4,-6,-6,162:12)
Block(4,-6,-5,3:1)
Block(4,-6,-4,3:1)
Block(4,-6,-3,162:12)
Block(4,-6,-2,3:1)
Block(4,-6,-1,3:1)
Block(4,-6,0,3:1)
Block(4,-6,1,3:1)
Block(4,-6,2,162:12)
Block(4,-6,3,3:1)
Block(4,-6,4,3:1)
Block(4,-6,5,3:1)
Block(4,-6,6,162:12)
Block(4,-6,7,3:1)
Block(4,-6,8,3:1)
Block(4,-6,9,3:1)
Block(4,-6,10,162:12)
Block(4,-6,11,3:1)
Block(4,-6,12,3:1)
Block(4,-5,-6,162:12)
Block(4,-5,-5,3:1)
Block(4,-5,-4,3:1)
Block(4,-5,-3,3:1)
Block(4,-5,-2,3:1)
Block(4,-5,-1,3:1)
Block(4,-5,0,3:1)
Block(4,-5,1,3:1)
Block(4,-5,2,3:1)
Block(4,-5,3,3:1)
Block(4,-5,4,3:1)
Block(4,-5,5,3:1)
Block(4,-5,6,162:12)
Block(4,-5,7,3:1)
Block(4,-5,8,3:1)
Block(4,-5,9,162:12)
Block(4,-5,10,3:1)
Block(4,-4,-6,3:1)
Block(4,-4,-5,162:12)
Block(4,-4,-4,3:1)
Block(4,-4,-3,162:12)
Block(4,-4,-2,3:1)
Block(4,-4,-1,3:1)
Block(4,-4,0,3:1)
Block(4,-4,1,3:1)
Block(4,-4,2,3:1)
Block(4,-4,3,3:1)
Block(4,-4,4,3:1)
Block(4,-4,5,162:12)
Block(4,-4,6,3:1)
Block(4,-4,7,3:1)
Block(4,-4,8,3:1)
Block(4,-4,9,162:12)
Block(4,-4,10,3:1)
Block(4,-3,-6,3:1)
Block(4,-3,-5,3:1)
Block(4,-3,-4,162:12)
Block(4,-3,-3,3:1)
Block(4,-3,-2,162:12)
Block(4,-3,-1,3:1)
Block(4,-3,0,3:1)
Block(4,-3,1,3:1)
Block(4,-3,2,3:1)
Block(4,-3,3,3:1)
Block(4,-3,4,162:12)
Block(4,-3,5,3:1)
Block(4,-3,6,3:1)
Block(4,-3,7,162:12)
Block(4,-3,8,3:1)
Block(4,-2,-4,162:12)
Block(4,-2,-3,3:1)
Block(4,-2,-2,3:1)
Block(4,-2,-1,3:1)
Block(4,-2,0,3:1)
Block(4,-2,1,162:12)
Block(4,-2,2,3:1)
Block(4,-2,3,162:12)
Block(4,-2,4,3:1)
Block(4,-2,5,3:1)
Block(4,-2,6,3:1)
Block(4,-2,7,3:1)
Block(4,-2,8,3:1)
Block(4,-1,-4,3:1)
Block(4,-1,-3,162:12)
Block(4,-1,-2,3:1)
Block(4,-1,-1,3:1)
Block(4,-1,0,162:12)
Block(4,-1,1,3:1)
Block(4,-1,2,3:1)
Block(4,-1,3,162:12)
Block(4,-1,4,3:1)
Block(4,-1,5,3:1)
Block(4,-1,6,3:1)
Block(4,-1,7,3:1)
Block(4,0,-3,162:12)
Block(4,0,-2,3:1)
Block(4,0,-1,3:1)
Block(4,0,0,162:12)
Block(4,0,1,3:1)
Block(4,0,2,3:1)
Block(4,0,3,3:1)
Block(4,0,4,3:1)
Block(4,1,0,3:1)
Block(4,1,4,162:12)
Block(4,1,5,162:12)
Block(4,3,1,162:12)
Block(4,20,3,162:12)
Block(4,21,3,162:12)
Block(4,29,5,LEAVES_2:0)
Block(4,30,0,LEAVES_2:0)
Block(4,30,2,162:12)
Block(4,30,3,LEAVES_2:0)
Block(4,30,4,LEAVES_2:0)
Block(4,31,1,LEAVES_2:0)
Block(4,31,2,LEAVES_2:0)
Block(4,34,1,LEAVES_2:0)
Block(4,34,3,LEAVES_2:0)
Block(4,34,5,LEAVES_2:0)
Block(4,34,7,LEAVES_2:0)
Block(4,35,-5,LEAVES_2:0)
Block(4,35,-2,LEAVES_2:0)
Block(4,35,0,LEAVES_2:0)
Block(4,35,2,LEAVES_2:0)
Block(4,35,3,162:12)
Block(4,35,10,LEAVES_2:0)
Block(4,36,-4,LEAVES_2:0)
Block(4,36,-3,162:12)
Block(4,36,-2,LEAVES_2:0)
Block(4,36,-1,LEAVES_2:0)
Block(4,36,3,LEAVES_2:0)
Block(4,36,4,LEAVES_2:0)
Block(4,36,5,LEAVES_2:0)
Block(4,36,7,LEAVES_2:0)
Block(4,36,8,LEAVES_2:0)
Block(4,36,9,162:12)
Block(4,36,11,LEAVES_2:0)
Block(4,37,-10,LEAVES_2:0)
Block(4,37,-8,LEAVES_2:0)
Block(4,37,-6,LEAVES_2:0)
Block(4,37,-5,LEAVES_2:0)
Block(4,37,-4,LEAVES_2:0)
Block(4,37,-3,LEAVES_2:0)
Block(4,37,-2,LEAVES_2:0)
Block(4,37,0,162:12)
Block(4,37,1,LEAVES_2:0)
Block(4,37,2,LEAVES_2:0)
Block(4,37,4,LEAVES_2:0)
Block(4,37,6,LEAVES_2:0)
Block(4,37,8,LEAVES_2:0)
Block(4,37,9,LEAVES_2:0)
Block(4,37,10,LEAVES_2:0)
Block(4,38,-7,LEAVES_2:0)
Block(4,38,-5,LEAVES_2:0)
Block(4,38,-4,LEAVES_2:0)
Block(4,38,-3,LEAVES_2:0)
Block(4,38,-2,LEAVES_2:0)
Block(4,38,-1,LEAVES_2:0)
Block(4,38,0,LEAVES_2:0)
Block(4,38,2,LEAVES_2:0)
Block(4,38,7,LEAVES_2:0)
Block(4,39,-4,LEAVES_2:0)
Block(4,39,-3,LEAVES_2:0)
Block(4,39,-2,LEAVES_2:0)
Block(4,39,1,LEAVES_2:0)
Block(4,39,2,162:12)
Block(4,39,3,LEAVES_2:0)
Block(4,39,4,LEAVES_2:0)
Block(4,40,-4,LEAVES_2:0)
Block(4,40,-3,162:12)
Block(4,40,-1,LEAVES_2:0)
Block(4,40,0,LEAVES_2:0)
Block(4,40,1,LEAVES_2:0)
Block(4,40,2,LEAVES_2:0)
Block(4,40,3,LEAVES_2:0)
Block(4,40,5,LEAVES_2:0)
Block(4,41,-3,LEAVES_2:0)
Block(4,41,-2,LEAVES_2:0)
Block(4,41,4,LEAVES_2:0)
Block(5,-6,-7,3:1)
Block(5,-6,-6,3:1)
Block(5,-6,-5,3:1)
Block(5,-6,-4,162:12)
Block(5,-6,-3,162:12)
Block(5,-6,-2,3:1)
Block(5,-6,-1,3:1)
Block(5,-6,0,3:1)
Block(5,-6,1,162:12)
Block(5,-6,2,3:1)
Block(5,-6,3,3:1)
Block(5,-6,4,3:1)
Block(5,-6,5,3:1)
Block(5,-6,6,3:1)
Block(5,-6,7,3:1)
Block(5,-6,8,3:1)
Block(5,-6,9,3:1)
Block(5,-6,10,3:1)
Block(5,-6,11,3:1)
Block(5,-6,12,3:1)
Block(5,-5,-6,3:1)
Block(5,-5,-5,3:1)
Block(5,-5,-4,162:12)
Block(5,-5,-3,162:12)
Block(5,-5,-2,3:1)
Block(5,-5,-1,162:12)
Block(5,-5,0,3:1)
Block(5,-5,1,3:1)
Block(5,-5,2,3:1)
Block(5,-5,3,3:1)
Block(5,-5,4,3:1)
Block(5,-5,5,3:1)
Block(5,-5,6,3:1)
Block(5,-5,7,3:1)
Block(5,-5,8,3:1)
Block(5,-5,9,3:1)
Block(5,-5,10,3:1)
Block(5,-5,11,3:1)
Block(5,-4,-6,3:1)
Block(5,-4,-5,3:1)
Block(5,-4,-4,3:1)
Block(5,-4,-3,3:1)
Block(5,-4,-2,3:1)
Block(5,-4,-1,162:12)
Block(5,-4,0,3:1)
Block(5,-4,1,3:1)
Block(5,-4,2,3:1)
Block(5,-4,3,3:1)
Block(5,-4,4,3:1)
Block(5,-4,5,3:1)
Block(5,-4,6,3:1)
Block(5,-4,7,3:1)
Block(5,-4,8,162:12)
Block(5,-4,9,3:1)
Block(5,-3,-4,3:1)
Block(5,-3,-3,3:1)
Block(5,-3,-2,3:1)
Block(5,-3,-1,3:1)
Block(5,-3,0,162:12)
Block(5,-3,1,3:1)
Block(5,-3,2,3:1)
Block(5,-3,3,3:1)
Block(5,-3,4,162:12)
Block(5,-3,5,3:1)
Block(5,-3,6,3:1)
Block(5,-3,7,3:1)
Block(5,-3,8,162:12)
Block(5,-2,-3,162:12)
Block(5,-2,-2,3:1)
Block(5,-2,-1,3:1)
Block(5,-2,0,162:12)
Block(5,-2,1,3:1)
Block(5,-2,2,3:1)
Block(5,-2,3,3:1)
Block(5,-2,4,3:1)
Block(5,-2,5,3:1)
Block(5,-2,6,162:12)
Block(5,-2,7,3:1)
Block(5,-1,-2,3:1)
Block(5,-1,-1,3:1)
Block(5,-1,0,3:1)
Block(5,-1,1,162:12)
Block(5,-1,2,3:1)
Block(5,-1,3,3:1)
Block(5,-1,4,3:1)
Block(5,-1,5,3:1)
Block(5,-1,6,162:12)
Block(5,-1,7,3:1)
Block(5,0,-1,3:1)
Block(5,0,0,3:1)
Block(5,0,1,162:12)
Block(5,0,2,3:1)
Block(5,0,3,3:1)
Block(5,0,4,162:12)
Block(5,0,6,162:12)
Block(5,1,6,162:12)
Block(5,2,0,162:12)
Block(5,3,0,162:12)
Block(5,29,0,LEAVES_2:0)
Block(5,29,2,LEAVES_2:0)
Block(5,29,4,LEAVES_2:0)
Block(5,30,1,LEAVES_2:0)
Block(5,30,3,LEAVES_2:0)
Block(5,31,0,LEAVES_2:0)
Block(5,31,2,162:12)
Block(5,31,3,LEAVES_2:0)
Block(5,31,4,LEAVES_2:0)
Block(5,32,2,LEAVES_2:0)
Block(5,33,5,LEAVES_2:0)
Block(5,34,-2,LEAVES_2:0)
Block(5,34,0,LEAVES_2:0)
Block(5,34,2,LEAVES_2:0)
Block(5,34,6,LEAVES_2:0)
Block(5,34,12,LEAVES_2:0)
Block(5,35,-3,LEAVES_2:0)
Block(5,35,1,LEAVES_2:0)
Block(5,35,3,162:12)
Block(5,35,4,LEAVES_2:0)
Block(5,35,5,LEAVES_2:0)
Block(5,35,9,LEAVES_2:0)
Block(5,35,11,LEAVES_2:0)
Block(5,36,-9,LEAVES_2:0)
Block(5,36,-6,LEAVES_2:0)
Block(5,36,-5,LEAVES_2:0)
Block(5,36,-4,LEAVES_2:0)
Block(5,36,-2,LEAVES_2:0)
Block(5,36,1,LEAVES_2:0)
Block(5,36,2,LEAVES_2:0)
Block(5,36,3,LEAVES_2:0)
Block(5,36,6,LEAVES_2:0)
Block(5,36,8,LEAVES_2:0)
Block(5,36,10,LEAVES_2:0)
Block(5,37,-7,LEAVES_2:0)
Block(5,37,-4,162:12)
Block(5,37,-3,LEAVES_2:0)
Block(5,37,-2,LEAVES_2:0)
Block(5,37,-1,LEAVES_2:0)
Block(5,37,0,LEAVES_2:0)
Block(5,37,1,162:12)
Block(5,37,3,LEAVES_2:0)
Block(5,37,7,LEAVES_2:0)
Block(5,37,9,LEAVES_2:0)
Block(5,38,-6,LEAVES_2:0)
Block(5,38,-4,LEAVES_2:0)
Block(5,38,-2,LEAVES_2:0)
Block(5,38,1,LEAVES_2:0)
Block(5,38,2,LEAVES_2:0)
Block(5,39,-5,LEAVES_2:0)
Block(5,39,-1,LEAVES_2:0)
Block(5,39,3,LEAVES_2:0)
Block(5,40,-3,LEAVES_2:0)
Block(5,40,-2,LEAVES_2:0)
Block(5,40,0,LEAVES_2:0)
Block(5,40,1,162:12)
Block(5,40,2,LEAVES_2:0)
Block(5,40,4,LEAVES_2:0)
Block(5,41,1,LEAVES_2:0)
Block(6,-6,-7,3:1)
Block(6,-6,-6,162:12)
Block(6,-6,-5,3:1)
Block(6,-6,-4,162:12)
Block(6,-6,-3,3:1)
Block(6,-6,-2,162:12)
Block(6,-6,-1,162:12)
Block(6,-6,0,162:12)
Block(6,-6,1,3:1)
Block(6,-6,2,3:1)
Block(6,-6,3,3:1)
Block(6,-6,4,3:1)
Block(6,-6,5,162:12)
Block(6,-6,6,3:1)
Block(6,-6,7,3:1)
Block(6,-6,8,3:1)
Block(6,-6,9,3:1)
Block(6,-6,10,3:1)
Block(6,-6,11,162:12)
Block(6,-6,12,3:1)
Block(6,-5,-6,162:12)
Block(6,-5,-5,3:1)
Block(6,-5,-4,3:1)
Block(6,-5,-3,3:1)
Block(6,-5,-2,3:1)
Block(6,-5,-1,162:12)
Block(6,-5,0,3:1)
Block(6,-5,1,3:1)
Block(6,-5,2,3:1)
Block(6,-5,3,3:1)
Block(6,-5,4,3:1)
Block(6,-5,5,162:12)
Block(6,-5,6,3:1)
Block(6,-5,7,3:1)
Block(6,-5,8,3:1)
Block(6,-5,9,3:1)
Block(6,-5,10,3:1)
Block(6,-5,11,3:1)
Block(6,-4,-5,3:1)
Block(6,-4,-4,3:1)
Block(6,-4,-3,162:12)
Block(6,-4,-2,3:1)
Block(6,-4,-1,3:1)
Block(6,-4,0,3:1)
Block(6,-4,1,3:1)
Block(6,-4,2,3:1)
Block(6,-4,3,3:1)
Block(6,-4,4,3:1)
Block(6,-4,5,3:1)
Block(6,-4,6,3:1)
Block(6,-4,7,3:1)
Block(6,-4,8,3:1)
Block(6,-4,9,3:1)
Block(6,-4,10,3:1)
Block(6,-3,-4,3:1)
Block(6,-3,-3,162:12)
Block(6,-3,-2,3:1)
Block(6,-3,-1,3:1)
Block(6,-3,0,3:1)
Block(6,-3,1,3:1)
Block(6,-3,2,3:1)
Block(6,-3,3,3:1)
Block(6,-3,4,3:1)
Block(6,-3,5,3:1)
Block(6,-3,6,3:1)
Block(6,-3,7,3:1)
Block(6,-3,9,162:12)
Block(6,-2,-3,3:1)
Block(6,-2,-2,3:1)
Block(6,-2,-1,3:1)
Block(6,-2,0,3:1)
Block(6,-2,1,162:12)
Block(6,-2,2,3:1)
Block(6,-2,3,3:1)
Block(6,-2,4,162:12)
Block(6,-2,5,3:1)
Block(6,-2,6,3:1)
Block(6,-2,8,162:12)
Block(6,-1,-2,3:1)
Block(6,-1,-1,3:1)
Block(6,-1,0,3:1)
Block(6,-1,1,3:1)
Block(6,-1,2,3:1)
Block(6,-1,3,3:1)
Block(6,-1,4,162:12)
Block(6,-1,5,162:12)
Block(6,-1,6,3:1)
Block(6,-1,7,162:12)
Block(6,0,-1,162:12)
Block(6,0,0,162:12)
Block(6,0,1,3:1)
Block(6,0,2,3:1)
Block(6,0,3,3:1)
Block(6,0,4,162:12)
Block(6,0,7,162:12)
Block(6,1,-1,162:12)
Block(6,1,0,162:12)
Block(6,2,-1,162:12)
Block(6,30,2,LEAVES_2:0)
Block(6,30,4,LEAVES_2:0)
Block(6,31,1,LEAVES_2:0)
Block(6,31,3,LEAVES_2:0)
Block(6,32,2,LEAVES_2:0)
Block(6,34,4,LEAVES_2:0)
Block(6,34,9,LEAVES_2:0)
Block(6,35,-6,LEAVES_2:0)
Block(6,35,-4,LEAVES_2:0)
Block(6,35,-2,LEAVES_2:0)
Block(6,35,0,LEAVES_2:0)
Block(6,35,2,LEAVES_2:0)
Block(6,35,3,LEAVES_2:0)
Block(6,35,4,LEAVES_2:0)
Block(6,35,5,LEAVES_2:0)
Block(6,35,7,LEAVES_2:0)
Block(6,35,8,LEAVES_2:0)
Block(6,36,-7,LEAVES_2:0)
Block(6,36,-5,LEAVES_2:0)
Block(6,36,-3,LEAVES_2:0)
Block(6,36,-1,LEAVES_2:0)
Block(6,36,0,LEAVES_2:0)
Block(6,36,3,162:12)
Block(6,36,5,LEAVES_2:0)
Block(6,36,9,LEAVES_2:0)
Block(6,37,-8,LEAVES_2:0)
Block(6,37,-6,LEAVES_2:0)
Block(6,37,-5,162:12)
Block(6,37,-4,LEAVES_2:0)
Block(6,37,-2,LEAVES_2:0)
Block(6,37,0,LEAVES_2:0)
Block(6,37,1,162:12)
Block(6,37,2,LEAVES_2:0)
Block(6,37,3,LEAVES_2:0)
Block(6,37,4,LEAVES_2:0)
Block(6,37,6,LEAVES_2:0)
Block(6,38,-6,LEAVES_2:0)
Block(6,38,-5,LEAVES_2:0)
Block(6,38,-2,LEAVES_2:0)
Block(6,38,-1,LEAVES_2:0)
Block(6,38,1,LEAVES_2:0)
Block(6,38,3,LEAVES_2:0)
Block(6,39,-4,LEAVES_2:0)
Block(6,39,-3,LEAVES_2:0)
Block(6,39,0,LEAVES_2:0)
Block(6,39,2,LEAVES_2:0)
Block(6,40,1,LEAVES_2:0)
Block(7,-6,-7,3:1)
Block(7,-6,-6,3:1)
Block(7,-6,-5,3:1)
Block(7,-6,-4,3:1)
Block(7,-6,-3,162:12)
Block(7,-6,-2,162:12)
Block(7,-6,-1,3:1)
Block(7,-6,0,3:1)
Block(7,-6,1,3:1)
Block(7,-6,2,3:1)
Block(7,-6,3,3:1)
Block(7,-6,4,3:1)
Block(7,-6,5,3:1)
Block(7,-6,6,3:1)
Block(7,-6,7,3:1)
Block(7,-6,8,3:1)
Block(7,-6,9,162:12)
Block(7,-6,10,3:1)
Block(7,-6,11,3:1)
Block(7,-5,-7,3:1)
Block(7,-5,-6,3:1)
Block(7,-5,-5,3:1)
Block(7,-5,-4,3:1)
Block(7,-5,-3,3:1)
Block(7,-5,-2,162:12)
Block(7,-5,-1,3:1)
Block(7,-5,0,3:1)
Block(7,-5,1,3:1)
Block(7,-5,2,3:1)
Block(7,-5,3,3:1)
Block(7,-5,4,3:1)
Block(7,-5,5,3:1)
Block(7,-5,6,3:1)
Block(7,-5,7,3:1)
Block(7,-5,8,3:1)
Block(7,-5,9,3:1)
Block(7,-5,10,162:12)
Block(7,-5,11,3:1)
Block(7,-4,-5,162:12)
Block(7,-4,-4,3:1)
Block(7,-4,-3,3:1)
Block(7,-4,-2,162:12)
Block(7,-4,-1,3:1)
Block(7,-4,0,162:12)
Block(7,-4,1,3:1)
Block(7,-4,2,3:1)
Block(7,-4,3,3:1)
Block(7,-4,4,3:1)
Block(7,-4,5,162:12)
Block(7,-4,6,3:1)
Block(7,-4,7,3:1)
Block(7,-4,9,162:12)
Block(7,-3,-4,162:12)
Block(7,-3,-3,3:1)
Block(7,-3,-2,3:1)
Block(7,-3,-1,3:1)
Block(7,-3,0,3:1)
Block(7,-3,1,162:12)
Block(7,-3,2,3:1)
Block(7,-3,3,3:1)
Block(7,-3,4,162:12)
Block(7,-3,5,3:1)
Block(7,-3,6,3:1)
Block(7,-3,7,162:12)
Block(7,-2,-4,162:12)
Block(7,-2,-2,162:12)
Block(7,-2,-1,3:1)
Block(7,-2,0,3:1)
Block(7,-2,1,3:1)
Block(7,-2,2,3:1)
Block(7,-2,3,3:1)
Block(7,-2,4,162:12)
Block(7,-2,5,3:1)
Block(7,-2,7,162:12)
Block(7,-1,-3,162:12)
Block(7,-1,-2,162:12)
Block(7,-1,-1,162:12)
Block(7,-1,0,3:1)
Block(7,-1,1,3:1)
Block(7,-1,2,3:1)
Block(7,0,1,3:1)
Block(7,0,3,162:12)
Block(7,1,-2,162:12)
Block(7,31,2,LEAVES_2:0)
Block(7,35,4,LEAVES_2:0)
Block(7,35,6,LEAVES_2:0)
Block(7,36,-5,LEAVES_2:0)
Block(7,36,-4,LEAVES_2:0)
Block(7,36,-2,LEAVES_2:0)
Block(7,36,1,LEAVES_2:0)
Block(7,36,3,LEAVES_2:0)
Block(7,36,4,162:12)
Block(7,36,5,LEAVES_2:0)
Block(7,36,7,LEAVES_2:0)
Block(7,37,-7,LEAVES_2:0)
Block(7,37,-6,LEAVES_2:0)
Block(7,37,-3,LEAVES_2:0)
Block(7,37,-2,LEAVES_2:0)
Block(7,37,-1,LEAVES_2:0)
Block(7,37,0,162:12)
Block(7,37,2,LEAVES_2:0)
Block(7,37,4,LEAVES_2:0)
Block(7,38,-8,LEAVES_2:0)
Block(7,38,-6,162:12)
Block(7,38,-5,LEAVES_2:0)
Block(7,38,-4,LEAVES_2:0)
Block(7,38,0,LEAVES_2:0)
Block(7,38,1,LEAVES_2:0)
Block(7,39,-7,LEAVES_2:0)
Block(7,39,-6,LEAVES_2:0)
Block(8,-6,-7,3:1)
Block(8,-6,-6,3:1)
Block(8,-6,-5,3:1)
Block(8,-6,-4,3:1)
Block(8,-6,-3,3:1)
Block(8,-6,-2,162:12)
Block(8,-6,-1,3:1)
Block(8,-6,0,3:1)
Block(8,-6,1,3:1)
Block(8,-6,2,162:12)
Block(8,-6,3,3:1)
Block(8,-6,4,3:1)
Block(8,-6,5,162:12)
Block(8,-6,6,162:12)
Block(8,-6,7,3:1)
Block(8,-6,8,3:1)
Block(8,-6,9,3:1)
Block(8,-6,10,3:1)
Block(8,-6,11,3:1)
Block(8,-5,-6,3:1)
Block(8,-5,-5,162:12)
Block(8,-5,-4,3:1)
Block(8,-5,-3,3:1)
Block(8,-5,-2,3:1)
Block(8,-5,-1,3:1)
Block(8,-5,0,3:1)
Block(8,-5,1,3:1)
Block(8,-5,2,3:1)
Block(8,-5,3,3:1)
Block(8,-5,4,3:1)
Block(8,-5,5,162:12)
Block(8,-5,6,3:1)
Block(8,-5,7,3:1)
Block(8,-5,8,162:12)
Block(8,-5,9,3:1)
Block(8,-5,10,3:1)
Block(8,-4,-6,3:1)
Block(8,-4,-4,3:1)
Block(8,-4,-3,3:1)
Block(8,-4,-2,3:1)
Block(8,-4,-1,162:12)
Block(8,-4,0,3:1)
Block(8,-4,1,3:1)
Block(8,-4,2,3:1)
Block(8,-4,3,162:12)
Block(8,-4,4,3:1)
Block(8,-4,7,162:12)
Block(8,-4,9,3:1)
Block(8,-3,-2,162:12)
Block(8,-3,-1,3:1)
Block(8,-3,0,3:1)
Block(8,-3,1,3:1)
Block(8,-3,2,3:1)
Block(8,-3,3,3:1)
Block(8,-2,-1,3:1)
Block(8,-2,0,3:1)
Block(8,-2,1,3:1)
Block(8,-2,2,162:12)
Block(8,-1,0,3:1)
Block(8,-1,1,3:1)
Block(8,-1,3,162:12)
Block(8,0,-3,162:12)
Block(8,1,-1,162:12)
Block(8,35,-4,LEAVES_2:0)
Block(8,35,-1,LEAVES_2:0)
Block(8,35,2,LEAVES_2:0)
Block(8,35,5,LEAVES_2:0)
Block(8,36,-8,LEAVES_2:0)
Block(8,36,-6,LEAVES_2:0)
Block(8,36,-2,LEAVES_2:0)
Block(8,36,0,LEAVES_2:0)
Block(8,36,3,LEAVES_2:0)
Block(8,36,4,162:12)
Block(8,36,6,LEAVES_2:0)
Block(8,37,-9,LEAVES_2:0)
Block(8,37,-7,LEAVES_2:0)
Block(8,37,-5,LEAVES_2:0)
Block(8,37,-4,LEAVES_2:0)
Block(8,37,-1,LEAVES_2:0)
Block(8,37,1,LEAVES_2:0)
Block(8,37,4,LEAVES_2:0)
Block(8,37,5,LEAVES_2:0)
Block(8,38,-8,LEAVES_2:0)
Block(8,38,-7,162:12)
Block(8,38,-6,LEAVES_2:0)
Block(8,38,-3,LEAVES_2:0)
Block(8,38,0,LEAVES_2:0)
Block(8,39,-7,LEAVES_2:0)
Block(9,-6,-7,3:1)
Block(9,-6,-6,162:12)
Block(9,-6,-5,3:1)
Block(9,-6,-4,162:12)
Block(9,-6,-3,3:1)
Block(9,-6,-2,162:12)
Block(9,-6,-1,3:1)
Block(9,-6,0,162:12)
Block(9,-6,1,3:1)
Block(9,-6,2,3:1)
Block(9,-6,3,3:1)
Block(9,-6,4,3:1)
Block(9,-6,5,3:1)
Block(9,-6,6,162:12)
Block(9,-6,7,3:1)
Block(9,-6,8,3:1)
Block(9,-6,9,3:1)
Block(9,-6,10,3:1)
Block(9,-5,-5,3:1)
Block(9,-5,-4,162:12)
Block(9,-5,-3,3:1)
Block(9,-5,-2,162:12)
Block(9,-5,-1,3:1)
Block(9,-5,0,162:12)
Block(9,-5,1,3:1)
Block(9,-5,2,162:12)
Block(9,-5,4,162:12)
Block(9,-5,6,162:12)
Block(9,-4,-5,162:12)
Block(9,-4,-3,3:1)
Block(9,-4,-2,3:1)
Block(9,-4,-1,3:1)
Block(9,-4,0,3:1)
Block(9,-4,1,3:1)
Block(9,-4,2,3:1)
Block(9,-3,-5,162:12)
Block(9,-3,-1,3:1)
Block(9,-3,1,3:1)
Block(9,-3,2,3:1)
Block(9,-2,-4,162:12)
Block(9,-2,-3,162:12)
Block(9,-1,-4,162:12)
Block(9,-1,-1,162:12)
Block(9,0,-1,162:12)
Block(9,35,4,LEAVES_2:0)
Block(9,36,-5,LEAVES_2:0)
Block(9,36,-3,LEAVES_2:0)
Block(9,36,-1,LEAVES_2:0)
Block(9,36,1,LEAVES_2:0)
Block(9,36,3,LEAVES_2:0)
Block(9,36,5,LEAVES_2:0)
Block(9,37,-7,LEAVES_2:0)
Block(9,37,0,LEAVES_2:0)
Block(9,37,4,LEAVES_2:0)
Block(9,38,-8,LEAVES_2:0)
Block(9,38,-6,LEAVES_2:0)
Block(9,39,-7,LEAVES_2:0)
Block(10,-6,-6,3:1)
Block(10,-6,-5,3:1)
Block(10,-6,-4,3:1)
Block(10,-6,-3,3:1)
Block(10,-6,-2,162:12)
Block(10,-6,-1,3:1)
Block(10,-6,0,3:1)
Block(10,-6,1,162:12)
Block(10,-6,2,3:1)
Block(10,-6,3,3:1)
Block(10,-6,4,162:12)
Block(10,-6,5,3:1)
Block(10,-6,6,3:1)
Block(10,-5,-6,3:1)
Block(10,-5,-5,3:1)
Block(10,-5,-2,3:1)
Block(10,-4,-3,162:12)
Block(10,-4,-1,162:12)
Block(10,-3,-3,162:12)
Block(10,-3,-1,162:12)
Block(10,-2,-1,162:12)
Block(10,35,1,LEAVES_2:0)
Block(10,36,0,LEAVES_2:0)
Block(10,36,4,LEAVES_2:0)
Block(10,37,-8,LEAVES_2:0)
Block(10,37,-6,LEAVES_2:0)
Block(10,38,-7,LEAVES_2:0)
Block(11,-6,-6,3:1)
Block(11,-6,-5,3:1)
Block(11,-6,-4,162:12)
Block(11,-6,-2,3:1)
Block(11,-6,-1,3:1)
Block(11,-6,0,3:1)
Block(11,-6,1,162:12)
Block(11,-5,-6,3:1)
Block(11,-5,-5,3:1)
Block(11,-5,-4,162:12)
Block(11,-5,0,162:12)
Block(12,-6,-6,3:1)


#######################################################################
# +-----------------------------------------------------------------+ #
# |                             Entities                            | #
# +-----------------------------------------------------------------+ #
#######################################################################

# Entity() spawns an entity instead of a block. The entity is spawned only once when the BO3 is spawned.
# Entities are persistent by default so they don't de-spawn when no player is near, they are only unloaded.
# Usage: Entity(x,y,z,mobName,groupSize,NameTagOrNBTFileName) or Entity(x,y,z,mobName,groupSize)
# Use /tc entities or /otg entities to get a list of entities that can be used as mobName, this includes entities added by other mods.
# NameTagOrNBTFileName can be either a nametag for the mob or an nbt file (such as mymobinfo.nbt or mymobinfo.txt).
# When using a text file you can use the same mob spawning parameters used with the /summon command to equip the
# entity and give it custom attributes etc. You can copy the DATA part of a summon command including surrounding
# curly braces to a .txt file, for instance for: "/summon Skeleton x y z {DATA}"

#######################################################################
# +-----------------------------------------------------------------+ #
# |                            BO3 checks                           | #
# +-----------------------------------------------------------------+ #
#######################################################################

# Require a condition at a certain location in order for the BO3 to be spawned.
# BlockCheck(x,y,z,BlockName[,BlockName[,...]]) - one of the blocks must be at the location
# BlockCheckNot(x,y,z,BlockName[,BlockName[,...]]) - all the blocks must not be at the location
# LightCheck(x,y,z,minLightLevel,maxLightLevel) - light must be between min and max (inclusive)

# You can use "Solid" as a BlockName for matching all solid blocks or "All" to match all blocks that aren't air.

# Examples:
#   BlockCheck(0,-1,0,GRASS,DIRT)  Require grass or dirt just below the object
#   BlockCheck(0,-1,0,Solid)       Require any solid block just below the object
#   BlockCheck(0,-1,0,WOOL)        Require any type of wool just below the object
#   BlockCheck(0,-1,0,WOOL:0)      Require white wool just below the object
#   BlockCheckNot(0,-1,0,WOOL:0)   Require that there is no white wool below the object
#   LightCheck(0,0,0,0,LEAVES_2:0)          Require almost complete darkness just below the object

