
#######################################################################
# +-----------------------------------------------------------------+ #
# |                            BO3 object                           | #
# +-----------------------------------------------------------------+ #
#######################################################################

# This is the config file of a custom object.
# If you add this object correctly to your BiomeConfigs, it will spawn in the world.

# This is the creator of this BO3 object
Author: Unknown

# A short description of this BO3 object
Description: This BO3 was converted from a schematic using OTGEdit. The author and description information of the schematic could not be found. If you know who the author of the schematic is then please add this information.

# The BO3 version, don't change this! It can be used by external applications to do a version check.
Version: 3

# The settings mode, WriteAll, WriteWithoutComments or WriteDisable. See WorldConfig.
SettingsMode: WriteAll


#######################################################################
# +-----------------------------------------------------------------+ #
# |                          Main settings                          | #
# +-----------------------------------------------------------------+ #
#######################################################################

# This needs to be set to true to spawn the object in the Tree and Sapling resources.
Tree: true

# The frequency of the BO3 from 1 to 200. Tries this many times to spawn this BO3 when using the CustomObject(...) resource.
# Ignored by Tree(..), Sapling(..) and CustomStructure(..)
Frequency: 40

# The rarity of the BO3 from 0 to 100. Each spawn attempt has rarity% chance to succeed when using the CustomObject(...) resource.
# Ignored by Tree(..), Sapling(..) and CustomStructure(..)
Rarity: 100.0

# If you set this to true, the BO3 will be placed with a random rotation.
RotateRandomly: true

# The spawn height of the BO3: randomY, highestBlock or highestSolidBlock.
SpawnHeight: randomY

# The offset from the spawn height to spawn this BO3
# Ex. SpawnHeight = highestSolidBlock, SpawnHeightOffset = 3; This object will spawn 3 blocks above the highest solid block
SpawnHeightOffset: 0

# A random amount to offset the spawn location from the spawn offset height
# Ex. SpawnHeightOffset = 3, SpawnHeightVariance = 3; This object will spawn 3 to 6 blocks above the original spot it would have spawned
SpawnHeightVariance: 0

##############################
# Height Limits for the BO3. #
##############################

# When in randomY mode used as the minimum Y or in atMinY mode as the actual Y to spawn this BO3 at.
MinHeight: 63

# When in randomY mode used as the maximum Y to spawn this BO3 at.
MaxHeight: 256

######################
# Extrusion settings #
######################

# The style of extrusion you wish to use - BottomDown, TopUp, None (Default)
ExtrudeMode: None

# The blocks to extrude your BO3 through
ExtrudeThroughBlocks: AIR

# Objects can have other objects attacthed to it: branches. Branches can also
# have branches attached to it, which can also have branches, etc. This is the
# maximum branch depth for this objects.
MaxBranchDepth: 10

# When spawned with the UseWorld keyword, this BO3 should NOT spawn in the following biomes.
# If you write the BO3 name directly in the BiomeConfigs, this will be ignored.
ExcludedBiomes: All


#######################################################################
# +-----------------------------------------------------------------+ #
# |                      Source block settings                      | #
# +-----------------------------------------------------------------+ #
#######################################################################

# The block(s) the BO3 should spawn in.
SourceBlocks: AIR,GRASS,DIRT,SNOW,SNOW_BLOCK

# The maximum percentage of the BO3 that can be outside the SourceBlock.
# The BO3 won't be placed on a location with more blocks outside the SourceBlock than this percentage.
MaxPercentageOutsideSourceBlock: 5

# What to do when a block is about to be placed outside the SourceBlock? (dontPlace, placeAnyway)
OutsideSourceBlock: dontPlace

# OTG+ settings #
# Legacy setting, rename this file to .BO4 instead. Set this to true to enable the advanced customstructure features of OTG+.
IsOTGPlus: false


#######################################################################
# +-----------------------------------------------------------------+ #
# |                              Blocks                             | #
# +-----------------------------------------------------------------+ #
#######################################################################

# All the blocks used in the BO3 are listed here. Possible blocks:
# Block(x,y,z,id[.data][,nbtfile.nbt)
# RandomBlock(x,y,z,id[:data][,nbtfile.nbt],chance[,id[:data][,nbtfile.nbt],chance[,...]])
#  So RandomBlock(0,0,0,CHEST,chest.nbt,50,CHEST,anotherchest.nbt,100) will spawn a chest at
#  the BO3 origin, and give it a 50% chance to have the contents of chest.nbt, or, if that
#  fails, a 100% percent chance to have the contents of anotherchest.nbt.
# *Note: Unlike Entity() and Spawner(), for Block() .txt files don't work, only .nbt files work.
# MinecraftObject(x,y,z,name) (TODO: This may not work anymore and needs to be tested.
#  Spawns an object in the Mojang NBT structure format. For example, 
#  MinecraftObject(0,0,0,minecraft:igloo/igloo_bottom)
#  spawns the bottom part of an igloo.
Block(-4,25,2,biomesoplenty:leaves_4:2)
Block(-4,26,1,biomesoplenty:leaves_4:2)
Block(-4,26,2,biomesoplenty:leaves_4:2)
Block(-4,26,3,biomesoplenty:leaves_4:2)
Block(-3,18,6,biomesoplenty:leaves_4:2)
Block(-3,19,5,biomesoplenty:leaves_4:2)
Block(-3,19,6,biomesoplenty:leaves_4:2)
Block(-3,19,7,biomesoplenty:leaves_4:2)
Block(-3,20,6,biomesoplenty:leaves_4:2)
Block(-3,24,-1,biomesoplenty:leaves_4:2)
Block(-3,24,0,biomesoplenty:leaves_4:2)
Block(-3,24,1,biomesoplenty:leaves_4:2)
Block(-3,24,2,biomesoplenty:leaves_4:2)
Block(-3,24,3,biomesoplenty:leaves_4:2)
Block(-3,25,-1,biomesoplenty:leaves_4:2)
Block(-3,25,0,biomesoplenty:leaves_4:2)
Block(-3,25,1,biomesoplenty:leaves_4:2)
Block(-3,25,2,biomesoplenty:leaves_4:2)
Block(-3,25,4,biomesoplenty:leaves_4:2)
Block(-3,25,5,biomesoplenty:leaves_4:2)
Block(-3,25,6,biomesoplenty:leaves_4:2)
Block(-3,26,0,biomesoplenty:leaves_4:2)
Block(-3,26,1,biomesoplenty:leaves_4:2)
Block(-3,26,2,biomesoplenty:leaves_4:2)
Block(-3,26,4,biomesoplenty:leaves_4:2)
Block(-3,26,5,biomesoplenty:leaves_4:2)
Block(-3,26,6,biomesoplenty:leaves_4:2)
Block(-3,27,1,biomesoplenty:leaves_4:2)
Block(-3,27,3,biomesoplenty:leaves_4:2)
Block(-3,27,4,biomesoplenty:leaves_4:2)
Block(-3,27,5,biomesoplenty:leaves_4:2)
Block(-3,27,6,biomesoplenty:leaves_4:2)
Block(-3,28,2,biomesoplenty:leaves_4:2)
Block(-3,28,3,biomesoplenty:leaves_4:2)
Block(-3,32,1,biomesoplenty:leaves_4:2)
Block(-3,32,2,biomesoplenty:leaves_4:2)
Block(-3,33,3,biomesoplenty:leaves_4:2)
Block(-3,34,1,biomesoplenty:leaves_4:2)
Block(-3,34,3,biomesoplenty:leaves_4:2)
Block(-3,37,2,biomesoplenty:leaves_4:2)
Block(-3,37,3,biomesoplenty:leaves_4:2)
Block(-3,37,4,biomesoplenty:leaves_4:2)
Block(-3,38,3,biomesoplenty:leaves_4:2)
Block(-3,38,4,biomesoplenty:leaves_4:2)
Block(-3,40,3,biomesoplenty:leaves_4:2)
Block(-3,41,2,biomesoplenty:leaves_4:2)
Block(-3,41,3,biomesoplenty:leaves_4:2)
Block(-3,41,4,biomesoplenty:leaves_4:2)
Block(-3,42,3,biomesoplenty:leaves_4:2)
Block(-2,18,5,biomesoplenty:leaves_4:2)
Block(-2,18,6,biomesoplenty:leaves_4:2)
Block(-2,18,7,biomesoplenty:leaves_4:2)
Block(-2,19,0,biomesoplenty:leaves_4:2)
Block(-2,19,1,biomesoplenty:leaves_4:2)
Block(-2,19,3,biomesoplenty:leaves_4:2)
Block(-2,19,5,biomesoplenty:leaves_4:2)
Block(-2,19,6,biomesoplenty:log_2)
Block(-2,19,7,biomesoplenty:leaves_4:2)
Block(-2,20,-3,biomesoplenty:leaves_4:2)
Block(-2,20,-2,biomesoplenty:leaves_4:2)
Block(-2,20,-1,biomesoplenty:leaves_4:2)
Block(-2,20,0,biomesoplenty:leaves_4:2)
Block(-2,20,1,biomesoplenty:leaves_4:2)
Block(-2,20,3,biomesoplenty:leaves_4:2)
Block(-2,20,4,biomesoplenty:leaves_4:2)
Block(-2,20,5,biomesoplenty:leaves_4:2)
Block(-2,20,6,biomesoplenty:leaves_4:2)
Block(-2,20,7,biomesoplenty:leaves_4:2)
Block(-2,21,-2,biomesoplenty:leaves_4:2)
Block(-2,21,-1,biomesoplenty:leaves_4:2)
Block(-2,21,0,biomesoplenty:leaves_4:2)
Block(-2,21,3,biomesoplenty:leaves_4:2)
Block(-2,21,4,biomesoplenty:leaves_4:2)
Block(-2,21,5,biomesoplenty:leaves_4:2)
Block(-2,23,-1,biomesoplenty:leaves_4:2)
Block(-2,23,0,biomesoplenty:leaves_4:2)
Block(-2,23,1,biomesoplenty:leaves_4:2)
Block(-2,23,6,biomesoplenty:leaves_4:2)
Block(-2,24,0,biomesoplenty:leaves_4:2)
Block(-2,24,1,biomesoplenty:leaves_4:2)
Block(-2,24,2,biomesoplenty:leaves_4:2)
Block(-2,24,3,biomesoplenty:leaves_4:2)
Block(-2,24,5,biomesoplenty:leaves_4:2)
Block(-2,24,6,biomesoplenty:leaves_4:2)
Block(-2,24,7,biomesoplenty:leaves_4:2)
Block(-2,25,-1,biomesoplenty:leaves_4:2)
Block(-2,25,0,biomesoplenty:leaves_4:2)
Block(-2,25,1,biomesoplenty:leaves_4:2)
Block(-2,25,2,biomesoplenty:log_2)
Block(-2,25,3,biomesoplenty:leaves_4:2)
Block(-2,25,4,biomesoplenty:leaves_4:2)
Block(-2,26,0,biomesoplenty:leaves_4:2)
Block(-2,26,1,biomesoplenty:leaves_4:2)
Block(-2,26,2,biomesoplenty:leaves_4:2)
Block(-2,26,3,biomesoplenty:leaves_4:2)
Block(-2,26,4,biomesoplenty:leaves_4:2)
Block(-2,26,5,biomesoplenty:leaves_4:2)
Block(-2,26,6,biomesoplenty:log_2)
Block(-2,26,7,biomesoplenty:leaves_4:2)
Block(-2,27,0,biomesoplenty:leaves_4:2)
Block(-2,27,1,biomesoplenty:leaves_4:2)
Block(-2,27,2,biomesoplenty:leaves_4:2)
Block(-2,27,3,biomesoplenty:leaves_4:2)
Block(-2,27,4,biomesoplenty:leaves_4:2)
Block(-2,27,5,biomesoplenty:leaves_4:2)
Block(-2,27,7,biomesoplenty:leaves_4:2)
Block(-2,28,0,biomesoplenty:leaves_4:2)
Block(-2,28,1,biomesoplenty:leaves_4:2)
Block(-2,28,2,biomesoplenty:leaves_4:2)
Block(-2,28,3,biomesoplenty:leaves_4:2)
Block(-2,28,5,biomesoplenty:leaves_4:2)
Block(-2,29,0,biomesoplenty:leaves_4:2)
Block(-2,29,1,biomesoplenty:leaves_4:2)
Block(-2,29,2,biomesoplenty:leaves_4:2)
Block(-2,30,0,biomesoplenty:leaves_4:2)
Block(-2,30,1,biomesoplenty:leaves_4:2)
Block(-2,31,2,biomesoplenty:leaves_4:2)
Block(-2,32,1,biomesoplenty:leaves_4:2)
Block(-2,32,2,biomesoplenty:leaves_4:2)
Block(-2,32,3,biomesoplenty:leaves_4:2)
Block(-2,33,0,biomesoplenty:leaves_4:2)
Block(-2,33,1,biomesoplenty:leaves_4:2)
Block(-2,33,2,biomesoplenty:leaves_4:2)
Block(-2,33,4,biomesoplenty:leaves_4:2)
Block(-2,34,0,biomesoplenty:leaves_4:2)
Block(-2,34,1,biomesoplenty:leaves_4:2)
Block(-2,34,2,biomesoplenty:leaves_4:2)
Block(-2,34,3,biomesoplenty:leaves_4:2)
Block(-2,34,5,biomesoplenty:leaves_4:2)
Block(-2,34,6,biomesoplenty:leaves_4:2)
Block(-2,34,7,biomesoplenty:leaves_4:2)
Block(-2,35,1,biomesoplenty:leaves_4:2)
Block(-2,35,2,biomesoplenty:leaves_4:2)
Block(-2,35,3,biomesoplenty:leaves_4:2)
Block(-2,35,5,biomesoplenty:leaves_4:2)
Block(-2,35,6,biomesoplenty:leaves_4:2)
Block(-2,35,7,biomesoplenty:leaves_4:2)
Block(-2,36,1,biomesoplenty:leaves_4:2)
Block(-2,36,3,biomesoplenty:leaves_4:2)
Block(-2,36,6,biomesoplenty:leaves_4:2)
Block(-2,36,7,biomesoplenty:leaves_4:2)
Block(-2,37,1,biomesoplenty:leaves_4:2)
Block(-2,37,2,biomesoplenty:leaves_4:2)
Block(-2,37,3,biomesoplenty:leaves_4:2)
Block(-2,37,5,biomesoplenty:leaves_4:2)
Block(-2,38,3,biomesoplenty:leaves_4:2)
Block(-2,38,4,biomesoplenty:leaves_4:2)
Block(-2,38,5,biomesoplenty:leaves_4:2)
Block(-2,39,1,biomesoplenty:leaves_4:2)
Block(-2,39,2,biomesoplenty:leaves_4:2)
Block(-2,39,3,biomesoplenty:leaves_4:2)
Block(-2,39,4,biomesoplenty:leaves_4:2)
Block(-2,39,5,biomesoplenty:leaves_4:2)
Block(-2,40,1,biomesoplenty:leaves_4:2)
Block(-2,40,2,biomesoplenty:leaves_4:2)
Block(-2,40,3,biomesoplenty:leaves_4:2)
Block(-2,40,5,biomesoplenty:leaves_4:2)
Block(-2,41,1,biomesoplenty:leaves_4:2)
Block(-2,41,4,biomesoplenty:leaves_4:2)
Block(-2,41,5,biomesoplenty:leaves_4:2)
Block(-2,42,4,biomesoplenty:leaves_4:2)
Block(-2,42,5,biomesoplenty:leaves_4:2)
Block(-2,43,2,biomesoplenty:leaves_4:2)
Block(-2,43,3,biomesoplenty:leaves_4:2)
Block(-1,3,5,biomesoplenty:leaves_4:2)
Block(-1,4,3,biomesoplenty:leaves_4:2)
Block(-1,4,4,biomesoplenty:leaves_4:2)
Block(-1,4,5,biomesoplenty:leaves_4:2)
Block(-1,18,-1,biomesoplenty:leaves_4:2)
Block(-1,18,0,biomesoplenty:leaves_4:2)
Block(-1,18,3,biomesoplenty:leaves_4:2)
Block(-1,18,4,biomesoplenty:leaves_4:2)
Block(-1,18,6,biomesoplenty:leaves_4:2)
Block(-1,19,-2,biomesoplenty:leaves_4:2)
Block(-1,19,-1,biomesoplenty:leaves_4:2)
Block(-1,19,0,biomesoplenty:leaves_4:2)
Block(-1,19,1,biomesoplenty:leaves_4:2)
Block(-1,19,2,biomesoplenty:leaves_4:2)
Block(-1,19,3,biomesoplenty:leaves_4:2)
Block(-1,19,4,biomesoplenty:leaves_4:2)
Block(-1,19,5,biomesoplenty:log_2)
Block(-1,19,6,biomesoplenty:log_2)
Block(-1,19,7,biomesoplenty:leaves_4:2)
Block(-1,20,-4,biomesoplenty:leaves_4:2)
Block(-1,20,-3,biomesoplenty:leaves_4:2)
Block(-1,20,-2,biomesoplenty:leaves_4:2)
Block(-1,20,-1,biomesoplenty:leaves_4:2)
Block(-1,20,0,biomesoplenty:log_2)
Block(-1,20,1,biomesoplenty:leaves_4:2)
Block(-1,20,2,biomesoplenty:leaves_4:2)
Block(-1,20,3,biomesoplenty:leaves_4:2)
Block(-1,20,4,biomesoplenty:leaves_4:2)
Block(-1,20,5,biomesoplenty:leaves_4:2)
Block(-1,20,6,biomesoplenty:leaves_4:2)
Block(-1,21,-3,biomesoplenty:leaves_4:2)
Block(-1,21,-2,biomesoplenty:leaves_4:2)
Block(-1,21,-1,biomesoplenty:leaves_4:2)
Block(-1,21,0,biomesoplenty:leaves_4:2)
Block(-1,21,1,biomesoplenty:leaves_4:2)
Block(-1,21,2,biomesoplenty:leaves_4:2)
Block(-1,21,3,biomesoplenty:leaves_4:2)
Block(-1,21,4,biomesoplenty:leaves_4:2)
Block(-1,21,5,biomesoplenty:leaves_4:2)
Block(-1,21,6,biomesoplenty:leaves_4:2)
Block(-1,22,-3,biomesoplenty:leaves_4:2)
Block(-1,22,-2,biomesoplenty:leaves_4:2)
Block(-1,22,-1,biomesoplenty:leaves_4:2)
Block(-1,22,0,biomesoplenty:leaves_4:2)
Block(-1,22,3,biomesoplenty:leaves_4:2)
Block(-1,22,4,biomesoplenty:leaves_4:2)
Block(-1,22,5,biomesoplenty:leaves_4:2)
Block(-1,22,6,biomesoplenty:leaves_4:2)
Block(-1,23,-3,biomesoplenty:leaves_4:2)
Block(-1,23,-2,biomesoplenty:leaves_4:2)
Block(-1,23,-1,biomesoplenty:leaves_4:2)
Block(-1,23,0,biomesoplenty:leaves_4:2)
Block(-1,23,1,biomesoplenty:leaves_4:2)
Block(-1,23,4,biomesoplenty:leaves_4:2)
Block(-1,23,5,biomesoplenty:leaves_4:2)
Block(-1,23,6,biomesoplenty:leaves_4:2)
Block(-1,23,7,biomesoplenty:leaves_4:2)
Block(-1,23,8,biomesoplenty:leaves_4:2)
Block(-1,24,-2,biomesoplenty:leaves_4:2)
Block(-1,24,-1,biomesoplenty:leaves_4:2)
Block(-1,24,0,biomesoplenty:leaves_4:2)
Block(-1,24,1,biomesoplenty:log_2)
Block(-1,24,2,biomesoplenty:log_2:8)
Block(-1,24,3,biomesoplenty:leaves_4:2)
Block(-1,24,4,biomesoplenty:leaves_4:2)
Block(-1,24,5,biomesoplenty:leaves_4:2)
Block(-1,24,6,biomesoplenty:leaves_4:2)
Block(-1,24,7,biomesoplenty:leaves_4:2)
Block(-1,24,8,biomesoplenty:leaves_4:2)
Block(-1,25,-2,biomesoplenty:leaves_4:2)
Block(-1,25,-1,biomesoplenty:leaves_4:2)
Block(-1,25,0,biomesoplenty:leaves_4:2)
Block(-1,25,1,biomesoplenty:log_2)
Block(-1,25,2,biomesoplenty:log_2:8)
Block(-1,25,3,biomesoplenty:leaves_4:2)
Block(-1,25,4,biomesoplenty:leaves_4:2)
Block(-1,25,5,biomesoplenty:leaves_4:2)
Block(-1,25,6,biomesoplenty:leaves_4:2)
Block(-1,25,7,biomesoplenty:leaves_4:2)
Block(-1,25,8,biomesoplenty:leaves_4:2)
Block(-1,26,-2,biomesoplenty:leaves_4:2)
Block(-1,26,0,biomesoplenty:leaves_4:2)
Block(-1,26,1,biomesoplenty:leaves_4:2)
Block(-1,26,2,biomesoplenty:leaves_4:2)
Block(-1,26,3,biomesoplenty:leaves_4:2)
Block(-1,26,4,biomesoplenty:log_2)
Block(-1,26,5,biomesoplenty:log_2:8)
Block(-1,26,6,biomesoplenty:log_2:8)
Block(-1,26,7,biomesoplenty:leaves_4:2)
Block(-1,27,-1,biomesoplenty:leaves_4:2)
Block(-1,27,0,biomesoplenty:leaves_4:2)
Block(-1,27,1,biomesoplenty:leaves_4:2)
Block(-1,27,2,biomesoplenty:leaves_4:2)
Block(-1,27,3,biomesoplenty:leaves_4:2)
Block(-1,27,4,biomesoplenty:log_2)
Block(-1,27,5,biomesoplenty:leaves_4:2)
Block(-1,27,6,biomesoplenty:leaves_4:2)
Block(-1,27,7,biomesoplenty:leaves_4:2)
Block(-1,28,-1,biomesoplenty:leaves_4:2)
Block(-1,28,0,biomesoplenty:leaves_4:2)
Block(-1,28,1,biomesoplenty:leaves_4:2)
Block(-1,28,2,biomesoplenty:leaves_4:2)
Block(-1,28,4,biomesoplenty:leaves_4:2)
Block(-1,28,5,biomesoplenty:leaves_4:2)
Block(-1,28,6,biomesoplenty:leaves_4:2)
Block(-1,29,-1,biomesoplenty:leaves_4:2)
Block(-1,29,0,biomesoplenty:leaves_4:2)
Block(-1,29,1,biomesoplenty:log_2)
Block(-1,29,2,biomesoplenty:leaves_4:2)
Block(-1,30,-1,biomesoplenty:leaves_4:2)
Block(-1,30,1,biomesoplenty:leaves_4:2)
Block(-1,30,2,biomesoplenty:leaves_4:2)
Block(-1,30,3,biomesoplenty:leaves_4:2)
Block(-1,31,1,biomesoplenty:leaves_4:2)
Block(-1,31,2,biomesoplenty:leaves_4:2)
Block(-1,31,3,biomesoplenty:leaves_4:2)
Block(-1,32,0,biomesoplenty:leaves_4:2)
Block(-1,32,1,biomesoplenty:leaves_4:2)
Block(-1,32,2,biomesoplenty:leaves_4:2)
Block(-1,32,3,biomesoplenty:leaves_4:2)
Block(-1,32,4,biomesoplenty:leaves_4:2)
Block(-1,33,0,biomesoplenty:leaves_4:2)
Block(-1,33,1,biomesoplenty:leaves_4:2)
Block(-1,33,2,biomesoplenty:log_2)
Block(-1,33,3,biomesoplenty:leaves_4:2)
Block(-1,33,4,biomesoplenty:leaves_4:2)
Block(-1,33,5,biomesoplenty:leaves_4:2)
Block(-1,33,6,biomesoplenty:leaves_4:2)
Block(-1,33,7,biomesoplenty:leaves_4:2)
Block(-1,34,0,biomesoplenty:leaves_4:2)
Block(-1,34,1,biomesoplenty:leaves_4:2)
Block(-1,34,2,biomesoplenty:leaves_4:2)
Block(-1,34,3,biomesoplenty:leaves_4:2)
Block(-1,34,5,biomesoplenty:leaves_4:2)
Block(-1,34,6,biomesoplenty:leaves_4:2)
Block(-1,34,7,biomesoplenty:leaves_4:2)
Block(-1,34,8,biomesoplenty:leaves_4:2)
Block(-1,35,0,biomesoplenty:leaves_4:2)
Block(-1,35,1,biomesoplenty:leaves_4:2)
Block(-1,35,2,biomesoplenty:leaves_4:2)
Block(-1,35,4,biomesoplenty:leaves_4:2)
Block(-1,35,5,biomesoplenty:leaves_4:2)
Block(-1,35,6,biomesoplenty:leaves_4:2)
Block(-1,35,7,biomesoplenty:leaves_4:2)
Block(-1,35,8,biomesoplenty:leaves_4:2)
Block(-1,36,0,biomesoplenty:leaves_4:2)
Block(-1,36,1,biomesoplenty:leaves_4:2)
Block(-1,36,2,biomesoplenty:leaves_4:2)
Block(-1,36,3,biomesoplenty:leaves_4:2)
Block(-1,36,6,biomesoplenty:leaves_4:2)
Block(-1,36,7,biomesoplenty:leaves_4:2)
Block(-1,36,8,biomesoplenty:leaves_4:2)
Block(-1,37,0,biomesoplenty:leaves_4:2)
Block(-1,37,1,biomesoplenty:leaves_4:2)
Block(-1,37,2,biomesoplenty:leaves_4:2)
Block(-1,37,3,biomesoplenty:log_2)
Block(-1,37,4,biomesoplenty:leaves_4:2)
Block(-1,37,5,biomesoplenty:leaves_4:2)
Block(-1,37,6,biomesoplenty:leaves_4:2)
Block(-1,37,7,biomesoplenty:leaves_4:2)
Block(-1,38,1,biomesoplenty:leaves_4:2)
Block(-1,38,2,biomesoplenty:leaves_4:2)
Block(-1,38,3,biomesoplenty:leaves_4:2)
Block(-1,38,4,biomesoplenty:leaves_4:2)
Block(-1,38,5,biomesoplenty:leaves_4:2)
Block(-1,39,1,biomesoplenty:leaves_4:2)
Block(-1,39,2,biomesoplenty:leaves_4:2)
Block(-1,39,3,biomesoplenty:leaves_4:2)
Block(-1,39,5,biomesoplenty:leaves_4:2)
Block(-1,40,1,biomesoplenty:leaves_4:2)
Block(-1,40,2,biomesoplenty:leaves_4:2)
Block(-1,40,3,biomesoplenty:log_2)
Block(-1,40,4,biomesoplenty:leaves_4:2)
Block(-1,40,5,biomesoplenty:leaves_4:2)
Block(-1,41,1,biomesoplenty:leaves_4:2)
Block(-1,41,2,biomesoplenty:leaves_4:2)
Block(-1,41,3,biomesoplenty:log_2)
Block(-1,41,4,biomesoplenty:leaves_4:2)
Block(-1,41,5,biomesoplenty:leaves_4:2)
Block(-1,42,2,biomesoplenty:leaves_4:2)
Block(-1,42,3,biomesoplenty:log_2)
Block(-1,42,4,biomesoplenty:leaves_4:2)
Block(-1,42,5,biomesoplenty:leaves_4:2)
Block(-1,43,3,biomesoplenty:leaves_4:2)
Block(-1,43,4,biomesoplenty:leaves_4:2)
Block(0,0,0,biomesoplenty:log_2)
Block(0,0,1,biomesoplenty:log_2)
Block(0,0,2,biomesoplenty:log_2)
Block(0,0,3,biomesoplenty:log_2)
Block(0,1,1,biomesoplenty:log_2)
Block(0,1,2,biomesoplenty:log_2)
Block(0,1,3,biomesoplenty:log_2)
Block(0,2,1,biomesoplenty:log_2)
Block(0,3,3,biomesoplenty:leaves_4:2)
Block(0,3,4,biomesoplenty:leaves_4:2)
Block(0,3,5,biomesoplenty:leaves_4:2)
Block(0,3,6,biomesoplenty:leaves_4:2)
Block(0,4,3,biomesoplenty:leaves_4:2)
Block(0,4,4,biomesoplenty:leaves_4:2)
Block(0,4,5,biomesoplenty:leaves_4:2)
Block(0,4,6,biomesoplenty:leaves_4:2)
Block(0,5,3,biomesoplenty:leaves_4:2)
Block(0,5,4,biomesoplenty:leaves_4:2)
Block(0,5,5,biomesoplenty:leaves_4:2)
Block(0,18,0,biomesoplenty:leaves_4:2)
Block(0,18,4,biomesoplenty:leaves_4:2)
Block(0,19,-3,biomesoplenty:leaves_4:2)
Block(0,19,-2,biomesoplenty:leaves_4:2)
Block(0,19,-1,biomesoplenty:leaves_4:2)
Block(0,19,0,biomesoplenty:leaves_4:2)
Block(0,19,1,biomesoplenty:leaves_4:2)
Block(0,19,2,biomesoplenty:leaves_4:2)
Block(0,19,3,biomesoplenty:leaves_4:2)
Block(0,19,4,biomesoplenty:leaves_4:2)
Block(0,19,5,biomesoplenty:log_2)
Block(0,19,6,biomesoplenty:log_2:8)
Block(0,20,-4,biomesoplenty:leaves_4:2)
Block(0,20,-3,biomesoplenty:leaves_4:2)
Block(0,20,-2,biomesoplenty:log_2:8)
Block(0,20,-1,biomesoplenty:log_2:8)
Block(0,20,0,biomesoplenty:log_2)
Block(0,20,1,biomesoplenty:leaves_4:2)
Block(0,20,2,biomesoplenty:leaves_4:2)
Block(0,20,3,biomesoplenty:leaves_4:2)
Block(0,20,4,biomesoplenty:log_2)
Block(0,20,5,biomesoplenty:leaves_4:2)
Block(0,20,6,biomesoplenty:leaves_4:2)
Block(0,21,-4,biomesoplenty:leaves_4:2)
Block(0,21,-3,biomesoplenty:leaves_4:2)
Block(0,21,-2,biomesoplenty:leaves_4:2)
Block(0,21,-1,biomesoplenty:log_2)
Block(0,21,0,biomesoplenty:leaves_4:2)
Block(0,21,1,biomesoplenty:leaves_4:2)
Block(0,21,2,biomesoplenty:leaves_4:2)
Block(0,21,3,biomesoplenty:leaves_4:2)
Block(0,21,4,biomesoplenty:leaves_4:2)
Block(0,21,5,biomesoplenty:leaves_4:2)
Block(0,21,6,biomesoplenty:leaves_4:2)
Block(0,22,-4,biomesoplenty:leaves_4:2)
Block(0,22,-3,biomesoplenty:leaves_4:2)
Block(0,22,-2,biomesoplenty:leaves_4:2)
Block(0,22,-1,biomesoplenty:leaves_4:2)
Block(0,22,0,biomesoplenty:leaves_4:2)
Block(0,22,1,biomesoplenty:leaves_4:2)
Block(0,22,3,biomesoplenty:leaves_4:2)
Block(0,22,4,biomesoplenty:leaves_4:2)
Block(0,22,5,biomesoplenty:leaves_4:2)
Block(0,22,6,biomesoplenty:leaves_4:2)
Block(0,22,7,biomesoplenty:leaves_4:2)
Block(0,23,-3,biomesoplenty:leaves_4:2)
Block(0,23,-2,biomesoplenty:leaves_4:2)
Block(0,23,-1,biomesoplenty:leaves_4:2)
Block(0,23,0,biomesoplenty:leaves_4:2)
Block(0,23,1,biomesoplenty:leaves_4:2)
Block(0,23,3,biomesoplenty:leaves_4:2)
Block(0,23,4,biomesoplenty:leaves_4:2)
Block(0,23,5,biomesoplenty:leaves_4:2)
Block(0,23,6,biomesoplenty:leaves_4:2)
Block(0,23,8,biomesoplenty:leaves_4:2)
Block(0,24,-2,biomesoplenty:leaves_4:2)
Block(0,24,-1,biomesoplenty:leaves_4:2)
Block(0,24,0,biomesoplenty:leaves_4:2)
Block(0,24,1,biomesoplenty:log_2)
Block(0,24,2,biomesoplenty:leaves_4:2)
Block(0,24,3,biomesoplenty:leaves_4:2)
Block(0,24,4,biomesoplenty:leaves_4:2)
Block(0,24,5,biomesoplenty:leaves_4:2)
Block(0,24,6,biomesoplenty:leaves_4:2)
Block(0,24,7,biomesoplenty:leaves_4:2)
Block(0,24,8,biomesoplenty:leaves_4:2)
Block(0,25,-3,biomesoplenty:leaves_4:2)
Block(0,25,-2,biomesoplenty:leaves_4:2)
Block(0,25,-1,biomesoplenty:leaves_4:2)
Block(0,25,0,biomesoplenty:leaves_4:2)
Block(0,25,1,biomesoplenty:leaves_4:2)
Block(0,25,2,biomesoplenty:leaves_4:2)
Block(0,25,3,biomesoplenty:leaves_4:2)
Block(0,25,4,biomesoplenty:log_2)
Block(0,25,5,biomesoplenty:leaves_4:2)
Block(0,25,6,biomesoplenty:leaves_4:2)
Block(0,25,8,biomesoplenty:leaves_4:2)
Block(0,26,-2,biomesoplenty:leaves_4:2)
Block(0,26,-1,biomesoplenty:leaves_4:2)
Block(0,26,0,biomesoplenty:leaves_4:2)
Block(0,26,1,biomesoplenty:leaves_4:2)
Block(0,26,2,biomesoplenty:leaves_4:2)
Block(0,26,3,biomesoplenty:leaves_4:2)
Block(0,26,4,biomesoplenty:log_2)
Block(0,26,5,biomesoplenty:leaves_4:2)
Block(0,26,6,biomesoplenty:leaves_4:2)
Block(0,26,7,biomesoplenty:leaves_4:2)
Block(0,27,-2,biomesoplenty:leaves_4:2)
Block(0,27,0,biomesoplenty:leaves_4:2)
Block(0,27,1,biomesoplenty:leaves_4:2)
Block(0,27,2,biomesoplenty:leaves_4:2)
Block(0,27,3,biomesoplenty:leaves_4:2)
Block(0,27,4,biomesoplenty:leaves_4:2)
Block(0,27,6,biomesoplenty:leaves_4:2)
Block(0,27,7,biomesoplenty:leaves_4:2)
Block(0,28,-2,biomesoplenty:leaves_4:2)
Block(0,28,-1,biomesoplenty:leaves_4:2)
Block(0,28,0,biomesoplenty:leaves_4:2)
Block(0,28,1,biomesoplenty:log_2)
Block(0,28,2,biomesoplenty:log_2)
Block(0,28,4,biomesoplenty:leaves_4:2)
Block(0,28,5,biomesoplenty:leaves_4:2)
Block(0,28,6,biomesoplenty:leaves_4:2)
Block(0,29,-1,biomesoplenty:leaves_4:2)
Block(0,29,0,biomesoplenty:leaves_4:2)
Block(0,29,1,biomesoplenty:log_2)
Block(0,29,3,biomesoplenty:leaves_4:2)
Block(0,29,6,biomesoplenty:leaves_4:2)
Block(0,29,7,biomesoplenty:leaves_4:2)
Block(0,29,8,biomesoplenty:leaves_4:2)
Block(0,29,9,biomesoplenty:leaves_4:2)
Block(0,30,-1,biomesoplenty:leaves_4:2)
Block(0,30,0,biomesoplenty:leaves_4:2)
Block(0,30,1,biomesoplenty:leaves_4:2)
Block(0,30,2,biomesoplenty:leaves_4:2)
Block(0,30,3,biomesoplenty:leaves_4:2)
Block(0,30,6,biomesoplenty:leaves_4:2)
Block(0,30,7,biomesoplenty:leaves_4:2)
Block(0,31,0,biomesoplenty:leaves_4:2)
Block(0,31,1,biomesoplenty:leaves_4:2)
Block(0,31,2,biomesoplenty:leaves_4:2)
Block(0,31,3,biomesoplenty:leaves_4:2)
Block(0,31,7,biomesoplenty:leaves_4:2)
Block(0,32,1,biomesoplenty:leaves_4:2)
Block(0,32,2,biomesoplenty:leaves_4:2)
Block(0,32,4,biomesoplenty:leaves_4:2)
Block(0,33,0,biomesoplenty:leaves_4:2)
Block(0,33,1,biomesoplenty:log_2:8)
Block(0,33,2,biomesoplenty:log_2:8)
Block(0,33,3,biomesoplenty:log_2)
Block(0,33,5,biomesoplenty:leaves_4:2)
Block(0,33,6,biomesoplenty:leaves_4:2)
Block(0,33,7,biomesoplenty:leaves_4:2)
Block(0,34,1,biomesoplenty:leaves_4:2)
Block(0,34,2,biomesoplenty:log_2:8)
Block(0,34,3,biomesoplenty:log_2)
Block(0,34,4,biomesoplenty:leaves_4:2)
Block(0,34,5,biomesoplenty:leaves_4:2)
Block(0,34,6,biomesoplenty:leaves_4:2)
Block(0,34,7,biomesoplenty:leaves_4:2)
Block(0,34,8,biomesoplenty:leaves_4:2)
Block(0,35,0,biomesoplenty:leaves_4:2)
Block(0,35,1,biomesoplenty:leaves_4:2)
Block(0,35,2,biomesoplenty:leaves_4:2)
Block(0,35,3,biomesoplenty:leaves_4:2)
Block(0,35,4,biomesoplenty:leaves_4:2)
Block(0,35,5,biomesoplenty:leaves_4:2)
Block(0,35,6,biomesoplenty:log_2)
Block(0,35,7,biomesoplenty:leaves_4:2)
Block(0,35,8,biomesoplenty:leaves_4:2)
Block(0,36,0,biomesoplenty:leaves_4:2)
Block(0,36,2,biomesoplenty:leaves_4:2)
Block(0,36,3,biomesoplenty:log_2)
Block(0,36,4,biomesoplenty:leaves_4:2)
Block(0,36,6,biomesoplenty:leaves_4:2)
Block(0,37,0,biomesoplenty:leaves_4:2)
Block(0,37,1,biomesoplenty:leaves_4:2)
Block(0,37,2,biomesoplenty:leaves_4:2)
Block(0,37,3,biomesoplenty:log_2)
Block(0,37,4,biomesoplenty:leaves_4:2)
Block(0,37,5,biomesoplenty:leaves_4:2)
Block(0,37,6,biomesoplenty:leaves_4:2)
Block(0,37,7,biomesoplenty:leaves_4:2)
Block(0,38,1,biomesoplenty:leaves_4:2)
Block(0,38,2,biomesoplenty:leaves_4:2)
Block(0,38,3,biomesoplenty:leaves_4:2)
Block(0,38,5,biomesoplenty:leaves_4:2)
Block(0,38,7,biomesoplenty:leaves_4:2)
Block(0,39,1,biomesoplenty:leaves_4:2)
Block(0,39,3,biomesoplenty:leaves_4:2)
Block(0,39,4,biomesoplenty:leaves_4:2)
Block(0,39,5,biomesoplenty:leaves_4:2)
Block(0,39,6,biomesoplenty:leaves_4:2)
Block(0,39,7,biomesoplenty:leaves_4:2)
Block(0,39,8,biomesoplenty:leaves_4:2)
Block(0,40,3,biomesoplenty:log_2)
Block(0,40,4,biomesoplenty:leaves_4:2)
Block(0,40,5,biomesoplenty:leaves_4:2)
Block(0,40,6,biomesoplenty:leaves_4:2)
Block(0,40,7,biomesoplenty:leaves_4:2)
Block(0,40,8,biomesoplenty:leaves_4:2)
Block(0,41,1,biomesoplenty:leaves_4:2)
Block(0,41,2,biomesoplenty:leaves_4:2)
Block(0,41,3,biomesoplenty:leaves_4:2)
Block(0,41,4,biomesoplenty:leaves_4:2)
Block(0,41,5,biomesoplenty:leaves_4:2)
Block(0,41,8,biomesoplenty:leaves_4:2)
Block(0,42,1,biomesoplenty:leaves_4:2)
Block(0,42,3,biomesoplenty:leaves_4:2)
Block(0,42,4,biomesoplenty:leaves_4:2)
Block(0,42,5,biomesoplenty:leaves_4:2)
Block(0,43,0,biomesoplenty:leaves_4:2)
Block(0,43,1,biomesoplenty:leaves_4:2)
Block(0,43,2,biomesoplenty:leaves_4:2)
Block(0,43,3,biomesoplenty:leaves_4:2)
Block(0,43,4,biomesoplenty:leaves_4:2)
Block(0,43,5,biomesoplenty:leaves_4:2)
Block(0,44,0,biomesoplenty:leaves_4:2)
Block(0,44,2,biomesoplenty:leaves_4:2)
Block(0,44,3,biomesoplenty:leaves_4:2)
Block(0,44,4,biomesoplenty:leaves_4:2)
Block(0,44,5,biomesoplenty:leaves_4:2)
Block(0,45,3,biomesoplenty:leaves_4:2)
Block(0,46,3,biomesoplenty:leaves_4:2)
Block(1,0,0,biomesoplenty:log_2)
Block(1,0,1,biomesoplenty:log_2)
Block(1,0,2,biomesoplenty:log_2)
Block(1,0,3,biomesoplenty:log_2)
Block(1,0,4,biomesoplenty:log_2)
Block(1,0,5,biomesoplenty:log_2)
Block(1,1,0,biomesoplenty:log_2)
Block(1,1,1,biomesoplenty:log_2)
Block(1,1,2,biomesoplenty:log_2)
Block(1,1,3,biomesoplenty:log_2)
Block(1,1,4,biomesoplenty:log_2)
Block(1,1,5,biomesoplenty:log_2)
Block(1,2,0,biomesoplenty:log_2)
Block(1,2,1,biomesoplenty:log_2)
Block(1,2,2,biomesoplenty:log_2)
Block(1,2,3,biomesoplenty:log_2)
Block(1,2,4,biomesoplenty:log_2)
Block(1,3,1,biomesoplenty:log_2)
Block(1,3,2,biomesoplenty:log_2)
Block(1,3,3,biomesoplenty:log_2)
Block(1,3,4,biomesoplenty:log_2)
Block(1,3,5,biomesoplenty:leaves_4:2)
Block(1,3,6,biomesoplenty:leaves_4:2)
Block(1,4,2,biomesoplenty:log_2)
Block(1,4,3,biomesoplenty:log_2)
Block(1,4,4,biomesoplenty:leaves_4:2)
Block(1,4,5,biomesoplenty:leaves_4:2)
Block(1,4,6,biomesoplenty:leaves_4:2)
Block(1,4,7,biomesoplenty:leaves_4:2)
Block(1,5,2,biomesoplenty:leaves_4:2)
Block(1,5,3,biomesoplenty:leaves_4:2)
Block(1,5,4,biomesoplenty:leaves_4:2)
Block(1,5,5,biomesoplenty:leaves_4:2)
Block(1,5,6,biomesoplenty:leaves_4:2)
Block(1,6,2,biomesoplenty:leaves_4:2)
Block(1,18,0,biomesoplenty:leaves_4:2)
Block(1,18,3,biomesoplenty:leaves_4:2)
Block(1,18,4,biomesoplenty:leaves_4:2)
Block(1,18,5,biomesoplenty:leaves_4:2)
Block(1,19,-4,biomesoplenty:leaves_4:2)
Block(1,19,-3,biomesoplenty:leaves_4:2)
Block(1,19,-2,biomesoplenty:leaves_4:2)
Block(1,19,-1,biomesoplenty:leaves_4:2)
Block(1,19,0,biomesoplenty:leaves_4:2)
Block(1,19,1,biomesoplenty:leaves_4:2)
Block(1,19,2,biomesoplenty:leaves_4:2)
Block(1,19,3,biomesoplenty:leaves_4:2)
Block(1,19,4,biomesoplenty:log_2)
Block(1,19,5,biomesoplenty:log_2:8)
Block(1,19,6,biomesoplenty:leaves_4:2)
Block(1,20,-4,biomesoplenty:leaves_4:2)
Block(1,20,-3,biomesoplenty:leaves_4:2)
Block(1,20,-2,biomesoplenty:leaves_4:2)
Block(1,20,-1,biomesoplenty:leaves_4:2)
Block(1,20,0,biomesoplenty:log_2:8)
Block(1,20,1,biomesoplenty:log_2)
Block(1,20,2,biomesoplenty:leaves_4:2)
Block(1,20,3,biomesoplenty:leaves_4:2)
Block(1,20,4,biomesoplenty:log_2)
Block(1,20,5,biomesoplenty:leaves_4:2)
Block(1,20,6,biomesoplenty:leaves_4:2)
Block(1,21,-4,biomesoplenty:leaves_4:2)
Block(1,21,-3,biomesoplenty:leaves_4:2)
Block(1,21,-2,biomesoplenty:leaves_4:2)
Block(1,21,-1,biomesoplenty:leaves_4:2)
Block(1,21,0,biomesoplenty:leaves_4:2)
Block(1,21,1,biomesoplenty:leaves_4:2)
Block(1,21,2,biomesoplenty:leaves_4:2)
Block(1,21,3,biomesoplenty:leaves_4:2)
Block(1,21,4,biomesoplenty:leaves_4:2)
Block(1,21,5,biomesoplenty:leaves_4:2)
Block(1,21,6,biomesoplenty:leaves_4:2)
Block(1,22,-4,biomesoplenty:leaves_4:2)
Block(1,22,-3,biomesoplenty:leaves_4:2)
Block(1,22,-2,biomesoplenty:leaves_4:2)
Block(1,22,-1,biomesoplenty:leaves_4:2)
Block(1,22,0,biomesoplenty:leaves_4:2)
Block(1,22,1,biomesoplenty:leaves_4:2)
Block(1,22,2,biomesoplenty:leaves_4:2)
Block(1,22,3,biomesoplenty:leaves_4:2)
Block(1,22,4,biomesoplenty:leaves_4:2)
Block(1,22,5,biomesoplenty:leaves_4:2)
Block(1,22,6,biomesoplenty:leaves_4:2)
Block(1,22,7,biomesoplenty:leaves_4:2)
Block(1,23,-4,biomesoplenty:leaves_4:2)
Block(1,23,-3,biomesoplenty:leaves_4:2)
Block(1,23,-2,biomesoplenty:leaves_4:2)
Block(1,23,-1,biomesoplenty:leaves_4:2)
Block(1,23,0,biomesoplenty:leaves_4:2)
Block(1,23,1,biomesoplenty:leaves_4:2)
Block(1,23,2,biomesoplenty:leaves_4:2)
Block(1,23,3,biomesoplenty:leaves_4:2)
Block(1,23,4,biomesoplenty:leaves_4:2)
Block(1,23,5,biomesoplenty:leaves_4:2)
Block(1,23,6,biomesoplenty:leaves_4:2)
Block(1,23,7,biomesoplenty:leaves_4:2)
Block(1,23,8,biomesoplenty:leaves_4:2)
Block(1,23,9,biomesoplenty:leaves_4:2)
Block(1,24,-4,biomesoplenty:leaves_4:2)
Block(1,24,-3,biomesoplenty:leaves_4:2)
Block(1,24,-2,biomesoplenty:leaves_4:2)
Block(1,24,-1,biomesoplenty:leaves_4:2)
Block(1,24,0,biomesoplenty:leaves_4:2)
Block(1,24,1,biomesoplenty:log_2)
Block(1,24,2,biomesoplenty:leaves_4:2)
Block(1,24,3,biomesoplenty:leaves_4:2)
Block(1,24,4,biomesoplenty:leaves_4:2)
Block(1,24,5,biomesoplenty:leaves_4:2)
Block(1,24,6,biomesoplenty:leaves_4:2)
Block(1,24,7,biomesoplenty:log_2)
Block(1,24,8,biomesoplenty:leaves_4:2)
Block(1,24,9,biomesoplenty:leaves_4:2)
Block(1,25,-2,biomesoplenty:leaves_4:2)
Block(1,25,-1,biomesoplenty:leaves_4:2)
Block(1,25,0,biomesoplenty:leaves_4:2)
Block(1,25,1,biomesoplenty:leaves_4:2)
Block(1,25,2,biomesoplenty:leaves_4:2)
Block(1,25,4,biomesoplenty:log_2)
Block(1,25,5,biomesoplenty:leaves_4:2)
Block(1,25,6,biomesoplenty:leaves_4:2)
Block(1,25,7,biomesoplenty:leaves_4:2)
Block(1,25,8,biomesoplenty:leaves_4:2)
Block(1,26,-4,biomesoplenty:leaves_4:2)
Block(1,26,-3,biomesoplenty:leaves_4:2)
Block(1,26,-2,biomesoplenty:leaves_4:2)
Block(1,26,-1,biomesoplenty:leaves_4:2)
Block(1,26,0,biomesoplenty:leaves_4:2)
Block(1,26,1,biomesoplenty:leaves_4:2)
Block(1,26,5,biomesoplenty:leaves_4:2)
Block(1,26,6,biomesoplenty:leaves_4:2)
Block(1,27,-2,biomesoplenty:leaves_4:2)
Block(1,27,-1,biomesoplenty:leaves_4:2)
Block(1,27,0,biomesoplenty:leaves_4:2)
Block(1,27,1,biomesoplenty:leaves_4:2)
Block(1,27,4,biomesoplenty:leaves_4:2)
Block(1,27,5,biomesoplenty:leaves_4:2)
Block(1,27,6,biomesoplenty:leaves_4:2)
Block(1,27,7,biomesoplenty:leaves_4:2)
Block(1,28,-1,biomesoplenty:leaves_4:2)
Block(1,28,0,biomesoplenty:leaves_4:2)
Block(1,28,1,biomesoplenty:log_2:8)
Block(1,28,2,biomesoplenty:log_2)
Block(1,28,4,biomesoplenty:leaves_4:2)
Block(1,28,5,biomesoplenty:leaves_4:2)
Block(1,28,6,biomesoplenty:leaves_4:2)
Block(1,28,7,biomesoplenty:leaves_4:2)
Block(1,28,8,biomesoplenty:leaves_4:2)
Block(1,28,9,biomesoplenty:leaves_4:2)
Block(1,29,-2,biomesoplenty:leaves_4:2)
Block(1,29,-1,biomesoplenty:leaves_4:2)
Block(1,29,1,biomesoplenty:log_2:8)
Block(1,29,2,biomesoplenty:log_2)
Block(1,29,5,biomesoplenty:leaves_4:2)
Block(1,29,6,biomesoplenty:leaves_4:2)
Block(1,29,7,biomesoplenty:leaves_4:2)
Block(1,29,8,biomesoplenty:leaves_4:2)
Block(1,30,-1,biomesoplenty:leaves_4:2)
Block(1,30,1,biomesoplenty:leaves_4:2)
Block(1,30,4,biomesoplenty:leaves_4:2)
Block(1,30,5,biomesoplenty:leaves_4:2)
Block(1,30,6,biomesoplenty:log_2)
Block(1,30,7,biomesoplenty:leaves_4:2)
Block(1,30,8,biomesoplenty:log_2)
Block(1,30,10,biomesoplenty:leaves_4:2)
Block(1,31,0,biomesoplenty:leaves_4:2)
Block(1,31,1,biomesoplenty:leaves_4:2)
Block(1,31,2,biomesoplenty:leaves_4:2)
Block(1,31,5,biomesoplenty:leaves_4:2)
Block(1,31,6,biomesoplenty:leaves_4:2)
Block(1,31,7,biomesoplenty:leaves_4:2)
Block(1,31,8,biomesoplenty:leaves_4:2)
Block(1,31,10,biomesoplenty:leaves_4:2)
Block(1,32,2,biomesoplenty:leaves_4:2)
Block(1,32,4,biomesoplenty:log_2)
Block(1,32,5,biomesoplenty:leaves_4:2)
Block(1,32,6,biomesoplenty:leaves_4:2)
Block(1,32,7,biomesoplenty:leaves_4:2)
Block(1,32,8,biomesoplenty:leaves_4:2)
Block(1,33,1,biomesoplenty:leaves_4:2)
Block(1,33,2,biomesoplenty:leaves_4:2)
Block(1,33,3,biomesoplenty:log_2:8)
Block(1,33,4,biomesoplenty:log_2)
Block(1,33,5,biomesoplenty:leaves_4:2)
Block(1,33,6,biomesoplenty:leaves_4:2)
Block(1,33,7,biomesoplenty:leaves_4:2)
Block(1,33,8,biomesoplenty:leaves_4:2)
Block(1,34,0,biomesoplenty:leaves_4:2)
Block(1,34,1,biomesoplenty:leaves_4:2)
Block(1,34,2,biomesoplenty:leaves_4:2)
Block(1,34,3,biomesoplenty:leaves_4:2)
Block(1,34,5,biomesoplenty:leaves_4:2)
Block(1,34,6,biomesoplenty:log_2)
Block(1,34,7,biomesoplenty:leaves_4:2)
Block(1,34,8,biomesoplenty:leaves_4:2)
Block(1,35,-2,biomesoplenty:leaves_4:2)
Block(1,35,0,biomesoplenty:leaves_4:2)
Block(1,35,1,biomesoplenty:leaves_4:2)
Block(1,35,2,biomesoplenty:leaves_4:2)
Block(1,35,3,biomesoplenty:leaves_4:2)
Block(1,35,4,biomesoplenty:leaves_4:2)
Block(1,35,5,biomesoplenty:leaves_4:2)
Block(1,35,6,biomesoplenty:log_2)
Block(1,35,7,biomesoplenty:leaves_4:2)
Block(1,35,8,biomesoplenty:leaves_4:2)
Block(1,36,-3,biomesoplenty:leaves_4:2)
Block(1,36,-2,biomesoplenty:leaves_4:2)
Block(1,36,-1,biomesoplenty:leaves_4:2)
Block(1,36,0,biomesoplenty:leaves_4:2)
Block(1,36,1,biomesoplenty:leaves_4:2)
Block(1,36,2,biomesoplenty:leaves_4:2)
Block(1,36,3,biomesoplenty:log_2)
Block(1,36,4,biomesoplenty:leaves_4:2)
Block(1,36,6,biomesoplenty:leaves_4:2)
Block(1,36,7,biomesoplenty:leaves_4:2)
Block(1,36,8,biomesoplenty:leaves_4:2)
Block(1,37,-2,biomesoplenty:leaves_4:2)
Block(1,37,0,biomesoplenty:leaves_4:2)
Block(1,37,1,biomesoplenty:leaves_4:2)
Block(1,37,2,biomesoplenty:leaves_4:2)
Block(1,37,3,biomesoplenty:leaves_4:2)
Block(1,37,4,biomesoplenty:leaves_4:2)
Block(1,37,5,biomesoplenty:leaves_4:2)
Block(1,37,7,biomesoplenty:leaves_4:2)
Block(1,38,1,biomesoplenty:leaves_4:2)
Block(1,38,2,biomesoplenty:leaves_4:2)
Block(1,38,3,biomesoplenty:leaves_4:2)
Block(1,38,4,biomesoplenty:leaves_4:2)
Block(1,38,5,biomesoplenty:leaves_4:2)
Block(1,38,6,biomesoplenty:leaves_4:2)
Block(1,38,7,biomesoplenty:leaves_4:2)
Block(1,38,8,biomesoplenty:leaves_4:2)
Block(1,39,1,biomesoplenty:leaves_4:2)
Block(1,39,2,biomesoplenty:leaves_4:2)
Block(1,39,3,biomesoplenty:log_2)
Block(1,39,4,biomesoplenty:leaves_4:2)
Block(1,39,5,biomesoplenty:leaves_4:2)
Block(1,39,6,biomesoplenty:leaves_4:2)
Block(1,39,7,biomesoplenty:leaves_4:2)
Block(1,39,8,biomesoplenty:leaves_4:2)
Block(1,40,1,biomesoplenty:leaves_4:2)
Block(1,40,2,biomesoplenty:leaves_4:2)
Block(1,40,3,biomesoplenty:log_2)
Block(1,40,4,biomesoplenty:log_2)
Block(1,40,5,biomesoplenty:leaves_4:2)
Block(1,40,6,biomesoplenty:leaves_4:2)
Block(1,40,7,biomesoplenty:leaves_4:2)
Block(1,40,8,biomesoplenty:leaves_4:2)
Block(1,40,9,biomesoplenty:leaves_4:2)
Block(1,41,0,biomesoplenty:leaves_4:2)
Block(1,41,1,biomesoplenty:leaves_4:2)
Block(1,41,3,biomesoplenty:leaves_4:2)
Block(1,41,4,biomesoplenty:leaves_4:2)
Block(1,41,7,biomesoplenty:leaves_4:2)
Block(1,41,8,biomesoplenty:leaves_4:2)
Block(1,41,9,biomesoplenty:leaves_4:2)
Block(1,42,0,biomesoplenty:leaves_4:2)
Block(1,42,1,biomesoplenty:leaves_4:2)
Block(1,42,2,biomesoplenty:leaves_4:2)
Block(1,42,3,biomesoplenty:leaves_4:2)
Block(1,42,4,biomesoplenty:leaves_4:2)
Block(1,42,5,biomesoplenty:leaves_4:2)
Block(1,42,6,biomesoplenty:leaves_4:2)
Block(1,42,7,biomesoplenty:leaves_4:2)
Block(1,42,8,biomesoplenty:leaves_4:2)
Block(1,43,0,biomesoplenty:log_2:8)
Block(1,43,1,biomesoplenty:log_2)
Block(1,43,2,biomesoplenty:leaves_4:2)
Block(1,43,3,biomesoplenty:log_2)
Block(1,43,4,biomesoplenty:leaves_4:2)
Block(1,43,6,biomesoplenty:leaves_4:2)
Block(1,44,-1,biomesoplenty:leaves_4:2)
Block(1,44,0,biomesoplenty:leaves_4:2)
Block(1,44,1,biomesoplenty:leaves_4:2)
Block(1,44,2,biomesoplenty:leaves_4:2)
Block(1,44,3,biomesoplenty:leaves_4:2)
Block(1,44,4,biomesoplenty:leaves_4:2)
Block(1,45,-1,biomesoplenty:leaves_4:2)
Block(1,45,0,biomesoplenty:leaves_4:2)
Block(1,45,1,biomesoplenty:leaves_4:2)
Block(1,45,2,biomesoplenty:leaves_4:2)
Block(1,45,3,biomesoplenty:leaves_4:2)
Block(1,45,4,biomesoplenty:leaves_4:2)
Block(1,45,5,biomesoplenty:leaves_4:2)
Block(1,46,0,biomesoplenty:leaves_4:2)
Block(1,46,1,biomesoplenty:leaves_4:2)
Block(1,46,2,biomesoplenty:leaves_4:2)
Block(1,46,3,biomesoplenty:leaves_4:2)
Block(1,46,4,biomesoplenty:leaves_4:2)
Block(1,47,1,biomesoplenty:leaves_4:2)
Block(1,47,2,biomesoplenty:leaves_4:2)
Block(1,47,3,biomesoplenty:leaves_4:2)
Block(1,47,4,biomesoplenty:leaves_4:2)
Block(1,48,2,biomesoplenty:leaves_4:2)
Block(1,48,3,biomesoplenty:leaves_4:2)
Block(1,48,4,biomesoplenty:leaves_4:2)
Block(1,49,2,biomesoplenty:leaves_4:2)
Block(1,49,3,biomesoplenty:leaves_4:2)
Block(1,49,4,biomesoplenty:leaves_4:2)
Block(1,50,2,biomesoplenty:leaves_4:2)
Block(1,50,3,biomesoplenty:leaves_4:2)
Block(2,0,0,biomesoplenty:log_2)
Block(2,0,1,biomesoplenty:log_2)
Block(2,0,2,biomesoplenty:log_2)
Block(2,0,3,biomesoplenty:log_2)
Block(2,0,4,biomesoplenty:log_2)
Block(2,0,5,biomesoplenty:log_2)
Block(2,0,6,biomesoplenty:log_2)
Block(2,1,0,biomesoplenty:log_2)
Block(2,1,1,biomesoplenty:log_2)
Block(2,1,2,biomesoplenty:log_2)
Block(2,1,3,biomesoplenty:log_2)
Block(2,1,4,biomesoplenty:log_2)
Block(2,1,5,biomesoplenty:log_2)
Block(2,2,1,biomesoplenty:log_2)
Block(2,2,2,biomesoplenty:log_2)
Block(2,2,3,biomesoplenty:log_2)
Block(2,2,4,biomesoplenty:log_2)
Block(2,2,5,biomesoplenty:log_2)
Block(2,3,1,biomesoplenty:log_2)
Block(2,3,2,biomesoplenty:log_2)
Block(2,3,3,biomesoplenty:log_2)
Block(2,3,4,biomesoplenty:log_2)
Block(2,3,5,biomesoplenty:log_2)
Block(2,3,6,biomesoplenty:leaves_4:2)
Block(2,4,2,biomesoplenty:log_2)
Block(2,4,3,biomesoplenty:log_2)
Block(2,4,4,biomesoplenty:log_2)
Block(2,4,5,biomesoplenty:leaves_4:2)
Block(2,4,6,biomesoplenty:leaves_4:2)
Block(2,4,7,biomesoplenty:leaves_4:2)
Block(2,5,2,biomesoplenty:log_2)
Block(2,5,3,biomesoplenty:log_2)
Block(2,5,4,biomesoplenty:log_2)
Block(2,5,5,biomesoplenty:leaves_4:2)
Block(2,5,6,biomesoplenty:leaves_4:2)
Block(2,6,2,biomesoplenty:log_2)
Block(2,6,3,biomesoplenty:log_2)
Block(2,6,4,biomesoplenty:log_2)
Block(2,6,5,biomesoplenty:leaves_4:2)
Block(2,7,2,biomesoplenty:log_2)
Block(2,7,3,biomesoplenty:log_2)
Block(2,7,4,biomesoplenty:log_2)
Block(2,8,2,biomesoplenty:log_2)
Block(2,8,3,biomesoplenty:log_2)
Block(2,9,3,biomesoplenty:log_2)
Block(2,10,3,biomesoplenty:log_2)
Block(2,11,3,biomesoplenty:log_2)
Block(2,12,3,biomesoplenty:log_2)
Block(2,13,3,biomesoplenty:log_2)
Block(2,14,3,biomesoplenty:log_2)
Block(2,15,3,biomesoplenty:log_2)
Block(2,16,3,biomesoplenty:log_2)
Block(2,17,3,biomesoplenty:log_2)
Block(2,18,1,biomesoplenty:leaves_4:2)
Block(2,18,2,biomesoplenty:leaves_4:2)
Block(2,18,3,biomesoplenty:log_2)
Block(2,19,-3,biomesoplenty:leaves_4:2)
Block(2,19,-2,biomesoplenty:leaves_4:2)
Block(2,19,-1,biomesoplenty:leaves_4:2)
Block(2,19,0,biomesoplenty:leaves_4:2)
Block(2,19,1,biomesoplenty:leaves_4:2)
Block(2,19,2,biomesoplenty:leaves_4:2)
Block(2,19,3,biomesoplenty:log_2)
Block(2,19,4,biomesoplenty:log_2)
Block(2,19,5,biomesoplenty:leaves_4:2)
Block(2,20,-4,biomesoplenty:leaves_4:2)
Block(2,20,-3,biomesoplenty:leaves_4:2)
Block(2,20,-2,biomesoplenty:leaves_4:2)
Block(2,20,-1,biomesoplenty:leaves_4:2)
Block(2,20,0,biomesoplenty:leaves_4:2)
Block(2,20,1,biomesoplenty:log_2:8)
Block(2,20,2,biomesoplenty:log_2:8)
Block(2,20,3,biomesoplenty:log_2)
Block(2,20,4,biomesoplenty:log_2:8)
Block(2,20,5,biomesoplenty:leaves_4:2)
Block(2,21,-3,biomesoplenty:leaves_4:2)
Block(2,21,-2,biomesoplenty:leaves_4:2)
Block(2,21,-1,biomesoplenty:leaves_4:2)
Block(2,21,0,biomesoplenty:leaves_4:2)
Block(2,21,2,biomesoplenty:log_2:8)
Block(2,21,3,biomesoplenty:log_2)
Block(2,21,4,biomesoplenty:leaves_4:2)
Block(2,21,5,biomesoplenty:leaves_4:2)
Block(2,21,6,biomesoplenty:leaves_4:2)
Block(2,22,-5,biomesoplenty:leaves_4:2)
Block(2,22,-4,biomesoplenty:leaves_4:2)
Block(2,22,-3,biomesoplenty:leaves_4:2)
Block(2,22,-2,biomesoplenty:leaves_4:2)
Block(2,22,-1,biomesoplenty:leaves_4:2)
Block(2,22,0,biomesoplenty:leaves_4:2)
Block(2,22,2,biomesoplenty:leaves_4:2)
Block(2,22,3,biomesoplenty:log_2)
Block(2,22,4,biomesoplenty:leaves_4:2)
Block(2,22,5,biomesoplenty:leaves_4:2)
Block(2,22,6,biomesoplenty:leaves_4:2)
Block(2,22,7,biomesoplenty:leaves_4:2)
Block(2,22,8,biomesoplenty:leaves_4:2)
Block(2,22,9,biomesoplenty:leaves_4:2)
Block(2,23,-4,biomesoplenty:leaves_4:2)
Block(2,23,-3,biomesoplenty:leaves_4:2)
Block(2,23,-2,biomesoplenty:leaves_4:2)
Block(2,23,-1,biomesoplenty:log_2:8)
Block(2,23,0,biomesoplenty:log_2)
Block(2,23,2,biomesoplenty:leaves_4:2)
Block(2,23,3,biomesoplenty:log_2)
Block(2,23,5,biomesoplenty:leaves_4:2)
Block(2,23,6,biomesoplenty:leaves_4:2)
Block(2,23,7,biomesoplenty:leaves_4:2)
Block(2,23,8,biomesoplenty:leaves_4:2)
Block(2,23,9,biomesoplenty:leaves_4:2)
Block(2,23,10,biomesoplenty:leaves_4:2)
Block(2,24,-3,biomesoplenty:log_2:8)
Block(2,24,-2,biomesoplenty:log_2:8)
Block(2,24,-1,biomesoplenty:log_2:8)
Block(2,24,0,biomesoplenty:log_2:8)
Block(2,24,1,biomesoplenty:log_2:8)
Block(2,24,2,biomesoplenty:log_2)
Block(2,24,3,biomesoplenty:log_2)
Block(2,24,4,biomesoplenty:leaves_4:2)
Block(2,24,5,biomesoplenty:leaves_4:2)
Block(2,24,6,biomesoplenty:leaves_4:2)
Block(2,24,7,biomesoplenty:log_2)
Block(2,24,8,biomesoplenty:leaves_4:2)
Block(2,24,9,biomesoplenty:leaves_4:2)
Block(2,24,10,biomesoplenty:leaves_4:2)
Block(2,25,-4,biomesoplenty:leaves_4:2)
Block(2,25,-3,biomesoplenty:leaves_4:2)
Block(2,25,-2,biomesoplenty:leaves_4:2)
Block(2,25,-1,biomesoplenty:leaves_4:2)
Block(2,25,0,biomesoplenty:leaves_4:2)
Block(2,25,1,biomesoplenty:leaves_4:2)
Block(2,25,3,biomesoplenty:log_2)
Block(2,25,4,biomesoplenty:log_2)
Block(2,25,5,biomesoplenty:leaves_4:2)
Block(2,25,6,biomesoplenty:leaves_4:2)
Block(2,25,7,biomesoplenty:leaves_4:2)
Block(2,25,8,biomesoplenty:leaves_4:2)
Block(2,25,9,biomesoplenty:leaves_4:2)
Block(2,25,10,biomesoplenty:leaves_4:2)
Block(2,26,-4,biomesoplenty:leaves_4:2)
Block(2,26,-2,biomesoplenty:leaves_4:2)
Block(2,26,-1,biomesoplenty:leaves_4:2)
Block(2,26,0,biomesoplenty:leaves_4:2)
Block(2,26,1,biomesoplenty:leaves_4:2)
Block(2,26,2,biomesoplenty:leaves_4:2)
Block(2,26,3,biomesoplenty:log_2)
Block(2,26,4,biomesoplenty:leaves_4:2)
Block(2,26,6,biomesoplenty:leaves_4:2)
Block(2,26,7,biomesoplenty:leaves_4:2)
Block(2,26,8,biomesoplenty:leaves_4:2)
Block(2,27,-4,biomesoplenty:leaves_4:2)
Block(2,27,-3,biomesoplenty:leaves_4:2)
Block(2,27,-2,biomesoplenty:leaves_4:2)
Block(2,27,-1,biomesoplenty:leaves_4:2)
Block(2,27,0,biomesoplenty:leaves_4:2)
Block(2,27,1,biomesoplenty:leaves_4:2)
Block(2,27,2,biomesoplenty:leaves_4:2)
Block(2,27,3,biomesoplenty:log_2)
Block(2,27,4,biomesoplenty:leaves_4:2)
Block(2,27,5,biomesoplenty:leaves_4:2)
Block(2,27,6,biomesoplenty:leaves_4:2)
Block(2,27,7,biomesoplenty:leaves_4:2)
Block(2,28,-2,biomesoplenty:leaves_4:2)
Block(2,28,-1,biomesoplenty:leaves_4:2)
Block(2,28,0,biomesoplenty:leaves_4:2)
Block(2,28,1,biomesoplenty:leaves_4:2)
Block(2,28,2,biomesoplenty:log_2:8)
Block(2,28,3,biomesoplenty:log_2)
Block(2,28,4,biomesoplenty:log_2:8)
Block(2,28,5,biomesoplenty:leaves_4:2)
Block(2,28,6,biomesoplenty:leaves_4:2)
Block(2,28,7,biomesoplenty:leaves_4:2)
Block(2,28,8,biomesoplenty:leaves_4:2)
Block(2,28,9,biomesoplenty:leaves_4:2)
Block(2,29,-3,biomesoplenty:leaves_4:2)
Block(2,29,-2,biomesoplenty:leaves_4:2)
Block(2,29,-1,biomesoplenty:leaves_4:2)
Block(2,29,0,biomesoplenty:leaves_4:2)
Block(2,29,1,biomesoplenty:leaves_4:2)
Block(2,29,2,biomesoplenty:leaves_4:2)
Block(2,29,3,biomesoplenty:log_2)
Block(2,29,4,biomesoplenty:log_2)
Block(2,29,5,biomesoplenty:log_2:8)
Block(2,29,6,biomesoplenty:log_2:8)
Block(2,29,7,biomesoplenty:leaves_4:2)
Block(2,29,8,biomesoplenty:leaves_4:2)
Block(2,29,9,biomesoplenty:leaves_4:2)
Block(2,29,10,biomesoplenty:leaves_4:2)
Block(2,30,0,biomesoplenty:leaves_4:2)
Block(2,30,1,biomesoplenty:leaves_4:2)
Block(2,30,2,biomesoplenty:leaves_4:2)
Block(2,30,3,biomesoplenty:log_2)
Block(2,30,4,biomesoplenty:leaves_4:2)
Block(2,30,5,biomesoplenty:leaves_4:2)
Block(2,30,6,biomesoplenty:log_2)
Block(2,30,7,biomesoplenty:log_2:8)
Block(2,30,8,biomesoplenty:log_2:8)
Block(2,30,9,biomesoplenty:leaves_4:2)
Block(2,30,10,biomesoplenty:leaves_4:2)
Block(2,31,-2,biomesoplenty:leaves_4:2)
Block(2,31,-1,biomesoplenty:log_2)
Block(2,31,1,biomesoplenty:leaves_4:2)
Block(2,31,2,biomesoplenty:leaves_4:2)
Block(2,31,3,biomesoplenty:log_2)
Block(2,31,5,biomesoplenty:leaves_4:2)
Block(2,31,6,biomesoplenty:leaves_4:2)
Block(2,31,7,biomesoplenty:leaves_4:2)
Block(2,31,8,biomesoplenty:leaves_4:2)
Block(2,31,9,biomesoplenty:leaves_4:2)
Block(2,32,-3,biomesoplenty:leaves_4:2)
Block(2,32,-2,biomesoplenty:leaves_4:2)
Block(2,32,-1,biomesoplenty:leaves_4:2)
Block(2,32,1,biomesoplenty:leaves_4:2)
Block(2,32,2,biomesoplenty:leaves_4:2)
Block(2,32,3,biomesoplenty:log_2)
Block(2,32,4,biomesoplenty:log_2)
Block(2,32,5,biomesoplenty:log_2:8)
Block(2,32,6,biomesoplenty:leaves_4:2)
Block(2,32,7,biomesoplenty:leaves_4:2)
Block(2,32,8,biomesoplenty:leaves_4:2)
Block(2,32,9,biomesoplenty:leaves_4:2)
Block(2,33,-3,biomesoplenty:leaves_4:2)
Block(2,33,-2,biomesoplenty:leaves_4:2)
Block(2,33,-1,biomesoplenty:leaves_4:2)
Block(2,33,1,biomesoplenty:leaves_4:2)
Block(2,33,2,biomesoplenty:leaves_4:2)
Block(2,33,3,biomesoplenty:log_2)
Block(2,33,4,biomesoplenty:log_2)
Block(2,33,5,biomesoplenty:log_2)
Block(2,33,6,biomesoplenty:log_2:8)
Block(2,33,7,biomesoplenty:leaves_4:2)
Block(2,33,8,biomesoplenty:leaves_4:2)
Block(2,34,-2,biomesoplenty:leaves_4:2)
Block(2,34,-1,biomesoplenty:leaves_4:2)
Block(2,34,0,biomesoplenty:leaves_4:2)
Block(2,34,1,biomesoplenty:leaves_4:2)
Block(2,34,2,biomesoplenty:log_2:8)
Block(2,34,3,biomesoplenty:log_2)
Block(2,34,4,biomesoplenty:leaves_4:2)
Block(2,34,5,biomesoplenty:log_2)
Block(2,34,6,biomesoplenty:log_2:8)
Block(2,34,7,biomesoplenty:leaves_4:2)
Block(2,34,8,biomesoplenty:leaves_4:2)
Block(2,35,-3,biomesoplenty:leaves_4:2)
Block(2,35,-2,biomesoplenty:leaves_4:2)
Block(2,35,-1,biomesoplenty:leaves_4:2)
Block(2,35,0,biomesoplenty:leaves_4:2)
Block(2,35,1,biomesoplenty:leaves_4:2)
Block(2,35,2,biomesoplenty:log_2)
Block(2,35,3,biomesoplenty:log_2)
Block(2,35,4,biomesoplenty:leaves_4:2)
Block(2,35,5,biomesoplenty:leaves_4:2)
Block(2,35,6,biomesoplenty:leaves_4:2)
Block(2,35,7,biomesoplenty:leaves_4:2)
Block(2,36,-4,biomesoplenty:leaves_4:2)
Block(2,36,-2,biomesoplenty:leaves_4:2)
Block(2,36,-1,biomesoplenty:log_2)
Block(2,36,0,biomesoplenty:log_2)
Block(2,36,2,biomesoplenty:leaves_4:2)
Block(2,36,3,biomesoplenty:log_2)
Block(2,36,6,biomesoplenty:leaves_4:2)
Block(2,37,-2,biomesoplenty:leaves_4:2)
Block(2,37,-1,biomesoplenty:leaves_4:2)
Block(2,37,0,biomesoplenty:leaves_4:2)
Block(2,37,1,biomesoplenty:leaves_4:2)
Block(2,37,2,biomesoplenty:leaves_4:2)
Block(2,37,3,biomesoplenty:log_2)
Block(2,37,5,biomesoplenty:leaves_4:2)
Block(2,37,6,biomesoplenty:log_2)
Block(2,38,-2,biomesoplenty:leaves_4:2)
Block(2,38,0,biomesoplenty:leaves_4:2)
Block(2,38,1,biomesoplenty:leaves_4:2)
Block(2,38,2,biomesoplenty:leaves_4:2)
Block(2,38,3,biomesoplenty:log_2)
Block(2,38,4,biomesoplenty:leaves_4:2)
Block(2,38,5,biomesoplenty:leaves_4:2)
Block(2,38,6,biomesoplenty:leaves_4:2)
Block(2,38,7,biomesoplenty:leaves_4:2)
Block(2,38,8,biomesoplenty:leaves_4:2)
Block(2,39,1,biomesoplenty:leaves_4:2)
Block(2,39,2,biomesoplenty:leaves_4:2)
Block(2,39,3,biomesoplenty:log_2)
Block(2,39,4,biomesoplenty:leaves_4:2)
Block(2,39,5,biomesoplenty:leaves_4:2)
Block(2,39,6,biomesoplenty:log_2)
Block(2,39,7,biomesoplenty:leaves_4:2)
Block(2,39,8,biomesoplenty:leaves_4:2)
Block(2,39,9,biomesoplenty:leaves_4:2)
Block(2,40,0,biomesoplenty:leaves_4:2)
Block(2,40,1,biomesoplenty:leaves_4:2)
Block(2,40,2,biomesoplenty:leaves_4:2)
Block(2,40,3,biomesoplenty:log_2)
Block(2,40,4,biomesoplenty:log_2:8)
Block(2,40,5,biomesoplenty:leaves_4:2)
Block(2,40,6,biomesoplenty:leaves_4:2)
Block(2,40,7,biomesoplenty:log_2)
Block(2,40,8,biomesoplenty:log_2:8)
Block(2,40,9,biomesoplenty:leaves_4:2)
Block(2,41,1,biomesoplenty:leaves_4:2)
Block(2,41,2,biomesoplenty:leaves_4:2)
Block(2,41,3,biomesoplenty:log_2)
Block(2,41,4,biomesoplenty:leaves_4:2)
Block(2,41,5,biomesoplenty:leaves_4:2)
Block(2,41,6,biomesoplenty:leaves_4:2)
Block(2,41,7,biomesoplenty:leaves_4:2)
Block(2,41,8,biomesoplenty:leaves_4:2)
Block(2,41,9,biomesoplenty:leaves_4:2)
Block(2,42,-1,biomesoplenty:leaves_4:2)
Block(2,42,0,biomesoplenty:leaves_4:2)
Block(2,42,1,biomesoplenty:leaves_4:2)
Block(2,42,2,biomesoplenty:leaves_4:2)
Block(2,42,3,biomesoplenty:log_2)
Block(2,42,4,biomesoplenty:leaves_4:2)
Block(2,42,5,biomesoplenty:leaves_4:2)
Block(2,42,6,biomesoplenty:leaves_4:2)
Block(2,42,7,biomesoplenty:leaves_4:2)
Block(2,43,-1,biomesoplenty:leaves_4:2)
Block(2,43,0,biomesoplenty:log_2:8)
Block(2,43,1,biomesoplenty:log_2:8)
Block(2,43,2,biomesoplenty:log_2:8)
Block(2,43,3,biomesoplenty:log_2)
Block(2,43,4,biomesoplenty:leaves_4:2)
Block(2,43,5,biomesoplenty:leaves_4:2)
Block(2,43,6,biomesoplenty:leaves_4:2)
Block(2,44,-1,biomesoplenty:log_2:8)
Block(2,44,0,biomesoplenty:log_2)
Block(2,44,1,biomesoplenty:leaves_4:2)
Block(2,44,2,biomesoplenty:leaves_4:2)
Block(2,44,3,biomesoplenty:log_2)
Block(2,44,4,biomesoplenty:leaves_4:2)
Block(2,44,5,biomesoplenty:leaves_4:2)
Block(2,44,6,biomesoplenty:leaves_4:2)
Block(2,45,0,biomesoplenty:leaves_4:2)
Block(2,45,1,biomesoplenty:leaves_4:2)
Block(2,45,2,biomesoplenty:leaves_4:2)
Block(2,45,3,biomesoplenty:log_2)
Block(2,45,4,biomesoplenty:leaves_4:2)
Block(2,45,5,biomesoplenty:leaves_4:2)
Block(2,46,0,biomesoplenty:leaves_4:2)
Block(2,46,1,biomesoplenty:leaves_4:2)
Block(2,46,2,biomesoplenty:leaves_4:2)
Block(2,46,3,biomesoplenty:leaves_4:2)
Block(2,46,4,biomesoplenty:leaves_4:2)
Block(2,47,0,biomesoplenty:leaves_4:2)
Block(2,47,2,biomesoplenty:leaves_4:2)
Block(2,47,3,biomesoplenty:leaves_4:2)
Block(2,47,4,biomesoplenty:leaves_4:2)
Block(2,48,1,biomesoplenty:leaves_4:2)
Block(2,48,2,biomesoplenty:leaves_4:2)
Block(2,48,3,biomesoplenty:leaves_4:2)
Block(2,49,2,biomesoplenty:leaves_4:2)
Block(2,49,3,biomesoplenty:leaves_4:2)
Block(2,49,5,biomesoplenty:leaves_4:2)
Block(2,50,1,biomesoplenty:leaves_4:2)
Block(2,50,2,biomesoplenty:leaves_4:2)
Block(2,51,3,biomesoplenty:leaves_4:2)
Block(3,0,-1,biomesoplenty:log_2)
Block(3,0,0,biomesoplenty:log_2)
Block(3,0,1,biomesoplenty:log_2)
Block(3,0,2,biomesoplenty:log_2)
Block(3,0,3,biomesoplenty:log_2)
Block(3,0,4,biomesoplenty:log_2)
Block(3,0,5,biomesoplenty:log_2)
Block(3,0,6,biomesoplenty:log_2)
Block(3,1,1,biomesoplenty:log_2)
Block(3,1,2,biomesoplenty:log_2)
Block(3,1,3,biomesoplenty:log_2)
Block(3,1,4,biomesoplenty:log_2)
Block(3,1,5,biomesoplenty:log_2)
Block(3,1,6,biomesoplenty:log_2)
Block(3,2,0,biomesoplenty:log_2)
Block(3,2,1,biomesoplenty:log_2)
Block(3,2,2,biomesoplenty:log_2)
Block(3,2,3,biomesoplenty:log_2)
Block(3,2,4,biomesoplenty:log_2)
Block(3,2,5,biomesoplenty:log_2)
Block(3,3,1,biomesoplenty:log_2)
Block(3,3,2,biomesoplenty:log_2)
Block(3,3,3,biomesoplenty:log_2)
Block(3,3,4,biomesoplenty:log_2)
Block(3,3,5,biomesoplenty:log_2)
Block(3,3,6,biomesoplenty:leaves_4:2)
Block(3,4,1,biomesoplenty:log_2)
Block(3,4,2,biomesoplenty:log_2)
Block(3,4,3,biomesoplenty:log_2)
Block(3,4,4,biomesoplenty:log_2)
Block(3,4,5,biomesoplenty:log_2)
Block(3,4,6,biomesoplenty:leaves_4:2)
Block(3,4,7,biomesoplenty:leaves_4:2)
Block(3,5,1,biomesoplenty:log_2)
Block(3,5,2,biomesoplenty:log_2)
Block(3,5,3,biomesoplenty:log_2)
Block(3,5,4,biomesoplenty:log_2)
Block(3,5,5,biomesoplenty:log_2)
Block(3,5,6,biomesoplenty:leaves_4:2)
Block(3,6,1,biomesoplenty:log_2)
Block(3,6,2,biomesoplenty:log_2)
Block(3,6,3,biomesoplenty:log_2)
Block(3,6,4,biomesoplenty:log_2)
Block(3,6,5,biomesoplenty:leaves_4:2)
Block(3,7,2,biomesoplenty:log_2)
Block(3,7,3,biomesoplenty:log_2)
Block(3,7,4,biomesoplenty:log_2)
Block(3,8,2,biomesoplenty:log_2)
Block(3,8,3,biomesoplenty:log_2)
Block(3,8,4,biomesoplenty:log_2)
Block(3,9,2,biomesoplenty:log_2)
Block(3,9,3,biomesoplenty:log_2)
Block(3,9,4,biomesoplenty:log_2)
Block(3,10,2,biomesoplenty:log_2)
Block(3,10,3,biomesoplenty:log_2)
Block(3,10,4,biomesoplenty:log_2)
Block(3,11,2,biomesoplenty:log_2)
Block(3,11,3,biomesoplenty:log_2)
Block(3,11,4,biomesoplenty:log_2)
Block(3,12,2,biomesoplenty:log_2)
Block(3,12,3,biomesoplenty:log_2)
Block(3,12,4,biomesoplenty:log_2)
Block(3,13,2,biomesoplenty:log_2)
Block(3,13,3,biomesoplenty:log_2)
Block(3,13,4,biomesoplenty:log_2)
Block(3,14,2,biomesoplenty:log_2)
Block(3,14,3,biomesoplenty:log_2)
Block(3,14,4,biomesoplenty:log_2)
Block(3,15,2,biomesoplenty:log_2)
Block(3,15,3,biomesoplenty:log_2)
Block(3,15,4,biomesoplenty:log_2)
Block(3,16,2,biomesoplenty:log_2)
Block(3,16,3,biomesoplenty:log_2)
Block(3,16,4,biomesoplenty:log_2)
Block(3,17,1,biomesoplenty:leaves_4:2)
Block(3,17,2,biomesoplenty:log_2)
Block(3,17,3,biomesoplenty:log_2)
Block(3,17,4,biomesoplenty:log_2)
Block(3,18,0,biomesoplenty:leaves_4:2)
Block(3,18,1,biomesoplenty:leaves_4:2)
Block(3,18,2,biomesoplenty:log_2)
Block(3,18,3,biomesoplenty:log_2)
Block(3,18,4,biomesoplenty:log_2)
Block(3,18,5,biomesoplenty:leaves_4:2)
Block(3,19,-1,biomesoplenty:leaves_4:2)
Block(3,19,0,biomesoplenty:leaves_4:2)
Block(3,19,1,biomesoplenty:leaves_4:2)
Block(3,19,2,biomesoplenty:log_2)
Block(3,19,3,biomesoplenty:log_2)
Block(3,19,4,biomesoplenty:log_2)
Block(3,19,5,biomesoplenty:leaves_4:2)
Block(3,20,-3,biomesoplenty:leaves_4:2)
Block(3,20,-2,biomesoplenty:leaves_4:2)
Block(3,20,-1,biomesoplenty:leaves_4:2)
Block(3,20,0,biomesoplenty:leaves_4:2)
Block(3,20,1,biomesoplenty:leaves_4:2)
Block(3,20,2,biomesoplenty:log_2)
Block(3,20,3,biomesoplenty:log_2)
Block(3,20,4,biomesoplenty:log_2)
Block(3,21,-3,biomesoplenty:leaves_4:2)
Block(3,21,-2,biomesoplenty:leaves_4:2)
Block(3,21,-1,biomesoplenty:leaves_4:2)
Block(3,21,0,biomesoplenty:leaves_4:2)
Block(3,21,1,biomesoplenty:leaves_4:2)
Block(3,21,2,biomesoplenty:log_2)
Block(3,21,3,biomesoplenty:log_2)
Block(3,21,4,biomesoplenty:log_2)
Block(3,21,5,biomesoplenty:leaves_4:2)
Block(3,21,6,biomesoplenty:leaves_4:2)
Block(3,21,7,biomesoplenty:leaves_4:2)
Block(3,22,-4,biomesoplenty:leaves_4:2)
Block(3,22,-3,biomesoplenty:leaves_4:2)
Block(3,22,-2,biomesoplenty:leaves_4:2)
Block(3,22,-1,biomesoplenty:leaves_4:2)
Block(3,22,2,biomesoplenty:log_2)
Block(3,22,3,biomesoplenty:log_2)
Block(3,22,4,biomesoplenty:log_2)
Block(3,22,5,biomesoplenty:leaves_4:2)
Block(3,22,8,biomesoplenty:leaves_4:2)
Block(3,22,9,biomesoplenty:leaves_4:2)
Block(3,23,-4,biomesoplenty:leaves_4:2)
Block(3,23,-3,biomesoplenty:leaves_4:2)
Block(3,23,-2,biomesoplenty:leaves_4:2)
Block(3,23,-1,biomesoplenty:leaves_4:2)
Block(3,23,0,biomesoplenty:log_2)
Block(3,23,1,biomesoplenty:leaves_4:2)
Block(3,23,2,biomesoplenty:log_2)
Block(3,23,3,biomesoplenty:log_2)
Block(3,23,4,biomesoplenty:log_2)
Block(3,23,5,biomesoplenty:leaves_4:2)
Block(3,23,6,biomesoplenty:leaves_4:2)
Block(3,23,7,biomesoplenty:leaves_4:2)
Block(3,23,8,biomesoplenty:leaves_4:2)
Block(3,23,9,biomesoplenty:leaves_4:2)
Block(3,23,10,biomesoplenty:leaves_4:2)
Block(3,23,11,biomesoplenty:leaves_4:2)
Block(3,24,-4,biomesoplenty:leaves_4:2)
Block(3,24,-3,biomesoplenty:leaves_4:2)
Block(3,24,-2,biomesoplenty:leaves_4:2)
Block(3,24,-1,biomesoplenty:log_2)
Block(3,24,0,biomesoplenty:leaves_4:2)
Block(3,24,1,biomesoplenty:leaves_4:2)
Block(3,24,2,biomesoplenty:log_2)
Block(3,24,3,biomesoplenty:log_2)
Block(3,24,4,biomesoplenty:log_2)
Block(3,24,5,biomesoplenty:log_2:8)
Block(3,24,6,biomesoplenty:log_2:8)
Block(3,24,7,biomesoplenty:log_2:8)
Block(3,24,8,biomesoplenty:log_2:8)
Block(3,24,9,biomesoplenty:leaves_4:2)
Block(3,24,10,biomesoplenty:leaves_4:2)
Block(3,24,11,biomesoplenty:leaves_4:2)
Block(3,25,-4,biomesoplenty:leaves_4:2)
Block(3,25,-3,biomesoplenty:leaves_4:2)
Block(3,25,-2,biomesoplenty:leaves_4:2)
Block(3,25,-1,biomesoplenty:leaves_4:2)
Block(3,25,0,biomesoplenty:leaves_4:2)
Block(3,25,1,biomesoplenty:leaves_4:2)
Block(3,25,2,biomesoplenty:log_2)
Block(3,25,3,biomesoplenty:log_2)
Block(3,25,4,biomesoplenty:log_2)
Block(3,25,5,biomesoplenty:leaves_4:2)
Block(3,25,6,biomesoplenty:log_2)
Block(3,25,7,biomesoplenty:log_2:8)
Block(3,25,8,biomesoplenty:leaves_4:2)
Block(3,25,9,biomesoplenty:leaves_4:2)
Block(3,25,10,biomesoplenty:leaves_4:2)
Block(3,25,11,biomesoplenty:leaves_4:2)
Block(3,26,-4,biomesoplenty:leaves_4:2)
Block(3,26,-3,biomesoplenty:leaves_4:2)
Block(3,26,-2,biomesoplenty:leaves_4:2)
Block(3,26,-1,biomesoplenty:leaves_4:2)
Block(3,26,0,biomesoplenty:leaves_4:2)
Block(3,26,1,biomesoplenty:leaves_4:2)
Block(3,26,2,biomesoplenty:log_2)
Block(3,26,3,biomesoplenty:log_2)
Block(3,26,4,biomesoplenty:log_2)
Block(3,26,5,biomesoplenty:leaves_4:2)
Block(3,26,6,biomesoplenty:leaves_4:2)
Block(3,26,7,biomesoplenty:leaves_4:2)
Block(3,26,8,biomesoplenty:leaves_4:2)
Block(3,26,9,biomesoplenty:leaves_4:2)
Block(3,27,-3,biomesoplenty:leaves_4:2)
Block(3,27,-2,biomesoplenty:leaves_4:2)
Block(3,27,-1,biomesoplenty:leaves_4:2)
Block(3,27,0,biomesoplenty:leaves_4:2)
Block(3,27,1,biomesoplenty:leaves_4:2)
Block(3,27,2,biomesoplenty:log_2)
Block(3,27,3,biomesoplenty:log_2)
Block(3,27,4,biomesoplenty:log_2)
Block(3,27,5,biomesoplenty:log_2:8)
Block(3,27,6,biomesoplenty:leaves_4:2)
Block(3,27,7,biomesoplenty:leaves_4:2)
Block(3,28,-2,biomesoplenty:leaves_4:2)
Block(3,28,-1,biomesoplenty:leaves_4:2)
Block(3,28,0,biomesoplenty:leaves_4:2)
Block(3,28,1,biomesoplenty:leaves_4:2)
Block(3,28,2,biomesoplenty:log_2)
Block(3,28,3,biomesoplenty:log_2)
Block(3,28,4,biomesoplenty:log_2)
Block(3,28,5,biomesoplenty:leaves_4:2)
Block(3,28,6,biomesoplenty:leaves_4:2)
Block(3,28,7,biomesoplenty:leaves_4:2)
Block(3,28,8,biomesoplenty:leaves_4:2)
Block(3,28,9,biomesoplenty:leaves_4:2)
Block(3,29,-3,biomesoplenty:leaves_4:2)
Block(3,29,-2,biomesoplenty:leaves_4:2)
Block(3,29,-1,biomesoplenty:leaves_4:2)
Block(3,29,0,biomesoplenty:leaves_4:2)
Block(3,29,1,biomesoplenty:log_2:8)
Block(3,29,2,biomesoplenty:log_2)
Block(3,29,3,biomesoplenty:log_2)
Block(3,29,4,biomesoplenty:log_2)
Block(3,29,5,biomesoplenty:leaves_4:2)
Block(3,29,6,biomesoplenty:leaves_4:2)
Block(3,29,7,biomesoplenty:leaves_4:2)
Block(3,29,8,biomesoplenty:leaves_4:2)
Block(3,30,-3,biomesoplenty:leaves_4:2)
Block(3,30,-2,biomesoplenty:leaves_4:2)
Block(3,30,-1,biomesoplenty:leaves_4:2)
Block(3,30,0,biomesoplenty:leaves_4:2)
Block(3,30,1,biomesoplenty:leaves_4:2)
Block(3,30,2,biomesoplenty:log_2)
Block(3,30,3,biomesoplenty:log_2)
Block(3,30,4,biomesoplenty:log_2)
Block(3,30,5,biomesoplenty:leaves_4:2)
Block(3,30,6,biomesoplenty:leaves_4:2)
Block(3,30,7,biomesoplenty:leaves_4:2)
Block(3,30,8,biomesoplenty:leaves_4:2)
Block(3,30,9,biomesoplenty:leaves_4:2)
Block(3,30,10,biomesoplenty:leaves_4:2)
Block(3,31,-3,biomesoplenty:leaves_4:2)
Block(3,31,-2,biomesoplenty:log_2:8)
Block(3,31,-1,biomesoplenty:log_2:8)
Block(3,31,0,biomesoplenty:log_2)
Block(3,31,2,biomesoplenty:log_2)
Block(3,31,3,biomesoplenty:log_2)
Block(3,31,4,biomesoplenty:log_2)
Block(3,31,5,biomesoplenty:leaves_4:2)
Block(3,31,6,biomesoplenty:leaves_4:2)
Block(3,31,7,biomesoplenty:leaves_4:2)
Block(3,31,8,biomesoplenty:leaves_4:2)
Block(3,32,-4,biomesoplenty:leaves_4:2)
Block(3,32,-3,biomesoplenty:leaves_4:2)
Block(3,32,-1,biomesoplenty:leaves_4:2)
Block(3,32,0,biomesoplenty:leaves_4:2)
Block(3,32,2,biomesoplenty:log_2)
Block(3,32,3,biomesoplenty:log_2)
Block(3,32,4,biomesoplenty:log_2)
Block(3,32,5,biomesoplenty:log_2:8)
Block(3,32,6,biomesoplenty:leaves_4:2)
Block(3,32,7,biomesoplenty:leaves_4:2)
Block(3,32,8,biomesoplenty:leaves_4:2)
Block(3,33,-2,biomesoplenty:leaves_4:2)
Block(3,33,-1,biomesoplenty:leaves_4:2)
Block(3,33,0,biomesoplenty:leaves_4:2)
Block(3,33,1,biomesoplenty:leaves_4:2)
Block(3,33,2,biomesoplenty:log_2)
Block(3,33,3,biomesoplenty:log_2)
Block(3,33,4,biomesoplenty:log_2)
Block(3,33,5,biomesoplenty:leaves_4:2)
Block(3,33,6,biomesoplenty:leaves_4:2)
Block(3,33,7,biomesoplenty:leaves_4:2)
Block(3,33,8,biomesoplenty:leaves_4:2)
Block(3,34,-3,biomesoplenty:leaves_4:2)
Block(3,34,-2,biomesoplenty:leaves_4:2)
Block(3,34,-1,biomesoplenty:leaves_4:2)
Block(3,34,0,biomesoplenty:leaves_4:2)
Block(3,34,1,biomesoplenty:leaves_4:2)
Block(3,34,2,biomesoplenty:log_2)
Block(3,34,3,biomesoplenty:log_2)
Block(3,34,4,biomesoplenty:log_2)
Block(3,34,6,biomesoplenty:leaves_4:2)
Block(3,34,8,biomesoplenty:leaves_4:2)
Block(3,35,-4,biomesoplenty:leaves_4:2)
Block(3,35,-3,biomesoplenty:leaves_4:2)
Block(3,35,-2,biomesoplenty:leaves_4:2)
Block(3,35,-1,biomesoplenty:leaves_4:2)
Block(3,35,0,biomesoplenty:log_2:8)
Block(3,35,1,biomesoplenty:log_2:8)
Block(3,35,2,biomesoplenty:log_2)
Block(3,35,3,biomesoplenty:log_2)
Block(3,35,4,biomesoplenty:log_2)
Block(3,35,5,biomesoplenty:leaves_4:2)
Block(3,35,6,biomesoplenty:leaves_4:2)
Block(3,36,-4,biomesoplenty:leaves_4:2)
Block(3,36,-3,biomesoplenty:leaves_4:2)
Block(3,36,-2,biomesoplenty:log_2:8)
Block(3,36,-1,biomesoplenty:log_2:8)
Block(3,36,0,biomesoplenty:log_2:8)
Block(3,36,1,biomesoplenty:log_2)
Block(3,36,2,biomesoplenty:log_2)
Block(3,36,3,biomesoplenty:log_2)
Block(3,36,4,biomesoplenty:log_2)
Block(3,36,5,biomesoplenty:leaves_4:2)
Block(3,36,6,biomesoplenty:leaves_4:2)
Block(3,36,7,biomesoplenty:leaves_4:2)
Block(3,37,-4,biomesoplenty:leaves_4:2)
Block(3,37,-3,biomesoplenty:leaves_4:2)
Block(3,37,-2,biomesoplenty:leaves_4:2)
Block(3,37,-1,biomesoplenty:leaves_4:2)
Block(3,37,0,biomesoplenty:leaves_4:2)
Block(3,37,1,biomesoplenty:leaves_4:2)
Block(3,37,2,biomesoplenty:log_2)
Block(3,37,3,biomesoplenty:log_2)
Block(3,37,4,biomesoplenty:log_2)
Block(3,37,5,biomesoplenty:log_2:8)
Block(3,37,6,biomesoplenty:log_2:8)
Block(3,37,7,biomesoplenty:leaves_4:2)
Block(3,38,-2,biomesoplenty:leaves_4:2)
Block(3,38,-1,biomesoplenty:leaves_4:2)
Block(3,38,0,biomesoplenty:leaves_4:2)
Block(3,38,1,biomesoplenty:leaves_4:2)
Block(3,38,2,biomesoplenty:log_2)
Block(3,38,3,biomesoplenty:log_2)
Block(3,38,4,biomesoplenty:log_2)
Block(3,38,6,biomesoplenty:leaves_4:2)
Block(3,38,7,biomesoplenty:leaves_4:2)
Block(3,38,8,biomesoplenty:leaves_4:2)
Block(3,39,0,biomesoplenty:leaves_4:2)
Block(3,39,1,biomesoplenty:leaves_4:2)
Block(3,39,2,biomesoplenty:log_2)
Block(3,39,3,biomesoplenty:log_2)
Block(3,39,4,biomesoplenty:log_2)
Block(3,39,5,biomesoplenty:log_2:8)
Block(3,39,6,biomesoplenty:log_2:8)
Block(3,39,7,biomesoplenty:log_2:8)
Block(3,40,0,biomesoplenty:leaves_4:2)
Block(3,40,1,biomesoplenty:leaves_4:2)
Block(3,40,2,biomesoplenty:log_2)
Block(3,40,3,biomesoplenty:log_2)
Block(3,40,4,biomesoplenty:log_2)
Block(3,40,5,biomesoplenty:log_2:8)
Block(3,40,6,biomesoplenty:log_2)
Block(3,40,7,biomesoplenty:log_2:8)
Block(3,40,8,biomesoplenty:leaves_4:2)
Block(3,40,9,biomesoplenty:leaves_4:2)
Block(3,41,-1,biomesoplenty:leaves_4:2)
Block(3,41,0,biomesoplenty:leaves_4:2)
Block(3,41,1,biomesoplenty:leaves_4:2)
Block(3,41,2,biomesoplenty:log_2)
Block(3,41,3,biomesoplenty:log_2)
Block(3,41,4,biomesoplenty:log_2)
Block(3,41,5,biomesoplenty:leaves_4:2)
Block(3,41,6,biomesoplenty:leaves_4:2)
Block(3,41,7,biomesoplenty:leaves_4:2)
Block(3,41,8,biomesoplenty:leaves_4:2)
Block(3,42,-1,biomesoplenty:leaves_4:2)
Block(3,42,0,biomesoplenty:leaves_4:2)
Block(3,42,1,biomesoplenty:leaves_4:2)
Block(3,42,2,biomesoplenty:log_2)
Block(3,42,3,biomesoplenty:log_2)
Block(3,42,4,biomesoplenty:log_2)
Block(3,42,5,biomesoplenty:leaves_4:2)
Block(3,42,6,biomesoplenty:leaves_4:2)
Block(3,42,7,biomesoplenty:leaves_4:2)
Block(3,43,-1,biomesoplenty:leaves_4:2)
Block(3,43,0,biomesoplenty:leaves_4:2)
Block(3,43,1,biomesoplenty:leaves_4:2)
Block(3,43,2,biomesoplenty:log_2)
Block(3,43,3,biomesoplenty:log_2)
Block(3,43,4,biomesoplenty:log_2)
Block(3,43,5,biomesoplenty:log_2:8)
Block(3,43,6,biomesoplenty:leaves_4:2)
Block(3,44,-1,biomesoplenty:leaves_4:2)
Block(3,44,0,biomesoplenty:leaves_4:2)
Block(3,44,1,biomesoplenty:leaves_4:2)
Block(3,44,2,biomesoplenty:log_2)
Block(3,44,3,biomesoplenty:log_2)
Block(3,44,4,biomesoplenty:log_2)
Block(3,44,6,biomesoplenty:leaves_4:2)
Block(3,45,0,biomesoplenty:leaves_4:2)
Block(3,45,1,biomesoplenty:leaves_4:2)
Block(3,45,2,biomesoplenty:log_2)
Block(3,45,3,biomesoplenty:log_2)
Block(3,45,4,biomesoplenty:log_2)
Block(3,45,5,biomesoplenty:leaves_4:2)
Block(3,46,0,biomesoplenty:leaves_4:2)
Block(3,46,1,biomesoplenty:leaves_4:2)
Block(3,46,2,biomesoplenty:log_2)
Block(3,46,3,biomesoplenty:log_2)
Block(3,46,4,biomesoplenty:leaves_4:2)
Block(3,46,5,biomesoplenty:leaves_4:2)
Block(3,47,0,biomesoplenty:leaves_4:2)
Block(3,47,1,biomesoplenty:leaves_4:2)
Block(3,47,2,biomesoplenty:leaves_4:2)
Block(3,47,3,biomesoplenty:log_2)
Block(3,47,4,biomesoplenty:leaves_4:2)
Block(3,48,1,biomesoplenty:leaves_4:2)
Block(3,48,2,biomesoplenty:leaves_4:2)
Block(3,48,3,biomesoplenty:log_2)
Block(3,48,4,biomesoplenty:leaves_4:2)
Block(3,49,1,biomesoplenty:leaves_4:2)
Block(3,49,2,biomesoplenty:leaves_4:2)
Block(3,49,3,biomesoplenty:log_2)
Block(3,49,4,biomesoplenty:leaves_4:2)
Block(3,49,5,biomesoplenty:leaves_4:2)
Block(3,50,2,biomesoplenty:leaves_4:2)
Block(3,50,3,biomesoplenty:log_2)
Block(3,50,4,biomesoplenty:leaves_4:2)
Block(3,50,5,biomesoplenty:leaves_4:2)
Block(3,51,2,biomesoplenty:leaves_4:2)
Block(3,51,3,biomesoplenty:leaves_4:2)
Block(4,0,0,biomesoplenty:log_2)
Block(4,0,1,biomesoplenty:log_2)
Block(4,0,2,biomesoplenty:log_2)
Block(4,0,3,biomesoplenty:log_2)
Block(4,0,4,biomesoplenty:log_2)
Block(4,0,5,biomesoplenty:log_2)
Block(4,0,6,biomesoplenty:log_2)
Block(4,1,0,biomesoplenty:log_2)
Block(4,1,1,biomesoplenty:log_2)
Block(4,1,2,biomesoplenty:log_2)
Block(4,1,3,biomesoplenty:log_2)
Block(4,1,4,biomesoplenty:log_2)
Block(4,1,5,biomesoplenty:log_2)
Block(4,1,6,biomesoplenty:log_2)
Block(4,2,0,biomesoplenty:log_2)
Block(4,2,1,biomesoplenty:log_2)
Block(4,2,2,biomesoplenty:log_2)
Block(4,2,3,biomesoplenty:log_2)
Block(4,2,4,biomesoplenty:log_2)
Block(4,2,5,biomesoplenty:log_2)
Block(4,3,1,biomesoplenty:log_2)
Block(4,3,2,biomesoplenty:log_2)
Block(4,3,3,biomesoplenty:log_2)
Block(4,3,4,biomesoplenty:log_2)
Block(4,3,5,biomesoplenty:log_2)
Block(4,4,2,biomesoplenty:log_2)
Block(4,4,3,biomesoplenty:log_2)
Block(4,4,4,biomesoplenty:log_2)
Block(4,4,5,biomesoplenty:leaves_4:2)
Block(4,5,2,biomesoplenty:log_2)
Block(4,5,3,biomesoplenty:log_2)
Block(4,5,4,biomesoplenty:log_2)
Block(4,6,2,biomesoplenty:log_2)
Block(4,6,3,biomesoplenty:log_2)
Block(4,7,2,biomesoplenty:log_2)
Block(4,7,3,biomesoplenty:log_2)
Block(4,8,2,biomesoplenty:log_2)
Block(4,8,3,biomesoplenty:log_2)
Block(4,8,4,biomesoplenty:log_2)
Block(4,9,2,biomesoplenty:log_2)
Block(4,9,3,biomesoplenty:log_2)
Block(4,9,4,biomesoplenty:log_2)
Block(4,10,2,biomesoplenty:log_2)
Block(4,10,3,biomesoplenty:log_2)
Block(4,10,4,biomesoplenty:log_2)
Block(4,11,3,biomesoplenty:log_2)
Block(4,12,3,biomesoplenty:log_2)
Block(4,13,3,biomesoplenty:log_2)
Block(4,14,3,biomesoplenty:log_2)
Block(4,15,3,biomesoplenty:log_2)
Block(4,16,3,biomesoplenty:log_2)
Block(4,17,1,biomesoplenty:leaves_4:2)
Block(4,17,2,biomesoplenty:leaves_4:2)
Block(4,17,3,biomesoplenty:log_2)
Block(4,17,4,biomesoplenty:leaves_4:2)
Block(4,17,5,biomesoplenty:leaves_4:2)
Block(4,18,-1,biomesoplenty:leaves_4:2)
Block(4,18,0,biomesoplenty:leaves_4:2)
Block(4,18,1,biomesoplenty:leaves_4:2)
Block(4,18,2,biomesoplenty:log_2:8)
Block(4,18,3,biomesoplenty:log_2)
Block(4,18,4,biomesoplenty:leaves_4:2)
Block(4,18,6,biomesoplenty:leaves_4:2)
Block(4,19,-2,biomesoplenty:leaves_4:2)
Block(4,19,0,biomesoplenty:leaves_4:2)
Block(4,19,1,biomesoplenty:leaves_4:2)
Block(4,19,2,biomesoplenty:log_2)
Block(4,19,3,biomesoplenty:log_2)
Block(4,19,4,biomesoplenty:log_2)
Block(4,19,5,biomesoplenty:leaves_4:2)
Block(4,19,6,biomesoplenty:leaves_4:2)
Block(4,20,-2,biomesoplenty:leaves_4:2)
Block(4,20,0,biomesoplenty:leaves_4:2)
Block(4,20,1,biomesoplenty:leaves_4:2)
Block(4,20,2,biomesoplenty:leaves_4:2)
Block(4,20,3,biomesoplenty:log_2)
Block(4,20,4,biomesoplenty:log_2)
Block(4,20,5,biomesoplenty:log_2:8)
Block(4,20,6,biomesoplenty:leaves_4:2)
Block(4,20,7,biomesoplenty:leaves_4:2)
Block(4,21,-2,biomesoplenty:leaves_4:2)
Block(4,21,0,biomesoplenty:leaves_4:2)
Block(4,21,1,biomesoplenty:leaves_4:2)
Block(4,21,2,biomesoplenty:leaves_4:2)
Block(4,21,3,biomesoplenty:log_2)
Block(4,21,4,biomesoplenty:leaves_4:2)
Block(4,21,5,biomesoplenty:leaves_4:2)
Block(4,21,6,biomesoplenty:leaves_4:2)
Block(4,21,7,biomesoplenty:leaves_4:2)
Block(4,22,-3,biomesoplenty:leaves_4:2)
Block(4,22,-2,biomesoplenty:leaves_4:2)
Block(4,22,0,biomesoplenty:leaves_4:2)
Block(4,22,1,biomesoplenty:leaves_4:2)
Block(4,22,2,biomesoplenty:leaves_4:2)
Block(4,22,3,biomesoplenty:log_2)
Block(4,22,4,biomesoplenty:leaves_4:2)
Block(4,22,5,biomesoplenty:leaves_4:2)
Block(4,22,6,biomesoplenty:leaves_4:2)
Block(4,22,7,biomesoplenty:leaves_4:2)
Block(4,22,10,biomesoplenty:leaves_4:2)
Block(4,23,-2,biomesoplenty:leaves_4:2)
Block(4,23,-1,biomesoplenty:leaves_4:2)
Block(4,23,1,biomesoplenty:leaves_4:2)
Block(4,23,2,biomesoplenty:log_2)
Block(4,23,3,biomesoplenty:log_2)
Block(4,23,4,biomesoplenty:leaves_4:2)
Block(4,23,5,biomesoplenty:leaves_4:2)
Block(4,23,6,biomesoplenty:leaves_4:2)
Block(4,23,7,biomesoplenty:leaves_4:2)
Block(4,23,8,biomesoplenty:leaves_4:2)
Block(4,23,9,biomesoplenty:leaves_4:2)
Block(4,23,10,biomesoplenty:leaves_4:2)
Block(4,24,-2,biomesoplenty:leaves_4:2)
Block(4,24,-1,biomesoplenty:log_2)
Block(4,24,0,biomesoplenty:leaves_4:2)
Block(4,24,1,biomesoplenty:leaves_4:2)
Block(4,24,3,biomesoplenty:log_2)
Block(4,24,4,biomesoplenty:leaves_4:2)
Block(4,24,5,biomesoplenty:leaves_4:2)
Block(4,24,6,biomesoplenty:leaves_4:2)
Block(4,24,7,biomesoplenty:leaves_4:2)
Block(4,24,8,biomesoplenty:log_2)
Block(4,24,9,biomesoplenty:log_2:8)
Block(4,24,10,biomesoplenty:leaves_4:2)
Block(4,24,11,biomesoplenty:leaves_4:2)
Block(4,25,-4,biomesoplenty:leaves_4:2)
Block(4,25,-3,biomesoplenty:leaves_4:2)
Block(4,25,-2,biomesoplenty:leaves_4:2)
Block(4,25,-1,biomesoplenty:log_2)
Block(4,25,0,biomesoplenty:leaves_4:2)
Block(4,25,1,biomesoplenty:leaves_4:2)
Block(4,25,2,biomesoplenty:log_2:8)
Block(4,25,3,biomesoplenty:log_2)
Block(4,25,4,biomesoplenty:log_2:8)
Block(4,25,5,biomesoplenty:log_2:8)
Block(4,25,6,biomesoplenty:leaves_4:2)
Block(4,25,7,biomesoplenty:leaves_4:2)
Block(4,25,8,biomesoplenty:leaves_4:2)
Block(4,25,9,biomesoplenty:leaves_4:2)
Block(4,25,10,biomesoplenty:leaves_4:2)
Block(4,25,11,biomesoplenty:leaves_4:2)
Block(4,26,-4,biomesoplenty:leaves_4:2)
Block(4,26,-3,biomesoplenty:leaves_4:2)
Block(4,26,-2,biomesoplenty:leaves_4:2)
Block(4,26,-1,biomesoplenty:log_2)
Block(4,26,0,biomesoplenty:leaves_4:2)
Block(4,26,1,biomesoplenty:leaves_4:2)
Block(4,26,2,biomesoplenty:leaves_4:2)
Block(4,26,3,biomesoplenty:log_2)
Block(4,26,4,biomesoplenty:leaves_4:2)
Block(4,26,5,biomesoplenty:leaves_4:2)
Block(4,26,6,biomesoplenty:leaves_4:2)
Block(4,26,7,biomesoplenty:leaves_4:2)
Block(4,26,8,biomesoplenty:leaves_4:2)
Block(4,26,9,biomesoplenty:leaves_4:2)
Block(4,26,10,biomesoplenty:leaves_4:2)
Block(4,27,-3,biomesoplenty:leaves_4:2)
Block(4,27,-2,biomesoplenty:leaves_4:2)
Block(4,27,-1,biomesoplenty:leaves_4:2)
Block(4,27,0,biomesoplenty:leaves_4:2)
Block(4,27,1,biomesoplenty:leaves_4:2)
Block(4,27,2,biomesoplenty:leaves_4:2)
Block(4,27,3,biomesoplenty:log_2)
Block(4,27,4,biomesoplenty:leaves_4:2)
Block(4,27,5,biomesoplenty:leaves_4:2)
Block(4,27,6,biomesoplenty:leaves_4:2)
Block(4,27,7,biomesoplenty:leaves_4:2)
Block(4,28,-2,biomesoplenty:leaves_4:2)
Block(4,28,-1,biomesoplenty:leaves_4:2)
Block(4,28,0,biomesoplenty:leaves_4:2)
Block(4,28,1,biomesoplenty:leaves_4:2)
Block(4,28,2,biomesoplenty:leaves_4:2)
Block(4,28,3,biomesoplenty:log_2)
Block(4,28,4,biomesoplenty:leaves_4:2)
Block(4,28,6,biomesoplenty:leaves_4:2)
Block(4,28,7,biomesoplenty:leaves_4:2)
Block(4,29,-1,biomesoplenty:leaves_4:2)
Block(4,29,0,biomesoplenty:leaves_4:2)
Block(4,29,1,biomesoplenty:log_2)
Block(4,29,2,biomesoplenty:log_2)
Block(4,29,3,biomesoplenty:log_2)
Block(4,29,4,biomesoplenty:log_2:8)
Block(4,29,5,biomesoplenty:leaves_4:2)
Block(4,29,6,biomesoplenty:leaves_4:2)
Block(4,29,7,biomesoplenty:leaves_4:2)
Block(4,29,8,biomesoplenty:leaves_4:2)
Block(4,29,9,biomesoplenty:leaves_4:2)
Block(4,30,-3,biomesoplenty:leaves_4:2)
Block(4,30,-2,biomesoplenty:leaves_4:2)
Block(4,30,-1,biomesoplenty:leaves_4:2)
Block(4,30,0,biomesoplenty:leaves_4:2)
Block(4,30,1,biomesoplenty:log_2)
Block(4,30,2,biomesoplenty:leaves_4:2)
Block(4,30,3,biomesoplenty:log_2)
Block(4,30,6,biomesoplenty:leaves_4:2)
Block(4,30,7,biomesoplenty:leaves_4:2)
Block(4,30,8,biomesoplenty:leaves_4:2)
Block(4,31,-2,biomesoplenty:leaves_4:2)
Block(4,31,-1,biomesoplenty:leaves_4:2)
Block(4,31,0,biomesoplenty:log_2:8)
Block(4,31,1,biomesoplenty:log_2)
Block(4,31,2,biomesoplenty:leaves_4:2)
Block(4,31,3,biomesoplenty:log_2)
Block(4,31,4,biomesoplenty:leaves_4:2)
Block(4,31,5,biomesoplenty:leaves_4:2)
Block(4,31,6,biomesoplenty:leaves_4:2)
Block(4,31,7,biomesoplenty:leaves_4:2)
Block(4,31,8,biomesoplenty:leaves_4:2)
Block(4,32,-4,biomesoplenty:leaves_4:2)
Block(4,32,-3,biomesoplenty:leaves_4:2)
Block(4,32,-2,biomesoplenty:leaves_4:2)
Block(4,32,-1,biomesoplenty:leaves_4:2)
Block(4,32,0,biomesoplenty:leaves_4:2)
Block(4,32,1,biomesoplenty:leaves_4:2)
Block(4,32,2,biomesoplenty:leaves_4:2)
Block(4,32,3,biomesoplenty:log_2)
Block(4,32,5,biomesoplenty:leaves_4:2)
Block(4,32,6,biomesoplenty:leaves_4:2)
Block(4,32,7,biomesoplenty:leaves_4:2)
Block(4,33,-3,biomesoplenty:leaves_4:2)
Block(4,33,-2,biomesoplenty:leaves_4:2)
Block(4,33,-1,biomesoplenty:leaves_4:2)
Block(4,33,0,biomesoplenty:leaves_4:2)
Block(4,33,1,biomesoplenty:leaves_4:2)
Block(4,33,2,biomesoplenty:leaves_4:2)
Block(4,33,3,biomesoplenty:log_2)
Block(4,33,4,biomesoplenty:leaves_4:2)
Block(4,33,5,biomesoplenty:leaves_4:2)
Block(4,33,6,biomesoplenty:leaves_4:2)
Block(4,33,7,biomesoplenty:leaves_4:2)
Block(4,34,-3,biomesoplenty:leaves_4:2)
Block(4,34,-2,biomesoplenty:leaves_4:2)
Block(4,34,-1,biomesoplenty:leaves_4:2)
Block(4,34,0,biomesoplenty:leaves_4:2)
Block(4,34,1,biomesoplenty:leaves_4:2)
Block(4,34,2,biomesoplenty:leaves_4:2)
Block(4,34,3,biomesoplenty:log_2)
Block(4,34,4,biomesoplenty:leaves_4:2)
Block(4,34,5,biomesoplenty:leaves_4:2)
Block(4,34,6,biomesoplenty:leaves_4:2)
Block(4,35,-3,biomesoplenty:leaves_4:2)
Block(4,35,-2,biomesoplenty:leaves_4:2)
Block(4,35,-1,biomesoplenty:leaves_4:2)
Block(4,35,0,biomesoplenty:leaves_4:2)
Block(4,35,1,biomesoplenty:log_2)
Block(4,35,2,biomesoplenty:leaves_4:2)
Block(4,35,3,biomesoplenty:log_2)
Block(4,35,4,biomesoplenty:log_2:8)
Block(4,35,6,biomesoplenty:leaves_4:2)
Block(4,36,-2,biomesoplenty:leaves_4:2)
Block(4,36,-1,biomesoplenty:leaves_4:2)
Block(4,36,0,biomesoplenty:leaves_4:2)
Block(4,36,1,biomesoplenty:leaves_4:2)
Block(4,36,2,biomesoplenty:leaves_4:2)
Block(4,36,3,biomesoplenty:log_2)
Block(4,36,4,biomesoplenty:log_2)
Block(4,36,5,biomesoplenty:leaves_4:2)
Block(4,36,6,biomesoplenty:leaves_4:2)
Block(4,36,7,biomesoplenty:leaves_4:2)
Block(4,36,8,biomesoplenty:leaves_4:2)
Block(4,37,-3,biomesoplenty:leaves_4:2)
Block(4,37,-2,biomesoplenty:leaves_4:2)
Block(4,37,-1,biomesoplenty:leaves_4:2)
Block(4,37,0,biomesoplenty:leaves_4:2)
Block(4,37,1,biomesoplenty:leaves_4:2)
Block(4,37,2,biomesoplenty:log_2)
Block(4,37,3,biomesoplenty:log_2)
Block(4,37,4,biomesoplenty:leaves_4:2)
Block(4,37,5,biomesoplenty:leaves_4:2)
Block(4,37,6,biomesoplenty:leaves_4:2)
Block(4,37,7,biomesoplenty:leaves_4:2)
Block(4,37,8,biomesoplenty:leaves_4:2)
Block(4,38,-2,biomesoplenty:leaves_4:2)
Block(4,38,-1,biomesoplenty:leaves_4:2)
Block(4,38,0,biomesoplenty:leaves_4:2)
Block(4,38,1,biomesoplenty:leaves_4:2)
Block(4,38,2,biomesoplenty:leaves_4:2)
Block(4,38,3,biomesoplenty:log_2)
Block(4,38,4,biomesoplenty:leaves_4:2)
Block(4,38,5,biomesoplenty:leaves_4:2)
Block(4,38,6,biomesoplenty:leaves_4:2)
Block(4,38,7,biomesoplenty:leaves_4:2)
Block(4,39,-1,biomesoplenty:leaves_4:2)
Block(4,39,0,biomesoplenty:leaves_4:2)
Block(4,39,1,biomesoplenty:leaves_4:2)
Block(4,39,2,biomesoplenty:leaves_4:2)
Block(4,39,3,biomesoplenty:log_2)
Block(4,39,4,biomesoplenty:leaves_4:2)
Block(4,39,5,biomesoplenty:leaves_4:2)
Block(4,39,6,biomesoplenty:leaves_4:2)
Block(4,39,7,biomesoplenty:leaves_4:2)
Block(4,39,8,biomesoplenty:leaves_4:2)
Block(4,40,0,biomesoplenty:leaves_4:2)
Block(4,40,2,biomesoplenty:leaves_4:2)
Block(4,40,3,biomesoplenty:log_2)
Block(4,40,4,biomesoplenty:log_2:8)
Block(4,40,6,biomesoplenty:leaves_4:2)
Block(4,40,7,biomesoplenty:leaves_4:2)
Block(4,40,8,biomesoplenty:leaves_4:2)
Block(4,41,1,biomesoplenty:leaves_4:2)
Block(4,41,2,biomesoplenty:leaves_4:2)
Block(4,41,3,biomesoplenty:log_2)
Block(4,41,4,biomesoplenty:leaves_4:2)
Block(4,41,5,biomesoplenty:leaves_4:2)
Block(4,41,6,biomesoplenty:leaves_4:2)
Block(4,41,7,biomesoplenty:leaves_4:2)
Block(4,42,0,biomesoplenty:log_2:8)
Block(4,42,1,biomesoplenty:log_2:8)
Block(4,42,2,biomesoplenty:log_2)
Block(4,42,3,biomesoplenty:log_2)
Block(4,42,4,biomesoplenty:leaves_4:2)
Block(4,42,5,biomesoplenty:leaves_4:2)
Block(4,43,-1,biomesoplenty:leaves_4:2)
Block(4,43,0,biomesoplenty:leaves_4:2)
Block(4,43,1,biomesoplenty:log_2)
Block(4,43,2,biomesoplenty:log_2)
Block(4,43,3,biomesoplenty:log_2)
Block(4,43,4,biomesoplenty:leaves_4:2)
Block(4,43,5,biomesoplenty:leaves_4:2)
Block(4,43,6,biomesoplenty:leaves_4:2)
Block(4,44,0,biomesoplenty:leaves_4:2)
Block(4,44,1,biomesoplenty:leaves_4:2)
Block(4,44,2,biomesoplenty:leaves_4:2)
Block(4,44,3,biomesoplenty:log_2)
Block(4,44,4,biomesoplenty:leaves_4:2)
Block(4,44,5,biomesoplenty:leaves_4:2)
Block(4,44,6,biomesoplenty:leaves_4:2)
Block(4,45,1,biomesoplenty:leaves_4:2)
Block(4,45,2,biomesoplenty:leaves_4:2)
Block(4,45,3,biomesoplenty:log_2)
Block(4,45,4,biomesoplenty:leaves_4:2)
Block(4,45,5,biomesoplenty:leaves_4:2)
Block(4,45,6,biomesoplenty:leaves_4:2)
Block(4,46,0,biomesoplenty:leaves_4:2)
Block(4,46,1,biomesoplenty:leaves_4:2)
Block(4,46,2,biomesoplenty:leaves_4:2)
Block(4,46,3,biomesoplenty:log_2)
Block(4,46,4,biomesoplenty:leaves_4:2)
Block(4,46,6,biomesoplenty:leaves_4:2)
Block(4,47,0,biomesoplenty:leaves_4:2)
Block(4,47,2,biomesoplenty:leaves_4:2)
Block(4,47,4,biomesoplenty:leaves_4:2)
Block(4,47,5,biomesoplenty:leaves_4:2)
Block(4,48,1,biomesoplenty:leaves_4:2)
Block(4,48,3,biomesoplenty:leaves_4:2)
Block(4,49,1,biomesoplenty:leaves_4:2)
Block(4,49,2,biomesoplenty:leaves_4:2)
Block(4,49,3,biomesoplenty:leaves_4:2)
Block(4,49,4,biomesoplenty:leaves_4:2)
Block(4,49,5,biomesoplenty:leaves_4:2)
Block(4,50,3,biomesoplenty:leaves_4:2)
Block(5,0,0,biomesoplenty:log_2)
Block(5,0,1,biomesoplenty:log_2)
Block(5,0,2,biomesoplenty:log_2)
Block(5,0,3,biomesoplenty:log_2)
Block(5,0,4,biomesoplenty:log_2)
Block(5,0,5,biomesoplenty:log_2)
Block(5,0,6,biomesoplenty:log_2)
Block(5,1,1,biomesoplenty:log_2)
Block(5,1,2,biomesoplenty:log_2)
Block(5,1,3,biomesoplenty:log_2)
Block(5,1,4,biomesoplenty:log_2)
Block(5,1,5,biomesoplenty:log_2)
Block(5,2,1,biomesoplenty:log_2)
Block(5,2,2,biomesoplenty:log_2)
Block(5,2,3,biomesoplenty:log_2)
Block(5,2,4,biomesoplenty:log_2)
Block(5,2,5,biomesoplenty:log_2)
Block(5,3,3,biomesoplenty:log_2)
Block(5,3,4,biomesoplenty:log_2)
Block(5,4,3,biomesoplenty:log_2)
Block(5,17,1,biomesoplenty:leaves_4:2)
Block(5,17,2,biomesoplenty:leaves_4:2)
Block(5,17,3,biomesoplenty:leaves_4:2)
Block(5,17,4,biomesoplenty:leaves_4:2)
Block(5,18,-1,biomesoplenty:leaves_4:2)
Block(5,18,0,biomesoplenty:leaves_4:2)
Block(5,18,1,biomesoplenty:leaves_4:2)
Block(5,18,2,biomesoplenty:log_2)
Block(5,18,3,biomesoplenty:leaves_4:2)
Block(5,18,4,biomesoplenty:leaves_4:2)
Block(5,18,6,biomesoplenty:leaves_4:2)
Block(5,19,-2,biomesoplenty:leaves_4:2)
Block(5,19,-1,biomesoplenty:leaves_4:2)
Block(5,19,0,biomesoplenty:log_2:8)
Block(5,19,1,biomesoplenty:log_2:8)
Block(5,19,2,biomesoplenty:log_2)
Block(5,19,3,biomesoplenty:leaves_4:2)
Block(5,19,4,biomesoplenty:log_2)
Block(5,19,5,biomesoplenty:log_2:8)
Block(5,19,6,biomesoplenty:leaves_4:2)
Block(5,20,-2,biomesoplenty:leaves_4:2)
Block(5,20,-1,biomesoplenty:leaves_4:2)
Block(5,20,0,biomesoplenty:leaves_4:2)
Block(5,20,1,biomesoplenty:leaves_4:2)
Block(5,20,2,biomesoplenty:leaves_4:2)
Block(5,20,3,biomesoplenty:leaves_4:2)
Block(5,20,4,biomesoplenty:log_2)
Block(5,20,5,biomesoplenty:log_2:8)
Block(5,20,6,biomesoplenty:leaves_4:2)
Block(5,21,-2,biomesoplenty:leaves_4:2)
Block(5,21,-1,biomesoplenty:leaves_4:2)
Block(5,21,0,biomesoplenty:leaves_4:2)
Block(5,21,1,biomesoplenty:leaves_4:2)
Block(5,21,2,biomesoplenty:leaves_4:2)
Block(5,21,3,biomesoplenty:leaves_4:2)
Block(5,21,4,biomesoplenty:leaves_4:2)
Block(5,21,5,biomesoplenty:leaves_4:2)
Block(5,21,6,biomesoplenty:leaves_4:2)
Block(5,22,-1,biomesoplenty:leaves_4:2)
Block(5,22,0,biomesoplenty:leaves_4:2)
Block(5,22,1,biomesoplenty:leaves_4:2)
Block(5,22,2,biomesoplenty:leaves_4:2)
Block(5,22,3,biomesoplenty:leaves_4:2)
Block(5,22,4,biomesoplenty:leaves_4:2)
Block(5,22,5,biomesoplenty:leaves_4:2)
Block(5,22,6,biomesoplenty:leaves_4:2)
Block(5,22,8,biomesoplenty:leaves_4:2)
Block(5,22,9,biomesoplenty:leaves_4:2)
Block(5,23,-3,biomesoplenty:leaves_4:2)
Block(5,23,-2,biomesoplenty:leaves_4:2)
Block(5,23,-1,biomesoplenty:leaves_4:2)
Block(5,23,1,biomesoplenty:leaves_4:2)
Block(5,23,2,biomesoplenty:leaves_4:2)
Block(5,23,3,biomesoplenty:log_2)
Block(5,23,4,biomesoplenty:leaves_4:2)
Block(5,23,5,biomesoplenty:leaves_4:2)
Block(5,23,6,biomesoplenty:leaves_4:2)
Block(5,23,9,biomesoplenty:leaves_4:2)
Block(5,23,10,biomesoplenty:leaves_4:2)
Block(5,24,-4,biomesoplenty:leaves_4:2)
Block(5,24,-2,biomesoplenty:leaves_4:2)
Block(5,24,-1,biomesoplenty:leaves_4:2)
Block(5,24,0,biomesoplenty:leaves_4:2)
Block(5,24,4,biomesoplenty:leaves_4:2)
Block(5,24,6,biomesoplenty:leaves_4:2)
Block(5,24,7,biomesoplenty:leaves_4:2)
Block(5,24,8,biomesoplenty:leaves_4:2)
Block(5,24,9,biomesoplenty:leaves_4:2)
Block(5,24,10,biomesoplenty:leaves_4:2)
Block(5,25,-4,biomesoplenty:leaves_4:2)
Block(5,25,-3,biomesoplenty:leaves_4:2)
Block(5,25,-2,biomesoplenty:log_2:8)
Block(5,25,-1,biomesoplenty:log_2)
Block(5,25,0,biomesoplenty:leaves_4:2)
Block(5,25,2,biomesoplenty:log_2)
Block(5,25,4,biomesoplenty:leaves_4:2)
Block(5,25,5,biomesoplenty:leaves_4:2)
Block(5,25,6,biomesoplenty:leaves_4:2)
Block(5,25,7,biomesoplenty:leaves_4:2)
Block(5,25,9,biomesoplenty:leaves_4:2)
Block(5,25,10,biomesoplenty:leaves_4:2)
Block(5,26,-4,biomesoplenty:leaves_4:2)
Block(5,26,-2,biomesoplenty:leaves_4:2)
Block(5,26,-1,biomesoplenty:log_2)
Block(5,26,0,biomesoplenty:leaves_4:2)
Block(5,26,1,biomesoplenty:leaves_4:2)
Block(5,26,3,biomesoplenty:leaves_4:2)
Block(5,26,4,biomesoplenty:leaves_4:2)
Block(5,26,5,biomesoplenty:leaves_4:2)
Block(5,26,6,biomesoplenty:leaves_4:2)
Block(5,26,7,biomesoplenty:leaves_4:2)
Block(5,26,9,biomesoplenty:leaves_4:2)
Block(5,26,10,biomesoplenty:leaves_4:2)
Block(5,27,-3,biomesoplenty:leaves_4:2)
Block(5,27,-2,biomesoplenty:leaves_4:2)
Block(5,27,-1,biomesoplenty:leaves_4:2)
Block(5,27,0,biomesoplenty:leaves_4:2)
Block(5,27,1,biomesoplenty:leaves_4:2)
Block(5,27,2,biomesoplenty:leaves_4:2)
Block(5,27,3,biomesoplenty:log_2)
Block(5,27,4,biomesoplenty:leaves_4:2)
Block(5,27,5,biomesoplenty:leaves_4:2)
Block(5,27,6,biomesoplenty:leaves_4:2)
Block(5,27,7,biomesoplenty:leaves_4:2)
Block(5,27,8,biomesoplenty:leaves_4:2)
Block(5,28,-3,biomesoplenty:leaves_4:2)
Block(5,28,-2,biomesoplenty:leaves_4:2)
Block(5,28,-1,biomesoplenty:leaves_4:2)
Block(5,28,0,biomesoplenty:leaves_4:2)
Block(5,28,1,biomesoplenty:leaves_4:2)
Block(5,28,2,biomesoplenty:leaves_4:2)
Block(5,28,3,biomesoplenty:leaves_4:2)
Block(5,28,4,biomesoplenty:leaves_4:2)
Block(5,28,5,biomesoplenty:leaves_4:2)
Block(5,28,6,biomesoplenty:log_2:8)
Block(5,28,8,biomesoplenty:leaves_4:2)
Block(5,29,-2,biomesoplenty:leaves_4:2)
Block(5,29,-1,biomesoplenty:leaves_4:2)
Block(5,29,0,biomesoplenty:log_2)
Block(5,29,1,biomesoplenty:leaves_4:2)
Block(5,29,2,biomesoplenty:leaves_4:2)
Block(5,29,3,biomesoplenty:log_2)
Block(5,29,4,biomesoplenty:log_2)
Block(5,29,5,biomesoplenty:leaves_4:2)
Block(5,29,6,biomesoplenty:leaves_4:2)
Block(5,29,7,biomesoplenty:leaves_4:2)
Block(5,30,-2,biomesoplenty:leaves_4:2)
Block(5,30,-1,biomesoplenty:leaves_4:2)
Block(5,30,0,biomesoplenty:log_2)
Block(5,30,1,biomesoplenty:leaves_4:2)
Block(5,30,2,biomesoplenty:leaves_4:2)
Block(5,30,3,biomesoplenty:leaves_4:2)
Block(5,30,4,biomesoplenty:log_2)
Block(5,31,-2,biomesoplenty:leaves_4:2)
Block(5,31,-1,biomesoplenty:log_2:8)
Block(5,31,0,biomesoplenty:log_2)
Block(5,31,1,biomesoplenty:log_2)
Block(5,31,2,biomesoplenty:leaves_4:2)
Block(5,31,3,biomesoplenty:leaves_4:2)
Block(5,31,4,biomesoplenty:log_2)
Block(5,31,5,biomesoplenty:leaves_4:2)
Block(5,31,6,biomesoplenty:leaves_4:2)
Block(5,31,7,biomesoplenty:leaves_4:2)
Block(5,31,8,biomesoplenty:leaves_4:2)
Block(5,32,-4,biomesoplenty:leaves_4:2)
Block(5,32,-3,biomesoplenty:leaves_4:2)
Block(5,32,-2,biomesoplenty:leaves_4:2)
Block(5,32,-1,biomesoplenty:leaves_4:2)
Block(5,32,0,biomesoplenty:leaves_4:2)
Block(5,32,1,biomesoplenty:leaves_4:2)
Block(5,32,2,biomesoplenty:leaves_4:2)
Block(5,32,3,biomesoplenty:leaves_4:2)
Block(5,32,4,biomesoplenty:leaves_4:2)
Block(5,32,5,biomesoplenty:leaves_4:2)
Block(5,32,6,biomesoplenty:leaves_4:2)
Block(5,33,-3,biomesoplenty:leaves_4:2)
Block(5,33,-2,biomesoplenty:leaves_4:2)
Block(5,33,-1,biomesoplenty:leaves_4:2)
Block(5,33,0,biomesoplenty:leaves_4:2)
Block(5,33,1,biomesoplenty:leaves_4:2)
Block(5,33,2,biomesoplenty:leaves_4:2)
Block(5,33,3,biomesoplenty:leaves_4:2)
Block(5,33,4,biomesoplenty:leaves_4:2)
Block(5,33,5,biomesoplenty:leaves_4:2)
Block(5,33,6,biomesoplenty:leaves_4:2)
Block(5,33,7,biomesoplenty:leaves_4:2)
Block(5,34,-2,biomesoplenty:leaves_4:2)
Block(5,34,-1,biomesoplenty:leaves_4:2)
Block(5,34,0,biomesoplenty:leaves_4:2)
Block(5,34,1,biomesoplenty:leaves_4:2)
Block(5,34,2,biomesoplenty:leaves_4:2)
Block(5,34,3,biomesoplenty:leaves_4:2)
Block(5,34,4,biomesoplenty:leaves_4:2)
Block(5,34,5,biomesoplenty:leaves_4:2)
Block(5,35,-2,biomesoplenty:leaves_4:2)
Block(5,35,-1,biomesoplenty:leaves_4:2)
Block(5,35,0,biomesoplenty:leaves_4:2)
Block(5,35,1,biomesoplenty:leaves_4:2)
Block(5,35,2,biomesoplenty:leaves_4:2)
Block(5,35,3,biomesoplenty:leaves_4:2)
Block(5,35,4,biomesoplenty:leaves_4:2)
Block(5,35,5,biomesoplenty:leaves_4:2)
Block(5,35,6,biomesoplenty:leaves_4:2)
Block(5,36,-2,biomesoplenty:leaves_4:2)
Block(5,36,-1,biomesoplenty:leaves_4:2)
Block(5,36,0,biomesoplenty:leaves_4:2)
Block(5,36,1,biomesoplenty:leaves_4:2)
Block(5,36,2,biomesoplenty:leaves_4:2)
Block(5,36,3,biomesoplenty:leaves_4:2)
Block(5,36,4,biomesoplenty:log_2)
Block(5,36,5,biomesoplenty:log_2:8)
Block(5,36,6,biomesoplenty:leaves_4:2)
Block(5,36,7,biomesoplenty:leaves_4:2)
Block(5,36,8,biomesoplenty:leaves_4:2)
Block(5,37,-2,biomesoplenty:leaves_4:2)
Block(5,37,-1,biomesoplenty:leaves_4:2)
Block(5,37,0,biomesoplenty:leaves_4:2)
Block(5,37,1,biomesoplenty:leaves_4:2)
Block(5,37,2,biomesoplenty:log_2)
Block(5,37,3,biomesoplenty:leaves_4:2)
Block(5,37,4,biomesoplenty:leaves_4:2)
Block(5,37,5,biomesoplenty:log_2)
Block(5,37,6,biomesoplenty:log_2:8)
Block(5,37,7,biomesoplenty:leaves_4:2)
Block(5,37,8,biomesoplenty:leaves_4:2)
Block(5,38,-2,biomesoplenty:leaves_4:2)
Block(5,38,-1,biomesoplenty:leaves_4:2)
Block(5,38,0,biomesoplenty:leaves_4:2)
Block(5,38,1,biomesoplenty:leaves_4:2)
Block(5,38,2,biomesoplenty:leaves_4:2)
Block(5,38,3,biomesoplenty:leaves_4:2)
Block(5,38,4,biomesoplenty:leaves_4:2)
Block(5,38,5,biomesoplenty:leaves_4:2)
Block(5,38,6,biomesoplenty:leaves_4:2)
Block(5,38,7,biomesoplenty:leaves_4:2)
Block(5,38,8,biomesoplenty:leaves_4:2)
Block(5,39,0,biomesoplenty:leaves_4:2)
Block(5,39,1,biomesoplenty:leaves_4:2)
Block(5,39,2,biomesoplenty:leaves_4:2)
Block(5,39,3,biomesoplenty:leaves_4:2)
Block(5,39,4,biomesoplenty:leaves_4:2)
Block(5,39,5,biomesoplenty:leaves_4:2)
Block(5,39,6,biomesoplenty:leaves_4:2)
Block(5,39,7,biomesoplenty:leaves_4:2)
Block(5,39,8,biomesoplenty:leaves_4:2)
Block(5,40,1,biomesoplenty:leaves_4:2)
Block(5,40,2,biomesoplenty:leaves_4:2)
Block(5,40,3,biomesoplenty:log_2)
Block(5,40,4,biomesoplenty:log_2:8)
Block(5,40,5,biomesoplenty:leaves_4:2)
Block(5,40,6,biomesoplenty:leaves_4:2)
Block(5,41,0,biomesoplenty:leaves_4:2)
Block(5,41,1,biomesoplenty:leaves_4:2)
Block(5,41,2,biomesoplenty:leaves_4:2)
Block(5,41,3,biomesoplenty:leaves_4:2)
Block(5,41,4,biomesoplenty:leaves_4:2)
Block(5,41,5,biomesoplenty:leaves_4:2)
Block(5,41,6,biomesoplenty:leaves_4:2)
Block(5,42,0,biomesoplenty:leaves_4:2)
Block(5,42,1,biomesoplenty:leaves_4:2)
Block(5,42,2,biomesoplenty:leaves_4:2)
Block(5,42,3,biomesoplenty:leaves_4:2)
Block(5,42,4,biomesoplenty:leaves_4:2)
Block(5,42,5,biomesoplenty:leaves_4:2)
Block(5,43,1,biomesoplenty:leaves_4:2)
Block(5,43,3,biomesoplenty:log_2)
Block(5,43,4,biomesoplenty:leaves_4:2)
Block(5,43,5,biomesoplenty:leaves_4:2)
Block(5,44,1,biomesoplenty:leaves_4:2)
Block(5,44,2,biomesoplenty:leaves_4:2)
Block(5,44,3,biomesoplenty:leaves_4:2)
Block(5,44,4,biomesoplenty:leaves_4:2)
Block(5,44,5,biomesoplenty:leaves_4:2)
Block(5,44,6,biomesoplenty:leaves_4:2)
Block(5,45,2,biomesoplenty:leaves_4:2)
Block(5,45,3,biomesoplenty:leaves_4:2)
Block(5,45,4,biomesoplenty:leaves_4:2)
Block(5,45,5,biomesoplenty:leaves_4:2)
Block(5,46,2,biomesoplenty:leaves_4:2)
Block(5,46,3,biomesoplenty:leaves_4:2)
Block(5,46,4,biomesoplenty:leaves_4:2)
Block(5,46,5,biomesoplenty:leaves_4:2)
Block(5,47,1,biomesoplenty:leaves_4:2)
Block(5,47,2,biomesoplenty:leaves_4:2)
Block(5,47,3,biomesoplenty:leaves_4:2)
Block(5,47,4,biomesoplenty:leaves_4:2)
Block(5,47,5,biomesoplenty:leaves_4:2)
Block(5,48,3,biomesoplenty:leaves_4:2)
Block(5,48,4,biomesoplenty:leaves_4:2)
Block(5,49,3,biomesoplenty:leaves_4:2)
Block(5,50,3,biomesoplenty:leaves_4:2)
Block(5,50,4,biomesoplenty:leaves_4:2)
Block(6,0,1,biomesoplenty:log_2)
Block(6,0,2,biomesoplenty:log_2)
Block(6,0,3,biomesoplenty:log_2)
Block(6,0,4,biomesoplenty:log_2)
Block(6,0,5,biomesoplenty:log_2)
Block(6,1,3,biomesoplenty:log_2)
Block(6,1,4,biomesoplenty:log_2)
Block(6,2,4,biomesoplenty:log_2)
Block(6,17,3,biomesoplenty:leaves_4:2)
Block(6,17,4,biomesoplenty:leaves_4:2)
Block(6,17,5,biomesoplenty:leaves_4:2)
Block(6,18,-1,biomesoplenty:leaves_4:2)
Block(6,18,0,biomesoplenty:leaves_4:2)
Block(6,18,1,biomesoplenty:leaves_4:2)
Block(6,18,2,biomesoplenty:leaves_4:2)
Block(6,18,4,biomesoplenty:leaves_4:2)
Block(6,18,6,biomesoplenty:leaves_4:2)
Block(6,19,-1,biomesoplenty:log_2:8)
Block(6,19,0,biomesoplenty:log_2:8)
Block(6,19,1,biomesoplenty:log_2)
Block(6,19,2,biomesoplenty:leaves_4:2)
Block(6,19,3,biomesoplenty:leaves_4:2)
Block(6,19,4,biomesoplenty:leaves_4:2)
Block(6,19,5,biomesoplenty:log_2)
Block(6,19,6,biomesoplenty:leaves_4:2)
Block(6,20,-2,biomesoplenty:leaves_4:2)
Block(6,20,-1,biomesoplenty:leaves_4:2)
Block(6,20,0,biomesoplenty:leaves_4:2)
Block(6,20,1,biomesoplenty:log_2)
Block(6,20,2,biomesoplenty:leaves_4:2)
Block(6,20,3,biomesoplenty:leaves_4:2)
Block(6,20,4,biomesoplenty:leaves_4:2)
Block(6,20,5,biomesoplenty:leaves_4:2)
Block(6,21,-2,biomesoplenty:leaves_4:2)
Block(6,21,-1,biomesoplenty:leaves_4:2)
Block(6,21,0,biomesoplenty:leaves_4:2)
Block(6,21,1,biomesoplenty:leaves_4:2)
Block(6,21,2,biomesoplenty:leaves_4:2)
Block(6,21,3,biomesoplenty:leaves_4:2)
Block(6,21,4,biomesoplenty:leaves_4:2)
Block(6,21,5,biomesoplenty:leaves_4:2)
Block(6,21,6,biomesoplenty:leaves_4:2)
Block(6,22,0,biomesoplenty:leaves_4:2)
Block(6,22,1,biomesoplenty:leaves_4:2)
Block(6,22,2,biomesoplenty:leaves_4:2)
Block(6,22,3,biomesoplenty:leaves_4:2)
Block(6,22,4,biomesoplenty:leaves_4:2)
Block(6,22,5,biomesoplenty:leaves_4:2)
Block(6,22,6,biomesoplenty:leaves_4:2)
Block(6,23,-3,biomesoplenty:leaves_4:2)
Block(6,23,-2,biomesoplenty:leaves_4:2)
Block(6,23,0,biomesoplenty:leaves_4:2)
Block(6,23,1,biomesoplenty:leaves_4:2)
Block(6,23,2,biomesoplenty:leaves_4:2)
Block(6,23,3,biomesoplenty:log_2)
Block(6,23,4,biomesoplenty:log_2:8)
Block(6,23,5,biomesoplenty:leaves_4:2)
Block(6,23,9,biomesoplenty:leaves_4:2)
Block(6,24,-3,biomesoplenty:leaves_4:2)
Block(6,24,-2,biomesoplenty:leaves_4:2)
Block(6,24,2,biomesoplenty:leaves_4:2)
Block(6,24,3,biomesoplenty:leaves_4:2)
Block(6,24,4,biomesoplenty:leaves_4:2)
Block(6,24,9,biomesoplenty:leaves_4:2)
Block(6,25,-4,biomesoplenty:leaves_4:2)
Block(6,25,-2,biomesoplenty:leaves_4:2)
Block(6,25,-1,biomesoplenty:leaves_4:2)
Block(6,25,0,biomesoplenty:leaves_4:2)
Block(6,25,2,biomesoplenty:leaves_4:2)
Block(6,25,3,biomesoplenty:leaves_4:2)
Block(6,25,4,biomesoplenty:leaves_4:2)
Block(6,25,6,biomesoplenty:leaves_4:2)
Block(6,25,8,biomesoplenty:leaves_4:2)
Block(6,25,9,biomesoplenty:leaves_4:2)
Block(6,26,-3,biomesoplenty:leaves_4:2)
Block(6,26,-2,biomesoplenty:leaves_4:2)
Block(6,26,-1,biomesoplenty:leaves_4:2)
Block(6,26,0,biomesoplenty:leaves_4:2)
Block(6,26,1,biomesoplenty:leaves_4:2)
Block(6,26,2,biomesoplenty:leaves_4:2)
Block(6,26,3,biomesoplenty:leaves_4:2)
Block(6,26,4,biomesoplenty:leaves_4:2)
Block(6,26,5,biomesoplenty:leaves_4:2)
Block(6,26,7,biomesoplenty:leaves_4:2)
Block(6,26,8,biomesoplenty:leaves_4:2)
Block(6,26,9,biomesoplenty:leaves_4:2)
Block(6,27,-2,biomesoplenty:leaves_4:2)
Block(6,27,-1,biomesoplenty:leaves_4:2)
Block(6,27,1,biomesoplenty:leaves_4:2)
Block(6,27,2,biomesoplenty:leaves_4:2)
Block(6,27,3,biomesoplenty:leaves_4:2)
Block(6,27,4,biomesoplenty:leaves_4:2)
Block(6,27,5,biomesoplenty:leaves_4:2)
Block(6,27,6,biomesoplenty:log_2:8)
Block(6,27,7,biomesoplenty:log_2:8)
Block(6,27,8,biomesoplenty:leaves_4:2)
Block(6,28,-3,biomesoplenty:leaves_4:2)
Block(6,28,-2,biomesoplenty:leaves_4:2)
Block(6,28,-1,biomesoplenty:log_2)
Block(6,28,0,biomesoplenty:leaves_4:2)
Block(6,28,1,biomesoplenty:leaves_4:2)
Block(6,28,2,biomesoplenty:leaves_4:2)
Block(6,28,3,biomesoplenty:leaves_4:2)
Block(6,28,4,biomesoplenty:leaves_4:2)
Block(6,28,5,biomesoplenty:leaves_4:2)
Block(6,28,9,biomesoplenty:leaves_4:2)
Block(6,29,-2,biomesoplenty:leaves_4:2)
Block(6,29,-1,biomesoplenty:leaves_4:2)
Block(6,29,0,biomesoplenty:log_2)
Block(6,29,1,biomesoplenty:leaves_4:2)
Block(6,29,2,biomesoplenty:leaves_4:2)
Block(6,29,3,biomesoplenty:leaves_4:2)
Block(6,29,4,biomesoplenty:leaves_4:2)
Block(6,29,5,biomesoplenty:leaves_4:2)
Block(6,29,6,biomesoplenty:leaves_4:2)
Block(6,29,7,biomesoplenty:leaves_4:2)
Block(6,30,-2,biomesoplenty:leaves_4:2)
Block(6,30,-1,biomesoplenty:leaves_4:2)
Block(6,30,0,biomesoplenty:leaves_4:2)
Block(6,30,1,biomesoplenty:leaves_4:2)
Block(6,30,2,biomesoplenty:leaves_4:2)
Block(6,30,4,biomesoplenty:log_2)
Block(6,30,5,biomesoplenty:leaves_4:2)
Block(6,30,6,biomesoplenty:leaves_4:2)
Block(6,30,7,biomesoplenty:leaves_4:2)
Block(6,30,8,biomesoplenty:leaves_4:2)
Block(6,31,-3,biomesoplenty:leaves_4:2)
Block(6,31,-2,biomesoplenty:leaves_4:2)
Block(6,31,-1,biomesoplenty:log_2)
Block(6,31,0,biomesoplenty:leaves_4:2)
Block(6,31,1,biomesoplenty:leaves_4:2)
Block(6,31,2,biomesoplenty:leaves_4:2)
Block(6,31,3,biomesoplenty:leaves_4:2)
Block(6,31,4,biomesoplenty:log_2)
Block(6,31,5,biomesoplenty:log_2:8)
Block(6,31,6,biomesoplenty:log_2:8)
Block(6,31,7,biomesoplenty:leaves_4:2)
Block(6,31,8,biomesoplenty:leaves_4:2)
Block(6,32,-3,biomesoplenty:leaves_4:2)
Block(6,32,-2,biomesoplenty:leaves_4:2)
Block(6,32,-1,biomesoplenty:leaves_4:2)
Block(6,32,0,biomesoplenty:leaves_4:2)
Block(6,32,1,biomesoplenty:leaves_4:2)
Block(6,32,2,biomesoplenty:leaves_4:2)
Block(6,32,3,biomesoplenty:leaves_4:2)
Block(6,32,4,biomesoplenty:leaves_4:2)
Block(6,32,5,biomesoplenty:log_2)
Block(6,32,6,biomesoplenty:leaves_4:2)
Block(6,32,7,biomesoplenty:leaves_4:2)
Block(6,32,8,biomesoplenty:leaves_4:2)
Block(6,33,-3,biomesoplenty:leaves_4:2)
Block(6,33,-2,biomesoplenty:leaves_4:2)
Block(6,33,-1,biomesoplenty:leaves_4:2)
Block(6,33,0,biomesoplenty:leaves_4:2)
Block(6,33,1,biomesoplenty:leaves_4:2)
Block(6,33,2,biomesoplenty:leaves_4:2)
Block(6,33,3,biomesoplenty:leaves_4:2)
Block(6,33,4,biomesoplenty:leaves_4:2)
Block(6,33,5,biomesoplenty:leaves_4:2)
Block(6,33,6,biomesoplenty:leaves_4:2)
Block(6,33,7,biomesoplenty:leaves_4:2)
Block(6,34,-2,biomesoplenty:leaves_4:2)
Block(6,34,-1,biomesoplenty:leaves_4:2)
Block(6,34,0,biomesoplenty:leaves_4:2)
Block(6,34,1,biomesoplenty:log_2)
Block(6,34,2,biomesoplenty:leaves_4:2)
Block(6,34,3,biomesoplenty:leaves_4:2)
Block(6,34,4,biomesoplenty:leaves_4:2)
Block(6,35,-1,biomesoplenty:leaves_4:2)
Block(6,35,0,biomesoplenty:leaves_4:2)
Block(6,35,1,biomesoplenty:log_2)
Block(6,35,2,biomesoplenty:leaves_4:2)
Block(6,35,3,biomesoplenty:leaves_4:2)
Block(6,35,4,biomesoplenty:leaves_4:2)
Block(6,35,6,biomesoplenty:leaves_4:2)
Block(6,35,7,biomesoplenty:leaves_4:2)
Block(6,36,-2,biomesoplenty:leaves_4:2)
Block(6,36,-1,biomesoplenty:leaves_4:2)
Block(6,36,0,biomesoplenty:leaves_4:2)
Block(6,36,1,biomesoplenty:log_2:8)
Block(6,36,2,biomesoplenty:log_2)
Block(6,36,3,biomesoplenty:leaves_4:2)
Block(6,36,4,biomesoplenty:leaves_4:2)
Block(6,36,5,biomesoplenty:leaves_4:2)
Block(6,36,6,biomesoplenty:leaves_4:2)
Block(6,36,7,biomesoplenty:leaves_4:2)
Block(6,36,8,biomesoplenty:leaves_4:2)
Block(6,37,0,biomesoplenty:leaves_4:2)
Block(6,37,1,biomesoplenty:leaves_4:2)
Block(6,37,2,biomesoplenty:log_2)
Block(6,37,3,biomesoplenty:leaves_4:2)
Block(6,37,4,biomesoplenty:leaves_4:2)
Block(6,37,5,biomesoplenty:leaves_4:2)
Block(6,37,6,biomesoplenty:leaves_4:2)
Block(6,37,7,biomesoplenty:leaves_4:2)
Block(6,37,8,biomesoplenty:leaves_4:2)
Block(6,38,-1,biomesoplenty:leaves_4:2)
Block(6,38,0,biomesoplenty:leaves_4:2)
Block(6,38,1,biomesoplenty:leaves_4:2)
Block(6,38,2,biomesoplenty:leaves_4:2)
Block(6,38,3,biomesoplenty:leaves_4:2)
Block(6,38,4,biomesoplenty:leaves_4:2)
Block(6,38,5,biomesoplenty:leaves_4:2)
Block(6,38,6,biomesoplenty:log_2)
Block(6,38,7,biomesoplenty:leaves_4:2)
