
#######################################################################
# +-----------------------------------------------------------------+ #
# |                            BO3 object                           | #
# +-----------------------------------------------------------------+ #
#######################################################################

Author: Unknown

Description: Converted version of the BO2 AcaciaSavanna2

Version: 3

SettingsMode: WriteWithoutComments


#######################################################################
# +-----------------------------------------------------------------+ #
# |                          Main settings                          | #
# +-----------------------------------------------------------------+ #
#######################################################################

Tree: true

Frequency: 1

Rarity: 5.0

RotateRandomly: true

SpawnHeight: highestSolidBlock

SpawnHeightOffset: 0

SpawnHeightVariance: 0

##############################
# Height Limits for the BO3. #
##############################

MinHeight: 63

MaxHeight: 255

######################
# Extrusion settings #
######################

ExtrudeMode: None

ExtrudeThroughBlocks: AIR

MaxBranchDepth: 10

ExcludedBiomes: All


#######################################################################
# +-----------------------------------------------------------------+ #
# |                      Source block settings                      | #
# +-----------------------------------------------------------------+ #
#######################################################################

SourceBlocks: STONE:1,STONE:3,STONE:5,DIRT:1,DIRT:0,SAND:0,GRASS:0,DIRT:2,STATIONARY_WATER:0,HARD_CLAY,STAINED_CLAY:0,CLAY,SANDSTONE:0,SAND:1,AIR,STONE:0,GRAVEL,LONG_GRASS:0,LONG_GRASS:1,LONG_GRASS:2,DEAD_BUSH,YELLOW_FLOWER:0,RED_ROSE:0,BROWN_MUSHROOM,RED_MUSHROOM

MaxPercentageOutsideSourceBlock: 0

OutsideSourceBlock: placeAnyway

DoReplaceBlocks: true

IsOTGPlus: false


#######################################################################
# +-----------------------------------------------------------------+ #
# |                              Blocks                             | #
# +-----------------------------------------------------------------+ #
#######################################################################

Block(3,6,-3,LOG_2:0)
Block(-4,9,2,LEAVES_2:0)
Block(3,7,-3,LOG_2:0)
Block(-4,8,2,LEAVES_2:0)
Block(3,8,-3,LEAVES_2:0)
Block(3,9,-3,LEAVES_2:0)
Block(-6,9,-6,LEAVES_2:0)
Block(4,10,-3,LEAVES_2:0)
Block(6,6,1,LEAVES_2:0)
Block(3,10,-4,LEAVES_2:0)
Block(1,8,-4,LEAVES_2:0)
Block(1,9,-4,LEAVES_2:0)
Block(-3,9,4,LEAVES_2:0)
Block(2,6,2,LEAVES_2:0)
Block(-3,10,-2,LEAVES_2:0)
Block(-1,10,1,LEAVES_2:0)
Block(-7,9,3,LEAVES_2:0)
Block(-1,11,1,LEAVES_2:0)
Block(-5,9,-2,LEAVES_2:0)
Block(-3,10,2,LEAVES_2:0)
Block(3,6,0,LEAVES_2:0)
Block(2,9,-7,LEAVES_2:0)
Block(-1,9,0,LEAVES_2:0)
Block(-1,8,0,LEAVES_2:0)
Block(3,9,0,LEAVES_2:0)
Block(-4,9,-7,LEAVES_2:0)
Block(-1,9,-3,LEAVES_2:0)
Block(-2,11,-3,LEAVES_2:0)
Block(-2,10,-3,LEAVES_2:0)
Block(2,10,-5,LEAVES_2:0)
Block(5,7,4,LEAVES_2:0)
Block(-3,8,-2,LEAVES_2:0)
Block(5,6,4,LEAVES_2:0)
Block(5,9,-3,LEAVES_2:0)
Block(-3,9,-2,LEAVES_2:0)
Block(5,5,4,LEAVES_2:0)
Block(4,6,6,LEAVES_2:0)
Block(5,8,-3,LEAVES_2:0)
Block(-1,3,0,LOG_2:0)
Block(3,8,-2,LEAVES_2:0)
Block(-4,9,1,LEAVES_2:0)
Block(3,9,-2,LEAVES_2:0)
Block(0,9,-1,LEAVES_2:0)
Block(-3,10,-3,LEAVES_2:0)
Block(-6,9,-5,LEAVES_2:0)
Block(6,6,0,LEAVES_2:0)
Block(-2,10,-4,LEAVES_2:0)
Block(0,1,-1,LOG_2:0)
Block(-6,10,-4,LEAVES_2:0)
Block(0,0,-1,LOG_2:0)
Block(0,2,-1,LOG_2:0)
Block(1,9,-3,LEAVES_2:0)
Block(1,8,-3,LEAVES_2:0)
Block(4,9,-6,LEAVES_2:0)
Block(7,9,-3,LEAVES_2:0)
Block(-3,8,3,LEAVES_2:0)
Block(2,6,3,LEAVES_2:0)
Block(-3,9,3,LEAVES_2:0)
Block(1,10,-1,LEAVES_2:0)
Block(-5,8,-3,LEAVES_2:0)
Block(-5,9,-3,LEAVES_2:0)
Block(3,6,1,LEAVES_2:0)
Block(-4,10,5,LEAVES_2:0)
Block(-1,3,-2,LOG_2:0)
Block(3,4,1,LOG_2:0)
Block(-1,2,-2,LOG_2:0)
Block(-2,9,5,LEAVES_2:0)
Block(4,10,-2,LEAVES_2:0)
Block(-1,9,-2,LEAVES_2:0)
Block(-1,8,-2,LEAVES_2:0)
Block(-4,9,-6,LEAVES_2:0)
Block(-4,8,-6,LEAVES_2:0)
Block(3,10,-5,LEAVES_2:0)
Block(-1,10,-4,LEAVES_2:0)
Block(-2,10,4,LEAVES_2:0)
Block(-3,8,-1,LEAVES_2:0)
Block(5,6,5,LEAVES_2:0)
Block(-3,9,-1,LEAVES_2:0)
Block(-5,10,-5,LEAVES_2:0)
Block(-1,10,2,LEAVES_2:0)
Block(5,9,-4,LEAVES_2:0)
Block(-3,11,-3,LEAVES_2:0)
Block(0,10,-1,LEAVES_2:0)
Block(-3,11,3,LEAVES_2:0)
Block(-3,10,3,LEAVES_2:0)
Block(-4,8,4,LEAVES_2:0)
Block(3,8,-5,LEAVES_2:0)
Block(3,9,-5,LEAVES_2:0)
Block(-4,9,4,LEAVES_2:0)
Block(-6,9,-4,LEAVES_2:0)
Block(-2,10,0,LEAVES_2:0)
Block(-2,9,-5,LEAVES_2:0)
Block(4,9,-5,LEAVES_2:0)
Block(2,6,4,LEAVES_2:0)
Block(1,9,-2,LEAVES_2:0)
Block(1,6,-2,LOG_2:0)
Block(1,7,-2,LOG_2:0)
Block(-2,8,-5,LEAVES_2:0)
Block(3,6,2,LOG_2:0)
Block(8,6,3,LEAVES_2:0)
Block(-4,10,-3,LEAVES_2:0)
Block(3,5,2,LEAVES_2:0)
Block(-7,9,-3,LEAVES_2:0)
Block(-4,9,-1,LEAVES_2:0)
Block(-3,10,-4,LEAVES_2:0)
Block(-4,10,3,LEAVES_2:0)
Block(-1,9,2,LEAVES_2:0)
Block(-5,10,-4,LEAVES_2:0)
Block(3,7,2,LEAVES_2:0)
Block(-1,8,2,LEAVES_2:0)
Block(4,10,-4,LEAVES_2:0)
Block(3,11,-3,LEAVES_2:0)
Block(-2,9,0,LEAVES_2:0)
Block(3,10,-3,LEAVES_2:0)
Block(-2,8,0,LOG_2:0)
Block(-1,9,-5,LEAVES_2:0)
Block(1,10,-4,LEAVES_2:0)
Block(4,6,0,LEAVES_2:0)
Block(-5,9,1,LEAVES_2:0)
Block(4,9,0,LEAVES_2:0)
Block(5,6,6,LEAVES_2:0)
Block(0,8,1,LEAVES_2:0)
Block(2,9,-1,LEAVES_2:0)
Block(0,9,1,LEAVES_2:0)
Block(-1,10,0,LEAVES_2:0)
Block(-1,11,0,LEAVES_2:0)
Block(5,9,-5,LEAVES_2:0)
Block(-4,9,3,LOG_2:0)
Block(-4,8,3,LOG_2:0)
Block(-4,7,3,LOG_2:0)
Block(3,8,-4,LEAVES_2:0)
Block(-4,10,4,LEAVES_2:0)
Block(3,9,-4,LEAVES_2:0)
Block(-6,9,-3,LEAVES_2:0)
Block(-2,9,-6,LEAVES_2:0)
Block(4,9,-4,LEAVES_2:0)
Block(-3,9,5,LEAVES_2:0)
Block(-5,10,3,LEAVES_2:0)
Block(7,6,4,LEAVES_2:0)
Block(1,9,-1,LEAVES_2:0)
Block(2,10,-4,LEAVES_2:0)
Block(4,8,-4,LEAVES_2:0)
Block(1,3,-1,LOG_2:0)
Block(1,2,-1,LOG_2:0)
Block(-3,10,4,LEAVES_2:0)
Block(-5,9,-1,LEAVES_2:0)
Block(8,6,2,LEAVES_2:0)
Block(-7,9,-4,LEAVES_2:0)
Block(-1,8,1,LOG_2:0)
Block(3,7,3,LEAVES_2:0)
Block(3,6,3,LEAVES_2:0)
Block(-1,9,1,LOG_2:0)
Block(-4,9,-8,LEAVES_2:0)
Block(-2,10,-5,LEAVES_2:0)
Block(-1,9,-4,LEAVES_2:0)
Block(4,6,1,LEAVES_2:0)
Block(-5,9,2,LEAVES_2:0)
Block(4,5,1,LEAVES_2:0)
Block(2,4,-2,LOG_2:0)
Block(4,7,1,LEAVES_2:0)
Block(0,9,0,LEAVES_2:0)
Block(2,5,-2,LOG_2:0)
Block(-3,9,-7,LEAVES_2:0)
Block(2,9,-2,LEAVES_2:0)
Block(-4,10,-4,LEAVES_2:0)
Block(5,10,-3,LEAVES_2:0)
Block(-4,11,-4,LEAVES_2:0)
Block(6,6,5,LEAVES_2:0)
Block(1,9,0,LEAVES_2:0)
Block(-4,9,6,LEAVES_2:0)
Block(-3,10,-5,LEAVES_2:0)
Block(-5,10,-3,LEAVES_2:0)
Block(-4,10,2,LEAVES_2:0)
Block(-6,9,-2,LEAVES_2:0)
Block(6,9,-2,LEAVES_2:0)
Block(-5,9,-6,LEAVES_2:0)
Block(-2,9,-3,LEAVES_2:0)
Block(1,10,-3,LEAVES_2:0)
Block(2,10,-2,LEAVES_2:0)
Block(7,6,3,LEAVES_2:0)
Block(2,11,-2,LEAVES_2:0)
Block(4,9,-3,LOG_2:0)
Block(4,8,-3,LOG_2:0)
Block(0,9,-4,LEAVES_2:0)
Block(-3,9,0,LEAVES_2:0)
Block(0,10,-4,LEAVES_2:0)
Block(-3,8,0,LEAVES_2:0)
Block(-2,5,-3,LOG_2:0)
Block(0,10,1,LEAVES_2:0)
Block(-2,4,-3,LOG_2:0)
Block(-4,8,-3,LOG_2:0)
Block(-7,9,-5,LEAVES_2:0)
Block(3,7,4,LEAVES_2:0)
Block(3,6,4,LEAVES_2:0)
Block(-2,9,2,LEAVES_2:0)
Block(-2,8,2,LEAVES_2:0)
Block(-1,9,4,LEAVES_2:0)
Block(-4,9,-3,LOG_2:0)
Block(4,5,2,LOG_2:0)
Block(-5,8,3,LEAVES_2:0)
Block(-1,10,-2,LEAVES_2:0)
Block(4,7,2,LEAVES_2:0)
Block(4,6,2,LEAVES_2:0)
Block(-5,9,3,LEAVES_2:0)
Block(4,8,2,LEAVES_2:0)
Block(5,6,0,LEAVES_2:0)
Block(-3,9,-6,LEAVES_2:0)
Block(0,9,3,LEAVES_2:0)
Block(2,9,-3,LEAVES_2:0)
Block(2,8,-3,LEAVES_2:0)
Block(1,9,1,LEAVES_2:0)
Block(6,6,4,LEAVES_2:0)
Block(-4,9,5,LEAVES_2:0)
Block(3,9,-6,LEAVES_2:0)
Block(3,10,-2,LEAVES_2:0)
Block(-5,9,-7,LEAVES_2:0)
Block(-2,10,-1,LEAVES_2:0)
Block(-1,10,-1,LEAVES_2:0)
Block(4,8,-2,LEAVES_2:0)
Block(-2,8,-4,LEAVES_2:0)
Block(-2,9,-4,LEAVES_2:0)
Block(4,9,-2,LEAVES_2:0)
Block(0,9,-5,LEAVES_2:0)
Block(7,6,2,LEAVES_2:0)
Block(5,10,-4,LEAVES_2:0)
Block(-4,10,-5,LEAVES_2:0)
Block(-4,9,-2,LEAVES_2:0)
Block(-4,8,-2,LEAVES_2:0)
Block(-3,10,0,LEAVES_2:0)
Block(3,6,5,LEAVES_2:0)
Block(-2,9,1,LEAVES_2:0)
Block(-2,8,1,LEAVES_2:0)
Block(-1,9,-6,LEAVES_2:0)
Block(-1,9,3,LEAVES_2:0)
Block(-2,7,1,LOG_2:0)
Block(-6,9,2,LEAVES_2:0)
Block(-2,10,1,LEAVES_2:0)
Block(-2,4,1,LOG_2:0)
Block(-2,11,1,LEAVES_2:0)
Block(4,6,3,LEAVES_2:0)
Block(-5,9,4,LEAVES_2:0)
Block(4,5,3,LEAVES_2:0)
Block(2,10,-3,LEAVES_2:0)
Block(-5,10,4,LEAVES_2:0)
Block(4,7,3,LEAVES_2:0)
Block(5,7,1,LEAVES_2:0)
Block(-3,8,-5,LEAVES_2:0)
Block(0,9,2,LEAVES_2:0)
Block(5,6,1,LEAVES_2:0)
Block(-3,9,-5,LEAVES_2:0)
Block(5,5,1,LEAVES_2:0)
Block(0,10,0,LEAVES_2:0)
Block(2,9,-4,LOG_2:0)
Block(2,8,-4,LOG_2:0)
Block(3,9,-1,LEAVES_2:0)
Block(-4,9,0,LEAVES_2:0)
Block(1,9,2,LEAVES_2:0)
Block(0,8,-2,LOG_2:0)
Block(6,7,3,LEAVES_2:0)
Block(1,6,2,LEAVES_2:0)
Block(0,9,-2,LOG_2:0)
Block(6,6,3,LEAVES_2:0)
Block(6,5,3,LEAVES_2:0)
Block(6,9,-4,LEAVES_2:0)
Block(-2,10,-2,LEAVES_2:0)
Block(1,9,-6,LEAVES_2:0)
Block(-1,10,-3,LEAVES_2:0)
Block(-2,10,3,LEAVES_2:0)
Block(-5,9,-4,LEAVES_2:0)
Block(-2,9,-1,LOG_2:0)
Block(4,9,-1,LEAVES_2:0)
Block(-3,9,2,LEAVES_2:0)
Block(-3,8,2,LEAVES_2:0)
Block(2,9,0,LEAVES_2:0)
Block(-3,5,2,LOG_2:0)
Block(4,6,-1,LEAVES_2:0)
Block(-3,6,2,LOG_2:0)
Block(-2,8,-1,LEAVES_2:0)
Block(7,6,1,LEAVES_2:0)
Block(-5,8,-4,LEAVES_2:0)
Block(-2,9,4,LEAVES_2:0)
Block(1,10,0,LEAVES_2:0)
Block(-6,9,3,LEAVES_2:0)
Block(-4,8,-5,LOG_2:0)
Block(-1,9,-1,LEAVES_2:0)
Block(-1,8,-1,LEAVES_2:0)
Block(-4,9,-5,LOG_2:0)
Block(2,10,-1,LEAVES_2:0)
Block(4,7,4,LEAVES_2:0)
Block(-3,6,-4,LOG_2:0)
Block(5,6,-1,LEAVES_2:0)
Block(4,6,4,LEAVES_2:0)
Block(-5,9,5,LEAVES_2:0)
Block(-3,7,-4,LOG_2:0)
Block(5,7,2,LEAVES_2:0)
Block(-3,8,-4,LEAVES_2:0)
Block(-3,10,-1,LEAVES_2:0)
Block(0,10,2,LEAVES_2:0)
Block(5,6,2,LEAVES_2:0)
Block(-3,9,-4,LEAVES_2:0)
Block(5,9,-1,LEAVES_2:0)
Block(5,5,2,LEAVES_2:0)
Block(0,10,-3,LEAVES_2:0)
Block(2,9,-5,LEAVES_2:0)
Block(-4,10,-6,LEAVES_2:0)
Block(2,8,-5,LEAVES_2:0)
Block(-4,10,-2,LEAVES_2:0)
Block(-3,10,1,LEAVES_2:0)
Block(1,6,3,LEAVES_2:0)
Block(0,9,-3,LEAVES_2:0)
Block(0,8,-3,LEAVES_2:0)
Block(6,7,2,LEAVES_2:0)
Block(6,6,2,LEAVES_2:0)
Block(1,9,-5,LEAVES_2:0)
Block(-2,10,2,LEAVES_2:0)
Block(6,9,-3,LEAVES_2:0)
Block(-2,11,2,LEAVES_2:0)
Block(1,8,-5,LEAVES_2:0)
Block(2,9,1,LEAVES_2:0)
Block(-5,8,-5,LEAVES_2:0)
Block(-2,9,-2,LEAVES_2:0)
Block(-2,8,-2,LEAVES_2:0)
Block(-5,9,-5,LEAVES_2:0)
Block(2,6,1,LEAVES_2:0)
Block(-3,9,1,LEAVES_2:0)
Block(-1,10,3,LEAVES_2:0)
Block(-3,8,1,LEAVES_2:0)
Block(0,10,-2,LEAVES_2:0)
Block(2,9,-6,LEAVES_2:0)
Block(-2,9,3,LEAVES_2:0)
Block(-6,9,4,LEAVES_2:0)
Block(3,10,-1,LEAVES_2:0)
Block(2,4,0,LOG_2:0)
Block(-4,9,-4,LEAVES_2:0)
Block(-4,8,-4,LEAVES_2:0)
Block(1,10,-2,LEAVES_2:0)
Block(1,11,-2,LEAVES_2:0)
Block(4,6,5,LEAVES_2:0)
Block(5,8,3,LEAVES_2:0)
Block(5,7,3,LEAVES_2:0)
Block(-3,8,-3,LEAVES_2:0)
Block(5,6,3,LOG_2:0)
Block(-3,9,-3,LEAVES_2:0)
Block(5,5,3,LEAVES_2:0)
Block(5,9,-2,LEAVES_2:0)

#######################################################################
# +-----------------------------------------------------------------+ #
# |                            BO3 checks                           | #
# +-----------------------------------------------------------------+ #
#######################################################################

BlockCheck(0,-1,-1,GRASS:0,DIRT:0,DIRT:2)

#######################################################################
# +-----------------------------------------------------------------+ #
# |                             Branches                            | #
# +-----------------------------------------------------------------+ #
#######################################################################


#######################################################################
# +-----------------------------------------------------------------+ #
# |                             Entities                            | #
# +-----------------------------------------------------------------+ #
#######################################################################


#######################################################################
# +-----------------------------------------------------------------+ #
# |                            Particles                            | #
# +-----------------------------------------------------------------+ #
#######################################################################


#######################################################################
# +-----------------------------------------------------------------+ #
# |                             Spawners                            | #
# +-----------------------------------------------------------------+ #
#######################################################################


#######################################################################
# +-----------------------------------------------------------------+ #
# |                             ModData                             | #
# +-----------------------------------------------------------------+ #
#######################################################################

