#######################################################################
# +-----------------------------------------------------------------+ #
# |                            BO3 object                           | #
# +-----------------------------------------------------------------+ #
#######################################################################

# The descriptions in this file are accurate only for TerrainControl and OTG.
# For MCW and OTG+ these descriptions are only accurate if the BO3 is used as a CustomObject.
# MCW and OTG+ completely reimplemented CustomStructure, check the MCW/OTG+ documentation for more information.

# This is the config file of a custom object.
# If you add this object correctly to your BiomeConfigs, it will spawn in the world.

# This is the creator of this BO3 object
Author: Unknown

# A short description of this BO3 object
Description: This BO3 was converted from a schematic using OTGEdit. The author and description information of the schematic could not be found. If you know who the author of the schematic is then please add this information.

# The BO3 version, don't change this! It can be used by external applications to do a version check.
Version: 3

# The settings mode, WriteAll, WriteWithoutComments or WriteDisable. See WorldConfig.
SettingsMode: WriteDisable

#######################################################################
# +-----------------------------------------------------------------+ #
# |                          Main settings                          | #
# +-----------------------------------------------------------------+ #
#######################################################################

# This needs to be set to true to spawn the object in the Tree and Sapling resources.
Tree: true

# The frequency of the BO3 from 1 to 200. Tries this many times to spawn this BO3 when using the CustomObject(...) resource.
# Ignored by Tree(..), Sapling(..) and CustomStructure(..)
Frequency: 1

# The rarity of the BO3 from 0 to 100. Each spawn attempt has rarity% chance to succeed when using the CustomObject(...) resource.
# Ignored by Tree(..), Sapling(..) and CustomStructure(..)
Rarity: 100.0

# If you set this to true, the BO3 will be placed with a random rotation.
RotateRandomly: false

# The spawn height of the BO3 - randomY, highestBlock or highestSolidBlock.
SpawnHeight: highestSolidBlock

SpawnHeightOffset: -4

# The height limits for the BO3.
MinHeight: 64

MaxHeight: 85

# Objects can have other objects attached to it: branches. Branches can also
# have branches attached to it, which can also have branches, etc. This is the
# maximum branch depth for this objects.
MaxBranchDepth: 10

# When spawned with the UseWorld keyword, this BO3 should NOT spawn in the following biomes.
# If you writer.write the BO3 name directly in the BiomeConfigs, this will be ignored.
ExcludedBiomes: All

# To optimise this BO3 for faster loading times you can use Notepad++ to find/replace comments and abbreviate things.
# Notepad++ find/replace with regex:
# Find: ^[#;].* replace to nothing removes all lines starting with # 
# Find: ^\s*$ replace to nothing removes most empty lines 
# Notepad++ find/replace without regex:
# *Warning: This will only work for OTG 1.10.2 v21 / OTG 1.11.2 v6 or higher. B( is not recognised by lower versions.
# Find: Block( replace to B(

#######################################################################
# +-----------------------------------------------------------------+ #
# |                      Source block settings                      | #
# +-----------------------------------------------------------------+ #
#######################################################################

# The block(s) the BO3 should spawn in.
SourceBlocks: STONE:1,STONE:3,STONE:5,DIRT:1,DIRT,SAND,GRASS,DIRT:2,STATIONARY_WATER,HARD_CLAY,STAINED_CLAY,CLAY,SANDSTONE,SAND:1,AIR,STONE,GRAVEL,LONG_GRASS,LONG_GRASS:1,LONG_GRASS:2,DEAD_BUSH,YELLOW_FLOWER,RED_ROSE,BROWN_MUSHROOM,RED_MUSHROOM

# The maximum percentage of the BO3 that can be outside the SourceBlock.
# The BO3 won't be placed on a location with more blocks outside the SourceBlock than this percentage.
MaxPercentageOutsideSourceBlock: 0

# What to do when a block is about to be placed outside the SourceBlock? (dontPlace, placeAnyway)
OutsideSourceBlock: placeAnyway

#######################################################################
# +-----------------------------------------------------------------+ #
# |                              Blocks                             | #
# +-----------------------------------------------------------------+ #
#######################################################################

# All the blocks used in the BO3 are listed here. Possible blocks:
# Block(x,y,z,id[.data][,nbtfile.nbt) or B(x,y,z,id[.data][,nbtfile.nbt)
# RandomBlock(x,y,z,id[:data][,nbtfile.nbt],chance[,id[:data][,nbtfile.nbt],chance[,...]])
# So RandomBlock(0,0,0,CHEST,chest.nbt,50,CHEST,anotherchest.nbt,100) will spawn a chest at
# the BO3 origin, and give it a 50% chance to have the contents of chest.nbt, or, if that
# fails, a 100% percent chance to have the contents of anotherchest.nbt.

Block(-11,19,0,LEAVES_2:0)
Block(-11,20,5,LEAVES_2:0)
Block(-10,13,3,LEAVES_2:0)
Block(-10,14,8,LEAVES_2:0)
Block(-10,19,-1,LEAVES_2:0)
Block(-10,19,0,LEAVES_2:0)
Block(-10,19,1,LEAVES_2:0)
Block(-10,20,0,LEAVES_2:0)
Block(-10,20,4,LEAVES_2:0)
Block(-10,20,5,LEAVES_2:0)
Block(-10,20,6,LEAVES_2:0)
Block(-9,13,2,LEAVES_2:0)
Block(-9,13,3,LEAVES_2:0)
Block(-9,13,4,LEAVES_2:0)
Block(-9,14,3,LEAVES_2:0)
Block(-9,14,7,LEAVES_2:0)
Block(-9,14,8,LEAVES_2:0)
Block(-9,14,9,LEAVES_2:0)
Block(-9,15,8,LEAVES_2:0)
Block(-9,18,-1,LEAVES_2:0)
Block(-9,18,2,LEAVES_2:0)
Block(-9,19,-2,LEAVES_2:0)
Block(-9,19,-1,LEAVES_2:0)
Block(-9,19,0,LEAVES_2:0)
Block(-9,19,1,LEAVES_2:0)
Block(-9,19,3,LEAVES_2:0)
Block(-9,19,6,LEAVES_2:0)
Block(-9,20,0,LEAVES_2:0)
Block(-9,20,4,LEAVES_2:0)
Block(-9,20,5,LEAVES_2:0)
Block(-9,20,6,LEAVES_2:0)
Block(-9,20,7,LEAVES_2:0)
Block(-9,21,5,LEAVES_2:0)
Block(-9,21,6,LEAVES_2:0)
Block(-8,12,3,LEAVES_2:0)
Block(-8,13,1,LEAVES_2:0)
Block(-8,13,2,LEAVES_2:0)
Block(-8,13,3,LEAVES_2:0)
Block(-8,13,4,LEAVES_2:0)
Block(-8,13,8,LEAVES_2:0)
Block(-8,14,2,LEAVES_2:0)
Block(-8,14,3,LEAVES_2:0)
Block(-8,14,6,LEAVES_2:0)
Block(-8,14,7,LEAVES_2:0)
Block(-8,14,8,162:12)
Block(-8,14,9,LEAVES_2:0)
Block(-8,14,10,LEAVES_2:0)
Block(-8,14,12,LEAVES_2:0)
Block(-8,15,6,LEAVES_2:0)
Block(-8,15,8,LEAVES_2:0)
Block(-8,15,9,LEAVES_2:0)
Block(-8,19,-1,LEAVES_2:0)
Block(-8,19,0,162:12)
Block(-8,19,1,LEAVES_2:0)
Block(-8,19,4,LEAVES_2:0)
Block(-8,20,0,LEAVES_2:0)
Block(-8,20,4,LEAVES_2:0)
Block(-8,20,5,162:12)
Block(-8,20,6,LEAVES_2:0)
Block(-8,21,5,LEAVES_2:0)
Block(-7,-6,-2,162:12)
Block(-7,-5,-2,162:12)
Block(-7,12,5,LEAVES_2:0)
Block(-7,13,2,LEAVES_2:0)
Block(-7,13,3,162:12)
Block(-7,13,4,LEAVES_2:0)
Block(-7,13,7,LEAVES_2:0)
Block(-7,13,8,162:12)
Block(-7,13,9,LEAVES_2:0)
Block(-7,14,3,LEAVES_2:0)
Block(-7,14,8,LEAVES_2:0)
Block(-7,14,11,LEAVES_2:0)
Block(-7,14,12,LEAVES_2:0)
Block(-7,14,13,LEAVES_2:0)
Block(-7,15,3,LEAVES_2:0)
Block(-7,15,4,LEAVES_2:0)
Block(-7,15,5,LEAVES_2:0)
Block(-7,15,6,LEAVES_2:0)
Block(-7,15,12,LEAVES_2:0)
Block(-7,16,6,LEAVES_2:0)
Block(-7,18,-1,LEAVES_2:0)
Block(-7,18,0,162:12)
Block(-7,18,1,LEAVES_2:0)
Block(-7,18,4,LEAVES_2:0)
Block(-7,19,-2,LEAVES_2:0)
Block(-7,19,-1,LEAVES_2:0)
Block(-7,19,0,LEAVES_2:0)
Block(-7,19,1,LEAVES_2:0)
Block(-7,19,3,LEAVES_2:0)
Block(-7,19,4,162:12)
Block(-7,19,6,LEAVES_2:0)
Block(-7,20,-1,LEAVES_2:0)
Block(-7,20,0,LEAVES_2:0)
Block(-7,20,3,LEAVES_2:0)
Block(-7,20,4,LEAVES_2:0)
Block(-7,20,5,LEAVES_2:0)
Block(-6,-6,-2,162:12)
Block(-6,-6,-1,162:12)
Block(-6,-6,2,162:12)
Block(-6,-5,-2,162:12)
Block(-6,-5,-1,162:12)
Block(-6,-5,2,162:12)
Block(-6,-4,-2,162:12)
Block(-6,-4,-1,162:12)
Block(-6,-3,-1,162:12)
Block(-6,12,-2,LEAVES_2:0)
Block(-6,12,1,LEAVES_2:0)
Block(-6,12,2,LEAVES_2:0)
Block(-6,12,3,162:12)
Block(-6,12,4,LEAVES_2:0)
Block(-6,12,7,LEAVES_2:0)
Block(-6,13,-1,LEAVES_2:0)
Block(-6,13,3,LEAVES_2:0)
Block(-6,13,8,LEAVES_2:0)
Block(-6,13,9,162:12)
Block(-6,13,10,LEAVES_2:0)
Block(-6,13,12,LEAVES_2:0)
Block(-6,14,8,LEAVES_2:0)
Block(-6,14,9,LEAVES_2:0)
Block(-6,14,10,LEAVES_2:0)
Block(-6,14,11,LEAVES_2:0)
Block(-6,14,12,LEAVES_2:0)
Block(-6,14,13,LEAVES_2:0)
Block(-6,14,14,LEAVES_2:0)
Block(-6,15,3,LEAVES_2:0)
Block(-6,15,4,LEAVES_2:0)
Block(-6,15,5,162:12)
Block(-6,15,6,LEAVES_2:0)
Block(-6,15,7,LEAVES_2:0)
Block(-6,15,9,LEAVES_2:0)
Block(-6,15,12,LEAVES_2:0)
Block(-6,15,13,LEAVES_2:0)
Block(-6,16,4,LEAVES_2:0)
Block(-6,16,5,LEAVES_2:0)
Block(-6,18,0,LEAVES_2:0)
Block(-6,18,1,162:12)
Block(-6,18,2,LEAVES_2:0)
Block(-6,18,3,LEAVES_2:0)
Block(-6,18,4,162:12)
Block(-6,18,5,LEAVES_2:0)
Block(-6,19,1,LEAVES_2:0)
Block(-6,19,4,LEAVES_2:0)
Block(-6,20,-3,LEAVES_2:0)
Block(-6,20,-2,LEAVES_2:0)
Block(-6,20,-1,LEAVES_2:0)
Block(-6,20,0,LEAVES_2:0)
Block(-6,20,4,LEAVES_2:0)
Block(-6,21,-1,LEAVES_2:0)
Block(-5,-6,-1,162:12)
Block(-5,-6,0,162:12)
Block(-5,-6,2,162:12)
Block(-5,-5,-1,162:12)
Block(-5,-5,0,162:12)
Block(-5,-5,2,162:12)
Block(-5,-4,0,162:12)
Block(-5,-4,2,162:12)
Block(-5,-3,0,162:12)
Block(-5,-2,0,162:12)
Block(-5,12,3,LEAVES_2:0)
Block(-5,12,4,162:12)
Block(-5,12,8,LEAVES_2:0)
Block(-5,12,9,162:12)
Block(-5,13,-2,LEAVES_2:0)
Block(-5,13,-1,LEAVES_2:0)
Block(-5,13,0,LEAVES_2:0)
Block(-5,13,1,LEAVES_2:0)
Block(-5,13,9,LEAVES_2:0)
Block(-5,13,10,LEAVES_2:0)
Block(-5,13,14,LEAVES_2:0)
Block(-5,14,-1,LEAVES_2:0)
Block(-5,14,11,LEAVES_2:0)
Block(-5,14,12,162:12)
Block(-5,14,13,LEAVES_2:0)
Block(-5,15,-3,LEAVES_2:0)
Block(-5,15,4,LEAVES_2:0)
Block(-5,15,5,LEAVES_2:0)
Block(-5,15,6,162:12)
Block(-5,15,7,LEAVES_2:0)
Block(-5,16,-4,LEAVES_2:0)
Block(-5,16,6,LEAVES_2:0)
Block(-5,17,2,162:12)
Block(-5,17,3,162:12)
Block(-5,18,1,LEAVES_2:0)
Block(-5,18,2,LEAVES_2:0)
Block(-5,18,3,LEAVES_2:0)
Block(-5,18,4,LEAVES_2:0)
Block(-5,18,5,LEAVES_2:0)
Block(-5,19,0,LEAVES_2:0)
Block(-5,19,1,LEAVES_2:0)
Block(-5,19,3,LEAVES_2:0)
Block(-5,19,4,LEAVES_2:0)
Block(-5,20,-4,LEAVES_2:0)
Block(-5,20,-3,LEAVES_2:0)
Block(-5,20,-2,LEAVES_2:0)
Block(-5,20,-1,162:12)
Block(-5,21,-3,LEAVES_2:0)
Block(-5,21,-2,LEAVES_2:0)
Block(-5,21,-1,LEAVES_2:0)
Block(-4,-6,-5,162:12)
Block(-4,-6,-4,162:12)
Block(-4,-6,-2,162:12)
Block(-4,-6,-1,162:12)
Block(-4,-6,0,162:12)
Block(-4,-6,1,162:12)
Block(-4,-6,2,162:12)
Block(-4,-6,3,162:12)
Block(-4,-6,4,162:12)
Block(-4,-5,-5,162:12)
Block(-4,-5,-4,162:12)
Block(-4,-5,-2,162:12)
Block(-4,-5,-1,162:12)
Block(-4,-5,0,162:12)
Block(-4,-5,1,162:12)
Block(-4,-5,2,162:12)
Block(-4,-5,4,162:12)
Block(-4,-4,-2,162:12)
Block(-4,-4,-1,162:12)
Block(-4,-4,0,162:12)
Block(-4,-4,1,162:12)
Block(-4,-3,-1,162:12)
Block(-4,-3,0,162:12)
Block(-4,-3,1,162:12)
Block(-4,-2,0,162:12)
Block(-4,-1,0,162:12)
Block(-4,11,4,162:12)
Block(-4,12,-1,LEAVES_2:0)
Block(-4,12,2,LEAVES_2:0)
Block(-4,12,4,LEAVES_2:0)
Block(-4,12,9,162:12)
Block(-4,13,-3,LEAVES_2:0)
Block(-4,13,-2,LEAVES_2:0)
Block(-4,13,-1,LEAVES_2:0)
Block(-4,13,0,162:12)
Block(-4,13,1,LEAVES_2:0)
Block(-4,13,8,LEAVES_2:0)
Block(-4,13,9,162:12)
Block(-4,13,10,162:12)
Block(-4,14,-2,LEAVES_2:0)
Block(-4,14,0,LEAVES_2:0)
Block(-4,14,1,LEAVES_2:0)
Block(-4,14,4,LEAVES_2:0)
Block(-4,14,5,LEAVES_2:0)
Block(-4,14,6,162:12)
Block(-4,14,7,LEAVES_2:0)
Block(-4,14,9,LEAVES_2:0)
Block(-4,14,10,LEAVES_2:0)
Block(-4,14,11,162:12)
Block(-4,14,12,LEAVES_2:0)
Block(-4,14,13,LEAVES_2:0)
Block(-4,15,6,LEAVES_2:0)
Block(-4,15,11,LEAVES_2:0)
Block(-4,15,12,LEAVES_2:0)
Block(-4,16,-5,LEAVES_2:0)
Block(-4,16,-4,LEAVES_2:0)
Block(-4,16,-3,LEAVES_2:0)
Block(-4,17,-7,LEAVES_2:0)
Block(-4,17,-4,LEAVES_2:0)
Block(-4,17,-2,LEAVES_2:0)
Block(-4,17,-1,LEAVES_2:0)
Block(-4,17,2,162:12)
Block(-4,18,1,162:12)
Block(-4,18,2,LEAVES_2:0)
Block(-4,18,3,LEAVES_2:0)
Block(-4,18,4,LEAVES_2:0)
Block(-4,18,5,LEAVES_2:0)
Block(-4,19,-2,LEAVES_2:0)
Block(-4,19,0,162:12)
Block(-4,19,1,LEAVES_2:0)
Block(-4,19,2,LEAVES_2:0)
Block(-4,19,4,LEAVES_2:0)
Block(-4,20,-3,LEAVES_2:0)
Block(-4,20,-2,LEAVES_2:0)
Block(-4,20,-1,LEAVES_2:0)
Block(-4,20,0,LEAVES_2:0)
Block(-4,20,1,LEAVES_2:0)
Block(-3,-6,-4,162:12)
Block(-3,-6,-3,162:12)
Block(-3,-6,-1,162:12)
Block(-3,-6,0,162:12)
Block(-3,-6,1,162:12)
Block(-3,-6,2,162:12)
Block(-3,-6,3,162:12)
Block(-3,-6,4,162:12)
Block(-3,-6,7,162:12)
Block(-3,-5,-4,162:12)
Block(-3,-5,-3,162:12)
Block(-3,-5,-2,162:12)
Block(-3,-5,-1,162:12)
Block(-3,-5,0,162:12)
Block(-3,-5,1,162:12)
Block(-3,-5,2,162:12)
Block(-3,-5,3,162:12)
Block(-3,-5,4,162:12)
Block(-3,-4,-4,162:12)
Block(-3,-4,-3,162:12)
Block(-3,-4,-2,162:12)
Block(-3,-4,-1,162:12)
Block(-3,-4,0,162:12)
Block(-3,-4,1,162:12)
Block(-3,-4,2,162:12)
Block(-3,-4,3,162:12)
Block(-3,-4,4,162:12)
Block(-3,-3,-3,162:12)
Block(-3,-3,-2,162:12)
Block(-3,-3,-1,162:12)
Block(-3,-3,0,162:12)
Block(-3,-3,1,162:12)
Block(-3,-3,2,162:12)
Block(-3,-3,3,162:12)
Block(-3,-2,-1,162:12)
Block(-3,-2,0,162:12)
Block(-3,-2,1,162:12)
Block(-3,-2,2,162:12)
Block(-3,-2,3,162:12)
Block(-3,-1,-1,162:12)
Block(-3,-1,0,162:12)
Block(-3,-1,1,162:12)
Block(-3,-1,2,162:12)
Block(-3,0,-1,162:12)
Block(-3,0,0,162:12)
Block(-3,0,1,162:12)
Block(-3,0,2,162:12)
Block(-3,1,-1,162:12)
Block(-3,1,0,162:12)
Block(-3,1,1,162:12)
Block(-3,1,2,162:12)
Block(-3,2,-1,162:12)
Block(-3,2,0,162:12)
Block(-3,2,1,162:12)
Block(-3,3,0,162:12)
Block(-3,4,0,162:12)
Block(-3,11,4,162:12)
Block(-3,12,2,162:12)
Block(-3,12,3,162:12)
Block(-3,12,8,162:12)
Block(-3,13,-2,LEAVES_2:0)
Block(-3,13,-1,LEAVES_2:0)
Block(-3,13,0,LEAVES_2:0)
Block(-3,13,1,162:12)
Block(-3,13,2,LEAVES_2:0)
Block(-3,13,3,LEAVES_2:0)
Block(-3,13,4,162:12)
Block(-3,13,7,162:12)
Block(-3,13,9,LEAVES_2:0)
Block(-3,13,10,LEAVES_2:0)
Block(-3,14,1,LEAVES_2:0)
Block(-3,14,3,LEAVES_2:0)
Block(-3,14,4,LEAVES_2:0)
Block(-3,14,5,LEAVES_2:0)
Block(-3,14,6,LEAVES_2:0)
Block(-3,14,7,LEAVES_2:0)
Block(-3,14,8,LEAVES_2:0)
Block(-3,14,10,LEAVES_2:0)
Block(-3,14,11,LEAVES_2:0)
Block(-3,14,12,LEAVES_2:0)
Block(-3,15,-4,LEAVES_2:0)
Block(-3,15,4,LEAVES_2:0)
Block(-3,15,7,LEAVES_2:0)
Block(-3,16,-5,LEAVES_2:0)
Block(-3,16,-4,LEAVES_2:0)
Block(-3,16,-3,162:12)
Block(-3,16,2,162:12)
Block(-3,17,-8,LEAVES_2:0)
Block(-3,17,-7,LEAVES_2:0)
Block(-3,17,-6,LEAVES_2:0)
Block(-3,17,-4,LEAVES_2:0)
Block(-3,17,-3,LEAVES_2:0)
Block(-3,17,-2,162:12)
Block(-3,17,-1,LEAVES_2:0)
Block(-3,17,0,LEAVES_2:0)
Block(-3,17,5,LEAVES_2:0)
Block(-3,17,7,LEAVES_2:0)
Block(-3,18,-7,LEAVES_2:0)
Block(-3,18,-2,LEAVES_2:0)
Block(-3,18,-1,LEAVES_2:0)
Block(-3,18,2,LEAVES_2:0)
Block(-3,18,4,LEAVES_2:0)
Block(-3,19,0,LEAVES_2:0)
Block(-3,19,1,LEAVES_2:0)
Block(-3,19,4,LEAVES_2:0)
Block(-3,19,8,LEAVES_2:0)
Block(-3,20,-2,LEAVES_2:0)
Block(-3,20,7,LEAVES_2:0)
Block(-2,-6,-3,162:12)
Block(-2,-6,-2,162:12)
Block(-2,-6,-1,162:12)
Block(-2,-6,0,162:12)
Block(-2,-6,1,162:12)
Block(-2,-6,2,162:12)
Block(-2,-6,3,162:12)
Block(-2,-6,4,162:12)
Block(-2,-6,6,162:12)
Block(-2,-5,-3,162:12)
Block(-2,-5,-2,162:12)
Block(-2,-5,-1,162:12)
Block(-2,-5,0,162:12)
Block(-2,-5,1,162:12)
Block(-2,-5,2,162:12)
Block(-2,-5,3,162:12)
Block(-2,-5,4,162:12)
Block(-2,-5,6,162:12)
Block(-2,-4,-3,162:12)
Block(-2,-4,-2,162:12)
Block(-2,-4,-1,162:12)
Block(-2,-4,0,162:12)
Block(-2,-4,1,162:12)
Block(-2,-4,2,162:12)
Block(-2,-4,3,162:12)
Block(-2,-4,4,162:12)
Block(-2,-3,-3,162:12)
Block(-2,-3,-2,162:12)
Block(-2,-3,-1,162:12)
Block(-2,-3,0,162:12)
Block(-2,-3,1,162:12)
Block(-2,-3,2,162:12)
Block(-2,-3,3,162:12)
Block(-2,-3,4,162:12)
Block(-2,-2,-3,162:12)
Block(-2,-2,-2,162:12)
Block(-2,-2,-1,162:12)
Block(-2,-2,0,162:12)
Block(-2,-2,1,162:12)
Block(-2,-2,2,162:12)
Block(-2,-2,3,162:12)
Block(-2,-1,-2,162:12)
Block(-2,-1,-1,162:12)
Block(-2,-1,0,162:12)
Block(-2,-1,1,162:12)
Block(-2,-1,2,162:12)
Block(-2,-1,3,162:12)
Block(-2,0,-2,162:12)
Block(-2,0,-1,162:12)
Block(-2,0,0,162:12)
Block(-2,0,1,162:12)
Block(-2,0,2,162:12)
Block(-2,0,3,162:12)
Block(-2,1,-2,162:12)
Block(-2,1,-1,162:12)
Block(-2,1,0,162:12)
Block(-2,1,1,162:12)
Block(-2,1,2,162:12)
Block(-2,1,3,162:12)
Block(-2,2,-2,162:12)
Block(-2,2,-1,162:12)
Block(-2,2,0,162:12)
Block(-2,2,1,162:12)
Block(-2,2,2,162:12)
Block(-2,2,3,162:12)
Block(-2,3,-2,162:12)
Block(-2,3,-1,162:12)
Block(-2,3,0,162:12)
Block(-2,3,1,162:12)
Block(-2,3,2,162:12)
Block(-2,4,-2,162:12)
Block(-2,4,-1,162:12)
Block(-2,4,0,162:12)
Block(-2,4,1,162:12)
Block(-2,4,2,162:12)
Block(-2,5,-2,162:12)
Block(-2,5,-1,162:12)
Block(-2,5,0,162:12)
Block(-2,5,1,162:12)
Block(-2,5,2,162:12)
Block(-2,6,-2,162:12)
Block(-2,6,-1,162:12)
Block(-2,6,0,162:12)
Block(-2,6,1,162:12)
Block(-2,7,-2,162:12)
Block(-2,7,-1,162:12)
Block(-2,7,0,162:12)
Block(-2,7,1,162:12)
Block(-2,8,-1,162:12)
Block(-2,8,0,162:12)
Block(-2,9,-1,162:12)
Block(-2,9,0,162:12)
Block(-2,10,-1,162:12)
Block(-2,10,0,162:12)
Block(-2,10,5,162:12)
Block(-2,11,0,162:12)
Block(-2,11,7,162:12)
Block(-2,12,0,LEAVES_2:0)
Block(-2,12,1,LEAVES_2:0)
Block(-2,12,7,162:12)
Block(-2,13,1,LEAVES_2:0)
Block(-2,13,7,LEAVES_2:0)
Block(-2,13,9,LEAVES_2:0)
Block(-2,13,10,LEAVES_2:0)
Block(-2,13,11,LEAVES_2:0)
Block(-2,14,3,LEAVES_2:0)
Block(-2,14,4,162:12)
Block(-2,14,5,LEAVES_2:0)
Block(-2,14,7,LEAVES_2:0)
Block(-2,15,-4,162:12)
Block(-2,15,1,162:12)
Block(-2,15,4,LEAVES_2:0)
Block(-2,16,-7,LEAVES_2:0)
Block(-2,16,-5,LEAVES_2:0)
Block(-2,16,-4,LEAVES_2:0)
Block(-2,16,-3,LEAVES_2:0)
Block(-2,16,1,162:12)
Block(-2,16,2,162:12)
Block(-2,16,9,LEAVES_2:0)
Block(-2,17,-9,LEAVES_2:0)
Block(-2,17,-8,LEAVES_2:0)
Block(-2,17,-7,LEAVES_2:0)
Block(-2,17,-6,LEAVES_2:0)
Block(-2,17,-2,LEAVES_2:0)
Block(-2,17,-1,LEAVES_2:0)
Block(-2,17,2,162:12)
Block(-2,17,3,162:12)
Block(-2,17,6,LEAVES_2:0)
Block(-2,17,7,LEAVES_2:0)
Block(-2,17,8,LEAVES_2:0)
Block(-2,18,-7,LEAVES_2:0)
Block(-2,18,2,LEAVES_2:0)
Block(-2,18,4,162:12)
Block(-2,18,7,LEAVES_2:0)
Block(-2,19,-3,LEAVES_2:0)
Block(-2,19,-2,LEAVES_2:0)
Block(-2,19,-1,LEAVES_2:0)
Block(-2,19,3,LEAVES_2:0)
Block(-2,19,4,LEAVES_2:0)
Block(-2,19,5,LEAVES_2:0)
Block(-2,20,-2,LEAVES_2:0)
Block(-2,20,4,LEAVES_2:0)
Block(-2,20,6,LEAVES_2:0)
Block(-2,20,7,LEAVES_2:0)
Block(-2,20,8,LEAVES_2:0)
Block(-2,21,-7,LEAVES_2:0)
Block(-1,-6,-6,162:12)
Block(-1,-6,-5,162:12)
Block(-1,-6,-3,162:12)
Block(-1,-6,-2,162:12)
Block(-1,-6,-1,162:12)
Block(-1,-6,0,162:12)
Block(-1,-6,1,162:12)
Block(-1,-6,2,162:12)
Block(-1,-6,3,162:12)
Block(-1,-6,4,162:12)
Block(-1,-6,5,162:12)
Block(-1,-6,6,162:12)
Block(-1,-5,-6,162:12)
Block(-1,-5,-5,162:12)
Block(-1,-5,-3,162:12)
Block(-1,-5,-2,162:12)
Block(-1,-5,-1,162:12)
Block(-1,-5,0,162:12)
Block(-1,-5,1,162:12)
Block(-1,-5,2,162:12)
Block(-1,-5,3,162:12)
Block(-1,-5,4,162:12)
Block(-1,-5,5,162:12)
Block(-1,-5,6,162:12)
Block(-1,-4,-5,162:12)
Block(-1,-4,-3,162:12)
Block(-1,-4,-2,162:12)
Block(-1,-4,-1,162:12)
Block(-1,-4,0,162:12)
Block(-1,-4,1,162:12)
Block(-1,-4,2,162:12)
Block(-1,-4,3,162:12)
Block(-1,-4,4,162:12)
Block(-1,-4,5,162:12)
Block(-1,-4,6,162:12)
Block(-1,-3,-3,162:12)
Block(-1,-3,-2,162:12)
Block(-1,-3,-1,162:12)
Block(-1,-3,0,162:12)
Block(-1,-3,1,162:12)
Block(-1,-3,2,162:12)
Block(-1,-3,3,162:12)
Block(-1,-3,4,162:12)
Block(-1,-3,5,162:12)
Block(-1,-2,-3,162:12)
Block(-1,-2,-2,162:12)
Block(-1,-2,-1,162:12)
Block(-1,-2,0,162:12)
Block(-1,-2,1,162:12)
Block(-1,-2,2,162:12)
Block(-1,-2,3,162:12)
Block(-1,-2,4,162:12)
Block(-1,-2,5,162:12)
Block(-1,-1,-3,162:12)
Block(-1,-1,-2,162:12)
Block(-1,-1,-1,162:12)
Block(-1,-1,0,162:12)
Block(-1,-1,1,162:12)
Block(-1,-1,2,162:12)
Block(-1,-1,3,162:12)
Block(-1,-1,4,162:12)
Block(-1,-1,5,162:12)
Block(-1,0,-3,162:12)
Block(-1,0,-2,162:12)
Block(-1,0,-1,162:12)
Block(-1,0,0,162:12)
Block(-1,0,2,162:12)
Block(-1,0,3,162:12)
Block(-1,0,4,162:12)
Block(-1,1,-3,162:12)
Block(-1,1,-2,162:12)
Block(-1,1,-1,162:12)
Block(-1,1,0,162:12)
Block(-1,1,1,162:12)
Block(-1,1,2,162:12)
Block(-1,1,3,162:12)
Block(-1,1,4,162:12)
Block(-1,2,-3,162:12)
Block(-1,2,-2,162:12)
Block(-1,2,-1,162:12)
Block(-1,2,0,162:12)
Block(-1,2,1,162:12)
Block(-1,2,2,162:12)
Block(-1,2,3,162:12)
Block(-1,3,-3,162:12)
Block(-1,3,-2,162:12)
Block(-1,3,-1,162:12)
Block(-1,3,0,162:12)
Block(-1,3,1,162:12)
Block(-1,3,2,162:12)
Block(-1,3,3,162:12)
Block(-1,4,-3,162:12)
Block(-1,4,-2,162:12)
Block(-1,4,-1,162:12)
Block(-1,4,0,162:12)
Block(-1,4,1,162:12)
Block(-1,4,2,162:12)
Block(-1,4,3,162:12)
Block(-1,5,-3,162:12)
Block(-1,5,-2,162:12)
Block(-1,5,-1,162:12)
Block(-1,5,0,162:12)
Block(-1,5,1,162:12)
Block(-1,5,2,162:12)
Block(-1,5,3,162:12)
Block(-1,6,-3,162:12)
Block(-1,6,-2,162:12)
Block(-1,6,-1,162:12)
Block(-1,6,0,162:12)
Block(-1,6,1,162:12)
Block(-1,6,2,162:12)
Block(-1,6,3,162:12)
Block(-1,7,-2,162:12)
Block(-1,7,-1,162:12)
Block(-1,7,0,162:12)
Block(-1,7,1,162:12)
Block(-1,7,2,162:12)
Block(-1,7,3,162:12)
Block(-1,7,4,162:12)
Block(-1,8,-2,162:12)
Block(-1,8,-1,162:12)
Block(-1,8,0,162:12)
Block(-1,8,1,162:12)
Block(-1,8,3,162:12)
Block(-1,8,4,162:12)
Block(-1,9,-2,162:12)
Block(-1,9,-1,162:12)
Block(-1,9,0,162:12)
Block(-1,9,1,162:12)
Block(-1,9,4,162:12)
Block(-1,10,-2,162:12)
Block(-1,10,-1,162:12)
Block(-1,10,0,162:12)
Block(-1,10,1,162:12)
Block(-1,10,6,162:12)
Block(-1,11,-1,162:12)
Block(-1,11,0,162:12)
Block(-1,11,1,162:12)
Block(-1,11,6,162:12)
Block(-1,12,-1,162:12)
Block(-1,12,0,162:12)
Block(-1,12,1,162:12)
Block(-1,12,8,162:12)
Block(-1,13,0,162:12)
Block(-1,13,6,LEAVES_2:0)
Block(-1,13,8,LEAVES_2:0)
Block(-1,13,9,162:12)
Block(-1,13,10,LEAVES_2:0)
Block(-1,14,-4,162:12)
Block(-1,14,-3,LEAVES_2:0)
Block(-1,14,0,162:12)
Block(-1,14,1,162:12)
Block(-1,14,4,LEAVES_2:0)
Block(-1,14,5,162:12)
Block(-1,14,6,LEAVES_2:0)
Block(-1,14,7,LEAVES_2:0)
Block(-1,14,8,LEAVES_2:0)
Block(-1,14,9,LEAVES_2:0)
Block(-1,14,11,LEAVES_2:0)
Block(-1,15,-5,LEAVES_2:0)
Block(-1,15,-4,LEAVES_2:0)
Block(-1,15,-3,LEAVES_2:0)
Block(-1,15,1,162:12)
Block(-1,15,5,LEAVES_2:0)
Block(-1,15,6,LEAVES_2:0)
Block(-1,16,1,LEAVES_2:0)
Block(-1,16,5,LEAVES_2:0)
Block(-1,17,-8,LEAVES_2:0)
Block(-1,17,-7,162:12)
Block(-1,17,-6,LEAVES_2:0)
Block(-1,17,-5,LEAVES_2:0)
Block(-1,17,1,LEAVES_2:0)
Block(-1,17,2,LEAVES_2:0)
Block(-1,17,3,LEAVES_2:0)
Block(-1,17,6,LEAVES_2:0)
Block(-1,17,7,LEAVES_2:0)
Block(-1,17,8,LEAVES_2:0)
Block(-1,17,9,LEAVES_2:0)
Block(-1,18,-7,LEAVES_2:0)
Block(-1,18,1,LEAVES_2:0)
Block(-1,18,2,LEAVES_2:0)
Block(-1,18,4,LEAVES_2:0)
Block(-1,18,7,LEAVES_2:0)
Block(-1,18,8,LEAVES_2:0)
Block(-1,19,-3,LEAVES_2:0)
Block(-1,19,-2,162:12)
Block(-1,19,-1,LEAVES_2:0)
Block(-1,19,4,LEAVES_2:0)
Block(-1,19,5,162:12)
Block(-1,19,6,LEAVES_2:0)
Block(-1,19,7,LEAVES_2:0)
Block(-1,20,-7,LEAVES_2:0)
Block(-1,20,5,LEAVES_2:0)
Block(-1,20,6,162:12)
Block(-1,20,7,LEAVES_2:0)
Block(-1,20,8,LEAVES_2:0)
Block(-1,20,9,LEAVES_2:0)
Block(-1,21,-8,LEAVES_2:0)
Block(-1,21,-7,LEAVES_2:0)
Block(-1,21,-6,LEAVES_2:0)
Block(-1,21,6,LEAVES_2:0)
Block(-1,21,7,LEAVES_2:0)
Block(0,-6,-4,162:12)
Block(0,-6,-3,162:12)
Block(0,-6,-2,162:12)
Block(0,-6,-1,162:12)
Block(0,-6,0,162:12)
Block(0,-6,1,162:12)
Block(0,-6,2,162:12)
Block(0,-6,3,162:12)
Block(0,-6,4,162:12)
Block(0,-6,5,162:12)
Block(0,-6,7,162:12)
Block(0,-5,-4,162:12)
Block(0,-5,-3,162:12)
Block(0,-5,-2,162:12)
Block(0,-5,-1,162:12)
Block(0,-5,0,162:12)
Block(0,-5,1,162:12)
Block(0,-5,2,162:12)
Block(0,-5,3,162:12)
Block(0,-5,4,162:12)
Block(0,-5,5,162:12)
Block(0,-5,7,162:12)
Block(0,-4,-4,162:12)
Block(0,-4,-3,162:12)
Block(0,-4,-2,162:12)
Block(0,-4,-1,162:12)
Block(0,-4,0,162:12)
Block(0,-4,1,162:12)
Block(0,-4,2,162:12)
Block(0,-4,3,162:12)
Block(0,-4,4,162:12)
Block(0,-3,-4,162:12)
Block(0,-3,-3,162:12)
Block(0,-3,-2,162:12)
Block(0,-3,-1,162:12)
Block(0,-3,0,162:12)
Block(0,-3,1,162:12)
Block(0,-3,2,162:12)
Block(0,-3,3,162:12)
Block(0,-3,4,162:12)
Block(0,-2,-3,162:12)
Block(0,-2,-2,162:12)
Block(0,-2,-1,162:12)
Block(0,-2,0,162:12)
Block(0,-2,1,162:12)
Block(0,-2,2,162:12)
Block(0,-2,3,162:12)
Block(0,-2,4,162:12)
Block(0,-1,-3,162:12)
Block(0,-1,-2,162:12)
Block(0,-1,-1,162:12)
Block(0,-1,0,162:12)
Block(0,-1,1,162:12)
Block(0,-1,2,162:12)
Block(0,-1,3,162:12)
Block(0,-1,4,162:12)
Block(0,0,-3,162:12)
Block(0,0,-2,162:12)
Block(0,0,-1,162)
Block(0,0,0,162:12)
Block(0,0,2,162:12)
Block(0,0,3,162:12)
Block(0,0,4,162:12)
Block(0,1,-3,162:12)
Block(0,1,-2,162:12)
Block(0,1,-1,162:12)
Block(0,1,0,162:12)
Block(0,1,1,162:12)
Block(0,1,2,162:12)
Block(0,1,3,162:12)
Block(0,2,-3,162:12)
Block(0,2,-2,162:12)
Block(0,2,-1,162:12)
Block(0,2,0,162:12)
Block(0,2,1,162:12)
Block(0,2,2,162:12)
Block(0,2,3,162:12)
Block(0,3,-3,162:12)
Block(0,3,-2,162:12)
Block(0,3,-1,162:12)
Block(0,3,0,162:12)
Block(0,3,1,162:12)
Block(0,3,2,162:12)
Block(0,3,3,162:12)
Block(0,3,4,162:12)
Block(0,4,-3,162:12)
Block(0,4,-2,162:12)
Block(0,4,-1,162:12)
Block(0,4,0,162:12)
Block(0,4,1,162:12)
Block(0,4,2,162:12)
Block(0,4,3,162:12)
Block(0,4,4,162:12)
Block(0,5,-2,162:12)
Block(0,5,-1,162:12)
Block(0,5,0,162:12)
Block(0,5,1,162:12)
Block(0,5,2,162:12)
Block(0,5,3,162:12)
Block(0,5,4,162:12)
Block(0,6,-2,162:12)
Block(0,6,-1,162:12)
Block(0,6,0,162:12)
Block(0,6,1,162:12)
Block(0,6,2,162:12)
Block(0,6,3,162:12)
Block(0,6,4,162:12)
Block(0,6,5,162:12)
Block(0,7,-2,162:12)
Block(0,7,-1,162:12)
Block(0,7,0,162:12)
Block(0,7,1,162:12)
Block(0,7,2,162:12)
Block(0,7,3,162:12)
Block(0,7,4,162:12)
Block(0,7,5,162:12)
Block(0,8,-2,162:12)
Block(0,8,-1,162:12)
Block(0,8,0,162:12)
Block(0,8,1,162:12)
Block(0,8,2,162:12)
Block(0,8,3,162:12)
Block(0,8,4,162:12)
Block(0,8,5,162:12)
Block(0,9,-2,162:12)
Block(0,9,-1,162:12)
Block(0,9,0,162:12)
Block(0,9,1,162:12)
Block(0,9,2,162:12)
Block(0,9,3,162:12)
Block(0,9,4,162:12)
Block(0,9,5,162:12)
Block(0,10,-2,162:12)
Block(0,10,-1,162:12)
Block(0,10,0,162:12)
Block(0,10,1,162:12)
Block(0,10,2,162:12)
Block(0,10,4,162:12)
Block(0,10,5,162:12)
Block(0,11,-2,162:12)
Block(0,11,-1,162:12)
Block(0,11,0,162:12)
Block(0,11,1,162:12)
Block(0,11,2,162:12)
Block(0,11,5,162:12)
Block(0,12,-1,162:12)
Block(0,12,0,162:12)
Block(0,12,1,162:12)
Block(0,13,-1,162:12)
Block(0,13,0,162:12)
Block(0,13,1,162:12)
Block(0,13,10,162:12)
Block(0,13,11,LEAVES_2:0)
Block(0,14,-3,162:12)
Block(0,14,0,162:12)
Block(0,14,1,162:12)
Block(0,14,5,LEAVES_2:0)
Block(0,14,6,LEAVES_2:0)
Block(0,14,7,LEAVES_2:0)
Block(0,14,10,LEAVES_2:0)
Block(0,15,-4,LEAVES_2:0)
Block(0,15,4,LEAVES_2:0)
Block(0,15,5,LEAVES_2:0)
Block(0,15,6,LEAVES_2:0)
Block(0,16,-8,LEAVES_2:0)
Block(0,16,-7,162:12)
Block(0,16,-5,LEAVES_2:0)
Block(0,16,7,LEAVES_2:0)
Block(0,17,-7,LEAVES_2:0)
Block(0,17,-6,LEAVES_2:0)
Block(0,17,-5,LEAVES_2:0)
Block(0,17,-4,LEAVES_2:0)
Block(0,17,2,LEAVES_2:0)
Block(0,17,7,162:12)
Block(0,17,8,LEAVES_2:0)
Block(0,18,-11,LEAVES_2:0)
Block(0,18,-10,LEAVES_2:0)
Block(0,18,-5,LEAVES_2:0)
Block(0,18,-3,LEAVES_2:0)
Block(0,18,-2,162:12)
Block(0,18,-1,LEAVES_2:0)
Block(0,18,0,LEAVES_2:0)
Block(0,18,1,LEAVES_2:0)
Block(0,18,2,LEAVES_2:0)
Block(0,18,7,LEAVES_2:0)
Block(0,19,-2,LEAVES_2:0)
Block(0,19,1,LEAVES_2:0)
Block(0,19,4,LEAVES_2:0)
Block(0,19,5,LEAVES_2:0)
Block(0,20,-5,LEAVES_2:0)
Block(0,20,6,LEAVES_2:0)
Block(0,20,7,LEAVES_2:0)
Block(0,20,8,LEAVES_2:0)
Block(0,21,-9,LEAVES_2:0)
Block(0,21,-8,LEAVES_2:0)
Block(0,21,-7,LEAVES_2:0)
Block(0,21,-6,LEAVES_2:0)
Block(0,22,-8,LEAVES_2:0)
Block(0,22,-7,LEAVES_2:0)
Block(1,-6,-3,162:12)
Block(1,-6,-2,162:12)
Block(1,-6,-1,162:12)
Block(1,-6,0,162:12)
Block(1,-6,1,162:12)
Block(1,-6,2,162:12)
Block(1,-6,3,162:12)
Block(1,-6,4,162:12)
Block(1,-5,-3,162:12)
Block(1,-5,-2,162:12)
Block(1,-5,-1,162:12)
Block(1,-5,0,162:12)
Block(1,-5,1,162:12)
Block(1,-5,2,162:12)
Block(1,-5,3,162:12)
Block(1,-5,4,162:12)
Block(1,-4,-3,162:12)
Block(1,-4,-2,162:12)
Block(1,-4,-1,162:12)
Block(1,-4,0,162:12)
Block(1,-4,1,162:12)
Block(1,-4,2,162:12)
Block(1,-4,3,162:12)
Block(1,-4,4,162:12)
Block(1,-3,-3,162:12)
Block(1,-3,-2,162:12)
Block(1,-3,-1,162:12)
Block(1,-3,0,162:12)
Block(1,-3,1,162:12)
Block(1,-3,2,162:12)
Block(1,-3,3,162:12)
Block(1,-3,4,162:12)
Block(1,-2,-3,162:12)
Block(1,-2,-2,162:12)
Block(1,-2,-1,162:12)
Block(1,-2,0,162:12)
Block(1,-2,1,162:12)
Block(1,-2,2,162:12)
Block(1,-2,3,162:12)
Block(1,-2,4,162:12)
Block(1,-1,-2,162:12)
Block(1,-1,-1,162:12)
Block(1,-1,0,162:12)
Block(1,-1,1,162:12)
Block(1,-1,2,162:12)
Block(1,-1,3,162:12)
Block(1,0,-2,162:12)
Block(1,0,-1,162)
Block(1,0,0,162:12)
Block(1,0,1,162:12)
Block(1,0,2,162:12)
Block(1,0,3,162:12)
Block(1,1,-2,162:12)
Block(1,1,-1,162:12)
Block(1,1,0,162:12)
Block(1,1,1,162:12)
Block(1,1,2,162:12)
Block(1,1,3,162:12)
Block(1,2,-2,162:12)
Block(1,2,-1,162:12)
Block(1,2,0,162:12)
Block(1,2,1,162:12)
Block(1,2,2,162:12)
Block(1,2,3,162:12)
Block(1,3,-2,162:12)
Block(1,3,-1,162:12)
Block(1,3,0,162:12)
Block(1,3,1,162:12)
Block(1,3,2,162:12)
Block(1,3,3,162:12)
Block(1,4,-2,162:12)
Block(1,4,-1,162:12)
Block(1,4,0,162:12)
Block(1,4,1,162:12)
Block(1,4,2,162:12)
Block(1,4,3,162:12)
Block(1,5,-2,162:12)
Block(1,5,-1,162:12)
Block(1,5,0,162:12)
Block(1,5,1,162:12)
Block(1,5,2,162:12)
Block(1,5,3,162:12)
Block(1,5,4,162:12)
Block(1,6,-2,162:12)
Block(1,6,-1,162:12)
Block(1,6,0,162:12)
Block(1,6,1,162:12)
Block(1,6,2,162:12)
Block(1,6,3,162:12)
Block(1,6,4,162:12)
Block(1,7,-2,162:12)
Block(1,7,-1,162:12)
Block(1,7,0,162:12)
Block(1,7,1,162:12)
Block(1,7,2,162:12)
Block(1,7,3,162:12)
Block(1,7,4,162:12)
Block(1,7,5,162:12)
Block(1,8,-1,162:12)
Block(1,8,0,162:12)
Block(1,8,2,162:12)
Block(1,8,3,162:12)
Block(1,8,4,162:12)
Block(1,8,5,162:12)
Block(1,9,-2,162:12)
Block(1,9,-1,162:12)
Block(1,9,0,162:12)
Block(1,9,3,162:12)
Block(1,9,4,162:12)
Block(1,9,5,162:12)
Block(1,9,6,162:12)
Block(1,10,-2,162:12)
Block(1,10,-1,162:12)
Block(1,10,0,162:12)
Block(1,10,3,162:12)
Block(1,10,4,162:12)
Block(1,10,5,162:12)
Block(1,10,6,162:12)
Block(1,11,-3,162:12)
Block(1,11,-2,162:12)
Block(1,11,-1,162:12)
Block(1,11,0,162:12)
Block(1,11,4,162:12)
Block(1,11,5,162:12)
Block(1,11,6,162:12)
Block(1,12,-3,162:12)
Block(1,12,-2,162:12)
Block(1,12,0,162:12)
Block(1,12,5,162:12)
Block(1,13,-3,162:12)
Block(1,13,-2,162:12)
Block(1,13,7,LEAVES_2:0)
Block(1,13,11,LEAVES_2:0)
Block(1,14,4,LEAVES_2:0)
Block(1,14,6,LEAVES_2:0)
Block(1,14,9,LEAVES_2:0)
Block(1,14,10,162:12)
Block(1,14,11,LEAVES_2:0)
Block(1,14,12,LEAVES_2:0)
Block(1,15,-5,162:12)
Block(1,15,3,LEAVES_2:0)
Block(1,15,4,LEAVES_2:0)
Block(1,15,5,LEAVES_2:0)
Block(1,15,10,LEAVES_2:0)
Block(1,15,11,LEAVES_2:0)
Block(1,16,-6,162:12)
Block(1,16,-5,LEAVES_2:0)
Block(1,16,4,LEAVES_2:0)
Block(1,16,6,LEAVES_2:0)
Block(1,16,7,162:12)
Block(1,16,8,LEAVES_2:0)
Block(1,16,12,LEAVES_2:0)
Block(1,17,-11,LEAVES_2:0)
Block(1,17,-9,LEAVES_2:0)
Block(1,17,-8,LEAVES_2:0)
Block(1,17,-6,LEAVES_2:0)
Block(1,17,-5,LEAVES_2:0)
Block(1,17,-4,LEAVES_2:0)
Block(1,17,6,LEAVES_2:0)
Block(1,17,7,LEAVES_2:0)
Block(1,18,-12,LEAVES_2:0)
Block(1,18,-11,LEAVES_2:0)
Block(1,18,-10,LEAVES_2:0)
Block(1,18,-8,LEAVES_2:0)
Block(1,18,-5,LEAVES_2:0)
Block(1,18,-3,162:12)
Block(1,18,0,LEAVES_2:0)
Block(1,18,1,LEAVES_2:0)
Block(1,18,2,LEAVES_2:0)
Block(1,18,3,LEAVES_2:0)
Block(1,19,-10,LEAVES_2:0)
Block(1,19,-4,LEAVES_2:0)
Block(1,19,-3,LEAVES_2:0)
Block(1,19,-2,LEAVES_2:0)
Block(1,19,1,LEAVES_2:0)
Block(1,19,2,LEAVES_2:0)
Block(1,19,5,LEAVES_2:0)
Block(1,20,-7,LEAVES_2:0)
Block(1,20,-3,LEAVES_2:0)
Block(1,20,1,LEAVES_2:0)
Block(1,21,-8,LEAVES_2:0)
Block(1,21,-7,162:12)
Block(1,21,-6,LEAVES_2:0)
Block(2,-6,-5,162:12)
Block(2,-6,-4,162:12)
Block(2,-6,-2,162:12)
Block(2,-6,-1,162:12)
Block(2,-6,0,162:12)
Block(2,-6,1,162:12)
Block(2,-6,2,162:12)
Block(2,-6,3,162:12)
Block(2,-6,4,162:12)
Block(2,-6,5,162:12)
Block(2,-5,-5,162:12)
Block(2,-5,-4,162:12)
Block(2,-5,-2,162:12)
Block(2,-5,-1,162:12)
Block(2,-5,0,162:12)
Block(2,-5,1,162:12)
Block(2,-5,2,162:12)
Block(2,-5,3,162:12)
Block(2,-5,4,162:12)
Block(2,-5,5,162:12)
Block(2,-4,-4,162:12)
Block(2,-4,-2,162:12)
Block(2,-4,-1,162:12)
Block(2,-4,0,162:12)
Block(2,-4,1,162:12)
Block(2,-4,2,162:12)
Block(2,-4,3,162:12)
Block(2,-4,4,162:12)
Block(2,-4,5,162:12)
Block(2,-3,-1,162:12)
Block(2,-3,0,162:12)
Block(2,-3,1,162:12)
Block(2,-3,2,162:12)
Block(2,-3,4,162:12)
Block(2,-2,-1,162:12)
Block(2,-2,0,162:12)
Block(2,-2,1,162:12)
Block(2,-2,2,162:12)
Block(2,-1,-1,162:12)
Block(2,-1,0,162:12)
Block(2,-1,1,162:12)
Block(2,-1,2,162:12)
Block(2,0,-1,162)
Block(2,0,0,162:12)
Block(2,0,1,162:12)
Block(2,0,2,162:12)
Block(2,1,-1,162:12)
Block(2,1,0,162:12)
Block(2,1,1,162:12)
Block(2,1,2,162:12)
Block(2,2,-1,162:12)
Block(2,2,0,162:12)
Block(2,2,1,162:12)
Block(2,2,2,162:12)
Block(2,3,-1,162:12)
Block(2,3,0,162:12)
Block(2,3,1,162:12)
Block(2,3,2,162:12)
Block(2,4,-1,162:12)
Block(2,4,0,162:12)
Block(2,4,1,162:12)
Block(2,4,2,162:12)
Block(2,5,0,162:12)
Block(2,5,1,162:12)
Block(2,6,0,162:12)
Block(2,6,3,162:12)
Block(2,7,3,162:12)
Block(2,8,3,162:12)
Block(2,8,4,162:12)
Block(2,9,3,162:12)
Block(2,9,4,162:12)
Block(2,10,-2,162:12)
Block(2,10,4,162:12)
Block(2,10,5,162:12)
Block(2,11,-2,162:12)
Block(2,11,4,162:12)
Block(2,11,5,162:12)
Block(2,11,6,162:12)
Block(2,12,-3,162:12)
Block(2,12,-2,162:12)
Block(2,12,4,162:12)
Block(2,12,5,162:12)
Block(2,12,6,162:12)
Block(2,13,-4,162:12)
Block(2,13,-3,162:12)
Block(2,13,5,162:12)
Block(2,14,-4,162:12)
Block(2,14,-3,162:12)
Block(2,14,10,LEAVES_2:0)
Block(2,14,11,LEAVES_2:0)
Block(2,15,-4,162:12)
Block(2,15,1,LEAVES_2:0)
Block(2,15,3,LEAVES_2:0)
Block(2,15,4,LEAVES_2:0)
Block(2,15,5,162:12)
Block(2,15,9,LEAVES_2:0)
Block(2,15,11,LEAVES_2:0)
Block(2,16,-4,LEAVES_2:0)
Block(2,16,4,LEAVES_2:0)
Block(2,16,5,LEAVES_2:0)
Block(2,16,6,162:12)
Block(2,16,7,LEAVES_2:0)
Block(2,16,11,LEAVES_2:0)
Block(2,16,12,LEAVES_2:0)
Block(2,16,13,LEAVES_2:0)
Block(2,16,14,LEAVES_2:0)
Block(2,17,-9,162:12)
Block(2,17,-8,162:12)
Block(2,17,-5,LEAVES_2:0)
Block(2,17,-3,162:12)
Block(2,17,-1,LEAVES_2:0)
Block(2,17,4,LEAVES_2:0)
Block(2,17,12,LEAVES_2:0)
Block(2,18,-11,LEAVES_2:0)
Block(2,18,-10,162:12)
Block(2,18,-9,LEAVES_2:0)
Block(2,18,-8,LEAVES_2:0)
Block(2,18,-3,LEAVES_2:0)
Block(2,18,0,LEAVES_2:0)
Block(2,18,1,162:12)
Block(2,18,2,LEAVES_2:0)
Block(2,19,-10,LEAVES_2:0)
Block(2,19,-8,LEAVES_2:0)
Block(2,19,-6,LEAVES_2:0)
Block(2,19,-3,LEAVES_2:0)
Block(2,19,1,LEAVES_2:0)
Block(2,20,-12,LEAVES_2:0)
Block(2,20,-8,LEAVES_2:0)
Block(2,20,-7,162:12)
Block(2,20,-6,LEAVES_2:0)
Block(2,20,-5,LEAVES_2:0)
Block(2,21,-7,LEAVES_2:0)
Block(3,-6,-2,162:12)
Block(3,-6,-1,162:12)
Block(3,-6,0,162:12)
Block(3,-6,1,162:12)
Block(3,-6,2,162:12)
Block(3,-6,3,162:12)
Block(3,-6,6,162:12)
Block(3,-5,-2,162:12)
Block(3,-5,-1,162:12)
Block(3,-5,0,162:12)
Block(3,-5,1,162:12)
Block(3,-5,2,162:12)
Block(3,-5,3,162:12)
Block(3,-5,6,162:12)
Block(3,-4,-2,162:12)
Block(3,-4,-1,162:12)
Block(3,-4,0,162:12)
Block(3,-4,1,162:12)
Block(3,-4,2,162:12)
Block(3,-3,-2,162:12)
Block(3,-3,-1,162:12)
Block(3,-3,0,162:12)
Block(3,-3,1,162:12)
Block(3,-3,2,162:12)
Block(3,-2,-1,162:12)
Block(3,-2,0,162:12)
Block(3,-2,1,162:12)
Block(3,-2,2,162:12)
Block(3,-1,0,162:12)
Block(3,-1,1,162:12)
Block(3,0,0,162:12)
Block(3,0,1,162:12)
Block(3,1,0,162:12)
Block(3,2,0,162:12)
Block(3,11,5,162:12)
Block(3,12,5,162:12)
Block(3,12,6,162:12)
Block(3,12,7,162:12)
Block(3,13,4,162:12)
Block(3,13,7,162:12)
Block(3,14,-4,162:12)
Block(3,14,3,LEAVES_2:0)
Block(3,14,4,162:12)
Block(3,14,10,LEAVES_2:0)
Block(3,15,-5,162:12)
Block(3,15,-4,162:12)
Block(3,15,-3,162:12)
Block(3,15,1,LEAVES_2:0)
Block(3,15,2,LEAVES_2:0)
Block(3,15,3,LEAVES_2:0)
Block(3,15,4,LEAVES_2:0)
Block(3,15,5,LEAVES_2:0)
Block(3,15,8,LEAVES_2:0)
Block(3,15,9,LEAVES_2:0)
Block(3,15,10,LEAVES_2:0)
Block(3,15,11,162:12)
Block(3,15,13,LEAVES_2:0)
Block(3,16,-7,162:12)
Block(3,16,-6,162:12)
Block(3,16,-4,162:12)
Block(3,16,4,LEAVES_2:0)
Block(3,16,6,LEAVES_2:0)
Block(3,16,9,LEAVES_2:0)
Block(3,16,12,162:12)
Block(3,16,13,LEAVES_2:0)
Block(3,16,14,LEAVES_2:0)
Block(3,16,15,LEAVES_2:0)
Block(3,17,-7,LEAVES_2:0)
Block(3,17,-4,LEAVES_2:0)
Block(3,17,-2,162:12)
Block(3,17,-1,162:12)
Block(3,17,12,LEAVES_2:0)
Block(3,17,13,LEAVES_2:0)
Block(3,18,-2,LEAVES_2:0)
Block(3,18,0,162:12)
Block(3,18,1,LEAVES_2:0)
Block(3,18,2,LEAVES_2:0)
Block(3,19,-10,LEAVES_2:0)
Block(3,19,-9,LEAVES_2:0)
Block(3,19,0,LEAVES_2:0)
Block(3,19,1,LEAVES_2:0)
Block(3,20,-13,LEAVES_2:0)
Block(3,20,-12,LEAVES_2:0)
Block(3,20,-11,LEAVES_2:0)
Block(3,20,-10,LEAVES_2:0)
Block(3,20,-7,LEAVES_2:0)
Block(3,20,-6,162:12)
Block(3,20,-5,LEAVES_2:0)
Block(3,21,-12,LEAVES_2:0)
Block(3,21,-6,LEAVES_2:0)
Block(4,-6,-3,162:12)
Block(4,-6,-2,162:12)
Block(4,-6,0,162:12)
Block(4,-6,1,162:12)
Block(4,-6,3,162:12)
Block(4,-6,4,162:12)
Block(4,-5,-3,162:12)
Block(4,-5,-2,162:12)
Block(4,-5,0,162:12)
Block(4,-5,1,162:12)
Block(4,-5,3,162:12)
Block(4,-5,4,162:12)
Block(4,-4,-2,162:12)
Block(4,-4,0,162:12)
Block(4,-4,1,162:12)
Block(4,-4,3,162:12)
Block(4,-3,0,162:12)
Block(4,-3,1,162:12)
Block(4,-2,0,162:12)
Block(4,-1,0,162:12)
Block(4,13,7,162:12)
Block(4,13,8,162:12)
Block(4,14,3,162:12)
Block(4,14,7,LEAVES_2:0)
Block(4,14,8,162:12)
Block(4,14,9,162:12)
Block(4,15,-4,162:12)
Block(4,15,0,LEAVES_2:0)
Block(4,15,1,LEAVES_2:0)
Block(4,15,2,LEAVES_2:0)
Block(4,15,3,LEAVES_2:0)
Block(4,15,4,LEAVES_2:0)
Block(4,15,8,LEAVES_2:0)
Block(4,15,9,LEAVES_2:0)
Block(4,15,10,162:12)
Block(4,15,11,LEAVES_2:0)
Block(4,15,15,LEAVES_2:0)
Block(4,16,-5,162:12)
Block(4,16,-4,162:12)
Block(4,16,1,LEAVES_2:0)
Block(4,16,2,LEAVES_2:0)
Block(4,16,8,LEAVES_2:0)
Block(4,16,9,LEAVES_2:0)
Block(4,16,10,LEAVES_2:0)
Block(4,16,12,LEAVES_2:0)
Block(4,16,13,LEAVES_2:0)
Block(4,16,14,LEAVES_2:0)
Block(4,17,-5,162:12)
Block(4,17,-4,LEAVES_2:0)
Block(4,17,-1,LEAVES_2:0)
Block(4,17,9,LEAVES_2:0)
Block(4,17,13,LEAVES_2:0)
Block(4,18,-7,LEAVES_2:0)
Block(4,18,0,LEAVES_2:0)
Block(4,18,1,LEAVES_2:0)
Block(4,19,-11,LEAVES_2:0)
Block(4,19,-10,162:12)
Block(4,19,-9,LEAVES_2:0)
Block(4,19,-6,162:12)
Block(4,19,-5,LEAVES_2:0)
Block(4,20,-14,LEAVES_2:0)
Block(4,20,-13,LEAVES_2:0)
Block(4,20,-12,LEAVES_2:0)
Block(4,20,-11,162:12)
Block(4,20,-10,LEAVES_2:0)
Block(4,20,-6,LEAVES_2:0)
Block(4,21,-13,LEAVES_2:0)
Block(4,21,-12,LEAVES_2:0)
Block(4,21,-11,LEAVES_2:0)
Block(5,-6,1,162:12)
Block(5,-5,1,162:12)
Block(5,-4,1,162:12)
Block(5,-3,1,162:12)
Block(5,-2,1,162:12)
Block(5,14,7,162:12)
Block(5,15,-3,162:12)
Block(5,15,1,162:12)
Block(5,15,2,162:12)
Block(5,15,5,LEAVES_2:0)
Block(5,15,6,162:12)
Block(5,15,8,LEAVES_2:0)
Block(5,15,10,LEAVES_2:0)
Block(5,16,-5,162:12)
Block(5,16,0,162:12)
Block(5,16,1,LEAVES_2:0)
Block(5,16,2,LEAVES_2:0)
Block(5,16,3,LEAVES_2:0)
Block(5,16,6,LEAVES_2:0)
Block(5,16,9,LEAVES_2:0)
Block(5,16,13,LEAVES_2:0)
Block(5,17,-6,162:12)
Block(5,17,-5,162:12)
Block(5,17,-4,LEAVES_2:0)
Block(5,17,0,LEAVES_2:0)
Block(5,17,2,LEAVES_2:0)
Block(5,17,5,LEAVES_2:0)
Block(5,18,-8,162:12)
Block(5,18,-7,162:12)
Block(5,18,-6,162:12)
Block(5,18,-5,LEAVES_2:0)
Block(5,19,-11,LEAVES_2:0)
Block(5,19,-10,LEAVES_2:0)
Block(5,19,-9,162:12)
Block(5,19,-8,LEAVES_2:0)
Block(5,19,-7,LEAVES_2:0)
Block(5,19,-6,LEAVES_2:0)
Block(5,19,-5,162:12)
Block(5,19,-4,LEAVES_2:0)
Block(5,20,-13,LEAVES_2:0)
Block(5,20,-11,LEAVES_2:0)
Block(5,20,-10,LEAVES_2:0)
Block(5,20,-9,LEAVES_2:0)
Block(5,20,-6,LEAVES_2:0)
Block(5,20,-5,LEAVES_2:0)
Block(5,20,-4,162:12)
Block(5,20,-3,LEAVES_2:0)
Block(5,21,-6,LEAVES_2:0)
Block(5,21,-4,LEAVES_2:0)
Block(6,-6,2,162:12)
Block(6,-6,3,162:12)
Block(6,-5,2,162:12)
Block(6,-5,3,162:12)
Block(6,-4,2,162:12)
Block(6,14,7,162:12)
Block(6,15,2,LEAVES_2:0)
Block(6,15,3,LEAVES_2:0)
Block(6,15,6,LEAVES_2:0)
Block(6,15,7,LEAVES_2:0)
Block(6,15,8,LEAVES_2:0)
Block(6,15,9,LEAVES_2:0)
Block(6,16,-3,162:12)
Block(6,16,-2,LEAVES_2:0)
Block(6,16,0,LEAVES_2:0)
Block(6,16,2,LEAVES_2:0)
Block(6,16,4,LEAVES_2:0)
Block(6,16,5,162:12)
Block(6,16,8,LEAVES_2:0)
Block(6,16,10,LEAVES_2:0)
Block(6,17,-5,LEAVES_2:0)
Block(6,17,-4,LEAVES_2:0)
Block(6,17,-3,LEAVES_2:0)
Block(6,17,-1,LEAVES_2:0)
Block(6,17,0,162:12)
Block(6,17,1,LEAVES_2:0)
Block(6,17,5,LEAVES_2:0)
Block(6,17,6,LEAVES_2:0)
Block(6,18,-7,162:12)
Block(6,18,0,LEAVES_2:0)
Block(6,18,5,LEAVES_2:0)
Block(6,19,-11,LEAVES_2:0)
Block(6,19,-10,LEAVES_2:0)
Block(6,19,-9,LEAVES_2:0)
Block(6,19,-7,LEAVES_2:0)
Block(6,19,-6,LEAVES_2:0)
Block(6,20,-6,LEAVES_2:0)
Block(6,20,-5,LEAVES_2:0)
Block(6,20,-4,LEAVES_2:0)
Block(6,20,-3,162:12)
Block(6,21,-4,LEAVES_2:0)
Block(6,21,-3,LEAVES_2:0)
Block(6,21,-2,LEAVES_2:0)
Block(6,21,-1,LEAVES_2:0)
Block(6,22,-3,LEAVES_2:0)
Block(7,15,7,LEAVES_2:0)
Block(7,15,8,162:12)
Block(7,15,9,LEAVES_2:0)
Block(7,16,-3,162:12)
Block(7,16,-2,LEAVES_2:0)
Block(7,16,3,LEAVES_2:0)
Block(7,16,4,162:12)
Block(7,16,5,LEAVES_2:0)
Block(7,16,8,LEAVES_2:0)
Block(7,17,-6,LEAVES_2:0)
Block(7,17,-5,LEAVES_2:0)
Block(7,17,-4,LEAVES_2:0)
Block(7,17,-3,LEAVES_2:0)
Block(7,17,-2,LEAVES_2:0)
Block(7,17,-1,LEAVES_2:0)
Block(7,17,0,LEAVES_2:0)
Block(7,17,1,LEAVES_2:0)
Block(7,17,2,LEAVES_2:0)
Block(7,17,4,LEAVES_2:0)
Block(7,17,9,LEAVES_2:0)
Block(7,17,10,LEAVES_2:0)
Block(7,17,11,LEAVES_2:0)
Block(7,18,-8,LEAVES_2:0)
Block(7,18,-7,162:12)
Block(7,18,-5,LEAVES_2:0)
Block(7,18,-4,LEAVES_2:0)
Block(7,18,-3,LEAVES_2:0)
Block(7,18,0,LEAVES_2:0)
Block(7,18,1,LEAVES_2:0)
Block(7,19,-10,LEAVES_2:0)
Block(7,19,-8,LEAVES_2:0)
Block(7,19,-7,LEAVES_2:0)
Block(7,19,-4,LEAVES_2:0)
Block(7,20,-7,LEAVES_2:0)
Block(7,20,-6,LEAVES_2:0)
Block(7,21,-3,LEAVES_2:0)
Block(7,21,-2,162:12)
Block(7,21,-1,LEAVES_2:0)
Block(7,21,0,LEAVES_2:0)
Block(7,22,-2,LEAVES_2:0)
Block(7,22,-1,LEAVES_2:0)
Block(8,15,6,LEAVES_2:0)
Block(8,16,-3,LEAVES_2:0)
Block(8,16,2,LEAVES_2:0)
Block(8,16,3,LEAVES_2:0)
Block(8,16,4,LEAVES_2:0)
Block(8,16,5,LEAVES_2:0)
Block(8,16,7,LEAVES_2:0)
Block(8,16,8,162:12)
Block(8,16,10,LEAVES_2:0)
Block(8,17,-5,LEAVES_2:0)
Block(8,17,-4,162:12)
Block(8,17,-3,LEAVES_2:0)
Block(8,17,-1,LEAVES_2:0)
Block(8,17,0,LEAVES_2:0)
Block(8,17,1,LEAVES_2:0)
Block(8,17,3,LEAVES_2:0)
Block(8,17,4,LEAVES_2:0)
Block(8,17,8,LEAVES_2:0)
Block(8,17,9,162:12)
Block(8,17,10,LEAVES_2:0)
Block(8,17,11,LEAVES_2:0)
Block(8,17,12,LEAVES_2:0)
Block(8,18,-7,LEAVES_2:0)
Block(8,18,-4,LEAVES_2:0)
Block(8,18,0,LEAVES_2:0)
Block(8,18,9,LEAVES_2:0)
Block(8,18,11,LEAVES_2:0)
Block(8,19,-11,LEAVES_2:0)
Block(8,19,-10,LEAVES_2:0)
Block(8,19,-9,LEAVES_2:0)
Block(8,19,-8,162:12)
Block(8,20,-9,LEAVES_2:0)
Block(8,20,-8,LEAVES_2:0)
Block(8,21,-3,LEAVES_2:0)
Block(8,21,-2,LEAVES_2:0)
Block(8,21,-1,LEAVES_2:0)
Block(9,15,4,LEAVES_2:0)
Block(9,16,3,LEAVES_2:0)
Block(9,16,4,LEAVES_2:0)
Block(9,16,5,LEAVES_2:0)
Block(9,16,8,LEAVES_2:0)
Block(9,17,-4,LEAVES_2:0)
Block(9,17,0,LEAVES_2:0)
Block(9,17,4,LEAVES_2:0)
Block(9,17,9,LEAVES_2:0)
Block(9,17,10,LEAVES_2:0)
Block(9,17,11,LEAVES_2:0)
Block(9,18,-5,LEAVES_2:0)
Block(9,18,-4,162:12)
Block(9,18,-3,LEAVES_2:0)
Block(9,18,10,LEAVES_2:0)
Block(9,19,-12,LEAVES_2:0)
Block(9,19,-11,LEAVES_2:0)
Block(9,19,-10,LEAVES_2:0)
Block(9,19,-9,162:12)
Block(9,19,-8,LEAVES_2:0)
Block(9,19,-4,LEAVES_2:0)
Block(9,20,-11,LEAVES_2:0)
Block(9,20,-10,LEAVES_2:0)
Block(9,20,-9,LEAVES_2:0)
Block(9,21,-9,LEAVES_2:0)
Block(9,21,-3,LEAVES_2:0)
Block(9,21,-2,LEAVES_2:0)
Block(9,21,-1,LEAVES_2:0)
Block(9,22,-2,LEAVES_2:0)
Block(10,16,4,LEAVES_2:0)
Block(10,16,11,LEAVES_2:0)
Block(10,17,-2,LEAVES_2:0)
Block(10,17,10,LEAVES_2:0)
Block(10,18,-6,LEAVES_2:0)
Block(10,18,-5,LEAVES_2:0)
Block(10,18,-4,LEAVES_2:0)
Block(10,18,-3,LEAVES_2:0)
Block(10,19,-11,LEAVES_2:0)
Block(10,19,-10,LEAVES_2:0)
Block(10,19,-9,LEAVES_2:0)
Block(10,19,-5,LEAVES_2:0)
Block(10,19,-4,LEAVES_2:0)
Block(10,20,-10,LEAVES_2:0)
Block(10,21,-2,LEAVES_2:0)
Block(11,17,-3,LEAVES_2:0)
Block(11,18,-5,LEAVES_2:0)
Block(11,18,-4,LEAVES_2:0)
Block(11,19,-10,LEAVES_2:0)


#######################################################################
# +-----------------------------------------------------------------+ #
# |                             Entities                            | #
# +-----------------------------------------------------------------+ #
#######################################################################

# Entity() spawns an entity instead of a block. The entity is spawned only once when the BO3 is spawned.
# Entities are persistent by default so they don't de-spawn when no player is near, they are only unloaded.
# Usage: Entity(x,y,z,mobName,groupSize,NameTagOrNBTFileName) or Entity(x,y,z,mobName,groupSize)
# Use /tc entities or /otg entities to get a list of entities that can be used as mobName, this includes entities added by other mods.
# NameTagOrNBTFileName can be either a nametag for the mob or an nbt file (such as mymobinfo.nbt or mymobinfo.txt).
# When using a text file you can use the same mob spawning parameters used with the /summon command to equip the
# entity and give it custom attributes etc. You can copy the DATA part of a summon command including surrounding
# curly braces to a .txt file, for instance for: "/summon Skeleton x y z {DATA}"

#######################################################################
# +-----------------------------------------------------------------+ #
# |                            BO3 checks                           | #
# +-----------------------------------------------------------------+ #
#######################################################################

# Require a condition at a certain location in order for the BO3 to be spawned.
# BlockCheck(x,y,z,BlockName[,BlockName[,...]]) - one of the blocks must be at the location
# BlockCheckNot(x,y,z,BlockName[,BlockName[,...]]) - all the blocks must not be at the location
# LightCheck(x,y,z,minLightLevel,maxLightLevel) - light must be between min and max (inclusive)

# You can use "Solid" as a BlockName for matching all solid blocks or "All" to match all blocks that aren't air.

# Examples:
#   BlockCheck(0,-1,0,GRASS,DIRT)  Require grass or dirt just below the object
#   BlockCheck(0,-1,0,Solid)       Require any solid block just below the object
#   BlockCheck(0,-1,0,WOOL)        Require any type of wool just below the object
#   BlockCheck(0,-1,0,WOOL:0)      Require white wool just below the object
#   BlockCheckNot(0,-1,0,WOOL:0)   Require that there is no white wool below the object
#   LightCheck(0,0,0,0,LEAVES_2:0)          Require almost complete darkness just below the object

BlockCheck(-1,-1,2,GRASS,DIRT,DIRT:2,SAND)