#######################################################################
# +-----------------------------------------------------------------+ #
# |                            BO3 object                           | #
# +-----------------------------------------------------------------+ #
#######################################################################

# The descriptions in this file are accurate only for TerrainControl and OTG.
# For MCW and OTG+ these descriptions are only accurate if the BO3 is used as a CustomObject.
# MCW and OTG+ completely reimplemented CustomStructure, check the MCW/OTG+ documentation for more information.

# This is the config file of a custom object.
# If you add this object correctly to your BiomeConfigs, it will spawn in the world.

# This is the creator of this BO3 object
Author: Unknown

# A short description of this BO3 object
Description: This BO3 was converted from a schematic using OTGEdit. The author and description information of the schematic could not be found. If you know who the author of the schematic is then please add this information.

# The BO3 version, don't change this! It can be used by external applications to do a version check.
Version: 3

# The settings mode, WriteAll, WriteWithoutComments or WriteDisable. See WorldConfig.
SettingsMode: WriteDisable

#######################################################################
# +-----------------------------------------------------------------+ #
# |                          Main settings                          | #
# +-----------------------------------------------------------------+ #
#######################################################################

# This needs to be set to true to spawn the object in the Tree and Sapling resources.
Tree: false

# The frequency of the BO3 from 1 to 200. Tries this many times to spawn this BO3 when using the CustomObject(...) resource.
# Ignored by Tree(..), Sapling(..) and CustomStructure(..)
Frequency: 1

# The rarity of the BO3 from 0 to 100. Each spawn attempt has rarity% chance to succeed when using the CustomObject(...) resource.
# Ignored by Tree(..), Sapling(..) and CustomStructure(..)
Rarity: 3.0

# If you set this to true, the BO3 will be placed with a random rotation.
RotateRandomly: true

# The spawn height of the BO3 - atMinY, randomY, highestBlock or highestSolidBlock.
SpawnHeight: highestSolidBlock

# The offset from the spawn height to spawn this BO3
# Ex. SpawnHeight = highestSolidBlock, SpawnHeightOffset = 3; This object will spawn 3 blocks above the highest solid block
SpawnHeightOffset: -50

# A random amount to offset the spawn location from the spawn offset height
# Ex. SpawnHeightOffset = 3, SpawnHeightVariance = 3; This object will spawn 3 to 6 blocks above the original spot it would have spawned
SpawnHeightVariance: 20

##############################
# Height Limits for the BO3. #
##############################

# When in randomY mode used as the minimum Y or in atMinY mode as the actual Y to spawn this BO3 at.
MinHeight: 0

# When in randomY mode used as the maximum Y to spawn this BO3 at.
MaxHeight: 70

######################
# Extrusion settings #
######################

# The style of extrusion you wish to use - BottomDown, TopUp, None (Default)
ExtrudeMode: BottomDown

# The blocks to extrude your BO3 through
ExtrudeThroughBlocks: AIR

# Objects can have other objects attacthed to it: branches. Branches can also
# have branches attached to it, which can also have branches, etc. This is the
# maximum branch depth for this objects.
MaxBranchDepth: 10

# When spawned with the UseWorld keyword, this BO3 should NOT spawn in the following biomes.
# If you write the BO3 name directly in the BiomeConfigs, this will be ignored.
ExcludedBiomes: All

#######################################################################
# +-----------------------------------------------------------------+ #
# |                      Source block settings                      | #
# +-----------------------------------------------------------------+ #
#######################################################################

# The block(s) the BO3 should spawn in.
SourceBlocks: AIR, STATIONARY_WATER

# The maximum percentage of the BO3 that can be outside the SourceBlock.
# The BO3 won't be placed on a location with more blocks outside the SourceBlock than this percentage.
MaxPercentageOutsideSourceBlock: 100

# What to do when a block is about to be placed outside the SourceBlock? (dontPlace, placeAnyway)
OutsideSourceBlock: placeAnyway

#######################################################################
# +-----------------------------------------------------------------+ #
# |                              Blocks                             | #
# +-----------------------------------------------------------------+ #
#######################################################################

# All the blocks used in the BO3 are listed here. Possible blocks:
# Block(x,y,z,id[.data][,nbtfile.nbt) or B(x,y,z,id[.data][,nbtfile.nbt)
# RandomBlock(x,y,z,id[:data][,nbtfile.nbt],chance[,id[:data][,nbtfile.nbt],chance[,...]])
# So RandomBlock(0,0,0,CHEST,chest.nbt,50,CHEST,anotherchest.nbt,100) will spawn a chest at
# the BO3 origin, and give it a 50% chance to have the contents of chest.nbt, or, if that
# fails, a 100% percent chance to have the contents of anotherchest.nbt.

Block(-16,0,0,172)
Block(-16,0,1,172)
Block(-16,0,2,172)
Block(-16,0,3,172)
Block(-16,0,4,172)
Block(-16,0,5,172)
Block(-16,1,1,172)
Block(-16,1,2,172)
Block(-16,1,3,172)
Block(-16,1,4,172)
Block(-16,2,1,172)
Block(-16,2,2,172)
Block(-16,2,3,172)
Block(-16,2,4,172)
Block(-16,3,1,172)
Block(-16,3,2,172)
Block(-16,3,3,172)
Block(-16,3,4,172)
Block(-16,4,2,172)
Block(-16,4,3,172)
Block(-16,4,4,172)
Block(-16,5,2,172)
Block(-16,5,3,172)
Block(-16,5,4,172)
Block(-16,6,2,172)
Block(-16,6,3,172)
Block(-16,7,2,172)
Block(-16,7,3,172)
Block(-16,8,2,172)
Block(-16,8,3,172)
Block(-16,9,2,172)
Block(-16,9,3,172)
Block(-16,10,2,172)
Block(-16,10,3,172)
Block(-16,11,2,172)
Block(-15,0,-9,172)
Block(-15,0,-2,172)
Block(-15,0,-1,172)
Block(-15,0,0,172)
Block(-15,0,1,172)
Block(-15,0,2,172)
Block(-15,0,3,172)
Block(-15,0,4,172)
Block(-15,0,5,172)
Block(-15,1,-2,172)
Block(-15,1,-1,172)
Block(-15,1,0,172)
Block(-15,1,1,172)
Block(-15,1,2,172)
Block(-15,1,3,172)
Block(-15,1,4,172)
Block(-15,1,5,172)
Block(-15,2,-2,172)
Block(-15,2,-1,172)
Block(-15,2,0,172)
Block(-15,2,1,172)
Block(-15,2,2,172)
Block(-15,2,3,172)
Block(-15,2,4,172)
Block(-15,3,-2,172)
Block(-15,3,-1,172)
Block(-15,3,0,172)
Block(-15,3,1,172)
Block(-15,3,2,172)
Block(-15,3,3,172)
Block(-15,3,4,172)
Block(-15,4,-2,172)
Block(-15,4,-1,172)
Block(-15,4,0,172)
Block(-15,4,1,172)
Block(-15,4,2,172)
Block(-15,4,3,172)
Block(-15,4,4,172)
Block(-15,5,-2,172)
Block(-15,5,1,172)
Block(-15,5,2,172)
Block(-15,5,3,172)
Block(-15,5,4,172)
Block(-15,6,1,172)
Block(-15,6,2,172)
Block(-15,6,3,172)
Block(-15,7,1,172)
Block(-15,7,2,172)
Block(-15,7,3,172)
Block(-15,8,1,172)
Block(-15,8,2,172)
Block(-15,8,3,172)
Block(-15,9,2,172)
Block(-15,9,3,172)
Block(-15,10,2,172)
Block(-15,10,3,172)
Block(-15,11,2,172)
Block(-15,12,2,172)
Block(-15,13,2,172)
Block(-15,14,2,172)
Block(-15,15,2,172)
Block(-14,0,-11,172)
Block(-14,0,-10,172)
Block(-14,0,-9,172)
Block(-14,0,-8,172)
Block(-14,0,-7,172)
Block(-14,0,-6,172)
Block(-14,0,-5,172)
Block(-14,0,-4,172)
Block(-14,0,-3,172)
Block(-14,0,-2,172)
Block(-14,0,-1,172)
Block(-14,0,0,172)
Block(-14,0,1,172)
Block(-14,0,2,172)
Block(-14,0,3,172)
Block(-14,0,4,172)
Block(-14,0,5,172)
Block(-14,0,6,172)
Block(-14,1,-9,172)
Block(-14,1,-4,172)
Block(-14,1,-3,172)
Block(-14,1,-2,172)
Block(-14,1,-1,172)
Block(-14,1,0,172)
Block(-14,1,1,172)
Block(-14,1,2,172)
Block(-14,1,3,172)
Block(-14,1,4,172)
Block(-14,1,5,172)
Block(-14,2,-9,172)
Block(-14,2,-2,172)
Block(-14,2,-1,172)
Block(-14,2,0,172)
Block(-14,2,1,172)
Block(-14,2,2,172)
Block(-14,2,3,172)
Block(-14,2,4,172)
Block(-14,2,5,172)
Block(-14,3,-2,172)
Block(-14,3,-1,172)
Block(-14,3,0,172)
Block(-14,3,1,172)
Block(-14,3,2,172)
Block(-14,3,3,172)
Block(-14,3,4,172)
Block(-14,3,5,172)
Block(-14,4,-2,172)
Block(-14,4,-1,172)
Block(-14,4,0,172)
Block(-14,4,1,172)
Block(-14,4,2,172)
Block(-14,4,3,172)
Block(-14,4,4,172)
Block(-14,5,-1,172)
Block(-14,5,0,172)
Block(-14,5,1,172)
Block(-14,5,2,172)
Block(-14,5,3,172)
Block(-14,5,4,172)
Block(-14,6,-1,172)
Block(-14,6,0,172)
Block(-14,6,1,172)
Block(-14,6,2,172)
Block(-14,6,3,172)
Block(-14,6,4,172)
Block(-14,7,-1,172)
Block(-14,7,0,172)
Block(-14,7,1,172)
Block(-14,7,2,172)
Block(-14,7,3,172)
Block(-14,7,4,172)
Block(-14,8,-1,172)
Block(-14,8,0,172)
Block(-14,8,1,172)
Block(-14,8,2,172)
Block(-14,8,3,172)
Block(-14,8,4,172)
Block(-14,9,-1,172)
Block(-14,9,0,172)
Block(-14,9,1,172)
Block(-14,9,2,172)
Block(-14,9,3,172)
Block(-14,9,4,172)
Block(-14,10,-1,172)
Block(-14,10,0,172)
Block(-14,10,1,172)
Block(-14,10,2,172)
Block(-14,10,3,172)
Block(-14,11,-1,172)
Block(-14,11,0,172)
Block(-14,11,1,172)
Block(-14,11,2,172)
Block(-14,11,3,172)
Block(-14,12,-1,172)
Block(-14,12,1,172)
Block(-14,12,2,172)
Block(-14,12,3,172)
Block(-14,13,-1,172)
Block(-14,13,1,172)
Block(-14,13,2,172)
Block(-14,13,3,172)
Block(-14,14,-1,172)
Block(-14,14,1,172)
Block(-14,14,2,172)
Block(-14,14,3,172)
Block(-14,15,-1,172)
Block(-14,15,1,172)
Block(-14,15,2,172)
Block(-14,15,3,172)
Block(-14,16,1,172)
Block(-14,16,2,172)
Block(-14,16,3,172)
Block(-14,17,1,172)
Block(-14,17,2,172)
Block(-14,17,3,172)
Block(-14,18,2,172)
Block(-14,18,3,172)
Block(-14,19,2,172)
Block(-14,19,3,172)
Block(-14,20,2,172)
Block(-14,21,2,172)
Block(-14,22,2,172)
Block(-14,23,2,172)
Block(-13,0,-12,172)
Block(-13,0,-11,172)
Block(-13,0,-10,172)
Block(-13,0,-9,172)
Block(-13,0,-8,172)
Block(-13,0,-7,172)
Block(-13,0,-6,172)
Block(-13,0,-5,172)
Block(-13,0,-4,172)
Block(-13,0,-3,172)
Block(-13,0,-2,172)
Block(-13,0,-1,172)
Block(-13,0,0,172)
Block(-13,0,1,172)
Block(-13,0,2,172)
Block(-13,0,3,172)
Block(-13,0,4,172)
Block(-13,0,5,172)
Block(-13,0,6,172)
Block(-13,1,-12,172)
Block(-13,1,-11,172)
Block(-13,1,-10,172)
Block(-13,1,-9,172)
Block(-13,1,-8,172)
Block(-13,1,-7,172)
Block(-13,1,-6,172)
Block(-13,1,-5,172)
Block(-13,1,-4,172)
Block(-13,1,-3,172)
Block(-13,1,-2,172)
Block(-13,1,-1,172)
Block(-13,1,0,172)
Block(-13,1,1,172)
Block(-13,1,2,172)
Block(-13,1,3,172)
Block(-13,1,4,172)
Block(-13,1,5,172)
Block(-13,1,6,172)
Block(-13,2,-12,172)
Block(-13,2,-11,172)
Block(-13,2,-10,172)
Block(-13,2,-9,172)
Block(-13,2,-8,172)
Block(-13,2,-7,172)
Block(-13,2,-6,172)
Block(-13,2,-5,172)
Block(-13,2,-4,172)
Block(-13,2,-3,172)
Block(-13,2,-2,172)
Block(-13,2,-1,172)
Block(-13,2,0,172)
Block(-13,2,1,172)
Block(-13,2,2,172)
Block(-13,2,3,172)
Block(-13,2,4,172)
Block(-13,2,5,172)
Block(-13,2,6,172)
Block(-13,3,-10,172)
Block(-13,3,-9,172)
Block(-13,3,-8,172)
Block(-13,3,-7,172)
Block(-13,3,-6,172)
Block(-13,3,-5,172)
Block(-13,3,-4,172)
Block(-13,3,-3,172)
Block(-13,3,-2,172)
Block(-13,3,-1,172)
Block(-13,3,0,172)
Block(-13,3,1,172)
Block(-13,3,2,172)
Block(-13,3,3,172)
Block(-13,3,4,172)
Block(-13,3,5,172)
Block(-13,4,-10,172)
Block(-13,4,-9,172)
Block(-13,4,-8,172)
Block(-13,4,-4,172)
Block(-13,4,-3,172)
Block(-13,4,-2,172)
Block(-13,4,-1,172)
Block(-13,4,0,172)
Block(-13,4,1,172)
Block(-13,4,2,172)
Block(-13,4,3,172)
Block(-13,4,4,172)
Block(-13,4,5,172)
Block(-13,5,-10,172)
Block(-13,5,-9,172)
Block(-13,5,-8,172)
Block(-13,5,-3,172)
Block(-13,5,-2,172)
Block(-13,5,-1,172)
Block(-13,5,0,172)
Block(-13,5,1,172)
Block(-13,5,2,172)
Block(-13,5,3,172)
Block(-13,5,4,172)
Block(-13,5,5,172)
Block(-13,6,-10,172)
Block(-13,6,-9,172)
Block(-13,6,-2,172)
Block(-13,6,-1,172)
Block(-13,6,0,172)
Block(-13,6,1,172)
Block(-13,6,2,172)
Block(-13,6,3,172)
Block(-13,6,4,172)
Block(-13,6,5,172)
Block(-13,7,-10,172)
Block(-13,7,-9,172)
Block(-13,7,-2,172)
Block(-13,7,-1,172)
Block(-13,7,0,172)
Block(-13,7,1,172)
Block(-13,7,2,172)
Block(-13,7,3,172)
Block(-13,7,4,172)
Block(-13,7,5,172)
Block(-13,8,-9,172)
Block(-13,8,-2,172)
Block(-13,8,-1,172)
Block(-13,8,0,172)
Block(-13,8,1,172)
Block(-13,8,2,172)
Block(-13,8,3,172)
Block(-13,8,4,172)
Block(-13,8,5,172)
Block(-13,9,-9,172)
Block(-13,9,-2,172)
Block(-13,9,-1,172)
Block(-13,9,0,172)
Block(-13,9,1,172)
Block(-13,9,2,172)
Block(-13,9,3,172)
Block(-13,9,4,172)
Block(-13,9,5,172)
Block(-13,10,-9,172)
Block(-13,10,-2,172)
Block(-13,10,-1,172)
Block(-13,10,0,172)
Block(-13,10,1,172)
Block(-13,10,2,172)
Block(-13,10,3,172)
Block(-13,10,4,172)
Block(-13,10,5,172)
Block(-13,11,-9,172)
Block(-13,11,-1,172)
Block(-13,11,0,172)
Block(-13,11,1,172)
Block(-13,11,2,172)
Block(-13,11,3,172)
Block(-13,11,4,172)
Block(-13,12,-1,172)
Block(-13,12,0,172)
Block(-13,12,1,172)
Block(-13,12,2,172)
Block(-13,12,3,172)
Block(-13,12,4,172)
Block(-13,13,-1,172)
Block(-13,13,0,172)
Block(-13,13,1,172)
Block(-13,13,2,172)
Block(-13,13,3,172)
Block(-13,13,4,172)
Block(-13,14,-1,172)
Block(-13,14,0,172)
Block(-13,14,1,172)
Block(-13,14,2,172)
Block(-13,14,3,172)
Block(-13,14,4,172)
Block(-13,15,-1,172)
Block(-13,15,0,172)
Block(-13,15,1,172)
Block(-13,15,2,172)
Block(-13,15,3,172)
Block(-13,15,4,172)
Block(-13,16,-1,172)
Block(-13,16,0,172)
Block(-13,16,1,172)
Block(-13,16,2,172)
Block(-13,16,3,172)
Block(-13,17,-1,172)
Block(-13,17,0,172)
Block(-13,17,1,172)
Block(-13,17,2,172)
Block(-13,17,3,172)
Block(-13,18,-1,172)
Block(-13,18,0,172)
Block(-13,18,1,172)
Block(-13,18,2,172)
Block(-13,18,3,172)
Block(-13,19,-1,172)
Block(-13,19,0,172)
Block(-13,19,1,172)
Block(-13,19,2,172)
Block(-13,19,3,172)
Block(-13,20,-1,172)
Block(-13,20,0,172)
Block(-13,20,1,172)
Block(-13,20,2,172)
Block(-13,20,3,172)
Block(-13,21,-1,172)
Block(-13,21,0,172)
Block(-13,21,1,172)
Block(-13,21,2,172)
Block(-13,21,3,172)
Block(-13,22,-1,172)
Block(-13,22,0,172)
Block(-13,22,1,172)
Block(-13,22,2,172)
Block(-13,22,3,172)
Block(-13,23,-1,172)
Block(-13,23,0,172)
Block(-13,23,1,172)
Block(-13,23,2,172)
Block(-13,23,3,172)
Block(-13,24,-1,172)
Block(-13,24,1,172)
Block(-13,24,2,172)
Block(-13,24,3,172)
Block(-13,25,-1,172)
Block(-13,25,1,172)
Block(-13,25,2,172)
Block(-13,25,3,172)
Block(-13,26,1,172)
Block(-13,26,2,172)
Block(-13,27,2,172)
Block(-13,28,2,172)
Block(-13,29,2,172)
Block(-13,30,2,172)
Block(-13,31,2,172)
Block(-13,32,2,172)
Block(-13,33,2,172)
Block(-13,34,2,172)
Block(-13,35,2,172)
Block(-12,0,-13,172)
Block(-12,0,-12,172)
Block(-12,0,-11,172)
Block(-12,0,-10,172)
Block(-12,0,-9,172)
Block(-12,0,-8,172)
Block(-12,0,-7,172)
Block(-12,0,-6,172)
Block(-12,0,-5,172)
Block(-12,0,-4,172)
Block(-12,0,-3,172)
Block(-12,0,-2,172)
Block(-12,0,-1,172)
Block(-12,0,0,172)
Block(-12,0,1,172)
Block(-12,0,2,172)
Block(-12,0,3,172)
Block(-12,0,4,172)
Block(-12,0,5,172)
Block(-12,0,6,172)
Block(-12,0,7,172)
Block(-12,1,-12,172)
Block(-12,1,-11,172)
Block(-12,1,-10,172)
Block(-12,1,-9,172)
Block(-12,1,-8,172)
Block(-12,1,-7,172)
Block(-12,1,-6,172)
Block(-12,1,-5,172)
Block(-12,1,-4,172)
Block(-12,1,-3,172)
Block(-12,1,-2,172)
Block(-12,1,-1,172)
Block(-12,1,0,172)
Block(-12,1,1,172)
Block(-12,1,2,172)
Block(-12,1,3,172)
Block(-12,1,4,172)
Block(-12,1,5,172)
Block(-12,1,6,172)
Block(-12,2,-12,172)
Block(-12,2,-11,172)
Block(-12,2,-10,172)
Block(-12,2,-9,172)
Block(-12,2,-8,172)
Block(-12,2,-7,172)
Block(-12,2,-6,172)
Block(-12,2,-5,172)
Block(-12,2,-4,172)
Block(-12,2,-3,172)
Block(-12,2,-2,172)
Block(-12,2,-1,172)
Block(-12,2,0,172)
Block(-12,2,1,172)
Block(-12,2,2,172)
Block(-12,2,3,172)
Block(-12,2,4,172)
Block(-12,2,5,172)
Block(-12,2,6,172)
Block(-12,3,-12,172)
Block(-12,3,-11,172)
Block(-12,3,-10,172)
Block(-12,3,-9,172)
Block(-12,3,-8,172)
Block(-12,3,-7,172)
Block(-12,3,-6,172)
Block(-12,3,-5,172)
Block(-12,3,-4,172)
Block(-12,3,-3,172)
Block(-12,3,-2,172)
Block(-12,3,-1,172)
Block(-12,3,0,172)
Block(-12,3,1,172)
Block(-12,3,2,172)
Block(-12,3,3,172)
Block(-12,3,4,172)
Block(-12,3,5,172)
Block(-12,3,6,172)
Block(-12,4,-12,172)
Block(-12,4,-11,172)
Block(-12,4,-10,172)
Block(-12,4,-9,172)
Block(-12,4,-8,172)
Block(-12,4,-7,172)
Block(-12,4,-6,172)
Block(-12,4,-5,172)
Block(-12,4,-4,172)
Block(-12,4,-3,172)
Block(-12,4,-2,172)
Block(-12,4,-1,172)
Block(-12,4,0,172)
Block(-12,4,1,172)
Block(-12,4,2,172)
Block(-12,4,3,172)
Block(-12,4,4,172)
Block(-12,4,5,172)
Block(-12,5,-12,172)
Block(-12,5,-11,172)
Block(-12,5,-10,172)
Block(-12,5,-9,172)
Block(-12,5,-8,172)
Block(-12,5,-7,172)
Block(-12,5,-6,172)
Block(-12,5,-5,172)
Block(-12,5,-4,172)
Block(-12,5,-3,172)
Block(-12,5,-2,172)
Block(-12,5,-1,172)
Block(-12,5,0,172)
Block(-12,5,1,172)
Block(-12,5,2,172)
Block(-12,5,3,172)
Block(-12,5,4,172)
Block(-12,5,5,172)
Block(-12,6,-11,172)
Block(-12,6,-10,172)
Block(-12,6,-9,172)
Block(-12,6,-8,172)
Block(-12,6,-7,172)
Block(-12,6,-6,172)
Block(-12,6,-5,172)
Block(-12,6,-4,172)
Block(-12,6,-3,172)
Block(-12,6,-2,172)
Block(-12,6,-1,172)
Block(-12,6,0,172)
Block(-12,6,1,172)
Block(-12,6,2,172)
Block(-12,6,3,172)
Block(-12,6,4,172)
Block(-12,6,5,172)
Block(-12,7,-11,172)
Block(-12,7,-10,172)
Block(-12,7,-9,172)
Block(-12,7,-8,172)
Block(-12,7,-7,172)
Block(-12,7,-6,172)
Block(-12,7,-4,172)
Block(-12,7,-3,172)
Block(-12,7,-2,172)
Block(-12,7,-1,172)
Block(-12,7,0,172)
Block(-12,7,1,172)
Block(-12,7,2,172)
Block(-12,7,3,172)
Block(-12,7,4,172)
Block(-12,7,5,172)
Block(-12,8,-10,172)
Block(-12,8,-9,172)
Block(-12,8,-8,172)
Block(-12,8,-7,172)
Block(-12,8,-3,172)
Block(-12,8,-2,172)
Block(-12,8,-1,172)
Block(-12,8,0,172)
Block(-12,8,1,172)
Block(-12,8,2,172)
Block(-12,8,3,172)
Block(-12,8,4,172)
Block(-12,9,-10,172)
Block(-12,9,-9,172)
Block(-12,9,-8,172)
Block(-12,9,-7,172)
Block(-12,9,-3,172)
Block(-12,9,-2,172)
Block(-12,9,-1,172)
Block(-12,9,0,172)
Block(-12,9,1,172)
Block(-12,9,2,172)
Block(-12,9,3,172)
Block(-12,9,4,172)
Block(-12,10,-10,172)
Block(-12,10,-9,172)
Block(-12,10,-8,172)
Block(-12,10,-7,172)
Block(-12,10,-2,172)
Block(-12,10,-1,172)
Block(-12,10,0,172)
Block(-12,10,1,172)
Block(-12,10,2,172)
Block(-12,10,3,172)
Block(-12,10,4,172)
Block(-12,11,-10,172)
Block(-12,11,-9,172)
Block(-12,11,-8,172)
Block(-12,11,-2,172)
Block(-12,11,-1,172)
Block(-12,11,0,172)
Block(-12,11,1,172)
Block(-12,11,2,172)
Block(-12,11,3,172)
Block(-12,11,4,172)
Block(-12,12,-10,172)
Block(-12,12,-9,172)
Block(-12,12,-2,172)
Block(-12,12,-1,172)
Block(-12,12,0,172)
Block(-12,12,1,172)
Block(-12,12,2,172)
Block(-12,12,3,172)
Block(-12,12,4,172)
Block(-12,13,-10,172)
Block(-12,13,-9,172)
Block(-12,13,-2,172)
Block(-12,13,-1,172)
Block(-12,13,0,172)
Block(-12,13,1,172)
Block(-12,13,2,172)
Block(-12,13,3,172)
Block(-12,13,4,172)
Block(-12,14,-10,172)
Block(-12,14,-9,172)
Block(-12,14,-2,172)
Block(-12,14,-1,172)
Block(-12,14,0,172)
Block(-12,14,1,172)
Block(-12,14,2,172)
Block(-12,14,3,172)
Block(-12,14,4,172)
Block(-12,15,-9,172)
Block(-12,15,-2,172)
Block(-12,15,-1,172)
Block(-12,15,0,172)
Block(-12,15,1,172)
Block(-12,15,2,172)
Block(-12,15,3,172)
Block(-12,15,4,172)
Block(-12,16,-9,172)
Block(-12,16,-2,172)
Block(-12,16,-1,172)
Block(-12,16,0,172)
Block(-12,16,1,172)
Block(-12,16,2,172)
Block(-12,16,3,172)
Block(-12,17,-9,172)
Block(-12,17,-2,172)
Block(-12,17,-1,172)
Block(-12,17,0,172)
Block(-12,17,1,172)
Block(-12,17,2,172)
Block(-12,17,3,172)
Block(-12,18,-9,172)
Block(-12,18,-2,172)
Block(-12,18,-1,172)
Block(-12,18,0,172)
Block(-12,18,1,172)
Block(-12,18,2,172)
Block(-12,18,3,172)
Block(-12,19,-9,172)
Block(-12,19,-2,172)
Block(-12,19,-1,172)
Block(-12,19,0,172)
Block(-12,19,1,172)
Block(-12,19,2,172)
Block(-12,19,3,172)
Block(-12,20,-9,172)
Block(-12,20,-2,172)
Block(-12,20,-1,172)
Block(-12,20,0,172)
Block(-12,20,1,172)
Block(-12,20,2,172)
Block(-12,20,3,172)
Block(-12,21,-9,172)
Block(-12,21,-1,172)
Block(-12,21,0,172)
Block(-12,21,1,172)
Block(-12,21,2,172)
Block(-12,21,3,172)
Block(-12,22,-9,172)
Block(-12,22,-1,172)
Block(-12,22,0,172)
Block(-12,22,1,172)
Block(-12,22,2,172)
Block(-12,22,3,172)
Block(-12,23,-9,172)
Block(-12,23,-1,172)
Block(-12,23,0,172)
Block(-12,23,1,172)
Block(-12,23,2,172)
Block(-12,23,3,172)
Block(-12,24,-1,172)
Block(-12,24,0,172)
Block(-12,24,1,172)
Block(-12,24,2,172)
Block(-12,24,3,172)
Block(-12,25,-1,172)
Block(-12,25,0,172)
Block(-12,25,1,172)
Block(-12,25,2,172)
Block(-12,25,3,172)
Block(-12,26,-1,172)
Block(-12,26,0,172)
Block(-12,26,1,172)
Block(-12,26,2,172)
Block(-12,27,-1,172)
Block(-12,27,0,172)
Block(-12,27,1,172)
Block(-12,27,2,172)
Block(-12,28,-1,172)
Block(-12,28,0,172)
Block(-12,28,1,172)
Block(-12,28,2,172)
Block(-12,29,-1,172)
Block(-12,29,0,172)
Block(-12,29,1,172)
Block(-12,29,2,172)
Block(-12,30,-1,172)
Block(-12,30,0,172)
Block(-12,30,1,172)
Block(-12,30,2,172)
Block(-12,31,0,172)
Block(-12,31,1,172)
Block(-12,31,2,172)
Block(-12,32,1,172)
Block(-12,32,2,172)
Block(-12,33,1,172)
Block(-12,33,2,172)
Block(-12,34,1,172)
Block(-12,34,2,172)
Block(-12,35,1,172)
Block(-12,35,2,172)
Block(-12,36,1,172)
Block(-12,36,2,172)
Block(-12,37,1,172)
Block(-12,37,2,172)
Block(-12,38,2,172)
Block(-12,39,2,172)
Block(-12,40,2,172)
Block(-12,41,2,172)
Block(-11,0,-14,172)
Block(-11,0,-13,172)
Block(-11,0,-12,172)
Block(-11,0,-11,172)
Block(-11,0,-10,172)
Block(-11,0,-9,172)
Block(-11,0,-8,172)
Block(-11,0,-7,172)
Block(-11,0,-6,172)
Block(-11,0,-5,172)
Block(-11,0,-4,172)
Block(-11,0,-3,172)
Block(-11,0,-2,172)
Block(-11,0,-1,172)
Block(-11,0,0,172)
Block(-11,0,1,172)
Block(-11,0,2,172)
Block(-11,0,3,172)
Block(-11,0,4,172)
Block(-11,0,5,172)
Block(-11,0,6,172)
Block(-11,0,7,172)
Block(-11,1,-13,172)
Block(-11,1,-12,172)
Block(-11,1,-11,172)
Block(-11,1,-10,172)
Block(-11,1,-9,172)
Block(-11,1,-8,172)
Block(-11,1,-7,172)
Block(-11,1,-6,172)
Block(-11,1,-5,172)
Block(-11,1,-4,172)
Block(-11,1,-3,172)
Block(-11,1,-2,172)
Block(-11,1,-1,172)
Block(-11,1,0,172)
Block(-11,1,1,172)
Block(-11,1,2,172)
Block(-11,1,3,172)
Block(-11,1,4,172)
Block(-11,1,5,172)
Block(-11,1,6,172)
Block(-11,1,7,172)
Block(-11,2,-13,172)
Block(-11,2,-12,172)
Block(-11,2,-11,172)
Block(-11,2,-10,172)
Block(-11,2,-9,172)
Block(-11,2,-8,172)
Block(-11,2,-7,172)
Block(-11,2,-6,172)
Block(-11,2,-5,172)
Block(-11,2,-4,172)
Block(-11,2,-3,172)
Block(-11,2,-2,172)
Block(-11,2,-1,172)
Block(-11,2,0,172)
Block(-11,2,1,172)
Block(-11,2,2,172)
Block(-11,2,3,172)
Block(-11,2,4,172)
Block(-11,2,5,172)
Block(-11,2,6,172)
Block(-11,2,7,172)
Block(-11,3,-13,172)
Block(-11,3,-12,172)
Block(-11,3,-11,172)
Block(-11,3,-10,172)
Block(-11,3,-9,172)
Block(-11,3,-8,172)
Block(-11,3,-7,172)
Block(-11,3,-6,172)
Block(-11,3,-5,172)
Block(-11,3,-4,172)
Block(-11,3,-3,172)
Block(-11,3,-2,172)
Block(-11,3,-1,172)
Block(-11,3,0,172)
Block(-11,3,1,172)
Block(-11,3,2,172)
Block(-11,3,3,172)
Block(-11,3,4,172)
Block(-11,3,5,172)
Block(-11,3,6,172)
Block(-11,4,-13,172)
Block(-11,4,-12,172)
Block(-11,4,-11,172)
Block(-11,4,-10,172)
Block(-11,4,-9,172)
Block(-11,4,-8,172)
Block(-11,4,-7,172)
Block(-11,4,-6,172)
Block(-11,4,-5,172)
Block(-11,4,-4,172)
Block(-11,4,-3,172)
Block(-11,4,-2,172)
Block(-11,4,-1,172)
Block(-11,4,0,172)
Block(-11,4,1,172)
Block(-11,4,2,172)
Block(-11,4,3,172)
Block(-11,4,4,172)
Block(-11,4,5,172)
Block(-11,4,6,172)
Block(-11,5,-13,172)
Block(-11,5,-12,172)
Block(-11,5,-11,172)
Block(-11,5,-10,172)
Block(-11,5,-9,172)
Block(-11,5,-8,172)
Block(-11,5,-7,172)
Block(-11,5,-6,172)
Block(-11,5,-5,172)
Block(-11,5,-4,172)
Block(-11,5,-3,172)
Block(-11,5,-2,172)
Block(-11,5,-1,172)
Block(-11,5,0,172)
Block(-11,5,1,172)
Block(-11,5,2,172)
Block(-11,5,3,172)
Block(-11,5,4,172)
Block(-11,5,5,172)
Block(-11,5,6,172)
Block(-11,6,-12,172)
Block(-11,6,-11,172)
Block(-11,6,-10,172)
Block(-11,6,-9,172)
Block(-11,6,-8,172)
Block(-11,6,-7,172)
Block(-11,6,-6,172)
Block(-11,6,-5,172)
Block(-11,6,-4,172)
Block(-11,6,-3,172)
Block(-11,6,-2,172)
Block(-11,6,-1,172)
Block(-11,6,0,172)
Block(-11,6,1,172)
Block(-11,6,2,172)
Block(-11,6,3,172)
Block(-11,6,4,172)
Block(-11,6,5,172)
Block(-11,7,-12,172)
Block(-11,7,-11,172)
Block(-11,7,-10,172)
Block(-11,7,-9,172)
Block(-11,7,-8,172)
Block(-11,7,-7,172)
Block(-11,7,-6,172)
Block(-11,7,-5,172)
Block(-11,7,-4,172)
Block(-11,7,-3,172)
Block(-11,7,-2,172)
Block(-11,7,-1,172)
Block(-11,7,0,172)
Block(-11,7,1,172)
Block(-11,7,2,172)
Block(-11,7,3,172)
Block(-11,7,4,172)
Block(-11,7,5,172)
Block(-11,8,-12,172)
Block(-11,8,-11,172)
Block(-11,8,-10,172)
Block(-11,8,-9,172)
Block(-11,8,-8,172)
Block(-11,8,-7,172)
Block(-11,8,-6,172)
Block(-11,8,-5,172)
Block(-11,8,-4,172)
Block(-11,8,-3,172)
Block(-11,8,-2,172)
Block(-11,8,-1,172)
Block(-11,8,0,172)
Block(-11,8,1,172)
Block(-11,8,2,172)
Block(-11,8,3,172)
Block(-11,8,4,172)
Block(-11,8,5,172)
Block(-11,9,-12,172)
Block(-11,9,-11,172)
Block(-11,9,-10,172)
Block(-11,9,-9,172)
Block(-11,9,-8,172)
Block(-11,9,-7,172)
Block(-11,9,-6,172)
Block(-11,9,-5,172)
Block(-11,9,-4,172)
Block(-11,9,-3,172)
Block(-11,9,-2,172)
Block(-11,9,-1,172)
Block(-11,9,0,172)
Block(-11,9,1,172)
Block(-11,9,2,172)
Block(-11,9,3,172)
Block(-11,9,4,172)
Block(-11,10,-11,172)
Block(-11,10,-10,172)
Block(-11,10,-9,172)
Block(-11,10,-8,172)
Block(-11,10,-7,172)
Block(-11,10,-6,172)
Block(-11,10,-5,172)
Block(-11,10,-4,172)
Block(-11,10,-3,172)
Block(-11,10,-2,172)
Block(-11,10,-1,172)
Block(-11,10,0,172)
Block(-11,10,1,172)
Block(-11,10,2,172)
Block(-11,10,3,172)
Block(-11,10,4,172)
Block(-11,11,-11,172)
Block(-11,11,-10,172)
Block(-11,11,-9,172)
Block(-11,11,-8,172)
Block(-11,11,-7,172)
Block(-11,11,-6,172)
Block(-11,11,-5,172)
Block(-11,11,-4,172)
Block(-11,11,-3,172)
Block(-11,11,-2,172)
Block(-11,11,-1,172)
Block(-11,11,0,172)
Block(-11,11,1,172)
Block(-11,11,2,172)
Block(-11,11,3,172)
Block(-11,11,4,172)
Block(-11,12,-11,172)
Block(-11,12,-10,172)
Block(-11,12,-9,172)
Block(-11,12,-8,172)
Block(-11,12,-7,172)
Block(-11,12,-6,172)
Block(-11,12,-5,172)
Block(-11,12,-4,172)
Block(-11,12,-3,172)
Block(-11,12,-2,172)
Block(-11,12,-1,172)
Block(-11,12,0,172)
Block(-11,12,1,172)
Block(-11,12,2,172)
Block(-11,12,3,172)
Block(-11,12,4,172)
Block(-11,13,-11,172)
Block(-11,13,-10,172)
Block(-11,13,-9,172)
Block(-11,13,-8,172)
Block(-11,13,-7,172)
Block(-11,13,-6,172)
Block(-11,13,-5,172)
Block(-11,13,-4,172)
Block(-11,13,-3,172)
Block(-11,13,-2,172)
Block(-11,13,-1,172)
Block(-11,13,0,172)
Block(-11,13,1,172)
Block(-11,13,2,172)
Block(-11,13,3,172)
Block(-11,13,4,172)
Block(-11,14,-10,172)
Block(-11,14,-9,172)
Block(-11,14,-8,172)
Block(-11,14,-7,172)
Block(-11,14,-6,172)
Block(-11,14,-5,172)
Block(-11,14,-4,172)
Block(-11,14,-3,172)
Block(-11,14,-2,172)
Block(-11,14,-1,172)
Block(-11,14,0,172)
Block(-11,14,1,172)
Block(-11,14,2,172)
Block(-11,14,3,172)
Block(-11,15,-10,172)
Block(-11,15,-9,172)
Block(-11,15,-8,172)
Block(-11,15,-7,172)
Block(-11,15,-5,172)
Block(-11,15,-4,172)
Block(-11,15,-3,172)
Block(-11,15,-2,172)
Block(-11,15,-1,172)
Block(-11,15,0,172)
Block(-11,15,1,172)
Block(-11,15,2,172)
Block(-11,15,3,172)
Block(-11,16,-10,172)
Block(-11,16,-9,172)
Block(-11,16,-8,172)
Block(-11,16,-7,172)
Block(-11,16,-5,172)
Block(-11,16,-4,172)
Block(-11,16,-3,172)
Block(-11,16,-2,172)
Block(-11,16,-1,172)
Block(-11,16,0,172)
Block(-11,16,1,172)
Block(-11,16,2,172)
Block(-11,16,3,172)
Block(-11,17,-10,172)
Block(-11,17,-9,172)
Block(-11,17,-8,172)
Block(-11,17,-7,172)
Block(-11,17,-5,172)
Block(-11,17,-3,172)
Block(-11,17,-2,172)
Block(-11,17,-1,172)
Block(-11,17,0,172)
Block(-11,17,1,172)
Block(-11,17,2,172)
Block(-11,17,3,172)
Block(-11,18,-10,172)
Block(-11,18,-9,172)
Block(-11,18,-8,172)
Block(-11,18,-7,172)
Block(-11,18,-3,172)
Block(-11,18,-2,172)
Block(-11,18,-1,172)
Block(-11,18,0,172)
Block(-11,18,1,172)
Block(-11,18,2,172)
Block(-11,18,3,172)
Block(-11,19,-10,172)
Block(-11,19,-9,172)
Block(-11,19,-8,172)
Block(-11,19,-2,172)
Block(-11,19,-1,172)
Block(-11,19,0,172)
Block(-11,19,1,172)
Block(-11,19,2,172)
Block(-11,19,3,172)
Block(-11,20,-9,172)
Block(-11,20,-8,172)
Block(-11,20,-2,172)
Block(-11,20,-1,172)
Block(-11,20,0,172)
Block(-11,20,1,172)
Block(-11,20,2,172)
Block(-11,20,3,172)
Block(-11,21,-9,172)
Block(-11,21,-8,172)
Block(-11,21,-2,172)
Block(-11,21,-1,172)
Block(-11,21,0,172)
Block(-11,21,1,172)
Block(-11,21,2,172)
Block(-11,21,3,172)
Block(-11,22,-9,172)
Block(-11,22,-8,172)
Block(-11,22,-2,172)
Block(-11,22,-1,172)
Block(-11,22,0,172)
Block(-11,22,1,172)
Block(-11,22,2,172)
Block(-11,22,3,172)
Block(-11,23,-9,172)
Block(-11,23,-2,172)
Block(-11,23,-1,172)
Block(-11,23,0,172)
Block(-11,23,1,172)
Block(-11,23,2,172)
Block(-11,23,3,172)
Block(-11,24,-9,172)
Block(-11,24,-2,172)
Block(-11,24,-1,172)
Block(-11,24,0,172)
Block(-11,24,1,172)
Block(-11,24,2,172)
Block(-11,24,3,172)
Block(-11,25,-9,172)
Block(-11,25,-2,172)
Block(-11,25,-1,172)
Block(-11,25,0,172)
Block(-11,25,1,172)
Block(-11,25,2,172)
Block(-11,25,3,172)
Block(-11,26,-9,172)
Block(-11,26,-2,172)
Block(-11,26,-1,172)
Block(-11,26,0,172)
Block(-11,26,1,172)
Block(-11,26,2,172)
Block(-11,26,3,172)
Block(-11,27,-2,172)
Block(-11,27,-1,172)
Block(-11,27,0,172)
Block(-11,27,1,172)
Block(-11,27,2,172)
Block(-11,27,3,172)
Block(-11,28,-2,172)
Block(-11,28,-1,172)
Block(-11,28,0,172)
Block(-11,28,1,172)
Block(-11,28,2,172)
Block(-11,28,3,172)
Block(-11,29,-2,172)
Block(-11,29,-1,172)
Block(-11,29,0,172)
Block(-11,29,1,172)
Block(-11,29,2,172)
Block(-11,29,3,172)
Block(-11,30,-2,172)
Block(-11,30,-1,172)
Block(-11,30,0,172)
Block(-11,30,1,172)
Block(-11,30,2,172)
Block(-11,30,3,172)
Block(-11,31,-2,172)
Block(-11,31,-1,172)
Block(-11,31,0,172)
Block(-11,31,1,172)
Block(-11,31,2,172)
Block(-11,31,3,172)
Block(-11,32,-2,172)
Block(-11,32,-1,172)
Block(-11,32,0,172)
Block(-11,32,1,172)
Block(-11,32,2,172)
Block(-11,33,-1,172)
Block(-11,33,0,172)
Block(-11,33,1,172)
Block(-11,33,2,172)
Block(-11,34,-1,172)
Block(-11,34,0,172)
Block(-11,34,1,172)
Block(-11,34,2,172)
Block(-11,35,-1,172)
Block(-11,35,0,172)
Block(-11,35,1,172)
Block(-11,35,2,172)
Block(-11,36,-1,172)
Block(-11,36,0,172)
Block(-11,36,1,172)
Block(-11,36,2,172)
Block(-11,37,-1,172)
Block(-11,37,0,172)
Block(-11,37,1,172)
Block(-11,37,2,172)
Block(-11,38,-1,172)
Block(-11,38,0,172)
Block(-11,38,1,172)
Block(-11,38,2,172)
Block(-11,39,-1,172)
Block(-11,39,0,172)
Block(-11,39,1,172)
Block(-11,39,2,172)
Block(-11,40,-1,172)
Block(-11,40,0,172)
Block(-11,40,1,172)
Block(-11,40,2,172)
Block(-11,41,-1,172)
Block(-11,41,0,172)
Block(-11,41,1,172)
Block(-11,42,-1,172)
Block(-11,42,0,172)
Block(-11,42,1,172)
Block(-11,43,-1,172)
Block(-11,43,0,172)
Block(-11,43,1,172)
Block(-11,44,-1,172)
Block(-11,44,1,172)
Block(-11,45,-1,172)
Block(-11,45,1,172)
Block(-11,46,-1,172)
Block(-11,46,1,172)
Block(-11,47,-1,172)
Block(-11,47,1,172)
Block(-11,48,-1,172)
Block(-11,48,1,172)
Block(-11,49,-1,172)
Block(-11,49,1,172)
Block(-11,50,-1,172)
Block(-11,50,1,172)
Block(-11,51,-1,172)
Block(-11,51,1,172)
Block(-11,52,1,172)
Block(-10,0,-14,172)
Block(-10,0,-13,172)
Block(-10,0,-12,172)
Block(-10,0,-11,172)
Block(-10,0,-10,172)
Block(-10,0,-9,172)
Block(-10,0,-8,172)
Block(-10,0,-7,172)
Block(-10,0,-6,172)
Block(-10,0,-5,172)
Block(-10,0,-4,172)
Block(-10,0,-3,172)
Block(-10,0,-2,172)
Block(-10,0,-1,172)
Block(-10,0,0,172)
Block(-10,0,1,172)
Block(-10,0,2,172)
Block(-10,0,3,172)
Block(-10,0,4,172)
Block(-10,0,5,172)
Block(-10,0,6,172)
Block(-10,0,7,172)
Block(-10,0,8,172)
Block(-10,0,9,172)
Block(-10,1,-14,172)
Block(-10,1,-13,172)
Block(-10,1,-12,172)
Block(-10,1,-11,172)
Block(-10,1,-10,172)
Block(-10,1,-9,172)
Block(-10,1,-8,172)
Block(-10,1,-7,172)
Block(-10,1,-6,172)
Block(-10,1,-5,172)
Block(-10,1,-4,172)
Block(-10,1,-3,172)
Block(-10,1,-2,172)
Block(-10,1,-1,172)
Block(-10,1,0,172)
Block(-10,1,1,172)
Block(-10,1,2,172)
Block(-10,1,3,172)
Block(-10,1,4,172)
Block(-10,1,5,172)
Block(-10,1,6,172)
Block(-10,1,7,172)
Block(-10,1,8,172)
Block(-10,2,-14,172)
Block(-10,2,-13,172)
Block(-10,2,-12,172)
Block(-10,2,-11,172)
Block(-10,2,-10,172)
Block(-10,2,-9,172)
Block(-10,2,-8,172)
Block(-10,2,-7,172)
Block(-10,2,-6,172)
Block(-10,2,-5,172)
Block(-10,2,-4,172)
Block(-10,2,-3,172)
Block(-10,2,-2,172)
Block(-10,2,-1,172)
Block(-10,2,0,172)
Block(-10,2,1,172)
Block(-10,2,2,172)
Block(-10,2,3,172)
Block(-10,2,4,172)
Block(-10,2,5,172)
Block(-10,2,6,172)
Block(-10,2,7,172)
Block(-10,2,8,172)
Block(-10,3,-14,172)
Block(-10,3,-13,172)
Block(-10,3,-12,172)
Block(-10,3,-11,172)
Block(-10,3,-10,172)
Block(-10,3,-9,172)
Block(-10,3,-8,172)
Block(-10,3,-7,172)
Block(-10,3,-6,172)
Block(-10,3,-5,172)
Block(-10,3,-4,172)
Block(-10,3,-3,172)
Block(-10,3,-2,172)
Block(-10,3,-1,172)
Block(-10,3,0,172)
Block(-10,3,1,172)
Block(-10,3,2,172)
Block(-10,3,3,172)
Block(-10,3,4,172)
Block(-10,3,5,172)
Block(-10,3,6,172)
Block(-10,3,7,172)
Block(-10,3,8,172)
Block(-10,4,-14,172)
Block(-10,4,-13,172)
Block(-10,4,-12,172)
Block(-10,4,-11,172)
Block(-10,4,-10,172)
Block(-10,4,-9,172)
Block(-10,4,-8,172)
Block(-10,4,-7,172)
Block(-10,4,-6,172)
Block(-10,4,-5,172)
Block(-10,4,-4,172)
Block(-10,4,-3,172)
Block(-10,4,-2,172)
Block(-10,4,-1,172)
Block(-10,4,0,172)
Block(-10,4,1,172)
Block(-10,4,2,172)
Block(-10,4,3,172)
Block(-10,4,4,172)
Block(-10,4,5,172)
Block(-10,4,6,172)
Block(-10,4,7,172)
Block(-10,5,-14,172)
Block(-10,5,-13,172)
Block(-10,5,-12,172)
Block(-10,5,-11,172)
Block(-10,5,-10,172)
Block(-10,5,-9,172)
Block(-10,5,-8,172)
Block(-10,5,-7,172)
Block(-10,5,-6,172)
Block(-10,5,-5,172)
Block(-10,5,-4,172)
Block(-10,5,-3,172)
Block(-10,5,-2,172)
Block(-10,5,-1,172)
Block(-10,5,0,172)
Block(-10,5,1,172)
Block(-10,5,2,172)
Block(-10,5,3,172)
Block(-10,5,4,172)
Block(-10,5,5,172)
Block(-10,5,6,172)
Block(-10,5,7,172)
Block(-10,6,-13,172)
Block(-10,6,-12,172)
Block(-10,6,-11,172)
Block(-10,6,-10,172)
Block(-10,6,-9,172)
Block(-10,6,-8,172)
Block(-10,6,-7,172)
Block(-10,6,-6,172)
Block(-10,6,-5,172)
Block(-10,6,-4,172)
Block(-10,6,-3,172)
Block(-10,6,-2,172)
Block(-10,6,-1,172)
Block(-10,6,0,172)
Block(-10,6,1,172)
Block(-10,6,2,172)
Block(-10,6,3,172)
Block(-10,6,4,172)
Block(-10,6,5,172)
Block(-10,6,6,172)
Block(-10,7,-13,172)
Block(-10,7,-12,172)
Block(-10,7,-11,172)
Block(-10,7,-10,172)
Block(-10,7,-9,172)
Block(-10,7,-8,172)
Block(-10,7,-7,172)
Block(-10,7,-6,172)
Block(-10,7,-5,172)
Block(-10,7,-4,172)
Block(-10,7,-3,172)
Block(-10,7,-2,172)
Block(-10,7,-1,172)
Block(-10,7,0,172)
Block(-10,7,1,172)
Block(-10,7,2,172)
Block(-10,7,3,172)
Block(-10,7,4,172)
Block(-10,7,5,172)
Block(-10,8,-13,172)
Block(-10,8,-12,172)
Block(-10,8,-11,172)
Block(-10,8,-10,172)
Block(-10,8,-9,172)
Block(-10,8,-8,172)
Block(-10,8,-7,172)
Block(-10,8,-6,172)
Block(-10,8,-5,172)
Block(-10,8,-4,172)
Block(-10,8,-3,172)
Block(-10,8,-2,172)
Block(-10,8,-1,172)
Block(-10,8,0,172)
Block(-10,8,1,172)
Block(-10,8,2,172)
Block(-10,8,3,172)
Block(-10,8,4,172)
Block(-10,8,5,172)
Block(-10,9,-13,172)
Block(-10,9,-12,172)
Block(-10,9,-11,172)
Block(-10,9,-10,172)
Block(-10,9,-9,172)
Block(-10,9,-8,172)
Block(-10,9,-7,172)
Block(-10,9,-6,172)
Block(-10,9,-5,172)
Block(-10,9,-4,172)
Block(-10,9,-3,172)
Block(-10,9,-2,172)
Block(-10,9,-1,172)
Block(-10,9,0,172)
Block(-10,9,1,172)
Block(-10,9,2,172)
Block(-10,9,3,172)
Block(-10,9,4,172)
Block(-10,9,5,172)
Block(-10,10,-13,172)
Block(-10,10,-12,172)
Block(-10,10,-11,172)
Block(-10,10,-10,172)
Block(-10,10,-9,172)
Block(-10,10,-8,172)
Block(-10,10,-7,172)
Block(-10,10,-6,172)
Block(-10,10,-5,172)
Block(-10,10,-4,172)
Block(-10,10,-3,172)
Block(-10,10,-2,172)
Block(-10,10,-1,172)
Block(-10,10,0,172)
Block(-10,10,1,172)
Block(-10,10,2,172)
Block(-10,10,3,172)
Block(-10,10,4,172)
Block(-10,11,-13,172)
Block(-10,11,-12,172)
Block(-10,11,-11,172)
Block(-10,11,-10,172)
Block(-10,11,-9,172)
Block(-10,11,-8,172)
Block(-10,11,-7,172)
Block(-10,11,-6,172)
Block(-10,11,-5,172)
Block(-10,11,-4,172)
Block(-10,11,-3,172)
Block(-10,11,-2,172)
Block(-10,11,-1,172)
Block(-10,11,0,172)
Block(-10,11,1,172)
Block(-10,11,2,172)
Block(-10,11,3,172)
Block(-10,11,4,172)
Block(-10,12,-13,172)
Block(-10,12,-12,172)
Block(-10,12,-11,172)
Block(-10,12,-10,172)
Block(-10,12,-9,172)
Block(-10,12,-8,172)
Block(-10,12,-7,172)
Block(-10,12,-6,172)
Block(-10,12,-5,172)
Block(-10,12,-4,172)
Block(-10,12,-3,172)
Block(-10,12,-2,172)
Block(-10,12,-1,172)
Block(-10,12,0,172)
Block(-10,12,1,172)
Block(-10,12,2,172)
Block(-10,12,3,172)
Block(-10,12,4,172)
Block(-10,13,-13,172)
Block(-10,13,-12,172)
Block(-10,13,-11,172)
Block(-10,13,-10,172)
Block(-10,13,-9,172)
Block(-10,13,-8,172)
Block(-10,13,-7,172)
Block(-10,13,-6,172)
Block(-10,13,-5,172)
Block(-10,13,-4,172)
Block(-10,13,-3,172)
Block(-10,13,-2,172)
Block(-10,13,-1,172)
Block(-10,13,0,172)
Block(-10,13,1,172)
Block(-10,13,2,172)
Block(-10,13,3,172)
Block(-10,13,4,172)
Block(-10,14,-13,172)
Block(-10,14,-12,172)
Block(-10,14,-11,172)
Block(-10,14,-10,172)
Block(-10,14,-9,172)
Block(-10,14,-8,172)
Block(-10,14,-7,172)
Block(-10,14,-6,172)
Block(-10,14,-5,172)
Block(-10,14,-4,172)
Block(-10,14,-3,172)
Block(-10,14,-2,172)
Block(-10,14,-1,172)
Block(-10,14,0,172)
Block(-10,14,1,172)
Block(-10,14,2,172)
Block(-10,14,3,172)
Block(-10,14,4,172)
Block(-10,15,-12,172)
Block(-10,15,-11,172)
Block(-10,15,-10,172)
Block(-10,15,-9,172)
Block(-10,15,-8,172)
Block(-10,15,-7,172)
Block(-10,15,-6,172)
Block(-10,15,-5,172)
Block(-10,15,-4,172)
Block(-10,15,-3,172)
Block(-10,15,-2,172)
Block(-10,15,-1,172)
Block(-10,15,0,172)
Block(-10,15,1,172)
Block(-10,15,2,172)
Block(-10,15,3,172)
Block(-10,15,4,172)
Block(-10,16,-12,172)
Block(-10,16,-11,172)
Block(-10,16,-10,172)
Block(-10,16,-9,172)
Block(-10,16,-8,172)
Block(-10,16,-7,172)
Block(-10,16,-6,172)
Block(-10,16,-5,172)
Block(-10,16,-4,172)
Block(-10,16,-3,172)
Block(-10,16,-2,172)
Block(-10,16,-1,172)
Block(-10,16,0,172)
Block(-10,16,1,172)
Block(-10,16,2,172)
Block(-10,16,3,172)
Block(-10,16,4,172)
Block(-10,17,-12,172)
Block(-10,17,-11,172)
Block(-10,17,-10,172)
Block(-10,17,-9,172)
Block(-10,17,-8,172)
Block(-10,17,-7,172)
Block(-10,17,-6,172)
Block(-10,17,-5,172)
Block(-10,17,-4,172)
Block(-10,17,-3,172)
Block(-10,17,-2,172)
Block(-10,17,-1,172)
Block(-10,17,0,172)
Block(-10,17,1,172)
Block(-10,17,2,172)
Block(-10,17,3,172)
Block(-10,17,4,172)
Block(-10,18,-12,172)
Block(-10,18,-11,172)
Block(-10,18,-10,172)
Block(-10,18,-9,172)
Block(-10,18,-8,172)
Block(-10,18,-7,172)
Block(-10,18,-6,172)
Block(-10,18,-5,172)
Block(-10,18,-4,172)
Block(-10,18,-3,172)
Block(-10,18,-2,172)
Block(-10,18,-1,172)
Block(-10,18,0,172)
Block(-10,18,1,172)
Block(-10,18,2,172)
Block(-10,18,3,172)
Block(-10,18,4,172)
Block(-10,19,-12,172)
Block(-10,19,-11,172)
Block(-10,19,-10,172)
Block(-10,19,-9,172)
Block(-10,19,-8,172)
Block(-10,19,-7,172)
Block(-10,19,-6,172)
Block(-10,19,-5,172)
Block(-10,19,-4,172)
Block(-10,19,-3,172)
Block(-10,19,-2,172)
Block(-10,19,-1,172)
Block(-10,19,0,172)
Block(-10,19,1,172)
Block(-10,19,2,172)
Block(-10,19,3,172)
Block(-10,19,4,172)
Block(-10,20,-11,172)
Block(-10,20,-10,172)
Block(-10,20,-9,172)
Block(-10,20,-8,172)
Block(-10,20,-7,172)
Block(-10,20,-6,172)
Block(-10,20,-5,172)
Block(-10,20,-4,172)
Block(-10,20,-3,172)
Block(-10,20,-2,172)
Block(-10,20,-1,172)
Block(-10,20,0,172)
Block(-10,20,1,172)
Block(-10,20,2,172)
Block(-10,20,3,172)
Block(-10,20,4,172)
Block(-10,21,-11,172)
Block(-10,21,-10,172)
Block(-10,21,-9,172)
Block(-10,21,-8,172)
Block(-10,21,-7,172)
Block(-10,21,-6,172)
Block(-10,21,-5,172)
Block(-10,21,-4,172)
Block(-10,21,-3,172)
Block(-10,21,-2,172)
Block(-10,21,-1,172)
Block(-10,21,0,172)
Block(-10,21,1,172)
Block(-10,21,2,172)
Block(-10,21,3,172)
Block(-10,21,4,172)
Block(-10,22,-11,172)
Block(-10,22,-10,172)
Block(-10,22,-9,172)
Block(-10,22,-8,172)
Block(-10,22,-7,172)
Block(-10,22,-6,172)
Block(-10,22,-5,172)
Block(-10,22,-4,172)
Block(-10,22,-3,172)
Block(-10,22,-2,172)
Block(-10,22,-1,172)
Block(-10,22,0,172)
Block(-10,22,1,172)
Block(-10,22,2,172)
Block(-10,22,3,172)
Block(-10,22,4,172)
Block(-10,23,-10,172)
Block(-10,23,-9,172)
Block(-10,23,-8,172)
Block(-10,23,-7,172)
Block(-10,23,-6,172)
Block(-10,23,-5,172)
Block(-10,23,-4,172)
Block(-10,23,-3,172)
Block(-10,23,-2,172)
Block(-10,23,-1,172)
Block(-10,23,0,172)
Block(-10,23,1,172)
Block(-10,23,2,172)
Block(-10,23,3,172)
Block(-10,24,-10,172)
Block(-10,24,-9,172)
Block(-10,24,-8,172)
Block(-10,24,-7,172)
Block(-10,24,-6,172)
Block(-10,24,-5,172)
Block(-10,24,-4,172)
Block(-10,24,-3,172)
Block(-10,24,-2,172)
Block(-10,24,-1,172)
Block(-10,24,0,172)
Block(-10,24,1,172)
Block(-10,24,2,172)
Block(-10,24,3,172)
Block(-10,25,-10,172)
Block(-10,25,-9,172)
Block(-10,25,-8,172)
Block(-10,25,-7,172)
Block(-10,25,-6,172)
Block(-10,25,-5,172)
Block(-10,25,-4,172)
Block(-10,25,-3,172)
Block(-10,25,-2,172)
Block(-10,25,-1,172)
Block(-10,25,0,172)
Block(-10,25,1,172)
Block(-10,25,2,172)
Block(-10,25,3,172)
Block(-10,26,-10,172)
Block(-10,26,-9,172)
Block(-10,26,-8,172)
Block(-10,26,-7,172)
Block(-10,26,-5,172)
Block(-10,26,-4,172)
Block(-10,26,-3,172)
Block(-10,26,-2,172)
Block(-10,26,-1,172)
Block(-10,26,0,172)
Block(-10,26,1,172)
Block(-10,26,2,172)
Block(-10,26,3,172)
Block(-10,27,-10,172)
Block(-10,27,-9,172)
Block(-10,27,-8,172)
Block(-10,27,-5,172)
Block(-10,27,-4,172)
Block(-10,27,-3,172)
Block(-10,27,-2,172)
Block(-10,27,-1,172)
Block(-10,27,0,172)
Block(-10,27,1,172)
Block(-10,27,2,172)
Block(-10,27,3,172)
Block(-10,28,-9,172)
Block(-10,28,-8,172)
Block(-10,28,-5,172)
Block(-10,28,-4,172)
Block(-10,28,-3,172)
Block(-10,28,-2,172)
Block(-10,28,-1,172)
Block(-10,28,0,172)
Block(-10,28,1,172)
Block(-10,28,2,172)
Block(-10,28,3,172)
Block(-10,29,-9,172)
Block(-10,29,-8,172)
Block(-10,29,-5,172)
Block(-10,29,-4,172)
Block(-10,29,-3,172)
Block(-10,29,-2,172)
Block(-10,29,-1,172)
Block(-10,29,0,172)
Block(-10,29,1,172)
Block(-10,29,2,172)
Block(-10,29,3,172)
Block(-10,30,-9,172)
Block(-10,30,-8,172)
Block(-10,30,-5,172)
Block(-10,30,-4,172)
Block(-10,30,-3,172)
Block(-10,30,-2,172)
Block(-10,30,-1,172)
Block(-10,30,0,172)
Block(-10,30,1,172)
Block(-10,30,2,172)
Block(-10,30,3,172)
Block(-10,31,-9,172)
Block(-10,31,-8,172)
Block(-10,31,-5,172)
Block(-10,31,-4,172)
Block(-10,31,-3,172)
Block(-10,31,-2,172)
Block(-10,31,-1,172)
Block(-10,31,0,172)
Block(-10,31,1,172)
Block(-10,31,2,172)
Block(-10,31,3,172)
Block(-10,32,-9,172)
Block(-10,32,-8,172)
Block(-10,32,-5,172)
Block(-10,32,-4,172)
Block(-10,32,-3,172)
Block(-10,32,-2,172)
Block(-10,32,-1,172)
Block(-10,32,0,172)
Block(-10,32,1,172)
Block(-10,32,2,172)
Block(-10,32,3,172)
Block(-10,33,-9,172)
Block(-10,33,-8,172)
Block(-10,33,-5,172)
Block(-10,33,-4,172)
Block(-10,33,-3,172)
Block(-10,33,-2,172)
Block(-10,33,-1,172)
Block(-10,33,0,172)
Block(-10,33,1,172)
Block(-10,33,2,172)
Block(-10,33,3,172)
Block(-10,34,-9,172)
Block(-10,34,-5,172)
Block(-10,34,-4,172)
Block(-10,34,-3,172)
Block(-10,34,-2,172)
Block(-10,34,-1,172)
Block(-10,34,0,172)
Block(-10,34,1,172)
Block(-10,34,2,172)
Block(-10,34,3,172)
Block(-10,35,-9,172)
Block(-10,35,-5,172)
Block(-10,35,-4,172)
Block(-10,35,-3,172)
Block(-10,35,-2,172)
Block(-10,35,-1,172)
Block(-10,35,0,172)
Block(-10,35,1,172)
Block(-10,35,2,172)
Block(-10,35,3,172)
Block(-10,36,-5,172)
Block(-10,36,-4,172)
Block(-10,36,-3,172)
Block(-10,36,-2,172)
Block(-10,36,-1,172)
Block(-10,36,0,172)
Block(-10,36,1,172)
Block(-10,36,2,172)
Block(-10,36,3,172)
Block(-10,37,-5,172)
Block(-10,37,-4,172)
Block(-10,37,-3,172)
Block(-10,37,-2,172)
Block(-10,37,-1,172)
Block(-10,37,0,172)
Block(-10,37,1,172)
Block(-10,37,2,172)
Block(-10,37,3,172)
Block(-10,38,-5,172)
Block(-10,38,-4,172)
Block(-10,38,-3,172)
Block(-10,38,-2,172)
Block(-10,38,-1,172)
Block(-10,38,0,172)
Block(-10,38,1,172)
Block(-10,38,2,172)
Block(-10,38,3,172)
Block(-10,39,-5,172)
Block(-10,39,-2,172)
Block(-10,39,-1,172)
Block(-10,39,0,172)
Block(-10,39,1,172)
Block(-10,39,2,172)
Block(-10,39,3,172)
Block(-10,40,-5,172)
Block(-10,40,-2,172)
Block(-10,40,-1,172)
Block(-10,40,0,172)
Block(-10,40,1,172)
Block(-10,40,2,172)
Block(-10,41,-5,172)
Block(-10,41,-2,172)
Block(-10,41,-1,172)
Block(-10,41,0,172)
Block(-10,41,1,172)
Block(-10,41,2,172)
Block(-10,42,-2,172)
Block(-10,42,-1,172)
Block(-10,42,0,172)
Block(-10,42,1,172)
Block(-10,42,2,172)
Block(-10,43,-2,172)
Block(-10,43,-1,172)
Block(-10,43,0,172)
Block(-10,43,1,172)
Block(-10,43,2,172)
Block(-10,44,-2,172)
Block(-10,44,-1,172)
Block(-10,44,0,172)
Block(-10,44,1,172)
Block(-10,44,2,172)
Block(-10,45,-2,172)
Block(-10,45,-1,172)
Block(-10,45,0,172)
Block(-10,45,1,172)
Block(-10,45,2,172)
Block(-10,46,-2,172)
Block(-10,46,-1,172)
Block(-10,46,0,172)
Block(-10,46,1,172)
Block(-10,46,2,172)
Block(-10,47,-1,172)
Block(-10,47,0,172)
Block(-10,47,1,172)
Block(-10,47,2,172)
Block(-10,48,-1,172)
Block(-10,48,0,172)
Block(-10,48,1,172)
Block(-10,48,2,172)
Block(-10,49,-1,172)
Block(-10,49,0,172)
Block(-10,49,1,172)
Block(-10,49,2,172)
Block(-10,50,-1,172)
Block(-10,50,0,172)
Block(-10,50,1,172)
Block(-10,50,2,172)
Block(-10,51,-1,172)
Block(-10,51,0,172)
Block(-10,51,1,172)
Block(-10,51,2,172)
Block(-10,52,-1,172)
Block(-10,52,0,172)
Block(-10,52,1,172)
Block(-10,52,2,172)
Block(-10,53,-1,172)
Block(-10,53,0,172)
Block(-10,53,1,172)
Block(-10,53,2,172)
Block(-10,54,-1,172)
Block(-10,54,0,172)
Block(-10,54,1,172)
Block(-10,54,2,172)
Block(-10,55,-1,172)
Block(-10,55,0,172)
Block(-10,55,1,172)
Block(-10,55,2,172)
Block(-10,56,-1,172)
Block(-10,56,0,172)
Block(-10,56,1,172)
Block(-10,57,-1,172)
Block(-10,57,1,172)
Block(-10,58,-1,172)
Block(-10,58,1,172)
Block(-10,59,-1,172)
Block(-10,59,1,172)
Block(-10,60,-1,172)
Block(-10,60,1,172)
Block(-9,0,-14,172)
Block(-9,0,-13,172)
Block(-9,0,-12,172)
Block(-9,0,-11,172)
Block(-9,0,-10,172)
Block(-9,0,-9,172)
Block(-9,0,-8,172)
Block(-9,0,-7,172)
Block(-9,0,-6,172)
Block(-9,0,-5,172)
Block(-9,0,-4,172)
Block(-9,0,-3,172)
Block(-9,0,-2,172)
Block(-9,0,-1,172)
Block(-9,0,0,172)
Block(-9,0,1,172)
Block(-9,0,2,172)
Block(-9,0,3,172)
Block(-9,0,4,172)
Block(-9,0,5,172)
Block(-9,0,6,172)
Block(-9,0,7,172)
Block(-9,0,8,172)
Block(-9,0,9,172)
Block(-9,0,10,172)
Block(-9,1,-14,172)
Block(-9,1,-13,172)
Block(-9,1,-12,172)
Block(-9,1,-11,172)
Block(-9,1,-10,172)
Block(-9,1,-9,172)
Block(-9,1,-8,172)
Block(-9,1,-7,172)
Block(-9,1,-6,172)
Block(-9,1,-5,172)
Block(-9,1,-4,172)
Block(-9,1,-3,172)
Block(-9,1,-2,172)
Block(-9,1,-1,172)
Block(-9,1,0,172)
Block(-9,1,1,172)
Block(-9,1,2,172)
Block(-9,1,3,172)
Block(-9,1,4,172)
Block(-9,1,5,172)
Block(-9,1,6,172)
Block(-9,1,7,172)
Block(-9,1,8,172)
Block(-9,1,9,172)
Block(-9,2,-13,172)
Block(-9,2,-12,172)
Block(-9,2,-11,172)
Block(-9,2,-10,172)
Block(-9,2,-9,172)
Block(-9,2,-8,172)
Block(-9,2,-7,172)
Block(-9,2,-6,172)
Block(-9,2,-5,172)
Block(-9,2,-4,172)
Block(-9,2,-3,172)
Block(-9,2,-2,172)
Block(-9,2,-1,172)
Block(-9,2,0,172)
Block(-9,2,1,172)
Block(-9,2,2,172)
Block(-9,2,3,172)
Block(-9,2,4,172)
Block(-9,2,5,172)
Block(-9,2,6,172)
Block(-9,2,7,172)
Block(-9,2,8,172)
Block(-9,2,9,172)
Block(-9,3,-13,172)
Block(-9,3,-12,172)
Block(-9,3,-11,172)
Block(-9,3,-10,172)
Block(-9,3,-9,172)
Block(-9,3,-8,172)
Block(-9,3,-7,172)
Block(-9,3,-6,172)
Block(-9,3,-5,172)
Block(-9,3,-4,172)
Block(-9,3,-3,172)
Block(-9,3,-2,172)
Block(-9,3,-1,172)
Block(-9,3,0,172)
Block(-9,3,1,172)
Block(-9,3,2,172)
Block(-9,3,3,172)
Block(-9,3,4,172)
Block(-9,3,5,172)
Block(-9,3,6,172)
Block(-9,3,7,172)
Block(-9,3,8,172)
Block(-9,4,-13,172)
Block(-9,4,-12,172)
Block(-9,4,-11,172)
Block(-9,4,-10,172)
Block(-9,4,-9,172)
Block(-9,4,-8,172)
Block(-9,4,-7,172)
Block(-9,4,-6,172)
Block(-9,4,-5,172)
Block(-9,4,-4,172)
Block(-9,4,-3,172)
Block(-9,4,-2,172)
Block(-9,4,-1,172)
Block(-9,4,0,172)
Block(-9,4,1,172)
Block(-9,4,2,172)
Block(-9,4,3,172)
Block(-9,4,4,172)
Block(-9,4,5,172)
Block(-9,4,6,172)
Block(-9,4,7,172)
Block(-9,4,8,172)
Block(-9,5,-13,172)
Block(-9,5,-12,172)
Block(-9,5,-11,172)
Block(-9,5,-10,172)
Block(-9,5,-9,172)
Block(-9,5,-8,172)
Block(-9,5,-7,172)
Block(-9,5,-6,172)
Block(-9,5,-5,172)
Block(-9,5,-4,172)
Block(-9,5,-3,172)
Block(-9,5,-2,172)
Block(-9,5,-1,172)
Block(-9,5,0,172)
Block(-9,5,1,172)
Block(-9,5,2,172)
Block(-9,5,3,172)
Block(-9,5,4,172)
Block(-9,5,5,172)
Block(-9,5,6,172)
Block(-9,5,7,172)
Block(-9,5,8,172)
Block(-9,6,-12,172)
Block(-9,6,-11,172)
Block(-9,6,-10,172)
Block(-9,6,-9,172)
Block(-9,6,-8,172)
Block(-9,6,-7,172)
Block(-9,6,-6,172)
Block(-9,6,-5,172)
Block(-9,6,-4,172)
Block(-9,6,-3,172)
Block(-9,6,-2,172)
Block(-9,6,-1,172)
Block(-9,6,0,172)
Block(-9,6,1,172)
Block(-9,6,2,172)
Block(-9,6,3,172)
Block(-9,6,4,172)
Block(-9,6,5,172)
Block(-9,6,6,172)
Block(-9,6,7,172)
Block(-9,6,8,172)
Block(-9,7,-12,172)
Block(-9,7,-11,172)
Block(-9,7,-10,172)
Block(-9,7,-9,172)
Block(-9,7,-8,172)
Block(-9,7,-7,172)
Block(-9,7,-6,172)
Block(-9,7,-5,172)
Block(-9,7,-4,172)
Block(-9,7,-3,172)
Block(-9,7,-2,172)
Block(-9,7,-1,172)
Block(-9,7,0,172)
Block(-9,7,1,172)
Block(-9,7,2,172)
Block(-9,7,3,172)
Block(-9,7,4,172)
Block(-9,7,5,172)
Block(-9,7,6,172)
Block(-9,7,7,172)
Block(-9,8,-12,172)
Block(-9,8,-11,172)
Block(-9,8,-10,172)
Block(-9,8,-9,172)
Block(-9,8,-8,172)
Block(-9,8,-7,172)
Block(-9,8,-6,172)
Block(-9,8,-5,172)
Block(-9,8,-4,172)
Block(-9,8,-3,172)
Block(-9,8,-2,172)
Block(-9,8,-1,172)
Block(-9,8,0,172)
Block(-9,8,1,172)
Block(-9,8,2,172)
Block(-9,8,3,172)
Block(-9,8,4,172)
Block(-9,8,5,172)
Block(-9,8,6,172)
Block(-9,8,7,172)
Block(-9,9,-12,172)
Block(-9,9,-11,172)
Block(-9,9,-10,172)
Block(-9,9,-9,172)
Block(-9,9,-8,172)
Block(-9,9,-7,172)
Block(-9,9,-6,172)
Block(-9,9,-5,172)
Block(-9,9,-4,172)
Block(-9,9,-3,172)
Block(-9,9,-2,172)
Block(-9,9,-1,172)
Block(-9,9,0,172)
Block(-9,9,1,172)
Block(-9,9,2,172)
Block(-9,9,3,172)
Block(-9,9,4,172)
Block(-9,9,5,172)
Block(-9,9,6,172)
Block(-9,9,7,172)
Block(-9,10,-12,172)
Block(-9,10,-11,172)
Block(-9,10,-10,172)
Block(-9,10,-9,172)
Block(-9,10,-8,172)
Block(-9,10,-7,172)
Block(-9,10,-6,172)
Block(-9,10,-5,172)
Block(-9,10,-4,172)
Block(-9,10,-3,172)
Block(-9,10,-2,172)
Block(-9,10,-1,172)
Block(-9,10,0,172)
Block(-9,10,1,172)
Block(-9,10,2,172)
Block(-9,10,3,172)
Block(-9,10,4,172)
Block(-9,10,5,172)
Block(-9,10,6,172)
Block(-9,10,7,172)
Block(-9,11,-12,172)
Block(-9,11,-11,172)
Block(-9,11,-10,172)
Block(-9,11,-9,172)
Block(-9,11,-8,172)
Block(-9,11,-7,172)
Block(-9,11,-6,172)
Block(-9,11,-5,172)
Block(-9,11,-4,172)
Block(-9,11,-3,172)
Block(-9,11,-2,172)
Block(-9,11,-1,172)
Block(-9,11,0,172)
Block(-9,11,1,172)
Block(-9,11,2,172)
Block(-9,11,3,172)
Block(-9,11,4,172)
Block(-9,11,5,172)
Block(-9,11,6,172)
Block(-9,12,-11,172)
Block(-9,12,-10,172)
Block(-9,12,-9,172)
Block(-9,12,-8,172)
Block(-9,12,-7,172)
Block(-9,12,-6,172)
Block(-9,12,-5,172)
Block(-9,12,-4,172)
Block(-9,12,-3,172)
Block(-9,12,-2,172)
Block(-9,12,-1,172)
Block(-9,12,0,172)
Block(-9,12,1,172)
Block(-9,12,2,172)
Block(-9,12,3,172)
Block(-9,12,4,172)
Block(-9,12,5,172)
Block(-9,12,6,172)
Block(-9,13,-11,172)
Block(-9,13,-10,172)
Block(-9,13,-9,172)
Block(-9,13,-8,172)
Block(-9,13,-7,172)
Block(-9,13,-6,172)
Block(-9,13,-5,172)
Block(-9,13,-4,172)
Block(-9,13,-3,172)
Block(-9,13,-2,172)
Block(-9,13,-1,172)
Block(-9,13,0,172)
Block(-9,13,1,172)
Block(-9,13,2,172)
Block(-9,13,3,172)
Block(-9,13,4,172)
Block(-9,13,5,172)
Block(-9,13,6,172)
Block(-9,14,-10,172)
Block(-9,14,-9,172)
Block(-9,14,-8,172)
Block(-9,14,-7,172)
Block(-9,14,-6,172)
Block(-9,14,-5,172)
Block(-9,14,-4,172)
Block(-9,14,-3,172)
Block(-9,14,-2,172)
Block(-9,14,-1,172)
Block(-9,14,0,172)
Block(-9,14,1,172)
Block(-9,14,2,172)
Block(-9,14,3,172)
Block(-9,14,4,172)
Block(-9,14,5,172)
Block(-9,14,6,172)
Block(-9,15,-10,172)
Block(-9,15,-9,172)
Block(-9,15,-8,172)
Block(-9,15,-7,172)
Block(-9,15,-6,172)
Block(-9,15,-5,172)
Block(-9,15,-4,172)
Block(-9,15,-3,172)
Block(-9,15,-2,172)
Block(-9,15,-1,172)
Block(-9,15,0,172)
Block(-9,15,1,172)
Block(-9,15,2,172)
Block(-9,15,3,172)
Block(-9,15,4,172)
Block(-9,15,5,172)
Block(-9,15,6,172)
Block(-9,16,-10,172)
Block(-9,16,-9,172)
Block(-9,16,-8,172)
Block(-9,16,-7,172)
Block(-9,16,-6,172)
Block(-9,16,-5,172)
Block(-9,16,-4,172)
Block(-9,16,-3,172)
Block(-9,16,-2,172)
Block(-9,16,-1,172)
Block(-9,16,0,172)
Block(-9,16,1,172)
Block(-9,16,2,172)
Block(-9,16,3,172)
Block(-9,16,4,172)
Block(-9,16,5,172)
Block(-9,16,6,172)
Block(-9,17,-10,172)
Block(-9,17,-9,172)
Block(-9,17,-8,172)
Block(-9,17,-7,172)
Block(-9,17,-6,172)
Block(-9,17,-5,172)
Block(-9,17,-4,172)
Block(-9,17,-3,172)
Block(-9,17,-2,172)
Block(-9,17,-1,172)
Block(-9,17,0,172)
Block(-9,17,1,172)
Block(-9,17,2,172)
Block(-9,17,3,172)
Block(-9,17,4,172)
Block(-9,17,5,172)
Block(-9,18,-10,172)
Block(-9,18,-9,172)
Block(-9,18,-8,172)
Block(-9,18,-7,172)
Block(-9,18,-6,172)
Block(-9,18,-5,172)
Block(-9,18,-4,172)
Block(-9,18,-3,172)
Block(-9,18,-2,172)
Block(-9,18,-1,172)
Block(-9,18,0,172)
Block(-9,18,1,172)
Block(-9,18,2,172)
Block(-9,18,3,172)
Block(-9,18,4,172)
Block(-9,18,5,172)
Block(-9,19,-10,172)
Block(-9,19,-9,172)
Block(-9,19,-8,172)
Block(-9,19,-7,172)
Block(-9,19,-6,172)
Block(-9,19,-5,172)
Block(-9,19,-4,172)
Block(-9,19,-3,172)
Block(-9,19,-2,172)
Block(-9,19,-1,172)
Block(-9,19,0,172)
Block(-9,19,1,172)
Block(-9,19,2,172)
Block(-9,19,3,172)
Block(-9,19,4,172)
Block(-9,19,5,172)
Block(-9,20,-10,172)
Block(-9,20,-9,172)
Block(-9,20,-8,172)
Block(-9,20,-7,172)
Block(-9,20,-6,172)
Block(-9,20,-5,172)
Block(-9,20,-4,172)
Block(-9,20,-3,172)
Block(-9,20,-2,172)
Block(-9,20,-1,172)
Block(-9,20,0,172)
Block(-9,20,1,172)
Block(-9,20,2,172)
Block(-9,20,3,172)
Block(-9,20,4,172)
Block(-9,20,5,172)
Block(-9,21,-10,172)
Block(-9,21,-9,172)
Block(-9,21,-8,172)
Block(-9,21,-7,172)
Block(-9,21,-6,172)
Block(-9,21,-5,172)
Block(-9,21,-4,172)
Block(-9,21,-3,172)
Block(-9,21,-2,172)
Block(-9,21,-1,172)
Block(-9,21,0,172)
Block(-9,21,1,172)
Block(-9,21,2,172)
Block(-9,21,3,172)
Block(-9,21,4,172)
Block(-9,21,5,172)
Block(-9,22,-9,172)
Block(-9,22,-8,172)
Block(-9,22,-7,172)
Block(-9,22,-6,172)
Block(-9,22,-5,172)
Block(-9,22,-4,172)
Block(-9,22,-3,172)
Block(-9,22,-2,172)
Block(-9,22,-1,172)
Block(-9,22,0,172)
Block(-9,22,1,172)
Block(-9,22,2,172)
Block(-9,22,3,172)
Block(-9,22,4,172)
Block(-9,22,5,172)
Block(-9,23,-9,172)
Block(-9,23,-8,172)
Block(-9,23,-7,172)
Block(-9,23,-6,172)
Block(-9,23,-5,172)
Block(-9,23,-4,172)
Block(-9,23,-3,172)
Block(-9,23,-2,172)
Block(-9,23,-1,172)
Block(-9,23,0,172)
Block(-9,23,1,172)
Block(-9,23,2,172)
Block(-9,23,3,172)
Block(-9,23,4,172)
Block(-9,23,5,172)
Block(-9,24,-9,172)
Block(-9,24,-8,172)
Block(-9,24,-7,172)
Block(-9,24,-6,172)
Block(-9,24,-5,172)
Block(-9,24,-4,172)
Block(-9,24,-3,172)
Block(-9,24,-2,172)
Block(-9,24,-1,172)
Block(-9,24,0,172)
Block(-9,24,1,172)
Block(-9,24,2,172)
Block(-9,24,3,172)
Block(-9,24,4,172)
Block(-9,25,-9,172)
Block(-9,25,-8,172)
Block(-9,25,-7,172)
Block(-9,25,-6,172)
Block(-9,25,-5,172)
Block(-9,25,-4,172)
Block(-9,25,-3,172)
Block(-9,25,-2,172)
Block(-9,25,-1,172)
Block(-9,25,0,172)
Block(-9,25,1,172)
Block(-9,25,2,172)
Block(-9,25,3,172)
Block(-9,25,4,172)
Block(-9,26,-9,172)
Block(-9,26,-8,172)
Block(-9,26,-7,172)
Block(-9,26,-6,172)
Block(-9,26,-5,172)
Block(-9,26,-4,172)
Block(-9,26,-3,172)
Block(-9,26,-2,172)
Block(-9,26,-1,172)
Block(-9,26,0,172)
Block(-9,26,1,172)
Block(-9,26,2,172)
Block(-9,26,3,172)
Block(-9,26,4,172)
Block(-9,27,-8,172)
Block(-9,27,-7,172)
Block(-9,27,-6,172)
Block(-9,27,-5,172)
Block(-9,27,-4,172)
Block(-9,27,-3,172)
Block(-9,27,-2,172)
Block(-9,27,-1,172)
Block(-9,27,0,172)
Block(-9,27,1,172)
Block(-9,27,2,172)
Block(-9,27,3,172)
Block(-9,27,4,172)
Block(-9,28,-8,172)
Block(-9,28,-7,172)
Block(-9,28,-6,172)
Block(-9,28,-5,172)
Block(-9,28,-4,172)
Block(-9,28,-3,172)
Block(-9,28,-2,172)
Block(-9,28,-1,172)
Block(-9,28,0,172)
Block(-9,28,1,172)
Block(-9,28,2,172)
Block(-9,28,3,172)
Block(-9,28,4,172)
Block(-9,29,-8,172)
Block(-9,29,-7,172)
Block(-9,29,-6,172)
Block(-9,29,-5,172)
Block(-9,29,-4,172)
Block(-9,29,-3,172)
Block(-9,29,-2,172)
Block(-9,29,-1,172)
Block(-9,29,0,172)
Block(-9,29,1,172)
Block(-9,29,2,172)
Block(-9,29,3,172)
Block(-9,29,4,172)
Block(-9,30,-8,172)
Block(-9,30,-7,172)
Block(-9,30,-6,172)
Block(-9,30,-5,172)
Block(-9,30,-4,172)
Block(-9,30,-3,172)
Block(-9,30,-2,172)
Block(-9,30,-1,172)
Block(-9,30,0,172)
Block(-9,30,1,172)
Block(-9,30,2,172)
Block(-9,30,3,172)
Block(-9,30,4,172)
Block(-9,31,-8,172)
Block(-9,31,-7,172)
Block(-9,31,-6,172)
Block(-9,31,-5,172)
Block(-9,31,-4,172)
Block(-9,31,-3,172)
Block(-9,31,-2,172)
Block(-9,31,-1,172)
Block(-9,31,0,172)
Block(-9,31,1,172)
Block(-9,31,2,172)
Block(-9,31,3,172)
Block(-9,31,4,172)
Block(-9,32,-8,172)
Block(-9,32,-7,172)
Block(-9,32,-6,172)
Block(-9,32,-5,172)
Block(-9,32,-4,172)
Block(-9,32,-3,172)
Block(-9,32,-2,172)
Block(-9,32,-1,172)
Block(-9,32,0,172)
Block(-9,32,1,172)
Block(-9,32,2,172)
Block(-9,32,3,172)
Block(-9,32,4,172)
Block(-9,33,-8,172)
Block(-9,33,-7,172)
Block(-9,33,-6,172)
Block(-9,33,-5,172)
Block(-9,33,-4,172)
Block(-9,33,-3,172)
Block(-9,33,-2,172)
Block(-9,33,-1,172)
Block(-9,33,0,172)
Block(-9,33,1,172)
Block(-9,33,2,172)
Block(-9,33,3,172)
Block(-9,33,4,172)
Block(-9,34,-7,172)
Block(-9,34,-6,172)
Block(-9,34,-5,172)
Block(-9,34,-4,172)
Block(-9,34,-3,172)
Block(-9,34,-2,172)
Block(-9,34,-1,172)
Block(-9,34,0,172)
Block(-9,34,1,172)
Block(-9,34,2,172)
Block(-9,34,3,172)
Block(-9,34,4,172)
Block(-9,35,-7,172)
Block(-9,35,-6,172)
Block(-9,35,-5,172)
Block(-9,35,-4,172)
Block(-9,35,-3,172)
Block(-9,35,-2,172)
Block(-9,35,-1,172)
Block(-9,35,0,172)
Block(-9,35,1,172)
Block(-9,35,2,172)
Block(-9,35,3,172)
Block(-9,35,4,172)
Block(-9,36,-7,172)
Block(-9,36,-6,172)
Block(-9,36,-5,172)
Block(-9,36,-4,172)
Block(-9,36,-3,172)
Block(-9,36,-2,172)
Block(-9,36,-1,172)
Block(-9,36,0,172)
Block(-9,36,1,172)
Block(-9,36,2,172)
Block(-9,36,3,172)
Block(-9,36,4,172)
Block(-9,37,-7,172)
Block(-9,37,-6,172)
Block(-9,37,-5,172)
Block(-9,37,-4,172)
Block(-9,37,-3,172)
Block(-9,37,-2,172)
Block(-9,37,-1,172)
Block(-9,37,0,172)
Block(-9,37,1,172)
Block(-9,37,2,172)
Block(-9,37,3,172)
Block(-9,37,4,172)
Block(-9,38,-7,172)
Block(-9,38,-6,172)
Block(-9,38,-5,172)
Block(-9,38,-4,172)
Block(-9,38,-3,172)
Block(-9,38,-2,172)
Block(-9,38,-1,172)
Block(-9,38,0,172)
Block(-9,38,1,172)
Block(-9,38,2,172)
Block(-9,38,3,172)
Block(-9,38,4,172)
Block(-9,39,-7,172)
Block(-9,39,-6,172)
Block(-9,39,-5,172)
Block(-9,39,-4,172)
Block(-9,39,-3,172)
Block(-9,39,-2,172)
Block(-9,39,-1,172)
Block(-9,39,0,172)
Block(-9,39,1,172)
Block(-9,39,2,172)
Block(-9,39,3,172)
Block(-9,39,4,172)
Block(-9,40,-7,172)
Block(-9,40,-6,172)
Block(-9,40,-5,172)
Block(-9,40,-4,172)
Block(-9,40,-3,172)
Block(-9,40,-2,172)
Block(-9,40,-1,172)
Block(-9,40,0,172)
Block(-9,40,1,172)
Block(-9,40,2,172)
Block(-9,40,3,172)
Block(-9,40,4,172)
Block(-9,41,-7,172)
Block(-9,41,-5,172)
Block(-9,41,-4,172)
Block(-9,41,-3,172)
Block(-9,41,-2,172)
Block(-9,41,-1,172)
Block(-9,41,0,172)
Block(-9,41,1,172)
Block(-9,41,2,172)
Block(-9,41,3,172)
Block(-9,41,4,172)
Block(-9,42,-7,172)
Block(-9,42,-5,172)
Block(-9,42,-4,172)
Block(-9,42,-3,172)
Block(-9,42,-2,172)
Block(-9,42,-1,172)
Block(-9,42,0,172)
Block(-9,42,1,172)
Block(-9,42,2,172)
Block(-9,42,3,172)
Block(-9,42,4,172)
Block(-9,43,-7,172)
Block(-9,43,-5,172)
Block(-9,43,-4,172)
Block(-9,43,-3,172)
Block(-9,43,-2,172)
Block(-9,43,-1,172)
Block(-9,43,0,172)
Block(-9,43,1,172)
Block(-9,43,2,172)
Block(-9,43,3,172)
Block(-9,43,4,172)
Block(-9,44,-5,172)
Block(-9,44,-4,172)
Block(-9,44,-3,172)
Block(-9,44,-2,172)
Block(-9,44,-1,172)
Block(-9,44,0,172)
Block(-9,44,1,172)
Block(-9,44,2,172)
Block(-9,44,3,172)
Block(-9,45,-5,172)
Block(-9,45,-4,172)
Block(-9,45,-3,172)
Block(-9,45,-2,172)
Block(-9,45,-1,172)
Block(-9,45,0,172)
Block(-9,45,1,172)
Block(-9,45,2,172)
Block(-9,45,3,172)
Block(-9,46,-5,172)
Block(-9,46,-4,172)
Block(-9,46,-3,172)
Block(-9,46,-2,172)
Block(-9,46,-1,172)
Block(-9,46,0,172)
Block(-9,46,1,172)
Block(-9,46,2,172)
Block(-9,46,3,172)
Block(-9,47,-5,172)
Block(-9,47,-4,172)
Block(-9,47,-3,172)
Block(-9,47,-2,172)
Block(-9,47,-1,172)
Block(-9,47,0,172)
Block(-9,47,1,172)
Block(-9,47,2,172)
Block(-9,47,3,172)
Block(-9,48,-5,172)
Block(-9,48,-4,172)
Block(-9,48,-3,172)
Block(-9,48,-2,172)
Block(-9,48,-1,172)
Block(-9,48,0,172)
Block(-9,48,1,172)
Block(-9,48,2,172)
Block(-9,48,3,172)
Block(-9,49,-5,172)
Block(-9,49,-4,172)
Block(-9,49,-3,172)
Block(-9,49,-2,172)
Block(-9,49,-1,172)
Block(-9,49,0,172)
Block(-9,49,1,172)
Block(-9,49,2,172)
Block(-9,49,3,172)
Block(-9,50,-5,172)
Block(-9,50,-4,172)
Block(-9,50,-3,172)
Block(-9,50,-2,172)
Block(-9,50,-1,172)
Block(-9,50,0,172)
Block(-9,50,1,172)
Block(-9,50,2,172)
Block(-9,50,3,172)
Block(-9,51,-5,172)
Block(-9,51,-4,172)
Block(-9,51,-3,172)
Block(-9,51,-2,172)
Block(-9,51,-1,172)
Block(-9,51,0,172)
Block(-9,51,1,172)
Block(-9,51,2,172)
Block(-9,51,3,172)
Block(-9,52,-5,172)
Block(-9,52,-4,172)
Block(-9,52,-3,172)
Block(-9,52,-2,172)
Block(-9,52,-1,172)
Block(-9,52,0,172)
Block(-9,52,1,172)
Block(-9,52,2,172)
Block(-9,52,3,172)
Block(-9,53,-5,172)
Block(-9,53,-4,172)
Block(-9,53,-3,172)
Block(-9,53,-2,172)
Block(-9,53,-1,172)
Block(-9,53,0,172)
Block(-9,53,1,172)
Block(-9,53,2,172)
Block(-9,53,3,172)
Block(-9,54,-5,172)
Block(-9,54,-4,172)
Block(-9,54,-3,172)
Block(-9,54,-2,172)
Block(-9,54,-1,172)
Block(-9,54,0,172)
Block(-9,54,1,172)
Block(-9,54,2,172)
Block(-9,54,3,172)
Block(-9,55,-5,172)
Block(-9,55,-4,172)
Block(-9,55,-3,172)
Block(-9,55,-2,172)
Block(-9,55,-1,172)
Block(-9,55,0,172)
Block(-9,55,1,172)
Block(-9,55,2,172)
Block(-9,55,3,172)
Block(-9,56,-5,172)
Block(-9,56,-4,172)
Block(-9,56,-3,172)
Block(-9,56,-2,172)
Block(-9,56,-1,172)
Block(-9,56,0,172)
Block(-9,56,1,172)
Block(-9,56,2,172)
Block(-9,56,3,172)
Block(-9,57,-5,172)
Block(-9,57,-4,172)
Block(-9,57,-3,172)
Block(-9,57,-2,172)
Block(-9,57,-1,172)
Block(-9,57,0,172)
Block(-9,57,1,172)
Block(-9,57,2,172)
Block(-9,57,3,172)
Block(-9,58,-5,172)
Block(-9,58,-4,172)
Block(-9,58,-3,172)
Block(-9,58,-2,172)
Block(-9,58,-1,172)
Block(-9,58,0,172)
Block(-9,58,1,172)
Block(-9,58,2,172)
Block(-9,58,3,172)
Block(-9,59,-5,172)
Block(-9,59,-4,172)
Block(-9,59,-3,172)
Block(-9,59,-2,172)
Block(-9,59,-1,172)
Block(-9,59,0,172)
Block(-9,59,1,172)
Block(-9,59,2,172)
Block(-9,59,3,172)
Block(-9,60,-5,172)
Block(-9,60,-4,172)
Block(-9,60,-3,172)
Block(-9,60,-2,172)
Block(-9,60,-1,172)
Block(-9,60,0,172)
Block(-9,60,1,172)
Block(-9,60,2,172)
Block(-9,60,3,172)
Block(-8,0,-14,172)
Block(-8,0,-13,172)
Block(-8,0,-12,172)
Block(-8,0,-11,172)
Block(-8,0,-10,172)
Block(-8,0,-9,172)
Block(-8,0,-8,172)
Block(-8,0,-7,172)
Block(-8,0,-6,172)
Block(-8,0,-5,172)
Block(-8,0,-4,172)
Block(-8,0,-3,172)
Block(-8,0,-2,172)
Block(-8,0,-1,172)
Block(-8,0,0,172)
Block(-8,0,1,172)
Block(-8,0,2,172)
Block(-8,0,3,172)
Block(-8,0,4,172)
Block(-8,0,5,172)
Block(-8,0,6,172)
Block(-8,0,7,172)
Block(-8,0,8,172)
Block(-8,0,9,172)
Block(-8,0,10,172)
Block(-8,1,-13,172)
Block(-8,1,-12,172)
Block(-8,1,-11,172)
Block(-8,1,-10,172)
Block(-8,1,-9,172)
Block(-8,1,-8,172)
Block(-8,1,-7,172)
Block(-8,1,-6,172)
Block(-8,1,-5,172)
Block(-8,1,-4,172)
Block(-8,1,-3,172)
Block(-8,1,-2,172)
Block(-8,1,-1,172)
Block(-8,1,0,172)
Block(-8,1,1,172)
Block(-8,1,2,172)
Block(-8,1,3,172)
Block(-8,1,4,172)
Block(-8,1,5,172)
Block(-8,1,6,172)
Block(-8,1,7,172)
Block(-8,1,8,172)
Block(-8,1,9,172)
Block(-8,1,10,172)
Block(-8,2,-12,172)
Block(-8,2,-11,172)
Block(-8,2,-10,172)
Block(-8,2,-9,172)
Block(-8,2,-8,172)
Block(-8,2,-7,172)
Block(-8,2,-6,172)
Block(-8,2,-5,172)
Block(-8,2,-4,172)
Block(-8,2,-3,172)
Block(-8,2,-2,172)
Block(-8,2,-1,172)
Block(-8,2,0,172)
Block(-8,2,1,172)
Block(-8,2,2,172)
Block(-8,2,3,172)
Block(-8,2,4,172)
Block(-8,2,5,172)
Block(-8,2,6,172)
Block(-8,2,7,172)
Block(-8,2,8,172)
Block(-8,2,9,172)
Block(-8,2,10,172)
Block(-8,3,-12,172)
Block(-8,3,-11,172)
Block(-8,3,-10,172)
Block(-8,3,-9,172)
Block(-8,3,-8,172)
Block(-8,3,-7,172)
Block(-8,3,-6,172)
Block(-8,3,-5,172)
Block(-8,3,-4,172)
Block(-8,3,-3,172)
Block(-8,3,-2,172)
Block(-8,3,-1,172)
Block(-8,3,0,172)
Block(-8,3,1,172)
Block(-8,3,2,172)
Block(-8,3,3,172)
Block(-8,3,4,172)
Block(-8,3,5,172)
Block(-8,3,6,172)
Block(-8,3,7,172)
Block(-8,3,8,172)
Block(-8,3,9,172)
Block(-8,3,10,172)
Block(-8,4,-11,172)
Block(-8,4,-10,172)
Block(-8,4,-9,172)
Block(-8,4,-8,172)
Block(-8,4,-7,172)
Block(-8,4,-6,172)
Block(-8,4,-5,172)
Block(-8,4,-4,172)
Block(-8,4,-3,172)
Block(-8,4,-2,172)
Block(-8,4,-1,172)
Block(-8,4,0,172)
Block(-8,4,1,172)
Block(-8,4,2,172)
Block(-8,4,3,172)
Block(-8,4,4,172)
Block(-8,4,5,172)
Block(-8,4,6,172)
Block(-8,4,7,172)
Block(-8,4,8,172)
Block(-8,4,9,172)
Block(-8,4,10,172)
Block(-8,5,-11,172)
Block(-8,5,-10,172)
Block(-8,5,-9,172)
Block(-8,5,-8,172)
Block(-8,5,-7,172)
Block(-8,5,-6,172)
Block(-8,5,-5,172)
Block(-8,5,-4,172)
Block(-8,5,-3,172)
Block(-8,5,-2,172)
Block(-8,5,-1,172)
Block(-8,5,0,172)
Block(-8,5,1,172)
Block(-8,5,2,172)
Block(-8,5,3,172)
Block(-8,5,4,172)
Block(-8,5,5,172)
Block(-8,5,6,172)
Block(-8,5,7,172)
Block(-8,5,8,172)
Block(-8,5,9,172)
Block(-8,6,-11,172)
Block(-8,6,-10,172)
Block(-8,6,-9,172)
Block(-8,6,-8,172)
Block(-8,6,-7,172)
Block(-8,6,-6,172)
Block(-8,6,-5,172)
Block(-8,6,-4,172)
Block(-8,6,-3,172)
Block(-8,6,-2,172)
Block(-8,6,-1,172)
Block(-8,6,0,172)
Block(-8,6,1,172)
Block(-8,6,2,172)
Block(-8,6,3,172)
Block(-8,6,4,172)
Block(-8,6,5,172)
Block(-8,6,6,172)
Block(-8,6,7,172)
Block(-8,6,8,172)
Block(-8,6,9,172)
Block(-8,7,-10,172)
Block(-8,7,-9,172)
Block(-8,7,-8,172)
Block(-8,7,-7,172)
Block(-8,7,-6,172)
Block(-8,7,-5,172)
Block(-8,7,-4,172)
Block(-8,7,-3,172)
Block(-8,7,-2,172)
Block(-8,7,-1,172)
Block(-8,7,0,172)
Block(-8,7,1,172)
Block(-8,7,2,172)
Block(-8,7,3,172)
Block(-8,7,4,172)
Block(-8,7,5,172)
Block(-8,7,6,172)
Block(-8,7,7,172)
Block(-8,7,8,172)
Block(-8,7,9,172)
Block(-8,8,-10,172)
Block(-8,8,-9,172)
Block(-8,8,-8,172)
Block(-8,8,-7,172)
Block(-8,8,-6,172)
Block(-8,8,-5,172)
Block(-8,8,-4,172)
Block(-8,8,-3,172)
Block(-8,8,-2,172)
Block(-8,8,-1,172)
Block(-8,8,0,172)
Block(-8,8,1,172)
Block(-8,8,2,172)
Block(-8,8,3,172)
Block(-8,8,4,172)
Block(-8,8,5,172)
Block(-8,8,6,172)
Block(-8,8,7,172)
Block(-8,8,8,172)
Block(-8,9,-10,172)
Block(-8,9,-9,172)
Block(-8,9,-8,172)
Block(-8,9,-7,172)
Block(-8,9,-6,172)
Block(-8,9,-5,172)
Block(-8,9,-4,172)
Block(-8,9,-3,172)
Block(-8,9,-2,172)
Block(-8,9,-1,172)
Block(-8,9,0,172)
Block(-8,9,1,172)
Block(-8,9,2,172)
Block(-8,9,3,172)
Block(-8,9,4,172)
Block(-8,9,5,172)
Block(-8,9,6,172)
Block(-8,9,7,172)
Block(-8,9,8,172)
Block(-8,10,-10,172)
Block(-8,10,-9,172)
Block(-8,10,-8,172)
Block(-8,10,-7,172)
Block(-8,10,-6,172)
Block(-8,10,-5,172)
Block(-8,10,-4,172)
Block(-8,10,-3,172)
Block(-8,10,-2,172)
Block(-8,10,-1,172)
Block(-8,10,0,172)
Block(-8,10,1,172)
Block(-8,10,2,172)
Block(-8,10,3,172)
Block(-8,10,4,172)
Block(-8,10,5,172)
Block(-8,10,6,172)
Block(-8,10,7,172)
Block(-8,10,8,172)
Block(-8,11,-10,172)
Block(-8,11,-9,172)
Block(-8,11,-8,172)
Block(-8,11,-7,172)
Block(-8,11,-6,172)
Block(-8,11,-5,172)
Block(-8,11,-4,172)
Block(-8,11,-3,172)
Block(-8,11,-2,172)
Block(-8,11,-1,172)
Block(-8,11,0,172)
Block(-8,11,1,172)
Block(-8,11,2,172)
Block(-8,11,3,172)
Block(-8,11,4,172)
Block(-8,11,5,172)
Block(-8,11,6,172)
Block(-8,11,7,172)
Block(-8,11,8,172)
Block(-8,12,-10,172)
Block(-8,12,-9,172)
Block(-8,12,-8,172)
Block(-8,12,-7,172)
Block(-8,12,-6,172)
Block(-8,12,-5,172)
Block(-8,12,-4,172)
Block(-8,12,-3,172)
Block(-8,12,-2,172)
Block(-8,12,-1,172)
Block(-8,12,0,172)
Block(-8,12,1,172)
Block(-8,12,2,172)
Block(-8,12,3,172)
Block(-8,12,4,172)
Block(-8,12,5,172)
Block(-8,12,6,172)
Block(-8,12,7,172)
Block(-8,13,-10,172)
Block(-8,13,-9,172)
Block(-8,13,-8,172)
Block(-8,13,-7,172)
Block(-8,13,-6,172)
Block(-8,13,-5,172)
Block(-8,13,-4,172)
Block(-8,13,-3,172)
Block(-8,13,-2,172)
Block(-8,13,-1,172)
Block(-8,13,0,172)
Block(-8,13,1,172)
Block(-8,13,2,172)
Block(-8,13,3,172)
Block(-8,13,4,172)
Block(-8,13,5,172)
Block(-8,13,6,172)
Block(-8,13,7,172)
Block(-8,14,-10,172)
Block(-8,14,-9,172)
Block(-8,14,-8,172)
Block(-8,14,-7,172)
Block(-8,14,-6,172)
Block(-8,14,-5,172)
Block(-8,14,-4,172)
Block(-8,14,-3,172)
Block(-8,14,-2,172)
Block(-8,14,-1,172)
Block(-8,14,0,172)
Block(-8,14,1,172)
Block(-8,14,2,172)
Block(-8,14,3,172)
Block(-8,14,4,172)
Block(-8,14,5,172)
Block(-8,14,6,172)
Block(-8,14,7,172)
Block(-8,15,-10,172)
Block(-8,15,-9,172)
Block(-8,15,-8,172)
Block(-8,15,-7,172)
Block(-8,15,-6,172)
Block(-8,15,-5,172)
Block(-8,15,-4,172)
Block(-8,15,-3,172)
Block(-8,15,-2,172)
Block(-8,15,-1,172)
Block(-8,15,0,172)
Block(-8,15,1,172)
Block(-8,15,2,172)
Block(-8,15,3,172)
Block(-8,15,4,172)
Block(-8,15,5,172)
Block(-8,15,6,172)
Block(-8,15,7,172)
Block(-8,16,-10,172)
Block(-8,16,-9,172)
Block(-8,16,-8,172)
Block(-8,16,-7,172)
Block(-8,16,-6,172)
Block(-8,16,-5,172)
Block(-8,16,-4,172)
Block(-8,16,-3,172)
Block(-8,16,-2,172)
Block(-8,16,-1,172)
Block(-8,16,0,172)
Block(-8,16,1,172)
Block(-8,16,2,172)
Block(-8,16,3,172)
Block(-8,16,4,172)
Block(-8,16,5,172)
Block(-8,16,6,172)
Block(-8,16,7,172)
Block(-8,17,-10,172)
Block(-8,17,-9,172)
Block(-8,17,-8,172)
Block(-8,17,-7,172)
Block(-8,17,-6,172)
Block(-8,17,-5,172)
Block(-8,17,-4,172)
Block(-8,17,-3,172)
Block(-8,17,-2,172)
Block(-8,17,-1,172)
Block(-8,17,0,172)
Block(-8,17,1,172)
Block(-8,17,2,172)
Block(-8,17,3,172)
Block(-8,17,4,172)
Block(-8,17,5,172)
Block(-8,17,6,172)
Block(-8,17,7,172)
Block(-8,18,-10,172)
Block(-8,18,-9,172)
Block(-8,18,-8,172)
Block(-8,18,-7,172)
Block(-8,18,-6,172)
Block(-8,18,-5,172)
Block(-8,18,-4,172)
Block(-8,18,-3,172)
Block(-8,18,-2,172)
Block(-8,18,-1,172)
Block(-8,18,0,172)
Block(-8,18,1,172)
Block(-8,18,2,172)
Block(-8,18,3,172)
Block(-8,18,4,172)
Block(-8,18,5,172)
Block(-8,18,6,172)
Block(-8,18,7,172)
Block(-8,19,-10,172)
Block(-8,19,-9,172)
Block(-8,19,-8,172)
Block(-8,19,-7,172)
Block(-8,19,-6,172)
Block(-8,19,-5,172)
Block(-8,19,-4,172)
Block(-8,19,-3,172)
Block(-8,19,-2,172)
Block(-8,19,-1,172)
Block(-8,19,0,172)
Block(-8,19,1,172)
Block(-8,19,2,172)
Block(-8,19,3,172)
Block(-8,19,4,172)
Block(-8,19,5,172)
Block(-8,19,6,172)
Block(-8,19,7,172)
Block(-8,20,-10,172)
Block(-8,20,-9,172)
Block(-8,20,-8,172)
Block(-8,20,-7,172)
Block(-8,20,-6,172)
Block(-8,20,-5,172)
Block(-8,20,-4,172)
Block(-8,20,-3,172)
Block(-8,20,-2,172)
Block(-8,20,-1,172)
Block(-8,20,0,172)
Block(-8,20,1,172)
Block(-8,20,2,172)
Block(-8,20,3,172)
Block(-8,20,4,172)
Block(-8,20,5,172)
Block(-8,20,6,172)
Block(-8,20,7,172)
Block(-8,21,-10,172)
Block(-8,21,-9,172)
Block(-8,21,-8,172)
Block(-8,21,-7,172)
Block(-8,21,-6,172)
Block(-8,21,-5,172)
Block(-8,21,-4,172)
Block(-8,21,-3,172)
Block(-8,21,-2,172)
Block(-8,21,-1,172)
Block(-8,21,0,172)
Block(-8,21,1,172)
Block(-8,21,2,172)
Block(-8,21,3,172)
Block(-8,21,4,172)
Block(-8,21,5,172)
Block(-8,21,6,172)
Block(-8,21,7,172)
Block(-8,22,-10,172)
Block(-8,22,-9,172)
Block(-8,22,-8,172)
Block(-8,22,-7,172)
Block(-8,22,-6,172)
Block(-8,22,-5,172)
Block(-8,22,-4,172)
Block(-8,22,-3,172)
Block(-8,22,-2,172)
Block(-8,22,-1,172)
Block(-8,22,0,172)
Block(-8,22,1,172)
Block(-8,22,2,172)
Block(-8,22,3,172)
Block(-8,22,4,172)
Block(-8,22,5,172)
Block(-8,22,6,172)
Block(-8,23,-9,172)
Block(-8,23,-8,172)
Block(-8,23,-7,172)
Block(-8,23,-6,172)
Block(-8,23,-5,172)
Block(-8,23,-4,172)
Block(-8,23,-3,172)
Block(-8,23,-2,172)
Block(-8,23,-1,172)
Block(-8,23,0,172)
Block(-8,23,1,172)
Block(-8,23,2,172)
Block(-8,23,3,172)
Block(-8,23,4,172)
Block(-8,23,5,172)
Block(-8,23,6,172)
Block(-8,24,-9,172)
Block(-8,24,-8,172)
Block(-8,24,-7,172)
Block(-8,24,-6,172)
Block(-8,24,-5,172)
Block(-8,24,-4,172)
Block(-8,24,-3,172)
Block(-8,24,-2,172)
Block(-8,24,-1,172)
Block(-8,24,0,172)
Block(-8,24,1,172)
Block(-8,24,2,172)
Block(-8,24,3,172)
Block(-8,24,4,172)
Block(-8,24,5,172)
Block(-8,24,6,172)
Block(-8,25,-9,172)
Block(-8,25,-8,172)
Block(-8,25,-7,172)
Block(-8,25,-6,172)
Block(-8,25,-5,172)
Block(-8,25,-4,172)
Block(-8,25,-3,172)
Block(-8,25,-2,172)
Block(-8,25,-1,172)
Block(-8,25,0,172)
Block(-8,25,1,172)
Block(-8,25,2,172)
Block(-8,25,3,172)
Block(-8,25,4,172)
Block(-8,25,5,172)
Block(-8,25,6,172)
Block(-8,26,-9,172)
Block(-8,26,-8,172)
Block(-8,26,-7,172)
Block(-8,26,-6,172)
Block(-8,26,-5,172)
Block(-8,26,-4,172)
Block(-8,26,-3,172)
Block(-8,26,-2,172)
Block(-8,26,-1,172)
Block(-8,26,0,172)
Block(-8,26,1,172)
Block(-8,26,2,172)
Block(-8,26,3,172)
Block(-8,26,4,172)
Block(-8,26,5,172)
Block(-8,26,6,172)
Block(-8,27,-9,172)
Block(-8,27,-8,172)
Block(-8,27,-7,172)
Block(-8,27,-6,172)
Block(-8,27,-5,172)
Block(-8,27,-4,172)
Block(-8,27,-3,172)
Block(-8,27,-2,172)
Block(-8,27,-1,172)
Block(-8,27,0,172)
Block(-8,27,1,172)
Block(-8,27,2,172)
Block(-8,27,3,172)
Block(-8,27,4,172)
Block(-8,27,5,172)
Block(-8,27,6,172)
Block(-8,28,-9,172)
Block(-8,28,-8,172)
Block(-8,28,-7,172)
Block(-8,28,-6,172)
Block(-8,28,-5,172)
Block(-8,28,-4,172)
Block(-8,28,-3,172)
Block(-8,28,-2,172)
Block(-8,28,-1,172)
Block(-8,28,0,172)
Block(-8,28,1,172)
Block(-8,28,2,172)
Block(-8,28,3,172)
Block(-8,28,4,172)
Block(-8,28,5,172)
Block(-8,28,6,172)
Block(-8,29,-9,172)
Block(-8,29,-8,172)
Block(-8,29,-7,172)
Block(-8,29,-6,172)
Block(-8,29,-5,172)
Block(-8,29,-4,172)
Block(-8,29,-3,172)
Block(-8,29,-2,172)
Block(-8,29,-1,172)
Block(-8,29,0,172)
Block(-8,29,1,172)
Block(-8,29,2,172)
Block(-8,29,3,172)
Block(-8,29,4,172)
Block(-8,29,5,172)
Block(-8,29,6,172)
Block(-8,30,-9,172)
Block(-8,30,-8,172)
Block(-8,30,-7,172)
Block(-8,30,-6,172)
Block(-8,30,-5,172)
Block(-8,30,-4,172)
Block(-8,30,-3,172)
Block(-8,30,-2,172)
Block(-8,30,-1,172)
Block(-8,30,0,172)
Block(-8,30,1,172)
Block(-8,30,2,172)
Block(-8,30,3,172)
Block(-8,30,4,172)
Block(-8,30,5,172)
Block(-8,30,6,172)
Block(-8,31,-9,172)
Block(-8,31,-8,172)
Block(-8,31,-7,172)
Block(-8,31,-6,172)
Block(-8,31,-5,172)
Block(-8,31,-4,172)
Block(-8,31,-3,172)
Block(-8,31,-2,172)
Block(-8,31,-1,172)
Block(-8,31,0,172)
Block(-8,31,1,172)
Block(-8,31,2,172)
Block(-8,31,3,172)
Block(-8,31,4,172)
Block(-8,31,5,172)
Block(-8,31,6,172)
Block(-8,32,-9,172)
Block(-8,32,-8,172)
Block(-8,32,-7,172)
Block(-8,32,-6,172)
Block(-8,32,-5,172)
Block(-8,32,-4,172)
Block(-8,32,-3,172)
Block(-8,32,-2,172)
Block(-8,32,-1,172)
Block(-8,32,0,172)
Block(-8,32,1,172)
Block(-8,32,2,172)
Block(-8,32,3,172)
Block(-8,32,4,172)
Block(-8,32,5,172)
Block(-8,32,6,172)
Block(-8,33,-9,172)
Block(-8,33,-8,172)
Block(-8,33,-7,172)
Block(-8,33,-6,172)
Block(-8,33,-5,172)
Block(-8,33,-4,172)
Block(-8,33,-3,172)
Block(-8,33,-2,172)
Block(-8,33,-1,172)
Block(-8,33,0,172)
Block(-8,33,1,172)
Block(-8,33,2,172)
Block(-8,33,3,172)
Block(-8,33,4,172)
Block(-8,33,5,172)
Block(-8,33,6,172)
Block(-8,34,-9,172)
Block(-8,34,-8,172)
Block(-8,34,-7,172)
Block(-8,34,-6,172)
Block(-8,34,-5,172)
Block(-8,34,-4,172)
Block(-8,34,-3,172)
Block(-8,34,-2,172)
Block(-8,34,-1,172)
Block(-8,34,0,172)
Block(-8,34,1,172)
Block(-8,34,2,172)
Block(-8,34,3,172)
Block(-8,34,4,172)
Block(-8,34,5,172)
Block(-8,34,6,172)
Block(-8,35,-9,172)
Block(-8,35,-8,172)
Block(-8,35,-7,172)
Block(-8,35,-6,172)
Block(-8,35,-5,172)
Block(-8,35,-4,172)
Block(-8,35,-3,172)
Block(-8,35,-2,172)
Block(-8,35,-1,172)
Block(-8,35,0,172)
Block(-8,35,1,172)
Block(-8,35,2,172)
Block(-8,35,3,172)
Block(-8,35,4,172)
Block(-8,35,5,172)
Block(-8,35,6,172)
Block(-8,36,-9,172)
Block(-8,36,-8,172)
Block(-8,36,-7,172)
Block(-8,36,-6,172)
Block(-8,36,-5,172)
Block(-8,36,-4,172)
Block(-8,36,-3,172)
Block(-8,36,-2,172)
Block(-8,36,-1,172)
Block(-8,36,0,172)
Block(-8,36,1,172)
Block(-8,36,2,172)
Block(-8,36,3,172)
Block(-8,36,4,172)
Block(-8,36,5,172)
Block(-8,36,6,172)
Block(-8,37,-9,172)
Block(-8,37,-8,172)
Block(-8,37,-7,172)
Block(-8,37,-6,172)
Block(-8,37,-5,172)
Block(-8,37,-4,172)
Block(-8,37,-3,172)
Block(-8,37,-2,172)
Block(-8,37,-1,172)
Block(-8,37,0,172)
Block(-8,37,1,172)
Block(-8,37,2,172)
Block(-8,37,3,172)
Block(-8,37,4,172)
Block(-8,37,5,172)
Block(-8,38,-9,172)
Block(-8,38,-8,172)
Block(-8,38,-7,172)
Block(-8,38,-6,172)
Block(-8,38,-5,172)
Block(-8,38,-4,172)
Block(-8,38,-3,172)
Block(-8,38,-2,172)
Block(-8,38,-1,172)
Block(-8,38,0,172)
Block(-8,38,1,172)
Block(-8,38,2,172)
Block(-8,38,3,172)
Block(-8,38,4,172)
Block(-8,38,5,172)
Block(-8,39,-9,172)
Block(-8,39,-8,172)
Block(-8,39,-7,172)
Block(-8,39,-6,172)
Block(-8,39,-5,172)
Block(-8,39,-4,172)
Block(-8,39,-3,172)
Block(-8,39,-2,172)
Block(-8,39,-1,172)
Block(-8,39,0,172)
Block(-8,39,1,172)
Block(-8,39,2,172)
Block(-8,39,3,172)
Block(-8,39,4,172)
Block(-8,39,5,172)
Block(-8,40,-9,172)
Block(-8,40,-8,172)
Block(-8,40,-7,172)
Block(-8,40,-6,172)
Block(-8,40,-5,172)
Block(-8,40,-4,172)
Block(-8,40,-3,172)
Block(-8,40,-2,172)
Block(-8,40,-1,172)
Block(-8,40,0,172)
Block(-8,40,1,172)
Block(-8,40,2,172)
Block(-8,40,3,172)
Block(-8,40,4,172)
Block(-8,40,5,172)
Block(-8,41,-9,172)
Block(-8,41,-8,172)
Block(-8,41,-7,172)
Block(-8,41,-6,172)
Block(-8,41,-5,172)
Block(-8,41,-4,172)
Block(-8,41,-3,172)
Block(-8,41,-2,172)
Block(-8,41,-1,172)
Block(-8,41,0,172)
Block(-8,41,1,172)
Block(-8,41,2,172)
Block(-8,41,3,172)
Block(-8,41,4,172)
Block(-8,41,5,172)
Block(-8,42,-9,172)
Block(-8,42,-8,172)
Block(-8,42,-7,172)
Block(-8,42,-6,172)
Block(-8,42,-5,172)
Block(-8,42,-4,172)
Block(-8,42,-3,172)
Block(-8,42,-2,172)
Block(-8,42,-1,172)
Block(-8,42,0,172)
Block(-8,42,1,172)
Block(-8,42,2,172)
Block(-8,42,3,172)
Block(-8,42,4,172)
Block(-8,42,5,172)
Block(-8,43,-8,172)
Block(-8,43,-7,172)
Block(-8,43,-6,172)
Block(-8,43,-5,172)
Block(-8,43,-4,172)
Block(-8,43,-3,172)
Block(-8,43,-2,172)
Block(-8,43,-1,172)
Block(-8,43,0,172)
Block(-8,43,1,172)
Block(-8,43,2,172)
Block(-8,43,3,172)
Block(-8,43,4,172)
Block(-8,43,5,172)
Block(-8,44,-8,172)
Block(-8,44,-7,172)
Block(-8,44,-6,172)
Block(-8,44,-5,172)
Block(-8,44,-4,172)
Block(-8,44,-3,172)
Block(-8,44,-2,172)
Block(-8,44,-1,172)
Block(-8,44,0,172)
Block(-8,44,1,172)
Block(-8,44,2,172)
Block(-8,44,3,172)
Block(-8,44,4,172)
Block(-8,45,-8,172)
Block(-8,45,-7,172)
Block(-8,45,-6,172)
Block(-8,45,-5,172)
Block(-8,45,-4,172)
Block(-8,45,-3,172)
Block(-8,45,-2,172)
Block(-8,45,-1,172)
Block(-8,45,0,172)
Block(-8,45,1,172)
Block(-8,45,2,172)
Block(-8,45,3,172)
Block(-8,45,4,172)
Block(-8,46,-8,172)
Block(-8,46,-7,172)
Block(-8,46,-6,172)
Block(-8,46,-5,172)
Block(-8,46,-4,172)
Block(-8,46,-3,172)
Block(-8,46,-2,172)
Block(-8,46,-1,172)
Block(-8,46,0,172)
Block(-8,46,1,172)
Block(-8,46,2,172)
Block(-8,46,3,172)
Block(-8,46,4,172)
Block(-8,47,-8,172)
Block(-8,47,-7,172)
Block(-8,47,-6,172)
Block(-8,47,-5,172)
Block(-8,47,-4,172)
Block(-8,47,-3,172)
Block(-8,47,-2,172)
Block(-8,47,-1,172)
Block(-8,47,0,172)
Block(-8,47,1,172)
Block(-8,47,2,172)
Block(-8,47,3,172)
Block(-8,47,4,172)
Block(-8,48,-8,172)
Block(-8,48,-7,172)
Block(-8,48,-6,172)
Block(-8,48,-5,172)
Block(-8,48,-4,172)
Block(-8,48,-3,172)
Block(-8,48,-2,172)
Block(-8,48,-1,172)
Block(-8,48,0,172)
Block(-8,48,1,172)
Block(-8,48,2,172)
Block(-8,48,3,172)
Block(-8,48,4,172)
Block(-8,49,-7,172)
Block(-8,49,-6,172)
Block(-8,49,-5,172)
Block(-8,49,-4,172)
Block(-8,49,-3,172)
Block(-8,49,-2,172)
Block(-8,49,-1,172)
Block(-8,49,0,172)
Block(-8,49,1,172)
Block(-8,49,2,172)
Block(-8,49,3,172)
Block(-8,49,4,172)
Block(-8,50,-7,172)
Block(-8,50,-6,172)
Block(-8,50,-5,172)
Block(-8,50,-4,172)
Block(-8,50,-3,172)
Block(-8,50,-2,172)
Block(-8,50,-1,172)
Block(-8,50,0,172)
Block(-8,50,1,172)
Block(-8,50,2,172)
Block(-8,50,3,172)
Block(-8,50,4,172)
Block(-8,51,-7,172)
Block(-8,51,-6,172)
Block(-8,51,-5,172)
Block(-8,51,-4,172)
Block(-8,51,-3,172)
Block(-8,51,-2,172)
Block(-8,51,-1,172)
Block(-8,51,0,172)
Block(-8,51,1,172)
Block(-8,51,2,172)
Block(-8,51,3,172)
Block(-8,51,4,172)
Block(-8,52,-7,172)
Block(-8,52,-6,172)
Block(-8,52,-5,172)
Block(-8,52,-4,172)
Block(-8,52,-3,172)
Block(-8,52,-2,172)
Block(-8,52,-1,172)
Block(-8,52,0,172)
Block(-8,52,1,172)
Block(-8,52,2,172)
Block(-8,52,3,172)
Block(-8,52,4,172)
Block(-8,53,-7,172)
Block(-8,53,-6,172)
Block(-8,53,-5,172)
Block(-8,53,-4,172)
Block(-8,53,-3,172)
Block(-8,53,-2,172)
Block(-8,53,-1,172)
Block(-8,53,0,172)
Block(-8,53,1,172)
Block(-8,53,2,172)
Block(-8,53,3,172)
Block(-8,53,4,172)
Block(-8,54,-7,172)
Block(-8,54,-6,172)
Block(-8,54,-5,172)
Block(-8,54,-4,172)
Block(-8,54,-3,172)
Block(-8,54,-2,172)
Block(-8,54,-1,172)
Block(-8,54,0,172)
Block(-8,54,1,172)
Block(-8,54,2,172)
Block(-8,54,3,172)
Block(-8,54,4,172)
Block(-8,55,-7,172)
Block(-8,55,-6,172)
Block(-8,55,-5,172)
Block(-8,55,-4,172)
Block(-8,55,-3,172)
Block(-8,55,-2,172)
Block(-8,55,-1,172)
Block(-8,55,0,172)
Block(-8,55,1,172)
Block(-8,55,2,172)
Block(-8,55,3,172)
Block(-8,55,4,172)
Block(-8,56,-7,172)
Block(-8,56,-6,172)
Block(-8,56,-5,172)
Block(-8,56,-4,172)
Block(-8,56,-3,172)
Block(-8,56,-2,172)
Block(-8,56,-1,172)
Block(-8,56,0,172)
Block(-8,56,1,172)
Block(-8,56,2,172)
Block(-8,56,3,172)
Block(-8,56,4,172)
Block(-8,57,-7,172)
Block(-8,57,-6,172)
Block(-8,57,-5,172)
Block(-8,57,-4,172)
Block(-8,57,-3,172)
Block(-8,57,-2,172)
Block(-8,57,-1,172)
Block(-8,57,0,172)
Block(-8,57,1,172)
Block(-8,57,2,172)
Block(-8,57,3,172)
Block(-8,57,4,172)
Block(-8,58,-7,172)
Block(-8,58,-6,172)
Block(-8,58,-5,172)
Block(-8,58,-4,172)
Block(-8,58,-3,172)
Block(-8,58,-2,172)
Block(-8,58,-1,172)
Block(-8,58,0,172)
Block(-8,58,1,172)
Block(-8,58,2,172)
Block(-8,58,3,172)
Block(-8,58,4,172)
Block(-8,59,-6,172)
Block(-8,59,-5,172)
Block(-8,59,-4,172)
Block(-8,59,-3,172)
Block(-8,59,-2,172)
Block(-8,59,-1,172)
Block(-8,59,0,172)
Block(-8,59,1,172)
Block(-8,59,2,172)
Block(-8,59,3,172)
Block(-8,59,4,172)
Block(-8,60,-6,172)
Block(-8,60,-5,172)
Block(-8,60,-4,2)
Block(-8,60,-3,2)
Block(-8,60,-2,2)
Block(-8,60,-1,2)
Block(-8,60,0,2)
Block(-8,60,1,2)
Block(-8,60,2,2)
Block(-8,60,3,172)
Block(-8,60,4,172)
Block(-7,0,-13,172)
Block(-7,0,-12,172)
Block(-7,0,-11,172)
Block(-7,0,-10,172)
Block(-7,0,-9,172)
Block(-7,0,-8,172)
Block(-7,0,-7,172)
Block(-7,0,-6,172)
Block(-7,0,-5,172)
Block(-7,0,-4,172)
Block(-7,0,-3,172)
Block(-7,0,-2,172)
Block(-7,0,-1,172)
Block(-7,0,0,172)
Block(-7,0,1,172)
Block(-7,0,2,172)
Block(-7,0,3,172)
Block(-7,0,4,172)
Block(-7,0,5,172)
Block(-7,0,6,172)
Block(-7,0,7,172)
Block(-7,0,8,172)
Block(-7,0,9,172)
Block(-7,0,10,172)
Block(-7,1,-12,172)
Block(-7,1,-11,172)
Block(-7,1,-10,172)
Block(-7,1,-9,172)
Block(-7,1,-8,172)
Block(-7,1,-7,172)
Block(-7,1,-6,172)
Block(-7,1,-5,172)
Block(-7,1,-4,172)
Block(-7,1,-3,172)
Block(-7,1,-2,172)
Block(-7,1,-1,172)
Block(-7,1,0,172)
Block(-7,1,1,172)
Block(-7,1,2,172)
Block(-7,1,3,172)
Block(-7,1,4,172)
Block(-7,1,5,172)
Block(-7,1,6,172)
Block(-7,1,7,172)
Block(-7,1,8,172)
Block(-7,1,9,172)
Block(-7,1,10,172)
Block(-7,2,-11,172)
Block(-7,2,-10,172)
Block(-7,2,-9,172)
Block(-7,2,-8,172)
Block(-7,2,-7,172)
Block(-7,2,-6,172)
Block(-7,2,-5,172)
Block(-7,2,-4,172)
Block(-7,2,-3,172)
Block(-7,2,-2,172)
Block(-7,2,-1,172)
Block(-7,2,0,172)
Block(-7,2,1,172)
Block(-7,2,2,172)
Block(-7,2,3,172)
Block(-7,2,4,172)
Block(-7,2,5,172)
Block(-7,2,6,172)
Block(-7,2,7,172)
Block(-7,2,8,172)
Block(-7,2,9,172)
Block(-7,2,10,172)
Block(-7,3,-11,172)
Block(-7,3,-10,172)
Block(-7,3,-9,172)
Block(-7,3,-8,172)
Block(-7,3,-7,172)
Block(-7,3,-6,172)
Block(-7,3,-5,172)
Block(-7,3,-4,172)
Block(-7,3,-3,172)
Block(-7,3,-2,172)
Block(-7,3,-1,172)
Block(-7,3,0,172)
Block(-7,3,1,172)
Block(-7,3,2,172)
Block(-7,3,3,172)
Block(-7,3,4,172)
Block(-7,3,5,172)
Block(-7,3,6,172)
Block(-7,3,7,172)
Block(-7,3,8,172)
Block(-7,3,9,172)
Block(-7,4,-11,172)
Block(-7,4,-10,172)
Block(-7,4,-9,172)
Block(-7,4,-8,172)
Block(-7,4,-7,172)
Block(-7,4,-6,172)
Block(-7,4,-5,172)
Block(-7,4,-4,172)
Block(-7,4,-3,172)
Block(-7,4,-2,172)
Block(-7,4,-1,172)
Block(-7,4,0,172)
Block(-7,4,1,172)
Block(-7,4,2,172)
Block(-7,4,3,172)
Block(-7,4,4,172)
Block(-7,4,5,172)
Block(-7,4,6,172)
Block(-7,4,7,172)
Block(-7,4,8,172)
Block(-7,4,9,172)
Block(-7,5,-10,172)
Block(-7,5,-9,172)
Block(-7,5,-8,172)
Block(-7,5,-7,172)
Block(-7,5,-6,172)
Block(-7,5,-5,172)
Block(-7,5,-4,172)
Block(-7,5,-3,172)
Block(-7,5,-2,172)
Block(-7,5,-1,172)
Block(-7,5,0,172)
Block(-7,5,1,172)
Block(-7,5,2,172)
Block(-7,5,3,172)
Block(-7,5,4,172)
Block(-7,5,5,172)
Block(-7,5,6,172)
Block(-7,5,7,172)
Block(-7,5,8,172)
Block(-7,5,9,172)
Block(-7,6,-10,172)
Block(-7,6,-9,172)
Block(-7,6,-8,172)
Block(-7,6,-7,172)
Block(-7,6,-6,172)
Block(-7,6,-5,172)
Block(-7,6,-4,172)
Block(-7,6,-3,172)
Block(-7,6,-2,172)
Block(-7,6,-1,172)
Block(-7,6,0,172)
Block(-7,6,1,172)
Block(-7,6,2,172)
Block(-7,6,3,172)
Block(-7,6,4,172)
Block(-7,6,5,172)
Block(-7,6,6,172)
Block(-7,6,7,172)
Block(-7,6,8,172)
Block(-7,6,9,172)
Block(-7,7,-10,172)
Block(-7,7,-9,172)
Block(-7,7,-8,172)
Block(-7,7,-7,172)
Block(-7,7,-6,172)
Block(-7,7,-5,172)
Block(-7,7,-4,172)
Block(-7,7,-3,172)
Block(-7,7,-2,172)
Block(-7,7,-1,172)
Block(-7,7,0,172)
Block(-7,7,1,172)
Block(-7,7,2,172)
Block(-7,7,3,172)
Block(-7,7,4,172)
Block(-7,7,5,172)
Block(-7,7,6,172)
Block(-7,7,7,172)
Block(-7,7,8,172)
Block(-7,7,9,172)
Block(-7,8,-10,172)
Block(-7,8,-9,172)
Block(-7,8,-8,172)
Block(-7,8,-7,172)
Block(-7,8,-6,172)
Block(-7,8,-5,172)
Block(-7,8,-4,172)
Block(-7,8,-3,172)
Block(-7,8,-2,172)
Block(-7,8,-1,172)
Block(-7,8,0,172)
Block(-7,8,1,172)
Block(-7,8,2,172)
Block(-7,8,3,172)
Block(-7,8,4,172)
Block(-7,8,5,172)
Block(-7,8,6,172)
Block(-7,8,7,172)
Block(-7,8,8,172)
Block(-7,8,9,172)
Block(-7,9,-10,172)
Block(-7,9,-9,172)
Block(-7,9,-8,172)
Block(-7,9,-7,172)
Block(-7,9,-6,172)
Block(-7,9,-5,172)
Block(-7,9,-4,172)
Block(-7,9,-3,172)
Block(-7,9,-2,172)
Block(-7,9,-1,172)
Block(-7,9,0,172)
Block(-7,9,1,172)
Block(-7,9,2,172)
Block(-7,9,3,172)
Block(-7,9,4,172)
Block(-7,9,5,172)
Block(-7,9,6,172)
Block(-7,9,7,172)
Block(-7,9,8,172)
Block(-7,9,9,172)
Block(-7,10,-10,172)
Block(-7,10,-9,172)
Block(-7,10,-8,172)
Block(-7,10,-7,172)
Block(-7,10,-6,172)
Block(-7,10,-5,172)
Block(-7,10,-4,172)
Block(-7,10,-3,172)
Block(-7,10,-2,172)
Block(-7,10,-1,172)
Block(-7,10,0,172)
Block(-7,10,1,172)
Block(-7,10,2,172)
Block(-7,10,3,172)
Block(-7,10,4,172)
Block(-7,10,5,172)
Block(-7,10,6,172)
Block(-7,10,7,172)
Block(-7,10,8,172)
Block(-7,10,9,172)
Block(-7,11,-10,172)
Block(-7,11,-9,172)
Block(-7,11,-8,172)
Block(-7,11,-7,172)
Block(-7,11,-6,172)
Block(-7,11,-5,172)
Block(-7,11,-4,172)
Block(-7,11,-3,172)
Block(-7,11,-2,172)
Block(-7,11,-1,172)
Block(-7,11,0,172)
Block(-7,11,1,172)
Block(-7,11,2,172)
Block(-7,11,3,172)
Block(-7,11,4,172)
Block(-7,11,5,172)
Block(-7,11,6,172)
Block(-7,11,7,172)
Block(-7,11,8,172)
Block(-7,11,9,172)
Block(-7,12,-10,172)
Block(-7,12,-9,172)
Block(-7,12,-8,172)
Block(-7,12,-7,172)
Block(-7,12,-6,172)
Block(-7,12,-5,172)
Block(-7,12,-4,172)
Block(-7,12,-3,172)
Block(-7,12,-2,172)
Block(-7,12,-1,172)
Block(-7,12,0,172)
Block(-7,12,1,172)
Block(-7,12,2,172)
Block(-7,12,3,172)
Block(-7,12,4,172)
Block(-7,12,5,172)
Block(-7,12,6,172)
Block(-7,12,7,172)
Block(-7,12,8,172)
Block(-7,13,-10,172)
Block(-7,13,-9,172)
Block(-7,13,-8,172)
Block(-7,13,-7,172)
Block(-7,13,-6,172)
Block(-7,13,-5,172)
Block(-7,13,-4,172)
Block(-7,13,-3,172)
Block(-7,13,-2,172)
Block(-7,13,-1,172)
Block(-7,13,0,172)
Block(-7,13,1,172)
Block(-7,13,2,172)
Block(-7,13,3,172)
Block(-7,13,4,172)
Block(-7,13,5,172)
Block(-7,13,6,172)
Block(-7,13,7,172)
Block(-7,13,8,172)
Block(-7,14,-10,172)
Block(-7,14,-9,172)
Block(-7,14,-8,172)
Block(-7,14,-7,172)
Block(-7,14,-6,172)
Block(-7,14,-5,172)
Block(-7,14,-4,172)
Block(-7,14,-3,172)
Block(-7,14,-2,172)
Block(-7,14,-1,172)
Block(-7,14,0,172)
Block(-7,14,1,172)
Block(-7,14,2,172)
Block(-7,14,3,172)
Block(-7,14,4,172)
Block(-7,14,5,172)
Block(-7,14,6,172)
Block(-7,14,7,172)
Block(-7,14,8,172)
Block(-7,15,-10,172)
Block(-7,15,-9,172)
Block(-7,15,-8,172)
Block(-7,15,-7,172)
Block(-7,15,-6,172)
Block(-7,15,-5,172)
Block(-7,15,-4,172)
Block(-7,15,-3,172)
Block(-7,15,-2,172)
Block(-7,15,-1,172)
Block(-7,15,0,172)
Block(-7,15,1,172)
Block(-7,15,2,172)
Block(-7,15,3,172)
Block(-7,15,4,172)
Block(-7,15,5,172)
Block(-7,15,6,172)
Block(-7,15,7,172)
Block(-7,15,8,172)
Block(-7,16,-9,172)
Block(-7,16,-8,172)
Block(-7,16,-7,172)
Block(-7,16,-6,172)
Block(-7,16,-5,172)
Block(-7,16,-4,172)
Block(-7,16,-3,172)
Block(-7,16,-2,172)
Block(-7,16,-1,172)
Block(-7,16,0,172)
Block(-7,16,1,172)
Block(-7,16,2,172)
Block(-7,16,3,172)
Block(-7,16,4,172)
Block(-7,16,5,172)
Block(-7,16,6,172)
Block(-7,16,7,172)
Block(-7,16,8,172)
Block(-7,17,-9,172)
Block(-7,17,-8,172)
Block(-7,17,-7,172)
Block(-7,17,-6,172)
Block(-7,17,-5,172)
Block(-7,17,-4,172)
Block(-7,17,-3,172)
Block(-7,17,-2,172)
Block(-7,17,-1,172)
Block(-7,17,0,172)
Block(-7,17,1,172)
Block(-7,17,2,172)
Block(-7,17,3,172)
Block(-7,17,4,172)
Block(-7,17,5,172)
Block(-7,17,6,172)
Block(-7,17,7,172)
Block(-7,17,8,172)
Block(-7,18,-9,172)
Block(-7,18,-8,172)
Block(-7,18,-7,172)
Block(-7,18,-6,172)
Block(-7,18,-5,172)
Block(-7,18,-4,172)
Block(-7,18,-3,172)
Block(-7,18,-2,172)
Block(-7,18,-1,172)
Block(-7,18,0,172)
Block(-7,18,1,172)
Block(-7,18,2,172)
Block(-7,18,3,172)
Block(-7,18,4,172)
Block(-7,18,5,172)
Block(-7,18,6,172)
Block(-7,18,7,172)
Block(-7,18,8,172)
Block(-7,19,-9,172)
Block(-7,19,-8,172)
Block(-7,19,-7,172)
Block(-7,19,-6,172)
Block(-7,19,-5,172)
Block(-7,19,-4,172)
Block(-7,19,-3,172)
Block(-7,19,-2,172)
Block(-7,19,-1,172)
Block(-7,19,0,172)
Block(-7,19,1,172)
Block(-7,19,2,172)
Block(-7,19,3,172)
Block(-7,19,4,172)
Block(-7,19,5,172)
Block(-7,19,6,172)
Block(-7,19,7,172)
Block(-7,19,8,172)
Block(-7,20,-9,172)
Block(-7,20,-8,172)
Block(-7,20,-7,172)
Block(-7,20,-6,172)
Block(-7,20,-5,172)
Block(-7,20,-4,172)
Block(-7,20,-3,172)
Block(-7,20,-2,172)
Block(-7,20,-1,172)
Block(-7,20,0,172)
Block(-7,20,1,172)
Block(-7,20,2,172)
Block(-7,20,3,172)
Block(-7,20,4,172)
Block(-7,20,5,172)
Block(-7,20,6,172)
Block(-7,20,7,172)
Block(-7,20,8,172)
Block(-7,21,-9,172)
Block(-7,21,-8,172)
Block(-7,21,-7,172)
Block(-7,21,-6,172)
Block(-7,21,-5,172)
Block(-7,21,-4,172)
Block(-7,21,-3,172)
Block(-7,21,-2,172)
Block(-7,21,-1,172)
Block(-7,21,0,172)
Block(-7,21,1,172)
Block(-7,21,2,172)
Block(-7,21,3,172)
Block(-7,21,4,172)
Block(-7,21,5,172)
Block(-7,21,6,172)
Block(-7,21,7,172)
Block(-7,21,8,172)
Block(-7,22,-9,172)
Block(-7,22,-8,172)
Block(-7,22,-7,172)
Block(-7,22,-6,172)
Block(-7,22,-5,172)
Block(-7,22,-4,172)
Block(-7,22,-3,172)
Block(-7,22,-2,172)
Block(-7,22,-1,172)
Block(-7,22,0,172)
Block(-7,22,1,172)
Block(-7,22,2,172)
Block(-7,22,3,172)
Block(-7,22,4,172)
Block(-7,22,5,172)
Block(-7,22,6,172)
Block(-7,22,7,172)
Block(-7,22,8,172)
Block(-7,23,-9,172)
Block(-7,23,-8,172)
Block(-7,23,-7,172)
Block(-7,23,-6,172)
Block(-7,23,-5,172)
Block(-7,23,-4,172)
Block(-7,23,-3,172)
Block(-7,23,-2,172)
Block(-7,23,-1,172)
Block(-7,23,0,172)
Block(-7,23,1,172)
Block(-7,23,2,172)
Block(-7,23,3,172)
Block(-7,23,4,172)
Block(-7,23,5,172)
Block(-7,23,6,172)
Block(-7,23,7,172)
Block(-7,23,8,172)
Block(-7,24,-9,172)
Block(-7,24,-8,172)
Block(-7,24,-7,172)
Block(-7,24,-6,172)
Block(-7,24,-5,172)
Block(-7,24,-4,172)
Block(-7,24,-3,172)
Block(-7,24,-2,172)
Block(-7,24,-1,172)
Block(-7,24,0,172)
Block(-7,24,1,172)
Block(-7,24,2,172)
Block(-7,24,3,172)
Block(-7,24,4,172)
Block(-7,24,5,172)
Block(-7,24,6,172)
Block(-7,24,7,172)
Block(-7,24,8,172)
Block(-7,25,-9,172)
Block(-7,25,-8,172)
Block(-7,25,-7,172)
Block(-7,25,-6,172)
Block(-7,25,-5,172)
Block(-7,25,-4,172)
Block(-7,25,-3,172)
Block(-7,25,-2,172)
Block(-7,25,-1,172)
Block(-7,25,0,172)
Block(-7,25,1,172)
Block(-7,25,2,172)
Block(-7,25,3,172)
Block(-7,25,4,172)
Block(-7,25,5,172)
Block(-7,25,6,172)
Block(-7,25,7,172)
Block(-7,25,8,172)
Block(-7,26,-9,172)
Block(-7,26,-8,172)
Block(-7,26,-7,172)
Block(-7,26,-6,172)
Block(-7,26,-5,172)
Block(-7,26,-4,172)
Block(-7,26,-3,172)
Block(-7,26,-2,172)
Block(-7,26,-1,172)
Block(-7,26,0,172)
Block(-7,26,1,172)
Block(-7,26,2,172)
Block(-7,26,3,172)
Block(-7,26,4,172)
Block(-7,26,5,172)
Block(-7,26,6,172)
Block(-7,26,7,172)
Block(-7,26,8,172)
Block(-7,27,-9,172)
Block(-7,27,-8,172)
Block(-7,27,-7,172)
Block(-7,27,-6,172)
Block(-7,27,-5,172)
Block(-7,27,-4,172)
Block(-7,27,-3,172)
Block(-7,27,-2,172)
Block(-7,27,-1,172)
Block(-7,27,0,172)
Block(-7,27,1,172)
Block(-7,27,2,172)
Block(-7,27,3,172)
Block(-7,27,4,172)
Block(-7,27,5,172)
Block(-7,27,6,172)
Block(-7,27,7,172)
Block(-7,27,8,172)
Block(-7,28,-9,172)
Block(-7,28,-8,172)
Block(-7,28,-7,172)
Block(-7,28,-6,172)
Block(-7,28,-5,172)
Block(-7,28,-4,172)
Block(-7,28,-3,172)
Block(-7,28,-2,172)
Block(-7,28,-1,172)
Block(-7,28,0,172)
Block(-7,28,1,172)
Block(-7,28,2,172)
Block(-7,28,3,172)
Block(-7,28,4,172)
Block(-7,28,5,172)
Block(-7,28,6,172)
Block(-7,28,7,172)
Block(-7,28,8,172)
Block(-7,29,-9,172)
Block(-7,29,-8,172)
Block(-7,29,-7,172)
Block(-7,29,-6,172)
Block(-7,29,-5,172)
Block(-7,29,-4,172)
Block(-7,29,-3,172)
Block(-7,29,-2,172)
Block(-7,29,-1,172)
Block(-7,29,0,172)
Block(-7,29,1,172)
Block(-7,29,2,172)
Block(-7,29,3,172)
Block(-7,29,4,172)
Block(-7,29,5,172)
Block(-7,29,6,172)
Block(-7,29,7,172)
Block(-7,30,-9,172)
Block(-7,30,-8,172)
Block(-7,30,-7,172)
Block(-7,30,-6,172)
Block(-7,30,-5,172)
Block(-7,30,-4,172)
Block(-7,30,-3,172)
Block(-7,30,-2,172)
Block(-7,30,-1,172)
Block(-7,30,0,172)
Block(-7,30,1,172)
Block(-7,30,2,172)
Block(-7,30,3,172)
Block(-7,30,4,172)
Block(-7,30,5,172)
Block(-7,30,6,172)
Block(-7,30,7,172)
Block(-7,31,-9,172)
Block(-7,31,-8,172)
Block(-7,31,-7,172)
Block(-7,31,-6,172)
Block(-7,31,-5,172)
Block(-7,31,-4,172)
Block(-7,31,-3,172)
Block(-7,31,-2,172)
Block(-7,31,-1,172)
Block(-7,31,0,172)
Block(-7,31,1,172)
Block(-7,31,2,172)
Block(-7,31,3,172)
Block(-7,31,4,172)
Block(-7,31,5,172)
Block(-7,31,6,172)
Block(-7,31,7,172)
Block(-7,32,-9,172)
Block(-7,32,-8,172)
Block(-7,32,-7,172)
Block(-7,32,-6,172)
Block(-7,32,-5,172)
Block(-7,32,-4,172)
Block(-7,32,-3,172)
Block(-7,32,-2,172)
Block(-7,32,-1,172)
Block(-7,32,0,172)
Block(-7,32,1,172)
Block(-7,32,2,172)
Block(-7,32,3,172)
Block(-7,32,4,172)
Block(-7,32,5,172)
Block(-7,32,6,172)
Block(-7,32,7,172)
Block(-7,33,-9,172)
Block(-7,33,-8,172)
Block(-7,33,-7,172)
Block(-7,33,-6,172)
Block(-7,33,-5,172)
Block(-7,33,-4,172)
Block(-7,33,-3,172)
Block(-7,33,-2,172)
Block(-7,33,-1,172)
Block(-7,33,0,172)
Block(-7,33,1,172)
Block(-7,33,2,172)
Block(-7,33,3,172)
Block(-7,33,4,172)
Block(-7,33,5,172)
Block(-7,33,6,172)
Block(-7,33,7,172)
Block(-7,34,-9,172)
Block(-7,34,-8,172)
Block(-7,34,-7,172)
Block(-7,34,-6,172)
Block(-7,34,-5,172)
Block(-7,34,-4,172)
Block(-7,34,-3,172)
Block(-7,34,-2,172)
Block(-7,34,-1,172)
Block(-7,34,0,172)
Block(-7,34,1,172)
Block(-7,34,2,172)
Block(-7,34,3,172)
Block(-7,34,4,172)
Block(-7,34,5,172)
Block(-7,34,6,172)
Block(-7,34,7,172)
Block(-7,35,-9,172)
Block(-7,35,-8,172)
Block(-7,35,-7,172)
Block(-7,35,-6,172)
Block(-7,35,-5,172)
Block(-7,35,-4,172)
Block(-7,35,-3,172)
Block(-7,35,-2,172)
Block(-7,35,-1,172)
Block(-7,35,0,172)
Block(-7,35,1,172)
Block(-7,35,2,172)
Block(-7,35,3,172)
Block(-7,35,4,172)
Block(-7,35,5,172)
Block(-7,35,6,172)
Block(-7,35,7,172)
Block(-7,36,-9,172)
Block(-7,36,-8,172)
Block(-7,36,-7,172)
Block(-7,36,-6,172)
Block(-7,36,-5,172)
Block(-7,36,-4,172)
Block(-7,36,-3,172)
Block(-7,36,-2,172)
Block(-7,36,-1,172)
Block(-7,36,0,172)
Block(-7,36,1,172)
Block(-7,36,2,172)
Block(-7,36,3,172)
Block(-7,36,4,172)
Block(-7,36,5,172)
Block(-7,36,6,172)
Block(-7,36,7,172)
Block(-7,37,-9,172)
Block(-7,37,-8,172)
Block(-7,37,-7,172)
Block(-7,37,-6,172)
Block(-7,37,-5,172)
Block(-7,37,-4,172)
Block(-7,37,-3,172)
Block(-7,37,-2,172)
Block(-7,37,-1,172)
Block(-7,37,0,172)
Block(-7,37,1,172)
Block(-7,37,2,172)
Block(-7,37,3,172)
Block(-7,37,4,172)
Block(-7,37,5,172)
Block(-7,37,6,172)
Block(-7,37,7,172)
Block(-7,38,-9,172)
Block(-7,38,-8,172)
Block(-7,38,-7,172)
Block(-7,38,-6,172)
Block(-7,38,-5,172)
Block(-7,38,-4,172)
Block(-7,38,-3,172)
Block(-7,38,-2,172)
Block(-7,38,-1,172)
Block(-7,38,0,172)
Block(-7,38,1,172)
Block(-7,38,2,172)
Block(-7,38,3,172)
Block(-7,38,4,172)
Block(-7,38,5,172)
Block(-7,38,6,172)
Block(-7,38,7,172)
Block(-7,39,-9,172)
Block(-7,39,-8,172)
Block(-7,39,-7,172)
Block(-7,39,-6,172)
Block(-7,39,-5,172)
Block(-7,39,-4,172)
Block(-7,39,-3,172)
Block(-7,39,-2,172)
Block(-7,39,-1,172)
Block(-7,39,0,172)
Block(-7,39,1,172)
Block(-7,39,2,172)
Block(-7,39,3,172)
Block(-7,39,4,172)
Block(-7,39,5,172)
Block(-7,39,6,172)
Block(-7,39,7,172)
Block(-7,40,-9,172)
Block(-7,40,-8,172)
Block(-7,40,-7,172)
Block(-7,40,-6,172)
Block(-7,40,-5,172)
Block(-7,40,-4,172)
Block(-7,40,-3,172)
Block(-7,40,-2,172)
Block(-7,40,-1,172)
Block(-7,40,0,172)
Block(-7,40,1,172)
Block(-7,40,2,172)
Block(-7,40,3,172)
Block(-7,40,4,172)
Block(-7,40,5,172)
Block(-7,40,6,172)
Block(-7,40,7,172)
Block(-7,41,-9,172)
Block(-7,41,-8,172)
Block(-7,41,-7,172)
Block(-7,41,-6,172)
Block(-7,41,-5,172)
Block(-7,41,-4,172)
Block(-7,41,-3,172)
Block(-7,41,-2,172)
Block(-7,41,-1,172)
Block(-7,41,0,172)
Block(-7,41,1,172)
Block(-7,41,2,172)
Block(-7,41,3,172)
Block(-7,41,4,172)
Block(-7,41,5,172)
Block(-7,41,6,172)
Block(-7,41,7,172)
Block(-7,42,-9,172)
Block(-7,42,-8,172)
Block(-7,42,-7,172)
Block(-7,42,-6,172)
Block(-7,42,-5,172)
Block(-7,42,-4,172)
Block(-7,42,-3,172)
Block(-7,42,-2,172)
Block(-7,42,-1,172)
Block(-7,42,0,172)
Block(-7,42,1,172)
Block(-7,42,2,172)
Block(-7,42,3,172)
Block(-7,42,4,172)
Block(-7,42,5,172)
Block(-7,42,6,172)
Block(-7,42,7,172)
Block(-7,43,-9,172)
Block(-7,43,-8,172)
Block(-7,43,-7,172)
Block(-7,43,-6,172)
Block(-7,43,-5,172)
Block(-7,43,-4,172)
Block(-7,43,-3,172)
Block(-7,43,-2,172)
Block(-7,43,-1,172)
Block(-7,43,0,172)
Block(-7,43,1,172)
Block(-7,43,2,172)
Block(-7,43,3,172)
Block(-7,43,4,172)
Block(-7,43,5,172)
Block(-7,43,6,172)
Block(-7,44,-9,172)
Block(-7,44,-8,172)
Block(-7,44,-7,172)
Block(-7,44,-6,172)
Block(-7,44,-5,172)
Block(-7,44,-4,172)
Block(-7,44,-3,172)
Block(-7,44,-2,172)
Block(-7,44,-1,172)
Block(-7,44,0,172)
Block(-7,44,1,172)
Block(-7,44,2,172)
Block(-7,44,3,172)
Block(-7,44,4,172)
Block(-7,44,5,172)
Block(-7,44,6,172)
Block(-7,45,-9,172)
Block(-7,45,-8,172)
Block(-7,45,-7,172)
Block(-7,45,-6,172)
Block(-7,45,-5,172)
Block(-7,45,-4,172)
Block(-7,45,-3,172)
Block(-7,45,-2,172)
Block(-7,45,-1,172)
Block(-7,45,0,172)
Block(-7,45,1,172)
Block(-7,45,2,172)
Block(-7,45,3,172)
Block(-7,45,4,172)
Block(-7,45,5,172)
Block(-7,45,6,172)
Block(-7,46,-9,172)
Block(-7,46,-8,172)
Block(-7,46,-7,172)
Block(-7,46,-6,172)
Block(-7,46,-5,172)
Block(-7,46,-4,172)
Block(-7,46,-3,172)
Block(-7,46,-2,172)
Block(-7,46,-1,172)
Block(-7,46,0,172)
Block(-7,46,1,172)
Block(-7,46,2,172)
Block(-7,46,3,172)
Block(-7,46,4,172)
Block(-7,46,5,172)
Block(-7,46,6,172)
Block(-7,47,-9,172)
Block(-7,47,-8,172)
Block(-7,47,-7,172)
Block(-7,47,-6,172)
Block(-7,47,-5,172)
Block(-7,47,-4,172)
Block(-7,47,-3,172)
Block(-7,47,-2,172)
Block(-7,47,-1,172)
Block(-7,47,0,172)
Block(-7,47,1,172)
Block(-7,47,2,172)
Block(-7,47,3,172)
Block(-7,47,4,172)
Block(-7,47,5,172)
Block(-7,47,6,172)
Block(-7,48,-9,172)
Block(-7,48,-8,172)
Block(-7,48,-7,172)
Block(-7,48,-6,172)
Block(-7,48,-5,172)
Block(-7,48,-4,172)
Block(-7,48,-3,172)
Block(-7,48,-2,172)
Block(-7,48,-1,172)
Block(-7,48,0,172)
Block(-7,48,1,172)
Block(-7,48,2,172)
Block(-7,48,3,172)
Block(-7,48,4,172)
Block(-7,48,5,172)
Block(-7,48,6,172)
Block(-7,49,-9,172)
Block(-7,49,-8,172)
Block(-7,49,-7,172)
Block(-7,49,-6,172)
Block(-7,49,-5,172)
Block(-7,49,-4,172)
Block(-7,49,-3,172)
Block(-7,49,-2,172)
Block(-7,49,-1,172)
Block(-7,49,0,172)
Block(-7,49,1,172)
Block(-7,49,2,172)
Block(-7,49,3,172)
Block(-7,49,4,172)
Block(-7,49,5,172)
Block(-7,49,6,172)
Block(-7,50,-9,172)
Block(-7,50,-8,172)
Block(-7,50,-7,172)
Block(-7,50,-6,172)
Block(-7,50,-5,172)
Block(-7,50,-4,172)
Block(-7,50,-3,172)
Block(-7,50,-2,172)
Block(-7,50,-1,172)
Block(-7,50,0,172)
Block(-7,50,1,172)
Block(-7,50,2,172)
Block(-7,50,3,172)
Block(-7,50,4,172)
Block(-7,50,5,172)
Block(-7,50,6,172)
Block(-7,51,-9,172)
Block(-7,51,-8,172)
Block(-7,51,-7,172)
Block(-7,51,-6,172)
Block(-7,51,-5,172)
Block(-7,51,-4,172)
Block(-7,51,-3,172)
Block(-7,51,-2,172)
Block(-7,51,-1,172)
Block(-7,51,0,172)
Block(-7,51,1,172)
Block(-7,51,2,172)
Block(-7,51,3,172)
Block(-7,51,4,172)
Block(-7,51,5,172)
Block(-7,51,6,172)
Block(-7,52,-9,172)
Block(-7,52,-8,172)
Block(-7,52,-7,172)
Block(-7,52,-6,172)
Block(-7,52,-5,172)
Block(-7,52,-4,172)
Block(-7,52,-3,172)
Block(-7,52,-2,172)
Block(-7,52,-1,172)
Block(-7,52,0,172)
Block(-7,52,1,172)
Block(-7,52,2,172)
Block(-7,52,3,172)
Block(-7,52,4,172)
Block(-7,52,5,172)
Block(-7,52,6,172)
Block(-7,53,-9,172)
Block(-7,53,-8,172)
Block(-7,53,-7,172)
Block(-7,53,-6,172)
Block(-7,53,-5,172)
Block(-7,53,-4,172)
Block(-7,53,-3,172)
Block(-7,53,-2,172)
Block(-7,53,-1,172)
Block(-7,53,0,172)
Block(-7,53,1,172)
Block(-7,53,2,172)
Block(-7,53,3,172)
Block(-7,53,4,172)
Block(-7,53,5,172)
Block(-7,53,6,172)
Block(-7,54,-9,172)
Block(-7,54,-8,172)
Block(-7,54,-7,172)
Block(-7,54,-6,172)
Block(-7,54,-5,172)
Block(-7,54,-4,172)
Block(-7,54,-3,172)
Block(-7,54,-2,172)
Block(-7,54,-1,172)
Block(-7,54,0,172)
Block(-7,54,1,172)
Block(-7,54,2,172)
Block(-7,54,3,172)
Block(-7,54,4,172)
Block(-7,54,5,172)
