
#######################################################################
# +-----------------------------------------------------------------+ #
# |                            BO3 object                           | #
# +-----------------------------------------------------------------+ #
#######################################################################

Author: MC_Pitman

Description: No description given

Version: 3

SettingsMode: WriteDisable


#######################################################################
# +-----------------------------------------------------------------+ #
# |                          Main settings                          | #
# +-----------------------------------------------------------------+ #
#######################################################################

Tree: false

Frequency: 1

Rarity: 5.0

RotateRandomly: true

SpawnHeight: highestSolidBlock

SpawnHeightOffset: -4

SpawnHeightVariance: 0

##############################
# Height Limits for the BO3. #
##############################

MinHeight: 121

MaxHeight: 255

######################
# Extrusion settings #
######################

ExtrudeMode: None

ExtrudeThroughBlocks: AIR

MaxBranchDepth: 10

ExcludedBiomes: All


#######################################################################
# +-----------------------------------------------------------------+ #
# |                      Source block settings                      | #
# +-----------------------------------------------------------------+ #
#######################################################################

SourceBlocks: STONE:1,STONE:3,STONE:5,DIRT:1,DIRT:0,SAND:0,GRASS:0,DIRT:2,STATIONARY_WATER:0,HARD_CLAY,STAINED_CLAY,CLAY,SANDSTONE:0,SAND:1,AIR,STONE:0,GRAVEL,LONG_GRASS:0,LONG_GRASS:1,LONG_GRASS:2,DEAD_BUSH,YELLOW_FLOWER:0,RED_ROSE:0,BROWN_MUSHROOM,RED_MUSHROOM

MaxPercentageOutsideSourceBlock: 0

OutsideSourceBlock: placeAnyway

IsOTGPlus: false


#######################################################################
# +-----------------------------------------------------------------+ #
# |                              Blocks                             | #
# +-----------------------------------------------------------------+ #
#######################################################################

Block(-11,-4,-2,STONE:0)
Block(-11,-3,-2,STONE:0)
Block(-10,-7,-2,STONE:0)
Block(-10,-7,-1,STONE:0)
Block(-10,-6,-2,STONE:0)
Block(-10,-6,-1,STONE:0)
Block(-10,-6,0,STONE:0)
Block(-10,-5,-2,STONE:0)
Block(-10,-5,-1,STONE:0)
Block(-10,-5,0,STONE:0)
Block(-10,-5,1,STONE:0)
Block(-10,-4,-3,STONE:0)
Block(-10,-4,-2,STONE:0)
Block(-10,-4,-1,STONE:0)
Block(-10,-4,0,STONE:0)
Block(-10,-4,1,STONE:0)
Block(-10,-4,2,STONE:0)
Block(-10,-3,-3,STONE:0)
Block(-10,-3,-2,STONE:0)
Block(-10,-3,-1,STONE:0)
Block(-10,-3,0,STONE:0)
Block(-10,-3,1,STONE:0)
Block(-10,-3,2,STONE:0)
Block(-10,-2,-3,STONE:0)
Block(-10,-2,-2,STONE:0)
Block(-10,-2,-1,STONE:0)
Block(-10,-2,0,STONE:0)
Block(-10,-2,1,STONE:0)
Block(-10,-2,2,STONE:0)
Block(-10,-1,-2,STONE:0)
Block(-10,-1,-1,STONE:0)
Block(-10,-1,0,STONE:0)
Block(-10,-1,1,STONE:0)
Block(-10,0,-2,STONE:0)
Block(-10,0,-1,STONE:0)
Block(-10,0,0,STONE:0)
Block(-10,0,1,STONE:0)
Block(-10,1,-2,STONE:0)
Block(-10,1,-1,STONE:0)
Block(-10,1,0,STONE:0)
Block(-10,1,1,STONE:0)
Block(-10,2,-2,STONE:0)
Block(-10,2,-1,STONE:0)
Block(-10,2,0,STONE:0)
Block(-9,-8,-2,STONE:0)
Block(-9,-8,-1,STONE:0)
Block(-9,-8,0,STONE:0)
Block(-9,-7,-2,STONE:0)
Block(-9,-7,-1,STONE:0)
Block(-9,-7,0,STONE:0)
Block(-9,-7,1,STONE:0)
Block(-9,-6,-3,STONE:0)
Block(-9,-6,-2,STONE:0)
Block(-9,-6,-1,STONE:0)
Block(-9,-6,0,STONE:0)
Block(-9,-6,1,STONE:0)
Block(-9,-6,2,STONE:0)
Block(-9,-5,-3,STONE:0)
Block(-9,-5,-2,STONE:0)
Block(-9,-5,-1,STONE:0)
Block(-9,-5,0,STONE:0)
Block(-9,-5,1,STONE:0)
Block(-9,-5,2,STONE:0)
Block(-9,-5,3,STONE:0)
Block(-9,-4,-3,STONE:0)
Block(-9,-4,-2,STONE:0)
Block(-9,-4,-1,STONE:0)
Block(-9,-4,0,STONE:0)
Block(-9,-4,1,STONE:0)
Block(-9,-4,2,STONE:0)
Block(-9,-4,3,STONE:0)
Block(-9,-3,-3,STONE:0)
Block(-9,-3,-2,STONE:0)
Block(-9,-3,-1,STONE:0)
Block(-9,-3,0,STONE:0)
Block(-9,-3,1,STONE:0)
Block(-9,-3,2,STONE:0)
Block(-9,-3,3,STONE:0)
Block(-9,-3,4,STONE:0)
Block(-9,-2,-3,STONE:0)
Block(-9,-2,-2,STONE:0)
Block(-9,-2,-1,STONE:0)
Block(-9,-2,0,STONE:0)
Block(-9,-2,1,STONE:0)
Block(-9,-2,2,STONE:0)
Block(-9,-2,3,STONE:0)
Block(-9,-2,4,STONE:0)
Block(-9,-1,-3,STONE:0)
Block(-9,-1,-2,STONE:0)
Block(-9,-1,-1,STONE:0)
Block(-9,-1,0,STONE:0)
Block(-9,-1,1,STONE:0)
Block(-9,-1,2,STONE:0)
Block(-9,-1,3,STONE:0)
Block(-9,-1,4,STONE:0)
Block(-9,0,-3,STONE:0)
Block(-9,0,-2,STONE:0)
Block(-9,0,-1,STONE:0)
Block(-9,0,0,STONE:0)
Block(-9,0,1,STONE:0)
Block(-9,0,2,STONE:0)
Block(-9,0,3,STONE:0)
Block(-9,1,-3,STONE:0)
Block(-9,1,-2,STONE:0)
Block(-9,1,-1,STONE:0)
Block(-9,1,0,STONE:0)
Block(-9,1,1,STONE:0)
Block(-9,1,2,STONE:0)
Block(-9,1,3,STONE:0)
Block(-9,2,-3,STONE:0)
Block(-9,2,-2,STONE:0)
Block(-9,2,-1,STONE:0)
Block(-9,2,0,STONE:0)
Block(-9,2,1,STONE:0)
Block(-9,2,2,STONE:0)
Block(-9,2,3,STONE:0)
Block(-9,3,1,STONE:0)
Block(-9,3,2,STONE:0)
Block(-8,-9,-2,STONE:0)
Block(-8,-9,-1,STONE:0)
Block(-8,-9,0,STONE:0)
Block(-8,-9,1,STONE:0)
Block(-8,-9,2,STONE:0)
Block(-8,-8,-2,STONE:0)
Block(-8,-8,-1,STONE:0)
Block(-8,-8,0,STONE:0)
Block(-8,-8,1,STONE:0)
Block(-8,-8,2,STONE:0)
Block(-8,-8,3,STONE:0)
Block(-8,-7,-3,STONE:0)
Block(-8,-7,-2,STONE:0)
Block(-8,-7,-1,STONE:0)
Block(-8,-7,0,STONE:0)
Block(-8,-7,1,STONE:0)
Block(-8,-7,2,STONE:0)
Block(-8,-7,3,STONE:0)
Block(-8,-6,-3,STONE:0)
Block(-8,-6,-2,STONE:0)
Block(-8,-6,-1,STONE:0)
Block(-8,-6,0,STONE:0)
Block(-8,-6,1,STONE:0)
Block(-8,-6,2,STONE:0)
Block(-8,-6,3,STONE:0)
Block(-8,-6,4,STONE:0)
Block(-8,-5,-4,STONE:0)
Block(-8,-5,-3,STONE:0)
Block(-8,-5,-2,STONE:0)
Block(-8,-5,-1,STONE:0)
Block(-8,-5,0,STONE:0)
Block(-8,-5,1,STONE:0)
Block(-8,-5,2,STONE:0)
Block(-8,-5,3,STONE:0)
Block(-8,-5,4,STONE:0)
Block(-8,-5,5,STONE:0)
Block(-8,-4,-4,STONE:0)
Block(-8,-4,-3,STONE:0)
Block(-8,-4,-2,STONE:0)
Block(-8,-4,-1,STONE:0)
Block(-8,-4,0,STONE:0)
Block(-8,-4,1,STONE:0)
Block(-8,-4,2,STONE:0)
Block(-8,-4,3,STONE:0)
Block(-8,-4,4,STONE:0)
Block(-8,-4,5,STONE:0)
Block(-8,-3,-4,STONE:0)
Block(-8,-3,-3,STONE:0)
Block(-8,-3,-2,STONE:0)
Block(-8,-3,-1,STONE:0)
Block(-8,-3,0,STONE:0)
Block(-8,-3,1,STONE:0)
Block(-8,-3,2,STONE:0)
Block(-8,-3,3,STONE:0)
Block(-8,-3,4,STONE:0)
Block(-8,-3,5,STONE:0)
Block(-8,-2,-4,STONE:0)
Block(-8,-2,-3,STONE:0)
Block(-8,-2,-2,STONE:0)
Block(-8,-2,-1,STONE:0)
Block(-8,-2,0,STONE:0)
Block(-8,-2,1,STONE:0)
Block(-8,-2,2,STONE:0)
Block(-8,-2,3,STONE:0)
Block(-8,-2,4,STONE:0)
Block(-8,-2,5,STONE:0)
Block(-8,-1,-4,STONE:0)
Block(-8,-1,-3,STONE:0)
Block(-8,-1,-2,STONE:0)
Block(-8,-1,-1,STONE:0)
Block(-8,-1,0,STONE:0)
Block(-8,-1,1,STONE:0)
Block(-8,-1,2,STONE:0)
Block(-8,-1,3,STONE:0)
Block(-8,-1,4,STONE:0)
Block(-8,-1,5,STONE:0)
Block(-8,0,-4,STONE:0)
Block(-8,0,-3,STONE:0)
Block(-8,0,-2,STONE:0)
Block(-8,0,-1,STONE:0)
Block(-8,0,0,STONE:0)
Block(-8,0,1,STONE:0)
Block(-8,0,2,STONE:0)
Block(-8,0,3,STONE:0)
Block(-8,0,4,STONE:0)
Block(-8,1,-3,STONE:0)
Block(-8,1,-2,STONE:0)
Block(-8,1,-1,STONE:0)
Block(-8,1,0,STONE:0)
Block(-8,1,1,STONE:0)
Block(-8,1,2,STONE:0)
Block(-8,1,3,STONE:0)
Block(-8,1,4,STONE:0)
Block(-8,2,-3,STONE:0)
Block(-8,2,-2,STONE:0)
Block(-8,2,-1,STONE:0)
Block(-8,2,0,STONE:0)
Block(-8,2,1,STONE:0)
Block(-8,2,2,STONE:0)
Block(-8,2,3,STONE:0)
Block(-8,3,-2,STONE:0)
Block(-8,3,-1,STONE:0)
Block(-8,3,0,STONE:0)
Block(-8,3,1,STONE:0)
Block(-8,3,2,STONE:0)
Block(-8,3,3,STONE:0)
Block(-7,-9,-3,STONE:0)
Block(-7,-9,-2,STONE:0)
Block(-7,-9,-1,STONE:0)
Block(-7,-9,0,STONE:0)
Block(-7,-9,1,STONE:0)
Block(-7,-9,2,STONE:0)
Block(-7,-9,3,STONE:0)
Block(-7,-9,4,STONE:0)
Block(-7,-8,-3,STONE:0)
Block(-7,-8,-2,STONE:0)
Block(-7,-8,-1,STONE:0)
Block(-7,-8,0,STONE:0)
Block(-7,-8,1,STONE:0)
Block(-7,-8,2,STONE:0)
Block(-7,-8,3,STONE:0)
Block(-7,-8,4,STONE:0)
Block(-7,-7,-4,STONE:0)
Block(-7,-7,-3,STONE:0)
Block(-7,-7,-2,STONE:0)
Block(-7,-7,-1,STONE:0)
Block(-7,-7,0,STONE:0)
Block(-7,-7,1,STONE:0)
Block(-7,-7,2,STONE:0)
Block(-7,-7,3,STONE:0)
Block(-7,-7,4,STONE:0)
Block(-7,-7,5,STONE:0)
Block(-7,-6,-4,STONE:0)
Block(-7,-6,-3,STONE:0)
Block(-7,-6,-2,STONE:0)
Block(-7,-6,-1,STONE:0)
Block(-7,-6,0,STONE:0)
Block(-7,-6,1,STONE:0)
Block(-7,-6,2,STONE:0)
Block(-7,-6,3,STONE:0)
Block(-7,-6,4,STONE:0)
Block(-7,-6,5,STONE:0)
Block(-7,-5,-4,STONE:0)
Block(-7,-5,-3,STONE:0)
Block(-7,-5,-2,STONE:0)
Block(-7,-5,-1,STONE:0)
Block(-7,-5,0,STONE:0)
Block(-7,-5,1,STONE:0)
Block(-7,-5,2,STONE:0)
Block(-7,-5,3,STONE:0)
Block(-7,-5,4,STONE:0)
Block(-7,-5,5,STONE:0)
Block(-7,-5,6,STONE:0)
Block(-7,-4,-5,STONE:0)
Block(-7,-4,-4,STONE:0)
Block(-7,-4,-3,STONE:0)
Block(-7,-4,-2,STONE:0)
Block(-7,-4,-1,STONE:0)
Block(-7,-4,0,STONE:0)
Block(-7,-4,1,STONE:0)
Block(-7,-4,2,STONE:0)
Block(-7,-4,3,STONE:0)
Block(-7,-4,4,STONE:0)
Block(-7,-4,5,STONE:0)
Block(-7,-4,6,STONE:0)
Block(-7,-3,-5,STONE:0)
Block(-7,-3,-4,STONE:0)
Block(-7,-3,-3,STONE:0)
Block(-7,-3,-2,STONE:0)
Block(-7,-3,-1,STONE:0)
Block(-7,-3,0,STONE:0)
Block(-7,-3,1,STONE:0)
Block(-7,-3,2,STONE:0)
Block(-7,-3,3,STONE:0)
Block(-7,-3,4,STONE:0)
Block(-7,-3,5,STONE:0)
Block(-7,-3,6,STONE:0)
Block(-7,-2,-5,STONE:0)
Block(-7,-2,-4,STONE:0)
Block(-7,-2,-3,STONE:0)
Block(-7,-2,-2,STONE:0)
Block(-7,-2,-1,STONE:0)
Block(-7,-2,0,STONE:0)
Block(-7,-2,1,STONE:0)
Block(-7,-2,2,STONE:0)
Block(-7,-2,3,STONE:0)
Block(-7,-2,4,STONE:0)
Block(-7,-2,5,STONE:0)
Block(-7,-2,6,STONE:0)
Block(-7,-1,-5,STONE:0)
Block(-7,-1,-4,STONE:0)
Block(-7,-1,-3,STONE:0)
Block(-7,-1,-2,STONE:0)
Block(-7,-1,-1,STONE:0)
Block(-7,-1,0,STONE:0)
Block(-7,-1,1,STONE:0)
Block(-7,-1,2,STONE:0)
Block(-7,-1,3,STONE:0)
Block(-7,-1,4,STONE:0)
Block(-7,-1,5,STONE:0)
Block(-7,0,-4,STONE:0)
Block(-7,0,-3,STONE:0)
Block(-7,0,-2,STONE:0)
Block(-7,0,-1,STONE:0)
Block(-7,0,0,STONE:0)
Block(-7,0,1,STONE:0)
Block(-7,0,2,STONE:0)
Block(-7,0,3,STONE:0)
Block(-7,0,4,STONE:0)
Block(-7,0,5,STONE:0)
Block(-7,1,-4,STONE:0)
Block(-7,1,-3,STONE:0)
Block(-7,1,-2,STONE:0)
Block(-7,1,-1,STONE:0)
Block(-7,1,0,STONE:0)
Block(-7,1,1,STONE:0)
Block(-7,1,2,STONE:0)
Block(-7,1,3,STONE:0)
Block(-7,1,4,STONE:0)
Block(-7,2,-4,STONE:0)
Block(-7,2,-3,STONE:0)
Block(-7,2,-2,STONE:0)
Block(-7,2,-1,STONE:0)
Block(-7,2,0,STONE:0)
Block(-7,2,1,STONE:0)
Block(-7,2,2,STONE:0)
Block(-7,2,3,STONE:0)
Block(-7,2,4,STONE:0)
Block(-7,3,-4,STONE:0)
Block(-7,3,-3,STONE:0)
Block(-7,3,-2,STONE:0)
Block(-7,3,-1,STONE:0)
Block(-7,3,0,STONE:0)
Block(-7,3,1,STONE:0)
Block(-7,3,2,STONE:0)
Block(-7,3,3,STONE:0)
Block(-6,-10,-1,STONE:0)
Block(-6,-10,0,STONE:0)
Block(-6,-9,-3,STONE:0)
Block(-6,-9,-2,STONE:0)
Block(-6,-9,-1,STONE:0)
Block(-6,-9,0,STONE:0)
Block(-6,-9,1,STONE:0)
Block(-6,-9,2,STONE:0)
Block(-6,-9,3,STONE:0)
Block(-6,-9,4,STONE:0)
Block(-6,-8,-4,STONE:0)
Block(-6,-8,-3,STONE:0)
Block(-6,-8,-2,STONE:0)
Block(-6,-8,-1,STONE:0)
Block(-6,-8,0,STONE:0)
Block(-6,-8,1,STONE:0)
Block(-6,-8,2,STONE:0)
Block(-6,-8,3,STONE:0)
Block(-6,-8,4,STONE:0)
Block(-6,-8,5,STONE:0)
Block(-6,-7,-4,STONE:0)
Block(-6,-7,-3,STONE:0)
Block(-6,-7,-2,STONE:0)
Block(-6,-7,-1,STONE:0)
Block(-6,-7,0,STONE:0)
Block(-6,-7,1,STONE:0)
Block(-6,-7,2,STONE:0)
Block(-6,-7,3,STONE:0)
Block(-6,-7,4,STONE:0)
Block(-6,-7,5,STONE:0)
Block(-6,-6,-4,STONE:0)
Block(-6,-6,-3,STONE:0)
Block(-6,-6,-2,STONE:0)
Block(-6,-6,-1,STONE:0)
Block(-6,-6,0,STONE:0)
Block(-6,-6,1,STONE:0)
Block(-6,-6,2,STONE:0)
Block(-6,-6,3,STONE:0)
Block(-6,-6,4,STONE:0)
Block(-6,-6,5,STONE:0)
Block(-6,-6,6,STONE:0)
Block(-6,-5,-5,STONE:0)
Block(-6,-5,-4,STONE:0)
Block(-6,-5,-3,STONE:0)
Block(-6,-5,-2,STONE:0)
Block(-6,-5,-1,STONE:0)
Block(-6,-5,0,STONE:0)
Block(-6,-5,1,STONE:0)
Block(-6,-5,2,STONE:0)
Block(-6,-5,3,STONE:0)
Block(-6,-5,4,STONE:0)
Block(-6,-5,5,STONE:0)
Block(-6,-5,6,STONE:0)
Block(-6,-4,-5,STONE:0)
Block(-6,-4,-4,STONE:0)
Block(-6,-4,-3,STONE:0)
Block(-6,-4,-2,STONE:0)
Block(-6,-4,-1,STONE:0)
Block(-6,-4,0,STONE:0)
Block(-6,-4,1,STONE:0)
Block(-6,-4,2,STONE:0)
Block(-6,-4,3,STONE:0)
Block(-6,-4,4,STONE:0)
Block(-6,-4,5,STONE:0)
Block(-6,-4,6,STONE:0)
Block(-6,-3,-5,STONE:0)
Block(-6,-3,-4,STONE:0)
Block(-6,-3,-3,STONE:0)
Block(-6,-3,-2,STONE:0)
Block(-6,-3,-1,STONE:0)
Block(-6,-3,0,STONE:0)
Block(-6,-3,1,STONE:0)
Block(-6,-3,2,STONE:0)
Block(-6,-3,3,STONE:0)
Block(-6,-3,4,STONE:0)
Block(-6,-3,5,STONE:0)
Block(-6,-3,6,STONE:0)
Block(-6,-2,-5,STONE:0)
Block(-6,-2,-4,STONE:0)
Block(-6,-2,-3,STONE:0)
Block(-6,-2,-2,STONE:0)
Block(-6,-2,-1,STONE:0)
Block(-6,-2,0,STONE:0)
Block(-6,-2,1,STONE:0)
Block(-6,-2,2,STONE:0)
Block(-6,-2,3,STONE:0)
Block(-6,-2,4,STONE:0)
Block(-6,-2,5,STONE:0)
Block(-6,-2,6,STONE:0)
Block(-6,-1,-5,STONE:0)
Block(-6,-1,-4,STONE:0)
Block(-6,-1,-3,STONE:0)
Block(-6,-1,-2,STONE:0)
Block(-6,-1,-1,STONE:0)
Block(-6,-1,0,STONE:0)
Block(-6,-1,1,STONE:0)
Block(-6,-1,2,STONE:0)
Block(-6,-1,3,STONE:0)
Block(-6,-1,4,STONE:0)
Block(-6,-1,5,STONE:0)
Block(-6,-1,6,STONE:0)
Block(-6,0,-5,STONE:0)
Block(-6,0,-4,STONE:0)
Block(-6,0,-3,STONE:0)
Block(-6,0,-2,STONE:0)
Block(-6,0,-1,STONE:0)
Block(-6,0,0,STONE:0)
Block(-6,0,1,STONE:0)
Block(-6,0,2,STONE:0)
Block(-6,0,3,STONE:0)
Block(-6,0,4,STONE:0)
Block(-6,0,5,STONE:0)
Block(-6,1,-5,STONE:0)
Block(-6,1,-4,STONE:0)
Block(-6,1,-3,STONE:0)
Block(-6,1,-2,STONE:0)
Block(-6,1,-1,STONE:0)
Block(-6,1,0,STONE:0)
Block(-6,1,1,STONE:0)
Block(-6,1,2,STONE:0)
Block(-6,1,3,STONE:0)
Block(-6,1,4,STONE:0)
Block(-6,1,5,STONE:0)
Block(-6,2,-5,STONE:0)
Block(-6,2,-4,STONE:0)
Block(-6,2,-3,STONE:0)
Block(-6,2,-2,STONE:0)
Block(-6,2,-1,STONE:0)
Block(-6,2,0,STONE:0)
Block(-6,2,1,STONE:0)
Block(-6,2,2,STONE:0)
Block(-6,2,3,STONE:0)
Block(-6,2,4,STONE:0)
Block(-6,3,-5,STONE:0)
Block(-6,3,-4,STONE:0)
Block(-6,3,-3,STONE:0)
Block(-6,3,-2,STONE:0)
Block(-6,3,-1,STONE:0)
Block(-6,3,0,STONE:0)
Block(-6,3,1,STONE:0)
Block(-6,3,2,STONE:0)
Block(-6,3,3,STONE:0)
Block(-6,3,4,STONE:0)
Block(-5,-10,-2,STONE:0)
Block(-5,-10,-1,STONE:0)
Block(-5,-10,0,STONE:0)
Block(-5,-10,1,STONE:0)
Block(-5,-9,-4,STONE:0)
Block(-5,-9,-3,STONE:0)
Block(-5,-9,-2,STONE:0)
Block(-5,-9,-1,STONE:0)
Block(-5,-9,0,STONE:0)
Block(-5,-9,1,STONE:0)
Block(-5,-9,2,STONE:0)
Block(-5,-9,3,STONE:0)
Block(-5,-9,4,STONE:0)
Block(-5,-9,5,STONE:0)
Block(-5,-8,-4,STONE:0)
Block(-5,-8,-3,STONE:0)
Block(-5,-8,-2,STONE:0)
Block(-5,-8,-1,STONE:0)
Block(-5,-8,0,STONE:0)
Block(-5,-8,1,STONE:0)
Block(-5,-8,2,STONE:0)
Block(-5,-8,3,STONE:0)
Block(-5,-8,4,STONE:0)
Block(-5,-8,5,STONE:0)
Block(-5,-7,-4,STONE:0)
Block(-5,-7,-3,STONE:0)
Block(-5,-7,-2,STONE:0)
Block(-5,-7,-1,STONE:0)
Block(-5,-7,0,STONE:0)
Block(-5,-7,1,STONE:0)
Block(-5,-7,2,STONE:0)
Block(-5,-7,3,STONE:0)
Block(-5,-7,4,STONE:0)
Block(-5,-7,5,STONE:0)
Block(-5,-7,6,STONE:0)
Block(-5,-6,-5,STONE:0)
Block(-5,-6,-4,STONE:0)
Block(-5,-6,-3,STONE:0)
Block(-5,-6,-2,STONE:0)
Block(-5,-6,-1,STONE:0)
Block(-5,-6,0,STONE:0)
Block(-5,-6,1,STONE:0)
Block(-5,-6,2,STONE:0)
Block(-5,-6,3,STONE:0)
Block(-5,-6,4,STONE:0)
Block(-5,-6,5,STONE:0)
Block(-5,-6,6,STONE:0)
Block(-5,-5,-5,STONE:0)
Block(-5,-5,-4,STONE:0)
Block(-5,-5,-3,STONE:0)
Block(-5,-5,-2,STONE:0)
Block(-5,-5,-1,STONE:0)
Block(-5,-5,0,STONE:0)
Block(-5,-5,1,STONE:0)
Block(-5,-5,2,STONE:0)
Block(-5,-5,3,STONE:0)
Block(-5,-5,4,STONE:0)
Block(-5,-5,5,STONE:0)
Block(-5,-5,6,STONE:0)
Block(-5,-5,7,STONE:0)
Block(-5,-4,-5,STONE:0)
Block(-5,-4,-4,STONE:0)
Block(-5,-4,-3,STONE:0)
Block(-5,-4,-2,STONE:0)
Block(-5,-4,-1,STONE:0)
Block(-5,-4,0,STONE:0)
Block(-5,-4,1,STONE:0)
Block(-5,-4,2,STONE:0)
Block(-5,-4,3,STONE:0)
Block(-5,-4,4,STONE:0)
Block(-5,-4,5,STONE:0)
Block(-5,-4,6,STONE:0)
Block(-5,-4,7,STONE:0)
Block(-5,-3,-5,STONE:0)
Block(-5,-3,-4,STONE:0)
Block(-5,-3,-3,STONE:0)
Block(-5,-3,-2,STONE:0)
Block(-5,-3,-1,STONE:0)
Block(-5,-3,0,STONE:0)
Block(-5,-3,1,STONE:0)
Block(-5,-3,2,STONE:0)
Block(-5,-3,3,STONE:0)
Block(-5,-3,4,STONE:0)
Block(-5,-3,5,STONE:0)
Block(-5,-3,6,STONE:0)
Block(-5,-3,7,STONE:0)
Block(-5,-2,-6,STONE:0)
Block(-5,-2,-5,STONE:0)
Block(-5,-2,-4,STONE:0)
Block(-5,-2,-3,STONE:0)
Block(-5,-2,-2,STONE:0)
Block(-5,-2,-1,STONE:0)
Block(-5,-2,0,STONE:0)
Block(-5,-2,1,STONE:0)
Block(-5,-2,2,STONE:0)
Block(-5,-2,3,STONE:0)
Block(-5,-2,4,STONE:0)
Block(-5,-2,5,STONE:0)
Block(-5,-2,6,STONE:0)
Block(-5,-1,-6,STONE:0)
Block(-5,-1,-5,STONE:0)
Block(-5,-1,-4,STONE:0)
Block(-5,-1,-3,STONE:0)
Block(-5,-1,-2,STONE:0)
Block(-5,-1,-1,STONE:0)
Block(-5,-1,0,STONE:0)
Block(-5,-1,1,STONE:0)
Block(-5,-1,2,STONE:0)
Block(-5,-1,3,STONE:0)
Block(-5,-1,4,STONE:0)
Block(-5,-1,5,STONE:0)
Block(-5,-1,6,STONE:0)
Block(-5,0,-6,STONE:0)
Block(-5,0,-5,STONE:0)
Block(-5,0,-4,STONE:0)
Block(-5,0,-3,STONE:0)
Block(-5,0,-2,STONE:0)
Block(-5,0,-1,STONE:0)
Block(-5,0,0,STONE:0)
Block(-5,0,1,STONE:0)
Block(-5,0,2,STONE:0)
Block(-5,0,3,STONE:0)
Block(-5,0,4,STONE:0)
Block(-5,0,5,STONE:0)
Block(-5,0,6,STONE:0)
Block(-5,1,-6,STONE:0)
Block(-5,1,-5,STONE:0)
Block(-5,1,-4,STONE:0)
Block(-5,1,-3,STONE:0)
Block(-5,1,-2,STONE:0)
Block(-5,1,-1,STONE:0)
Block(-5,1,0,STONE:0)
Block(-5,1,1,STONE:0)
Block(-5,1,2,STONE:0)
Block(-5,1,3,STONE:0)
Block(-5,1,4,STONE:0)
Block(-5,1,5,STONE:0)
Block(-5,2,-5,STONE:0)
Block(-5,2,-4,STONE:0)
Block(-5,2,-3,STONE:0)
Block(-5,2,-2,STONE:0)
Block(-5,2,-1,STONE:0)
Block(-5,2,0,STONE:0)
Block(-5,2,1,STONE:0)
Block(-5,2,2,STONE:0)
Block(-5,2,3,STONE:0)
Block(-5,2,4,STONE:0)
Block(-5,2,5,STONE:0)
Block(-5,3,-5,STONE:0)
Block(-5,3,-4,STONE:0)
Block(-5,3,-3,STONE:0)
Block(-5,3,-2,STONE:0)
Block(-5,3,-1,STONE:0)
Block(-5,3,0,STONE:0)
Block(-5,3,1,STONE:0)
Block(-5,3,2,STONE:0)
Block(-5,3,3,STONE:0)
Block(-5,3,4,STONE:0)
Block(-4,-10,-3,STONE:0)
Block(-4,-10,-2,STONE:0)
Block(-4,-10,-1,STONE:0)
Block(-4,-10,0,STONE:0)
Block(-4,-10,1,STONE:0)
Block(-4,-9,-4,STONE:0)
Block(-4,-9,-3,STONE:0)
Block(-4,-9,-2,STONE:0)
Block(-4,-9,-1,STONE:0)
Block(-4,-9,0,STONE:0)
Block(-4,-9,1,STONE:0)
Block(-4,-9,2,STONE:0)
Block(-4,-9,3,STONE:0)
Block(-4,-9,4,STONE:0)
Block(-4,-9,5,STONE:0)
Block(-4,-8,-4,STONE:0)
Block(-4,-8,-3,STONE:0)
Block(-4,-8,-2,STONE:0)
Block(-4,-8,-1,STONE:0)
Block(-4,-8,0,STONE:0)
Block(-4,-8,1,STONE:0)
Block(-4,-8,2,STONE:0)
Block(-4,-8,3,STONE:0)
Block(-4,-8,4,STONE:0)
Block(-4,-8,5,STONE:0)
Block(-4,-8,6,STONE:0)
Block(-4,-7,-5,STONE:0)
Block(-4,-7,-4,STONE:0)
Block(-4,-7,-3,STONE:0)
Block(-4,-7,-2,STONE:0)
Block(-4,-7,-1,STONE:0)
Block(-4,-7,0,STONE:0)
Block(-4,-7,1,STONE:0)
Block(-4,-7,2,STONE:0)
Block(-4,-7,3,STONE:0)
Block(-4,-7,4,STONE:0)
Block(-4,-7,5,STONE:0)
Block(-4,-7,6,STONE:0)
Block(-4,-6,-5,STONE:0)
Block(-4,-6,-4,STONE:0)
Block(-4,-6,-3,STONE:0)
Block(-4,-6,-2,STONE:0)
Block(-4,-6,-1,STONE:0)
Block(-4,-6,0,STONE:0)
Block(-4,-6,1,STONE:0)
Block(-4,-6,2,STONE:0)
Block(-4,-6,3,STONE:0)
Block(-4,-6,4,STONE:0)
Block(-4,-6,5,STONE:0)
Block(-4,-6,6,STONE:0)
Block(-4,-6,7,STONE:0)
Block(-4,-5,-5,STONE:0)
Block(-4,-5,-4,STONE:0)
Block(-4,-5,-3,STONE:0)
Block(-4,-5,-2,STONE:0)
Block(-4,-5,-1,STONE:0)
Block(-4,-5,0,STONE:0)
Block(-4,-5,1,STONE:0)
Block(-4,-5,2,STONE:0)
Block(-4,-5,3,STONE:0)
Block(-4,-5,4,STONE:0)
Block(-4,-5,5,STONE:0)
Block(-4,-5,6,STONE:0)
Block(-4,-5,7,STONE:0)
Block(-4,-4,-5,STONE:0)
Block(-4,-4,-4,STONE:0)
Block(-4,-4,-3,STONE:0)
Block(-4,-4,-2,STONE:0)
Block(-4,-4,-1,STONE:0)
Block(-4,-4,0,STONE:0)
Block(-4,-4,1,STONE:0)
Block(-4,-4,2,STONE:0)
Block(-4,-4,3,STONE:0)
Block(-4,-4,4,STONE:0)
Block(-4,-4,5,STONE:0)
Block(-4,-4,6,STONE:0)
Block(-4,-4,7,STONE:0)
Block(-4,-3,-6,STONE:0)
Block(-4,-3,-5,STONE:0)
Block(-4,-3,-4,STONE:0)
Block(-4,-3,-3,STONE:0)
Block(-4,-3,-2,STONE:0)
Block(-4,-3,-1,STONE:0)
Block(-4,-3,0,STONE:0)
Block(-4,-3,1,STONE:0)
Block(-4,-3,2,STONE:0)
Block(-4,-3,3,STONE:0)
Block(-4,-3,4,STONE:0)
Block(-4,-3,5,STONE:0)
Block(-4,-3,6,STONE:0)
Block(-4,-3,7,STONE:0)
Block(-4,-2,-6,STONE:0)
Block(-4,-2,-5,STONE:0)
Block(-4,-2,-4,STONE:0)
Block(-4,-2,-3,STONE:0)
Block(-4,-2,-2,STONE:0)
Block(-4,-2,-1,STONE:0)
Block(-4,-2,0,STONE:0)
Block(-4,-2,1,STONE:0)
Block(-4,-2,2,STONE:0)
Block(-4,-2,3,STONE:0)
Block(-4,-2,4,STONE:0)
Block(-4,-2,5,STONE:0)
Block(-4,-2,6,STONE:0)
Block(-4,-1,-6,STONE:0)
Block(-4,-1,-5,STONE:0)
Block(-4,-1,-4,STONE:0)
Block(-4,-1,-3,STONE:0)
Block(-4,-1,-2,STONE:0)
Block(-4,-1,-1,STONE:0)
Block(-4,-1,0,STONE:0)
Block(-4,-1,1,STONE:0)
Block(-4,-1,2,STONE:0)
Block(-4,-1,3,STONE:0)
Block(-4,-1,4,STONE:0)
Block(-4,-1,5,STONE:0)
Block(-4,-1,6,STONE:0)
Block(-4,0,-6,STONE:0)
Block(-4,0,-5,STONE:0)
Block(-4,0,-4,STONE:0)
Block(-4,0,-3,STONE:0)
Block(-4,0,-2,STONE:0)
Block(-4,0,-1,STONE:0)
Block(-4,0,0,STONE:0)
Block(-4,0,1,STONE:0)
Block(-4,0,2,STONE:0)
Block(-4,0,3,STONE:0)
Block(-4,0,4,STONE:0)
Block(-4,0,5,STONE:0)
Block(-4,0,6,STONE:0)
Block(-4,1,-6,STONE:0)
Block(-4,1,-5,STONE:0)
Block(-4,1,-4,STONE:0)
Block(-4,1,-3,STONE:0)
Block(-4,1,-2,STONE:0)
Block(-4,1,-1,STONE:0)
Block(-4,1,0,STONE:0)
Block(-4,1,1,STONE:0)
Block(-4,1,2,STONE:0)
Block(-4,1,3,STONE:0)
Block(-4,1,4,STONE:0)
Block(-4,1,5,STONE:0)
Block(-4,2,-6,STONE:0)
Block(-4,2,-5,STONE:0)
Block(-4,2,-4,STONE:0)
Block(-4,2,-3,STONE:0)
Block(-4,2,-2,STONE:0)
Block(-4,2,-1,STONE:0)
Block(-4,2,0,STONE:0)
Block(-4,2,1,STONE:0)
Block(-4,2,2,STONE:0)
Block(-4,2,3,STONE:0)
Block(-4,2,4,STONE:0)
Block(-4,2,5,STONE:0)
Block(-4,3,-5,STONE:0)
Block(-4,3,-4,STONE:0)
Block(-4,3,-3,STONE:0)
Block(-4,3,-2,STONE:0)
Block(-4,3,-1,STONE:0)
Block(-4,3,0,STONE:0)
Block(-4,3,1,STONE:0)
Block(-4,3,2,STONE:0)
Block(-4,3,3,STONE:0)
Block(-4,3,4,STONE:0)
Block(-4,3,5,STONE:0)
Block(-3,-10,-3,STONE:0)
Block(-3,-10,-2,STONE:0)
Block(-3,-10,-1,STONE:0)
Block(-3,-10,0,STONE:0)
Block(-3,-10,1,STONE:0)
Block(-3,-10,2,STONE:0)
Block(-3,-10,3,STONE:0)
Block(-3,-10,4,STONE:0)
Block(-3,-9,-4,STONE:0)
Block(-3,-9,-3,STONE:0)
Block(-3,-9,-2,STONE:0)
Block(-3,-9,-1,STONE:0)
Block(-3,-9,0,STONE:0)
Block(-3,-9,1,STONE:0)
Block(-3,-9,2,STONE:0)
Block(-3,-9,3,STONE:0)
Block(-3,-9,4,STONE:0)
Block(-3,-9,5,STONE:0)
Block(-3,-9,6,STONE:0)
Block(-3,-8,-5,STONE:0)
Block(-3,-8,-4,STONE:0)
Block(-3,-8,-3,STONE:0)
Block(-3,-8,-2,STONE:0)
Block(-3,-8,-1,STONE:0)
Block(-3,-8,0,STONE:0)
Block(-3,-8,1,STONE:0)
Block(-3,-8,2,STONE:0)
Block(-3,-8,3,STONE:0)
Block(-3,-8,4,STONE:0)
Block(-3,-8,5,STONE:0)
Block(-3,-8,6,STONE:0)
Block(-3,-7,-5,STONE:0)
Block(-3,-7,-4,STONE:0)
Block(-3,-7,-3,STONE:0)
Block(-3,-7,-2,STONE:0)
Block(-3,-7,-1,STONE:0)
Block(-3,-7,0,STONE:0)
Block(-3,-7,1,STONE:0)
Block(-3,-7,2,STONE:0)
Block(-3,-7,3,STONE:0)
Block(-3,-7,4,STONE:0)
Block(-3,-7,5,STONE:0)
Block(-3,-7,6,STONE:0)
Block(-3,-7,7,STONE:0)
Block(-3,-6,-5,STONE:0)
Block(-3,-6,-4,STONE:0)
Block(-3,-6,-3,STONE:0)
Block(-3,-6,-2,STONE:0)
Block(-3,-6,-1,STONE:0)
Block(-3,-6,0,STONE:0)
Block(-3,-6,1,STONE:0)
Block(-3,-6,2,STONE:0)
Block(-3,-6,3,STONE:0)
Block(-3,-6,4,STONE:0)
Block(-3,-6,5,STONE:0)
Block(-3,-6,6,STONE:0)
Block(-3,-6,7,STONE:0)
Block(-3,-5,-6,STONE:0)
Block(-3,-5,-5,STONE:0)
Block(-3,-5,-4,STONE:0)
Block(-3,-5,-3,STONE:0)
Block(-3,-5,-2,STONE:0)
Block(-3,-5,-1,STONE:0)
Block(-3,-5,0,STONE:0)
Block(-3,-5,1,STONE:0)
Block(-3,-5,2,STONE:0)
Block(-3,-5,3,STONE:0)
Block(-3,-5,4,STONE:0)
Block(-3,-5,5,STONE:0)
Block(-3,-5,6,STONE:0)
Block(-3,-5,7,STONE:0)
Block(-3,-4,-6,STONE:0)
Block(-3,-4,-5,STONE:0)
Block(-3,-4,-4,STONE:0)
Block(-3,-4,-3,STONE:0)
Block(-3,-4,-2,STONE:0)
Block(-3,-4,-1,STONE:0)
Block(-3,-4,0,STONE:0)
Block(-3,-4,1,STONE:0)
Block(-3,-4,2,STONE:0)
Block(-3,-4,3,STONE:0)
Block(-3,-4,4,STONE:0)
Block(-3,-4,5,STONE:0)
Block(-3,-4,6,STONE:0)
Block(-3,-4,7,STONE:0)
Block(-3,-3,-6,STONE:0)
Block(-3,-3,-5,STONE:0)
Block(-3,-3,-4,STONE:0)
Block(-3,-3,-3,STONE:0)
Block(-3,-3,-2,STONE:0)
Block(-3,-3,-1,STONE:0)
Block(-3,-3,0,STONE:0)
Block(-3,-3,1,STONE:0)
Block(-3,-3,2,STONE:0)
Block(-3,-3,3,STONE:0)
Block(-3,-3,4,STONE:0)
Block(-3,-3,5,STONE:0)
Block(-3,-3,6,STONE:0)
Block(-3,-3,7,STONE:0)
Block(-3,-2,-6,STONE:0)
Block(-3,-2,-5,STONE:0)
Block(-3,-2,-4,STONE:0)
Block(-3,-2,-3,STONE:0)
Block(-3,-2,-2,STONE:0)
Block(-3,-2,-1,STONE:0)
Block(-3,-2,0,STONE:0)
Block(-3,-2,1,STONE:0)
Block(-3,-2,2,STONE:0)
Block(-3,-2,3,STONE:0)
Block(-3,-2,4,STONE:0)
Block(-3,-2,5,STONE:0)
Block(-3,-2,6,STONE:0)
Block(-3,-2,7,STONE:0)
Block(-3,-1,-6,STONE:0)
Block(-3,-1,-5,STONE:0)
Block(-3,-1,-4,STONE:0)
Block(-3,-1,-3,STONE:0)
Block(-3,-1,-2,STONE:0)
Block(-3,-1,-1,STONE:0)
Block(-3,-1,0,STONE:0)
Block(-3,-1,1,STONE:0)
Block(-3,-1,2,STONE:0)
Block(-3,-1,3,STONE:0)
Block(-3,-1,4,STONE:0)
Block(-3,-1,5,STONE:0)
Block(-3,-1,6,STONE:0)
Block(-3,0,-7,STONE:0)
Block(-3,0,-6,STONE:0)
Block(-3,0,-5,STONE:0)
Block(-3,0,-4,STONE:0)
Block(-3,0,-3,STONE:0)
Block(-3,0,-2,STONE:0)
Block(-3,0,-1,STONE:0)
Block(-3,0,0,STONE:0)
Block(-3,0,1,STONE:0)
Block(-3,0,2,STONE:0)
Block(-3,0,3,STONE:0)
Block(-3,0,4,STONE:0)
Block(-3,0,5,STONE:0)
Block(-3,0,6,STONE:0)
Block(-3,1,-6,STONE:0)
Block(-3,1,-5,STONE:0)
Block(-3,1,-4,STONE:0)
Block(-3,1,-3,STONE:0)
Block(-3,1,-2,STONE:0)
Block(-3,1,-1,STONE:0)
Block(-3,1,0,STONE:0)
Block(-3,1,1,STONE:0)
Block(-3,1,2,STONE:0)
Block(-3,1,3,STONE:0)
Block(-3,1,4,STONE:0)
Block(-3,1,5,STONE:0)
Block(-3,2,-6,STONE:0)
Block(-3,2,-5,STONE:0)
Block(-3,2,-4,STONE:0)
Block(-3,2,-3,STONE:0)
Block(-3,2,-2,STONE:0)
Block(-3,2,-1,STONE:0)
Block(-3,2,0,STONE:0)
Block(-3,2,1,STONE:0)
Block(-3,2,2,STONE:0)
Block(-3,2,3,STONE:0)
Block(-3,2,4,STONE:0)
Block(-3,2,5,STONE:0)
Block(-3,3,-5,STONE:0)
Block(-3,3,-4,STONE:0)
Block(-3,3,-3,STONE:0)
Block(-3,3,-2,STONE:0)
Block(-3,3,-1,STONE:0)
Block(-3,3,0,STONE:0)
Block(-3,3,1,STONE:0)
Block(-3,3,2,STONE:0)
Block(-3,3,3,STONE:0)
Block(-3,3,4,STONE:0)
Block(-3,3,5,STONE:0)
Block(-2,-10,-4,STONE:0)
Block(-2,-10,-3,STONE:0)
Block(-2,-10,-2,STONE:0)
Block(-2,-10,-1,STONE:0)
Block(-2,-10,0,STONE:0)
Block(-2,-10,1,STONE:0)
Block(-2,-10,2,STONE:0)
Block(-2,-10,3,STONE:0)
Block(-2,-10,4,STONE:0)
Block(-2,-9,-4,STONE:0)
Block(-2,-9,-3,STONE:0)
Block(-2,-9,-2,STONE:0)
Block(-2,-9,-1,STONE:0)
Block(-2,-9,0,STONE:0)
Block(-2,-9,1,STONE:0)
Block(-2,-9,2,STONE:0)
Block(-2,-9,3,STONE:0)
Block(-2,-9,4,STONE:0)
Block(-2,-9,5,STONE:0)
Block(-2,-9,6,STONE:0)
Block(-2,-8,-5,STONE:0)
Block(-2,-8,-4,STONE:0)
Block(-2,-8,-3,STONE:0)
Block(-2,-8,-2,STONE:0)
Block(-2,-8,-1,STONE:0)
Block(-2,-8,0,STONE:0)
Block(-2,-8,1,STONE:0)
Block(-2,-8,2,STONE:0)
Block(-2,-8,3,STONE:0)
Block(-2,-8,4,STONE:0)
Block(-2,-8,5,STONE:0)
Block(-2,-8,6,STONE:0)
Block(-2,-7,-5,STONE:0)
Block(-2,-7,-4,STONE:0)
Block(-2,-7,-3,STONE:0)
Block(-2,-7,-2,STONE:0)
Block(-2,-7,-1,STONE:0)
Block(-2,-7,0,STONE:0)
Block(-2,-7,1,STONE:0)
Block(-2,-7,2,STONE:0)
Block(-2,-7,3,STONE:0)
Block(-2,-7,4,STONE:0)
Block(-2,-7,5,STONE:0)
Block(-2,-7,6,STONE:0)
Block(-2,-7,7,STONE:0)
Block(-2,-6,-5,STONE:0)
Block(-2,-6,-4,STONE:0)
Block(-2,-6,-3,STONE:0)
Block(-2,-6,-2,STONE:0)
Block(-2,-6,-1,STONE:0)
Block(-2,-6,0,STONE:0)
Block(-2,-6,1,STONE:0)
Block(-2,-6,2,STONE:0)
Block(-2,-6,3,STONE:0)
Block(-2,-6,4,STONE:0)
Block(-2,-6,5,STONE:0)
Block(-2,-6,6,STONE:0)
Block(-2,-6,7,STONE:0)
Block(-2,-5,-6,STONE:0)
Block(-2,-5,-5,STONE:0)
Block(-2,-5,-4,STONE:0)
Block(-2,-5,-3,STONE:0)
Block(-2,-5,-2,STONE:0)
Block(-2,-5,-1,STONE:0)
Block(-2,-5,0,STONE:0)
Block(-2,-5,1,STONE:0)
Block(-2,-5,2,STONE:0)
Block(-2,-5,3,STONE:0)
Block(-2,-5,4,STONE:0)
Block(-2,-5,5,STONE:0)
Block(-2,-5,6,STONE:0)
Block(-2,-5,7,STONE:0)
Block(-2,-4,-6,STONE:0)
Block(-2,-4,-5,STONE:0)
Block(-2,-4,-4,STONE:0)
Block(-2,-4,-3,STONE:0)
Block(-2,-4,-2,STONE:0)
Block(-2,-4,-1,STONE:0)
Block(-2,-4,0,STONE:0)
Block(-2,-4,1,STONE:0)
Block(-2,-4,2,STONE:0)
Block(-2,-4,3,STONE:0)
Block(-2,-4,4,STONE:0)
Block(-2,-4,5,STONE:0)
Block(-2,-4,6,STONE:0)
Block(-2,-4,7,STONE:0)
Block(-2,-3,-6,STONE:0)
Block(-2,-3,-5,STONE:0)
Block(-2,-3,-4,STONE:0)
Block(-2,-3,-3,STONE:0)
Block(-2,-3,-2,STONE:0)
Block(-2,-3,-1,STONE:0)
Block(-2,-3,0,STONE:0)
Block(-2,-3,1,STONE:0)
Block(-2,-3,2,STONE:0)
Block(-2,-3,3,STONE:0)
Block(-2,-3,4,STONE:0)
Block(-2,-3,5,STONE:0)
Block(-2,-3,6,STONE:0)
Block(-2,-3,7,STONE:0)
Block(-2,-2,-6,STONE:0)
Block(-2,-2,-5,STONE:0)
Block(-2,-2,-4,STONE:0)
Block(-2,-2,-3,STONE:0)
Block(-2,-2,-2,STONE:0)
Block(-2,-2,-1,STONE:0)
Block(-2,-2,0,STONE:0)
Block(-2,-2,1,STONE:0)
Block(-2,-2,2,STONE:0)
Block(-2,-2,3,STONE:0)
Block(-2,-2,4,STONE:0)
Block(-2,-2,5,STONE:0)
Block(-2,-2,6,STONE:0)
Block(-2,-2,7,STONE:0)
Block(-2,-1,-7,STONE:0)
Block(-2,-1,-6,STONE:0)
Block(-2,-1,-5,STONE:0)
Block(-2,-1,-4,STONE:0)
Block(-2,-1,-3,STONE:0)
Block(-2,-1,-2,STONE:0)
Block(-2,-1,-1,STONE:0)
Block(-2,-1,0,STONE:0)
Block(-2,-1,1,STONE:0)
Block(-2,-1,2,STONE:0)
Block(-2,-1,3,STONE:0)
Block(-2,-1,4,STONE:0)
Block(-2,-1,5,STONE:0)
Block(-2,-1,6,STONE:0)
Block(-2,0,-7,STONE:0)
Block(-2,0,-6,STONE:0)
Block(-2,0,-5,STONE:0)
Block(-2,0,-4,STONE:0)
Block(-2,0,-3,STONE:0)
Block(-2,0,-2,STONE:0)
Block(-2,0,-1,STONE:0)
Block(-2,0,0,STONE:0)
Block(-2,0,1,STONE:0)
Block(-2,0,2,STONE:0)
Block(-2,0,3,STONE:0)
Block(-2,0,4,STONE:0)
Block(-2,0,5,STONE:0)
Block(-2,0,6,STONE:0)
Block(-2,1,-7,STONE:0)
Block(-2,1,-6,STONE:0)
Block(-2,1,-5,STONE:0)
Block(-2,1,-4,STONE:0)
Block(-2,1,-3,STONE:0)
Block(-2,1,-2,STONE:0)
Block(-2,1,-1,STONE:0)
Block(-2,1,0,STONE:0)
Block(-2,1,1,STONE:0)
Block(-2,1,2,STONE:0)
Block(-2,1,3,STONE:0)
Block(-2,1,4,STONE:0)
Block(-2,1,5,STONE:0)
Block(-2,1,6,STONE:0)
Block(-2,2,-7,STONE:0)
Block(-2,2,-6,STONE:0)
Block(-2,2,-5,STONE:0)
Block(-2,2,-4,STONE:0)
Block(-2,2,-3,STONE:0)
Block(-2,2,-2,STONE:0)
Block(-2,2,-1,STONE:0)
Block(-2,2,0,STONE:0)
Block(-2,2,1,STONE:0)
Block(-2,2,2,STONE:0)
Block(-2,2,3,STONE:0)
Block(-2,2,4,STONE:0)
Block(-2,2,5,STONE:0)
Block(-2,3,-5,STONE:0)
Block(-2,3,-4,STONE:0)
Block(-2,3,-3,STONE:0)
Block(-2,3,-2,STONE:0)
Block(-2,3,-1,STONE:0)
Block(-2,3,0,STONE:0)
Block(-2,3,1,STONE:0)
Block(-2,3,2,STONE:0)
Block(-2,3,3,STONE:0)
Block(-2,3,4,STONE:0)
Block(-1,-10,-4,STONE:0)
Block(-1,-10,-3,STONE:0)
Block(-1,-10,-2,STONE:0)
Block(-1,-10,-1,STONE:0)
Block(-1,-10,0,STONE:0)
Block(-1,-10,1,STONE:0)
Block(-1,-10,2,STONE:0)
Block(-1,-10,3,STONE:0)
Block(-1,-10,4,STONE:0)
Block(-1,-10,5,STONE:0)
Block(-1,-9,-5,STONE:0)
Block(-1,-9,-4,STONE:0)
Block(-1,-9,-3,STONE:0)
Block(-1,-9,-2,STONE:0)
Block(-1,-9,-1,STONE:0)
Block(-1,-9,0,STONE:0)
Block(-1,-9,1,STONE:0)
Block(-1,-9,2,STONE:0)
Block(-1,-9,3,STONE:0)
Block(-1,-9,4,STONE:0)
Block(-1,-9,5,STONE:0)
Block(-1,-9,6,STONE:0)
Block(-1,-8,-5,STONE:0)
Block(-1,-8,-4,STONE:0)
Block(-1,-8,-3,STONE:0)
Block(-1,-8,-2,STONE:0)
Block(-1,-8,-1,STONE:0)
Block(-1,-8,0,STONE:0)
Block(-1,-8,1,STONE:0)
Block(-1,-8,2,STONE:0)
Block(-1,-8,3,STONE:0)
Block(-1,-8,4,STONE:0)
Block(-1,-8,5,STONE:0)
Block(-1,-8,6,STONE:0)
Block(-1,-8,7,STONE:0)
Block(-1,-7,-5,STONE:0)
Block(-1,-7,-4,STONE:0)
Block(-1,-7,-3,STONE:0)
Block(-1,-7,-2,STONE:0)
Block(-1,-7,-1,STONE:0)
Block(-1,-7,0,STONE:0)
Block(-1,-7,1,STONE:0)
Block(-1,-7,2,STONE:0)
Block(-1,-7,3,STONE:0)
Block(-1,-7,4,STONE:0)
Block(-1,-7,5,STONE:0)
Block(-1,-7,6,STONE:0)
Block(-1,-7,7,STONE:0)
Block(-1,-6,-6,STONE:0)
Block(-1,-6,-5,STONE:0)
Block(-1,-6,-4,STONE:0)
Block(-1,-6,-3,STONE:0)
Block(-1,-6,-2,STONE:0)
Block(-1,-6,-1,STONE:0)
Block(-1,-6,0,STONE:0)
Block(-1,-6,1,STONE:0)
Block(-1,-6,2,STONE:0)
Block(-1,-6,3,STONE:0)
Block(-1,-6,4,STONE:0)
Block(-1,-6,5,STONE:0)
Block(-1,-6,6,STONE:0)
Block(-1,-6,7,STONE:0)
Block(-1,-5,-6,STONE:0)
Block(-1,-5,-5,STONE:0)
Block(-1,-5,-4,STONE:0)
Block(-1,-5,-3,STONE:0)
Block(-1,-5,-2,STONE:0)
Block(-1,-5,-1,STONE:0)
Block(-1,-5,0,STONE:0)
Block(-1,-5,1,STONE:0)
Block(-1,-5,2,STONE:0)
Block(-1,-5,3,STONE:0)
Block(-1,-5,4,STONE:0)
Block(-1,-5,5,STONE:0)
Block(-1,-5,6,STONE:0)
Block(-1,-5,7,STONE:0)
Block(-1,-4,-6,STONE:0)
Block(-1,-4,-5,STONE:0)
Block(-1,-4,-4,STONE:0)
Block(-1,-4,-3,STONE:0)
Block(-1,-4,-2,STONE:0)
Block(-1,-4,-1,STONE:0)
Block(-1,-4,0,STONE:0)
Block(-1,-4,1,STONE:0)
Block(-1,-4,2,STONE:0)
Block(-1,-4,3,STONE:0)
Block(-1,-4,4,STONE:0)
Block(-1,-4,5,STONE:0)
Block(-1,-4,6,STONE:0)
Block(-1,-4,7,STONE:0)
Block(-1,-3,-6,STONE:0)
Block(-1,-3,-5,STONE:0)
Block(-1,-3,-4,STONE:0)
Block(-1,-3,-3,STONE:0)
Block(-1,-3,-2,STONE:0)
Block(-1,-3,-1,STONE:0)
Block(-1,-3,0,STONE:0)
Block(-1,-3,1,STONE:0)
Block(-1,-3,2,STONE:0)
Block(-1,-3,3,STONE:0)
Block(-1,-3,4,STONE:0)
Block(-1,-3,5,STONE:0)
Block(-1,-3,6,STONE:0)
Block(-1,-3,7,STONE:0)
Block(-1,-2,-7,STONE:0)
Block(-1,-2,-6,STONE:0)
Block(-1,-2,-5,STONE:0)
Block(-1,-2,-4,STONE:0)
Block(-1,-2,-3,STONE:0)
Block(-1,-2,-2,STONE:0)
Block(-1,-2,-1,STONE:0)
Block(-1,-2,0,STONE:0)
Block(-1,-2,1,STONE:0)
Block(-1,-2,2,STONE:0)
Block(-1,-2,3,STONE:0)
Block(-1,-2,4,STONE:0)
Block(-1,-2,5,STONE:0)
Block(-1,-2,6,STONE:0)
Block(-1,-2,7,STONE:0)
Block(-1,-1,-7,STONE:0)
Block(-1,-1,-6,STONE:0)
Block(-1,-1,-5,STONE:0)
Block(-1,-1,-4,STONE:0)
Block(-1,-1,-3,STONE:0)
Block(-1,-1,-2,STONE:0)
Block(-1,-1,-1,STONE:0)
Block(-1,-1,0,STONE:0)
Block(-1,-1,1,STONE:0)
Block(-1,-1,2,STONE:0)
Block(-1,-1,3,STONE:0)
Block(-1,-1,4,STONE:0)
Block(-1,-1,5,STONE:0)
Block(-1,-1,6,STONE:0)
Block(-1,0,-7,STONE:0)
Block(-1,0,-6,STONE:0)
Block(-1,0,-5,STONE:0)
Block(-1,0,-4,STONE:0)
Block(-1,0,-3,STONE:0)
Block(-1,0,-2,STONE:0)
Block(-1,0,-1,STONE:0)
Block(-1,0,0,STONE:0)
Block(-1,0,1,STONE:0)
Block(-1,0,2,STONE:0)
Block(-1,0,3,STONE:0)
Block(-1,0,4,STONE:0)
Block(-1,0,5,STONE:0)
Block(-1,0,6,STONE:0)
Block(-1,1,-7,STONE:0)
Block(-1,1,-6,STONE:0)
Block(-1,1,-5,STONE:0)
Block(-1,1,-4,STONE:0)
Block(-1,1,-3,STONE:0)
Block(-1,1,-2,STONE:0)
Block(-1,1,-1,STONE:0)
Block(-1,1,0,STONE:0)
Block(-1,1,1,STONE:0)
Block(-1,1,2,STONE:0)
Block(-1,1,3,STONE:0)
Block(-1,1,4,STONE:0)
Block(-1,1,5,STONE:0)
Block(-1,1,6,STONE:0)
Block(-1,2,-7,STONE:0)
Block(-1,2,-6,STONE:0)
Block(-1,2,-5,STONE:0)
Block(-1,2,-4,STONE:0)
Block(-1,2,-3,STONE:0)
Block(-1,2,-2,STONE:0)
Block(-1,2,-1,STONE:0)
Block(-1,2,0,STONE:0)
Block(-1,2,1,STONE:0)
Block(-1,2,2,STONE:0)
Block(-1,2,3,STONE:0)
Block(-1,2,4,STONE:0)
Block(-1,2,5,STONE:0)
Block(-1,3,-5,STONE:0)
Block(-1,3,-4,STONE:0)
Block(-1,3,-3,STONE:0)
Block(-1,3,-2,STONE:0)
Block(-1,3,-1,STONE:0)
Block(-1,3,0,STONE:0)
Block(-1,3,1,STONE:0)
Block(-1,3,2,STONE:0)
Block(0,-10,-4,STONE:0)
Block(0,-10,-3,STONE:0)
Block(0,-10,-2,STONE:0)
Block(0,-10,-1,STONE:0)
Block(0,-10,0,STONE:0)
Block(0,-10,1,STONE:0)
Block(0,-10,2,STONE:0)
Block(0,-10,3,STONE:0)
Block(0,-10,4,STONE:0)
Block(0,-10,5,STONE:0)
Block(0,-9,-5,STONE:0)
Block(0,-9,-4,STONE:0)
Block(0,-9,-3,STONE:0)
Block(0,-9,-2,STONE:0)
Block(0,-9,-1,STONE:0)
Block(0,-9,0,STONE:0)
Block(0,-9,1,STONE:0)
Block(0,-9,2,STONE:0)
Block(0,-9,3,STONE:0)
Block(0,-9,4,STONE:0)
Block(0,-9,5,STONE:0)
Block(0,-9,6,STONE:0)
Block(0,-8,-5,STONE:0)
Block(0,-8,-4,STONE:0)
Block(0,-8,-3,STONE:0)
Block(0,-8,-2,STONE:0)
Block(0,-8,-1,STONE:0)
Block(0,-8,0,STONE:0)
Block(0,-8,1,STONE:0)
Block(0,-8,2,STONE:0)
Block(0,-8,3,STONE:0)
Block(0,-8,4,STONE:0)
Block(0,-8,5,STONE:0)
Block(0,-8,6,STONE:0)
Block(0,-8,7,STONE:0)
Block(0,-7,-6,STONE:0)
Block(0,-7,-5,STONE:0)
Block(0,-7,-4,STONE:0)
Block(0,-7,-3,STONE:0)
Block(0,-7,-2,STONE:0)
Block(0,-7,-1,STONE:0)
Block(0,-7,0,STONE:0)
Block(0,-7,1,STONE:0)
Block(0,-7,2,STONE:0)
Block(0,-7,3,STONE:0)
Block(0,-7,4,STONE:0)
Block(0,-7,5,STONE:0)
Block(0,-7,6,STONE:0)
Block(0,-7,7,STONE:0)
Block(0,-6,-6,STONE:0)
Block(0,-6,-5,STONE:0)
Block(0,-6,-4,STONE:0)
Block(0,-6,-3,STONE:0)
Block(0,-6,-2,STONE:0)
Block(0,-6,-1,STONE:0)
Block(0,-6,0,STONE:0)
Block(0,-6,1,STONE:0)
Block(0,-6,2,STONE:0)
Block(0,-6,3,STONE:0)
Block(0,-6,4,STONE:0)
Block(0,-6,5,STONE:0)
Block(0,-6,6,STONE:0)
Block(0,-6,7,STONE:0)
Block(0,-5,-6,STONE:0)
Block(0,-5,-5,STONE:0)
Block(0,-5,-4,STONE:0)
Block(0,-5,-3,STONE:0)
Block(0,-5,-2,STONE:0)
Block(0,-5,-1,STONE:0)
Block(0,-5,0,STONE:0)
Block(0,-5,1,STONE:0)
Block(0,-5,2,STONE:0)
Block(0,-5,3,STONE:0)
Block(0,-5,4,STONE:0)
Block(0,-5,5,STONE:0)
Block(0,-5,6,STONE:0)
Block(0,-5,7,STONE:0)
Block(0,-5,8,STONE:0)
Block(0,-4,-6,STONE:0)
Block(0,-4,-5,STONE:0)
Block(0,-4,-4,STONE:0)
Block(0,-4,-3,STONE:0)
Block(0,-4,-2,STONE:0)
Block(0,-4,-1,STONE:0)
Block(0,-4,0,STONE:0)
Block(0,-4,1,STONE:0)
Block(0,-4,2,STONE:0)
Block(0,-4,3,STONE:0)
Block(0,-4,4,STONE:0)
Block(0,-4,5,STONE:0)
Block(0,-4,6,STONE:0)
Block(0,-4,7,STONE:0)
Block(0,-4,8,STONE:0)
Block(0,-3,-7,STONE:0)
Block(0,-3,-6,STONE:0)
Block(0,-3,-5,STONE:0)
Block(0,-3,-4,STONE:0)
Block(0,-3,-3,STONE:0)
Block(0,-3,-2,STONE:0)
Block(0,-3,-1,STONE:0)
Block(0,-3,0,STONE:0)
Block(0,-3,1,STONE:0)
Block(0,-3,2,STONE:0)
Block(0,-3,3,STONE:0)
Block(0,-3,4,STONE:0)
Block(0,-3,5,STONE:0)
Block(0,-3,6,STONE:0)
Block(0,-3,7,STONE:0)
Block(0,-2,-7,STONE:0)
Block(0,-2,-6,STONE:0)
Block(0,-2,-5,STONE:0)
Block(0,-2,-4,STONE:0)
Block(0,-2,-3,STONE:0)
Block(0,-2,-2,STONE:0)
Block(0,-2,-1,STONE:0)
Block(0,-2,0,STONE:0)
Block(0,-2,1,STONE:0)
Block(0,-2,2,STONE:0)
Block(0,-2,3,STONE:0)
Block(0,-2,4,STONE:0)
Block(0,-2,5,STONE:0)
Block(0,-2,6,STONE:0)
Block(0,-2,7,STONE:0)
Block(0,-1,-7,STONE:0)
Block(0,-1,-6,STONE:0)
Block(0,-1,-5,STONE:0)
Block(0,-1,-4,STONE:0)
Block(0,-1,-3,STONE:0)
Block(0,-1,-2,STONE:0)
Block(0,-1,-1,STONE:0)
Block(0,-1,0,STONE:0)
Block(0,-1,1,STONE:0)
Block(0,-1,2,STONE:0)
Block(0,-1,3,STONE:0)
Block(0,-1,4,STONE:0)
Block(0,-1,5,STONE:0)
Block(0,-1,6,STONE:0)
Block(0,0,-7,STONE:0)
Block(0,0,-6,STONE:0)
Block(0,0,-5,STONE:0)
Block(0,0,-4,STONE:0)
Block(0,0,-3,STONE:0)
Block(0,0,-2,STONE:0)
Block(0,0,-1,STONE:0)
Block(0,0,0,STONE:0)
Block(0,0,1,STONE:0)
Block(0,0,2,STONE:0)
Block(0,0,3,STONE:0)
Block(0,0,4,STONE:0)
Block(0,0,5,STONE:0)
Block(0,0,6,STONE:0)
Block(0,1,-7,STONE:0)
Block(0,1,-6,STONE:0)
Block(0,1,-5,STONE:0)
Block(0,1,-4,STONE:0)
Block(0,1,-3,STONE:0)
Block(0,1,-2,STONE:0)
Block(0,1,-1,STONE:0)
Block(0,1,0,STONE:0)
Block(0,1,1,STONE:0)
Block(0,1,2,STONE:0)
Block(0,1,3,STONE:0)
Block(0,1,4,STONE:0)
Block(0,1,5,STONE:0)
Block(0,1,6,STONE:0)
Block(0,2,-8,STONE:0)
Block(0,2,-7,STONE:0)
Block(0,2,-6,STONE:0)
Block(0,2,-5,STONE:0)
Block(0,2,-4,STONE:0)
Block(0,2,-3,STONE:0)
Block(0,2,-2,STONE:0)
Block(0,2,-1,STONE:0)
Block(0,2,0,STONE:0)
Block(0,2,1,STONE:0)
Block(0,2,2,STONE:0)
Block(0,2,3,STONE:0)
Block(0,2,4,STONE:0)
Block(0,2,5,STONE:0)
Block(0,3,-5,STONE:0)
Block(0,3,-4,STONE:0)
Block(0,3,-3,STONE:0)
Block(0,3,-2,STONE:0)
Block(0,3,-1,STONE:0)
Block(0,3,1,STONE:0)
Block(1,-10,-4,STONE:0)
Block(1,-10,-3,STONE:0)
Block(1,-10,-2,STONE:0)
Block(1,-10,-1,STONE:0)
Block(1,-10,0,STONE:0)
Block(1,-10,1,STONE:0)
Block(1,-10,2,STONE:0)
Block(1,-10,3,STONE:0)
Block(1,-10,4,STONE:0)
Block(1,-10,5,STONE:0)
Block(1,-9,-5,STONE:0)
Block(1,-9,-4,STONE:0)
Block(1,-9,-3,STONE:0)
Block(1,-9,-2,STONE:0)
Block(1,-9,-1,STONE:0)
Block(1,-9,0,STONE:0)
Block(1,-9,1,STONE:0)
Block(1,-9,2,STONE:0)
Block(1,-9,3,STONE:0)
Block(1,-9,4,STONE:0)
Block(1,-9,5,STONE:0)
Block(1,-9,6,STONE:0)
Block(1,-8,-5,STONE:0)
Block(1,-8,-4,STONE:0)
Block(1,-8,-3,STONE:0)
Block(1,-8,-2,STONE:0)
Block(1,-8,-1,STONE:0)
Block(1,-8,0,STONE:0)
Block(1,-8,1,STONE:0)
Block(1,-8,2,STONE:0)
Block(1,-8,3,STONE:0)
Block(1,-8,4,STONE:0)
Block(1,-8,5,STONE:0)
Block(1,-8,6,STONE:0)
Block(1,-8,7,STONE:0)
Block(1,-7,-6,STONE:0)
Block(1,-7,-5,STONE:0)
Block(1,-7,-4,STONE:0)
Block(1,-7,-3,STONE:0)
Block(1,-7,-2,STONE:0)
Block(1,-7,-1,STONE:0)
Block(1,-7,0,STONE:0)
Block(1,-7,1,STONE:0)
Block(1,-7,2,STONE:0)
Block(1,-7,3,STONE:0)
Block(1,-7,4,STONE:0)
Block(1,-7,5,STONE:0)
Block(1,-7,6,STONE:0)
Block(1,-7,7,STONE:0)
Block(1,-6,-6,STONE:0)
Block(1,-6,-5,STONE:0)
Block(1,-6,-4,STONE:0)
Block(1,-6,-3,STONE:0)
Block(1,-6,-2,STONE:0)
Block(1,-6,-1,STONE:0)
Block(1,-6,0,STONE:0)
Block(1,-6,1,STONE:0)
Block(1,-6,2,STONE:0)
Block(1,-6,3,STONE:0)
Block(1,-6,4,STONE:0)
Block(1,-6,5,STONE:0)
Block(1,-6,6,STONE:0)
Block(1,-6,7,STONE:0)
Block(1,-5,-6,STONE:0)
Block(1,-5,-5,STONE:0)
Block(1,-5,-4,STONE:0)
Block(1,-5,-3,STONE:0)
Block(1,-5,-2,STONE:0)
Block(1,-5,-1,STONE:0)
Block(1,-5,0,STONE:0)
Block(1,-5,1,STONE:0)
Block(1,-5,2,STONE:0)
Block(1,-5,3,STONE:0)
Block(1,-5,4,STONE:0)
Block(1,-5,5,STONE:0)
Block(1,-5,6,STONE:0)
Block(1,-5,7,STONE:0)
Block(1,-5,8,STONE:0)
Block(1,-4,-7,STONE:0)
Block(1,-4,-6,STONE:0)
Block(1,-4,-5,STONE:0)
Block(1,-4,-4,STONE:0)
Block(1,-4,-3,STONE:0)
Block(1,-4,-2,STONE:0)
Block(1,-4,-1,STONE:0)
Block(1,-4,0,STONE:0)
Block(1,-4,1,STONE:0)
Block(1,-4,2,STONE:0)
Block(1,-4,3,STONE:0)
Block(1,-4,4,STONE:0)
Block(1,-4,5,STONE:0)
Block(1,-4,6,STONE:0)
Block(1,-4,7,STONE:0)
Block(1,-4,8,STONE:0)
Block(1,-3,-7,STONE:0)
Block(1,-3,-6,STONE:0)
Block(1,-3,-5,STONE:0)
Block(1,-3,-4,STONE:0)
Block(1,-3,-3,STONE:0)
Block(1,-3,-2,STONE:0)
Block(1,-3,-1,STONE:0)
Block(1,-3,0,STONE:0)
Block(1,-3,1,STONE:0)
Block(1,-3,2,STONE:0)
Block(1,-3,3,STONE:0)
Block(1,-3,4,STONE:0)
Block(1,-3,5,STONE:0)
Block(1,-3,6,STONE:0)
Block(1,-3,7,STONE:0)
Block(1,-2,-7,STONE:0)
Block(1,-2,-6,STONE:0)
Block(1,-2,-5,STONE:0)
Block(1,-2,-4,STONE:0)
Block(1,-2,-3,STONE:0)
Block(1,-2,-2,STONE:0)
Block(1,-2,-1,STONE:0)
Block(1,-2,0,STONE:0)
Block(1,-2,1,STONE:0)
Block(1,-2,2,STONE:0)
Block(1,-2,3,STONE:0)
Block(1,-2,4,STONE:0)
Block(1,-2,5,STONE:0)
Block(1,-2,6,STONE:0)
Block(1,-2,7,STONE:0)
Block(1,-1,-7,STONE:0)
Block(1,-1,-6,STONE:0)
Block(1,-1,-5,STONE:0)
Block(1,-1,-4,STONE:0)
Block(1,-1,-3,STONE:0)
Block(1,-1,-2,STONE:0)
Block(1,-1,-1,STONE:0)
Block(1,-1,0,STONE:0)
Block(1,-1,1,STONE:0)
Block(1,-1,2,STONE:0)
Block(1,-1,3,STONE:0)
Block(1,-1,4,STONE:0)
Block(1,-1,5,STONE:0)
Block(1,-1,6,STONE:0)
Block(1,-1,7,STONE:0)
Block(1,0,-8,STONE:0)
Block(1,0,-7,STONE:0)
Block(1,0,-6,STONE:0)
Block(1,0,-5,STONE:0)
Block(1,0,-4,STONE:0)
Block(1,0,-3,STONE:0)
Block(1,0,-2,STONE:0)
Block(1,0,-1,STONE:0)
Block(1,0,0,STONE:0)
Block(1,0,1,STONE:0)
Block(1,0,2,STONE:0)
Block(1,0,3,STONE:0)
Block(1,0,4,STONE:0)
Block(1,0,5,STONE:0)
Block(1,0,6,STONE:0)
Block(1,1,-8,STONE:0)
Block(1,1,-7,STONE:0)
Block(1,1,-6,STONE:0)
Block(1,1,-5,STONE:0)
Block(1,1,-4,STONE:0)
Block(1,1,-3,STONE:0)
Block(1,1,-2,STONE:0)
Block(1,1,-1,STONE:0)
Block(1,1,0,STONE:0)
Block(1,1,1,STONE:0)
Block(1,1,2,STONE:0)
Block(1,1,3,STONE:0)
Block(1,1,4,STONE:0)
Block(1,1,5,STONE:0)
Block(1,1,6,STONE:0)
Block(1,2,-8,STONE:0)
Block(1,2,-7,STONE:0)
Block(1,2,-6,STONE:0)
Block(1,2,-5,STONE:0)
Block(1,2,-4,STONE:0)
Block(1,2,-3,STONE:0)
Block(1,2,-2,STONE:0)
Block(1,2,-1,STONE:0)
Block(1,2,0,STONE:0)
Block(1,2,1,STONE:0)
Block(1,2,2,STONE:0)
Block(1,2,3,STONE:0)
Block(1,2,4,STONE:0)
Block(1,2,5,STONE:0)
Block(1,2,6,STONE:0)
Block(2,-10,-4,STONE:0)
Block(2,-10,-3,STONE:0)
Block(2,-10,-2,STONE:0)
Block(2,-10,-1,STONE:0)
Block(2,-10,0,STONE:0)
Block(2,-10,1,STONE:0)
Block(2,-10,2,STONE:0)
Block(2,-10,3,STONE:0)
Block(2,-10,4,STONE:0)
Block(2,-10,5,STONE:0)
Block(2,-9,-5,STONE:0)
Block(2,-9,-4,STONE:0)
Block(2,-9,-3,STONE:0)
Block(2,-9,-2,STONE:0)
Block(2,-9,-1,STONE:0)
Block(2,-9,0,STONE:0)
Block(2,-9,1,STONE:0)
Block(2,-9,2,STONE:0)
Block(2,-9,3,STONE:0)
Block(2,-9,4,STONE:0)
Block(2,-9,5,STONE:0)
Block(2,-9,6,STONE:0)
Block(2,-8,-6,STONE:0)
Block(2,-8,-5,STONE:0)
Block(2,-8,-4,STONE:0)
Block(2,-8,-3,STONE:0)
Block(2,-8,-2,STONE:0)
Block(2,-8,-1,STONE:0)
Block(2,-8,0,STONE:0)
Block(2,-8,1,STONE:0)
Block(2,-8,2,STONE:0)
Block(2,-8,3,STONE:0)
Block(2,-8,4,STONE:0)
Block(2,-8,5,STONE:0)
Block(2,-8,6,STONE:0)
Block(2,-7,-6,STONE:0)
Block(2,-7,-5,STONE:0)
Block(2,-7,-4,STONE:0)
Block(2,-7,-3,STONE:0)
Block(2,-7,-2,STONE:0)
Block(2,-7,-1,STONE:0)
Block(2,-7,0,STONE:0)
Block(2,-7,1,STONE:0)
Block(2,-7,2,STONE:0)
Block(2,-7,3,STONE:0)
Block(2,-7,4,STONE:0)
Block(2,-7,5,STONE:0)
Block(2,-7,6,STONE:0)
Block(2,-7,7,STONE:0)
Block(2,-6,-6,STONE:0)
Block(2,-6,-5,STONE:0)
Block(2,-6,-4,STONE:0)
Block(2,-6,-3,STONE:0)
Block(2,-6,-2,STONE:0)
Block(2,-6,-1,STONE:0)
Block(2,-6,0,STONE:0)
Block(2,-6,1,STONE:0)
Block(2,-6,2,STONE:0)
Block(2,-6,3,STONE:0)
Block(2,-6,4,STONE:0)
Block(2,-6,5,STONE:0)
Block(2,-6,6,STONE:0)
Block(2,-6,7,STONE:0)
Block(2,-5,-6,STONE:0)
Block(2,-5,-5,STONE:0)
Block(2,-5,-4,STONE:0)
Block(2,-5,-3,STONE:0)
Block(2,-5,-2,STONE:0)
Block(2,-5,-1,STONE:0)
Block(2,-5,0,STONE:0)
Block(2,-5,1,STONE:0)
Block(2,-5,2,STONE:0)
Block(2,-5,3,STONE:0)
Block(2,-5,4,STONE:0)
Block(2,-5,5,STONE:0)
Block(2,-5,6,STONE:0)
Block(2,-5,7,STONE:0)
Block(2,-4,-7,STONE:0)
Block(2,-4,-6,STONE:0)
Block(2,-4,-5,STONE:0)
Block(2,-4,-4,STONE:0)
Block(2,-4,-3,STONE:0)
Block(2,-4,-2,STONE:0)
Block(2,-4,-1,STONE:0)
Block(2,-4,0,STONE:0)
Block(2,-4,1,STONE:0)
Block(2,-4,2,STONE:0)
Block(2,-4,3,STONE:0)
Block(2,-4,4,STONE:0)
Block(2,-4,5,STONE:0)
Block(2,-4,6,STONE:0)
Block(2,-4,7,STONE:0)
Block(2,-4,8,STONE:0)
Block(2,-3,-7,STONE:0)
Block(2,-3,-6,STONE:0)
Block(2,-3,-5,STONE:0)
Block(2,-3,-4,STONE:0)
Block(2,-3,-3,STONE:0)
Block(2,-3,-2,STONE:0)
Block(2,-3,-1,STONE:0)
Block(2,-3,0,STONE:0)
Block(2,-3,1,STONE:0)
Block(2,-3,2,STONE:0)
Block(2,-3,3,STONE:0)
Block(2,-3,4,STONE:0)
Block(2,-3,5,STONE:0)
Block(2,-3,6,STONE:0)
Block(2,-3,7,STONE:0)
Block(2,-2,-7,STONE:0)
Block(2,-2,-6,STONE:0)
Block(2,-2,-5,STONE:0)
Block(2,-2,-4,STONE:0)
Block(2,-2,-3,STONE:0)
Block(2,-2,-2,STONE:0)
Block(2,-2,-1,STONE:0)
Block(2,-2,0,STONE:0)
Block(2,-2,1,STONE:0)
Block(2,-2,2,STONE:0)
Block(2,-2,3,STONE:0)
Block(2,-2,4,STONE:0)
Block(2,-2,5,STONE:0)
Block(2,-2,6,STONE:0)
Block(2,-2,7,STONE:0)
Block(2,-1,-8,STONE:0)
Block(2,-1,-7,STONE:0)
Block(2,-1,-6,STONE:0)
Block(2,-1,-5,STONE:0)
Block(2,-1,-4,STONE:0)
Block(2,-1,-3,STONE:0)
Block(2,-1,-2,STONE:0)
Block(2,-1,-1,STONE:0)
Block(2,-1,0,STONE:0)
Block(2,-1,1,STONE:0)
Block(2,-1,2,STONE:0)
Block(2,-1,3,STONE:0)
Block(2,-1,4,STONE:0)
Block(2,-1,5,STONE:0)
Block(2,-1,6,STONE:0)
Block(2,-1,7,STONE:0)
Block(2,0,-8,STONE:0)
Block(2,0,-7,STONE:0)
Block(2,0,-6,STONE:0)
Block(2,0,-5,STONE:0)
Block(2,0,-4,STONE:0)
Block(2,0,-3,STONE:0)
Block(2,0,-2,STONE:0)
Block(2,0,-1,STONE:0)
Block(2,0,0,STONE:0)
Block(2,0,1,STONE:0)
Block(2,0,2,STONE:0)
Block(2,0,3,STONE:0)
Block(2,0,4,STONE:0)
Block(2,0,5,STONE:0)
Block(2,0,6,STONE:0)
Block(2,1,-8,STONE:0)
Block(2,1,-7,STONE:0)
Block(2,1,-6,STONE:0)
Block(2,1,-5,STONE:0)
Block(2,1,-4,STONE:0)
Block(2,1,-3,STONE:0)
Block(2,1,-2,STONE:0)
Block(2,1,-1,STONE:0)
Block(2,1,0,STONE:0)
Block(2,1,1,STONE:0)
Block(2,1,2,STONE:0)
Block(2,1,3,STONE:0)
Block(2,1,4,STONE:0)
Block(2,1,5,STONE:0)
Block(2,1,6,STONE:0)
Block(2,2,-7,STONE:0)
Block(2,2,-6,STONE:0)
Block(2,2,-5,STONE:0)
Block(2,2,-4,STONE:0)
Block(2,2,-3,STONE:0)
Block(2,2,-2,STONE:0)
Block(2,2,-1,STONE:0)
Block(2,2,0,STONE:0)
Block(2,2,1,STONE:0)
Block(2,2,2,STONE:0)
Block(2,2,3,STONE:0)
Block(2,2,4,STONE:0)
Block(2,2,5,STONE:0)
Block(2,2,6,STONE:0)
Block(3,-10,-5,STONE:0)
Block(3,-10,-4,STONE:0)
Block(3,-10,-3,STONE:0)
Block(3,-10,-2,STONE:0)
Block(3,-10,-1,STONE:0)
Block(3,-10,0,STONE:0)
Block(3,-10,1,STONE:0)
Block(3,-10,2,STONE:0)
Block(3,-10,3,STONE:0)
Block(3,-10,4,STONE:0)
Block(3,-9,-5,STONE:0)
Block(3,-9,-4,STONE:0)
Block(3,-9,-3,STONE:0)
Block(3,-9,-2,STONE:0)
Block(3,-9,-1,STONE:0)
Block(3,-9,0,STONE:0)
Block(3,-9,1,STONE:0)
Block(3,-9,2,STONE:0)
Block(3,-9,3,STONE:0)
Block(3,-9,4,STONE:0)
Block(3,-9,5,STONE:0)
Block(3,-9,6,STONE:0)
Block(3,-8,-6,STONE:0)
Block(3,-8,-5,STONE:0)
Block(3,-8,-4,STONE:0)
Block(3,-8,-3,STONE:0)
Block(3,-8,-2,STONE:0)
Block(3,-8,-1,STONE:0)
Block(3,-8,0,STONE:0)
Block(3,-8,1,STONE:0)
Block(3,-8,2,STONE:0)
Block(3,-8,3,STONE:0)
Block(3,-8,4,STONE:0)
Block(3,-8,5,STONE:0)
Block(3,-8,6,STONE:0)
Block(3,-7,-6,STONE:0)
Block(3,-7,-5,STONE:0)
Block(3,-7,-4,STONE:0)
Block(3,-7,-3,STONE:0)
Block(3,-7,-2,STONE:0)
Block(3,-7,-1,STONE:0)
Block(3,-7,0,STONE:0)
Block(3,-7,1,STONE:0)
Block(3,-7,2,STONE:0)
Block(3,-7,3,STONE:0)
Block(3,-7,4,STONE:0)
Block(3,-7,5,STONE:0)
Block(3,-7,6,STONE:0)
Block(3,-7,7,STONE:0)
Block(3,-6,-6,STONE:0)
Block(3,-6,-5,STONE:0)
Block(3,-6,-4,STONE:0)
Block(3,-6,-3,STONE:0)
Block(3,-6,-2,STONE:0)
Block(3,-6,-1,STONE:0)
Block(3,-6,0,STONE:0)
Block(3,-6,1,STONE:0)
Block(3,-6,2,STONE:0)
Block(3,-6,3,STONE:0)
Block(3,-6,4,STONE:0)
Block(3,-6,5,STONE:0)
Block(3,-6,6,STONE:0)
Block(3,-6,7,STONE:0)
Block(3,-5,-7,STONE:0)
Block(3,-5,-6,STONE:0)
Block(3,-5,-5,STONE:0)
Block(3,-5,-4,STONE:0)
Block(3,-5,-3,STONE:0)
Block(3,-5,-2,STONE:0)
Block(3,-5,-1,STONE:0)
Block(3,-5,0,STONE:0)
Block(3,-5,1,STONE:0)
Block(3,-5,2,STONE:0)
Block(3,-5,3,STONE:0)
Block(3,-5,4,STONE:0)
Block(3,-5,5,STONE:0)
Block(3,-5,6,STONE:0)
Block(3,-5,7,STONE:0)
Block(3,-4,-7,STONE:0)
Block(3,-4,-6,STONE:0)
Block(3,-4,-5,STONE:0)
Block(3,-4,-4,STONE:0)
Block(3,-4,-3,STONE:0)
Block(3,-4,-2,STONE:0)
Block(3,-4,-1,STONE:0)
Block(3,-4,0,STONE:0)
Block(3,-4,1,STONE:0)
Block(3,-4,2,STONE:0)
Block(3,-4,3,STONE:0)
Block(3,-4,4,STONE:0)
Block(3,-4,5,STONE:0)
Block(3,-4,6,STONE:0)
Block(3,-4,7,STONE:0)
Block(3,-3,-7,STONE:0)
Block(3,-3,-6,STONE:0)
Block(3,-3,-5,STONE:0)
Block(3,-3,-4,STONE:0)
Block(3,-3,-3,STONE:0)
Block(3,-3,-2,STONE:0)
Block(3,-3,-1,STONE:0)
Block(3,-3,0,STONE:0)
Block(3,-3,1,STONE:0)
Block(3,-3,2,STONE:0)
Block(3,-3,3,STONE:0)
Block(3,-3,4,STONE:0)
Block(3,-3,5,STONE:0)
Block(3,-3,6,STONE:0)
Block(3,-3,7,STONE:0)
Block(3,-2,-8,STONE:0)
Block(3,-2,-7,STONE:0)
Block(3,-2,-6,STONE:0)
Block(3,-2,-5,STONE:0)
Block(3,-2,-4,STONE:0)
Block(3,-2,-3,STONE:0)
Block(3,-2,-2,STONE:0)
Block(3,-2,-1,STONE:0)
Block(3,-2,0,STONE:0)
Block(3,-2,1,STONE:0)
Block(3,-2,2,STONE:0)
Block(3,-2,3,STONE:0)
Block(3,-2,4,STONE:0)
Block(3,-2,5,STONE:0)
Block(3,-2,6,STONE:0)
Block(3,-2,7,STONE:0)
Block(3,-1,-8,STONE:0)
Block(3,-1,-7,STONE:0)
Block(3,-1,-6,STONE:0)
Block(3,-1,-5,STONE:0)
Block(3,-1,-4,STONE:0)
Block(3,-1,-3,STONE:0)
Block(3,-1,-2,STONE:0)
Block(3,-1,-1,STONE:0)
Block(3,-1,0,STONE:0)
Block(3,-1,1,STONE:0)
Block(3,-1,2,STONE:0)
Block(3,-1,3,STONE:0)
Block(3,-1,4,STONE:0)
Block(3,-1,5,STONE:0)
Block(3,-1,6,STONE:0)
Block(3,-1,7,STONE:0)
Block(3,0,-7,STONE:0)
Block(3,0,-6,STONE:0)
Block(3,0,-5,STONE:0)
Block(3,0,-4,STONE:0)
Block(3,0,-3,STONE:0)
Block(3,0,-2,STONE:0)
Block(3,0,-1,STONE:0)
Block(3,0,0,STONE:0)
Block(3,0,1,STONE:0)
Block(3,0,2,STONE:0)
Block(3,0,3,STONE:0)
Block(3,0,4,STONE:0)
Block(3,0,5,STONE:0)
Block(3,0,6,STONE:0)
Block(3,0,7,STONE:0)
Block(3,1,-7,STONE:0)
Block(3,1,-6,STONE:0)
Block(3,1,-5,STONE:0)
Block(3,1,-4,STONE:0)
Block(3,1,-3,STONE:0)
Block(3,1,-2,STONE:0)
Block(3,1,-1,STONE:0)
Block(3,1,0,STONE:0)
Block(3,1,1,STONE:0)
Block(3,1,2,STONE:0)
Block(3,1,3,STONE:0)
Block(3,1,4,STONE:0)
Block(3,1,5,STONE:0)
Block(3,1,6,STONE:0)
Block(3,2,-7,STONE:0)
Block(3,2,-6,STONE:0)
Block(3,2,-5,STONE:0)
Block(3,2,-4,STONE:0)
Block(3,2,-3,STONE:0)
Block(3,2,-2,STONE:0)
Block(3,2,-1,STONE:0)
Block(3,2,0,STONE:0)
Block(3,2,1,STONE:0)
Block(3,2,2,STONE:0)
Block(3,2,3,STONE:0)
Block(3,2,4,STONE:0)
Block(3,2,5,STONE:0)
Block(3,2,6,STONE:0)
Block(4,-10,-4,STONE:0)
Block(4,-10,-3,STONE:0)
Block(4,-10,-1,STONE:0)
Block(4,-10,0,STONE:0)
Block(4,-10,1,STONE:0)
Block(4,-10,2,STONE:0)
Block(4,-10,3,STONE:0)
Block(4,-9,-5,STONE:0)
Block(4,-9,-4,STONE:0)
Block(4,-9,-3,STONE:0)
Block(4,-9,-2,STONE:0)
Block(4,-9,-1,STONE:0)
Block(4,-9,0,STONE:0)
Block(4,-9,1,STONE:0)
Block(4,-9,2,STONE:0)
Block(4,-9,3,STONE:0)
Block(4,-9,4,STONE:0)
Block(4,-9,5,STONE:0)
Block(4,-8,-5,STONE:0)
Block(4,-8,-4,STONE:0)
Block(4,-8,-3,STONE:0)
Block(4,-8,-2,STONE:0)
Block(4,-8,-1,STONE:0)
Block(4,-8,0,STONE:0)
Block(4,-8,1,STONE:0)
Block(4,-8,2,STONE:0)
Block(4,-8,3,STONE:0)
Block(4,-8,4,STONE:0)
Block(4,-8,5,STONE:0)
Block(4,-8,6,STONE:0)
Block(4,-7,-6,STONE:0)
Block(4,-7,-5,STONE:0)
Block(4,-7,-4,STONE:0)
Block(4,-7,-3,STONE:0)
Block(4,-7,-2,STONE:0)
Block(4,-7,-1,STONE:0)
Block(4,-7,0,STONE:0)
Block(4,-7,1,STONE:0)
Block(4,-7,2,STONE:0)
Block(4,-7,3,STONE:0)
Block(4,-7,4,STONE:0)
Block(4,-7,5,STONE:0)
Block(4,-7,6,STONE:0)
Block(4,-7,7,STONE:0)
Block(4,-6,-6,STONE:0)
Block(4,-6,-5,STONE:0)
Block(4,-6,-4,STONE:0)
Block(4,-6,-3,STONE:0)
Block(4,-6,-2,STONE:0)
Block(4,-6,-1,STONE:0)
Block(4,-6,0,STONE:0)
Block(4,-6,1,STONE:0)
Block(4,-6,2,STONE:0)
Block(4,-6,3,STONE:0)
Block(4,-6,4,STONE:0)
Block(4,-6,5,STONE:0)
Block(4,-6,6,STONE:0)
Block(4,-6,7,STONE:0)
Block(4,-5,-7,STONE:0)
Block(4,-5,-6,STONE:0)
Block(4,-5,-5,STONE:0)
Block(4,-5,-4,STONE:0)
Block(4,-5,-3,STONE:0)
Block(4,-5,-2,STONE:0)
Block(4,-5,-1,STONE:0)
Block(4,-5,0,STONE:0)
Block(4,-5,1,STONE:0)
Block(4,-5,2,STONE:0)
Block(4,-5,3,STONE:0)
Block(4,-5,4,STONE:0)
Block(4,-5,5,STONE:0)
Block(4,-5,6,STONE:0)
Block(4,-5,7,STONE:0)
Block(4,-4,-7,STONE:0)
Block(4,-4,-6,STONE:0)
Block(4,-4,-5,STONE:0)
Block(4,-4,-4,STONE:0)
Block(4,-4,-3,STONE:0)
Block(4,-4,-2,STONE:0)
Block(4,-4,-1,STONE:0)
Block(4,-4,0,STONE:0)
Block(4,-4,1,STONE:0)
Block(4,-4,2,STONE:0)
Block(4,-4,3,STONE:0)
Block(4,-4,4,STONE:0)
Block(4,-4,5,STONE:0)
Block(4,-4,6,STONE:0)
Block(4,-4,7,STONE:0)
Block(4,-3,-7,STONE:0)
Block(4,-3,-6,STONE:0)
Block(4,-3,-5,STONE:0)
Block(4,-3,-4,STONE:0)
Block(4,-3,-3,STONE:0)
Block(4,-3,-2,STONE:0)
Block(4,-3,-1,STONE:0)
Block(4,-3,0,STONE:0)
Block(4,-3,1,STONE:0)
Block(4,-3,2,STONE:0)
Block(4,-3,3,STONE:0)
Block(4,-3,4,STONE:0)
Block(4,-3,5,STONE:0)
Block(4,-3,6,STONE:0)
Block(4,-3,7,STONE:0)
Block(4,-2,-7,STONE:0)
Block(4,-2,-6,STONE:0)
Block(4,-2,-5,STONE:0)
Block(4,-2,-4,STONE:0)
Block(4,-2,-3,STONE:0)
Block(4,-2,-2,STONE:0)
Block(4,-2,-1,STONE:0)
Block(4,-2,0,STONE:0)
Block(4,-2,1,STONE:0)
Block(4,-2,2,STONE:0)
Block(4,-2,3,STONE:0)
Block(4,-2,4,STONE:0)
Block(4,-2,5,STONE:0)
Block(4,-2,6,STONE:0)
Block(4,-2,7,STONE:0)
Block(4,-1,-6,STONE:0)
Block(4,-1,-5,STONE:0)
Block(4,-1,-4,STONE:0)
Block(4,-1,-3,STONE:0)
Block(4,-1,-2,STONE:0)
Block(4,-1,-1,STONE:0)
Block(4,-1,0,STONE:0)
Block(4,-1,1,STONE:0)
Block(4,-1,2,STONE:0)
Block(4,-1,3,STONE:0)
Block(4,-1,4,STONE:0)
Block(4,-1,5,STONE:0)
Block(4,-1,6,STONE:0)
Block(4,-1,7,STONE:0)
Block(4,0,-6,STONE:0)
Block(4,0,-5,STONE:0)
Block(4,0,-4,STONE:0)
Block(4,0,-3,STONE:0)
Block(4,0,-2,STONE:0)
Block(4,0,-1,STONE:0)
Block(4,0,0,STONE:0)
Block(4,0,1,STONE:0)
Block(4,0,2,STONE:0)
Block(4,0,3,STONE:0)
Block(4,0,4,STONE:0)
Block(4,0,5,STONE:0)
Block(4,0,6,STONE:0)
Block(4,0,7,STONE:0)
Block(4,1,-6,STONE:0)
Block(4,1,-5,STONE:0)
Block(4,1,-4,STONE:0)
Block(4,1,-3,STONE:0)
Block(4,1,-2,STONE:0)
Block(4,1,-1,STONE:0)
Block(4,1,0,STONE:0)
Block(4,1,1,STONE:0)
Block(4,1,2,STONE:0)
Block(4,1,3,STONE:0)
Block(4,1,4,STONE:0)
Block(4,1,5,STONE:0)
Block(4,1,6,STONE:0)
Block(4,2,-5,STONE:0)
Block(4,2,-4,STONE:0)
Block(4,2,-3,STONE:0)
Block(4,2,-2,STONE:0)
Block(4,2,-1,STONE:0)
Block(4,2,0,STONE:0)
Block(4,2,1,STONE:0)
Block(4,2,2,STONE:0)
Block(4,2,3,STONE:0)
Block(4,2,4,STONE:0)
Block(4,2,5,STONE:0)
Block(4,2,6,STONE:0)
Block(5,-9,-4,STONE:0)
Block(5,-9,-3,STONE:0)
Block(5,-9,-2,STONE:0)
Block(5,-9,-1,STONE:0)
Block(5,-9,0,STONE:0)
Block(5,-9,1,STONE:0)
Block(5,-9,2,STONE:0)
Block(5,-9,3,STONE:0)
Block(5,-9,4,STONE:0)
Block(5,-9,5,STONE:0)
Block(5,-8,-4,STONE:0)
Block(5,-8,-3,STONE:0)
Block(5,-8,-2,STONE:0)
Block(5,-8,-1,STONE:0)
Block(5,-8,0,STONE:0)
Block(5,-8,1,STONE:0)
Block(5,-8,2,STONE:0)
Block(5,-8,3,STONE:0)
Block(5,-8,4,STONE:0)
Block(5,-8,5,STONE:0)
Block(5,-8,6,STONE:0)
Block(5,-7,-5,STONE:0)
Block(5,-7,-4,STONE:0)
Block(5,-7,-3,STONE:0)
Block(5,-7,-2,STONE:0)
Block(5,-7,-1,STONE:0)
Block(5,-7,0,STONE:0)
Block(5,-7,1,STONE:0)
Block(5,-7,2,STONE:0)
Block(5,-7,3,STONE:0)
Block(5,-7,4,STONE:0)
Block(5,-7,5,STONE:0)
Block(5,-7,6,STONE:0)
Block(5,-6,-5,STONE:0)
Block(5,-6,-4,STONE:0)
Block(5,-6,-3,STONE:0)
Block(5,-6,-2,STONE:0)
Block(5,-6,-1,STONE:0)
Block(5,-6,0,STONE:0)
Block(5,-6,1,STONE:0)
Block(5,-6,2,STONE:0)
Block(5,-6,3,STONE:0)
Block(5,-6,4,STONE:0)
Block(5,-6,5,STONE:0)
Block(5,-6,6,STONE:0)
Block(5,-6,7,STONE:0)
Block(5,-5,-6,STONE:0)
Block(5,-5,-5,STONE:0)
Block(5,-5,-4,STONE:0)
Block(5,-5,-3,STONE:0)
Block(5,-5,-2,STONE:0)
Block(5,-5,-1,STONE:0)
Block(5,-5,0,STONE:0)
Block(5,-5,1,STONE:0)
Block(5,-5,2,STONE:0)
Block(5,-5,3,STONE:0)
Block(5,-5,4,STONE:0)
Block(5,-5,5,STONE:0)
Block(5,-5,6,STONE:0)
Block(5,-5,7,STONE:0)
Block(5,-4,-6,STONE:0)
Block(5,-4,-5,STONE:0)
Block(5,-4,-4,STONE:0)
Block(5,-4,-3,STONE:0)
Block(5,-4,-2,STONE:0)
Block(5,-4,-1,STONE:0)
Block(5,-4,0,STONE:0)
Block(5,-4,1,STONE:0)
Block(5,-4,2,STONE:0)
Block(5,-4,3,STONE:0)
Block(5,-4,4,STONE:0)
Block(5,-4,5,STONE:0)
Block(5,-4,6,STONE:0)
Block(5,-4,7,STONE:0)
Block(5,-3,-6,STONE:0)
Block(5,-3,-5,STONE:0)
Block(5,-3,-4,STONE:0)
Block(5,-3,-3,STONE:0)
Block(5,-3,-2,STONE:0)
Block(5,-3,-1,STONE:0)
Block(5,-3,0,STONE:0)
Block(5,-3,1,STONE:0)
Block(5,-3,2,STONE:0)
Block(5,-3,3,STONE:0)
Block(5,-3,4,STONE:0)
Block(5,-3,5,STONE:0)
Block(5,-3,6,STONE:0)
Block(5,-3,7,STONE:0)
Block(5,-2,-6,STONE:0)
Block(5,-2,-5,STONE:0)
Block(5,-2,-4,STONE:0)
Block(5,-2,-3,STONE:0)
Block(5,-2,-2,STONE:0)
Block(5,-2,-1,STONE:0)
Block(5,-2,0,STONE:0)
Block(5,-2,1,STONE:0)
Block(5,-2,2,STONE:0)
Block(5,-2,3,STONE:0)
Block(5,-2,4,STONE:0)
Block(5,-2,5,STONE:0)
Block(5,-2,6,STONE:0)
Block(5,-2,7,STONE:0)
Block(5,-1,-5,STONE:0)
Block(5,-1,-4,STONE:0)
Block(5,-1,-3,STONE:0)
Block(5,-1,-2,STONE:0)
Block(5,-1,-1,STONE:0)
Block(5,-1,0,STONE:0)
Block(5,-1,1,STONE:0)
Block(5,-1,2,STONE:0)
Block(5,-1,3,STONE:0)
Block(5,-1,4,STONE:0)
Block(5,-1,5,STONE:0)
Block(5,-1,6,STONE:0)
Block(5,-1,7,STONE:0)
Block(5,0,-5,STONE:0)
Block(5,0,-4,STONE:0)
Block(5,0,-3,STONE:0)
Block(5,0,-2,STONE:0)
Block(5,0,-1,STONE:0)
Block(5,0,0,STONE:0)
Block(5,0,1,STONE:0)
Block(5,0,2,STONE:0)
Block(5,0,3,STONE:0)
Block(5,0,4,STONE:0)
Block(5,0,5,STONE:0)
Block(5,0,6,STONE:0)
Block(5,0,7,STONE:0)
Block(5,1,-4,STONE:0)
Block(5,1,-3,STONE:0)
Block(5,1,-2,STONE:0)
Block(5,1,-1,STONE:0)
Block(5,1,0,STONE:0)
Block(5,1,1,STONE:0)
Block(5,1,2,STONE:0)
Block(5,1,3,STONE:0)
Block(5,1,4,STONE:0)
Block(5,1,5,STONE:0)
Block(5,1,6,STONE:0)
Block(5,2,-1,STONE:0)
Block(5,2,0,STONE:0)
Block(5,2,1,STONE:0)
Block(5,2,2,STONE:0)
Block(5,2,3,STONE:0)
Block(5,2,4,STONE:0)
Block(5,2,5,STONE:0)
Block(6,-9,-3,STONE:0)
Block(6,-9,-2,STONE:0)
Block(6,-9,-1,STONE:0)
Block(6,-9,0,STONE:0)
Block(6,-9,1,STONE:0)
Block(6,-9,2,STONE:0)
Block(6,-9,3,STONE:0)
Block(6,-9,4,STONE:0)
Block(6,-8,-3,STONE:0)
Block(6,-8,-2,STONE:0)
Block(6,-8,-1,STONE:0)
Block(6,-8,0,STONE:0)
Block(6,-8,1,STONE:0)
Block(6,-8,2,STONE:0)
Block(6,-8,3,STONE:0)
Block(6,-8,4,STONE:0)
Block(6,-8,5,STONE:0)
Block(6,-7,-4,STONE:0)
Block(6,-7,-3,STONE:0)
Block(6,-7,-2,STONE:0)
Block(6,-7,-1,STONE:0)
Block(6,-7,0,STONE:0)
Block(6,-7,1,STONE:0)
Block(6,-7,2,STONE:0)
Block(6,-7,3,STONE:0)
Block(6,-7,4,STONE:0)
Block(6,-7,5,STONE:0)
Block(6,-6,-4,STONE:0)
Block(6,-6,-3,STONE:0)
Block(6,-6,-2,STONE:0)
Block(6,-6,-1,STONE:0)
Block(6,-6,0,STONE:0)
Block(6,-6,1,STONE:0)
Block(6,-6,2,STONE:0)
Block(6,-6,3,STONE:0)
Block(6,-6,4,STONE:0)
Block(6,-6,5,STONE:0)
Block(6,-6,6,STONE:0)
Block(6,-5,-5,STONE:0)
Block(6,-5,-4,STONE:0)
Block(6,-5,-3,STONE:0)
Block(6,-5,-2,STONE:0)
Block(6,-5,-1,STONE:0)
Block(6,-5,0,STONE:0)
Block(6,-5,1,STONE:0)
Block(6,-5,2,STONE:0)
Block(6,-5,3,STONE:0)
Block(6,-5,4,STONE:0)
Block(6,-5,5,STONE:0)
Block(6,-5,6,STONE:0)
Block(6,-4,-6,STONE:0)
Block(6,-4,-5,STONE:0)
Block(6,-4,-4,STONE:0)
Block(6,-4,-3,STONE:0)
Block(6,-4,-2,STONE:0)
Block(6,-4,-1,STONE:0)
Block(6,-4,0,STONE:0)
Block(6,-4,1,STONE:0)
Block(6,-4,2,STONE:0)
Block(6,-4,3,STONE:0)
Block(6,-4,4,STONE:0)
Block(6,-4,5,STONE:0)
Block(6,-4,6,STONE:0)
Block(6,-3,-5,STONE:0)
Block(6,-3,-4,STONE:0)
Block(6,-3,-3,STONE:0)
Block(6,-3,-2,STONE:0)
Block(6,-3,-1,STONE:0)
Block(6,-3,0,STONE:0)
Block(6,-3,1,STONE:0)
Block(6,-3,2,STONE:0)
Block(6,-3,3,STONE:0)
Block(6,-3,4,STONE:0)
Block(6,-3,5,STONE:0)
Block(6,-3,6,STONE:0)
Block(6,-2,-5,STONE:0)
Block(6,-2,-4,STONE:0)
Block(6,-2,-3,STONE:0)
Block(6,-2,-2,STONE:0)
Block(6,-2,-1,STONE:0)
Block(6,-2,0,STONE:0)
Block(6,-2,1,STONE:0)
Block(6,-2,2,STONE:0)
Block(6,-2,3,STONE:0)
Block(6,-2,4,STONE:0)
Block(6,-2,5,STONE:0)
Block(6,-2,6,STONE:0)
Block(6,-1,-3,STONE:0)
Block(6,-1,-2,STONE:0)
Block(6,-1,-1,STONE:0)
Block(6,-1,0,STONE:0)
Block(6,-1,1,STONE:0)
Block(6,-1,2,STONE:0)
Block(6,-1,3,STONE:0)
Block(6,-1,4,STONE:0)
Block(6,-1,5,STONE:0)
Block(6,-1,6,STONE:0)
Block(6,-1,7,STONE:0)
Block(6,0,1,STONE:0)
Block(6,0,2,STONE:0)
Block(6,0,3,STONE:0)
Block(7,-9,-2,STONE:0)
Block(7,-9,-1,STONE:0)
Block(7,-9,0,STONE:0)
Block(7,-9,1,STONE:0)
Block(7,-9,2,STONE:0)
Block(7,-9,3,STONE:0)
Block(7,-8,-3,STONE:0)
Block(7,-8,-2,STONE:0)
Block(7,-8,-1,STONE:0)
Block(7,-8,0,STONE:0)
Block(7,-8,1,STONE:0)
Block(7,-8,2,STONE:0)
Block(7,-8,3,STONE:0)
Block(7,-7,-3,STONE:0)
Block(7,-7,-2,STONE:0)
Block(7,-7,-1,STONE:0)
Block(7,-7,0,STONE:0)
Block(7,-7,1,STONE:0)
Block(7,-7,2,STONE:0)
Block(7,-7,3,STONE:0)
Block(7,-7,4,STONE:0)
Block(7,-6,-4,STONE:0)
Block(7,-6,-3,STONE:0)
Block(7,-6,-2,STONE:0)
Block(7,-6,-1,STONE:0)
Block(7,-6,0,STONE:0)
Block(7,-6,1,STONE:0)
Block(7,-6,2,STONE:0)
Block(7,-6,3,STONE:0)
Block(7,-6,4,STONE:0)
Block(7,-6,5,STONE:0)
Block(7,-5,-4,STONE:0)
Block(7,-5,-3,STONE:0)
Block(7,-5,-2,STONE:0)
Block(7,-5,-1,STONE:0)
Block(7,-5,0,STONE:0)
Block(7,-5,1,STONE:0)
Block(7,-5,2,STONE:0)
Block(7,-5,3,STONE:0)
Block(7,-5,4,STONE:0)
Block(7,-5,5,STONE:0)
Block(7,-4,-4,STONE:0)
Block(7,-4,-3,STONE:0)
Block(7,-4,-2,STONE:0)
Block(7,-4,-1,STONE:0)
Block(7,-4,0,STONE:0)
Block(7,-4,1,STONE:0)
Block(7,-4,2,STONE:0)
Block(7,-4,3,STONE:0)
Block(7,-4,4,STONE:0)
Block(7,-4,5,STONE:0)
Block(7,-4,6,STONE:0)
Block(7,-3,-1,STONE:0)
Block(7,-3,0,STONE:0)
Block(7,-3,1,STONE:0)
Block(7,-3,2,STONE:0)
Block(7,-3,3,STONE:0)
Block(7,-3,4,STONE:0)
Block(7,-3,5,STONE:0)
Block(7,-3,6,STONE:0)
Block(8,-9,1,STONE:0)
Block(8,-9,2,STONE:0)
Block(8,-8,-1,STONE:0)
Block(8,-8,0,STONE:0)
Block(8,-8,1,STONE:0)
Block(8,-8,2,STONE:0)
Block(8,-7,-2,STONE:0)
Block(8,-7,-1,STONE:0)
Block(8,-7,0,STONE:0)
Block(8,-7,1,STONE:0)
Block(8,-7,2,STONE:0)
Block(8,-7,3,STONE:0)
Block(8,-6,-2,STONE:0)
Block(8,-6,-1,STONE:0)
Block(8,-6,0,STONE:0)
Block(8,-6,1,STONE:0)
Block(8,-6,2,STONE:0)
Block(8,-6,3,STONE:0)
Block(8,-6,4,STONE:0)
Block(8,-5,1,STONE:0)
Block(8,-5,2,STONE:0)

#######################################################################
# +-----------------------------------------------------------------+ #
# |                            BO3 checks                           | #
# +-----------------------------------------------------------------+ #
#######################################################################


#######################################################################
# +-----------------------------------------------------------------+ #
# |                             Branches                            | #
# +-----------------------------------------------------------------+ #
#######################################################################


#######################################################################
# +-----------------------------------------------------------------+ #
# |                             Entities                            | #
# +-----------------------------------------------------------------+ #
#######################################################################


#######################################################################
# +-----------------------------------------------------------------+ #
# |                            Particles                            | #
# +-----------------------------------------------------------------+ #
#######################################################################


#######################################################################
# +-----------------------------------------------------------------+ #
# |                             Spawners                            | #
# +-----------------------------------------------------------------+ #
#######################################################################


#######################################################################
# +-----------------------------------------------------------------+ #
# |                             ModData                             | #
# +-----------------------------------------------------------------+ #
#######################################################################

