
#######################################################################
# +-----------------------------------------------------------------+ #
# |                            BO3 object                           | #
# +-----------------------------------------------------------------+ #
#######################################################################

Author: MC_Pitman

Description: No description given

Version: 3

SettingsMode: WriteWithoutComments


#######################################################################
# +-----------------------------------------------------------------+ #
# |                          Main settings                          | #
# +-----------------------------------------------------------------+ #
#######################################################################

Tree: true

Frequency: 1

Rarity: 100.0

RotateRandomly: true

SpawnHeight: highestSolidBlock

SpawnHeightOffset: 0

SpawnHeightVariance: 0

##############################
# Height Limits for the BO3. #
##############################

MinHeight: 63

MaxHeight: 100

######################
# Extrusion settings #
######################

ExtrudeMode: None

ExtrudeThroughBlocks: AIR

MaxBranchDepth: 10

ExcludedBiomes: All


#######################################################################
# +-----------------------------------------------------------------+ #
# |                      Source block settings                      | #
# +-----------------------------------------------------------------+ #
#######################################################################

SourceBlocks: STONE:1,STONE:3,STONE:5,DIRT:1,DIRT:0,SAND:0,GRASS:0,DIRT:2,HARD_CLAY,STAINED_CLAY:0,CLAY,SANDSTONE:0,SAND:1,AIR,STONE:0,GRAVEL,LONG_GRASS:0,LONG_GRASS:1,LONG_GRASS:2,DEAD_BUSH,YELLOW_FLOWER:0,RED_ROSE:0,BROWN_MUSHROOM,RED_MUSHROOM

MaxPercentageOutsideSourceBlock: 0

OutsideSourceBlock: placeAnyway

DoReplaceBlocks: true

IsOTGPlus: false


#######################################################################
# +-----------------------------------------------------------------+ #
# |                              Blocks                             | #
# +-----------------------------------------------------------------+ #
#######################################################################

Block(-9,8,-6,LEAVES:0)
Block(-9,8,-4,LEAVES:0)
Block(-9,8,-3,LEAVES:0)
Block(-9,8,-2,LEAVES:0)
Block(-9,9,-7,LEAVES:0)
Block(-9,9,-5,LEAVES:0)
Block(-9,10,0,LEAVES:0)
Block(-8,7,-6,LEAVES:0)
Block(-8,7,-4,LEAVES:0)
Block(-8,8,-7,LEAVES:0)
Block(-8,8,-5,LEAVES:0)
Block(-8,8,-4,LEAVES:0)
Block(-8,8,-3,LOG:0)
Block(-8,8,-2,LEAVES:0)
Block(-8,8,-1,LEAVES:0)
Block(-8,9,-8,LEAVES:0)
Block(-8,9,-7,LEAVES:0)
Block(-8,9,-6,LEAVES:0)
Block(-8,9,-4,LEAVES:0)
Block(-8,9,-3,LEAVES:0)
Block(-8,9,-2,LEAVES:0)
Block(-8,9,0,LEAVES:0)
Block(-8,10,-7,LEAVES:0)
Block(-8,10,-2,LEAVES:0)
Block(-8,10,-1,LEAVES:0)
Block(-8,10,0,LEAVES:0)
Block(-8,10,1,LEAVES:0)
Block(-8,11,0,LEAVES:0)
Block(-7,8,-9,LEAVES:0)
Block(-7,8,-8,LEAVES:0)
Block(-7,8,-6,LEAVES:0)
Block(-7,8,-5,LEAVES:0)
Block(-7,8,-4,LOG:0)
Block(-7,8,-3,LEAVES:0)
Block(-7,8,-2,LEAVES:0)
Block(-7,9,-8,LEAVES:0)
Block(-7,9,-7,LOG:0)
Block(-7,9,-6,LEAVES:0)
Block(-7,9,-5,LEAVES:0)
Block(-7,9,-4,LEAVES:0)
Block(-7,9,-3,LEAVES:0)
Block(-7,10,-8,LEAVES:0)
Block(-7,10,-7,LEAVES:0)
Block(-7,10,-5,LEAVES:0)
Block(-7,10,-4,LEAVES:0)
Block(-7,10,-3,LEAVES:0)
Block(-7,10,-2,LEAVES:0)
Block(-7,10,-1,LEAVES:0)
Block(-7,10,0,LOG:0)
Block(-7,10,1,LEAVES:0)
Block(-7,10,2,LEAVES:0)
Block(-7,11,-7,LEAVES:0)
Block(-7,11,-2,LEAVES:0)
Block(-7,11,0,LEAVES:0)
Block(-7,11,1,LEAVES:0)
Block(-7,12,0,LEAVES:0)
Block(-6,4,-1,LEAVES:0)
Block(-6,7,-9,LEAVES:0)
Block(-6,8,-10,LEAVES:0)
Block(-6,8,-9,LEAVES:0)
Block(-6,8,-8,LEAVES:0)
Block(-6,8,-7,LOG:0)
Block(-6,8,-6,LEAVES:0)
Block(-6,8,-5,LOG:0)
Block(-6,8,-3,LEAVES:0)
Block(-6,8,-2,LEAVES:0)
Block(-6,9,-9,LEAVES:0)
Block(-6,9,-8,LEAVES:0)
Block(-6,9,-7,LEAVES:0)
Block(-6,9,-5,LEAVES:0)
Block(-6,9,-3,LEAVES:0)
Block(-6,10,-8,LEAVES:0)
Block(-6,10,-5,LEAVES:0)
Block(-6,10,-4,LEAVES:0)
Block(-6,10,-3,LEAVES:0)
Block(-6,10,-2,LEAVES:0)
Block(-6,10,-1,LOG:0)
Block(-6,10,0,LEAVES:0)
Block(-6,10,1,LEAVES:0)
Block(-6,10,2,LEAVES:0)
Block(-6,11,-4,LEAVES:0)
Block(-6,11,-2,LEAVES:0)
Block(-6,11,-1,LEAVES:0)
Block(-6,11,0,LEAVES:0)
Block(-6,12,-2,LEAVES:0)
Block(-5,4,-2,LEAVES:0)
Block(-5,4,-1,LEAVES:0)
Block(-5,4,0,LEAVES:0)
Block(-5,5,-1,LEAVES:0)
Block(-5,7,-6,LOG:0)
Block(-5,8,-9,LEAVES:0)
Block(-5,8,-8,LEAVES:0)
Block(-5,8,-7,LEAVES:0)
Block(-5,8,-6,LEAVES:0)
Block(-5,9,-9,LEAVES:0)
Block(-5,9,-8,LEAVES:0)
Block(-5,9,-7,LEAVES:0)
Block(-5,9,2,LEAVES:0)
Block(-5,10,-6,LEAVES:0)
Block(-5,10,-5,LEAVES:0)
Block(-5,10,-4,LOG:0)
Block(-5,10,-3,LEAVES:0)
Block(-5,10,-1,LOG:0)
Block(-5,10,0,LEAVES:0)
Block(-5,10,1,LEAVES:0)
Block(-5,10,2,LEAVES:0)
Block(-5,10,3,LEAVES:0)
Block(-5,11,-4,LEAVES:0)
Block(-5,11,-3,LEAVES:0)
Block(-5,11,-2,LEAVES:0)
Block(-5,11,-1,LEAVES:0)
Block(-5,11,0,LEAVES:0)
Block(-5,11,2,LEAVES:0)
Block(-5,12,-6,LEAVES:0)
Block(-5,12,-5,LEAVES:0)
Block(-5,12,-4,LEAVES:0)
Block(-5,12,-2,LEAVES:0)
Block(-5,12,-1,LEAVES:0)
Block(-5,13,-2,LEAVES:0)
Block(-4,3,-2,LEAVES:0)
Block(-4,3,0,LEAVES:0)
Block(-4,4,-3,LEAVES:0)
Block(-4,4,-2,LEAVES:0)
Block(-4,4,-1,LOG:0)
Block(-4,4,0,LEAVES:0)
Block(-4,4,1,LEAVES:0)
Block(-4,5,-2,LEAVES:0)
Block(-4,5,-1,LEAVES:0)
Block(-4,5,0,LEAVES:0)
Block(-4,7,-5,LOG:0)
Block(-4,8,-8,LEAVES:0)
Block(-4,8,-6,LOG:0)
Block(-4,9,-10,LEAVES:0)
Block(-4,9,-9,LEAVES:0)
Block(-4,9,-8,LOG:0)
Block(-4,9,-7,LOG:0)
Block(-4,9,-6,LEAVES:0)
Block(-4,9,-5,LEAVES:0)
Block(-4,9,-1,LOG:0)
Block(-4,9,0,LEAVES:0)
Block(-4,10,-9,LEAVES:0)
Block(-4,10,-8,LEAVES:0)
Block(-4,10,-7,LEAVES:0)
Block(-4,10,-6,LEAVES:0)
Block(-4,10,-3,LOG:0)
Block(-4,10,-1,LEAVES:0)
Block(-4,10,0,LEAVES:0)
Block(-4,10,1,LEAVES:0)
Block(-4,10,2,LOG:0)
Block(-4,10,3,LEAVES:0)
Block(-4,11,-6,LEAVES:0)
Block(-4,11,-4,LEAVES:0)
Block(-4,11,-3,LEAVES:0)
Block(-4,11,-2,LEAVES:0)
Block(-4,11,0,LEAVES:0)
Block(-4,11,1,LEAVES:0)
Block(-4,11,2,LEAVES:0)
Block(-4,11,4,LEAVES:0)
Block(-4,12,-7,LEAVES:0)
Block(-4,12,-6,LEAVES:0)
Block(-4,12,-5,LOG:0)
Block(-4,12,-4,LEAVES:0)
Block(-4,12,-3,LEAVES:0)
Block(-4,12,-2,LEAVES:0)
Block(-4,12,-1,LEAVES:0)
Block(-4,12,0,LEAVES:0)
Block(-4,13,-6,LEAVES:0)
Block(-4,13,-5,LEAVES:0)
Block(-4,13,-4,LEAVES:0)
Block(-3,4,-3,LEAVES:0)
Block(-3,4,-2,LOG:0)
Block(-3,4,0,LEAVES:0)
Block(-3,5,-3,LEAVES:0)
Block(-3,5,-2,LEAVES:0)
Block(-3,5,-1,LEAVES:0)
Block(-3,6,-4,LOG:0)
Block(-3,6,-2,LEAVES:0)
Block(-3,8,-7,LEAVES:0)
Block(-3,8,-6,LEAVES:0)
Block(-3,9,-9,LEAVES:0)
Block(-3,9,-8,LEAVES:0)
Block(-3,9,-7,LEAVES:0)
Block(-3,9,-6,LEAVES:0)
Block(-3,9,-2,LOG:0)
Block(-3,9,1,LEAVES:0)
Block(-3,9,3,LEAVES:0)
Block(-3,10,-7,LEAVES:0)
Block(-3,10,-1,LEAVES:0)
Block(-3,10,1,LEAVES:0)
Block(-3,10,2,LOG:0)
Block(-3,10,3,LEAVES:0)
Block(-3,10,4,LEAVES:0)
Block(-3,11,-7,LEAVES:0)
Block(-3,11,-5,LEAVES:0)
Block(-3,11,-3,LEAVES:0)
Block(-3,11,0,LEAVES:0)
Block(-3,11,1,LEAVES:0)
Block(-3,11,2,LEAVES:0)
Block(-3,11,3,LEAVES:0)
Block(-3,11,4,LEAVES:0)
Block(-3,12,-6,LEAVES:0)
Block(-3,12,-5,LEAVES:0)
Block(-3,12,-4,LOG:0)
Block(-3,12,-3,LEAVES:0)
Block(-3,12,-2,LEAVES:0)
Block(-3,12,-1,LEAVES:0)
Block(-3,12,1,LEAVES:0)
Block(-3,12,3,LEAVES:0)
Block(-3,13,-5,LEAVES:0)
Block(-3,13,-4,LEAVES:0)
Block(-3,13,-3,LEAVES:0)
Block(-3,13,-2,LEAVES:0)
Block(-3,13,0,LEAVES:0)
Block(-3,14,-4,LEAVES:0)
Block(-2,4,-3,LOG:0)
Block(-2,4,-1,LEAVES:0)
Block(-2,5,-3,LOG:0)
Block(-2,5,-2,LEAVES:0)
Block(-2,8,-8,LEAVES:0)
Block(-2,9,-7,LEAVES:0)
Block(-2,9,-1,LOG:0)
Block(-2,10,-7,LEAVES:0)
Block(-2,10,1,LOG:0)
Block(-2,10,2,LEAVES:0)
Block(-2,10,3,LEAVES:0)
Block(-2,10,5,LEAVES:0)
Block(-2,11,-6,LEAVES:0)
Block(-2,11,-1,LEAVES:0)
Block(-2,11,1,LEAVES:0)
Block(-2,11,2,LEAVES:0)
Block(-2,11,3,LEAVES:0)
Block(-2,11,4,LEAVES:0)
Block(-2,12,-5,LEAVES:0)
Block(-2,12,-4,LEAVES:0)
Block(-2,12,-3,LOG:0)
Block(-2,12,-2,LEAVES:0)
Block(-2,12,0,LEAVES:0)
Block(-2,12,2,LEAVES:0)
Block(-2,12,3,LEAVES:0)
Block(-2,13,-4,LEAVES:0)
Block(-2,13,-3,LEAVES:0)
Block(-2,13,-1,LEAVES:0)
Block(-2,13,2,LEAVES:0)
Block(-1,3,-2,LOG:0)
Block(-1,6,-1,LOG:0)
Block(-1,7,-1,LOG:0)
Block(-1,8,-1,LOG:0)
Block(-1,8,0,LOG:0)
Block(-1,8,2,LEAVES:0)
Block(-1,9,-2,LEAVES:0)
Block(-1,9,-1,LOG:0)
Block(-1,9,1,LOG:0)
Block(-1,9,2,LEAVES:0)
Block(-1,9,3,LEAVES:0)
Block(-1,10,-2,LEAVES:0)
Block(-1,10,-1,LOG:0)
Block(-1,10,2,LEAVES:0)
Block(-1,10,4,LEAVES:0)
Block(-1,11,-4,LEAVES:0)
Block(-1,11,-3,LEAVES:0)
Block(-1,11,-2,LOG:0)
Block(-1,11,-1,LEAVES:0)
Block(-1,11,0,LEAVES:0)
Block(-1,11,2,LOG:0)
Block(-1,11,3,LOG:0)
Block(-1,11,4,LEAVES:0)
Block(-1,11,5,LEAVES:0)
Block(-1,12,-5,LEAVES:0)
Block(-1,12,-4,LEAVES:0)
Block(-1,12,-3,LEAVES:0)
Block(-1,12,-2,LEAVES:0)
Block(-1,12,-1,LEAVES:0)
Block(-1,12,1,LEAVES:0)
Block(-1,12,2,LEAVES:0)
Block(-1,12,3,LEAVES:0)
Block(-1,12,4,LEAVES:0)
Block(-1,13,-4,LEAVES:0)
Block(-1,13,-3,LEAVES:0)
Block(-1,13,-2,LEAVES:0)
Block(-1,13,-1,LEAVES:0)
Block(-1,13,0,LEAVES:0)
Block(-1,14,-3,LEAVES:0)
Block(0,0,0,LOG:0)
Block(0,1,0,LOG:0)
Block(0,2,0,LOG:0)
Block(0,3,-1,LOG:0)
Block(0,3,0,LOG:0)
Block(0,4,-1,LOG:0)
Block(0,4,1,LEAVES:0)
Block(0,5,-1,LOG:0)
Block(0,6,-1,LOG:0)
Block(0,7,-2,LOG:0)
Block(0,9,0,LOG:0)
Block(0,9,1,LEAVES:0)
Block(0,9,2,LEAVES:0)
Block(0,9,3,LEAVES:0)
Block(0,10,-1,LEAVES:0)
Block(0,10,2,LEAVES:0)
Block(0,11,-2,LEAVES:0)
Block(0,11,-1,LEAVES:0)
Block(0,11,0,LEAVES:0)
Block(0,11,1,LEAVES:0)
Block(0,11,2,LEAVES:0)
Block(0,11,3,LEAVES:0)
Block(0,11,4,LEAVES:0)
Block(0,12,-4,LEAVES:0)
Block(0,12,-3,LEAVES:0)
Block(0,12,-2,LEAVES:0)
Block(0,12,2,LEAVES:0)
Block(0,13,-3,LEAVES:0)
Block(0,13,-1,LEAVES:0)
Block(0,13,1,LEAVES:0)
Block(1,3,1,LOG:0)
Block(1,3,3,LEAVES:0)
Block(1,4,0,LEAVES:0)
Block(1,4,1,LEAVES:0)
Block(1,4,2,LEAVES:0)
Block(1,5,1,LEAVES:0)
Block(1,8,-3,LEAVES:0)
Block(1,8,-2,LOG:0)
Block(1,9,0,LEAVES:0)
Block(1,9,2,LEAVES:0)
Block(1,10,-2,LEAVES:0)
Block(1,10,-1,LEAVES:0)
Block(1,10,0,LEAVES:0)
Block(1,10,1,LOG:0)
Block(1,10,2,LEAVES:0)
Block(1,11,-4,LEAVES:0)
Block(1,11,-3,LEAVES:0)
Block(1,11,-1,LEAVES:0)
Block(1,11,0,LEAVES:0)
Block(1,11,1,LEAVES:0)
Block(1,11,2,LEAVES:0)
Block(1,12,-3,LEAVES:0)
Block(1,12,0,LEAVES:0)
Block(1,12,1,LEAVES:0)
Block(1,12,3,LEAVES:0)
Block(2,4,1,LEAVES:0)
Block(2,4,2,LOG:0)
Block(2,4,3,LEAVES:0)
Block(2,5,2,LEAVES:0)
Block(2,8,-2,LEAVES:0)
Block(2,8,-1,LEAVES:0)
Block(2,9,-5,LEAVES:0)
Block(2,9,-4,LEAVES:0)
Block(2,9,-3,LOG:0)
Block(2,9,-2,LEAVES:0)
Block(2,9,0,LEAVES:0)
Block(2,10,-4,LEAVES:0)
Block(2,10,-3,LEAVES:0)
Block(2,10,-2,LEAVES:0)
Block(2,10,-1,LEAVES:0)
Block(2,10,0,LEAVES:0)
Block(2,10,1,LEAVES:0)
Block(2,10,4,LEAVES:0)
Block(2,11,0,LEAVES:0)
Block(2,11,1,LOG:0)
Block(2,11,2,LEAVES:0)
Block(2,11,3,LEAVES:0)
Block(2,12,0,LEAVES:0)
Block(2,12,1,LEAVES:0)
Block(2,12,2,LEAVES:0)
Block(2,13,1,LEAVES:0)
Block(2,13,2,LEAVES:0)
Block(3,3,2,LEAVES:0)
Block(3,4,1,LEAVES:0)
Block(3,4,2,LEAVES:0)
Block(3,4,3,LEAVES:0)
Block(3,5,2,LEAVES:0)
Block(3,8,-5,LEAVES:0)
Block(3,8,-2,LEAVES:0)
Block(3,9,-6,LEAVES:0)
Block(3,9,-5,LEAVES:0)
Block(3,9,-4,LOG:0)
Block(3,9,-3,LEAVES:0)
Block(3,9,-2,LEAVES:0)
Block(3,9,-1,LEAVES:0)
Block(3,10,-5,LEAVES:0)
Block(3,10,-4,LEAVES:0)
Block(3,10,-2,LEAVES:0)
Block(3,10,0,LEAVES:0)
Block(3,10,1,LEAVES:0)
Block(3,11,-4,LEAVES:0)
Block(3,11,0,LEAVES:0)
Block(3,11,1,LEAVES:0)
Block(3,11,2,LOG:0)
Block(3,11,3,LEAVES:0)
Block(3,11,4,LEAVES:0)
Block(3,12,1,LEAVES:0)
Block(3,12,2,LEAVES:0)
Block(3,12,3,LEAVES:0)
Block(4,4,2,LEAVES:0)
Block(4,8,-3,LEAVES:0)
Block(4,9,-5,LEAVES:0)
Block(4,9,-4,LEAVES:0)
Block(4,9,-2,LEAVES:0)
Block(4,9,0,LEAVES:0)
Block(4,10,-4,LEAVES:0)
Block(4,10,2,LEAVES:0)
Block(4,11,1,LEAVES:0)
Block(4,11,2,LEAVES:0)
Block(4,11,3,LEAVES:0)
Block(5,10,1,LEAVES:0)
Block(5,11,2,LEAVES:0)

#######################################################################
# +-----------------------------------------------------------------+ #
# |                            BO3 checks                           | #
# +-----------------------------------------------------------------+ #
#######################################################################

BlockCheck(0,-1,0,GRASS:0,DIRT:0)

#######################################################################
# +-----------------------------------------------------------------+ #
# |                             Branches                            | #
# +-----------------------------------------------------------------+ #
#######################################################################


#######################################################################
# +-----------------------------------------------------------------+ #
# |                             Entities                            | #
# +-----------------------------------------------------------------+ #
#######################################################################


#######################################################################
# +-----------------------------------------------------------------+ #
# |                            Particles                            | #
# +-----------------------------------------------------------------+ #
#######################################################################


#######################################################################
# +-----------------------------------------------------------------+ #
# |                             Spawners                            | #
# +-----------------------------------------------------------------+ #
#######################################################################


#######################################################################
# +-----------------------------------------------------------------+ #
# |                             ModData                             | #
# +-----------------------------------------------------------------+ #
#######################################################################

