
#######################################################################
# +-----------------------------------------------------------------+ #
# |                            BO3 object                           | #
# +-----------------------------------------------------------------+ #
#######################################################################

# This is the config file of a custom object.
# If you add this object correctly to your BiomeConfigs, it will spawn in the world.

# This is the creator of this BO3 object
Author: Unknown

# A short description of this BO3 object
Description: No description given

# The BO3 version, don't change this! It can be used by external applications to do a version check.
Version: 3

# The settings mode, WriteAll, WriteWithoutComments or WriteDisable. See WorldConfig.
SettingsMode: WriteDisable


#######################################################################
# +-----------------------------------------------------------------+ #
# |                          Main settings                          | #
# +-----------------------------------------------------------------+ #
#######################################################################

# This needs to be set to true to spawn the object in the Tree and Sapling resources.
Tree: true

# The frequency of the BO3 from 1 to 200. Tries this many times to spawn this BO3 when using the CustomObject(...) resource.
# Ignored by Tree(..), Sapling(..) and CustomStructure(..)
Frequency: 0

# The rarity of the BO3 from 0 to 100. Each spawn attempt has rarity% chance to succeed when using the CustomObject(...) resource.
# Ignored by Tree(..), Sapling(..) and CustomStructure(..)
Rarity: 100.0

# If you set this to true, the BO3 will be placed with a random rotation.
RotateRandomly: true

# The spawn height of the BO3: randomY, highestBlock or highestSolidBlock.
SpawnHeight: highestSolidBlock

# The offset from the spawn height to spawn this BO3
# Ex. SpawnHeight = highestSolidBlock, SpawnHeightOffset = 3; This object will spawn 3 blocks above the highest solid block
SpawnHeightOffset: 0

# A random amount to offset the spawn location from the spawn offset height
# Ex. SpawnHeightOffset = 3, SpawnHeightVariance = 3; This object will spawn 3 to 6 blocks above the original spot it would have spawned
SpawnHeightVariance: 0

##############################
# Height Limits for the BO3. #
##############################

# When in randomY mode used as the minimum Y or in atMinY mode as the actual Y to spawn this BO3 at.
MinHeight: 61

# When in randomY mode used as the maximum Y to spawn this BO3 at.
MaxHeight: 256

######################
# Extrusion settings #
######################

# The style of extrusion you wish to use - BottomDown, TopUp, None (Default)
ExtrudeMode: BottomDown

# The blocks to extrude your BO3 through
ExtrudeThroughBlocks: AIR,STATIONARY_WATER

# Objects can have other objects attacthed to it: branches. Branches can also
# have branches attached to it, which can also have branches, etc. This is the
# maximum branch depth for this objects.
MaxBranchDepth: 10

# When spawned with the UseWorld keyword, this BO3 should NOT spawn in the following biomes.
# If you write the BO3 name directly in the BiomeConfigs, this will be ignored.
ExcludedBiomes: All


#######################################################################
# +-----------------------------------------------------------------+ #
# |                      Source block settings                      | #
# +-----------------------------------------------------------------+ #
#######################################################################

# The block(s) the BO3 should spawn in.
SourceBlocks: AIR

# The maximum percentage of the BO3 that can be outside the SourceBlock.
# The BO3 won't be placed on a location with more blocks outside the SourceBlock than this percentage.
MaxPercentageOutsideSourceBlock: 100

# What to do when a block is about to be placed outside the SourceBlock? (dontPlace, placeAnyway)
OutsideSourceBlock: placeAnyway

# OTG+ settings #
# Legacy setting, rename this file to .BO4 instead. Set this to true to enable the advanced customstructure features of OTG+.
IsOTGPlus: false


#######################################################################
# +-----------------------------------------------------------------+ #
# |                              Blocks                             | #
# +-----------------------------------------------------------------+ #
#######################################################################

# All the blocks used in the BO3 are listed here. Possible blocks:
# Block(x,y,z,id[.data][,nbtfile.nbt)
# RandomBlock(x,y,z,id[:data][,nbtfile.nbt],chance[,id[:data][,nbtfile.nbt],chance[,...]])
#  So RandomBlock(0,0,0,CHEST,chest.nbt,50,CHEST,anotherchest.nbt,100) will spawn a chest at
#  the BO3 origin, and give it a 50% chance to have the contents of chest.nbt, or, if that
#  fails, a 100% percent chance to have the contents of anotherchest.nbt.
# *Note: Unlike Entity() and Spawner(), for Block() .txt files don't work, only .nbt files work.
# MinecraftObject(x,y,z,name) (TODO: This may not work anymore and needs to be tested.
#  Spawns an object in the Mojang NBT structure format. For example, 
#  MinecraftObject(0,0,0,minecraft:igloo/igloo_bottom)
#  spawns the bottom part of an igloo.
Block(-14,33,-2,LEAVES:1)
Block(-13,33,-4,LEAVES:1)
Block(-13,33,-2,LEAVES:1)
Block(-13,33,-1,LEAVES:1)
Block(-13,33,0,LEAVES:1)
Block(-13,34,-2,LEAVES:1)
Block(-12,33,-4,LEAVES:1)
Block(-12,33,-2,LEAVES:1)
Block(-12,33,0,LEAVES:1)
Block(-12,33,1,LEAVES:1)
Block(-12,34,-3,LEAVES:1)
Block(-12,34,-2,LOG:13)
Block(-12,34,-1,LEAVES:1)
Block(-12,34,0,LEAVES:1)
Block(-11,29,4,LEAVES:1)
Block(-11,33,-4,LEAVES:1)
Block(-11,33,-3,LEAVES:1)
Block(-11,33,1,LEAVES:1)
Block(-11,33,2,LEAVES:1)
Block(-11,34,-3,LEAVES:1)
Block(-11,34,-2,LEAVES:1)
Block(-11,34,-1,LOG:13)
Block(-11,34,0,LEAVES:1)
Block(-11,34,1,LEAVES:1)
Block(-11,35,-1,LEAVES:1)
Block(-11,37,6,LEAVES:1)
Block(-11,37,8,LEAVES:1)
Block(-11,41,-2,LEAVES:1)
Block(-11,41,0,LEAVES:1)
Block(-10,15,9,LEAVES:1)
Block(-10,15,11,LEAVES:1)
Block(-10,19,-7,LEAVES:1)
Block(-10,29,3,LEAVES:1)
Block(-10,29,4,LEAVES:1)
Block(-10,29,5,LEAVES:1)
Block(-10,30,-6,LEAVES:1)
Block(-10,31,13,LEAVES:1)
Block(-10,31,15,LEAVES:1)
Block(-10,34,-3,LEAVES:1)
Block(-10,34,1,LEAVES:1)
Block(-10,35,-2,LEAVES:1)
Block(-10,35,-1,LOG:13)
Block(-10,35,0,LEAVES:1)
Block(-10,37,5,LEAVES:1)
Block(-10,37,6,LEAVES:1)
Block(-10,37,7,LEAVES:1)
Block(-10,37,8,LEAVES:1)
Block(-10,38,7,LEAVES:1)
Block(-10,41,-3,LEAVES:1)
Block(-10,41,-2,LEAVES:1)
Block(-10,41,-1,LEAVES:1)
Block(-10,41,0,LEAVES:1)
Block(-10,42,-1,LEAVES:1)
Block(-10,45,6,LEAVES:1)
Block(-10,47,-5,LEAVES:1)
Block(-9,15,8,LEAVES:1)
Block(-9,15,9,LEAVES:1)
Block(-9,15,11,LEAVES:1)
Block(-9,16,10,LEAVES:1)
Block(-9,19,-9,LEAVES:1)
Block(-9,19,-8,LEAVES:1)
Block(-9,19,-7,LEAVES:1)
Block(-9,19,-6,LEAVES:1)
Block(-9,19,-5,LEAVES:1)
Block(-9,20,-7,LEAVES:1)
Block(-9,29,2,LEAVES:1)
Block(-9,29,4,LEAVES:1)
Block(-9,29,5,LEAVES:1)
Block(-9,29,6,LEAVES:1)
Block(-9,30,-8,LEAVES:1)
Block(-9,30,-6,LEAVES:1)
Block(-9,30,-4,LEAVES:1)
Block(-9,30,4,LEAVES:1)
Block(-9,31,-6,LEAVES:1)
Block(-9,31,13,LEAVES:1)
Block(-9,31,14,LEAVES:1)
Block(-9,31,15,LEAVES:1)
Block(-9,32,14,LEAVES:1)
Block(-9,34,2,LEAVES:1)
Block(-9,35,-1,LEAVES:1)
Block(-9,35,0,LOG:13)
Block(-9,35,1,LEAVES:1)
Block(-9,37,-9,LEAVES:1)
Block(-9,37,6,LEAVES:1)
Block(-9,37,8,LEAVES:1)
Block(-9,37,9,LEAVES:1)
Block(-9,38,6,LEAVES:1)
Block(-9,38,7,LOG:13)
Block(-9,38,8,LEAVES:1)
Block(-9,41,0,LEAVES:1)
Block(-9,41,1,LEAVES:1)
Block(-9,42,-2,LEAVES:1)
Block(-9,42,-1,LOG:13)
Block(-9,42,0,LEAVES:1)
Block(-9,45,5,LEAVES:1)
Block(-9,45,6,LEAVES:1)
Block(-9,45,7,LEAVES:1)
Block(-9,47,-6,LEAVES:1)
Block(-9,47,-5,LEAVES:1)
Block(-9,47,-4,LEAVES:1)
Block(-9,54,0,LEAVES:1)
Block(-8,15,9,LEAVES:1)
Block(-8,15,10,LEAVES:1)
Block(-8,15,11,LEAVES:1)
Block(-8,15,12,LEAVES:1)
Block(-8,16,7,LEAVES:1)
Block(-8,16,8,LEAVES:1)
Block(-8,16,9,LEAVES:1)
Block(-8,16,10,LOG:13)
Block(-8,16,11,LEAVES:1)
Block(-8,19,-8,LEAVES:1)
Block(-8,19,-6,LEAVES:1)
Block(-8,20,-8,LEAVES:1)
Block(-8,20,-7,LOG:13)
Block(-8,20,-6,LEAVES:1)
Block(-8,20,-4,LEAVES:1)
Block(-8,29,2,LEAVES:1)
Block(-8,29,3,LEAVES:1)
Block(-8,30,-8,LEAVES:1)
Block(-8,30,-4,LEAVES:1)
Block(-8,30,3,LEAVES:1)
Block(-8,30,4,LOG:13)
Block(-8,30,5,LEAVES:1)
Block(-8,30,6,LEAVES:1)
Block(-8,30,7,LEAVES:1)
Block(-8,31,-7,LEAVES:1)
Block(-8,31,-6,LOG:13)
Block(-8,31,-5,LEAVES:1)
Block(-8,31,-3,LEAVES:1)
Block(-8,31,12,LEAVES:1)
Block(-8,31,15,LEAVES:1)
Block(-8,31,16,LEAVES:1)
Block(-8,32,13,LEAVES:1)
Block(-8,32,14,LOG:13)
Block(-8,32,15,LEAVES:1)
Block(-8,34,-2,LEAVES:1)
Block(-8,34,-1,LEAVES:1)
Block(-8,35,-1,LEAVES:1)
Block(-8,35,2,LEAVES:1)
Block(-8,35,3,LEAVES:1)
Block(-8,36,0,LEAVES:1)
Block(-8,36,1,LOG:13)
Block(-8,36,2,LEAVES:1)
Block(-8,37,-9,LEAVES:1)
Block(-8,37,-8,LEAVES:1)
Block(-8,37,-7,LEAVES:1)
Block(-8,37,5,LEAVES:1)
Block(-8,37,6,LEAVES:1)
Block(-8,37,7,LEAVES:1)
Block(-8,38,-8,LEAVES:1)
Block(-8,38,6,LEAVES:1)
Block(-8,38,7,LOG:13)
Block(-8,38,8,LEAVES:1)
Block(-8,39,7,LEAVES:1)
Block(-8,41,1,LEAVES:1)
Block(-8,42,-3,LEAVES:1)
Block(-8,42,-2,LEAVES:1)
Block(-8,42,-1,LEAVES:1)
Block(-8,42,1,LEAVES:1)
Block(-8,43,-2,LEAVES:1)
Block(-8,43,-1,LOG:13)
Block(-8,43,0,LEAVES:1)
Block(-8,45,6,LEAVES:1)
Block(-8,46,4,LEAVES:1)
Block(-8,46,5,LEAVES:1)
Block(-8,46,6,LEAVES:1)
Block(-8,47,-5,LEAVES:1)
Block(-8,47,-4,LEAVES:1)
Block(-8,47,-3,LEAVES:1)
Block(-8,48,-5,LEAVES:1)
Block(-8,52,5,LEAVES:1)
Block(-8,52,7,LEAVES:1)
Block(-8,54,-2,LEAVES:1)
Block(-8,54,-1,LEAVES:1)
Block(-8,54,0,LEAVES:1)
Block(-8,54,1,LEAVES:1)
Block(-8,54,2,LEAVES:1)
Block(-8,55,0,LEAVES:1)
Block(-7,15,7,LEAVES:1)
Block(-7,16,9,LOG:13)
Block(-7,16,10,LEAVES:1)
Block(-7,17,8,LEAVES:1)
Block(-7,17,9,LEAVES:1)
Block(-7,19,-9,LEAVES:1)
Block(-7,19,-8,LEAVES:1)
Block(-7,19,-5,LEAVES:1)
Block(-7,20,-7,LEAVES:1)
Block(-7,20,-5,LEAVES:1)
Block(-7,20,-4,LEAVES:1)
Block(-7,21,-7,LEAVES:1)
Block(-7,21,-6,LOG:13)
Block(-7,21,-5,LEAVES:1)
Block(-7,29,2,LEAVES:1)
Block(-7,29,6,LEAVES:1)
Block(-7,29,7,LEAVES:1)
Block(-7,29,8,LEAVES:1)
Block(-7,30,-8,LEAVES:1)
Block(-7,30,-7,LEAVES:1)
Block(-7,30,-4,LEAVES:1)
Block(-7,30,6,LEAVES:1)
Block(-7,31,-7,LEAVES:1)
Block(-7,31,-6,LEAVES:1)
Block(-7,31,-4,LEAVES:1)
Block(-7,31,-3,LEAVES:1)
Block(-7,31,-2,LEAVES:1)
Block(-7,31,4,LEAVES:1)
Block(-7,31,5,LOG:13)
Block(-7,31,6,LEAVES:1)
Block(-7,31,11,LEAVES:1)
Block(-7,31,14,LEAVES:1)
Block(-7,32,-5,LOG:13)
Block(-7,32,-4,LEAVES:1)
Block(-7,32,-3,LEAVES:1)
Block(-7,32,10,LEAVES:1)
Block(-7,32,11,LEAVES:1)
Block(-7,32,12,LEAVES:1)
Block(-7,32,13,LOG:13)
Block(-7,32,14,LEAVES:1)
Block(-7,33,12,LEAVES:1)
Block(-7,33,13,LOG:13)
Block(-7,33,14,LEAVES:1)
Block(-7,35,-1,LEAVES:1)
Block(-7,36,0,LEAVES:1)
Block(-7,36,1,LOG:13)
Block(-7,36,2,LEAVES:1)
Block(-7,37,-10,LEAVES:1)
Block(-7,37,-9,LEAVES:1)
Block(-7,37,-6,LEAVES:1)
Block(-7,37,-5,LEAVES:1)
Block(-7,37,1,LEAVES:1)
Block(-7,37,8,LEAVES:1)
Block(-7,37,9,LEAVES:1)
Block(-7,38,-9,LEAVES:1)
Block(-7,38,-8,LOG:13)
Block(-7,38,-7,LEAVES:1)
Block(-7,38,5,LEAVES:1)
Block(-7,38,7,LEAVES:1)
Block(-7,38,8,LEAVES:1)
Block(-7,39,6,LEAVES:1)
Block(-7,39,7,LOG:13)
Block(-7,39,8,LEAVES:1)
Block(-7,40,14,LEAVES:1)
Block(-7,41,1,LEAVES:1)
Block(-7,41,2,LEAVES:1)
Block(-7,42,1,LEAVES:1)
Block(-7,43,-2,LEAVES:1)
Block(-7,43,-1,LOG:13)
Block(-7,43,0,LEAVES:1)
Block(-7,43,4,LEAVES:1)
Block(-7,43,6,LEAVES:1)
Block(-7,44,-1,LEAVES:1)
Block(-7,45,4,LEAVES:1)
Block(-7,45,7,LEAVES:1)
Block(-7,45,8,LEAVES:1)
Block(-7,46,4,LEAVES:1)
Block(-7,46,6,LOG:13)
Block(-7,46,7,LEAVES:1)
Block(-7,47,-7,LEAVES:1)
Block(-7,47,-6,LEAVES:1)
Block(-7,47,-5,LEAVES:1)
Block(-7,47,-3,LEAVES:1)
Block(-7,47,5,LEAVES:1)
Block(-7,47,6,LEAVES:1)
Block(-7,48,-6,LEAVES:1)
Block(-7,48,-5,LOG:13)
Block(-7,48,-4,LEAVES:1)
Block(-7,50,14,LEAVES:1)
Block(-7,52,5,LEAVES:1)
Block(-7,52,6,LEAVES:1)
Block(-7,52,7,LEAVES:1)
Block(-7,52,8,LEAVES:1)
Block(-7,53,6,LEAVES:1)
Block(-7,54,0,LEAVES:1)
Block(-7,55,-1,LEAVES:1)
Block(-7,55,0,LOG:13)
Block(-7,55,1,LEAVES:1)
Block(-6,0,0,LOG:13)
Block(-6,0,1,LOG:13)
Block(-6,0,2,LOG:13)
Block(-6,1,1,LOG:13)
Block(-6,15,7,LEAVES:1)
Block(-6,15,10,LEAVES:1)
Block(-6,15,11,LEAVES:1)
Block(-6,16,6,LEAVES:1)
Block(-6,16,7,LEAVES:1)
Block(-6,16,8,LEAVES:1)
Block(-6,16,9,LEAVES:1)
Block(-6,16,10,LEAVES:1)
Block(-6,17,7,LEAVES:1)
Block(-6,17,8,LOG:13)
Block(-6,20,-8,LEAVES:1)
Block(-6,20,-7,LEAVES:1)
Block(-6,20,-6,LEAVES:1)
Block(-6,20,-4,LEAVES:1)
Block(-6,21,-7,LEAVES:1)
Block(-6,21,-6,LOG:13)
Block(-6,21,-5,LEAVES:1)
Block(-6,22,-6,LEAVES:1)
Block(-6,22,-3,LEAVES:1)
Block(-6,30,-7,LEAVES:1)
Block(-6,30,-5,LEAVES:1)
Block(-6,30,3,LEAVES:1)
Block(-6,30,4,LEAVES:1)
Block(-6,30,5,LEAVES:1)
Block(-6,30,7,LEAVES:1)
Block(-6,31,-5,LEAVES:1)
Block(-6,31,-4,LEAVES:1)
Block(-6,31,4,LEAVES:1)
Block(-6,31,5,LOG:13)
Block(-6,31,6,LEAVES:1)
Block(-6,32,-5,LEAVES:1)
Block(-6,32,-4,LOG:13)
Block(-6,32,-3,LEAVES:1)
Block(-6,32,5,LEAVES:1)
Block(-6,32,12,LEAVES:1)
Block(-6,32,13,LEAVES:1)
Block(-6,32,14,LEAVES:1)
Block(-6,32,15,LEAVES:1)
Block(-6,33,-4,LEAVES:1)
Block(-6,33,9,LEAVES:1)
Block(-6,33,10,LEAVES:1)
Block(-6,33,11,LEAVES:1)
Block(-6,33,12,LOG:13)
Block(-6,33,13,LEAVES:1)
Block(-6,34,12,LEAVES:1)
Block(-6,35,3,LEAVES:1)
Block(-6,36,-1,LEAVES:1)
Block(-6,36,1,LEAVES:1)
Block(-6,37,-10,LEAVES:1)
Block(-6,37,-9,LEAVES:1)
Block(-6,37,-7,LEAVES:1)
Block(-6,37,-6,LEAVES:1)
Block(-6,37,0,LEAVES:1)
Block(-6,37,1,LOG:13)
Block(-6,38,-8,LEAVES:1)
Block(-6,38,-7,LOG:13)
Block(-6,38,-6,LEAVES:1)
Block(-6,38,-4,LEAVES:1)
Block(-6,38,8,LEAVES:1)
Block(-6,38,9,LEAVES:1)
Block(-6,39,-7,LEAVES:1)
Block(-6,39,-5,LEAVES:1)
Block(-6,39,5,LEAVES:1)
Block(-6,39,6,LEAVES:1)
Block(-6,39,7,LOG:13)
Block(-6,39,8,LEAVES:1)
Block(-6,40,4,LEAVES:1)
Block(-6,40,7,LEAVES:1)
Block(-6,40,12,LEAVES:1)
Block(-6,40,14,LEAVES:1)
Block(-6,40,15,LEAVES:1)
Block(-6,41,14,LEAVES:1)
Block(-6,42,1,LEAVES:1)
Block(-6,43,-3,LEAVES:1)
Block(-6,43,-2,LEAVES:1)
Block(-6,43,-1,LEAVES:1)
Block(-6,43,0,LEAVES:1)
Block(-6,43,1,LEAVES:1)
Block(-6,43,2,LEAVES:1)
Block(-6,43,7,LEAVES:1)
Block(-6,44,-2,LEAVES:1)
Block(-6,44,-1,LOG:13)
Block(-6,44,0,LEAVES:1)
Block(-6,44,4,LEAVES:1)
Block(-6,44,5,LEAVES:1)
Block(-6,45,7,LEAVES:1)
Block(-6,46,3,LEAVES:1)
Block(-6,46,4,LEAVES:1)
Block(-6,46,5,LOG:13)
Block(-6,46,6,LEAVES:1)
Block(-6,47,-6,LEAVES:1)
Block(-6,47,-3,LEAVES:1)
Block(-6,47,-2,LEAVES:1)
Block(-6,47,4,LEAVES:1)
Block(-6,47,5,LOG:13)
Block(-6,48,-5,LEAVES:1)
Block(-6,48,-4,LOG:13)
Block(-6,48,-3,LEAVES:1)
Block(-6,49,-4,LEAVES:1)
Block(-6,50,12,LEAVES:1)
Block(-6,50,14,LEAVES:1)
Block(-6,51,13,LEAVES:1)
Block(-6,51,14,LEAVES:1)
Block(-6,52,4,LEAVES:1)
Block(-6,52,5,LEAVES:1)
Block(-6,52,6,LEAVES:1)
Block(-6,52,7,LEAVES:1)
Block(-6,53,5,LEAVES:1)
Block(-6,53,6,LOG:13)
Block(-6,53,7,LEAVES:1)
Block(-6,54,-1,LEAVES:1)
Block(-6,54,0,LEAVES:1)
Block(-6,54,1,LEAVES:1)
Block(-6,54,2,LEAVES:1)
Block(-6,55,0,LEAVES:1)
Block(-6,55,2,LEAVES:1)
Block(-6,55,3,LEAVES:1)
Block(-6,56,0,LEAVES:1)
Block(-6,56,1,LOG:13)
Block(-6,56,2,LEAVES:1)
Block(-6,60,1,LEAVES:1)
Block(-5,0,-2,LOG:13)
Block(-5,0,-1,LOG:13)
Block(-5,0,0,LOG:13)
Block(-5,0,1,LOG:13)
Block(-5,0,2,LOG:13)
Block(-5,0,3,LOG:13)
Block(-5,1,-1,LOG:13)
Block(-5,1,0,LOG:13)
Block(-5,1,1,LOG:13)
Block(-5,1,2,LOG:13)
Block(-5,2,0,LOG:13)
Block(-5,2,1,LOG:13)
Block(-5,3,1,LOG:13)
Block(-5,4,1,LOG:13)
Block(-5,15,10,LEAVES:1)
Block(-5,16,8,LEAVES:1)
Block(-5,17,5,LEAVES:1)
Block(-5,17,7,LOG:13)
Block(-5,17,8,LEAVES:1)
Block(-5,18,6,LEAVES:1)
Block(-5,18,7,LEAVES:1)
Block(-5,20,-6,LEAVES:1)
Block(-5,20,-3,LEAVES:1)
Block(-5,21,-6,LEAVES:1)
Block(-5,21,-5,LOG:13)
Block(-5,21,-4,LEAVES:1)
Block(-5,21,-3,LEAVES:1)
Block(-5,21,-2,LEAVES:1)
Block(-5,22,-5,LOG:13)
Block(-5,22,-4,LEAVES:1)
Block(-5,22,-3,LEAVES:1)
Block(-5,22,-2,LEAVES:1)
Block(-5,23,-3,LEAVES:1)
Block(-5,30,-10,LEAVES:1)
Block(-5,30,-8,LEAVES:1)
Block(-5,30,-7,LEAVES:1)
Block(-5,31,-7,LEAVES:1)
Block(-5,31,-6,LEAVES:1)
Block(-5,31,3,LEAVES:1)
Block(-5,31,7,LEAVES:1)
Block(-5,32,-4,LEAVES:1)
Block(-5,32,-3,LOG:13)
Block(-5,32,-1,LEAVES:1)
Block(-5,32,4,LEAVES:1)
Block(-5,32,5,LOG:13)
Block(-5,32,6,LEAVES:1)
Block(-5,32,10,LEAVES:1)
Block(-5,32,13,LEAVES:1)
Block(-5,32,14,LEAVES:1)
Block(-5,33,-3,LOG:13)
Block(-5,33,-2,LEAVES:1)
Block(-5,33,10,LEAVES:1)
Block(-5,33,11,LOG:13)
Block(-5,33,12,LEAVES:1)
Block(-5,34,8,LEAVES:1)
Block(-5,34,9,LEAVES:1)
Block(-5,34,10,LEAVES:1)
Block(-5,35,-2,LEAVES:1)
Block(-5,35,-1,LEAVES:1)
Block(-5,35,0,LEAVES:1)
Block(-5,35,3,LEAVES:1)
Block(-5,36,-1,LEAVES:1)
Block(-5,36,0,LEAVES:1)
Block(-5,36,1,LEAVES:1)
Block(-5,36,2,LEAVES:1)
Block(-5,36,3,LEAVES:1)
Block(-5,37,-9,LEAVES:1)
Block(-5,37,-8,LEAVES:1)
Block(-5,37,-7,LEAVES:1)
Block(-5,37,-6,LEAVES:1)
Block(-5,37,-4,LEAVES:1)
Block(-5,37,-3,LEAVES:1)
Block(-5,37,0,LEAVES:1)
Block(-5,37,1,LOG:13)
Block(-5,37,2,LEAVES:1)
Block(-5,38,-7,LEAVES:1)
Block(-5,38,-6,LEAVES:1)
Block(-5,38,-5,LEAVES:1)
Block(-5,38,-4,LEAVES:1)
Block(-5,38,1,LEAVES:1)
Block(-5,38,5,LEAVES:1)
Block(-5,38,7,LEAVES:1)
Block(-5,39,-6,LOG:13)
Block(-5,39,-5,LOG:13)
Block(-5,39,-4,LEAVES:1)
Block(-5,39,7,LEAVES:1)
Block(-5,39,9,LEAVES:1)
Block(-5,39,14,LEAVES:1)
Block(-5,40,-5,LEAVES:1)
Block(-5,40,3,LEAVES:1)
Block(-5,40,4,LEAVES:1)
Block(-5,40,6,LEAVES:1)
Block(-5,40,7,LOG:13)
Block(-5,40,8,LEAVES:1)
Block(-5,40,11,LEAVES:1)
Block(-5,40,12,LEAVES:1)
Block(-5,40,14,LEAVES:1)
Block(-5,41,3,LEAVES:1)
Block(-5,41,4,LEAVES:1)
Block(-5,41,13,LEAVES:1)
Block(-5,41,14,LOG:13)
Block(-5,41,15,LEAVES:1)
Block(-5,43,1,LEAVES:1)
Block(-5,43,4,LEAVES:1)
Block(-5,44,-2,LEAVES:1)
Block(-5,44,-1,LOG:13)
Block(-5,44,0,LEAVES:1)
Block(-5,44,2,LEAVES:1)
Block(-5,44,3,LEAVES:1)
Block(-5,44,4,LOG:13)
Block(-5,44,5,LOG:13)
Block(-5,44,6,LEAVES:1)
Block(-5,45,-1,LEAVES:1)
Block(-5,45,5,LEAVES:1)
Block(-5,47,1,LEAVES:1)
Block(-5,47,2,LEAVES:1)
Block(-5,47,3,LEAVES:1)
Block(-5,47,4,LOG:13)
Block(-5,47,5,LEAVES:1)
Block(-5,48,-5,LEAVES:1)
Block(-5,48,-2,LEAVES:1)
Block(-5,48,-1,LEAVES:1)
Block(-5,48,3,LEAVES:1)
Block(-5,49,-4,LEAVES:1)
Block(-5,49,-3,LOG:13)
Block(-5,49,-2,LEAVES:1)
Block(-5,50,10,LEAVES:1)
Block(-5,50,11,LEAVES:1)
Block(-5,50,13,LEAVES:1)
Block(-5,50,15,LEAVES:1)
Block(-5,51,12,LEAVES:1)
Block(-5,51,13,LOG:13)
Block(-5,51,14,LEAVES:1)
Block(-5,52,4,LEAVES:1)
Block(-5,52,5,LEAVES:1)
Block(-5,52,8,LEAVES:1)
Block(-5,53,5,LEAVES:1)
Block(-5,53,6,LOG:13)
Block(-5,53,7,LEAVES:1)
Block(-5,54,6,LEAVES:1)
Block(-5,55,-1,LEAVES:1)
Block(-5,56,0,LEAVES:1)
Block(-5,56,1,LEAVES:1)
Block(-5,57,1,LEAVES:1)
Block(-5,57,2,LOG:13)
Block(-5,57,3,LEAVES:1)
Block(-5,58,6,LEAVES:1)
Block(-5,60,-1,LEAVES:1)
Block(-5,60,0,LEAVES:1)
Block(-5,60,1,LEAVES:1)
Block(-5,61,0,LEAVES:1)
Block(-4,0,-2,LOG:13)
Block(-4,0,-1,LOG:13)
Block(-4,0,0,LOG:13)
Block(-4,0,1,LOG:13)
Block(-4,0,2,LOG:13)
Block(-4,0,3,LOG:13)
Block(-4,0,4,LOG:13)
Block(-4,0,5,LOG:13)
Block(-4,1,-2,LOG:13)
Block(-4,1,-1,LOG:13)
Block(-4,1,0,LOG:13)
Block(-4,1,1,LOG:13)
Block(-4,1,2,LOG:13)
Block(-4,1,3,LOG:13)
Block(-4,1,4,LOG:13)
Block(-4,2,-1,LOG:13)
Block(-4,2,0,LOG:13)
Block(-4,2,1,LOG:13)
Block(-4,2,2,LOG:13)
Block(-4,2,3,LOG:13)
Block(-4,3,0,LOG:13)
Block(-4,3,1,LOG:13)
Block(-4,3,2,LOG:13)
Block(-4,3,3,LOG:13)
Block(-4,4,0,LOG:13)
Block(-4,4,1,LOG:13)
Block(-4,4,2,LOG:13)
Block(-4,5,0,LOG:13)
Block(-4,5,1,LOG:13)
Block(-4,5,2,LOG:13)
Block(-4,6,0,LOG:13)
Block(-4,6,2,LOG:13)
Block(-4,16,7,LEAVES:1)
Block(-4,16,8,LEAVES:1)
Block(-4,16,9,LEAVES:1)
Block(-4,17,4,LEAVES:1)
Block(-4,17,6,LEAVES:1)
Block(-4,17,7,LEAVES:1)
Block(-4,18,5,LEAVES:1)
Block(-4,18,6,LOG:13)
Block(-4,18,7,LEAVES:1)
Block(-4,19,3,LEAVES:1)
Block(-4,20,-7,LEAVES:1)
Block(-4,20,-6,LEAVES:1)
Block(-4,21,-4,LEAVES:1)
Block(-4,21,1,LEAVES:1)
Block(-4,22,-5,LEAVES:1)
Block(-4,22,-4,LOG:13)
Block(-4,22,-3,LEAVES:1)
Block(-4,22,-2,LEAVES:1)
Block(-4,22,-1,LEAVES:1)
Block(-4,23,-4,LEAVES:1)
Block(-4,23,-3,LOG:13)
Block(-4,23,-2,LEAVES:1)
Block(-4,30,-10,LEAVES:1)
Block(-4,30,-8,LEAVES:1)
Block(-4,30,-7,LEAVES:1)
Block(-4,30,4,LEAVES:1)
Block(-4,31,-9,LEAVES:1)
Block(-4,31,-8,LEAVES:1)
Block(-4,31,-6,LEAVES:1)
Block(-4,31,-5,LEAVES:1)
Block(-4,31,4,LEAVES:1)
Block(-4,31,5,LEAVES:1)
Block(-4,31,7,LEAVES:1)
Block(-4,31,8,LEAVES:1)
Block(-4,32,-5,LEAVES:1)
Block(-4,32,-2,LEAVES:1)
Block(-4,32,0,LEAVES:1)
Block(-4,32,4,LEAVES:1)
Block(-4,32,5,LOG:13)
Block(-4,32,6,LEAVES:1)
Block(-4,32,12,LEAVES:1)
Block(-4,32,13,LEAVES:1)
Block(-4,33,-5,LEAVES:1)
Block(-4,33,-3,LEAVES:1)
Block(-4,33,-2,LOG:13)
Block(-4,33,-1,LEAVES:1)
Block(-4,33,5,LEAVES:1)
Block(-4,33,8,LEAVES:1)
Block(-4,33,11,LEAVES:1)
Block(-4,34,-2,LEAVES:1)
Block(-4,34,7,LEAVES:1)
Block(-4,34,9,LEAVES:1)
Block(-4,34,10,LOG:13)
Block(-4,35,-1,LEAVES:1)
Block(-4,35,9,LEAVES:1)
Block(-4,36,-1,LEAVES:1)
Block(-4,36,4,LEAVES:1)
Block(-4,37,-7,LEAVES:1)
Block(-4,37,-4,LEAVES:1)
Block(-4,38,-6,LEAVES:1)
Block(-4,38,-4,LEAVES:1)
Block(-4,38,-2,LEAVES:1)
Block(-4,38,1,LEAVES:1)
Block(-4,38,2,LOG:13)
Block(-4,38,3,LEAVES:1)
Block(-4,38,6,LEAVES:1)
Block(-4,38,7,LEAVES:1)
Block(-4,38,8,LEAVES:1)
Block(-4,39,-6,LEAVES:1)
Block(-4,39,-5,LEAVES:1)
Block(-4,39,-4,LOG:13)
Block(-4,39,-3,LEAVES:1)
Block(-4,39,-2,LEAVES:1)
Block(-4,39,-1,LEAVES:1)
Block(-4,40,-4,LEAVES:1)
Block(-4,40,7,LEAVES:1)
Block(-4,40,8,LOG:13)
Block(-4,40,9,LEAVES:1)
Block(-4,40,12,LEAVES:1)
Block(-4,40,13,LEAVES:1)
Block(-4,40,15,LEAVES:1)
Block(-4,40,16,LEAVES:1)
Block(-4,41,2,LEAVES:1)
Block(-4,41,3,LEAVES:1)
Block(-4,41,4,LOG:13)
Block(-4,41,5,LEAVES:1)
Block(-4,41,10,LEAVES:1)
Block(-4,41,11,LEAVES:1)
Block(-4,41,12,LEAVES:1)
Block(-4,41,13,LOG:13)
Block(-4,41,14,LEAVES:1)
Block(-4,41,15,LEAVES:1)
Block(-4,42,2,LEAVES:1)
Block(-4,42,13,LEAVES:1)
Block(-4,43,-2,LEAVES:1)
Block(-4,43,-1,LEAVES:1)
Block(-4,43,2,LEAVES:1)
Block(-4,44,-1,LEAVES:1)
Block(-4,44,0,LOG:13)
Block(-4,44,4,LEAVES:1)
Block(-4,44,5,LEAVES:1)
Block(-4,44,6,LOG:13)
Block(-4,44,7,LEAVES:1)
Block(-4,44,8,LEAVES:1)
Block(-4,45,0,LOG:13)
Block(-4,45,1,LEAVES:1)
Block(-4,45,6,LEAVES:1)
Block(-4,45,7,LEAVES:1)
Block(-4,46,2,LEAVES:1)
Block(-4,46,6,LEAVES:1)
Block(-4,47,-6,LEAVES:1)
Block(-4,47,-5,LEAVES:1)
Block(-4,47,3,LEAVES:1)
Block(-4,47,4,LEAVES:1)
Block(-4,48,-5,LEAVES:1)
Block(-4,48,-4,LEAVES:1)
Block(-4,48,2,LEAVES:1)
Block(-4,48,3,LOG:13)
Block(-4,48,4,LEAVES:1)
Block(-4,49,-4,LEAVES:1)
Block(-4,49,-3,LOG:13)
Block(-4,49,-2,LEAVES:1)
Block(-4,49,0,LEAVES:1)
Block(-4,50,-3,LEAVES:1)
Block(-4,50,9,LEAVES:1)
Block(-4,50,10,LEAVES:1)
Block(-4,50,11,LEAVES:1)
Block(-4,50,12,LEAVES:1)
Block(-4,50,13,LEAVES:1)
Block(-4,50,14,LEAVES:1)
Block(-4,51,9,LEAVES:1)
Block(-4,51,11,LEAVES:1)
Block(-4,51,12,LOG:13)
Block(-4,51,13,LEAVES:1)
Block(-4,52,4,LEAVES:1)
Block(-4,52,12,LEAVES:1)
Block(-4,53,6,LEAVES:1)
Block(-4,53,8,LEAVES:1)
Block(-4,53,9,LEAVES:1)
Block(-4,54,-6,LEAVES:1)
Block(-4,54,-4,LEAVES:1)
Block(-4,54,6,LEAVES:1)
Block(-4,54,7,LOG:13)
Block(-4,54,8,LEAVES:1)
Block(-4,56,0,LEAVES:1)
Block(-4,56,2,LEAVES:1)
Block(-4,57,1,LEAVES:1)
Block(-4,57,2,LOG:13)
Block(-4,57,3,LEAVES:1)
Block(-4,57,4,LEAVES:1)
Block(-4,58,2,LEAVES:1)
Block(-4,58,5,LEAVES:1)
Block(-4,58,6,LEAVES:1)
Block(-4,58,7,LEAVES:1)
Block(-4,58,8,LEAVES:1)
Block(-4,59,7,LEAVES:1)
Block(-4,60,0,LEAVES:1)
Block(-4,60,1,LEAVES:1)
Block(-4,60,2,LEAVES:1)
Block(-4,61,-1,LEAVES:1)
Block(-4,61,0,LOG:13)
Block(-4,61,1,LEAVES:1)
Block(-4,62,0,LEAVES:1)
Block(-3,0,-3,LOG:13)
Block(-3,0,-2,LOG:13)
Block(-3,0,-1,LOG:13)
Block(-3,0,0,LOG:13)
Block(-3,0,1,LOG:13)
Block(-3,0,2,LOG:13)
Block(-3,0,3,LOG:13)
Block(-3,0,4,LOG:13)
Block(-3,0,5,LOG:13)
Block(-3,0,6,LOG:13)
Block(-3,1,-3,LOG:13)
Block(-3,1,-2,LOG:13)
Block(-3,1,-1,LOG:13)
Block(-3,1,0,LOG:13)
Block(-3,1,1,LOG:13)
Block(-3,1,2,LOG:13)
Block(-3,1,3,LOG:13)
Block(-3,1,4,LOG:13)
Block(-3,1,5,LOG:13)
Block(-3,1,6,LOG:13)
Block(-3,2,-2,LOG:13)
Block(-3,2,-1,LOG:13)
Block(-3,2,0,LOG:13)
Block(-3,2,1,LOG:13)
Block(-3,2,2,LOG:13)
Block(-3,2,3,LOG:13)
Block(-3,2,4,LOG:13)
Block(-3,2,5,LOG:13)
Block(-3,3,-2,LOG:13)
Block(-3,3,-1,LOG:13)
Block(-3,3,0,LOG:13)
Block(-3,3,1,LOG:13)
Block(-3,3,2,LOG:13)
Block(-3,3,3,LOG:13)
Block(-3,3,4,LOG:13)
Block(-3,4,-1,LOG:13)
Block(-3,4,0,LOG:13)
Block(-3,4,1,LOG:13)
Block(-3,4,2,LOG:13)
Block(-3,4,3,LOG:13)
Block(-3,4,4,LOG:13)
Block(-3,5,-1,LOG:13)
Block(-3,5,1,LOG:13)
Block(-3,5,2,LOG:13)
Block(-3,5,3,LOG:13)
Block(-3,5,4,LOG:13)
Block(-3,6,0,LOG:13)
Block(-3,6,1,LOG:13)
Block(-3,6,2,LOG:13)
Block(-3,6,3,LOG:13)
Block(-3,6,4,LOG:13)
Block(-3,7,0,LOG:13)
Block(-3,7,1,LOG:13)
Block(-3,7,2,LOG:13)
Block(-3,7,3,LOG:13)
Block(-3,7,4,LOG:13)
Block(-3,8,0,LOG:13)
Block(-3,8,1,LOG:13)
Block(-3,8,2,LOG:13)
Block(-3,8,3,LOG:13)
Block(-3,8,4,LOG:13)
Block(-3,9,1,LOG:13)
Block(-3,9,2,LOG:13)
Block(-3,9,3,LOG:13)
Block(-3,10,1,LOG:13)
Block(-3,10,2,LOG:13)
Block(-3,10,3,LOG:13)
Block(-3,11,1,LOG:13)
Block(-3,11,2,LOG:13)
Block(-3,12,1,LOG:13)
Block(-3,12,2,LOG:13)
Block(-3,13,1,LOG:13)
Block(-3,13,2,LOG:13)
Block(-3,14,1,LOG:13)
Block(-3,14,2,LOG:13)
Block(-3,15,1,LOG:13)
Block(-3,15,2,LOG:13)
Block(-3,16,1,LOG:13)
Block(-3,16,2,LOG:13)
Block(-3,16,3,LEAVES:1)
Block(-3,17,1,LOG:13)
Block(-3,17,2,LOG:13)
Block(-3,17,7,LEAVES:1)
Block(-3,17,8,LEAVES:1)
Block(-3,18,1,LOG:13)
Block(-3,18,2,LOG:13)
Block(-3,18,6,LOG:13)
Block(-3,19,1,LOG:13)
Block(-3,19,2,LOG:13)
Block(-3,19,4,LEAVES:1)
Block(-3,19,5,LEAVES:1)
Block(-3,19,6,LEAVES:1)
Block(-3,20,1,LOG:13)
Block(-3,20,2,LOG:13)
Block(-3,20,3,LEAVES:1)
Block(-3,21,-6,LEAVES:1)
Block(-3,21,-5,LEAVES:1)
Block(-3,21,-2,LEAVES:1)
Block(-3,21,0,LEAVES:1)
Block(-3,21,1,LOG:13)
Block(-3,21,2,LOG:13)
Block(-3,22,-5,LEAVES:1)
Block(-3,22,-4,LEAVES:1)
Block(-3,22,-2,LEAVES:1)
Block(-3,22,0,LEAVES:1)
Block(-3,22,1,LEAVES:1)
Block(-3,22,2,LOG:13)
Block(-3,23,-3,LEAVES:1)
Block(-3,23,-2,LOG:13)
Block(-3,23,0,LEAVES:1)
Block(-3,23,2,LOG:13)
Block(-3,24,-2,LOG:13)
Block(-3,24,-1,LEAVES:1)
Block(-3,24,2,LOG:13)
Block(-3,25,2,LOG:13)
Block(-3,26,2,LOG:13)
Block(-3,30,-11,LEAVES:1)
Block(-3,30,-10,LEAVES:1)
Block(-3,30,2,LEAVES:1)
Block(-3,31,-10,LEAVES:1)
Block(-3,31,-9,LOG:13)
Block(-3,31,-8,LEAVES:1)
Block(-3,31,-6,LEAVES:1)
Block(-3,31,-3,LEAVES:1)
Block(-3,31,3,LEAVES:1)
Block(-3,32,-9,LEAVES:1)
Block(-3,32,-7,LEAVES:1)
Block(-3,32,-6,LEAVES:1)
Block(-3,32,-4,LEAVES:1)
Block(-3,32,5,LEAVES:1)
Block(-3,32,6,LOG:13)
Block(-3,32,7,LEAVES:1)
Block(-3,32,12,LEAVES:1)
Block(-3,33,-6,LEAVES:1)
Block(-3,33,-2,LEAVES:1)
Block(-3,33,-1,LOG:13)
Block(-3,33,1,LEAVES:1)
Block(-3,33,6,LOG:13)
Block(-3,33,7,LEAVES:1)
Block(-3,33,9,LEAVES:1)
Block(-3,34,-5,LEAVES:1)
Block(-3,34,-3,LEAVES:1)
Block(-3,34,-1,LOG:13)
Block(-3,34,0,LEAVES:1)
Block(-3,34,6,LEAVES:1)
Block(-3,34,10,LEAVES:1)
Block(-3,34,15,LEAVES:1)
Block(-3,34,16,LEAVES:1)
Block(-3,34,17,LEAVES:1)
Block(-3,35,8,LEAVES:1)
Block(-3,35,9,LOG:13)
Block(-3,35,10,LOG:13)
Block(-3,35,11,LEAVES:1)
Block(-3,35,12,LEAVES:1)
Block(-3,35,13,LEAVES:1)
Block(-3,35,14,LEAVES:1)
Block(-3,36,-1,LEAVES:1)
Block(-3,36,0,LEAVES:1)
Block(-3,36,9,LEAVES:1)
Block(-3,37,-5,LEAVES:1)
Block(-3,37,0,LEAVES:1)
Block(-3,37,4,LEAVES:1)
Block(-3,38,-5,LEAVES:1)
Block(-3,38,-4,LEAVES:1)
Block(-3,38,1,LEAVES:1)
Block(-3,38,2,LOG:13)
Block(-3,38,3,LEAVES:1)
Block(-3,39,-4,LEAVES:1)
Block(-3,39,-1,LEAVES:1)
Block(-3,39,1,LEAVES:1)
Block(-3,39,2,LEAVES:1)
Block(-3,39,6,LEAVES:1)
Block(-3,39,9,LEAVES:1)
Block(-3,40,-3,LOG:13)
Block(-3,40,-2,LEAVES:1)
Block(-3,40,-1,LEAVES:1)
Block(-3,40,6,LEAVES:1)
Block(-3,40,14,LEAVES:1)
Block(-3,40,15,LEAVES:1)
Block(-3,41,3,LEAVES:1)
Block(-3,41,4,LOG:13)
Block(-3,41,5,LEAVES:1)
Block(-3,41,7,LEAVES:1)
Block(-3,41,8,LOG:13)
Block(-3,41,9,LEAVES:1)
Block(-3,41,13,LEAVES:1)
Block(-3,41,14,LEAVES:1)
Block(-3,42,2,LEAVES:1)
Block(-3,42,4,LEAVES:1)
Block(-3,42,9,LEAVES:1)
Block(-3,42,11,LEAVES:1)
Block(-3,42,12,LOG:13)
Block(-3,42,13,LEAVES:1)
Block(-3,43,-1,LEAVES:1)
Block(-3,43,3,LEAVES:1)
Block(-3,43,4,LEAVES:1)
Block(-3,43,5,LEAVES:1)
Block(-3,43,12,LEAVES:1)
Block(-3,45,0,LEAVES:1)
Block(-3,45,1,LOG:13)
Block(-3,45,6,LEAVES:1)
Block(-3,45,7,LOG:13)
Block(-3,45,8,LEAVES:1)
Block(-3,45,9,LEAVES:1)
Block(-3,45,10,LEAVES:1)
Block(-3,46,5,LEAVES:1)
Block(-3,47,1,LEAVES:1)
Block(-3,47,2,LEAVES:1)
Block(-3,48,-5,LEAVES:1)
Block(-3,48,-4,LEAVES:1)
Block(-3,48,2,LEAVES:1)
Block(-3,48,3,LOG:13)
Block(-3,48,4,LEAVES:1)
Block(-3,49,-3,LEAVES:1)
Block(-3,49,-2,LOG:13)
Block(-3,49,0,LEAVES:1)
Block(-3,49,1,LEAVES:1)
Block(-3,49,3,LEAVES:1)
Block(-3,50,-2,LOG:13)
Block(-3,50,-1,LEAVES:1)
Block(-3,50,12,LEAVES:1)
Block(-3,50,14,LEAVES:1)
Block(-3,51,11,LOG:13)
Block(-3,51,12,LEAVES:1)
Block(-3,52,8,LEAVES:1)
Block(-3,52,10,LEAVES:1)
Block(-3,52,11,LOG:13)
Block(-3,53,5,LEAVES:1)
Block(-3,53,6,LEAVES:1)
Block(-3,53,7,LEAVES:1)
Block(-3,53,8,LEAVES:1)
Block(-3,54,-6,LEAVES:1)
Block(-3,54,-5,LEAVES:1)
Block(-3,54,-4,LEAVES:1)
Block(-3,54,-2,LEAVES:1)
Block(-3,54,6,LEAVES:1)
Block(-3,54,7,LOG:13)
Block(-3,54,8,LEAVES:1)
Block(-3,55,-5,LEAVES:1)
Block(-3,55,-4,LEAVES:1)
Block(-3,55,-1,LEAVES:1)
Block(-3,55,0,LEAVES:1)
Block(-3,55,7,LEAVES:1)
Block(-3,56,0,LEAVES:1)
Block(-3,57,6,LEAVES:1)
Block(-3,58,0,LEAVES:1)
Block(-3,58,1,LEAVES:1)
Block(-3,58,2,LOG:13)
Block(-3,58,3,LEAVES:1)
Block(-3,58,6,LEAVES:1)
Block(-3,58,7,LEAVES:1)
Block(-3,58,9,LEAVES:1)
Block(-3,59,2,LEAVES:1)
Block(-3,59,3,LEAVES:1)
Block(-3,59,5,LEAVES:1)
Block(-3,59,6,LEAVES:1)
Block(-3,59,7,LOG:13)
Block(-3,59,8,LEAVES:1)
Block(-3,60,-2,LEAVES:1)
Block(-3,60,-1,LEAVES:1)
Block(-3,60,0,LEAVES:1)
Block(-3,60,1,LEAVES:1)
Block(-3,60,2,LEAVES:1)
Block(-3,61,1,LEAVES:1)
Block(-3,62,0,LEAVES:1)
Block(-3,62,1,LOG:13)
Block(-3,62,2,LEAVES:1)
Block(-2,0,-4,LOG:13)
Block(-2,0,-3,LOG:13)
Block(-2,0,-2,LOG:13)
Block(-2,0,-1,LOG:13)
Block(-2,0,0,LOG:13)
Block(-2,0,1,LOG:13)
Block(-2,0,2,LOG:13)
Block(-2,0,3,LOG:13)
Block(-2,0,4,LOG:13)
Block(-2,0,5,LOG:13)
Block(-2,0,6,LOG:13)
Block(-2,0,7,LOG:13)
Block(-2,1,-3,LOG:13)
Block(-2,1,-2,LOG:13)
Block(-2,1,-1,LOG:13)
Block(-2,1,0,LOG:13)
Block(-2,1,1,LOG:13)
Block(-2,1,2,LOG:13)
Block(-2,1,3,LOG:13)
Block(-2,1,4,LOG:13)
Block(-2,1,5,LOG:13)
Block(-2,1,6,LOG:13)
Block(-2,2,-3,LOG:13)
Block(-2,2,-2,LOG:13)
Block(-2,2,-1,LOG:13)
Block(-2,2,0,LOG:13)
Block(-2,2,1,LOG:13)
Block(-2,2,2,LOG:13)
Block(-2,2,3,LOG:13)
Block(-2,2,4,LOG:13)
Block(-2,2,5,LOG:13)
Block(-2,2,6,LOG:13)
Block(-2,3,-3,LOG:13)
Block(-2,3,-2,LOG:13)
Block(-2,3,-1,LOG:13)
Block(-2,3,0,LOG:13)
Block(-2,3,1,LOG:13)
Block(-2,3,2,LOG:13)
Block(-2,3,3,LOG:13)
Block(-2,3,4,LOG:13)
Block(-2,3,5,LOG:13)
Block(-2,3,6,LOG:13)
Block(-2,4,-3,LOG:13)
Block(-2,4,-2,LOG:13)
Block(-2,4,-1,LOG:13)
Block(-2,4,0,LOG:13)
Block(-2,4,1,LOG:13)
Block(-2,4,2,LOG:13)
Block(-2,4,3,LOG:13)
Block(-2,4,4,LOG:13)
Block(-2,4,5,LOG:13)
Block(-2,5,-2,LOG:13)
Block(-2,5,-1,LOG:13)
Block(-2,5,0,LOG:13)
Block(-2,5,1,LOG:13)
Block(-2,5,2,LOG:13)
Block(-2,5,3,LOG:13)
Block(-2,5,4,LOG:13)
Block(-2,5,5,LOG:13)
Block(-2,6,-2,LOG:13)
Block(-2,6,-1,LOG:13)
Block(-2,6,0,LOG:13)
Block(-2,6,1,LOG:13)
Block(-2,6,2,LOG:13)
Block(-2,6,3,LOG:13)
Block(-2,6,4,LOG:13)
Block(-2,6,5,LOG:13)
Block(-2,7,-1,LOG:13)
Block(-2,7,0,LOG:13)
Block(-2,7,1,LOG:13)
Block(-2,7,2,LOG:13)
Block(-2,7,3,LOG:13)
Block(-2,7,4,LOG:13)
Block(-2,8,-1,LOG:13)
Block(-2,8,0,LOG:13)
Block(-2,8,1,LOG:13)
Block(-2,8,2,LOG:13)
Block(-2,8,3,LOG:13)
Block(-2,8,4,LOG:13)
Block(-2,9,-1,LOG:13)
Block(-2,9,0,LOG:13)
Block(-2,9,1,LOG:13)
Block(-2,9,2,LOG:13)
Block(-2,9,3,LOG:13)
Block(-2,9,4,LOG:13)
Block(-2,10,-1,LOG:13)
Block(-2,10,0,LOG:13)
Block(-2,10,1,LOG:13)
Block(-2,10,2,LOG:13)
Block(-2,10,3,LOG:13)
Block(-2,10,4,LOG:13)
Block(-2,11,-1,LOG:13)
Block(-2,11,0,LOG:13)
Block(-2,11,1,LOG:13)
Block(-2,11,2,LOG:13)
Block(-2,11,3,LOG:13)
Block(-2,11,4,LOG:13)
Block(-2,12,-1,LOG:13)
Block(-2,12,0,LOG:13)
Block(-2,12,1,LOG:13)
Block(-2,12,2,LOG:13)
Block(-2,12,3,LOG:13)
Block(-2,12,4,LOG:13)
Block(-2,13,-1,LOG:13)
Block(-2,13,0,LOG:13)
Block(-2,13,1,LOG:13)
Block(-2,13,2,LOG:13)
Block(-2,13,3,LOG:13)
Block(-2,13,4,LOG:13)
Block(-2,14,0,LOG:13)
Block(-2,14,1,LOG:13)
Block(-2,14,2,LOG:13)
Block(-2,14,3,LOG:13)
Block(-2,14,4,LOG:13)
Block(-2,15,0,LOG:13)
Block(-2,15,1,LOG:13)
Block(-2,15,2,LOG:13)
Block(-2,15,3,LOG:13)
Block(-2,15,4,LOG:13)
Block(-2,16,0,LOG:13)
Block(-2,16,1,LOG:13)
Block(-2,16,2,LOG:13)
Block(-2,16,3,LOG:13)
Block(-2,16,4,LOG:13)
Block(-2,16,5,LEAVES:1)
Block(-2,17,0,LOG:13)
Block(-2,17,1,LOG:13)
Block(-2,17,2,LOG:13)
Block(-2,17,3,LOG:13)
Block(-2,17,4,LOG:13)
Block(-2,17,7,LEAVES:1)
Block(-2,18,0,LOG:13)
Block(-2,18,1,LOG:13)
Block(-2,18,2,LOG:13)
Block(-2,18,3,LOG:13)
Block(-2,18,4,LOG:13)
Block(-2,18,6,LEAVES:1)
Block(-2,19,0,LOG:13)
Block(-2,19,1,LOG:13)
Block(-2,19,2,LOG:13)
Block(-2,19,3,LOG:13)
Block(-2,19,4,LOG:13)
Block(-2,19,5,LOG:13)
Block(-2,20,0,LOG:13)
Block(-2,20,1,LOG:13)
Block(-2,20,2,LOG:13)
Block(-2,20,3,LOG:13)
Block(-2,20,4,LEAVES:1)
Block(-2,21,-5,LEAVES:1)
Block(-2,21,-3,LEAVES:1)
Block(-2,21,-1,LEAVES:1)
Block(-2,21,0,LOG:13)
Block(-2,21,1,LOG:13)
Block(-2,21,2,LOG:13)
Block(-2,21,3,LOG:13)
Block(-2,22,-3,LEAVES:1)
Block(-2,22,-1,LEAVES:1)
Block(-2,22,0,LOG:13)
Block(-2,22,1,LOG:13)
Block(-2,22,2,LOG:13)
Block(-2,22,3,LOG:13)
Block(-2,22,4,LOG:13)
Block(-2,23,-1,LEAVES:1)
Block(-2,23,0,LOG:13)
Block(-2,23,1,LOG:13)
Block(-2,23,2,LOG:13)
Block(-2,23,3,LOG:13)
Block(-2,23,4,LOG:13)
Block(-2,24,-2,LEAVES:1)
Block(-2,24,-1,LOG:13)
Block(-2,24,0,LOG:13)
Block(-2,24,1,LOG:13)
Block(-2,24,2,LOG:13)
Block(-2,24,3,LOG:13)
Block(-2,24,4,LOG:13)
Block(-2,25,-1,LEAVES:1)
Block(-2,25,0,LOG:13)
Block(-2,25,1,LOG:13)
Block(-2,25,2,LOG:13)
Block(-2,25,3,LOG:13)
Block(-2,25,4,LOG:13)
Block(-2,25,5,LOG:13)
Block(-2,26,0,LOG:13)
Block(-2,26,1,LOG:13)
Block(-2,26,2,LOG:13)
Block(-2,26,3,LOG:13)
Block(-2,27,0,LOG:13)
Block(-2,27,1,LOG:13)
Block(-2,27,2,LOG:13)
Block(-2,27,3,LOG:13)
Block(-2,28,0,LOG:13)
Block(-2,28,1,LOG:13)
Block(-2,28,2,LOG:13)
Block(-2,28,3,LOG:13)
Block(-2,29,0,LOG:13)
Block(-2,29,1,LOG:13)
Block(-2,29,2,LOG:13)
Block(-2,29,3,LOG:13)
Block(-2,30,-5,LEAVES:1)
Block(-2,30,0,LOG:13)
Block(-2,30,1,LOG:13)
Block(-2,30,2,LOG:13)
Block(-2,30,3,LOG:13)
Block(-2,31,-9,LEAVES:1)
Block(-2,31,-8,LEAVES:1)
Block(-2,31,-7,LEAVES:1)
Block(-2,31,-6,LEAVES:1)
Block(-2,31,-5,LEAVES:1)
Block(-2,31,1,LOG:13)
Block(-2,31,2,LOG:13)
Block(-2,31,3,LOG:13)
Block(-2,31,4,LEAVES:1)
Block(-2,31,8,LEAVES:1)
Block(-2,32,-8,LOG:13)
Block(-2,32,-7,LOG:13)
Block(-2,32,-6,LEAVES:1)
Block(-2,32,-5,LEAVES:1)
Block(-2,32,-2,LEAVES:1)
Block(-2,32,1,LOG:13)
Block(-2,32,2,LOG:13)
Block(-2,32,3,LOG:13)
Block(-2,32,8,LEAVES:1)
Block(-2,32,9,LEAVES:1)
Block(-2,33,-7,LEAVES:1)
Block(-2,33,-6,LOG:13)
Block(-2,33,-5,LEAVES:1)
Block(-2,33,1,LOG:13)
Block(-2,33,2,LOG:13)
Block(-2,33,3,LOG:13)
Block(-2,33,6,LEAVES:1)
Block(-2,33,7,LOG:13)
Block(-2,33,8,LEAVES:1)
Block(-2,33,10,LEAVES:1)
Block(-2,33,11,LEAVES:1)
Block(-2,33,18,LEAVES:1)
Block(-2,34,-5,LOG:13)
Block(-2,34,-4,LEAVES:1)
Block(-2,34,-1,LEAVES:1)
Block(-2,34,0,LOG:13)
Block(-2,34,1,LOG:13)
Block(-2,34,2,LOG:13)
Block(-2,34,3,LOG:13)
Block(-2,34,17,LEAVES:1)
Block(-2,35,-2,LEAVES:1)
Block(-2,35,0,LEAVES:1)
Block(-2,35,1,LOG:13)
Block(-2,35,2,LOG:13)
Block(-2,35,3,LOG:13)
Block(-2,35,15,LEAVES:1)
Block(-2,35,16,LEAVES:1)
Block(-2,36,1,LOG:13)
Block(-2,36,2,LOG:13)
Block(-2,36,3,LOG:13)
Block(-2,36,4,LEAVES:1)
Block(-2,36,8,LEAVES:1)
Block(-2,36,9,LOG:13)
Block(-2,36,11,LEAVES:1)
Block(-2,36,12,LEAVES:1)
Block(-2,36,13,LEAVES:1)
Block(-2,36,14,LEAVES:1)
Block(-2,37,1,LOG:13)
Block(-2,37,2,LOG:13)
Block(-2,37,3,LEAVES:1)
Block(-2,37,9,LEAVES:1)
Block(-2,37,10,LEAVES:1)
Block(-2,38,-6,LEAVES:1)
Block(-2,38,-5,LEAVES:1)
Block(-2,38,-4,LEAVES:1)
Block(-2,38,-2,LEAVES:1)
Block(-2,38,0,LEAVES:1)
Block(-2,38,1,LOG:13)
Block(-2,38,2,LOG:13)
Block(-2,38,8,LEAVES:1)
Block(-2,39,-5,LEAVES:1)
Block(-2,39,1,LOG:13)
Block(-2,39,2,LOG:13)
Block(-2,40,-3,LEAVES:1)
Block(-2,40,-2,LOG:13)
Block(-2,40,0,LEAVES:1)
Block(-2,40,1,LOG:13)
Block(-2,40,2,LOG:13)
Block(-2,40,6,LEAVES:1)
Block(-2,40,8,LEAVES:1)
Block(-2,40,10,LEAVES:1)
Block(-2,40,13,LEAVES:1)
Block(-2,40,14,LEAVES:1)
Block(-2,41,-2,LOG:13)
Block(-2,41,-1,LEAVES:1)
Block(-2,41,1,LOG:13)
Block(-2,41,2,LOG:13)
Block(-2,41,3,LEAVES:1)
Block(-2,41,8,LOG:13)
Block(-2,41,9,LEAVES:1)
Block(-2,41,12,LEAVES:1)
Block(-2,41,13,LEAVES:1)
Block(-2,42,1,LOG:13)
Block(-2,42,2,LOG:13)
Block(-2,42,3,LOG:13)
Block(-2,42,4,LEAVES:1)
Block(-2,42,8,LEAVES:1)
Block(-2,42,11,LOG:13)
Block(-2,42,12,LEAVES:1)
Block(-2,43,1,LOG:13)
Block(-2,43,2,LOG:13)
Block(-2,43,10,LEAVES:1)
Block(-2,43,11,LOG:13)
Block(-2,44,2,LOG:13)
Block(-2,44,3,LEAVES:1)
Block(-2,44,6,LEAVES:1)
Block(-2,44,7,LEAVES:1)
Block(-2,44,8,LEAVES:1)
Block(-2,45,1,LOG:13)
Block(-2,45,2,LOG:13)
Block(-2,45,7,LEAVES:1)
Block(-2,45,8,LOG:13)
Block(-2,45,9,LEAVES:1)
Block(-2,46,-3,LEAVES:1)
Block(-2,46,-1,LEAVES:1)
Block(-2,46,1,LOG:13)
Block(-2,46,2,LOG:13)
Block(-2,46,7,LEAVES:1)
Block(-2,46,8,LOG:13)
Block(-2,46,9,LEAVES:1)
Block(-2,47,2,LOG:13)
Block(-2,47,5,LEAVES:1)
Block(-2,47,6,LEAVES:1)
Block(-2,47,8,LEAVES:1)
Block(-2,48,-4,LEAVES:1)
Block(-2,48,-3,LEAVES:1)
Block(-2,48,-2,LEAVES:1)
Block(-2,48,1,LEAVES:1)
Block(-2,48,2,LOG:13)
Block(-2,48,3,LEAVES:1)
Block(-2,48,9,LEAVES:1)
Block(-2,48,11,LEAVES:1)
Block(-2,49,2,LOG:13)
Block(-2,49,3,LOG:13)
Block(-2,49,4,LEAVES:1)
Block(-2,50,-2,LEAVES:1)
Block(-2,50,-1,LOG:13)
Block(-2,50,0,LEAVES:1)
Block(-2,50,2,LEAVES:1)
Block(-2,50,12,LEAVES:1)
Block(-2,51,-1,LEAVES:1)
Block(-2,51,0,LEAVES:1)
Block(-2,51,8,LEAVES:1)
Block(-2,51,11,LEAVES:1)
Block(-2,52,9,LEAVES:1)
Block(-2,52,10,LOG:13)
Block(-2,53,-3,LEAVES:1)
Block(-2,53,8,LEAVES:1)
Block(-2,53,10,LEAVES:1)
Block(-2,54,-7,LEAVES:1)
Block(-2,54,-6,LEAVES:1)
Block(-2,54,-5,LEAVES:1)
Block(-2,54,-4,LEAVES:1)
Block(-2,54,-3,LEAVES:1)
Block(-2,54,-2,LEAVES:1)
Block(-2,54,6,LEAVES:1)
Block(-2,55,-6,LEAVES:1)
Block(-2,55,-5,LOG:13)
Block(-2,55,-4,LOG:13)
Block(-2,55,-3,LEAVES:1)
Block(-2,55,-2,LEAVES:1)
Block(-2,55,7,LEAVES:1)
Block(-2,55,8,LOG:13)
Block(-2,56,-4,LEAVES:1)
Block(-2,56,-2,LEAVES:1)
Block(-2,56,0,LEAVES:1)
Block(-2,57,2,LEAVES:1)
Block(-2,57,4,LEAVES:1)
Block(-2,57,9,LEAVES:1)
Block(-2,57,10,LEAVES:1)
Block(-2,57,11,LEAVES:1)
Block(-2,58,1,LEAVES:1)
Block(-2,58,4,LEAVES:1)
Block(-2,58,5,LEAVES:1)
Block(-2,58,9,LEAVES:1)
Block(-2,59,1,LEAVES:1)
Block(-2,59,2,LOG:13)
Block(-2,59,4,LEAVES:1)
Block(-2,59,5,LEAVES:1)
Block(-2,59,6,LOG:13)
Block(-2,59,7,LEAVES:1)
Block(-2,60,0,LEAVES:1)
Block(-2,60,1,LEAVES:1)
Block(-2,60,2,LEAVES:1)
Block(-2,60,4,LEAVES:1)
Block(-2,60,5,LEAVES:1)
Block(-2,60,9,LEAVES:1)
Block(-2,61,9,LEAVES:1)
Block(-2,62,1,LOG:13)
Block(-2,63,1,LEAVES:1)
Block(-2,63,2,LEAVES:1)
Block(-2,63,3,LEAVES:1)
Block(-2,63,4,LEAVES:1)
Block(-2,63,5,LEAVES:1)
Block(-2,64,2,LEAVES:1)
Block(-2,66,3,LEAVES:1)
Block(-2,66,4,LEAVES:1)
Block(-1,0,-5,LOG:13)
Block(-1,0,-4,LOG:13)
Block(-1,0,-3,LOG:13)
Block(-1,0,-2,LOG:13)
Block(-1,0,-1,LOG:13)
Block(-1,0,0,LOG:13)
Block(-1,0,1,LOG:13)
Block(-1,0,2,LOG:13)
Block(-1,0,3,LOG:13)
Block(-1,0,4,LOG:13)
Block(-1,0,5,LOG:13)
Block(-1,0,6,LOG:13)
Block(-1,0,7,LOG:13)
Block(-1,1,-4,LOG:13)
Block(-1,1,-3,LOG:13)
Block(-1,1,-2,LOG:13)
Block(-1,1,-1,LOG:13)
Block(-1,1,0,LOG:13)
Block(-1,1,1,LOG:13)
Block(-1,1,2,LOG:13)
Block(-1,1,3,LOG:13)
Block(-1,1,4,LOG:13)
Block(-1,1,5,LOG:13)
Block(-1,1,6,LOG:13)
Block(-1,1,7,LOG:13)
Block(-1,2,-4,LOG:13)
Block(-1,2,-3,LOG:13)
Block(-1,2,-2,LOG:13)
Block(-1,2,-1,LOG:13)
Block(-1,2,0,LOG:13)
Block(-1,2,1,LOG:13)
Block(-1,2,2,LOG:13)
Block(-1,2,3,LOG:13)
Block(-1,2,4,LOG:13)
Block(-1,2,5,LOG:13)
Block(-1,2,6,LOG:13)
Block(-1,3,-3,LOG:13)
Block(-1,3,-2,LOG:13)
Block(-1,3,-1,LOG:13)
Block(-1,3,0,LOG:13)
Block(-1,3,1,LOG:13)
Block(-1,3,2,LOG:13)
Block(-1,3,3,LOG:13)
Block(-1,3,4,LOG:13)
Block(-1,3,5,LOG:13)
Block(-1,3,6,LOG:13)
Block(-1,4,-2,LOG:13)
Block(-1,4,-1,LOG:13)
Block(-1,4,0,LOG:13)
Block(-1,4,1,LOG:13)
Block(-1,4,2,LOG:13)
Block(-1,4,3,LOG:13)
Block(-1,4,4,LOG:13)
Block(-1,4,5,LOG:13)
Block(-1,4,6,LOG:13)
Block(-1,5,-2,LOG:13)
Block(-1,5,-1,LOG:13)
Block(-1,5,0,LOG:13)
Block(-1,5,1,LOG:13)
Block(-1,5,2,LOG:13)
Block(-1,5,3,LOG:13)
Block(-1,5,4,LOG:13)
Block(-1,5,5,LOG:13)
Block(-1,6,-2,LOG:13)
Block(-1,6,-1,LOG:13)
Block(-1,6,0,LOG:13)
Block(-1,6,1,LOG:13)
Block(-1,6,2,LOG:13)
Block(-1,6,3,LOG:13)
Block(-1,6,4,LOG:13)
Block(-1,6,5,LOG:13)
Block(-1,7,-2,LOG:13)
Block(-1,7,-1,LOG:13)
Block(-1,7,0,LOG:13)
Block(-1,7,1,LOG:13)
Block(-1,7,2,LOG:13)
Block(-1,7,3,LOG:13)
Block(-1,7,4,LOG:13)
Block(-1,7,5,LOG:13)
Block(-1,8,-2,LOG:13)
Block(-1,8,-1,LOG:13)
Block(-1,8,0,LOG:13)
Block(-1,8,1,LOG:13)
Block(-1,8,2,LOG:13)
Block(-1,8,3,LOG:13)
Block(-1,8,4,LOG:13)
Block(-1,8,5,LOG:13)
Block(-1,9,-2,LOG:13)
Block(-1,9,-1,LOG:13)
Block(-1,9,0,LOG:13)
Block(-1,9,1,LOG:13)
Block(-1,9,2,LOG:13)
Block(-1,9,3,LOG:13)
Block(-1,9,4,LOG:13)
Block(-1,9,5,LOG:13)
Block(-1,10,-1,LOG:13)
Block(-1,10,0,LOG:13)
Block(-1,10,1,LOG:13)
Block(-1,10,2,LOG:13)
Block(-1,10,3,LOG:13)
Block(-1,10,4,LOG:13)
Block(-1,10,5,LOG:13)
Block(-1,11,-1,LOG:13)
Block(-1,11,0,LOG:13)
Block(-1,11,1,LOG:13)
Block(-1,11,2,LOG:13)
Block(-1,11,3,LOG:13)
Block(-1,11,4,LOG:13)
Block(-1,11,5,LOG:13)
Block(-1,12,-1,LOG:13)
Block(-1,12,0,LOG:13)
Block(-1,12,1,LOG:13)
Block(-1,12,2,LOG:13)
Block(-1,12,3,LOG:13)
Block(-1,12,4,LOG:13)
Block(-1,12,5,LOG:13)
Block(-1,13,-1,LOG:13)
Block(-1,13,0,LOG:13)
Block(-1,13,1,LOG:13)
Block(-1,13,2,LOG:13)
Block(-1,13,3,LOG:13)
Block(-1,13,4,LOG:13)
Block(-1,14,-1,LOG:13)
Block(-1,14,0,LOG:13)
Block(-1,14,1,LOG:13)
Block(-1,14,2,LOG:13)
Block(-1,14,3,LOG:13)
Block(-1,14,4,LOG:13)
Block(-1,15,-1,LOG:13)
Block(-1,15,0,LOG:13)
Block(-1,15,1,LOG:13)
Block(-1,15,2,LOG:13)
Block(-1,15,3,LOG:13)
Block(-1,15,4,LOG:13)
Block(-1,16,-1,LOG:13)
Block(-1,16,0,LOG:13)
Block(-1,16,1,LOG:13)
Block(-1,16,2,LOG:13)
Block(-1,16,3,LOG:13)
Block(-1,16,4,LOG:13)
Block(-1,17,-1,LOG:13)
Block(-1,17,0,LOG:13)
Block(-1,17,1,LOG:13)
Block(-1,17,2,LOG:13)
Block(-1,17,3,LOG:13)
Block(-1,17,4,LOG:13)
Block(-1,17,5,LEAVES:1)
Block(-1,18,-1,LOG:13)
Block(-1,18,0,LOG:13)
Block(-1,18,1,LOG:13)
Block(-1,18,2,LOG:13)
Block(-1,18,3,LOG:13)
Block(-1,18,4,LOG:13)
Block(-1,19,-1,LOG:13)
Block(-1,19,0,LOG:13)
Block(-1,19,1,LOG:13)
Block(-1,19,2,LOG:13)
Block(-1,19,3,LOG:13)
Block(-1,19,4,LOG:13)
Block(-1,19,5,LEAVES:1)
Block(-1,20,-1,LOG:13)
Block(-1,20,0,LOG:13)
Block(-1,20,1,LOG:13)
Block(-1,20,2,LOG:13)
Block(-1,20,3,LOG:13)
Block(-1,20,4,LOG:13)
Block(-1,21,-3,LEAVES:1)
Block(-1,21,-1,LOG:13)
Block(-1,21,0,LOG:13)
Block(-1,21,1,LOG:13)
Block(-1,21,2,LOG:13)
Block(-1,21,3,LOG:13)
Block(-1,21,4,LOG:13)
Block(-1,22,-1,LOG:13)
Block(-1,22,0,LOG:13)
Block(-1,22,1,LOG:13)
Block(-1,22,2,LOG:13)
Block(-1,22,3,LOG:13)
Block(-1,22,4,LOG:13)
Block(-1,23,-2,LEAVES:1)
Block(-1,23,-1,LOG:13)
Block(-1,23,0,LOG:13)
Block(-1,23,1,LOG:13)
Block(-1,23,2,LOG:13)
Block(-1,23,3,LOG:13)
Block(-1,23,4,LOG:13)
Block(-1,23,5,LOG:13)
Block(-1,24,-1,LOG:13)
Block(-1,24,0,LOG:13)
Block(-1,24,1,LOG:13)
Block(-1,24,2,LOG:13)
Block(-1,24,3,LOG:13)
Block(-1,24,4,LOG:13)
Block(-1,24,5,LOG:13)
Block(-1,25,-1,LOG:13)
Block(-1,25,0,LOG:13)
Block(-1,25,1,LOG:13)
Block(-1,25,2,LOG:13)
Block(-1,25,3,LOG:13)
Block(-1,25,4,LOG:13)
Block(-1,25,5,LOG:13)
Block(-1,25,6,LOG:13)
Block(-1,26,-1,LOG:13)
Block(-1,26,0,LOG:13)
Block(-1,26,1,LOG:13)
Block(-1,26,2,LOG:13)
Block(-1,26,3,LOG:13)
Block(-1,26,4,LOG:13)
Block(-1,26,5,LOG:13)
Block(-1,26,6,LOG:13)
Block(-1,27,0,LOG:13)
Block(-1,27,1,LOG:13)
Block(-1,27,2,LOG:13)
Block(-1,27,3,LOG:13)
Block(-1,27,4,LOG:13)
Block(-1,27,5,LOG:13)
Block(-1,27,7,LOG:13)
Block(-1,28,0,LOG:13)
Block(-1,28,1,LOG:13)
Block(-1,28,2,LOG:13)
Block(-1,28,3,LOG:13)
Block(-1,28,4,LOG:13)
Block(-1,28,7,LOG:13)
Block(-1,28,8,LOG:13)
Block(-1,29,0,LOG:13)
Block(-1,29,1,LOG:13)
Block(-1,29,2,LOG:13)
Block(-1,29,3,LOG:13)
Block(-1,29,4,LOG:13)
Block(-1,29,7,LOG:13)
Block(-1,29,8,LOG:13)
Block(-1,30,-10,LEAVES:1)
Block(-1,30,-9,LEAVES:1)
Block(-1,30,0,LOG:13)
Block(-1,30,1,LOG:13)
Block(-1,30,2,LOG:13)
Block(-1,30,3,LOG:13)
Block(-1,30,4,LOG:13)
Block(-1,30,7,LOG:13)
Block(-1,30,8,LOG:13)
Block(-1,31,-9,LEAVES:1)
Block(-1,31,-7,LEAVES:1)
Block(-1,31,0,LOG:13)
Block(-1,31,1,LOG:13)
Block(-1,31,2,LOG:13)
Block(-1,31,3,LOG:13)
Block(-1,31,4,LOG:13)
Block(-1,31,7,LOG:13)
Block(-1,31,8,LOG:13)
Block(-1,31,9,LOG:13)
Block(-1,32,-8,LEAVES:1)
Block(-1,32,-7,LEAVES:1)
Block(-1,32,0,LOG:13)
Block(-1,32,1,LOG:13)
Block(-1,32,2,LOG:13)
Block(-1,32,3,LOG:13)
Block(-1,32,4,LOG:13)
Block(-1,32,5,LEAVES:1)
Block(-1,32,7,LOG:13)
Block(-1,32,8,LOG:13)
Block(-1,32,9,LOG:13)
Block(-1,32,10,LEAVES:1)
Block(-1,33,-6,LEAVES:1)
Block(-1,33,-2,LEAVES:1)
Block(-1,33,-1,LEAVES:1)
Block(-1,33,0,LOG:13)
Block(-1,33,1,LOG:13)
Block(-1,33,2,LOG:13)
Block(-1,33,3,LOG:13)
Block(-1,33,4,LOG:13)
Block(-1,33,7,LOG:13)
Block(-1,33,8,LOG:13)
Block(-1,33,9,LOG:13)
Block(-1,33,10,LEAVES:1)
Block(-1,33,18,LEAVES:1)
Block(-1,33,19,LEAVES:1)
Block(-1,34,-5,LEAVES:1)
Block(-1,34,-4,LOG:13)
Block(-1,34,-3,LEAVES:1)
Block(-1,34,0,LOG:13)
Block(-1,34,1,LOG:13)
Block(-1,34,2,LOG:13)
Block(-1,34,3,LOG:13)
Block(-1,34,4,LOG:13)
Block(-1,34,7,LEAVES:1)
Block(-1,34,8,LOG:13)
Block(-1,34,9,LOG:13)
Block(-1,34,10,LEAVES:1)
Block(-1,34,15,LEAVES:1)
Block(-1,34,17,LEAVES:1)
Block(-1,34,18,LEAVES:1)
Block(-1,35,-3,LOG:13)
Block(-1,35,-2,LOG:13)
Block(-1,35,0,LOG:13)
Block(-1,35,1,LOG:13)
Block(-1,35,2,LOG:13)
Block(-1,35,3,LOG:13)
Block(-1,35,4,LOG:13)
Block(-1,35,8,LOG:13)
Block(-1,35,9,LOG:13)
Block(-1,35,13,LEAVES:1)
Block(-1,35,15,LOG:13)
Block(-1,35,16,LOG:13)
Block(-1,36,-2,LEAVES:1)
Block(-1,36,-1,LOG:13)
Block(-1,36,0,LOG:13)
Block(-1,36,1,LOG:13)
Block(-1,36,2,LOG:13)
Block(-1,36,3,LOG:13)
Block(-1,36,4,LOG:13)
Block(-1,36,8,LOG:13)
Block(-1,36,9,LOG:13)
Block(-1,36,10,LEAVES:1)
Block(-1,36,13,LOG:13)
Block(-1,36,14,LOG:13)
Block(-1,36,15,LEAVES:1)
Block(-1,37,-4,LEAVES:1)
Block(-1,37,0,LOG:13)
Block(-1,37,1,LOG:13)
Block(-1,37,2,LOG:13)
Block(-1,37,3,LOG:13)
Block(-1,37,4,LOG:13)
Block(-1,37,8,LOG:13)
Block(-1,37,9,LOG:13)
Block(-1,37,11,LEAVES:1)
Block(-1,37,12,LEAVES:1)
Block(-1,38,-1,LEAVES:1)
Block(-1,38,0,LOG:13)
Block(-1,38,1,LOG:13)
Block(-1,38,2,LOG:13)
Block(-1,38,3,LOG:13)
Block(-1,38,4,LOG:13)
Block(-1,38,8,LOG:13)
Block(-1,38,9,LOG:13)
Block(-1,38,10,LEAVES:1)
Block(-1,39,-3,LEAVES:1)
Block(-1,39,0,LOG:13)
Block(-1,39,1,LOG:13)
Block(-1,39,2,LOG:13)
Block(-1,39,3,LOG:13)
Block(-1,39,8,LOG:13)
Block(-1,39,9,LOG:13)
Block(-1,39,10,LEAVES:1)
Block(-1,40,0,LOG:13)
Block(-1,40,1,LOG:13)
Block(-1,40,2,LOG:13)
Block(-1,40,3,LOG:13)
Block(-1,40,4,LEAVES:1)
Block(-1,40,7,LEAVES:1)
Block(-1,40,8,LOG:13)
Block(-1,40,9,LOG:13)
Block(-1,40,13,LEAVES:1)
Block(-1,41,-2,LEAVES:1)
Block(-1,41,-1,LOG:13)
Block(-1,41,0,LOG:13)
Block(-1,41,1,LOG:13)
Block(-1,41,2,LOG:13)
Block(-1,41,3,LOG:13)
Block(-1,41,7,LEAVES:1)
Block(-1,41,8,LOG:13)
Block(-1,41,9,LOG:13)
Block(-1,41,12,LEAVES:1)
Block(-1,42,0,LEAVES:1)
Block(-1,42,1,LOG:13)
Block(-1,42,2,LOG:13)
Block(-1,42,3,LOG:13)
Block(-1,42,6,LEAVES:1)
Block(-1,42,8,LOG:13)
Block(-1,42,9,LOG:13)
Block(-1,42,10,LEAVES:1)
Block(-1,42,11,LEAVES:1)
Block(-1,42,12,LEAVES:1)
Block(-1,43,0,LEAVES:1)
Block(-1,43,1,LOG:13)
Block(-1,43,2,LOG:13)
Block(-1,43,3,LOG:13)
Block(-1,43,7,LEAVES:1)
Block(-1,43,8,LOG:13)
Block(-1,43,9,LOG:13)
Block(-1,43,10,LOG:13)
Block(-1,43,11,LEAVES:1)
Block(-1,44,-7,LEAVES:1)
Block(-1,44,-5,LEAVES:1)
Block(-1,44,1,LOG:13)
Block(-1,44,2,LOG:13)
Block(-1,44,3,LOG:13)
Block(-1,44,8,LOG:13)
Block(-1,44,9,LOG:13)
Block(-1,44,10,LEAVES:1)
Block(-1,45,-4,LEAVES:1)
Block(-1,45,-2,LEAVES:1)
Block(-1,45,0,LEAVES:1)
Block(-1,45,1,LOG:13)
Block(-1,45,2,LOG:13)
Block(-1,45,3,LOG:13)
Block(-1,45,7,LEAVES:1)
Block(-1,45,8,LOG:13)
Block(-1,45,9,LEAVES:1)
Block(-1,46,-3,LEAVES:1)
Block(-1,46,-2,LEAVES:1)
Block(-1,46,-1,LEAVES:1)
Block(-1,46,0,LEAVES:1)
Block(-1,46,1,LOG:13)
Block(-1,46,2,LOG:13)
Block(-1,46,3,LOG:13)
Block(-1,46,8,LOG:13)
Block(-1,47,-2,LEAVES:1)
Block(-1,47,1,LOG:13)
Block(-1,47,2,LOG:13)
Block(-1,47,3,LOG:13)
Block(-1,47,8,LOG:13)
Block(-1,47,10,LEAVES:1)
Block(-1,47,12,LEAVES:1)
Block(-1,48,-2,LEAVES:1)
Block(-1,48,1,LOG:13)
Block(-1,48,2,LOG:13)
Block(-1,48,3,LOG:13)
Block(-1,48,5,LEAVES:1)
Block(-1,48,7,LEAVES:1)
Block(-1,48,8,LOG:13)
Block(-1,48,10,LEAVES:1)
Block(-1,48,11,LEAVES:1)
Block(-1,49,-2,LEAVES:1)
Block(-1,49,1,LOG:13)
Block(-1,49,2,LOG:13)
Block(-1,49,3,LOG:13)
Block(-1,49,8,LOG:13)
Block(-1,49,9,LEAVES:1)
Block(-1,49,10,LEAVES:1)
Block(-1,50,0,LOG:13)
Block(-1,50,1,LOG:13)
Block(-1,50,2,LOG:13)
Block(-1,50,3,LOG:13)
Block(-1,50,8,LOG:13)
Block(-1,51,-1,LEAVES:1)
Block(-1,51,0,LOG:13)
Block(-1,51,1,LOG:13)
Block(-1,51,2,LOG:13)
Block(-1,51,3,LOG:13)
Block(-1,51,7,LEAVES:1)
Block(-1,51,8,LOG:13)
Block(-1,51,9,LEAVES:1)
Block(-1,51,10,LEAVES:1)
Block(-1,51,11,LEAVES:1)
Block(-1,52,0,LEAVES:1)
Block(-1,52,1,LOG:13)
Block(-1,52,2,LOG:13)
Block(-1,52,3,LOG:13)
Block(-1,52,6,LEAVES:1)
Block(-1,52,8,LOG:13)
Block(-1,52,9,LOG:13)
Block(-1,52,10,LEAVES:1)
Block(-1,53,-4,LEAVES:1)
Block(-1,53,1,LOG:13)
Block(-1,53,2,LOG:13)
Block(-1,53,6,LEAVES:1)
Block(-1,53,8,LOG:13)
Block(-1,53,9,LOG:13)
Block(-1,53,10,LEAVES:1)
Block(-1,53,11,LEAVES:1)
Block(-1,54,-6,LEAVES:1)
Block(-1,54,-5,LEAVES:1)
Block(-1,54,-4,LEAVES:1)
Block(-1,54,1,LOG:13)
Block(-1,54,2,LOG:13)
Block(-1,54,7,LEAVES:1)
Block(-1,54,8,LOG:13)
Block(-1,55,-5,LEAVES:1)
Block(-1,55,-4,LEAVES:1)
Block(-1,55,1,LEAVES:1)
Block(-1,55,2,LOG:13)
Block(-1,55,8,LOG:13)
Block(-1,55,9,LEAVES:1)
Block(-1,56,-3,LOG:13)
Block(-1,56,-2,LOG:13)
Block(-1,56,2,LOG:13)
Block(-1,56,3,LEAVES:1)
Block(-1,56,8,LEAVES:1)
Block(-1,57,-2,LEAVES:1)
Block(-1,57,-1,LEAVES:1)
Block(-1,57,0,LEAVES:1)
Block(-1,57,2,LOG:13)
Block(-1,57,10,LEAVES:1)
Block(-1,58,1,LEAVES:1)
Block(-1,58,2,LOG:13)
Block(-1,58,3,LEAVES:1)
Block(-1,58,8,LEAVES:1)
Block(-1,58,9,LEAVES:1)
Block(-1,58,10,LEAVES:1)
Block(-1,59,2,LOG:13)
Block(-1,59,5,LEAVES:1)
Block(-1,59,9,LEAVES:1)
Block(-1,60,-3,LEAVES:1)
Block(-1,60,4,LOG:13)
Block(-1,60,5,LOG:13)
Block(-1,60,6,LEAVES:1)
Block(-1,60,8,LEAVES:1)
Block(-1,60,9,LEAVES:1)
Block(-1,60,10,LEAVES:1)
Block(-1,61,-1,LEAVES:1)
Block(-1,61,3,LEAVES:1)
Block(-1,61,4,LEAVES:1)
Block(-1,62,0,LEAVES:1)
Block(-1,62,2,LEAVES:1)
Block(-1,62,8,LEAVES:1)
Block(-1,63,2,LOG:13)
Block(-1,63,3,LEAVES:1)
Block(-1,63,4,LEAVES:1)
Block(-1,64,4,LEAVES:1)
Block(-1,65,1,LEAVES:1)
Block(-1,65,2,LEAVES:1)
Block(-1,65,3,LEAVES:1)
Block(-1,66,2,LEAVES:1)
Block(-1,66,3,LEAVES:1)
Block(-1,67,3,LEAVES:1)
Block(0,0,-5,LOG:13)
Block(0,0,-4,LOG:13)
Block(0,0,-3,LOG:13)
Block(0,0,-2,LOG:13)
Block(0,0,-1,LOG:13)
Block(0,0,0,LOG:13)
Block(0,0,1,LOG:13)
Block(0,0,2,LOG:13)
Block(0,0,3,LOG:13)
Block(0,0,4,LOG:13)
Block(0,0,5,LOG:13)
Block(0,0,6,LOG:13)
Block(0,0,7,LOG:13)
Block(0,1,-4,LOG:13)
Block(0,1,-3,LOG:13)
Block(0,1,-2,LOG:13)
Block(0,1,-1,LOG:13)
Block(0,1,0,LOG:13)
Block(0,1,1,LOG:13)
Block(0,1,2,LOG:13)
Block(0,1,3,LOG:13)
Block(0,1,4,LOG:13)
Block(0,1,5,LOG:13)
Block(0,1,6,LOG:13)
Block(0,1,7,LOG:13)
Block(0,2,-3,LOG:13)
Block(0,2,-2,LOG:13)
Block(0,2,-1,LOG:13)
Block(0,2,0,LOG:13)
Block(0,2,1,LOG:13)
Block(0,2,2,LOG:13)
Block(0,2,3,LOG:13)
Block(0,2,4,LOG:13)
Block(0,2,5,LOG:13)
Block(0,2,6,LOG:13)
Block(0,2,7,LOG:13)
Block(0,3,-3,LOG:13)
Block(0,3,-2,LOG:13)
Block(0,3,-1,LOG:13)
Block(0,3,0,LOG:13)
Block(0,3,1,LOG:13)
Block(0,3,2,LOG:13)
Block(0,3,3,LOG:13)
Block(0,3,4,LOG:13)
Block(0,3,5,LOG:13)
Block(0,3,6,LOG:13)
Block(0,4,-3,LOG:13)
Block(0,4,-2,LOG:13)
Block(0,4,-1,LOG:13)
Block(0,4,0,LOG:13)
Block(0,4,1,LOG:13)
Block(0,4,2,LOG:13)
Block(0,4,3,LOG:13)
Block(0,4,4,LOG:13)
Block(0,4,5,LOG:13)
Block(0,4,6,LOG:13)
Block(0,5,-2,LOG:13)
Block(0,5,-1,LOG:13)
Block(0,5,0,LOG:13)
Block(0,5,1,LOG:13)
Block(0,5,2,LOG:13)
Block(0,5,3,LOG:13)
Block(0,5,4,LOG:13)
Block(0,5,5,LOG:13)
Block(0,5,6,LOG:13)
Block(0,6,-2,LOG:13)
Block(0,6,-1,LOG:13)
Block(0,6,0,LOG:13)
Block(0,6,1,LOG:13)
Block(0,6,2,LOG:13)
Block(0,6,3,LOG:13)
Block(0,6,4,LOG:13)
Block(0,6,5,LOG:13)
Block(0,6,6,LOG:13)
Block(0,7,-2,LOG:13)
Block(0,7,-1,LOG:13)
Block(0,7,0,LOG:13)
Block(0,7,1,LOG:13)
Block(0,7,2,LOG:13)
Block(0,7,3,LOG:13)
Block(0,7,4,LOG:13)
Block(0,7,5,LOG:13)
Block(0,8,-1,LOG:13)
Block(0,8,0,LOG:13)
Block(0,8,1,LOG:13)
Block(0,8,2,LOG:13)
Block(0,8,3,LOG:13)
Block(0,8,4,LOG:13)
Block(0,8,5,LOG:13)
Block(0,9,-1,LOG:13)
Block(0,9,0,LOG:13)
Block(0,9,1,LOG:13)
Block(0,9,2,LOG:13)
Block(0,9,3,LOG:13)
Block(0,9,4,LOG:13)
Block(0,9,5,LOG:13)
Block(0,10,-1,LOG:13)
Block(0,10,0,LOG:13)
Block(0,10,1,LOG:13)
Block(0,10,2,LOG:13)
Block(0,10,3,LOG:13)
Block(0,10,4,LOG:13)
Block(0,10,5,LOG:13)
Block(0,11,-1,LOG:13)
Block(0,11,0,LOG:13)
Block(0,11,1,LOG:13)
Block(0,11,2,LOG:13)
Block(0,11,3,LOG:13)
Block(0,11,4,LOG:13)
Block(0,11,5,LOG:13)
Block(0,12,-1,LOG:13)
Block(0,12,0,LOG:13)
Block(0,12,1,LOG:13)
Block(0,12,2,LOG:13)
Block(0,12,3,LOG:13)
Block(0,12,4,LOG:13)
Block(0,12,5,LOG:13)
Block(0,13,-1,LOG:13)
Block(0,13,0,LOG:13)
Block(0,13,1,LOG:13)
Block(0,13,2,LOG:13)
Block(0,13,3,LOG:13)
Block(0,13,4,LOG:13)
Block(0,13,5,LOG:13)
Block(0,14,-1,LOG:13)
Block(0,14,0,LOG:13)
Block(0,14,1,LOG:13)
Block(0,14,2,LOG:13)
Block(0,14,3,LOG:13)
Block(0,14,4,LOG:13)
Block(0,14,5,LOG:13)
Block(0,15,-1,LOG:13)
Block(0,15,0,LOG:13)
Block(0,15,1,LOG:13)
Block(0,15,2,LOG:13)
Block(0,15,3,LOG:13)
Block(0,15,4,LOG:13)
Block(0,15,5,LOG:13)
Block(0,16,-1,LOG:13)
Block(0,16,0,LOG:13)
Block(0,16,1,LOG:13)
Block(0,16,2,LOG:13)
Block(0,16,3,LOG:13)
Block(0,16,4,LOG:13)
Block(0,16,5,LOG:13)
Block(0,17,-1,LOG:13)
Block(0,17,0,LOG:13)
Block(0,17,1,LOG:13)
Block(0,17,2,LOG:13)
Block(0,17,3,LOG:13)
Block(0,17,4,LOG:13)
Block(0,17,5,LOG:13)
Block(0,18,-1,LOG:13)
Block(0,18,0,LOG:13)
Block(0,18,1,LOG:13)
Block(0,18,2,LOG:13)
Block(0,18,3,LOG:13)
Block(0,18,4,LOG:13)
Block(0,18,5,LOG:13)
Block(0,19,-1,LOG:13)
Block(0,19,0,LOG:13)
Block(0,19,1,LOG:13)
Block(0,19,2,LOG:13)
Block(0,19,3,LOG:13)
Block(0,19,4,LOG:13)
Block(0,19,5,LOG:13)
Block(0,20,-1,LOG:13)
Block(0,20,0,LOG:13)
Block(0,20,1,LOG:13)
Block(0,20,2,LOG:13)
Block(0,20,3,LOG:13)
Block(0,20,4,LOG:13)
Block(0,20,5,LOG:13)
Block(0,21,-1,LOG:13)
Block(0,21,0,LOG:13)
Block(0,21,1,LOG:13)
Block(0,21,2,LOG:13)
Block(0,21,3,LOG:13)
Block(0,21,4,LOG:13)
Block(0,21,5,LOG:13)
Block(0,22,-1,LOG:13)
Block(0,22,0,LOG:13)
Block(0,22,1,LOG:13)
Block(0,22,2,LOG:13)
Block(0,22,3,LOG:13)
Block(0,22,4,LOG:13)
Block(0,22,5,LOG:13)
Block(0,23,-1,LOG:13)
Block(0,23,0,LOG:13)
Block(0,23,1,LOG:13)
Block(0,23,2,LOG:13)
Block(0,23,3,LOG:13)
Block(0,23,4,LOG:13)
Block(0,23,5,LOG:13)
Block(0,24,-1,LOG:13)
Block(0,24,0,LOG:13)
Block(0,24,1,LOG:13)
Block(0,24,2,LOG:13)
Block(0,24,3,LOG:13)
Block(0,24,4,LOG:13)
Block(0,24,5,LOG:13)
Block(0,24,6,LOG:13)
Block(0,25,-1,LOG:13)
Block(0,25,0,LOG:13)
Block(0,25,1,LOG:13)
Block(0,25,2,LOG:13)
Block(0,25,3,LOG:13)
Block(0,25,4,LOG:13)
Block(0,25,5,LOG:13)
Block(0,25,6,LOG:13)
Block(0,25,7,LOG:13)
Block(0,26,-1,LOG:13)
Block(0,26,0,LOG:13)
Block(0,26,1,LOG:13)
Block(0,26,2,LOG:13)
Block(0,26,3,LOG:13)
Block(0,26,4,LOG:13)
Block(0,26,5,LOG:13)
Block(0,26,6,LOG:13)
Block(0,26,7,LOG:13)
Block(0,26,8,LOG:13)
Block(0,27,-1,LOG:13)
Block(0,27,0,LOG:13)
Block(0,27,1,LOG:13)
Block(0,27,2,LOG:13)
Block(0,27,3,LOG:13)
Block(0,27,4,LOG:13)
Block(0,27,5,LOG:13)
Block(0,27,6,LOG:13)
Block(0,27,7,LOG:13)
Block(0,27,8,LOG:13)
Block(0,27,9,LOG:13)
Block(0,28,-1,LOG:13)
Block(0,28,0,LOG:13)
Block(0,28,1,LOG:13)
Block(0,28,2,LOG:13)
Block(0,28,3,LOG:13)
Block(0,28,4,LOG:13)
Block(0,28,5,LOG:13)
Block(0,28,6,LOG:13)
Block(0,28,7,LOG:13)
Block(0,28,8,LOG:13)
Block(0,28,9,LOG:13)
Block(0,29,-1,LOG:13)
Block(0,29,0,LOG:13)
Block(0,29,1,LOG:13)
Block(0,29,2,LOG:13)
Block(0,29,3,LOG:13)
Block(0,29,4,LOG:13)
Block(0,29,6,LOG:13)
Block(0,29,7,LOG:13)
Block(0,29,8,LOG:13)
Block(0,29,9,LOG:13)
Block(0,30,-1,LOG:13)
Block(0,30,0,LOG:13)
Block(0,30,1,LOG:13)
Block(0,30,2,LOG:13)
Block(0,30,3,LOG:13)
Block(0,30,4,LOG:13)
Block(0,30,7,LOG:13)
Block(0,30,8,LOG:13)
Block(0,30,9,LOG:13)
Block(0,31,-9,LEAVES:1)
Block(0,31,-7,LEAVES:1)
Block(0,31,-1,LOG:13)
Block(0,31,0,LOG:13)
Block(0,31,1,LOG:13)
Block(0,31,2,LOG:13)
Block(0,31,3,LOG:13)
Block(0,31,4,LOG:13)
Block(0,31,7,LOG:13)
Block(0,31,8,LOG:13)
Block(0,31,9,LOG:13)
Block(0,32,-6,LEAVES:1)
Block(0,32,-1,LOG:13)
Block(0,32,0,LOG:13)
Block(0,32,1,LOG:13)
Block(0,32,2,LOG:13)
Block(0,32,3,LOG:13)
Block(0,32,4,LOG:13)
Block(0,32,7,LOG:13)
Block(0,32,8,LOG:13)
Block(0,32,9,LOG:13)
Block(0,32,11,LEAVES:1)
Block(0,33,-5,LEAVES:1)
Block(0,33,-4,LEAVES:1)
Block(0,33,-3,LEAVES:1)
Block(0,33,-1,LOG:13)
Block(0,33,0,LOG:13)
Block(0,33,1,LOG:13)
Block(0,33,2,LOG:13)
Block(0,33,3,LOG:13)
Block(0,33,4,LOG:13)
Block(0,33,7,LOG:13)
Block(0,33,8,LOG:13)
Block(0,33,9,LOG:13)
Block(0,33,15,LEAVES:1)
Block(0,33,17,LEAVES:1)
Block(0,34,-4,LEAVES:1)
Block(0,34,-1,LOG:13)
Block(0,34,0,LOG:13)
Block(0,34,1,LOG:13)
Block(0,34,2,LOG:13)
Block(0,34,3,LOG:13)
Block(0,34,4,LOG:13)
Block(0,34,7,LOG:13)
Block(0,34,8,LOG:13)
Block(0,34,9,LOG:13)
Block(0,34,14,LEAVES:1)
Block(0,34,15,LEAVES:1)
Block(0,34,17,LOG:13)
Block(0,34,18,LEAVES:1)
Block(0,35,-3,LEAVES:1)
Block(0,35,-2,LEAVES:1)
Block(0,35,-1,LOG:13)
Block(0,35,0,LOG:13)
Block(0,35,1,LOG:13)
Block(0,35,2,LOG:13)
Block(0,35,3,LOG:13)
Block(0,35,4,LOG:13)
Block(0,35,7,LOG:13)
Block(0,35,8,LOG:13)
Block(0,35,9,LOG:13)
Block(0,35,13,LEAVES:1)
Block(0,35,14,LEAVES:1)
Block(0,35,15,LEAVES:1)
Block(0,35,16,LEAVES:1)
Block(0,36,-7,LEAVES:1)
Block(0,36,-1,LOG:13)
Block(0,36,0,LOG:13)
Block(0,36,1,LOG:13)
Block(0,36,2,LOG:13)
Block(0,36,3,LOG:13)
Block(0,36,4,LOG:13)
Block(0,36,5,LEAVES:1)
Block(0,36,7,LOG:13)
Block(0,36,8,LOG:13)
Block(0,36,9,LOG:13)
Block(0,36,13,LEAVES:1)
Block(0,36,14,LEAVES:1)
Block(0,37,-5,LEAVES:1)
Block(0,37,-4,LEAVES:1)
Block(0,37,-1,LOG:13)
Block(0,37,0,LOG:13)
Block(0,37,1,LOG:13)
Block(0,37,2,LOG:13)
Block(0,37,3,LOG:13)
Block(0,37,4,LOG:13)
Block(0,37,7,LOG:13)
Block(0,37,8,LOG:13)
Block(0,37,9,LOG:13)
Block(0,37,11,LEAVES:1)
Block(0,37,12,LOG:13)
Block(0,38,-3,LEAVES:1)
Block(0,38,0,LOG:13)
Block(0,38,1,LOG:13)
Block(0,38,2,LOG:13)
Block(0,38,3,LOG:13)
Block(0,38,4,LOG:13)
Block(0,38,7,LOG:13)
Block(0,38,8,LOG:13)
Block(0,38,9,LOG:13)
Block(0,38,10,LOG:13)
Block(0,38,11,LOG:13)
Block(0,39,-3,LEAVES:1)
Block(0,39,-2,LEAVES:1)
Block(0,39,-1,LEAVES:1)
Block(0,39,0,LOG:13)
Block(0,39,1,LOG:13)
Block(0,39,2,LOG:13)
Block(0,39,3,LOG:13)
Block(0,39,4,LOG:13)
Block(0,39,7,LOG:13)
Block(0,39,8,LOG:13)
Block(0,39,9,LOG:13)
Block(0,39,11,LEAVES:1)
Block(0,40,-3,LEAVES:1)
Block(0,40,0,LOG:13)
Block(0,40,1,LOG:13)
Block(0,40,2,LOG:13)
Block(0,40,3,LOG:13)
Block(0,40,4,LOG:13)
Block(0,40,7,LOG:13)
Block(0,40,8,LOG:13)
Block(0,40,9,LOG:13)
Block(0,40,10,LEAVES:1)
Block(0,41,-1,LEAVES:1)
Block(0,41,0,LOG:13)
Block(0,41,1,LOG:13)
Block(0,41,2,LOG:13)
Block(0,41,3,LOG:13)
Block(0,41,4,LOG:13)
Block(0,41,6,LEAVES:1)
Block(0,41,7,LOG:13)
Block(0,41,8,LOG:13)
Block(0,41,9,LOG:13)
Block(0,42,-1,LEAVES:1)
Block(0,42,0,LOG:13)
Block(0,42,1,LOG:13)
Block(0,42,2,LOG:13)
Block(0,42,3,LOG:13)
Block(0,42,4,LOG:13)
Block(0,42,7,LOG:13)
Block(0,42,8,LOG:13)
Block(0,42,9,LOG:13)
Block(0,42,10,LEAVES:1)
Block(0,42,12,LEAVES:1)
Block(0,43,-8,LEAVES:1)
Block(0,43,0,LOG:13)
Block(0,43,1,LOG:13)
Block(0,43,2,LOG:13)
Block(0,43,3,LOG:13)
Block(0,43,4,LOG:13)
Block(0,43,6,LEAVES:1)
Block(0,43,7,LOG:13)
Block(0,43,8,LOG:13)
Block(0,43,9,LOG:13)
Block(0,43,10,LEAVES:1)
Block(0,44,-7,LEAVES:1)
Block(0,44,-6,LEAVES:1)
Block(0,44,-5,LEAVES:1)
Block(0,44,0,LOG:13)
Block(0,44,1,LOG:13)
Block(0,44,2,LOG:13)
Block(0,44,3,LOG:13)
Block(0,44,4,LOG:13)
Block(0,44,7,LOG:13)
Block(0,44,8,LOG:13)
Block(0,44,9,LOG:13)
Block(0,45,-6,LEAVES:1)
Block(0,45,-5,LEAVES:1)
Block(0,45,0,LOG:13)
Block(0,45,1,LOG:13)
Block(0,45,2,LOG:13)
Block(0,45,3,LOG:13)
Block(0,45,4,LOG:13)
Block(0,45,7,LOG:13)
Block(0,45,8,LOG:13)
Block(0,45,9,LOG:13)
Block(0,46,-4,LEAVES:1)
Block(0,46,-3,LEAVES:1)
Block(0,46,-2,LEAVES:1)
Block(0,46,-1,LEAVES:1)
Block(0,46,0,LOG:13)
Block(0,46,1,LOG:13)
Block(0,46,2,LOG:13)
Block(0,46,3,LOG:13)
Block(0,46,4,LOG:13)
Block(0,46,7,LOG:13)
Block(0,46,8,LOG:13)
Block(0,46,9,LOG:13)
Block(0,46,13,LEAVES:1)
Block(0,46,15,LEAVES:1)
Block(0,47,-2,LOG:13)
Block(0,47,-1,LOG:13)
Block(0,47,0,LOG:13)
Block(0,47,1,LOG:13)
Block(0,47,2,LOG:13)
Block(0,47,3,LOG:13)
Block(0,47,7,LOG:13)
Block(0,47,8,LOG:13)
Block(0,47,9,LOG:13)
Block(0,47,12,LEAVES:1)
Block(0,48,-2,LEAVES:1)
Block(0,48,-1,LOG:13)
Block(0,48,0,LOG:13)
Block(0,48,1,LOG:13)
Block(0,48,2,LOG:13)
Block(0,48,3,LOG:13)
Block(0,48,7,LOG:13)
Block(0,48,8,LOG:13)
Block(0,48,9,LOG:13)
Block(0,48,11,LEAVES:1)
Block(0,48,12,LEAVES:1)
Block(0,49,0,LOG:13)
Block(0,49,1,LOG:13)
Block(0,49,2,LOG:13)
Block(0,49,3,LOG:13)
Block(0,49,4,LEAVES:1)
Block(0,49,6,LEAVES:1)
Block(0,49,7,LOG:13)
Block(0,49,8,LOG:13)
Block(0,49,9,LOG:13)
Block(0,49,10,LOG:13)
Block(0,50,-1,LEAVES:1)
Block(0,50,0,LOG:13)
Block(0,50,1,LOG:13)
Block(0,50,2,LOG:13)
Block(0,50,3,LOG:13)
Block(0,50,7,LOG:13)
Block(0,50,8,LOG:13)
Block(0,50,9,LEAVES:1)
Block(0,51,0,LOG:13)
Block(0,51,1,LOG:13)
Block(0,51,2,LOG:13)
Block(0,51,3,LOG:13)
Block(0,51,7,LOG:13)
Block(0,51,8,LOG:13)
Block(0,51,11,LEAVES:1)
Block(0,52,0,LOG:13)
Block(0,52,1,LOG:13)
Block(0,52,2,LOG:13)
Block(0,52,3,LOG:13)
Block(0,52,4,LEAVES:1)
Block(0,52,7,LOG:13)
Block(0,52,8,LOG:13)
Block(0,53,1,LOG:13)
Block(0,53,2,LOG:13)
Block(0,53,3,LOG:13)
Block(0,53,6,LEAVES:1)
Block(0,53,8,LOG:13)
Block(0,53,9,LEAVES:1)
Block(0,53,10,LEAVES:1)
Block(0,53,11,LEAVES:1)
Block(0,54,-6,LEAVES:1)
Block(0,54,-4,LEAVES:1)
Block(0,54,1,LOG:13)
Block(0,54,2,LOG:13)
Block(0,54,3,LOG:13)
Block(0,54,7,LOG:13)
Block(0,54,8,LOG:13)
Block(0,54,9,LOG:13)
Block(0,54,10,LEAVES:1)
Block(0,55,-3,LEAVES:1)
Block(0,55,1,LOG:13)
Block(0,55,2,LOG:13)
Block(0,55,3,LOG:13)
Block(0,55,8,LOG:13)
Block(0,55,9,LEAVES:1)
Block(0,56,-3,LEAVES:1)
Block(0,56,-2,LEAVES:1)
Block(0,56,0,LEAVES:1)
Block(0,56,1,LOG:13)
Block(0,56,2,LOG:13)
Block(0,56,3,LOG:13)
Block(0,56,6,LEAVES:1)
Block(0,56,7,LEAVES:1)
Block(0,56,8,LOG:13)
Block(0,56,9,LEAVES:1)
Block(0,56,10,LEAVES:1)
Block(0,57,-1,LOG:13)
Block(0,57,0,LOG:13)
Block(0,57,1,LOG:13)
Block(0,57,2,LOG:13)
Block(0,57,3,LOG:13)
Block(0,57,4,LEAVES:1)
Block(0,57,7,LEAVES:1)
Block(0,57,8,LOG:13)
Block(0,57,9,LEAVES:1)
Block(0,57,10,LEAVES:1)
Block(0,57,11,LEAVES:1)
Block(0,57,12,LEAVES:1)
Block(0,58,0,LEAVES:1)
Block(0,58,1,LOG:13)
Block(0,58,2,LOG:13)
Block(0,58,3,LOG:13)
Block(0,58,8,LOG:13)
Block(0,58,9,LEAVES:1)
Block(0,58,10,LOG:13)
Block(0,58,11,LEAVES:1)
Block(0,59,-4,LEAVES:1)
Block(0,59,-3,LEAVES:1)
Block(0,59,0,LEAVES:1)
Block(0,59,1,LOG:13)
Block(0,59,2,LOG:13)
Block(0,59,5,LEAVES:1)
Block(0,59,7,LEAVES:1)
Block(0,59,8,LOG:13)
Block(0,59,9,LOG:13)
Block(0,59,10,LEAVES:1)
Block(0,60,-3,LEAVES:1)
Block(0,60,1,LOG:13)
Block(0,60,2,LOG:13)
Block(0,60,5,LEAVES:1)
Block(0,60,8,LOG:13)
Block(0,61,-2,LEAVES:1)
Block(0,61,1,LOG:13)
Block(0,61,2,LOG:13)
Block(0,61,3,LOG:13)
Block(0,61,4,LEAVES:1)
Block(0,61,5,LEAVES:1)
Block(0,61,6,LEAVES:1)
Block(0,61,7,LEAVES:1)
Block(0,61,8,LOG:13)
Block(0,61,9,LEAVES:1)
Block(0,62,-1,LEAVES:1)
Block(0,62,0,LOG:13)
Block(0,62,1,LOG:13)
Block(0,62,2,LOG:13)
Block(0,62,3,LEAVES:1)
Block(0,62,6,LEAVES:1)
Block(0,62,7,LEAVES:1)
Block(0,62,8,LEAVES:1)
Block(0,63,1,LEAVES:1)
Block(0,63,2,LOG:13)
Block(0,63,3,LEAVES:1)
Block(0,63,4,LEAVES:1)
Block(0,63,5,LEAVES:1)
Block(0,63,6,LEAVES:1)
Block(0,63,8,LEAVES:1)
Block(0,64,2,LOG:13)
Block(0,64,3,LEAVES:1)
Block(0,64,4,LOG:13)
Block(0,64,5,LEAVES:1)
Block(0,65,2,LOG:13)
Block(0,65,3,LOG:13)
Block(0,65,4,LEAVES:1)
Block(0,66,1,LEAVES:1)
Block(0,66,2,LOG:13)
Block(0,66,3,LEAVES:1)
Block(0,67,1,LEAVES:1)
Block(0,67,2,LEAVES:1)
Block(0,68,2,LEAVES:1)
Block(1,0,-4,LOG:13)
Block(1,0,-3,LOG:13)
Block(1,0,-2,LOG:13)
Block(1,0,-1,LOG:13)
Block(1,0,0,LOG:13)
Block(1,0,1,LOG:13)
Block(1,0,2,LOG:13)
Block(1,0,3,LOG:13)
Block(1,0,4,LOG:13)
Block(1,0,5,LOG:13)
Block(1,0,6,LOG:13)
Block(1,0,7,LOG:13)
Block(1,1,-3,LOG:13)
Block(1,1,-2,LOG:13)
Block(1,1,-1,LOG:13)
Block(1,1,0,LOG:13)
Block(1,1,1,LOG:13)
Block(1,1,2,LOG:13)
Block(1,1,3,LOG:13)
Block(1,1,4,LOG:13)
Block(1,1,5,LOG:13)
Block(1,1,6,LOG:13)
Block(1,2,-3,LOG:13)
Block(1,2,-2,LOG:13)
Block(1,2,-1,LOG:13)
Block(1,2,0,LOG:13)
Block(1,2,1,LOG:13)
Block(1,2,2,LOG:13)
Block(1,2,3,LOG:13)
Block(1,2,4,LOG:13)
Block(1,2,5,LOG:13)
Block(1,2,6,LOG:13)
Block(1,3,-2,LOG:13)
Block(1,3,-1,LOG:13)
Block(1,3,0,LOG:13)
Block(1,3,1,LOG:13)
Block(1,3,2,LOG:13)
Block(1,3,3,LOG:13)
Block(1,3,4,LOG:13)
Block(1,3,5,LOG:13)
Block(1,3,6,LOG:13)
Block(1,4,-2,LOG:13)
Block(1,4,-1,LOG:13)
Block(1,4,0,LOG:13)
Block(1,4,1,LOG:13)
Block(1,4,2,LOG:13)
Block(1,4,3,LOG:13)
Block(1,4,4,LOG:13)
Block(1,4,5,LOG:13)
Block(1,4,6,LOG:13)
Block(1,5,-1,LOG:13)
Block(1,5,0,LOG:13)
Block(1,5,1,LOG:13)
Block(1,5,2,LOG:13)
Block(1,5,3,LOG:13)
Block(1,5,4,LOG:13)
Block(1,5,5,LOG:13)
Block(1,6,-1,LOG:13)
Block(1,6,0,LOG:13)
Block(1,6,1,LOG:13)
Block(1,6,2,LOG:13)
Block(1,6,3,LOG:13)
Block(1,6,4,LOG:13)
Block(1,6,5,LOG:13)
Block(1,7,-1,LOG:13)
Block(1,7,0,LOG:13)
Block(1,7,1,LOG:13)
Block(1,7,2,LOG:13)
Block(1,7,3,LOG:13)
Block(1,7,4,LOG:13)
Block(1,7,5,LOG:13)
Block(1,8,-1,LOG:13)
Block(1,8,0,LOG:13)
Block(1,8,1,LOG:13)
Block(1,8,2,LOG:13)
Block(1,8,3,LOG:13)
Block(1,8,4,LOG:13)
Block(1,8,5,LOG:13)
Block(1,9,-1,LOG:13)
Block(1,9,0,LOG:13)
Block(1,9,1,LOG:13)
Block(1,9,2,LOG:13)
Block(1,9,3,LOG:13)
Block(1,9,4,LOG:13)
Block(1,10,-1,LOG:13)
Block(1,10,0,LOG:13)
Block(1,10,1,LOG:13)
Block(1,10,2,LOG:13)
Block(1,10,3,LOG:13)
Block(1,10,4,LOG:13)
Block(1,11,-1,LOG:13)
Block(1,11,0,LOG:13)
Block(1,11,1,LOG:13)
Block(1,11,2,LOG:13)
Block(1,11,3,LOG:13)
Block(1,11,4,LOG:13)
Block(1,12,0,LOG:13)
Block(1,12,1,LOG:13)
Block(1,12,2,LOG:13)
Block(1,12,3,LOG:13)
Block(1,12,4,LOG:13)
Block(1,13,0,LOG:13)
Block(1,13,1,LOG:13)
Block(1,13,2,LOG:13)
Block(1,13,3,LOG:13)
Block(1,13,4,LOG:13)
Block(1,14,0,LOG:13)
Block(1,14,1,LOG:13)
Block(1,14,2,LOG:13)
Block(1,14,3,LOG:13)
Block(1,14,4,LOG:13)
Block(1,15,0,LOG:13)
Block(1,15,1,LOG:13)
Block(1,15,2,LOG:13)
Block(1,15,3,LOG:13)
Block(1,15,4,LOG:13)
Block(1,16,0,LOG:13)
Block(1,16,1,LOG:13)
Block(1,16,2,LOG:13)
Block(1,16,3,LOG:13)
Block(1,16,4,LOG:13)
Block(1,17,0,LOG:13)
Block(1,17,1,LOG:13)
Block(1,17,2,LOG:13)
Block(1,17,3,LOG:13)
Block(1,17,4,LOG:13)
Block(1,18,-1,LEAVES:1)
Block(1,18,0,LOG:13)
Block(1,18,1,LOG:13)
Block(1,18,2,LOG:13)
Block(1,18,3,LOG:13)
Block(1,18,4,LOG:13)
Block(1,19,-2,LEAVES:1)
Block(1,19,0,LOG:13)
Block(1,19,1,LOG:13)
Block(1,19,2,LOG:13)
Block(1,19,3,LOG:13)
Block(1,19,4,LOG:13)
Block(1,20,0,LOG:13)
Block(1,20,1,LOG:13)
Block(1,20,2,LOG:13)
Block(1,20,3,LOG:13)
Block(1,20,4,LOG:13)
Block(1,21,0,LOG:13)
Block(1,21,1,LOG:13)
Block(1,21,2,LOG:13)
Block(1,21,3,LOG:13)
Block(1,21,4,LOG:13)
Block(1,22,0,LOG:13)
Block(1,22,1,LOG:13)
Block(1,22,2,LOG:13)
Block(1,22,3,LOG:13)
Block(1,22,4,LOG:13)
Block(1,23,0,LOG:13)
Block(1,23,1,LOG:13)
Block(1,23,2,LOG:13)
Block(1,23,3,LOG:13)
Block(1,23,4,LOG:13)
Block(1,23,5,LOG:13)
Block(1,24,0,LOG:13)
Block(1,24,1,LOG:13)
Block(1,24,2,LOG:13)
Block(1,24,3,LOG:13)
Block(1,24,4,LOG:13)
Block(1,24,5,LOG:13)
Block(1,24,6,LOG:13)
Block(1,25,0,LOG:13)
Block(1,25,1,LOG:13)
Block(1,25,2,LOG:13)
Block(1,25,3,LOG:13)
Block(1,25,4,LOG:13)
Block(1,25,5,LOG:13)
Block(1,25,6,LOG:13)
Block(1,25,7,LOG:13)
Block(1,26,0,LOG:13)
Block(1,26,1,LOG:13)
Block(1,26,2,LOG:13)
Block(1,26,3,LOG:13)
Block(1,26,4,LOG:13)
Block(1,26,5,LOG:13)
Block(1,26,6,LOG:13)
Block(1,26,7,LOG:13)
Block(1,27,0,LOG:13)
Block(1,27,1,LOG:13)
Block(1,27,2,LOG:13)
Block(1,27,3,LOG:13)
Block(1,27,4,LOG:13)
Block(1,27,5,LOG:13)
Block(1,27,6,LOG:13)
Block(1,27,7,LOG:13)
Block(1,27,8,LOG:13)
Block(1,28,0,LOG:13)
Block(1,28,1,LOG:13)
Block(1,28,2,LOG:13)
Block(1,28,3,LOG:13)
Block(1,28,4,LOG:13)
Block(1,28,5,LOG:13)
Block(1,28,6,LOG:13)
Block(1,28,7,LOG:13)
Block(1,28,8,LOG:13)
Block(1,29,0,LOG:13)
Block(1,29,1,LOG:13)
Block(1,29,2,LOG:13)
Block(1,29,3,LOG:13)
Block(1,29,4,LOG:13)
Block(1,29,7,LOG:13)
Block(1,29,8,LOG:13)
Block(1,30,0,LOG:13)
Block(1,30,1,LOG:13)
Block(1,30,2,LOG:13)
Block(1,30,3,LOG:13)
Block(1,30,4,LOG:13)
Block(1,30,8,LOG:13)
Block(1,30,9,LOG:13)
Block(1,31,0,LOG:13)
Block(1,31,1,LOG:13)
Block(1,31,2,LOG:13)
Block(1,31,3,LOG:13)
Block(1,31,4,LOG:13)
Block(1,31,8,LOG:13)
Block(1,31,9,LOG:13)
Block(1,31,10,LEAVES:1)
Block(1,31,13,LEAVES:1)
Block(1,32,0,LOG:13)
Block(1,32,1,LOG:13)
Block(1,32,2,LOG:13)
Block(1,32,3,LOG:13)
Block(1,32,4,LOG:13)
Block(1,32,8,LOG:13)
Block(1,32,9,LOG:13)
Block(1,32,12,LEAVES:1)
Block(1,33,-5,LEAVES:1)
Block(1,33,-3,LEAVES:1)
Block(1,33,0,LOG:13)
Block(1,33,1,LOG:13)
Block(1,33,2,LOG:13)
Block(1,33,3,LOG:13)
Block(1,33,4,LOG:13)
Block(1,33,8,LOG:13)
Block(1,33,9,LOG:13)
Block(1,33,10,LEAVES:1)
Block(1,33,17,LEAVES:1)
Block(1,33,18,LEAVES:1)
Block(1,33,19,LEAVES:1)
Block(1,34,-2,LEAVES:1)
Block(1,34,0,LOG:13)
Block(1,34,1,LOG:13)
Block(1,34,2,LOG:13)
Block(1,34,3,LOG:13)
Block(1,34,8,LOG:13)
Block(1,34,9,LEAVES:1)
Block(1,34,14,LEAVES:1)
Block(1,34,16,LEAVES:1)
Block(1,34,17,LEAVES:1)
Block(1,35,0,LOG:13)
Block(1,35,1,LOG:13)
Block(1,35,2,LOG:13)
Block(1,35,3,LOG:13)
Block(1,35,8,LOG:13)
Block(1,35,13,LEAVES:1)
Block(1,36,-7,LEAVES:1)
Block(1,36,-1,LEAVES:1)
Block(1,36,0,LOG:13)
Block(1,36,1,LOG:13)
Block(1,36,2,LOG:13)
Block(1,36,3,LOG:13)
Block(1,36,7,LEAVES:1)
Block(1,36,8,LOG:13)
Block(1,36,10,LEAVES:1)
Block(1,36,12,LEAVES:1)
Block(1,37,-6,LEAVES:1)
Block(1,37,-5,LEAVES:1)
Block(1,37,0,LOG:13)
Block(1,37,1,LOG:13)
Block(1,37,2,LOG:13)
Block(1,37,3,LOG:13)
Block(1,37,6,LEAVES:1)
Block(1,37,7,LOG:13)
Block(1,37,8,LOG:13)
Block(1,37,12,LEAVES:1)
Block(1,38,-5,LEAVES:1)
Block(1,38,-4,LEAVES:1)
Block(1,38,-3,LOG:13)
Block(1,38,0,LOG:13)
Block(1,38,1,LOG:13)
Block(1,38,2,LOG:13)
Block(1,38,3,LOG:13)
Block(1,38,8,LOG:13)
Block(1,38,9,LEAVES:1)
Block(1,38,11,LEAVES:1)
Block(1,39,-2,LOG:13)
Block(1,39,-1,LOG:13)
Block(1,39,0,LOG:13)
Block(1,39,1,LOG:13)
Block(1,39,2,LOG:13)
Block(1,39,3,LOG:13)
Block(1,39,8,LOG:13)
Block(1,39,11,LEAVES:1)
Block(1,39,12,LEAVES:1)
Block(1,40,-1,LEAVES:1)
Block(1,40,0,LOG:13)
Block(1,40,1,LOG:13)
Block(1,40,2,LOG:13)
Block(1,40,3,LOG:13)
Block(1,40,8,LOG:13)
Block(1,40,9,LEAVES:1)
Block(1,40,10,LEAVES:1)
Block(1,41,0,LOG:13)
Block(1,41,1,LOG:13)
Block(1,41,2,LOG:13)
Block(1,41,3,LOG:13)
Block(1,41,8,LOG:13)
Block(1,41,9,LOG:13)
Block(1,41,10,LEAVES:1)
Block(1,42,0,LOG:13)
Block(1,42,1,LOG:13)
Block(1,42,2,LOG:13)
Block(1,42,3,LOG:13)
Block(1,42,4,LEAVES:1)
Block(1,42,5,LEAVES:1)
Block(1,42,7,LEAVES:1)
Block(1,42,8,LOG:13)
Block(1,42,9,LEAVES:1)
Block(1,42,10,LEAVES:1)
Block(1,42,11,LEAVES:1)
Block(1,43,-10,LEAVES:1)
Block(1,43,-9,LEAVES:1)
Block(1,43,-8,LEAVES:1)
Block(1,43,-6,LEAVES:1)
Block(1,43,-1,LEAVES:1)
Block(1,43,0,LOG:13)
Block(1,43,1,LOG:13)
Block(1,43,2,LOG:13)
Block(1,43,3,LOG:13)
Block(1,43,4,LEAVES:1)
Block(1,43,8,LOG:13)
Block(1,44,-8,LEAVES:1)
Block(1,44,-7,LEAVES:1)
Block(1,44,-5,LEAVES:1)
Block(1,44,0,LOG:13)
Block(1,44,1,LOG:13)
Block(1,44,2,LOG:13)
Block(1,44,3,LOG:13)
Block(1,44,4,LOG:13)
Block(1,44,5,LEAVES:1)
Block(1,44,8,LOG:13)
Block(1,45,-6,LOG:13)
Block(1,45,-5,LOG:13)
Block(1,45,-3,LEAVES:1)
Block(1,45,0,LOG:13)
Block(1,45,1,LOG:13)
Block(1,45,2,LOG:13)
Block(1,45,3,LOG:13)
Block(1,45,4,LEAVES:1)
Block(1,45,8,LOG:13)
Block(1,45,14,LEAVES:1)
Block(1,46,-5,LEAVES:1)
Block(1,46,-4,LOG:13)
Block(1,46,-3,LOG:13)
Block(1,46,0,LEAVES:1)
Block(1,46,1,LOG:13)
Block(1,46,2,LOG:13)
Block(1,46,3,LOG:13)
Block(1,46,8,LOG:13)
Block(1,46,11,LEAVES:1)
Block(1,46,14,LEAVES:1)
Block(1,46,15,LEAVES:1)
Block(1,46,16,LEAVES:1)
Block(1,46,17,LEAVES:1)
Block(1,47,-3,LEAVES:1)
Block(1,47,-2,LEAVES:1)
Block(1,47,0,LEAVES:1)
Block(1,47,1,LOG:13)
Block(1,47,2,LOG:13)
Block(1,47,3,LOG:13)
Block(1,47,4,LEAVES:1)
Block(1,47,11,LEAVES:1)
Block(1,47,12,LEAVES:1)
Block(1,47,13,LEAVES:1)
Block(1,47,14,LEAVES:1)
Block(1,47,15,LEAVES:1)
Block(1,48,-1,LEAVES:1)
Block(1,48,0,LOG:13)
Block(1,48,1,LOG:13)
Block(1,48,2,LOG:13)
Block(1,48,3,LOG:13)
Block(1,48,5,LEAVES:1)
Block(1,48,9,LEAVES:1)
Block(1,48,11,LOG:13)
Block(1,48,12,LOG:13)
Block(1,49,0,LEAVES:1)
Block(1,49,1,LOG:13)
Block(1,49,2,LOG:13)
Block(1,49,3,LEAVES:1)
Block(1,49,8,LEAVES:1)
Block(1,49,9,LEAVES:1)
Block(1,49,10,LEAVES:1)
Block(1,49,11,LEAVES:1)
Block(1,50,1,LOG:13)
Block(1,50,2,LOG:13)
Block(1,50,3,LOG:13)
Block(1,50,4,LEAVES:1)
Block(1,50,7,LEAVES:1)
Block(1,50,8,LOG:13)
Block(1,51,1,LOG:13)
Block(1,51,2,LOG:13)
Block(1,51,3,LEAVES:1)
Block(1,51,8,LEAVES:1)
Block(1,52,0,LEAVES:1)
Block(1,52,1,LOG:13)
Block(1,52,2,LOG:13)
Block(1,52,7,LEAVES:1)
Block(1,53,1,LOG:13)
Block(1,53,2,LOG:13)
Block(1,53,5,LEAVES:1)
Block(1,53,6,LOG:13)
Block(1,53,7,LEAVES:1)
Block(1,53,12,LEAVES:1)
Block(1,54,-2,LEAVES:1)
Block(1,54,1,LOG:13)
Block(1,54,2,LOG:13)
Block(1,54,7,LEAVES:1)
Block(1,54,8,LEAVES:1)
Block(1,54,10,LOG:13)
Block(1,54,11,LEAVES:1)
Block(1,55,-3,LEAVES:1)
Block(1,55,-2,LEAVES:1)
Block(1,55,-1,LEAVES:1)
Block(1,55,1,LOG:13)
Block(1,55,2,LOG:13)
Block(1,55,5,LEAVES:1)
Block(1,56,1,LOG:13)
Block(1,56,2,LOG:13)
Block(1,56,3,LEAVES:1)
Block(1,56,6,LEAVES:1)
Block(1,56,7,LEAVES:1)
Block(1,56,8,LEAVES:1)
Block(1,56,10,LEAVES:1)
Block(1,57,-1,LEAVES:1)
Block(1,57,0,LEAVES:1)
Block(1,57,1,LOG:13)
Block(1,57,2,LOG:13)
Block(1,57,7,LEAVES:1)
Block(1,57,8,LOG:13)
Block(1,57,9,LEAVES:1)
Block(1,57,11,LEAVES:1)
Block(1,58,1,LEAVES:1)
Block(1,58,2,LOG:13)
Block(1,58,8,LEAVES:1)
Block(1,58,10,LEAVES:1)
Block(1,59,2,LOG:13)
Block(1,59,5,LEAVES:1)
Block(1,59,6,LEAVES:1)
Block(1,59,7,LEAVES:1)
Block(1,59,9,LEAVES:1)
Block(1,60,-3,LEAVES:1)
Block(1,60,-1,LEAVES:1)
Block(1,60,2,LOG:13)
Block(1,60,3,LEAVES:1)
Block(1,60,5,LEAVES:1)
Block(1,60,8,LEAVES:1)
Block(1,61,-2,LOG:13)
Block(1,61,-1,LOG:13)
Block(1,61,4,LEAVES:1)
Block(1,61,9,LEAVES:1)
Block(1,62,0,LEAVES:1)
Block(1,62,8,LEAVES:1)
Block(1,63,1,LEAVES:1)
Block(1,63,2,LOG:13)
Block(1,63,3,LEAVES:1)
Block(1,63,4,LEAVES:1)
Block(1,64,2,LEAVES:1)
Block(1,64,3,LEAVES:1)
Block(1,64,4,LEAVES:1)
Block(1,65,1,LEAVES:1)
Block(1,65,2,LEAVES:1)
Block(1,65,3,LEAVES:1)
Block(1,66,3,LEAVES:1)
Block(1,67,2,LEAVES:1)
Block(2,0,-3,LOG:13)
Block(2,0,-2,LOG:13)
Block(2,0,-1,LOG:13)
Block(2,0,0,LOG:13)
Block(2,0,1,LOG:13)
Block(2,0,2,LOG:13)
Block(2,0,3,LOG:13)
Block(2,0,4,LOG:13)
Block(2,0,5,LOG:13)
Block(2,0,6,LOG:13)
Block(2,1,-3,LOG:13)
Block(2,1,-2,LOG:13)
Block(2,1,-1,LOG:13)
Block(2,1,0,LOG:13)
Block(2,1,1,LOG:13)
Block(2,1,2,LOG:13)
Block(2,1,3,LOG:13)
Block(2,1,4,LOG:13)
Block(2,1,5,LOG:13)
Block(2,1,6,LOG:13)
Block(2,2,-2,LOG:13)
Block(2,2,-1,LOG:13)
Block(2,2,0,LOG:13)
Block(2,2,1,LOG:13)
Block(2,2,2,LOG:13)
Block(2,2,3,LOG:13)
Block(2,2,4,LOG:13)
Block(2,2,5,LOG:13)
Block(2,3,-2,LOG:13)
Block(2,3,-1,LOG:13)
Block(2,3,0,LOG:13)
Block(2,3,1,LOG:13)
Block(2,3,2,LOG:13)
Block(2,3,3,LOG:13)
Block(2,3,4,LOG:13)
Block(2,3,5,LOG:13)
Block(2,4,-1,LOG:13)
Block(2,4,0,LOG:13)
Block(2,4,1,LOG:13)
Block(2,4,2,LOG:13)
Block(2,4,3,LOG:13)
Block(2,4,4,LOG:13)
Block(2,4,5,LOG:13)
Block(2,5,-1,LOG:13)
Block(2,5,0,LOG:13)
Block(2,5,1,LOG:13)
Block(2,5,2,LOG:13)
Block(2,5,3,LOG:13)
Block(2,5,4,LOG:13)
Block(2,5,5,LOG:13)
Block(2,6,-1,LOG:13)
Block(2,6,0,LOG:13)
Block(2,6,1,LOG:13)
Block(2,6,2,LOG:13)
Block(2,6,3,LOG:13)
Block(2,6,4,LOG:13)
Block(2,7,0,LOG:13)
Block(2,7,1,LOG:13)
Block(2,7,2,LOG:13)
Block(2,7,3,LOG:13)
Block(2,7,4,LOG:13)
Block(2,8,0,LOG:13)
Block(2,8,1,LOG:13)
Block(2,8,2,LOG:13)
Block(2,8,3,LOG:13)
Block(2,8,4,LOG:13)
Block(2,9,0,LOG:13)
Block(2,9,1,LOG:13)
Block(2,9,2,LOG:13)
Block(2,9,3,LOG:13)
Block(2,9,4,LOG:13)
Block(2,10,0,LOG:13)
Block(2,10,1,LOG:13)
Block(2,10,2,LOG:13)
Block(2,10,3,LOG:13)
Block(2,10,4,LOG:13)
Block(2,11,0,LOG:13)
Block(2,11,1,LOG:13)
Block(2,11,2,LOG:13)
Block(2,11,3,LOG:13)
Block(2,12,0,LOG:13)
Block(2,12,1,LOG:13)
Block(2,12,2,LOG:13)
Block(2,12,3,LOG:13)
Block(2,13,0,LOG:13)
Block(2,13,1,LOG:13)
Block(2,13,2,LOG:13)
Block(2,13,3,LOG:13)
Block(2,14,0,LOG:13)
Block(2,14,1,LOG:13)
Block(2,14,2,LOG:13)
Block(2,14,3,LOG:13)
Block(2,15,0,LOG:13)
Block(2,15,1,LOG:13)
Block(2,15,2,LOG:13)
Block(2,15,3,LOG:13)
Block(2,16,0,LOG:13)
Block(2,16,1,LOG:13)
Block(2,16,2,LOG:13)
Block(2,16,3,LOG:13)
Block(2,17,0,LEAVES:1)
Block(2,17,1,LOG:13)
Block(2,17,2,LOG:13)
Block(2,17,3,LOG:13)
Block(2,18,-3,LEAVES:1)
Block(2,18,1,LOG:13)
Block(2,18,2,LOG:13)
Block(2,18,3,LOG:13)
Block(2,19,-2,LEAVES:1)
Block(2,19,0,LEAVES:1)
Block(2,19,1,LOG:13)
Block(2,19,2,LOG:13)
Block(2,19,3,LOG:13)
Block(2,20,-1,LEAVES:1)
Block(2,20,0,LOG:13)
Block(2,20,1,LOG:13)
Block(2,20,2,LOG:13)
Block(2,20,3,LOG:13)
Block(2,21,0,LEAVES:1)
Block(2,21,1,LOG:13)
Block(2,21,2,LOG:13)
Block(2,21,3,LOG:13)
Block(2,22,1,LOG:13)
Block(2,22,2,LOG:13)
Block(2,22,3,LOG:13)
Block(2,22,4,LOG:13)
Block(2,23,1,LOG:13)
Block(2,23,2,LOG:13)
Block(2,23,3,LOG:13)
Block(2,23,4,LOG:13)
Block(2,24,1,LOG:13)
Block(2,24,2,LOG:13)
Block(2,24,3,LOG:13)
Block(2,24,4,LOG:13)
Block(2,25,1,LOG:13)
Block(2,25,2,LOG:13)
Block(2,25,3,LOG:13)
Block(2,25,4,LOG:13)
Block(2,25,5,LOG:13)
Block(2,26,1,LOG:13)
Block(2,26,2,LOG:13)
Block(2,26,3,LOG:13)
Block(2,26,6,LOG:13)
Block(2,27,1,LOG:13)
Block(2,27,2,LOG:13)
Block(2,27,3,LOG:13)
Block(2,27,6,LOG:13)
Block(2,27,7,LOG:13)
Block(2,28,1,LOG:13)
Block(2,28,2,LOG:13)
Block(2,28,7,LOG:13)
Block(2,29,1,LOG:13)
Block(2,29,2,LOG:13)
Block(2,30,1,LOG:13)
Block(2,30,2,LOG:13)
Block(2,30,9,LEAVES:1)
Block(2,31,1,LOG:13)
Block(2,31,2,LOG:13)
Block(2,31,8,LEAVES:1)
Block(2,31,12,LEAVES:1)
Block(2,32,1,LOG:13)
Block(2,32,2,LOG:13)
Block(2,32,11,LEAVES:1)
Block(2,33,-1,LEAVES:1)
Block(2,33,0,LEAVES:1)
Block(2,33,1,LOG:13)
Block(2,33,2,LOG:13)
Block(2,33,8,LEAVES:1)
Block(2,33,10,LOG:13)
Block(2,33,11,LEAVES:1)
Block(2,33,17,LEAVES:1)
Block(2,34,0,LEAVES:1)
Block(2,34,1,LOG:13)
Block(2,34,2,LOG:13)
Block(2,34,8,LEAVES:1)
Block(2,35,-8,LEAVES:1)
Block(2,35,-1,LEAVES:1)
Block(2,35,0,LEAVES:1)
Block(2,35,1,LOG:13)
Block(2,35,2,LOG:13)
Block(2,35,10,LEAVES:1)
Block(2,36,-7,LEAVES:1)
Block(2,36,-6,LEAVES:1)
Block(2,36,1,LOG:13)
Block(2,36,2,LOG:13)
Block(2,36,5,LEAVES:1)
Block(2,36,8,LOG:13)
Block(2,36,9,LEAVES:1)
Block(2,36,10,LEAVES:1)
Block(2,36,12,LEAVES:1)
Block(2,37,-7,LEAVES:1)
Block(2,37,-6,LOG:13)
Block(2,37,-1,LEAVES:1)
Block(2,37,1,LOG:13)
Block(2,37,2,LOG:13)
Block(2,37,7,LEAVES:1)
Block(2,37,10,LEAVES:1)
Block(2,38,-6,LEAVES:1)
Block(2,38,-5,LOG:13)
Block(2,38,-4,LOG:13)
Block(2,38,-3,LEAVES:1)
Block(2,38,0,LEAVES:1)
Block(2,38,1,LOG:13)
Block(2,38,2,LOG:13)
Block(2,38,8,LEAVES:1)
Block(2,38,12,LEAVES:1)
Block(2,39,-4,LEAVES:1)
Block(2,39,-3,LEAVES:1)
Block(2,39,-2,LEAVES:1)
Block(2,39,1,LOG:13)
Block(2,39,2,LOG:13)
Block(2,39,9,LEAVES:1)
Block(2,39,11,LEAVES:1)
Block(2,40,1,LOG:13)
Block(2,40,2,LOG:13)
Block(2,40,8,LEAVES:1)
Block(2,40,10,LOG:13)
Block(2,40,11,LEAVES:1)
Block(2,41,1,LEAVES:1)
Block(2,41,2,LOG:13)
Block(2,41,3,LEAVES:1)
Block(2,41,9,LEAVES:1)
Block(2,41,10,LOG:13)
Block(2,42,-2,LEAVES:1)
Block(2,42,2,LOG:13)
Block(2,42,3,LOG:13)
Block(2,42,10,LEAVES:1)
Block(2,43,-7,LEAVES:1)
Block(2,43,-6,LEAVES:1)
Block(2,43,1,LEAVES:1)
Block(2,43,2,LOG:13)
Block(2,43,3,LEAVES:1)
Block(2,43,7,LEAVES:1)
Block(2,44,-9,LEAVES:1)
Block(2,44,-8,LOG:13)
Block(2,44,-7,LOG:13)
Block(2,44,0,LEAVES:1)
Block(2,44,1,LOG:13)
Block(2,44,2,LOG:13)
Block(2,44,4,LEAVES:1)
Block(2,44,5,LOG:13)
Block(2,44,6,LEAVES:1)
Block(2,45,-7,LEAVES:1)
Block(2,45,-6,LEAVES:1)
Block(2,45,-5,LEAVES:1)
Block(2,45,-3,LEAVES:1)
Block(2,45,1,LEAVES:1)
Block(2,45,3,LEAVES:1)
Block(2,46,-4,LEAVES:1)
Block(2,46,-3,LEAVES:1)
Block(2,46,-1,LEAVES:1)
Block(2,46,0,LEAVES:1)
Block(2,46,13,LEAVES:1)
Block(2,46,15,LEAVES:1)
Block(2,47,0,LEAVES:1)
Block(2,47,2,LEAVES:1)
Block(2,47,9,LEAVES:1)
Block(2,47,11,LEAVES:1)
Block(2,47,12,LEAVES:1)
Block(2,47,13,LOG:13)
Block(2,47,14,LOG:13)
Block(2,47,15,LOG:13)
Block(2,47,16,LEAVES:1)
Block(2,48,0,LEAVES:1)
Block(2,48,1,LEAVES:1)
Block(2,48,5,LEAVES:1)
Block(2,48,10,LEAVES:1)
Block(2,48,11,LEAVES:1)
Block(2,48,13,LEAVES:1)
Block(2,48,14,LEAVES:1)
Block(2,49,1,LEAVES:1)
Block(2,49,6,LEAVES:1)
Block(2,49,9,LEAVES:1)
Block(2,50,2,LEAVES:1)
Block(2,50,3,LOG:13)
Block(2,50,4,LEAVES:1)
Block(2,50,7,LEAVES:1)
Block(2,50,8,LOG:13)
Block(2,50,9,LEAVES:1)
Block(2,51,-2,LEAVES:1)
Block(2,51,-1,LEAVES:1)
Block(2,52,0,LEAVES:1)
Block(2,52,1,LEAVES:1)
Block(2,52,2,LEAVES:1)
Block(2,52,3,LEAVES:1)
Block(2,52,4,LEAVES:1)
Block(2,52,5,LEAVES:1)
Block(2,52,6,LEAVES:1)
Block(2,52,7,LEAVES:1)
Block(2,52,8,LEAVES:1)
Block(2,52,9,LEAVES:1)
Block(2,52,11,LEAVES:1)
Block(2,52,12,LEAVES:1)
Block(2,52,13,LEAVES:1)
Block(2,53,0,LEAVES:1)
Block(2,53,1,LOG:13)
Block(2,53,2,LEAVES:1)
Block(2,53,4,LEAVES:1)
Block(2,53,5,LOG:13)
Block(2,53,6,LEAVES:1)
Block(2,53,9,LEAVES:1)
Block(2,53,10,LOG:13)
Block(2,53,11,LEAVES:1)
Block(2,54,-2,LEAVES:1)
Block(2,54,1,LEAVES:1)
Block(2,55,4,LEAVES:1)
Block(2,55,5,LEAVES:1)
Block(2,55,7,LEAVES:1)
Block(2,56,-1,LEAVES:1)
Block(2,56,0,LEAVES:1)
Block(2,56,1,LEAVES:1)
Block(2,56,5,LEAVES:1)
Block(2,56,6,LEAVES:1)
Block(2,56,7,LOG:13)
Block(2,56,8,LEAVES:1)
Block(2,56,9,LEAVES:1)
Block(2,57,0,LEAVES:1)
Block(2,57,1,LEAVES:1)
Block(2,57,2,LEAVES:1)
Block(2,57,7,LEAVES:1)
Block(2,57,8,LEAVES:1)
Block(2,58,2,LOG:13)
Block(2,58,3,LEAVES:1)
Block(2,59,-3,LEAVES:1)
Block(2,59,-2,LEAVES:1)
Block(2,59,2,LEAVES:1)
Block(2,60,-4,LEAVES:1)
Block(2,60,-3,LOG:13)
Block(2,60,-2,LEAVES:1)
Block(2,60,-1,LEAVES:1)
Block(2,60,5,LEAVES:1)
Block(2,61,-3,LEAVES:1)
Block(2,61,-1,LEAVES:1)
Block(2,62,1,LEAVES:1)
Block(2,62,2,LOG:13)
Block(2,62,3,LEAVES:1)
Block(2,64,4,LEAVES:1)
Block(2,66,3,LEAVES:1)
Block(3,0,-2,LOG:13)
Block(3,0,-1,LOG:13)
Block(3,0,0,LOG:13)
Block(3,0,1,LOG:13)
Block(3,0,2,LOG:13)
Block(3,0,3,LOG:13)
Block(3,0,4,LOG:13)
Block(3,0,5,LOG:13)
Block(3,0,6,LOG:13)
Block(3,1,-1,LOG:13)
Block(3,1,0,LOG:13)
Block(3,1,1,LOG:13)
Block(3,1,2,LOG:13)
Block(3,1,3,LOG:13)
Block(3,1,4,LOG:13)
Block(3,1,5,LOG:13)
Block(3,2,-1,LOG:13)
Block(3,2,0,LOG:13)
Block(3,2,1,LOG:13)
Block(3,2,2,LOG:13)
Block(3,2,3,LOG:13)
Block(3,2,4,LOG:13)
Block(3,2,5,LOG:13)
Block(3,3,-1,LOG:13)
Block(3,3,0,LOG:13)
Block(3,3,1,LOG:13)
Block(3,3,2,LOG:13)
Block(3,3,3,LOG:13)
Block(3,3,4,LOG:13)
Block(3,4,-1,LOG:13)
Block(3,4,0,LOG:13)
Block(3,4,1,LOG:13)
Block(3,4,2,LOG:13)
Block(3,4,3,LOG:13)
Block(3,5,0,LOG:13)
Block(3,5,1,LOG:13)
Block(3,5,2,LOG:13)
Block(3,5,3,LOG:13)
Block(3,6,0,LOG:13)
Block(3,6,1,LOG:13)
Block(3,6,2,LOG:13)
Block(3,6,3,LOG:13)
Block(3,7,0,LOG:13)
Block(3,7,1,LOG:13)
Block(3,7,2,LOG:13)
Block(3,7,3,LOG:13)
Block(3,8,1,LOG:13)
Block(3,8,2,LOG:13)
Block(3,9,1,LOG:13)
Block(3,9,2,LOG:13)
Block(3,10,2,LOG:13)
Block(3,11,2,LOG:13)
Block(3,12,2,LOG:13)
Block(3,13,2,LOG:13)
Block(3,14,2,LOG:13)
Block(3,15,2,LOG:13)
Block(3,16,2,LOG:13)
Block(3,17,-4,LEAVES:1)
Block(3,17,-2,LEAVES:1)
Block(3,17,2,LOG:13)
Block(3,18,-3,LEAVES:1)
Block(3,18,-2,LEAVES:1)
Block(3,18,-1,LEAVES:1)
Block(3,18,2,LOG:13)
Block(3,19,-2,LEAVES:1)
Block(3,19,-1,LOG:13)
Block(3,19,0,LEAVES:1)
Block(3,19,1,LEAVES:1)
Block(3,19,2,LOG:13)
Block(3,20,-1,LOG:13)
Block(3,20,0,LOG:13)
Block(3,20,1,LEAVES:1)
Block(3,20,2,LOG:13)
Block(3,20,3,LEAVES:1)
Block(3,20,4,LEAVES:1)
Block(3,21,0,LEAVES:1)
Block(3,21,1,LEAVES:1)
Block(3,21,2,LOG:13)
Block(3,21,3,LEAVES:1)
Block(3,22,2,LEAVES:1)
Block(3,30,10,LEAVES:1)
Block(3,30,13,LEAVES:1)
Block(3,31,10,LEAVES:1)
Block(3,31,11,LEAVES:1)
Block(3,31,12,LEAVES:1)
Block(3,32,9,LEAVES:1)
Block(3,32,10,LOG:13)
Block(3,32,11,LEAVES:1)
Block(3,33,10,LEAVES:1)
Block(3,34,-9,LEAVES:1)
Block(3,34,0,LEAVES:1)
Block(3,35,-8,LEAVES:1)
Block(3,35,-2,LEAVES:1)
Block(3,35,-1,LEAVES:1)
Block(3,35,5,LEAVES:1)
Block(3,35,6,LEAVES:1)
Block(3,35,7,LEAVES:1)
Block(3,36,-8,LEAVES:1)
Block(3,36,-7,LEAVES:1)
Block(3,36,-6,LEAVES:1)
Block(3,36,0,LEAVES:1)
Block(3,36,1,LOG:13)
Block(3,36,3,LEAVES:1)
Block(3,36,6,LEAVES:1)
Block(3,36,7,LOG:13)
Block(3,36,8,LEAVES:1)
Block(3,37,-7,LOG:13)
Block(3,37,-6,LEAVES:1)
Block(3,37,-5,LEAVES:1)
Block(3,37,-3,LEAVES:1)
Block(3,37,1,LOG:13)
Block(3,37,2,LEAVES:1)
Block(3,37,7,LEAVES:1)
Block(3,37,16,LEAVES:1)
Block(3,38,-5,LEAVES:1)
Block(3,38,-4,LEAVES:1)
Block(3,38,1,LEAVES:1)
Block(3,38,12,LEAVES:1)
Block(3,38,13,LEAVES:1)
Block(3,38,14,LEAVES:1)
Block(3,39,11,LEAVES:1)
Block(3,39,12,LEAVES:1)
Block(3,40,10,LEAVES:1)
Block(3,40,11,LOG:13)
Block(3,41,10,LEAVES:1)
Block(3,42,-3,LEAVES:1)
Block(3,42,-2,LEAVES:1)
Block(3,42,2,LEAVES:1)
Block(3,42,3,LOG:13)
Block(3,42,4,LEAVES:1)
Block(3,42,8,LEAVES:1)
Block(3,43,-9,LEAVES:1)
Block(3,43,-8,LEAVES:1)
Block(3,43,-6,LEAVES:1)
Block(3,43,-2,LEAVES:1)
Block(3,43,-1,LEAVES:1)
Block(3,43,0,LOG:13)
Block(3,43,4,LEAVES:1)
Block(3,43,6,LOG:13)
Block(3,43,7,LEAVES:1)
Block(3,44,-8,LEAVES:1)
Block(3,44,-7,LEAVES:1)
Block(3,44,-6,LEAVES:1)
Block(3,44,-5,LEAVES:1)
Block(3,44,0,LOG:13)
Block(3,44,1,LEAVES:1)
Block(3,44,5,LEAVES:1)
Block(3,45,-4,LEAVES:1)
Block(3,45,-3,LEAVES:1)
Block(3,45,-2,LEAVES:1)
Block(3,46,11,LEAVES:1)
Block(3,46,12,LEAVES:1)
Block(3,46,13,LEAVES:1)
Block(3,46,14,LEAVES:1)
Block(3,46,15,LEAVES:1)
Block(3,46,16,LEAVES:1)
Block(3,47,0,LEAVES:1)
Block(3,47,10,LEAVES:1)
Block(3,47,13,LEAVES:1)
Block(3,47,15,LEAVES:1)
Block(3,48,1,LEAVES:1)
Block(3,48,3,LEAVES:1)
Block(3,48,6,LEAVES:1)
Block(3,48,8,LEAVES:1)
Block(3,48,10,LEAVES:1)
Block(3,49,2,LEAVES:1)
Block(3,49,3,LOG:13)
Block(3,49,4,LEAVES:1)
Block(3,49,7,LEAVES:1)
Block(3,49,8,LOG:13)
Block(3,49,10,LEAVES:1)
Block(3,50,-3,LEAVES:1)
Block(3,50,8,LEAVES:1)
Block(3,51,-2,LEAVES:1)
Block(3,51,-1,LEAVES:1)
Block(3,52,-1,LEAVES:1)
Block(3,52,0,LOG:13)
Block(3,52,1,LEAVES:1)
Block(3,52,2,LEAVES:1)
Block(3,52,5,LEAVES:1)
Block(3,52,6,LEAVES:1)
Block(3,52,7,LEAVES:1)
Block(3,52,11,LEAVES:1)
Block(3,53,0,LOG:13)
Block(3,53,1,LEAVES:1)
Block(3,53,5,LEAVES:1)
Block(3,53,10,LEAVES:1)
Block(3,53,11,LOG:13)
Block(3,53,12,LEAVES:1)
Block(3,54,11,LEAVES:1)
Block(3,55,7,LEAVES:1)
Block(3,55,8,LEAVES:1)
Block(3,56,0,LEAVES:1)
Block(3,56,5,LEAVES:1)
Block(3,56,6,LOG:13)
Block(3,56,7,LEAVES:1)
Block(3,56,8,LEAVES:1)
Block(3,57,1,LEAVES:1)
Block(3,57,2,LEAVES:1)
Block(3,57,3,LEAVES:1)
Block(3,57,4,LEAVES:1)
Block(3,57,6,LEAVES:1)
Block(3,58,1,LEAVES:1)
Block(3,58,2,LOG:13)
Block(3,59,-5,LEAVES:1)
Block(3,59,-4,LEAVES:1)
Block(3,59,-3,LEAVES:1)
Block(3,59,-2,LEAVES:1)
Block(3,60,-3,LEAVES:1)
Block(3,60,-1,LEAVES:1)
Block(3,60,1,LEAVES:1)
Block(3,61,0,LEAVES:1)
Block(3,61,2,LEAVES:1)
Block(3,61,3,LOG:13)
Block(3,61,4,LEAVES:1)
Block(3,62,3,LEAVES:1)
Block(4,0,-2,LOG:13)
Block(4,0,-1,LOG:13)
Block(4,0,0,LOG:13)
Block(4,0,1,LOG:13)
Block(4,0,2,LOG:13)
Block(4,0,3,LOG:13)
Block(4,0,4,LOG:13)
Block(4,1,0,LOG:13)
Block(4,1,1,LOG:13)
Block(4,1,2,LOG:13)
Block(4,1,3,LOG:13)
Block(4,1,4,LOG:13)
Block(4,2,0,LOG:13)
Block(4,2,1,LOG:13)
Block(4,2,2,LOG:13)
Block(4,2,3,LOG:13)
Block(4,3,0,LOG:13)
Block(4,3,1,LOG:13)
Block(4,3,2,LOG:13)
Block(4,4,1,LOG:13)
Block(4,4,2,LOG:13)
Block(4,5,1,LOG:13)
Block(4,5,2,LOG:13)
Block(4,6,2,LOG:13)
Block(4,17,-5,LEAVES:1)
Block(4,17,-4,LEAVES:1)
Block(4,18,-3,LEAVES:1)
Block(4,18,0,LEAVES:1)
Block(4,19,-2,LOG:13)
Block(4,19,1,LEAVES:1)
Block(4,19,2,LEAVES:1)
Block(4,20,-1,LEAVES:1)
Block(4,20,0,LEAVES:1)
Block(4,20,2,LEAVES:1)
Block(4,20,3,LEAVES:1)
Block(4,21,2,LEAVES:1)
Block(4,30,9,LEAVES:1)
Block(4,30,10,LEAVES:1)
Block(4,30,11,LEAVES:1)
Block(4,30,13,LEAVES:1)
Block(4,31,10,LEAVES:1)
Block(4,31,11,LOG:13)
Block(4,31,12,LEAVES:1)
Block(4,32,11,LOG:13)
Block(4,34,-11,LEAVES:1)
Block(4,34,-9,LEAVES:1)
Block(4,34,-3,LEAVES:1)
Block(4,34,4,LEAVES:1)
Block(4,34,5,LEAVES:1)
Block(4,34,6,LEAVES:1)
Block(4,34,7,LEAVES:1)
Block(4,35,-10,LEAVES:1)
Block(4,35,-9,LEAVES:1)
Block(4,35,-8,LEAVES:1)
Block(4,35,-7,LEAVES:1)
Block(4,35,1,LEAVES:1)
Block(4,35,2,LEAVES:1)
Block(4,35,7,LEAVES:1)
Block(4,35,8,LEAVES:1)
Block(4,35,9,LEAVES:1)
Block(4,36,-8,LOG:13)
Block(4,36,-6,LEAVES:1)
Block(4,36,-5,LEAVES:1)
Block(4,36,-1,LEAVES:1)
Block(4,36,0,LOG:13)
Block(4,36,1,LEAVES:1)
Block(4,36,6,LEAVES:1)
Block(4,36,7,LOG:13)
Block(4,36,8,LEAVES:1)
Block(4,37,-7,LEAVES:1)
Block(4,37,-4,LEAVES:1)
Block(4,37,0,LEAVES:1)
Block(4,37,16,LEAVES:1)
Block(4,38,10,LEAVES:1)
Block(4,38,11,LEAVES:1)
Block(4,38,12,LEAVES:1)
Block(4,38,14,LEAVES:1)
Block(4,38,15,LEAVES:1)
Block(4,39,4,LEAVES:1)
Block(4,39,9,LEAVES:1)
Block(4,39,10,LEAVES:1)
Block(4,39,11,LEAVES:1)
Block(4,39,12,LOG:13)
Block(4,39,13,LEAVES:1)
Block(4,40,1,LEAVES:1)
Block(4,40,11,LEAVES:1)
Block(4,41,2,LEAVES:1)
Block(4,41,3,LOG:13)
Block(4,41,4,LEAVES:1)
Block(4,42,2,LEAVES:1)
Block(4,42,3,LEAVES:1)
Block(4,42,6,LEAVES:1)
Block(4,42,8,LEAVES:1)
Block(4,42,9,LEAVES:1)
Block(4,43,-8,LEAVES:1)
Block(4,43,-6,LEAVES:1)
Block(4,43,-2,LEAVES:1)
Block(4,43,-1,LOG:13)
Block(4,43,0,LEAVES:1)
Block(4,43,2,LEAVES:1)
Block(4,43,5,LEAVES:1)
Block(4,43,6,LOG:13)
Block(4,43,7,LEAVES:1)
Block(4,44,-1,LEAVES:1)
Block(4,44,6,LEAVES:1)
Block(4,46,13,LEAVES:1)
Block(4,46,14,LEAVES:1)
Block(4,48,1,LEAVES:1)
Block(4,48,4,LEAVES:1)
Block(4,48,6,LEAVES:1)
Block(4,48,9,LEAVES:1)
Block(4,49,3,LEAVES:1)
Block(4,49,4,LOG:13)
Block(4,49,5,LEAVES:1)
Block(4,49,7,LEAVES:1)
Block(4,49,8,LOG:13)
Block(4,49,9,LEAVES:1)
Block(4,50,-3,LEAVES:1)
Block(4,50,-2,LEAVES:1)
Block(4,50,4,LEAVES:1)
Block(4,51,-2,LEAVES:1)
Block(4,51,-1,LOG:13)
Block(4,52,-1,LOG:13)
Block(4,52,0,LEAVES:1)
Block(4,52,2,LEAVES:1)
Block(4,52,4,LEAVES:1)
Block(4,52,5,LEAVES:1)
Block(4,52,6,LEAVES:1)
Block(4,52,9,LEAVES:1)
Block(4,52,10,LEAVES:1)
Block(4,52,11,LEAVES:1)
Block(4,52,12,LEAVES:1)
Block(4,52,13,LEAVES:1)
Block(4,53,0,LEAVES:1)
Block(4,53,11,LOG:13)
Block(4,53,12,LEAVES:1)
Block(4,55,4,LEAVES:1)
Block(4,55,5,LEAVES:1)
Block(4,55,6,LEAVES:1)
Block(4,55,8,LEAVES:1)
Block(4,56,6,LEAVES:1)
Block(4,57,1,LEAVES:1)
Block(4,57,2,LOG:13)
Block(4,57,3,LEAVES:1)
Block(4,58,2,LEAVES:1)
Block(4,59,-2,LEAVES:1)
Block(4,60,1,LEAVES:1)
Block(4,60,2,LEAVES:1)
Block(4,60,3,LEAVES:1)
Block(4,60,4,LEAVES:1)
Block(4,60,5,LEAVES:1)
Block(4,61,2,LEAVES:1)
Block(4,61,3,LOG:13)
Block(4,61,4,LEAVES:1)
Block(5,0,1,LOG:13)
Block(5,0,2,LOG:13)
Block(5,1,1,LOG:13)
Block(5,1,2,LOG:13)
Block(5,2,1,LOG:13)
Block(5,16,-6,LEAVES:1)
Block(5,17,-5,LEAVES:1)
Block(5,17,-4,LEAVES:1)
Block(5,18,-4,LEAVES:1)
Block(5,18,-3,LOG:13)
Block(5,18,-2,LEAVES:1)
Block(5,18,0,LEAVES:1)
Block(5,19,-3,LEAVES:1)
Block(5,19,-2,LEAVES:1)
Block(5,19,-1,LEAVES:1)
Block(5,19,1,LEAVES:1)
Block(5,20,3,LEAVES:1)
Block(5,30,10,LEAVES:1)
Block(5,30,13,LEAVES:1)
Block(5,30,14,LEAVES:1)
Block(5,31,11,LEAVES:1)
Block(5,31,12,LOG:13)
Block(5,31,13,LEAVES:1)
Block(5,32,12,LEAVES:1)
Block(5,34,-12,LEAVES:1)
Block(5,34,-11,LEAVES:1)
Block(5,34,-10,LEAVES:1)
Block(5,34,-4,LEAVES:1)
Block(5,34,0,LEAVES:1)
Block(5,34,6,LEAVES:1)
Block(5,34,8,LEAVES:1)
Block(5,35,-11,LEAVES:1)
Block(5,35,-10,LOG:13)
Block(5,35,-9,LOG:13)
Block(5,35,-8,LEAVES:1)
Block(5,35,-7,LEAVES:1)
Block(5,35,-2,LEAVES:1)
Block(5,35,-1,LOG:13)
Block(5,35,1,LEAVES:1)
Block(5,35,5,LEAVES:1)
Block(5,35,6,LOG:13)
Block(5,36,-9,LEAVES:1)
Block(5,36,-8,LEAVES:1)
Block(5,36,-6,LEAVES:1)
Block(5,36,-1,LOG:13)
Block(5,36,0,LEAVES:1)
Block(5,36,7,LEAVES:1)
Block(5,37,14,LEAVES:1)
Block(5,37,16,LEAVES:1)
Block(5,37,17,LEAVES:1)
Block(5,38,4,LEAVES:1)
Block(5,38,11,LEAVES:1)
Block(5,38,14,LOG:13)
Block(5,38,15,LOG:13)
Block(5,38,16,LEAVES:1)
Block(5,39,1,LEAVES:1)
Block(5,39,4,LEAVES:1)
Block(5,39,10,LEAVES:1)
Block(5,39,12,LEAVES:1)
Block(5,39,13,LOG:13)
Block(5,39,14,LEAVES:1)
Block(5,40,1,LEAVES:1)
Block(5,40,3,LEAVES:1)
Block(5,40,4,LEAVES:1)
Block(5,40,5,LEAVES:1)
Block(5,41,-3,LEAVES:1)
Block(5,41,2,LEAVES:1)
Block(5,41,3,LOG:13)
Block(5,41,4,LEAVES:1)
Block(5,42,-2,LEAVES:1)
Block(5,42,0,LEAVES:1)
Block(5,42,1,LEAVES:1)
Block(5,42,5,LEAVES:1)
Block(5,42,6,LEAVES:1)
Block(5,42,7,LEAVES:1)
Block(5,43,-1,LOG:13)
Block(5,43,0,LEAVES:1)
Block(5,43,6,LEAVES:1)
Block(5,43,7,LOG:13)
Block(5,43,8,LEAVES:1)
Block(5,47,3,LEAVES:1)
Block(5,48,6,LEAVES:1)
Block(5,48,7,LOG:13)
Block(5,48,8,LEAVES:1)
Block(5,48,9,LEAVES:1)
Block(5,48,10,LEAVES:1)
Block(5,49,3,LEAVES:1)
Block(5,49,4,LOG:13)
Block(5,49,5,LEAVES:1)
Block(5,49,8,LEAVES:1)
Block(5,50,-4,LEAVES:1)
Block(5,51,-3,LEAVES:1)
Block(5,51,-2,LOG:13)
Block(5,51,-1,LEAVES:1)
Block(5,51,0,LEAVES:1)
Block(5,51,1,LEAVES:1)
Block(5,52,-2,LEAVES:1)
Block(5,52,10,LEAVES:1)
Block(5,52,11,LEAVES:1)
Block(5,52,12,LEAVES:1)
Block(5,53,11,LEAVES:1)
Block(5,55,1,LEAVES:1)
Block(5,55,6,LEAVES:1)
Block(5,56,0,LEAVES:1)
Block(5,56,1,LEAVES:1)
Block(5,56,2,LEAVES:1)
Block(5,56,3,LEAVES:1)
Block(5,56,4,LEAVES:1)
Block(5,57,1,LEAVES:1)
Block(5,57,2,LOG:13)
Block(5,57,3,LEAVES:1)
Block(5,60,1,LEAVES:1)
Block(5,60,2,LEAVES:1)
Block(5,60,3,LEAVES:1)
Block(5,60,4,LEAVES:1)
Block(5,61,3,LEAVES:1)
Block(6,0,2,LOG:13)
Block(6,16,-6,LEAVES:1)
Block(6,16,-5,LEAVES:1)
Block(6,16,-4,LEAVES:1)
Block(6,16,-3,LEAVES:1)
Block(6,17,-5,LEAVES:1)
Block(6,17,-4,LEAVES:1)
Block(6,17,-1,LEAVES:1)
Block(6,18,-4,LOG:13)
Block(6,18,-3,LEAVES:1)
Block(6,18,-1,LEAVES:1)
Block(6,18,0,LEAVES:1)
Block(6,29,10,LEAVES:1)
Block(6,29,12,LEAVES:1)
Block(6,29,13,LEAVES:1)
Block(6,29,14,LEAVES:1)
Block(6,29,15,LEAVES:1)
Block(6,30,11,LEAVES:1)
Block(6,30,12,LOG:13)
Block(6,30,13,LEAVES:1)
Block(6,33,-5,LEAVES:1)
Block(6,33,-4,LEAVES:1)
Block(6,33,-1,LEAVES:1)
Block(6,33,5,LEAVES:1)
Block(6,33,6,LEAVES:1)
Block(6,33,7,LEAVES:1)
Block(6,33,8,LEAVES:1)
Block(6,34,-11,LEAVES:1)
Block(6,34,-9,LEAVES:1)
Block(6,34,-8,LEAVES:1)
Block(6,34,-7,LEAVES:1)
Block(6,34,-4,LEAVES:1)
Block(6,34,-1,LEAVES:1)
Block(6,34,4,LEAVES:1)
Block(6,34,6,LEAVES:1)
Block(6,34,7,LEAVES:1)
Block(6,35,-10,LEAVES:1)
Block(6,35,-9,LEAVES:1)
Block(6,35,-8,LEAVES:1)
Block(6,35,-7,LEAVES:1)
Block(6,35,-3,LEAVES:1)
Block(6,35,-2,LOG:13)
Block(6,35,-1,LEAVES:1)
Block(6,35,0,LEAVES:1)
Block(6,35,1,LEAVES:1)
Block(6,35,6,LOG:13)
Block(6,35,7,LEAVES:1)
Block(6,36,-2,LEAVES:1)
Block(6,37,13,LEAVES:1)
Block(6,37,16,LEAVES:1)
Block(6,38,6,LEAVES:1)
Block(6,38,11,LEAVES:1)
Block(6,38,12,LEAVES:1)
Block(6,38,14,LEAVES:1)
Block(6,38,15,LEAVES:1)
Block(6,39,3,LEAVES:1)
Block(6,39,13,LEAVES:1)
Block(6,40,-6,LEAVES:1)
Block(6,40,-5,LEAVES:1)
Block(6,40,-4,LEAVES:1)
Block(6,40,2,LEAVES:1)
Block(6,40,3,LOG:13)
Block(6,40,4,LEAVES:1)
Block(6,41,-3,LEAVES:1)
Block(6,41,-2,LEAVES:1)
Block(6,41,1,LEAVES:1)
Block(6,41,3,LEAVES:1)
Block(6,41,7,LEAVES:1)
Block(6,42,-3,LEAVES:1)
Block(6,42,-2,LOG:13)
Block(6,42,-1,LEAVES:1)
Block(6,42,0,LEAVES:1)
Block(6,42,6,LEAVES:1)
Block(6,42,7,LEAVES:1)
Block(6,42,8,LEAVES:1)
Block(6,42,9,LEAVES:1)
Block(6,43,-2,LEAVES:1)
Block(6,43,7,LEAVES:1)
Block(6,43,8,LEAVES:1)
Block(6,47,2,LEAVES:1)
Block(6,47,5,LEAVES:1)
Block(6,47,6,LEAVES:1)
Block(6,48,3,LEAVES:1)
Block(6,48,4,LOG:13)
Block(6,48,5,LEAVES:1)
Block(6,48,6,LEAVES:1)
Block(6,48,7,LEAVES:1)
Block(6,48,9,LEAVES:1)
Block(6,49,-4,LEAVES:1)
Block(6,49,4,LEAVES:1)
Block(6,50,-4,LEAVES:1)
Block(6,50,-1,LEAVES:1)
Block(6,50,0,LEAVES:1)
Block(6,51,-4,LEAVES:1)
Block(6,51,-3,LOG:13)
Block(6,51,-2,LEAVES:1)
Block(6,52,-3,LEAVES:1)
Block(6,52,12,LEAVES:1)
Block(6,55,-1,LEAVES:1)
Block(6,55,0,LEAVES:1)
Block(6,55,1,LEAVES:1)
Block(6,55,2,LEAVES:1)
Block(6,55,3,LEAVES:1)
Block(6,56,0,LEAVES:1)
Block(6,56,1,LOG:13)
Block(6,56,2,LEAVES:1)
Block(6,57,2,LEAVES:1)
Block(6,60,4,LEAVES:1)
Block(7,16,-7,LEAVES:1)
Block(7,16,-5,LEAVES:1)
Block(7,17,-6,LEAVES:1)
Block(7,17,-5,LOG:13)
Block(7,17,-3,LEAVES:1)
Block(7,17,-2,LEAVES:1)
Block(7,18,-5,LEAVES:1)
Block(7,18,-4,LEAVES:1)
Block(7,28,15,LEAVES:1)
Block(7,29,11,LEAVES:1)
Block(7,29,13,LEAVES:1)
Block(7,30,12,LEAVES:1)
Block(7,30,13,LOG:13)
Block(7,30,14,LEAVES:1)
Block(7,31,13,LEAVES:1)
Block(7,33,3,LEAVES:1)
Block(7,33,4,LEAVES:1)
Block(7,33,6,LEAVES:1)
Block(7,34,-11,LEAVES:1)
Block(7,34,-9,LEAVES:1)
Block(7,34,-4,LEAVES:1)
Block(7,34,-2,LEAVES:1)
Block(7,34,0,LEAVES:1)
Block(7,34,4,LEAVES:1)
Block(7,34,5,LEAVES:1)
Block(7,34,6,LOG:13)
Block(7,34,7,LEAVES:1)
Block(7,35,-3,LEAVES:1)
Block(7,35,-2,LOG:13)
Block(7,35,-1,LEAVES:1)
Block(7,35,6,LEAVES:1)
Block(7,37,14,LEAVES:1)
Block(7,37,16,LEAVES:1)
Block(7,38,6,LEAVES:1)
Block(7,38,12,LEAVES:1)
Block(7,38,13,LEAVES:1)
Block(7,39,-5,LEAVES:1)
Block(7,39,1,LEAVES:1)
Block(7,39,2,LEAVES:1)
Block(7,39,3,LEAVES:1)
Block(7,39,5,LEAVES:1)
Block(7,40,-6,LEAVES:1)
Block(7,40,2,LEAVES:1)
Block(7,40,3,LOG:13)
Block(7,40,4,LEAVES:1)
Block(7,41,-5,LEAVES:1)
Block(7,41,-4,LEAVES:1)
Block(7,41,-2,LEAVES:1)
Block(7,41,-1,LEAVES:1)
Block(7,41,0,LEAVES:1)
Block(7,42,-3,LOG:13)
Block(7,42,-2,LEAVES:1)
Block(7,42,6,LEAVES:1)
Block(7,42,8,LEAVES:1)
Block(7,47,4,LEAVES:1)
Block(7,47,5,LEAVES:1)
Block(7,47,6,LEAVES:1)
Block(7,47,7,LEAVES:1)
Block(7,48,3,LEAVES:1)
Block(7,48,4,LOG:13)
Block(7,48,5,LEAVES:1)
Block(7,49,-4,LEAVES:1)
Block(7,50,-5,LEAVES:1)
Block(7,50,-4,LEAVES:1)
Block(7,50,-3,LEAVES:1)
Block(7,50,-1,LEAVES:1)
Block(7,51,-4,LEAVES:1)
Block(7,51,-3,LOG:13)
Block(7,51,-2,LEAVES:1)
Block(7,55,1,LEAVES:1)
Block(7,55,2,LEAVES:1)
Block(7,56,0,LEAVES:1)
Block(7,56,1,LOG:13)
Block(7,56,2,LEAVES:1)
Block(8,15,-6,LEAVES:1)
Block(8,16,-7,LEAVES:1)
Block(8,16,-6,LEAVES:1)
Block(8,17,-7,LEAVES:1)
Block(8,17,-6,LOG:13)
Block(8,17,-5,LEAVES:1)
Block(8,17,-4,LEAVES:1)
Block(8,17,-3,LEAVES:1)
Block(8,28,13,LEAVES:1)
Block(8,28,15,LEAVES:1)
Block(8,28,16,LEAVES:1)
Block(8,29,14,LEAVES:1)
Block(8,30,12,LEAVES:1)
Block(8,30,13,LOG:13)
Block(8,33,-4,LEAVES:1)
Block(8,33,6,LEAVES:1)
Block(8,33,7,LEAVES:1)
Block(8,33,8,LEAVES:1)
Block(8,34,-3,LEAVES:1)
Block(8,34,-2,LOG:13)
Block(8,34,-1,LEAVES:1)
Block(8,34,4,LEAVES:1)
Block(8,34,5,LOG:13)
Block(8,34,6,LEAVES:1)
Block(8,35,-2,LEAVES:1)
Block(8,38,2,LEAVES:1)
Block(8,38,3,LEAVES:1)
Block(8,38,4,LEAVES:1)
Block(8,38,5,LEAVES:1)
Block(8,38,6,LEAVES:1)
Block(8,39,-7,LEAVES:1)
Block(8,39,-5,LEAVES:1)
Block(8,39,3,LEAVES:1)
Block(8,39,4,LOG:13)
Block(8,40,-6,LEAVES:1)
Block(8,40,-4,LEAVES:1)
Block(8,40,-2,LEAVES:1)
Block(8,40,-1,LEAVES:1)
Block(8,40,4,LEAVES:1)
Block(8,41,-5,LOG:13)
Block(8,41,-4,LOG:13)
Block(8,41,-3,LEAVES:1)
Block(8,41,-2,LEAVES:1)
Block(8,42,-4,LEAVES:1)
Block(8,47,2,LEAVES:1)
Block(8,47,3,LEAVES:1)
Block(8,47,4,LEAVES:1)
Block(8,47,5,LEAVES:1)
Block(8,47,6,LEAVES:1)
Block(8,48,4,LEAVES:1)
Block(8,49,-5,LEAVES:1)
Block(8,49,-4,LEAVES:1)
Block(8,49,-2,LEAVES:1)
Block(8,49,-1,LEAVES:1)
Block(8,49,0,LEAVES:1)
Block(8,50,-4,LEAVES:1)
Block(8,50,-3,LOG:13)
Block(8,50,-2,LEAVES:1)
Block(8,55,-1,LEAVES:1)
Block(8,55,0,LEAVES:1)
Block(8,55,1,LEAVES:1)
Block(8,55,2,LEAVES:1)
Block(8,55,3,LEAVES:1)
Block(8,56,1,LEAVES:1)
Block(9,16,-8,LEAVES:1)
Block(9,16,-7,LEAVES:1)
Block(9,16,-6,LEAVES:1)
Block(9,16,-5,LEAVES:1)
Block(9,16,-4,LEAVES:1)
Block(9,17,-6,LEAVES:1)
Block(9,28,12,LEAVES:1)
Block(9,28,13,LEAVES:1)
Block(9,28,14,LEAVES:1)
Block(9,28,15,LEAVES:1)
Block(9,29,13,LEAVES:1)
Block(9,29,14,LOG:13)
Block(9,29,15,LEAVES:1)
Block(9,32,3,LEAVES:1)
Block(9,32,4,LEAVES:1)
Block(9,32,5,LEAVES:1)
Block(9,32,6,LEAVES:1)
Block(9,32,7,LEAVES:1)
Block(9,33,-3,LEAVES:1)
Block(9,33,-2,LEAVES:1)
Block(9,33,0,LEAVES:1)
Block(9,33,4,LEAVES:1)
Block(9,33,5,LOG:13)
Block(9,33,6,LEAVES:1)
Block(9,34,-3,LEAVES:1)
Block(9,34,-2,LOG:13)
Block(9,34,-1,LEAVES:1)
Block(9,34,5,LEAVES:1)
Block(9,38,3,LEAVES:1)
Block(9,38,5,LEAVES:1)
Block(9,39,-8,LEAVES:1)
Block(9,39,-7,LEAVES:1)
Block(9,39,-6,LEAVES:1)
Block(9,39,-5,LEAVES:1)
Block(9,39,3,LEAVES:1)
Block(9,39,4,LOG:13)
Block(9,39,5,LEAVES:1)
Block(9,40,-7,LEAVES:1)
Block(9,40,-6,LOG:13)
Block(9,40,-5,LEAVES:1)
Block(9,40,-4,LEAVES:1)
Block(9,40,-3,LEAVES:1)
Block(9,41,-5,LEAVES:1)
Block(9,47,4,LEAVES:1)
Block(9,49,-4,LEAVES:1)
Block(9,49,-3,LEAVES:1)
Block(9,49,-2,LEAVES:1)
Block(9,50,-3,LEAVES:1)
Block(9,55,1,LEAVES:1)
Block(10,16,-6,LEAVES:1)
Block(10,28,13,LEAVES:1)
Block(10,28,14,LEAVES:1)
Block(10,28,15,LEAVES:1)
Block(10,28,16,LEAVES:1)
Block(10,29,14,LEAVES:1)
Block(10,32,-1,LEAVES:1)
Block(10,32,6,LEAVES:1)
Block(10,33,-4,LEAVES:1)
Block(10,33,-3,LEAVES:1)
Block(10,33,-2,LEAVES:1)
Block(10,33,-1,LEAVES:1)
Block(10,33,0,LEAVES:1)
Block(10,33,4,LEAVES:1)
Block(10,33,5,LOG:13)
Block(10,33,6,LEAVES:1)
Block(10,34,-2,LEAVES:1)
Block(10,34,-1,LOG:13)
Block(10,34,0,LEAVES:1)
Block(10,38,2,LEAVES:1)
Block(10,38,3,LEAVES:1)
Block(10,38,4,LEAVES:1)
Block(10,38,5,LOG:13)
Block(10,38,6,LEAVES:1)
Block(10,39,-7,LEAVES:1)
Block(10,39,-5,LEAVES:1)
Block(10,40,-6,LEAVES:1)
Block(10,40,-4,LEAVES:1)
Block(10,49,-4,LEAVES:1)
Block(11,28,13,LEAVES:1)
Block(11,28,15,LEAVES:1)
Block(11,32,3,LEAVES:1)
Block(11,32,4,LEAVES:1)
