
#######################################################################
# +-----------------------------------------------------------------+ #
# |                            BO3 object                           | #
# +-----------------------------------------------------------------+ #
#######################################################################

# This is the config file of a custom object.
# If you add this object correctly to your BiomeConfigs, it will spawn in the world.

# This is the creator of this BO3 object
Author: Unknown

# A short description of this BO3 object
Description: No description given

# The BO3 version, don't change this! It can be used by external applications to do a version check.
Version: 3

# The settings mode, WriteAll, WriteWithoutComments or WriteDisable. See WorldConfig.
SettingsMode: WriteDisable


#######################################################################
# +-----------------------------------------------------------------+ #
# |                          Main settings                          | #
# +-----------------------------------------------------------------+ #
#######################################################################

# This needs to be set to true to spawn the object in the Tree and Sapling resources.
Tree: true

# The frequency of the BO3 from 1 to 200. Tries this many times to spawn this BO3 when using the CustomObject(...) resource.
# Ignored by Tree(..), Sapling(..) and CustomStructure(..)
Frequency: 0

# The rarity of the BO3 from 0 to 100. Each spawn attempt has rarity% chance to succeed when using the CustomObject(...) resource.
# Ignored by Tree(..), Sapling(..) and CustomStructure(..)
Rarity: 100.0

# If you set this to true, the BO3 will be placed with a random rotation.
RotateRandomly: true

# The spawn height of the BO3: randomY, highestBlock or highestSolidBlock.
SpawnHeight: highestSolidBlock

# The offset from the spawn height to spawn this BO3
# Ex. SpawnHeight = highestSolidBlock, SpawnHeightOffset = 3; This object will spawn 3 blocks above the highest solid block
SpawnHeightOffset: 0

# A random amount to offset the spawn location from the spawn offset height
# Ex. SpawnHeightOffset = 3, SpawnHeightVariance = 3; This object will spawn 3 to 6 blocks above the original spot it would have spawned
SpawnHeightVariance: 0

##############################
# Height Limits for the BO3. #
##############################

# When in randomY mode used as the minimum Y or in atMinY mode as the actual Y to spawn this BO3 at.
MinHeight: 61

# When in randomY mode used as the maximum Y to spawn this BO3 at.
MaxHeight: 256

######################
# Extrusion settings #
######################

# The style of extrusion you wish to use - BottomDown, TopUp, None (Default)
ExtrudeMode: BottomDown

# The blocks to extrude your BO3 through
ExtrudeThroughBlocks: AIR,STATIONARY_WATER

# Objects can have other objects attacthed to it: branches. Branches can also
# have branches attached to it, which can also have branches, etc. This is the
# maximum branch depth for this objects.
MaxBranchDepth: 10

# When spawned with the UseWorld keyword, this BO3 should NOT spawn in the following biomes.
# If you write the BO3 name directly in the BiomeConfigs, this will be ignored.
ExcludedBiomes: All


#######################################################################
# +-----------------------------------------------------------------+ #
# |                      Source block settings                      | #
# +-----------------------------------------------------------------+ #
#######################################################################

# The block(s) the BO3 should spawn in.
SourceBlocks: AIR

# The maximum percentage of the BO3 that can be outside the SourceBlock.
# The BO3 won't be placed on a location with more blocks outside the SourceBlock than this percentage.
MaxPercentageOutsideSourceBlock: 100

# What to do when a block is about to be placed outside the SourceBlock? (dontPlace, placeAnyway)
OutsideSourceBlock: placeAnyway

# OTG+ settings #
# Legacy setting, rename this file to .BO4 instead. Set this to true to enable the advanced customstructure features of OTG+.
IsOTGPlus: false


#######################################################################
# +-----------------------------------------------------------------+ #
# |                              Blocks                             | #
# +-----------------------------------------------------------------+ #
#######################################################################

# All the blocks used in the BO3 are listed here. Possible blocks:
# Block(x,y,z,id[.data][,nbtfile.nbt)
# RandomBlock(x,y,z,id[:data][,nbtfile.nbt],chance[,id[:data][,nbtfile.nbt],chance[,...]])
#  So RandomBlock(0,0,0,CHEST,chest.nbt,50,CHEST,anotherchest.nbt,100) will spawn a chest at
#  the BO3 origin, and give it a 50% chance to have the contents of chest.nbt, or, if that
#  fails, a 100% percent chance to have the contents of anotherchest.nbt.
# *Note: Unlike Entity() and Spawner(), for Block() .txt files don't work, only .nbt files work.
# MinecraftObject(x,y,z,name) (TODO: This may not work anymore and needs to be tested.
#  Spawns an object in the Mojang NBT structure format. For example, 
#  MinecraftObject(0,0,0,minecraft:igloo/igloo_bottom)
#  spawns the bottom part of an igloo.
Block(-11,29,7,LEAVES:1)
Block(-11,29,9,LEAVES:1)
Block(-10,29,7,LEAVES:1)
Block(-10,29,9,LEAVES:1)
Block(-10,29,10,LEAVES:1)
Block(-10,30,6,LEAVES:1)
Block(-10,30,7,LEAVES:1)
Block(-10,30,8,LEAVES:1)
Block(-9,29,8,LEAVES:1)
Block(-9,29,9,LEAVES:1)
Block(-9,30,7,LEAVES:1)
Block(-9,30,8,LOG:13)
Block(-9,30,9,LEAVES:1)
Block(-9,31,7,LEAVES:1)
Block(-9,31,8,LEAVES:1)
Block(-9,41,-8,LEAVES:1)
Block(-9,41,-6,LEAVES:1)
Block(-9,49,1,LEAVES:1)
Block(-8,29,8,LEAVES:1)
Block(-8,29,9,LEAVES:1)
Block(-8,30,5,LEAVES:1)
Block(-8,30,6,LEAVES:1)
Block(-8,30,8,LEAVES:1)
Block(-8,31,6,LEAVES:1)
Block(-8,31,7,LOG:13)
Block(-8,41,-8,LEAVES:1)
Block(-8,41,-6,LEAVES:1)
Block(-8,41,-5,LEAVES:1)
Block(-8,42,-7,LEAVES:1)
Block(-8,49,-1,LEAVES:1)
Block(-8,49,0,LEAVES:1)
Block(-8,49,1,LEAVES:1)
Block(-8,49,3,LEAVES:1)
Block(-8,50,1,LEAVES:1)
Block(-7,20,-11,LEAVES:1)
Block(-7,30,8,LEAVES:1)
Block(-7,31,4,LEAVES:1)
Block(-7,31,5,LEAVES:1)
Block(-7,31,6,LEAVES:1)
Block(-7,31,7,LOG:13)
Block(-7,31,8,LEAVES:1)
Block(-7,32,7,LEAVES:1)
Block(-7,40,-6,LEAVES:1)
Block(-7,41,-9,LEAVES:1)
Block(-7,41,-8,LEAVES:1)
Block(-7,41,-7,LEAVES:1)
Block(-7,41,-6,LEAVES:1)
Block(-7,41,-5,LEAVES:1)
Block(-7,41,-4,LEAVES:1)
Block(-7,42,-8,LEAVES:1)
Block(-7,42,-7,LOG:13)
Block(-7,42,-6,LEAVES:1)
Block(-7,46,7,LEAVES:1)
Block(-7,46,9,LEAVES:1)
Block(-7,49,2,LEAVES:1)
Block(-7,49,3,LEAVES:1)
Block(-7,50,0,LEAVES:1)
Block(-7,50,1,LOG:13)
Block(-7,50,2,LEAVES:1)
Block(-7,52,-7,LEAVES:1)
Block(-6,19,-11,LEAVES:1)
Block(-6,20,-13,LEAVES:1)
Block(-6,20,-12,LEAVES:1)
Block(-6,20,-11,LEAVES:1)
Block(-6,20,-9,LEAVES:1)
Block(-6,20,-8,LEAVES:1)
Block(-6,21,-11,LEAVES:1)
Block(-6,21,-10,LEAVES:1)
Block(-6,30,8,LEAVES:1)
Block(-6,30,9,LEAVES:1)
Block(-6,31,5,LEAVES:1)
Block(-6,31,6,LOG:13)
Block(-6,31,7,LEAVES:1)
Block(-6,32,3,LEAVES:1)
Block(-6,32,5,LEAVES:1)
Block(-6,32,6,LOG:13)
Block(-6,41,-8,LEAVES:1)
Block(-6,41,-6,LEAVES:1)
Block(-6,41,-4,LEAVES:1)
Block(-6,41,-3,LEAVES:1)
Block(-6,42,-7,LEAVES:1)
Block(-6,42,-6,LOG:13)
Block(-6,42,-5,LEAVES:1)
Block(-6,43,-6,LEAVES:1)
Block(-6,46,6,LEAVES:1)
Block(-6,46,7,LEAVES:1)
Block(-6,46,8,LEAVES:1)
Block(-6,46,9,LEAVES:1)
Block(-6,47,8,LEAVES:1)
Block(-6,49,-1,LEAVES:1)
Block(-6,49,0,LEAVES:1)
Block(-6,50,0,LEAVES:1)
Block(-6,50,1,LEAVES:1)
Block(-6,50,2,LEAVES:1)
Block(-6,50,3,LEAVES:1)
Block(-6,51,0,LEAVES:1)
Block(-6,51,1,LOG:13)
Block(-6,51,2,LEAVES:1)
Block(-6,52,-8,LEAVES:1)
Block(-6,52,-7,LEAVES:1)
Block(-6,52,-6,LEAVES:1)
Block(-6,52,-5,LEAVES:1)
Block(-6,53,-6,LEAVES:1)
Block(-5,20,-12,LEAVES:1)
Block(-5,20,-10,LEAVES:1)
Block(-5,20,-9,LEAVES:1)
Block(-5,20,-7,LEAVES:1)
Block(-5,20,-6,LEAVES:1)
Block(-5,21,-12,LEAVES:1)
Block(-5,21,-11,LOG:13)
Block(-5,21,-10,LOG:13)
Block(-5,21,-9,LEAVES:1)
Block(-5,21,-8,LEAVES:1)
Block(-5,21,-7,LEAVES:1)
Block(-5,22,-10,LEAVES:1)
Block(-5,22,-8,LEAVES:1)
Block(-5,30,4,LEAVES:1)
Block(-5,30,7,LEAVES:1)
Block(-5,31,3,LEAVES:1)
Block(-5,31,4,LEAVES:1)
Block(-5,31,5,LEAVES:1)
Block(-5,32,3,LEAVES:1)
Block(-5,32,4,LEAVES:1)
Block(-5,32,5,LOG:13)
Block(-5,32,6,LEAVES:1)
Block(-5,33,4,LEAVES:1)
Block(-5,33,5,LEAVES:1)
Block(-5,41,-8,LEAVES:1)
Block(-5,41,-7,LEAVES:1)
Block(-5,41,-5,LEAVES:1)
Block(-5,41,-4,LEAVES:1)
Block(-5,42,-7,LEAVES:1)
Block(-5,42,-6,LEAVES:1)
Block(-5,42,-5,LOG:13)
Block(-5,42,-4,LEAVES:1)
Block(-5,42,-2,LEAVES:1)
Block(-5,42,-1,LEAVES:1)
Block(-5,43,-5,LOG:13)
Block(-5,46,9,LEAVES:1)
Block(-5,46,10,LEAVES:1)
Block(-5,47,5,LEAVES:1)
Block(-5,47,6,LEAVES:1)
Block(-5,47,7,LEAVES:1)
Block(-5,47,8,LOG:13)
Block(-5,47,9,LEAVES:1)
Block(-5,48,8,LEAVES:1)
Block(-5,50,-1,LEAVES:1)
Block(-5,50,0,LEAVES:1)
Block(-5,51,0,LEAVES:1)
Block(-5,51,1,LOG:13)
Block(-5,51,2,LEAVES:1)
Block(-5,52,1,LEAVES:1)
Block(-5,53,-7,LEAVES:1)
Block(-5,53,-6,LOG:13)
Block(-5,53,-3,LEAVES:1)
Block(-5,54,-5,LEAVES:1)
Block(-4,0,-1,LOG:13)
Block(-4,0,0,LOG:13)
Block(-4,1,0,LOG:13)
Block(-4,19,-12,LEAVES:1)
Block(-4,20,-13,LEAVES:1)
Block(-4,20,-12,LEAVES:1)
Block(-4,20,-11,LEAVES:1)
Block(-4,21,-11,LEAVES:1)
Block(-4,21,-10,LEAVES:1)
Block(-4,21,-6,LEAVES:1)
Block(-4,22,-9,LOG:13)
Block(-4,22,-8,LOG:13)
Block(-4,22,-7,LEAVES:1)
Block(-4,23,-8,LEAVES:1)
Block(-4,29,10,LEAVES:1)
Block(-4,30,7,LEAVES:1)
Block(-4,30,8,LEAVES:1)
Block(-4,31,5,LEAVES:1)
Block(-4,31,6,LEAVES:1)
Block(-4,32,2,LEAVES:1)
Block(-4,32,4,LEAVES:1)
Block(-4,33,3,LEAVES:1)
Block(-4,33,4,LOG:13)
Block(-4,41,-7,LEAVES:1)
Block(-4,41,-4,LEAVES:1)
Block(-4,42,-4,LEAVES:1)
Block(-4,42,-2,LEAVES:1)
Block(-4,42,0,LEAVES:1)
Block(-4,42,1,LEAVES:1)
Block(-4,43,-5,LEAVES:1)
Block(-4,43,-4,LOG:13)
Block(-4,43,-3,LEAVES:1)
Block(-4,43,-1,LEAVES:1)
Block(-4,43,0,LEAVES:1)
Block(-4,44,-4,LEAVES:1)
Block(-4,46,6,LEAVES:1)
Block(-4,46,8,LEAVES:1)
Block(-4,46,9,LEAVES:1)
Block(-4,47,6,LEAVES:1)
Block(-4,47,7,LEAVES:1)
Block(-4,47,8,LEAVES:1)
Block(-4,48,4,LEAVES:1)
Block(-4,48,6,LEAVES:1)
Block(-4,48,7,LOG:13)
Block(-4,50,2,LEAVES:1)
Block(-4,50,3,LEAVES:1)
Block(-4,51,-1,LEAVES:1)
Block(-4,51,1,LEAVES:1)
Block(-4,51,2,LEAVES:1)
Block(-4,52,-8,LEAVES:1)
Block(-4,52,1,LOG:13)
Block(-4,52,2,LEAVES:1)
Block(-4,53,-8,LEAVES:1)
Block(-4,53,-7,LEAVES:1)
Block(-4,53,-6,LEAVES:1)
Block(-4,53,-5,LEAVES:1)
Block(-4,53,-3,LEAVES:1)
Block(-4,54,-6,LEAVES:1)
Block(-4,54,-5,LOG:13)
Block(-4,54,-4,LEAVES:1)
Block(-4,54,-3,LEAVES:1)
Block(-4,54,-1,LEAVES:1)
Block(-4,56,3,LEAVES:1)
Block(-3,0,-4,LOG:13)
Block(-3,0,-2,LOG:13)
Block(-3,0,-1,LOG:13)
Block(-3,0,1,LOG:13)
Block(-3,0,2,LOG:13)
Block(-3,1,-2,LOG:13)
Block(-3,1,-1,LOG:13)
Block(-3,1,0,LOG:13)
Block(-3,1,1,LOG:13)
Block(-3,2,-1,LOG:13)
Block(-3,2,0,LOG:13)
Block(-3,3,0,LOG:13)
Block(-3,20,-11,LEAVES:1)
Block(-3,21,-9,LEAVES:1)
Block(-3,21,-7,LEAVES:1)
Block(-3,21,-6,LEAVES:1)
Block(-3,22,-9,LEAVES:1)
Block(-3,22,-8,LEAVES:1)
Block(-3,22,-7,LOG:13)
Block(-3,22,-6,LEAVES:1)
Block(-3,22,-5,LEAVES:1)
Block(-3,22,-4,LEAVES:1)
Block(-3,22,-3,LEAVES:1)
Block(-3,23,-7,LOG:13)
Block(-3,23,-6,LEAVES:1)
Block(-3,23,-4,LEAVES:1)
Block(-3,28,10,LEAVES:1)
Block(-3,28,11,LEAVES:1)
Block(-3,29,8,LEAVES:1)
Block(-3,29,10,LEAVES:1)
Block(-3,30,6,LEAVES:1)
Block(-3,30,7,LOG:13)
Block(-3,30,8,LOG:13)
Block(-3,30,9,LEAVES:1)
Block(-3,31,2,LEAVES:1)
Block(-3,31,3,LEAVES:1)
Block(-3,31,4,LEAVES:1)
Block(-3,31,5,LOG:13)
Block(-3,31,6,LOG:13)
Block(-3,31,7,LEAVES:1)
Block(-3,32,0,LEAVES:1)
Block(-3,32,1,LEAVES:1)
Block(-3,32,2,LEAVES:1)
Block(-3,32,3,LEAVES:1)
Block(-3,32,4,LOG:13)
Block(-3,32,5,LEAVES:1)
Block(-3,33,1,LEAVES:1)
Block(-3,33,2,LEAVES:1)
Block(-3,33,3,LOG:13)
Block(-3,33,4,LEAVES:1)
Block(-3,34,2,LEAVES:1)
Block(-3,41,-5,LEAVES:1)
Block(-3,42,-6,LEAVES:1)
Block(-3,42,-5,LEAVES:1)
Block(-3,42,-4,LEAVES:1)
Block(-3,42,-3,LEAVES:1)
Block(-3,42,-2,LEAVES:1)
Block(-3,43,-4,LEAVES:1)
Block(-3,43,-2,LEAVES:1)
Block(-3,43,-1,LOG:13)
Block(-3,43,0,LEAVES:1)
Block(-3,43,1,LEAVES:1)
Block(-3,44,-4,LEAVES:1)
Block(-3,44,-3,LOG:13)
Block(-3,44,-2,LEAVES:1)
Block(-3,44,1,LEAVES:1)
Block(-3,46,9,LEAVES:1)
Block(-3,47,5,LEAVES:1)
Block(-3,47,6,LEAVES:1)
Block(-3,47,7,LEAVES:1)
Block(-3,47,8,LEAVES:1)
Block(-3,48,3,LEAVES:1)
Block(-3,48,4,LEAVES:1)
Block(-3,48,5,LEAVES:1)
Block(-3,48,6,LOG:13)
Block(-3,48,7,LEAVES:1)
Block(-3,49,4,LEAVES:1)
Block(-3,49,5,LEAVES:1)
Block(-3,49,6,LEAVES:1)
Block(-3,50,-2,LEAVES:1)
Block(-3,50,-1,LEAVES:1)
Block(-3,50,0,LEAVES:1)
Block(-3,51,-1,LEAVES:1)
Block(-3,51,2,LEAVES:1)
Block(-3,51,3,LEAVES:1)
Block(-3,52,-6,LEAVES:1)
Block(-3,52,0,LEAVES:1)
Block(-3,52,1,LOG:13)
Block(-3,52,2,LEAVES:1)
Block(-3,53,-6,LEAVES:1)
Block(-3,53,1,LEAVES:1)
Block(-3,54,-5,LEAVES:1)
Block(-3,54,-4,LOG:13)
Block(-3,54,-1,LEAVES:1)
Block(-3,54,0,LEAVES:1)
Block(-3,55,-3,LEAVES:1)
Block(-3,55,-2,LEAVES:1)
Block(-3,55,-1,LEAVES:1)
Block(-3,56,2,LEAVES:1)
Block(-3,56,3,LEAVES:1)
Block(-3,56,4,LEAVES:1)
Block(-3,56,5,LEAVES:1)
Block(-3,57,3,LEAVES:1)
Block(-3,57,4,LEAVES:1)
Block(-2,0,-4,LOG:13)
Block(-2,0,-3,LOG:13)
Block(-2,0,-2,LOG:13)
Block(-2,0,0,LOG:13)
Block(-2,0,2,LOG:13)
Block(-2,0,3,LOG:13)
Block(-2,1,-4,LOG:13)
Block(-2,1,-3,LOG:13)
Block(-2,1,-2,LOG:13)
Block(-2,1,-1,LOG:13)
Block(-2,1,0,LOG:13)
Block(-2,1,1,LOG:13)
Block(-2,1,2,LOG:13)
Block(-2,2,-2,LOG:13)
Block(-2,2,-1,LOG:13)
Block(-2,2,0,LOG:13)
Block(-2,2,1,LOG:13)
Block(-2,2,2,LOG:13)
Block(-2,3,-2,LOG:13)
Block(-2,3,-1,LOG:13)
Block(-2,3,0,LOG:13)
Block(-2,3,1,LOG:13)
Block(-2,4,-2,LOG:13)
Block(-2,4,-1,LOG:13)
Block(-2,4,0,LOG:13)
Block(-2,4,1,LOG:13)
Block(-2,5,-1,LOG:13)
Block(-2,5,0,LOG:13)
Block(-2,5,1,LOG:13)
Block(-2,6,-1,LOG:13)
Block(-2,6,0,LOG:13)
Block(-2,6,1,LOG:13)
Block(-2,7,-1,LOG:13)
Block(-2,7,0,LOG:13)
Block(-2,8,-1,LOG:13)
Block(-2,8,0,LOG:13)
Block(-2,9,-1,LOG:13)
Block(-2,9,0,LOG:13)
Block(-2,10,-1,LOG:13)
Block(-2,10,0,LOG:13)
Block(-2,11,-1,LOG:13)
Block(-2,11,0,LOG:13)
Block(-2,12,-1,LOG:13)
Block(-2,12,0,LOG:13)
Block(-2,13,-1,LOG:13)
Block(-2,13,0,LOG:13)
Block(-2,14,-1,LOG:13)
Block(-2,14,0,LOG:13)
Block(-2,15,-1,LOG:13)
Block(-2,15,0,LOG:13)
Block(-2,16,-1,LOG:13)
Block(-2,16,0,LOG:13)
Block(-2,17,-1,LOG:13)
Block(-2,17,0,LOG:13)
Block(-2,18,0,LOG:13)
Block(-2,19,0,LOG:13)
Block(-2,20,0,LOG:13)
Block(-2,21,-9,LEAVES:1)
Block(-2,21,0,LOG:13)
Block(-2,22,-8,LEAVES:1)
Block(-2,22,-7,LEAVES:1)
Block(-2,22,-6,LEAVES:1)
Block(-2,22,0,LOG:13)
Block(-2,23,-7,LEAVES:1)
Block(-2,23,-6,LOG:13)
Block(-2,23,-5,LEAVES:1)
Block(-2,23,-4,LEAVES:1)
Block(-2,23,3,LEAVES:1)
Block(-2,24,-6,LEAVES:1)
Block(-2,24,-5,LEAVES:1)
Block(-2,29,7,LEAVES:1)
Block(-2,29,8,LEAVES:1)
Block(-2,29,9,LOG:13)
Block(-2,29,10,LEAVES:1)
Block(-2,30,6,LEAVES:1)
Block(-2,30,7,LEAVES:1)
Block(-2,30,8,LEAVES:1)
Block(-2,31,1,LEAVES:1)
Block(-2,31,3,LEAVES:1)
Block(-2,31,4,LEAVES:1)
Block(-2,31,5,LEAVES:1)
Block(-2,31,6,LEAVES:1)
Block(-2,32,2,LEAVES:1)
Block(-2,32,3,LEAVES:1)
Block(-2,32,4,LEAVES:1)
Block(-2,33,2,LOG:13)
Block(-2,33,3,LEAVES:1)
Block(-2,34,0,LEAVES:1)
Block(-2,34,2,LOG:13)
Block(-2,35,1,LEAVES:1)
Block(-2,42,-5,LEAVES:1)
Block(-2,42,-4,LEAVES:1)
Block(-2,42,0,LEAVES:1)
Block(-2,43,-3,LEAVES:1)
Block(-2,43,-2,LEAVES:1)
Block(-2,43,-1,LEAVES:1)
Block(-2,44,-3,LEAVES:1)
Block(-2,44,-2,LOG:13)
Block(-2,45,-2,LEAVES:1)
Block(-2,45,0,LEAVES:1)
Block(-2,47,6,LEAVES:1)
Block(-2,47,7,LEAVES:1)
Block(-2,47,8,LEAVES:1)
Block(-2,48,4,LEAVES:1)
Block(-2,48,6,LEAVES:1)
Block(-2,49,2,LEAVES:1)
Block(-2,49,3,LEAVES:1)
Block(-2,49,4,LOG:13)
Block(-2,49,5,LOG:13)
Block(-2,50,4,LEAVES:1)
Block(-2,51,-1,LEAVES:1)
Block(-2,52,-2,LEAVES:1)
Block(-2,52,-1,LEAVES:1)
Block(-2,52,0,LEAVES:1)
Block(-2,53,-6,LEAVES:1)
Block(-2,53,-1,LEAVES:1)
Block(-2,53,0,LOG:13)
Block(-2,53,1,LEAVES:1)
Block(-2,54,-3,LEAVES:1)
Block(-2,55,-4,LEAVES:1)
Block(-2,55,-3,LOG:13)
Block(-2,55,-2,LOG:13)
Block(-2,55,-1,LEAVES:1)
Block(-2,56,-3,LEAVES:1)
Block(-2,56,3,LEAVES:1)
Block(-2,57,1,LEAVES:1)
Block(-2,57,3,LOG:13)
Block(-2,57,4,LEAVES:1)
Block(-2,58,2,LEAVES:1)
Block(-2,58,3,LEAVES:1)
Block(-1,0,-5,LOG:13)
Block(-1,0,-4,LOG:13)
Block(-1,0,-3,LOG:13)
Block(-1,0,-2,LOG:13)
Block(-1,0,-1,LOG:13)
Block(-1,0,0,LOG:13)
Block(-1,0,1,LOG:13)
Block(-1,0,3,LOG:13)
Block(-1,1,-4,LOG:13)
Block(-1,1,-3,LOG:13)
Block(-1,1,-2,LOG:13)
Block(-1,1,-1,LOG:13)
Block(-1,1,0,LOG:13)
Block(-1,1,1,LOG:13)
Block(-1,1,2,LOG:13)
Block(-1,1,3,LOG:13)
Block(-1,2,-4,LOG:13)
Block(-1,2,-3,LOG:13)
Block(-1,2,0,LOG:13)
Block(-1,2,1,LOG:13)
Block(-1,2,2,LOG:13)
Block(-1,3,-4,LOG:13)
Block(-1,3,-3,LOG:13)
Block(-1,3,-2,LOG:13)
Block(-1,3,0,LOG:13)
Block(-1,3,1,LOG:13)
Block(-1,3,2,LOG:13)
Block(-1,4,-3,LOG:13)
Block(-1,4,-2,LOG:13)
Block(-1,4,1,LOG:13)
Block(-1,4,2,LOG:13)
Block(-1,5,-3,LOG:13)
Block(-1,5,-2,LOG:13)
Block(-1,5,1,LOG:13)
Block(-1,5,2,LOG:13)
Block(-1,6,-3,LOG:13)
Block(-1,6,-2,LOG:13)
Block(-1,6,-1,LOG:13)
Block(-1,6,1,LOG:13)
Block(-1,6,2,LOG:13)
Block(-1,7,-3,LOG:13)
Block(-1,7,-2,LOG:13)
Block(-1,7,-1,LOG:13)
Block(-1,7,0,LOG:13)
Block(-1,7,1,LOG:13)
Block(-1,7,2,LOG:13)
Block(-1,8,-3,LOG:13)
Block(-1,8,-2,LOG:13)
Block(-1,8,-1,LOG:13)
Block(-1,8,0,LOG:13)
Block(-1,8,1,LOG:13)
Block(-1,8,2,LOG:13)
Block(-1,9,-3,LOG:13)
Block(-1,9,-2,LOG:13)
Block(-1,9,-1,LOG:13)
Block(-1,9,0,LOG:13)
Block(-1,9,1,LOG:13)
Block(-1,9,2,LOG:13)
Block(-1,10,-2,LOG:13)
Block(-1,10,-1,LOG:13)
Block(-1,10,0,LOG:13)
Block(-1,10,1,LOG:13)
Block(-1,10,2,LOG:13)
Block(-1,11,-2,LOG:13)
Block(-1,11,-1,LOG:13)
Block(-1,11,0,LOG:13)
Block(-1,11,1,LOG:13)
Block(-1,11,2,LOG:13)
Block(-1,12,-2,LOG:13)
Block(-1,12,-1,LOG:13)
Block(-1,12,0,LOG:13)
Block(-1,12,1,LOG:13)
Block(-1,12,2,LOG:13)
Block(-1,13,-2,LOG:13)
Block(-1,13,-1,LOG:13)
Block(-1,13,0,LOG:13)
Block(-1,13,1,LOG:13)
Block(-1,13,2,LOG:13)
Block(-1,14,-2,LOG:13)
Block(-1,14,-1,LOG:13)
Block(-1,14,0,LOG:13)
Block(-1,14,1,LOG:13)
Block(-1,14,2,LOG:13)
Block(-1,15,-2,LOG:13)
Block(-1,15,-1,LOG:13)
Block(-1,15,0,LOG:13)
Block(-1,15,1,LOG:13)
Block(-1,15,2,LOG:13)
Block(-1,16,-2,LOG:13)
Block(-1,16,-1,LOG:13)
Block(-1,16,0,LOG:13)
Block(-1,16,1,LOG:13)
Block(-1,17,-2,LOG:13)
Block(-1,17,-1,LOG:13)
Block(-1,17,0,LOG:13)
Block(-1,17,1,LOG:13)
Block(-1,18,-2,LOG:13)
Block(-1,18,-1,LOG:13)
Block(-1,18,0,LOG:13)
Block(-1,18,1,LOG:13)
Block(-1,19,-2,LOG:13)
Block(-1,19,-1,LOG:13)
Block(-1,19,0,LOG:13)
Block(-1,19,1,LOG:13)
Block(-1,20,-2,LOG:13)
Block(-1,20,-1,LOG:13)
Block(-1,20,0,LOG:13)
Block(-1,20,1,LOG:13)
Block(-1,21,-7,LEAVES:1)
Block(-1,21,-2,LOG:13)
Block(-1,21,-1,LOG:13)
Block(-1,21,0,LOG:13)
Block(-1,21,1,LOG:13)
Block(-1,22,-8,LEAVES:1)
Block(-1,22,-7,LEAVES:1)
Block(-1,22,-6,LEAVES:1)
Block(-1,22,-3,LEAVES:1)
Block(-1,22,-2,LOG:13)
Block(-1,22,-1,LOG:13)
Block(-1,22,0,LOG:13)
Block(-1,22,1,LOG:13)
Block(-1,23,-6,LEAVES:1)
Block(-1,23,-2,LOG:13)
Block(-1,23,-1,LOG:13)
Block(-1,23,0,LOG:13)
Block(-1,23,1,LOG:13)
Block(-1,23,3,LEAVES:1)
Block(-1,23,4,LEAVES:1)
Block(-1,23,5,LEAVES:1)
Block(-1,23,7,LEAVES:1)
Block(-1,24,-5,LOG:13)
Block(-1,24,-4,LEAVES:1)
Block(-1,24,-3,LEAVES:1)
Block(-1,24,-2,LOG:13)
Block(-1,24,-1,LOG:13)
Block(-1,24,0,LOG:13)
Block(-1,24,1,LOG:13)
Block(-1,24,2,LEAVES:1)
Block(-1,24,4,LEAVES:1)
Block(-1,25,-2,LOG:13)
Block(-1,25,-1,LOG:13)
Block(-1,25,0,LOG:13)
Block(-1,25,1,LOG:13)
Block(-1,26,-2,LOG:13)
Block(-1,26,-1,LOG:13)
Block(-1,26,0,LOG:13)
Block(-1,26,1,LOG:13)
Block(-1,27,-1,LOG:13)
Block(-1,27,0,LOG:13)
Block(-1,27,1,LOG:13)
Block(-1,28,-1,LOG:13)
Block(-1,28,0,LOG:13)
Block(-1,28,1,LOG:13)
Block(-1,28,7,LEAVES:1)
Block(-1,28,9,LEAVES:1)
Block(-1,28,10,LEAVES:1)
Block(-1,28,11,LEAVES:1)
Block(-1,29,-1,LOG:13)
Block(-1,29,0,LOG:13)
Block(-1,29,1,LOG:13)
Block(-1,29,6,LEAVES:1)
Block(-1,29,7,LEAVES:1)
Block(-1,29,8,LEAVES:1)
Block(-1,29,9,LEAVES:1)
Block(-1,30,-1,LOG:13)
Block(-1,30,0,LOG:13)
Block(-1,30,1,LOG:13)
Block(-1,30,5,LEAVES:1)
Block(-1,30,6,LEAVES:1)
Block(-1,31,-1,LOG:13)
Block(-1,31,0,LOG:13)
Block(-1,31,1,LOG:13)
Block(-1,31,4,LEAVES:1)
Block(-1,32,-1,LOG:13)
Block(-1,32,0,LOG:13)
Block(-1,32,1,LOG:13)
Block(-1,32,4,LEAVES:1)
Block(-1,33,-1,LOG:13)
Block(-1,33,0,LOG:13)
Block(-1,33,1,LEAVES:1)
Block(-1,34,-1,LOG:13)
Block(-1,34,0,LOG:13)
Block(-1,34,1,LOG:13)
Block(-1,34,2,LEAVES:1)
Block(-1,35,-1,LOG:13)
Block(-1,35,0,LOG:13)
Block(-1,35,1,LOG:13)
Block(-1,36,-1,LOG:13)
Block(-1,36,0,LOG:13)
Block(-1,36,1,LEAVES:1)
Block(-1,37,-1,LOG:13)
Block(-1,37,0,LOG:13)
Block(-1,38,-1,LOG:13)
Block(-1,38,0,LOG:13)
Block(-1,39,-1,LOG:13)
Block(-1,39,0,LOG:13)
Block(-1,40,0,LOG:13)
Block(-1,41,0,LOG:13)
Block(-1,41,1,LEAVES:1)
Block(-1,42,0,LOG:13)
Block(-1,43,-3,LEAVES:1)
Block(-1,43,0,LOG:13)
Block(-1,44,-1,LOG:13)
Block(-1,44,0,LOG:13)
Block(-1,44,1,LEAVES:1)
Block(-1,45,-2,LEAVES:1)
Block(-1,45,-1,LOG:13)
Block(-1,45,0,LOG:13)
Block(-1,46,0,LEAVES:1)
Block(-1,47,5,LEAVES:1)
Block(-1,47,7,LEAVES:1)
Block(-1,48,1,LEAVES:1)
Block(-1,48,4,LEAVES:1)
Block(-1,48,5,LEAVES:1)
Block(-1,48,6,LEAVES:1)
Block(-1,49,-1,LEAVES:1)
Block(-1,49,3,LOG:13)
Block(-1,49,4,LEAVES:1)
Block(-1,49,5,LEAVES:1)
Block(-1,50,-5,LEAVES:1)
Block(-1,50,-3,LEAVES:1)
Block(-1,50,-2,LEAVES:1)
Block(-1,50,1,LEAVES:1)
Block(-1,50,2,LEAVES:1)
Block(-1,51,-2,LEAVES:1)
Block(-1,51,0,LEAVES:1)
Block(-1,52,1,LEAVES:1)
Block(-1,52,2,LEAVES:1)
Block(-1,53,-1,LEAVES:1)
Block(-1,53,0,LOG:13)
Block(-1,53,1,LEAVES:1)
Block(-1,54,-5,LEAVES:1)
Block(-1,54,-4,LEAVES:1)
Block(-1,54,-3,LEAVES:1)
Block(-1,54,1,LEAVES:1)
Block(-1,54,3,LEAVES:1)
Block(-1,55,-4,LEAVES:1)
Block(-1,55,-2,LEAVES:1)
Block(-1,55,0,LEAVES:1)
Block(-1,56,-5,LEAVES:1)
Block(-1,56,-3,LEAVES:1)
Block(-1,56,-2,LOG:13)
Block(-1,56,-1,LEAVES:1)
Block(-1,57,-3,LEAVES:1)
Block(-1,57,-2,LEAVES:1)
Block(-1,57,0,LEAVES:1)
Block(-1,57,3,LEAVES:1)
Block(-1,58,1,LEAVES:1)
Block(-1,58,2,LOG:13)
Block(-1,61,-1,LEAVES:1)
Block(-1,61,0,LEAVES:1)
Block(0,0,-5,LOG:13)
Block(0,0,-4,LOG:13)
Block(0,0,-3,LOG:13)
Block(0,0,-2,LOG:13)
Block(0,0,-1,LOG:13)
Block(0,0,0,LOG:13)
Block(0,0,1,LOG:13)
Block(0,0,2,LOG:13)
Block(0,0,3,LOG:13)
Block(0,0,4,LOG:13)
Block(0,1,-5,LOG:13)
Block(0,1,-4,LOG:13)
Block(0,1,-3,LOG:13)
Block(0,1,1,LOG:13)
Block(0,1,2,LOG:13)
Block(0,1,3,LOG:13)
Block(0,2,-4,LOG:13)
Block(0,2,-3,LOG:13)
Block(0,2,1,LOG:13)
Block(0,2,2,LOG:13)
Block(0,2,3,LOG:13)
Block(0,3,-4,LOG:13)
Block(0,3,-3,LOG:13)
Block(0,3,2,LOG:13)
Block(0,3,3,LOG:13)
Block(0,4,-4,LOG:13)
Block(0,4,-3,LOG:13)
Block(0,4,2,LOG:13)
Block(0,4,3,LOG:13)
Block(0,5,-4,LOG:13)
Block(0,5,-3,LOG:13)
Block(0,5,-2,LOG:13)
Block(0,5,2,LOG:13)
Block(0,5,3,LOG:13)
Block(0,6,-3,LOG:13)
Block(0,6,-2,LOG:13)
Block(0,6,2,LOG:13)
Block(0,6,3,LOG:13)
Block(0,7,-3,LOG:13)
Block(0,7,-2,LOG:13)
Block(0,7,2,LOG:13)
Block(0,7,3,LOG:13)
Block(0,8,-3,LOG:13)
Block(0,8,-2,LOG:13)
Block(0,8,0,LOG:13)
Block(0,8,1,LOG:13)
Block(0,8,2,LOG:13)
Block(0,8,3,LOG:13)
Block(0,9,-3,LOG:13)
Block(0,9,-2,LOG:13)
Block(0,9,-1,LOG:13)
Block(0,9,0,LOG:13)
Block(0,9,1,LOG:13)
Block(0,9,2,LOG:13)
Block(0,10,-3,LOG:13)
Block(0,10,-2,LOG:13)
Block(0,10,-1,LOG:13)
Block(0,10,0,LOG:13)
Block(0,10,1,LOG:13)
Block(0,10,2,LOG:13)
Block(0,11,-3,LOG:13)
Block(0,11,-2,LOG:13)
Block(0,11,-1,LOG:13)
Block(0,11,0,LOG:13)
Block(0,11,1,LOG:13)
Block(0,11,2,LOG:13)
Block(0,12,-3,LOG:13)
Block(0,12,-2,LOG:13)
Block(0,12,-1,LOG:13)
Block(0,12,0,LOG:13)
Block(0,12,1,LOG:13)
Block(0,12,2,LOG:13)
Block(0,13,-3,LOG:13)
Block(0,13,-2,LOG:13)
Block(0,13,-1,LOG:13)
Block(0,13,0,LOG:13)
Block(0,13,1,LOG:13)
Block(0,13,2,LOG:13)
Block(0,14,-3,LOG:13)
Block(0,14,-2,LOG:13)
Block(0,14,-1,LOG:13)
Block(0,14,0,LOG:13)
Block(0,14,1,LOG:13)
Block(0,14,2,LOG:13)
Block(0,15,-3,LOG:13)
Block(0,15,-2,LOG:13)
Block(0,15,-1,LOG:13)
Block(0,15,0,LOG:13)
Block(0,15,1,LOG:13)
Block(0,15,2,LOG:13)
Block(0,16,-3,LOG:13)
Block(0,16,-2,LOG:13)
Block(0,16,-1,LOG:13)
Block(0,16,0,LOG:13)
Block(0,16,1,LOG:13)
Block(0,16,2,LOG:13)
Block(0,17,-3,LOG:13)
Block(0,17,-2,LOG:13)
Block(0,17,-1,LOG:13)
Block(0,17,0,LOG:13)
Block(0,17,1,LOG:13)
Block(0,17,2,LOG:13)
Block(0,18,-3,LOG:13)
Block(0,18,-2,LOG:13)
Block(0,18,-1,LOG:13)
Block(0,18,0,LOG:13)
Block(0,18,1,LOG:13)
Block(0,18,2,LOG:13)
Block(0,19,-3,LOG:13)
Block(0,19,-2,LOG:13)
Block(0,19,-1,LOG:13)
Block(0,19,0,LOG:13)
Block(0,19,1,LOG:13)
Block(0,19,2,LOG:13)
Block(0,20,-3,LOG:13)
Block(0,20,-2,LOG:13)
Block(0,20,-1,LOG:13)
Block(0,20,0,LOG:13)
Block(0,20,1,LOG:13)
Block(0,20,2,LOG:13)
Block(0,21,-3,LOG:13)
Block(0,21,-2,LOG:13)
Block(0,21,-1,LOG:13)
Block(0,21,0,LOG:13)
Block(0,21,1,LOG:13)
Block(0,21,2,LOG:13)
Block(0,22,-7,LEAVES:1)
Block(0,22,-3,LOG:13)
Block(0,22,-2,LOG:13)
Block(0,22,-1,LOG:13)
Block(0,22,0,LOG:13)
Block(0,22,1,LOG:13)
Block(0,22,2,LOG:13)
Block(0,22,8,LEAVES:1)
Block(0,22,9,LEAVES:1)
Block(0,22,10,LEAVES:1)
Block(0,23,-6,LEAVES:1)
Block(0,23,-2,LOG:13)
Block(0,23,-1,LOG:13)
Block(0,23,0,LOG:13)
Block(0,23,1,LOG:13)
Block(0,23,2,LOG:13)
Block(0,23,3,LEAVES:1)
Block(0,23,7,LEAVES:1)
Block(0,23,8,LEAVES:1)
Block(0,24,-5,LEAVES:1)
Block(0,24,-4,LOG:13)
Block(0,24,-3,LOG:13)
Block(0,24,-2,LOG:13)
Block(0,24,-1,LOG:13)
Block(0,24,0,LOG:13)
Block(0,24,1,LOG:13)
Block(0,24,2,LOG:13)
Block(0,24,6,LEAVES:1)
Block(0,24,7,LEAVES:1)
Block(0,25,-3,LOG:13)
Block(0,25,-2,LOG:13)
Block(0,25,-1,LOG:13)
Block(0,25,0,LOG:13)
Block(0,25,1,LOG:13)
Block(0,25,2,LOG:13)
Block(0,25,4,LEAVES:1)
Block(0,25,5,LEAVES:1)
Block(0,26,-3,LEAVES:1)
Block(0,26,-2,LOG:13)
Block(0,26,-1,LOG:13)
Block(0,26,0,LOG:13)
Block(0,26,1,LOG:13)
Block(0,26,2,LOG:13)
Block(0,26,3,LEAVES:1)
Block(0,27,-2,LOG:13)
Block(0,27,-1,LOG:13)
Block(0,27,0,LOG:13)
Block(0,27,1,LOG:13)
Block(0,27,2,LOG:13)
Block(0,28,-2,LOG:13)
Block(0,28,-1,LOG:13)
Block(0,28,0,LOG:13)
Block(0,28,1,LOG:13)
Block(0,28,2,LOG:13)
Block(0,28,7,LEAVES:1)
Block(0,28,9,LEAVES:1)
Block(0,29,-2,LOG:13)
Block(0,29,-1,LOG:13)
Block(0,29,0,LOG:13)
Block(0,29,1,LOG:13)
Block(0,29,2,LOG:13)
Block(0,30,-2,LOG:13)
Block(0,30,-1,LOG:13)
Block(0,30,0,LOG:13)
Block(0,30,1,LOG:13)
Block(0,30,2,LOG:13)
Block(0,31,-2,LOG:13)
Block(0,31,-1,LOG:13)
Block(0,31,0,LOG:13)
Block(0,31,1,LOG:13)
Block(0,31,2,LOG:13)
Block(0,31,4,LEAVES:1)
Block(0,32,-2,LOG:13)
Block(0,32,-1,LOG:13)
Block(0,32,0,LOG:13)
Block(0,32,1,LOG:13)
Block(0,32,2,LOG:13)
Block(0,32,3,LEAVES:1)
Block(0,33,-2,LOG:13)
Block(0,33,-1,LOG:13)
Block(0,33,0,LOG:13)
Block(0,33,1,LOG:13)
Block(0,33,2,LOG:13)
Block(0,34,-2,LOG:13)
Block(0,34,-1,LOG:13)
Block(0,34,0,LOG:13)
Block(0,34,1,LOG:13)
Block(0,34,2,LOG:13)
Block(0,35,-3,LEAVES:1)
Block(0,35,-2,LOG:13)
Block(0,35,-1,LOG:13)
Block(0,35,0,LOG:13)
Block(0,35,1,LOG:13)
Block(0,36,-2,LOG:13)
Block(0,36,-1,LOG:13)
Block(0,36,0,LOG:13)
Block(0,36,1,LOG:13)
Block(0,37,-3,LEAVES:1)
Block(0,37,-2,LOG:13)
Block(0,37,-1,LOG:13)
Block(0,37,0,LOG:13)
Block(0,37,1,LOG:13)
Block(0,38,-1,LOG:13)
Block(0,38,0,LOG:13)
Block(0,38,1,LOG:13)
Block(0,39,-1,LOG:13)
Block(0,39,0,LOG:13)
Block(0,39,1,LOG:13)
Block(0,40,-1,LOG:13)
Block(0,40,0,LOG:13)
Block(0,40,1,LOG:13)
Block(0,41,-1,LOG:13)
Block(0,41,0,LOG:13)
Block(0,41,1,LOG:13)
Block(0,42,-1,LOG:13)
Block(0,42,0,LOG:13)
Block(0,42,1,LOG:13)
Block(0,43,-1,LOG:13)
Block(0,43,0,LOG:13)
Block(0,43,1,LOG:13)
Block(0,44,-2,LEAVES:1)
Block(0,44,-1,LOG:13)
Block(0,44,0,LOG:13)
Block(0,44,1,LOG:13)
Block(0,45,-1,LOG:13)
Block(0,45,0,LOG:13)
Block(0,45,1,LOG:13)
Block(0,46,-1,LOG:13)
Block(0,46,0,LOG:13)
Block(0,46,1,LOG:13)
Block(0,47,-1,LOG:13)
Block(0,47,0,LOG:13)
Block(0,47,1,LOG:13)
Block(0,47,2,LEAVES:1)
Block(0,48,-1,LOG:13)
Block(0,48,0,LOG:13)
Block(0,48,1,LOG:13)
Block(0,48,2,LEAVES:1)
Block(0,48,3,LEAVES:1)
Block(0,48,4,LEAVES:1)
Block(0,48,6,LEAVES:1)
Block(0,49,-8,LEAVES:1)
Block(0,49,-7,LEAVES:1)
Block(0,49,-1,LOG:13)
Block(0,49,0,LOG:13)
Block(0,49,2,LEAVES:1)
Block(0,49,3,LEAVES:1)
Block(0,50,-7,LEAVES:1)
Block(0,50,-6,LEAVES:1)
Block(0,50,-5,LEAVES:1)
Block(0,50,-2,LEAVES:1)
Block(0,50,-1,LOG:13)
Block(0,50,0,LOG:13)
Block(0,50,1,LOG:13)
Block(0,50,2,LOG:13)
Block(0,51,-5,LEAVES:1)
Block(0,51,-4,LEAVES:1)
Block(0,51,-1,LEAVES:1)
Block(0,51,0,LOG:13)
Block(0,51,1,LEAVES:1)
Block(0,52,-3,LEAVES:1)
Block(0,52,-2,LEAVES:1)
Block(0,52,0,LOG:13)
Block(0,52,1,LEAVES:1)
Block(0,53,-1,LEAVES:1)
Block(0,53,0,LOG:13)
Block(0,54,-1,LEAVES:1)
Block(0,54,0,LOG:13)
Block(0,54,3,LEAVES:1)
Block(0,54,4,LEAVES:1)
Block(0,55,-4,LEAVES:1)
Block(0,55,0,LOG:13)
Block(0,55,1,LEAVES:1)
Block(0,55,2,LEAVES:1)
Block(0,55,3,LEAVES:1)
Block(0,56,-5,LEAVES:1)
Block(0,56,-2,LEAVES:1)
Block(0,56,-1,LOG:13)
Block(0,56,3,LEAVES:1)
Block(0,56,4,LEAVES:1)
Block(0,57,-4,LEAVES:1)
Block(0,57,2,LEAVES:1)
Block(0,57,3,LEAVES:1)
Block(0,58,-3,LEAVES:1)
Block(0,58,-1,LEAVES:1)
Block(0,58,0,LEAVES:1)
Block(0,58,1,LOG:13)
Block(0,58,2,LEAVES:1)
Block(0,59,-2,LEAVES:1)
Block(0,59,1,LEAVES:1)
Block(0,60,0,LEAVES:1)
Block(0,61,0,LEAVES:1)
Block(0,62,0,LEAVES:1)
Block(1,0,-5,LOG:13)
Block(1,0,-4,LOG:13)
Block(1,0,-3,LOG:13)
Block(1,0,-2,LOG:13)
Block(1,0,-1,LOG:13)
Block(1,0,0,LOG:13)
Block(1,0,1,LOG:13)
Block(1,0,2,LOG:13)
Block(1,0,4,LOG:13)
Block(1,0,5,LOG:13)
Block(1,1,-4,LOG:13)
Block(1,1,-3,LOG:13)
Block(1,1,1,LOG:13)
Block(1,1,2,LOG:13)
Block(1,1,3,LOG:13)
Block(1,1,4,LOG:13)
Block(1,1,5,LOG:13)
Block(1,2,-4,LOG:13)
Block(1,2,-3,LOG:13)
Block(1,2,2,LOG:13)
Block(1,2,3,LOG:13)
Block(1,2,4,LOG:13)
Block(1,3,-3,LOG:13)
Block(1,3,2,LOG:13)
Block(1,3,3,LOG:13)
Block(1,3,4,LOG:13)
Block(1,4,-3,LOG:13)
Block(1,4,3,LOG:13)
Block(1,5,-3,LOG:13)
Block(1,5,3,LOG:13)
Block(1,6,-3,LOG:13)
Block(1,6,-2,LOG:13)
Block(1,6,2,LOG:13)
Block(1,6,3,LOG:13)
Block(1,7,-3,LOG:13)
Block(1,7,-2,LOG:13)
Block(1,7,2,LOG:13)
Block(1,7,3,LOG:13)
Block(1,8,-3,LOG:13)
Block(1,8,-2,LOG:13)
Block(1,8,-1,LOG:13)
Block(1,8,2,LOG:13)
Block(1,8,3,LOG:13)
Block(1,9,-3,LOG:13)
Block(1,9,-2,LOG:13)
Block(1,9,-1,LOG:13)
Block(1,9,0,LOG:13)
Block(1,9,1,LOG:13)
Block(1,9,2,LOG:13)
Block(1,9,3,LOG:13)
Block(1,10,-3,LOG:13)
Block(1,10,-2,LOG:13)
Block(1,10,-1,LOG:13)
Block(1,10,0,LOG:13)
Block(1,10,1,LOG:13)
Block(1,10,2,LOG:13)
Block(1,10,3,LOG:13)
Block(1,11,-3,LOG:13)
Block(1,11,-2,LOG:13)
Block(1,11,-1,LOG:13)
Block(1,11,0,LOG:13)
Block(1,11,1,LOG:13)
Block(1,11,2,LOG:13)
Block(1,11,3,LOG:13)
Block(1,12,-3,LOG:13)
Block(1,12,-2,LOG:13)
Block(1,12,-1,LOG:13)
Block(1,12,0,LOG:13)
Block(1,12,1,LOG:13)
Block(1,12,2,LOG:13)
Block(1,12,3,LOG:13)
Block(1,13,-3,LOG:13)
Block(1,13,-2,LOG:13)
Block(1,13,-1,LOG:13)
Block(1,13,0,LOG:13)
Block(1,13,1,LOG:13)
Block(1,13,2,LOG:13)
Block(1,13,3,LOG:13)
Block(1,14,-3,LOG:13)
Block(1,14,-2,LOG:13)
Block(1,14,-1,LOG:13)
Block(1,14,0,LOG:13)
Block(1,14,1,LOG:13)
Block(1,14,2,LOG:13)
Block(1,14,3,LOG:13)
Block(1,15,-3,LOG:13)
Block(1,15,-2,LOG:13)
Block(1,15,-1,LOG:13)
Block(1,15,0,LOG:13)
Block(1,15,1,LOG:13)
Block(1,15,2,LOG:13)
Block(1,15,3,LOG:13)
Block(1,16,-3,LOG:13)
Block(1,16,-2,LOG:13)
Block(1,16,-1,LOG:13)
Block(1,16,0,LOG:13)
Block(1,16,1,LOG:13)
Block(1,16,2,LOG:13)
Block(1,16,3,LOG:13)
Block(1,17,-3,LOG:13)
Block(1,17,-2,LOG:13)
Block(1,17,-1,LOG:13)
Block(1,17,0,LOG:13)
Block(1,17,1,LOG:13)
Block(1,17,2,LOG:13)
Block(1,17,3,LOG:13)
Block(1,18,-3,LOG:13)
Block(1,18,-2,LOG:13)
Block(1,18,-1,LOG:13)
Block(1,18,0,LOG:13)
Block(1,18,1,LOG:13)
Block(1,18,2,LOG:13)
Block(1,18,3,LOG:13)
Block(1,19,-3,LOG:13)
Block(1,19,-2,LOG:13)
Block(1,19,-1,LOG:13)
Block(1,19,0,LOG:13)
Block(1,19,1,LOG:13)
Block(1,19,2,LOG:13)
Block(1,19,3,LOG:13)
Block(1,20,-3,LOG:13)
Block(1,20,-2,LOG:13)
Block(1,20,-1,LOG:13)
Block(1,20,0,LOG:13)
Block(1,20,1,LOG:13)
Block(1,20,2,LOG:13)
Block(1,20,3,LOG:13)
Block(1,21,-3,LOG:13)
Block(1,21,-2,LOG:13)
Block(1,21,-1,LOG:13)
Block(1,21,0,LOG:13)
Block(1,21,1,LOG:13)
Block(1,21,2,LOG:13)
Block(1,21,3,LOG:13)
Block(1,21,11,LEAVES:1)
Block(1,21,12,LEAVES:1)
Block(1,22,-3,LOG:13)
Block(1,22,-2,LOG:13)
Block(1,22,-1,LOG:13)
Block(1,22,0,LOG:13)
Block(1,22,1,LOG:13)
Block(1,22,2,LOG:13)
Block(1,22,3,LOG:13)
Block(1,23,-6,LEAVES:1)
Block(1,23,-4,LEAVES:1)
Block(1,23,-3,LOG:13)
Block(1,23,-2,LOG:13)
Block(1,23,-1,LOG:13)
Block(1,23,0,LOG:13)
Block(1,23,1,LOG:13)
Block(1,23,2,LOG:13)
Block(1,23,3,LOG:13)
Block(1,23,5,LEAVES:1)
Block(1,23,6,LEAVES:1)
Block(1,23,7,LEAVES:1)
Block(1,23,8,LEAVES:1)
Block(1,23,9,LEAVES:1)
Block(1,24,-5,LEAVES:1)
Block(1,24,-4,LEAVES:1)
Block(1,24,-3,LOG:13)
Block(1,24,-2,LOG:13)
Block(1,24,-1,LOG:13)
Block(1,24,0,LOG:13)
Block(1,24,1,LOG:13)
Block(1,24,2,LOG:13)
Block(1,24,3,LOG:13)
Block(1,24,4,LEAVES:1)
Block(1,24,5,LEAVES:1)
Block(1,24,6,LOG:13)
Block(1,24,7,LOG:13)
Block(1,25,-4,LEAVES:1)
Block(1,25,-3,LOG:13)
Block(1,25,-2,LOG:13)
Block(1,25,-1,LOG:13)
Block(1,25,0,LOG:13)
Block(1,25,1,LOG:13)
Block(1,25,2,LOG:13)
Block(1,25,3,LOG:13)
Block(1,25,4,LOG:13)
Block(1,25,5,LOG:13)
Block(1,25,6,LEAVES:1)
Block(1,26,-3,LOG:13)
Block(1,26,-2,LOG:13)
Block(1,26,-1,LOG:13)
Block(1,26,0,LOG:13)
Block(1,26,1,LOG:13)
Block(1,26,2,LOG:13)
Block(1,26,3,LOG:13)
Block(1,26,4,LEAVES:1)
Block(1,27,-3,LOG:13)
Block(1,27,-2,LOG:13)
Block(1,27,-1,LOG:13)
Block(1,27,0,LOG:13)
Block(1,27,1,LOG:13)
Block(1,27,2,LOG:13)
Block(1,27,3,LEAVES:1)
Block(1,28,-3,LOG:13)
Block(1,28,-2,LOG:13)
Block(1,28,-1,LOG:13)
Block(1,28,0,LOG:13)
Block(1,28,1,LOG:13)
Block(1,28,2,LOG:13)
Block(1,29,-3,LOG:13)
Block(1,29,-2,LOG:13)
Block(1,29,-1,LOG:13)
Block(1,29,0,LOG:13)
Block(1,29,1,LOG:13)
Block(1,29,2,LOG:13)
Block(1,30,-3,LOG:13)
Block(1,30,-2,LOG:13)
Block(1,30,-1,LOG:13)
Block(1,30,0,LOG:13)
Block(1,30,1,LOG:13)
Block(1,30,2,LOG:13)
Block(1,31,-3,LOG:13)
Block(1,31,-2,LOG:13)
Block(1,31,-1,LOG:13)
Block(1,31,0,LOG:13)
Block(1,31,1,LOG:13)
Block(1,31,2,LOG:13)
Block(1,32,-3,LOG:13)
Block(1,32,-2,LOG:13)
Block(1,32,-1,LOG:13)
Block(1,32,0,LOG:13)
Block(1,32,1,LOG:13)
Block(1,32,2,LOG:13)
Block(1,33,-6,LEAVES:1)
Block(1,33,-5,LEAVES:1)
Block(1,33,-4,LEAVES:1)
Block(1,33,-3,LOG:13)
Block(1,33,-2,LOG:13)
Block(1,33,-1,LOG:13)
Block(1,33,0,LOG:13)
Block(1,33,1,LOG:13)
Block(1,33,2,LOG:13)
Block(1,34,-2,LOG:13)
Block(1,34,-1,LOG:13)
Block(1,34,0,LOG:13)
Block(1,34,1,LOG:13)
Block(1,34,2,LOG:13)
Block(1,35,-5,LEAVES:1)
Block(1,35,-2,LOG:13)
Block(1,35,-1,LOG:13)
Block(1,35,0,LOG:13)
Block(1,35,1,LOG:13)
Block(1,35,2,LOG:13)
Block(1,36,-4,LEAVES:1)
Block(1,36,-2,LOG:13)
Block(1,36,-1,LOG:13)
Block(1,36,0,LOG:13)
Block(1,36,1,LOG:13)
Block(1,36,2,LOG:13)
Block(1,37,-2,LOG:13)
Block(1,37,-1,LOG:13)
Block(1,37,0,LOG:13)
Block(1,37,1,LOG:13)
Block(1,37,2,LOG:13)
Block(1,38,-2,LOG:13)
Block(1,38,-1,LOG:13)
Block(1,38,0,LOG:13)
Block(1,38,1,LOG:13)
Block(1,38,2,LOG:13)
Block(1,39,-2,LOG:13)
Block(1,39,-1,LOG:13)
Block(1,39,0,LOG:13)
Block(1,39,1,LOG:13)
Block(1,39,2,LOG:13)
Block(1,40,-2,LOG:13)
Block(1,40,-1,LOG:13)
Block(1,40,0,LOG:13)
Block(1,40,1,LOG:13)
Block(1,40,2,LOG:13)
Block(1,41,-2,LOG:13)
Block(1,41,-1,LOG:13)
Block(1,41,0,LOG:13)
Block(1,41,1,LOG:13)
Block(1,41,2,LOG:13)
Block(1,42,-2,LOG:13)
Block(1,42,-1,LOG:13)
Block(1,42,0,LOG:13)
Block(1,42,1,LOG:13)
Block(1,42,2,LOG:13)
Block(1,43,-3,LEAVES:1)
Block(1,43,-2,LOG:13)
Block(1,43,-1,LOG:13)
Block(1,43,0,LOG:13)
Block(1,43,1,LOG:13)
Block(1,44,-2,LOG:13)
Block(1,44,-1,LOG:13)
Block(1,44,0,LOG:13)
Block(1,44,1,LOG:13)
Block(1,45,-2,LOG:13)
Block(1,45,-1,LOG:13)
Block(1,45,0,LOG:13)
Block(1,45,1,LOG:13)
Block(1,46,-2,LOG:13)
Block(1,46,-1,LOG:13)
Block(1,46,0,LOG:13)
Block(1,46,1,LOG:13)
Block(1,46,2,LEAVES:1)
Block(1,47,-2,LOG:13)
Block(1,47,-1,LOG:13)
Block(1,47,0,LOG:13)
Block(1,47,1,LOG:13)
Block(1,48,-3,LEAVES:1)
Block(1,48,-2,LOG:13)
Block(1,48,-1,LOG:13)
Block(1,48,0,LOG:13)
Block(1,48,1,LOG:13)
Block(1,48,3,LEAVES:1)
Block(1,49,-10,LEAVES:1)
Block(1,49,-1,LOG:13)
Block(1,49,0,LOG:13)
Block(1,49,1,LOG:13)
Block(1,49,2,LEAVES:1)
Block(1,50,-8,LEAVES:1)
Block(1,50,-5,LEAVES:1)
Block(1,50,-1,LOG:13)
Block(1,50,0,LOG:13)
Block(1,50,1,LOG:13)
Block(1,50,2,LEAVES:1)
Block(1,51,-6,LEAVES:1)
Block(1,51,-5,LOG:13)
Block(1,51,-4,LOG:13)
Block(1,51,-3,LEAVES:1)
Block(1,51,-1,LOG:13)
Block(1,51,0,LOG:13)
Block(1,51,1,LOG:13)
Block(1,52,-4,LEAVES:1)
Block(1,52,-3,LOG:13)
Block(1,52,-2,LOG:13)
Block(1,52,-1,LOG:13)
Block(1,52,0,LOG:13)
Block(1,52,1,LOG:13)
Block(1,53,-2,LEAVES:1)
Block(1,53,-1,LOG:13)
Block(1,53,0,LOG:13)
Block(1,53,1,LOG:13)
Block(1,53,2,LEAVES:1)
Block(1,53,5,LEAVES:1)
Block(1,54,-1,LOG:13)
Block(1,54,0,LOG:13)
Block(1,54,1,LOG:13)
Block(1,55,-2,LEAVES:1)
Block(1,55,-1,LOG:13)
Block(1,55,0,LOG:13)
Block(1,55,1,LOG:13)
Block(1,55,2,LOG:13)
Block(1,55,3,LEAVES:1)
Block(1,56,-6,LEAVES:1)
Block(1,56,-5,LEAVES:1)
Block(1,56,-1,LOG:13)
Block(1,56,0,LOG:13)
Block(1,56,1,LEAVES:1)
Block(1,57,-5,LEAVES:1)
Block(1,57,-4,LOG:13)
Block(1,57,-1,LOG:13)
Block(1,57,0,LOG:13)
Block(1,57,3,LEAVES:1)
Block(1,58,-4,LEAVES:1)
Block(1,58,-3,LOG:13)
Block(1,58,-1,LOG:13)
Block(1,58,0,LOG:13)
Block(1,58,1,LEAVES:1)
Block(1,59,-2,LOG:13)
Block(1,59,-1,LOG:13)
Block(1,59,0,LOG:13)
Block(1,59,1,LEAVES:1)
Block(1,59,3,LEAVES:1)
Block(1,60,-2,LEAVES:1)
Block(1,60,0,LOG:13)
Block(1,61,-1,LEAVES:1)
Block(1,61,0,LOG:13)
Block(1,61,1,LEAVES:1)
Block(1,62,0,LOG:13)
Block(1,63,0,LEAVES:1)
Block(2,0,-4,LOG:13)
Block(2,0,-3,LOG:13)
Block(2,0,-2,LOG:13)
Block(2,0,-1,LOG:13)
Block(2,0,0,LOG:13)
Block(2,0,1,LOG:13)
Block(2,0,2,LOG:13)
Block(2,0,3,LOG:13)
Block(2,0,4,LOG:13)
Block(2,1,-4,LOG:13)
Block(2,1,-3,LOG:13)
Block(2,1,1,LOG:13)
Block(2,1,2,LOG:13)
Block(2,1,3,LOG:13)
Block(2,1,4,LOG:13)
Block(2,2,-3,LOG:13)
Block(2,2,2,LOG:13)
Block(2,2,3,LOG:13)
Block(2,3,-3,LOG:13)
Block(2,3,2,LOG:13)
Block(2,4,-3,LOG:13)
Block(2,4,2,LOG:13)
Block(2,5,-3,LOG:13)
Block(2,5,-2,LOG:13)
Block(2,5,2,LOG:13)
Block(2,6,-3,LOG:13)
Block(2,6,-2,LOG:13)
Block(2,6,2,LOG:13)
Block(2,7,-3,LOG:13)
Block(2,7,-2,LOG:13)
Block(2,7,2,LOG:13)
Block(2,8,-2,LOG:13)
Block(2,8,-1,LOG:13)
Block(2,8,2,LOG:13)
Block(2,9,-2,LOG:13)
Block(2,9,-1,LOG:13)
Block(2,9,0,LOG:13)
Block(2,9,1,LOG:13)
Block(2,9,2,LOG:13)
Block(2,10,-2,LOG:13)
Block(2,10,-1,LOG:13)
Block(2,10,0,LOG:13)
Block(2,10,1,LOG:13)
Block(2,10,2,LOG:13)
Block(2,11,-2,LOG:13)
Block(2,11,-1,LOG:13)
Block(2,11,0,LOG:13)
Block(2,11,1,LOG:13)
Block(2,11,2,LOG:13)
Block(2,12,-2,LOG:13)
Block(2,12,-1,LOG:13)
Block(2,12,0,LOG:13)
Block(2,12,1,LOG:13)
Block(2,12,2,LOG:13)
Block(2,13,-2,LOG:13)
Block(2,13,-1,LOG:13)
Block(2,13,0,LOG:13)
Block(2,13,1,LOG:13)
Block(2,13,2,LOG:13)
Block(2,14,-2,LOG:13)
Block(2,14,-1,LOG:13)
Block(2,14,0,LOG:13)
Block(2,14,1,LOG:13)
Block(2,14,2,LOG:13)
Block(2,15,-2,LOG:13)
Block(2,15,-1,LOG:13)
Block(2,15,0,LOG:13)
Block(2,15,1,LOG:13)
Block(2,15,2,LOG:13)
Block(2,16,-2,LOG:13)
Block(2,16,-1,LOG:13)
Block(2,16,0,LOG:13)
Block(2,16,1,LOG:13)
Block(2,16,2,LOG:13)
Block(2,17,-2,LOG:13)
Block(2,17,-1,LOG:13)
Block(2,17,0,LOG:13)
Block(2,17,1,LOG:13)
Block(2,17,2,LOG:13)
Block(2,18,-2,LOG:13)
Block(2,18,-1,LOG:13)
Block(2,18,0,LOG:13)
Block(2,18,1,LOG:13)
Block(2,18,2,LOG:13)
Block(2,19,-2,LOG:13)
Block(2,19,-1,LOG:13)
Block(2,19,0,LOG:13)
Block(2,19,1,LOG:13)
Block(2,19,2,LOG:13)
Block(2,20,-2,LOG:13)
Block(2,20,-1,LOG:13)
Block(2,20,0,LOG:13)
Block(2,20,1,LOG:13)
Block(2,20,2,LOG:13)
Block(2,21,-2,LOG:13)
Block(2,21,-1,LOG:13)
Block(2,21,0,LOG:13)
Block(2,21,1,LOG:13)
Block(2,21,2,LOG:13)
Block(2,21,11,LEAVES:1)
Block(2,22,-2,LOG:13)
Block(2,22,-1,LOG:13)
Block(2,22,0,LOG:13)
Block(2,22,1,LOG:13)
Block(2,22,2,LOG:13)
Block(2,22,5,LEAVES:1)
Block(2,22,6,LEAVES:1)
Block(2,22,7,LEAVES:1)
Block(2,22,10,LEAVES:1)
Block(2,22,11,LEAVES:1)
Block(2,23,-3,LEAVES:1)
Block(2,23,-2,LOG:13)
Block(2,23,-1,LOG:13)
Block(2,23,0,LOG:13)
Block(2,23,1,LOG:13)
Block(2,23,2,LOG:13)
Block(2,23,3,LEAVES:1)
Block(2,23,6,LEAVES:1)
Block(2,23,7,LEAVES:1)
Block(2,23,8,LOG:13)
Block(2,23,9,LOG:13)
Block(2,24,-5,LEAVES:1)
Block(2,24,-3,LEAVES:1)
Block(2,24,-2,LOG:13)
Block(2,24,-1,LOG:13)
Block(2,24,0,LOG:13)
Block(2,24,1,LOG:13)
Block(2,24,2,LOG:13)
Block(2,24,5,LEAVES:1)
Block(2,24,6,LEAVES:1)
Block(2,24,8,LEAVES:1)
Block(2,25,-2,LOG:13)
Block(2,25,-1,LOG:5)
Block(2,25,0,LOG:13)
Block(2,25,1,LOG:13)
Block(2,25,2,LOG:13)
Block(2,25,3,LEAVES:1)
Block(2,25,5,LEAVES:1)
Block(2,26,-2,LOG:13)
Block(2,26,-1,LOG:5)
Block(2,26,0,LOG:13)
Block(2,26,1,LOG:13)
Block(2,26,2,LOG:13)
Block(2,27,-2,LOG:13)
Block(2,27,-1,LOG:13)
Block(2,27,0,LOG:13)
Block(2,27,1,LOG:13)
Block(2,27,2,LOG:13)
Block(2,28,-2,LOG:13)
Block(2,28,-1,LOG:13)
Block(2,28,0,LOG:13)
Block(2,28,1,LOG:13)
Block(2,28,2,LOG:13)
Block(2,29,-2,LOG:13)
Block(2,29,-1,LOG:13)
Block(2,29,0,LOG:13)
Block(2,29,1,LOG:13)
Block(2,29,2,LOG:13)
Block(2,30,-2,LOG:13)
Block(2,30,-1,LOG:13)
Block(2,30,0,LOG:13)
Block(2,30,1,LOG:13)
Block(2,31,-2,LOG:13)
Block(2,31,-1,LOG:13)
Block(2,31,0,LOG:13)
Block(2,31,1,LOG:13)
Block(2,32,-2,LOG:13)
Block(2,32,-1,LOG:13)
Block(2,32,0,LOG:13)
Block(2,32,1,LOG:13)
Block(2,33,-8,LEAVES:1)
Block(2,33,-7,LEAVES:1)
Block(2,33,-6,LEAVES:1)
Block(2,33,-2,LOG:13)
Block(2,33,-1,LOG:13)
Block(2,33,0,LOG:13)
Block(2,33,1,LOG:13)
Block(2,34,-5,LEAVES:1)
Block(2,34,-4,LEAVES:1)
Block(2,34,-3,LEAVES:1)
Block(2,34,-2,LOG:13)
Block(2,34,-1,LOG:13)
Block(2,34,0,LOG:13)
Block(2,34,1,LOG:13)
Block(2,35,-6,LEAVES:1)
Block(2,35,-5,LEAVES:1)
Block(2,35,-4,LEAVES:1)
Block(2,35,-2,LOG:13)
Block(2,35,-1,LOG:13)
Block(2,35,0,LOG:13)
Block(2,35,1,LOG:13)
Block(2,36,-4,LOG:13)
Block(2,36,-3,LOG:13)
Block(2,36,-2,LOG:13)
Block(2,36,-1,LOG:13)
Block(2,36,0,LOG:13)
Block(2,36,1,LOG:13)
Block(2,37,-3,LEAVES:1)
Block(2,37,-2,LOG:13)
Block(2,37,-1,LOG:13)
Block(2,37,0,LOG:13)
Block(2,37,1,LOG:13)
Block(2,38,-2,LOG:13)
Block(2,38,-1,LOG:13)
Block(2,38,0,LOG:13)
Block(2,38,1,LOG:13)
Block(2,39,-2,LOG:13)
Block(2,39,-1,LOG:13)
Block(2,39,0,LOG:13)
Block(2,39,1,LOG:13)
Block(2,40,-2,LOG:13)
Block(2,40,-1,LOG:13)
Block(2,40,0,LOG:13)
Block(2,40,1,LOG:13)
Block(2,41,-2,LOG:13)
Block(2,41,-1,LOG:13)
Block(2,41,0,LOG:13)
Block(2,41,1,LOG:13)
Block(2,42,-1,LOG:13)
Block(2,42,0,LOG:13)
Block(2,42,1,LOG:13)
Block(2,43,-1,LOG:13)
Block(2,43,0,LOG:13)
Block(2,43,1,LOG:13)
Block(2,43,2,LEAVES:1)
Block(2,44,-1,LOG:13)
Block(2,44,0,LOG:13)
Block(2,44,1,LOG:13)
Block(2,44,3,LEAVES:1)
Block(2,45,-1,LOG:13)
Block(2,45,0,LOG:13)
Block(2,46,-1,LOG:13)
Block(2,46,0,LOG:13)
Block(2,46,1,LOG:13)
Block(2,46,2,LEAVES:1)
Block(2,47,-4,LEAVES:1)
Block(2,47,-3,LEAVES:1)
Block(2,47,-1,LOG:13)
Block(2,47,0,LOG:13)
Block(2,47,1,LEAVES:1)
Block(2,48,-3,LEAVES:1)
Block(2,48,-2,LEAVES:1)
Block(2,48,-1,LOG:13)
Block(2,48,0,LOG:13)
Block(2,49,-10,LEAVES:1)
Block(2,49,-7,LEAVES:1)
Block(2,49,-6,LEAVES:1)
Block(2,49,-3,LEAVES:1)
Block(2,49,-2,LOG:13)
Block(2,49,-1,LOG:13)
Block(2,49,0,LOG:13)
Block(2,49,2,LEAVES:1)
Block(2,50,-9,LEAVES:1)
Block(2,50,-8,LOG:13)
Block(2,50,-7,LEAVES:1)
Block(2,50,-2,LEAVES:1)
Block(2,50,-1,LOG:13)
Block(2,50,0,LOG:13)
Block(2,51,-7,LOG:13)
Block(2,51,-6,LOG:13)
Block(2,51,-5,LEAVES:1)
Block(2,51,-4,LEAVES:1)
Block(2,51,-1,LOG:13)
Block(2,51,0,LOG:13)
Block(2,52,-6,LEAVES:1)
Block(2,52,-2,LEAVES:1)
Block(2,52,-1,LOG:13)
Block(2,52,0,LOG:13)
Block(2,52,1,LEAVES:1)
Block(2,53,-3,LEAVES:1)
Block(2,53,-1,LOG:13)
Block(2,53,0,LOG:13)
Block(2,53,1,LEAVES:1)
Block(2,53,2,LEAVES:1)
Block(2,53,3,LEAVES:1)
Block(2,53,5,LEAVES:1)
Block(2,53,6,LEAVES:1)
Block(2,54,-2,LEAVES:1)
Block(2,54,-1,LOG:13)
Block(2,54,0,LOG:13)
Block(2,54,1,LEAVES:1)
Block(2,54,2,LEAVES:1)
Block(2,54,3,LOG:13)
Block(2,54,4,LEAVES:1)
Block(2,54,5,LEAVES:1)
Block(2,55,0,LOG:13)
Block(2,55,2,LEAVES:1)
Block(2,56,-5,LEAVES:1)
Block(2,56,0,LOG:13)
Block(2,57,-4,LEAVES:1)
Block(2,57,-2,LEAVES:1)
Block(2,57,2,LEAVES:1)
Block(2,58,-3,LEAVES:1)
Block(2,58,0,LOG:13)
Block(2,58,1,LEAVES:1)
Block(2,59,-2,LEAVES:1)
Block(2,59,-1,LEAVES:1)
Block(2,59,2,LEAVES:1)
Block(2,59,3,LEAVES:1)
Block(2,60,-1,LEAVES:1)
Block(2,60,0,LEAVES:1)
Block(2,60,1,LOG:13)
Block(2,60,2,LEAVES:1)
Block(2,61,0,LEAVES:1)
Block(2,62,0,LEAVES:1)
Block(3,0,-5,LOG:13)
Block(3,0,-4,LOG:13)
Block(3,0,-3,LOG:13)
Block(3,0,-2,LOG:13)
Block(3,0,0,LOG:13)
Block(3,0,1,LOG:13)
Block(3,0,3,LOG:13)
Block(3,1,-5,LOG:13)
Block(3,1,-4,LOG:13)
Block(3,1,-3,LOG:13)
Block(3,1,0,LOG:13)
Block(3,1,1,LOG:13)
Block(3,1,2,LOG:13)
Block(3,2,-3,LOG:13)
Block(3,2,0,LOG:13)
Block(3,2,1,LOG:13)
Block(3,2,2,LOG:13)
Block(3,3,-2,LOG:13)
Block(3,3,1,LOG:13)
Block(3,3,2,LOG:13)
Block(3,4,-2,LOG:13)
Block(3,4,-1,LOG:13)
Block(3,4,1,LOG:13)
Block(3,4,2,LOG:13)
Block(3,5,-2,LOG:13)
Block(3,5,-1,LOG:13)
Block(3,5,1,LOG:13)
Block(3,5,2,LOG:13)
Block(3,6,-2,LOG:13)
Block(3,6,-1,LOG:13)
Block(3,6,1,LOG:13)
Block(3,6,2,LOG:13)
Block(3,7,-2,LOG:13)
Block(3,7,-1,LOG:13)
Block(3,7,1,LOG:13)
Block(3,8,-2,LOG:13)
Block(3,8,-1,LOG:13)
Block(3,8,0,LOG:13)
Block(3,8,1,LOG:13)
Block(3,9,-2,LOG:13)
Block(3,9,-1,LOG:13)
Block(3,9,0,LOG:13)
Block(3,9,1,LOG:13)
Block(3,10,-2,LOG:13)
Block(3,10,-1,LOG:13)
Block(3,10,0,LOG:13)
Block(3,10,1,LOG:13)
Block(3,11,-2,LOG:13)
Block(3,11,-1,LOG:13)
Block(3,11,0,LOG:13)
Block(3,11,1,LOG:13)
Block(3,12,-2,LOG:13)
Block(3,12,-1,LOG:13)
Block(3,12,0,LOG:13)
Block(3,12,1,LOG:13)
Block(3,13,-1,LOG:13)
Block(3,13,0,LOG:13)
Block(3,13,1,LOG:13)
Block(3,14,-1,LOG:13)
Block(3,14,0,LOG:13)
Block(3,14,1,LOG:13)
Block(3,15,-1,LOG:13)
Block(3,15,0,LOG:13)
Block(3,15,1,LOG:13)
Block(3,16,-1,LOG:13)
Block(3,16,0,LOG:13)
Block(3,16,1,LOG:13)
Block(3,17,-1,LOG:13)
Block(3,17,0,LOG:13)
Block(3,17,1,LOG:13)
Block(3,18,-1,LOG:13)
Block(3,18,0,LOG:13)
Block(3,18,1,LOG:13)
Block(3,19,-1,LOG:13)
Block(3,19,0,LOG:13)
Block(3,19,1,LOG:13)
Block(3,20,-1,LOG:13)
Block(3,20,0,LOG:13)
Block(3,20,1,LOG:13)
Block(3,21,-1,LOG:13)
Block(3,21,0,LOG:13)
Block(3,21,1,LOG:13)
Block(3,21,10,LEAVES:1)
Block(3,21,12,LEAVES:1)
Block(3,21,13,LEAVES:1)
Block(3,22,-1,LOG:13)
Block(3,22,0,LOG:13)
Block(3,22,1,LOG:13)
Block(3,22,6,LEAVES:1)
Block(3,22,9,LEAVES:1)
Block(3,22,10,LOG:13)
Block(3,22,11,LOG:13)
Block(3,22,12,LEAVES:1)
Block(3,23,-3,LEAVES:1)
Block(3,23,-1,LOG:13)
Block(3,23,0,LOG:13)
Block(3,23,1,LOG:13)
Block(3,23,8,LEAVES:1)
Block(3,23,10,LEAVES:1)
Block(3,24,-1,LOG:13)
Block(3,24,0,LOG:13)
Block(3,24,5,LEAVES:1)
Block(3,25,-1,LOG:13)
Block(3,25,0,LOG:13)
Block(3,26,-1,LOG:13)
Block(3,26,0,LOG:13)
Block(3,26,3,LEAVES:1)
Block(3,26,4,LEAVES:1)
Block(3,27,-1,LOG:13)
Block(3,27,0,LOG:13)
Block(3,27,3,LEAVES:1)
Block(3,28,-1,LOG:13)
Block(3,28,0,LOG:13)
Block(3,28,1,LOG:13)
Block(3,29,-1,LOG:13)
Block(3,29,0,LOG:13)
Block(3,29,1,LOG:13)
Block(3,29,2,LEAVES:1)
Block(3,30,-1,LOG:13)
Block(3,30,0,LOG:13)
Block(3,30,1,LEAVES:1)
Block(3,31,-1,LOG:13)
Block(3,31,0,LOG:13)
Block(3,32,-6,LEAVES:1)
Block(3,32,-1,LOG:13)
Block(3,32,0,LOG:13)
Block(3,33,-9,LEAVES:1)
Block(3,33,-8,LEAVES:1)
Block(3,33,-6,LEAVES:1)
Block(3,33,-1,LOG:13)
Block(3,33,0,LOG:13)
Block(3,34,-7,LEAVES:1)
Block(3,34,-6,LEAVES:1)
Block(3,34,-4,LEAVES:1)
Block(3,34,-3,LEAVES:1)
Block(3,34,-2,LEAVES:1)
Block(3,34,-1,LOG:13)
Block(3,34,0,LOG:13)
Block(3,35,-6,LOG:13)
Block(3,35,-5,LOG:13)
Block(3,35,-3,LEAVES:1)
Block(3,35,-1,LOG:13)
Block(3,35,0,LOG:13)
Block(3,36,-5,LEAVES:1)
Block(3,36,-4,LEAVES:1)
Block(3,36,-3,LEAVES:1)
Block(3,36,-2,LEAVES:1)
Block(3,36,-1,LOG:13)
Block(3,36,0,LOG:13)
Block(3,37,0,LOG:13)
Block(3,38,0,LOG:13)
Block(3,39,0,LOG:13)
Block(3,40,0,LOG:13)
Block(3,42,-2,LEAVES:1)
Block(3,42,-1,LEAVES:1)
Block(3,42,0,LEAVES:1)
Block(3,43,-1,LEAVES:1)
Block(3,43,3,LEAVES:1)
Block(3,43,4,LEAVES:1)
Block(3,44,2,LEAVES:1)
Block(3,44,3,LEAVES:1)
Block(3,44,4,LEAVES:1)
Block(3,44,5,LEAVES:1)
Block(3,45,1,LEAVES:1)
Block(3,45,2,LOG:13)
Block(3,45,3,LEAVES:1)
Block(3,46,2,LOG:13)
Block(3,47,-1,LEAVES:1)
Block(3,49,-11,LEAVES:1)
Block(3,49,-10,LEAVES:1)
Block(3,49,-9,LEAVES:1)
Block(3,49,-3,LEAVES:1)
Block(3,49,-2,LOG:13)
Block(3,49,-1,LEAVES:1)
Block(3,50,-10,LEAVES:1)
Block(3,50,-9,LOG:13)
Block(3,50,-8,LEAVES:1)
Block(3,50,-4,LEAVES:1)
Block(3,50,-2,LEAVES:1)
Block(3,50,1,LEAVES:1)
Block(3,51,-7,LEAVES:1)
Block(3,51,-6,LEAVES:1)
Block(3,51,-2,LEAVES:1)
Block(3,51,-1,LOG:13)
Block(3,51,0,LEAVES:1)
Block(3,52,-1,LEAVES:1)
Block(3,52,2,LEAVES:1)
Block(3,52,7,LEAVES:1)
Block(3,53,-5,LEAVES:1)
Block(3,53,0,LEAVES:1)
Block(3,53,2,LEAVES:1)
Block(3,53,6,LEAVES:1)
Block(3,54,-3,LEAVES:1)
Block(3,54,-2,LOG:13)
Block(3,54,-1,LEAVES:1)
Block(3,54,3,LEAVES:1)
Block(3,54,4,LOG:13)
Block(3,54,5,LEAVES:1)
Block(3,55,-2,LEAVES:1)
Block(3,56,-5,LEAVES:1)
Block(3,56,-3,LEAVES:1)
Block(3,56,-2,LEAVES:1)
Block(3,56,1,LEAVES:1)
Block(3,58,-2,LEAVES:1)
Block(3,58,-1,LEAVES:1)
Block(3,58,0,LOG:13)
Block(3,58,1,LEAVES:1)
Block(3,59,0,LEAVES:1)
Block(3,59,3,LEAVES:1)
Block(3,60,-1,LEAVES:1)
Block(3,60,1,LEAVES:1)
Block(4,0,-6,LOG:13)
Block(4,0,-5,LOG:13)
Block(4,0,0,LOG:13)
Block(4,0,1,LOG:13)
Block(4,0,2,LOG:13)
Block(4,1,0,LOG:13)
Block(4,1,1,LOG:13)
Block(4,1,2,LOG:13)
Block(4,2,0,LOG:13)
Block(4,2,1,LOG:13)
Block(4,2,2,LOG:13)
Block(4,3,-1,LOG:13)
Block(4,3,0,LOG:13)
Block(4,3,1,LOG:13)
Block(4,4,-2,LOG:13)
Block(4,4,-1,LOG:13)
Block(4,4,0,LOG:13)
Block(4,5,-1,LOG:13)
Block(4,5,0,LOG:13)
Block(4,6,0,LOG:13)
Block(4,7,0,LOG:13)
Block(4,8,0,LOG:13)
Block(4,9,0,LOG:13)
Block(4,10,0,LOG:13)
Block(4,11,0,LOG:13)
Block(4,12,0,LOG:13)
Block(4,13,0,LOG:13)
Block(4,14,0,LOG:13)
Block(4,15,0,LOG:13)
Block(4,16,0,LOG:13)
Block(4,17,0,LOG:13)
Block(4,21,8,LEAVES:1)
Block(4,21,9,LEAVES:1)
Block(4,21,10,LEAVES:1)
Block(4,22,8,LEAVES:1)
Block(4,22,10,LEAVES:1)
Block(4,22,11,LEAVES:1)
Block(4,25,0,LEAVES:1)
Block(4,26,-1,LEAVES:1)
Block(4,26,0,LEAVES:1)
Block(4,26,3,LEAVES:1)
Block(4,27,0,LEAVES:1)
Block(4,27,3,LEAVES:1)
Block(4,27,4,LEAVES:1)
Block(4,28,1,LEAVES:1)
Block(4,28,2,LOG:13)
Block(4,28,3,LEAVES:1)
Block(4,32,-10,LEAVES:1)
Block(4,33,-9,LEAVES:1)
Block(4,33,-8,LEAVES:1)
Block(4,33,-7,LEAVES:1)
Block(4,33,-6,LEAVES:1)
Block(4,33,-5,LEAVES:1)
Block(4,33,-3,LEAVES:1)
Block(4,34,-8,LEAVES:1)
Block(4,34,-7,LOG:13)
Block(4,34,-4,LEAVES:1)
Block(4,34,-3,LEAVES:1)
Block(4,34,-2,LEAVES:1)
Block(4,35,-7,LEAVES:1)
Block(4,35,-6,LEAVES:1)
Block(4,35,-5,LEAVES:1)
Block(4,35,-3,LEAVES:1)
Block(4,35,-1,LEAVES:1)
Block(4,43,-1,LEAVES:1)
Block(4,43,1,LEAVES:1)
Block(4,43,3,LEAVES:1)
Block(4,43,6,LEAVES:1)
Block(4,44,0,LEAVES:1)
Block(4,44,1,LOG:13)
Block(4,44,3,LEAVES:1)
Block(4,44,4,LEAVES:1)
Block(4,45,1,LEAVES:1)
Block(4,45,2,LEAVES:1)
Block(4,45,3,LOG:13)
Block(4,45,4,LEAVES:1)
Block(4,46,3,LEAVES:1)
Block(4,47,-5,LEAVES:1)
Block(4,48,-4,LEAVES:1)
Block(4,48,-2,LEAVES:1)
Block(4,49,-10,LEAVES:1)
Block(4,49,-7,LEAVES:1)
Block(4,49,-3,LOG:13)
Block(4,49,-2,LEAVES:1)
Block(4,49,2,LEAVES:1)
Block(4,50,-9,LEAVES:1)
Block(4,50,-6,LEAVES:1)
Block(4,50,-3,LEAVES:1)
Block(4,50,1,LEAVES:1)
Block(4,50,2,LEAVES:1)
Block(4,51,-2,LEAVES:1)
Block(4,51,-1,LOG:13)
Block(4,51,0,LEAVES:1)
Block(4,51,7,LEAVES:1)
Block(4,51,8,LEAVES:1)
Block(4,52,-6,LEAVES:1)
Block(4,52,3,LEAVES:1)
Block(4,52,5,LEAVES:1)
Block(4,52,7,LEAVES:1)
Block(4,53,-5,LEAVES:1)
Block(4,53,-3,LEAVES:1)
Block(4,53,-1,LEAVES:1)
Block(4,53,2,LEAVES:1)
Block(4,53,4,LEAVES:1)
Block(4,53,5,LOG:13)
Block(4,53,6,LEAVES:1)
Block(4,54,-4,LEAVES:1)
Block(4,54,-3,LOG:13)
Block(4,54,-2,LEAVES:1)
Block(4,54,5,LEAVES:1)
Block(4,55,-1,LEAVES:1)
Block(4,56,-2,LEAVES:1)
Block(4,56,0,LEAVES:1)
Block(4,56,1,LEAVES:1)
Block(4,56,2,LEAVES:1)
Block(4,57,-1,LEAVES:1)
Block(4,57,0,LOG:13)
Block(4,57,1,LEAVES:1)
Block(4,58,0,LEAVES:1)
Block(5,0,-2,LOG:13)
Block(5,0,-1,LOG:13)
Block(5,0,0,LOG:13)
Block(5,0,1,LOG:13)
Block(5,1,-1,LOG:13)
Block(5,1,0,LOG:13)
Block(5,1,1,LOG:13)
Block(5,2,-1,LOG:13)
Block(5,2,0,LOG:13)
Block(5,21,10,LEAVES:1)
Block(5,21,11,LEAVES:1)
Block(5,21,12,LEAVES:1)
Block(5,25,1,LEAVES:1)
Block(5,25,5,LEAVES:1)
Block(5,26,1,LEAVES:1)
Block(5,26,2,LEAVES:1)
Block(5,27,1,LEAVES:1)
Block(5,27,2,LOG:13)
Block(5,27,3,LEAVES:1)
Block(5,28,2,LEAVES:1)
Block(5,31,-11,LEAVES:1)
Block(5,32,-10,LEAVES:1)
Block(5,32,-8,LEAVES:1)
Block(5,32,-6,LEAVES:1)
Block(5,33,-9,LEAVES:1)
Block(5,33,-8,LEAVES:1)
Block(5,33,-6,LEAVES:1)
Block(5,34,-8,LOG:13)
Block(5,34,-7,LEAVES:1)
Block(5,34,-6,LEAVES:1)
Block(5,34,-4,LEAVES:1)
Block(5,34,-2,LEAVES:1)
Block(5,41,-2,LEAVES:1)
Block(5,42,-2,LEAVES:1)
Block(5,42,7,LEAVES:1)
Block(5,43,1,LEAVES:1)
Block(5,43,4,LEAVES:1)
Block(5,43,6,LEAVES:1)
Block(5,43,7,LEAVES:1)
Block(5,44,0,LEAVES:1)
Block(5,44,1,LOG:13)
Block(5,44,2,LEAVES:1)
Block(5,44,3,LEAVES:1)
Block(5,44,4,LOG:13)
Block(5,44,5,LEAVES:1)
Block(5,44,6,LEAVES:1)
Block(5,45,3,LEAVES:1)
Block(5,45,4,LOG:13)
Block(5,46,-6,LEAVES:1)
Block(5,47,-6,LEAVES:1)
Block(5,47,-5,LEAVES:1)
Block(5,48,-5,LEAVES:1)
Block(5,48,-4,LOG:13)
Block(5,48,-3,LEAVES:1)
Block(5,49,-10,LEAVES:1)
Block(5,49,-8,LEAVES:1)
Block(5,49,-7,LEAVES:1)
Block(5,49,-6,LEAVES:1)
Block(5,49,-4,LEAVES:1)
Block(5,49,-2,LEAVES:1)
Block(5,50,-6,LEAVES:1)
Block(5,50,-1,LEAVES:1)
Block(5,50,0,LOG:13)
Block(5,50,1,LEAVES:1)
Block(5,51,-7,LEAVES:1)
Block(5,51,-6,LEAVES:1)
Block(5,51,-5,LEAVES:1)
Block(5,51,-1,LEAVES:1)
Block(5,51,0,LEAVES:1)
Block(5,51,4,LEAVES:1)
Block(5,51,6,LEAVES:1)
Block(5,52,-6,LEAVES:1)
Block(5,52,-5,LEAVES:1)
Block(5,52,-4,LEAVES:1)
Block(5,52,-1,LEAVES:1)
Block(5,52,4,LEAVES:1)
Block(5,52,7,LEAVES:1)
Block(5,53,-5,LEAVES:1)
Block(5,53,-4,LOG:13)
Block(5,53,-3,LEAVES:1)
Block(5,53,4,LEAVES:1)
Block(5,53,5,LOG:13)
Block(5,53,6,LEAVES:1)
Block(5,54,-4,LEAVES:1)
Block(5,54,-3,LEAVES:1)
Block(5,55,-3,LEAVES:1)
Block(5,55,1,LEAVES:1)
Block(5,56,-1,LEAVES:1)
Block(5,56,1,LEAVES:1)
Block(5,57,0,LOG:13)
Block(5,57,1,LEAVES:1)
Block(6,0,-1,LOG:13)
Block(6,0,0,LOG:13)
Block(6,24,2,LEAVES:1)
Block(6,24,3,LEAVES:1)
Block(6,25,3,LEAVES:1)
Block(6,25,4,LEAVES:1)
Block(6,25,5,LEAVES:1)
Block(6,26,0,LEAVES:1)
Block(6,26,1,LEAVES:1)
Block(6,26,4,LEAVES:1)
Block(6,27,1,LEAVES:1)
Block(6,27,2,LOG:13)
Block(6,27,3,LEAVES:1)
Block(6,31,-12,LEAVES:1)
Block(6,31,-11,LEAVES:1)
Block(6,32,-10,LEAVES:1)
Block(6,32,-6,LEAVES:1)
Block(6,33,-9,LOG:13)
Block(6,33,-8,LEAVES:1)
Block(6,33,-7,LEAVES:1)
Block(6,41,-3,LEAVES:1)
Block(6,41,-2,LEAVES:1)
Block(6,41,-1,LEAVES:1)
Block(6,42,3,LEAVES:1)
Block(6,42,7,LEAVES:1)
Block(6,42,8,LEAVES:1)
Block(6,43,-1,LEAVES:1)
Block(6,43,0,LOG:13)
Block(6,43,1,LEAVES:1)
Block(6,44,0,LEAVES:1)
Block(6,44,4,LEAVES:1)
Block(6,44,5,LOG:13)
Block(6,44,6,LEAVES:1)
Block(6,46,-8,LEAVES:1)
Block(6,47,-6,LEAVES:1)
Block(6,47,-5,LOG:13)
Block(6,47,-3,LEAVES:1)
Block(6,47,-2,LEAVES:1)
Block(6,48,-5,LOG:13)
Block(6,48,-4,LEAVES:1)
Block(6,48,-3,LEAVES:1)
Block(6,48,-2,LEAVES:1)
Block(6,48,-1,LEAVES:1)
Block(6,48,2,LEAVES:1)
Block(6,49,-2,LEAVES:1)
Block(6,49,0,LEAVES:1)
Block(6,50,-1,LEAVES:1)
Block(6,50,0,LOG:13)
Block(6,50,1,LEAVES:1)
Block(6,51,-6,LEAVES:1)
Block(6,51,-2,LEAVES:1)
Block(6,51,-1,LEAVES:1)
Block(6,51,4,LEAVES:1)
Block(6,52,-6,LEAVES:1)
Block(6,52,3,LEAVES:1)
Block(6,52,4,LEAVES:1)
Block(6,52,5,LEAVES:1)
Block(6,52,6,LOG:13)
Block(6,52,7,LEAVES:1)
Block(6,53,-5,LEAVES:1)
Block(6,53,-4,LOG:13)
Block(6,53,-3,LEAVES:1)
Block(6,54,-1,LEAVES:1)
Block(6,54,0,LEAVES:1)
Block(6,55,-1,LEAVES:1)
Block(6,56,-2,LEAVES:1)
Block(6,56,-1,LOG:13)
Block(6,56,0,LEAVES:1)
Block(6,56,1,LEAVES:1)
Block(6,56,2,LEAVES:1)
Block(6,57,-1,LEAVES:1)
Block(7,24,4,LEAVES:1)
Block(7,24,5,LEAVES:1)
Block(7,25,2,LEAVES:1)
Block(7,25,3,LEAVES:1)
Block(7,25,4,LEAVES:1)
Block(7,26,1,LEAVES:1)
Block(7,26,2,LOG:13)
Block(7,26,3,LEAVES:1)
Block(7,31,-11,LEAVES:1)
Block(7,31,-9,LEAVES:1)
Block(7,32,-11,LEAVES:1)
Block(7,32,-10,LOG:13)
Block(7,32,-9,LEAVES:1)
Block(7,32,-8,LEAVES:1)
Block(7,41,-1,LEAVES:1)
Block(7,42,-2,LEAVES:1)
Block(7,42,-1,LEAVES:1)
Block(7,42,0,LEAVES:1)
Block(7,42,2,LEAVES:1)
Block(7,42,3,LEAVES:1)
Block(7,43,-1,LEAVES:1)
Block(7,43,0,LOG:13)
Block(7,43,1,LEAVES:1)
Block(7,43,3,LEAVES:1)
Block(7,43,4,LEAVES:1)
Block(7,43,5,LEAVES:1)
Block(7,43,6,LOG:13)
Block(7,43,7,LEAVES:1)
Block(7,44,6,LEAVES:1)
Block(7,46,-9,LEAVES:1)
Block(7,46,-8,LEAVES:1)
Block(7,46,-6,LEAVES:1)
Block(7,47,-8,LEAVES:1)
Block(7,47,-7,LEAVES:1)
Block(7,47,-6,LOG:13)
Block(7,47,-5,LEAVES:1)
Block(7,47,-3,LEAVES:1)
Block(7,48,-6,LEAVES:1)
Block(7,48,2,LEAVES:1)
Block(7,48,3,LEAVES:1)
Block(7,49,-2,LEAVES:1)
Block(7,49,0,LEAVES:1)
Block(7,49,1,LOG:13)
Block(7,49,2,LEAVES:1)
Block(7,50,-7,LEAVES:1)
Block(7,50,-6,LEAVES:1)
Block(7,50,1,LEAVES:1)
Block(7,51,-6,LEAVES:1)
Block(7,51,4,LEAVES:1)
Block(7,51,6,LEAVES:1)
Block(7,51,7,LEAVES:1)
Block(7,51,8,LEAVES:1)
Block(7,52,-5,LEAVES:1)
Block(7,52,-4,LOG:13)
Block(7,52,-3,LEAVES:1)
Block(7,52,6,LEAVES:1)
Block(7,53,-4,LEAVES:1)
Block(7,55,-3,LEAVES:1)
Block(7,55,1,LEAVES:1)
Block(7,56,-2,LEAVES:1)
Block(7,56,-1,LOG:13)
Block(7,56,0,LEAVES:1)
Block(8,23,2,LEAVES:1)
Block(8,24,2,LEAVES:1)
Block(8,25,0,LEAVES:1)
Block(8,25,1,LEAVES:1)
Block(8,25,2,LEAVES:1)
Block(8,25,3,LOG:13)
Block(8,25,4,LEAVES:1)
Block(8,26,3,LEAVES:1)
Block(8,31,-12,LEAVES:1)
Block(8,31,-11,LEAVES:1)
Block(8,31,-9,LEAVES:1)
Block(8,32,-10,LEAVES:1)
Block(8,41,1,LEAVES:1)
Block(8,41,2,LEAVES:1)
Block(8,42,-1,LEAVES:1)
Block(8,42,0,LOG:13)
Block(8,42,1,LEAVES:1)
Block(8,42,3,LEAVES:1)
Block(8,42,4,LEAVES:1)
Block(8,42,6,LEAVES:1)
Block(8,42,7,LEAVES:1)
Block(8,42,8,LEAVES:1)
Block(8,42,9,LEAVES:1)
Block(8,43,0,LEAVES:1)
Block(8,43,6,LEAVES:1)
Block(8,43,7,LOG:13)
Block(8,43,8,LEAVES:1)
Block(8,46,-5,LEAVES:1)
Block(8,46,-4,LEAVES:1)
Block(8,47,-8,LEAVES:1)
Block(8,47,-7,LOG:13)
Block(8,47,-6,LEAVES:1)
Block(8,47,-5,LEAVES:1)
Block(8,48,0,LEAVES:1)
Block(8,49,1,LEAVES:1)
Block(8,49,2,LOG:13)
Block(8,49,3,LEAVES:1)
Block(8,50,2,LEAVES:1)
Block(8,51,-6,LEAVES:1)
Block(8,51,-4,LEAVES:1)
Block(8,51,-3,LEAVES:1)
Block(8,51,-2,LEAVES:1)
Block(8,51,6,LEAVES:1)
Block(8,52,-5,LEAVES:1)
Block(8,52,-4,LOG:13)
Block(8,52,-3,LEAVES:1)
Block(8,55,-2,LEAVES:1)
Block(8,55,-1,LEAVES:1)
Block(8,55,0,LEAVES:1)
Block(8,56,-1,LEAVES:1)
Block(9,24,1,LEAVES:1)
Block(9,24,2,LEAVES:1)
Block(9,24,3,LEAVES:1)
Block(9,24,4,LEAVES:1)
Block(9,24,5,LEAVES:1)
Block(9,25,2,LEAVES:1)
Block(9,25,3,LOG:13)
Block(9,25,4,LEAVES:1)
Block(9,31,-11,LEAVES:1)
Block(9,41,-2,LEAVES:1)
Block(9,41,-1,LEAVES:1)
Block(9,41,1,LEAVES:1)
Block(9,42,-1,LEAVES:1)
Block(9,42,0,LEAVES:1)
Block(9,42,1,LEAVES:1)
Block(9,42,6,LEAVES:1)
Block(9,42,8,LEAVES:1)
Block(9,43,7,LEAVES:1)
Block(9,46,-8,LEAVES:1)
Block(9,46,-7,LEAVES:1)
Block(9,46,-5,LEAVES:1)
Block(9,47,-7,LEAVES:1)
Block(9,47,-1,LEAVES:1)
Block(9,47,0,LEAVES:1)
Block(9,48,0,LEAVES:1)
Block(9,48,2,LEAVES:1)
Block(9,48,4,LEAVES:1)
Block(9,49,1,LEAVES:1)
Block(9,49,2,LOG:13)
Block(9,49,3,LEAVES:1)
Block(9,50,-6,LEAVES:1)
Block(9,50,-5,LEAVES:1)
Block(9,51,-5,LEAVES:1)
Block(9,51,-4,LOG:13)
Block(9,51,-3,LEAVES:1)
Block(9,55,-2,LEAVES:1)
Block(9,55,0,LEAVES:1)
Block(10,23,2,LEAVES:1)
Block(10,24,2,LEAVES:1)
Block(10,24,3,LOG:13)
Block(10,24,4,LEAVES:1)
Block(10,41,-1,LEAVES:1)
Block(10,41,1,LEAVES:1)
Block(10,42,8,LEAVES:1)
Block(10,46,-7,LEAVES:1)
Block(10,47,0,LEAVES:1)
Block(10,47,2,LEAVES:1)
Block(10,47,4,LEAVES:1)
Block(10,48,0,LEAVES:1)
Block(10,48,1,LEAVES:1)
Block(10,48,2,LOG:13)
Block(10,48,3,LEAVES:1)
Block(10,50,-6,LEAVES:1)
Block(10,50,-4,LEAVES:1)
Block(10,50,-3,LEAVES:1)
Block(10,50,-2,LEAVES:1)
Block(10,51,-4,LEAVES:1)
Block(11,23,1,LEAVES:1)
Block(11,23,2,LEAVES:1)
Block(11,23,4,LEAVES:1)
Block(11,23,5,LEAVES:1)
Block(11,24,3,LEAVES:1)
Block(11,24,4,LEAVES:1)
Block(11,46,1,LEAVES:1)
Block(11,46,2,LEAVES:1)
Block(11,47,2,LEAVES:1)
Block(11,48,2,LEAVES:1)
Block(11,50,-4,LEAVES:1)
Block(12,23,2,LEAVES:1)
Block(12,23,3,LEAVES:1)
Block(12,47,1,LEAVES:1)
Block(12,47,2,LEAVES:1)
Block(12,47,3,LEAVES:1)
Block(13,47,2,LEAVES:1)

#######################################################################
# +-----------------------------------------------------------------+ #
# |                            BO3 checks                           | #
# +-----------------------------------------------------------------+ #
#######################################################################

# Require a condition at a certain location in order for the BO3 to be spawned.
# BlockCheck(x,y,z,BlockName[,BlockName[,...]]) - one of the blocks must be at the location
# BlockCheckNot(x,y,z,BlockName[,BlockName[,...]]) - all the blocks must not be at the location
# LightCheck(x,y,z,minLightLevel,maxLightLevel) - light must be between min and max (inclusive)
# ModCheck(ModName[,ModName[,...]]) - all the mods listed must be loaded
# ModCheckNot(ModName[,ModName[,...]]) - all the mods listed must not be loaded

# You can use "Solid" as a BlockName for matching all solid blocks or "All" to match all blocks that aren't air.

# Examples:
#   BlockCheck(0,-1,0,GRASS,DIRT)  Require grass or dirt just below the object
#   BlockCheck(0,-1,0,Solid)       Require any solid block just below the object
#   BlockCheck(0,-1,0,WOOL)        Require any type of wool just below the object
#   BlockCheck(0,-1,0,WOOL:0)      Require white wool just below the object
#   BlockCheckNot(0,-1,0,WOOL:0)   Require that there is no white wool below the object
#   LightCheck(0,0,0,0,1)          Require almost complete darkness just below the object

BlockCheck(0,-1,0,GRASS,DIRT)

#######################################################################
# +-----------------------------------------------------------------+ #
# |                             Branches                            | #
# +-----------------------------------------------------------------+ #
#######################################################################

# Branches are child-BO3's that spawn if this BO3 is configured to spawn as a
# CustomStructure resource in a biome config. Branches can have branches,
# making complex structures possible. See the wiki for more details.

# Regular Branches spawn each branch with an independent chance of spawning.
# Branch(x,y,z,branchName,rotation,chance[,anotherBranchName,rotation,chance[,...]][IndividualChance])
# branchName - name of the object to spawn.
# rotation - NORTH, SOUTH, EAST or WEST.
# IndividualChance - The chance each branch has to spawn, assumed to be 100 when left blank
# isRequiredBranch - If this is set to true then at least one of the branches in this BO3 must spawn at these x,y,z coordinates. If no branch can spawn there then this BO3 fails to spawn and its branch is rolled back.
# isRequiredBranch:true branches must spawn or the current branch is rolled back entirely. This is useful for grouping BO3's that must spawn together, for instance a single room made of multiple BO3's/branches.
# If all parts of the room are connected together via isRequiredBranch:true branches then either the entire room will spawns or no part of it will spawn.
# *Note: When isRequiredBranch:true only one BO3 can be added per Branch() and it will automatically have a rarity of 100.0.
# isRequiredBranch:false branches are used to make optional parts of structures, for instance the middle section of a tunnel that has a beginning, middle and end BO3/branch and can have a variable length by repeating the middle BO3/branch.
# By making the start and end branches isRequiredBranch:true and the middle branch isRequiredbranch:false you can make it so that either:
# A. A tunnel spawns with at least a beginning and end branch
# B. A tunnel spawns with a beginning and end branch and as many middle branches as will fit in the available space.
# C. No tunnel spawns at all because there wasn't enough space to spawn at least a beginning and end branch.
# branchDepth - When creating a chain of branches that contains optional (isRequiredBranch:false) branches branch depth is configured for the first BO3 in the chain to determine the maximum length of the chain.
# branchDepth - 1 is inherited by each isRequiredBranch:false branch in the chain. When branchDepth is zero isRequiredBranch:false branches cannot spawn and the chain ends. In the case of the tunnel this means the last middle branch would be
# rolled back and an IsRequiredBranch:true end branch could be spawned in its place to make sure the tunnel has a proper ending.
# Instead of inheriting branchDepth - 1 from the parent branchDepth can be overridden by child branches if it is set higher than 0 (the default value).
# isRequiredBranch:true branches do inherit branchDepth and pass it on to their own branches, however they cannot be prevented from spawning by it and also don't subtract 1 from branchDepth when inheriting it.

# Weighted Branches spawn branches with a dependent chance of spawning.
# WeightedBranch(x,y,z,branchName,rotation,chance[,anotherBranchName,rotation,chance[,...]][MaxChanceOutOf])
# *Note: isRequiredBranch must be set to false. It is not possible to use isRequiredBranch:true with WeightedBranch() since isRequired:true branches must spawn and automatically have a rarity of 100.0.
# MaxChanceOutOf - The chance all branches have to spawn out of, assumed to be 100 when left blank

#######################################################################
# +-----------------------------------------------------------------+ #
# |                             Entities                            | #
# +-----------------------------------------------------------------+ #
#######################################################################

# Forge only (this may have changed, check for updates).
# An EntityFunction spawns an entity instead of a block. The entity is spawned only once when the BO3 is spawned.
# Entities are persistent by default so they don't de-spawn when no player is near, they are only unloaded.
# Usage: Entity(x,y,z,entityName,groupSize,NameTagOrNBTFileName) or Entity(x,y,z,mobName,groupSize)
# Use /otg entities to get a list of entities that can be used as entityName, this includes entities added by other mods and non-living entities.
# NameTagOrNBTFileName can be either a nametag for the mob or an .txt file with nbt data (such as myentityinfo.txt).
# In the text file you can use the same mob spawning parameters used with the /summon command to equip the
# entity and give it custom attributes etc. You can copy the DATA part of a summon command including surrounding 
# curly braces to a .txt file, for instance for: "/summon Skeleton x y z {DATA}"
# *Note: Unlike Block(), for Entity() .nbt files don't work, only .txt files work.

#######################################################################
# +-----------------------------------------------------------------+ #
# |                            Particles                            | #
# +-----------------------------------------------------------------+ #
#######################################################################

# Forge only (this may have changed, check for updates).
# Creates an invisible particle spawner at the given location that spawns particles every x milliseconds.
# Usage: Particle(x,y,z,particleName,interval,velocityX,velocityY,velocityZ)
# velocityX, velocityY and velocityZ are optional.
# Only vanilla particle names can be used, for 1.11.2 these are;
# explode, largeexplode, hugeexplosion, fireworksSpark, bubble, splash, wake, suspended
# depthsuspend, crit, magicCrit, smoke, largesmoke, spell, instantSpell, mobSpell
# mobSpellAmbient, witchMagic, dripWater, dripLava, angryVillager, happyVillager
# townaura, note, portal, enchantmenttable, flame, lava, footstep, cloud, reddust
# snowballpoof,  snowshovel, slime, heart, barrier, iconcrack, blockcrack, blockdust
# droplet, take, mobappearance, dragonbreath, endRod, damageIndicator, sweepAttack
# fallingdust, totem, spit.
# velocityX,velocityY,velocityZ - Spawn the enemy with the given velocity. If this is not filled in then a small random velocity is applied.

#######################################################################
# +-----------------------------------------------------------------+ #
# |                             Spawners                            | #
# +-----------------------------------------------------------------+ #
#######################################################################

# Forge only (this may have changed, check for updates).
# Creates an invisible entity spawner at the given location that spawns entities every x seconds.
# Entities can only spawn if their spawn requirements are met (zombies/skeletons only spawn in the dark etc). Max entity count for the server is ignored, each spawner has its own maxCount setting.
# Usage: Spawner(x,y,z,entityName,nbtFileName,groupSize,interval,spawnChance,maxCount,despawnTime,velocityX,velocityY,velocityZ,yaw,pitch)
# nbtFileName, despawnTime, velocityX, velocityY, velocityZ, yaw and pitch are optional
# Example Spawner(0, 0, 0, Villager, 1, 5, 100, 5) or Spawner(0, 0, 0, Villager, villager1.txt, 1, 5, 100, 5) or Spawner(0, 0, 0, Villager, 1, 5, 100, 5, 30, 1, 1, 1, 0, 0)
# entityName - Name of the entity to spawn, use /otg entities to get a list of entities that can be used as entityName, this includes entities added by other mods and non-living entities.
# nbtFileName - A .txt file with nbt data (such as myentityinfo.txt).
# In the text file you can use the same mob spawning parameters used with the /summon command to equip the
# entity and give it custom attributes etc. You can copy the DATA part of a summon command including surrounding 
# curly braces to a .txt file, for instance for: "/summon Skeleton x y z {DATA}"
# *Note: Unlike Block(), for Spawner() .nbt files don't work, only .txt files work.
# groupSize - Number of entities that should spawn for each successful spawn attempt.
# interval - Time in seconds between each spawn attempt.
# spawnChance - For each spawn attempt, the chance between 0-100 that the spawn attempt will succeed.
# maxCount - The maximum amount of this kind of entity that can exist within 32 blocks. If there are already maxCount or more entities of this type in a 32 radius this spawner will not spawn anything.
# despawnTime - After despawnTime seconds, if there is no player within 32 blocks of the entity it will despawn..
# velocityX,velocityY,velocityZ,yaw,pitch - Spawn the enemy with the given velocity and angle, handy for making traps and launchers (shooting arrows and fireballs etc).

#######################################################################
# +-----------------------------------------------------------------+ #
# |                             ModData                             | #
# +-----------------------------------------------------------------+ #
#######################################################################

# Forge only.
# Use the ModData() tag to include data that other mods can use
# Mod makers can use ModData and the /otg GetModData command to test IMC communications between OTG
# and their mod.
# Normal users can use it to spawn some mobs and blocks on command.
# ModData(x,y,z,"ModName", "MyModDataAsText"
# Example: ModData(x,y,z,MyCystomNPCMod,SpawnBobHere/WithAPotato/And50Health)
# Try not to use exotic/reserved characters, like brackets and comma's etc, this stuff isn't fool-proof.
# Also, use this only to store IDs/object names etc for your mod, DO NOT include things like character dialogue,
# messages on signs, loot lists etc in this file. As much as possible just store id's/names here and store all the data related to those id's/names in your own mod.
# OTG has some built in ModData commands for basic mob and block spawning.
# These are mostly just a demonstration for mod makers to show how ModData.
# can be used by other mods.
# For mob spawning in OTG use: ModData(x,y,z,OTG,mob/MobType/Count/Persistent/Name)
# mob: Makes OTG recognise this as a mob spawning command.
# MobType: Lower-case, no spaces. Any vanilla mob like dragon, skeleton, wither, villager etc
# Count: The number of mobs to spawn
# Persistent (true/false): Should the mobs never de-spawn? If set to true the mob will get a
# name-tag ingame so you can recognise it.
# Name: A name-tag for the monster/npc.
# Example: ModData(0,0,0,OTG,villager/1/true/Bob)
# To spawn blocks using ModData use: ModData(x,y,z,OTG,block/material)
# block: Makes OTG recognise this as a block spawning command.
# material: id or text, custom blocks can be added using ModName:MaterialName.
# To send all ModData within a radius in chunks around the player to the specified mod
# use this console command: /otg GetModData ModName Radius
# ModName: name of the mod, for OTG commands use OTG 
# Radius (optional): Radius in chunks around the player.
