
#######################################################################
# +-----------------------------------------------------------------+ #
# |                            BO3 object                           | #
# +-----------------------------------------------------------------+ #
#######################################################################

# This is the config file of a custom object.
# If you add this object correctly to your BiomeConfigs, it will spawn in the world.

# This is the creator of this BO3 object
Author: Unknown

# A short description of this BO3 object
Description: This BO3 was converted from a schematic using OTGEdit. The author and description information of the schematic could not be found. If you know who the author of the schematic is then please add this information.

# The BO3 version, don't change this! It can be used by external applications to do a version check.
Version: 3

# The settings mode, WriteAll, WriteWithoutComments or WriteDisable. See WorldConfig.
SettingsMode: WriteAll


#######################################################################
# +-----------------------------------------------------------------+ #
# |                          Main settings                          | #
# +-----------------------------------------------------------------+ #
#######################################################################

# This needs to be set to true to spawn the object in the Tree and Sapling resources.
Tree: true

# The frequency of the BO3 from 1 to 200. Tries this many times to spawn this BO3 when using the CustomObject(...) resource.
# Ignored by Tree(..), Sapling(..) and CustomStructure(..)
Frequency: 40

# The rarity of the BO3 from 0 to 100. Each spawn attempt has rarity% chance to succeed when using the CustomObject(...) resource.
# Ignored by Tree(..), Sapling(..) and CustomStructure(..)
Rarity: 100.0

# If you set this to true, the BO3 will be placed with a random rotation.
RotateRandomly: true

# The spawn height of the BO3: randomY, highestBlock or highestSolidBlock.
SpawnHeight: randomY

# The offset from the spawn height to spawn this BO3
# Ex. SpawnHeight = highestSolidBlock, SpawnHeightOffset = 3; This object will spawn 3 blocks above the highest solid block
SpawnHeightOffset: 0

# A random amount to offset the spawn location from the spawn offset height
# Ex. SpawnHeightOffset = 3, SpawnHeightVariance = 3; This object will spawn 3 to 6 blocks above the original spot it would have spawned
SpawnHeightVariance: 0

##############################
# Height Limits for the BO3. #
##############################

# When in randomY mode used as the minimum Y or in atMinY mode as the actual Y to spawn this BO3 at.
MinHeight: 63

# When in randomY mode used as the maximum Y to spawn this BO3 at.
MaxHeight: 255

######################
# Extrusion settings #
######################

# The style of extrusion you wish to use - BottomDown, TopUp, None (Default)
ExtrudeMode: None

# The blocks to extrude your BO3 through
ExtrudeThroughBlocks: AIR

# Objects can have other objects attacthed to it: branches. Branches can also
# have branches attached to it, which can also have branches, etc. This is the
# maximum branch depth for this objects.
MaxBranchDepth: 10

# When spawned with the UseWorld keyword, this BO3 should NOT spawn in the following biomes.
# If you write the BO3 name directly in the BiomeConfigs, this will be ignored.
ExcludedBiomes: All


#######################################################################
# +-----------------------------------------------------------------+ #
# |                      Source block settings                      | #
# +-----------------------------------------------------------------+ #
#######################################################################

# The block(s) the BO3 should spawn in.
SourceBlocks: AIR,GRASS:0,DIRT:0

# The maximum percentage of the BO3 that can be outside the SourceBlock.
# The BO3 won't be placed on a location with more blocks outside the SourceBlock than this percentage.
MaxPercentageOutsideSourceBlock: 5

# What to do when a block is about to be placed outside the SourceBlock? (dontPlace, placeAnyway)
OutsideSourceBlock: dontPlace

# Disable doReplaceBlocks to make this BO3 ignore any ReplacedBlocks settings in biome configs, improves performance.
DoReplaceBlocks: true

# OTG+ settings #
# Legacy setting, rename this file to .BO4 instead. Set this to true to enable the advanced customstructure features of OTG+.
IsOTGPlus: false


#######################################################################
# +-----------------------------------------------------------------+ #
# |                              Blocks                             | #
# +-----------------------------------------------------------------+ #
#######################################################################

# All the blocks used in the BO3 are listed here. Possible blocks:
# Block(x,y,z,id[.data][,nbtfile.nbt)
# RandomBlock(x,y,z,id[:data][,nbtfile.nbt],chance[,id[:data][,nbtfile.nbt],chance[,...]])
#  So RandomBlock(0,0,0,CHEST,chest.nbt,50,CHEST,anotherchest.nbt,100) will spawn a chest at
#  the BO3 origin, and give it a 50% chance to have the contents of chest.nbt, or, if that
#  fails, a 100% percent chance to have the contents of anotherchest.nbt.
# *Note: Unlike Entity() and Spawner(), for Block() .txt files don't work, only .nbt files work.
# MinecraftObject(x,y,z,name) (TODO: This may not work anymore and needs to be tested.
#  Spawns an object in the Mojang NBT structure format. For example, 
#  MinecraftObject(0,0,0,minecraft:igloo/igloo_bottom)
#  spawns the bottom part of an igloo.
Block(-12,18,-2,biomesoplenty:leaves_3:11)
Block(-12,18,-1,biomesoplenty:leaves_3:11)
Block(-12,18,0,biomesoplenty:leaves_3:11)
Block(-12,19,-2,biomesoplenty:leaves_3:11)
Block(-12,19,-1,biomesoplenty:leaves_3:11)
Block(-12,19,0,biomesoplenty:leaves_3:11)
Block(-12,21,5,biomesoplenty:leaves_3:11)
Block(-12,21,6,biomesoplenty:leaves_3:11)
Block(-12,21,7,biomesoplenty:leaves_3:11)
Block(-12,22,5,biomesoplenty:leaves_3:11)
Block(-12,22,6,biomesoplenty:leaves_3:11)
Block(-12,22,7,biomesoplenty:leaves_3:11)
Block(-11,14,4,biomesoplenty:leaves_3:11)
Block(-11,14,5,biomesoplenty:leaves_3:11)
Block(-11,14,6,biomesoplenty:leaves_3:11)
Block(-11,15,4,biomesoplenty:leaves_3:11)
Block(-11,15,5,biomesoplenty:leaves_3:11)
Block(-11,15,6,biomesoplenty:leaves_3:11)
Block(-11,17,-1,biomesoplenty:leaves_3:11)
Block(-11,18,-3,biomesoplenty:leaves_3:11)
Block(-11,18,-2,biomesoplenty:leaves_3:11)
Block(-11,18,-1,biomesoplenty:leaves_3:11)
Block(-11,18,0,biomesoplenty:leaves_3:11)
Block(-11,18,1,biomesoplenty:leaves_3:11)
Block(-11,19,-3,biomesoplenty:leaves_3:11)
Block(-11,19,-2,biomesoplenty:leaves_3:11)
Block(-11,19,-1,biomesoplenty:leaves_3:11)
Block(-11,19,0,biomesoplenty:leaves_3:11)
Block(-11,19,1,biomesoplenty:leaves_3:11)
Block(-11,20,-3,biomesoplenty:leaves_3:11)
Block(-11,20,-2,biomesoplenty:leaves_3:11)
Block(-11,20,-1,biomesoplenty:leaves_3:11)
Block(-11,20,2,biomesoplenty:leaves_3:11)
Block(-11,20,3,biomesoplenty:leaves_3:11)
Block(-11,20,4,biomesoplenty:leaves_3:11)
Block(-11,20,6,biomesoplenty:leaves_3:11)
Block(-11,21,2,biomesoplenty:leaves_3:11)
Block(-11,21,3,biomesoplenty:leaves_3:11)
Block(-11,21,4,biomesoplenty:leaves_3:11)
Block(-11,21,5,biomesoplenty:leaves_3:11)
Block(-11,21,6,biomesoplenty:leaves_3:11)
Block(-11,21,7,biomesoplenty:leaves_3:11)
Block(-11,21,8,biomesoplenty:leaves_3:11)
Block(-11,22,4,biomesoplenty:leaves_3:11)
Block(-11,22,5,biomesoplenty:leaves_3:11)
Block(-11,22,6,biomesoplenty:leaves_3:11)
Block(-11,22,7,biomesoplenty:leaves_3:11)
Block(-11,22,8,biomesoplenty:leaves_3:11)
Block(-11,23,6,biomesoplenty:leaves_3:11)
Block(-10,13,5,biomesoplenty:leaves_3:11)
Block(-10,14,3,biomesoplenty:leaves_3:11)
Block(-10,14,4,biomesoplenty:leaves_3:11)
Block(-10,14,5,biomesoplenty:leaves_3:11)
Block(-10,14,6,biomesoplenty:leaves_3:11)
Block(-10,14,7,biomesoplenty:leaves_3:11)
Block(-10,14,8,biomesoplenty:leaves_3:11)
Block(-10,14,9,biomesoplenty:leaves_3:11)
Block(-10,15,3,biomesoplenty:leaves_3:11)
Block(-10,15,4,biomesoplenty:leaves_3:11)
Block(-10,15,5,biomesoplenty:leaves_3:11)
Block(-10,15,6,biomesoplenty:leaves_3:11)
Block(-10,15,7,biomesoplenty:leaves_3:11)
Block(-10,15,8,biomesoplenty:leaves_3:11)
Block(-10,15,9,biomesoplenty:leaves_3:11)
Block(-10,16,5,biomesoplenty:leaves_3:11)
Block(-10,16,7,biomesoplenty:leaves_3:11)
Block(-10,16,8,biomesoplenty:leaves_3:11)
Block(-10,16,9,biomesoplenty:leaves_3:11)
Block(-10,17,-2,biomesoplenty:leaves_3:11)
Block(-10,17,-1,biomesoplenty:leaves_3:11)
Block(-10,17,0,biomesoplenty:leaves_3:11)
Block(-10,18,-3,biomesoplenty:leaves_3:11)
Block(-10,18,-2,biomesoplenty:leaves_3:11)
Block(-10,18,-1,biomesoplenty:leaves_3:11)
Block(-10,18,0,biomesoplenty:leaves_3:11)
Block(-10,18,1,biomesoplenty:leaves_3:11)
Block(-10,19,-4,biomesoplenty:leaves_3:11)
Block(-10,19,-3,biomesoplenty:leaves_3:11)
Block(-10,19,-2,biomesoplenty:leaves_3:11)
Block(-10,19,-1,biomesoplenty:leaves_3:11)
Block(-10,19,0,biomesoplenty:leaves_3:11)
Block(-10,19,1,biomesoplenty:leaves_3:11)
Block(-10,19,3,biomesoplenty:leaves_3:11)
Block(-10,20,-4,biomesoplenty:leaves_3:11)
Block(-10,20,-3,biomesoplenty:leaves_3:11)
Block(-10,20,-2,biomesoplenty:leaves_3:11)
Block(-10,20,-1,biomesoplenty:leaves_3:11)
Block(-10,20,0,biomesoplenty:leaves_3:11)
Block(-10,20,1,biomesoplenty:leaves_3:11)
Block(-10,20,2,biomesoplenty:leaves_3:11)
Block(-10,20,3,biomesoplenty:leaves_3:11)
Block(-10,20,4,biomesoplenty:leaves_3:11)
Block(-10,20,5,biomesoplenty:leaves_3:11)
Block(-10,20,6,biomesoplenty:leaves_3:11)
Block(-10,20,7,biomesoplenty:leaves_3:11)
Block(-10,20,9,biomesoplenty:leaves_3:11)
Block(-10,20,10,biomesoplenty:leaves_3:11)
Block(-10,20,11,biomesoplenty:leaves_3:11)
Block(-10,21,-2,biomesoplenty:leaves_3:11)
Block(-10,21,1,biomesoplenty:leaves_3:11)
Block(-10,21,2,biomesoplenty:leaves_3:11)
Block(-10,21,3,biomesoplenty:leaves_3:11)
Block(-10,21,4,biomesoplenty:leaves_3:11)
Block(-10,21,5,biomesoplenty:leaves_3:11)
Block(-10,21,6,biomesoplenty:leaves_3:11)
Block(-10,21,7,biomesoplenty:leaves_3:11)
Block(-10,21,8,biomesoplenty:leaves_3:11)
Block(-10,21,9,biomesoplenty:leaves_3:11)
Block(-10,21,10,biomesoplenty:leaves_3:11)
Block(-10,21,11,biomesoplenty:leaves_3:11)
Block(-10,22,3,biomesoplenty:leaves_3:11)
Block(-10,22,4,biomesoplenty:leaves_3:11)
Block(-10,22,5,biomesoplenty:leaves_3:11)
Block(-10,22,6,biomesoplenty:leaves_3:11)
Block(-10,22,7,biomesoplenty:leaves_3:11)
Block(-10,22,8,biomesoplenty:leaves_3:11)
Block(-10,23,5,biomesoplenty:leaves_3:11)
Block(-10,23,6,biomesoplenty:leaves_3:11)
Block(-10,23,7,biomesoplenty:leaves_3:11)
Block(-9,13,4,biomesoplenty:leaves_3:11)
Block(-9,13,5,biomesoplenty:leaves_3:11)
Block(-9,13,6,biomesoplenty:leaves_3:11)
Block(-9,13,8,biomesoplenty:leaves_3:11)
Block(-9,14,3,biomesoplenty:leaves_3:11)
Block(-9,14,4,biomesoplenty:leaves_3:11)
Block(-9,14,5,biomesoplenty:leaves_3:11)
Block(-9,14,6,biomesoplenty:leaves_3:11)
Block(-9,14,7,biomesoplenty:leaves_3:11)
Block(-9,14,8,biomesoplenty:leaves_3:11)
Block(-9,14,9,biomesoplenty:leaves_3:11)
Block(-9,14,10,biomesoplenty:leaves_3:11)
Block(-9,15,3,biomesoplenty:leaves_3:11)
Block(-9,15,4,biomesoplenty:leaves_3:11)
Block(-9,15,5,biomesoplenty:leaves_3:11)
Block(-9,15,6,biomesoplenty:leaves_3:11)
Block(-9,15,7,biomesoplenty:leaves_3:11)
Block(-9,15,8,biomesoplenty:leaves_3:11)
Block(-9,15,9,biomesoplenty:leaves_3:11)
Block(-9,15,10,biomesoplenty:leaves_3:11)
Block(-9,16,4,biomesoplenty:leaves_3:11)
Block(-9,16,5,biomesoplenty:leaves_3:11)
Block(-9,16,6,biomesoplenty:leaves_3:11)
Block(-9,16,7,biomesoplenty:leaves_3:11)
Block(-9,16,8,biomesoplenty:leaves_3:11)
Block(-9,16,9,biomesoplenty:leaves_3:11)
Block(-9,16,10,biomesoplenty:leaves_3:11)
Block(-9,16,11,biomesoplenty:leaves_3:11)
Block(-9,17,-1,biomesoplenty:leaves_3:11)
Block(-9,17,8,biomesoplenty:leaves_3:11)
Block(-9,17,9,biomesoplenty:leaves_3:11)
Block(-9,17,10,biomesoplenty:leaves_3:11)
Block(-9,17,11,biomesoplenty:leaves_3:11)
Block(-9,18,-3,biomesoplenty:leaves_3:11)
Block(-9,18,-2,biomesoplenty:leaves_3:11)
Block(-9,18,-1,biomesoplenty:leaves_3:11)
Block(-9,18,0,biomesoplenty:leaves_3:11)
Block(-9,18,1,biomesoplenty:leaves_3:11)
Block(-9,19,-4,biomesoplenty:leaves_3:11)
Block(-9,19,-3,biomesoplenty:leaves_3:11)
Block(-9,19,-2,biomesoplenty:leaves_3:11)
Block(-9,19,-1,biomesoplenty:leaves_3:11)
Block(-9,19,0,biomesoplenty:leaves_3:11)
Block(-9,19,1,biomesoplenty:leaves_3:11)
Block(-9,19,2,biomesoplenty:leaves_3:11)
Block(-9,19,3,biomesoplenty:leaves_3:11)
Block(-9,19,4,biomesoplenty:leaves_3:11)
Block(-9,19,10,biomesoplenty:leaves_3:11)
Block(-9,20,-4,biomesoplenty:leaves_3:11)
Block(-9,20,-3,biomesoplenty:leaves_3:11)
Block(-9,20,-2,biomesoplenty:leaves_3:11)
Block(-9,20,-1,biomesoplenty:leaves_3:11)
Block(-9,20,0,biomesoplenty:leaves_3:11)
Block(-9,20,1,biomesoplenty:leaves_3:11)
Block(-9,20,2,biomesoplenty:leaves_3:11)
Block(-9,20,3,biomesoplenty:leaves_3:11)
Block(-9,20,4,biomesoplenty:leaves_3:11)
Block(-9,20,5,biomesoplenty:leaves_3:11)
Block(-9,20,6,biomesoplenty:leaves_3:11)
Block(-9,20,7,biomesoplenty:leaves_3:11)
Block(-9,20,8,biomesoplenty:leaves_3:11)
Block(-9,20,9,biomesoplenty:leaves_3:11)
Block(-9,20,10,biomesoplenty:leaves_3:11)
Block(-9,20,11,biomesoplenty:leaves_3:11)
Block(-9,20,12,biomesoplenty:leaves_3:11)
Block(-9,21,-3,biomesoplenty:leaves_3:11)
Block(-9,21,-2,biomesoplenty:leaves_3:11)
Block(-9,21,-1,biomesoplenty:leaves_3:11)
Block(-9,21,1,biomesoplenty:leaves_3:11)
Block(-9,21,2,biomesoplenty:leaves_3:11)
Block(-9,21,3,biomesoplenty:leaves_3:11)
Block(-9,21,4,biomesoplenty:leaves_3:11)
Block(-9,21,5,biomesoplenty:leaves_3:11)
Block(-9,21,6,biomesoplenty:leaves_3:11)
Block(-9,21,7,biomesoplenty:leaves_3:11)
Block(-9,21,8,biomesoplenty:leaves_3:11)
Block(-9,21,9,biomesoplenty:leaves_3:11)
Block(-9,21,10,biomesoplenty:leaves_3:11)
Block(-9,21,11,biomesoplenty:leaves_3:11)
Block(-9,21,12,biomesoplenty:leaves_3:11)
Block(-9,22,2,biomesoplenty:leaves_3:11)
Block(-9,22,3,biomesoplenty:leaves_3:11)
Block(-9,22,4,biomesoplenty:leaves_3:11)
Block(-9,22,5,biomesoplenty:leaves_3:11)
Block(-9,22,6,biomesoplenty:leaves_3:11)
Block(-9,22,7,biomesoplenty:leaves_3:11)
Block(-9,22,8,biomesoplenty:leaves_3:11)
Block(-9,22,9,biomesoplenty:leaves_3:11)
Block(-9,22,10,biomesoplenty:leaves_3:11)
Block(-9,23,4,biomesoplenty:leaves_3:11)
Block(-9,23,5,biomesoplenty:leaves_3:11)
Block(-9,23,6,biomesoplenty:leaves_3:11)
Block(-9,23,7,biomesoplenty:leaves_3:11)
Block(-9,32,1,biomesoplenty:leaves_3:11)
Block(-9,32,2,biomesoplenty:leaves_3:11)
Block(-9,32,3,biomesoplenty:leaves_3:11)
Block(-9,33,1,biomesoplenty:leaves_3:11)
Block(-9,33,2,biomesoplenty:leaves_3:11)
Block(-9,33,3,biomesoplenty:leaves_3:11)
Block(-8,13,5,biomesoplenty:leaves_3:11)
Block(-8,13,7,biomesoplenty:leaves_3:11)
Block(-8,13,8,biomesoplenty:leaves_3:11)
Block(-8,13,9,biomesoplenty:leaves_3:11)
Block(-8,14,3,biomesoplenty:leaves_3:11)
Block(-8,14,4,biomesoplenty:leaves_3:11)
Block(-8,14,5,biomesoplenty:leaves_3:11)
Block(-8,14,6,biomesoplenty:leaves_3:11)
Block(-8,14,7,biomesoplenty:leaves_3:11)
Block(-8,14,8,biomesoplenty:leaves_3:11)
Block(-8,14,9,biomesoplenty:leaves_3:11)
Block(-8,14,10,biomesoplenty:leaves_3:11)
Block(-8,15,2,biomesoplenty:leaves_3:11)
Block(-8,15,3,biomesoplenty:leaves_3:11)
Block(-8,15,4,biomesoplenty:leaves_3:11)
Block(-8,15,5,biomesoplenty:leaves_3:11)
Block(-8,15,6,biomesoplenty:leaves_3:11)
Block(-8,15,7,biomesoplenty:leaves_3:11)
Block(-8,15,8,biomesoplenty:leaves_3:11)
Block(-8,15,9,biomesoplenty:leaves_3:11)
Block(-8,15,10,biomesoplenty:leaves_3:11)
Block(-8,16,-3,biomesoplenty:leaves_3:11)
Block(-8,16,-2,biomesoplenty:leaves_3:11)
Block(-8,16,-1,biomesoplenty:leaves_3:11)
Block(-8,16,0,biomesoplenty:leaves_3:11)
Block(-8,16,2,biomesoplenty:leaves_3:11)
Block(-8,16,3,biomesoplenty:leaves_3:11)
Block(-8,16,4,biomesoplenty:leaves_3:11)
Block(-8,16,5,biomesoplenty:leaves_3:11)
Block(-8,16,6,biomesoplenty:leaves_3:11)
Block(-8,16,7,biomesoplenty:leaves_3:11)
Block(-8,16,8,biomesoplenty:leaves_3:11)
Block(-8,16,9,biomesoplenty:leaves_3:11)
Block(-8,16,10,biomesoplenty:leaves_3:11)
Block(-8,16,11,biomesoplenty:leaves_3:11)
Block(-8,16,12,biomesoplenty:leaves_3:11)
Block(-8,17,-3,biomesoplenty:leaves_3:11)
Block(-8,17,-2,biomesoplenty:leaves_3:11)
Block(-8,17,-1,biomesoplenty:leaves_3:11)
Block(-8,17,0,biomesoplenty:leaves_3:11)
Block(-8,17,6,biomesoplenty:leaves_3:11)
Block(-8,17,7,biomesoplenty:leaves_3:11)
Block(-8,17,8,biomesoplenty:leaves_3:11)
Block(-8,17,9,biomesoplenty:leaves_3:11)
Block(-8,17,10,biomesoplenty:leaves_3:11)
Block(-8,17,11,biomesoplenty:leaves_3:11)
Block(-8,17,12,biomesoplenty:leaves_3:11)
Block(-8,18,-3,biomesoplenty:leaves_3:11)
Block(-8,18,-2,biomesoplenty:leaves_3:11)
Block(-8,18,-1,biomesoplenty:leaves_3:11)
Block(-8,18,0,biomesoplenty:leaves_3:11)
Block(-8,18,1,biomesoplenty:leaves_3:11)
Block(-8,18,10,biomesoplenty:leaves_3:11)
Block(-8,18,11,biomesoplenty:leaves_3:11)
Block(-8,18,12,biomesoplenty:leaves_3:11)
Block(-8,18,13,biomesoplenty:leaves_3:11)
Block(-8,19,-4,biomesoplenty:leaves_3:11)
Block(-8,19,-3,biomesoplenty:leaves_3:11)
Block(-8,19,-2,biomesoplenty:leaves_3:11)
Block(-8,19,-1,biomesoplenty:leaves_3:11)
Block(-8,19,0,biomesoplenty:leaves_3:11)
Block(-8,19,1,biomesoplenty:leaves_3:11)
Block(-8,19,3,biomesoplenty:leaves_3:11)
Block(-8,19,4,biomesoplenty:leaves_3:11)
Block(-8,19,5,biomesoplenty:leaves_3:11)
Block(-8,19,6,biomesoplenty:leaves_3:11)
Block(-8,19,9,biomesoplenty:leaves_3:11)
Block(-8,19,10,biomesoplenty:leaves_3:11)
Block(-8,19,11,biomesoplenty:leaves_3:11)
Block(-8,19,12,biomesoplenty:leaves_3:11)
Block(-8,19,13,biomesoplenty:leaves_3:11)
Block(-8,20,-4,biomesoplenty:leaves_3:11)
Block(-8,20,-3,biomesoplenty:leaves_3:11)
Block(-8,20,-2,biomesoplenty:leaves_3:11)
Block(-8,20,-1,biomesoplenty:leaves_3:11)
Block(-8,20,0,biomesoplenty:leaves_3:11)
Block(-8,20,1,biomesoplenty:leaves_3:11)
Block(-8,20,2,biomesoplenty:leaves_3:11)
Block(-8,20,3,biomesoplenty:leaves_3:11)
Block(-8,20,4,biomesoplenty:leaves_3:11)
Block(-8,20,5,biomesoplenty:leaves_3:11)
Block(-8,20,6,biomesoplenty:leaves_3:11)
Block(-8,20,7,biomesoplenty:leaves_3:11)
Block(-8,20,8,biomesoplenty:leaves_3:11)
Block(-8,20,9,biomesoplenty:leaves_3:11)
Block(-8,20,10,biomesoplenty:leaves_3:11)
Block(-8,20,11,biomesoplenty:leaves_3:11)
Block(-8,20,12,biomesoplenty:leaves_3:11)
Block(-8,21,-2,biomesoplenty:leaves_3:11)
Block(-8,21,1,biomesoplenty:leaves_3:11)
Block(-8,21,2,biomesoplenty:leaves_3:11)
Block(-8,21,3,biomesoplenty:leaves_3:11)
Block(-8,21,4,biomesoplenty:leaves_3:11)
Block(-8,21,5,biomesoplenty:leaves_3:11)
Block(-8,21,6,biomesoplenty:leaves_3:11)
Block(-8,21,7,biomesoplenty:leaves_3:11)
Block(-8,21,8,biomesoplenty:leaves_3:11)
Block(-8,21,9,biomesoplenty:leaves_3:11)
Block(-8,21,10,biomesoplenty:leaves_3:11)
Block(-8,21,11,biomesoplenty:leaves_3:11)
Block(-8,21,12,biomesoplenty:leaves_3:11)
Block(-8,22,3,biomesoplenty:leaves_3:11)
Block(-8,22,4,biomesoplenty:leaves_3:11)
Block(-8,22,5,biomesoplenty:leaves_3:11)
Block(-8,22,6,biomesoplenty:leaves_3:11)
Block(-8,22,7,biomesoplenty:leaves_3:11)
Block(-8,22,8,biomesoplenty:leaves_3:11)
Block(-8,22,9,biomesoplenty:leaves_3:11)
Block(-8,22,10,biomesoplenty:leaves_3:11)
Block(-8,22,11,biomesoplenty:leaves_3:11)
Block(-8,23,-2,biomesoplenty:leaves_3:11)
Block(-8,23,-1,biomesoplenty:leaves_3:11)
Block(-8,23,0,biomesoplenty:leaves_3:11)
Block(-8,23,3,biomesoplenty:leaves_3:11)
Block(-8,23,4,biomesoplenty:leaves_3:11)
Block(-8,23,5,biomesoplenty:leaves_3:11)
Block(-8,23,6,biomesoplenty:leaves_3:11)
Block(-8,23,7,biomesoplenty:leaves_3:11)
Block(-8,23,8,biomesoplenty:leaves_3:11)
Block(-8,23,9,biomesoplenty:leaves_3:11)
Block(-8,24,-2,biomesoplenty:leaves_3:11)
Block(-8,24,-1,biomesoplenty:leaves_3:11)
Block(-8,24,0,biomesoplenty:leaves_3:11)
Block(-8,24,2,biomesoplenty:leaves_3:11)
Block(-8,24,3,biomesoplenty:leaves_3:11)
Block(-8,24,4,biomesoplenty:leaves_3:11)
Block(-8,24,5,biomesoplenty:leaves_3:11)
Block(-8,25,2,biomesoplenty:leaves_3:11)
Block(-8,25,3,biomesoplenty:leaves_3:11)
Block(-8,25,4,biomesoplenty:leaves_3:11)
Block(-8,29,8,biomesoplenty:leaves_3:11)
Block(-8,29,9,biomesoplenty:leaves_3:11)
Block(-8,29,10,biomesoplenty:leaves_3:11)
Block(-8,30,8,biomesoplenty:leaves_3:11)
Block(-8,30,9,biomesoplenty:leaves_3:11)
Block(-8,30,10,biomesoplenty:leaves_3:11)
Block(-8,31,2,biomesoplenty:leaves_3:11)
Block(-8,32,0,biomesoplenty:leaves_3:11)
Block(-8,32,1,biomesoplenty:leaves_3:11)
Block(-8,32,2,biomesoplenty:leaves_3:11)
Block(-8,32,3,biomesoplenty:leaves_3:11)
Block(-8,32,4,biomesoplenty:leaves_3:11)
Block(-8,33,0,biomesoplenty:leaves_3:11)
Block(-8,33,1,biomesoplenty:leaves_3:11)
Block(-8,33,2,biomesoplenty:leaves_3:11)
Block(-8,33,3,biomesoplenty:leaves_3:11)
Block(-8,33,4,biomesoplenty:leaves_3:11)
Block(-8,33,5,biomesoplenty:leaves_3:11)
Block(-8,33,6,biomesoplenty:leaves_3:11)
Block(-8,33,7,biomesoplenty:leaves_3:11)
Block(-8,34,2,biomesoplenty:leaves_3:11)
Block(-8,34,5,biomesoplenty:leaves_3:11)
Block(-8,34,6,biomesoplenty:leaves_3:11)
Block(-8,34,7,biomesoplenty:leaves_3:11)
Block(-7,13,8,biomesoplenty:leaves_3:11)
Block(-7,13,11,biomesoplenty:leaves_3:11)
Block(-7,13,12,biomesoplenty:leaves_3:11)
Block(-7,13,13,biomesoplenty:leaves_3:11)
Block(-7,14,3,biomesoplenty:leaves_3:11)
Block(-7,14,4,biomesoplenty:leaves_3:11)
Block(-7,14,5,biomesoplenty:leaves_3:11)
Block(-7,14,6,biomesoplenty:leaves_3:11)
Block(-7,14,7,biomesoplenty:leaves_3:11)
Block(-7,14,8,biomesoplenty:leaves_3:11)
Block(-7,14,9,biomesoplenty:leaves_3:11)
Block(-7,14,10,biomesoplenty:leaves_3:11)
Block(-7,14,11,biomesoplenty:leaves_3:11)
Block(-7,14,12,biomesoplenty:leaves_3:11)
Block(-7,14,13,biomesoplenty:leaves_3:11)
Block(-7,15,-6,biomesoplenty:leaves_3:11)
Block(-7,15,-5,biomesoplenty:leaves_3:11)
Block(-7,15,-4,biomesoplenty:leaves_3:11)
Block(-7,15,-2,biomesoplenty:leaves_3:11)
Block(-7,15,1,biomesoplenty:leaves_3:11)
Block(-7,15,2,biomesoplenty:leaves_3:11)
Block(-7,15,3,biomesoplenty:leaves_3:11)
Block(-7,15,4,biomesoplenty:leaves_3:11)
Block(-7,15,5,biomesoplenty:leaves_3:11)
Block(-7,15,6,biomesoplenty:leaves_3:11)
Block(-7,15,7,biomesoplenty:leaves_3:11)
Block(-7,15,8,biomesoplenty:leaves_3:11)
Block(-7,15,9,biomesoplenty:leaves_3:11)
Block(-7,15,10,biomesoplenty:leaves_3:11)
Block(-7,15,11,biomesoplenty:leaves_3:11)
Block(-7,16,-6,biomesoplenty:leaves_3:11)
Block(-7,16,-5,biomesoplenty:leaves_3:11)
Block(-7,16,-4,biomesoplenty:leaves_3:11)
Block(-7,16,-3,biomesoplenty:leaves_3:11)
Block(-7,16,-2,biomesoplenty:leaves_3:11)
Block(-7,16,-1,biomesoplenty:leaves_3:11)
Block(-7,16,0,biomesoplenty:leaves_3:11)
Block(-7,16,1,biomesoplenty:leaves_3:11)
Block(-7,16,2,biomesoplenty:leaves_3:11)
Block(-7,16,3,biomesoplenty:leaves_3:11)
Block(-7,16,4,biomesoplenty:leaves_3:11)
Block(-7,16,5,biomesoplenty:leaves_3:11)
Block(-7,16,6,biomesoplenty:leaves_3:11)
Block(-7,16,7,biomesoplenty:leaves_3:11)
Block(-7,16,8,biomesoplenty:leaves_3:11)
Block(-7,16,9,biomesoplenty:leaves_3:11)
Block(-7,16,10,biomesoplenty:leaves_3:11)
Block(-7,16,11,biomesoplenty:leaves_3:11)
Block(-7,16,12,biomesoplenty:leaves_3:11)
Block(-7,17,-4,biomesoplenty:leaves_3:11)
Block(-7,17,-3,biomesoplenty:leaves_3:11)
Block(-7,17,-2,biomesoplenty:leaves_3:11)
Block(-7,17,-1,biomesoplenty:leaves_3:11)
Block(-7,17,0,biomesoplenty:leaves_3:11)
Block(-7,17,3,biomesoplenty:leaves_3:11)
Block(-7,17,5,biomesoplenty:leaves_3:11)
Block(-7,17,6,biomesoplenty:leaves_3:11)
Block(-7,17,7,biomesoplenty:leaves_3:11)
Block(-7,17,8,biomesoplenty:leaves_3:11)
Block(-7,17,9,biomesoplenty:leaves_3:11)
Block(-7,17,10,biomesoplenty:leaves_3:11)
Block(-7,17,11,biomesoplenty:leaves_3:11)
Block(-7,17,12,biomesoplenty:leaves_3:11)
Block(-7,18,-4,biomesoplenty:leaves_3:11)
Block(-7,18,-3,biomesoplenty:leaves_3:11)
Block(-7,18,-2,biomesoplenty:leaves_3:11)
Block(-7,18,-1,biomesoplenty:leaves_3:11)
Block(-7,18,0,biomesoplenty:leaves_3:11)
Block(-7,18,1,biomesoplenty:leaves_3:11)
Block(-7,18,3,biomesoplenty:leaves_3:11)
Block(-7,18,4,biomesoplenty:leaves_3:11)
Block(-7,18,7,biomesoplenty:leaves_3:11)
Block(-7,18,9,biomesoplenty:leaves_3:11)
Block(-7,18,10,biomesoplenty:leaves_3:11)
Block(-7,18,11,biomesoplenty:leaves_3:11)
Block(-7,18,12,biomesoplenty:leaves_3:11)
Block(-7,18,13,biomesoplenty:leaves_3:11)
Block(-7,18,14,biomesoplenty:leaves_3:11)
Block(-7,19,-4,biomesoplenty:leaves_3:11)
Block(-7,19,-3,biomesoplenty:leaves_3:11)
Block(-7,19,-2,biomesoplenty:leaves_3:11)
Block(-7,19,-1,biomesoplenty:leaves_3:11)
Block(-7,19,0,biomesoplenty:leaves_3:11)
Block(-7,19,1,biomesoplenty:leaves_3:11)
Block(-7,19,2,biomesoplenty:leaves_3:11)
Block(-7,19,3,biomesoplenty:leaves_3:11)
Block(-7,19,4,biomesoplenty:leaves_3:11)
Block(-7,19,5,biomesoplenty:leaves_3:11)
Block(-7,19,6,biomesoplenty:leaves_3:11)
Block(-7,19,9,biomesoplenty:leaves_3:11)
Block(-7,19,10,biomesoplenty:leaves_3:11)
Block(-7,19,11,biomesoplenty:leaves_3:11)
Block(-7,19,12,biomesoplenty:leaves_3:11)
Block(-7,19,13,biomesoplenty:leaves_3:11)
Block(-7,19,14,biomesoplenty:leaves_3:11)
Block(-7,20,-7,biomesoplenty:leaves_3:11)
Block(-7,20,-6,biomesoplenty:leaves_3:11)
Block(-7,20,-5,biomesoplenty:leaves_3:11)
Block(-7,20,-3,biomesoplenty:leaves_3:11)
Block(-7,20,-2,biomesoplenty:leaves_3:11)
Block(-7,20,-1,biomesoplenty:leaves_3:11)
Block(-7,20,1,biomesoplenty:leaves_3:11)
Block(-7,20,2,biomesoplenty:leaves_3:11)
Block(-7,20,3,biomesoplenty:leaves_3:11)
Block(-7,20,4,biomesoplenty:leaves_3:11)
Block(-7,20,5,biomesoplenty:leaves_3:11)
Block(-7,20,6,biomesoplenty:leaves_3:11)
Block(-7,20,7,biomesoplenty:leaves_3:11)
Block(-7,20,8,biomesoplenty:leaves_3:11)
Block(-7,20,9,biomesoplenty:leaves_3:11)
Block(-7,20,10,biomesoplenty:leaves_3:11)
Block(-7,20,11,biomesoplenty:leaves_3:11)
Block(-7,20,12,biomesoplenty:leaves_3:11)
Block(-7,21,-7,biomesoplenty:leaves_3:11)
Block(-7,21,-6,biomesoplenty:leaves_3:11)
Block(-7,21,-5,biomesoplenty:leaves_3:11)
Block(-7,21,1,biomesoplenty:leaves_3:11)
Block(-7,21,2,biomesoplenty:leaves_3:11)
Block(-7,21,3,biomesoplenty:leaves_3:11)
Block(-7,21,4,biomesoplenty:leaves_3:11)
Block(-7,21,5,biomesoplenty:leaves_3:11)
Block(-7,21,6,biomesoplenty:leaves_3:11)
Block(-7,21,7,biomesoplenty:leaves_3:11)
Block(-7,21,8,biomesoplenty:leaves_3:11)
Block(-7,21,9,biomesoplenty:leaves_3:11)
Block(-7,21,10,biomesoplenty:leaves_3:11)
Block(-7,21,11,biomesoplenty:leaves_3:11)
Block(-7,21,12,biomesoplenty:leaves_3:11)
Block(-7,22,-1,biomesoplenty:leaves_3:11)
Block(-7,22,3,biomesoplenty:leaves_3:11)
Block(-7,22,4,biomesoplenty:leaves_3:11)
Block(-7,22,5,biomesoplenty:leaves_3:11)
Block(-7,22,6,biomesoplenty:leaves_3:11)
Block(-7,22,7,biomesoplenty:leaves_3:11)
Block(-7,22,8,biomesoplenty:leaves_3:11)
Block(-7,22,9,biomesoplenty:leaves_3:11)
Block(-7,22,10,biomesoplenty:leaves_3:11)
Block(-7,22,11,biomesoplenty:leaves_3:11)
Block(-7,22,12,biomesoplenty:leaves_3:11)
Block(-7,22,13,biomesoplenty:leaves_3:11)
Block(-7,23,-3,biomesoplenty:leaves_3:11)
Block(-7,23,-2,biomesoplenty:leaves_3:11)
Block(-7,23,-1,biomesoplenty:leaves_3:11)
Block(-7,23,0,biomesoplenty:leaves_3:11)
Block(-7,23,1,biomesoplenty:leaves_3:11)
Block(-7,23,3,biomesoplenty:leaves_3:11)
Block(-7,23,4,biomesoplenty:leaves_3:11)
Block(-7,23,5,biomesoplenty:leaves_3:11)
Block(-7,23,6,biomesoplenty:leaves_3:11)
Block(-7,23,7,biomesoplenty:leaves_3:11)
Block(-7,23,8,biomesoplenty:leaves_3:11)
Block(-7,23,9,biomesoplenty:leaves_3:11)
Block(-7,23,10,biomesoplenty:leaves_3:11)
Block(-7,23,11,biomesoplenty:leaves_3:11)
Block(-7,23,12,biomesoplenty:leaves_3:11)
Block(-7,23,13,biomesoplenty:leaves_3:11)
Block(-7,24,-3,biomesoplenty:leaves_3:11)
Block(-7,24,-2,biomesoplenty:leaves_3:11)
Block(-7,24,-1,biomesoplenty:leaves_3:11)
Block(-7,24,0,biomesoplenty:leaves_3:11)
Block(-7,24,1,biomesoplenty:leaves_3:11)
Block(-7,24,2,biomesoplenty:leaves_3:11)
Block(-7,24,3,biomesoplenty:leaves_3:11)
Block(-7,24,4,biomesoplenty:leaves_3:11)
Block(-7,24,5,biomesoplenty:leaves_3:11)
Block(-7,24,6,biomesoplenty:leaves_3:11)
Block(-7,24,8,biomesoplenty:leaves_3:11)
Block(-7,25,-1,biomesoplenty:leaves_3:11)
Block(-7,25,1,biomesoplenty:leaves_3:11)
Block(-7,25,2,biomesoplenty:leaves_3:11)
Block(-7,25,3,biomesoplenty:leaves_3:11)
Block(-7,25,4,biomesoplenty:leaves_3:11)
Block(-7,25,5,biomesoplenty:leaves_3:11)
Block(-7,25,6,biomesoplenty:leaves_3:11)
Block(-7,25,7,biomesoplenty:leaves_3:11)
Block(-7,26,3,biomesoplenty:leaves_3:11)
Block(-7,26,5,biomesoplenty:leaves_3:11)
Block(-7,26,6,biomesoplenty:leaves_3:11)
Block(-7,26,7,biomesoplenty:leaves_3:11)
Block(-7,26,12,biomesoplenty:leaves_3:11)
Block(-7,26,13,biomesoplenty:leaves_3:11)
Block(-7,26,14,biomesoplenty:leaves_3:11)
Block(-7,27,10,biomesoplenty:leaves_3:11)
Block(-7,27,11,biomesoplenty:leaves_3:11)
Block(-7,27,12,biomesoplenty:leaves_3:11)
Block(-7,27,13,biomesoplenty:leaves_3:11)
Block(-7,27,14,biomesoplenty:leaves_3:11)
Block(-7,28,9,biomesoplenty:leaves_3:11)
Block(-7,28,10,biomesoplenty:leaves_3:11)
Block(-7,28,11,biomesoplenty:leaves_3:11)
Block(-7,28,12,biomesoplenty:leaves_3:11)
Block(-7,29,7,biomesoplenty:leaves_3:11)
Block(-7,29,8,biomesoplenty:leaves_3:11)
Block(-7,29,9,biomesoplenty:leaves_3:11)
Block(-7,29,10,biomesoplenty:leaves_3:11)
Block(-7,29,11,biomesoplenty:leaves_3:11)
Block(-7,30,5,biomesoplenty:leaves_3:11)
Block(-7,30,6,biomesoplenty:leaves_3:11)
Block(-7,30,7,biomesoplenty:leaves_3:11)
Block(-7,30,8,biomesoplenty:leaves_3:11)
Block(-7,30,9,biomesoplenty:leaves_3:11)
Block(-7,30,10,biomesoplenty:leaves_3:11)
Block(-7,30,11,biomesoplenty:leaves_3:11)
Block(-7,31,-4,biomesoplenty:leaves_3:11)
Block(-7,31,-3,biomesoplenty:leaves_3:11)
Block(-7,31,-2,biomesoplenty:leaves_3:11)
Block(-7,31,1,biomesoplenty:leaves_3:11)
Block(-7,31,2,biomesoplenty:leaves_3:11)
Block(-7,31,3,biomesoplenty:leaves_3:11)
Block(-7,31,5,biomesoplenty:leaves_3:11)
Block(-7,31,6,biomesoplenty:leaves_3:11)
Block(-7,31,7,biomesoplenty:leaves_3:11)
Block(-7,31,8,biomesoplenty:leaves_3:11)
Block(-7,31,9,biomesoplenty:leaves_3:11)
Block(-7,32,-4,biomesoplenty:leaves_3:11)
Block(-7,32,-3,biomesoplenty:leaves_3:11)
Block(-7,32,-2,biomesoplenty:leaves_3:11)
Block(-7,32,0,biomesoplenty:leaves_3:11)
Block(-7,32,1,biomesoplenty:leaves_3:11)
Block(-7,32,2,biomesoplenty:leaves_3:11)
Block(-7,32,3,biomesoplenty:leaves_3:11)
Block(-7,32,4,biomesoplenty:leaves_3:11)
Block(-7,32,6,biomesoplenty:leaves_3:11)
Block(-7,33,0,biomesoplenty:leaves_3:11)
Block(-7,33,1,biomesoplenty:leaves_3:11)
Block(-7,33,2,biomesoplenty:leaves_3:11)
Block(-7,33,3,biomesoplenty:leaves_3:11)
Block(-7,33,4,biomesoplenty:leaves_3:11)
Block(-7,33,5,biomesoplenty:leaves_3:11)
Block(-7,33,6,biomesoplenty:leaves_3:11)
Block(-7,33,7,biomesoplenty:leaves_3:11)
Block(-7,33,8,biomesoplenty:leaves_3:11)
Block(-7,34,1,biomesoplenty:leaves_3:11)
Block(-7,34,2,biomesoplenty:leaves_3:11)
Block(-7,34,3,biomesoplenty:leaves_3:11)
Block(-7,34,4,biomesoplenty:leaves_3:11)
Block(-7,34,5,biomesoplenty:leaves_3:11)
Block(-7,34,6,biomesoplenty:leaves_3:11)
Block(-7,34,7,biomesoplenty:leaves_3:11)
Block(-7,34,8,biomesoplenty:leaves_3:11)
Block(-7,35,3,biomesoplenty:leaves_3:11)
Block(-7,35,4,biomesoplenty:leaves_3:11)
Block(-7,35,5,biomesoplenty:leaves_3:11)
Block(-7,35,6,biomesoplenty:leaves_3:11)
Block(-7,36,3,biomesoplenty:leaves_3:11)
Block(-7,36,4,biomesoplenty:leaves_3:11)
Block(-7,36,5,biomesoplenty:leaves_3:11)
Block(-6,12,12,biomesoplenty:leaves_3:11)
Block(-6,13,7,biomesoplenty:leaves_3:11)
Block(-6,13,10,biomesoplenty:leaves_3:11)
Block(-6,13,11,biomesoplenty:leaves_3:11)
Block(-6,13,12,biomesoplenty:leaves_3:11)
Block(-6,13,13,biomesoplenty:leaves_3:11)
Block(-6,13,14,biomesoplenty:leaves_3:11)
Block(-6,14,-5,biomesoplenty:leaves_3:11)
Block(-6,14,-2,biomesoplenty:leaves_3:11)
Block(-6,14,-1,biomesoplenty:leaves_3:11)
Block(-6,14,0,biomesoplenty:leaves_3:11)
Block(-6,14,2,biomesoplenty:leaves_3:11)
Block(-6,14,3,biomesoplenty:leaves_3:11)
Block(-6,14,4,biomesoplenty:leaves_3:11)
Block(-6,14,7,biomesoplenty:leaves_3:11)
Block(-6,14,8,biomesoplenty:leaves_3:11)
Block(-6,14,9,biomesoplenty:leaves_3:11)
Block(-6,14,10,biomesoplenty:leaves_3:11)
Block(-6,14,11,biomesoplenty:leaves_3:11)
Block(-6,14,12,biomesoplenty:leaves_3:11)
Block(-6,14,13,biomesoplenty:leaves_3:11)
Block(-6,14,14,biomesoplenty:leaves_3:11)
Block(-6,15,-7,biomesoplenty:leaves_3:11)
Block(-6,15,-6,biomesoplenty:leaves_3:11)
Block(-6,15,-5,biomesoplenty:leaves_3:11)
Block(-6,15,-4,biomesoplenty:leaves_3:11)
Block(-6,15,-3,biomesoplenty:leaves_3:11)
Block(-6,15,-2,biomesoplenty:leaves_3:11)
Block(-6,15,-1,biomesoplenty:leaves_3:11)
Block(-6,15,0,biomesoplenty:leaves_3:11)
Block(-6,15,1,biomesoplenty:leaves_3:11)
Block(-6,15,2,biomesoplenty:leaves_3:11)
Block(-6,15,3,biomesoplenty:leaves_3:11)
Block(-6,15,4,biomesoplenty:leaves_3:11)
Block(-6,15,5,biomesoplenty:leaves_3:11)
Block(-6,15,6,biomesoplenty:leaves_3:11)
Block(-6,15,7,biomesoplenty:leaves_3:11)
Block(-6,15,8,biomesoplenty:leaves_3:11)
Block(-6,15,9,biomesoplenty:leaves_3:11)
Block(-6,15,10,biomesoplenty:leaves_3:11)
Block(-6,15,11,biomesoplenty:leaves_3:11)
Block(-6,15,12,biomesoplenty:leaves_3:11)
Block(-6,16,-7,biomesoplenty:leaves_3:11)
Block(-6,16,-6,biomesoplenty:leaves_3:11)
Block(-6,16,-5,biomesoplenty:leaves_3:11)
Block(-6,16,-4,biomesoplenty:leaves_3:11)
Block(-6,16,-3,biomesoplenty:leaves_3:11)
Block(-6,16,-2,biomesoplenty:leaves_3:11)
Block(-6,16,-1,biomesoplenty:leaves_3:11)
Block(-6,16,0,biomesoplenty:leaves_3:11)
Block(-6,16,1,biomesoplenty:leaves_3:11)
Block(-6,16,2,biomesoplenty:leaves_3:11)
Block(-6,16,3,biomesoplenty:leaves_3:11)
Block(-6,16,4,biomesoplenty:leaves_3:11)
Block(-6,16,5,biomesoplenty:leaves_3:11)
Block(-6,16,6,biomesoplenty:leaves_3:11)
Block(-6,16,7,biomesoplenty:leaves_3:11)
Block(-6,16,8,biomesoplenty:leaves_3:11)
Block(-6,16,9,biomesoplenty:leaves_3:11)
Block(-6,16,10,biomesoplenty:leaves_3:11)
Block(-6,16,11,biomesoplenty:leaves_3:11)
Block(-6,16,12,biomesoplenty:leaves_3:11)
Block(-6,17,-5,biomesoplenty:leaves_3:11)
Block(-6,17,-4,biomesoplenty:leaves_3:11)
Block(-6,17,-3,biomesoplenty:leaves_3:11)
Block(-6,17,-2,biomesoplenty:leaves_3:11)
Block(-6,17,-1,biomesoplenty:leaves_3:11)
Block(-6,17,0,biomesoplenty:leaves_3:11)
Block(-6,17,1,biomesoplenty:leaves_3:11)
Block(-6,17,2,biomesoplenty:leaves_3:11)
Block(-6,17,3,biomesoplenty:leaves_3:11)
Block(-6,17,4,biomesoplenty:leaves_3:11)
Block(-6,17,5,biomesoplenty:leaves_3:11)
Block(-6,17,6,biomesoplenty:leaves_3:11)
Block(-6,17,7,biomesoplenty:leaves_3:11)
Block(-6,17,8,biomesoplenty:leaves_3:11)
Block(-6,17,9,biomesoplenty:leaves_3:11)
Block(-6,17,10,biomesoplenty:leaves_3:11)
Block(-6,17,11,biomesoplenty:leaves_3:11)
Block(-6,17,12,biomesoplenty:leaves_3:11)
Block(-6,17,13,biomesoplenty:leaves_3:11)
Block(-6,18,-4,biomesoplenty:leaves_3:11)
Block(-6,18,-3,biomesoplenty:leaves_3:11)
Block(-6,18,-2,biomesoplenty:leaves_3:11)
Block(-6,18,-1,biomesoplenty:leaves_3:11)
Block(-6,18,0,biomesoplenty:leaves_3:11)
Block(-6,18,1,biomesoplenty:leaves_3:11)
Block(-6,18,3,biomesoplenty:leaves_3:11)
Block(-6,18,4,biomesoplenty:leaves_3:11)
Block(-6,18,5,biomesoplenty:leaves_3:11)
Block(-6,18,6,biomesoplenty:leaves_3:11)
Block(-6,18,7,biomesoplenty:leaves_3:11)
Block(-6,18,8,biomesoplenty:leaves_3:11)
Block(-6,18,9,biomesoplenty:leaves_3:11)
Block(-6,18,10,biomesoplenty:leaves_3:11)
Block(-6,18,11,biomesoplenty:leaves_3:11)
Block(-6,18,12,biomesoplenty:leaves_3:11)
Block(-6,18,13,biomesoplenty:leaves_3:11)
Block(-6,18,14,biomesoplenty:leaves_3:11)
Block(-6,19,-6,biomesoplenty:leaves_3:11)
Block(-6,19,-4,biomesoplenty:leaves_3:11)
Block(-6,19,-3,biomesoplenty:leaves_3:11)
Block(-6,19,-2,biomesoplenty:leaves_3:11)
Block(-6,19,-1,biomesoplenty:leaves_3:11)
Block(-6,19,0,biomesoplenty:leaves_3:11)
Block(-6,19,2,biomesoplenty:leaves_3:11)
Block(-6,19,3,biomesoplenty:leaves_3:11)
Block(-6,19,4,biomesoplenty:leaves_3:11)
Block(-6,19,5,biomesoplenty:leaves_3:11)
Block(-6,19,6,biomesoplenty:leaves_3:11)
Block(-6,19,9,biomesoplenty:leaves_3:11)
Block(-6,19,10,biomesoplenty:leaves_3:11)
Block(-6,19,11,biomesoplenty:leaves_3:11)
Block(-6,19,12,biomesoplenty:leaves_3:11)
Block(-6,19,13,biomesoplenty:leaves_3:11)
Block(-6,19,14,biomesoplenty:leaves_3:11)
Block(-6,20,-8,biomesoplenty:leaves_3:11)
Block(-6,20,-7,biomesoplenty:leaves_3:11)
Block(-6,20,-6,biomesoplenty:leaves_3:11)
Block(-6,20,-5,biomesoplenty:leaves_3:11)
Block(-6,20,-4,biomesoplenty:leaves_3:11)
Block(-6,20,-3,biomesoplenty:leaves_3:11)
Block(-6,20,-2,biomesoplenty:leaves_3:11)
Block(-6,20,-1,biomesoplenty:leaves_3:11)
Block(-6,20,0,biomesoplenty:leaves_3:11)
Block(-6,20,1,biomesoplenty:leaves_3:11)
Block(-6,20,2,biomesoplenty:leaves_3:11)
Block(-6,20,3,biomesoplenty:leaves_3:11)
Block(-6,20,4,biomesoplenty:leaves_3:11)
Block(-6,20,5,biomesoplenty:leaves_3:11)
Block(-6,20,6,biomesoplenty:leaves_3:11)
Block(-6,20,7,biomesoplenty:leaves_3:11)
Block(-6,20,8,biomesoplenty:leaves_3:11)
Block(-6,20,9,biomesoplenty:leaves_3:11)
Block(-6,20,10,biomesoplenty:leaves_3:11)
Block(-6,20,11,biomesoplenty:leaves_3:11)
Block(-6,20,12,biomesoplenty:leaves_3:11)
Block(-6,20,13,biomesoplenty:leaves_3:11)
Block(-6,21,-8,biomesoplenty:leaves_3:11)
Block(-6,21,-7,biomesoplenty:leaves_3:11)
Block(-6,21,-6,biomesoplenty:leaves_3:11)
Block(-6,21,-5,biomesoplenty:leaves_3:11)
Block(-6,21,-4,biomesoplenty:leaves_3:11)
Block(-6,21,0,biomesoplenty:leaves_3:11)
Block(-6,21,1,biomesoplenty:leaves_3:11)
Block(-6,21,2,biomesoplenty:leaves_3:11)
Block(-6,21,3,biomesoplenty:leaves_3:11)
Block(-6,21,4,biomesoplenty:leaves_3:11)
Block(-6,21,5,biomesoplenty:leaves_3:11)
Block(-6,21,6,biomesoplenty:leaves_3:11)
Block(-6,21,7,biomesoplenty:leaves_3:11)
Block(-6,21,8,biomesoplenty:leaves_3:11)
Block(-6,21,9,biomesoplenty:leaves_3:11)
Block(-6,21,10,biomesoplenty:leaves_3:11)
Block(-6,21,11,biomesoplenty:leaves_3:11)
Block(-6,21,12,biomesoplenty:leaves_3:11)
Block(-6,22,-6,biomesoplenty:leaves_3:11)
Block(-6,22,-2,biomesoplenty:leaves_3:11)
Block(-6,22,-1,biomesoplenty:leaves_3:11)
Block(-6,22,0,biomesoplenty:leaves_3:11)
Block(-6,22,2,biomesoplenty:leaves_3:11)
Block(-6,22,3,biomesoplenty:leaves_3:11)
Block(-6,22,4,biomesoplenty:leaves_3:11)
Block(-6,22,5,biomesoplenty:leaves_3:11)
Block(-6,22,6,biomesoplenty:leaves_3:11)
Block(-6,22,7,biomesoplenty:leaves_3:11)
Block(-6,22,8,biomesoplenty:leaves_3:11)
Block(-6,22,9,biomesoplenty:leaves_3:11)
Block(-6,22,10,biomesoplenty:leaves_3:11)
Block(-6,22,11,biomesoplenty:leaves_3:11)
Block(-6,22,12,biomesoplenty:leaves_3:11)
Block(-6,22,13,biomesoplenty:leaves_3:11)
Block(-6,22,14,biomesoplenty:leaves_3:11)
Block(-6,22,15,biomesoplenty:leaves_3:11)
Block(-6,23,-3,biomesoplenty:leaves_3:11)
Block(-6,23,-2,biomesoplenty:leaves_3:11)
Block(-6,23,-1,biomesoplenty:leaves_3:11)
Block(-6,23,0,biomesoplenty:leaves_3:11)
Block(-6,23,1,biomesoplenty:leaves_3:11)
Block(-6,23,2,biomesoplenty:leaves_3:11)
Block(-6,23,3,biomesoplenty:leaves_3:11)
Block(-6,23,4,biomesoplenty:leaves_3:11)
Block(-6,23,5,biomesoplenty:leaves_3:11)
Block(-6,23,6,biomesoplenty:leaves_3:11)
Block(-6,23,7,biomesoplenty:leaves_3:11)
Block(-6,23,8,biomesoplenty:leaves_3:11)
Block(-6,23,9,biomesoplenty:leaves_3:11)
Block(-6,23,10,biomesoplenty:leaves_3:11)
Block(-6,23,11,biomesoplenty:leaves_3:11)
Block(-6,23,12,biomesoplenty:leaves_3:11)
Block(-6,23,13,biomesoplenty:leaves_3:11)
Block(-6,23,14,biomesoplenty:leaves_3:11)
Block(-6,23,15,biomesoplenty:leaves_3:11)
Block(-6,24,-3,biomesoplenty:leaves_3:11)
Block(-6,24,-2,biomesoplenty:leaves_3:11)
Block(-6,24,-1,biomesoplenty:leaves_3:11)
Block(-6,24,0,biomesoplenty:leaves_3:11)
Block(-6,24,1,biomesoplenty:leaves_3:11)
Block(-6,24,2,biomesoplenty:leaves_3:11)
Block(-6,24,3,biomesoplenty:leaves_3:11)
Block(-6,24,4,biomesoplenty:leaves_3:11)
Block(-6,24,5,biomesoplenty:leaves_3:11)
Block(-6,24,6,biomesoplenty:leaves_3:11)
Block(-6,24,7,biomesoplenty:leaves_3:11)
Block(-6,24,8,biomesoplenty:leaves_3:11)
Block(-6,24,9,biomesoplenty:leaves_3:11)
Block(-6,24,10,biomesoplenty:leaves_3:11)
Block(-6,24,12,biomesoplenty:leaves_3:11)
Block(-6,25,-9,biomesoplenty:leaves_3:11)
Block(-6,25,-8,biomesoplenty:leaves_3:11)
Block(-6,25,-7,biomesoplenty:leaves_3:11)
Block(-6,25,-2,biomesoplenty:leaves_3:11)
Block(-6,25,-1,biomesoplenty:leaves_3:11)
Block(-6,25,0,biomesoplenty:leaves_3:11)
Block(-6,25,1,biomesoplenty:leaves_3:11)
Block(-6,25,2,biomesoplenty:leaves_3:11)
Block(-6,25,3,biomesoplenty:leaves_3:11)
Block(-6,25,4,biomesoplenty:leaves_3:11)
Block(-6,25,5,biomesoplenty:leaves_3:11)
Block(-6,25,6,biomesoplenty:leaves_3:11)
Block(-6,25,7,biomesoplenty:leaves_3:11)
Block(-6,25,8,biomesoplenty:leaves_3:11)
Block(-6,25,9,biomesoplenty:leaves_3:11)
Block(-6,25,10,biomesoplenty:leaves_3:11)
Block(-6,25,13,biomesoplenty:leaves_3:11)
Block(-6,25,14,biomesoplenty:leaves_3:11)
Block(-6,25,15,biomesoplenty:leaves_3:11)
Block(-6,26,-9,biomesoplenty:leaves_3:11)
Block(-6,26,-8,biomesoplenty:leaves_3:11)
Block(-6,26,-7,biomesoplenty:leaves_3:11)
Block(-6,26,2,biomesoplenty:leaves_3:11)
Block(-6,26,3,biomesoplenty:leaves_3:11)
Block(-6,26,4,biomesoplenty:leaves_3:11)
Block(-6,26,5,biomesoplenty:leaves_3:11)
Block(-6,26,6,biomesoplenty:leaves_3:11)
Block(-6,26,7,biomesoplenty:leaves_3:11)
Block(-6,26,8,biomesoplenty:leaves_3:11)
Block(-6,26,11,biomesoplenty:leaves_3:11)
Block(-6,26,12,biomesoplenty:leaves_3:11)
Block(-6,26,13,biomesoplenty:leaves_3:11)
Block(-6,26,14,biomesoplenty:leaves_3:11)
Block(-6,26,15,biomesoplenty:leaves_3:11)
Block(-6,27,2,biomesoplenty:leaves_3:11)
Block(-6,27,3,biomesoplenty:leaves_3:11)
Block(-6,27,4,biomesoplenty:leaves_3:11)
Block(-6,27,6,biomesoplenty:leaves_3:11)
Block(-6,27,9,biomesoplenty:leaves_3:11)
Block(-6,27,10,biomesoplenty:leaves_3:11)
Block(-6,27,11,biomesoplenty:leaves_3:11)
Block(-6,27,12,biomesoplenty:leaves_3:11)
Block(-6,27,13,biomesoplenty:leaves_3:11)
Block(-6,27,14,biomesoplenty:leaves_3:11)
Block(-6,27,15,biomesoplenty:leaves_3:11)
Block(-6,28,2,biomesoplenty:leaves_3:11)
Block(-6,28,3,biomesoplenty:leaves_3:11)
Block(-6,28,4,biomesoplenty:leaves_3:11)
Block(-6,28,8,biomesoplenty:leaves_3:11)
Block(-6,28,9,biomesoplenty:leaves_3:11)
Block(-6,28,10,biomesoplenty:leaves_3:11)
Block(-6,28,11,biomesoplenty:leaves_3:11)
Block(-6,28,12,biomesoplenty:leaves_3:11)
Block(-6,28,13,biomesoplenty:leaves_3:11)
Block(-6,29,6,biomesoplenty:leaves_3:11)
Block(-6,29,7,biomesoplenty:leaves_3:11)
Block(-6,29,8,biomesoplenty:leaves_3:11)
Block(-6,29,9,biomesoplenty:leaves_3:11)
Block(-6,29,10,biomesoplenty:leaves_3:11)
Block(-6,29,11,biomesoplenty:leaves_3:11)
Block(-6,30,-3,biomesoplenty:leaves_3:11)
Block(-6,30,2,biomesoplenty:leaves_3:11)
Block(-6,30,4,biomesoplenty:leaves_3:11)
Block(-6,30,5,biomesoplenty:leaves_3:11)
Block(-6,30,6,biomesoplenty:leaves_3:11)
Block(-6,30,7,biomesoplenty:leaves_3:11)
Block(-6,30,8,biomesoplenty:leaves_3:11)
Block(-6,30,9,biomesoplenty:leaves_3:11)
Block(-6,30,10,biomesoplenty:leaves_3:11)
Block(-6,30,11,biomesoplenty:leaves_3:11)
Block(-6,31,-5,biomesoplenty:leaves_3:11)
Block(-6,31,-4,biomesoplenty:leaves_3:11)
Block(-6,31,-3,biomesoplenty:leaves_3:11)
Block(-6,31,-2,biomesoplenty:leaves_3:11)
Block(-6,31,-1,biomesoplenty:leaves_3:11)
Block(-6,31,2,biomesoplenty:leaves_3:11)
Block(-6,31,4,biomesoplenty:leaves_3:11)
Block(-6,31,5,biomesoplenty:leaves_3:11)
Block(-6,31,6,biomesoplenty:leaves_3:11)
Block(-6,31,7,biomesoplenty:leaves_3:11)
Block(-6,31,8,biomesoplenty:leaves_3:11)
Block(-6,31,9,biomesoplenty:leaves_3:11)
Block(-6,31,10,biomesoplenty:leaves_3:11)
Block(-6,32,-5,biomesoplenty:leaves_3:11)
Block(-6,32,-4,biomesoplenty:leaves_3:11)
Block(-6,32,-3,biomesoplenty:leaves_3:11)
Block(-6,32,-2,biomesoplenty:leaves_3:11)
Block(-6,32,-1,biomesoplenty:leaves_3:11)
Block(-6,32,0,biomesoplenty:leaves_3:11)
Block(-6,32,1,biomesoplenty:leaves_3:11)
Block(-6,32,2,biomesoplenty:leaves_3:11)
Block(-6,32,3,biomesoplenty:leaves_3:11)
Block(-6,32,4,biomesoplenty:leaves_3:11)
Block(-6,32,5,biomesoplenty:leaves_3:11)
Block(-6,32,6,biomesoplenty:leaves_3:11)
Block(-6,32,7,biomesoplenty:leaves_3:11)
Block(-6,33,-3,biomesoplenty:leaves_3:11)
Block(-6,33,0,biomesoplenty:leaves_3:11)
Block(-6,33,1,biomesoplenty:leaves_3:11)
Block(-6,33,2,biomesoplenty:leaves_3:11)
Block(-6,33,3,biomesoplenty:leaves_3:11)
Block(-6,33,4,biomesoplenty:leaves_3:11)
Block(-6,33,5,biomesoplenty:leaves_3:11)
Block(-6,33,6,biomesoplenty:leaves_3:11)
Block(-6,33,7,biomesoplenty:leaves_3:11)
Block(-6,33,8,biomesoplenty:leaves_3:11)
Block(-6,34,0,biomesoplenty:leaves_3:11)
Block(-6,34,1,biomesoplenty:leaves_3:11)
Block(-6,34,2,biomesoplenty:leaves_3:11)
Block(-6,34,4,biomesoplenty:leaves_3:11)
Block(-6,34,5,biomesoplenty:leaves_3:11)
Block(-6,34,6,biomesoplenty:leaves_3:11)
Block(-6,34,7,biomesoplenty:leaves_3:11)
Block(-6,34,8,biomesoplenty:leaves_3:11)
Block(-6,35,2,biomesoplenty:leaves_3:11)
Block(-6,35,3,biomesoplenty:leaves_3:11)
Block(-6,35,4,biomesoplenty:leaves_3:11)
Block(-6,35,5,biomesoplenty:leaves_3:11)
Block(-6,35,6,biomesoplenty:leaves_3:11)
Block(-6,35,7,biomesoplenty:leaves_3:11)
Block(-6,35,8,biomesoplenty:leaves_3:11)
Block(-6,35,9,biomesoplenty:leaves_3:11)
Block(-6,36,-1,biomesoplenty:leaves_3:11)
Block(-6,36,0,biomesoplenty:leaves_3:11)
Block(-6,36,1,biomesoplenty:leaves_3:11)
Block(-6,36,2,biomesoplenty:leaves_3:11)
Block(-6,36,3,biomesoplenty:leaves_3:11)
Block(-6,36,4,biomesoplenty:leaves_3:11)
Block(-6,36,5,biomesoplenty:leaves_3:11)
Block(-6,36,6,biomesoplenty:leaves_3:11)
Block(-6,36,7,biomesoplenty:leaves_3:11)
Block(-6,36,8,biomesoplenty:leaves_3:11)
Block(-6,36,9,biomesoplenty:leaves_3:11)
Block(-6,37,-1,biomesoplenty:leaves_3:11)
Block(-6,37,0,biomesoplenty:leaves_3:11)
Block(-6,37,1,biomesoplenty:leaves_3:11)
Block(-6,37,4,biomesoplenty:leaves_3:11)
Block(-5,12,11,biomesoplenty:leaves_3:11)
Block(-5,12,12,biomesoplenty:leaves_3:11)
Block(-5,12,13,biomesoplenty:leaves_3:11)
Block(-5,13,-3,biomesoplenty:leaves_3:11)
Block(-5,13,-2,biomesoplenty:leaves_3:11)
Block(-5,13,-1,biomesoplenty:leaves_3:11)
Block(-5,13,0,biomesoplenty:leaves_3:11)
Block(-5,13,7,biomesoplenty:leaves_3:11)
Block(-5,13,10,biomesoplenty:leaves_3:11)
Block(-5,13,11,biomesoplenty:leaves_3:11)
Block(-5,13,12,biomesoplenty:leaves_3:11)
Block(-5,13,13,biomesoplenty:leaves_3:11)
Block(-5,13,14,biomesoplenty:leaves_3:11)
Block(-5,14,-6,biomesoplenty:leaves_3:11)
Block(-5,14,-5,biomesoplenty:leaves_3:11)
Block(-5,14,-4,biomesoplenty:leaves_3:11)
Block(-5,14,-3,biomesoplenty:leaves_3:11)
Block(-5,14,-2,biomesoplenty:leaves_3:11)
Block(-5,14,-1,biomesoplenty:leaves_3:11)
Block(-5,14,0,biomesoplenty:leaves_3:11)
Block(-5,14,1,biomesoplenty:leaves_3:11)
Block(-5,14,3,biomesoplenty:leaves_3:11)
Block(-5,14,8,biomesoplenty:leaves_3:11)
Block(-5,14,9,biomesoplenty:leaves_3:11)
Block(-5,14,10,biomesoplenty:leaves_3:11)
Block(-5,14,11,biomesoplenty:leaves_3:11)
Block(-5,14,12,biomesoplenty:leaves_3:11)
Block(-5,14,13,biomesoplenty:leaves_3:11)
Block(-5,14,14,biomesoplenty:leaves_3:11)
Block(-5,15,-10,biomesoplenty:leaves_3:11)
Block(-5,15,-9,biomesoplenty:leaves_3:11)
Block(-5,15,-8,biomesoplenty:leaves_3:11)
Block(-5,15,-7,biomesoplenty:leaves_3:11)
Block(-5,15,-6,biomesoplenty:leaves_3:11)
Block(-5,15,-5,biomesoplenty:leaves_3:11)
Block(-5,15,-4,biomesoplenty:leaves_3:11)
Block(-5,15,-3,biomesoplenty:leaves_3:11)
Block(-5,15,-2,biomesoplenty:leaves_3:11)
Block(-5,15,-1,biomesoplenty:leaves_3:11)
Block(-5,15,0,biomesoplenty:leaves_3:11)
Block(-5,15,1,biomesoplenty:leaves_3:11)
Block(-5,15,2,biomesoplenty:leaves_3:11)
Block(-5,15,3,biomesoplenty:leaves_3:11)
Block(-5,15,4,biomesoplenty:leaves_3:11)
Block(-5,15,5,biomesoplenty:leaves_3:11)
Block(-5,15,7,biomesoplenty:leaves_3:11)
Block(-5,15,8,biomesoplenty:leaves_3:11)
Block(-5,15,9,biomesoplenty:leaves_3:11)
Block(-5,15,10,biomesoplenty:leaves_3:11)
Block(-5,15,11,biomesoplenty:leaves_3:11)
Block(-5,15,12,biomesoplenty:leaves_3:11)
Block(-5,15,13,biomesoplenty:leaves_3:11)
Block(-5,16,-10,biomesoplenty:leaves_3:11)
Block(-5,16,-9,biomesoplenty:leaves_3:11)
Block(-5,16,-8,biomesoplenty:leaves_3:11)
Block(-5,16,-7,biomesoplenty:leaves_3:11)
Block(-5,16,-6,biomesoplenty:leaves_3:11)
Block(-5,16,-5,biomesoplenty:leaves_3:11)
Block(-5,16,-4,biomesoplenty:leaves_3:11)
Block(-5,16,-3,biomesoplenty:leaves_3:11)
Block(-5,16,-2,biomesoplenty:leaves_3:11)
Block(-5,16,-1,biomesoplenty:leaves_3:11)
Block(-5,16,0,biomesoplenty:leaves_3:11)
Block(-5,16,1,biomesoplenty:leaves_3:11)
Block(-5,16,2,biomesoplenty:leaves_3:11)
Block(-5,16,3,biomesoplenty:leaves_3:11)
Block(-5,16,4,biomesoplenty:leaves_3:11)
Block(-5,16,5,biomesoplenty:leaves_3:11)
Block(-5,16,6,biomesoplenty:leaves_3:11)
Block(-5,16,7,biomesoplenty:leaves_3:11)
Block(-5,16,8,biomesoplenty:leaves_3:11)
Block(-5,16,9,biomesoplenty:leaves_3:11)
Block(-5,16,10,biomesoplenty:leaves_3:11)
Block(-5,16,11,biomesoplenty:leaves_3:11)
Block(-5,17,-7,biomesoplenty:leaves_3:11)
Block(-5,17,-6,biomesoplenty:leaves_3:11)
Block(-5,17,-5,biomesoplenty:leaves_3:11)
Block(-5,17,-4,biomesoplenty:leaves_3:11)
Block(-5,17,-3,biomesoplenty:leaves_3:11)
Block(-5,17,-2,biomesoplenty:leaves_3:11)
Block(-5,17,-1,biomesoplenty:leaves_3:11)
Block(-5,17,0,biomesoplenty:leaves_3:11)
Block(-5,17,1,biomesoplenty:leaves_3:11)
Block(-5,17,3,biomesoplenty:leaves_3:11)
Block(-5,17,5,biomesoplenty:leaves_3:11)
Block(-5,17,6,biomesoplenty:leaves_3:11)
Block(-5,17,7,biomesoplenty:leaves_3:11)
Block(-5,17,8,biomesoplenty:leaves_3:11)
Block(-5,17,9,biomesoplenty:leaves_3:11)
Block(-5,17,10,biomesoplenty:leaves_3:11)
Block(-5,17,11,biomesoplenty:leaves_3:11)
Block(-5,17,12,biomesoplenty:leaves_3:11)
Block(-5,18,-7,biomesoplenty:leaves_3:11)
Block(-5,18,-6,biomesoplenty:leaves_3:11)
Block(-5,18,-5,biomesoplenty:leaves_3:11)
Block(-5,18,-4,biomesoplenty:leaves_3:11)
Block(-5,18,-3,biomesoplenty:leaves_3:11)
Block(-5,18,-2,biomesoplenty:leaves_3:11)
Block(-5,18,-1,biomesoplenty:leaves_3:11)
Block(-5,18,0,biomesoplenty:leaves_3:11)
Block(-5,18,1,biomesoplenty:leaves_3:11)
Block(-5,18,3,biomesoplenty:leaves_3:11)
Block(-5,18,4,biomesoplenty:leaves_3:11)
Block(-5,18,5,biomesoplenty:leaves_3:11)
Block(-5,18,6,biomesoplenty:leaves_3:11)
Block(-5,18,7,biomesoplenty:leaves_3:11)
Block(-5,18,8,biomesoplenty:leaves_3:11)
Block(-5,18,9,biomesoplenty:leaves_3:11)
Block(-5,18,10,biomesoplenty:leaves_3:11)
Block(-5,18,11,biomesoplenty:leaves_3:11)
Block(-5,18,12,biomesoplenty:leaves_3:11)
Block(-5,18,13,biomesoplenty:leaves_3:11)
Block(-5,18,14,biomesoplenty:leaves_3:11)
Block(-5,19,-7,biomesoplenty:leaves_3:11)
Block(-5,19,-6,biomesoplenty:log_0:8)
Block(-5,19,-5,biomesoplenty:leaves_3:11)
Block(-5,19,-4,biomesoplenty:leaves_3:11)
Block(-5,19,-3,biomesoplenty:leaves_3:11)
Block(-5,19,-2,biomesoplenty:leaves_3:11)
Block(-5,19,-1,biomesoplenty:leaves_3:11)
Block(-5,19,0,biomesoplenty:leaves_3:11)
Block(-5,19,1,biomesoplenty:leaves_3:11)
Block(-5,19,2,biomesoplenty:leaves_3:11)
Block(-5,19,3,biomesoplenty:leaves_3:11)
Block(-5,19,4,biomesoplenty:leaves_3:11)
Block(-5,19,5,biomesoplenty:leaves_3:11)
Block(-5,19,6,biomesoplenty:leaves_3:11)
Block(-5,19,7,biomesoplenty:leaves_3:11)
Block(-5,19,8,biomesoplenty:leaves_3:11)
Block(-5,19,9,biomesoplenty:leaves_3:11)
Block(-5,19,10,biomesoplenty:leaves_3:11)
Block(-5,19,11,biomesoplenty:leaves_3:11)
Block(-5,19,12,biomesoplenty:leaves_3:11)
Block(-5,19,13,biomesoplenty:leaves_3:11)
Block(-5,19,14,biomesoplenty:leaves_3:11)
Block(-5,20,-8,biomesoplenty:leaves_3:11)
Block(-5,20,-7,biomesoplenty:leaves_3:11)
Block(-5,20,-6,biomesoplenty:leaves_3:11)
Block(-5,20,-5,biomesoplenty:leaves_3:11)
Block(-5,20,-4,biomesoplenty:leaves_3:11)
Block(-5,20,-3,biomesoplenty:leaves_3:11)
Block(-5,20,-2,biomesoplenty:leaves_3:11)
Block(-5,20,-1,biomesoplenty:leaves_3:11)
Block(-5,20,0,biomesoplenty:leaves_3:11)
Block(-5,20,1,biomesoplenty:leaves_3:11)
Block(-5,20,2,biomesoplenty:leaves_3:11)
Block(-5,20,3,biomesoplenty:leaves_3:11)
Block(-5,20,4,biomesoplenty:leaves_3:11)
Block(-5,20,5,biomesoplenty:leaves_3:11)
Block(-5,20,6,biomesoplenty:leaves_3:11)
Block(-5,20,7,biomesoplenty:leaves_3:11)
Block(-5,20,8,biomesoplenty:leaves_3:11)
Block(-5,20,9,biomesoplenty:leaves_3:11)
Block(-5,20,10,biomesoplenty:leaves_3:11)
Block(-5,20,11,biomesoplenty:leaves_3:11)
Block(-5,20,12,biomesoplenty:leaves_3:11)
Block(-5,21,-8,biomesoplenty:leaves_3:11)
Block(-5,21,-7,biomesoplenty:leaves_3:11)
Block(-5,21,-6,biomesoplenty:leaves_3:11)
Block(-5,21,-5,biomesoplenty:leaves_3:11)
Block(-5,21,-4,biomesoplenty:leaves_3:11)
Block(-5,21,-2,biomesoplenty:leaves_3:11)
Block(-5,21,0,biomesoplenty:leaves_3:11)
Block(-5,21,1,biomesoplenty:leaves_3:11)
Block(-5,21,2,biomesoplenty:leaves_3:11)
Block(-5,21,3,biomesoplenty:leaves_3:11)
Block(-5,21,4,biomesoplenty:leaves_3:11)
Block(-5,21,5,biomesoplenty:leaves_3:11)
Block(-5,21,6,biomesoplenty:leaves_3:11)
Block(-5,21,7,biomesoplenty:leaves_3:11)
Block(-5,21,8,biomesoplenty:leaves_3:11)
Block(-5,21,9,biomesoplenty:leaves_3:11)
Block(-5,21,10,biomesoplenty:leaves_3:11)
Block(-5,21,11,biomesoplenty:leaves_3:11)
Block(-5,21,12,biomesoplenty:log_0:8)
Block(-5,21,13,biomesoplenty:leaves_3:11)
Block(-5,21,14,biomesoplenty:leaves_3:11)
Block(-5,22,-7,biomesoplenty:leaves_3:11)
Block(-5,22,-6,biomesoplenty:leaves_3:11)
Block(-5,22,-5,biomesoplenty:leaves_3:11)
Block(-5,22,-1,biomesoplenty:leaves_3:11)
Block(-5,22,1,biomesoplenty:leaves_3:11)
Block(-5,22,2,biomesoplenty:leaves_3:11)
Block(-5,22,3,biomesoplenty:leaves_3:11)
Block(-5,22,4,biomesoplenty:leaves_3:11)
Block(-5,22,5,biomesoplenty:leaves_3:11)
Block(-5,22,6,biomesoplenty:leaves_3:11)
Block(-5,22,7,biomesoplenty:leaves_3:11)
Block(-5,22,8,biomesoplenty:leaves_3:11)
Block(-5,22,9,biomesoplenty:leaves_3:11)
Block(-5,22,10,biomesoplenty:leaves_3:11)
Block(-5,22,11,biomesoplenty:leaves_3:11)
Block(-5,22,12,biomesoplenty:leaves_3:11)
Block(-5,22,13,biomesoplenty:leaves_3:11)
Block(-5,22,14,biomesoplenty:leaves_3:11)
Block(-5,22,15,biomesoplenty:leaves_3:11)
Block(-5,22,16,biomesoplenty:leaves_3:11)
Block(-5,23,-3,biomesoplenty:leaves_3:11)
Block(-5,23,-2,biomesoplenty:leaves_3:11)
Block(-5,23,-1,biomesoplenty:leaves_3:11)
Block(-5,23,0,biomesoplenty:leaves_3:11)
Block(-5,23,1,biomesoplenty:leaves_3:11)
Block(-5,23,3,biomesoplenty:leaves_3:11)
Block(-5,23,4,biomesoplenty:leaves_3:11)
Block(-5,23,5,biomesoplenty:leaves_3:11)
Block(-5,23,6,biomesoplenty:leaves_3:11)
Block(-5,23,7,biomesoplenty:leaves_3:11)
Block(-5,23,8,biomesoplenty:leaves_3:11)
Block(-5,23,9,biomesoplenty:leaves_3:11)
Block(-5,23,10,biomesoplenty:leaves_3:11)
Block(-5,23,11,biomesoplenty:leaves_3:11)
Block(-5,23,12,biomesoplenty:leaves_3:11)
Block(-5,23,13,biomesoplenty:leaves_3:11)
Block(-5,23,14,biomesoplenty:leaves_3:11)
Block(-5,23,15,biomesoplenty:leaves_3:11)
Block(-5,23,16,biomesoplenty:leaves_3:11)
Block(-5,24,-8,biomesoplenty:leaves_3:11)
Block(-5,24,-3,biomesoplenty:leaves_3:11)
Block(-5,24,-2,biomesoplenty:leaves_3:11)
Block(-5,24,-1,biomesoplenty:leaves_3:11)
Block(-5,24,0,biomesoplenty:leaves_3:11)
Block(-5,24,1,biomesoplenty:leaves_3:11)
Block(-5,24,2,biomesoplenty:leaves_3:11)
Block(-5,24,3,biomesoplenty:leaves_3:11)
Block(-5,24,4,biomesoplenty:leaves_3:11)
Block(-5,24,5,biomesoplenty:leaves_3:11)
Block(-5,24,6,biomesoplenty:leaves_3:11)
Block(-5,24,7,biomesoplenty:leaves_3:11)
Block(-5,24,8,biomesoplenty:leaves_3:11)
Block(-5,24,9,biomesoplenty:leaves_3:11)
Block(-5,24,10,biomesoplenty:leaves_3:11)
Block(-5,24,11,biomesoplenty:leaves_3:11)
Block(-5,24,12,biomesoplenty:leaves_3:11)
Block(-5,24,13,biomesoplenty:leaves_3:11)
Block(-5,24,14,biomesoplenty:leaves_3:11)
Block(-5,25,-10,biomesoplenty:leaves_3:11)
Block(-5,25,-9,biomesoplenty:leaves_3:11)
Block(-5,25,-8,biomesoplenty:leaves_3:11)
Block(-5,25,-7,biomesoplenty:leaves_3:11)
Block(-5,25,-6,biomesoplenty:leaves_3:11)
Block(-5,25,-3,biomesoplenty:leaves_3:11)
Block(-5,25,-2,biomesoplenty:leaves_3:11)
Block(-5,25,-1,biomesoplenty:leaves_3:11)
Block(-5,25,0,biomesoplenty:leaves_3:11)
Block(-5,25,1,biomesoplenty:leaves_3:11)
Block(-5,25,2,biomesoplenty:leaves_3:11)
Block(-5,25,3,biomesoplenty:leaves_3:11)
Block(-5,25,4,biomesoplenty:leaves_3:11)
Block(-5,25,5,biomesoplenty:leaves_3:11)
Block(-5,25,6,biomesoplenty:leaves_3:11)
Block(-5,25,7,biomesoplenty:leaves_3:11)
Block(-5,25,8,biomesoplenty:leaves_3:11)
Block(-5,25,9,biomesoplenty:leaves_3:11)
Block(-5,25,10,biomesoplenty:leaves_3:11)
Block(-5,25,11,biomesoplenty:leaves_3:11)
Block(-5,25,12,biomesoplenty:leaves_3:11)
Block(-5,25,13,biomesoplenty:log_0:8)
Block(-5,25,14,biomesoplenty:leaves_3:11)
Block(-5,25,15,biomesoplenty:leaves_3:11)
Block(-5,25,16,biomesoplenty:leaves_3:11)
Block(-5,26,-10,biomesoplenty:leaves_3:11)
Block(-5,26,-9,biomesoplenty:leaves_3:11)
Block(-5,26,-8,biomesoplenty:leaves_3:11)
Block(-5,26,-7,biomesoplenty:leaves_3:11)
Block(-5,26,-6,biomesoplenty:leaves_3:11)
Block(-5,26,-1,biomesoplenty:leaves_3:11)
Block(-5,26,3,biomesoplenty:leaves_3:11)
Block(-5,26,4,biomesoplenty:leaves_3:11)
Block(-5,26,5,biomesoplenty:leaves_3:11)
Block(-5,26,6,biomesoplenty:leaves_3:11)
Block(-5,26,7,biomesoplenty:leaves_3:11)
Block(-5,26,8,biomesoplenty:leaves_3:11)
Block(-5,26,9,biomesoplenty:leaves_3:11)
Block(-5,26,10,biomesoplenty:leaves_3:11)
Block(-5,26,11,biomesoplenty:leaves_3:11)
Block(-5,26,12,biomesoplenty:leaves_3:11)
Block(-5,26,13,biomesoplenty:leaves_3:11)
Block(-5,26,14,biomesoplenty:leaves_3:11)
Block(-5,26,15,biomesoplenty:leaves_3:11)
Block(-5,26,16,biomesoplenty:leaves_3:11)
Block(-5,27,-8,biomesoplenty:leaves_3:11)
Block(-5,27,-5,biomesoplenty:leaves_3:11)
Block(-5,27,-4,biomesoplenty:leaves_3:11)
Block(-5,27,-3,biomesoplenty:leaves_3:11)
Block(-5,27,1,biomesoplenty:leaves_3:11)
Block(-5,27,2,biomesoplenty:leaves_3:11)
Block(-5,27,3,biomesoplenty:leaves_3:11)
Block(-5,27,4,biomesoplenty:leaves_3:11)
Block(-5,27,5,biomesoplenty:leaves_3:11)
Block(-5,27,6,biomesoplenty:leaves_3:11)
Block(-5,27,7,biomesoplenty:leaves_3:11)
Block(-5,27,8,biomesoplenty:leaves_3:11)
Block(-5,27,9,biomesoplenty:leaves_3:11)
Block(-5,27,10,biomesoplenty:leaves_3:11)
Block(-5,27,11,biomesoplenty:leaves_3:11)
Block(-5,27,12,biomesoplenty:leaves_3:11)
Block(-5,27,13,biomesoplenty:leaves_3:11)
Block(-5,27,14,biomesoplenty:leaves_3:11)
Block(-5,27,15,biomesoplenty:leaves_3:11)
Block(-5,27,16,biomesoplenty:leaves_3:11)
Block(-5,28,-5,biomesoplenty:leaves_3:11)
Block(-5,28,-4,biomesoplenty:leaves_3:11)
Block(-5,28,-3,biomesoplenty:leaves_3:11)
Block(-5,28,-2,biomesoplenty:leaves_3:11)
Block(-5,28,1,biomesoplenty:leaves_3:11)
Block(-5,28,2,biomesoplenty:leaves_3:11)
Block(-5,28,3,biomesoplenty:leaves_3:11)
Block(-5,28,4,biomesoplenty:leaves_3:11)
Block(-5,28,5,biomesoplenty:leaves_3:11)
Block(-5,28,8,biomesoplenty:leaves_3:11)
Block(-5,28,9,biomesoplenty:leaves_3:11)
Block(-5,28,10,biomesoplenty:leaves_3:11)
Block(-5,28,11,biomesoplenty:leaves_3:11)
Block(-5,28,12,biomesoplenty:leaves_3:11)
Block(-5,28,13,biomesoplenty:leaves_3:11)
Block(-5,28,14,biomesoplenty:leaves_3:11)
Block(-5,29,-4,biomesoplenty:leaves_3:11)
Block(-5,29,-3,biomesoplenty:leaves_3:11)
Block(-5,29,-2,biomesoplenty:leaves_3:11)
Block(-5,29,3,biomesoplenty:leaves_3:11)
Block(-5,29,5,biomesoplenty:leaves_3:11)
Block(-5,29,6,biomesoplenty:leaves_3:11)
Block(-5,29,7,biomesoplenty:leaves_3:11)
Block(-5,29,8,biomesoplenty:leaves_3:11)
Block(-5,29,9,biomesoplenty:leaves_3:11)
Block(-5,29,10,biomesoplenty:leaves_3:11)
Block(-5,29,11,biomesoplenty:leaves_3:11)
Block(-5,29,12,biomesoplenty:leaves_3:11)
Block(-5,30,-4,biomesoplenty:leaves_3:11)
Block(-5,30,-3,biomesoplenty:leaves_3:11)
Block(-5,30,-2,biomesoplenty:leaves_3:11)
Block(-5,30,2,biomesoplenty:leaves_3:11)
Block(-5,30,4,biomesoplenty:leaves_3:11)
Block(-5,30,5,biomesoplenty:leaves_3:11)
Block(-5,30,6,biomesoplenty:leaves_3:11)
Block(-5,30,7,biomesoplenty:leaves_3:11)
Block(-5,30,8,biomesoplenty:leaves_3:11)
Block(-5,30,9,biomesoplenty:leaves_3:11)
Block(-5,30,10,biomesoplenty:leaves_3:11)
Block(-5,30,11,biomesoplenty:leaves_3:11)
Block(-5,31,-5,biomesoplenty:leaves_3:11)
Block(-5,31,-4,biomesoplenty:leaves_3:11)
Block(-5,31,-3,biomesoplenty:leaves_3:11)
Block(-5,31,-2,biomesoplenty:leaves_3:11)
Block(-5,31,-1,biomesoplenty:leaves_3:11)
Block(-5,31,3,biomesoplenty:leaves_3:11)
Block(-5,31,4,biomesoplenty:leaves_3:11)
Block(-5,31,5,biomesoplenty:leaves_3:11)
Block(-5,31,6,biomesoplenty:leaves_3:11)
Block(-5,31,7,biomesoplenty:leaves_3:11)
Block(-5,31,8,biomesoplenty:leaves_3:11)
Block(-5,31,9,biomesoplenty:leaves_3:11)
Block(-5,32,-5,biomesoplenty:leaves_3:11)
Block(-5,32,-4,biomesoplenty:leaves_3:11)
Block(-5,32,-3,biomesoplenty:leaves_3:11)
Block(-5,32,-2,biomesoplenty:leaves_3:11)
Block(-5,32,-1,biomesoplenty:leaves_3:11)
Block(-5,32,1,biomesoplenty:leaves_3:11)
Block(-5,32,2,biomesoplenty:leaves_3:11)
Block(-5,32,3,biomesoplenty:leaves_3:11)
Block(-5,32,4,biomesoplenty:leaves_3:11)
Block(-5,32,5,biomesoplenty:leaves_3:11)
Block(-5,32,6,biomesoplenty:leaves_3:11)
Block(-5,32,7,biomesoplenty:leaves_3:11)
Block(-5,32,8,biomesoplenty:leaves_3:11)
Block(-5,33,-4,biomesoplenty:leaves_3:11)
Block(-5,33,-3,biomesoplenty:leaves_3:11)
Block(-5,33,-2,biomesoplenty:leaves_3:11)
Block(-5,33,-1,biomesoplenty:leaves_3:11)
Block(-5,33,0,biomesoplenty:leaves_3:11)
Block(-5,33,1,biomesoplenty:leaves_3:11)
Block(-5,33,2,biomesoplenty:leaves_3:11)
Block(-5,33,3,biomesoplenty:leaves_3:11)
Block(-5,33,4,biomesoplenty:leaves_3:11)
Block(-5,33,5,biomesoplenty:leaves_3:11)
Block(-5,33,6,biomesoplenty:leaves_3:11)
Block(-5,33,7,biomesoplenty:leaves_3:11)
Block(-5,33,8,biomesoplenty:leaves_3:11)
Block(-5,34,-1,biomesoplenty:leaves_3:11)
Block(-5,34,0,biomesoplenty:leaves_3:11)
Block(-5,34,1,biomesoplenty:leaves_3:11)
Block(-5,34,2,biomesoplenty:leaves_3:11)
Block(-5,34,3,biomesoplenty:leaves_3:11)
Block(-5,34,4,biomesoplenty:leaves_3:11)
Block(-5,34,5,biomesoplenty:leaves_3:11)
Block(-5,34,6,biomesoplenty:leaves_3:11)
Block(-5,34,7,biomesoplenty:leaves_3:11)
Block(-5,34,8,biomesoplenty:leaves_3:11)
Block(-5,35,0,biomesoplenty:leaves_3:11)
Block(-5,35,1,biomesoplenty:leaves_3:11)
Block(-5,35,2,biomesoplenty:leaves_3:11)
Block(-5,35,3,biomesoplenty:leaves_3:11)
Block(-5,35,4,biomesoplenty:leaves_3:11)
Block(-5,35,5,biomesoplenty:leaves_3:11)
Block(-5,35,6,biomesoplenty:leaves_3:11)
Block(-5,35,7,biomesoplenty:leaves_3:11)
Block(-5,35,8,biomesoplenty:leaves_3:11)
Block(-5,35,9,biomesoplenty:leaves_3:11)
Block(-5,35,10,biomesoplenty:leaves_3:11)
Block(-5,36,-2,biomesoplenty:leaves_3:11)
Block(-5,36,-1,biomesoplenty:leaves_3:11)
Block(-5,36,0,biomesoplenty:leaves_3:11)
Block(-5,36,1,biomesoplenty:leaves_3:11)
Block(-5,36,2,biomesoplenty:leaves_3:11)
Block(-5,36,3,biomesoplenty:leaves_3:11)
Block(-5,36,4,biomesoplenty:leaves_3:11)
Block(-5,36,5,biomesoplenty:leaves_3:11)
Block(-5,36,6,biomesoplenty:leaves_3:11)
Block(-5,36,7,biomesoplenty:leaves_3:11)
Block(-5,36,8,biomesoplenty:leaves_3:11)
Block(-5,36,9,biomesoplenty:leaves_3:11)
Block(-5,36,10,biomesoplenty:leaves_3:11)
Block(-5,37,-2,biomesoplenty:leaves_3:11)
Block(-5,37,-1,biomesoplenty:leaves_3:11)
Block(-5,37,0,biomesoplenty:leaves_3:11)
Block(-5,37,1,biomesoplenty:leaves_3:11)
Block(-5,37,2,biomesoplenty:leaves_3:11)
Block(-5,37,3,biomesoplenty:leaves_3:11)
Block(-5,37,4,biomesoplenty:leaves_3:11)
Block(-5,37,5,biomesoplenty:leaves_3:11)
Block(-5,37,6,biomesoplenty:leaves_3:11)
Block(-5,37,8,biomesoplenty:leaves_3:11)
Block(-5,38,0,biomesoplenty:leaves_3:11)
Block(-5,38,2,biomesoplenty:leaves_3:11)
Block(-5,38,3,biomesoplenty:leaves_3:11)
Block(-5,38,4,biomesoplenty:leaves_3:11)
Block(-4,12,-2,biomesoplenty:leaves_3:11)
Block(-4,12,-1,biomesoplenty:leaves_3:11)
Block(-4,12,6,biomesoplenty:leaves_3:11)
Block(-4,12,12,biomesoplenty:leaves_3:11)
Block(-4,13,-4,biomesoplenty:leaves_3:11)
Block(-4,13,-3,biomesoplenty:leaves_3:11)
Block(-4,13,-2,biomesoplenty:leaves_3:11)
Block(-4,13,-1,biomesoplenty:leaves_3:11)
Block(-4,13,0,biomesoplenty:leaves_3:11)
Block(-4,13,1,biomesoplenty:leaves_3:11)
Block(-4,13,3,biomesoplenty:leaves_3:11)
Block(-4,13,10,biomesoplenty:leaves_3:11)
Block(-4,13,11,biomesoplenty:leaves_3:11)
Block(-4,13,12,biomesoplenty:leaves_3:11)
Block(-4,13,13,biomesoplenty:leaves_3:11)
Block(-4,13,14,biomesoplenty:leaves_3:11)
Block(-4,14,-9,biomesoplenty:leaves_3:11)
Block(-4,14,-5,biomesoplenty:leaves_3:11)
Block(-4,14,-4,biomesoplenty:leaves_3:11)
Block(-4,14,-3,biomesoplenty:leaves_3:11)
Block(-4,14,-2,biomesoplenty:leaves_3:11)
Block(-4,14,-1,biomesoplenty:leaves_3:11)
Block(-4,14,0,biomesoplenty:leaves_3:11)
Block(-4,14,1,biomesoplenty:leaves_3:11)
Block(-4,14,6,biomesoplenty:leaves_3:11)
Block(-4,14,8,biomesoplenty:leaves_3:11)
Block(-4,14,9,biomesoplenty:leaves_3:11)
Block(-4,14,10,biomesoplenty:leaves_3:11)
Block(-4,14,11,biomesoplenty:leaves_3:11)
Block(-4,14,12,biomesoplenty:leaves_3:11)
Block(-4,14,13,biomesoplenty:leaves_3:11)
Block(-4,14,14,biomesoplenty:leaves_3:11)
Block(-4,15,-11,biomesoplenty:leaves_3:11)
Block(-4,15,-10,biomesoplenty:leaves_3:11)
Block(-4,15,-9,biomesoplenty:leaves_3:11)
Block(-4,15,-8,biomesoplenty:leaves_3:11)
Block(-4,15,-7,biomesoplenty:leaves_3:11)
Block(-4,15,-6,biomesoplenty:leaves_3:11)
Block(-4,15,-5,biomesoplenty:leaves_3:11)
Block(-4,15,-4,biomesoplenty:leaves_3:11)
Block(-4,15,-3,biomesoplenty:leaves_3:11)
Block(-4,15,-2,biomesoplenty:leaves_3:11)
Block(-4,15,-1,biomesoplenty:leaves_3:11)
Block(-4,15,0,biomesoplenty:leaves_3:11)
Block(-4,15,1,biomesoplenty:leaves_3:11)
Block(-4,15,2,biomesoplenty:leaves_3:11)
Block(-4,15,3,biomesoplenty:leaves_3:11)
Block(-4,15,4,biomesoplenty:leaves_3:11)
Block(-4,15,6,biomesoplenty:leaves_3:11)
Block(-4,15,7,biomesoplenty:leaves_3:11)
Block(-4,15,8,biomesoplenty:leaves_3:11)
Block(-4,15,9,biomesoplenty:leaves_3:11)
Block(-4,15,10,biomesoplenty:leaves_3:11)
Block(-4,15,11,biomesoplenty:leaves_3:11)
Block(-4,15,12,biomesoplenty:leaves_3:11)
Block(-4,15,13,biomesoplenty:leaves_3:11)
Block(-4,16,-11,biomesoplenty:leaves_3:11)
Block(-4,16,-10,biomesoplenty:leaves_3:11)
Block(-4,16,-9,biomesoplenty:leaves_3:11)
Block(-4,16,-8,biomesoplenty:leaves_3:11)
Block(-4,16,-7,biomesoplenty:leaves_3:11)
Block(-4,16,-6,biomesoplenty:leaves_3:11)
Block(-4,16,-5,biomesoplenty:leaves_3:11)
Block(-4,16,-4,biomesoplenty:leaves_3:11)
Block(-4,16,-3,biomesoplenty:leaves_3:11)
Block(-4,16,-2,biomesoplenty:leaves_3:11)
Block(-4,16,-1,biomesoplenty:leaves_3:11)
Block(-4,16,0,biomesoplenty:leaves_3:11)
Block(-4,16,2,biomesoplenty:leaves_3:11)
Block(-4,16,3,biomesoplenty:leaves_3:11)
Block(-4,16,4,biomesoplenty:leaves_3:11)
Block(-4,16,5,biomesoplenty:leaves_3:11)
Block(-4,16,6,biomesoplenty:leaves_3:11)
Block(-4,16,7,biomesoplenty:leaves_3:11)
Block(-4,16,8,biomesoplenty:leaves_3:11)
Block(-4,16,9,biomesoplenty:leaves_3:11)
Block(-4,16,10,biomesoplenty:leaves_3:11)
Block(-4,16,11,biomesoplenty:leaves_3:11)
Block(-4,16,12,biomesoplenty:leaves_3:11)
Block(-4,16,13,biomesoplenty:leaves_3:11)
Block(-4,17,-9,biomesoplenty:leaves_3:11)
Block(-4,17,-8,biomesoplenty:leaves_3:11)
Block(-4,17,-7,biomesoplenty:leaves_3:11)
Block(-4,17,-6,biomesoplenty:leaves_3:11)
Block(-4,17,-5,biomesoplenty:leaves_3:11)
Block(-4,17,-4,biomesoplenty:leaves_3:11)
Block(-4,17,-3,biomesoplenty:leaves_3:11)
Block(-4,17,-2,biomesoplenty:leaves_3:11)
Block(-4,17,-1,biomesoplenty:leaves_3:11)
Block(-4,17,0,biomesoplenty:leaves_3:11)
Block(-4,17,1,biomesoplenty:leaves_3:11)
Block(-4,17,3,biomesoplenty:leaves_3:11)
Block(-4,17,4,biomesoplenty:leaves_3:11)
Block(-4,17,5,biomesoplenty:leaves_3:11)
Block(-4,17,6,biomesoplenty:leaves_3:11)
Block(-4,17,7,biomesoplenty:leaves_3:11)
Block(-4,17,8,biomesoplenty:leaves_3:11)
Block(-4,17,9,biomesoplenty:leaves_3:11)
Block(-4,17,10,biomesoplenty:leaves_3:11)
Block(-4,17,11,biomesoplenty:leaves_3:11)
Block(-4,17,12,biomesoplenty:leaves_3:11)
Block(-4,18,-8,biomesoplenty:leaves_3:11)
Block(-4,18,-7,biomesoplenty:leaves_3:11)
Block(-4,18,-6,biomesoplenty:leaves_3:11)
Block(-4,18,-5,biomesoplenty:log_0:8)
Block(-4,18,-4,biomesoplenty:leaves_3:11)
Block(-4,18,-3,biomesoplenty:leaves_3:11)
Block(-4,18,-2,biomesoplenty:leaves_3:11)
Block(-4,18,-1,biomesoplenty:leaves_3:11)
Block(-4,18,0,biomesoplenty:leaves_3:11)
Block(-4,18,1,biomesoplenty:leaves_3:11)
Block(-4,18,2,biomesoplenty:leaves_3:11)
Block(-4,18,3,biomesoplenty:leaves_3:11)
Block(-4,18,4,biomesoplenty:leaves_3:11)
Block(-4,18,5,biomesoplenty:leaves_3:11)
Block(-4,18,6,biomesoplenty:leaves_3:11)
Block(-4,18,7,biomesoplenty:leaves_3:11)
Block(-4,18,8,biomesoplenty:leaves_3:11)
Block(-4,18,9,biomesoplenty:leaves_3:11)
Block(-4,18,10,biomesoplenty:leaves_3:11)
Block(-4,18,11,biomesoplenty:leaves_3:11)
Block(-4,18,12,biomesoplenty:leaves_3:11)
Block(-4,18,13,biomesoplenty:leaves_3:11)
Block(-4,18,14,biomesoplenty:leaves_3:11)
Block(-4,19,-6,biomesoplenty:leaves_3:11)
Block(-4,19,-4,biomesoplenty:leaves_3:11)
Block(-4,19,-3,biomesoplenty:leaves_3:11)
Block(-4,19,-2,biomesoplenty:leaves_3:11)
Block(-4,19,-1,biomesoplenty:leaves_3:11)
Block(-4,19,0,biomesoplenty:leaves_3:11)
Block(-4,19,1,biomesoplenty:leaves_3:11)
Block(-4,19,2,biomesoplenty:leaves_3:11)
Block(-4,19,3,biomesoplenty:leaves_3:11)
Block(-4,19,4,biomesoplenty:leaves_3:11)
Block(-4,19,5,biomesoplenty:leaves_3:11)
Block(-4,19,6,biomesoplenty:leaves_3:11)
Block(-4,19,7,biomesoplenty:leaves_3:11)
Block(-4,19,8,biomesoplenty:leaves_3:11)
Block(-4,19,9,biomesoplenty:leaves_3:11)
Block(-4,19,10,biomesoplenty:leaves_3:11)
Block(-4,19,11,biomesoplenty:leaves_3:11)
Block(-4,19,12,biomesoplenty:leaves_3:11)
Block(-4,19,13,biomesoplenty:leaves_3:11)
Block(-4,19,14,biomesoplenty:leaves_3:11)
Block(-4,20,-8,biomesoplenty:leaves_3:11)
Block(-4,20,-7,biomesoplenty:leaves_3:11)
Block(-4,20,-6,biomesoplenty:leaves_3:11)
Block(-4,20,-5,biomesoplenty:leaves_3:11)
Block(-4,20,-4,biomesoplenty:leaves_3:11)
Block(-4,20,-3,biomesoplenty:leaves_3:11)
Block(-4,20,-2,biomesoplenty:leaves_3:11)
Block(-4,20,-1,biomesoplenty:leaves_3:11)
Block(-4,20,0,biomesoplenty:leaves_3:11)
Block(-4,20,1,biomesoplenty:leaves_3:11)
Block(-4,20,2,biomesoplenty:leaves_3:11)
Block(-4,20,3,biomesoplenty:leaves_3:11)
Block(-4,20,4,biomesoplenty:leaves_3:11)
Block(-4,20,5,biomesoplenty:leaves_3:11)
Block(-4,20,6,biomesoplenty:leaves_3:11)
Block(-4,20,7,biomesoplenty:leaves_3:11)
Block(-4,20,8,biomesoplenty:leaves_3:11)
Block(-4,20,9,biomesoplenty:leaves_3:11)
Block(-4,20,10,biomesoplenty:leaves_3:11)
Block(-4,20,11,biomesoplenty:log_0:8)
Block(-4,20,12,biomesoplenty:leaves_3:11)
Block(-4,20,13,biomesoplenty:leaves_3:11)
Block(-4,21,-8,biomesoplenty:leaves_3:11)
Block(-4,21,-7,biomesoplenty:leaves_3:11)
Block(-4,21,-6,biomesoplenty:leaves_3:11)
Block(-4,21,-5,biomesoplenty:leaves_3:11)
Block(-4,21,-4,biomesoplenty:leaves_3:11)
Block(-4,21,-3,biomesoplenty:leaves_3:11)
Block(-4,21,-2,biomesoplenty:leaves_3:11)
Block(-4,21,-1,biomesoplenty:leaves_3:11)
Block(-4,21,0,biomesoplenty:leaves_3:11)
Block(-4,21,1,biomesoplenty:leaves_3:11)
Block(-4,21,2,biomesoplenty:leaves_3:11)
Block(-4,21,3,biomesoplenty:leaves_3:11)
Block(-4,21,4,biomesoplenty:leaves_3:11)
Block(-4,21,5,biomesoplenty:leaves_3:11)
Block(-4,21,6,biomesoplenty:leaves_3:11)
Block(-4,21,7,biomesoplenty:leaves_3:11)
Block(-4,21,8,biomesoplenty:leaves_3:11)
Block(-4,21,9,biomesoplenty:leaves_3:11)
Block(-4,21,10,biomesoplenty:leaves_3:11)
Block(-4,21,11,biomesoplenty:leaves_3:11)
Block(-4,21,12,biomesoplenty:leaves_3:11)
Block(-4,21,13,biomesoplenty:leaves_3:11)
Block(-4,21,14,biomesoplenty:log_0:8)
Block(-4,21,15,biomesoplenty:leaves_3:11)
Block(-4,22,-8,biomesoplenty:leaves_3:11)
Block(-4,22,-7,biomesoplenty:leaves_3:11)
Block(-4,22,-6,biomesoplenty:leaves_3:11)
Block(-4,22,-5,biomesoplenty:leaves_3:11)
Block(-4,22,-4,biomesoplenty:leaves_3:11)
Block(-4,22,1,biomesoplenty:leaves_3:11)
Block(-4,22,2,biomesoplenty:leaves_3:11)
Block(-4,22,3,biomesoplenty:leaves_3:11)
Block(-4,22,4,biomesoplenty:leaves_3:11)
Block(-4,22,5,biomesoplenty:leaves_3:11)
Block(-4,22,6,biomesoplenty:leaves_3:11)
Block(-4,22,7,biomesoplenty:leaves_3:11)
Block(-4,22,8,biomesoplenty:leaves_3:11)
Block(-4,22,9,biomesoplenty:leaves_3:11)
Block(-4,22,10,biomesoplenty:leaves_3:11)
Block(-4,22,11,biomesoplenty:leaves_3:11)
Block(-4,22,12,biomesoplenty:leaves_3:11)
Block(-4,22,13,biomesoplenty:leaves_3:11)
Block(-4,22,14,biomesoplenty:leaves_3:11)
Block(-4,22,15,biomesoplenty:leaves_3:11)
Block(-4,22,16,biomesoplenty:leaves_3:11)
Block(-4,23,-8,biomesoplenty:leaves_3:11)
Block(-4,23,-7,biomesoplenty:leaves_3:11)
Block(-4,23,-6,biomesoplenty:leaves_3:11)
Block(-4,23,-5,biomesoplenty:leaves_3:11)
Block(-4,23,-4,biomesoplenty:leaves_3:11)
Block(-4,23,-2,biomesoplenty:leaves_3:11)
Block(-4,23,-1,biomesoplenty:leaves_3:11)
Block(-4,23,0,biomesoplenty:leaves_3:11)
Block(-4,23,3,biomesoplenty:leaves_3:11)
Block(-4,23,4,biomesoplenty:leaves_3:11)
Block(-4,23,5,biomesoplenty:leaves_3:11)
Block(-4,23,6,biomesoplenty:leaves_3:11)
Block(-4,23,7,biomesoplenty:leaves_3:11)
Block(-4,23,8,biomesoplenty:leaves_3:11)
Block(-4,23,9,biomesoplenty:leaves_3:11)
Block(-4,23,10,biomesoplenty:leaves_3:11)
Block(-4,23,11,biomesoplenty:leaves_3:11)
Block(-4,23,12,biomesoplenty:leaves_3:11)
Block(-4,23,13,biomesoplenty:leaves_3:11)
Block(-4,23,14,biomesoplenty:leaves_3:11)
Block(-4,23,15,biomesoplenty:leaves_3:11)
Block(-4,23,16,biomesoplenty:leaves_3:11)
Block(-4,24,-9,biomesoplenty:leaves_3:11)
Block(-4,24,-8,biomesoplenty:log_0:8)
Block(-4,24,-7,biomesoplenty:leaves_3:11)
Block(-4,24,-3,biomesoplenty:leaves_3:11)
Block(-4,24,-2,biomesoplenty:leaves_3:11)
Block(-4,24,-1,biomesoplenty:leaves_3:11)
Block(-4,24,0,biomesoplenty:leaves_3:11)
Block(-4,24,1,biomesoplenty:leaves_3:11)
Block(-4,24,2,biomesoplenty:leaves_3:11)
Block(-4,24,3,biomesoplenty:leaves_3:11)
Block(-4,24,4,biomesoplenty:leaves_3:11)
Block(-4,24,5,biomesoplenty:leaves_3:11)
Block(-4,24,6,biomesoplenty:leaves_3:11)
Block(-4,24,7,biomesoplenty:leaves_3:11)
Block(-4,24,8,biomesoplenty:leaves_3:11)
Block(-4,24,9,biomesoplenty:leaves_3:11)
Block(-4,24,10,biomesoplenty:leaves_3:11)
Block(-4,24,11,biomesoplenty:leaves_3:11)
Block(-4,24,12,biomesoplenty:leaves_3:11)
Block(-4,24,13,biomesoplenty:leaves_3:11)
Block(-4,24,14,biomesoplenty:log_0:8)
Block(-4,24,15,biomesoplenty:leaves_3:11)
Block(-4,25,-10,biomesoplenty:leaves_3:11)
Block(-4,25,-9,biomesoplenty:leaves_3:11)
Block(-4,25,-8,biomesoplenty:leaves_3:11)
Block(-4,25,-7,biomesoplenty:leaves_3:11)
Block(-4,25,-6,biomesoplenty:leaves_3:11)
Block(-4,25,-3,biomesoplenty:leaves_3:11)
Block(-4,25,-2,biomesoplenty:leaves_3:11)
Block(-4,25,-1,biomesoplenty:leaves_3:11)
Block(-4,25,0,biomesoplenty:leaves_3:11)
Block(-4,25,1,biomesoplenty:leaves_3:11)
Block(-4,25,2,biomesoplenty:leaves_3:11)
Block(-4,25,3,biomesoplenty:leaves_3:11)
Block(-4,25,4,biomesoplenty:leaves_3:11)
Block(-4,25,5,biomesoplenty:leaves_3:11)
Block(-4,25,6,biomesoplenty:leaves_3:11)
Block(-4,25,7,biomesoplenty:leaves_3:11)
Block(-4,25,8,biomesoplenty:leaves_3:11)
Block(-4,25,9,biomesoplenty:leaves_3:11)
Block(-4,25,10,biomesoplenty:leaves_3:11)
Block(-4,25,11,biomesoplenty:leaves_3:11)
Block(-4,25,12,biomesoplenty:log_0:8)
Block(-4,25,13,biomesoplenty:leaves_3:11)
Block(-4,25,14,biomesoplenty:log_0:8)
Block(-4,25,15,biomesoplenty:leaves_3:11)
Block(-4,25,16,biomesoplenty:leaves_3:11)
Block(-4,26,-10,biomesoplenty:leaves_3:11)
Block(-4,26,-9,biomesoplenty:leaves_3:11)
Block(-4,26,-8,biomesoplenty:leaves_3:11)
Block(-4,26,-7,biomesoplenty:leaves_3:11)
Block(-4,26,-6,biomesoplenty:leaves_3:11)
Block(-4,26,-4,biomesoplenty:leaves_3:11)
Block(-4,26,-2,biomesoplenty:leaves_3:11)
Block(-4,26,-1,biomesoplenty:leaves_3:11)
Block(-4,26,0,biomesoplenty:leaves_3:11)
Block(-4,26,2,biomesoplenty:leaves_3:11)
Block(-4,26,3,biomesoplenty:leaves_3:11)
Block(-4,26,4,biomesoplenty:leaves_3:11)
Block(-4,26,5,biomesoplenty:leaves_3:11)
Block(-4,26,6,biomesoplenty:leaves_3:11)
Block(-4,26,7,biomesoplenty:leaves_3:11)
Block(-4,26,8,biomesoplenty:leaves_3:11)
Block(-4,26,9,biomesoplenty:leaves_3:11)
Block(-4,26,10,biomesoplenty:leaves_3:11)
Block(-4,26,11,biomesoplenty:leaves_3:11)
Block(-4,26,12,biomesoplenty:leaves_3:11)
Block(-4,26,13,biomesoplenty:leaves_3:11)
Block(-4,26,14,biomesoplenty:leaves_3:11)
Block(-4,26,15,biomesoplenty:leaves_3:11)
Block(-4,26,16,biomesoplenty:leaves_3:11)
Block(-4,27,-9,biomesoplenty:leaves_3:11)
Block(-4,27,-8,biomesoplenty:leaves_3:11)
Block(-4,27,-7,biomesoplenty:leaves_3:11)
Block(-4,27,-6,biomesoplenty:leaves_3:11)
Block(-4,27,-5,biomesoplenty:leaves_3:11)
Block(-4,27,-4,biomesoplenty:leaves_3:11)
Block(-4,27,-3,biomesoplenty:leaves_3:11)
Block(-4,27,-2,biomesoplenty:leaves_3:11)
Block(-4,27,1,biomesoplenty:leaves_3:11)
Block(-4,27,2,biomesoplenty:leaves_3:11)
Block(-4,27,3,biomesoplenty:leaves_3:11)
Block(-4,27,4,biomesoplenty:leaves_3:11)
Block(-4,27,5,biomesoplenty:leaves_3:11)
Block(-4,27,6,biomesoplenty:leaves_3:11)
Block(-4,27,7,biomesoplenty:leaves_3:11)
Block(-4,27,8,biomesoplenty:leaves_3:11)
Block(-4,27,9,biomesoplenty:leaves_3:11)
Block(-4,27,10,biomesoplenty:leaves_3:11)
Block(-4,27,11,biomesoplenty:leaves_3:11)
Block(-4,27,12,biomesoplenty:leaves_3:11)
Block(-4,27,13,biomesoplenty:leaves_3:11)
Block(-4,27,14,biomesoplenty:leaves_3:11)
Block(-4,27,15,biomesoplenty:leaves_3:11)
Block(-4,27,16,biomesoplenty:leaves_3:11)
Block(-4,28,-6,biomesoplenty:leaves_3:11)
Block(-4,28,-5,biomesoplenty:leaves_3:11)
Block(-4,28,-4,biomesoplenty:leaves_3:11)
Block(-4,28,-3,biomesoplenty:leaves_3:11)
Block(-4,28,-2,biomesoplenty:leaves_3:11)
Block(-4,28,-1,biomesoplenty:leaves_3:11)
Block(-4,28,1,biomesoplenty:leaves_3:11)
Block(-4,28,2,biomesoplenty:leaves_3:11)
Block(-4,28,3,biomesoplenty:leaves_3:11)
Block(-4,28,4,biomesoplenty:leaves_3:11)
Block(-4,28,5,biomesoplenty:leaves_3:11)
Block(-4,28,6,biomesoplenty:leaves_3:11)
Block(-4,28,7,biomesoplenty:leaves_3:11)
Block(-4,28,8,biomesoplenty:leaves_3:11)
Block(-4,28,9,biomesoplenty:leaves_3:11)
Block(-4,28,10,biomesoplenty:leaves_3:11)
Block(-4,28,11,biomesoplenty:leaves_3:11)
Block(-4,28,12,biomesoplenty:leaves_3:11)
Block(-4,28,13,biomesoplenty:leaves_3:11)
Block(-4,28,14,biomesoplenty:leaves_3:11)
Block(-4,28,15,biomesoplenty:leaves_3:11)
Block(-4,29,-5,biomesoplenty:leaves_3:11)
Block(-4,29,-4,biomesoplenty:leaves_3:11)
Block(-4,29,-3,biomesoplenty:leaves_3:11)
Block(-4,29,-2,biomesoplenty:leaves_3:11)
Block(-4,29,-1,biomesoplenty:leaves_3:11)
Block(-4,29,2,biomesoplenty:leaves_3:11)
Block(-4,29,3,biomesoplenty:leaves_3:11)
Block(-4,29,4,biomesoplenty:leaves_3:11)
Block(-4,29,5,biomesoplenty:leaves_3:11)
Block(-4,29,6,biomesoplenty:leaves_3:11)
Block(-4,29,7,biomesoplenty:leaves_3:11)
Block(-4,29,8,biomesoplenty:leaves_3:11)
Block(-4,29,9,biomesoplenty:leaves_3:11)
Block(-4,29,10,biomesoplenty:leaves_3:11)
Block(-4,29,11,biomesoplenty:leaves_3:11)
Block(-4,29,12,biomesoplenty:leaves_3:11)
Block(-4,29,13,biomesoplenty:leaves_3:11)
Block(-4,30,-3,biomesoplenty:leaves_3:11)
Block(-4,30,4,biomesoplenty:leaves_3:11)
Block(-4,30,5,biomesoplenty:leaves_3:11)
Block(-4,30,6,biomesoplenty:leaves_3:11)
Block(-4,30,7,biomesoplenty:leaves_3:11)
Block(-4,30,8,biomesoplenty:leaves_3:11)
Block(-4,30,9,biomesoplenty:leaves_3:11)
Block(-4,30,10,biomesoplenty:leaves_3:11)
Block(-4,30,11,biomesoplenty:leaves_3:11)
Block(-4,30,12,biomesoplenty:leaves_3:11)
Block(-4,30,13,biomesoplenty:leaves_3:11)
Block(-4,31,-5,biomesoplenty:leaves_3:11)
Block(-4,31,-4,biomesoplenty:leaves_3:11)
Block(-4,31,-3,biomesoplenty:leaves_3:11)
Block(-4,31,-2,biomesoplenty:leaves_3:11)
Block(-4,31,-1,biomesoplenty:leaves_3:11)
Block(-4,31,0,biomesoplenty:leaves_3:11)
Block(-4,31,1,biomesoplenty:leaves_3:11)
Block(-4,31,2,biomesoplenty:leaves_3:11)
Block(-4,31,3,biomesoplenty:leaves_3:11)
Block(-4,31,4,biomesoplenty:leaves_3:11)
Block(-4,31,5,biomesoplenty:leaves_3:11)
Block(-4,31,6,biomesoplenty:leaves_3:11)
Block(-4,31,7,biomesoplenty:leaves_3:11)
Block(-4,31,8,biomesoplenty:leaves_3:11)
Block(-4,31,9,biomesoplenty:leaves_3:11)
Block(-4,31,10,biomesoplenty:leaves_3:11)
Block(-4,31,11,biomesoplenty:leaves_3:11)
Block(-4,31,12,biomesoplenty:leaves_3:11)
Block(-4,32,-5,biomesoplenty:leaves_3:11)
Block(-4,32,-4,biomesoplenty:leaves_3:11)
Block(-4,32,-3,biomesoplenty:leaves_3:11)
Block(-4,32,-2,biomesoplenty:leaves_3:11)
Block(-4,32,-1,biomesoplenty:leaves_3:11)
Block(-4,32,0,biomesoplenty:leaves_3:11)
Block(-4,32,1,biomesoplenty:leaves_3:11)
Block(-4,32,2,biomesoplenty:leaves_3:11)
Block(-4,32,3,biomesoplenty:leaves_3:11)
Block(-4,32,4,biomesoplenty:leaves_3:11)
Block(-4,32,5,biomesoplenty:leaves_3:11)
Block(-4,32,6,biomesoplenty:leaves_3:11)
Block(-4,32,7,biomesoplenty:leaves_3:11)
Block(-4,32,8,biomesoplenty:leaves_3:11)
Block(-4,32,10,biomesoplenty:leaves_3:11)
Block(-4,32,11,biomesoplenty:leaves_3:11)
Block(-4,32,12,biomesoplenty:leaves_3:11)
Block(-4,33,-5,biomesoplenty:leaves_3:11)
Block(-4,33,-4,biomesoplenty:leaves_3:11)
Block(-4,33,-3,biomesoplenty:leaves_3:11)
Block(-4,33,-1,biomesoplenty:leaves_3:11)
Block(-4,33,0,biomesoplenty:leaves_3:11)
Block(-4,33,1,biomesoplenty:leaves_3:11)
Block(-4,33,2,biomesoplenty:leaves_3:11)
Block(-4,33,3,biomesoplenty:leaves_3:11)
Block(-4,33,4,biomesoplenty:leaves_3:11)
Block(-4,33,5,biomesoplenty:leaves_3:11)
Block(-4,33,6,biomesoplenty:leaves_3:11)
Block(-4,33,7,biomesoplenty:leaves_3:11)
Block(-4,33,8,biomesoplenty:leaves_3:11)
Block(-4,34,-1,biomesoplenty:leaves_3:11)
Block(-4,34,0,biomesoplenty:leaves_3:11)
Block(-4,34,1,biomesoplenty:leaves_3:11)
Block(-4,34,2,biomesoplenty:leaves_3:11)
Block(-4,34,3,biomesoplenty:leaves_3:11)
Block(-4,34,4,biomesoplenty:leaves_3:11)
Block(-4,34,5,biomesoplenty:leaves_3:11)
Block(-4,34,6,biomesoplenty:leaves_3:11)
Block(-4,34,7,biomesoplenty:leaves_3:11)
Block(-4,34,8,biomesoplenty:leaves_3:11)
Block(-4,34,9,biomesoplenty:leaves_3:11)
Block(-4,35,-2,biomesoplenty:leaves_3:11)
Block(-4,35,-1,biomesoplenty:leaves_3:11)
Block(-4,35,0,biomesoplenty:leaves_3:11)
Block(-4,35,1,biomesoplenty:leaves_3:11)
Block(-4,35,2,biomesoplenty:leaves_3:11)
Block(-4,35,3,biomesoplenty:leaves_3:11)
Block(-4,35,4,biomesoplenty:leaves_3:11)
Block(-4,35,5,biomesoplenty:leaves_3:11)
Block(-4,35,6,biomesoplenty:leaves_3:11)
Block(-4,35,7,biomesoplenty:leaves_3:11)
Block(-4,35,8,biomesoplenty:leaves_3:11)
Block(-4,35,9,biomesoplenty:leaves_3:11)
Block(-4,35,10,biomesoplenty:leaves_3:11)
Block(-4,35,11,biomesoplenty:leaves_3:11)
Block(-4,35,12,biomesoplenty:leaves_3:11)
Block(-4,36,-2,biomesoplenty:leaves_3:11)
Block(-4,36,-1,biomesoplenty:leaves_3:11)
Block(-4,36,0,biomesoplenty:leaves_3:11)
Block(-4,36,1,biomesoplenty:leaves_3:11)
Block(-4,36,2,biomesoplenty:leaves_3:11)
Block(-4,36,3,biomesoplenty:leaves_3:11)
Block(-4,36,4,biomesoplenty:leaves_3:11)
Block(-4,36,5,biomesoplenty:leaves_3:11)
Block(-4,36,6,biomesoplenty:leaves_3:11)
Block(-4,36,7,biomesoplenty:leaves_3:11)
Block(-4,36,8,biomesoplenty:leaves_3:11)
Block(-4,36,9,biomesoplenty:leaves_3:11)
Block(-4,36,10,biomesoplenty:leaves_3:11)
Block(-4,36,11,biomesoplenty:leaves_3:11)
Block(-4,36,12,biomesoplenty:leaves_3:11)
Block(-4,37,-4,biomesoplenty:leaves_3:11)
Block(-4,37,-3,biomesoplenty:leaves_3:11)
Block(-4,37,-2,biomesoplenty:leaves_3:11)
Block(-4,37,-1,biomesoplenty:leaves_3:11)
Block(-4,37,0,biomesoplenty:leaves_3:11)
Block(-4,37,1,biomesoplenty:leaves_3:11)
Block(-4,37,2,biomesoplenty:leaves_3:11)
Block(-4,37,3,biomesoplenty:leaves_3:11)
Block(-4,37,4,biomesoplenty:leaves_3:11)
Block(-4,37,5,biomesoplenty:leaves_3:11)
Block(-4,37,6,biomesoplenty:leaves_3:11)
Block(-4,37,7,biomesoplenty:leaves_3:11)
Block(-4,37,8,biomesoplenty:leaves_3:11)
Block(-4,37,9,biomesoplenty:leaves_3:11)
Block(-4,37,10,biomesoplenty:leaves_3:11)
Block(-4,37,11,biomesoplenty:leaves_3:11)
Block(-4,38,-4,biomesoplenty:leaves_3:11)
Block(-4,38,-3,biomesoplenty:leaves_3:11)
Block(-4,38,-2,biomesoplenty:leaves_3:11)
Block(-4,38,-1,biomesoplenty:leaves_3:11)
Block(-4,38,0,biomesoplenty:leaves_3:11)
Block(-4,38,1,biomesoplenty:leaves_3:11)
Block(-4,38,2,biomesoplenty:leaves_3:11)
Block(-4,38,3,biomesoplenty:leaves_3:11)
Block(-4,38,4,biomesoplenty:leaves_3:11)
Block(-4,38,5,biomesoplenty:leaves_3:11)
Block(-4,38,6,biomesoplenty:leaves_3:11)
Block(-4,38,7,biomesoplenty:leaves_3:11)
Block(-4,38,8,biomesoplenty:leaves_3:11)
Block(-4,39,3,biomesoplenty:leaves_3:11)
Block(-3,12,-3,biomesoplenty:leaves_3:11)
Block(-3,12,-2,biomesoplenty:leaves_3:11)
Block(-3,12,-1,biomesoplenty:leaves_3:11)
Block(-3,12,0,biomesoplenty:leaves_3:11)
Block(-3,12,6,biomesoplenty:leaves_3:11)
Block(-3,13,-4,biomesoplenty:leaves_3:11)
Block(-3,13,-3,biomesoplenty:leaves_3:11)
Block(-3,13,-2,biomesoplenty:leaves_3:11)
Block(-3,13,-1,biomesoplenty:leaves_3:11)
Block(-3,13,0,biomesoplenty:leaves_3:11)
Block(-3,13,1,biomesoplenty:leaves_3:11)
Block(-3,13,3,biomesoplenty:leaves_3:11)
Block(-3,13,4,biomesoplenty:leaves_3:11)
Block(-3,13,5,biomesoplenty:leaves_3:11)
Block(-3,13,6,biomesoplenty:leaves_3:11)
Block(-3,13,7,biomesoplenty:leaves_3:11)
Block(-3,13,8,biomesoplenty:leaves_3:11)
Block(-3,13,11,biomesoplenty:leaves_3:11)
Block(-3,13,12,biomesoplenty:leaves_3:11)
Block(-3,13,13,biomesoplenty:leaves_3:11)
Block(-3,13,14,biomesoplenty:leaves_3:11)
Block(-3,14,-10,biomesoplenty:leaves_3:11)
Block(-3,14,-9,biomesoplenty:leaves_3:11)
Block(-3,14,-8,biomesoplenty:leaves_3:11)
Block(-3,14,-5,biomesoplenty:leaves_3:11)
Block(-3,14,-4,biomesoplenty:leaves_3:11)
Block(-3,14,-3,biomesoplenty:leaves_3:11)
Block(-3,14,-2,biomesoplenty:leaves_3:11)
Block(-3,14,-1,biomesoplenty:leaves_3:11)
Block(-3,14,0,biomesoplenty:leaves_3:11)
Block(-3,14,1,biomesoplenty:leaves_3:11)
Block(-3,14,2,biomesoplenty:leaves_3:11)
Block(-3,14,3,biomesoplenty:leaves_3:11)
Block(-3,14,4,biomesoplenty:leaves_3:11)
Block(-3,14,5,biomesoplenty:leaves_3:11)
Block(-3,14,6,biomesoplenty:leaves_3:11)
Block(-3,14,9,biomesoplenty:leaves_3:11)
Block(-3,14,11,biomesoplenty:leaves_3:11)
Block(-3,14,12,biomesoplenty:leaves_3:11)
Block(-3,14,13,biomesoplenty:leaves_3:11)
Block(-3,14,14,biomesoplenty:leaves_3:11)
Block(-3,15,-11,biomesoplenty:leaves_3:11)
Block(-3,15,-10,biomesoplenty:leaves_3:11)
Block(-3,15,-9,biomesoplenty:leaves_3:11)
Block(-3,15,-8,biomesoplenty:leaves_3:11)
Block(-3,15,-7,biomesoplenty:leaves_3:11)
Block(-3,15,-6,biomesoplenty:leaves_3:11)
Block(-3,15,-5,biomesoplenty:leaves_3:11)
Block(-3,15,-4,biomesoplenty:leaves_3:11)
Block(-3,15,-3,biomesoplenty:leaves_3:11)
Block(-3,15,-2,biomesoplenty:leaves_3:11)
Block(-3,15,-1,biomesoplenty:leaves_3:11)
Block(-3,15,0,biomesoplenty:leaves_3:11)
Block(-3,15,1,biomesoplenty:leaves_3:11)
Block(-3,15,2,biomesoplenty:leaves_3:11)
Block(-3,15,3,biomesoplenty:leaves_3:11)
Block(-3,15,4,biomesoplenty:leaves_3:11)
Block(-3,15,7,biomesoplenty:leaves_3:11)
Block(-3,15,8,biomesoplenty:leaves_3:11)
Block(-3,15,9,biomesoplenty:leaves_3:11)
Block(-3,15,10,biomesoplenty:leaves_3:11)
Block(-3,15,11,biomesoplenty:leaves_3:11)
Block(-3,15,12,biomesoplenty:leaves_3:11)
Block(-3,15,13,biomesoplenty:leaves_3:11)
Block(-3,15,14,biomesoplenty:leaves_3:11)
Block(-3,16,-11,biomesoplenty:leaves_3:11)
Block(-3,16,-10,biomesoplenty:leaves_3:11)
Block(-3,16,-9,biomesoplenty:leaves_3:11)
Block(-3,16,-8,biomesoplenty:leaves_3:11)
Block(-3,16,-7,biomesoplenty:leaves_3:11)
Block(-3,16,-6,biomesoplenty:log_0:8)
Block(-3,16,-5,biomesoplenty:leaves_3:11)
Block(-3,16,-4,biomesoplenty:leaves_3:11)
Block(-3,16,-3,biomesoplenty:leaves_3:11)
Block(-3,16,-2,biomesoplenty:leaves_3:11)
Block(-3,16,-1,biomesoplenty:leaves_3:11)
Block(-3,16,0,biomesoplenty:leaves_3:11)
Block(-3,16,1,biomesoplenty:leaves_3:11)
Block(-3,16,5,biomesoplenty:leaves_3:11)
Block(-3,16,6,biomesoplenty:leaves_3:11)
Block(-3,16,7,biomesoplenty:leaves_3:11)
Block(-3,16,8,biomesoplenty:leaves_3:11)
Block(-3,16,9,biomesoplenty:leaves_3:11)
Block(-3,16,10,biomesoplenty:leaves_3:11)
Block(-3,16,11,biomesoplenty:leaves_3:11)
Block(-3,16,12,biomesoplenty:leaves_3:11)
Block(-3,16,13,biomesoplenty:leaves_3:11)
Block(-3,16,14,biomesoplenty:leaves_3:11)
Block(-3,17,-10,biomesoplenty:leaves_3:11)
Block(-3,17,-9,biomesoplenty:leaves_3:11)
Block(-3,17,-8,biomesoplenty:leaves_3:11)
Block(-3,17,-7,biomesoplenty:leaves_3:11)
Block(-3,17,-6,biomesoplenty:leaves_3:11)
Block(-3,17,-5,biomesoplenty:leaves_3:11)
Block(-3,17,-4,biomesoplenty:leaves_3:11)
Block(-3,17,-3,biomesoplenty:leaves_3:11)
Block(-3,17,-2,biomesoplenty:leaves_3:11)
Block(-3,17,-1,biomesoplenty:leaves_3:11)
Block(-3,17,0,biomesoplenty:leaves_3:11)
Block(-3,17,1,biomesoplenty:leaves_3:11)
Block(-3,17,3,biomesoplenty:leaves_3:11)
Block(-3,17,4,biomesoplenty:leaves_3:11)
Block(-3,17,5,biomesoplenty:leaves_3:11)
Block(-3,17,6,biomesoplenty:leaves_3:11)
Block(-3,17,7,biomesoplenty:leaves_3:11)
Block(-3,17,8,biomesoplenty:leaves_3:11)
Block(-3,17,9,biomesoplenty:leaves_3:11)
Block(-3,17,10,biomesoplenty:leaves_3:11)
Block(-3,17,11,biomesoplenty:log_0:8)
Block(-3,17,12,biomesoplenty:log_0:8)
Block(-3,17,13,biomesoplenty:leaves_3:11)
Block(-3,18,-8,biomesoplenty:leaves_3:11)
Block(-3,18,-7,biomesoplenty:leaves_3:11)
Block(-3,18,-6,biomesoplenty:leaves_3:11)
Block(-3,18,-5,biomesoplenty:leaves_3:11)
Block(-3,18,-4,biomesoplenty:log_0:8)
Block(-3,18,-3,biomesoplenty:leaves_3:11)
Block(-3,18,-2,biomesoplenty:leaves_3:11)
Block(-3,18,-1,biomesoplenty:leaves_3:11)
Block(-3,18,0,biomesoplenty:leaves_3:11)
Block(-3,18,1,biomesoplenty:leaves_3:11)
Block(-3,18,2,biomesoplenty:leaves_3:11)
Block(-3,18,3,biomesoplenty:leaves_3:11)
Block(-3,18,4,biomesoplenty:leaves_3:11)
Block(-3,18,5,biomesoplenty:leaves_3:11)
Block(-3,18,6,biomesoplenty:leaves_3:11)
Block(-3,18,7,biomesoplenty:leaves_3:11)
Block(-3,18,8,biomesoplenty:leaves_3:11)
Block(-3,18,9,biomesoplenty:leaves_3:11)
Block(-3,18,10,biomesoplenty:leaves_3:11)
Block(-3,18,11,biomesoplenty:log_0:8)
Block(-3,18,12,biomesoplenty:leaves_3:11)
Block(-3,18,13,biomesoplenty:leaves_3:11)
Block(-3,18,14,biomesoplenty:leaves_3:11)
Block(-3,19,-7,biomesoplenty:leaves_3:11)
Block(-3,19,-6,biomesoplenty:leaves_3:11)
Block(-3,19,-5,biomesoplenty:leaves_3:11)
Block(-3,19,-4,biomesoplenty:leaves_3:11)
Block(-3,19,-3,biomesoplenty:leaves_3:11)
Block(-3,19,-2,biomesoplenty:leaves_3:11)
Block(-3,19,-1,biomesoplenty:leaves_3:11)
Block(-3,19,0,biomesoplenty:leaves_3:11)
Block(-3,19,1,biomesoplenty:leaves_3:11)
Block(-3,19,2,biomesoplenty:leaves_3:11)
Block(-3,19,3,biomesoplenty:leaves_3:11)
Block(-3,19,4,biomesoplenty:leaves_3:11)
Block(-3,19,5,biomesoplenty:leaves_3:11)
Block(-3,19,6,biomesoplenty:leaves_3:11)
Block(-3,19,7,biomesoplenty:leaves_3:11)
Block(-3,19,8,biomesoplenty:leaves_3:11)
Block(-3,19,9,biomesoplenty:leaves_3:11)
Block(-3,19,10,biomesoplenty:leaves_3:11)
Block(-3,19,11,biomesoplenty:leaves_3:11)
Block(-3,19,12,biomesoplenty:leaves_3:11)
Block(-3,19,13,biomesoplenty:leaves_3:11)
Block(-3,19,14,biomesoplenty:leaves_3:11)
Block(-3,20,-7,biomesoplenty:leaves_3:11)
Block(-3,20,-6,biomesoplenty:leaves_3:11)
Block(-3,20,-5,biomesoplenty:leaves_3:11)
Block(-3,20,-4,biomesoplenty:leaves_3:11)
Block(-3,20,-3,biomesoplenty:leaves_3:11)
Block(-3,20,-2,biomesoplenty:leaves_3:11)
Block(-3,20,-1,biomesoplenty:leaves_3:11)
Block(-3,20,0,biomesoplenty:leaves_3:11)
Block(-3,20,1,biomesoplenty:leaves_3:11)
Block(-3,20,2,biomesoplenty:leaves_3:11)
Block(-3,20,3,biomesoplenty:leaves_3:11)
Block(-3,20,4,biomesoplenty:leaves_3:11)
Block(-3,20,5,biomesoplenty:leaves_3:11)
Block(-3,20,6,biomesoplenty:leaves_3:11)
Block(-3,20,7,biomesoplenty:leaves_3:11)
Block(-3,20,8,biomesoplenty:leaves_3:11)
Block(-3,20,9,biomesoplenty:leaves_3:11)
Block(-3,20,10,biomesoplenty:log_0:8)
Block(-3,20,11,biomesoplenty:leaves_3:11)
Block(-3,20,12,biomesoplenty:log_0:8)
Block(-3,20,13,biomesoplenty:leaves_3:11)
Block(-3,21,-7,biomesoplenty:leaves_3:11)
Block(-3,21,-6,biomesoplenty:leaves_3:11)
Block(-3,21,-5,biomesoplenty:leaves_3:11)
Block(-3,21,-3,biomesoplenty:leaves_3:11)
Block(-3,21,-2,biomesoplenty:leaves_3:11)
Block(-3,21,-1,biomesoplenty:leaves_3:11)
Block(-3,21,0,biomesoplenty:leaves_3:11)
Block(-3,21,1,biomesoplenty:leaves_3:11)
Block(-3,21,2,biomesoplenty:leaves_3:11)
Block(-3,21,3,biomesoplenty:leaves_3:11)
Block(-3,21,4,biomesoplenty:leaves_3:11)
Block(-3,21,5,biomesoplenty:leaves_3:11)
Block(-3,21,6,biomesoplenty:leaves_3:11)
Block(-3,21,7,biomesoplenty:leaves_3:11)
Block(-3,21,8,biomesoplenty:leaves_3:11)
Block(-3,21,9,biomesoplenty:leaves_3:11)
Block(-3,21,10,biomesoplenty:leaves_3:11)
Block(-3,21,11,biomesoplenty:leaves_3:11)
Block(-3,21,12,biomesoplenty:log_0:8)
Block(-3,21,13,biomesoplenty:log_0:8)
Block(-3,21,14,biomesoplenty:leaves_3:11)
Block(-3,21,15,biomesoplenty:leaves_3:11)
Block(-3,22,-9,biomesoplenty:leaves_3:11)
Block(-3,22,-8,biomesoplenty:leaves_3:11)
Block(-3,22,-7,biomesoplenty:leaves_3:11)
Block(-3,22,-6,biomesoplenty:leaves_3:11)
Block(-3,22,-5,biomesoplenty:leaves_3:11)
Block(-3,22,-4,biomesoplenty:leaves_3:11)
Block(-3,22,-3,biomesoplenty:leaves_3:11)
Block(-3,22,-2,biomesoplenty:leaves_3:11)
Block(-3,22,-1,biomesoplenty:leaves_3:11)
Block(-3,22,0,biomesoplenty:leaves_3:11)
Block(-3,22,1,biomesoplenty:leaves_3:11)
Block(-3,22,2,biomesoplenty:leaves_3:11)
Block(-3,22,3,biomesoplenty:leaves_3:11)
Block(-3,22,4,biomesoplenty:leaves_3:11)
Block(-3,22,5,biomesoplenty:leaves_3:11)
Block(-3,22,7,biomesoplenty:leaves_3:11)
Block(-3,22,8,biomesoplenty:leaves_3:11)
Block(-3,22,9,biomesoplenty:leaves_3:11)
Block(-3,22,10,biomesoplenty:leaves_3:11)
Block(-3,22,11,biomesoplenty:leaves_3:11)
Block(-3,22,12,biomesoplenty:leaves_3:11)
Block(-3,22,13,biomesoplenty:leaves_3:11)
Block(-3,22,14,biomesoplenty:leaves_3:11)
Block(-3,22,15,biomesoplenty:leaves_3:11)
Block(-3,22,16,biomesoplenty:leaves_3:11)
Block(-3,23,-9,biomesoplenty:leaves_3:11)
Block(-3,23,-8,biomesoplenty:leaves_3:11)
Block(-3,23,-7,biomesoplenty:leaves_3:11)
Block(-3,23,-6,biomesoplenty:log_0:8)
Block(-3,23,-5,biomesoplenty:leaves_3:11)
Block(-3,23,-4,biomesoplenty:leaves_3:11)
Block(-3,23,-3,biomesoplenty:leaves_3:11)
Block(-3,23,-2,biomesoplenty:leaves_3:11)
Block(-3,23,-1,biomesoplenty:leaves_3:11)
Block(-3,23,0,biomesoplenty:leaves_3:11)
Block(-3,23,1,biomesoplenty:leaves_3:11)
Block(-3,23,2,biomesoplenty:leaves_3:11)
Block(-3,23,3,biomesoplenty:leaves_3:11)
Block(-3,23,4,biomesoplenty:leaves_3:11)
Block(-3,23,5,biomesoplenty:leaves_3:11)
Block(-3,23,6,biomesoplenty:leaves_3:11)
Block(-3,23,7,biomesoplenty:leaves_3:11)
Block(-3,23,8,biomesoplenty:leaves_3:11)
Block(-3,23,9,biomesoplenty:leaves_3:11)
Block(-3,23,10,biomesoplenty:leaves_3:11)
Block(-3,23,11,biomesoplenty:leaves_3:11)
Block(-3,23,12,biomesoplenty:log_0:8)
Block(-3,23,13,biomesoplenty:leaves_3:11)
Block(-3,23,14,biomesoplenty:leaves_3:11)
Block(-3,23,15,biomesoplenty:leaves_3:11)
Block(-3,23,16,biomesoplenty:leaves_3:11)
Block(-3,24,-8,biomesoplenty:leaves_3:11)
Block(-3,24,-7,biomesoplenty:log_0:8)
Block(-3,24,-5,biomesoplenty:leaves_3:11)
Block(-3,24,-4,biomesoplenty:leaves_3:11)
Block(-3,24,-3,biomesoplenty:leaves_3:11)
Block(-3,24,-2,biomesoplenty:leaves_3:11)
Block(-3,24,-1,biomesoplenty:leaves_3:11)
Block(-3,24,0,biomesoplenty:leaves_3:11)
Block(-3,24,1,biomesoplenty:leaves_3:11)
Block(-3,24,3,biomesoplenty:leaves_3:11)
Block(-3,24,4,biomesoplenty:leaves_3:11)
Block(-3,24,5,biomesoplenty:leaves_3:11)
Block(-3,24,6,biomesoplenty:leaves_3:11)
Block(-3,24,7,biomesoplenty:leaves_3:11)
Block(-3,24,8,biomesoplenty:leaves_3:11)
Block(-3,24,9,biomesoplenty:leaves_3:11)
Block(-3,24,10,biomesoplenty:log_0:8)
Block(-3,24,11,biomesoplenty:log_0:8)
Block(-3,24,12,biomesoplenty:log_0:8)
Block(-3,24,13,biomesoplenty:log_0:8)
Block(-3,24,14,biomesoplenty:log_0:8)
Block(-3,24,15,biomesoplenty:leaves_3:11)
Block(-3,25,-10,biomesoplenty:leaves_3:11)
Block(-3,25,-9,biomesoplenty:leaves_3:11)
Block(-3,25,-8,biomesoplenty:leaves_3:11)
Block(-3,25,-7,biomesoplenty:leaves_3:11)
Block(-3,25,-6,biomesoplenty:leaves_3:11)
Block(-3,25,-4,biomesoplenty:leaves_3:11)
Block(-3,25,-3,biomesoplenty:leaves_3:11)
Block(-3,25,-2,biomesoplenty:leaves_3:11)
Block(-3,25,-1,biomesoplenty:leaves_3:11)
Block(-3,25,0,biomesoplenty:leaves_3:11)
Block(-3,25,1,biomesoplenty:leaves_3:11)
Block(-3,25,4,biomesoplenty:leaves_3:11)
Block(-3,25,5,biomesoplenty:leaves_3:11)
Block(-3,25,6,biomesoplenty:leaves_3:11)
Block(-3,25,7,biomesoplenty:leaves_3:11)
Block(-3,25,8,biomesoplenty:leaves_3:11)
Block(-3,25,9,biomesoplenty:leaves_3:11)
Block(-3,25,10,biomesoplenty:leaves_3:11)
Block(-3,25,11,biomesoplenty:leaves_3:11)
Block(-3,25,12,biomesoplenty:leaves_3:11)
Block(-3,25,13,biomesoplenty:log_0:8)
Block(-3,25,14,biomesoplenty:leaves_3:11)
Block(-3,25,15,biomesoplenty:leaves_3:11)
Block(-3,25,16,biomesoplenty:leaves_3:11)
Block(-3,26,-10,biomesoplenty:leaves_3:11)
Block(-3,26,-9,biomesoplenty:leaves_3:11)
Block(-3,26,-8,biomesoplenty:leaves_3:11)
Block(-3,26,-7,biomesoplenty:leaves_3:11)
Block(-3,26,-6,biomesoplenty:leaves_3:11)
Block(-3,26,-5,biomesoplenty:leaves_3:11)
Block(-3,26,-4,biomesoplenty:log_0:8)
Block(-3,26,-3,biomesoplenty:leaves_3:11)
Block(-3,26,-2,biomesoplenty:leaves_3:11)
Block(-3,26,-1,biomesoplenty:leaves_3:11)
Block(-3,26,3,biomesoplenty:leaves_3:11)
Block(-3,26,5,biomesoplenty:leaves_3:11)
Block(-3,26,6,biomesoplenty:leaves_3:11)
Block(-3,26,7,biomesoplenty:leaves_3:11)
Block(-3,26,9,biomesoplenty:leaves_3:11)
Block(-3,26,10,biomesoplenty:leaves_3:11)
Block(-3,26,11,biomesoplenty:leaves_3:11)
Block(-3,26,12,biomesoplenty:leaves_3:11)
Block(-3,26,13,biomesoplenty:leaves_3:11)
Block(-3,26,14,biomesoplenty:leaves_3:11)
Block(-3,26,15,biomesoplenty:leaves_3:11)
Block(-3,26,16,biomesoplenty:leaves_3:11)
Block(-3,27,-8,biomesoplenty:leaves_3:11)
Block(-3,27,-6,biomesoplenty:leaves_3:11)
Block(-3,27,-5,biomesoplenty:leaves_3:11)
Block(-3,27,-4,biomesoplenty:leaves_3:11)
Block(-3,27,-3,biomesoplenty:leaves_3:11)
Block(-3,27,-2,biomesoplenty:leaves_3:11)
Block(-3,27,-1,biomesoplenty:leaves_3:11)
Block(-3,27,1,biomesoplenty:leaves_3:11)
Block(-3,27,2,biomesoplenty:leaves_3:11)
Block(-3,27,3,biomesoplenty:leaves_3:11)
Block(-3,27,4,biomesoplenty:leaves_3:11)
Block(-3,27,5,biomesoplenty:leaves_3:11)
Block(-3,27,6,biomesoplenty:leaves_3:11)
Block(-3,27,7,biomesoplenty:leaves_3:11)
Block(-3,27,8,biomesoplenty:leaves_3:11)
Block(-3,27,9,biomesoplenty:leaves_3:11)
Block(-3,27,10,biomesoplenty:leaves_3:11)
Block(-3,27,11,biomesoplenty:leaves_3:11)
Block(-3,27,12,biomesoplenty:leaves_3:11)
Block(-3,27,13,biomesoplenty:leaves_3:11)
Block(-3,27,14,biomesoplenty:leaves_3:11)
Block(-3,27,15,biomesoplenty:leaves_3:11)
Block(-3,27,16,biomesoplenty:leaves_3:11)
Block(-3,28,-6,biomesoplenty:leaves_3:11)
Block(-3,28,-5,biomesoplenty:leaves_3:11)
Block(-3,28,-4,biomesoplenty:leaves_3:11)
Block(-3,28,-3,biomesoplenty:leaves_3:11)
Block(-3,28,-2,biomesoplenty:leaves_3:11)
Block(-3,28,-1,biomesoplenty:leaves_3:11)
Block(-3,28,1,biomesoplenty:leaves_3:11)
Block(-3,28,2,biomesoplenty:leaves_3:11)
Block(-3,28,3,biomesoplenty:leaves_3:11)
Block(-3,28,4,biomesoplenty:leaves_3:11)
Block(-3,28,5,biomesoplenty:leaves_3:11)
Block(-3,28,6,biomesoplenty:leaves_3:11)
Block(-3,28,7,biomesoplenty:leaves_3:11)
Block(-3,28,8,biomesoplenty:leaves_3:11)
Block(-3,28,10,biomesoplenty:leaves_3:11)
Block(-3,28,11,biomesoplenty:leaves_3:11)
Block(-3,28,12,biomesoplenty:leaves_3:11)
Block(-3,28,13,biomesoplenty:leaves_3:11)
Block(-3,28,14,biomesoplenty:leaves_3:11)
Block(-3,29,-5,biomesoplenty:leaves_3:11)
Block(-3,29,-4,biomesoplenty:leaves_3:11)
Block(-3,29,-3,biomesoplenty:leaves_3:11)
Block(-3,29,-2,biomesoplenty:leaves_3:11)
Block(-3,29,-1,biomesoplenty:leaves_3:11)
Block(-3,29,2,biomesoplenty:leaves_3:11)
Block(-3,29,3,biomesoplenty:leaves_3:11)
Block(-3,29,4,biomesoplenty:leaves_3:11)
Block(-3,29,5,biomesoplenty:leaves_3:11)
Block(-3,29,6,biomesoplenty:leaves_3:11)
Block(-3,29,7,biomesoplenty:leaves_3:11)
Block(-3,29,8,biomesoplenty:leaves_3:11)
Block(-3,29,9,biomesoplenty:leaves_3:11)
Block(-3,29,10,biomesoplenty:leaves_3:11)
Block(-3,29,11,biomesoplenty:leaves_3:11)
Block(-3,29,12,biomesoplenty:leaves_3:11)
Block(-3,29,13,biomesoplenty:leaves_3:11)
Block(-3,29,14,biomesoplenty:leaves_3:11)
Block(-3,30,-8,biomesoplenty:leaves_3:11)
Block(-3,30,-7,biomesoplenty:leaves_3:11)
Block(-3,30,-6,biomesoplenty:leaves_3:11)
Block(-3,30,-4,biomesoplenty:leaves_3:11)
Block(-3,30,-3,biomesoplenty:leaves_3:11)
Block(-3,30,-2,biomesoplenty:leaves_3:11)
Block(-3,30,0,biomesoplenty:leaves_3:11)
Block(-3,30,2,biomesoplenty:leaves_3:11)
