
#######################################################################
# +-----------------------------------------------------------------+ #
# |                            BO3 object                           | #
# +-----------------------------------------------------------------+ #
#######################################################################

# This is the config file of a custom object.
# If you add this object correctly to your BiomeConfigs, it will spawn in the world.

# This is the creator of this BO3 object
Author: Unknown

# A short description of this BO3 object
Description: No description given

# The BO3 version, don't change this! It can be used by external applications to do a version check.
Version: 3

# The settings mode, WriteAll, WriteWithoutComments or WriteDisable. See WorldConfig.
SettingsMode: WriteDisable


#######################################################################
# +-----------------------------------------------------------------+ #
# |                          Main settings                          | #
# +-----------------------------------------------------------------+ #
#######################################################################

# This needs to be set to true to spawn the object in the Tree and Sapling resources.
Tree: true

# The frequency of the BO3 from 1 to 200. Tries this many times to spawn this BO3 when using the CustomObject(...) resource.
# Ignored by Tree(..), Sapling(..) and CustomStructure(..)
Frequency: 1

# The rarity of the BO3 from 0 to 100. Each spawn attempt has rarity% chance to succeed when using the CustomObject(...) resource.
# Ignored by Tree(..), Sapling(..) and CustomStructure(..)
Rarity: 10.0

# If you set this to true, the BO3 will be placed with a random rotation.
RotateRandomly: true

# The spawn height of the BO3: randomY, highestBlock or highestSolidBlock.
SpawnHeight: highestSolidBlock

# The offset from the spawn height to spawn this BO3
# Ex. SpawnHeight = highestSolidBlock, SpawnHeightOffset = 3; This object will spawn 3 blocks above the highest solid block
SpawnHeightOffset: 0

# A random amount to offset the spawn location from the spawn offset height
# Ex. SpawnHeightOffset = 3, SpawnHeightVariance = 3; This object will spawn 3 to 6 blocks above the original spot it would have spawned
SpawnHeightVariance: 0

##############################
# Height Limits for the BO3. #
##############################

# When in randomY mode used as the minimum Y or in atMinY mode as the actual Y to spawn this BO3 at.
MinHeight: 60

# When in randomY mode used as the maximum Y to spawn this BO3 at.
MaxHeight: 140

######################
# Extrusion settings #
######################

# The style of extrusion you wish to use - BottomDown, TopUp, None (Default)
ExtrudeMode: BottomDown

# The blocks to extrude your BO3 through
ExtrudeThroughBlocks: AIR

# Objects can have other objects attacthed to it: branches. Branches can also
# have branches attached to it, which can also have branches, etc. This is the
# maximum branch depth for this objects.
MaxBranchDepth: 10

# When spawned with the UseWorld keyword, this BO3 should NOT spawn in the following biomes.
# If you write the BO3 name directly in the BiomeConfigs, this will be ignored.
ExcludedBiomes: All


#######################################################################
# +-----------------------------------------------------------------+ #
# |                      Source block settings                      | #
# +-----------------------------------------------------------------+ #
#######################################################################

# The block(s) the BO3 should spawn in.
SourceBlocks: AIR

# The maximum percentage of the BO3 that can be outside the SourceBlock.
# The BO3 won't be placed on a location with more blocks outside the SourceBlock than this percentage.
MaxPercentageOutsideSourceBlock: 100

# What to do when a block is about to be placed outside the SourceBlock? (dontPlace, placeAnyway)
OutsideSourceBlock: placeAnyway

# OTG+ settings #
# Legacy setting, rename this file to .BO4 instead. Set this to true to enable the advanced customstructure features of OTG+.
IsOTGPlus: false


#######################################################################
# +-----------------------------------------------------------------+ #
# |                              Blocks                             | #
# +-----------------------------------------------------------------+ #
#######################################################################

# All the blocks used in the BO3 are listed here. Possible blocks:
# Block(x,y,z,id[.data][,nbtfile.nbt)
# RandomBlock(x,y,z,id[:data][,nbtfile.nbt],chance[,id[:data][,nbtfile.nbt],chance[,...]])
#  So RandomBlock(0,0,0,CHEST,chest.nbt,50,CHEST,anotherchest.nbt,100) will spawn a chest at
#  the BO3 origin, and give it a 50% chance to have the contents of chest.nbt, or, if that
#  fails, a 100% percent chance to have the contents of anotherchest.nbt.
# *Note: Unlike Entity() and Spawner(), for Block() .txt files don't work, only .nbt files work.
# MinecraftObject(x,y,z,name) (TODO: This may not work anymore and needs to be tested.
#  Spawns an object in the Mojang NBT structure format. For example, 
#  MinecraftObject(0,0,0,minecraft:igloo/igloo_bottom)
#  spawns the bottom part of an igloo.
Block(-15,0,1,HARD_CLAY)
Block(-15,0,2,HARD_CLAY)
Block(-15,0,3,HARD_CLAY)
Block(-15,0,4,HARD_CLAY)
Block(-15,1,2,HARD_CLAY)
Block(-15,2,2,HARD_CLAY)
Block(-15,3,2,HARD_CLAY)
Block(-14,0,2,HARD_CLAY)
Block(-14,0,3,HARD_CLAY)
Block(-14,0,4,HARD_CLAY)
Block(-14,1,2,HARD_CLAY)
Block(-14,1,3,HARD_CLAY)
Block(-14,1,4,HARD_CLAY)
Block(-14,2,2,HARD_CLAY)
Block(-14,2,3,HARD_CLAY)
Block(-14,2,4,HARD_CLAY)
Block(-14,3,3,HARD_CLAY)
Block(-14,4,3,HARD_CLAY)
Block(-14,5,3,HARD_CLAY)
Block(-14,6,3,HARD_CLAY)
Block(-14,7,3,HARD_CLAY)
Block(-14,8,3,HARD_CLAY)
Block(-13,0,0,HARD_CLAY)
Block(-13,0,1,HARD_CLAY)
Block(-13,0,2,HARD_CLAY)
Block(-13,0,3,HARD_CLAY)
Block(-13,0,4,HARD_CLAY)
Block(-13,0,5,HARD_CLAY)
Block(-13,0,6,HARD_CLAY)
Block(-13,0,7,HARD_CLAY)
Block(-13,0,8,HARD_CLAY)
Block(-13,1,1,HARD_CLAY)
Block(-13,1,2,HARD_CLAY)
Block(-13,1,3,HARD_CLAY)
Block(-13,1,4,HARD_CLAY)
Block(-13,1,5,HARD_CLAY)
Block(-13,2,1,HARD_CLAY)
Block(-13,2,2,HARD_CLAY)
Block(-13,2,3,HARD_CLAY)
Block(-13,2,4,HARD_CLAY)
Block(-13,3,2,HARD_CLAY)
Block(-13,3,3,HARD_CLAY)
Block(-13,4,2,HARD_CLAY)
Block(-13,4,3,HARD_CLAY)
Block(-13,5,2,HARD_CLAY)
Block(-13,5,3,HARD_CLAY)
Block(-13,6,2,HARD_CLAY)
Block(-13,6,3,HARD_CLAY)
Block(-13,7,3,HARD_CLAY)
Block(-13,8,3,HARD_CLAY)
Block(-13,9,3,HARD_CLAY)
Block(-13,10,3,HARD_CLAY)
Block(-13,11,3,HARD_CLAY)
Block(-13,12,3,HARD_CLAY)
Block(-12,0,-1,HARD_CLAY)
Block(-12,0,0,HARD_CLAY)
Block(-12,0,1,HARD_CLAY)
Block(-12,0,2,HARD_CLAY)
Block(-12,0,3,HARD_CLAY)
Block(-12,0,4,HARD_CLAY)
Block(-12,0,5,HARD_CLAY)
Block(-12,0,6,HARD_CLAY)
Block(-12,0,7,HARD_CLAY)
Block(-12,0,8,HARD_CLAY)
Block(-12,1,0,HARD_CLAY)
Block(-12,1,1,HARD_CLAY)
Block(-12,1,2,HARD_CLAY)
Block(-12,1,3,HARD_CLAY)
Block(-12,1,4,HARD_CLAY)
Block(-12,1,5,HARD_CLAY)
Block(-12,1,6,HARD_CLAY)
Block(-12,1,7,HARD_CLAY)
Block(-12,1,8,HARD_CLAY)
Block(-12,2,1,HARD_CLAY)
Block(-12,2,2,HARD_CLAY)
Block(-12,2,3,HARD_CLAY)
Block(-12,2,4,HARD_CLAY)
Block(-12,2,5,HARD_CLAY)
Block(-12,2,6,HARD_CLAY)
Block(-12,2,7,HARD_CLAY)
Block(-12,3,1,HARD_CLAY)
Block(-12,3,2,HARD_CLAY)
Block(-12,3,3,HARD_CLAY)
Block(-12,3,4,HARD_CLAY)
Block(-12,3,5,HARD_CLAY)
Block(-12,3,6,HARD_CLAY)
Block(-12,4,2,HARD_CLAY)
Block(-12,4,3,HARD_CLAY)
Block(-12,4,4,HARD_CLAY)
Block(-12,4,5,HARD_CLAY)
Block(-12,5,2,HARD_CLAY)
Block(-12,5,3,HARD_CLAY)
Block(-12,5,4,HARD_CLAY)
Block(-12,5,5,HARD_CLAY)
Block(-12,6,2,HARD_CLAY)
Block(-12,6,3,HARD_CLAY)
Block(-12,6,4,HARD_CLAY)
Block(-12,7,2,HARD_CLAY)
Block(-12,7,3,HARD_CLAY)
Block(-12,8,2,HARD_CLAY)
Block(-12,8,3,HARD_CLAY)
Block(-12,9,2,HARD_CLAY)
Block(-12,9,3,HARD_CLAY)
Block(-12,10,2,HARD_CLAY)
Block(-12,10,3,HARD_CLAY)
Block(-12,11,2,HARD_CLAY)
Block(-12,11,3,HARD_CLAY)
Block(-12,12,3,HARD_CLAY)
Block(-11,0,-9,HARD_CLAY)
Block(-11,0,-1,HARD_CLAY)
Block(-11,0,0,HARD_CLAY)
Block(-11,0,1,HARD_CLAY)
Block(-11,0,2,HARD_CLAY)
Block(-11,0,3,HARD_CLAY)
Block(-11,0,4,HARD_CLAY)
Block(-11,0,5,HARD_CLAY)
Block(-11,0,6,HARD_CLAY)
Block(-11,0,7,HARD_CLAY)
Block(-11,0,8,HARD_CLAY)
Block(-11,0,9,HARD_CLAY)
Block(-11,0,10,HARD_CLAY)
Block(-11,0,11,HARD_CLAY)
Block(-11,0,12,HARD_CLAY)
Block(-11,0,13,HARD_CLAY)
Block(-11,1,-1,HARD_CLAY)
Block(-11,1,0,HARD_CLAY)
Block(-11,1,1,HARD_CLAY)
Block(-11,1,2,HARD_CLAY)
Block(-11,1,3,HARD_CLAY)
Block(-11,1,4,HARD_CLAY)
Block(-11,1,5,HARD_CLAY)
Block(-11,1,6,HARD_CLAY)
Block(-11,1,7,HARD_CLAY)
Block(-11,1,8,HARD_CLAY)
Block(-11,1,9,HARD_CLAY)
Block(-11,2,-1,HARD_CLAY)
Block(-11,2,0,HARD_CLAY)
Block(-11,2,1,HARD_CLAY)
Block(-11,2,2,HARD_CLAY)
Block(-11,2,3,HARD_CLAY)
Block(-11,2,4,HARD_CLAY)
Block(-11,2,5,HARD_CLAY)
Block(-11,2,6,HARD_CLAY)
Block(-11,2,7,HARD_CLAY)
Block(-11,2,8,HARD_CLAY)
Block(-11,2,9,HARD_CLAY)
Block(-11,3,0,HARD_CLAY)
Block(-11,3,1,HARD_CLAY)
Block(-11,3,2,HARD_CLAY)
Block(-11,3,3,HARD_CLAY)
Block(-11,3,4,HARD_CLAY)
Block(-11,3,5,HARD_CLAY)
Block(-11,3,6,HARD_CLAY)
Block(-11,3,7,HARD_CLAY)
Block(-11,3,8,HARD_CLAY)
Block(-11,4,2,HARD_CLAY)
Block(-11,4,3,HARD_CLAY)
Block(-11,4,4,HARD_CLAY)
Block(-11,4,5,HARD_CLAY)
Block(-11,4,6,HARD_CLAY)
Block(-11,4,7,HARD_CLAY)
Block(-11,5,2,HARD_CLAY)
Block(-11,5,3,HARD_CLAY)
Block(-11,5,4,HARD_CLAY)
Block(-11,5,5,HARD_CLAY)
Block(-11,5,6,HARD_CLAY)
Block(-11,5,7,HARD_CLAY)
Block(-11,6,2,HARD_CLAY)
Block(-11,6,3,HARD_CLAY)
Block(-11,6,4,HARD_CLAY)
Block(-11,6,5,HARD_CLAY)
Block(-11,6,6,HARD_CLAY)
Block(-11,7,2,HARD_CLAY)
Block(-11,7,3,HARD_CLAY)
Block(-11,7,4,HARD_CLAY)
Block(-11,7,5,HARD_CLAY)
Block(-11,7,6,HARD_CLAY)
Block(-11,8,3,HARD_CLAY)
Block(-11,8,4,HARD_CLAY)
Block(-11,8,5,HARD_CLAY)
Block(-11,8,6,HARD_CLAY)
Block(-11,9,3,HARD_CLAY)
Block(-11,9,4,HARD_CLAY)
Block(-11,9,5,HARD_CLAY)
Block(-11,9,6,HARD_CLAY)
Block(-11,10,3,HARD_CLAY)
Block(-11,10,4,HARD_CLAY)
Block(-11,10,5,HARD_CLAY)
Block(-11,10,6,HARD_CLAY)
Block(-11,11,3,HARD_CLAY)
Block(-11,11,4,HARD_CLAY)
Block(-11,11,5,HARD_CLAY)
Block(-11,11,6,HARD_CLAY)
Block(-11,12,3,HARD_CLAY)
Block(-11,12,4,HARD_CLAY)
Block(-11,12,5,HARD_CLAY)
Block(-11,13,4,HARD_CLAY)
Block(-11,13,5,HARD_CLAY)
Block(-11,14,5,HARD_CLAY)
Block(-11,15,5,HARD_CLAY)
Block(-10,0,-10,HARD_CLAY)
Block(-10,0,-9,HARD_CLAY)
Block(-10,0,-8,HARD_CLAY)
Block(-10,0,-7,HARD_CLAY)
Block(-10,0,-4,HARD_CLAY)
Block(-10,0,-3,HARD_CLAY)
Block(-10,0,-2,HARD_CLAY)
Block(-10,0,-1,HARD_CLAY)
Block(-10,0,0,HARD_CLAY)
Block(-10,0,1,HARD_CLAY)
Block(-10,0,2,HARD_CLAY)
Block(-10,0,3,HARD_CLAY)
Block(-10,0,4,HARD_CLAY)
Block(-10,0,5,HARD_CLAY)
Block(-10,0,6,HARD_CLAY)
Block(-10,0,7,HARD_CLAY)
Block(-10,0,8,HARD_CLAY)
Block(-10,0,9,HARD_CLAY)
Block(-10,0,10,HARD_CLAY)
Block(-10,0,11,HARD_CLAY)
Block(-10,0,12,HARD_CLAY)
Block(-10,0,13,HARD_CLAY)
Block(-10,1,-9,HARD_CLAY)
Block(-10,1,-8,HARD_CLAY)
Block(-10,1,-3,HARD_CLAY)
Block(-10,1,-2,HARD_CLAY)
Block(-10,1,-1,HARD_CLAY)
Block(-10,1,0,HARD_CLAY)
Block(-10,1,1,HARD_CLAY)
Block(-10,1,2,HARD_CLAY)
Block(-10,1,3,HARD_CLAY)
Block(-10,1,4,HARD_CLAY)
Block(-10,1,5,HARD_CLAY)
Block(-10,1,6,HARD_CLAY)
Block(-10,1,7,HARD_CLAY)
Block(-10,1,8,HARD_CLAY)
Block(-10,1,9,HARD_CLAY)
Block(-10,1,10,HARD_CLAY)
Block(-10,1,12,HARD_CLAY)
Block(-10,1,13,HARD_CLAY)
Block(-10,2,-2,HARD_CLAY)
Block(-10,2,-1,HARD_CLAY)
Block(-10,2,0,HARD_CLAY)
Block(-10,2,1,HARD_CLAY)
Block(-10,2,2,HARD_CLAY)
Block(-10,2,3,HARD_CLAY)
Block(-10,2,4,HARD_CLAY)
Block(-10,2,5,HARD_CLAY)
Block(-10,2,6,HARD_CLAY)
Block(-10,2,7,HARD_CLAY)
Block(-10,2,8,HARD_CLAY)
Block(-10,2,9,HARD_CLAY)
Block(-10,3,-1,HARD_CLAY)
Block(-10,3,0,HARD_CLAY)
Block(-10,3,1,HARD_CLAY)
Block(-10,3,2,HARD_CLAY)
Block(-10,3,3,HARD_CLAY)
Block(-10,3,4,HARD_CLAY)
Block(-10,3,5,HARD_CLAY)
Block(-10,3,6,HARD_CLAY)
Block(-10,3,7,HARD_CLAY)
Block(-10,3,8,HARD_CLAY)
Block(-10,3,9,HARD_CLAY)
Block(-10,4,-1,HARD_CLAY)
Block(-10,4,0,HARD_CLAY)
Block(-10,4,1,HARD_CLAY)
Block(-10,4,2,HARD_CLAY)
Block(-10,4,3,HARD_CLAY)
Block(-10,4,4,HARD_CLAY)
Block(-10,4,5,HARD_CLAY)
Block(-10,4,6,HARD_CLAY)
Block(-10,4,7,HARD_CLAY)
Block(-10,5,-1,HARD_CLAY)
Block(-10,5,0,HARD_CLAY)
Block(-10,5,1,HARD_CLAY)
Block(-10,5,2,HARD_CLAY)
Block(-10,5,3,HARD_CLAY)
Block(-10,5,4,HARD_CLAY)
Block(-10,5,5,HARD_CLAY)
Block(-10,5,6,HARD_CLAY)
Block(-10,5,7,HARD_CLAY)
Block(-10,6,0,HARD_CLAY)
Block(-10,6,1,HARD_CLAY)
Block(-10,6,2,HARD_CLAY)
Block(-10,6,3,HARD_CLAY)
Block(-10,6,4,HARD_CLAY)
Block(-10,6,5,HARD_CLAY)
Block(-10,6,6,HARD_CLAY)
Block(-10,7,1,HARD_CLAY)
Block(-10,7,2,HARD_CLAY)
Block(-10,7,3,HARD_CLAY)
Block(-10,7,4,HARD_CLAY)
Block(-10,7,5,HARD_CLAY)
Block(-10,7,6,HARD_CLAY)
Block(-10,8,3,HARD_CLAY)
Block(-10,8,4,HARD_CLAY)
Block(-10,8,5,HARD_CLAY)
Block(-10,8,6,HARD_CLAY)
Block(-10,9,3,HARD_CLAY)
Block(-10,9,4,HARD_CLAY)
Block(-10,9,5,HARD_CLAY)
Block(-10,9,6,HARD_CLAY)
Block(-10,10,3,HARD_CLAY)
Block(-10,10,4,HARD_CLAY)
Block(-10,10,5,HARD_CLAY)
Block(-10,10,6,HARD_CLAY)
Block(-10,11,3,HARD_CLAY)
Block(-10,11,4,HARD_CLAY)
Block(-10,11,5,HARD_CLAY)
Block(-10,11,6,HARD_CLAY)
Block(-10,12,3,HARD_CLAY)
Block(-10,12,4,HARD_CLAY)
Block(-10,12,5,HARD_CLAY)
Block(-10,12,6,HARD_CLAY)
Block(-10,13,4,HARD_CLAY)
Block(-10,13,5,HARD_CLAY)
Block(-10,13,6,HARD_CLAY)
Block(-10,14,4,HARD_CLAY)
Block(-10,14,5,HARD_CLAY)
Block(-10,14,6,HARD_CLAY)
Block(-10,15,4,HARD_CLAY)
Block(-10,15,5,HARD_CLAY)
Block(-10,15,6,HARD_CLAY)
Block(-10,16,4,HARD_CLAY)
Block(-10,16,5,HARD_CLAY)
Block(-10,16,6,HARD_CLAY)
Block(-10,17,5,HARD_CLAY)
Block(-10,18,5,HARD_CLAY)
Block(-10,19,5,HARD_CLAY)
Block(-10,20,5,HARD_CLAY)
Block(-10,21,5,HARD_CLAY)
Block(-10,22,5,HARD_CLAY)
Block(-9,0,-11,HARD_CLAY)
Block(-9,0,-10,HARD_CLAY)
Block(-9,0,-9,HARD_CLAY)
Block(-9,0,-8,HARD_CLAY)
Block(-9,0,-7,HARD_CLAY)
Block(-9,0,-6,HARD_CLAY)
Block(-9,0,-5,HARD_CLAY)
Block(-9,0,-4,HARD_CLAY)
Block(-9,0,-3,HARD_CLAY)
Block(-9,0,-2,HARD_CLAY)
Block(-9,0,-1,HARD_CLAY)
Block(-9,0,0,HARD_CLAY)
Block(-9,0,1,HARD_CLAY)
Block(-9,0,2,HARD_CLAY)
Block(-9,0,3,HARD_CLAY)
Block(-9,0,4,HARD_CLAY)
Block(-9,0,5,HARD_CLAY)
Block(-9,0,6,HARD_CLAY)
Block(-9,0,7,HARD_CLAY)
Block(-9,0,8,HARD_CLAY)
Block(-9,0,9,HARD_CLAY)
Block(-9,0,10,HARD_CLAY)
Block(-9,0,11,HARD_CLAY)
Block(-9,0,12,HARD_CLAY)
Block(-9,0,13,HARD_CLAY)
Block(-9,0,14,HARD_CLAY)
Block(-9,1,-11,HARD_CLAY)
Block(-9,1,-10,HARD_CLAY)
Block(-9,1,-9,HARD_CLAY)
Block(-9,1,-8,HARD_CLAY)
Block(-9,1,-7,HARD_CLAY)
Block(-9,1,-6,HARD_CLAY)
Block(-9,1,-5,HARD_CLAY)
Block(-9,1,-4,HARD_CLAY)
Block(-9,1,-3,HARD_CLAY)
Block(-9,1,-2,HARD_CLAY)
Block(-9,1,-1,HARD_CLAY)
Block(-9,1,0,HARD_CLAY)
Block(-9,1,1,HARD_CLAY)
Block(-9,1,2,HARD_CLAY)
Block(-9,1,3,HARD_CLAY)
Block(-9,1,4,HARD_CLAY)
Block(-9,1,5,HARD_CLAY)
Block(-9,1,6,HARD_CLAY)
Block(-9,1,7,HARD_CLAY)
Block(-9,1,8,HARD_CLAY)
Block(-9,1,9,HARD_CLAY)
Block(-9,1,10,HARD_CLAY)
Block(-9,1,12,HARD_CLAY)
Block(-9,1,13,HARD_CLAY)
Block(-9,2,-11,HARD_CLAY)
Block(-9,2,-10,HARD_CLAY)
Block(-9,2,-9,HARD_CLAY)
Block(-9,2,-8,HARD_CLAY)
Block(-9,2,-7,HARD_CLAY)
Block(-9,2,-6,HARD_CLAY)
Block(-9,2,-5,HARD_CLAY)
Block(-9,2,-4,HARD_CLAY)
Block(-9,2,-3,HARD_CLAY)
Block(-9,2,-2,HARD_CLAY)
Block(-9,2,-1,HARD_CLAY)
Block(-9,2,0,HARD_CLAY)
Block(-9,2,1,HARD_CLAY)
Block(-9,2,2,HARD_CLAY)
Block(-9,2,3,HARD_CLAY)
Block(-9,2,4,HARD_CLAY)
Block(-9,2,5,HARD_CLAY)
Block(-9,2,6,HARD_CLAY)
Block(-9,2,7,HARD_CLAY)
Block(-9,2,8,HARD_CLAY)
Block(-9,3,-10,HARD_CLAY)
Block(-9,3,-9,HARD_CLAY)
Block(-9,3,-8,HARD_CLAY)
Block(-9,3,-7,HARD_CLAY)
Block(-9,3,-5,HARD_CLAY)
Block(-9,3,-4,HARD_CLAY)
Block(-9,3,-3,HARD_CLAY)
Block(-9,3,-2,HARD_CLAY)
Block(-9,3,-1,HARD_CLAY)
Block(-9,3,0,HARD_CLAY)
Block(-9,3,1,HARD_CLAY)
Block(-9,3,2,HARD_CLAY)
Block(-9,3,3,HARD_CLAY)
Block(-9,3,4,HARD_CLAY)
Block(-9,3,5,HARD_CLAY)
Block(-9,3,6,HARD_CLAY)
Block(-9,3,7,HARD_CLAY)
Block(-9,4,-8,HARD_CLAY)
Block(-9,4,-7,HARD_CLAY)
Block(-9,4,-5,HARD_CLAY)
Block(-9,4,-4,HARD_CLAY)
Block(-9,4,-2,HARD_CLAY)
Block(-9,4,-1,HARD_CLAY)
Block(-9,4,0,HARD_CLAY)
Block(-9,4,1,HARD_CLAY)
Block(-9,4,2,HARD_CLAY)
Block(-9,4,3,HARD_CLAY)
Block(-9,4,4,HARD_CLAY)
Block(-9,4,5,HARD_CLAY)
Block(-9,4,6,HARD_CLAY)
Block(-9,4,7,HARD_CLAY)
Block(-9,5,-8,HARD_CLAY)
Block(-9,5,-7,HARD_CLAY)
Block(-9,5,-5,HARD_CLAY)
Block(-9,5,-4,HARD_CLAY)
Block(-9,5,-1,HARD_CLAY)
Block(-9,5,0,HARD_CLAY)
Block(-9,5,1,HARD_CLAY)
Block(-9,5,2,HARD_CLAY)
Block(-9,5,3,HARD_CLAY)
Block(-9,5,4,HARD_CLAY)
Block(-9,5,5,HARD_CLAY)
Block(-9,5,6,HARD_CLAY)
Block(-9,5,7,HARD_CLAY)
Block(-9,6,-8,HARD_CLAY)
Block(-9,6,-1,HARD_CLAY)
Block(-9,6,0,HARD_CLAY)
Block(-9,6,1,HARD_CLAY)
Block(-9,6,2,HARD_CLAY)
Block(-9,6,3,HARD_CLAY)
Block(-9,6,4,HARD_CLAY)
Block(-9,6,5,HARD_CLAY)
Block(-9,6,6,HARD_CLAY)
Block(-9,6,7,HARD_CLAY)
Block(-9,7,-8,HARD_CLAY)
Block(-9,7,-1,HARD_CLAY)
Block(-9,7,0,HARD_CLAY)
Block(-9,7,1,HARD_CLAY)
Block(-9,7,2,HARD_CLAY)
Block(-9,7,3,HARD_CLAY)
Block(-9,7,4,HARD_CLAY)
Block(-9,7,5,HARD_CLAY)
Block(-9,7,6,HARD_CLAY)
Block(-9,7,7,HARD_CLAY)
Block(-9,8,-8,HARD_CLAY)
Block(-9,8,-1,HARD_CLAY)
Block(-9,8,0,HARD_CLAY)
Block(-9,8,1,HARD_CLAY)
Block(-9,8,2,HARD_CLAY)
Block(-9,8,3,HARD_CLAY)
Block(-9,8,4,HARD_CLAY)
Block(-9,8,5,HARD_CLAY)
Block(-9,8,6,HARD_CLAY)
Block(-9,9,-8,HARD_CLAY)
Block(-9,9,-1,HARD_CLAY)
Block(-9,9,0,HARD_CLAY)
Block(-9,9,1,HARD_CLAY)
Block(-9,9,2,HARD_CLAY)
Block(-9,9,3,HARD_CLAY)
Block(-9,9,4,HARD_CLAY)
Block(-9,9,5,HARD_CLAY)
Block(-9,9,6,HARD_CLAY)
Block(-9,10,0,HARD_CLAY)
Block(-9,10,1,HARD_CLAY)
Block(-9,10,2,HARD_CLAY)
Block(-9,10,3,HARD_CLAY)
Block(-9,10,4,HARD_CLAY)
Block(-9,10,5,HARD_CLAY)
Block(-9,10,6,HARD_CLAY)
Block(-9,11,0,HARD_CLAY)
Block(-9,11,1,HARD_CLAY)
Block(-9,11,2,HARD_CLAY)
Block(-9,11,3,HARD_CLAY)
Block(-9,11,4,HARD_CLAY)
Block(-9,11,5,HARD_CLAY)
Block(-9,11,6,HARD_CLAY)
Block(-9,12,0,HARD_CLAY)
Block(-9,12,1,HARD_CLAY)
Block(-9,12,2,HARD_CLAY)
Block(-9,12,3,HARD_CLAY)
Block(-9,12,4,HARD_CLAY)
Block(-9,12,5,HARD_CLAY)
Block(-9,12,6,HARD_CLAY)
Block(-9,13,0,HARD_CLAY)
Block(-9,13,1,HARD_CLAY)
Block(-9,13,2,HARD_CLAY)
Block(-9,13,3,HARD_CLAY)
Block(-9,13,4,HARD_CLAY)
Block(-9,13,5,HARD_CLAY)
Block(-9,13,6,HARD_CLAY)
Block(-9,14,0,HARD_CLAY)
Block(-9,14,1,HARD_CLAY)
Block(-9,14,2,HARD_CLAY)
Block(-9,14,3,HARD_CLAY)
Block(-9,14,4,HARD_CLAY)
Block(-9,14,5,HARD_CLAY)
Block(-9,14,6,HARD_CLAY)
Block(-9,15,0,HARD_CLAY)
Block(-9,15,1,HARD_CLAY)
Block(-9,15,2,HARD_CLAY)
Block(-9,15,3,HARD_CLAY)
Block(-9,15,4,HARD_CLAY)
Block(-9,15,5,HARD_CLAY)
Block(-9,15,6,HARD_CLAY)
Block(-9,16,0,HARD_CLAY)
Block(-9,16,1,HARD_CLAY)
Block(-9,16,2,HARD_CLAY)
Block(-9,16,3,HARD_CLAY)
Block(-9,16,4,HARD_CLAY)
Block(-9,16,5,HARD_CLAY)
Block(-9,16,6,HARD_CLAY)
Block(-9,17,0,HARD_CLAY)
Block(-9,17,1,HARD_CLAY)
Block(-9,17,2,HARD_CLAY)
Block(-9,17,3,HARD_CLAY)
Block(-9,17,4,HARD_CLAY)
Block(-9,17,5,HARD_CLAY)
Block(-9,17,6,HARD_CLAY)
Block(-9,18,1,HARD_CLAY)
Block(-9,18,2,HARD_CLAY)
Block(-9,18,3,HARD_CLAY)
Block(-9,18,4,HARD_CLAY)
Block(-9,18,5,HARD_CLAY)
Block(-9,18,6,HARD_CLAY)
Block(-9,19,2,HARD_CLAY)
Block(-9,19,3,HARD_CLAY)
Block(-9,19,4,HARD_CLAY)
Block(-9,19,5,HARD_CLAY)
Block(-9,19,6,HARD_CLAY)
Block(-9,20,4,HARD_CLAY)
Block(-9,20,5,HARD_CLAY)
Block(-9,20,6,HARD_CLAY)
Block(-9,21,4,HARD_CLAY)
Block(-9,21,5,HARD_CLAY)
Block(-9,22,4,HARD_CLAY)
Block(-9,22,5,HARD_CLAY)
Block(-9,23,4,HARD_CLAY)
Block(-9,23,5,HARD_CLAY)
Block(-9,24,5,HARD_CLAY)
Block(-9,25,5,HARD_CLAY)
Block(-8,0,-14,HARD_CLAY)
Block(-8,0,-13,HARD_CLAY)
Block(-8,0,-12,HARD_CLAY)
Block(-8,0,-11,HARD_CLAY)
Block(-8,0,-10,HARD_CLAY)
Block(-8,0,-9,HARD_CLAY)
Block(-8,0,-8,HARD_CLAY)
Block(-8,0,-7,HARD_CLAY)
Block(-8,0,-6,HARD_CLAY)
Block(-8,0,-5,HARD_CLAY)
Block(-8,0,-4,HARD_CLAY)
Block(-8,0,-3,HARD_CLAY)
Block(-8,0,-2,HARD_CLAY)
Block(-8,0,-1,HARD_CLAY)
Block(-8,0,0,HARD_CLAY)
Block(-8,0,1,HARD_CLAY)
Block(-8,0,2,HARD_CLAY)
Block(-8,0,3,HARD_CLAY)
Block(-8,0,4,HARD_CLAY)
Block(-8,0,5,HARD_CLAY)
Block(-8,0,6,HARD_CLAY)
Block(-8,0,7,HARD_CLAY)
Block(-8,0,8,HARD_CLAY)
Block(-8,0,9,HARD_CLAY)
Block(-8,0,10,HARD_CLAY)
Block(-8,0,11,HARD_CLAY)
Block(-8,0,12,HARD_CLAY)
Block(-8,0,13,HARD_CLAY)
Block(-8,0,14,HARD_CLAY)
Block(-8,1,-13,HARD_CLAY)
Block(-8,1,-12,HARD_CLAY)
Block(-8,1,-11,HARD_CLAY)
Block(-8,1,-10,HARD_CLAY)
Block(-8,1,-9,HARD_CLAY)
Block(-8,1,-8,HARD_CLAY)
Block(-8,1,-7,HARD_CLAY)
Block(-8,1,-6,HARD_CLAY)
Block(-8,1,-5,HARD_CLAY)
Block(-8,1,-4,HARD_CLAY)
Block(-8,1,-3,HARD_CLAY)
Block(-8,1,-2,HARD_CLAY)
Block(-8,1,-1,HARD_CLAY)
Block(-8,1,0,HARD_CLAY)
Block(-8,1,1,HARD_CLAY)
Block(-8,1,2,HARD_CLAY)
Block(-8,1,3,HARD_CLAY)
Block(-8,1,4,HARD_CLAY)
Block(-8,1,5,HARD_CLAY)
Block(-8,1,6,HARD_CLAY)
Block(-8,1,7,HARD_CLAY)
Block(-8,1,8,HARD_CLAY)
Block(-8,1,9,HARD_CLAY)
Block(-8,1,10,HARD_CLAY)
Block(-8,1,11,HARD_CLAY)
Block(-8,1,12,HARD_CLAY)
Block(-8,1,13,HARD_CLAY)
Block(-8,2,-13,HARD_CLAY)
Block(-8,2,-12,HARD_CLAY)
Block(-8,2,-11,HARD_CLAY)
Block(-8,2,-10,HARD_CLAY)
Block(-8,2,-9,HARD_CLAY)
Block(-8,2,-8,HARD_CLAY)
Block(-8,2,-7,HARD_CLAY)
Block(-8,2,-6,HARD_CLAY)
Block(-8,2,-5,HARD_CLAY)
Block(-8,2,-4,HARD_CLAY)
Block(-8,2,-3,HARD_CLAY)
Block(-8,2,-2,HARD_CLAY)
Block(-8,2,-1,HARD_CLAY)
Block(-8,2,0,HARD_CLAY)
Block(-8,2,1,HARD_CLAY)
Block(-8,2,2,HARD_CLAY)
Block(-8,2,3,HARD_CLAY)
Block(-8,2,4,HARD_CLAY)
Block(-8,2,5,HARD_CLAY)
Block(-8,2,6,HARD_CLAY)
Block(-8,2,7,HARD_CLAY)
Block(-8,2,8,HARD_CLAY)
Block(-8,2,9,HARD_CLAY)
Block(-8,2,13,HARD_CLAY)
Block(-8,3,-11,HARD_CLAY)
Block(-8,3,-10,HARD_CLAY)
Block(-8,3,-9,HARD_CLAY)
Block(-8,3,-8,HARD_CLAY)
Block(-8,3,-7,HARD_CLAY)
Block(-8,3,-6,HARD_CLAY)
Block(-8,3,-5,HARD_CLAY)
Block(-8,3,-4,HARD_CLAY)
Block(-8,3,-3,HARD_CLAY)
Block(-8,3,-2,HARD_CLAY)
Block(-8,3,-1,HARD_CLAY)
Block(-8,3,0,HARD_CLAY)
Block(-8,3,1,HARD_CLAY)
Block(-8,3,2,HARD_CLAY)
Block(-8,3,3,HARD_CLAY)
Block(-8,3,4,HARD_CLAY)
Block(-8,3,5,HARD_CLAY)
Block(-8,3,6,HARD_CLAY)
Block(-8,3,7,HARD_CLAY)
Block(-8,3,8,HARD_CLAY)
Block(-8,4,-10,HARD_CLAY)
Block(-8,4,-9,HARD_CLAY)
Block(-8,4,-8,HARD_CLAY)
Block(-8,4,-7,HARD_CLAY)
Block(-8,4,-6,HARD_CLAY)
Block(-8,4,-5,HARD_CLAY)
Block(-8,4,-4,HARD_CLAY)
Block(-8,4,-3,HARD_CLAY)
Block(-8,4,-2,HARD_CLAY)
Block(-8,4,-1,HARD_CLAY)
Block(-8,4,0,HARD_CLAY)
Block(-8,4,1,HARD_CLAY)
Block(-8,4,2,HARD_CLAY)
Block(-8,4,3,HARD_CLAY)
Block(-8,4,4,HARD_CLAY)
Block(-8,4,5,HARD_CLAY)
Block(-8,4,6,HARD_CLAY)
Block(-8,4,7,HARD_CLAY)
Block(-8,5,-10,HARD_CLAY)
Block(-8,5,-9,HARD_CLAY)
Block(-8,5,-8,HARD_CLAY)
Block(-8,5,-7,HARD_CLAY)
Block(-8,5,-6,HARD_CLAY)
Block(-8,5,-5,HARD_CLAY)
Block(-8,5,-4,HARD_CLAY)
Block(-8,5,-3,HARD_CLAY)
Block(-8,5,-2,HARD_CLAY)
Block(-8,5,-1,HARD_CLAY)
Block(-8,5,0,HARD_CLAY)
Block(-8,5,1,HARD_CLAY)
Block(-8,5,2,HARD_CLAY)
Block(-8,5,3,HARD_CLAY)
Block(-8,5,4,HARD_CLAY)
Block(-8,5,5,HARD_CLAY)
Block(-8,5,6,HARD_CLAY)
Block(-8,5,7,HARD_CLAY)
Block(-8,6,-10,HARD_CLAY)
Block(-8,6,-9,HARD_CLAY)
Block(-8,6,-8,HARD_CLAY)
Block(-8,6,-7,HARD_CLAY)
Block(-8,6,-6,HARD_CLAY)
Block(-8,6,-5,HARD_CLAY)
Block(-8,6,-4,HARD_CLAY)
Block(-8,6,-3,HARD_CLAY)
Block(-8,6,-2,HARD_CLAY)
Block(-8,6,-1,HARD_CLAY)
Block(-8,6,0,HARD_CLAY)
Block(-8,6,1,HARD_CLAY)
Block(-8,6,2,HARD_CLAY)
Block(-8,6,3,HARD_CLAY)
Block(-8,6,4,HARD_CLAY)
Block(-8,6,5,HARD_CLAY)
Block(-8,6,6,HARD_CLAY)
Block(-8,7,-9,HARD_CLAY)
Block(-8,7,-8,HARD_CLAY)
Block(-8,7,-7,HARD_CLAY)
Block(-8,7,-6,HARD_CLAY)
Block(-8,7,-5,HARD_CLAY)
Block(-8,7,-4,HARD_CLAY)
Block(-8,7,-3,HARD_CLAY)
Block(-8,7,-1,HARD_CLAY)
Block(-8,7,0,HARD_CLAY)
Block(-8,7,1,HARD_CLAY)
Block(-8,7,2,HARD_CLAY)
Block(-8,7,3,HARD_CLAY)
Block(-8,7,4,HARD_CLAY)
Block(-8,7,5,HARD_CLAY)
Block(-8,7,6,HARD_CLAY)
Block(-8,8,-8,HARD_CLAY)
Block(-8,8,-7,HARD_CLAY)
Block(-8,8,-6,HARD_CLAY)
Block(-8,8,-5,HARD_CLAY)
Block(-8,8,-4,HARD_CLAY)
Block(-8,8,-3,HARD_CLAY)
Block(-8,8,-1,HARD_CLAY)
Block(-8,8,0,HARD_CLAY)
Block(-8,8,1,HARD_CLAY)
Block(-8,8,2,HARD_CLAY)
Block(-8,8,3,HARD_CLAY)
Block(-8,8,4,HARD_CLAY)
Block(-8,8,5,HARD_CLAY)
Block(-8,8,6,HARD_CLAY)
Block(-8,9,-8,HARD_CLAY)
Block(-8,9,-7,HARD_CLAY)
Block(-8,9,-6,HARD_CLAY)
Block(-8,9,-5,HARD_CLAY)
Block(-8,9,-4,HARD_CLAY)
Block(-8,9,-3,HARD_CLAY)
Block(-8,9,-1,HARD_CLAY)
Block(-8,9,0,HARD_CLAY)
Block(-8,9,1,HARD_CLAY)
Block(-8,9,2,HARD_CLAY)
Block(-8,9,3,HARD_CLAY)
Block(-8,9,4,HARD_CLAY)
Block(-8,9,5,HARD_CLAY)
Block(-8,9,6,HARD_CLAY)
Block(-8,10,-8,HARD_CLAY)
Block(-8,10,-7,HARD_CLAY)
Block(-8,10,-6,HARD_CLAY)
Block(-8,10,-5,HARD_CLAY)
Block(-8,10,-4,HARD_CLAY)
Block(-8,10,-3,HARD_CLAY)
Block(-8,10,-1,HARD_CLAY)
Block(-8,10,0,HARD_CLAY)
Block(-8,10,1,HARD_CLAY)
Block(-8,10,2,HARD_CLAY)
Block(-8,10,3,HARD_CLAY)
Block(-8,10,4,HARD_CLAY)
Block(-8,10,5,HARD_CLAY)
Block(-8,10,6,HARD_CLAY)
Block(-8,11,-8,HARD_CLAY)
Block(-8,11,-7,HARD_CLAY)
Block(-8,11,-6,HARD_CLAY)
Block(-8,11,-5,HARD_CLAY)
Block(-8,11,-4,HARD_CLAY)
Block(-8,11,-3,HARD_CLAY)
Block(-8,11,-1,HARD_CLAY)
Block(-8,11,0,HARD_CLAY)
Block(-8,11,1,HARD_CLAY)
Block(-8,11,2,HARD_CLAY)
Block(-8,11,3,HARD_CLAY)
Block(-8,11,4,HARD_CLAY)
Block(-8,11,5,HARD_CLAY)
Block(-8,11,6,HARD_CLAY)
Block(-8,12,-8,HARD_CLAY)
Block(-8,12,-7,HARD_CLAY)
Block(-8,12,-6,HARD_CLAY)
Block(-8,12,-5,HARD_CLAY)
Block(-8,12,-4,HARD_CLAY)
Block(-8,12,-3,HARD_CLAY)
Block(-8,12,-1,HARD_CLAY)
Block(-8,12,0,HARD_CLAY)
Block(-8,12,1,HARD_CLAY)
Block(-8,12,2,HARD_CLAY)
Block(-8,12,3,HARD_CLAY)
Block(-8,12,4,HARD_CLAY)
Block(-8,12,5,HARD_CLAY)
Block(-8,12,6,HARD_CLAY)
Block(-8,13,-5,HARD_CLAY)
Block(-8,13,-4,HARD_CLAY)
Block(-8,13,-1,HARD_CLAY)
Block(-8,13,0,HARD_CLAY)
Block(-8,13,1,HARD_CLAY)
Block(-8,13,2,HARD_CLAY)
Block(-8,13,3,HARD_CLAY)
Block(-8,13,4,HARD_CLAY)
Block(-8,13,5,HARD_CLAY)
Block(-8,13,6,HARD_CLAY)
Block(-8,14,-4,HARD_CLAY)
Block(-8,14,-1,HARD_CLAY)
Block(-8,14,0,HARD_CLAY)
Block(-8,14,1,HARD_CLAY)
Block(-8,14,2,HARD_CLAY)
Block(-8,14,3,HARD_CLAY)
Block(-8,14,4,HARD_CLAY)
Block(-8,14,5,HARD_CLAY)
Block(-8,15,0,HARD_CLAY)
Block(-8,15,1,HARD_CLAY)
Block(-8,15,2,HARD_CLAY)
Block(-8,15,3,HARD_CLAY)
Block(-8,15,4,HARD_CLAY)
Block(-8,15,5,HARD_CLAY)
Block(-8,16,0,HARD_CLAY)
Block(-8,16,1,HARD_CLAY)
Block(-8,16,2,HARD_CLAY)
Block(-8,16,3,HARD_CLAY)
Block(-8,16,4,HARD_CLAY)
Block(-8,16,5,HARD_CLAY)
Block(-8,17,0,HARD_CLAY)
Block(-8,17,1,HARD_CLAY)
Block(-8,17,2,HARD_CLAY)
Block(-8,17,3,HARD_CLAY)
Block(-8,17,4,HARD_CLAY)
Block(-8,17,5,HARD_CLAY)
Block(-8,18,0,HARD_CLAY)
Block(-8,18,1,HARD_CLAY)
Block(-8,18,2,HARD_CLAY)
Block(-8,18,3,HARD_CLAY)
Block(-8,18,4,HARD_CLAY)
Block(-8,18,5,HARD_CLAY)
Block(-8,19,0,HARD_CLAY)
Block(-8,19,1,HARD_CLAY)
Block(-8,19,2,HARD_CLAY)
Block(-8,19,3,HARD_CLAY)
Block(-8,19,4,HARD_CLAY)
Block(-8,19,5,HARD_CLAY)
Block(-8,20,0,HARD_CLAY)
Block(-8,20,1,HARD_CLAY)
Block(-8,20,2,HARD_CLAY)
Block(-8,20,3,HARD_CLAY)
Block(-8,20,4,HARD_CLAY)
Block(-8,20,5,HARD_CLAY)
Block(-8,21,0,HARD_CLAY)
Block(-8,21,1,HARD_CLAY)
Block(-8,21,2,HARD_CLAY)
Block(-8,21,3,HARD_CLAY)
Block(-8,21,4,HARD_CLAY)
Block(-8,21,5,HARD_CLAY)
Block(-8,22,0,HARD_CLAY)
Block(-8,22,1,HARD_CLAY)
Block(-8,22,2,HARD_CLAY)
Block(-8,22,3,HARD_CLAY)
Block(-8,22,4,HARD_CLAY)
Block(-8,22,5,HARD_CLAY)
Block(-8,23,0,HARD_CLAY)
Block(-8,23,1,HARD_CLAY)
Block(-8,23,2,HARD_CLAY)
Block(-8,23,3,HARD_CLAY)
Block(-8,23,4,HARD_CLAY)
Block(-8,23,5,HARD_CLAY)
Block(-8,24,0,HARD_CLAY)
Block(-8,24,1,HARD_CLAY)
Block(-8,24,2,HARD_CLAY)
Block(-8,24,3,HARD_CLAY)
Block(-8,24,4,HARD_CLAY)
Block(-8,24,5,HARD_CLAY)
Block(-8,25,0,HARD_CLAY)
Block(-8,25,1,HARD_CLAY)
Block(-8,25,2,HARD_CLAY)
Block(-8,25,3,HARD_CLAY)
Block(-8,25,4,HARD_CLAY)
Block(-8,26,0,HARD_CLAY)
Block(-8,26,1,HARD_CLAY)
Block(-8,26,2,HARD_CLAY)
Block(-8,26,3,HARD_CLAY)
Block(-8,26,4,HARD_CLAY)
Block(-8,27,0,HARD_CLAY)
Block(-8,27,1,HARD_CLAY)
Block(-8,27,2,HARD_CLAY)
Block(-8,27,3,HARD_CLAY)
Block(-8,27,4,HARD_CLAY)
Block(-8,28,0,HARD_CLAY)
Block(-8,28,1,HARD_CLAY)
Block(-8,28,2,HARD_CLAY)
Block(-8,28,3,HARD_CLAY)
Block(-8,28,4,HARD_CLAY)
Block(-8,29,0,HARD_CLAY)
Block(-8,29,1,HARD_CLAY)
Block(-8,29,2,HARD_CLAY)
Block(-8,29,3,HARD_CLAY)
Block(-8,29,4,HARD_CLAY)
Block(-8,30,0,HARD_CLAY)
Block(-8,30,1,HARD_CLAY)
Block(-8,30,2,HARD_CLAY)
Block(-8,30,3,HARD_CLAY)
Block(-8,30,4,HARD_CLAY)
Block(-8,31,0,HARD_CLAY)
Block(-8,31,1,HARD_CLAY)
Block(-8,31,2,HARD_CLAY)
Block(-8,31,3,HARD_CLAY)
Block(-8,31,4,HARD_CLAY)
Block(-7,0,-14,HARD_CLAY)
Block(-7,0,-13,HARD_CLAY)
Block(-7,0,-12,HARD_CLAY)
Block(-7,0,-11,HARD_CLAY)
Block(-7,0,-10,HARD_CLAY)
Block(-7,0,-9,HARD_CLAY)
Block(-7,0,-8,HARD_CLAY)
Block(-7,0,-7,HARD_CLAY)
Block(-7,0,-6,HARD_CLAY)
Block(-7,0,-5,HARD_CLAY)
Block(-7,0,-4,HARD_CLAY)
Block(-7,0,-3,HARD_CLAY)
Block(-7,0,-2,HARD_CLAY)
Block(-7,0,-1,HARD_CLAY)
Block(-7,0,0,HARD_CLAY)
Block(-7,0,1,HARD_CLAY)
Block(-7,0,2,HARD_CLAY)
Block(-7,0,3,HARD_CLAY)
Block(-7,0,4,HARD_CLAY)
Block(-7,0,5,HARD_CLAY)
Block(-7,0,6,HARD_CLAY)
Block(-7,0,7,HARD_CLAY)
Block(-7,0,8,HARD_CLAY)
Block(-7,0,9,HARD_CLAY)
Block(-7,0,10,HARD_CLAY)
Block(-7,0,11,HARD_CLAY)
Block(-7,0,12,HARD_CLAY)
Block(-7,0,13,HARD_CLAY)
Block(-7,0,14,HARD_CLAY)
Block(-7,0,15,HARD_CLAY)
Block(-7,1,-13,HARD_CLAY)
Block(-7,1,-12,HARD_CLAY)
Block(-7,1,-11,HARD_CLAY)
Block(-7,1,-10,HARD_CLAY)
Block(-7,1,-9,HARD_CLAY)
Block(-7,1,-8,HARD_CLAY)
Block(-7,1,-7,HARD_CLAY)
Block(-7,1,-6,HARD_CLAY)
Block(-7,1,-5,HARD_CLAY)
Block(-7,1,-4,HARD_CLAY)
Block(-7,1,-3,HARD_CLAY)
Block(-7,1,-2,HARD_CLAY)
Block(-7,1,-1,HARD_CLAY)
Block(-7,1,0,HARD_CLAY)
Block(-7,1,1,HARD_CLAY)
Block(-7,1,2,HARD_CLAY)
Block(-7,1,3,HARD_CLAY)
Block(-7,1,4,HARD_CLAY)
Block(-7,1,5,HARD_CLAY)
Block(-7,1,6,HARD_CLAY)
Block(-7,1,7,HARD_CLAY)
Block(-7,1,8,HARD_CLAY)
Block(-7,1,9,HARD_CLAY)
Block(-7,1,10,HARD_CLAY)
Block(-7,1,11,HARD_CLAY)
Block(-7,1,12,HARD_CLAY)
Block(-7,1,13,HARD_CLAY)
Block(-7,1,14,HARD_CLAY)
Block(-7,2,-13,HARD_CLAY)
Block(-7,2,-12,HARD_CLAY)
Block(-7,2,-11,HARD_CLAY)
Block(-7,2,-10,HARD_CLAY)
Block(-7,2,-9,HARD_CLAY)
Block(-7,2,-8,HARD_CLAY)
Block(-7,2,-7,HARD_CLAY)
Block(-7,2,-6,HARD_CLAY)
Block(-7,2,-5,HARD_CLAY)
Block(-7,2,-4,HARD_CLAY)
Block(-7,2,-3,HARD_CLAY)
Block(-7,2,-2,HARD_CLAY)
Block(-7,2,-1,HARD_CLAY)
Block(-7,2,0,HARD_CLAY)
Block(-7,2,1,HARD_CLAY)
Block(-7,2,2,HARD_CLAY)
Block(-7,2,3,HARD_CLAY)
Block(-7,2,4,HARD_CLAY)
Block(-7,2,5,HARD_CLAY)
Block(-7,2,6,HARD_CLAY)
Block(-7,2,7,HARD_CLAY)
Block(-7,2,8,HARD_CLAY)
Block(-7,2,9,HARD_CLAY)
Block(-7,2,10,HARD_CLAY)
Block(-7,2,11,HARD_CLAY)
Block(-7,2,12,HARD_CLAY)
Block(-7,2,13,HARD_CLAY)
Block(-7,3,-13,HARD_CLAY)
Block(-7,3,-12,HARD_CLAY)
Block(-7,3,-11,HARD_CLAY)
Block(-7,3,-10,HARD_CLAY)
Block(-7,3,-9,HARD_CLAY)
Block(-7,3,-8,HARD_CLAY)
Block(-7,3,-7,HARD_CLAY)
Block(-7,3,-6,HARD_CLAY)
Block(-7,3,-5,HARD_CLAY)
Block(-7,3,-4,HARD_CLAY)
Block(-7,3,-3,HARD_CLAY)
Block(-7,3,-2,HARD_CLAY)
Block(-7,3,-1,HARD_CLAY)
Block(-7,3,0,HARD_CLAY)
Block(-7,3,1,HARD_CLAY)
Block(-7,3,2,HARD_CLAY)
Block(-7,3,3,HARD_CLAY)
Block(-7,3,4,HARD_CLAY)
Block(-7,3,5,HARD_CLAY)
Block(-7,3,6,HARD_CLAY)
Block(-7,3,7,HARD_CLAY)
Block(-7,3,8,HARD_CLAY)
Block(-7,3,9,HARD_CLAY)
Block(-7,3,10,HARD_CLAY)
Block(-7,3,11,HARD_CLAY)
Block(-7,4,-13,HARD_CLAY)
Block(-7,4,-12,HARD_CLAY)
Block(-7,4,-11,HARD_CLAY)
Block(-7,4,-10,HARD_CLAY)
Block(-7,4,-9,HARD_CLAY)
Block(-7,4,-8,HARD_CLAY)
Block(-7,4,-7,HARD_CLAY)
Block(-7,4,-6,HARD_CLAY)
Block(-7,4,-5,HARD_CLAY)
Block(-7,4,-4,HARD_CLAY)
Block(-7,4,-3,HARD_CLAY)
Block(-7,4,-2,HARD_CLAY)
Block(-7,4,-1,HARD_CLAY)
Block(-7,4,0,HARD_CLAY)
Block(-7,4,1,HARD_CLAY)
Block(-7,4,2,HARD_CLAY)
Block(-7,4,3,HARD_CLAY)
Block(-7,4,4,HARD_CLAY)
Block(-7,4,5,HARD_CLAY)
Block(-7,4,6,HARD_CLAY)
Block(-7,4,7,HARD_CLAY)
Block(-7,4,8,HARD_CLAY)
Block(-7,4,9,HARD_CLAY)
Block(-7,5,-11,HARD_CLAY)
Block(-7,5,-10,HARD_CLAY)
Block(-7,5,-9,HARD_CLAY)
Block(-7,5,-8,HARD_CLAY)
Block(-7,5,-7,HARD_CLAY)
Block(-7,5,-6,HARD_CLAY)
Block(-7,5,-5,HARD_CLAY)
Block(-7,5,-4,HARD_CLAY)
Block(-7,5,-3,HARD_CLAY)
Block(-7,5,-2,HARD_CLAY)
Block(-7,5,-1,HARD_CLAY)
Block(-7,5,0,HARD_CLAY)
Block(-7,5,1,HARD_CLAY)
Block(-7,5,2,HARD_CLAY)
Block(-7,5,3,HARD_CLAY)
Block(-7,5,4,HARD_CLAY)
Block(-7,5,5,HARD_CLAY)
Block(-7,5,6,HARD_CLAY)
Block(-7,5,7,HARD_CLAY)
Block(-7,5,8,HARD_CLAY)
Block(-7,5,9,HARD_CLAY)
Block(-7,6,-11,HARD_CLAY)
Block(-7,6,-10,HARD_CLAY)
Block(-7,6,-9,HARD_CLAY)
Block(-7,6,-8,HARD_CLAY)
Block(-7,6,-7,HARD_CLAY)
Block(-7,6,-6,HARD_CLAY)
Block(-7,6,-5,HARD_CLAY)
Block(-7,6,-4,HARD_CLAY)
Block(-7,6,-3,HARD_CLAY)
Block(-7,6,-2,HARD_CLAY)
Block(-7,6,-1,HARD_CLAY)
Block(-7,6,0,HARD_CLAY)
Block(-7,6,1,HARD_CLAY)
Block(-7,6,2,HARD_CLAY)
Block(-7,6,3,HARD_CLAY)
Block(-7,6,4,HARD_CLAY)
Block(-7,6,5,HARD_CLAY)
Block(-7,6,6,HARD_CLAY)
Block(-7,6,7,HARD_CLAY)
Block(-7,6,8,HARD_CLAY)
Block(-7,6,9,HARD_CLAY)
Block(-7,7,-11,HARD_CLAY)
Block(-7,7,-10,HARD_CLAY)
Block(-7,7,-9,HARD_CLAY)
Block(-7,7,-8,HARD_CLAY)
Block(-7,7,-7,HARD_CLAY)
Block(-7,7,-6,HARD_CLAY)
Block(-7,7,-5,HARD_CLAY)
Block(-7,7,-4,HARD_CLAY)
Block(-7,7,-3,HARD_CLAY)
Block(-7,7,-2,HARD_CLAY)
Block(-7,7,-1,HARD_CLAY)
Block(-7,7,0,HARD_CLAY)
Block(-7,7,1,HARD_CLAY)
Block(-7,7,2,HARD_CLAY)
Block(-7,7,3,HARD_CLAY)
Block(-7,7,4,HARD_CLAY)
Block(-7,7,5,HARD_CLAY)
Block(-7,7,6,HARD_CLAY)
Block(-7,7,7,HARD_CLAY)
Block(-7,8,-10,HARD_CLAY)
Block(-7,8,-9,HARD_CLAY)
Block(-7,8,-8,HARD_CLAY)
Block(-7,8,-7,HARD_CLAY)
Block(-7,8,-6,HARD_CLAY)
Block(-7,8,-5,HARD_CLAY)
Block(-7,8,-4,HARD_CLAY)
Block(-7,8,-3,HARD_CLAY)
Block(-7,8,-2,HARD_CLAY)
Block(-7,8,-1,HARD_CLAY)
Block(-7,8,0,HARD_CLAY)
Block(-7,8,1,HARD_CLAY)
Block(-7,8,2,HARD_CLAY)
Block(-7,8,3,HARD_CLAY)
Block(-7,8,4,HARD_CLAY)
Block(-7,8,5,HARD_CLAY)
Block(-7,8,6,HARD_CLAY)
Block(-7,8,7,HARD_CLAY)
Block(-7,9,-10,HARD_CLAY)
Block(-7,9,-9,HARD_CLAY)
Block(-7,9,-8,HARD_CLAY)
Block(-7,9,-7,HARD_CLAY)
Block(-7,9,-6,HARD_CLAY)
Block(-7,9,-5,HARD_CLAY)
Block(-7,9,-4,HARD_CLAY)
Block(-7,9,-3,HARD_CLAY)
Block(-7,9,-2,HARD_CLAY)
Block(-7,9,-1,HARD_CLAY)
Block(-7,9,0,HARD_CLAY)
Block(-7,9,1,HARD_CLAY)
Block(-7,9,2,HARD_CLAY)
Block(-7,9,3,HARD_CLAY)
Block(-7,9,4,HARD_CLAY)
Block(-7,9,5,HARD_CLAY)
Block(-7,9,6,HARD_CLAY)
Block(-7,10,-10,HARD_CLAY)
Block(-7,10,-9,HARD_CLAY)
Block(-7,10,-8,HARD_CLAY)
Block(-7,10,-7,HARD_CLAY)
Block(-7,10,-6,HARD_CLAY)
Block(-7,10,-5,HARD_CLAY)
Block(-7,10,-4,HARD_CLAY)
Block(-7,10,-3,HARD_CLAY)
Block(-7,10,-2,HARD_CLAY)
Block(-7,10,-1,HARD_CLAY)
Block(-7,10,0,HARD_CLAY)
Block(-7,10,1,HARD_CLAY)
Block(-7,10,2,HARD_CLAY)
Block(-7,10,3,HARD_CLAY)
Block(-7,10,4,HARD_CLAY)
Block(-7,10,5,HARD_CLAY)
Block(-7,10,6,HARD_CLAY)
Block(-7,11,-10,HARD_CLAY)
Block(-7,11,-9,HARD_CLAY)
Block(-7,11,-8,HARD_CLAY)
Block(-7,11,-7,HARD_CLAY)
Block(-7,11,-6,HARD_CLAY)
Block(-7,11,-5,HARD_CLAY)
Block(-7,11,-4,HARD_CLAY)
Block(-7,11,-3,HARD_CLAY)
Block(-7,11,-2,HARD_CLAY)
Block(-7,11,-1,HARD_CLAY)
Block(-7,11,0,HARD_CLAY)
Block(-7,11,1,HARD_CLAY)
Block(-7,11,2,HARD_CLAY)
Block(-7,11,3,HARD_CLAY)
Block(-7,11,4,HARD_CLAY)
Block(-7,11,5,HARD_CLAY)
Block(-7,11,6,HARD_CLAY)
Block(-7,12,-10,HARD_CLAY)
Block(-7,12,-9,HARD_CLAY)
Block(-7,12,-8,HARD_CLAY)
Block(-7,12,-7,HARD_CLAY)
Block(-7,12,-6,HARD_CLAY)
Block(-7,12,-5,HARD_CLAY)
Block(-7,12,-4,HARD_CLAY)
Block(-7,12,-3,HARD_CLAY)
Block(-7,12,-2,HARD_CLAY)
Block(-7,12,-1,HARD_CLAY)
Block(-7,12,0,HARD_CLAY)
Block(-7,12,1,HARD_CLAY)
Block(-7,12,2,HARD_CLAY)
Block(-7,12,3,HARD_CLAY)
Block(-7,12,4,HARD_CLAY)
Block(-7,12,5,HARD_CLAY)
Block(-7,12,6,HARD_CLAY)
Block(-7,13,-8,HARD_CLAY)
Block(-7,13,-7,HARD_CLAY)
Block(-7,13,-6,HARD_CLAY)
Block(-7,13,-5,HARD_CLAY)
Block(-7,13,-4,HARD_CLAY)
Block(-7,13,-3,HARD_CLAY)
Block(-7,13,-2,HARD_CLAY)
Block(-7,13,-1,HARD_CLAY)
Block(-7,13,0,HARD_CLAY)
Block(-7,13,1,HARD_CLAY)
Block(-7,13,2,HARD_CLAY)
Block(-7,13,3,HARD_CLAY)
Block(-7,13,4,HARD_CLAY)
Block(-7,13,5,HARD_CLAY)
Block(-7,13,6,HARD_CLAY)
Block(-7,14,-8,HARD_CLAY)
Block(-7,14,-7,HARD_CLAY)
Block(-7,14,-5,HARD_CLAY)
Block(-7,14,-4,HARD_CLAY)
Block(-7,14,-3,HARD_CLAY)
Block(-7,14,-1,HARD_CLAY)
Block(-7,14,0,HARD_CLAY)
Block(-7,14,1,HARD_CLAY)
Block(-7,14,2,HARD_CLAY)
Block(-7,14,3,HARD_CLAY)
Block(-7,14,4,HARD_CLAY)
Block(-7,14,5,HARD_CLAY)
Block(-7,14,6,HARD_CLAY)
Block(-7,15,-7,HARD_CLAY)
Block(-7,15,-5,HARD_CLAY)
Block(-7,15,-4,HARD_CLAY)
Block(-7,15,-1,HARD_CLAY)
Block(-7,15,0,HARD_CLAY)
Block(-7,15,1,HARD_CLAY)
Block(-7,15,2,HARD_CLAY)
Block(-7,15,3,HARD_CLAY)
Block(-7,15,4,HARD_CLAY)
Block(-7,15,5,HARD_CLAY)
Block(-7,15,6,HARD_CLAY)
Block(-7,16,-5,HARD_CLAY)
Block(-7,16,-4,HARD_CLAY)
Block(-7,16,-1,HARD_CLAY)
Block(-7,16,0,HARD_CLAY)
Block(-7,16,1,HARD_CLAY)
Block(-7,16,2,HARD_CLAY)
Block(-7,16,3,HARD_CLAY)
Block(-7,16,4,HARD_CLAY)
Block(-7,16,5,HARD_CLAY)
Block(-7,16,6,HARD_CLAY)
Block(-7,17,-5,HARD_CLAY)
Block(-7,17,-4,HARD_CLAY)
Block(-7,17,-1,HARD_CLAY)
Block(-7,17,0,HARD_CLAY)
Block(-7,17,1,HARD_CLAY)
Block(-7,17,2,HARD_CLAY)
Block(-7,17,3,HARD_CLAY)
Block(-7,17,4,HARD_CLAY)
Block(-7,17,5,HARD_CLAY)
Block(-7,18,-4,HARD_CLAY)
Block(-7,18,0,HARD_CLAY)
Block(-7,18,1,HARD_CLAY)
Block(-7,18,2,HARD_CLAY)
Block(-7,18,3,HARD_CLAY)
Block(-7,18,4,HARD_CLAY)
Block(-7,18,5,HARD_CLAY)
Block(-7,19,-4,HARD_CLAY)
Block(-7,19,0,HARD_CLAY)
Block(-7,19,1,HARD_CLAY)
Block(-7,19,2,HARD_CLAY)
Block(-7,19,3,HARD_CLAY)
Block(-7,19,4,HARD_CLAY)
Block(-7,19,5,HARD_CLAY)
Block(-7,20,-4,HARD_CLAY)
Block(-7,20,0,HARD_CLAY)
Block(-7,20,1,HARD_CLAY)
Block(-7,20,2,HARD_CLAY)
Block(-7,20,3,HARD_CLAY)
Block(-7,20,4,HARD_CLAY)
Block(-7,20,5,HARD_CLAY)
Block(-7,21,-4,HARD_CLAY)
Block(-7,21,0,HARD_CLAY)
Block(-7,21,1,HARD_CLAY)
Block(-7,21,2,HARD_CLAY)
Block(-7,21,3,HARD_CLAY)
Block(-7,21,4,HARD_CLAY)
Block(-7,21,5,HARD_CLAY)
Block(-7,22,-4,HARD_CLAY)
Block(-7,22,0,HARD_CLAY)
Block(-7,22,1,HARD_CLAY)
Block(-7,22,2,HARD_CLAY)
Block(-7,22,3,HARD_CLAY)
Block(-7,22,4,HARD_CLAY)
Block(-7,22,5,HARD_CLAY)
Block(-7,23,-4,HARD_CLAY)
Block(-7,23,0,HARD_CLAY)
Block(-7,23,1,HARD_CLAY)
Block(-7,23,2,HARD_CLAY)
Block(-7,23,3,HARD_CLAY)
Block(-7,23,4,HARD_CLAY)
Block(-7,23,5,HARD_CLAY)
Block(-7,24,0,HARD_CLAY)
Block(-7,24,1,HARD_CLAY)
Block(-7,24,2,HARD_CLAY)
Block(-7,24,3,HARD_CLAY)
Block(-7,24,4,HARD_CLAY)
Block(-7,24,5,HARD_CLAY)
Block(-7,25,0,HARD_CLAY)
Block(-7,25,1,HARD_CLAY)
Block(-7,25,2,HARD_CLAY)
Block(-7,25,3,HARD_CLAY)
Block(-7,25,4,HARD_CLAY)
Block(-7,25,5,HARD_CLAY)
Block(-7,26,0,HARD_CLAY)
Block(-7,26,1,HARD_CLAY)
Block(-7,26,2,HARD_CLAY)
Block(-7,26,3,HARD_CLAY)
Block(-7,26,4,HARD_CLAY)
Block(-7,26,5,HARD_CLAY)
Block(-7,27,0,HARD_CLAY)
Block(-7,27,1,HARD_CLAY)
Block(-7,27,2,HARD_CLAY)
Block(-7,27,3,HARD_CLAY)
Block(-7,27,4,HARD_CLAY)
Block(-7,27,5,HARD_CLAY)
Block(-7,28,0,HARD_CLAY)
Block(-7,28,1,HARD_CLAY)
Block(-7,28,2,HARD_CLAY)
Block(-7,28,3,HARD_CLAY)
Block(-7,28,4,HARD_CLAY)
Block(-7,28,5,HARD_CLAY)
Block(-7,29,0,HARD_CLAY)
Block(-7,29,1,HARD_CLAY)
Block(-7,29,2,HARD_CLAY)
Block(-7,29,3,HARD_CLAY)
Block(-7,29,4,HARD_CLAY)
Block(-7,29,5,HARD_CLAY)
Block(-7,30,0,HARD_CLAY)
Block(-7,30,1,HARD_CLAY)
Block(-7,30,2,HARD_CLAY)
Block(-7,30,3,HARD_CLAY)
Block(-7,30,4,HARD_CLAY)
Block(-7,30,5,HARD_CLAY)
Block(-7,31,0,HARD_CLAY)
Block(-7,31,1,HARD_CLAY)
Block(-7,31,2,SAND:1)
Block(-7,31,3,SAND:1)
Block(-7,31,4,HARD_CLAY)
Block(-7,31,5,HARD_CLAY)
Block(-6,0,-13,HARD_CLAY)
Block(-6,0,-12,HARD_CLAY)
Block(-6,0,-11,HARD_CLAY)
Block(-6,0,-10,HARD_CLAY)
Block(-6,0,-9,HARD_CLAY)
Block(-6,0,-8,HARD_CLAY)
Block(-6,0,-7,HARD_CLAY)
Block(-6,0,-6,HARD_CLAY)
Block(-6,0,-5,HARD_CLAY)
Block(-6,0,-4,HARD_CLAY)
Block(-6,0,-3,HARD_CLAY)
Block(-6,0,-2,HARD_CLAY)
Block(-6,0,-1,HARD_CLAY)
Block(-6,0,0,HARD_CLAY)
Block(-6,0,1,HARD_CLAY)
Block(-6,0,2,HARD_CLAY)
Block(-6,0,3,HARD_CLAY)
Block(-6,0,4,HARD_CLAY)
Block(-6,0,5,HARD_CLAY)
Block(-6,0,6,HARD_CLAY)
Block(-6,0,7,HARD_CLAY)
Block(-6,0,8,HARD_CLAY)
Block(-6,0,9,HARD_CLAY)
Block(-6,0,10,HARD_CLAY)
Block(-6,0,11,HARD_CLAY)
Block(-6,0,12,HARD_CLAY)
Block(-6,0,13,HARD_CLAY)
Block(-6,0,14,HARD_CLAY)
Block(-6,1,-12,HARD_CLAY)
Block(-6,1,-11,HARD_CLAY)
Block(-6,1,-10,HARD_CLAY)
Block(-6,1,-9,HARD_CLAY)
Block(-6,1,-8,HARD_CLAY)
Block(-6,1,-7,HARD_CLAY)
Block(-6,1,-6,HARD_CLAY)
Block(-6,1,-5,HARD_CLAY)
Block(-6,1,-4,HARD_CLAY)
Block(-6,1,-3,HARD_CLAY)
Block(-6,1,-2,HARD_CLAY)
Block(-6,1,-1,HARD_CLAY)
Block(-6,1,0,HARD_CLAY)
Block(-6,1,1,HARD_CLAY)
Block(-6,1,2,HARD_CLAY)
Block(-6,1,3,HARD_CLAY)
Block(-6,1,4,HARD_CLAY)
Block(-6,1,5,HARD_CLAY)
Block(-6,1,6,HARD_CLAY)
Block(-6,1,7,HARD_CLAY)
Block(-6,1,8,HARD_CLAY)
Block(-6,1,9,HARD_CLAY)
Block(-6,1,10,HARD_CLAY)
Block(-6,1,11,HARD_CLAY)
Block(-6,1,12,HARD_CLAY)
Block(-6,1,13,HARD_CLAY)
Block(-6,2,-12,HARD_CLAY)
Block(-6,2,-11,HARD_CLAY)
Block(-6,2,-10,HARD_CLAY)
Block(-6,2,-9,HARD_CLAY)
Block(-6,2,-8,HARD_CLAY)
Block(-6,2,-7,HARD_CLAY)
Block(-6,2,-6,HARD_CLAY)
Block(-6,2,-5,HARD_CLAY)
Block(-6,2,-4,HARD_CLAY)
Block(-6,2,-3,HARD_CLAY)
Block(-6,2,-2,HARD_CLAY)
Block(-6,2,-1,HARD_CLAY)
Block(-6,2,0,HARD_CLAY)
Block(-6,2,1,HARD_CLAY)
Block(-6,2,2,HARD_CLAY)
Block(-6,2,3,HARD_CLAY)
Block(-6,2,4,HARD_CLAY)
Block(-6,2,5,HARD_CLAY)
Block(-6,2,6,HARD_CLAY)
Block(-6,2,7,HARD_CLAY)
Block(-6,2,8,HARD_CLAY)
Block(-6,2,9,HARD_CLAY)
Block(-6,2,10,HARD_CLAY)
Block(-6,2,11,HARD_CLAY)
Block(-6,2,12,HARD_CLAY)
Block(-6,2,13,HARD_CLAY)
Block(-6,3,-11,HARD_CLAY)
Block(-6,3,-10,HARD_CLAY)
Block(-6,3,-9,HARD_CLAY)
Block(-6,3,-8,HARD_CLAY)
Block(-6,3,-7,HARD_CLAY)
Block(-6,3,-6,HARD_CLAY)
Block(-6,3,-5,HARD_CLAY)
Block(-6,3,-4,HARD_CLAY)
Block(-6,3,-3,HARD_CLAY)
Block(-6,3,-2,HARD_CLAY)
Block(-6,3,-1,HARD_CLAY)
Block(-6,3,0,HARD_CLAY)
Block(-6,3,1,HARD_CLAY)
Block(-6,3,2,HARD_CLAY)
Block(-6,3,3,HARD_CLAY)
Block(-6,3,4,HARD_CLAY)
Block(-6,3,5,HARD_CLAY)
Block(-6,3,6,HARD_CLAY)
Block(-6,3,7,HARD_CLAY)
Block(-6,3,8,HARD_CLAY)
Block(-6,3,9,HARD_CLAY)
Block(-6,3,10,HARD_CLAY)
Block(-6,3,11,HARD_CLAY)
Block(-6,3,12,HARD_CLAY)
Block(-6,4,-11,HARD_CLAY)
Block(-6,4,-10,HARD_CLAY)
Block(-6,4,-9,HARD_CLAY)
Block(-6,4,-8,HARD_CLAY)
Block(-6,4,-7,HARD_CLAY)
Block(-6,4,-6,HARD_CLAY)
Block(-6,4,-5,HARD_CLAY)
Block(-6,4,-4,HARD_CLAY)
Block(-6,4,-3,HARD_CLAY)
Block(-6,4,-2,HARD_CLAY)
Block(-6,4,-1,HARD_CLAY)
Block(-6,4,0,HARD_CLAY)
Block(-6,4,1,HARD_CLAY)
Block(-6,4,2,HARD_CLAY)
Block(-6,4,3,HARD_CLAY)
Block(-6,4,4,HARD_CLAY)
Block(-6,4,5,HARD_CLAY)
Block(-6,4,6,HARD_CLAY)
Block(-6,4,7,HARD_CLAY)
Block(-6,4,8,HARD_CLAY)
Block(-6,4,9,HARD_CLAY)
Block(-6,4,10,HARD_CLAY)
Block(-6,4,11,HARD_CLAY)
Block(-6,4,12,HARD_CLAY)
Block(-6,5,-11,HARD_CLAY)
Block(-6,5,-10,HARD_CLAY)
Block(-6,5,-9,HARD_CLAY)
Block(-6,5,-8,HARD_CLAY)
Block(-6,5,-7,HARD_CLAY)
Block(-6,5,-6,HARD_CLAY)
Block(-6,5,-5,HARD_CLAY)
Block(-6,5,-4,HARD_CLAY)
Block(-6,5,-3,HARD_CLAY)
Block(-6,5,-2,HARD_CLAY)
Block(-6,5,-1,HARD_CLAY)
Block(-6,5,0,HARD_CLAY)
Block(-6,5,1,HARD_CLAY)
Block(-6,5,2,HARD_CLAY)
Block(-6,5,3,HARD_CLAY)
Block(-6,5,4,HARD_CLAY)
Block(-6,5,5,HARD_CLAY)
Block(-6,5,6,HARD_CLAY)
Block(-6,5,7,HARD_CLAY)
Block(-6,5,8,HARD_CLAY)
Block(-6,5,9,HARD_CLAY)
Block(-6,5,10,HARD_CLAY)
Block(-6,5,12,HARD_CLAY)
Block(-6,6,-11,HARD_CLAY)
Block(-6,6,-10,HARD_CLAY)
Block(-6,6,-9,HARD_CLAY)
Block(-6,6,-8,HARD_CLAY)
Block(-6,6,-7,HARD_CLAY)
Block(-6,6,-6,HARD_CLAY)
Block(-6,6,-5,HARD_CLAY)
Block(-6,6,-4,HARD_CLAY)
Block(-6,6,-3,HARD_CLAY)
Block(-6,6,-2,HARD_CLAY)
Block(-6,6,-1,HARD_CLAY)
Block(-6,6,0,HARD_CLAY)
Block(-6,6,1,HARD_CLAY)
Block(-6,6,2,HARD_CLAY)
Block(-6,6,3,HARD_CLAY)
Block(-6,6,4,HARD_CLAY)
Block(-6,6,5,HARD_CLAY)
Block(-6,6,6,HARD_CLAY)
Block(-6,6,7,HARD_CLAY)
Block(-6,6,8,HARD_CLAY)
Block(-6,6,9,HARD_CLAY)
Block(-6,6,10,HARD_CLAY)
Block(-6,7,-11,HARD_CLAY)
Block(-6,7,-10,HARD_CLAY)
Block(-6,7,-9,HARD_CLAY)
Block(-6,7,-8,HARD_CLAY)
Block(-6,7,-7,HARD_CLAY)
Block(-6,7,-6,HARD_CLAY)
Block(-6,7,-5,HARD_CLAY)
Block(-6,7,-4,HARD_CLAY)
Block(-6,7,-3,HARD_CLAY)
Block(-6,7,-2,HARD_CLAY)
Block(-6,7,-1,HARD_CLAY)
Block(-6,7,0,HARD_CLAY)
Block(-6,7,1,HARD_CLAY)
Block(-6,7,2,HARD_CLAY)
Block(-6,7,3,HARD_CLAY)
Block(-6,7,4,HARD_CLAY)
Block(-6,7,5,HARD_CLAY)
Block(-6,7,6,HARD_CLAY)
Block(-6,7,7,HARD_CLAY)
Block(-6,7,8,HARD_CLAY)
Block(-6,7,9,HARD_CLAY)
Block(-6,7,10,HARD_CLAY)
Block(-6,8,-10,HARD_CLAY)
Block(-6,8,-9,HARD_CLAY)
Block(-6,8,-8,HARD_CLAY)
Block(-6,8,-7,HARD_CLAY)
Block(-6,8,-6,HARD_CLAY)
Block(-6,8,-5,HARD_CLAY)
Block(-6,8,-4,HARD_CLAY)
Block(-6,8,-3,HARD_CLAY)
Block(-6,8,-2,HARD_CLAY)
Block(-6,8,-1,HARD_CLAY)
Block(-6,8,0,HARD_CLAY)
Block(-6,8,1,HARD_CLAY)
Block(-6,8,2,HARD_CLAY)
Block(-6,8,3,HARD_CLAY)
Block(-6,8,4,HARD_CLAY)
Block(-6,8,5,HARD_CLAY)
Block(-6,8,6,HARD_CLAY)
Block(-6,8,7,HARD_CLAY)
Block(-6,8,8,HARD_CLAY)
Block(-6,8,9,HARD_CLAY)
Block(-6,8,10,HARD_CLAY)
Block(-6,9,-10,HARD_CLAY)
Block(-6,9,-9,HARD_CLAY)
Block(-6,9,-8,HARD_CLAY)
Block(-6,9,-7,HARD_CLAY)
Block(-6,9,-6,HARD_CLAY)
Block(-6,9,-5,HARD_CLAY)
Block(-6,9,-4,HARD_CLAY)
Block(-6,9,-3,HARD_CLAY)
Block(-6,9,-2,HARD_CLAY)
Block(-6,9,-1,HARD_CLAY)
Block(-6,9,0,HARD_CLAY)
Block(-6,9,1,HARD_CLAY)
Block(-6,9,2,HARD_CLAY)
Block(-6,9,3,HARD_CLAY)
Block(-6,9,4,HARD_CLAY)
Block(-6,9,5,HARD_CLAY)
Block(-6,9,6,HARD_CLAY)
Block(-6,9,7,HARD_CLAY)
Block(-6,9,8,HARD_CLAY)
Block(-6,9,9,HARD_CLAY)
Block(-6,10,-10,HARD_CLAY)
Block(-6,10,-9,HARD_CLAY)
Block(-6,10,-8,HARD_CLAY)
Block(-6,10,-7,HARD_CLAY)
Block(-6,10,-6,HARD_CLAY)
Block(-6,10,-5,HARD_CLAY)
Block(-6,10,-4,HARD_CLAY)
Block(-6,10,-3,HARD_CLAY)
Block(-6,10,-2,HARD_CLAY)
Block(-6,10,-1,HARD_CLAY)
Block(-6,10,0,HARD_CLAY)
Block(-6,10,1,HARD_CLAY)
Block(-6,10,2,HARD_CLAY)
Block(-6,10,3,HARD_CLAY)
Block(-6,10,4,HARD_CLAY)
Block(-6,10,5,HARD_CLAY)
Block(-6,10,6,HARD_CLAY)
Block(-6,10,7,HARD_CLAY)
Block(-6,10,8,HARD_CLAY)
Block(-6,10,9,HARD_CLAY)
Block(-6,11,-10,HARD_CLAY)
Block(-6,11,-9,HARD_CLAY)
Block(-6,11,-8,HARD_CLAY)
Block(-6,11,-7,HARD_CLAY)
Block(-6,11,-6,HARD_CLAY)
Block(-6,11,-5,HARD_CLAY)
Block(-6,11,-4,HARD_CLAY)
Block(-6,11,-3,HARD_CLAY)
Block(-6,11,-2,HARD_CLAY)
Block(-6,11,-1,HARD_CLAY)
Block(-6,11,0,HARD_CLAY)
Block(-6,11,1,HARD_CLAY)
Block(-6,11,2,HARD_CLAY)
Block(-6,11,3,HARD_CLAY)
Block(-6,11,4,HARD_CLAY)
Block(-6,11,5,HARD_CLAY)
Block(-6,11,6,HARD_CLAY)
Block(-6,11,7,HARD_CLAY)
Block(-6,11,9,HARD_CLAY)
Block(-6,12,-10,HARD_CLAY)
Block(-6,12,-9,HARD_CLAY)
Block(-6,12,-8,HARD_CLAY)
Block(-6,12,-7,HARD_CLAY)
Block(-6,12,-6,HARD_CLAY)
Block(-6,12,-5,HARD_CLAY)
Block(-6,12,-4,HARD_CLAY)
Block(-6,12,-3,HARD_CLAY)
Block(-6,12,-2,HARD_CLAY)
Block(-6,12,-1,HARD_CLAY)
Block(-6,12,0,HARD_CLAY)
Block(-6,12,1,HARD_CLAY)
Block(-6,12,2,HARD_CLAY)
Block(-6,12,3,HARD_CLAY)
Block(-6,12,4,HARD_CLAY)
Block(-6,12,5,HARD_CLAY)
Block(-6,12,6,HARD_CLAY)
Block(-6,12,7,HARD_CLAY)
Block(-6,13,-10,HARD_CLAY)
Block(-6,13,-9,HARD_CLAY)
Block(-6,13,-8,HARD_CLAY)
Block(-6,13,-7,HARD_CLAY)
Block(-6,13,-6,HARD_CLAY)
Block(-6,13,-5,HARD_CLAY)
Block(-6,13,-4,HARD_CLAY)
Block(-6,13,-3,HARD_CLAY)
Block(-6,13,-2,HARD_CLAY)
Block(-6,13,-1,HARD_CLAY)
Block(-6,13,0,HARD_CLAY)
Block(-6,13,1,HARD_CLAY)
Block(-6,13,2,HARD_CLAY)
Block(-6,13,3,HARD_CLAY)
Block(-6,13,4,HARD_CLAY)
Block(-6,13,5,HARD_CLAY)
Block(-6,13,6,HARD_CLAY)
Block(-6,13,7,HARD_CLAY)
Block(-6,14,-9,HARD_CLAY)
Block(-6,14,-8,HARD_CLAY)
Block(-6,14,-7,HARD_CLAY)
Block(-6,14,-5,HARD_CLAY)
Block(-6,14,-4,HARD_CLAY)
Block(-6,14,-3,HARD_CLAY)
Block(-6,14,-2,HARD_CLAY)
Block(-6,14,-1,HARD_CLAY)
Block(-6,14,0,HARD_CLAY)
Block(-6,14,1,HARD_CLAY)
Block(-6,14,2,HARD_CLAY)
Block(-6,14,3,HARD_CLAY)
Block(-6,14,4,HARD_CLAY)
Block(-6,14,5,HARD_CLAY)
Block(-6,14,6,HARD_CLAY)
Block(-6,15,-9,HARD_CLAY)
Block(-6,15,-8,HARD_CLAY)
Block(-6,15,-5,HARD_CLAY)
Block(-6,15,-4,HARD_CLAY)
Block(-6,15,-3,HARD_CLAY)
Block(-6,15,-2,HARD_CLAY)
Block(-6,15,-1,HARD_CLAY)
Block(-6,15,0,HARD_CLAY)
Block(-6,15,1,HARD_CLAY)
Block(-6,15,2,HARD_CLAY)
Block(-6,15,3,HARD_CLAY)
Block(-6,15,4,HARD_CLAY)
Block(-6,15,5,HARD_CLAY)
Block(-6,15,6,HARD_CLAY)
Block(-6,16,-9,HARD_CLAY)
Block(-6,16,-8,HARD_CLAY)
Block(-6,16,-5,HARD_CLAY)
Block(-6,16,-4,HARD_CLAY)
Block(-6,16,-3,HARD_CLAY)
Block(-6,16,-2,HARD_CLAY)
Block(-6,16,-1,HARD_CLAY)
Block(-6,16,0,HARD_CLAY)
Block(-6,16,1,HARD_CLAY)
Block(-6,16,2,HARD_CLAY)
Block(-6,16,3,HARD_CLAY)
Block(-6,16,4,HARD_CLAY)
Block(-6,16,5,HARD_CLAY)
Block(-6,17,-9,HARD_CLAY)
Block(-6,17,-5,HARD_CLAY)
Block(-6,17,-4,HARD_CLAY)
Block(-6,17,-3,HARD_CLAY)
Block(-6,17,-2,HARD_CLAY)
Block(-6,17,-1,HARD_CLAY)
Block(-6,17,0,HARD_CLAY)
Block(-6,17,1,HARD_CLAY)
Block(-6,17,2,HARD_CLAY)
Block(-6,17,3,HARD_CLAY)
Block(-6,17,4,HARD_CLAY)
Block(-6,17,5,HARD_CLAY)
Block(-6,18,-5,HARD_CLAY)
Block(-6,18,-4,HARD_CLAY)
Block(-6,18,-3,HARD_CLAY)
Block(-6,18,-2,HARD_CLAY)
Block(-6,18,-1,HARD_CLAY)
Block(-6,18,0,HARD_CLAY)
Block(-6,18,1,HARD_CLAY)
Block(-6,18,2,HARD_CLAY)
Block(-6,18,3,HARD_CLAY)
Block(-6,18,4,HARD_CLAY)
Block(-6,18,5,HARD_CLAY)
Block(-6,19,-5,HARD_CLAY)
Block(-6,19,-4,HARD_CLAY)
Block(-6,19,-3,HARD_CLAY)
Block(-6,19,-2,HARD_CLAY)
Block(-6,19,-1,HARD_CLAY)
Block(-6,19,0,HARD_CLAY)
Block(-6,19,1,HARD_CLAY)
Block(-6,19,2,HARD_CLAY)
Block(-6,19,3,HARD_CLAY)
Block(-6,19,4,HARD_CLAY)
Block(-6,19,5,HARD_CLAY)
Block(-6,20,-5,HARD_CLAY)
Block(-6,20,-4,HARD_CLAY)
Block(-6,20,-3,HARD_CLAY)
Block(-6,20,-2,HARD_CLAY)
Block(-6,20,-1,HARD_CLAY)
Block(-6,20,0,HARD_CLAY)
Block(-6,20,1,HARD_CLAY)
Block(-6,20,2,HARD_CLAY)
Block(-6,20,3,HARD_CLAY)
Block(-6,20,4,HARD_CLAY)
Block(-6,20,5,HARD_CLAY)
Block(-6,21,-5,HARD_CLAY)
Block(-6,21,-4,HARD_CLAY)
Block(-6,21,-3,HARD_CLAY)
Block(-6,21,-2,HARD_CLAY)
Block(-6,21,-1,HARD_CLAY)
Block(-6,21,0,HARD_CLAY)
Block(-6,21,1,HARD_CLAY)
Block(-6,21,2,HARD_CLAY)
Block(-6,21,3,HARD_CLAY)
Block(-6,21,4,HARD_CLAY)
Block(-6,21,5,HARD_CLAY)
Block(-6,22,-4,HARD_CLAY)
Block(-6,22,-3,HARD_CLAY)
Block(-6,22,-2,HARD_CLAY)
Block(-6,22,-1,HARD_CLAY)
Block(-6,22,0,HARD_CLAY)
Block(-6,22,1,HARD_CLAY)
Block(-6,22,2,HARD_CLAY)
Block(-6,22,3,HARD_CLAY)
Block(-6,22,4,HARD_CLAY)
Block(-6,22,5,HARD_CLAY)
Block(-6,23,-4,HARD_CLAY)
Block(-6,23,-3,HARD_CLAY)
Block(-6,23,-2,HARD_CLAY)
Block(-6,23,-1,HARD_CLAY)
Block(-6,23,0,HARD_CLAY)
Block(-6,23,1,HARD_CLAY)
Block(-6,23,2,HARD_CLAY)
Block(-6,23,3,HARD_CLAY)
Block(-6,23,4,HARD_CLAY)
Block(-6,23,5,HARD_CLAY)
Block(-6,24,-4,HARD_CLAY)
Block(-6,24,-3,HARD_CLAY)
Block(-6,24,-2,HARD_CLAY)
Block(-6,24,-1,HARD_CLAY)
Block(-6,24,0,HARD_CLAY)
Block(-6,24,1,HARD_CLAY)
Block(-6,24,2,HARD_CLAY)
Block(-6,24,3,HARD_CLAY)
Block(-6,24,4,HARD_CLAY)
Block(-6,24,5,HARD_CLAY)
Block(-6,25,-4,HARD_CLAY)
Block(-6,25,-3,HARD_CLAY)
Block(-6,25,-1,HARD_CLAY)
Block(-6,25,0,HARD_CLAY)
Block(-6,25,1,HARD_CLAY)
Block(-6,25,2,HARD_CLAY)
Block(-6,25,3,HARD_CLAY)
Block(-6,25,4,HARD_CLAY)
Block(-6,25,5,HARD_CLAY)
Block(-6,26,-4,HARD_CLAY)
Block(-6,26,-3,HARD_CLAY)
Block(-6,26,-1,HARD_CLAY)
Block(-6,26,0,HARD_CLAY)
Block(-6,26,1,HARD_CLAY)
Block(-6,26,2,HARD_CLAY)
Block(-6,26,3,HARD_CLAY)
Block(-6,26,4,HARD_CLAY)
Block(-6,26,5,HARD_CLAY)
Block(-6,27,-4,HARD_CLAY)
Block(-6,27,-3,HARD_CLAY)
Block(-6,27,-1,HARD_CLAY)
Block(-6,27,0,HARD_CLAY)
Block(-6,27,1,HARD_CLAY)
Block(-6,27,2,HARD_CLAY)
Block(-6,27,3,HARD_CLAY)
Block(-6,27,4,HARD_CLAY)
Block(-6,27,5,HARD_CLAY)
Block(-6,28,-4,HARD_CLAY)
Block(-6,28,-3,HARD_CLAY)
Block(-6,28,-1,HARD_CLAY)
Block(-6,28,0,HARD_CLAY)
Block(-6,28,1,HARD_CLAY)
Block(-6,28,2,HARD_CLAY)
Block(-6,28,3,HARD_CLAY)
Block(-6,28,4,HARD_CLAY)
Block(-6,28,5,HARD_CLAY)
Block(-6,29,-4,HARD_CLAY)
Block(-6,29,-3,HARD_CLAY)
Block(-6,29,-1,HARD_CLAY)
Block(-6,29,0,HARD_CLAY)
Block(-6,29,1,HARD_CLAY)
Block(-6,29,2,HARD_CLAY)
Block(-6,29,3,HARD_CLAY)
Block(-6,29,4,HARD_CLAY)
Block(-6,29,5,HARD_CLAY)
Block(-6,30,-4,HARD_CLAY)
Block(-6,30,-3,HARD_CLAY)
Block(-6,30,-1,HARD_CLAY)
Block(-6,30,0,HARD_CLAY)
Block(-6,30,1,HARD_CLAY)
Block(-6,30,2,HARD_CLAY)
Block(-6,30,3,HARD_CLAY)
Block(-6,30,4,HARD_CLAY)
Block(-6,30,5,HARD_CLAY)
Block(-6,31,-4,HARD_CLAY)
Block(-6,31,-3,HARD_CLAY)
Block(-6,31,-1,HARD_CLAY)
Block(-6,31,0,HARD_CLAY)
Block(-6,31,1,HARD_CLAY)
Block(-6,31,2,HARD_CLAY)
Block(-6,31,3,HARD_CLAY)
Block(-6,31,4,SAND:1)
Block(-6,31,5,HARD_CLAY)
Block(-6,32,-3,HARD_CLAY)
Block(-6,32,-1,HARD_CLAY)
Block(-6,32,0,HARD_CLAY)
Block(-6,33,-1,HARD_CLAY)
Block(-6,33,0,HARD_CLAY)
Block(-6,34,-1,HARD_CLAY)
Block(-6,34,0,HARD_CLAY)
Block(-6,35,-1,HARD_CLAY)
Block(-6,35,0,HARD_CLAY)
Block(-6,36,-1,HARD_CLAY)
Block(-6,36,0,HARD_CLAY)
Block(-6,37,-1,HARD_CLAY)
Block(-6,37,0,HARD_CLAY)
Block(-6,38,-1,HARD_CLAY)
Block(-5,0,-13,HARD_CLAY)
Block(-5,0,-12,HARD_CLAY)
Block(-5,0,-11,HARD_CLAY)
Block(-5,0,-10,HARD_CLAY)
Block(-5,0,-9,HARD_CLAY)
Block(-5,0,-8,HARD_CLAY)
Block(-5,0,-7,HARD_CLAY)
Block(-5,0,-6,HARD_CLAY)
Block(-5,0,-5,HARD_CLAY)
Block(-5,0,-4,HARD_CLAY)
Block(-5,0,-3,HARD_CLAY)
Block(-5,0,-2,HARD_CLAY)
Block(-5,0,-1,HARD_CLAY)
Block(-5,0,0,HARD_CLAY)
Block(-5,0,1,HARD_CLAY)
Block(-5,0,2,HARD_CLAY)
Block(-5,0,3,HARD_CLAY)
Block(-5,0,4,HARD_CLAY)
Block(-5,0,5,HARD_CLAY)
Block(-5,0,6,HARD_CLAY)
Block(-5,0,7,HARD_CLAY)
Block(-5,0,8,HARD_CLAY)
Block(-5,0,9,HARD_CLAY)
Block(-5,0,10,HARD_CLAY)
Block(-5,0,11,HARD_CLAY)
Block(-5,0,12,HARD_CLAY)
Block(-5,0,13,HARD_CLAY)
Block(-5,0,14,HARD_CLAY)
Block(-5,0,15,HARD_CLAY)
Block(-5,1,-12,HARD_CLAY)
Block(-5,1,-11,HARD_CLAY)
Block(-5,1,-10,HARD_CLAY)
Block(-5,1,-9,HARD_CLAY)
Block(-5,1,-8,HARD_CLAY)
Block(-5,1,-7,HARD_CLAY)
Block(-5,1,-6,HARD_CLAY)
Block(-5,1,-5,HARD_CLAY)
Block(-5,1,-4,HARD_CLAY)
Block(-5,1,-3,HARD_CLAY)
Block(-5,1,-2,HARD_CLAY)
Block(-5,1,-1,HARD_CLAY)
Block(-5,1,0,HARD_CLAY)
Block(-5,1,1,HARD_CLAY)
Block(-5,1,2,HARD_CLAY)
Block(-5,1,3,HARD_CLAY)
Block(-5,1,4,HARD_CLAY)
Block(-5,1,5,HARD_CLAY)
Block(-5,1,6,HARD_CLAY)
Block(-5,1,7,HARD_CLAY)
Block(-5,1,8,HARD_CLAY)
Block(-5,1,9,HARD_CLAY)
Block(-5,1,10,HARD_CLAY)
Block(-5,1,11,HARD_CLAY)
Block(-5,1,12,HARD_CLAY)
Block(-5,1,13,HARD_CLAY)
Block(-5,2,-12,HARD_CLAY)
Block(-5,2,-11,HARD_CLAY)
Block(-5,2,-10,HARD_CLAY)
Block(-5,2,-9,HARD_CLAY)
Block(-5,2,-8,HARD_CLAY)
Block(-5,2,-7,HARD_CLAY)
Block(-5,2,-6,HARD_CLAY)
Block(-5,2,-5,HARD_CLAY)
Block(-5,2,-4,HARD_CLAY)
Block(-5,2,-3,HARD_CLAY)
Block(-5,2,-2,HARD_CLAY)
Block(-5,2,-1,HARD_CLAY)
Block(-5,2,0,HARD_CLAY)
Block(-5,2,1,HARD_CLAY)
Block(-5,2,2,HARD_CLAY)
Block(-5,2,3,HARD_CLAY)
Block(-5,2,4,HARD_CLAY)
Block(-5,2,5,HARD_CLAY)
Block(-5,2,6,HARD_CLAY)
Block(-5,2,7,HARD_CLAY)
Block(-5,2,8,HARD_CLAY)
Block(-5,2,9,HARD_CLAY)
Block(-5,2,10,HARD_CLAY)
Block(-5,2,11,HARD_CLAY)
Block(-5,2,12,HARD_CLAY)
Block(-5,2,13,HARD_CLAY)
Block(-5,3,-12,HARD_CLAY)
Block(-5,3,-11,HARD_CLAY)
Block(-5,3,-10,HARD_CLAY)
Block(-5,3,-9,HARD_CLAY)
Block(-5,3,-8,HARD_CLAY)
Block(-5,3,-7,HARD_CLAY)
Block(-5,3,-6,HARD_CLAY)
Block(-5,3,-5,HARD_CLAY)
Block(-5,3,-4,HARD_CLAY)
Block(-5,3,-3,HARD_CLAY)
Block(-5,3,-2,HARD_CLAY)
Block(-5,3,-1,HARD_CLAY)
Block(-5,3,0,HARD_CLAY)
Block(-5,3,1,HARD_CLAY)
Block(-5,3,2,HARD_CLAY)
Block(-5,3,3,HARD_CLAY)
Block(-5,3,4,HARD_CLAY)
Block(-5,3,5,HARD_CLAY)
Block(-5,3,6,HARD_CLAY)
Block(-5,3,7,HARD_CLAY)
Block(-5,3,8,HARD_CLAY)
Block(-5,3,9,HARD_CLAY)
Block(-5,3,10,HARD_CLAY)
Block(-5,3,11,HARD_CLAY)
Block(-5,3,12,HARD_CLAY)
Block(-5,4,-12,HARD_CLAY)
Block(-5,4,-11,HARD_CLAY)
Block(-5,4,-10,HARD_CLAY)
Block(-5,4,-9,HARD_CLAY)
Block(-5,4,-8,HARD_CLAY)
Block(-5,4,-7,HARD_CLAY)
Block(-5,4,-6,HARD_CLAY)
Block(-5,4,-5,HARD_CLAY)
Block(-5,4,-4,HARD_CLAY)
Block(-5,4,-3,HARD_CLAY)
Block(-5,4,-2,HARD_CLAY)
Block(-5,4,-1,HARD_CLAY)
Block(-5,4,0,HARD_CLAY)
Block(-5,4,1,HARD_CLAY)
Block(-5,4,2,HARD_CLAY)
Block(-5,4,3,HARD_CLAY)
Block(-5,4,4,HARD_CLAY)
Block(-5,4,5,HARD_CLAY)
Block(-5,4,6,HARD_CLAY)
Block(-5,4,7,HARD_CLAY)
Block(-5,4,8,HARD_CLAY)
Block(-5,4,9,HARD_CLAY)
Block(-5,4,10,HARD_CLAY)
Block(-5,4,11,HARD_CLAY)
Block(-5,4,12,HARD_CLAY)
Block(-5,5,-11,HARD_CLAY)
Block(-5,5,-10,HARD_CLAY)
Block(-5,5,-9,HARD_CLAY)
Block(-5,5,-8,HARD_CLAY)
Block(-5,5,-7,HARD_CLAY)
Block(-5,5,-6,HARD_CLAY)
Block(-5,5,-5,HARD_CLAY)
Block(-5,5,-4,HARD_CLAY)
Block(-5,5,-3,HARD_CLAY)
Block(-5,5,-2,HARD_CLAY)
Block(-5,5,-1,HARD_CLAY)
Block(-5,5,0,HARD_CLAY)
Block(-5,5,1,HARD_CLAY)
Block(-5,5,2,HARD_CLAY)
Block(-5,5,3,HARD_CLAY)
Block(-5,5,4,HARD_CLAY)
Block(-5,5,5,HARD_CLAY)
Block(-5,5,6,HARD_CLAY)
Block(-5,5,7,HARD_CLAY)
Block(-5,5,8,HARD_CLAY)
Block(-5,5,9,HARD_CLAY)
Block(-5,5,10,HARD_CLAY)
Block(-5,5,11,HARD_CLAY)
Block(-5,5,12,HARD_CLAY)
Block(-5,6,-10,HARD_CLAY)
Block(-5,6,-9,HARD_CLAY)
Block(-5,6,-8,HARD_CLAY)
Block(-5,6,-7,HARD_CLAY)
Block(-5,6,-6,HARD_CLAY)
Block(-5,6,-5,HARD_CLAY)
Block(-5,6,-4,HARD_CLAY)
Block(-5,6,-3,HARD_CLAY)
Block(-5,6,-2,HARD_CLAY)
Block(-5,6,-1,HARD_CLAY)
Block(-5,6,0,HARD_CLAY)
Block(-5,6,1,HARD_CLAY)
Block(-5,6,2,HARD_CLAY)
Block(-5,6,3,HARD_CLAY)
Block(-5,6,4,HARD_CLAY)
Block(-5,6,5,HARD_CLAY)
Block(-5,6,6,HARD_CLAY)
Block(-5,6,7,HARD_CLAY)
Block(-5,6,8,HARD_CLAY)
Block(-5,6,9,HARD_CLAY)
Block(-5,6,10,HARD_CLAY)
Block(-5,6,11,HARD_CLAY)
Block(-5,6,12,HARD_CLAY)
Block(-5,7,-10,HARD_CLAY)
Block(-5,7,-9,HARD_CLAY)
Block(-5,7,-8,HARD_CLAY)
Block(-5,7,-7,HARD_CLAY)
Block(-5,7,-6,HARD_CLAY)
Block(-5,7,-5,HARD_CLAY)
Block(-5,7,-4,HARD_CLAY)
Block(-5,7,-3,HARD_CLAY)
Block(-5,7,-2,HARD_CLAY)
Block(-5,7,-1,HARD_CLAY)
Block(-5,7,0,HARD_CLAY)
Block(-5,7,1,HARD_CLAY)
Block(-5,7,2,HARD_CLAY)
Block(-5,7,3,HARD_CLAY)
Block(-5,7,4,HARD_CLAY)
Block(-5,7,5,HARD_CLAY)
Block(-5,7,6,HARD_CLAY)
Block(-5,7,7,HARD_CLAY)
Block(-5,7,8,HARD_CLAY)
Block(-5,7,9,HARD_CLAY)
Block(-5,7,10,HARD_CLAY)
Block(-5,7,11,HARD_CLAY)
Block(-5,8,-10,HARD_CLAY)
Block(-5,8,-9,HARD_CLAY)
Block(-5,8,-8,HARD_CLAY)
Block(-5,8,-7,HARD_CLAY)
Block(-5,8,-6,HARD_CLAY)
Block(-5,8,-5,HARD_CLAY)
Block(-5,8,-4,HARD_CLAY)
Block(-5,8,-3,HARD_CLAY)
Block(-5,8,-2,HARD_CLAY)
Block(-5,8,-1,HARD_CLAY)
Block(-5,8,0,HARD_CLAY)
Block(-5,8,1,HARD_CLAY)
Block(-5,8,2,HARD_CLAY)
Block(-5,8,3,HARD_CLAY)
Block(-5,8,4,HARD_CLAY)
Block(-5,8,5,HARD_CLAY)
Block(-5,8,6,HARD_CLAY)
Block(-5,8,7,HARD_CLAY)
Block(-5,8,8,HARD_CLAY)
Block(-5,8,9,HARD_CLAY)
Block(-5,8,10,HARD_CLAY)
Block(-5,8,11,HARD_CLAY)
Block(-5,9,-10,HARD_CLAY)
Block(-5,9,-9,HARD_CLAY)
Block(-5,9,-8,HARD_CLAY)
Block(-5,9,-7,HARD_CLAY)
Block(-5,9,-6,HARD_CLAY)
Block(-5,9,-5,HARD_CLAY)
Block(-5,9,-4,HARD_CLAY)
Block(-5,9,-3,HARD_CLAY)
Block(-5,9,-2,HARD_CLAY)
Block(-5,9,-1,HARD_CLAY)
Block(-5,9,0,HARD_CLAY)
Block(-5,9,1,HARD_CLAY)
Block(-5,9,2,HARD_CLAY)
Block(-5,9,3,HARD_CLAY)
Block(-5,9,4,HARD_CLAY)
Block(-5,9,5,HARD_CLAY)
Block(-5,9,6,HARD_CLAY)
Block(-5,9,7,HARD_CLAY)
Block(-5,9,8,HARD_CLAY)
Block(-5,9,9,HARD_CLAY)
Block(-5,9,10,HARD_CLAY)
Block(-5,9,11,HARD_CLAY)
Block(-5,10,-10,HARD_CLAY)
Block(-5,10,-9,HARD_CLAY)
Block(-5,10,-8,HARD_CLAY)
Block(-5,10,-7,HARD_CLAY)
Block(-5,10,-6,HARD_CLAY)
Block(-5,10,-5,HARD_CLAY)
Block(-5,10,-4,HARD_CLAY)
Block(-5,10,-3,HARD_CLAY)
Block(-5,10,-2,HARD_CLAY)
Block(-5,10,-1,HARD_CLAY)
Block(-5,10,0,HARD_CLAY)
Block(-5,10,1,HARD_CLAY)
Block(-5,10,2,HARD_CLAY)
Block(-5,10,3,HARD_CLAY)
Block(-5,10,4,HARD_CLAY)
Block(-5,10,5,HARD_CLAY)
Block(-5,10,6,HARD_CLAY)
Block(-5,10,7,HARD_CLAY)
Block(-5,10,8,HARD_CLAY)
Block(-5,10,9,HARD_CLAY)
Block(-5,10,10,HARD_CLAY)
Block(-5,10,11,HARD_CLAY)
Block(-5,11,-10,HARD_CLAY)
Block(-5,11,-9,HARD_CLAY)
Block(-5,11,-8,HARD_CLAY)
Block(-5,11,-7,HARD_CLAY)
Block(-5,11,-6,HARD_CLAY)
Block(-5,11,-5,HARD_CLAY)
Block(-5,11,-4,HARD_CLAY)
Block(-5,11,-3,HARD_CLAY)
Block(-5,11,-2,HARD_CLAY)
Block(-5,11,-1,HARD_CLAY)
Block(-5,11,0,HARD_CLAY)
Block(-5,11,1,HARD_CLAY)
Block(-5,11,2,HARD_CLAY)
Block(-5,11,3,HARD_CLAY)
Block(-5,11,4,HARD_CLAY)
Block(-5,11,5,HARD_CLAY)
Block(-5,11,6,HARD_CLAY)
Block(-5,11,7,HARD_CLAY)
Block(-5,11,8,HARD_CLAY)
Block(-5,11,9,HARD_CLAY)
Block(-5,11,10,HARD_CLAY)
Block(-5,11,11,HARD_CLAY)
Block(-5,12,-10,HARD_CLAY)
Block(-5,12,-9,HARD_CLAY)
Block(-5,12,-8,HARD_CLAY)
Block(-5,12,-7,HARD_CLAY)
Block(-5,12,-6,HARD_CLAY)
Block(-5,12,-5,HARD_CLAY)
Block(-5,12,-4,HARD_CLAY)
Block(-5,12,-3,HARD_CLAY)
Block(-5,12,-2,HARD_CLAY)
Block(-5,12,-1,HARD_CLAY)
Block(-5,12,0,HARD_CLAY)
Block(-5,12,1,HARD_CLAY)
Block(-5,12,2,HARD_CLAY)
Block(-5,12,3,HARD_CLAY)
Block(-5,12,4,HARD_CLAY)
Block(-5,12,5,HARD_CLAY)
Block(-5,12,6,HARD_CLAY)
Block(-5,12,7,HARD_CLAY)
Block(-5,12,8,HARD_CLAY)
Block(-5,12,9,HARD_CLAY)
Block(-5,12,10,HARD_CLAY)
Block(-5,12,11,HARD_CLAY)
Block(-5,13,-10,HARD_CLAY)
Block(-5,13,-9,HARD_CLAY)
Block(-5,13,-8,HARD_CLAY)
Block(-5,13,-7,HARD_CLAY)
Block(-5,13,-6,HARD_CLAY)
Block(-5,13,-5,HARD_CLAY)
Block(-5,13,-4,HARD_CLAY)
Block(-5,13,-3,HARD_CLAY)
Block(-5,13,-2,HARD_CLAY)
Block(-5,13,-1,HARD_CLAY)
Block(-5,13,0,HARD_CLAY)
Block(-5,13,1,HARD_CLAY)
Block(-5,13,2,HARD_CLAY)
Block(-5,13,3,HARD_CLAY)
Block(-5,13,4,HARD_CLAY)
Block(-5,13,5,HARD_CLAY)
Block(-5,13,6,HARD_CLAY)
Block(-5,13,7,HARD_CLAY)
Block(-5,13,8,HARD_CLAY)
Block(-5,13,9,HARD_CLAY)
Block(-5,13,10,HARD_CLAY)
Block(-5,14,-9,HARD_CLAY)
Block(-5,14,-8,HARD_CLAY)
Block(-5,14,-7,HARD_CLAY)
Block(-5,14,-6,HARD_CLAY)
Block(-5,14,-5,HARD_CLAY)
Block(-5,14,-4,HARD_CLAY)
Block(-5,14,-3,HARD_CLAY)
Block(-5,14,-2,HARD_CLAY)
Block(-5,14,-1,HARD_CLAY)
Block(-5,14,0,HARD_CLAY)
Block(-5,14,1,HARD_CLAY)
Block(-5,14,2,HARD_CLAY)
Block(-5,14,3,HARD_CLAY)
Block(-5,14,4,HARD_CLAY)
Block(-5,14,5,HARD_CLAY)
Block(-5,14,6,HARD_CLAY)
Block(-5,14,7,HARD_CLAY)
Block(-5,14,8,HARD_CLAY)
Block(-5,14,9,HARD_CLAY)
Block(-5,14,10,HARD_CLAY)
Block(-5,15,-9,HARD_CLAY)
Block(-5,15,-8,HARD_CLAY)
Block(-5,15,-6,HARD_CLAY)
Block(-5,15,-5,HARD_CLAY)
Block(-5,15,-4,HARD_CLAY)
Block(-5,15,-3,HARD_CLAY)
Block(-5,15,-2,HARD_CLAY)
Block(-5,15,-1,HARD_CLAY)
Block(-5,15,0,HARD_CLAY)
Block(-5,15,1,HARD_CLAY)
Block(-5,15,2,HARD_CLAY)
Block(-5,15,3,HARD_CLAY)
Block(-5,15,4,HARD_CLAY)
Block(-5,15,5,HARD_CLAY)
Block(-5,15,6,HARD_CLAY)
Block(-5,15,7,HARD_CLAY)
Block(-5,16,-9,HARD_CLAY)
Block(-5,16,-8,HARD_CLAY)
Block(-5,16,-5,HARD_CLAY)
Block(-5,16,-4,HARD_CLAY)
Block(-5,16,-3,HARD_CLAY)
Block(-5,16,-2,HARD_CLAY)
Block(-5,16,-1,HARD_CLAY)
Block(-5,16,0,HARD_CLAY)
Block(-5,16,1,HARD_CLAY)
Block(-5,16,2,HARD_CLAY)
Block(-5,16,3,HARD_CLAY)
Block(-5,16,4,HARD_CLAY)
Block(-5,16,5,HARD_CLAY)
Block(-5,16,6,HARD_CLAY)
Block(-5,17,-9,HARD_CLAY)
Block(-5,17,-5,HARD_CLAY)
Block(-5,17,-4,HARD_CLAY)
Block(-5,17,-3,HARD_CLAY)
Block(-5,17,-2,HARD_CLAY)
Block(-5,17,-1,HARD_CLAY)
Block(-5,17,0,HARD_CLAY)
Block(-5,17,1,HARD_CLAY)
Block(-5,17,2,HARD_CLAY)
Block(-5,17,3,HARD_CLAY)
Block(-5,17,4,HARD_CLAY)
Block(-5,17,5,HARD_CLAY)
Block(-5,17,6,HARD_CLAY)
Block(-5,18,-9,HARD_CLAY)
Block(-5,18,-5,HARD_CLAY)
Block(-5,18,-4,HARD_CLAY)
Block(-5,18,-3,HARD_CLAY)
Block(-5,18,-2,HARD_CLAY)
Block(-5,18,-1,HARD_CLAY)
Block(-5,18,0,HARD_CLAY)
Block(-5,18,1,HARD_CLAY)
Block(-5,18,2,HARD_CLAY)
Block(-5,18,3,HARD_CLAY)
Block(-5,18,4,HARD_CLAY)
Block(-5,18,5,HARD_CLAY)
Block(-5,18,6,HARD_CLAY)
Block(-5,19,-5,HARD_CLAY)
Block(-5,19,-4,HARD_CLAY)
Block(-5,19,-3,HARD_CLAY)
Block(-5,19,-2,HARD_CLAY)
Block(-5,19,-1,HARD_CLAY)
Block(-5,19,0,HARD_CLAY)
Block(-5,19,1,HARD_CLAY)
Block(-5,19,2,HARD_CLAY)
Block(-5,19,3,HARD_CLAY)
Block(-5,19,4,HARD_CLAY)
Block(-5,19,5,HARD_CLAY)
Block(-5,19,6,HARD_CLAY)
Block(-5,20,-4,HARD_CLAY)
Block(-5,20,-3,HARD_CLAY)
Block(-5,20,-2,HARD_CLAY)
Block(-5,20,-1,HARD_CLAY)
Block(-5,20,0,HARD_CLAY)
Block(-5,20,1,HARD_CLAY)
Block(-5,20,2,HARD_CLAY)
Block(-5,20,3,HARD_CLAY)
Block(-5,20,4,HARD_CLAY)
Block(-5,20,5,HARD_CLAY)
Block(-5,20,6,HARD_CLAY)
Block(-5,21,-4,HARD_CLAY)
Block(-5,21,-3,HARD_CLAY)
Block(-5,21,-2,HARD_CLAY)
Block(-5,21,-1,HARD_CLAY)
Block(-5,21,0,HARD_CLAY)
Block(-5,21,1,HARD_CLAY)
Block(-5,21,2,HARD_CLAY)
Block(-5,21,3,HARD_CLAY)
Block(-5,21,4,HARD_CLAY)
Block(-5,21,5,HARD_CLAY)
Block(-5,21,6,HARD_CLAY)
Block(-5,22,-4,HARD_CLAY)
Block(-5,22,-3,HARD_CLAY)
Block(-5,22,-2,HARD_CLAY)
Block(-5,22,-1,HARD_CLAY)
Block(-5,22,0,HARD_CLAY)
Block(-5,22,1,HARD_CLAY)
Block(-5,22,2,HARD_CLAY)
Block(-5,22,3,HARD_CLAY)
Block(-5,22,4,HARD_CLAY)
Block(-5,22,5,HARD_CLAY)
Block(-5,23,-4,HARD_CLAY)
Block(-5,23,-3,HARD_CLAY)
Block(-5,23,-2,HARD_CLAY)
Block(-5,23,-1,HARD_CLAY)
Block(-5,23,0,HARD_CLAY)
Block(-5,23,1,HARD_CLAY)
Block(-5,23,2,HARD_CLAY)
Block(-5,23,3,HARD_CLAY)
Block(-5,23,4,HARD_CLAY)
Block(-5,23,5,HARD_CLAY)
Block(-5,24,-4,HARD_CLAY)
Block(-5,24,-3,HARD_CLAY)
Block(-5,24,-2,HARD_CLAY)
Block(-5,24,-1,HARD_CLAY)
Block(-5,24,0,HARD_CLAY)
Block(-5,24,1,HARD_CLAY)
Block(-5,24,2,HARD_CLAY)
Block(-5,24,3,HARD_CLAY)
Block(-5,24,4,HARD_CLAY)
Block(-5,24,5,HARD_CLAY)
Block(-5,25,-4,HARD_CLAY)
Block(-5,25,-3,HARD_CLAY)
Block(-5,25,-2,HARD_CLAY)
Block(-5,25,-1,HARD_CLAY)
Block(-5,25,0,HARD_CLAY)
Block(-5,25,1,HARD_CLAY)
Block(-5,25,2,HARD_CLAY)
Block(-5,25,3,HARD_CLAY)
Block(-5,25,4,HARD_CLAY)
Block(-5,25,5,HARD_CLAY)
Block(-5,26,-4,HARD_CLAY)
Block(-5,26,-3,HARD_CLAY)
Block(-5,26,-2,HARD_CLAY)
Block(-5,26,-1,HARD_CLAY)
Block(-5,26,0,HARD_CLAY)
Block(-5,26,1,HARD_CLAY)
Block(-5,26,2,HARD_CLAY)
Block(-5,26,3,HARD_CLAY)
Block(-5,26,4,HARD_CLAY)
Block(-5,26,5,HARD_CLAY)
Block(-5,27,-4,HARD_CLAY)
Block(-5,27,-3,HARD_CLAY)
Block(-5,27,-2,HARD_CLAY)
Block(-5,27,-1,HARD_CLAY)
Block(-5,27,0,HARD_CLAY)
Block(-5,27,1,HARD_CLAY)
Block(-5,27,2,HARD_CLAY)
Block(-5,27,3,HARD_CLAY)
Block(-5,27,4,HARD_CLAY)
Block(-5,27,5,HARD_CLAY)
Block(-5,28,-4,HARD_CLAY)
Block(-5,28,-3,HARD_CLAY)
Block(-5,28,-2,HARD_CLAY)
Block(-5,28,-1,HARD_CLAY)
Block(-5,28,0,HARD_CLAY)
Block(-5,28,1,HARD_CLAY)
Block(-5,28,2,HARD_CLAY)
Block(-5,28,3,HARD_CLAY)
Block(-5,28,4,HARD_CLAY)
Block(-5,28,5,HARD_CLAY)
Block(-5,29,-4,HARD_CLAY)
Block(-5,29,-3,HARD_CLAY)
Block(-5,29,-2,HARD_CLAY)
Block(-5,29,-1,HARD_CLAY)
Block(-5,29,0,HARD_CLAY)
Block(-5,29,1,HARD_CLAY)
Block(-5,29,2,HARD_CLAY)
Block(-5,29,3,HARD_CLAY)
Block(-5,29,4,HARD_CLAY)
Block(-5,29,5,HARD_CLAY)
Block(-5,30,-4,HARD_CLAY)
Block(-5,30,-3,HARD_CLAY)
Block(-5,30,-2,HARD_CLAY)
Block(-5,30,-1,HARD_CLAY)
Block(-5,30,0,HARD_CLAY)
Block(-5,30,1,HARD_CLAY)
Block(-5,30,2,HARD_CLAY)
Block(-5,30,3,HARD_CLAY)
Block(-5,30,4,HARD_CLAY)
Block(-5,30,5,HARD_CLAY)
Block(-5,31,-4,HARD_CLAY)
Block(-5,31,-3,HARD_CLAY)
Block(-5,31,-2,HARD_CLAY)
Block(-5,31,-1,HARD_CLAY)
Block(-5,31,0,HARD_CLAY)
Block(-5,31,1,HARD_CLAY)
Block(-5,31,2,HARD_CLAY)
Block(-5,31,3,HARD_CLAY)
Block(-5,31,4,HARD_CLAY)
Block(-5,31,5,HARD_CLAY)
Block(-5,32,-3,HARD_CLAY)
Block(-5,32,-2,HARD_CLAY)
Block(-5,32,-1,HARD_CLAY)
Block(-5,32,0,HARD_CLAY)
Block(-5,32,1,HARD_CLAY)
Block(-5,32,2,HARD_CLAY)
Block(-5,32,3,HARD_CLAY)
Block(-5,33,-2,HARD_CLAY)
Block(-5,33,-1,HARD_CLAY)
Block(-5,33,0,HARD_CLAY)
Block(-5,33,1,HARD_CLAY)
Block(-5,33,2,HARD_CLAY)
Block(-5,34,-2,HARD_CLAY)
Block(-5,34,-1,HARD_CLAY)
Block(-5,34,0,HARD_CLAY)
Block(-5,34,1,HARD_CLAY)
Block(-5,34,2,HARD_CLAY)
Block(-5,35,-2,HARD_CLAY)
Block(-5,35,-1,HARD_CLAY)
Block(-5,35,0,HARD_CLAY)
Block(-5,35,1,HARD_CLAY)
Block(-5,35,2,HARD_CLAY)
Block(-5,36,-1,HARD_CLAY)
Block(-5,36,0,HARD_CLAY)
Block(-5,36,1,HARD_CLAY)
Block(-5,36,2,HARD_CLAY)
Block(-5,37,-1,HARD_CLAY)
Block(-5,37,0,HARD_CLAY)
Block(-5,37,1,HARD_CLAY)
Block(-5,37,2,HARD_CLAY)
Block(-5,38,-1,HARD_CLAY)
Block(-5,38,0,HARD_CLAY)
Block(-5,38,1,HARD_CLAY)
Block(-5,39,-1,HARD_CLAY)
Block(-5,39,0,HARD_CLAY)
Block(-5,39,1,HARD_CLAY)
Block(-5,40,-1,HARD_CLAY)
Block(-5,40,0,HARD_CLAY)
Block(-5,40,1,HARD_CLAY)
Block(-5,41,-1,HARD_CLAY)
Block(-5,41,0,HARD_CLAY)
Block(-5,41,1,HARD_CLAY)
Block(-5,42,-1,HARD_CLAY)
Block(-5,42,0,HARD_CLAY)
Block(-5,42,1,HARD_CLAY)
Block(-5,43,-1,HARD_CLAY)
Block(-5,43,0,HARD_CLAY)
Block(-5,43,1,HARD_CLAY)
Block(-5,44,-1,HARD_CLAY)
Block(-5,44,0,HARD_CLAY)
Block(-5,44,1,HARD_CLAY)
Block(-5,45,-1,HARD_CLAY)
Block(-5,45,0,HARD_CLAY)
Block(-5,45,1,HARD_CLAY)
Block(-5,46,-1,HARD_CLAY)
Block(-5,46,0,HARD_CLAY)
Block(-5,46,1,HARD_CLAY)
Block(-5,47,-1,HARD_CLAY)
Block(-5,47,0,HARD_CLAY)
Block(-5,47,1,HARD_CLAY)
Block(-5,48,1,HARD_CLAY)
Block(-4,0,-13,HARD_CLAY)
Block(-4,0,-12,HARD_CLAY)
Block(-4,0,-11,HARD_CLAY)
Block(-4,0,-10,HARD_CLAY)
Block(-4,0,-9,HARD_CLAY)
Block(-4,0,-8,HARD_CLAY)
Block(-4,0,-7,HARD_CLAY)
Block(-4,0,-6,HARD_CLAY)
Block(-4,0,-5,HARD_CLAY)
Block(-4,0,-4,HARD_CLAY)
Block(-4,0,-3,HARD_CLAY)
Block(-4,0,-2,HARD_CLAY)
Block(-4,0,-1,HARD_CLAY)
Block(-4,0,0,HARD_CLAY)
Block(-4,0,1,HARD_CLAY)
Block(-4,0,2,HARD_CLAY)
Block(-4,0,3,HARD_CLAY)
Block(-4,0,4,HARD_CLAY)
Block(-4,0,5,HARD_CLAY)
Block(-4,0,6,HARD_CLAY)
Block(-4,0,7,HARD_CLAY)
Block(-4,0,8,HARD_CLAY)
Block(-4,0,9,HARD_CLAY)
Block(-4,0,10,HARD_CLAY)
Block(-4,0,11,HARD_CLAY)
Block(-4,0,12,HARD_CLAY)
Block(-4,0,13,HARD_CLAY)
Block(-4,0,14,HARD_CLAY)
Block(-4,1,-12,HARD_CLAY)
Block(-4,1,-11,HARD_CLAY)
Block(-4,1,-10,HARD_CLAY)
Block(-4,1,-9,HARD_CLAY)
Block(-4,1,-8,HARD_CLAY)
Block(-4,1,-7,HARD_CLAY)
Block(-4,1,-6,HARD_CLAY)
Block(-4,1,-5,HARD_CLAY)
Block(-4,1,-4,HARD_CLAY)
Block(-4,1,-3,HARD_CLAY)
Block(-4,1,-2,HARD_CLAY)
Block(-4,1,-1,HARD_CLAY)
Block(-4,1,0,HARD_CLAY)
Block(-4,1,1,HARD_CLAY)
Block(-4,1,2,HARD_CLAY)
Block(-4,1,3,HARD_CLAY)
Block(-4,1,4,HARD_CLAY)
Block(-4,1,5,HARD_CLAY)
Block(-4,1,6,HARD_CLAY)
Block(-4,1,7,HARD_CLAY)
Block(-4,1,8,HARD_CLAY)
Block(-4,1,9,HARD_CLAY)
Block(-4,1,10,HARD_CLAY)
Block(-4,1,11,HARD_CLAY)
Block(-4,1,12,HARD_CLAY)
Block(-4,1,13,HARD_CLAY)
Block(-4,2,-12,HARD_CLAY)
Block(-4,2,-11,HARD_CLAY)
Block(-4,2,-10,HARD_CLAY)
Block(-4,2,-9,HARD_CLAY)
Block(-4,2,-8,HARD_CLAY)
Block(-4,2,-7,HARD_CLAY)
Block(-4,2,-6,HARD_CLAY)
Block(-4,2,-5,HARD_CLAY)
Block(-4,2,-4,HARD_CLAY)
Block(-4,2,-3,HARD_CLAY)
Block(-4,2,-2,HARD_CLAY)
Block(-4,2,-1,HARD_CLAY)
Block(-4,2,0,HARD_CLAY)
Block(-4,2,1,HARD_CLAY)
Block(-4,2,2,HARD_CLAY)
Block(-4,2,3,HARD_CLAY)
Block(-4,2,4,HARD_CLAY)
Block(-4,2,5,HARD_CLAY)
Block(-4,2,6,HARD_CLAY)
Block(-4,2,7,HARD_CLAY)
Block(-4,2,8,HARD_CLAY)
Block(-4,2,9,HARD_CLAY)
Block(-4,2,10,HARD_CLAY)
Block(-4,2,11,HARD_CLAY)
Block(-4,2,12,HARD_CLAY)
Block(-4,2,13,HARD_CLAY)
Block(-4,3,-12,HARD_CLAY)
Block(-4,3,-11,HARD_CLAY)
Block(-4,3,-10,HARD_CLAY)
Block(-4,3,-9,HARD_CLAY)
Block(-4,3,-8,HARD_CLAY)
Block(-4,3,-7,HARD_CLAY)
Block(-4,3,-6,HARD_CLAY)
Block(-4,3,-5,HARD_CLAY)
Block(-4,3,-4,HARD_CLAY)
Block(-4,3,-3,HARD_CLAY)
Block(-4,3,-2,HARD_CLAY)
Block(-4,3,-1,HARD_CLAY)
Block(-4,3,0,HARD_CLAY)
Block(-4,3,1,HARD_CLAY)
Block(-4,3,2,HARD_CLAY)
Block(-4,3,3,HARD_CLAY)
Block(-4,3,4,HARD_CLAY)
Block(-4,3,5,HARD_CLAY)
Block(-4,3,6,HARD_CLAY)
Block(-4,3,7,HARD_CLAY)
Block(-4,3,8,HARD_CLAY)
Block(-4,3,9,HARD_CLAY)
Block(-4,3,10,HARD_CLAY)
Block(-4,3,11,HARD_CLAY)
Block(-4,3,12,HARD_CLAY)
Block(-4,3,13,HARD_CLAY)
Block(-4,4,-12,HARD_CLAY)
Block(-4,4,-11,HARD_CLAY)
Block(-4,4,-10,HARD_CLAY)
Block(-4,4,-9,HARD_CLAY)
Block(-4,4,-8,HARD_CLAY)
Block(-4,4,-7,HARD_CLAY)
Block(-4,4,-6,HARD_CLAY)
Block(-4,4,-5,HARD_CLAY)
Block(-4,4,-4,HARD_CLAY)
Block(-4,4,-3,HARD_CLAY)
Block(-4,4,-2,HARD_CLAY)
Block(-4,4,-1,HARD_CLAY)
Block(-4,4,0,HARD_CLAY)
Block(-4,4,1,HARD_CLAY)
Block(-4,4,2,HARD_CLAY)
Block(-4,4,3,HARD_CLAY)
Block(-4,4,4,HARD_CLAY)
Block(-4,4,5,HARD_CLAY)
Block(-4,4,6,HARD_CLAY)
Block(-4,4,7,HARD_CLAY)
Block(-4,4,8,HARD_CLAY)
Block(-4,4,9,HARD_CLAY)
Block(-4,4,10,HARD_CLAY)
Block(-4,4,11,HARD_CLAY)
Block(-4,4,12,HARD_CLAY)
Block(-4,5,-12,HARD_CLAY)
Block(-4,5,-11,HARD_CLAY)
Block(-4,5,-10,HARD_CLAY)
Block(-4,5,-9,HARD_CLAY)
Block(-4,5,-8,HARD_CLAY)
Block(-4,5,-7,HARD_CLAY)
Block(-4,5,-6,HARD_CLAY)
Block(-4,5,-5,HARD_CLAY)
Block(-4,5,-4,HARD_CLAY)
Block(-4,5,-3,HARD_CLAY)
Block(-4,5,-2,HARD_CLAY)
Block(-4,5,-1,HARD_CLAY)
Block(-4,5,0,HARD_CLAY)
Block(-4,5,1,HARD_CLAY)
Block(-4,5,2,HARD_CLAY)
Block(-4,5,3,HARD_CLAY)
Block(-4,5,4,HARD_CLAY)
Block(-4,5,5,HARD_CLAY)
Block(-4,5,6,HARD_CLAY)
Block(-4,5,7,HARD_CLAY)
Block(-4,5,8,HARD_CLAY)
Block(-4,5,9,HARD_CLAY)
Block(-4,5,10,HARD_CLAY)
Block(-4,5,11,HARD_CLAY)
Block(-4,5,12,HARD_CLAY)
Block(-4,6,-12,HARD_CLAY)
Block(-4,6,-11,HARD_CLAY)
Block(-4,6,-10,HARD_CLAY)
Block(-4,6,-9,HARD_CLAY)
Block(-4,6,-8,HARD_CLAY)
Block(-4,6,-7,HARD_CLAY)
Block(-4,6,-6,HARD_CLAY)
Block(-4,6,-5,HARD_CLAY)
Block(-4,6,-4,HARD_CLAY)
Block(-4,6,-3,HARD_CLAY)
Block(-4,6,-2,HARD_CLAY)
Block(-4,6,-1,HARD_CLAY)
Block(-4,6,0,HARD_CLAY)
Block(-4,6,1,HARD_CLAY)
Block(-4,6,2,HARD_CLAY)
Block(-4,6,3,HARD_CLAY)
Block(-4,6,4,HARD_CLAY)
Block(-4,6,5,HARD_CLAY)
Block(-4,6,6,HARD_CLAY)
Block(-4,6,7,HARD_CLAY)
Block(-4,6,8,HARD_CLAY)
Block(-4,6,9,HARD_CLAY)
Block(-4,6,10,HARD_CLAY)
Block(-4,6,11,HARD_CLAY)
Block(-4,6,12,HARD_CLAY)
Block(-4,7,-11,HARD_CLAY)
Block(-4,7,-10,HARD_CLAY)
Block(-4,7,-9,HARD_CLAY)
Block(-4,7,-8,HARD_CLAY)
Block(-4,7,-7,HARD_CLAY)
Block(-4,7,-6,HARD_CLAY)
Block(-4,7,-5,HARD_CLAY)
Block(-4,7,-4,HARD_CLAY)
Block(-4,7,-3,HARD_CLAY)
Block(-4,7,-2,HARD_CLAY)
Block(-4,7,-1,HARD_CLAY)
Block(-4,7,0,HARD_CLAY)
Block(-4,7,1,HARD_CLAY)
Block(-4,7,2,HARD_CLAY)
Block(-4,7,3,HARD_CLAY)
Block(-4,7,4,HARD_CLAY)
Block(-4,7,5,HARD_CLAY)
Block(-4,7,6,HARD_CLAY)
Block(-4,7,7,HARD_CLAY)
Block(-4,7,8,HARD_CLAY)
Block(-4,7,9,HARD_CLAY)
Block(-4,7,10,HARD_CLAY)
Block(-4,7,11,HARD_CLAY)
Block(-4,7,12,HARD_CLAY)
Block(-4,8,-11,HARD_CLAY)
Block(-4,8,-10,HARD_CLAY)
Block(-4,8,-9,HARD_CLAY)
Block(-4,8,-8,HARD_CLAY)
Block(-4,8,-7,HARD_CLAY)
Block(-4,8,-6,HARD_CLAY)
Block(-4,8,-5,HARD_CLAY)
Block(-4,8,-4,HARD_CLAY)
Block(-4,8,-3,HARD_CLAY)
Block(-4,8,-2,HARD_CLAY)
Block(-4,8,-1,HARD_CLAY)
Block(-4,8,0,HARD_CLAY)
Block(-4,8,1,HARD_CLAY)
Block(-4,8,2,HARD_CLAY)
Block(-4,8,3,HARD_CLAY)
Block(-4,8,4,HARD_CLAY)
Block(-4,8,5,HARD_CLAY)
Block(-4,8,6,HARD_CLAY)
Block(-4,8,7,HARD_CLAY)
Block(-4,8,8,HARD_CLAY)
Block(-4,8,9,HARD_CLAY)
Block(-4,8,10,HARD_CLAY)
Block(-4,8,11,HARD_CLAY)
Block(-4,8,12,HARD_CLAY)
Block(-4,9,-11,HARD_CLAY)
Block(-4,9,-10,HARD_CLAY)
Block(-4,9,-9,HARD_CLAY)
Block(-4,9,-8,HARD_CLAY)
Block(-4,9,-7,HARD_CLAY)
Block(-4,9,-6,HARD_CLAY)
Block(-4,9,-5,HARD_CLAY)
Block(-4,9,-4,HARD_CLAY)
Block(-4,9,-3,HARD_CLAY)
Block(-4,9,-2,HARD_CLAY)
Block(-4,9,-1,HARD_CLAY)
Block(-4,9,0,HARD_CLAY)
Block(-4,9,1,HARD_CLAY)
Block(-4,9,2,HARD_CLAY)
Block(-4,9,3,HARD_CLAY)
Block(-4,9,4,HARD_CLAY)
Block(-4,9,5,HARD_CLAY)
Block(-4,9,6,HARD_CLAY)
Block(-4,9,7,HARD_CLAY)
Block(-4,9,8,HARD_CLAY)
Block(-4,9,9,HARD_CLAY)
Block(-4,9,10,HARD_CLAY)
Block(-4,9,11,HARD_CLAY)
Block(-4,9,12,HARD_CLAY)
Block(-4,10,-11,HARD_CLAY)
Block(-4,10,-10,HARD_CLAY)
Block(-4,10,-9,HARD_CLAY)
Block(-4,10,-8,HARD_CLAY)
Block(-4,10,-7,HARD_CLAY)
Block(-4,10,-6,HARD_CLAY)
Block(-4,10,-5,HARD_CLAY)
Block(-4,10,-4,HARD_CLAY)
Block(-4,10,-3,HARD_CLAY)
Block(-4,10,-2,HARD_CLAY)
Block(-4,10,-1,HARD_CLAY)
Block(-4,10,0,HARD_CLAY)
Block(-4,10,1,HARD_CLAY)
Block(-4,10,2,HARD_CLAY)
Block(-4,10,3,HARD_CLAY)
Block(-4,10,4,HARD_CLAY)
Block(-4,10,5,HARD_CLAY)
Block(-4,10,6,HARD_CLAY)
Block(-4,10,7,HARD_CLAY)
Block(-4,10,8,HARD_CLAY)
Block(-4,10,9,HARD_CLAY)
Block(-4,10,10,HARD_CLAY)
Block(-4,10,11,HARD_CLAY)
Block(-4,10,12,HARD_CLAY)
Block(-4,11,-11,HARD_CLAY)
Block(-4,11,-10,HARD_CLAY)
Block(-4,11,-9,HARD_CLAY)
Block(-4,11,-8,HARD_CLAY)
Block(-4,11,-7,HARD_CLAY)
Block(-4,11,-6,HARD_CLAY)
Block(-4,11,-5,HARD_CLAY)
Block(-4,11,-4,HARD_CLAY)
Block(-4,11,-3,HARD_CLAY)
Block(-4,11,-2,HARD_CLAY)
Block(-4,11,-1,HARD_CLAY)
Block(-4,11,0,HARD_CLAY)
Block(-4,11,1,HARD_CLAY)
Block(-4,11,2,HARD_CLAY)
Block(-4,11,3,HARD_CLAY)
Block(-4,11,4,HARD_CLAY)
Block(-4,11,5,HARD_CLAY)
Block(-4,11,6,HARD_CLAY)
Block(-4,11,7,HARD_CLAY)
Block(-4,11,8,HARD_CLAY)
Block(-4,11,9,HARD_CLAY)
Block(-4,11,10,HARD_CLAY)
Block(-4,11,11,HARD_CLAY)
Block(-4,11,12,HARD_CLAY)
Block(-4,12,-11,HARD_CLAY)
Block(-4,12,-10,HARD_CLAY)
Block(-4,12,-9,HARD_CLAY)
Block(-4,12,-8,HARD_CLAY)
Block(-4,12,-7,HARD_CLAY)
Block(-4,12,-6,HARD_CLAY)
Block(-4,12,-5,HARD_CLAY)
Block(-4,12,-4,HARD_CLAY)
Block(-4,12,-3,HARD_CLAY)
Block(-4,12,-2,HARD_CLAY)
Block(-4,12,-1,HARD_CLAY)
Block(-4,12,0,HARD_CLAY)
Block(-4,12,1,HARD_CLAY)
Block(-4,12,2,HARD_CLAY)
Block(-4,12,3,HARD_CLAY)
Block(-4,12,4,HARD_CLAY)
Block(-4,12,5,HARD_CLAY)
Block(-4,12,6,HARD_CLAY)
Block(-4,12,7,HARD_CLAY)
Block(-4,12,8,HARD_CLAY)
Block(-4,12,9,HARD_CLAY)
Block(-4,12,10,HARD_CLAY)
Block(-4,12,11,HARD_CLAY)
Block(-4,12,12,HARD_CLAY)
Block(-4,13,-10,HARD_CLAY)
Block(-4,13,-9,HARD_CLAY)
Block(-4,13,-8,HARD_CLAY)
Block(-4,13,-7,HARD_CLAY)
Block(-4,13,-6,HARD_CLAY)
Block(-4,13,-5,HARD_CLAY)
Block(-4,13,-4,HARD_CLAY)
Block(-4,13,-3,HARD_CLAY)
Block(-4,13,-2,HARD_CLAY)
Block(-4,13,-1,HARD_CLAY)
Block(-4,13,0,HARD_CLAY)
Block(-4,13,1,HARD_CLAY)
Block(-4,13,2,HARD_CLAY)
Block(-4,13,3,HARD_CLAY)
Block(-4,13,4,HARD_CLAY)
Block(-4,13,5,HARD_CLAY)
Block(-4,13,6,HARD_CLAY)
Block(-4,13,7,HARD_CLAY)
Block(-4,13,8,HARD_CLAY)
Block(-4,13,9,HARD_CLAY)
Block(-4,13,10,HARD_CLAY)
Block(-4,14,-10,HARD_CLAY)
Block(-4,14,-9,HARD_CLAY)
Block(-4,14,-8,HARD_CLAY)
Block(-4,14,-7,HARD_CLAY)
Block(-4,14,-6,HARD_CLAY)
Block(-4,14,-5,HARD_CLAY)
Block(-4,14,-4,HARD_CLAY)
Block(-4,14,-3,HARD_CLAY)
Block(-4,14,-2,HARD_CLAY)
Block(-4,14,-1,HARD_CLAY)
Block(-4,14,0,HARD_CLAY)
Block(-4,14,1,HARD_CLAY)
Block(-4,14,2,HARD_CLAY)
Block(-4,14,3,HARD_CLAY)
Block(-4,14,4,HARD_CLAY)
Block(-4,14,5,HARD_CLAY)
Block(-4,14,6,HARD_CLAY)
Block(-4,14,7,HARD_CLAY)
Block(-4,14,8,HARD_CLAY)
Block(-4,14,9,HARD_CLAY)
Block(-4,14,10,HARD_CLAY)
Block(-4,15,-5,HARD_CLAY)
Block(-4,15,-4,HARD_CLAY)
Block(-4,15,-3,HARD_CLAY)
Block(-4,15,-2,HARD_CLAY)
Block(-4,15,-1,HARD_CLAY)
Block(-4,15,0,HARD_CLAY)
Block(-4,15,1,HARD_CLAY)
Block(-4,15,2,HARD_CLAY)
Block(-4,15,3,HARD_CLAY)
Block(-4,15,4,HARD_CLAY)
Block(-4,15,5,HARD_CLAY)
Block(-4,15,6,HARD_CLAY)
Block(-4,15,7,HARD_CLAY)
Block(-4,15,8,HARD_CLAY)
Block(-4,15,9,HARD_CLAY)
Block(-4,15,10,HARD_CLAY)
Block(-4,16,-5,HARD_CLAY)
Block(-4,16,-4,HARD_CLAY)
Block(-4,16,-3,HARD_CLAY)
Block(-4,16,-2,HARD_CLAY)
Block(-4,16,-1,HARD_CLAY)
Block(-4,16,0,HARD_CLAY)
Block(-4,16,1,HARD_CLAY)
Block(-4,16,2,HARD_CLAY)
Block(-4,16,3,HARD_CLAY)
Block(-4,16,4,HARD_CLAY)
Block(-4,16,5,HARD_CLAY)
Block(-4,16,6,HARD_CLAY)
Block(-4,16,7,HARD_CLAY)
Block(-4,16,8,HARD_CLAY)
Block(-4,16,9,HARD_CLAY)
Block(-4,17,-5,HARD_CLAY)
Block(-4,17,-4,HARD_CLAY)
Block(-4,17,-3,HARD_CLAY)
Block(-4,17,-2,HARD_CLAY)
Block(-4,17,-1,HARD_CLAY)
Block(-4,17,0,HARD_CLAY)
Block(-4,17,1,HARD_CLAY)
Block(-4,17,2,HARD_CLAY)
Block(-4,17,3,HARD_CLAY)
Block(-4,17,4,HARD_CLAY)
Block(-4,17,5,HARD_CLAY)
Block(-4,17,6,HARD_CLAY)
Block(-4,17,7,HARD_CLAY)
Block(-4,17,8,HARD_CLAY)
Block(-4,17,9,HARD_CLAY)
Block(-4,18,-5,HARD_CLAY)
Block(-4,18,-4,HARD_CLAY)
Block(-4,18,-3,HARD_CLAY)
Block(-4,18,-2,HARD_CLAY)
Block(-4,18,-1,HARD_CLAY)
Block(-4,18,0,HARD_CLAY)
Block(-4,18,1,HARD_CLAY)
Block(-4,18,2,HARD_CLAY)
Block(-4,18,3,HARD_CLAY)
Block(-4,18,4,HARD_CLAY)
Block(-4,18,5,HARD_CLAY)
Block(-4,18,6,HARD_CLAY)
Block(-4,18,7,HARD_CLAY)
Block(-4,18,8,HARD_CLAY)
Block(-4,18,9,HARD_CLAY)
Block(-4,19,-5,HARD_CLAY)
Block(-4,19,-4,HARD_CLAY)
Block(-4,19,-3,HARD_CLAY)
Block(-4,19,-2,HARD_CLAY)
Block(-4,19,-1,HARD_CLAY)
Block(-4,19,0,HARD_CLAY)
Block(-4,19,1,HARD_CLAY)
Block(-4,19,2,HARD_CLAY)
Block(-4,19,3,HARD_CLAY)
Block(-4,19,4,HARD_CLAY)
Block(-4,19,5,HARD_CLAY)
Block(-4,19,6,HARD_CLAY)
Block(-4,19,7,HARD_CLAY)
Block(-4,19,8,HARD_CLAY)
Block(-4,19,9,HARD_CLAY)
Block(-4,20,-5,HARD_CLAY)
Block(-4,20,-4,HARD_CLAY)
Block(-4,20,-3,HARD_CLAY)
Block(-4,20,-2,HARD_CLAY)
Block(-4,20,-1,HARD_CLAY)
Block(-4,20,0,HARD_CLAY)
Block(-4,20,1,HARD_CLAY)
Block(-4,20,2,HARD_CLAY)
Block(-4,20,3,HARD_CLAY)
Block(-4,20,4,HARD_CLAY)
Block(-4,20,5,HARD_CLAY)
Block(-4,20,6,HARD_CLAY)
Block(-4,20,7,HARD_CLAY)
Block(-4,20,8,HARD_CLAY)
Block(-4,20,9,HARD_CLAY)
Block(-4,21,-5,HARD_CLAY)
Block(-4,21,-4,HARD_CLAY)
Block(-4,21,-3,HARD_CLAY)
Block(-4,21,-2,HARD_CLAY)
Block(-4,21,-1,HARD_CLAY)
Block(-4,21,0,HARD_CLAY)
Block(-4,21,1,HARD_CLAY)
Block(-4,21,2,HARD_CLAY)
Block(-4,21,3,HARD_CLAY)
Block(-4,21,4,HARD_CLAY)
Block(-4,21,5,HARD_CLAY)
Block(-4,21,6,HARD_CLAY)
Block(-4,21,7,HARD_CLAY)
Block(-4,21,8,HARD_CLAY)
Block(-4,22,-5,HARD_CLAY)
Block(-4,22,-4,HARD_CLAY)
Block(-4,22,-3,HARD_CLAY)
Block(-4,22,-2,HARD_CLAY)
Block(-4,22,-1,HARD_CLAY)
Block(-4,22,0,HARD_CLAY)
Block(-4,22,1,HARD_CLAY)
Block(-4,22,2,HARD_CLAY)
Block(-4,22,3,HARD_CLAY)
Block(-4,22,4,HARD_CLAY)
Block(-4,22,5,HARD_CLAY)
Block(-4,22,6,HARD_CLAY)
Block(-4,22,7,HARD_CLAY)
Block(-4,22,8,HARD_CLAY)
Block(-4,23,-5,HARD_CLAY)
Block(-4,23,-4,HARD_CLAY)
Block(-4,23,-3,HARD_CLAY)
Block(-4,23,-2,HARD_CLAY)
Block(-4,23,-1,HARD_CLAY)
Block(-4,23,0,HARD_CLAY)
Block(-4,23,1,HARD_CLAY)
Block(-4,23,2,HARD_CLAY)
Block(-4,23,3,HARD_CLAY)
Block(-4,23,4,HARD_CLAY)
Block(-4,23,5,HARD_CLAY)
Block(-4,23,6,HARD_CLAY)
Block(-4,23,7,HARD_CLAY)
Block(-4,24,-4,HARD_CLAY)
Block(-4,24,-3,HARD_CLAY)
Block(-4,24,-2,HARD_CLAY)
Block(-4,24,-1,HARD_CLAY)
Block(-4,24,0,HARD_CLAY)
Block(-4,24,1,HARD_CLAY)
Block(-4,24,2,HARD_CLAY)
Block(-4,24,3,HARD_CLAY)
Block(-4,24,4,HARD_CLAY)
Block(-4,24,5,HARD_CLAY)
Block(-4,24,6,HARD_CLAY)
Block(-4,24,7,HARD_CLAY)
Block(-4,25,-4,HARD_CLAY)
Block(-4,25,-3,HARD_CLAY)
Block(-4,25,-2,HARD_CLAY)
Block(-4,25,-1,HARD_CLAY)
Block(-4,25,0,HARD_CLAY)
Block(-4,25,1,HARD_CLAY)
Block(-4,25,2,HARD_CLAY)
Block(-4,25,3,HARD_CLAY)
Block(-4,25,4,HARD_CLAY)
Block(-4,25,5,HARD_CLAY)
Block(-4,25,6,HARD_CLAY)
Block(-4,25,7,HARD_CLAY)
Block(-4,26,-4,HARD_CLAY)
Block(-4,26,-3,HARD_CLAY)
Block(-4,26,-2,HARD_CLAY)
Block(-4,26,-1,HARD_CLAY)
Block(-4,26,0,HARD_CLAY)
Block(-4,26,1,HARD_CLAY)
Block(-4,26,2,HARD_CLAY)
Block(-4,26,3,HARD_CLAY)
Block(-4,26,4,HARD_CLAY)
Block(-4,26,5,HARD_CLAY)
Block(-4,26,6,HARD_CLAY)
Block(-4,27,-4,HARD_CLAY)
Block(-4,27,-3,HARD_CLAY)
Block(-4,27,-2,HARD_CLAY)
Block(-4,27,-1,HARD_CLAY)
Block(-4,27,0,HARD_CLAY)
Block(-4,27,1,HARD_CLAY)
Block(-4,27,2,HARD_CLAY)
Block(-4,27,3,HARD_CLAY)
Block(-4,27,4,HARD_CLAY)
Block(-4,27,5,HARD_CLAY)
Block(-4,27,6,HARD_CLAY)
Block(-4,28,-4,HARD_CLAY)
Block(-4,28,-3,HARD_CLAY)
Block(-4,28,-2,HARD_CLAY)
Block(-4,28,-1,HARD_CLAY)
Block(-4,28,0,HARD_CLAY)
Block(-4,28,1,HARD_CLAY)
Block(-4,28,2,HARD_CLAY)
Block(-4,28,3,HARD_CLAY)
Block(-4,28,4,HARD_CLAY)
Block(-4,28,5,HARD_CLAY)
Block(-4,28,6,HARD_CLAY)
Block(-4,29,-4,HARD_CLAY)
Block(-4,29,-3,HARD_CLAY)
Block(-4,29,-2,HARD_CLAY)
Block(-4,29,-1,HARD_CLAY)
Block(-4,29,0,HARD_CLAY)
Block(-4,29,1,HARD_CLAY)
Block(-4,29,2,HARD_CLAY)
Block(-4,29,3,HARD_CLAY)
Block(-4,29,4,HARD_CLAY)
Block(-4,29,5,HARD_CLAY)
Block(-4,29,6,HARD_CLAY)
Block(-4,30,-4,HARD_CLAY)
Block(-4,30,-3,HARD_CLAY)
Block(-4,30,-2,HARD_CLAY)
Block(-4,30,-1,HARD_CLAY)
Block(-4,30,0,HARD_CLAY)
Block(-4,30,1,HARD_CLAY)
Block(-4,30,2,HARD_CLAY)
Block(-4,30,3,HARD_CLAY)
Block(-4,30,4,HARD_CLAY)
Block(-4,30,5,HARD_CLAY)
Block(-4,30,6,HARD_CLAY)
Block(-4,31,-4,HARD_CLAY)
Block(-4,31,-3,HARD_CLAY)
Block(-4,31,-2,HARD_CLAY)
Block(-4,31,-1,HARD_CLAY)
Block(-4,31,0,HARD_CLAY)
Block(-4,31,1,HARD_CLAY)
Block(-4,31,2,HARD_CLAY)
Block(-4,31,3,HARD_CLAY)
Block(-4,31,4,HARD_CLAY)
Block(-4,31,5,HARD_CLAY)
Block(-4,31,6,HARD_CLAY)
Block(-4,32,-4,HARD_CLAY)
Block(-4,32,-3,HARD_CLAY)
Block(-4,32,-2,HARD_CLAY)
Block(-4,32,-1,HARD_CLAY)
Block(-4,32,0,HARD_CLAY)
Block(-4,32,1,HARD_CLAY)
Block(-4,32,2,HARD_CLAY)
Block(-4,32,3,HARD_CLAY)
Block(-4,33,-4,HARD_CLAY)
Block(-4,33,-3,HARD_CLAY)
Block(-4,33,-2,HARD_CLAY)
Block(-4,33,-1,HARD_CLAY)
Block(-4,33,0,HARD_CLAY)
Block(-4,33,1,HARD_CLAY)
Block(-4,33,2,HARD_CLAY)
Block(-4,33,3,HARD_CLAY)
Block(-4,34,-4,HARD_CLAY)
Block(-4,34,-3,HARD_CLAY)
Block(-4,34,-2,HARD_CLAY)
Block(-4,34,-1,HARD_CLAY)
Block(-4,34,0,HARD_CLAY)
Block(-4,34,1,HARD_CLAY)
Block(-4,34,2,HARD_CLAY)
Block(-4,34,3,HARD_CLAY)
Block(-4,35,-4,HARD_CLAY)
Block(-4,35,-3,HARD_CLAY)
Block(-4,35,-2,HARD_CLAY)
Block(-4,35,-1,HARD_CLAY)
Block(-4,35,0,HARD_CLAY)
Block(-4,35,1,HARD_CLAY)
Block(-4,35,2,HARD_CLAY)
Block(-4,36,-3,HARD_CLAY)
Block(-4,36,-2,HARD_CLAY)
Block(-4,36,-1,HARD_CLAY)
Block(-4,36,0,HARD_CLAY)
Block(-4,36,1,HARD_CLAY)
Block(-4,36,2,HARD_CLAY)
Block(-4,37,-2,HARD_CLAY)
Block(-4,37,-1,HARD_CLAY)
Block(-4,37,0,HARD_CLAY)
Block(-4,37,1,HARD_CLAY)
Block(-4,37,2,HARD_CLAY)
Block(-4,38,-1,HARD_CLAY)
Block(-4,38,0,HARD_CLAY)
Block(-4,38,1,HARD_CLAY)
Block(-4,38,2,HARD_CLAY)
Block(-4,39,-1,HARD_CLAY)
Block(-4,39,0,HARD_CLAY)
Block(-4,39,1,HARD_CLAY)
Block(-4,39,2,HARD_CLAY)
Block(-4,40,-1,HARD_CLAY)
Block(-4,40,0,HARD_CLAY)
Block(-4,40,1,HARD_CLAY)
Block(-4,40,2,HARD_CLAY)
Block(-4,41,-1,HARD_CLAY)
Block(-4,41,0,HARD_CLAY)
Block(-4,41,1,HARD_CLAY)
Block(-4,41,2,HARD_CLAY)
Block(-4,42,-1,HARD_CLAY)
Block(-4,42,0,HARD_CLAY)
Block(-4,42,1,HARD_CLAY)
Block(-4,42,2,HARD_CLAY)
Block(-4,43,-1,HARD_CLAY)
Block(-4,43,0,HARD_CLAY)
Block(-4,43,1,HARD_CLAY)
Block(-4,43,2,HARD_CLAY)
Block(-4,44,-1,HARD_CLAY)
Block(-4,44,0,HARD_CLAY)
Block(-4,44,1,HARD_CLAY)
Block(-4,44,2,HARD_CLAY)
Block(-4,45,-1,HARD_CLAY)
Block(-4,45,0,HARD_CLAY)
Block(-4,45,1,HARD_CLAY)
Block(-4,46,-1,HARD_CLAY)
Block(-4,46,0,HARD_CLAY)
Block(-4,46,1,HARD_CLAY)
Block(-4,47,-1,HARD_CLAY)
Block(-4,47,0,HARD_CLAY)
Block(-4,47,1,HARD_CLAY)
Block(-4,48,0,HARD_CLAY)
Block(-4,48,1,HARD_CLAY)
Block(-4,49,0,HARD_CLAY)
Block(-4,49,1,HARD_CLAY)
Block(-4,50,0,HARD_CLAY)
Block(-4,50,1,HARD_CLAY)
Block(-4,51,0,HARD_CLAY)
Block(-4,51,1,HARD_CLAY)
Block(-4,52,0,HARD_CLAY)
Block(-4,52,1,HARD_CLAY)
Block(-4,53,0,HARD_CLAY)
Block(-4,53,1,HARD_CLAY)
Block(-4,54,0,HARD_CLAY)
Block(-4,54,1,HARD_CLAY)
Block(-4,55,0,HARD_CLAY)
Block(-4,55,1,HARD_CLAY)
Block(-4,56,0,HARD_CLAY)
Block(-4,56,1,HARD_CLAY)
Block(-4,57,0,HARD_CLAY)
Block(-4,57,1,HARD_CLAY)
Block(-4,58,0,HARD_CLAY)
Block(-4,58,1,HARD_CLAY)
Block(-4,59,0,HARD_CLAY)
Block(-4,59,1,HARD_CLAY)
Block(-4,60,0,HARD_CLAY)
Block(-4,60,1,HARD_CLAY)
Block(-4,61,0,HARD_CLAY)
Block(-4,61,1,HARD_CLAY)
Block(-4,62,0,HARD_CLAY)
Block(-4,62,1,HARD_CLAY)
Block(-4,63,0,HARD_CLAY)
Block(-4,63,1,HARD_CLAY)
Block(-4,64,0,HARD_CLAY)
Block(-3,0,-13,HARD_CLAY)
Block(-3,0,-12,HARD_CLAY)
Block(-3,0,-11,HARD_CLAY)
Block(-3,0,-10,HARD_CLAY)
Block(-3,0,-9,HARD_CLAY)
Block(-3,0,-8,HARD_CLAY)
Block(-3,0,-7,HARD_CLAY)
Block(-3,0,-6,HARD_CLAY)
Block(-3,0,-5,HARD_CLAY)
Block(-3,0,-4,HARD_CLAY)
Block(-3,0,-3,HARD_CLAY)
Block(-3,0,-2,HARD_CLAY)
Block(-3,0,-1,HARD_CLAY)
Block(-3,0,0,HARD_CLAY)
Block(-3,0,1,HARD_CLAY)
Block(-3,0,2,HARD_CLAY)
Block(-3,0,3,HARD_CLAY)
Block(-3,0,4,HARD_CLAY)
Block(-3,0,5,HARD_CLAY)
Block(-3,0,6,HARD_CLAY)
Block(-3,0,7,HARD_CLAY)
Block(-3,0,8,HARD_CLAY)
Block(-3,0,9,HARD_CLAY)
Block(-3,0,10,HARD_CLAY)
Block(-3,0,11,HARD_CLAY)
Block(-3,0,12,HARD_CLAY)
Block(-3,0,13,HARD_CLAY)
Block(-3,1,-13,HARD_CLAY)
Block(-3,1,-12,HARD_CLAY)
Block(-3,1,-11,HARD_CLAY)
Block(-3,1,-10,HARD_CLAY)
Block(-3,1,-9,HARD_CLAY)
Block(-3,1,-8,HARD_CLAY)
Block(-3,1,-7,HARD_CLAY)
Block(-3,1,-6,HARD_CLAY)
Block(-3,1,-5,HARD_CLAY)
Block(-3,1,-4,HARD_CLAY)
Block(-3,1,-3,HARD_CLAY)
Block(-3,1,-2,HARD_CLAY)
Block(-3,1,-1,HARD_CLAY)
Block(-3,1,0,HARD_CLAY)
Block(-3,1,1,HARD_CLAY)
Block(-3,1,2,HARD_CLAY)
Block(-3,1,3,HARD_CLAY)
Block(-3,1,4,HARD_CLAY)
Block(-3,1,5,HARD_CLAY)
Block(-3,1,6,HARD_CLAY)
Block(-3,1,7,HARD_CLAY)
Block(-3,1,8,HARD_CLAY)
Block(-3,1,9,HARD_CLAY)
Block(-3,1,10,HARD_CLAY)
Block(-3,1,11,HARD_CLAY)
Block(-3,1,12,HARD_CLAY)
Block(-3,1,13,HARD_CLAY)
Block(-3,2,-13,HARD_CLAY)
Block(-3,2,-12,HARD_CLAY)
Block(-3,2,-11,HARD_CLAY)
Block(-3,2,-10,HARD_CLAY)
Block(-3,2,-9,HARD_CLAY)
Block(-3,2,-8,HARD_CLAY)
Block(-3,2,-7,HARD_CLAY)
Block(-3,2,-6,HARD_CLAY)
Block(-3,2,-5,HARD_CLAY)
Block(-3,2,-4,HARD_CLAY)
Block(-3,2,-3,HARD_CLAY)
Block(-3,2,-2,HARD_CLAY)
Block(-3,2,-1,HARD_CLAY)
Block(-3,2,0,HARD_CLAY)
Block(-3,2,1,HARD_CLAY)
Block(-3,2,2,HARD_CLAY)
Block(-3,2,3,HARD_CLAY)
Block(-3,2,4,HARD_CLAY)
Block(-3,2,5,HARD_CLAY)
Block(-3,2,6,HARD_CLAY)
Block(-3,2,7,HARD_CLAY)
Block(-3,2,8,HARD_CLAY)
Block(-3,2,9,HARD_CLAY)
Block(-3,2,10,HARD_CLAY)
Block(-3,2,11,HARD_CLAY)
Block(-3,2,12,HARD_CLAY)
Block(-3,3,-12,HARD_CLAY)
Block(-3,3,-11,HARD_CLAY)
Block(-3,3,-10,HARD_CLAY)
Block(-3,3,-9,HARD_CLAY)
Block(-3,3,-8,HARD_CLAY)
Block(-3,3,-7,HARD_CLAY)
Block(-3,3,-6,HARD_CLAY)
Block(-3,3,-5,HARD_CLAY)
Block(-3,3,-4,HARD_CLAY)
Block(-3,3,-3,HARD_CLAY)
Block(-3,3,-2,HARD_CLAY)
Block(-3,3,-1,HARD_CLAY)
Block(-3,3,0,HARD_CLAY)
Block(-3,3,1,HARD_CLAY)
Block(-3,3,2,HARD_CLAY)
Block(-3,3,3,HARD_CLAY)
Block(-3,3,4,HARD_CLAY)
Block(-3,3,5,HARD_CLAY)
Block(-3,3,6,HARD_CLAY)
Block(-3,3,7,HARD_CLAY)
Block(-3,3,8,HARD_CLAY)
Block(-3,3,9,HARD_CLAY)
Block(-3,3,10,HARD_CLAY)
Block(-3,3,11,HARD_CLAY)
Block(-3,3,12,HARD_CLAY)
Block(-3,4,-12,HARD_CLAY)
Block(-3,4,-11,HARD_CLAY)
Block(-3,4,-10,HARD_CLAY)
Block(-3,4,-9,HARD_CLAY)
Block(-3,4,-8,HARD_CLAY)
Block(-3,4,-7,HARD_CLAY)
Block(-3,4,-6,HARD_CLAY)
Block(-3,4,-5,HARD_CLAY)
Block(-3,4,-4,HARD_CLAY)
Block(-3,4,-3,HARD_CLAY)
Block(-3,4,-2,HARD_CLAY)
Block(-3,4,-1,HARD_CLAY)
Block(-3,4,0,HARD_CLAY)
Block(-3,4,1,HARD_CLAY)
Block(-3,4,2,HARD_CLAY)
Block(-3,4,3,HARD_CLAY)
Block(-3,4,4,HARD_CLAY)
Block(-3,4,5,HARD_CLAY)
Block(-3,4,6,HARD_CLAY)
Block(-3,4,7,HARD_CLAY)
Block(-3,4,8,HARD_CLAY)
Block(-3,4,9,HARD_CLAY)
Block(-3,4,10,HARD_CLAY)
Block(-3,4,11,HARD_CLAY)
Block(-3,4,12,HARD_CLAY)
Block(-3,5,-12,HARD_CLAY)
Block(-3,5,-11,HARD_CLAY)
Block(-3,5,-10,HARD_CLAY)
Block(-3,5,-9,HARD_CLAY)
Block(-3,5,-8,HARD_CLAY)
Block(-3,5,-7,HARD_CLAY)
Block(-3,5,-6,HARD_CLAY)
Block(-3,5,-5,HARD_CLAY)
Block(-3,5,-4,HARD_CLAY)
Block(-3,5,-3,HARD_CLAY)
Block(-3,5,-2,HARD_CLAY)
Block(-3,5,-1,HARD_CLAY)
Block(-3,5,0,HARD_CLAY)
Block(-3,5,1,HARD_CLAY)
Block(-3,5,2,HARD_CLAY)
Block(-3,5,3,HARD_CLAY)
Block(-3,5,4,HARD_CLAY)
Block(-3,5,5,HARD_CLAY)
Block(-3,5,6,HARD_CLAY)
Block(-3,5,7,HARD_CLAY)
Block(-3,5,8,HARD_CLAY)
Block(-3,5,9,HARD_CLAY)
Block(-3,5,10,HARD_CLAY)
Block(-3,5,11,HARD_CLAY)
Block(-3,5,12,HARD_CLAY)
Block(-3,6,-11,HARD_CLAY)
Block(-3,6,-10,HARD_CLAY)
Block(-3,6,-9,HARD_CLAY)
Block(-3,6,-8,HARD_CLAY)
Block(-3,6,-7,HARD_CLAY)
Block(-3,6,-6,HARD_CLAY)
Block(-3,6,-5,HARD_CLAY)
Block(-3,6,-4,HARD_CLAY)
Block(-3,6,-3,HARD_CLAY)
Block(-3,6,-2,HARD_CLAY)
Block(-3,6,-1,HARD_CLAY)
Block(-3,6,0,HARD_CLAY)
Block(-3,6,1,HARD_CLAY)
Block(-3,6,2,HARD_CLAY)
Block(-3,6,3,HARD_CLAY)
Block(-3,6,4,HARD_CLAY)
Block(-3,6,5,HARD_CLAY)
Block(-3,6,6,HARD_CLAY)
Block(-3,6,7,HARD_CLAY)
Block(-3,6,8,HARD_CLAY)
Block(-3,6,9,HARD_CLAY)
Block(-3,6,10,HARD_CLAY)
Block(-3,6,11,HARD_CLAY)
Block(-3,6,12,HARD_CLAY)
Block(-3,7,-11,HARD_CLAY)
Block(-3,7,-10,HARD_CLAY)
Block(-3,7,-9,HARD_CLAY)
Block(-3,7,-8,HARD_CLAY)
Block(-3,7,-7,HARD_CLAY)
Block(-3,7,-6,HARD_CLAY)
Block(-3,7,-5,HARD_CLAY)
Block(-3,7,-4,HARD_CLAY)
Block(-3,7,-3,HARD_CLAY)
Block(-3,7,-2,HARD_CLAY)
Block(-3,7,-1,HARD_CLAY)
Block(-3,7,0,HARD_CLAY)
Block(-3,7,1,HARD_CLAY)
Block(-3,7,2,HARD_CLAY)
Block(-3,7,3,HARD_CLAY)
Block(-3,7,4,HARD_CLAY)
Block(-3,7,5,HARD_CLAY)
Block(-3,7,6,HARD_CLAY)
Block(-3,7,7,HARD_CLAY)
Block(-3,7,8,HARD_CLAY)
Block(-3,7,9,HARD_CLAY)
Block(-3,7,10,HARD_CLAY)
Block(-3,7,11,HARD_CLAY)
Block(-3,7,12,HARD_CLAY)
Block(-3,8,-11,HARD_CLAY)
Block(-3,8,-10,HARD_CLAY)
Block(-3,8,-9,HARD_CLAY)
Block(-3,8,-8,HARD_CLAY)
Block(-3,8,-7,HARD_CLAY)
Block(-3,8,-6,HARD_CLAY)
Block(-3,8,-5,HARD_CLAY)
Block(-3,8,-4,HARD_CLAY)
Block(-3,8,-3,HARD_CLAY)
Block(-3,8,-2,HARD_CLAY)
Block(-3,8,-1,HARD_CLAY)
Block(-3,8,0,HARD_CLAY)
Block(-3,8,1,HARD_CLAY)
Block(-3,8,2,HARD_CLAY)
Block(-3,8,3,HARD_CLAY)
Block(-3,8,4,HARD_CLAY)
Block(-3,8,5,HARD_CLAY)
Block(-3,8,6,HARD_CLAY)
Block(-3,8,7,HARD_CLAY)
Block(-3,8,8,HARD_CLAY)
Block(-3,8,9,HARD_CLAY)
Block(-3,8,10,HARD_CLAY)
Block(-3,8,11,HARD_CLAY)
Block(-3,8,12,HARD_CLAY)
Block(-3,9,-11,HARD_CLAY)
Block(-3,9,-10,HARD_CLAY)
Block(-3,9,-9,HARD_CLAY)
Block(-3,9,-8,HARD_CLAY)
Block(-3,9,-7,HARD_CLAY)
Block(-3,9,-6,HARD_CLAY)
Block(-3,9,-5,HARD_CLAY)
Block(-3,9,-4,HARD_CLAY)
Block(-3,9,-3,HARD_CLAY)
Block(-3,9,-2,HARD_CLAY)
Block(-3,9,-1,HARD_CLAY)
Block(-3,9,0,HARD_CLAY)
Block(-3,9,1,HARD_CLAY)
Block(-3,9,2,HARD_CLAY)
Block(-3,9,3,HARD_CLAY)
Block(-3,9,4,HARD_CLAY)
Block(-3,9,5,HARD_CLAY)
Block(-3,9,6,HARD_CLAY)
Block(-3,9,7,HARD_CLAY)
Block(-3,9,8,HARD_CLAY)
Block(-3,9,9,HARD_CLAY)
Block(-3,9,10,HARD_CLAY)
Block(-3,9,11,HARD_CLAY)
Block(-3,10,-11,HARD_CLAY)
Block(-3,10,-10,HARD_CLAY)
Block(-3,10,-9,HARD_CLAY)
Block(-3,10,-8,HARD_CLAY)
Block(-3,10,-7,HARD_CLAY)
Block(-3,10,-6,HARD_CLAY)
Block(-3,10,-5,HARD_CLAY)
Block(-3,10,-4,HARD_CLAY)
Block(-3,10,-3,HARD_CLAY)
Block(-3,10,-2,HARD_CLAY)
Block(-3,10,-1,HARD_CLAY)
Block(-3,10,0,HARD_CLAY)
Block(-3,10,1,HARD_CLAY)
Block(-3,10,2,HARD_CLAY)
Block(-3,10,3,HARD_CLAY)
Block(-3,10,4,HARD_CLAY)
Block(-3,10,5,HARD_CLAY)
Block(-3,10,6,HARD_CLAY)
Block(-3,10,7,HARD_CLAY)
Block(-3,10,8,HARD_CLAY)
Block(-3,10,9,HARD_CLAY)
Block(-3,10,10,HARD_CLAY)
Block(-3,10,11,HARD_CLAY)
Block(-3,11,-11,HARD_CLAY)
Block(-3,11,-10,HARD_CLAY)
Block(-3,11,-9,HARD_CLAY)
Block(-3,11,-8,HARD_CLAY)
Block(-3,11,-7,HARD_CLAY)
Block(-3,11,-6,HARD_CLAY)
Block(-3,11,-5,HARD_CLAY)
Block(-3,11,-4,HARD_CLAY)
Block(-3,11,-3,HARD_CLAY)
Block(-3,11,-2,HARD_CLAY)
Block(-3,11,-1,HARD_CLAY)
Block(-3,11,0,HARD_CLAY)
Block(-3,11,1,HARD_CLAY)
Block(-3,11,2,HARD_CLAY)
Block(-3,11,3,HARD_CLAY)
Block(-3,11,4,HARD_CLAY)
Block(-3,11,5,HARD_CLAY)
Block(-3,11,6,HARD_CLAY)
Block(-3,11,7,HARD_CLAY)
Block(-3,11,8,HARD_CLAY)
Block(-3,11,9,HARD_CLAY)
Block(-3,11,10,HARD_CLAY)
Block(-3,11,11,HARD_CLAY)
Block(-3,12,-11,HARD_CLAY)
Block(-3,12,-10,HARD_CLAY)
Block(-3,12,-9,HARD_CLAY)
Block(-3,12,-8,HARD_CLAY)
Block(-3,12,-7,HARD_CLAY)
Block(-3,12,-6,HARD_CLAY)
Block(-3,12,-5,HARD_CLAY)
Block(-3,12,-4,HARD_CLAY)
Block(-3,12,-3,HARD_CLAY)
Block(-3,12,-2,HARD_CLAY)
Block(-3,12,-1,HARD_CLAY)
Block(-3,12,0,HARD_CLAY)
Block(-3,12,1,HARD_CLAY)
Block(-3,12,2,HARD_CLAY)
Block(-3,12,3,HARD_CLAY)
Block(-3,12,4,HARD_CLAY)
Block(-3,12,5,HARD_CLAY)
Block(-3,12,6,HARD_CLAY)
Block(-3,12,7,HARD_CLAY)
Block(-3,12,8,HARD_CLAY)
Block(-3,12,9,HARD_CLAY)
Block(-3,12,10,HARD_CLAY)
Block(-3,12,11,HARD_CLAY)
Block(-3,13,-10,HARD_CLAY)
Block(-3,13,-9,HARD_CLAY)
Block(-3,13,-8,HARD_CLAY)
Block(-3,13,-7,HARD_CLAY)
Block(-3,13,-6,HARD_CLAY)
Block(-3,13,-5,HARD_CLAY)
Block(-3,13,-4,HARD_CLAY)
Block(-3,13,-3,HARD_CLAY)
Block(-3,13,-2,HARD_CLAY)
Block(-3,13,-1,HARD_CLAY)
Block(-3,13,0,HARD_CLAY)
Block(-3,13,1,HARD_CLAY)
Block(-3,13,2,HARD_CLAY)
Block(-3,13,3,HARD_CLAY)
Block(-3,13,4,HARD_CLAY)
Block(-3,13,5,HARD_CLAY)
Block(-3,13,6,HARD_CLAY)
Block(-3,13,7,HARD_CLAY)
Block(-3,13,8,HARD_CLAY)
Block(-3,13,9,HARD_CLAY)
Block(-3,13,10,HARD_CLAY)
Block(-3,14,-10,HARD_CLAY)
Block(-3,14,-9,HARD_CLAY)
Block(-3,14,-8,HARD_CLAY)
Block(-3,14,-7,HARD_CLAY)
Block(-3,14,-6,HARD_CLAY)
Block(-3,14,-5,HARD_CLAY)
Block(-3,14,-4,HARD_CLAY)
Block(-3,14,-3,HARD_CLAY)
Block(-3,14,-2,HARD_CLAY)
Block(-3,14,-1,HARD_CLAY)
Block(-3,14,0,HARD_CLAY)
Block(-3,14,1,HARD_CLAY)
Block(-3,14,2,HARD_CLAY)
Block(-3,14,3,HARD_CLAY)
Block(-3,14,4,HARD_CLAY)
Block(-3,14,5,HARD_CLAY)
Block(-3,14,6,HARD_CLAY)
Block(-3,14,7,HARD_CLAY)
Block(-3,14,8,HARD_CLAY)
Block(-3,14,9,HARD_CLAY)
Block(-3,14,10,HARD_CLAY)
Block(-3,15,-6,HARD_CLAY)
Block(-3,15,-5,HARD_CLAY)
Block(-3,15,-4,HARD_CLAY)
Block(-3,15,-3,HARD_CLAY)
Block(-3,15,-2,HARD_CLAY)
Block(-3,15,-1,HARD_CLAY)
Block(-3,15,0,HARD_CLAY)
Block(-3,15,1,HARD_CLAY)
Block(-3,15,2,HARD_CLAY)
Block(-3,15,3,HARD_CLAY)
Block(-3,15,4,HARD_CLAY)
Block(-3,15,5,HARD_CLAY)
Block(-3,15,6,HARD_CLAY)
Block(-3,15,7,HARD_CLAY)
Block(-3,15,8,HARD_CLAY)
Block(-3,15,9,HARD_CLAY)
Block(-3,16,-6,HARD_CLAY)
Block(-3,16,-5,HARD_CLAY)
Block(-3,16,-4,HARD_CLAY)
Block(-3,16,-3,HARD_CLAY)
Block(-3,16,-2,HARD_CLAY)
Block(-3,16,-1,HARD_CLAY)
Block(-3,16,0,HARD_CLAY)
Block(-3,16,1,HARD_CLAY)
Block(-3,16,2,HARD_CLAY)
Block(-3,16,3,HARD_CLAY)
Block(-3,16,4,HARD_CLAY)
Block(-3,16,5,HARD_CLAY)
Block(-3,16,6,HARD_CLAY)
Block(-3,16,7,HARD_CLAY)
Block(-3,16,8,HARD_CLAY)
Block(-3,16,9,HARD_CLAY)
Block(-3,17,-6,HARD_CLAY)
Block(-3,17,-5,HARD_CLAY)
Block(-3,17,-4,HARD_CLAY)
Block(-3,17,-3,HARD_CLAY)
Block(-3,17,-2,HARD_CLAY)
Block(-3,17,-1,HARD_CLAY)
Block(-3,17,0,HARD_CLAY)
Block(-3,17,1,HARD_CLAY)
Block(-3,17,2,HARD_CLAY)
Block(-3,17,3,HARD_CLAY)
Block(-3,17,4,HARD_CLAY)
Block(-3,17,5,HARD_CLAY)
Block(-3,17,6,HARD_CLAY)
Block(-3,17,7,HARD_CLAY)
Block(-3,17,8,HARD_CLAY)
Block(-3,17,9,HARD_CLAY)
Block(-3,18,-6,HARD_CLAY)
Block(-3,18,-5,HARD_CLAY)
Block(-3,18,-4,HARD_CLAY)
Block(-3,18,-3,HARD_CLAY)
Block(-3,18,-2,HARD_CLAY)
Block(-3,18,-1,HARD_CLAY)
Block(-3,18,0,HARD_CLAY)
Block(-3,18,1,HARD_CLAY)
Block(-3,18,2,HARD_CLAY)
Block(-3,18,3,HARD_CLAY)
Block(-3,18,4,HARD_CLAY)
Block(-3,18,5,HARD_CLAY)
Block(-3,18,6,HARD_CLAY)
Block(-3,18,7,HARD_CLAY)
Block(-3,18,8,HARD_CLAY)
Block(-3,18,9,HARD_CLAY)
Block(-3,19,-6,HARD_CLAY)
Block(-3,19,-5,HARD_CLAY)
Block(-3,19,-4,HARD_CLAY)
Block(-3,19,-3,HARD_CLAY)
Block(-3,19,-2,HARD_CLAY)
Block(-3,19,-1,HARD_CLAY)
Block(-3,19,0,HARD_CLAY)
Block(-3,19,1,HARD_CLAY)
Block(-3,19,2,HARD_CLAY)
Block(-3,19,3,HARD_CLAY)
Block(-3,19,4,HARD_CLAY)
Block(-3,19,5,HARD_CLAY)
Block(-3,19,6,HARD_CLAY)
Block(-3,19,7,HARD_CLAY)
Block(-3,19,8,HARD_CLAY)
Block(-3,19,9,HARD_CLAY)
Block(-3,20,-5,HARD_CLAY)
Block(-3,20,-4,HARD_CLAY)
Block(-3,20,-3,HARD_CLAY)
Block(-3,20,-2,HARD_CLAY)
Block(-3,20,-1,HARD_CLAY)
Block(-3,20,0,HARD_CLAY)
Block(-3,20,1,HARD_CLAY)
Block(-3,20,2,HARD_CLAY)
Block(-3,20,3,HARD_CLAY)
Block(-3,20,4,HARD_CLAY)
Block(-3,20,5,HARD_CLAY)
Block(-3,20,6,HARD_CLAY)
Block(-3,20,7,HARD_CLAY)
Block(-3,20,8,HARD_CLAY)
Block(-3,20,9,HARD_CLAY)
Block(-3,21,-5,HARD_CLAY)
Block(-3,21,-4,HARD_CLAY)
Block(-3,21,-3,HARD_CLAY)
Block(-3,21,-2,HARD_CLAY)
Block(-3,21,-1,HARD_CLAY)
Block(-3,21,0,HARD_CLAY)
Block(-3,21,1,HARD_CLAY)
Block(-3,21,2,HARD_CLAY)
Block(-3,21,3,HARD_CLAY)
Block(-3,21,4,HARD_CLAY)
Block(-3,21,5,HARD_CLAY)
Block(-3,21,6,HARD_CLAY)
Block(-3,21,7,HARD_CLAY)
Block(-3,21,8,HARD_CLAY)
Block(-3,22,-5,HARD_CLAY)
Block(-3,22,-4,HARD_CLAY)
Block(-3,22,-3,HARD_CLAY)
Block(-3,22,-2,HARD_CLAY)
Block(-3,22,-1,HARD_CLAY)
Block(-3,22,0,HARD_CLAY)
Block(-3,22,1,HARD_CLAY)
Block(-3,22,2,HARD_CLAY)
Block(-3,22,3,HARD_CLAY)
Block(-3,22,4,HARD_CLAY)
Block(-3,22,5,HARD_CLAY)
Block(-3,22,6,HARD_CLAY)
Block(-3,22,7,HARD_CLAY)
Block(-3,22,8,HARD_CLAY)
Block(-3,23,-5,HARD_CLAY)
Block(-3,23,-4,HARD_CLAY)
Block(-3,23,-3,HARD_CLAY)
Block(-3,23,-2,HARD_CLAY)
Block(-3,23,-1,HARD_CLAY)
Block(-3,23,0,HARD_CLAY)
Block(-3,23,1,HARD_CLAY)
Block(-3,23,2,HARD_CLAY)
Block(-3,23,3,HARD_CLAY)
Block(-3,23,4,HARD_CLAY)
Block(-3,23,5,HARD_CLAY)
Block(-3,23,6,HARD_CLAY)
Block(-3,23,7,HARD_CLAY)
Block(-3,23,8,HARD_CLAY)
Block(-3,24,-5,HARD_CLAY)
Block(-3,24,-4,HARD_CLAY)
Block(-3,24,-3,HARD_CLAY)
Block(-3,24,-2,HARD_CLAY)
Block(-3,24,-1,HARD_CLAY)
Block(-3,24,0,HARD_CLAY)
Block(-3,24,1,HARD_CLAY)
Block(-3,24,2,HARD_CLAY)
Block(-3,24,3,HARD_CLAY)
Block(-3,24,4,HARD_CLAY)
Block(-3,24,5,HARD_CLAY)
Block(-3,24,6,HARD_CLAY)
Block(-3,24,7,HARD_CLAY)
Block(-3,24,8,HARD_CLAY)
Block(-3,25,-5,HARD_CLAY)
Block(-3,25,-4,HARD_CLAY)
Block(-3,25,-3,HARD_CLAY)
Block(-3,25,-2,HARD_CLAY)
Block(-3,25,-1,HARD_CLAY)
Block(-3,25,0,HARD_CLAY)
Block(-3,25,1,HARD_CLAY)
Block(-3,25,2,HARD_CLAY)
Block(-3,25,3,HARD_CLAY)
Block(-3,25,4,HARD_CLAY)
Block(-3,25,5,HARD_CLAY)
Block(-3,25,6,HARD_CLAY)
Block(-3,25,7,HARD_CLAY)
Block(-3,25,8,HARD_CLAY)
Block(-3,26,-5,HARD_CLAY)
Block(-3,26,-4,HARD_CLAY)
Block(-3,26,-3,HARD_CLAY)
Block(-3,26,-2,HARD_CLAY)
Block(-3,26,-1,HARD_CLAY)
Block(-3,26,0,HARD_CLAY)
Block(-3,26,1,HARD_CLAY)
Block(-3,26,2,HARD_CLAY)
Block(-3,26,3,HARD_CLAY)
Block(-3,26,4,HARD_CLAY)
Block(-3,26,5,HARD_CLAY)
Block(-3,26,6,HARD_CLAY)
Block(-3,26,7,HARD_CLAY)
Block(-3,26,8,HARD_CLAY)
Block(-3,27,-5,HARD_CLAY)
Block(-3,27,-4,HARD_CLAY)
Block(-3,27,-3,HARD_CLAY)
Block(-3,27,-2,HARD_CLAY)
Block(-3,27,-1,HARD_CLAY)
Block(-3,27,0,HARD_CLAY)
Block(-3,27,1,HARD_CLAY)
Block(-3,27,2,HARD_CLAY)
Block(-3,27,3,HARD_CLAY)
Block(-3,27,4,HARD_CLAY)
Block(-3,27,5,HARD_CLAY)
Block(-3,27,6,HARD_CLAY)
Block(-3,27,7,HARD_CLAY)
Block(-3,28,-5,HARD_CLAY)
Block(-3,28,-4,HARD_CLAY)
Block(-3,28,-3,HARD_CLAY)
Block(-3,28,-2,HARD_CLAY)
Block(-3,28,-1,HARD_CLAY)
Block(-3,28,0,HARD_CLAY)
Block(-3,28,1,HARD_CLAY)
Block(-3,28,2,HARD_CLAY)
Block(-3,28,3,HARD_CLAY)
Block(-3,28,4,HARD_CLAY)
Block(-3,28,5,HARD_CLAY)
Block(-3,28,6,HARD_CLAY)
Block(-3,28,7,HARD_CLAY)
Block(-3,29,-5,HARD_CLAY)
Block(-3,29,-4,HARD_CLAY)
Block(-3,29,-3,HARD_CLAY)
Block(-3,29,-2,HARD_CLAY)
Block(-3,29,-1,HARD_CLAY)
Block(-3,29,0,HARD_CLAY)
Block(-3,29,1,HARD_CLAY)
Block(-3,29,2,HARD_CLAY)
Block(-3,29,3,HARD_CLAY)
Block(-3,29,4,HARD_CLAY)
Block(-3,29,5,HARD_CLAY)
Block(-3,29,6,HARD_CLAY)
Block(-3,29,7,HARD_CLAY)
Block(-3,30,-5,HARD_CLAY)
Block(-3,30,-4,HARD_CLAY)
Block(-3,30,-3,HARD_CLAY)
Block(-3,30,-2,HARD_CLAY)
Block(-3,30,-1,HARD_CLAY)
Block(-3,30,0,HARD_CLAY)
Block(-3,30,1,HARD_CLAY)
Block(-3,30,2,HARD_CLAY)
Block(-3,30,3,HARD_CLAY)
Block(-3,30,4,HARD_CLAY)
Block(-3,30,5,HARD_CLAY)
Block(-3,30,6,HARD_CLAY)
Block(-3,30,7,HARD_CLAY)
Block(-3,31,-5,HARD_CLAY)
Block(-3,31,-4,HARD_CLAY)
Block(-3,31,-3,HARD_CLAY)
Block(-3,31,-2,HARD_CLAY)
Block(-3,31,-1,HARD_CLAY)
Block(-3,31,0,HARD_CLAY)
Block(-3,31,1,HARD_CLAY)
Block(-3,31,2,HARD_CLAY)
Block(-3,31,3,HARD_CLAY)
Block(-3,31,4,HARD_CLAY)
Block(-3,31,5,HARD_CLAY)
Block(-3,31,6,HARD_CLAY)
Block(-3,31,7,HARD_CLAY)
Block(-3,32,-4,HARD_CLAY)
Block(-3,32,-3,HARD_CLAY)
Block(-3,32,-2,HARD_CLAY)
Block(-3,32,-1,HARD_CLAY)
Block(-3,32,0,HARD_CLAY)
Block(-3,32,1,HARD_CLAY)
Block(-3,32,2,HARD_CLAY)
