#######################################################################
# +-----------------------------------------------------------------+ #
# |                            BO3 object                           | #
# +-----------------------------------------------------------------+ #
#######################################################################

Author: Bo3 BulkEdit

Description: Converted Schematic - Modified by Bo3BulkEdit

Version: 3

SettingsMode: WriteDisable

#######################################################################
# +-----------------------------------------------------------------+ #
# |                          Main settings                          | #
# +-----------------------------------------------------------------+ #
#######################################################################

IsOTGPlus: false
Tree: false
Frequency: 1
Rarity: 100
RotateRandomly: false
SpawnHeight: randomY
SpawnHeightOffset: 0
SpawnHeightVariance: 0
MaxBranchDepth: 50
ExcludedBiomes: All

##############################
# Height Limits for the BO3. #
##############################

MinHeight: 0
MaxHeight: 256

#######################################################################
# +-----------------------------------------------------------------+ #
# |                      Source block settings                      | #
# +-----------------------------------------------------------------+ #
#######################################################################

SourceBlocks: AIR
MaxPercentageOutsideSourceBlock: 100
OutsideSourceBlock: placeAnyway

#######################################################################
# +-----------------------------------------------------------------+ #
# |                              Blocks                             | #
# +-----------------------------------------------------------------+ #
#######################################################################

B(-8,0,-8,STONE:6)
B(-7,0,-8,STONE:6)
B(-6,0,-8,STONE:6)
B(-5,0,-8,STONE:6)
B(-4,0,-8,STONE:6)
B(-3,0,-8,STONE:6)
B(-2,0,-8,STONE:6)
B(-1,0,-8,STONE:6)
B(0,0,-8,STONE:6)
B(1,0,-8,STONE:6)
B(2,0,-8,STONE:6)
B(3,0,-8,STONE:6)
B(4,0,-8,STONE:6)
B(5,0,-8,STONE:6)
B(6,0,-8,STONE:6)
B(7,0,-8,STONE:6)
B(-8,0,-7,STONE:6)
B(-7,0,-7,STONE:6)
B(-6,0,-7,STONE:6)
B(-5,0,-7,STONE:6)
B(-4,0,-7,STONE:6)
B(-3,0,-7,STONE:6)
B(-2,0,-7,STONE:6)
B(-1,0,-7,STONE:6)
B(0,0,-7,STONE:6)
B(1,0,-7,STONE:6)
B(2,0,-7,STONE:6)
B(3,0,-7,STONE:6)
B(4,0,-7,STONE:6)
B(5,0,-7,STONE:6)
B(6,0,-7,STONE:6)
B(7,0,-7,STONE:6)
B(-8,0,-6,STONE:6)
B(-7,0,-6,STONE:6)
B(-6,0,-6,STONE:6)
B(-5,0,-6,STONE:6)
B(-4,0,-6,STONE:6)
B(-3,0,-6,STONE:6)
B(-2,0,-6,STONE:6)
B(-1,0,-6,STONE:6)
B(0,0,-6,STONE:6)
B(1,0,-6,STONE:6)
B(2,0,-6,STONE:6)
B(3,0,-6,STONE:6)
B(4,0,-6,STONE:6)
B(5,0,-6,STONE:6)
B(6,0,-6,STONE:6)
B(7,0,-6,STONE:6)
B(-8,0,-5,STONE:6)
B(-7,0,-5,STONE:6)
B(-6,0,-5,STONE:6)
B(-5,0,-5,STONE:6)
B(-4,0,-5,STONE:6)
B(-3,0,-5,STONE:6)
B(-2,0,-5,STONE:6)
B(-1,0,-5,STONE:6)
B(0,0,-5,STONE:6)
B(1,0,-5,STONE:6)
B(2,0,-5,STONE:6)
B(3,0,-5,STONE:6)
B(4,0,-5,STONE:6)
B(5,0,-5,STONE:6)
B(6,0,-5,STONE:6)
B(7,0,-5,STONE:6)
B(-8,0,-4,STONE:6)
B(-7,0,-4,STONE:6)
B(-6,0,-4,STONE:6)
B(-5,0,-4,STONE:6)
B(-4,0,-4,STONE:6)
B(-3,0,-4,STONE:6)
B(-2,0,-4,STONE:6)
B(-1,0,-4,STONE:6)
B(0,0,-4,STONE:6)
B(1,0,-4,STONE:6)
B(2,0,-4,STONE:6)
B(3,0,-4,STONE:6)
B(4,0,-4,STONE:6)
B(5,0,-4,STONE:6)
B(6,0,-4,STONE:6)
B(7,0,-4,STONE:6)
B(-8,0,-3,STONE:6)
B(-7,0,-3,STONE:6)
B(-6,0,-3,STONE:6)
B(-5,0,-3,STONE:6)
B(-4,0,-3,STONE:6)
B(-3,0,-3,STONE:6)
B(-2,0,-3,STONE:6)
B(-1,0,-3,STONE:6)
B(0,0,-3,STONE:6)
B(1,0,-3,STONE:6)
B(2,0,-3,STONE:6)
B(3,0,-3,STONE:6)
B(4,0,-3,STONE:6)
B(5,0,-3,STONE:6)
B(6,0,-3,STONE:6)
B(7,0,-3,STONE:6)
B(-8,0,-2,STONE:6)
B(-7,0,-2,STONE:6)
B(-6,0,-2,STONE:6)
B(-5,0,-2,STONE:6)
B(-4,0,-2,STONE:6)
B(-3,0,-2,STONE:6)
B(-2,0,-2,STONE:6)
B(-1,0,-2,STONE:6)
B(0,0,-2,STONE:6)
B(1,0,-2,STONE:6)
B(2,0,-2,STONE:6)
B(3,0,-2,STONE:6)
B(4,0,-2,STONE:6)
B(5,0,-2,STONE:6)
B(6,0,-2,STONE:6)
B(7,0,-2,STONE:6)
B(-8,0,-1,STONE:6)
B(-7,0,-1,STONE:6)
B(-6,0,-1,STONE:6)
B(-5,0,-1,STONE:6)
B(-4,0,-1,STONE:6)
B(-3,0,-1,STONE:6)
B(-2,0,-1,STONE:6)
B(-1,0,-1,STONE:6)
B(0,0,-1,STONE:6)
B(1,0,-1,STONE:6)
B(2,0,-1,STONE:6)
B(3,0,-1,STONE:6)
B(4,0,-1,STONE:6)
B(5,0,-1,STONE:6)
B(6,0,-1,STONE:6)
B(7,0,-1,STONE:6)
B(-8,0,0,STONE:6)
B(-7,0,0,STONE:6)
B(-6,0,0,STONE:6)
B(-5,0,0,STONE:6)
B(-4,0,0,STONE:6)
B(-3,0,0,STONE:6)
B(-2,0,0,STONE:6)
B(-1,0,0,STONE:6)
B(0,0,0,STONE:6)
B(1,0,0,STONE:6)
B(2,0,0,STONE:6)
B(3,0,0,STONE:6)
B(4,0,0,STONE:6)
B(5,0,0,STONE:6)
B(6,0,0,STONE:6)
B(7,0,0,STONE:6)
B(-8,0,1,STONE:6)
B(-7,0,1,STONE:6)
B(-6,0,1,STONE:6)
B(-5,0,1,STONE:6)
B(-4,0,1,STONE:6)
B(-3,0,1,STONE:6)
B(-2,0,1,STONE:6)
B(-1,0,1,STONE:6)
B(0,0,1,STONE:6)
B(1,0,1,STONE:6)
B(2,0,1,STONE:6)
B(3,0,1,STONE:6)
B(4,0,1,STONE:6)
B(5,0,1,STONE:6)
B(6,0,1,STONE:6)
B(7,0,1,STONE:6)
B(-8,0,2,STONE:6)
B(-7,0,2,STONE:6)
B(-6,0,2,STONE:6)
B(-5,0,2,STONE:6)
B(-4,0,2,STONE:6)
B(-3,0,2,STONE:6)
B(-2,0,2,STONE:6)
B(-1,0,2,STONE:6)
B(0,0,2,STONE:6)
B(1,0,2,STONE:6)
B(2,0,2,STONE:6)
B(3,0,2,STONE:6)
B(4,0,2,STONE:6)
B(5,0,2,STONE:6)
B(6,0,2,STONE:6)
B(7,0,2,STONE:6)
B(-8,0,3,STONE:6)
B(-7,0,3,STONE:6)
B(-6,0,3,STONE:6)
B(-5,0,3,STONE:6)
B(-4,0,3,STONE:6)
B(-3,0,3,STONE:6)
B(-2,0,3,STONE:6)
B(-1,0,3,STONE:6)
B(0,0,3,STONE:6)
B(1,0,3,STONE:6)
B(2,0,3,STONE:6)
B(3,0,3,STONE:6)
B(4,0,3,STONE:6)
B(5,0,3,STONE:6)
B(6,0,3,STONE:6)
B(7,0,3,STONE:6)
B(-8,0,4,STONE:6)
B(-7,0,4,STONE:6)
B(-6,0,4,STONE:6)
B(-5,0,4,STONE:6)
B(-4,0,4,STONE:6)
B(-3,0,4,STONE:6)
B(-2,0,4,STONE:6)
B(-1,0,4,STONE:6)
B(0,0,4,STONE:6)
B(1,0,4,STONE:6)
B(2,0,4,STONE:6)
B(3,0,4,STONE:6)
B(4,0,4,STONE:6)
B(5,0,4,STONE:6)
B(6,0,4,STONE:6)
B(7,0,4,STONE:6)
B(-8,0,5,STONE:6)
B(-7,0,5,STONE:6)
B(-6,0,5,STONE:6)
B(-5,0,5,STONE:6)
B(-4,0,5,STONE:6)
B(-3,0,5,STONE:6)
B(-2,0,5,STONE:6)
B(-1,0,5,STONE:6)
B(0,0,5,STONE:6)
B(1,0,5,STONE:6)
B(2,0,5,STONE:6)
B(3,0,5,STONE:6)
B(4,0,5,STONE:6)
B(5,0,5,STONE:6)
B(6,0,5,STONE:6)
B(7,0,5,STONE:6)
B(-8,0,6,STONE:6)
B(-7,0,6,STONE:6)
B(-6,0,6,STONE:6)
B(-5,0,6,STONE:6)
B(-4,0,6,STONE:6)
B(-3,0,6,STONE:6)
B(-2,0,6,STONE:6)
B(-1,0,6,STONE:6)
B(0,0,6,STONE:6)
B(1,0,6,STONE:6)
B(2,0,6,STONE:6)
B(3,0,6,STONE:6)
B(4,0,6,STONE:6)
B(5,0,6,STONE:6)
B(6,0,6,STONE:6)
B(7,0,6,STONE:6)
B(-8,1,-8,COBBLESTONE)
B(-7,1,-8,COBBLESTONE)
B(-6,1,-8,COBBLESTONE)
B(-5,1,-8,COBBLESTONE)
B(-4,1,-8,COBBLESTONE)
B(-3,1,-8,COBBLESTONE)
B(-2,1,-8,COBBLESTONE)
B(-1,1,-8,COBBLESTONE)
B(0,1,-8,COBBLESTONE)
B(1,1,-8,COBBLESTONE)
B(2,1,-8,COBBLESTONE)
B(3,1,-8,COBBLESTONE)
B(4,1,-8,COBBLESTONE)
B(5,1,-8,COBBLESTONE)
B(6,1,-8,COBBLESTONE)
B(7,1,-8,COBBLESTONE)
B(-8,1,-7,COBBLESTONE)
B(-7,1,-7,COBBLESTONE)
B(-6,1,-7,COBBLESTONE)
B(-5,1,-7,COBBLESTONE)
B(-4,1,-7,COBBLESTONE)
B(-3,1,-7,COBBLESTONE)
B(-2,1,-7,COBBLESTONE)
B(-1,1,-7,COBBLESTONE)
B(0,1,-7,COBBLESTONE)
B(1,1,-7,COBBLESTONE)
B(2,1,-7,COBBLESTONE)
B(3,1,-7,COBBLESTONE)
B(4,1,-7,COBBLESTONE)
B(5,1,-7,COBBLESTONE)
B(6,1,-7,COBBLESTONE)
B(7,1,-7,COBBLESTONE)
B(-8,1,-6,COBBLESTONE)
B(-7,1,-6,COBBLESTONE)
B(-6,1,-6,COBBLESTONE)
B(-5,1,-6,COBBLESTONE)
B(-4,1,-6,COBBLESTONE)
B(-3,1,-6,COBBLESTONE)
B(-2,1,-6,COBBLESTONE)
B(-1,1,-6,COBBLESTONE)
B(0,1,-6,COBBLESTONE)
B(1,1,-6,COBBLESTONE)
B(2,1,-6,COBBLESTONE)
B(3,1,-6,COBBLESTONE)
B(4,1,-6,COBBLESTONE)
B(5,1,-6,COBBLESTONE)
B(6,1,-6,COBBLESTONE)
B(7,1,-6,COBBLESTONE)
B(-8,1,-5,COBBLESTONE)
B(-7,1,-5,COBBLESTONE)
B(-6,1,-5,COBBLESTONE)
B(-5,1,-5,COBBLESTONE)
B(-4,1,-5,COBBLESTONE)
B(-3,1,-5,COBBLESTONE)
B(-2,1,-5,COBBLESTONE)
B(-1,1,-5,COBBLESTONE)
B(0,1,-5,COBBLESTONE)
B(1,1,-5,COBBLESTONE)
B(2,1,-5,COBBLESTONE)
B(3,1,-5,COBBLESTONE)
B(4,1,-5,COBBLESTONE)
B(5,1,-5,COBBLESTONE)
B(6,1,-5,COBBLESTONE)
B(7,1,-5,COBBLESTONE)
B(-8,1,-4,COBBLESTONE)
B(-7,1,-4,COBBLESTONE)
B(-6,1,-4,COBBLESTONE)
B(-5,1,-4,COBBLESTONE)
B(-4,1,-4,COBBLESTONE)
B(-3,1,-4,COBBLESTONE)
B(-2,1,-4,COBBLESTONE)
B(-1,1,-4,COBBLESTONE)
B(0,1,-4,COBBLESTONE)
B(1,1,-4,COBBLESTONE)
B(2,1,-4,COBBLESTONE)
B(3,1,-4,COBBLESTONE)
B(4,1,-4,COBBLESTONE)
B(5,1,-4,COBBLESTONE)
B(6,1,-4,COBBLESTONE)
B(7,1,-4,COBBLESTONE)
B(-8,1,-3,COBBLESTONE)
B(-7,1,-3,COBBLESTONE)
B(-6,1,-3,COBBLESTONE)
B(-5,1,-3,COBBLESTONE)
B(-4,1,-3,COBBLESTONE)
B(-3,1,-3,COBBLESTONE)
B(-2,1,-3,COBBLESTONE)
B(-1,1,-3,COBBLESTONE)
B(0,1,-3,COBBLESTONE)
B(1,1,-3,COBBLESTONE)
B(2,1,-3,COBBLESTONE)
B(3,1,-3,COBBLESTONE)
B(4,1,-3,COBBLESTONE)
B(5,1,-3,COBBLESTONE)
B(6,1,-3,COBBLESTONE)
B(7,1,-3,COBBLESTONE)
B(-8,1,-2,COBBLESTONE)
B(-7,1,-2,COBBLESTONE)
B(-6,1,-2,COBBLESTONE)
B(-5,1,-2,COBBLESTONE)
B(-4,1,-2,COBBLESTONE)
B(-3,1,-2,COBBLESTONE)
B(-2,1,-2,COBBLESTONE)
B(-1,1,-2,COBBLESTONE)
B(0,1,-2,COBBLESTONE)
B(1,1,-2,COBBLESTONE)
B(2,1,-2,COBBLESTONE)
B(3,1,-2,COBBLESTONE)
B(4,1,-2,COBBLESTONE)
B(5,1,-2,COBBLESTONE)
B(6,1,-2,COBBLESTONE)
B(7,1,-2,COBBLESTONE)
B(-8,1,-1,COBBLESTONE)
B(-7,1,-1,COBBLESTONE)
B(-6,1,-1,COBBLESTONE)
B(-5,1,-1,COBBLESTONE)
B(-4,1,-1,COBBLESTONE)
B(-3,1,-1,COBBLESTONE)
B(-2,1,-1,COBBLESTONE)
B(-1,1,-1,COBBLESTONE)
B(0,1,-1,COBBLESTONE)
B(1,1,-1,COBBLESTONE)
B(2,1,-1,COBBLESTONE)
B(3,1,-1,COBBLESTONE)
B(4,1,-1,COBBLESTONE)
B(5,1,-1,COBBLESTONE)
B(6,1,-1,COBBLESTONE)
B(7,1,-1,COBBLESTONE)
B(-8,1,0,COBBLESTONE)
B(-7,1,0,COBBLESTONE)
B(-6,1,0,COBBLESTONE)
B(-5,1,0,COBBLESTONE)
B(-4,1,0,COBBLESTONE)
B(-3,1,0,COBBLESTONE)
B(-2,1,0,COBBLESTONE)
B(-1,1,0,COBBLESTONE)
B(0,1,0,COBBLESTONE)
B(1,1,0,COBBLESTONE)
B(2,1,0,COBBLESTONE)
B(3,1,0,COBBLESTONE)
B(4,1,0,COBBLESTONE)
B(5,1,0,COBBLESTONE)
B(6,1,0,COBBLESTONE)
B(7,1,0,COBBLESTONE)
B(-8,1,1,COBBLESTONE)
B(-7,1,1,COBBLESTONE)
B(-6,1,1,COBBLESTONE)
B(-5,1,1,COBBLESTONE)
B(-4,1,1,COBBLESTONE)
B(-3,1,1,COBBLESTONE)
B(-2,1,1,COBBLESTONE)
B(-1,1,1,COBBLESTONE)
B(0,1,1,COBBLESTONE)
B(1,1,1,COBBLESTONE)
B(2,1,1,COBBLESTONE)
B(3,1,1,COBBLESTONE)
B(4,1,1,COBBLESTONE)
B(5,1,1,COBBLESTONE)
B(6,1,1,COBBLESTONE)
B(7,1,1,COBBLESTONE)
B(-8,1,2,COBBLESTONE)
B(-7,1,2,COBBLESTONE)
B(-6,1,2,COBBLESTONE)
B(-5,1,2,COBBLESTONE)
B(-4,1,2,COBBLESTONE)
B(-3,1,2,COBBLESTONE)
B(-2,1,2,COBBLESTONE)
B(-1,1,2,COBBLESTONE)
B(0,1,2,COBBLESTONE)
B(1,1,2,COBBLESTONE)
B(2,1,2,COBBLESTONE)
B(3,1,2,COBBLESTONE)
B(4,1,2,COBBLESTONE)
B(5,1,2,COBBLESTONE)
B(6,1,2,COBBLESTONE)
B(7,1,2,COBBLESTONE)
B(-8,1,3,COBBLESTONE)
B(-7,1,3,COBBLESTONE)
B(-6,1,3,COBBLESTONE)
B(-5,1,3,COBBLESTONE)
B(-4,1,3,COBBLESTONE)
B(-3,1,3,COBBLESTONE)
B(-2,1,3,COBBLESTONE)
B(-1,1,3,COBBLESTONE)
B(0,1,3,COBBLESTONE)
B(1,1,3,COBBLESTONE)
B(2,1,3,COBBLESTONE)
B(3,1,3,COBBLESTONE)
B(4,1,3,COBBLESTONE)
B(5,1,3,COBBLESTONE)
B(6,1,3,COBBLESTONE)
B(7,1,3,COBBLESTONE)
B(-8,1,4,COBBLESTONE)
B(-7,1,4,COBBLESTONE)
B(-6,1,4,COBBLESTONE)
B(-5,1,4,COBBLESTONE)
B(-4,1,4,COBBLESTONE)
B(-3,1,4,COBBLESTONE)
B(-2,1,4,COBBLESTONE)
B(-1,1,4,COBBLESTONE)
B(0,1,4,COBBLESTONE)
B(1,1,4,COBBLESTONE)
B(2,1,4,COBBLESTONE)
B(3,1,4,COBBLESTONE)
B(4,1,4,COBBLESTONE)
B(5,1,4,COBBLESTONE)
B(6,1,4,COBBLESTONE)
B(7,1,4,COBBLESTONE)
B(-8,1,5,COBBLESTONE)
B(-7,1,5,COBBLESTONE)
B(-6,1,5,COBBLESTONE)
B(-5,1,5,COBBLESTONE)
B(-4,1,5,COBBLESTONE)
B(-3,1,5,COBBLESTONE)
B(-2,1,5,COBBLESTONE)
B(-1,1,5,COBBLESTONE)
B(0,1,5,COBBLESTONE)
B(1,1,5,COBBLESTONE)
B(2,1,5,COBBLESTONE)
B(3,1,5,COBBLESTONE)
B(4,1,5,COBBLESTONE)
B(5,1,5,COBBLESTONE)
B(6,1,5,COBBLESTONE)
B(7,1,5,COBBLESTONE)
B(-8,1,6,COBBLESTONE)
B(-7,1,6,COBBLESTONE)
B(-6,1,6,COBBLESTONE)
B(-5,1,6,COBBLESTONE)
B(-4,1,6,COBBLESTONE)
B(-3,1,6,COBBLESTONE)
B(-2,1,6,COBBLESTONE)
B(-1,1,6,COBBLESTONE)
B(0,1,6,COBBLESTONE)
B(1,1,6,COBBLESTONE)
B(2,1,6,COBBLESTONE)
B(3,1,6,COBBLESTONE)
B(4,1,6,COBBLESTONE)
B(5,1,6,COBBLESTONE)
B(6,1,6,COBBLESTONE)
B(7,1,6,COBBLESTONE)
B(-8,2,-8,COBBLESTONE)
B(-7,2,-8,COBBLESTONE)
B(-6,2,-8,COBBLESTONE)
B(-5,2,-8,COBBLESTONE)
B(-4,2,-8,COBBLESTONE)
B(-3,2,-8,COBBLESTONE)
B(-2,2,-8,COBBLESTONE)
B(-1,2,-8,COBBLESTONE)
B(0,2,-8,COBBLESTONE)
B(1,2,-8,COBBLESTONE)
B(2,2,-8,COBBLESTONE)
B(3,2,-8,COBBLESTONE)
B(4,2,-8,COBBLESTONE)
B(5,2,-8,COBBLESTONE)
B(6,2,-8,COBBLESTONE)
B(7,2,-8,COBBLESTONE)
B(-8,2,-7,COBBLESTONE)
B(-7,2,-7,COBBLESTONE)
B(-6,2,-7,COBBLESTONE)
B(-5,2,-7,COBBLESTONE)
B(-4,2,-7,COBBLESTONE)
B(-3,2,-7,COBBLESTONE)
B(-2,2,-7,COBBLESTONE)
B(-1,2,-7,COBBLESTONE)
B(0,2,-7,COBBLESTONE)
B(1,2,-7,COBBLESTONE)
B(2,2,-7,COBBLESTONE)
B(3,2,-7,COBBLESTONE)
B(4,2,-7,COBBLESTONE)
B(5,2,-7,COBBLESTONE)
B(6,2,-7,COBBLESTONE)
B(7,2,-7,COBBLESTONE)
B(-8,2,-6,COBBLESTONE)
B(-7,2,-6,COBBLESTONE)
B(-6,2,-6,COBBLESTONE)
B(-5,2,-6,COBBLESTONE)
B(-4,2,-6,COBBLESTONE)
B(-3,2,-6,COBBLESTONE)
B(-2,2,-6,COBBLESTONE)
B(-1,2,-6,COBBLESTONE)
B(0,2,-6,COBBLESTONE)
B(1,2,-6,COBBLESTONE)
B(2,2,-6,COBBLESTONE)
B(3,2,-6,COBBLESTONE)
B(4,2,-6,COBBLESTONE)
B(5,2,-6,COBBLESTONE)
B(6,2,-6,COBBLESTONE)
B(7,2,-6,COBBLESTONE)
B(-8,2,-5,COBBLESTONE)
B(-7,2,-5,COBBLESTONE)
B(-6,2,-5,COBBLESTONE)
B(-5,2,-5,COBBLESTONE)
B(-4,2,-5,COBBLESTONE)
B(-3,2,-5,COBBLESTONE)
B(-2,2,-5,COBBLESTONE)
B(-1,2,-5,COBBLESTONE)
B(0,2,-5,COBBLESTONE)
B(1,2,-5,COBBLESTONE)
B(2,2,-5,COBBLESTONE)
B(3,2,-5,COBBLESTONE)
B(4,2,-5,COBBLESTONE)
B(5,2,-5,COBBLESTONE)
B(6,2,-5,COBBLESTONE)
B(7,2,-5,COBBLESTONE)
B(-8,2,-4,COBBLESTONE)
B(-7,2,-4,COBBLESTONE)
B(-6,2,-4,COBBLESTONE)
B(-5,2,-4,COBBLESTONE)
B(-4,2,-4,COBBLESTONE)
B(-3,2,-4,COBBLESTONE)
B(-2,2,-4,COBBLESTONE)
B(-1,2,-4,COBBLESTONE)
B(0,2,-4,COBBLESTONE)
B(1,2,-4,COBBLESTONE)
B(2,2,-4,COBBLESTONE)
B(3,2,-4,COBBLESTONE)
B(4,2,-4,COBBLESTONE)
B(5,2,-4,COBBLESTONE)
B(6,2,-4,COBBLESTONE)
B(7,2,-4,COBBLESTONE)
B(-8,2,-3,COBBLESTONE)
B(-7,2,-3,COBBLESTONE)
B(-6,2,-3,COBBLESTONE)
B(-5,2,-3,COBBLESTONE)
B(-4,2,-3,COBBLESTONE)
B(-3,2,-3,COBBLESTONE)
B(-2,2,-3,COBBLESTONE)
B(-1,2,-3,COBBLESTONE)
B(0,2,-3,COBBLESTONE)
B(1,2,-3,COBBLESTONE)
B(2,2,-3,COBBLESTONE)
B(3,2,-3,COBBLESTONE)
B(4,2,-3,COBBLESTONE)
B(5,2,-3,COBBLESTONE)
B(6,2,-3,COBBLESTONE)
B(7,2,-3,COBBLESTONE)
B(-8,2,-2,COBBLESTONE)
B(-7,2,-2,COBBLESTONE)
B(-6,2,-2,COBBLESTONE)
B(-5,2,-2,COBBLESTONE)
B(-4,2,-2,COBBLESTONE)
B(-3,2,-2,COBBLESTONE)
B(-2,2,-2,COBBLESTONE)
B(-1,2,-2,COBBLESTONE)
RB(0,2,-2,SKULL:1,./NBT/Skulls/dungeon_skull_01.nbt,6,AIR,9,SKULL:1,./NBT/Skulls/dungeon_skull_02.nbt,12,AIR,15,SKULL:1,./NBT/Skulls/dungeon_skull_03.nbt,18,AIR,21,SKULL:1,./NBT/Skulls/dungeon_skull_04.nbt,24,AIR,27,SKULL:1,./NBT/Skulls/dungeon_skull_05.nbt,30,AIR,33,SKULL:1,./NBT/Skulls/dungeon_skull_06.nbt,36,AIR,39,SKULL:1,./NBT/Skulls/dungeon_skull_07.nbt,42,AIR,45,SKULL:1,./NBT/Skulls/dungeon_skull_08.nbt,48,AIR,51,SKULL:1,./NBT/Skulls/dungeon_skull_09.nbt,54,AIR,57,SKULL:1,./NBT/Skulls/dungeon_skull_10.nbt,60,AIR,63,SKULL:1,./NBT/Skulls/dungeon_skull_11.nbt,66,AIR,69,SKULL:1,./NBT/Skulls/dungeon_skull_12.nbt,72,AIR,75,SKULL:1,./NBT/Skulls/dungeon_skull_13.nbt,78,AIR,81,SKULL:1,./NBT/Skulls/dungeon_skull_14.nbt,84,AIR,87,SKULL:1,./NBT/Skulls/dungeon_skull_15.nbt,90,AIR,93,SKULL:1,./NBT/Skulls/dungeon_skull_16.nbt,96,AIR,100)
B(1,2,-2,COBBLESTONE)
B(2,2,-2,COBBLESTONE)
RB(3,2,-2,SKULL:1,./NBT/Skulls/dungeon_skull_01.nbt,6,AIR,9,SKULL:1,./NBT/Skulls/dungeon_skull_02.nbt,12,AIR,15,SKULL:1,./NBT/Skulls/dungeon_skull_03.nbt,18,AIR,21,SKULL:1,./NBT/Skulls/dungeon_skull_04.nbt,24,AIR,27,SKULL:1,./NBT/Skulls/dungeon_skull_05.nbt,30,AIR,33,SKULL:1,./NBT/Skulls/dungeon_skull_06.nbt,36,AIR,39,SKULL:1,./NBT/Skulls/dungeon_skull_07.nbt,42,AIR,45,SKULL:1,./NBT/Skulls/dungeon_skull_08.nbt,48,AIR,51,SKULL:1,./NBT/Skulls/dungeon_skull_09.nbt,54,AIR,57,SKULL:1,./NBT/Skulls/dungeon_skull_10.nbt,60,AIR,63,SKULL:1,./NBT/Skulls/dungeon_skull_11.nbt,66,AIR,69,SKULL:1,./NBT/Skulls/dungeon_skull_12.nbt,72,AIR,75,SKULL:1,./NBT/Skulls/dungeon_skull_13.nbt,78,AIR,81,SKULL:1,./NBT/Skulls/dungeon_skull_14.nbt,84,AIR,87,SKULL:1,./NBT/Skulls/dungeon_skull_15.nbt,90,AIR,93,SKULL:1,./NBT/Skulls/dungeon_skull_16.nbt,96,AIR,100)
B(4,2,-2,COBBLESTONE)
B(5,2,-2,COBBLESTONE)
B(6,2,-2,COBBLESTONE)
B(7,2,-2,COBBLESTONE)
B(-8,2,-1,COBBLESTONE)
B(-7,2,-1,COBBLESTONE)
B(-6,2,-1,COBBLESTONE)
B(-5,2,-1,COBBLESTONE)
B(-4,2,-1,COBBLESTONE)
B(-3,2,-1,COBBLESTONE)
RB(-2,2,-1,SKULL:1,./NBT/Skulls/dungeon_skull_01.nbt,6,AIR,9,SKULL:1,./NBT/Skulls/dungeon_skull_02.nbt,12,AIR,15,SKULL:1,./NBT/Skulls/dungeon_skull_03.nbt,18,AIR,21,SKULL:1,./NBT/Skulls/dungeon_skull_04.nbt,24,AIR,27,SKULL:1,./NBT/Skulls/dungeon_skull_05.nbt,30,AIR,33,SKULL:1,./NBT/Skulls/dungeon_skull_06.nbt,36,AIR,39,SKULL:1,./NBT/Skulls/dungeon_skull_07.nbt,42,AIR,45,SKULL:1,./NBT/Skulls/dungeon_skull_08.nbt,48,AIR,51,SKULL:1,./NBT/Skulls/dungeon_skull_09.nbt,54,AIR,57,SKULL:1,./NBT/Skulls/dungeon_skull_10.nbt,60,AIR,63,SKULL:1,./NBT/Skulls/dungeon_skull_11.nbt,66,AIR,69,SKULL:1,./NBT/Skulls/dungeon_skull_12.nbt,72,AIR,75,SKULL:1,./NBT/Skulls/dungeon_skull_13.nbt,78,AIR,81,SKULL:1,./NBT/Skulls/dungeon_skull_14.nbt,84,AIR,87,SKULL:1,./NBT/Skulls/dungeon_skull_15.nbt,90,AIR,93,SKULL:1,./NBT/Skulls/dungeon_skull_16.nbt,96,AIR,100)
RB(-1,2,-1,SKULL:1,./NBT/Skulls/dungeon_skull_01.nbt,6,AIR,9,SKULL:1,./NBT/Skulls/dungeon_skull_02.nbt,12,AIR,15,SKULL:1,./NBT/Skulls/dungeon_skull_03.nbt,18,AIR,21,SKULL:1,./NBT/Skulls/dungeon_skull_04.nbt,24,AIR,27,SKULL:1,./NBT/Skulls/dungeon_skull_05.nbt,30,AIR,33,SKULL:1,./NBT/Skulls/dungeon_skull_06.nbt,36,AIR,39,SKULL:1,./NBT/Skulls/dungeon_skull_07.nbt,42,AIR,45,SKULL:1,./NBT/Skulls/dungeon_skull_08.nbt,48,AIR,51,SKULL:1,./NBT/Skulls/dungeon_skull_09.nbt,54,AIR,57,SKULL:1,./NBT/Skulls/dungeon_skull_10.nbt,60,AIR,63,SKULL:1,./NBT/Skulls/dungeon_skull_11.nbt,66,AIR,69,SKULL:1,./NBT/Skulls/dungeon_skull_12.nbt,72,AIR,75,SKULL:1,./NBT/Skulls/dungeon_skull_13.nbt,78,AIR,81,SKULL:1,./NBT/Skulls/dungeon_skull_14.nbt,84,AIR,87,SKULL:1,./NBT/Skulls/dungeon_skull_15.nbt,90,AIR,93,SKULL:1,./NBT/Skulls/dungeon_skull_16.nbt,96,AIR,100)
B(0,2,-1,COBBLESTONE)
RB(1,2,-1,SKULL:1,./NBT/Skulls/dungeon_skull_01.nbt,6,AIR,9,SKULL:1,./NBT/Skulls/dungeon_skull_02.nbt,12,AIR,15,SKULL:1,./NBT/Skulls/dungeon_skull_03.nbt,18,AIR,21,SKULL:1,./NBT/Skulls/dungeon_skull_04.nbt,24,AIR,27,SKULL:1,./NBT/Skulls/dungeon_skull_05.nbt,30,AIR,33,SKULL:1,./NBT/Skulls/dungeon_skull_06.nbt,36,AIR,39,SKULL:1,./NBT/Skulls/dungeon_skull_07.nbt,42,AIR,45,SKULL:1,./NBT/Skulls/dungeon_skull_08.nbt,48,AIR,51,SKULL:1,./NBT/Skulls/dungeon_skull_09.nbt,54,AIR,57,SKULL:1,./NBT/Skulls/dungeon_skull_10.nbt,60,AIR,63,SKULL:1,./NBT/Skulls/dungeon_skull_11.nbt,66,AIR,69,SKULL:1,./NBT/Skulls/dungeon_skull_12.nbt,72,AIR,75,SKULL:1,./NBT/Skulls/dungeon_skull_13.nbt,78,AIR,81,SKULL:1,./NBT/Skulls/dungeon_skull_14.nbt,84,AIR,87,SKULL:1,./NBT/Skulls/dungeon_skull_15.nbt,90,AIR,93,SKULL:1,./NBT/Skulls/dungeon_skull_16.nbt,96,AIR,100)
RB(2,2,-1,SKULL:1,./NBT/Skulls/dungeon_skull_01.nbt,6,AIR,9,SKULL:1,./NBT/Skulls/dungeon_skull_02.nbt,12,AIR,15,SKULL:1,./NBT/Skulls/dungeon_skull_03.nbt,18,AIR,21,SKULL:1,./NBT/Skulls/dungeon_skull_04.nbt,24,AIR,27,SKULL:1,./NBT/Skulls/dungeon_skull_05.nbt,30,AIR,33,SKULL:1,./NBT/Skulls/dungeon_skull_06.nbt,36,AIR,39,SKULL:1,./NBT/Skulls/dungeon_skull_07.nbt,42,AIR,45,SKULL:1,./NBT/Skulls/dungeon_skull_08.nbt,48,AIR,51,SKULL:1,./NBT/Skulls/dungeon_skull_09.nbt,54,AIR,57,SKULL:1,./NBT/Skulls/dungeon_skull_10.nbt,60,AIR,63,SKULL:1,./NBT/Skulls/dungeon_skull_11.nbt,66,AIR,69,SKULL:1,./NBT/Skulls/dungeon_skull_12.nbt,72,AIR,75,SKULL:1,./NBT/Skulls/dungeon_skull_13.nbt,78,AIR,81,SKULL:1,./NBT/Skulls/dungeon_skull_14.nbt,84,AIR,87,SKULL:1,./NBT/Skulls/dungeon_skull_15.nbt,90,AIR,93,SKULL:1,./NBT/Skulls/dungeon_skull_16.nbt,96,AIR,100)
RB(3,2,-1,SKULL:1,./NBT/Skulls/dungeon_skull_01.nbt,6,AIR,9,SKULL:1,./NBT/Skulls/dungeon_skull_02.nbt,12,AIR,15,SKULL:1,./NBT/Skulls/dungeon_skull_03.nbt,18,AIR,21,SKULL:1,./NBT/Skulls/dungeon_skull_04.nbt,24,AIR,27,SKULL:1,./NBT/Skulls/dungeon_skull_05.nbt,30,AIR,33,SKULL:1,./NBT/Skulls/dungeon_skull_06.nbt,36,AIR,39,SKULL:1,./NBT/Skulls/dungeon_skull_07.nbt,42,AIR,45,SKULL:1,./NBT/Skulls/dungeon_skull_08.nbt,48,AIR,51,SKULL:1,./NBT/Skulls/dungeon_skull_09.nbt,54,AIR,57,SKULL:1,./NBT/Skulls/dungeon_skull_10.nbt,60,AIR,63,SKULL:1,./NBT/Skulls/dungeon_skull_11.nbt,66,AIR,69,SKULL:1,./NBT/Skulls/dungeon_skull_12.nbt,72,AIR,75,SKULL:1,./NBT/Skulls/dungeon_skull_13.nbt,78,AIR,81,SKULL:1,./NBT/Skulls/dungeon_skull_14.nbt,84,AIR,87,SKULL:1,./NBT/Skulls/dungeon_skull_15.nbt,90,AIR,93,SKULL:1,./NBT/Skulls/dungeon_skull_16.nbt,96,AIR,100)
RB(4,2,-1,SKULL:1,./NBT/Skulls/dungeon_skull_01.nbt,6,AIR,9,SKULL:1,./NBT/Skulls/dungeon_skull_02.nbt,12,AIR,15,SKULL:1,./NBT/Skulls/dungeon_skull_03.nbt,18,AIR,21,SKULL:1,./NBT/Skulls/dungeon_skull_04.nbt,24,AIR,27,SKULL:1,./NBT/Skulls/dungeon_skull_05.nbt,30,AIR,33,SKULL:1,./NBT/Skulls/dungeon_skull_06.nbt,36,AIR,39,SKULL:1,./NBT/Skulls/dungeon_skull_07.nbt,42,AIR,45,SKULL:1,./NBT/Skulls/dungeon_skull_08.nbt,48,AIR,51,SKULL:1,./NBT/Skulls/dungeon_skull_09.nbt,54,AIR,57,SKULL:1,./NBT/Skulls/dungeon_skull_10.nbt,60,AIR,63,SKULL:1,./NBT/Skulls/dungeon_skull_11.nbt,66,AIR,69,SKULL:1,./NBT/Skulls/dungeon_skull_12.nbt,72,AIR,75,SKULL:1,./NBT/Skulls/dungeon_skull_13.nbt,78,AIR,81,SKULL:1,./NBT/Skulls/dungeon_skull_14.nbt,84,AIR,87,SKULL:1,./NBT/Skulls/dungeon_skull_15.nbt,90,AIR,93,SKULL:1,./NBT/Skulls/dungeon_skull_16.nbt,96,AIR,100)
B(5,2,-1,COBBLESTONE)
RB(6,2,-1,SKULL:1,./NBT/Skulls/dungeon_skull_01.nbt,6,AIR,9,SKULL:1,./NBT/Skulls/dungeon_skull_02.nbt,12,AIR,15,SKULL:1,./NBT/Skulls/dungeon_skull_03.nbt,18,AIR,21,SKULL:1,./NBT/Skulls/dungeon_skull_04.nbt,24,AIR,27,SKULL:1,./NBT/Skulls/dungeon_skull_05.nbt,30,AIR,33,SKULL:1,./NBT/Skulls/dungeon_skull_06.nbt,36,AIR,39,SKULL:1,./NBT/Skulls/dungeon_skull_07.nbt,42,AIR,45,SKULL:1,./NBT/Skulls/dungeon_skull_08.nbt,48,AIR,51,SKULL:1,./NBT/Skulls/dungeon_skull_09.nbt,54,AIR,57,SKULL:1,./NBT/Skulls/dungeon_skull_10.nbt,60,AIR,63,SKULL:1,./NBT/Skulls/dungeon_skull_11.nbt,66,AIR,69,SKULL:1,./NBT/Skulls/dungeon_skull_12.nbt,72,AIR,75,SKULL:1,./NBT/Skulls/dungeon_skull_13.nbt,78,AIR,81,SKULL:1,./NBT/Skulls/dungeon_skull_14.nbt,84,AIR,87,SKULL:1,./NBT/Skulls/dungeon_skull_15.nbt,90,AIR,93,SKULL:1,./NBT/Skulls/dungeon_skull_16.nbt,96,AIR,100)
RB(7,2,-1,SKULL:1,./NBT/Skulls/dungeon_skull_01.nbt,6,AIR,9,SKULL:1,./NBT/Skulls/dungeon_skull_02.nbt,12,AIR,15,SKULL:1,./NBT/Skulls/dungeon_skull_03.nbt,18,AIR,21,SKULL:1,./NBT/Skulls/dungeon_skull_04.nbt,24,AIR,27,SKULL:1,./NBT/Skulls/dungeon_skull_05.nbt,30,AIR,33,SKULL:1,./NBT/Skulls/dungeon_skull_06.nbt,36,AIR,39,SKULL:1,./NBT/Skulls/dungeon_skull_07.nbt,42,AIR,45,SKULL:1,./NBT/Skulls/dungeon_skull_08.nbt,48,AIR,51,SKULL:1,./NBT/Skulls/dungeon_skull_09.nbt,54,AIR,57,SKULL:1,./NBT/Skulls/dungeon_skull_10.nbt,60,AIR,63,SKULL:1,./NBT/Skulls/dungeon_skull_11.nbt,66,AIR,69,SKULL:1,./NBT/Skulls/dungeon_skull_12.nbt,72,AIR,75,SKULL:1,./NBT/Skulls/dungeon_skull_13.nbt,78,AIR,81,SKULL:1,./NBT/Skulls/dungeon_skull_14.nbt,84,AIR,87,SKULL:1,./NBT/Skulls/dungeon_skull_15.nbt,90,AIR,93,SKULL:1,./NBT/Skulls/dungeon_skull_16.nbt,96,AIR,100)
B(-8,2,0,COBBLESTONE)
B(-7,2,0,COBBLESTONE)
B(-6,2,0,COBBLESTONE)
B(-5,2,0,COBBLESTONE)
B(-4,2,0,COBBLESTONE)
B(-3,2,0,COBBLESTONE)
B(-2,2,0,COBBLESTONE)
B(-1,2,0,COBBLESTONE)
B(0,2,0,COBBLESTONE)
B(1,2,0,COBBLESTONE)
B(2,2,0,COBBLESTONE)
RB(3,2,0,SKULL:1,./NBT/Skulls/dungeon_skull_01.nbt,6,AIR,9,SKULL:1,./NBT/Skulls/dungeon_skull_02.nbt,12,AIR,15,SKULL:1,./NBT/Skulls/dungeon_skull_03.nbt,18,AIR,21,SKULL:1,./NBT/Skulls/dungeon_skull_04.nbt,24,AIR,27,SKULL:1,./NBT/Skulls/dungeon_skull_05.nbt,30,AIR,33,SKULL:1,./NBT/Skulls/dungeon_skull_06.nbt,36,AIR,39,SKULL:1,./NBT/Skulls/dungeon_skull_07.nbt,42,AIR,45,SKULL:1,./NBT/Skulls/dungeon_skull_08.nbt,48,AIR,51,SKULL:1,./NBT/Skulls/dungeon_skull_09.nbt,54,AIR,57,SKULL:1,./NBT/Skulls/dungeon_skull_10.nbt,60,AIR,63,SKULL:1,./NBT/Skulls/dungeon_skull_11.nbt,66,AIR,69,SKULL:1,./NBT/Skulls/dungeon_skull_12.nbt,72,AIR,75,SKULL:1,./NBT/Skulls/dungeon_skull_13.nbt,78,AIR,81,SKULL:1,./NBT/Skulls/dungeon_skull_14.nbt,84,AIR,87,SKULL:1,./NBT/Skulls/dungeon_skull_15.nbt,90,AIR,93,SKULL:1,./NBT/Skulls/dungeon_skull_16.nbt,96,AIR,100)
RB(4,2,0,SKULL:1,./NBT/Skulls/dungeon_skull_01.nbt,6,AIR,9,SKULL:1,./NBT/Skulls/dungeon_skull_02.nbt,12,AIR,15,SKULL:1,./NBT/Skulls/dungeon_skull_03.nbt,18,AIR,21,SKULL:1,./NBT/Skulls/dungeon_skull_04.nbt,24,AIR,27,SKULL:1,./NBT/Skulls/dungeon_skull_05.nbt,30,AIR,33,SKULL:1,./NBT/Skulls/dungeon_skull_06.nbt,36,AIR,39,SKULL:1,./NBT/Skulls/dungeon_skull_07.nbt,42,AIR,45,SKULL:1,./NBT/Skulls/dungeon_skull_08.nbt,48,AIR,51,SKULL:1,./NBT/Skulls/dungeon_skull_09.nbt,54,AIR,57,SKULL:1,./NBT/Skulls/dungeon_skull_10.nbt,60,AIR,63,SKULL:1,./NBT/Skulls/dungeon_skull_11.nbt,66,AIR,69,SKULL:1,./NBT/Skulls/dungeon_skull_12.nbt,72,AIR,75,SKULL:1,./NBT/Skulls/dungeon_skull_13.nbt,78,AIR,81,SKULL:1,./NBT/Skulls/dungeon_skull_14.nbt,84,AIR,87,SKULL:1,./NBT/Skulls/dungeon_skull_15.nbt,90,AIR,93,SKULL:1,./NBT/Skulls/dungeon_skull_16.nbt,96,AIR,100)
RB(5,2,0,SKULL:1,./NBT/Skulls/dungeon_skull_01.nbt,6,AIR,9,SKULL:1,./NBT/Skulls/dungeon_skull_02.nbt,12,AIR,15,SKULL:1,./NBT/Skulls/dungeon_skull_03.nbt,18,AIR,21,SKULL:1,./NBT/Skulls/dungeon_skull_04.nbt,24,AIR,27,SKULL:1,./NBT/Skulls/dungeon_skull_05.nbt,30,AIR,33,SKULL:1,./NBT/Skulls/dungeon_skull_06.nbt,36,AIR,39,SKULL:1,./NBT/Skulls/dungeon_skull_07.nbt,42,AIR,45,SKULL:1,./NBT/Skulls/dungeon_skull_08.nbt,48,AIR,51,SKULL:1,./NBT/Skulls/dungeon_skull_09.nbt,54,AIR,57,SKULL:1,./NBT/Skulls/dungeon_skull_10.nbt,60,AIR,63,SKULL:1,./NBT/Skulls/dungeon_skull_11.nbt,66,AIR,69,SKULL:1,./NBT/Skulls/dungeon_skull_12.nbt,72,AIR,75,SKULL:1,./NBT/Skulls/dungeon_skull_13.nbt,78,AIR,81,SKULL:1,./NBT/Skulls/dungeon_skull_14.nbt,84,AIR,87,SKULL:1,./NBT/Skulls/dungeon_skull_15.nbt,90,AIR,93,SKULL:1,./NBT/Skulls/dungeon_skull_16.nbt,96,AIR,100)
B(6,2,0,COBBLESTONE)
B(7,2,0,COBBLESTONE)
B(-8,2,1,COBBLESTONE)
B(-7,2,1,COBBLESTONE)
B(-6,2,1,COBBLESTONE)
B(-5,2,1,COBBLESTONE)
B(-4,2,1,COBBLESTONE)
B(-3,2,1,COBBLESTONE)
B(-2,2,1,COBBLESTONE)
B(-1,2,1,COBBLESTONE)
B(0,2,1,COBBLESTONE)
B(1,2,1,COBBLESTONE)
B(2,2,1,COBBLESTONE)
B(3,2,1,COBBLESTONE)
B(4,2,1,COBBLESTONE)
B(5,2,1,COBBLESTONE)
B(6,2,1,COBBLESTONE)
B(7,2,1,COBBLESTONE)
B(-8,2,2,COBBLESTONE)
B(-7,2,2,COBBLESTONE)
B(-6,2,2,COBBLESTONE)
B(-5,2,2,COBBLESTONE)
B(-4,2,2,COBBLESTONE)
B(-3,2,2,COBBLESTONE)
B(-2,2,2,COBBLESTONE)
B(-1,2,2,COBBLESTONE)
B(0,2,2,COBBLESTONE)
B(1,2,2,COBBLESTONE)
B(2,2,2,COBBLESTONE)
B(3,2,2,COBBLESTONE)
B(4,2,2,COBBLESTONE)
B(5,2,2,COBBLESTONE)
B(6,2,2,COBBLESTONE)
B(7,2,2,COBBLESTONE)
B(-8,2,3,COBBLESTONE)
B(-7,2,3,COBBLESTONE)
B(-6,2,3,COBBLESTONE)
B(-5,2,3,COBBLESTONE)
B(-4,2,3,COBBLESTONE)
B(-3,2,3,COBBLESTONE)
B(-2,2,3,COBBLESTONE)
B(-1,2,3,COBBLESTONE)
B(0,2,3,COBBLESTONE)
B(1,2,3,COBBLESTONE)
B(2,2,3,COBBLESTONE)
B(3,2,3,COBBLESTONE)
B(4,2,3,COBBLESTONE)
B(5,2,3,COBBLESTONE)
B(6,2,3,COBBLESTONE)
B(7,2,3,COBBLESTONE)
B(-8,2,4,COBBLESTONE)
B(-7,2,4,COBBLESTONE)
B(-6,2,4,COBBLESTONE)
B(-5,2,4,COBBLESTONE)
B(-4,2,4,COBBLESTONE)
B(-3,2,4,COBBLESTONE)
B(-2,2,4,COBBLESTONE)
B(-1,2,4,COBBLESTONE)
B(0,2,4,COBBLESTONE)
B(1,2,4,COBBLESTONE)
B(2,2,4,COBBLESTONE)
B(3,2,4,COBBLESTONE)
B(4,2,4,COBBLESTONE)
B(5,2,4,COBBLESTONE)
B(6,2,4,COBBLESTONE)
B(7,2,4,COBBLESTONE)
B(-8,2,5,COBBLESTONE)
B(-7,2,5,COBBLESTONE)
B(-6,2,5,COBBLESTONE)
B(-5,2,5,COBBLESTONE)
B(-4,2,5,COBBLESTONE)
B(-3,2,5,COBBLESTONE)
B(-2,2,5,COBBLESTONE)
B(-1,2,5,COBBLESTONE)
B(0,2,5,COBBLESTONE)
B(1,2,5,COBBLESTONE)
B(2,2,5,COBBLESTONE)
B(3,2,5,COBBLESTONE)
B(4,2,5,COBBLESTONE)
B(5,2,5,COBBLESTONE)
B(6,2,5,COBBLESTONE)
B(7,2,5,COBBLESTONE)
B(-8,2,6,COBBLESTONE)
B(-7,2,6,COBBLESTONE)
B(-6,2,6,COBBLESTONE)
B(-5,2,6,COBBLESTONE)
B(-4,2,6,COBBLESTONE)
B(-3,2,6,COBBLESTONE)
B(-2,2,6,COBBLESTONE)
B(-1,2,6,COBBLESTONE)
B(0,2,6,COBBLESTONE)
B(1,2,6,COBBLESTONE)
B(2,2,6,COBBLESTONE)
B(3,2,6,COBBLESTONE)
B(4,2,6,COBBLESTONE)
B(5,2,6,COBBLESTONE)
B(6,2,6,COBBLESTONE)
B(7,2,6,COBBLESTONE)
B(-8,3,-8,STONE:6)
B(-7,3,-8,AIR)
B(-6,3,-8,STONE:6)
RB(-5,3,-8,SKULL:1,./NBT/Skulls/dungeon_skull_01.nbt,6,AIR,9,SKULL:1,./NBT/Skulls/dungeon_skull_02.nbt,12,AIR,15,SKULL:1,./NBT/Skulls/dungeon_skull_03.nbt,18,AIR,21,SKULL:1,./NBT/Skulls/dungeon_skull_04.nbt,24,AIR,27,SKULL:1,./NBT/Skulls/dungeon_skull_05.nbt,30,AIR,33,SKULL:1,./NBT/Skulls/dungeon_skull_06.nbt,36,AIR,39,SKULL:1,./NBT/Skulls/dungeon_skull_07.nbt,42,AIR,45,SKULL:1,./NBT/Skulls/dungeon_skull_08.nbt,48,AIR,51,SKULL:1,./NBT/Skulls/dungeon_skull_09.nbt,54,AIR,57,SKULL:1,./NBT/Skulls/dungeon_skull_10.nbt,60,AIR,63,SKULL:1,./NBT/Skulls/dungeon_skull_11.nbt,66,AIR,69,SKULL:1,./NBT/Skulls/dungeon_skull_12.nbt,72,AIR,75,SKULL:1,./NBT/Skulls/dungeon_skull_13.nbt,78,AIR,81,SKULL:1,./NBT/Skulls/dungeon_skull_14.nbt,84,AIR,87,SKULL:1,./NBT/Skulls/dungeon_skull_15.nbt,90,AIR,93,SKULL:1,./NBT/Skulls/dungeon_skull_16.nbt,96,AIR,100)
B(-4,3,-8,IRON_BARS)
B(-3,3,-8,LIGHT_WEIGHTED_PRESSURE_PLATE)
B(-2,3,-8,STONE_SLAB:7)
B(-1,3,-8,STONEBRICK:3)
RB(0,3,-8,CHEST:5,./NBT/StructureLoot/JunkChest_1.nbt,10,CHEST:5,./NBT/StructureLoot/JunkChest_2.nbt,5,CHEST:5,./NBT/StructureLoot/JunkChest_3.nbt,5,CHEST:5,./NBT/StructureLoot/JunkChest_4.nbt,5,CHEST:5,./NBT/StructureLoot/JunkChest_5.nbt,5,CHEST:5,./NBT/Lorestoryline/LoreSpooky_5.nbt,2,CHEST:5,./NBT/Lorestoryline/LoreSpooky_4.nbt,2,CHEST:5,./NBT/Lorestoryline/LoreSpooky_3.nbt,2,CHEST:5,./NBT/Lorestoryline/LoreSpooky_2.nbt,2,CHEST:5,./NBT/Lorestoryline/LoreSpooky_1.nbt,2,CHEST:5,./NBT/StructureLoot/JunkChest_1.nbt,10,CHEST:5,./NBT/StructureLoot/JunkChest_2.nbt,5,CHEST:5,./NBT/StructureLoot/JunkChest_3.nbt,5,CHEST:5,./NBT/StructureLoot/JunkChest_4.nbt,5,CHEST:5,./NBT/StructureLoot/JunkChest_5.nbt,100)
B(1,3,-8,STONEBRICK:3)
B(2,3,-8,STONE_SLAB:7)
B(3,3,-8,LIGHT_WEIGHTED_PRESSURE_PLATE)
B(4,3,-8,AIR)
B(5,3,-8,AIR)
B(6,3,-8,AIR)
B(7,3,-8,AIR)
B(-8,3,-7,STONE:6)
B(-7,3,-7,AIR)
B(-6,3,-7,STONE:6)
RB(-5,3,-7,SKULL:1,./NBT/Skulls/dungeon_skull_01.nbt,6,AIR,9,SKULL:1,./NBT/Skulls/dungeon_skull_02.nbt,12,AIR,15,SKULL:1,./NBT/Skulls/dungeon_skull_03.nbt,18,AIR,21,SKULL:1,./NBT/Skulls/dungeon_skull_04.nbt,24,AIR,27,SKULL:1,./NBT/Skulls/dungeon_skull_05.nbt,30,AIR,33,SKULL:1,./NBT/Skulls/dungeon_skull_06.nbt,36,AIR,39,SKULL:1,./NBT/Skulls/dungeon_skull_07.nbt,42,AIR,45,SKULL:1,./NBT/Skulls/dungeon_skull_08.nbt,48,AIR,51,SKULL:1,./NBT/Skulls/dungeon_skull_09.nbt,54,AIR,57,SKULL:1,./NBT/Skulls/dungeon_skull_10.nbt,60,AIR,63,SKULL:1,./NBT/Skulls/dungeon_skull_11.nbt,66,AIR,69,SKULL:1,./NBT/Skulls/dungeon_skull_12.nbt,72,AIR,75,SKULL:1,./NBT/Skulls/dungeon_skull_13.nbt,78,AIR,81,SKULL:1,./NBT/Skulls/dungeon_skull_14.nbt,84,AIR,87,SKULL:1,./NBT/Skulls/dungeon_skull_15.nbt,90,AIR,93,SKULL:1,./NBT/Skulls/dungeon_skull_16.nbt,96,AIR,100)
B(-4,3,-7,STONEBRICK:3)
B(-3,3,-7,LIGHT_WEIGHTED_PRESSURE_PLATE)
B(-2,3,-7,QUARTZ_BLOCK:1)
B(-1,3,-7,STONE_SLAB:7)
B(0,3,-7,QUARTZ_STAIRS:3)
B(1,3,-7,STONE_SLAB:7)
B(2,3,-7,QUARTZ_BLOCK:1)
B(3,3,-7,LIGHT_WEIGHTED_PRESSURE_PLATE)
B(4,3,-7,AIR)
B(5,3,-7,STONEBRICK:3)
RB(6,3,-7,SKULL:1,./NBT/Skulls/dungeon_skull_01.nbt,6,AIR,9,SKULL:1,./NBT/Skulls/dungeon_skull_02.nbt,12,AIR,15,SKULL:1,./NBT/Skulls/dungeon_skull_03.nbt,18,AIR,21,SKULL:1,./NBT/Skulls/dungeon_skull_04.nbt,24,AIR,27,SKULL:1,./NBT/Skulls/dungeon_skull_05.nbt,30,AIR,33,SKULL:1,./NBT/Skulls/dungeon_skull_06.nbt,36,AIR,39,SKULL:1,./NBT/Skulls/dungeon_skull_07.nbt,42,AIR,45,SKULL:1,./NBT/Skulls/dungeon_skull_08.nbt,48,AIR,51,SKULL:1,./NBT/Skulls/dungeon_skull_09.nbt,54,AIR,57,SKULL:1,./NBT/Skulls/dungeon_skull_10.nbt,60,AIR,63,SKULL:1,./NBT/Skulls/dungeon_skull_11.nbt,66,AIR,69,SKULL:1,./NBT/Skulls/dungeon_skull_12.nbt,72,AIR,75,SKULL:1,./NBT/Skulls/dungeon_skull_13.nbt,78,AIR,81,SKULL:1,./NBT/Skulls/dungeon_skull_14.nbt,84,AIR,87,SKULL:1,./NBT/Skulls/dungeon_skull_15.nbt,90,AIR,93,SKULL:1,./NBT/Skulls/dungeon_skull_16.nbt,96,AIR,100)
B(7,3,-7,AIR)
B(-8,3,-6,LOG)
B(-7,3,-6,AIR)
B(-6,3,-6,LOG)
RB(-5,3,-6,SKULL:1,./NBT/Skulls/dungeon_skull_01.nbt,6,AIR,9,SKULL:1,./NBT/Skulls/dungeon_skull_02.nbt,12,AIR,15,SKULL:1,./NBT/Skulls/dungeon_skull_03.nbt,18,AIR,21,SKULL:1,./NBT/Skulls/dungeon_skull_04.nbt,24,AIR,27,SKULL:1,./NBT/Skulls/dungeon_skull_05.nbt,30,AIR,33,SKULL:1,./NBT/Skulls/dungeon_skull_06.nbt,36,AIR,39,SKULL:1,./NBT/Skulls/dungeon_skull_07.nbt,42,AIR,45,SKULL:1,./NBT/Skulls/dungeon_skull_08.nbt,48,AIR,51,SKULL:1,./NBT/Skulls/dungeon_skull_09.nbt,54,AIR,57,SKULL:1,./NBT/Skulls/dungeon_skull_10.nbt,60,AIR,63,SKULL:1,./NBT/Skulls/dungeon_skull_11.nbt,66,AIR,69,SKULL:1,./NBT/Skulls/dungeon_skull_12.nbt,72,AIR,75,SKULL:1,./NBT/Skulls/dungeon_skull_13.nbt,78,AIR,81,SKULL:1,./NBT/Skulls/dungeon_skull_14.nbt,84,AIR,87,SKULL:1,./NBT/Skulls/dungeon_skull_15.nbt,90,AIR,93,SKULL:1,./NBT/Skulls/dungeon_skull_16.nbt,96,AIR,100)
B(-4,3,-6,IRON_BARS)
B(-3,3,-6,LIGHT_WEIGHTED_PRESSURE_PLATE)
B(-2,3,-6,LIGHT_WEIGHTED_PRESSURE_PLATE)
B(-1,3,-6,LIGHT_WEIGHTED_PRESSURE_PLATE)
B(0,3,-6,LIGHT_WEIGHTED_PRESSURE_PLATE)
B(1,3,-6,LIGHT_WEIGHTED_PRESSURE_PLATE)
B(2,3,-6,LIGHT_WEIGHTED_PRESSURE_PLATE)
B(3,3,-6,LIGHT_WEIGHTED_PRESSURE_PLATE)
B(4,3,-6,AIR)
B(5,3,-6,IRON_BARS)
RB(6,3,-6,SKULL:1,./NBT/Skulls/dungeon_skull_01.nbt,6,AIR,9,SKULL:1,./NBT/Skulls/dungeon_skull_02.nbt,12,AIR,15,SKULL:1,./NBT/Skulls/dungeon_skull_03.nbt,18,AIR,21,SKULL:1,./NBT/Skulls/dungeon_skull_04.nbt,24,AIR,27,SKULL:1,./NBT/Skulls/dungeon_skull_05.nbt,30,AIR,33,SKULL:1,./NBT/Skulls/dungeon_skull_06.nbt,36,AIR,39,SKULL:1,./NBT/Skulls/dungeon_skull_07.nbt,42,AIR,45,SKULL:1,./NBT/Skulls/dungeon_skull_08.nbt,48,AIR,51,SKULL:1,./NBT/Skulls/dungeon_skull_09.nbt,54,AIR,57,SKULL:1,./NBT/Skulls/dungeon_skull_10.nbt,60,AIR,63,SKULL:1,./NBT/Skulls/dungeon_skull_11.nbt,66,AIR,69,SKULL:1,./NBT/Skulls/dungeon_skull_12.nbt,72,AIR,75,SKULL:1,./NBT/Skulls/dungeon_skull_13.nbt,78,AIR,81,SKULL:1,./NBT/Skulls/dungeon_skull_14.nbt,84,AIR,87,SKULL:1,./NBT/Skulls/dungeon_skull_15.nbt,90,AIR,93,SKULL:1,./NBT/Skulls/dungeon_skull_16.nbt,96,AIR,100)
RB(7,3,-6,SKULL:1,./NBT/Skulls/dungeon_skull_01.nbt,6,AIR,9,SKULL:1,./NBT/Skulls/dungeon_skull_02.nbt,12,AIR,15,SKULL:1,./NBT/Skulls/dungeon_skull_03.nbt,18,AIR,21,SKULL:1,./NBT/Skulls/dungeon_skull_04.nbt,24,AIR,27,SKULL:1,./NBT/Skulls/dungeon_skull_05.nbt,30,AIR,33,SKULL:1,./NBT/Skulls/dungeon_skull_06.nbt,36,AIR,39,SKULL:1,./NBT/Skulls/dungeon_skull_07.nbt,42,AIR,45,SKULL:1,./NBT/Skulls/dungeon_skull_08.nbt,48,AIR,51,SKULL:1,./NBT/Skulls/dungeon_skull_09.nbt,54,AIR,57,SKULL:1,./NBT/Skulls/dungeon_skull_10.nbt,60,AIR,63,SKULL:1,./NBT/Skulls/dungeon_skull_11.nbt,66,AIR,69,SKULL:1,./NBT/Skulls/dungeon_skull_12.nbt,72,AIR,75,SKULL:1,./NBT/Skulls/dungeon_skull_13.nbt,78,AIR,81,SKULL:1,./NBT/Skulls/dungeon_skull_14.nbt,84,AIR,87,SKULL:1,./NBT/Skulls/dungeon_skull_15.nbt,90,AIR,93,SKULL:1,./NBT/Skulls/dungeon_skull_16.nbt,96,AIR,100)
B(-8,3,-5,STONE:6)
B(-7,3,-5,AIR)
B(-6,3,-5,STONE:6)
RB(-5,3,-5,SKULL:1,./NBT/Skulls/dungeon_skull_01.nbt,6,AIR,9,SKULL:1,./NBT/Skulls/dungeon_skull_02.nbt,12,AIR,15,SKULL:1,./NBT/Skulls/dungeon_skull_03.nbt,18,AIR,21,SKULL:1,./NBT/Skulls/dungeon_skull_04.nbt,24,AIR,27,SKULL:1,./NBT/Skulls/dungeon_skull_05.nbt,30,AIR,33,SKULL:1,./NBT/Skulls/dungeon_skull_06.nbt,36,AIR,39,SKULL:1,./NBT/Skulls/dungeon_skull_07.nbt,42,AIR,45,SKULL:1,./NBT/Skulls/dungeon_skull_08.nbt,48,AIR,51,SKULL:1,./NBT/Skulls/dungeon_skull_09.nbt,54,AIR,57,SKULL:1,./NBT/Skulls/dungeon_skull_10.nbt,60,AIR,63,SKULL:1,./NBT/Skulls/dungeon_skull_11.nbt,66,AIR,69,SKULL:1,./NBT/Skulls/dungeon_skull_12.nbt,72,AIR,75,SKULL:1,./NBT/Skulls/dungeon_skull_13.nbt,78,AIR,81,SKULL:1,./NBT/Skulls/dungeon_skull_14.nbt,84,AIR,87,SKULL:1,./NBT/Skulls/dungeon_skull_15.nbt,90,AIR,93,SKULL:1,./NBT/Skulls/dungeon_skull_16.nbt,96,AIR,100)
B(-4,3,-5,STONEBRICK:3)
B(-3,3,-5,IRON_BARS)
B(-2,3,-5,IRON_BARS)
B(-1,3,-5,STONEBRICK:3)
B(0,3,-5,AIR)
B(1,3,-5,AIR)
B(2,3,-5,STONEBRICK:3)
B(3,3,-5,IRON_BARS)
B(4,3,-5,IRON_BARS)
B(5,3,-5,STONEBRICK:3)
B(6,3,-5,QUARTZ_STAIRS:5)
B(7,3,-5,QUARTZ_STAIRS:6)
B(-8,3,-4,STONE:6)
B(-7,3,-4,AIR)
B(-6,3,-4,STONE:6)
RB(-5,3,-4,SKULL:1,./NBT/Skulls/dungeon_skull_01.nbt,6,AIR,9,SKULL:1,./NBT/Skulls/dungeon_skull_02.nbt,12,AIR,15,SKULL:1,./NBT/Skulls/dungeon_skull_03.nbt,18,AIR,21,SKULL:1,./NBT/Skulls/dungeon_skull_04.nbt,24,AIR,27,SKULL:1,./NBT/Skulls/dungeon_skull_05.nbt,30,AIR,33,SKULL:1,./NBT/Skulls/dungeon_skull_06.nbt,36,AIR,39,SKULL:1,./NBT/Skulls/dungeon_skull_07.nbt,42,AIR,45,SKULL:1,./NBT/Skulls/dungeon_skull_08.nbt,48,AIR,51,SKULL:1,./NBT/Skulls/dungeon_skull_09.nbt,54,AIR,57,SKULL:1,./NBT/Skulls/dungeon_skull_10.nbt,60,AIR,63,SKULL:1,./NBT/Skulls/dungeon_skull_11.nbt,66,AIR,69,SKULL:1,./NBT/Skulls/dungeon_skull_12.nbt,72,AIR,75,SKULL:1,./NBT/Skulls/dungeon_skull_13.nbt,78,AIR,81,SKULL:1,./NBT/Skulls/dungeon_skull_14.nbt,84,AIR,87,SKULL:1,./NBT/Skulls/dungeon_skull_15.nbt,90,AIR,93,SKULL:1,./NBT/Skulls/dungeon_skull_16.nbt,96,AIR,100)
RB(-4,3,-4,SKULL:1,./NBT/Skulls/dungeon_skull_01.nbt,6,AIR,9,SKULL:1,./NBT/Skulls/dungeon_skull_02.nbt,12,AIR,15,SKULL:1,./NBT/Skulls/dungeon_skull_03.nbt,18,AIR,21,SKULL:1,./NBT/Skulls/dungeon_skull_04.nbt,24,AIR,27,SKULL:1,./NBT/Skulls/dungeon_skull_05.nbt,30,AIR,33,SKULL:1,./NBT/Skulls/dungeon_skull_06.nbt,36,AIR,39,SKULL:1,./NBT/Skulls/dungeon_skull_07.nbt,42,AIR,45,SKULL:1,./NBT/Skulls/dungeon_skull_08.nbt,48,AIR,51,SKULL:1,./NBT/Skulls/dungeon_skull_09.nbt,54,AIR,57,SKULL:1,./NBT/Skulls/dungeon_skull_10.nbt,60,AIR,63,SKULL:1,./NBT/Skulls/dungeon_skull_11.nbt,66,AIR,69,SKULL:1,./NBT/Skulls/dungeon_skull_12.nbt,72,AIR,75,SKULL:1,./NBT/Skulls/dungeon_skull_13.nbt,78,AIR,81,SKULL:1,./NBT/Skulls/dungeon_skull_14.nbt,84,AIR,87,SKULL:1,./NBT/Skulls/dungeon_skull_15.nbt,90,AIR,93,SKULL:1,./NBT/Skulls/dungeon_skull_16.nbt,96,AIR,100)
RB(-3,3,-4,SKULL:1,./NBT/Skulls/dungeon_skull_01.nbt,6,AIR,9,SKULL:1,./NBT/Skulls/dungeon_skull_02.nbt,12,AIR,15,SKULL:1,./NBT/Skulls/dungeon_skull_03.nbt,18,AIR,21,SKULL:1,./NBT/Skulls/dungeon_skull_04.nbt,24,AIR,27,SKULL:1,./NBT/Skulls/dungeon_skull_05.nbt,30,AIR,33,SKULL:1,./NBT/Skulls/dungeon_skull_06.nbt,36,AIR,39,SKULL:1,./NBT/Skulls/dungeon_skull_07.nbt,42,AIR,45,SKULL:1,./NBT/Skulls/dungeon_skull_08.nbt,48,AIR,51,SKULL:1,./NBT/Skulls/dungeon_skull_09.nbt,54,AIR,57,SKULL:1,./NBT/Skulls/dungeon_skull_10.nbt,60,AIR,63,SKULL:1,./NBT/Skulls/dungeon_skull_11.nbt,66,AIR,69,SKULL:1,./NBT/Skulls/dungeon_skull_12.nbt,72,AIR,75,SKULL:1,./NBT/Skulls/dungeon_skull_13.nbt,78,AIR,81,SKULL:1,./NBT/Skulls/dungeon_skull_14.nbt,84,AIR,87,SKULL:1,./NBT/Skulls/dungeon_skull_15.nbt,90,AIR,93,SKULL:1,./NBT/Skulls/dungeon_skull_16.nbt,96,AIR,100)
RB(-2,3,-4,SKULL:1,./NBT/Skulls/dungeon_skull_01.nbt,6,AIR,9,SKULL:1,./NBT/Skulls/dungeon_skull_02.nbt,12,AIR,15,SKULL:1,./NBT/Skulls/dungeon_skull_03.nbt,18,AIR,21,SKULL:1,./NBT/Skulls/dungeon_skull_04.nbt,24,AIR,27,SKULL:1,./NBT/Skulls/dungeon_skull_05.nbt,30,AIR,33,SKULL:1,./NBT/Skulls/dungeon_skull_06.nbt,36,AIR,39,SKULL:1,./NBT/Skulls/dungeon_skull_07.nbt,42,AIR,45,SKULL:1,./NBT/Skulls/dungeon_skull_08.nbt,48,AIR,51,SKULL:1,./NBT/Skulls/dungeon_skull_09.nbt,54,AIR,57,SKULL:1,./NBT/Skulls/dungeon_skull_10.nbt,60,AIR,63,SKULL:1,./NBT/Skulls/dungeon_skull_11.nbt,66,AIR,69,SKULL:1,./NBT/Skulls/dungeon_skull_12.nbt,72,AIR,75,SKULL:1,./NBT/Skulls/dungeon_skull_13.nbt,78,AIR,81,SKULL:1,./NBT/Skulls/dungeon_skull_14.nbt,84,AIR,87,SKULL:1,./NBT/Skulls/dungeon_skull_15.nbt,90,AIR,93,SKULL:1,./NBT/Skulls/dungeon_skull_16.nbt,96,AIR,100)
B(-1,3,-4,QUARTZ_STAIRS:5)
B(0,3,-4,AIR)
B(1,3,-4,AIR)
B(2,3,-4,QUARTZ_STAIRS:4)
RB(3,3,-4,SKULL:1,./NBT/Skulls/dungeon_skull_01.nbt,6,AIR,9,SKULL:1,./NBT/Skulls/dungeon_skull_02.nbt,12,AIR,15,SKULL:1,./NBT/Skulls/dungeon_skull_03.nbt,18,AIR,21,SKULL:1,./NBT/Skulls/dungeon_skull_04.nbt,24,AIR,27,SKULL:1,./NBT/Skulls/dungeon_skull_05.nbt,30,AIR,33,SKULL:1,./NBT/Skulls/dungeon_skull_06.nbt,36,AIR,39,SKULL:1,./NBT/Skulls/dungeon_skull_07.nbt,42,AIR,45,SKULL:1,./NBT/Skulls/dungeon_skull_08.nbt,48,AIR,51,SKULL:1,./NBT/Skulls/dungeon_skull_09.nbt,54,AIR,57,SKULL:1,./NBT/Skulls/dungeon_skull_10.nbt,60,AIR,63,SKULL:1,./NBT/Skulls/dungeon_skull_11.nbt,66,AIR,69,SKULL:1,./NBT/Skulls/dungeon_skull_12.nbt,72,AIR,75,SKULL:1,./NBT/Skulls/dungeon_skull_13.nbt,78,AIR,81,SKULL:1,./NBT/Skulls/dungeon_skull_14.nbt,84,AIR,87,SKULL:1,./NBT/Skulls/dungeon_skull_15.nbt,90,AIR,93,SKULL:1,./NBT/Skulls/dungeon_skull_16.nbt,96,AIR,100)
RB(4,3,-4,SKULL:1,./NBT/Skulls/dungeon_skull_01.nbt,6,AIR,9,SKULL:1,./NBT/Skulls/dungeon_skull_02.nbt,12,AIR,15,SKULL:1,./NBT/Skulls/dungeon_skull_03.nbt,18,AIR,21,SKULL:1,./NBT/Skulls/dungeon_skull_04.nbt,24,AIR,27,SKULL:1,./NBT/Skulls/dungeon_skull_05.nbt,30,AIR,33,SKULL:1,./NBT/Skulls/dungeon_skull_06.nbt,36,AIR,39,SKULL:1,./NBT/Skulls/dungeon_skull_07.nbt,42,AIR,45,SKULL:1,./NBT/Skulls/dungeon_skull_08.nbt,48,AIR,51,SKULL:1,./NBT/Skulls/dungeon_skull_09.nbt,54,AIR,57,SKULL:1,./NBT/Skulls/dungeon_skull_10.nbt,60,AIR,63,SKULL:1,./NBT/Skulls/dungeon_skull_11.nbt,66,AIR,69,SKULL:1,./NBT/Skulls/dungeon_skull_12.nbt,72,AIR,75,SKULL:1,./NBT/Skulls/dungeon_skull_13.nbt,78,AIR,81,SKULL:1,./NBT/Skulls/dungeon_skull_14.nbt,84,AIR,87,SKULL:1,./NBT/Skulls/dungeon_skull_15.nbt,90,AIR,93,SKULL:1,./NBT/Skulls/dungeon_skull_16.nbt,96,AIR,100)
B(5,3,-4,IRON_BARS)
B(6,3,-4,QUARTZ_STAIRS:4)
B(7,3,-4,QUARTZ_BLOCK:1)
B(-8,3,-3,LOG)
B(-7,3,-3,AIR)
B(-6,3,-3,LOG)
B(-5,3,-3,QUARTZ_STAIRS:7)
B(-4,3,-3,STONEBRICK:3)
B(-3,3,-3,QUARTZ_STAIRS:7)
B(-2,3,-3,QUARTZ_STAIRS:7)
B(-1,3,-3,STONEBRICK:3)
B(0,3,-3,AIR)
B(1,3,-3,AIR)
B(2,3,-3,STONEBRICK:3)
B(3,3,-3,QUARTZ_STAIRS:7)
B(4,3,-3,QUARTZ_STAIRS:7)
B(5,3,-3,IRON_BARS)
B(6,3,-3,QUARTZ_STAIRS:4)
B(7,3,-3,QUARTZ_BLOCK:1)
B(-8,3,-2,STONE:6)
B(-7,3,-2,AIR)
B(-6,3,-2,STONE:6)
B(-5,3,-2,QUARTZ_STAIRS:5)
B(-4,3,-2,QUARTZ_STAIRS:7)
RB(-3,3,-2,SKULL:1,./NBT/Skulls/dungeon_skull_01.nbt,6,AIR,9,SKULL:1,./NBT/Skulls/dungeon_skull_02.nbt,12,AIR,15,SKULL:1,./NBT/Skulls/dungeon_skull_03.nbt,18,AIR,21,SKULL:1,./NBT/Skulls/dungeon_skull_04.nbt,24,AIR,27,SKULL:1,./NBT/Skulls/dungeon_skull_05.nbt,30,AIR,33,SKULL:1,./NBT/Skulls/dungeon_skull_06.nbt,36,AIR,39,SKULL:1,./NBT/Skulls/dungeon_skull_07.nbt,42,AIR,45,SKULL:1,./NBT/Skulls/dungeon_skull_08.nbt,48,AIR,51,SKULL:1,./NBT/Skulls/dungeon_skull_09.nbt,54,AIR,57,SKULL:1,./NBT/Skulls/dungeon_skull_10.nbt,60,AIR,63,SKULL:1,./NBT/Skulls/dungeon_skull_11.nbt,66,AIR,69,SKULL:1,./NBT/Skulls/dungeon_skull_12.nbt,72,AIR,75,SKULL:1,./NBT/Skulls/dungeon_skull_13.nbt,78,AIR,81,SKULL:1,./NBT/Skulls/dungeon_skull_14.nbt,84,AIR,87,SKULL:1,./NBT/Skulls/dungeon_skull_15.nbt,90,AIR,93,SKULL:1,./NBT/Skulls/dungeon_skull_16.nbt,96,AIR,100)
RB(-2,3,-2,SKULL:1,./NBT/Skulls/dungeon_skull_01.nbt,6,AIR,9,SKULL:1,./NBT/Skulls/dungeon_skull_02.nbt,12,AIR,15,SKULL:1,./NBT/Skulls/dungeon_skull_03.nbt,18,AIR,21,SKULL:1,./NBT/Skulls/dungeon_skull_04.nbt,24,AIR,27,SKULL:1,./NBT/Skulls/dungeon_skull_05.nbt,30,AIR,33,SKULL:1,./NBT/Skulls/dungeon_skull_06.nbt,36,AIR,39,SKULL:1,./NBT/Skulls/dungeon_skull_07.nbt,42,AIR,45,SKULL:1,./NBT/Skulls/dungeon_skull_08.nbt,48,AIR,51,SKULL:1,./NBT/Skulls/dungeon_skull_09.nbt,54,AIR,57,SKULL:1,./NBT/Skulls/dungeon_skull_10.nbt,60,AIR,63,SKULL:1,./NBT/Skulls/dungeon_skull_11.nbt,66,AIR,69,SKULL:1,./NBT/Skulls/dungeon_skull_12.nbt,72,AIR,75,SKULL:1,./NBT/Skulls/dungeon_skull_13.nbt,78,AIR,81,SKULL:1,./NBT/Skulls/dungeon_skull_14.nbt,84,AIR,87,SKULL:1,./NBT/Skulls/dungeon_skull_15.nbt,90,AIR,93,SKULL:1,./NBT/Skulls/dungeon_skull_16.nbt,96,AIR,100)
RB(-1,3,-2,SKULL:1,./NBT/Skulls/dungeon_skull_01.nbt,6,AIR,9,SKULL:1,./NBT/Skulls/dungeon_skull_02.nbt,12,AIR,15,SKULL:1,./NBT/Skulls/dungeon_skull_03.nbt,18,AIR,21,SKULL:1,./NBT/Skulls/dungeon_skull_04.nbt,24,AIR,27,SKULL:1,./NBT/Skulls/dungeon_skull_05.nbt,30,AIR,33,SKULL:1,./NBT/Skulls/dungeon_skull_06.nbt,36,AIR,39,SKULL:1,./NBT/Skulls/dungeon_skull_07.nbt,42,AIR,45,SKULL:1,./NBT/Skulls/dungeon_skull_08.nbt,48,AIR,51,SKULL:1,./NBT/Skulls/dungeon_skull_09.nbt,54,AIR,57,SKULL:1,./NBT/Skulls/dungeon_skull_10.nbt,60,AIR,63,SKULL:1,./NBT/Skulls/dungeon_skull_11.nbt,66,AIR,69,SKULL:1,./NBT/Skulls/dungeon_skull_12.nbt,72,AIR,75,SKULL:1,./NBT/Skulls/dungeon_skull_13.nbt,78,AIR,81,SKULL:1,./NBT/Skulls/dungeon_skull_14.nbt,84,AIR,87,SKULL:1,./NBT/Skulls/dungeon_skull_15.nbt,90,AIR,93,SKULL:1,./NBT/Skulls/dungeon_skull_16.nbt,96,AIR,100)
B(0,3,-2,AIR)
RB(1,3,-2,SKULL:1,./NBT/Skulls/dungeon_skull_01.nbt,6,AIR,9,SKULL:1,./NBT/Skulls/dungeon_skull_02.nbt,12,AIR,15,SKULL:1,./NBT/Skulls/dungeon_skull_03.nbt,18,AIR,21,SKULL:1,./NBT/Skulls/dungeon_skull_04.nbt,24,AIR,27,SKULL:1,./NBT/Skulls/dungeon_skull_05.nbt,30,AIR,33,SKULL:1,./NBT/Skulls/dungeon_skull_06.nbt,36,AIR,39,SKULL:1,./NBT/Skulls/dungeon_skull_07.nbt,42,AIR,45,SKULL:1,./NBT/Skulls/dungeon_skull_08.nbt,48,AIR,51,SKULL:1,./NBT/Skulls/dungeon_skull_09.nbt,54,AIR,57,SKULL:1,./NBT/Skulls/dungeon_skull_10.nbt,60,AIR,63,SKULL:1,./NBT/Skulls/dungeon_skull_11.nbt,66,AIR,69,SKULL:1,./NBT/Skulls/dungeon_skull_12.nbt,72,AIR,75,SKULL:1,./NBT/Skulls/dungeon_skull_13.nbt,78,AIR,81,SKULL:1,./NBT/Skulls/dungeon_skull_14.nbt,84,AIR,87,SKULL:1,./NBT/Skulls/dungeon_skull_15.nbt,90,AIR,93,SKULL:1,./NBT/Skulls/dungeon_skull_16.nbt,96,AIR,100)
B(2,3,-2,AIR)
B(3,3,-2,AIR)
RB(4,3,-2,SKULL:1,./NBT/Skulls/dungeon_skull_01.nbt,6,AIR,9,SKULL:1,./NBT/Skulls/dungeon_skull_02.nbt,12,AIR,15,SKULL:1,./NBT/Skulls/dungeon_skull_03.nbt,18,AIR,21,SKULL:1,./NBT/Skulls/dungeon_skull_04.nbt,24,AIR,27,SKULL:1,./NBT/Skulls/dungeon_skull_05.nbt,30,AIR,33,SKULL:1,./NBT/Skulls/dungeon_skull_06.nbt,36,AIR,39,SKULL:1,./NBT/Skulls/dungeon_skull_07.nbt,42,AIR,45,SKULL:1,./NBT/Skulls/dungeon_skull_08.nbt,48,AIR,51,SKULL:1,./NBT/Skulls/dungeon_skull_09.nbt,54,AIR,57,SKULL:1,./NBT/Skulls/dungeon_skull_10.nbt,60,AIR,63,SKULL:1,./NBT/Skulls/dungeon_skull_11.nbt,66,AIR,69,SKULL:1,./NBT/Skulls/dungeon_skull_12.nbt,72,AIR,75,SKULL:1,./NBT/Skulls/dungeon_skull_13.nbt,78,AIR,81,SKULL:1,./NBT/Skulls/dungeon_skull_14.nbt,84,AIR,87,SKULL:1,./NBT/Skulls/dungeon_skull_15.nbt,90,AIR,93,SKULL:1,./NBT/Skulls/dungeon_skull_16.nbt,96,AIR,100)
B(5,3,-2,STONEBRICK:3)
B(6,3,-2,QUARTZ_STAIRS:5)
B(7,3,-2,QUARTZ_STAIRS:7)
B(-8,3,-1,STONE:6)
B(-7,3,-1,AIR)
B(-6,3,-1,STONE:6)
B(-5,3,-1,QUARTZ_STAIRS:5)
B(-4,3,-1,QUARTZ_STAIRS:5)
RB(-3,3,-1,SKULL:1,./NBT/Skulls/dungeon_skull_01.nbt,6,AIR,9,SKULL:1,./NBT/Skulls/dungeon_skull_02.nbt,12,AIR,15,SKULL:1,./NBT/Skulls/dungeon_skull_03.nbt,18,AIR,21,SKULL:1,./NBT/Skulls/dungeon_skull_04.nbt,24,AIR,27,SKULL:1,./NBT/Skulls/dungeon_skull_05.nbt,30,AIR,33,SKULL:1,./NBT/Skulls/dungeon_skull_06.nbt,36,AIR,39,SKULL:1,./NBT/Skulls/dungeon_skull_07.nbt,42,AIR,45,SKULL:1,./NBT/Skulls/dungeon_skull_08.nbt,48,AIR,51,SKULL:1,./NBT/Skulls/dungeon_skull_09.nbt,54,AIR,57,SKULL:1,./NBT/Skulls/dungeon_skull_10.nbt,60,AIR,63,SKULL:1,./NBT/Skulls/dungeon_skull_11.nbt,66,AIR,69,SKULL:1,./NBT/Skulls/dungeon_skull_12.nbt,72,AIR,75,SKULL:1,./NBT/Skulls/dungeon_skull_13.nbt,78,AIR,81,SKULL:1,./NBT/Skulls/dungeon_skull_14.nbt,84,AIR,87,SKULL:1,./NBT/Skulls/dungeon_skull_15.nbt,90,AIR,93,SKULL:1,./NBT/Skulls/dungeon_skull_16.nbt,96,AIR,100)
B(-2,3,-1,AIR)
B(-1,3,-1,AIR)
B(0,3,-1,AIR)
B(1,3,-1,AIR)
B(2,3,-1,AIR)
B(3,3,-1,AIR)
B(4,3,-1,AIR)
B(5,3,-1,AIR)
B(6,3,-1,AIR)
B(7,3,-1,AIR)
B(-8,3,0,LOG)
B(-7,3,0,AIR)
B(-6,3,0,LOG)
B(-5,3,0,QUARTZ_STAIRS:5)
B(-4,3,0,QUARTZ_STAIRS:6)
B(-3,3,0,AIR)
RB(-2,3,0,SKULL:1,./NBT/Skulls/dungeon_skull_01.nbt,6,AIR,9,SKULL:1,./NBT/Skulls/dungeon_skull_02.nbt,12,AIR,15,SKULL:1,./NBT/Skulls/dungeon_skull_03.nbt,18,AIR,21,SKULL:1,./NBT/Skulls/dungeon_skull_04.nbt,24,AIR,27,SKULL:1,./NBT/Skulls/dungeon_skull_05.nbt,30,AIR,33,SKULL:1,./NBT/Skulls/dungeon_skull_06.nbt,36,AIR,39,SKULL:1,./NBT/Skulls/dungeon_skull_07.nbt,42,AIR,45,SKULL:1,./NBT/Skulls/dungeon_skull_08.nbt,48,AIR,51,SKULL:1,./NBT/Skulls/dungeon_skull_09.nbt,54,AIR,57,SKULL:1,./NBT/Skulls/dungeon_skull_10.nbt,60,AIR,63,SKULL:1,./NBT/Skulls/dungeon_skull_11.nbt,66,AIR,69,SKULL:1,./NBT/Skulls/dungeon_skull_12.nbt,72,AIR,75,SKULL:1,./NBT/Skulls/dungeon_skull_13.nbt,78,AIR,81,SKULL:1,./NBT/Skulls/dungeon_skull_14.nbt,84,AIR,87,SKULL:1,./NBT/Skulls/dungeon_skull_15.nbt,90,AIR,93,SKULL:1,./NBT/Skulls/dungeon_skull_16.nbt,96,AIR,100)
RB(-1,3,0,SKULL:1,./NBT/Skulls/dungeon_skull_01.nbt,6,AIR,9,SKULL:1,./NBT/Skulls/dungeon_skull_02.nbt,12,AIR,15,SKULL:1,./NBT/Skulls/dungeon_skull_03.nbt,18,AIR,21,SKULL:1,./NBT/Skulls/dungeon_skull_04.nbt,24,AIR,27,SKULL:1,./NBT/Skulls/dungeon_skull_05.nbt,30,AIR,33,SKULL:1,./NBT/Skulls/dungeon_skull_06.nbt,36,AIR,39,SKULL:1,./NBT/Skulls/dungeon_skull_07.nbt,42,AIR,45,SKULL:1,./NBT/Skulls/dungeon_skull_08.nbt,48,AIR,51,SKULL:1,./NBT/Skulls/dungeon_skull_09.nbt,54,AIR,57,SKULL:1,./NBT/Skulls/dungeon_skull_10.nbt,60,AIR,63,SKULL:1,./NBT/Skulls/dungeon_skull_11.nbt,66,AIR,69,SKULL:1,./NBT/Skulls/dungeon_skull_12.nbt,72,AIR,75,SKULL:1,./NBT/Skulls/dungeon_skull_13.nbt,78,AIR,81,SKULL:1,./NBT/Skulls/dungeon_skull_14.nbt,84,AIR,87,SKULL:1,./NBT/Skulls/dungeon_skull_15.nbt,90,AIR,93,SKULL:1,./NBT/Skulls/dungeon_skull_16.nbt,96,AIR,100)
B(0,3,0,AIR)
B(1,3,0,AIR)
RB(2,3,0,SKULL:1,./NBT/Skulls/dungeon_skull_01.nbt,6,AIR,9,SKULL:1,./NBT/Skulls/dungeon_skull_02.nbt,12,AIR,15,SKULL:1,./NBT/Skulls/dungeon_skull_03.nbt,18,AIR,21,SKULL:1,./NBT/Skulls/dungeon_skull_04.nbt,24,AIR,27,SKULL:1,./NBT/Skulls/dungeon_skull_05.nbt,30,AIR,33,SKULL:1,./NBT/Skulls/dungeon_skull_06.nbt,36,AIR,39,SKULL:1,./NBT/Skulls/dungeon_skull_07.nbt,42,AIR,45,SKULL:1,./NBT/Skulls/dungeon_skull_08.nbt,48,AIR,51,SKULL:1,./NBT/Skulls/dungeon_skull_09.nbt,54,AIR,57,SKULL:1,./NBT/Skulls/dungeon_skull_10.nbt,60,AIR,63,SKULL:1,./NBT/Skulls/dungeon_skull_11.nbt,66,AIR,69,SKULL:1,./NBT/Skulls/dungeon_skull_12.nbt,72,AIR,75,SKULL:1,./NBT/Skulls/dungeon_skull_13.nbt,78,AIR,81,SKULL:1,./NBT/Skulls/dungeon_skull_14.nbt,84,AIR,87,SKULL:1,./NBT/Skulls/dungeon_skull_15.nbt,90,AIR,93,SKULL:1,./NBT/Skulls/dungeon_skull_16.nbt,96,AIR,100)
B(3,3,0,AIR)
B(4,3,0,AIR)
B(5,3,0,AIR)
B(6,3,0,AIR)
RB(7,3,0,SKULL:1,./NBT/Skulls/dungeon_skull_01.nbt,6,AIR,9,SKULL:1,./NBT/Skulls/dungeon_skull_02.nbt,12,AIR,15,SKULL:1,./NBT/Skulls/dungeon_skull_03.nbt,18,AIR,21,SKULL:1,./NBT/Skulls/dungeon_skull_04.nbt,24,AIR,27,SKULL:1,./NBT/Skulls/dungeon_skull_05.nbt,30,AIR,33,SKULL:1,./NBT/Skulls/dungeon_skull_06.nbt,36,AIR,39,SKULL:1,./NBT/Skulls/dungeon_skull_07.nbt,42,AIR,45,SKULL:1,./NBT/Skulls/dungeon_skull_08.nbt,48,AIR,51,SKULL:1,./NBT/Skulls/dungeon_skull_09.nbt,54,AIR,57,SKULL:1,./NBT/Skulls/dungeon_skull_10.nbt,60,AIR,63,SKULL:1,./NBT/Skulls/dungeon_skull_11.nbt,66,AIR,69,SKULL:1,./NBT/Skulls/dungeon_skull_12.nbt,72,AIR,75,SKULL:1,./NBT/Skulls/dungeon_skull_13.nbt,78,AIR,81,SKULL:1,./NBT/Skulls/dungeon_skull_14.nbt,84,AIR,87,SKULL:1,./NBT/Skulls/dungeon_skull_15.nbt,90,AIR,93,SKULL:1,./NBT/Skulls/dungeon_skull_16.nbt,96,AIR,100)
B(-8,3,1,STONE:6)
B(-7,3,1,AIR)
B(-6,3,1,STONE:6)
B(-5,3,1,QUARTZ_STAIRS:6)
B(-4,3,1,STONEBRICK:3)
B(-3,3,1,QUARTZ_STAIRS:5)
B(-2,3,1,QUARTZ_STAIRS:4)
B(-1,3,1,STONEBRICK:3)
B(0,3,1,QUARTZ_STAIRS:5)
B(1,3,1,QUARTZ_STAIRS:4)
B(2,3,1,STONEBRICK:3)
B(3,3,1,QUARTZ_STAIRS:5)
B(4,3,1,QUARTZ_STAIRS:4)
B(5,3,1,STONEBRICK:3)
B(6,3,1,QUARTZ_STAIRS:5)
B(7,3,1,QUARTZ_STAIRS:6)
B(-8,3,2,STONE:6)
B(-7,3,2,AIR)
B(-6,3,2,STONE:6)
B(-5,3,2,QUARTZ_BLOCK:1)
B(-4,3,2,QUARTZ_BLOCK:1)
B(-3,3,2,QUARTZ_BLOCK:1)
B(-2,3,2,QUARTZ_BLOCK:1)
B(-1,3,2,QUARTZ_BLOCK:1)
B(0,3,2,QUARTZ_BLOCK:1)
B(1,3,2,QUARTZ_BLOCK:1)
B(2,3,2,QUARTZ_BLOCK:1)
B(3,3,2,QUARTZ_BLOCK:1)
B(4,3,2,QUARTZ_BLOCK:1)
B(5,3,2,IRON_BARS)
B(6,3,2,QUARTZ_STAIRS:4)
B(7,3,2,QUARTZ_BLOCK:1)
B(-8,3,3,LOG)
B(-7,3,3,AIR)
B(-6,3,3,LOG)
B(-5,3,3,QUARTZ_BLOCK:1)
B(-4,3,3,QUARTZ_BLOCK:1)
B(-3,3,3,QUARTZ_BLOCK:1)
B(-2,3,3,QUARTZ_BLOCK:1)
B(-1,3,3,QUARTZ_BLOCK:1)
B(0,3,3,QUARTZ_BLOCK:1)
B(1,3,3,QUARTZ_BLOCK:1)
B(2,3,3,QUARTZ_BLOCK:1)
B(3,3,3,QUARTZ_BLOCK:1)
B(4,3,3,QUARTZ_BLOCK:1)
B(5,3,3,IRON_BARS)
B(6,3,3,QUARTZ_STAIRS:4)
B(7,3,3,QUARTZ_BLOCK:1)
B(-8,3,4,STONE:6)
B(-7,3,4,AIR)
B(-6,3,4,AIR)
B(-5,3,4,LOG)
B(-4,3,4,STONE:6)
B(-3,3,4,STONE:6)
B(-2,3,4,LOG)
B(-1,3,4,STONE:6)
B(0,3,4,STONE:6)
B(1,3,4,LOG)
B(2,3,4,STONE:6)
B(3,3,4,STONE:6)
B(4,3,4,LOG)
B(5,3,4,STONE:6)
B(6,3,4,STONE:6)
B(7,3,4,LOG)
B(-8,3,5,STONE:6)
B(-7,3,5,AIR)
B(-6,3,5,AIR)
B(-5,3,5,AIR)
B(-4,3,5,AIR)
B(-3,3,5,AIR)
B(-2,3,5,AIR)
B(-1,3,5,AIR)
B(0,3,5,AIR)
B(1,3,5,AIR)
B(2,3,5,AIR)
B(3,3,5,AIR)
B(4,3,5,AIR)
B(5,3,5,AIR)
B(6,3,5,AIR)
B(7,3,5,AIR)
B(-8,3,6,LOG)
B(-7,3,6,STONE:6)
B(-6,3,6,STONE:6)
B(-5,3,6,LOG)
B(-4,3,6,STONE:6)
B(-3,3,6,STONE:6)
B(-2,3,6,LOG)
B(-1,3,6,STONE:6)
B(0,3,6,STONE:6)
B(1,3,6,LOG)
B(2,3,6,STONE:6)
B(3,3,6,STONE:6)
B(4,3,6,LOG)
B(5,3,6,STONE:6)
B(6,3,6,STONE:6)
B(7,3,6,LOG)
B(-8,4,-8,STONE:6)
B(-7,4,-8,WOODEN_SLAB:13)
B(-6,4,-8,STONE:6)
RB(-5,4,-8,CHEST:5,./NBT/StructureLoot/JunkChest_1.nbt,10,CHEST:5,./NBT/StructureLoot/JunkChest_2.nbt,5,CHEST:5,./NBT/StructureLoot/JunkChest_3.nbt,5,CHEST:5,./NBT/StructureLoot/JunkChest_4.nbt,5,CHEST:5,./NBT/StructureLoot/JunkChest_5.nbt,5,CHEST:5,./NBT/Lorestoryline/LoreSpooky_5.nbt,2,CHEST:5,./NBT/Lorestoryline/LoreSpooky_4.nbt,2,CHEST:5,./NBT/Lorestoryline/LoreSpooky_3.nbt,2,CHEST:5,./NBT/Lorestoryline/LoreSpooky_2.nbt,2,CHEST:5,./NBT/Lorestoryline/LoreSpooky_1.nbt,2,CHEST:5,./NBT/StructureLoot/JunkChest_1.nbt,10,CHEST:5,./NBT/StructureLoot/JunkChest_2.nbt,5,CHEST:5,./NBT/StructureLoot/JunkChest_3.nbt,5,CHEST:5,./NBT/StructureLoot/JunkChest_4.nbt,5,CHEST:5,./NBT/StructureLoot/JunkChest_5.nbt,100)
B(-4,4,-8,STONE_SLAB)
B(-3,4,-8,AIR)
B(-2,4,-8,AIR)
B(-1,4,-8,STONE_BRICK_STAIRS)
B(0,4,-8,STONE_BRICK_STAIRS:3)
B(1,4,-8,STONE_BRICK_STAIRS:1)
B(2,4,-8,AIR)
B(3,4,-8,AIR)
B(4,4,-8,AIR)
B(5,4,-8,AIR)
B(6,4,-8,AIR)
B(7,4,-8,AIR)
B(-8,4,-7,STONE:6)
B(-7,4,-7,WOODEN_SLAB:13)
B(-6,4,-7,STONE:6)
B(-5,4,-7,SKULL:5)
B(-4,4,-7,STONEBRICK:3)
B(-3,4,-7,AIR)
B(-2,4,-7,STONEBRICK:3)
B(-1,4,-7,AIR)
B(0,4,-7,AIR)
B(1,4,-7,AIR)
B(2,4,-7,STONEBRICK:3)
B(3,4,-7,AIR)
B(4,4,-7,AIR)
B(5,4,-7,STONEBRICK:3)
B(6,4,-7,AIR)
B(7,4,-7,AIR)
B(-8,4,-6,LOG)
B(-7,4,-6,LOG:4)
B(-6,4,-6,LOG)
RB(-5,4,-6,CHEST:4,./NBT/StructureLoot/JunkChest_1.nbt,10,CHEST:4,./NBT/StructureLoot/JunkChest_2.nbt,5,CHEST:4,./NBT/StructureLoot/JunkChest_3.nbt,5,CHEST:4,./NBT/StructureLoot/JunkChest_4.nbt,5,CHEST:4,./NBT/StructureLoot/JunkChest_5.nbt,5,CHEST:4,./NBT/Lorestoryline/LoreSpooky_5.nbt,2,CHEST:4,./NBT/Lorestoryline/LoreSpooky_4.nbt,2,CHEST:4,./NBT/Lorestoryline/LoreSpooky_3.nbt,2,CHEST:4,./NBT/Lorestoryline/LoreSpooky_2.nbt,2,CHEST:4,./NBT/Lorestoryline/LoreSpooky_1.nbt,2,CHEST:4,./NBT/StructureLoot/JunkChest_1.nbt,10,CHEST:4,./NBT/StructureLoot/JunkChest_2.nbt,5,CHEST:4,./NBT/StructureLoot/JunkChest_3.nbt,5,CHEST:4,./NBT/StructureLoot/JunkChest_4.nbt,5,CHEST:4,./NBT/StructureLoot/JunkChest_5.nbt,100)
B(-4,4,-6,STONE_SLAB)
B(-3,4,-6,AIR)
B(-2,4,-6,AIR)
B(-1,4,-6,AIR)
B(0,4,-6,AIR)
B(1,4,-6,AIR)
B(2,4,-6,AIR)
B(3,4,-6,AIR)
B(4,4,-6,AIR)
B(5,4,-6,IRON_BARS)
B(6,4,-6,AIR)
B(7,4,-6,AIR)
B(-8,4,-5,STONE:6)
B(-7,4,-5,WOODEN_SLAB:13)
B(-6,4,-5,STONE:6)
B(-5,4,-5,SKULL:5)
B(-4,4,-5,STONEBRICK:3)
B(-3,4,-5,STONE_SLAB)
B(-2,4,-5,STONE_SLAB)
B(-1,4,-5,STONEBRICK:3)
B(0,4,-5,AIR)
B(1,4,-5,AIR)
B(2,4,-5,STONEBRICK:3)
B(3,4,-5,STONE_SLAB)
B(4,4,-5,STONE_SLAB)
B(5,4,-5,STONEBRICK:3)
RB(6,4,-5,CHEST:2,./NBT/StructureLoot/JunkChest_1.nbt,10,CHEST:2,./NBT/StructureLoot/JunkChest_2.nbt,5,CHEST:2,./NBT/StructureLoot/JunkChest_3.nbt,5,CHEST:2,./NBT/StructureLoot/JunkChest_4.nbt,5,CHEST:2,./NBT/StructureLoot/JunkChest_5.nbt,5,CHEST:2,./NBT/Lorestoryline/LoreSpooky_5.nbt,2,CHEST:2,./NBT/Lorestoryline/LoreSpooky_4.nbt,2,CHEST:2,./NBT/Lorestoryline/LoreSpooky_3.nbt,2,CHEST:2,./NBT/Lorestoryline/LoreSpooky_2.nbt,2,CHEST:2,./NBT/Lorestoryline/LoreSpooky_1.nbt,2,CHEST:2,./NBT/StructureLoot/JunkChest_1.nbt,10,CHEST:2,./NBT/StructureLoot/JunkChest_2.nbt,5,CHEST:2,./NBT/StructureLoot/JunkChest_3.nbt,5,CHEST:2,./NBT/StructureLoot/JunkChest_4.nbt,5,CHEST:2,./NBT/StructureLoot/JunkChest_5.nbt,100)
B(7,4,-5,QUARTZ_STAIRS:2)
B(-8,4,-4,STONE:6)
B(-7,4,-4,WOODEN_SLAB:13)
B(-6,4,-4,STONE:6)
B(-5,4,-4,SKULL:5)
B(-4,4,-4,SKULL:3)
RB(-3,4,-4,CHEST:3,./NBT/StructureLoot/JunkChest_1.nbt,10,CHEST:3,./NBT/StructureLoot/JunkChest_2.nbt,5,CHEST:3,./NBT/StructureLoot/JunkChest_3.nbt,5,CHEST:3,./NBT/StructureLoot/JunkChest_4.nbt,5,CHEST:3,./NBT/StructureLoot/JunkChest_5.nbt,5,CHEST:3,./NBT/Lorestoryline/LoreSpooky_5.nbt,2,CHEST:3,./NBT/Lorestoryline/LoreSpooky_4.nbt,2,CHEST:3,./NBT/Lorestoryline/LoreSpooky_3.nbt,2,CHEST:3,./NBT/Lorestoryline/LoreSpooky_2.nbt,2,CHEST:3,./NBT/Lorestoryline/LoreSpooky_1.nbt,2,CHEST:3,./NBT/StructureLoot/JunkChest_1.nbt,10,CHEST:3,./NBT/StructureLoot/JunkChest_2.nbt,5,CHEST:3,./NBT/StructureLoot/JunkChest_3.nbt,5,CHEST:3,./NBT/StructureLoot/JunkChest_4.nbt,5,CHEST:3,./NBT/StructureLoot/JunkChest_5.nbt,100)
RB(-2,4,-4,CHEST:3,./NBT/StructureLoot/JunkChest_1.nbt,10,CHEST:3,./NBT/StructureLoot/JunkChest_2.nbt,5,CHEST:3,./NBT/StructureLoot/JunkChest_3.nbt,5,CHEST:3,./NBT/StructureLoot/JunkChest_4.nbt,5,CHEST:3,./NBT/StructureLoot/JunkChest_5.nbt,5,CHEST:3,./NBT/Lorestoryline/LoreSpooky_5.nbt,2,CHEST:3,./NBT/Lorestoryline/LoreSpooky_4.nbt,2,CHEST:3,./NBT/Lorestoryline/LoreSpooky_3.nbt,2,CHEST:3,./NBT/Lorestoryline/LoreSpooky_2.nbt,2,CHEST:3,./NBT/Lorestoryline/LoreSpooky_1.nbt,2,CHEST:3,./NBT/StructureLoot/JunkChest_1.nbt,10,CHEST:3,./NBT/StructureLoot/JunkChest_2.nbt,5,CHEST:3,./NBT/StructureLoot/JunkChest_3.nbt,5,CHEST:3,./NBT/StructureLoot/JunkChest_4.nbt,5,CHEST:3,./NBT/StructureLoot/JunkChest_5.nbt,100)
RB(-1,4,-4,SKULL:1,./NBT/Skulls/dungeon_skull_01.nbt,6,AIR,9,SKULL:1,./NBT/Skulls/dungeon_skull_02.nbt,12,AIR,15,SKULL:1,./NBT/Skulls/dungeon_skull_03.nbt,18,AIR,21,SKULL:1,./NBT/Skulls/dungeon_skull_04.nbt,24,AIR,27,SKULL:1,./NBT/Skulls/dungeon_skull_05.nbt,30,AIR,33,SKULL:1,./NBT/Skulls/dungeon_skull_06.nbt,36,AIR,39,SKULL:1,./NBT/Skulls/dungeon_skull_07.nbt,42,AIR,45,SKULL:1,./NBT/Skulls/dungeon_skull_08.nbt,48,AIR,51,SKULL:1,./NBT/Skulls/dungeon_skull_09.nbt,54,AIR,57,SKULL:1,./NBT/Skulls/dungeon_skull_10.nbt,60,AIR,63,SKULL:1,./NBT/Skulls/dungeon_skull_11.nbt,66,AIR,69,SKULL:1,./NBT/Skulls/dungeon_skull_12.nbt,72,AIR,75,SKULL:1,./NBT/Skulls/dungeon_skull_13.nbt,78,AIR,81,SKULL:1,./NBT/Skulls/dungeon_skull_14.nbt,84,AIR,87,SKULL:1,./NBT/Skulls/dungeon_skull_15.nbt,90,AIR,93,SKULL:1,./NBT/Skulls/dungeon_skull_16.nbt,96,AIR,100)
B(0,4,-4,AIR)
B(1,4,-4,AIR)
RB(2,4,-4,SKULL:1,./NBT/Skulls/dungeon_skull_01.nbt,6,AIR,9,SKULL:1,./NBT/Skulls/dungeon_skull_02.nbt,12,AIR,15,SKULL:1,./NBT/Skulls/dungeon_skull_03.nbt,18,AIR,21,SKULL:1,./NBT/Skulls/dungeon_skull_04.nbt,24,AIR,27,SKULL:1,./NBT/Skulls/dungeon_skull_05.nbt,30,AIR,33,SKULL:1,./NBT/Skulls/dungeon_skull_06.nbt,36,AIR,39,SKULL:1,./NBT/Skulls/dungeon_skull_07.nbt,42,AIR,45,SKULL:1,./NBT/Skulls/dungeon_skull_08.nbt,48,AIR,51,SKULL:1,./NBT/Skulls/dungeon_skull_09.nbt,54,AIR,57,SKULL:1,./NBT/Skulls/dungeon_skull_10.nbt,60,AIR,63,SKULL:1,./NBT/Skulls/dungeon_skull_11.nbt,66,AIR,69,SKULL:1,./NBT/Skulls/dungeon_skull_12.nbt,72,AIR,75,SKULL:1,./NBT/Skulls/dungeon_skull_13.nbt,78,AIR,81,SKULL:1,./NBT/Skulls/dungeon_skull_14.nbt,84,AIR,87,SKULL:1,./NBT/Skulls/dungeon_skull_15.nbt,90,AIR,93,SKULL:1,./NBT/Skulls/dungeon_skull_16.nbt,96,AIR,100)
RB(3,4,-4,CHEST:3,./NBT/StructureLoot/JunkChest_1.nbt,10,CHEST:3,./NBT/StructureLoot/JunkChest_2.nbt,5,CHEST:3,./NBT/StructureLoot/JunkChest_3.nbt,5,CHEST:3,./NBT/StructureLoot/JunkChest_4.nbt,5,CHEST:3,./NBT/StructureLoot/JunkChest_5.nbt,5,CHEST:3,./NBT/Lorestoryline/LoreSpooky_5.nbt,2,CHEST:3,./NBT/Lorestoryline/LoreSpooky_4.nbt,2,CHEST:3,./NBT/Lorestoryline/LoreSpooky_3.nbt,2,CHEST:3,./NBT/Lorestoryline/LoreSpooky_2.nbt,2,CHEST:3,./NBT/Lorestoryline/LoreSpooky_1.nbt,2,CHEST:3,./NBT/StructureLoot/JunkChest_1.nbt,10,CHEST:3,./NBT/StructureLoot/JunkChest_2.nbt,5,CHEST:3,./NBT/StructureLoot/JunkChest_3.nbt,5,CHEST:3,./NBT/StructureLoot/JunkChest_4.nbt,5,CHEST:3,./NBT/StructureLoot/JunkChest_5.nbt,100)
RB(4,4,-4,CHEST:3,./NBT/StructureLoot/JunkChest_1.nbt,10,CHEST:3,./NBT/StructureLoot/JunkChest_2.nbt,5,CHEST:3,./NBT/StructureLoot/JunkChest_3.nbt,5,CHEST:3,./NBT/StructureLoot/JunkChest_4.nbt,5,CHEST:3,./NBT/StructureLoot/JunkChest_5.nbt,5,CHEST:3,./NBT/Lorestoryline/LoreSpooky_5.nbt,2,CHEST:3,./NBT/Lorestoryline/LoreSpooky_4.nbt,2,CHEST:3,./NBT/Lorestoryline/LoreSpooky_3.nbt,2,CHEST:3,./NBT/Lorestoryline/LoreSpooky_2.nbt,2,CHEST:3,./NBT/Lorestoryline/LoreSpooky_1.nbt,2,CHEST:3,./NBT/StructureLoot/JunkChest_1.nbt,10,CHEST:3,./NBT/StructureLoot/JunkChest_2.nbt,5,CHEST:3,./NBT/StructureLoot/JunkChest_3.nbt,5,CHEST:3,./NBT/StructureLoot/JunkChest_4.nbt,5,CHEST:3,./NBT/StructureLoot/JunkChest_5.nbt,100)
B(5,4,-4,IRON_BARS)
RB(6,4,-4,CHEST:2,./NBT/StructureLoot/JunkChest_1.nbt,10,CHEST:2,./NBT/StructureLoot/JunkChest_2.nbt,5,CHEST:2,./NBT/StructureLoot/JunkChest_3.nbt,5,CHEST:2,./NBT/StructureLoot/JunkChest_4.nbt,5,CHEST:2,./NBT/StructureLoot/JunkChest_5.nbt,5,CHEST:2,./NBT/Lorestoryline/LoreSpooky_5.nbt,2,CHEST:2,./NBT/Lorestoryline/LoreSpooky_4.nbt,2,CHEST:2,./NBT/Lorestoryline/LoreSpooky_3.nbt,2,CHEST:2,./NBT/Lorestoryline/LoreSpooky_2.nbt,2,CHEST:2,./NBT/Lorestoryline/LoreSpooky_1.nbt,2,CHEST:2,./NBT/StructureLoot/JunkChest_1.nbt,10,CHEST:2,./NBT/StructureLoot/JunkChest_2.nbt,5,CHEST:2,./NBT/StructureLoot/JunkChest_3.nbt,5,CHEST:2,./NBT/StructureLoot/JunkChest_4.nbt,5,CHEST:2,./NBT/StructureLoot/JunkChest_5.nbt,100)
B(7,4,-4,QUARTZ_BLOCK:1)
B(-8,4,-3,LOG)
B(-7,4,-3,LOG:4)
B(-6,4,-3,LOG)
RB(-5,4,-3,SKULL:1,./NBT/Skulls/dungeon_skull_01.nbt,6,AIR,9,SKULL:1,./NBT/Skulls/dungeon_skull_02.nbt,12,AIR,15,SKULL:1,./NBT/Skulls/dungeon_skull_03.nbt,18,AIR,21,SKULL:1,./NBT/Skulls/dungeon_skull_04.nbt,24,AIR,27,SKULL:1,./NBT/Skulls/dungeon_skull_05.nbt,30,AIR,33,SKULL:1,./NBT/Skulls/dungeon_skull_06.nbt,36,AIR,39,SKULL:1,./NBT/Skulls/dungeon_skull_07.nbt,42,AIR,45,SKULL:1,./NBT/Skulls/dungeon_skull_08.nbt,48,AIR,51,SKULL:1,./NBT/Skulls/dungeon_skull_09.nbt,54,AIR,57,SKULL:1,./NBT/Skulls/dungeon_skull_10.nbt,60,AIR,63,SKULL:1,./NBT/Skulls/dungeon_skull_11.nbt,66,AIR,69,SKULL:1,./NBT/Skulls/dungeon_skull_12.nbt,72,AIR,75,SKULL:1,./NBT/Skulls/dungeon_skull_13.nbt,78,AIR,81,SKULL:1,./NBT/Skulls/dungeon_skull_14.nbt,84,AIR,87,SKULL:1,./NBT/Skulls/dungeon_skull_15.nbt,90,AIR,93,SKULL:1,./NBT/Skulls/dungeon_skull_16.nbt,96,AIR,100)
B(-4,4,-3,STONEBRICK:3)
RB(-3,4,-3,SKULL:1,./NBT/Skulls/dungeon_skull_01.nbt,6,AIR,9,SKULL:1,./NBT/Skulls/dungeon_skull_02.nbt,12,AIR,15,SKULL:1,./NBT/Skulls/dungeon_skull_03.nbt,18,AIR,21,SKULL:1,./NBT/Skulls/dungeon_skull_04.nbt,24,AIR,27,SKULL:1,./NBT/Skulls/dungeon_skull_05.nbt,30,AIR,33,SKULL:1,./NBT/Skulls/dungeon_skull_06.nbt,36,AIR,39,SKULL:1,./NBT/Skulls/dungeon_skull_07.nbt,42,AIR,45,SKULL:1,./NBT/Skulls/dungeon_skull_08.nbt,48,AIR,51,SKULL:1,./NBT/Skulls/dungeon_skull_09.nbt,54,AIR,57,SKULL:1,./NBT/Skulls/dungeon_skull_10.nbt,60,AIR,63,SKULL:1,./NBT/Skulls/dungeon_skull_11.nbt,66,AIR,69,SKULL:1,./NBT/Skulls/dungeon_skull_12.nbt,72,AIR,75,SKULL:1,./NBT/Skulls/dungeon_skull_13.nbt,78,AIR,81,SKULL:1,./NBT/Skulls/dungeon_skull_14.nbt,84,AIR,87,SKULL:1,./NBT/Skulls/dungeon_skull_15.nbt,90,AIR,93,SKULL:1,./NBT/Skulls/dungeon_skull_16.nbt,96,AIR,100)
RB(-2,4,-3,SKULL:1,./NBT/Skulls/dungeon_skull_01.nbt,6,AIR,9,SKULL:1,./NBT/Skulls/dungeon_skull_02.nbt,12,AIR,15,SKULL:1,./NBT/Skulls/dungeon_skull_03.nbt,18,AIR,21,SKULL:1,./NBT/Skulls/dungeon_skull_04.nbt,24,AIR,27,SKULL:1,./NBT/Skulls/dungeon_skull_05.nbt,30,AIR,33,SKULL:1,./NBT/Skulls/dungeon_skull_06.nbt,36,AIR,39,SKULL:1,./NBT/Skulls/dungeon_skull_07.nbt,42,AIR,45,SKULL:1,./NBT/Skulls/dungeon_skull_08.nbt,48,AIR,51,SKULL:1,./NBT/Skulls/dungeon_skull_09.nbt,54,AIR,57,SKULL:1,./NBT/Skulls/dungeon_skull_10.nbt,60,AIR,63,SKULL:1,./NBT/Skulls/dungeon_skull_11.nbt,66,AIR,69,SKULL:1,./NBT/Skulls/dungeon_skull_12.nbt,72,AIR,75,SKULL:1,./NBT/Skulls/dungeon_skull_13.nbt,78,AIR,81,SKULL:1,./NBT/Skulls/dungeon_skull_14.nbt,84,AIR,87,SKULL:1,./NBT/Skulls/dungeon_skull_15.nbt,90,AIR,93,SKULL:1,./NBT/Skulls/dungeon_skull_16.nbt,96,AIR,100)
B(-1,4,-3,STONEBRICK:3)
B(0,4,-3,AIR)
B(1,4,-3,AIR)
B(2,4,-3,STONEBRICK:3)
RB(3,4,-3,SKULL:1,./NBT/Skulls/dungeon_skull_01.nbt,6,AIR,9,SKULL:1,./NBT/Skulls/dungeon_skull_02.nbt,12,AIR,15,SKULL:1,./NBT/Skulls/dungeon_skull_03.nbt,18,AIR,21,SKULL:1,./NBT/Skulls/dungeon_skull_04.nbt,24,AIR,27,SKULL:1,./NBT/Skulls/dungeon_skull_05.nbt,30,AIR,33,SKULL:1,./NBT/Skulls/dungeon_skull_06.nbt,36,AIR,39,SKULL:1,./NBT/Skulls/dungeon_skull_07.nbt,42,AIR,45,SKULL:1,./NBT/Skulls/dungeon_skull_08.nbt,48,AIR,51,SKULL:1,./NBT/Skulls/dungeon_skull_09.nbt,54,AIR,57,SKULL:1,./NBT/Skulls/dungeon_skull_10.nbt,60,AIR,63,SKULL:1,./NBT/Skulls/dungeon_skull_11.nbt,66,AIR,69,SKULL:1,./NBT/Skulls/dungeon_skull_12.nbt,72,AIR,75,SKULL:1,./NBT/Skulls/dungeon_skull_13.nbt,78,AIR,81,SKULL:1,./NBT/Skulls/dungeon_skull_14.nbt,84,AIR,87,SKULL:1,./NBT/Skulls/dungeon_skull_15.nbt,90,AIR,93,SKULL:1,./NBT/Skulls/dungeon_skull_16.nbt,96,AIR,100)
RB(4,4,-3,SKULL:1,./NBT/Skulls/dungeon_skull_01.nbt,6,AIR,9,SKULL:1,./NBT/Skulls/dungeon_skull_02.nbt,12,AIR,15,SKULL:1,./NBT/Skulls/dungeon_skull_03.nbt,18,AIR,21,SKULL:1,./NBT/Skulls/dungeon_skull_04.nbt,24,AIR,27,SKULL:1,./NBT/Skulls/dungeon_skull_05.nbt,30,AIR,33,SKULL:1,./NBT/Skulls/dungeon_skull_06.nbt,36,AIR,39,SKULL:1,./NBT/Skulls/dungeon_skull_07.nbt,42,AIR,45,SKULL:1,./NBT/Skulls/dungeon_skull_08.nbt,48,AIR,51,SKULL:1,./NBT/Skulls/dungeon_skull_09.nbt,54,AIR,57,SKULL:1,./NBT/Skulls/dungeon_skull_10.nbt,60,AIR,63,SKULL:1,./NBT/Skulls/dungeon_skull_11.nbt,66,AIR,69,SKULL:1,./NBT/Skulls/dungeon_skull_12.nbt,72,AIR,75,SKULL:1,./NBT/Skulls/dungeon_skull_13.nbt,78,AIR,81,SKULL:1,./NBT/Skulls/dungeon_skull_14.nbt,84,AIR,87,SKULL:1,./NBT/Skulls/dungeon_skull_15.nbt,90,AIR,93,SKULL:1,./NBT/Skulls/dungeon_skull_16.nbt,96,AIR,100)
B(5,4,-3,IRON_BARS)
RB(6,4,-3,CHEST:5,./NBT/StructureLoot/JunkChest_1.nbt,10,CHEST:5,./NBT/StructureLoot/JunkChest_2.nbt,5,CHEST:5,./NBT/StructureLoot/JunkChest_3.nbt,5,CHEST:5,./NBT/StructureLoot/JunkChest_4.nbt,5,CHEST:5,./NBT/StructureLoot/JunkChest_5.nbt,5,CHEST:5,./NBT/Lorestoryline/LoreSpooky_5.nbt,2,CHEST:5,./NBT/Lorestoryline/LoreSpooky_4.nbt,2,CHEST:5,./NBT/Lorestoryline/LoreSpooky_3.nbt,2,CHEST:5,./NBT/Lorestoryline/LoreSpooky_2.nbt,2,CHEST:5,./NBT/Lorestoryline/LoreSpooky_1.nbt,2,CHEST:5,./NBT/StructureLoot/JunkChest_1.nbt,10,CHEST:5,./NBT/StructureLoot/JunkChest_2.nbt,5,CHEST:5,./NBT/StructureLoot/JunkChest_3.nbt,5,CHEST:5,./NBT/StructureLoot/JunkChest_4.nbt,5,CHEST:5,./NBT/StructureLoot/JunkChest_5.nbt,100)
B(7,4,-3,QUARTZ_BLOCK:1)
B(-8,4,-2,STONE:6)
B(-7,4,-2,WOODEN_SLAB:13)
B(-6,4,-2,STONE:6)
RB(-5,4,-2,CHEST:3,./NBT/StructureLoot/JunkChest_1.nbt,10,CHEST:3,./NBT/StructureLoot/JunkChest_2.nbt,5,CHEST:3,./NBT/StructureLoot/JunkChest_3.nbt,5,CHEST:3,./NBT/StructureLoot/JunkChest_4.nbt,5,CHEST:3,./NBT/StructureLoot/JunkChest_5.nbt,5,CHEST:3,./NBT/Lorestoryline/LoreSpooky_5.nbt,2,CHEST:3,./NBT/Lorestoryline/LoreSpooky_4.nbt,2,CHEST:3,./NBT/Lorestoryline/LoreSpooky_3.nbt,2,CHEST:3,./NBT/Lorestoryline/LoreSpooky_2.nbt,2,CHEST:3,./NBT/Lorestoryline/LoreSpooky_1.nbt,2,CHEST:3,./NBT/StructureLoot/JunkChest_1.nbt,10,CHEST:3,./NBT/StructureLoot/JunkChest_2.nbt,5,CHEST:3,./NBT/StructureLoot/JunkChest_3.nbt,5,CHEST:3,./NBT/StructureLoot/JunkChest_4.nbt,5,CHEST:3,./NBT/StructureLoot/JunkChest_5.nbt,100)
RB(-4,4,-2,CHEST:3,./NBT/StructureLoot/JunkChest_1.nbt,10,CHEST:3,./NBT/StructureLoot/JunkChest_2.nbt,5,CHEST:3,./NBT/StructureLoot/JunkChest_3.nbt,5,CHEST:3,./NBT/StructureLoot/JunkChest_4.nbt,5,CHEST:3,./NBT/StructureLoot/JunkChest_5.nbt,5,CHEST:3,./NBT/Lorestoryline/LoreSpooky_5.nbt,2,CHEST:3,./NBT/Lorestoryline/LoreSpooky_4.nbt,2,CHEST:3,./NBT/Lorestoryline/LoreSpooky_3.nbt,2,CHEST:3,./NBT/Lorestoryline/LoreSpooky_2.nbt,2,CHEST:3,./NBT/Lorestoryline/LoreSpooky_1.nbt,2,CHEST:3,./NBT/StructureLoot/JunkChest_1.nbt,10,CHEST:3,./NBT/StructureLoot/JunkChest_2.nbt,5,CHEST:3,./NBT/StructureLoot/JunkChest_3.nbt,5,CHEST:3,./NBT/StructureLoot/JunkChest_4.nbt,5,CHEST:3,./NBT/StructureLoot/JunkChest_5.nbt,100)
B(-3,4,-2,AIR)
B(-2,4,-2,AIR)
B(-1,4,-2,AIR)
B(0,4,-2,AIR)
B(1,4,-2,AIR)
B(2,4,-2,AIR)
B(3,4,-2,AIR)
B(4,4,-2,AIR)
B(5,4,-2,STONEBRICK:3)
RB(6,4,-2,CHEST:5,./NBT/StructureLoot/JunkChest_1.nbt,10,CHEST:5,./NBT/StructureLoot/JunkChest_2.nbt,5,CHEST:5,./NBT/StructureLoot/JunkChest_3.nbt,5,CHEST:5,./NBT/StructureLoot/JunkChest_4.nbt,5,CHEST:5,./NBT/StructureLoot/JunkChest_5.nbt,5,CHEST:5,./NBT/Lorestoryline/LoreSpooky_5.nbt,2,CHEST:5,./NBT/Lorestoryline/LoreSpooky_4.nbt,2,CHEST:5,./NBT/Lorestoryline/LoreSpooky_3.nbt,2,CHEST:5,./NBT/Lorestoryline/LoreSpooky_2.nbt,2,CHEST:5,./NBT/Lorestoryline/LoreSpooky_1.nbt,2,CHEST:5,./NBT/StructureLoot/JunkChest_1.nbt,10,CHEST:5,./NBT/StructureLoot/JunkChest_2.nbt,5,CHEST:5,./NBT/StructureLoot/JunkChest_3.nbt,5,CHEST:5,./NBT/StructureLoot/JunkChest_4.nbt,5,CHEST:5,./NBT/StructureLoot/JunkChest_5.nbt,100)
B(7,4,-2,QUARTZ_STAIRS:3)
B(-8,4,-1,STONE:6)
B(-7,4,-1,WOODEN_SLAB:13)
B(-6,4,-1,STONE:6)
B(-5,4,-1,QUARTZ_BLOCK:1)
B(-4,4,-1,QUARTZ_STAIRS:1)
B(-3,4,-1,AIR)
B(-2,4,-1,AIR)
B(-1,4,-1,AIR)
B(0,4,-1,AIR)
B(1,4,-1,AIR)
B(2,4,-1,AIR)
B(3,4,-1,AIR)
B(4,4,-1,AIR)
B(5,4,-1,AIR)
B(6,4,-1,AIR)
B(7,4,-1,AIR)
B(-8,4,0,LOG)
B(-7,4,0,LOG:4)
B(-6,4,0,LOG)
RB(-5,4,0,CHEST:3,./NBT/StructureLoot/JunkChest_1.nbt,10,CHEST:3,./NBT/StructureLoot/JunkChest_2.nbt,5,CHEST:3,./NBT/StructureLoot/JunkChest_3.nbt,5,CHEST:3,./NBT/StructureLoot/JunkChest_4.nbt,5,CHEST:3,./NBT/StructureLoot/JunkChest_5.nbt,5,CHEST:3,./NBT/Lorestoryline/LoreSpooky_5.nbt,2,CHEST:3,./NBT/Lorestoryline/LoreSpooky_4.nbt,2,CHEST:3,./NBT/Lorestoryline/LoreSpooky_3.nbt,2,CHEST:3,./NBT/Lorestoryline/LoreSpooky_2.nbt,2,CHEST:3,./NBT/Lorestoryline/LoreSpooky_1.nbt,2,CHEST:3,./NBT/StructureLoot/JunkChest_1.nbt,10,CHEST:3,./NBT/StructureLoot/JunkChest_2.nbt,5,CHEST:3,./NBT/StructureLoot/JunkChest_3.nbt,5,CHEST:3,./NBT/StructureLoot/JunkChest_4.nbt,5,CHEST:3,./NBT/StructureLoot/JunkChest_5.nbt,100)
RB(-4,4,0,CHEST:3,./NBT/StructureLoot/JunkChest_1.nbt,10,CHEST:3,./NBT/StructureLoot/JunkChest_2.nbt,5,CHEST:3,./NBT/StructureLoot/JunkChest_3.nbt,5,CHEST:3,./NBT/StructureLoot/JunkChest_4.nbt,5,CHEST:3,./NBT/StructureLoot/JunkChest_5.nbt,5,CHEST:3,./NBT/Lorestoryline/LoreSpooky_5.nbt,2,CHEST:3,./NBT/Lorestoryline/LoreSpooky_4.nbt,2,CHEST:3,./NBT/Lorestoryline/LoreSpooky_3.nbt,2,CHEST:3,./NBT/Lorestoryline/LoreSpooky_2.nbt,2,CHEST:3,./NBT/Lorestoryline/LoreSpooky_1.nbt,2,CHEST:3,./NBT/StructureLoot/JunkChest_1.nbt,10,CHEST:3,./NBT/StructureLoot/JunkChest_2.nbt,5,CHEST:3,./NBT/StructureLoot/JunkChest_3.nbt,5,CHEST:3,./NBT/StructureLoot/JunkChest_4.nbt,5,CHEST:3,./NBT/StructureLoot/JunkChest_5.nbt,100)
B(-3,4,0,AIR)
B(-2,4,0,AIR)
B(-1,4,0,AIR)
B(0,4,0,AIR)
B(1,4,0,AIR)
B(2,4,0,AIR)
B(3,4,0,AIR)
B(4,4,0,AIR)
B(5,4,0,AIR)
B(6,4,0,AIR)
B(7,4,0,AIR)
B(-8,4,1,STONE:6)
B(-7,4,1,WOODEN_SLAB:13)
B(-6,4,1,STONE:6)
RB(-5,4,1,SKULL:1,./NBT/Skulls/dungeon_skull_01.nbt,6,AIR,9,SKULL:1,./NBT/Skulls/dungeon_skull_02.nbt,12,AIR,15,SKULL:1,./NBT/Skulls/dungeon_skull_03.nbt,18,AIR,21,SKULL:1,./NBT/Skulls/dungeon_skull_04.nbt,24,AIR,27,SKULL:1,./NBT/Skulls/dungeon_skull_05.nbt,30,AIR,33,SKULL:1,./NBT/Skulls/dungeon_skull_06.nbt,36,AIR,39,SKULL:1,./NBT/Skulls/dungeon_skull_07.nbt,42,AIR,45,SKULL:1,./NBT/Skulls/dungeon_skull_08.nbt,48,AIR,51,SKULL:1,./NBT/Skulls/dungeon_skull_09.nbt,54,AIR,57,SKULL:1,./NBT/Skulls/dungeon_skull_10.nbt,60,AIR,63,SKULL:1,./NBT/Skulls/dungeon_skull_11.nbt,66,AIR,69,SKULL:1,./NBT/Skulls/dungeon_skull_12.nbt,72,AIR,75,SKULL:1,./NBT/Skulls/dungeon_skull_13.nbt,78,AIR,81,SKULL:1,./NBT/Skulls/dungeon_skull_14.nbt,84,AIR,87,SKULL:1,./NBT/Skulls/dungeon_skull_15.nbt,90,AIR,93,SKULL:1,./NBT/Skulls/dungeon_skull_16.nbt,96,AIR,100)
B(-4,4,1,STONEBRICK:3)
RB(-3,4,1,SKULL:1,./NBT/Skulls/dungeon_skull_01.nbt,6,AIR,9,SKULL:1,./NBT/Skulls/dungeon_skull_02.nbt,12,AIR,15,SKULL:1,./NBT/Skulls/dungeon_skull_03.nbt,18,AIR,21,SKULL:1,./NBT/Skulls/dungeon_skull_04.nbt,24,AIR,27,SKULL:1,./NBT/Skulls/dungeon_skull_05.nbt,30,AIR,33,SKULL:1,./NBT/Skulls/dungeon_skull_06.nbt,36,AIR,39,SKULL:1,./NBT/Skulls/dungeon_skull_07.nbt,42,AIR,45,SKULL:1,./NBT/Skulls/dungeon_skull_08.nbt,48,AIR,51,SKULL:1,./NBT/Skulls/dungeon_skull_09.nbt,54,AIR,57,SKULL:1,./NBT/Skulls/dungeon_skull_10.nbt,60,AIR,63,SKULL:1,./NBT/Skulls/dungeon_skull_11.nbt,66,AIR,69,SKULL:1,./NBT/Skulls/dungeon_skull_12.nbt,72,AIR,75,SKULL:1,./NBT/Skulls/dungeon_skull_13.nbt,78,AIR,81,SKULL:1,./NBT/Skulls/dungeon_skull_14.nbt,84,AIR,87,SKULL:1,./NBT/Skulls/dungeon_skull_15.nbt,90,AIR,93,SKULL:1,./NBT/Skulls/dungeon_skull_16.nbt,96,AIR,100)
RB(-2,4,1,SKULL:1,./NBT/Skulls/dungeon_skull_01.nbt,6,AIR,9,SKULL:1,./NBT/Skulls/dungeon_skull_02.nbt,12,AIR,15,SKULL:1,./NBT/Skulls/dungeon_skull_03.nbt,18,AIR,21,SKULL:1,./NBT/Skulls/dungeon_skull_04.nbt,24,AIR,27,SKULL:1,./NBT/Skulls/dungeon_skull_05.nbt,30,AIR,33,SKULL:1,./NBT/Skulls/dungeon_skull_06.nbt,36,AIR,39,SKULL:1,./NBT/Skulls/dungeon_skull_07.nbt,42,AIR,45,SKULL:1,./NBT/Skulls/dungeon_skull_08.nbt,48,AIR,51,SKULL:1,./NBT/Skulls/dungeon_skull_09.nbt,54,AIR,57,SKULL:1,./NBT/Skulls/dungeon_skull_10.nbt,60,AIR,63,SKULL:1,./NBT/Skulls/dungeon_skull_11.nbt,66,AIR,69,SKULL:1,./NBT/Skulls/dungeon_skull_12.nbt,72,AIR,75,SKULL:1,./NBT/Skulls/dungeon_skull_13.nbt,78,AIR,81,SKULL:1,./NBT/Skulls/dungeon_skull_14.nbt,84,AIR,87,SKULL:1,./NBT/Skulls/dungeon_skull_15.nbt,90,AIR,93,SKULL:1,./NBT/Skulls/dungeon_skull_16.nbt,96,AIR,100)
B(-1,4,1,STONEBRICK:3)
RB(0,4,1,SKULL:1,./NBT/Skulls/dungeon_skull_01.nbt,6,AIR,9,SKULL:1,./NBT/Skulls/dungeon_skull_02.nbt,12,AIR,15,SKULL:1,./NBT/Skulls/dungeon_skull_03.nbt,18,AIR,21,SKULL:1,./NBT/Skulls/dungeon_skull_04.nbt,24,AIR,27,SKULL:1,./NBT/Skulls/dungeon_skull_05.nbt,30,AIR,33,SKULL:1,./NBT/Skulls/dungeon_skull_06.nbt,36,AIR,39,SKULL:1,./NBT/Skulls/dungeon_skull_07.nbt,42,AIR,45,SKULL:1,./NBT/Skulls/dungeon_skull_08.nbt,48,AIR,51,SKULL:1,./NBT/Skulls/dungeon_skull_09.nbt,54,AIR,57,SKULL:1,./NBT/Skulls/dungeon_skull_10.nbt,60,AIR,63,SKULL:1,./NBT/Skulls/dungeon_skull_11.nbt,66,AIR,69,SKULL:1,./NBT/Skulls/dungeon_skull_12.nbt,72,AIR,75,SKULL:1,./NBT/Skulls/dungeon_skull_13.nbt,78,AIR,81,SKULL:1,./NBT/Skulls/dungeon_skull_14.nbt,84,AIR,87,SKULL:1,./NBT/Skulls/dungeon_skull_15.nbt,90,AIR,93,SKULL:1,./NBT/Skulls/dungeon_skull_16.nbt,96,AIR,100)
RB(1,4,1,SKULL:1,./NBT/Skulls/dungeon_skull_01.nbt,6,AIR,9,SKULL:1,./NBT/Skulls/dungeon_skull_02.nbt,12,AIR,15,SKULL:1,./NBT/Skulls/dungeon_skull_03.nbt,18,AIR,21,SKULL:1,./NBT/Skulls/dungeon_skull_04.nbt,24,AIR,27,SKULL:1,./NBT/Skulls/dungeon_skull_05.nbt,30,AIR,33,SKULL:1,./NBT/Skulls/dungeon_skull_06.nbt,36,AIR,39,SKULL:1,./NBT/Skulls/dungeon_skull_07.nbt,42,AIR,45,SKULL:1,./NBT/Skulls/dungeon_skull_08.nbt,48,AIR,51,SKULL:1,./NBT/Skulls/dungeon_skull_09.nbt,54,AIR,57,SKULL:1,./NBT/Skulls/dungeon_skull_10.nbt,60,AIR,63,SKULL:1,./NBT/Skulls/dungeon_skull_11.nbt,66,AIR,69,SKULL:1,./NBT/Skulls/dungeon_skull_12.nbt,72,AIR,75,SKULL:1,./NBT/Skulls/dungeon_skull_13.nbt,78,AIR,81,SKULL:1,./NBT/Skulls/dungeon_skull_14.nbt,84,AIR,87,SKULL:1,./NBT/Skulls/dungeon_skull_15.nbt,90,AIR,93,SKULL:1,./NBT/Skulls/dungeon_skull_16.nbt,96,AIR,100)
B(2,4,1,STONEBRICK:3)
RB(3,4,1,SKULL:1,./NBT/Skulls/dungeon_skull_01.nbt,6,AIR,9,SKULL:1,./NBT/Skulls/dungeon_skull_02.nbt,12,AIR,15,SKULL:1,./NBT/Skulls/dungeon_skull_03.nbt,18,AIR,21,SKULL:1,./NBT/Skulls/dungeon_skull_04.nbt,24,AIR,27,SKULL:1,./NBT/Skulls/dungeon_skull_05.nbt,30,AIR,33,SKULL:1,./NBT/Skulls/dungeon_skull_06.nbt,36,AIR,39,SKULL:1,./NBT/Skulls/dungeon_skull_07.nbt,42,AIR,45,SKULL:1,./NBT/Skulls/dungeon_skull_08.nbt,48,AIR,51,SKULL:1,./NBT/Skulls/dungeon_skull_09.nbt,54,AIR,57,SKULL:1,./NBT/Skulls/dungeon_skull_10.nbt,60,AIR,63,SKULL:1,./NBT/Skulls/dungeon_skull_11.nbt,66,AIR,69,SKULL:1,./NBT/Skulls/dungeon_skull_12.nbt,72,AIR,75,SKULL:1,./NBT/Skulls/dungeon_skull_13.nbt,78,AIR,81,SKULL:1,./NBT/Skulls/dungeon_skull_14.nbt,84,AIR,87,SKULL:1,./NBT/Skulls/dungeon_skull_15.nbt,90,AIR,93,SKULL:1,./NBT/Skulls/dungeon_skull_16.nbt,96,AIR,100)
RB(4,4,1,SKULL:1,./NBT/Skulls/dungeon_skull_01.nbt,6,AIR,9,SKULL:1,./NBT/Skulls/dungeon_skull_02.nbt,12,AIR,15,SKULL:1,./NBT/Skulls/dungeon_skull_03.nbt,18,AIR,21,SKULL:1,./NBT/Skulls/dungeon_skull_04.nbt,24,AIR,27,SKULL:1,./NBT/Skulls/dungeon_skull_05.nbt,30,AIR,33,SKULL:1,./NBT/Skulls/dungeon_skull_06.nbt,36,AIR,39,SKULL:1,./NBT/Skulls/dungeon_skull_07.nbt,42,AIR,45,SKULL:1,./NBT/Skulls/dungeon_skull_08.nbt,48,AIR,51,SKULL:1,./NBT/Skulls/dungeon_skull_09.nbt,54,AIR,57,SKULL:1,./NBT/Skulls/dungeon_skull_10.nbt,60,AIR,63,SKULL:1,./NBT/Skulls/dungeon_skull_11.nbt,66,AIR,69,SKULL:1,./NBT/Skulls/dungeon_skull_12.nbt,72,AIR,75,SKULL:1,./NBT/Skulls/dungeon_skull_13.nbt,78,AIR,81,SKULL:1,./NBT/Skulls/dungeon_skull_14.nbt,84,AIR,87,SKULL:1,./NBT/Skulls/dungeon_skull_15.nbt,90,AIR,93,SKULL:1,./NBT/Skulls/dungeon_skull_16.nbt,96,AIR,100)
B(5,4,1,STONEBRICK:3)
RB(6,4,1,CHEST:5,./NBT/StructureLoot/JunkChest_1.nbt,10,CHEST:5,./NBT/StructureLoot/JunkChest_2.nbt,5,CHEST:5,./NBT/StructureLoot/JunkChest_3.nbt,5,CHEST:5,./NBT/StructureLoot/JunkChest_4.nbt,5,CHEST:5,./NBT/StructureLoot/JunkChest_5.nbt,5,CHEST:5,./NBT/Lorestoryline/LoreSpooky_5.nbt,2,CHEST:5,./NBT/Lorestoryline/LoreSpooky_4.nbt,2,CHEST:5,./NBT/Lorestoryline/LoreSpooky_3.nbt,2,CHEST:5,./NBT/Lorestoryline/LoreSpooky_2.nbt,2,CHEST:5,./NBT/Lorestoryline/LoreSpooky_1.nbt,2,CHEST:5,./NBT/StructureLoot/JunkChest_1.nbt,10,CHEST:5,./NBT/StructureLoot/JunkChest_2.nbt,5,CHEST:5,./NBT/StructureLoot/JunkChest_3.nbt,5,CHEST:5,./NBT/StructureLoot/JunkChest_4.nbt,5,CHEST:5,./NBT/StructureLoot/JunkChest_5.nbt,100)
B(7,4,1,QUARTZ_STAIRS:2)
B(-8,4,2,STONE:6)
B(-7,4,2,WOODEN_SLAB:13)
B(-6,4,2,STONE:6)
RB(-5,4,2,CHEST:5,./NBT/StructureLoot/JunkChest_1.nbt,10,CHEST:5,./NBT/StructureLoot/JunkChest_2.nbt,5,CHEST:5,./NBT/StructureLoot/JunkChest_3.nbt,5,CHEST:5,./NBT/StructureLoot/JunkChest_4.nbt,5,CHEST:5,./NBT/StructureLoot/JunkChest_5.nbt,5,CHEST:5,./NBT/Lorestoryline/LoreSpooky_5.nbt,2,CHEST:5,./NBT/Lorestoryline/LoreSpooky_4.nbt,2,CHEST:5,./NBT/Lorestoryline/LoreSpooky_3.nbt,2,CHEST:5,./NBT/Lorestoryline/LoreSpooky_2.nbt,2,CHEST:5,./NBT/Lorestoryline/LoreSpooky_1.nbt,2,CHEST:5,./NBT/StructureLoot/JunkChest_1.nbt,10,CHEST:5,./NBT/StructureLoot/JunkChest_2.nbt,5,CHEST:5,./NBT/StructureLoot/JunkChest_3.nbt,5,CHEST:5,./NBT/StructureLoot/JunkChest_4.nbt,5,CHEST:5,./NBT/StructureLoot/JunkChest_5.nbt,100)
B(-4,4,2,QUARTZ_BLOCK:1)
RB(-3,4,2,CHEST:5,./NBT/StructureLoot/JunkChest_1.nbt,10,CHEST:5,./NBT/StructureLoot/JunkChest_2.nbt,5,CHEST:5,./NBT/StructureLoot/JunkChest_3.nbt,5,CHEST:5,./NBT/StructureLoot/JunkChest_4.nbt,5,CHEST:5,./NBT/StructureLoot/JunkChest_5.nbt,5,CHEST:5,./NBT/Lorestoryline/LoreSpooky_5.nbt,2,CHEST:5,./NBT/Lorestoryline/LoreSpooky_4.nbt,2,CHEST:5,./NBT/Lorestoryline/LoreSpooky_3.nbt,2,CHEST:5,./NBT/Lorestoryline/LoreSpooky_2.nbt,2,CHEST:5,./NBT/Lorestoryline/LoreSpooky_1.nbt,2,CHEST:5,./NBT/StructureLoot/JunkChest_1.nbt,10,CHEST:5,./NBT/StructureLoot/JunkChest_2.nbt,5,CHEST:5,./NBT/StructureLoot/JunkChest_3.nbt,5,CHEST:5,./NBT/StructureLoot/JunkChest_4.nbt,5,CHEST:5,./NBT/StructureLoot/JunkChest_5.nbt,100)
RB(-2,4,2,CHEST:2,./NBT/StructureLoot/JunkChest_1.nbt,10,CHEST:2,./NBT/StructureLoot/JunkChest_2.nbt,5,CHEST:2,./NBT/StructureLoot/JunkChest_3.nbt,5,CHEST:2,./NBT/StructureLoot/JunkChest_4.nbt,5,CHEST:2,./NBT/StructureLoot/JunkChest_5.nbt,5,CHEST:2,./NBT/Lorestoryline/LoreSpooky_5.nbt,2,CHEST:2,./NBT/Lorestoryline/LoreSpooky_4.nbt,2,CHEST:2,./NBT/Lorestoryline/LoreSpooky_3.nbt,2,CHEST:2,./NBT/Lorestoryline/LoreSpooky_2.nbt,2,CHEST:2,./NBT/Lorestoryline/LoreSpooky_1.nbt,2,CHEST:2,./NBT/StructureLoot/JunkChest_1.nbt,10,CHEST:2,./NBT/StructureLoot/JunkChest_2.nbt,5,CHEST:2,./NBT/StructureLoot/JunkChest_3.nbt,5,CHEST:2,./NBT/StructureLoot/JunkChest_4.nbt,5,CHEST:2,./NBT/StructureLoot/JunkChest_5.nbt,100)
B(-1,4,2,QUARTZ_BLOCK:1)
RB(0,4,2,CHEST:2,./NBT/StructureLoot/JunkChest_1.nbt,10,CHEST:2,./NBT/StructureLoot/JunkChest_2.nbt,5,CHEST:2,./NBT/StructureLoot/JunkChest_3.nbt,5,CHEST:2,./NBT/StructureLoot/JunkChest_4.nbt,5,CHEST:2,./NBT/StructureLoot/JunkChest_5.nbt,5,CHEST:2,./NBT/Lorestoryline/LoreSpooky_5.nbt,2,CHEST:2,./NBT/Lorestoryline/LoreSpooky_4.nbt,2,CHEST:2,./NBT/Lorestoryline/LoreSpooky_3.nbt,2,CHEST:2,./NBT/Lorestoryline/LoreSpooky_2.nbt,2,CHEST:2,./NBT/Lorestoryline/LoreSpooky_1.nbt,2,CHEST:2,./NBT/StructureLoot/JunkChest_1.nbt,10,CHEST:2,./NBT/StructureLoot/JunkChest_2.nbt,5,CHEST:2,./NBT/StructureLoot/JunkChest_3.nbt,5,CHEST:2,./NBT/StructureLoot/JunkChest_4.nbt,5,CHEST:2,./NBT/StructureLoot/JunkChest_5.nbt,100)
RB(1,4,2,CHEST:4,./NBT/StructureLoot/JunkChest_1.nbt,10,CHEST:4,./NBT/StructureLoot/JunkChest_2.nbt,5,CHEST:4,./NBT/StructureLoot/JunkChest_3.nbt,5,CHEST:4,./NBT/StructureLoot/JunkChest_4.nbt,5,CHEST:4,./NBT/StructureLoot/JunkChest_5.nbt,5,CHEST:4,./NBT/Lorestoryline/LoreSpooky_5.nbt,2,CHEST:4,./NBT/Lorestoryline/LoreSpooky_4.nbt,2,CHEST:4,./NBT/Lorestoryline/LoreSpooky_3.nbt,2,CHEST:4,./NBT/Lorestoryline/LoreSpooky_2.nbt,2,CHEST:4,./NBT/Lorestoryline/LoreSpooky_1.nbt,2,CHEST:4,./NBT/StructureLoot/JunkChest_1.nbt,10,CHEST:4,./NBT/StructureLoot/JunkChest_2.nbt,5,CHEST:4,./NBT/StructureLoot/JunkChest_3.nbt,5,CHEST:4,./NBT/StructureLoot/JunkChest_4.nbt,5,CHEST:4,./NBT/StructureLoot/JunkChest_5.nbt,100)
B(2,4,2,QUARTZ_BLOCK:1)
RB(3,4,2,CHEST:5,./NBT/StructureLoot/JunkChest_1.nbt,10,CHEST:5,./NBT/StructureLoot/JunkChest_2.nbt,5,CHEST:5,./NBT/StructureLoot/JunkChest_3.nbt,5,CHEST:5,./NBT/StructureLoot/JunkChest_4.nbt,5,CHEST:5,./NBT/StructureLoot/JunkChest_5.nbt,5,CHEST:5,./NBT/Lorestoryline/LoreSpooky_5.nbt,2,CHEST:5,./NBT/Lorestoryline/LoreSpooky_4.nbt,2,CHEST:5,./NBT/Lorestoryline/LoreSpooky_3.nbt,2,CHEST:5,./NBT/Lorestoryline/LoreSpooky_2.nbt,2,CHEST:5,./NBT/Lorestoryline/LoreSpooky_1.nbt,2,CHEST:5,./NBT/StructureLoot/JunkChest_1.nbt,10,CHEST:5,./NBT/StructureLoot/JunkChest_2.nbt,5,CHEST:5,./NBT/StructureLoot/JunkChest_3.nbt,5,CHEST:5,./NBT/StructureLoot/JunkChest_4.nbt,5,CHEST:5,./NBT/StructureLoot/JunkChest_5.nbt,100)
RB(4,4,2,CHEST:2,./NBT/StructureLoot/JunkChest_1.nbt,10,CHEST:2,./NBT/StructureLoot/JunkChest_2.nbt,5,CHEST:2,./NBT/StructureLoot/JunkChest_3.nbt,5,CHEST:2,./NBT/StructureLoot/JunkChest_4.nbt,5,CHEST:2,./NBT/StructureLoot/JunkChest_5.nbt,5,CHEST:2,./NBT/Lorestoryline/LoreSpooky_5.nbt,2,CHEST:2,./NBT/Lorestoryline/LoreSpooky_4.nbt,2,CHEST:2,./NBT/Lorestoryline/LoreSpooky_3.nbt,2,CHEST:2,./NBT/Lorestoryline/LoreSpooky_2.nbt,2,CHEST:2,./NBT/Lorestoryline/LoreSpooky_1.nbt,2,CHEST:2,./NBT/StructureLoot/JunkChest_1.nbt,10,CHEST:2,./NBT/StructureLoot/JunkChest_2.nbt,5,CHEST:2,./NBT/StructureLoot/JunkChest_3.nbt,5,CHEST:2,./NBT/StructureLoot/JunkChest_4.nbt,5,CHEST:2,./NBT/StructureLoot/JunkChest_5.nbt,100)
B(5,4,2,IRON_BARS)
RB(6,4,2,CHEST:5,./NBT/StructureLoot/JunkChest_1.nbt,10,CHEST:5,./NBT/StructureLoot/JunkChest_2.nbt,5,CHEST:5,./NBT/StructureLoot/JunkChest_3.nbt,5,CHEST:5,./NBT/StructureLoot/JunkChest_4.nbt,5,CHEST:5,./NBT/StructureLoot/JunkChest_5.nbt,5,CHEST:5,./NBT/Lorestoryline/LoreSpooky_5.nbt,2,CHEST:5,./NBT/Lorestoryline/LoreSpooky_4.nbt,2,CHEST:5,./NBT/Lorestoryline/LoreSpooky_3.nbt,2,CHEST:5,./NBT/Lorestoryline/LoreSpooky_2.nbt,2,CHEST:5,./NBT/Lorestoryline/LoreSpooky_1.nbt,2,CHEST:5,./NBT/StructureLoot/JunkChest_1.nbt,10,CHEST:5,./NBT/StructureLoot/JunkChest_2.nbt,5,CHEST:5,./NBT/StructureLoot/JunkChest_3.nbt,5,CHEST:5,./NBT/StructureLoot/JunkChest_4.nbt,5,CHEST:5,./NBT/StructureLoot/JunkChest_5.nbt,100)
B(7,4,2,QUARTZ_BLOCK:1)
B(-8,4,3,LOG)
B(-7,4,3,LOG:4)
B(-6,4,3,LOG)
RB(-5,4,3,CHEST:5,./NBT/StructureLoot/JunkChest_1.nbt,10,CHEST:5,./NBT/StructureLoot/JunkChest_2.nbt,5,CHEST:5,./NBT/StructureLoot/JunkChest_3.nbt,5,CHEST:5,./NBT/StructureLoot/JunkChest_4.nbt,5,CHEST:5,./NBT/StructureLoot/JunkChest_5.nbt,5,CHEST:5,./NBT/Lorestoryline/LoreSpooky_5.nbt,2,CHEST:5,./NBT/Lorestoryline/LoreSpooky_4.nbt,2,CHEST:5,./NBT/Lorestoryline/LoreSpooky_3.nbt,2,CHEST:5,./NBT/Lorestoryline/LoreSpooky_2.nbt,2,CHEST:5,./NBT/Lorestoryline/LoreSpooky_1.nbt,2,CHEST:5,./NBT/StructureLoot/JunkChest_1.nbt,10,CHEST:5,./NBT/StructureLoot/JunkChest_2.nbt,5,CHEST:5,./NBT/StructureLoot/JunkChest_3.nbt,5,CHEST:5,./NBT/StructureLoot/JunkChest_4.nbt,5,CHEST:5,./NBT/StructureLoot/JunkChest_5.nbt,100)
B(-4,4,3,QUARTZ_BLOCK:1)
RB(-3,4,3,CHEST:5,./NBT/StructureLoot/JunkChest_1.nbt,10,CHEST:5,./NBT/StructureLoot/JunkChest_2.nbt,5,CHEST:5,./NBT/StructureLoot/JunkChest_3.nbt,5,CHEST:5,./NBT/StructureLoot/JunkChest_4.nbt,5,CHEST:5,./NBT/StructureLoot/JunkChest_5.nbt,5,CHEST:5,./NBT/Lorestoryline/LoreSpooky_5.nbt,2,CHEST:5,./NBT/Lorestoryline/LoreSpooky_4.nbt,2,CHEST:5,./NBT/Lorestoryline/LoreSpooky_3.nbt,2,CHEST:5,./NBT/Lorestoryline/LoreSpooky_2.nbt,2,CHEST:5,./NBT/Lorestoryline/LoreSpooky_1.nbt,2,CHEST:5,./NBT/StructureLoot/JunkChest_1.nbt,10,CHEST:5,./NBT/StructureLoot/JunkChest_2.nbt,5,CHEST:5,./NBT/StructureLoot/JunkChest_3.nbt,5,CHEST:5,./NBT/StructureLoot/JunkChest_4.nbt,5,CHEST:5,./NBT/StructureLoot/JunkChest_5.nbt,100)
RB(-2,4,3,CHEST:2,./NBT/StructureLoot/JunkChest_1.nbt,10,CHEST:2,./NBT/StructureLoot/JunkChest_2.nbt,5,CHEST:2,./NBT/StructureLoot/JunkChest_3.nbt,5,CHEST:2,./NBT/StructureLoot/JunkChest_4.nbt,5,CHEST:2,./NBT/StructureLoot/JunkChest_5.nbt,5,CHEST:2,./NBT/Lorestoryline/LoreSpooky_5.nbt,2,CHEST:2,./NBT/Lorestoryline/LoreSpooky_4.nbt,2,CHEST:2,./NBT/Lorestoryline/LoreSpooky_3.nbt,2,CHEST:2,./NBT/Lorestoryline/LoreSpooky_2.nbt,2,CHEST:2,./NBT/Lorestoryline/LoreSpooky_1.nbt,2,CHEST:2,./NBT/StructureLoot/JunkChest_1.nbt,10,CHEST:2,./NBT/StructureLoot/JunkChest_2.nbt,5,CHEST:2,./NBT/StructureLoot/JunkChest_3.nbt,5,CHEST:2,./NBT/StructureLoot/JunkChest_4.nbt,5,CHEST:2,./NBT/StructureLoot/JunkChest_5.nbt,100)
B(-1,4,3,QUARTZ_BLOCK:1)
RB(0,4,3,CHEST:2,./NBT/StructureLoot/JunkChest_1.nbt,10,CHEST:2,./NBT/StructureLoot/JunkChest_2.nbt,5,CHEST:2,./NBT/StructureLoot/JunkChest_3.nbt,5,CHEST:2,./NBT/StructureLoot/JunkChest_4.nbt,5,CHEST:2,./NBT/StructureLoot/JunkChest_5.nbt,5,CHEST:2,./NBT/Lorestoryline/LoreSpooky_5.nbt,2,CHEST:2,./NBT/Lorestoryline/LoreSpooky_4.nbt,2,CHEST:2,./NBT/Lorestoryline/LoreSpooky_3.nbt,2,CHEST:2,./NBT/Lorestoryline/LoreSpooky_2.nbt,2,CHEST:2,./NBT/Lorestoryline/LoreSpooky_1.nbt,2,CHEST:2,./NBT/StructureLoot/JunkChest_1.nbt,10,CHEST:2,./NBT/StructureLoot/JunkChest_2.nbt,5,CHEST:2,./NBT/StructureLoot/JunkChest_3.nbt,5,CHEST:2,./NBT/StructureLoot/JunkChest_4.nbt,5,CHEST:2,./NBT/StructureLoot/JunkChest_5.nbt,100)
RB(1,4,3,CHEST:4,./NBT/StructureLoot/JunkChest_1.nbt,10,CHEST:4,./NBT/StructureLoot/JunkChest_2.nbt,5,CHEST:4,./NBT/StructureLoot/JunkChest_3.nbt,5,CHEST:4,./NBT/StructureLoot/JunkChest_4.nbt,5,CHEST:4,./NBT/StructureLoot/JunkChest_5.nbt,5,CHEST:4,./NBT/Lorestoryline/LoreSpooky_5.nbt,2,CHEST:4,./NBT/Lorestoryline/LoreSpooky_4.nbt,2,CHEST:4,./NBT/Lorestoryline/LoreSpooky_3.nbt,2,CHEST:4,./NBT/Lorestoryline/LoreSpooky_2.nbt,2,CHEST:4,./NBT/Lorestoryline/LoreSpooky_1.nbt,2,CHEST:4,./NBT/StructureLoot/JunkChest_1.nbt,10,CHEST:4,./NBT/StructureLoot/JunkChest_2.nbt,5,CHEST:4,./NBT/StructureLoot/JunkChest_3.nbt,5,CHEST:4,./NBT/StructureLoot/JunkChest_4.nbt,5,CHEST:4,./NBT/StructureLoot/JunkChest_5.nbt,100)
B(2,4,3,QUARTZ_BLOCK:1)
RB(3,4,3,CHEST:5,./NBT/StructureLoot/JunkChest_1.nbt,10,CHEST:5,./NBT/StructureLoot/JunkChest_2.nbt,5,CHEST:5,./NBT/StructureLoot/JunkChest_3.nbt,5,CHEST:5,./NBT/StructureLoot/JunkChest_4.nbt,5,CHEST:5,./NBT/StructureLoot/JunkChest_5.nbt,5,CHEST:5,./NBT/Lorestoryline/LoreSpooky_5.nbt,2,CHEST:5,./NBT/Lorestoryline/LoreSpooky_4.nbt,2,CHEST:5,./NBT/Lorestoryline/LoreSpooky_3.nbt,2,CHEST:5,./NBT/Lorestoryline/LoreSpooky_2.nbt,2,CHEST:5,./NBT/Lorestoryline/LoreSpooky_1.nbt,2,CHEST:5,./NBT/StructureLoot/JunkChest_1.nbt,10,CHEST:5,./NBT/StructureLoot/JunkChest_2.nbt,5,CHEST:5,./NBT/StructureLoot/JunkChest_3.nbt,5,CHEST:5,./NBT/StructureLoot/JunkChest_4.nbt,5,CHEST:5,./NBT/StructureLoot/JunkChest_5.nbt,100)
RB(4,4,3,CHEST:2,./NBT/StructureLoot/JunkChest_1.nbt,10,CHEST:2,./NBT/StructureLoot/JunkChest_2.nbt,5,CHEST:2,./NBT/StructureLoot/JunkChest_3.nbt,5,CHEST:2,./NBT/StructureLoot/JunkChest_4.nbt,5,CHEST:2,./NBT/StructureLoot/JunkChest_5.nbt,5,CHEST:2,./NBT/Lorestoryline/LoreSpooky_5.nbt,2,CHEST:2,./NBT/Lorestoryline/LoreSpooky_4.nbt,2,CHEST:2,./NBT/Lorestoryline/LoreSpooky_3.nbt,2,CHEST:2,./NBT/Lorestoryline/LoreSpooky_2.nbt,2,CHEST:2,./NBT/Lorestoryline/LoreSpooky_1.nbt,2,CHEST:2,./NBT/StructureLoot/JunkChest_1.nbt,10,CHEST:2,./NBT/StructureLoot/JunkChest_2.nbt,5,CHEST:2,./NBT/StructureLoot/JunkChest_3.nbt,5,CHEST:2,./NBT/StructureLoot/JunkChest_4.nbt,5,CHEST:2,./NBT/StructureLoot/JunkChest_5.nbt,100)
B(5,4,3,IRON_BARS)
RB(6,4,3,SKULL:1,./NBT/Skulls/dungeon_skull_01.nbt,6,AIR,9,SKULL:1,./NBT/Skulls/dungeon_skull_02.nbt,12,AIR,15,SKULL:1,./NBT/Skulls/dungeon_skull_03.nbt,18,AIR,21,SKULL:1,./NBT/Skulls/dungeon_skull_04.nbt,24,AIR,27,SKULL:1,./NBT/Skulls/dungeon_skull_05.nbt,30,AIR,33,SKULL:1,./NBT/Skulls/dungeon_skull_06.nbt,36,AIR,39,SKULL:1,./NBT/Skulls/dungeon_skull_07.nbt,42,AIR,45,SKULL:1,./NBT/Skulls/dungeon_skull_08.nbt,48,AIR,51,SKULL:1,./NBT/Skulls/dungeon_skull_09.nbt,54,AIR,57,SKULL:1,./NBT/Skulls/dungeon_skull_10.nbt,60,AIR,63,SKULL:1,./NBT/Skulls/dungeon_skull_11.nbt,66,AIR,69,SKULL:1,./NBT/Skulls/dungeon_skull_12.nbt,72,AIR,75,SKULL:1,./NBT/Skulls/dungeon_skull_13.nbt,78,AIR,81,SKULL:1,./NBT/Skulls/dungeon_skull_14.nbt,84,AIR,87,SKULL:1,./NBT/Skulls/dungeon_skull_15.nbt,90,AIR,93,SKULL:1,./NBT/Skulls/dungeon_skull_16.nbt,96,AIR,100)
B(7,4,3,QUARTZ_BLOCK:1)
B(-8,4,4,STONE:6)
B(-7,4,4,WOODEN_SLAB:13)
B(-6,4,4,WOODEN_SLAB:13)
B(-5,4,4,LOG)
B(-4,4,4,STONE:6)
B(-3,4,4,STONE:6)
B(-2,4,4,LOG)
B(-1,4,4,STONE:6)
B(0,4,4,STONE:6)
B(1,4,4,LOG)
B(2,4,4,STONE:6)
B(3,4,4,STONE:6)
B(4,4,4,LOG)
B(5,4,4,STONE:6)
B(6,4,4,STONE:6)
B(7,4,4,LOG)
B(-8,4,5,STONE:6)
B(-7,4,5,WOODEN_SLAB:13)
B(-6,4,5,WOODEN_SLAB:13)
B(-5,4,5,LOG:8)
B(-4,4,5,WOODEN_SLAB:13)
B(-3,4,5,WOODEN_SLAB:13)
B(-2,4,5,LOG:8)
B(-1,4,5,WOODEN_SLAB:13)
B(0,4,5,WOODEN_SLAB:13)
B(1,4,5,LOG:8)
B(2,4,5,WOODEN_SLAB:13)
B(3,4,5,WOODEN_SLAB:13)
B(4,4,5,LOG:8)
B(5,4,5,WOODEN_SLAB:13)
B(6,4,5,WOODEN_SLAB:13)
B(7,4,5,LOG:8)
B(-8,4,6,LOG)
B(-7,4,6,STONE:6)
B(-6,4,6,STONE:6)
B(-5,4,6,LOG)
B(-4,4,6,STONE:6)
B(-3,4,6,STONE:6)
B(-2,4,6,LOG)
B(-1,4,6,STONE:6)
B(0,4,6,STONE:6)
B(1,4,6,LOG)
B(2,4,6,STONE:6)
B(3,4,6,STONE:6)
B(4,4,6,LOG)
B(5,4,6,STONE:6)
B(6,4,6,STONE:6)
B(7,4,6,LOG)
B(-8,5,-8,STONE:6)
B(-7,5,-8,AIR)
B(-6,5,-8,STONE:6)
B(-5,5,-8,STONE_SLAB:8)
B(-4,5,-8,STONE_BRICK_STAIRS:6)
B(-3,5,-8,AIR)
B(-2,5,-8,AIR)
B(-1,5,-8,STONE_SLAB:7)
B(0,5,-8,STONE_SLAB:7)
B(1,5,-8,STONE_SLAB:7)
B(2,5,-8,AIR)
B(3,5,-8,AIR)
B(4,5,-8,AIR)
B(5,5,-8,STONE_BRICK_STAIRS:6)
B(6,5,-8,STONE_SLAB:8)
B(7,5,-8,STONE_SLAB:8)
B(-8,5,-7,STONE:6)
B(-7,5,-7,AIR)
B(-6,5,-7,STONE:6)
B(-5,5,-7,STONE_SLAB:8)
B(-4,5,-7,STONEBRICK:3)
B(-3,5,-7,QUARTZ_STAIRS:6)
B(-2,5,-7,STONEBRICK:3)
B(-1,5,-7,AIR)
B(0,5,-7,AIR)
B(1,5,-7,AIR)
B(2,5,-7,STONEBRICK:3)
B(3,5,-7,QUARTZ_STAIRS:6)
B(4,5,-7,AIR)
B(5,5,-7,STONEBRICK:3)
B(6,5,-7,STONE_BRICK_STAIRS:5)
B(7,5,-7,STONE_SLAB:8)
B(-8,5,-6,LOG)
B(-7,5,-6,AIR)
B(-6,5,-6,LOG)
B(-5,5,-6,STONE_SLAB:8)
B(-4,5,-6,STONE_SLAB:8)
B(-3,5,-6,QUARTZ_STAIRS:3)
B(-2,5,-6,QUARTZ_STAIRS:3)
B(-1,5,-6,QUARTZ_STAIRS:3)
B(0,5,-6,QUARTZ_STAIRS:3)
B(1,5,-6,QUARTZ_STAIRS:3)
B(2,5,-6,QUARTZ_STAIRS:3)
B(3,5,-6,QUARTZ_STAIRS:3)
B(4,5,-6,AIR)
B(5,5,-6,DOUBLE_STONE_SLAB)
B(6,5,-6,STONE_SLAB:8)
B(7,5,-6,STONE_SLAB:8)
B(-8,5,-5,STONE:6)
B(-7,5,-5,AIR)
B(-6,5,-5,STONE:6)
B(-5,5,-5,STONE_SLAB:8)
B(-4,5,-5,STONEBRICK:3)
B(-3,5,-5,STONE_BRICK_STAIRS:5)
B(-2,5,-5,STONE_BRICK_STAIRS:4)
B(-1,5,-5,STONEBRICK:3)
B(0,5,-5,STONE_BRICK_STAIRS:5)
B(1,5,-5,STONE_BRICK_STAIRS:4)
B(2,5,-5,STONEBRICK:3)
B(3,5,-5,STONE_BRICK_STAIRS:5)
B(4,5,-5,STONE_BRICK_STAIRS:4)
B(5,5,-5,STONEBRICK:3)
B(6,5,-5,STONE_BRICK_STAIRS:5)
B(7,5,-5,QUARTZ_BLOCK:1)
B(-8,5,-4,STONE:6)
B(-7,5,-4,AIR)
B(-6,5,-4,STONE:6)
B(-5,5,-4,STONE_SLAB:8)
B(-4,5,-4,STONE_SLAB:8)
B(-3,5,-4,STONE_SLAB:8)
B(-2,5,-4,STONE_SLAB:8)
B(-1,5,-4,STONE_SLAB:8)
B(0,5,-4,STONE_SLAB:8)
B(1,5,-4,STONE_SLAB:8)
B(2,5,-4,STONE_SLAB:8)
B(3,5,-4,STONE_SLAB:8)
B(4,5,-4,STONE_SLAB:8)
B(5,5,-4,STONEBRICK)
B(6,5,-4,STONE_SLAB:8)
B(7,5,-4,STONE_SLAB:8)
B(-8,5,-3,LOG)
B(-7,5,-3,AIR)
B(-6,5,-3,LOG)
B(-5,5,-3,DOUBLE_STONE_SLAB)
B(-4,5,-3,STONEBRICK:3)
B(-3,5,-3,STONE_BRICK_STAIRS:5)
B(-2,5,-3,STONE_BRICK_STAIRS:4)
B(-1,5,-3,STONEBRICK:3)
B(0,5,-3,STONE_BRICK_STAIRS:5)
B(1,5,-3,STONE_BRICK_STAIRS:4)
B(2,5,-3,STONEBRICK:3)
B(3,5,-3,STONE_BRICK_STAIRS:5)
B(4,5,-3,STONE_BRICK_STAIRS:4)
B(5,5,-3,STONEBRICK)
B(6,5,-3,STONE_SLAB:8)
B(7,5,-3,STONE_SLAB:8)
B(-8,5,-2,STONE:6)
B(-7,5,-2,AIR)
B(-6,5,-2,STONE:6)
B(-5,5,-2,STONE_SLAB:8)
B(-4,5,-2,STONE_BRICK_STAIRS:7)
B(-3,5,-2,STONE_SLAB:8)
B(-2,5,-2,STONE_SLAB:8)
B(-1,5,-2,STONE_BRICK_STAIRS:7)
B(0,5,-2,STONE_SLAB:8)
B(1,5,-2,STONE_SLAB:8)
B(2,5,-2,STONE_BRICK_STAIRS:7)
B(3,5,-2,STONE_SLAB:8)
B(4,5,-2,STONE_SLAB:8)
B(5,5,-2,STONEBRICK:3)
B(6,5,-2,STONE_BRICK_STAIRS:5)
B(7,5,-2,QUARTZ_BLOCK:1)
B(-8,5,-1,STONE:6)
B(-7,5,-1,AIR)
B(-6,5,-1,STONE:6)
B(-5,5,-1,STONE_SLAB:8)
B(-4,5,-1,QUARTZ_BLOCK:1)
B(-3,5,-1,STONE_SLAB:8)
B(-2,5,-1,STONE_SLAB:8)
B(-1,5,-1,STONE_SLAB:8)
B(0,5,-1,STONE_SLAB:8)
B(1,5,-1,STONE_SLAB:8)
B(2,5,-1,STONE_SLAB:8)
B(3,5,-1,STONE_SLAB:8)
B(4,5,-1,STONE_SLAB:8)
B(5,5,-1,STONE_BRICK_STAIRS:7)
B(6,5,-1,STONE_SLAB:8)
B(7,5,-1,STONE_SLAB:8)
B(-8,5,0,LOG)
B(-7,5,0,AIR)
B(-6,5,0,LOG)
B(-5,5,0,STONE_SLAB:8)
B(-4,5,0,STONE_BRICK_STAIRS:6)
B(-3,5,0,STONE_SLAB:8)
B(-2,5,0,STONE_SLAB:8)
B(-1,5,0,STONE_BRICK_STAIRS:6)
B(0,5,0,STONE_SLAB:8)
B(1,5,0,STONE_SLAB:8)
B(2,5,0,STONE_BRICK_STAIRS:6)
B(3,5,0,STONE_SLAB:8)
B(4,5,0,STONE_SLAB:8)
B(5,5,0,STONE_BRICK_STAIRS:6)
B(6,5,0,STONE_SLAB:8)
B(7,5,0,STONE_SLAB:8)
B(-8,5,1,STONE:6)
B(-7,5,1,AIR)
B(-6,5,1,STONE:6)
B(-5,5,1,STONE_SLAB:8)
B(-4,5,1,STONEBRICK:3)
B(-3,5,1,STONE_BRICK_STAIRS:5)
B(-2,5,1,STONE_BRICK_STAIRS:4)
B(-1,5,1,STONEBRICK:3)
B(0,5,1,STONE_BRICK_STAIRS:5)
B(1,5,1,STONE_BRICK_STAIRS:4)
B(2,5,1,STONEBRICK:3)
B(3,5,1,STONE_BRICK_STAIRS:5)
B(4,5,1,STONE_BRICK_STAIRS:4)
B(5,5,1,STONEBRICK:3)
B(6,5,1,STONE_BRICK_STAIRS:5)
B(7,5,1,QUARTZ_BLOCK:1)
B(-8,5,2,STONE:6)
B(-7,5,2,AIR)
B(-6,5,2,STONE:6)
B(-5,5,2,STONE_SLAB:8)
B(-4,5,2,STONE_BRICK_STAIRS:7)
B(-3,5,2,STONE_SLAB:8)
B(-2,5,2,STONE_SLAB:8)
B(-1,5,2,STONE_BRICK_STAIRS:7)
B(0,5,2,STONE_SLAB:8)
B(1,5,2,STONE_SLAB:8)
B(2,5,2,STONE_BRICK_STAIRS:7)
B(3,5,2,STONE_SLAB:8)
B(4,5,2,STONE_SLAB:8)
B(5,5,2,STONEBRICK)
B(6,5,2,STONE_SLAB:8)
B(7,5,2,STONE_SLAB:8)
B(-8,5,3,LOG)
B(-7,5,3,AIR)
B(-6,5,3,LOG)
B(-5,5,3,STONE_SLAB:8)
B(-4,5,3,STONE_BRICK_STAIRS:6)
B(-3,5,3,STONE_SLAB:8)
B(-2,5,3,STONE_SLAB:8)
B(-1,5,3,STONE_BRICK_STAIRS:6)
B(0,5,3,STONE_SLAB:8)
B(1,5,3,STONE_SLAB:8)
B(2,5,3,STONE_BRICK_STAIRS:6)
B(3,5,3,STONE_SLAB:8)
B(4,5,3,STONE_SLAB:8)
B(5,5,3,STONEBRICK)
B(6,5,3,STONE_SLAB:8)
B(7,5,3,STONE_SLAB:8)
B(-8,5,4,STONE:6)
B(-7,5,4,AIR)
B(-6,5,4,AIR)
B(-5,5,4,LOG)
B(-4,5,4,STONE:6)
B(-3,5,4,STONE:6)
B(-2,5,4,LOG)
B(-1,5,4,STONE:6)
B(0,5,4,STONE:6)
B(1,5,4,LOG)
B(2,5,4,STONE:6)
B(3,5,4,STONE:6)
B(4,5,4,LOG)
B(5,5,4,STONE:6)
B(6,5,4,STONE:6)
B(7,5,4,LOG)
B(-8,5,5,STONE:6)
B(-7,5,5,AIR)
B(-6,5,5,AIR)
B(-5,5,5,AIR)
B(-4,5,5,AIR)
B(-3,5,5,AIR)
B(-2,5,5,AIR)
B(-1,5,5,AIR)
B(0,5,5,AIR)
B(1,5,5,AIR)
B(2,5,5,AIR)
B(3,5,5,AIR)
B(4,5,5,AIR)
B(5,5,5,AIR)
B(6,5,5,AIR)
B(7,5,5,AIR)
B(-8,5,6,LOG)
B(-7,5,6,STONE:6)
B(-6,5,6,STONE:6)
B(-5,5,6,LOG)
B(-4,5,6,STONE:6)
B(-3,5,6,STONE:6)
B(-2,5,6,LOG)
B(-1,5,6,STONE:6)
B(0,5,6,STONE:6)
B(1,5,6,LOG)
B(2,5,6,STONE:6)
B(3,5,6,STONE:6)
B(4,5,6,LOG)
B(5,5,6,STONE:6)
B(6,5,6,STONE:6)
B(7,5,6,LOG)
B(-8,6,-8,FENCE)
B(-7,6,-8,AIR)
B(-6,6,-8,STONE:6)
B(-5,6,-8,AIR)
B(-4,6,-8,IRON_BARS)
B(-3,6,-8,QUARTZ_STAIRS:6)
B(-2,6,-8,STONE_BRICK_STAIRS:6)
B(-1,6,-8,QUARTZ_STAIRS:6)
B(0,6,-8,QUARTZ_STAIRS:6)
B(1,6,-8,QUARTZ_STAIRS:6)
B(2,6,-8,STONE_BRICK_STAIRS:6)
B(3,6,-8,QUARTZ_STAIRS:6)
B(4,6,-8,AIR)
B(5,6,-8,IRON_BARS)
B(6,6,-8,AIR)
B(7,6,-8,AIR)
B(-8,6,-7,FENCE)
B(-7,6,-7,AIR)
B(-6,6,-7,STONE:6)
B(-5,6,-7,AIR)
B(-4,6,-7,STONEBRICK:3)
B(-3,6,-7,QUARTZ_STAIRS:3)
B(-2,6,-7,QUARTZ_STAIRS:3)
B(-1,6,-7,QUARTZ_STAIRS:3)
B(0,6,-7,QUARTZ_STAIRS:3)
B(1,6,-7,QUARTZ_STAIRS:3)
B(2,6,-7,QUARTZ_STAIRS:3)
B(3,6,-7,QUARTZ_STAIRS:3)
B(4,6,-7,AIR)
B(5,6,-7,STONEBRICK:3)
B(6,6,-7,AIR)
B(7,6,-7,AIR)
B(-8,6,-6,LOG)
B(-7,6,-6,AIR)
B(-6,6,-6,LOG)
B(-5,6,-6,AIR)
B(-4,6,-6,IRON_BARS)
B(-3,6,-6,AIR)
B(-2,6,-6,AIR)
B(-1,6,-6,AIR)
B(0,6,-6,AIR)
B(1,6,-6,AIR)
B(2,6,-6,AIR)
B(3,6,-6,AIR)
B(4,6,-6,AIR)
B(5,6,-6,IRON_BARS)
RB(6,6,-6,SKULL:1,./NBT/Skulls/dungeon_skull_01.nbt,6,AIR,9,SKULL:1,./NBT/Skulls/dungeon_skull_02.nbt,12,AIR,15,SKULL:1,./NBT/Skulls/dungeon_skull_03.nbt,18,AIR,21,SKULL:1,./NBT/Skulls/dungeon_skull_04.nbt,24,AIR,27,SKULL:1,./NBT/Skulls/dungeon_skull_05.nbt,30,AIR,33,SKULL:1,./NBT/Skulls/dungeon_skull_06.nbt,36,AIR,39,SKULL:1,./NBT/Skulls/dungeon_skull_07.nbt,42,AIR,45,SKULL:1,./NBT/Skulls/dungeon_skull_08.nbt,48,AIR,51,SKULL:1,./NBT/Skulls/dungeon_skull_09.nbt,54,AIR,57,SKULL:1,./NBT/Skulls/dungeon_skull_10.nbt,60,AIR,63,SKULL:1,./NBT/Skulls/dungeon_skull_11.nbt,66,AIR,69,SKULL:1,./NBT/Skulls/dungeon_skull_12.nbt,72,AIR,75,SKULL:1,./NBT/Skulls/dungeon_skull_13.nbt,78,AIR,81,SKULL:1,./NBT/Skulls/dungeon_skull_14.nbt,84,AIR,87,SKULL:1,./NBT/Skulls/dungeon_skull_15.nbt,90,AIR,93,SKULL:1,./NBT/Skulls/dungeon_skull_16.nbt,96,AIR,100)
B(7,6,-6,AIR)
B(-8,6,-5,FENCE)
B(-7,6,-5,AIR)
B(-6,6,-5,STONE:6)
B(-5,6,-5,AIR)
B(-4,6,-5,STONEBRICK:3)
B(-3,6,-5,IRON_BARS)
B(-2,6,-5,IRON_BARS)
B(-1,6,-5,STONEBRICK:3)
B(0,6,-5,IRON_BARS)
B(1,6,-5,IRON_BARS)
B(2,6,-5,STONEBRICK:3)
B(3,6,-5,IRON_BARS)
B(4,6,-5,IRON_BARS)
B(5,6,-5,STONEBRICK:3)
RB(6,6,-5,SKULL:1,./NBT/Skulls/dungeon_skull_01.nbt,6,AIR,9,SKULL:1,./NBT/Skulls/dungeon_skull_02.nbt,12,AIR,15,SKULL:1,./NBT/Skulls/dungeon_skull_03.nbt,18,AIR,21,SKULL:1,./NBT/Skulls/dungeon_skull_04.nbt,24,AIR,27,SKULL:1,./NBT/Skulls/dungeon_skull_05.nbt,30,AIR,33,SKULL:1,./NBT/Skulls/dungeon_skull_06.nbt,36,AIR,39,SKULL:1,./NBT/Skulls/dungeon_skull_07.nbt,42,AIR,45,SKULL:1,./NBT/Skulls/dungeon_skull_08.nbt,48,AIR,51,SKULL:1,./NBT/Skulls/dungeon_skull_09.nbt,54,AIR,57,SKULL:1,./NBT/Skulls/dungeon_skull_10.nbt,60,AIR,63,SKULL:1,./NBT/Skulls/dungeon_skull_11.nbt,66,AIR,69,SKULL:1,./NBT/Skulls/dungeon_skull_12.nbt,72,AIR,75,SKULL:1,./NBT/Skulls/dungeon_skull_13.nbt,78,AIR,81,SKULL:1,./NBT/Skulls/dungeon_skull_14.nbt,84,AIR,87,SKULL:1,./NBT/Skulls/dungeon_skull_15.nbt,90,AIR,93,SKULL:1,./NBT/Skulls/dungeon_skull_16.nbt,96,AIR,100)
B(7,6,-5,AIR)
B(-8,6,-4,FENCE)
B(-7,6,-4,AIR)
B(-6,6,-4,STONE:6)
B(-5,6,-4,AIR)
B(-4,6,-4,AIR)
B(-3,6,-4,AIR)
B(-2,6,-4,AIR)
B(-1,6,-4,IRON_BARS)
B(0,6,-4,QUARTZ_BLOCK:1)
B(1,6,-4,QUARTZ_BLOCK:1)
B(2,6,-4,IRON_BARS)
RB(3,6,-4,SKULL:1,./NBT/Skulls/dungeon_skull_01.nbt,6,AIR,9,SKULL:1,./NBT/Skulls/dungeon_skull_02.nbt,12,AIR,15,SKULL:1,./NBT/Skulls/dungeon_skull_03.nbt,18,AIR,21,SKULL:1,./NBT/Skulls/dungeon_skull_04.nbt,24,AIR,27,SKULL:1,./NBT/Skulls/dungeon_skull_05.nbt,30,AIR,33,SKULL:1,./NBT/Skulls/dungeon_skull_06.nbt,36,AIR,39,SKULL:1,./NBT/Skulls/dungeon_skull_07.nbt,42,AIR,45,SKULL:1,./NBT/Skulls/dungeon_skull_08.nbt,48,AIR,51,SKULL:1,./NBT/Skulls/dungeon_skull_09.nbt,54,AIR,57,SKULL:1,./NBT/Skulls/dungeon_skull_10.nbt,60,AIR,63,SKULL:1,./NBT/Skulls/dungeon_skull_11.nbt,66,AIR,69,SKULL:1,./NBT/Skulls/dungeon_skull_12.nbt,72,AIR,75,SKULL:1,./NBT/Skulls/dungeon_skull_13.nbt,78,AIR,81,SKULL:1,./NBT/Skulls/dungeon_skull_14.nbt,84,AIR,87,SKULL:1,./NBT/Skulls/dungeon_skull_15.nbt,90,AIR,93,SKULL:1,./NBT/Skulls/dungeon_skull_16.nbt,96,AIR,100)
B(4,6,-4,AIR)
RB(5,6,-4,SKULL:1,./NBT/Skulls/dungeon_skull_01.nbt,6,AIR,9,SKULL:1,./NBT/Skulls/dungeon_skull_02.nbt,12,AIR,15,SKULL:1,./NBT/Skulls/dungeon_skull_03.nbt,18,AIR,21,SKULL:1,./NBT/Skulls/dungeon_skull_04.nbt,24,AIR,27,SKULL:1,./NBT/Skulls/dungeon_skull_05.nbt,30,AIR,33,SKULL:1,./NBT/Skulls/dungeon_skull_06.nbt,36,AIR,39,SKULL:1,./NBT/Skulls/dungeon_skull_07.nbt,42,AIR,45,SKULL:1,./NBT/Skulls/dungeon_skull_08.nbt,48,AIR,51,SKULL:1,./NBT/Skulls/dungeon_skull_09.nbt,54,AIR,57,SKULL:1,./NBT/Skulls/dungeon_skull_10.nbt,60,AIR,63,SKULL:1,./NBT/Skulls/dungeon_skull_11.nbt,66,AIR,69,SKULL:1,./NBT/Skulls/dungeon_skull_12.nbt,72,AIR,75,SKULL:1,./NBT/Skulls/dungeon_skull_13.nbt,78,AIR,81,SKULL:1,./NBT/Skulls/dungeon_skull_14.nbt,84,AIR,87,SKULL:1,./NBT/Skulls/dungeon_skull_15.nbt,90,AIR,93,SKULL:1,./NBT/Skulls/dungeon_skull_16.nbt,96,AIR,100)
B(6,6,-4,AIR)
B(7,6,-4,AIR)
B(-8,6,-3,LOG)
B(-7,6,-3,AIR)
B(-6,6,-3,LOG)
B(-5,6,-3,BOOKSHELF)
B(-4,6,-3,STONEBRICK:3)
B(-3,6,-3,AIR)
B(-2,6,-3,AIR)
B(-1,6,-3,STONEBRICK:3)
B(0,6,-3,QUARTZ_STAIRS:7)
B(1,6,-3,QUARTZ_STAIRS:7)
B(2,6,-3,STONEBRICK:3)
B(3,6,-3,AIR)
B(4,6,-3,QUARTZ_STAIRS:4)
B(5,6,-3,QUARTZ_STAIRS:6)
B(6,6,-3,QUARTZ_STAIRS:5)
B(7,6,-3,AIR)
B(-8,6,-2,FENCE)
B(-7,6,-2,AIR)
B(-6,6,-2,STONE:6)
B(-5,6,-2,QUARTZ_STAIRS:5)
B(-4,6,-2,QUARTZ_STAIRS:7)
