#######################################################################
# +-----------------------------------------------------------------+ #
# |                            BO3 object                           | #
# +-----------------------------------------------------------------+ #
#######################################################################

# The descriptions in this file are accurate only for TerrainControl and OTG.
# For MCW and OTG+ these descriptions are only accurate if the BO3 is used as a CustomObject.
# MCW and OTG+ completely reimplemented CustomStructure, check the MCW/OTG+ documentation for more information.

# This is the config file of a custom object.
# If you add this object correctly to your BiomeConfigs, it will spawn in the world.

# This is the creator of this BO3 object
Author: Unknown

# A short description of this BO3 object
Description: This BO3 was converted from a schematic using OTGEdit. The author and description information of the schematic could not be found. If you know who the author of the schematic is then please add this information.

# The BO3 version, don't change this! It can be used by external applications to do a version check.
Version: 3

# The settings mode, WriteAll, WriteWithoutComments or WriteDisable. See WorldConfig.
SettingsMode: WriteDisable

#######################################################################
# +-----------------------------------------------------------------+ #
# |                          Main settings                          | #
# +-----------------------------------------------------------------+ #
#######################################################################

# This needs to be set to true to spawn the object in the Tree and Sapling resources.
Tree: false

# The frequency of the BO3 from 1 to 200. Tries this many times to spawn this BO3 when using the CustomObject(...) resource.
# Ignored by Tree(..), Sapling(..) and CustomStructure(..)
Frequency: 40

# The rarity of the BO3 from 0 to 100. Each spawn attempt has rarity% chance to succeed when using the CustomObject(...) resource.
# Ignored by Tree(..), Sapling(..) and CustomStructure(..)
Rarity: 100.0

# If you set this to true, the BO3 will be placed with a random rotation.
RotateRandomly: false

# The spawn height of the BO3 - randomY, highestBlock or highestSolidBlock.
SpawnHeight: highestBlock

# The height limits for the BO3.
MinHeight: 0

MaxHeight: 256

# Objects can have other objects attached to it: branches. Branches can also
# have branches attached to it, which can also have branches, etc. This is the
# maximum branch depth for this objects.
MaxBranchDepth: 10

# When spawned with the UseWorld keyword, this BO3 should NOT spawn in the following biomes.
# If you writer.write the BO3 name directly in the BiomeConfigs, this will be ignored.
ExcludedBiomes: All

# To optimise this BO3 for faster loading times you can use Notepad++ to find/replace comments and abbreviate things.
# Notepad++ find/replace with regex:
# Find: ^[#;].* replace to nothing removes all lines starting with # 
# Find: ^\s*$ replace to nothing removes most empty lines 
# Notepad++ find/replace without regex:
# *Warning: This will only work for OTG 1.10.2 v21 / OTG 1.11.2 v6 or higher. B( is not recognised by lower versions.
# Find: Block( replace to B(

#######################################################################
# +-----------------------------------------------------------------+ #
# |                      Source block settings                      | #
# +-----------------------------------------------------------------+ #
#######################################################################

# The block(s) the BO3 should spawn in.
SourceBlocks: AIR

# The maximum percentage of the BO3 that can be outside the SourceBlock.
# The BO3 won't be placed on a location with more blocks outside the SourceBlock than this percentage.
MaxPercentageOutsideSourceBlock: 100

# What to do when a block is about to be placed outside the SourceBlock? (dontPlace, placeAnyway)
OutsideSourceBlock: placeAnyway

#######################################################################
# +-----------------------------------------------------------------+ #
# |                              Blocks                             | #
# +-----------------------------------------------------------------+ #
#######################################################################

# All the blocks used in the BO3 are listed here. Possible blocks:
# Block(x,y,z,id[.data][,nbtfile.nbt) or B(x,y,z,id[.data][,nbtfile.nbt)
# RandomBlock(x,y,z,id[:data][,nbtfile.nbt],chance[,id[:data][,nbtfile.nbt],chance[,...]])
# So RandomBlock(0,0,0,CHEST,chest.nbt,50,CHEST,anotherchest.nbt,100) will spawn a chest at
# the BO3 origin, and give it a 50% chance to have the contents of chest.nbt, or, if that
# fails, a 100% percent chance to have the contents of anotherchest.nbt.

Block(-8,6,1,1)
Block(-8,7,0,1)
Block(-8,7,1,1)
Block(-8,7,2,1)
Block(-8,8,0,1)
Block(-8,8,1,1)
Block(-8,8,2,1)
Block(-8,9,0,1)
Block(-8,9,1,1)
Block(-8,9,2,1)
Block(-8,10,-1,1)
Block(-8,10,0,1)
Block(-8,10,1,1)
Block(-8,10,2,1)
Block(-8,10,3,1)
Block(-8,11,-1,1)
Block(-8,11,0,1)
Block(-8,11,1,1)
Block(-8,11,2,1)
Block(-8,11,3,1)
Block(-8,12,0,1)
Block(-8,12,1,1)
Block(-8,12,2,1)
Block(-8,31,2,1)
Block(-8,32,1,1)
Block(-8,32,2,1)
Block(-8,32,3,1)
Block(-8,33,1,1)
Block(-8,33,2,1)
Block(-8,33,3,1)
Block(-8,33,4,1)
Block(-8,34,1,1)
Block(-8,34,2,1)
Block(-8,34,3,1)
Block(-8,34,4,1)
Block(-8,35,2,1)
Block(-8,35,3,1)
Block(-8,48,0,1)
Block(-8,48,1,1)
Block(-8,49,-1,1)
Block(-8,49,0,1)
Block(-8,49,1,1)
Block(-8,49,2,1)
Block(-8,50,-1,1)
Block(-8,50,0,1)
Block(-8,50,1,1)
Block(-8,50,2,1)
Block(-8,50,3,1)
Block(-8,51,-1,1)
Block(-8,51,0,1)
Block(-8,51,1,1)
Block(-8,51,2,1)
Block(-8,51,3,1)
Block(-8,52,0,1)
Block(-8,52,1,1)
Block(-8,52,2,1)
Block(-8,58,1,1)
Block(-8,58,2,1)
Block(-8,58,3,1)
Block(-8,58,4,1)
Block(-8,59,0,1)
Block(-8,59,1,1)
Block(-8,59,2,1)
Block(-8,59,3,1)
Block(-8,59,4,1)
Block(-8,59,5,1)
Block(-8,60,-1,1)
Block(-8,60,0,1)
Block(-8,60,1,1)
Block(-8,60,2,1)
Block(-8,60,3,1)
Block(-8,60,4,1)
Block(-8,60,5,1)
Block(-8,60,6,1)
Block(-8,61,-1,1)
Block(-8,61,0,1)
Block(-8,61,1,1)
Block(-8,61,2,1)
Block(-8,61,3,1)
Block(-8,61,4,1)
Block(-8,61,5,1)
Block(-8,61,6,1)
Block(-8,62,0,1)
Block(-8,62,1,1)
Block(-8,62,2,1)
Block(-8,62,3,1)
Block(-8,62,4,1)
Block(-8,62,5,1)
Block(-8,62,6,1)
Block(-8,63,2,1)
Block(-8,63,3,1)
Block(-8,63,4,1)
Block(-8,63,5,1)
Block(-7,0,2,1)
Block(-7,0,3,1)
Block(-7,0,4,1)
Block(-7,0,5,1)
Block(-7,1,2,1)
Block(-7,1,3,1)
Block(-7,1,4,1)
Block(-7,2,1,1)
Block(-7,2,2,1)
Block(-7,2,3,1)
Block(-7,2,4,1)
Block(-7,3,1,1)
Block(-7,3,2,1)
Block(-7,3,3,1)
Block(-7,4,1,1)
Block(-7,4,2,1)
Block(-7,4,3,1)
Block(-7,5,0,1)
Block(-7,5,1,1)
Block(-7,5,2,1)
Block(-7,5,3,1)
Block(-7,6,-1,1)
Block(-7,6,0,1)
Block(-7,6,1,1)
Block(-7,6,2,1)
Block(-7,6,3,1)
Block(-7,7,-1,1)
Block(-7,7,0,1)
Block(-7,7,1,1)
Block(-7,7,2,1)
Block(-7,7,3,1)
Block(-7,8,-1,1)
Block(-7,8,0,1)
Block(-7,8,1,1)
Block(-7,8,2,1)
Block(-7,8,3,1)
Block(-7,8,4,1)
Block(-7,9,-2,1)
Block(-7,9,-1,1)
Block(-7,9,0,1)
Block(-7,9,1,1)
Block(-7,9,2,1)
Block(-7,9,3,1)
Block(-7,9,4,1)
Block(-7,10,-2,1)
Block(-7,10,-1,1)
Block(-7,10,0,1)
Block(-7,10,1,1)
Block(-7,10,2,1)
Block(-7,10,3,1)
Block(-7,10,4,1)
Block(-7,11,-2,1)
Block(-7,11,-1,1)
Block(-7,11,0,1)
Block(-7,11,1,1)
Block(-7,11,2,1)
Block(-7,11,3,1)
Block(-7,11,4,1)
Block(-7,11,5,1)
Block(-7,12,-2,1)
Block(-7,12,-1,1)
Block(-7,12,0,1)
Block(-7,12,1,1)
Block(-7,12,2,1)
Block(-7,12,3,1)
Block(-7,12,4,1)
Block(-7,12,5,1)
Block(-7,13,-2,1)
Block(-7,13,-1,1)
Block(-7,13,0,1)
Block(-7,13,1,1)
Block(-7,13,2,1)
Block(-7,13,3,1)
Block(-7,13,4,1)
Block(-7,13,5,1)
Block(-7,14,0,1)
Block(-7,14,1,1)
Block(-7,14,2,1)
Block(-7,14,3,1)
Block(-7,14,4,1)
Block(-7,17,-1,1)
Block(-7,17,0,1)
Block(-7,17,1,1)
Block(-7,18,-2,1)
Block(-7,18,-1,1)
Block(-7,18,0,1)
Block(-7,18,1,1)
Block(-7,18,2,1)
Block(-7,19,-2,1)
Block(-7,19,-1,1)
Block(-7,19,0,1)
Block(-7,19,1,1)
Block(-7,19,2,1)
Block(-7,19,3,1)
Block(-7,20,0,1)
Block(-7,20,1,1)
Block(-7,20,2,1)
Block(-7,20,3,1)
Block(-7,21,1,1)
Block(-7,21,2,1)
Block(-7,21,3,1)
Block(-7,21,4,1)
Block(-7,22,1,1)
Block(-7,22,2,1)
Block(-7,22,3,1)
Block(-7,26,-1,1)
Block(-7,26,0,1)
Block(-7,27,-1,1)
Block(-7,27,0,1)
Block(-7,27,1,1)
Block(-7,28,-2,1)
Block(-7,28,-1,1)
Block(-7,28,0,1)
Block(-7,28,1,1)
Block(-7,29,-1,1)
Block(-7,29,0,1)
Block(-7,29,1,1)
Block(-7,29,2,1)
Block(-7,30,0,1)
Block(-7,30,1,1)
Block(-7,30,2,1)
Block(-7,30,3,1)
Block(-7,31,0,1)
Block(-7,31,1,1)
Block(-7,31,2,1)
Block(-7,31,3,1)
Block(-7,31,4,1)
Block(-7,32,0,1)
Block(-7,32,1,1)
Block(-7,32,2,1)
Block(-7,32,3,1)
Block(-7,32,4,1)
Block(-7,32,5,1)
Block(-7,33,0,1)
Block(-7,33,1,1)
Block(-7,33,2,1)
Block(-7,33,3,1)
Block(-7,33,4,1)
Block(-7,33,5,1)
Block(-7,33,6,1)
Block(-7,34,0,1)
Block(-7,34,1,1)
Block(-7,34,2,1)
Block(-7,34,3,1)
Block(-7,34,4,1)
Block(-7,34,5,1)
Block(-7,34,6,1)
Block(-7,35,-1,1)
Block(-7,35,0,1)
Block(-7,35,1,1)
Block(-7,35,2,1)
Block(-7,35,3,1)
Block(-7,35,4,1)
Block(-7,35,5,1)
Block(-7,35,6,1)
Block(-7,36,-1,1)
Block(-7,36,0,1)
Block(-7,36,1,1)
Block(-7,36,2,1)
Block(-7,36,3,1)
Block(-7,36,4,1)
Block(-7,36,5,1)
Block(-7,37,-2,1)
Block(-7,37,-1,1)
Block(-7,37,0,1)
Block(-7,37,1,1)
Block(-7,37,2,1)
Block(-7,37,3,1)
Block(-7,37,4,1)
Block(-7,38,-3,1)
Block(-7,38,-2,1)
Block(-7,38,-1,1)
Block(-7,38,0,1)
Block(-7,38,1,1)
Block(-7,38,2,1)
Block(-7,38,3,1)
Block(-7,38,4,1)
Block(-7,39,-3,1)
Block(-7,39,-2,1)
Block(-7,39,-1,1)
Block(-7,39,0,1)
Block(-7,39,1,1)
Block(-7,39,2,1)
Block(-7,39,3,1)
Block(-7,39,4,1)
Block(-7,40,-3,1)
Block(-7,40,-2,1)
Block(-7,40,-1,1)
Block(-7,40,0,1)
Block(-7,40,1,1)
Block(-7,40,2,1)
Block(-7,40,3,1)
Block(-7,40,4,1)
Block(-7,41,-2,1)
Block(-7,41,-1,1)
Block(-7,41,0,1)
Block(-7,41,1,1)
Block(-7,41,2,1)
Block(-7,41,3,1)
Block(-7,46,0,1)
Block(-7,46,1,1)
Block(-7,46,2,1)
Block(-7,47,-1,1)
Block(-7,47,0,1)
Block(-7,47,1,1)
Block(-7,47,2,1)
Block(-7,47,3,1)
Block(-7,48,-2,1)
Block(-7,48,-1,1)
Block(-7,48,0,1)
Block(-7,48,1,1)
Block(-7,48,2,1)
Block(-7,48,3,1)
Block(-7,49,-2,1)
Block(-7,49,-1,1)
Block(-7,49,0,1)
Block(-7,49,1,1)
Block(-7,49,2,1)
Block(-7,49,3,1)
Block(-7,49,4,1)
Block(-7,50,-3,1)
Block(-7,50,-2,1)
Block(-7,50,-1,1)
Block(-7,50,0,1)
Block(-7,50,1,1)
Block(-7,50,2,1)
Block(-7,50,3,1)
Block(-7,50,4,1)
Block(-7,51,-3,1)
Block(-7,51,-2,1)
Block(-7,51,-1,1)
Block(-7,51,0,1)
Block(-7,51,1,1)
Block(-7,51,2,1)
Block(-7,51,3,1)
Block(-7,51,4,1)
Block(-7,51,5,1)
Block(-7,52,-4,1)
Block(-7,52,-3,1)
Block(-7,52,-2,1)
Block(-7,52,-1,1)
Block(-7,52,0,1)
Block(-7,52,1,1)
Block(-7,52,2,1)
Block(-7,52,3,1)
Block(-7,52,4,1)
Block(-7,52,5,1)
Block(-7,52,6,1)
Block(-7,53,-3,1)
Block(-7,53,-2,1)
Block(-7,53,-1,1)
Block(-7,53,0,1)
Block(-7,53,1,1)
Block(-7,53,2,1)
Block(-7,53,3,1)
Block(-7,53,4,1)
Block(-7,53,5,1)
Block(-7,53,6,1)
Block(-7,54,-3,1)
Block(-7,54,-2,1)
Block(-7,54,-1,1)
Block(-7,54,0,1)
Block(-7,54,1,1)
Block(-7,54,2,1)
Block(-7,54,3,1)
Block(-7,54,4,1)
Block(-7,54,5,1)
Block(-7,54,6,1)
Block(-7,55,-2,1)
Block(-7,55,-1,1)
Block(-7,55,0,1)
Block(-7,55,1,1)
Block(-7,55,2,1)
Block(-7,55,3,1)
Block(-7,55,4,1)
Block(-7,55,5,1)
Block(-7,55,6,1)
Block(-7,56,-2,1)
Block(-7,56,-1,1)
Block(-7,56,0,1)
Block(-7,56,1,1)
Block(-7,56,2,1)
Block(-7,56,3,1)
Block(-7,56,4,1)
Block(-7,56,5,1)
Block(-7,56,6,1)
Block(-7,57,-2,1)
Block(-7,57,-1,1)
Block(-7,57,0,1)
Block(-7,57,1,1)
Block(-7,57,2,1)
Block(-7,57,3,1)
Block(-7,57,4,1)
Block(-7,57,5,1)
Block(-7,57,6,1)
Block(-7,58,-3,1)
Block(-7,58,-2,1)
Block(-7,58,-1,1)
Block(-7,58,0,1)
Block(-7,58,1,1)
Block(-7,58,2,1)
Block(-7,58,3,1)
Block(-7,58,4,1)
Block(-7,58,5,1)
Block(-7,58,6,1)
Block(-7,59,-4,1)
Block(-7,59,-3,1)
Block(-7,59,-2,1)
Block(-7,59,-1,1)
Block(-7,59,0,1)
Block(-7,59,1,1)
Block(-7,59,2,1)
Block(-7,59,3,1)
Block(-7,59,4,1)
Block(-7,59,5,1)
Block(-7,59,6,1)
Block(-7,59,7,1)
Block(-7,60,-4,1)
Block(-7,60,-3,1)
Block(-7,60,-2,1)
Block(-7,60,-1,1)
Block(-7,60,0,1)
Block(-7,60,1,1)
Block(-7,60,2,1)
Block(-7,60,3,1)
Block(-7,60,4,1)
Block(-7,60,5,1)
Block(-7,60,6,1)
Block(-7,60,7,1)
Block(-7,61,-4,1)
Block(-7,61,-3,1)
Block(-7,61,-2,1)
Block(-7,61,-1,1)
Block(-7,61,0,1)
Block(-7,61,1,1)
Block(-7,61,2,1)
Block(-7,61,3,1)
Block(-7,61,4,1)
Block(-7,61,5,1)
Block(-7,61,6,1)
Block(-7,61,7,1)
Block(-7,62,-3,1)
Block(-7,62,-2,1)
Block(-7,62,-1,1)
Block(-7,62,0,1)
Block(-7,62,1,1)
Block(-7,62,2,1)
Block(-7,62,3,1)
Block(-7,62,4,1)
Block(-7,62,5,1)
Block(-7,62,6,1)
Block(-7,62,7,1)
Block(-7,63,-1,1)
Block(-7,63,0,1)
Block(-7,63,1,1)
Block(-7,63,2,1)
Block(-7,63,3,1)
Block(-7,63,4,1)
Block(-7,63,5,1)
Block(-7,63,6,1)
Block(-7,63,7,1)
Block(-7,64,1,1)
Block(-7,64,2,1)
Block(-7,64,3,1)
Block(-7,64,4,1)
Block(-7,64,5,1)
Block(-7,64,6,1)
Block(-7,65,3,1)
Block(-7,65,4,1)
Block(-7,65,5,1)
Block(-7,66,4,1)
Block(-7,66,5,1)
Block(-6,0,-3,1)
Block(-6,0,-2,1)
Block(-6,0,-1,1)
Block(-6,0,0,1)
Block(-6,0,1,1)
Block(-6,0,2,1)
Block(-6,0,3,1)
Block(-6,0,4,1)
Block(-6,0,5,1)
Block(-6,0,6,1)
Block(-6,0,7,1)
Block(-6,1,-1,1)
Block(-6,1,0,1)
Block(-6,1,1,1)
Block(-6,1,2,1)
Block(-6,1,3,1)
Block(-6,1,4,1)
Block(-6,1,5,1)
Block(-6,1,6,1)
Block(-6,2,0,1)
Block(-6,2,1,1)
Block(-6,2,2,1)
Block(-6,2,3,1)
Block(-6,2,4,1)
Block(-6,2,5,1)
Block(-6,3,0,1)
Block(-6,3,1,1)
Block(-6,3,2,1)
Block(-6,3,3,1)
Block(-6,3,4,1)
Block(-6,3,5,1)
Block(-6,4,-1,1)
Block(-6,4,0,1)
Block(-6,4,1,1)
Block(-6,4,2,1)
Block(-6,4,3,1)
Block(-6,4,4,1)
Block(-6,4,5,1)
Block(-6,5,-2,1)
Block(-6,5,-1,1)
Block(-6,5,0,1)
Block(-6,5,1,1)
Block(-6,5,2,1)
Block(-6,5,3,1)
Block(-6,5,4,1)
Block(-6,5,5,1)
Block(-6,6,-2,1)
Block(-6,6,-1,1)
Block(-6,6,0,1)
Block(-6,6,1,1)
Block(-6,6,2,1)
Block(-6,6,3,1)
Block(-6,6,4,1)
Block(-6,6,5,1)
Block(-6,7,-2,1)
Block(-6,7,-1,1)
Block(-6,7,0,1)
Block(-6,7,1,1)
Block(-6,7,2,1)
Block(-6,7,3,1)
Block(-6,7,4,1)
Block(-6,7,5,1)
Block(-6,8,-3,1)
Block(-6,8,-2,1)
Block(-6,8,-1,1)
Block(-6,8,0,1)
Block(-6,8,1,1)
Block(-6,8,2,1)
Block(-6,8,3,1)
Block(-6,8,4,1)
Block(-6,8,5,1)
Block(-6,9,-3,1)
Block(-6,9,-2,1)
Block(-6,9,-1,1)
Block(-6,9,0,1)
Block(-6,9,1,1)
Block(-6,9,2,1)
Block(-6,9,3,1)
Block(-6,9,4,1)
Block(-6,9,5,1)
Block(-6,10,-3,1)
Block(-6,10,-2,1)
Block(-6,10,-1,1)
Block(-6,10,0,1)
Block(-6,10,1,1)
Block(-6,10,2,1)
Block(-6,10,3,1)
Block(-6,10,4,1)
Block(-6,10,5,1)
Block(-6,10,6,1)
Block(-6,11,-4,1)
Block(-6,11,-3,1)
Block(-6,11,-2,1)
Block(-6,11,-1,1)
Block(-6,11,0,1)
Block(-6,11,1,1)
Block(-6,11,2,1)
Block(-6,11,3,1)
Block(-6,11,4,1)
Block(-6,11,5,1)
Block(-6,11,6,1)
Block(-6,12,-4,1)
Block(-6,12,-3,1)
Block(-6,12,-2,1)
Block(-6,12,-1,1)
Block(-6,12,0,1)
Block(-6,12,1,1)
Block(-6,12,2,1)
Block(-6,12,3,1)
Block(-6,12,4,1)
Block(-6,12,5,1)
Block(-6,12,6,1)
Block(-6,13,-4,1)
Block(-6,13,-3,1)
Block(-6,13,-2,1)
Block(-6,13,-1,1)
Block(-6,13,0,1)
Block(-6,13,1,1)
Block(-6,13,2,1)
Block(-6,13,3,1)
Block(-6,13,4,1)
Block(-6,13,5,1)
Block(-6,13,6,1)
Block(-6,14,-4,1)
Block(-6,14,-3,1)
Block(-6,14,-2,1)
Block(-6,14,-1,1)
Block(-6,14,0,1)
Block(-6,14,1,1)
Block(-6,14,2,1)
Block(-6,14,3,1)
Block(-6,14,4,1)
Block(-6,14,5,1)
Block(-6,14,6,1)
Block(-6,15,-3,1)
Block(-6,15,-2,1)
Block(-6,15,-1,1)
Block(-6,15,0,1)
Block(-6,15,1,1)
Block(-6,15,2,1)
Block(-6,15,3,1)
Block(-6,15,4,1)
Block(-6,15,5,1)
Block(-6,16,-3,1)
Block(-6,16,-2,1)
Block(-6,16,-1,1)
Block(-6,16,0,1)
Block(-6,16,1,1)
Block(-6,16,2,1)
Block(-6,16,3,1)
Block(-6,16,4,1)
Block(-6,17,-4,1)
Block(-6,17,-3,1)
Block(-6,17,-2,1)
Block(-6,17,-1,1)
Block(-6,17,0,1)
Block(-6,17,1,1)
Block(-6,17,2,1)
Block(-6,17,3,1)
Block(-6,17,4,1)
Block(-6,18,-5,1)
Block(-6,18,-4,1)
Block(-6,18,-3,1)
Block(-6,18,-2,1)
Block(-6,18,-1,1)
Block(-6,18,0,1)
Block(-6,18,1,1)
Block(-6,18,2,1)
Block(-6,18,3,1)
Block(-6,18,4,1)
Block(-6,19,-4,1)
Block(-6,19,-3,1)
Block(-6,19,-2,1)
Block(-6,19,-1,1)
Block(-6,19,0,1)
Block(-6,19,1,1)
Block(-6,19,2,1)
Block(-6,19,3,1)
Block(-6,19,4,1)
Block(-6,20,-3,1)
Block(-6,20,-2,1)
Block(-6,20,-1,1)
Block(-6,20,0,1)
Block(-6,20,1,1)
Block(-6,20,2,1)
Block(-6,20,3,1)
Block(-6,20,4,1)
Block(-6,20,5,1)
Block(-6,21,-2,1)
Block(-6,21,-1,1)
Block(-6,21,0,1)
Block(-6,21,1,1)
Block(-6,21,2,1)
Block(-6,21,3,1)
Block(-6,21,4,1)
Block(-6,21,5,1)
Block(-6,22,-1,1)
Block(-6,22,0,1)
Block(-6,22,1,1)
Block(-6,22,2,1)
Block(-6,22,3,1)
Block(-6,22,4,1)
Block(-6,22,5,1)
Block(-6,23,-1,1)
Block(-6,23,0,1)
Block(-6,23,1,1)
Block(-6,23,2,1)
Block(-6,23,3,1)
Block(-6,23,4,1)
Block(-6,23,5,1)
Block(-6,24,-2,1)
Block(-6,24,-1,1)
Block(-6,24,0,1)
Block(-6,24,1,1)
Block(-6,24,2,1)
Block(-6,24,3,1)
Block(-6,24,4,1)
Block(-6,25,-2,1)
Block(-6,25,-1,1)
Block(-6,25,0,1)
Block(-6,25,1,1)
Block(-6,25,2,1)
Block(-6,25,3,1)
Block(-6,25,4,1)
Block(-6,26,-3,1)
Block(-6,26,-2,1)
Block(-6,26,-1,1)
Block(-6,26,0,1)
Block(-6,26,1,1)
Block(-6,26,2,1)
Block(-6,26,3,1)
Block(-6,27,-3,1)
Block(-6,27,-2,1)
Block(-6,27,-1,1)
Block(-6,27,0,1)
Block(-6,27,1,1)
Block(-6,27,2,1)
Block(-6,27,3,1)
Block(-6,28,-3,1)
Block(-6,28,-2,1)
Block(-6,28,-1,1)
Block(-6,28,0,1)
Block(-6,28,1,1)
Block(-6,28,2,1)
Block(-6,28,3,1)
Block(-6,28,4,1)
Block(-6,29,-2,1)
Block(-6,29,-1,1)
Block(-6,29,0,1)
Block(-6,29,1,1)
Block(-6,29,2,1)
Block(-6,29,3,1)
Block(-6,29,4,1)
Block(-6,29,5,1)
Block(-6,30,-2,1)
Block(-6,30,-1,1)
Block(-6,30,0,1)
Block(-6,30,1,1)
Block(-6,30,2,1)
Block(-6,30,3,1)
Block(-6,30,4,1)
Block(-6,30,5,1)
Block(-6,31,-2,1)
Block(-6,31,-1,1)
Block(-6,31,0,1)
Block(-6,31,1,1)
Block(-6,31,2,1)
Block(-6,31,3,1)
Block(-6,31,4,1)
Block(-6,31,5,1)
Block(-6,31,6,1)
Block(-6,32,-2,1)
Block(-6,32,-1,1)
Block(-6,32,0,1)
Block(-6,32,1,1)
Block(-6,32,2,1)
Block(-6,32,3,1)
Block(-6,32,4,1)
Block(-6,32,5,1)
Block(-6,32,6,1)
Block(-6,32,7,1)
Block(-6,33,-2,1)
Block(-6,33,-1,1)
Block(-6,33,0,1)
Block(-6,33,1,1)
Block(-6,33,2,1)
Block(-6,33,3,1)
Block(-6,33,4,1)
Block(-6,33,5,1)
Block(-6,33,6,1)
Block(-6,33,7,1)
Block(-6,33,8,1)
Block(-6,34,-2,1)
Block(-6,34,-1,1)
Block(-6,34,0,1)
Block(-6,34,1,1)
Block(-6,34,2,1)
Block(-6,34,3,1)
Block(-6,34,4,1)
Block(-6,34,5,1)
Block(-6,34,6,1)
Block(-6,34,7,1)
Block(-6,35,-2,1)
Block(-6,35,-1,1)
Block(-6,35,0,1)
Block(-6,35,1,1)
Block(-6,35,2,1)
Block(-6,35,3,1)
Block(-6,35,4,1)
Block(-6,35,5,1)
Block(-6,35,6,1)
Block(-6,35,7,1)
Block(-6,36,-3,1)
Block(-6,36,-2,1)
Block(-6,36,-1,1)
Block(-6,36,0,1)
Block(-6,36,1,1)
Block(-6,36,2,1)
Block(-6,36,3,1)
Block(-6,36,4,1)
Block(-6,36,5,1)
Block(-6,36,6,1)
Block(-6,36,7,1)
Block(-6,37,-4,1)
Block(-6,37,-3,1)
Block(-6,37,-2,1)
Block(-6,37,-1,1)
Block(-6,37,0,1)
Block(-6,37,1,1)
Block(-6,37,2,1)
Block(-6,37,3,1)
Block(-6,37,4,1)
Block(-6,37,5,1)
Block(-6,37,6,1)
Block(-6,38,-4,1)
Block(-6,38,-3,1)
Block(-6,38,-2,1)
Block(-6,38,-1,1)
Block(-6,38,0,1)
Block(-6,38,1,1)
Block(-6,38,2,1)
Block(-6,38,3,1)
Block(-6,38,4,1)
Block(-6,38,5,1)
Block(-6,38,6,1)
Block(-6,39,-4,1)
Block(-6,39,-3,1)
Block(-6,39,-2,1)
Block(-6,39,-1,1)
Block(-6,39,0,1)
Block(-6,39,1,1)
Block(-6,39,2,1)
Block(-6,39,3,1)
Block(-6,39,4,1)
Block(-6,39,5,1)
Block(-6,39,6,1)
Block(-6,40,-5,1)
Block(-6,40,-4,1)
Block(-6,40,-3,1)
Block(-6,40,-2,1)
Block(-6,40,-1,1)
Block(-6,40,0,1)
Block(-6,40,1,1)
Block(-6,40,2,1)
Block(-6,40,3,1)
Block(-6,40,4,1)
Block(-6,40,5,1)
Block(-6,40,6,1)
Block(-6,40,7,1)
Block(-6,41,-5,1)
Block(-6,41,-4,1)
Block(-6,41,-3,1)
Block(-6,41,-2,1)
Block(-6,41,-1,1)
Block(-6,41,0,1)
Block(-6,41,1,1)
Block(-6,41,2,1)
Block(-6,41,3,1)
Block(-6,41,4,1)
Block(-6,41,5,1)
Block(-6,41,6,1)
Block(-6,42,-5,1)
Block(-6,42,-4,1)
Block(-6,42,-3,1)
Block(-6,42,-2,1)
Block(-6,42,-1,1)
Block(-6,42,0,1)
Block(-6,42,1,1)
Block(-6,42,2,1)
Block(-6,42,3,1)
Block(-6,42,4,1)
Block(-6,42,5,1)
Block(-6,42,6,1)
Block(-6,43,-4,1)
Block(-6,43,-3,1)
Block(-6,43,-2,1)
Block(-6,43,-1,1)
Block(-6,43,0,1)
Block(-6,43,1,1)
Block(-6,43,2,1)
Block(-6,43,3,1)
Block(-6,43,4,1)
Block(-6,43,5,1)
Block(-6,44,-3,1)
Block(-6,44,-2,1)
Block(-6,44,-1,1)
Block(-6,44,0,1)
Block(-6,44,1,1)
Block(-6,44,2,1)
Block(-6,44,3,1)
Block(-6,44,4,1)
Block(-6,45,-3,1)
Block(-6,45,-2,1)
Block(-6,45,-1,1)
Block(-6,45,0,1)
Block(-6,45,1,1)
Block(-6,45,2,1)
Block(-6,45,3,1)
Block(-6,45,4,1)
Block(-6,46,-3,1)
Block(-6,46,-2,1)
Block(-6,46,-1,1)
Block(-6,46,0,1)
Block(-6,46,1,1)
Block(-6,46,2,1)
Block(-6,46,3,1)
Block(-6,46,4,1)
Block(-6,47,-3,1)
Block(-6,47,-2,1)
Block(-6,47,-1,1)
Block(-6,47,0,1)
Block(-6,47,1,1)
Block(-6,47,2,1)
Block(-6,47,3,1)
Block(-6,47,4,1)
Block(-6,48,-3,1)
Block(-6,48,-2,1)
Block(-6,48,-1,1)
Block(-6,48,0,1)
Block(-6,48,1,1)
Block(-6,48,2,1)
Block(-6,48,3,1)
Block(-6,48,4,1)
Block(-6,49,-4,1)
Block(-6,49,-3,1)
Block(-6,49,-2,1)
Block(-6,49,-1,1)
Block(-6,49,0,1)
Block(-6,49,1,1)
Block(-6,49,2,1)
Block(-6,49,3,1)
Block(-6,49,4,1)
Block(-6,49,5,1)
Block(-6,50,-4,1)
Block(-6,50,-3,1)
Block(-6,50,-2,1)
Block(-6,50,-1,1)
Block(-6,50,0,1)
Block(-6,50,1,1)
Block(-6,50,2,1)
Block(-6,50,3,1)
Block(-6,50,4,1)
Block(-6,50,5,1)
Block(-6,50,6,1)
Block(-6,51,-5,1)
Block(-6,51,-4,1)
Block(-6,51,-3,1)
Block(-6,51,-2,1)
Block(-6,51,-1,1)
Block(-6,51,0,1)
Block(-6,51,1,1)
Block(-6,51,2,1)
Block(-6,51,3,1)
Block(-6,51,4,1)
Block(-6,51,5,1)
Block(-6,51,6,1)
Block(-6,51,7,1)
Block(-6,52,-5,1)
Block(-6,52,-4,1)
Block(-6,52,-3,1)
Block(-6,52,-2,1)
Block(-6,52,-1,1)
Block(-6,52,0,1)
Block(-6,52,1,1)
Block(-6,52,2,1)
Block(-6,52,3,1)
Block(-6,52,4,1)
Block(-6,52,5,1)
Block(-6,52,6,1)
Block(-6,52,7,1)
Block(-6,53,-5,1)
Block(-6,53,-4,1)
Block(-6,53,-3,1)
Block(-6,53,-2,1)
Block(-6,53,-1,1)
Block(-6,53,0,1)
Block(-6,53,1,1)
Block(-6,53,2,1)
Block(-6,53,3,1)
Block(-6,53,4,1)
Block(-6,53,5,1)
Block(-6,53,6,1)
Block(-6,53,7,1)
Block(-6,54,-4,1)
Block(-6,54,-3,1)
Block(-6,54,-2,1)
Block(-6,54,-1,1)
Block(-6,54,0,1)
Block(-6,54,1,1)
Block(-6,54,2,1)
Block(-6,54,3,1)
Block(-6,54,4,1)
Block(-6,54,5,1)
Block(-6,54,6,1)
Block(-6,54,7,1)
Block(-6,55,-4,1)
Block(-6,55,-3,1)
Block(-6,55,-2,1)
Block(-6,55,-1,1)
Block(-6,55,0,1)
Block(-6,55,1,1)
Block(-6,55,2,1)
Block(-6,55,3,1)
Block(-6,55,4,1)
Block(-6,55,5,1)
Block(-6,55,6,1)
Block(-6,55,7,1)
Block(-6,56,-4,1)
Block(-6,56,-3,1)
Block(-6,56,-2,1)
Block(-6,56,-1,1)
Block(-6,56,0,1)
Block(-6,56,1,1)
Block(-6,56,2,1)
Block(-6,56,3,1)
Block(-6,56,4,1)
Block(-6,56,5,1)
Block(-6,56,6,1)
Block(-6,56,7,1)
Block(-6,57,-4,1)
Block(-6,57,-3,1)
Block(-6,57,-2,1)
Block(-6,57,-1,1)
Block(-6,57,0,1)
Block(-6,57,1,1)
Block(-6,57,2,1)
Block(-6,57,3,1)
Block(-6,57,4,1)
Block(-6,57,5,1)
Block(-6,57,6,1)
Block(-6,57,7,1)
Block(-6,58,-5,1)
Block(-6,58,-4,1)
Block(-6,58,-3,1)
Block(-6,58,-2,1)
Block(-6,58,-1,1)
Block(-6,58,0,1)
Block(-6,58,1,1)
Block(-6,58,2,1)
Block(-6,58,3,1)
Block(-6,58,4,1)
Block(-6,58,5,1)
Block(-6,58,6,1)
Block(-6,58,7,1)
Block(-6,58,8,1)
Block(-6,59,-6,1)
Block(-6,59,-5,1)
Block(-6,59,-4,1)
Block(-6,59,-3,1)
Block(-6,59,-2,1)
Block(-6,59,-1,1)
Block(-6,59,0,1)
Block(-6,59,1,1)
Block(-6,59,2,1)
Block(-6,59,3,1)
Block(-6,59,4,1)
Block(-6,59,5,1)
Block(-6,59,6,1)
Block(-6,59,7,1)
Block(-6,59,8,1)
Block(-6,60,-7,1)
Block(-6,60,-6,1)
Block(-6,60,-5,1)
Block(-6,60,-4,1)
Block(-6,60,-3,1)
Block(-6,60,-2,1)
Block(-6,60,-1,1)
Block(-6,60,0,1)
Block(-6,60,1,1)
Block(-6,60,2,1)
Block(-6,60,3,1)
Block(-6,60,4,1)
Block(-6,60,5,1)
Block(-6,60,6,1)
Block(-6,60,7,1)
Block(-6,60,8,1)
Block(-6,61,-7,1)
Block(-6,61,-6,1)
Block(-6,61,-5,1)
Block(-6,61,-4,1)
Block(-6,61,-3,1)
Block(-6,61,-2,1)
Block(-6,61,-1,1)
Block(-6,61,0,1)
Block(-6,61,1,1)
Block(-6,61,2,1)
Block(-6,61,3,1)
Block(-6,61,4,1)
Block(-6,61,5,1)
Block(-6,61,6,1)
Block(-6,61,7,1)
Block(-6,61,8,1)
Block(-6,62,-6,1)
Block(-6,62,-5,1)
Block(-6,62,-4,1)
Block(-6,62,-3,1)
Block(-6,62,-2,1)
Block(-6,62,-1,1)
Block(-6,62,0,1)
Block(-6,62,1,1)
Block(-6,62,2,1)
Block(-6,62,3,1)
Block(-6,62,4,1)
Block(-6,62,5,1)
Block(-6,62,6,1)
Block(-6,62,7,1)
Block(-6,62,8,1)
Block(-6,63,-5,1)
Block(-6,63,-4,1)
Block(-6,63,-3,1)
Block(-6,63,-2,1)
Block(-6,63,-1,1)
Block(-6,63,0,1)
Block(-6,63,1,1)
Block(-6,63,2,1)
Block(-6,63,3,1)
Block(-6,63,4,1)
Block(-6,63,5,1)
Block(-6,63,6,1)
Block(-6,63,7,1)
Block(-6,63,8,1)
Block(-6,64,-3,1)
Block(-6,64,-2,1)
Block(-6,64,-1,1)
Block(-6,64,0,1)
Block(-6,64,1,1)
Block(-6,64,2,1)
Block(-6,64,3,1)
Block(-6,64,4,1)
Block(-6,64,5,1)
Block(-6,64,6,1)
Block(-6,64,7,1)
Block(-6,65,-2,1)
Block(-6,65,-1,1)
Block(-6,65,0,1)
Block(-6,65,1,1)
Block(-6,65,2,1)
Block(-6,65,3,1)
Block(-6,65,4,1)
Block(-6,65,5,1)
Block(-6,65,6,1)
Block(-6,65,7,1)
Block(-6,66,-1,1)
Block(-6,66,0,1)
Block(-6,66,1,1)
Block(-6,66,2,1)
Block(-6,66,3,1)
Block(-6,66,4,1)
Block(-6,66,5,1)
Block(-6,66,6,1)
Block(-6,67,0,1)
Block(-6,67,1,1)
Block(-6,67,2,1)
Block(-6,67,3,1)
Block(-6,67,4,1)
Block(-6,67,5,1)
Block(-6,67,6,1)
Block(-6,68,0,1)
Block(-6,68,1,1)
Block(-6,68,2,1)
Block(-6,68,3,1)
Block(-6,68,4,1)
Block(-6,68,5,1)
Block(-6,69,0,1)
Block(-6,69,1,1)
Block(-6,69,2,1)
Block(-6,69,3,1)
Block(-6,69,4,1)
Block(-6,69,5,1)
Block(-6,70,0,1)
Block(-6,70,1,1)
Block(-6,70,2,1)
Block(-6,70,3,1)
Block(-6,70,4,1)
Block(-6,70,5,1)
Block(-6,71,0,1)
Block(-6,71,1,1)
Block(-6,71,2,1)
Block(-6,71,3,1)
Block(-6,71,4,1)
Block(-6,71,5,1)
Block(-6,72,0,1)
Block(-6,72,1,1)
Block(-6,72,2,1)
Block(-6,72,3,1)
Block(-6,72,4,1)
Block(-6,72,5,1)
Block(-6,72,6,1)
Block(-6,73,1,1)
Block(-6,73,2,1)
Block(-6,73,3,1)
Block(-6,73,4,1)
Block(-6,73,5,1)
Block(-6,73,6,1)
Block(-6,74,1,1)
Block(-6,74,2,1)
Block(-6,74,3,1)
Block(-6,74,4,1)
Block(-6,74,5,1)
Block(-6,74,6,1)
Block(-6,75,1,1)
Block(-6,75,2,1)
Block(-6,75,3,1)
Block(-6,75,4,1)
Block(-6,75,5,1)
Block(-6,76,2,1)
Block(-6,76,3,1)
Block(-6,76,4,1)
Block(-6,83,-2,1)
Block(-6,84,-3,1)
Block(-6,84,-2,1)
Block(-6,84,-1,1)
Block(-6,84,0,1)
Block(-6,84,1,1)
Block(-6,84,2,1)
Block(-6,84,3,1)
Block(-6,85,-2,1)
Block(-6,85,-1,1)
Block(-6,85,0,1)
Block(-6,85,1,1)
Block(-6,85,2,1)
Block(-6,85,3,1)
Block(-6,85,4,1)
Block(-6,86,-2,1)
Block(-6,86,-1,1)
Block(-6,86,0,1)
Block(-6,86,1,1)
Block(-6,86,2,1)
Block(-6,86,3,1)
Block(-6,86,4,1)
Block(-6,87,-1,1)
Block(-6,87,0,1)
Block(-6,87,1,1)
Block(-6,87,2,1)
Block(-6,87,3,1)
Block(-6,87,4,1)
Block(-6,88,0,1)
Block(-6,88,1,1)
Block(-6,88,2,1)
Block(-6,88,3,1)
Block(-6,89,0,1)
Block(-6,89,1,1)
Block(-6,89,2,1)
Block(-5,0,-7,1)
Block(-5,0,-6,1)
Block(-5,0,-5,1)
Block(-5,0,-4,1)
Block(-5,0,-3,1)
Block(-5,0,-2,1)
Block(-5,0,-1,1)
Block(-5,0,0,1)
Block(-5,0,1,1)
Block(-5,0,2,1)
Block(-5,0,3,1)
Block(-5,0,4,1)
Block(-5,0,5,1)
Block(-5,0,6,1)
Block(-5,0,7,1)
Block(-5,1,-5,1)
Block(-5,1,-4,1)
Block(-5,1,-3,1)
Block(-5,1,-2,1)
Block(-5,1,-1,1)
Block(-5,1,0,1)
Block(-5,1,1,1)
Block(-5,1,2,1)
Block(-5,1,3,1)
Block(-5,1,4,1)
Block(-5,1,5,1)
Block(-5,1,6,1)
Block(-5,1,7,1)
Block(-5,2,-4,1)
Block(-5,2,-3,1)
Block(-5,2,-2,1)
Block(-5,2,-1,1)
Block(-5,2,0,1)
Block(-5,2,1,1)
Block(-5,2,2,1)
Block(-5,2,3,1)
Block(-5,2,4,1)
Block(-5,2,5,1)
Block(-5,2,6,1)
Block(-5,3,-3,1)
Block(-5,3,-2,1)
Block(-5,3,-1,1)
Block(-5,3,0,1)
Block(-5,3,1,1)
Block(-5,3,2,1)
Block(-5,3,3,1)
Block(-5,3,4,1)
Block(-5,3,5,1)
Block(-5,3,6,1)
Block(-5,4,-3,1)
Block(-5,4,-2,1)
Block(-5,4,-1,1)
Block(-5,4,0,1)
Block(-5,4,1,1)
Block(-5,4,2,1)
Block(-5,4,3,1)
Block(-5,4,4,1)
Block(-5,4,5,1)
Block(-5,4,6,1)
Block(-5,5,-3,1)
Block(-5,5,-2,1)
Block(-5,5,-1,1)
Block(-5,5,0,1)
Block(-5,5,1,1)
Block(-5,5,2,1)
Block(-5,5,3,1)
Block(-5,5,4,1)
Block(-5,5,5,1)
Block(-5,5,6,1)
Block(-5,6,-4,1)
Block(-5,6,-3,1)
Block(-5,6,-2,1)
Block(-5,6,-1,1)
Block(-5,6,0,1)
Block(-5,6,1,1)
Block(-5,6,2,1)
Block(-5,6,3,1)
Block(-5,6,4,1)
Block(-5,6,5,1)
Block(-5,6,6,1)
Block(-5,6,7,1)
Block(-5,7,-4,1)
Block(-5,7,-3,1)
Block(-5,7,-2,1)
Block(-5,7,-1,1)
Block(-5,7,0,1)
Block(-5,7,1,1)
Block(-5,7,2,1)
Block(-5,7,3,1)
Block(-5,7,4,1)
Block(-5,7,5,1)
Block(-5,7,6,1)
Block(-5,8,-4,1)
Block(-5,8,-3,1)
Block(-5,8,-2,1)
Block(-5,8,-1,1)
Block(-5,8,0,1)
Block(-5,8,1,1)
Block(-5,8,2,1)
Block(-5,8,3,1)
Block(-5,8,4,1)
Block(-5,8,5,1)
Block(-5,8,6,1)
Block(-5,8,7,1)
Block(-5,9,-4,1)
Block(-5,9,-3,1)
Block(-5,9,-2,1)
Block(-5,9,-1,1)
Block(-5,9,0,1)
Block(-5,9,1,1)
Block(-5,9,2,1)
Block(-5,9,3,1)
Block(-5,9,4,1)
Block(-5,9,5,1)
Block(-5,9,6,1)
Block(-5,9,7,1)
Block(-5,10,-5,1)
Block(-5,10,-4,1)
Block(-5,10,-3,1)
Block(-5,10,-2,1)
Block(-5,10,-1,1)
Block(-5,10,0,1)
Block(-5,10,1,1)
Block(-5,10,2,1)
Block(-5,10,3,1)
Block(-5,10,4,1)
Block(-5,10,5,1)
Block(-5,10,6,1)
Block(-5,10,7,1)
Block(-5,11,-5,1)
Block(-5,11,-4,1)
Block(-5,11,-3,1)
Block(-5,11,-2,1)
Block(-5,11,-1,1)
Block(-5,11,0,1)
Block(-5,11,1,1)
Block(-5,11,2,1)
Block(-5,11,3,1)
Block(-5,11,4,1)
Block(-5,11,5,1)
Block(-5,11,6,1)
Block(-5,11,7,1)
Block(-5,12,-5,1)
Block(-5,12,-4,1)
Block(-5,12,-3,1)
Block(-5,12,-2,1)
Block(-5,12,-1,1)
Block(-5,12,0,1)
Block(-5,12,1,1)
Block(-5,12,2,1)
Block(-5,12,3,1)
Block(-5,12,4,1)
Block(-5,12,5,1)
Block(-5,12,6,1)
Block(-5,12,7,1)
Block(-5,12,8,1)
Block(-5,13,-5,1)
Block(-5,13,-4,1)
Block(-5,13,-3,1)
Block(-5,13,-2,1)
Block(-5,13,-1,1)
Block(-5,13,0,1)
Block(-5,13,1,1)
Block(-5,13,2,1)
Block(-5,13,3,1)
Block(-5,13,4,1)
Block(-5,13,5,1)
Block(-5,13,6,1)
Block(-5,13,7,1)
Block(-5,13,8,1)
Block(-5,14,-5,1)
Block(-5,14,-4,1)
Block(-5,14,-3,1)
Block(-5,14,-2,1)
Block(-5,14,-1,1)
Block(-5,14,0,1)
Block(-5,14,1,1)
Block(-5,14,2,1)
Block(-5,14,3,1)
Block(-5,14,4,1)
Block(-5,14,5,1)
Block(-5,14,6,1)
Block(-5,14,7,1)
Block(-5,15,-5,1)
Block(-5,15,-4,1)
Block(-5,15,-3,1)
Block(-5,15,-2,1)
Block(-5,15,-1,1)
Block(-5,15,0,1)
Block(-5,15,1,1)
Block(-5,15,2,1)
Block(-5,15,3,1)
Block(-5,15,4,1)
Block(-5,15,5,1)
Block(-5,15,6,1)
Block(-5,15,7,1)
Block(-5,16,-5,1)
Block(-5,16,-4,1)
Block(-5,16,-3,1)
Block(-5,16,-2,1)
Block(-5,16,-1,1)
Block(-5,16,0,1)
Block(-5,16,1,1)
Block(-5,16,2,1)
Block(-5,16,3,1)
Block(-5,16,4,1)
Block(-5,16,5,1)
Block(-5,16,6,1)
Block(-5,17,-6,1)
Block(-5,17,-5,1)
Block(-5,17,-4,1)
Block(-5,17,-3,1)
Block(-5,17,-2,1)
Block(-5,17,-1,1)
Block(-5,17,0,1)
Block(-5,17,1,1)
Block(-5,17,2,1)
Block(-5,17,3,1)
Block(-5,17,4,1)
Block(-5,17,5,1)
Block(-5,18,-7,1)
Block(-5,18,-6,1)
Block(-5,18,-5,1)
Block(-5,18,-4,1)
Block(-5,18,-3,1)
Block(-5,18,-2,1)
Block(-5,18,-1,1)
Block(-5,18,0,1)
Block(-5,18,1,1)
Block(-5,18,2,1)
Block(-5,18,3,1)
Block(-5,18,4,1)
Block(-5,18,5,1)
Block(-5,19,-7,1)
Block(-5,19,-6,1)
Block(-5,19,-5,1)
Block(-5,19,-4,1)
Block(-5,19,-3,1)
Block(-5,19,-2,1)
Block(-5,19,-1,1)
Block(-5,19,0,1)
Block(-5,19,1,1)
Block(-5,19,2,1)
Block(-5,19,3,1)
Block(-5,19,4,1)
Block(-5,19,5,1)
Block(-5,20,-6,1)
Block(-5,20,-5,1)
Block(-5,20,-4,1)
Block(-5,20,-3,1)
Block(-5,20,-2,1)
Block(-5,20,-1,1)
Block(-5,20,0,1)
Block(-5,20,1,1)
Block(-5,20,2,1)
Block(-5,20,3,1)
Block(-5,20,4,1)
Block(-5,20,5,1)
Block(-5,20,6,1)
Block(-5,21,-5,1)
Block(-5,21,-4,1)
Block(-5,21,-3,1)
Block(-5,21,-2,1)
Block(-5,21,-1,1)
Block(-5,21,0,1)
Block(-5,21,1,1)
Block(-5,21,2,1)
Block(-5,21,3,1)
Block(-5,21,4,1)
Block(-5,21,5,1)
Block(-5,21,6,1)
Block(-5,22,-5,1)
Block(-5,22,-4,1)
Block(-5,22,-3,1)
Block(-5,22,-2,1)
Block(-5,22,-1,1)
Block(-5,22,0,1)
Block(-5,22,1,1)
Block(-5,22,2,1)
Block(-5,22,3,1)
Block(-5,22,4,1)
Block(-5,22,5,1)
Block(-5,22,6,1)
Block(-5,22,7,1)
Block(-5,23,-3,1)
Block(-5,23,-2,1)
Block(-5,23,-1,1)
Block(-5,23,0,1)
Block(-5,23,1,1)
Block(-5,23,2,1)
Block(-5,23,3,1)
Block(-5,23,4,1)
Block(-5,23,5,1)
Block(-5,23,6,1)
Block(-5,23,7,1)
Block(-5,24,-3,1)
Block(-5,24,-2,1)
Block(-5,24,-1,1)
Block(-5,24,0,1)
Block(-5,24,1,1)
Block(-5,24,2,1)
Block(-5,24,3,1)
Block(-5,24,4,1)
Block(-5,24,5,1)
Block(-5,24,6,1)
Block(-5,25,-4,1)
Block(-5,25,-3,1)
Block(-5,25,-2,1)
Block(-5,25,-1,1)
Block(-5,25,0,1)
Block(-5,25,1,1)
Block(-5,25,2,1)
Block(-5,25,3,1)
Block(-5,25,4,1)
Block(-5,25,5,1)
Block(-5,25,6,1)
Block(-5,26,-4,1)
Block(-5,26,-3,1)
Block(-5,26,-2,1)
Block(-5,26,-1,1)
Block(-5,26,0,1)
Block(-5,26,1,1)
Block(-5,26,2,1)
Block(-5,26,3,1)
Block(-5,26,4,1)
Block(-5,26,5,1)
Block(-5,27,-4,1)
Block(-5,27,-3,1)
Block(-5,27,-2,1)
Block(-5,27,-1,1)
Block(-5,27,0,1)
Block(-5,27,1,1)
Block(-5,27,2,1)
Block(-5,27,3,1)
Block(-5,27,4,1)
Block(-5,27,5,1)
Block(-5,28,-4,1)
Block(-5,28,-3,1)
Block(-5,28,-2,1)
Block(-5,28,-1,1)
Block(-5,28,0,1)
Block(-5,28,1,1)
Block(-5,28,2,1)
Block(-5,28,3,1)
Block(-5,28,4,1)
Block(-5,28,5,1)
Block(-5,28,6,1)
Block(-5,29,-4,1)
Block(-5,29,-3,1)
Block(-5,29,-2,1)
Block(-5,29,-1,1)
Block(-5,29,0,1)
Block(-5,29,1,1)
Block(-5,29,2,1)
Block(-5,29,3,1)
Block(-5,29,4,1)
Block(-5,29,5,1)
Block(-5,29,6,1)
Block(-5,29,7,1)
Block(-5,30,-3,1)
Block(-5,30,-2,1)
Block(-5,30,-1,1)
Block(-5,30,0,1)
Block(-5,30,1,1)
Block(-5,30,2,1)
Block(-5,30,3,1)
Block(-5,30,4,1)
Block(-5,30,5,1)
Block(-5,30,6,1)
Block(-5,30,7,1)
Block(-5,31,-3,1)
Block(-5,31,-2,1)
Block(-5,31,-1,1)
Block(-5,31,0,1)
Block(-5,31,1,1)
Block(-5,31,2,1)
Block(-5,31,3,1)
Block(-5,31,4,1)
Block(-5,31,5,1)
Block(-5,31,6,1)
Block(-5,31,7,1)
Block(-5,31,8,1)
Block(-5,32,-3,1)
Block(-5,32,-2,1)
Block(-5,32,-1,1)
Block(-5,32,0,1)
Block(-5,32,1,1)
Block(-5,32,2,1)
Block(-5,32,3,1)
Block(-5,32,4,1)
Block(-5,32,5,1)
Block(-5,32,6,1)
Block(-5,32,7,1)
Block(-5,32,8,1)
Block(-5,32,9,1)
Block(-5,33,-3,1)
Block(-5,33,-2,1)
Block(-5,33,-1,1)
Block(-5,33,0,1)
Block(-5,33,1,1)
Block(-5,33,2,1)
Block(-5,33,3,1)
Block(-5,33,4,1)
Block(-5,33,5,1)
Block(-5,33,6,1)
Block(-5,33,7,1)
Block(-5,33,8,1)
Block(-5,33,9,1)
Block(-5,34,-3,1)
Block(-5,34,-2,1)
Block(-5,34,-1,1)
Block(-5,34,0,1)
Block(-5,34,1,1)
Block(-5,34,2,1)
Block(-5,34,3,1)
Block(-5,34,4,1)
Block(-5,34,5,1)
Block(-5,34,6,1)
Block(-5,34,7,1)
Block(-5,34,8,1)
Block(-5,34,9,1)
Block(-5,35,-3,1)
Block(-5,35,-2,1)
Block(-5,35,-1,1)
Block(-5,35,0,1)
Block(-5,35,1,1)
Block(-5,35,2,1)
Block(-5,35,3,1)
Block(-5,35,4,1)
Block(-5,35,5,1)
Block(-5,35,6,1)
Block(-5,35,7,1)
Block(-5,35,8,1)
Block(-5,36,-4,1)
Block(-5,36,-3,1)
Block(-5,36,-2,1)
Block(-5,36,-1,1)
Block(-5,36,0,1)
Block(-5,36,1,1)
Block(-5,36,2,1)
Block(-5,36,3,1)
Block(-5,36,4,1)
Block(-5,36,5,1)
Block(-5,36,6,1)
Block(-5,36,7,1)
Block(-5,36,8,1)
Block(-5,37,-5,1)
Block(-5,37,-4,1)
Block(-5,37,-3,1)
Block(-5,37,-2,1)
Block(-5,37,-1,1)
Block(-5,37,0,1)
Block(-5,37,1,1)
Block(-5,37,2,1)
Block(-5,37,3,1)
Block(-5,37,4,1)
Block(-5,37,5,1)
Block(-5,37,6,1)
Block(-5,37,7,1)
Block(-5,38,-5,1)
Block(-5,38,-4,1)
Block(-5,38,-3,1)
Block(-5,38,-2,1)
Block(-5,38,-1,1)
Block(-5,38,0,1)
Block(-5,38,1,1)
Block(-5,38,2,1)
Block(-5,38,3,1)
Block(-5,38,4,1)
Block(-5,38,5,1)
Block(-5,38,6,1)
Block(-5,38,7,1)
Block(-5,39,-6,1)
Block(-5,39,-5,1)
Block(-5,39,-4,1)
Block(-5,39,-3,1)
Block(-5,39,-2,1)
Block(-5,39,-1,1)
Block(-5,39,0,1)
Block(-5,39,1,1)
Block(-5,39,2,1)
Block(-5,39,3,1)
Block(-5,39,4,1)
Block(-5,39,5,1)
Block(-5,39,6,1)
Block(-5,39,7,1)
Block(-5,39,8,1)
Block(-5,40,-6,1)
Block(-5,40,-5,1)
Block(-5,40,-4,1)
Block(-5,40,-3,1)
Block(-5,40,-2,1)
Block(-5,40,-1,1)
Block(-5,40,0,1)
Block(-5,40,1,1)
Block(-5,40,2,1)
Block(-5,40,3,1)
Block(-5,40,4,1)
Block(-5,40,5,1)
Block(-5,40,6,1)
Block(-5,40,7,1)
Block(-5,40,8,1)
Block(-5,41,-6,1)
Block(-5,41,-5,1)
Block(-5,41,-4,1)
Block(-5,41,-3,1)
Block(-5,41,-2,1)
Block(-5,41,-1,1)
Block(-5,41,0,1)
Block(-5,41,1,1)
Block(-5,41,2,1)
Block(-5,41,3,1)
Block(-5,41,4,1)
Block(-5,41,5,1)
Block(-5,41,6,1)
Block(-5,41,7,1)
Block(-5,41,8,1)
Block(-5,42,-6,1)
Block(-5,42,-5,1)
Block(-5,42,-4,1)
Block(-5,42,-3,1)
Block(-5,42,-2,1)
Block(-5,42,-1,1)
Block(-5,42,0,1)
Block(-5,42,1,1)
Block(-5,42,2,1)
Block(-5,42,3,1)
Block(-5,42,4,1)
Block(-5,42,5,1)
Block(-5,42,6,1)
Block(-5,42,7,1)
Block(-5,43,-6,1)
Block(-5,43,-5,1)
Block(-5,43,-4,1)
Block(-5,43,-3,1)
Block(-5,43,-2,1)
Block(-5,43,-1,1)
Block(-5,43,0,1)
Block(-5,43,1,1)
Block(-5,43,2,1)
Block(-5,43,3,1)
Block(-5,43,4,1)
Block(-5,43,5,1)
Block(-5,43,6,1)
Block(-5,43,7,1)
Block(-5,44,-5,1)
Block(-5,44,-4,1)
Block(-5,44,-3,1)
Block(-5,44,-2,1)
Block(-5,44,-1,1)
Block(-5,44,0,1)
Block(-5,44,1,1)
Block(-5,44,2,1)
Block(-5,44,3,1)
Block(-5,44,4,1)
Block(-5,44,5,1)
Block(-5,44,6,1)
Block(-5,45,-4,1)
Block(-5,45,-3,1)
Block(-5,45,-2,1)
Block(-5,45,-1,1)
Block(-5,45,0,1)
Block(-5,45,1,1)
Block(-5,45,2,1)
Block(-5,45,3,1)
Block(-5,45,4,1)
Block(-5,45,5,1)
Block(-5,46,-4,1)
Block(-5,46,-3,1)
Block(-5,46,-2,1)
Block(-5,46,-1,1)
Block(-5,46,0,1)
Block(-5,46,1,1)
Block(-5,46,2,1)
Block(-5,46,3,1)
Block(-5,46,4,1)
Block(-5,46,5,1)
Block(-5,47,-4,1)
Block(-5,47,-3,1)
Block(-5,47,-2,1)
Block(-5,47,-1,1)
Block(-5,47,0,1)
Block(-5,47,1,1)
Block(-5,47,2,1)
Block(-5,47,3,1)
Block(-5,47,4,1)
Block(-5,47,5,1)
Block(-5,48,-4,1)
Block(-5,48,-3,1)
Block(-5,48,-2,1)
Block(-5,48,-1,1)
Block(-5,48,0,1)
Block(-5,48,1,1)
Block(-5,48,2,1)
Block(-5,48,3,1)
Block(-5,48,4,1)
Block(-5,48,5,1)
Block(-5,48,6,1)
Block(-5,49,-5,1)
Block(-5,49,-4,1)
Block(-5,49,-3,1)
Block(-5,49,-2,1)
Block(-5,49,-1,1)
Block(-5,49,0,1)
Block(-5,49,1,1)
Block(-5,49,2,1)
Block(-5,49,3,1)
Block(-5,49,4,1)
Block(-5,49,5,1)
Block(-5,49,6,1)
Block(-5,50,-6,1)
Block(-5,50,-5,1)
Block(-5,50,-4,1)
Block(-5,50,-3,1)
Block(-5,50,-2,1)
Block(-5,50,-1,1)
Block(-5,50,0,1)
Block(-5,50,1,1)
Block(-5,50,2,1)
Block(-5,50,3,1)
Block(-5,50,4,1)
Block(-5,50,5,1)
Block(-5,50,6,1)
Block(-5,50,7,1)
Block(-5,51,-6,1)
Block(-5,51,-5,1)
Block(-5,51,-4,1)
Block(-5,51,-3,1)
Block(-5,51,-2,1)
Block(-5,51,-1,1)
Block(-5,51,0,1)
Block(-5,51,1,1)
Block(-5,51,2,1)
Block(-5,51,3,1)
Block(-5,51,4,1)
Block(-5,51,5,1)
Block(-5,51,6,1)
Block(-5,51,7,1)
Block(-5,51,8,1)
Block(-5,52,-6,1)
Block(-5,52,-5,1)
Block(-5,52,-4,1)
Block(-5,52,-3,1)
Block(-5,52,-2,1)
Block(-5,52,-1,1)
Block(-5,52,0,1)
Block(-5,52,1,1)
Block(-5,52,2,1)
Block(-5,52,3,1)
Block(-5,52,4,1)
Block(-5,52,5,1)
Block(-5,52,6,1)
Block(-5,52,7,1)
Block(-5,52,8,1)
Block(-5,53,-6,1)
Block(-5,53,-5,1)
Block(-5,53,-4,1)
Block(-5,53,-3,1)
Block(-5,53,-2,1)
Block(-5,53,-1,1)
Block(-5,53,0,1)
Block(-5,53,1,1)
Block(-5,53,2,1)
Block(-5,53,3,1)
Block(-5,53,4,1)
Block(-5,53,5,1)
Block(-5,53,6,1)
Block(-5,53,7,1)
Block(-5,53,8,1)
Block(-5,54,-5,1)
Block(-5,54,-4,1)
Block(-5,54,-3,1)
Block(-5,54,-2,1)
Block(-5,54,-1,1)
Block(-5,54,0,1)
Block(-5,54,1,1)
Block(-5,54,2,1)
Block(-5,54,3,1)
Block(-5,54,4,1)
Block(-5,54,5,1)
Block(-5,54,6,1)
Block(-5,54,7,1)
Block(-5,54,8,1)
Block(-5,55,-5,1)
Block(-5,55,-4,1)
Block(-5,55,-3,1)
Block(-5,55,-2,1)
Block(-5,55,-1,1)
Block(-5,55,0,1)
Block(-5,55,1,1)
Block(-5,55,2,1)
Block(-5,55,3,1)
Block(-5,55,4,1)
Block(-5,55,5,1)
Block(-5,55,6,1)
Block(-5,55,7,1)
Block(-5,55,8,1)
Block(-5,56,-5,1)
Block(-5,56,-4,1)
Block(-5,56,-3,1)
Block(-5,56,-2,1)
Block(-5,56,-1,1)
Block(-5,56,0,1)
Block(-5,56,1,1)
Block(-5,56,2,1)
Block(-5,56,3,1)
Block(-5,56,4,1)
Block(-5,56,5,1)
Block(-5,56,6,1)
Block(-5,56,7,1)
Block(-5,56,8,1)
Block(-5,57,-6,1)
Block(-5,57,-5,1)
Block(-5,57,-4,1)
Block(-5,57,-3,1)
Block(-5,57,-2,1)
Block(-5,57,-1,1)
Block(-5,57,0,1)
Block(-5,57,1,1)
Block(-5,57,2,1)
Block(-5,57,3,1)
Block(-5,57,4,1)
Block(-5,57,5,1)
Block(-5,57,6,1)
Block(-5,57,7,1)
Block(-5,57,8,1)
Block(-5,58,-7,1)
Block(-5,58,-6,1)
Block(-5,58,-5,1)
Block(-5,58,-4,1)
Block(-5,58,-3,1)
Block(-5,58,-2,1)
Block(-5,58,-1,1)
Block(-5,58,0,1)
Block(-5,58,1,1)
Block(-5,58,2,1)
Block(-5,58,3,1)
Block(-5,58,4,1)
Block(-5,58,5,1)
Block(-5,58,6,1)
Block(-5,58,7,1)
Block(-5,58,8,1)
Block(-5,58,9,1)
Block(-5,59,-7,1)
Block(-5,59,-6,1)
Block(-5,59,-5,1)
Block(-5,59,-4,1)
Block(-5,59,-3,1)
Block(-5,59,-2,1)
Block(-5,59,-1,1)
Block(-5,59,0,1)
Block(-5,59,1,1)
Block(-5,59,2,1)
Block(-5,59,3,1)
Block(-5,59,4,1)
Block(-5,59,5,1)
Block(-5,59,6,1)
Block(-5,59,7,1)
Block(-5,59,8,1)
Block(-5,59,9,1)
Block(-5,60,-8,1)
Block(-5,60,-7,1)
Block(-5,60,-6,1)
Block(-5,60,-5,1)
Block(-5,60,-4,1)
Block(-5,60,-3,1)
Block(-5,60,-2,1)
Block(-5,60,-1,1)
Block(-5,60,0,1)
Block(-5,60,1,1)
Block(-5,60,2,1)
Block(-5,60,3,1)
Block(-5,60,4,1)
Block(-5,60,5,1)
Block(-5,60,6,1)
Block(-5,60,7,1)
Block(-5,60,8,1)
Block(-5,60,9,1)
Block(-5,61,-8,1)
Block(-5,61,-7,1)
Block(-5,61,-6,1)
Block(-5,61,-5,1)
Block(-5,61,-4,1)
Block(-5,61,-3,1)
Block(-5,61,-2,1)
Block(-5,61,-1,1)
Block(-5,61,0,1)
Block(-5,61,1,1)
Block(-5,61,2,1)
Block(-5,61,3,1)
Block(-5,61,4,1)
Block(-5,61,5,1)
Block(-5,61,6,1)
Block(-5,61,7,1)
Block(-5,61,8,1)
Block(-5,61,9,1)
Block(-5,62,-8,1)
Block(-5,62,-7,1)
Block(-5,62,-6,1)
Block(-5,62,-5,1)
Block(-5,62,-4,1)
Block(-5,62,-3,1)
Block(-5,62,-2,1)
Block(-5,62,-1,1)
Block(-5,62,0,1)
Block(-5,62,1,1)
Block(-5,62,2,1)
Block(-5,62,3,1)
Block(-5,62,4,1)
Block(-5,62,5,1)
Block(-5,62,6,1)
Block(-5,62,7,1)
Block(-5,62,8,1)
Block(-5,62,9,1)
Block(-5,63,-7,1)
Block(-5,63,-6,1)
Block(-5,63,-5,1)
Block(-5,63,-4,1)
Block(-5,63,-3,1)
Block(-5,63,-2,1)
Block(-5,63,-1,1)
Block(-5,63,0,1)
Block(-5,63,1,1)
Block(-5,63,2,1)
Block(-5,63,3,1)
Block(-5,63,4,1)
Block(-5,63,5,1)
Block(-5,63,6,1)
Block(-5,63,7,1)
Block(-5,63,8,1)
Block(-5,63,9,1)
Block(-5,64,-6,1)
Block(-5,64,-5,1)
Block(-5,64,-4,1)
Block(-5,64,-3,1)
Block(-5,64,-2,1)
Block(-5,64,-1,1)
Block(-5,64,0,1)
Block(-5,64,1,1)
Block(-5,64,2,1)
Block(-5,64,3,1)
Block(-5,64,4,1)
Block(-5,64,5,1)
Block(-5,64,6,1)
Block(-5,64,7,1)
Block(-5,64,8,1)
Block(-5,65,-5,1)
Block(-5,65,-4,1)
Block(-5,65,-3,1)
Block(-5,65,-2,1)
Block(-5,65,-1,1)
Block(-5,65,0,1)
Block(-5,65,1,1)
Block(-5,65,2,1)
Block(-5,65,3,1)
Block(-5,65,4,1)
Block(-5,65,5,1)
Block(-5,65,6,1)
Block(-5,65,7,1)
Block(-5,65,8,1)
Block(-5,66,-4,1)
Block(-5,66,-3,1)
Block(-5,66,-2,1)
Block(-5,66,-1,1)
Block(-5,66,0,1)
Block(-5,66,1,1)
Block(-5,66,2,1)
Block(-5,66,3,1)
Block(-5,66,4,1)
Block(-5,66,5,1)
Block(-5,66,6,1)
Block(-5,66,7,1)
Block(-5,67,-4,1)
Block(-5,67,-3,1)
Block(-5,67,-2,1)
Block(-5,67,-1,1)
Block(-5,67,0,1)
Block(-5,67,1,1)
Block(-5,67,2,1)
Block(-5,67,3,1)
Block(-5,67,4,1)
Block(-5,67,5,1)
Block(-5,67,6,1)
Block(-5,67,7,1)
Block(-5,68,-4,1)
Block(-5,68,-3,1)
Block(-5,68,-2,1)
Block(-5,68,-1,1)
Block(-5,68,0,1)
Block(-5,68,1,1)
Block(-5,68,2,1)
Block(-5,68,3,1)
Block(-5,68,4,1)
Block(-5,68,5,1)
Block(-5,68,6,1)
Block(-5,69,-4,1)
Block(-5,69,-3,1)
Block(-5,69,-2,1)
Block(-5,69,-1,1)
Block(-5,69,0,1)
Block(-5,69,1,1)
Block(-5,69,2,1)
Block(-5,69,3,1)
Block(-5,69,4,1)
Block(-5,69,5,1)
Block(-5,69,6,1)
Block(-5,70,-3,1)
Block(-5,70,-2,1)
Block(-5,70,-1,1)
Block(-5,70,0,1)
Block(-5,70,1,1)
Block(-5,70,2,1)
Block(-5,70,3,1)
Block(-5,70,4,1)
Block(-5,70,5,1)
Block(-5,70,6,1)
Block(-5,71,-3,1)
Block(-5,71,-2,1)
Block(-5,71,-1,1)
Block(-5,71,0,1)
Block(-5,71,1,1)
Block(-5,71,2,1)
Block(-5,71,3,1)
Block(-5,71,4,1)
Block(-5,71,5,1)
Block(-5,71,6,1)
Block(-5,71,7,1)
Block(-5,72,-3,1)
Block(-5,72,-2,1)
Block(-5,72,-1,1)
Block(-5,72,0,1)
Block(-5,72,1,1)
Block(-5,72,2,1)
Block(-5,72,3,1)
Block(-5,72,4,1)
Block(-5,72,5,1)
Block(-5,72,6,1)
Block(-5,72,7,1)
Block(-5,73,-3,1)
Block(-5,73,-2,1)
Block(-5,73,-1,1)
Block(-5,73,0,1)
Block(-5,73,1,1)
Block(-5,73,2,1)
Block(-5,73,3,1)
Block(-5,73,4,1)
Block(-5,73,5,1)
Block(-5,73,6,1)
Block(-5,73,7,1)
Block(-5,74,-3,1)
Block(-5,74,-2,1)
Block(-5,74,-1,1)
Block(-5,74,0,1)
Block(-5,74,1,1)
Block(-5,74,2,1)
Block(-5,74,3,1)
Block(-5,74,4,1)
Block(-5,74,5,1)
Block(-5,74,6,1)
Block(-5,74,7,1)
Block(-5,75,-3,1)
Block(-5,75,-2,1)
Block(-5,75,-1,1)
Block(-5,75,0,1)
Block(-5,75,1,1)
Block(-5,75,2,1)
Block(-5,75,3,1)
Block(-5,75,4,1)
Block(-5,75,5,1)
Block(-5,75,6,1)
Block(-5,76,-3,1)
Block(-5,76,-2,1)
Block(-5,76,-1,1)
Block(-5,76,0,1)
Block(-5,76,1,1)
Block(-5,76,2,1)
Block(-5,76,3,1)
Block(-5,76,4,1)
Block(-5,76,5,1)
Block(-5,76,6,1)
Block(-5,77,-3,1)
Block(-5,77,-2,1)
Block(-5,77,-1,1)
Block(-5,77,0,1)
Block(-5,77,1,1)
Block(-5,77,2,1)
Block(-5,77,3,1)
Block(-5,77,4,1)
Block(-5,77,5,1)
Block(-5,78,-3,1)
Block(-5,78,-2,1)
Block(-5,78,-1,1)
Block(-5,78,0,1)
Block(-5,78,1,1)
Block(-5,78,2,1)
Block(-5,78,3,1)
Block(-5,79,-3,1)
Block(-5,79,-2,1)
Block(-5,79,-1,1)
Block(-5,79,0,1)
Block(-5,79,1,1)
Block(-5,79,2,1)
Block(-5,80,-3,1)
Block(-5,80,-2,1)
Block(-5,80,-1,1)
Block(-5,80,0,1)
Block(-5,80,1,1)
Block(-5,81,-4,1)
Block(-5,81,-3,1)
Block(-5,81,-2,1)
Block(-5,81,-1,1)
Block(-5,81,0,1)
Block(-5,81,1,1)
Block(-5,82,-4,1)
Block(-5,82,-3,1)
Block(-5,82,-2,1)
Block(-5,82,-1,1)
Block(-5,82,0,1)
Block(-5,82,1,1)
Block(-5,82,2,1)
Block(-5,83,-4,1)
Block(-5,83,-3,1)
Block(-5,83,-2,1)
Block(-5,83,-1,1)
Block(-5,83,0,1)
Block(-5,83,1,1)
Block(-5,83,2,1)
Block(-5,83,3,1)
Block(-5,83,4,1)
Block(-5,83,5,1)
Block(-5,83,6,1)
Block(-5,84,-4,1)
Block(-5,84,-3,3)
Block(-5,84,-2,1)
Block(-5,84,-1,1)
Block(-5,84,0,1)
Block(-5,84,1,1)
Block(-5,84,2,1)
Block(-5,84,3,1)
Block(-5,84,4,1)
Block(-5,84,5,1)
Block(-5,84,6,1)
Block(-5,85,-4,1)
Block(-5,85,-3,1)
Block(-5,85,-2,3)
Block(-5,85,-1,1)
Block(-5,85,0,1)
Block(-5,85,1,1)
Block(-5,85,2,1)
Block(-5,85,3,1)
Block(-5,85,4,1)
Block(-5,85,5,1)
Block(-5,85,6,1)
Block(-5,86,-3,1)
Block(-5,86,-2,3)
Block(-5,86,-1,3)
Block(-5,86,0,1)
Block(-5,86,1,1)
Block(-5,86,2,1)
Block(-5,86,3,1)
Block(-5,86,4,3)
Block(-5,86,5,1)
Block(-5,86,6,1)
Block(-5,87,-3,1)
Block(-5,87,-2,1)
Block(-5,87,-1,3)
Block(-5,87,0,3)
Block(-5,87,1,3)
Block(-5,87,2,3)
Block(-5,87,3,3)
Block(-5,87,4,3)
Block(-5,87,5,1)
Block(-5,87,6,1)
Block(-5,88,-2,1)
Block(-5,88,-1,1)
Block(-5,88,0,3)
Block(-5,88,1,3)
Block(-5,88,2,3)
Block(-5,88,3,3)
Block(-5,88,4,1)
Block(-5,88,5,1)
Block(-5,89,-1,1)
Block(-5,89,0,3)
Block(-5,89,1,3)
Block(-5,89,2,3)
Block(-5,89,3,1)
Block(-5,89,4,1)
Block(-5,89,5,1)
Block(-5,90,0,1)
Block(-5,90,1,1)
Block(-5,90,2,1)
Block(-5,90,3,1)
Block(-4,0,-8,1)
Block(-4,0,-7,1)
Block(-4,0,-6,1)
Block(-4,0,-5,1)
Block(-4,0,-4,1)
Block(-4,0,-3,1)
Block(-4,0,-2,1)
Block(-4,0,-1,1)
Block(-4,0,0,1)
Block(-4,0,1,1)
Block(-4,0,2,1)
Block(-4,0,3,1)
Block(-4,0,4,1)
Block(-4,0,5,1)
Block(-4,0,6,1)
Block(-4,0,7,1)
Block(-4,0,8,1)
Block(-4,1,-7,1)
Block(-4,1,-6,1)
Block(-4,1,-5,1)
Block(-4,1,-4,1)
Block(-4,1,-3,1)
Block(-4,1,-2,1)
Block(-4,1,-1,1)
Block(-4,1,0,1)
Block(-4,1,1,1)
Block(-4,1,2,1)
Block(-4,1,3,1)
Block(-4,1,4,1)
Block(-4,1,5,1)
Block(-4,1,6,1)
Block(-4,1,7,1)
Block(-4,2,-7,1)
Block(-4,2,-6,1)
Block(-4,2,-5,1)
Block(-4,2,-4,1)
Block(-4,2,-3,1)
Block(-4,2,-2,1)
Block(-4,2,-1,1)
Block(-4,2,0,1)
Block(-4,2,1,1)
Block(-4,2,2,1)
Block(-4,2,3,1)
Block(-4,2,4,1)
Block(-4,2,5,1)
Block(-4,2,6,1)
Block(-4,2,7,1)
Block(-4,3,-7,1)
Block(-4,3,-6,1)
Block(-4,3,-5,1)
Block(-4,3,-4,1)
Block(-4,3,-3,1)
Block(-4,3,-2,1)
Block(-4,3,-1,1)
Block(-4,3,0,1)
Block(-4,3,1,1)
Block(-4,3,2,1)
Block(-4,3,3,1)
Block(-4,3,4,1)
Block(-4,3,5,1)
Block(-4,3,6,1)
Block(-4,3,7,1)
Block(-4,4,-6,1)
Block(-4,4,-5,1)
Block(-4,4,-4,1)
Block(-4,4,-3,1)
Block(-4,4,-2,1)
Block(-4,4,-1,1)
Block(-4,4,0,1)
Block(-4,4,1,1)
Block(-4,4,2,1)
Block(-4,4,3,1)
Block(-4,4,4,1)
Block(-4,4,5,1)
Block(-4,4,6,1)
Block(-4,4,7,1)
Block(-4,4,8,1)
Block(-4,5,-5,1)
Block(-4,5,-4,1)
Block(-4,5,-3,1)
Block(-4,5,-2,1)
Block(-4,5,-1,1)
Block(-4,5,0,1)
Block(-4,5,1,1)
Block(-4,5,2,1)
Block(-4,5,3,1)
Block(-4,5,4,1)
Block(-4,5,5,1)
Block(-4,5,6,1)
Block(-4,5,7,1)
Block(-4,5,8,1)
Block(-4,6,-5,1)
Block(-4,6,-4,1)
Block(-4,6,-3,1)
Block(-4,6,-2,1)
Block(-4,6,-1,1)
Block(-4,6,0,1)
Block(-4,6,1,1)
Block(-4,6,2,1)
Block(-4,6,3,1)
Block(-4,6,4,1)
Block(-4,6,5,1)
Block(-4,6,6,1)
Block(-4,6,7,1)
Block(-4,6,8,1)
Block(-4,7,-5,1)
Block(-4,7,-4,1)
Block(-4,7,-3,1)
Block(-4,7,-2,1)
Block(-4,7,-1,1)
Block(-4,7,0,1)
Block(-4,7,1,1)
Block(-4,7,2,1)
Block(-4,7,3,1)
Block(-4,7,4,1)
Block(-4,7,5,1)
Block(-4,7,6,1)
Block(-4,7,7,1)
Block(-4,7,8,1)
Block(-4,8,-5,1)
Block(-4,8,-4,1)
Block(-4,8,-3,1)
Block(-4,8,-2,1)
Block(-4,8,-1,1)
Block(-4,8,0,1)
Block(-4,8,1,1)
Block(-4,8,2,1)
Block(-4,8,3,1)
Block(-4,8,4,1)
Block(-4,8,5,1)
Block(-4,8,6,1)
Block(-4,8,7,1)
Block(-4,8,8,1)
Block(-4,9,-6,1)
Block(-4,9,-5,1)
Block(-4,9,-4,1)
Block(-4,9,-3,1)
Block(-4,9,-2,1)
Block(-4,9,-1,1)
Block(-4,9,0,1)
Block(-4,9,1,1)
Block(-4,9,2,1)
Block(-4,9,3,1)
Block(-4,9,4,1)
Block(-4,9,5,1)
Block(-4,9,6,1)
Block(-4,9,7,1)
Block(-4,9,8,1)
Block(-4,10,-6,1)
Block(-4,10,-5,1)
Block(-4,10,-4,1)
Block(-4,10,-3,1)
Block(-4,10,-2,1)
Block(-4,10,-1,1)
Block(-4,10,0,1)
Block(-4,10,1,1)
Block(-4,10,2,1)
Block(-4,10,3,1)
Block(-4,10,4,1)
Block(-4,10,5,1)
Block(-4,10,6,1)
Block(-4,10,7,1)
Block(-4,10,8,1)
Block(-4,10,9,1)
Block(-4,11,-6,1)
Block(-4,11,-5,1)
Block(-4,11,-4,1)
Block(-4,11,-3,1)
Block(-4,11,-2,1)
Block(-4,11,-1,1)
Block(-4,11,0,1)
Block(-4,11,1,1)
Block(-4,11,2,1)
Block(-4,11,3,1)
Block(-4,11,4,1)
Block(-4,11,5,1)
Block(-4,11,6,1)
Block(-4,11,7,1)
Block(-4,11,8,1)
Block(-4,11,9,1)
Block(-4,12,-6,1)
Block(-4,12,-5,1)
Block(-4,12,-4,1)
Block(-4,12,-3,1)
Block(-4,12,-2,1)
Block(-4,12,-1,1)
Block(-4,12,0,1)
Block(-4,12,1,1)
Block(-4,12,2,1)
Block(-4,12,3,1)
Block(-4,12,4,1)
Block(-4,12,5,1)
Block(-4,12,6,1)
Block(-4,12,7,1)
Block(-4,12,8,1)
Block(-4,12,9,1)
Block(-4,13,-6,1)
Block(-4,13,-5,1)
Block(-4,13,-4,1)
Block(-4,13,-3,1)
Block(-4,13,-2,1)
Block(-4,13,-1,1)
Block(-4,13,0,1)
Block(-4,13,1,1)
Block(-4,13,2,1)
Block(-4,13,3,1)
Block(-4,13,4,1)
Block(-4,13,5,1)
Block(-4,13,6,1)
Block(-4,13,7,1)
Block(-4,13,8,1)
Block(-4,13,9,1)
Block(-4,14,-6,1)
Block(-4,14,-5,1)
Block(-4,14,-4,1)
Block(-4,14,-3,1)
Block(-4,14,-2,1)
Block(-4,14,-1,1)
Block(-4,14,0,1)
Block(-4,14,1,1)
Block(-4,14,2,1)
Block(-4,14,3,1)
Block(-4,14,4,1)
Block(-4,14,5,1)
Block(-4,14,6,1)
Block(-4,14,7,1)
Block(-4,14,8,1)
Block(-4,14,9,1)
Block(-4,15,-6,1)
Block(-4,15,-5,1)
Block(-4,15,-4,1)
Block(-4,15,-3,1)
Block(-4,15,-2,1)
Block(-4,15,-1,1)
Block(-4,15,0,1)
Block(-4,15,1,1)
Block(-4,15,2,1)
Block(-4,15,3,1)
Block(-4,15,4,1)
Block(-4,15,5,1)
Block(-4,15,6,1)
Block(-4,15,7,1)
Block(-4,15,8,1)
Block(-4,16,-7,1)
Block(-4,16,-6,1)
Block(-4,16,-5,1)
Block(-4,16,-4,1)
Block(-4,16,-3,1)
Block(-4,16,-2,1)
Block(-4,16,-1,1)
Block(-4,16,0,1)
Block(-4,16,1,1)
Block(-4,16,2,1)
Block(-4,16,3,1)
Block(-4,16,4,1)
Block(-4,16,5,1)
Block(-4,16,6,1)
Block(-4,16,7,1)
Block(-4,17,-7,1)
Block(-4,17,-6,1)
Block(-4,17,-5,1)
Block(-4,17,-4,1)
Block(-4,17,-3,1)
Block(-4,17,-2,1)
Block(-4,17,-1,1)
Block(-4,17,0,1)
Block(-4,17,1,1)
Block(-4,17,2,1)
Block(-4,17,3,1)
Block(-4,17,4,1)
Block(-4,17,5,1)
Block(-4,17,6,1)
Block(-4,18,-8,1)
Block(-4,18,-7,1)
Block(-4,18,-6,1)
Block(-4,18,-5,1)
Block(-4,18,-4,1)
Block(-4,18,-3,1)
Block(-4,18,-2,1)
Block(-4,18,-1,1)
Block(-4,18,0,1)
Block(-4,18,1,1)
Block(-4,18,2,1)
Block(-4,18,3,1)
Block(-4,18,4,1)
Block(-4,18,5,1)
Block(-4,18,6,1)
Block(-4,19,-8,1)
Block(-4,19,-7,1)
Block(-4,19,-6,1)
Block(-4,19,-5,1)
Block(-4,19,-4,1)
Block(-4,19,-3,1)
Block(-4,19,-2,1)
Block(-4,19,-1,1)
Block(-4,19,0,1)
Block(-4,19,1,1)
Block(-4,19,2,1)
Block(-4,19,3,1)
Block(-4,19,4,1)
Block(-4,19,5,1)
Block(-4,19,6,1)
Block(-4,19,7,1)
Block(-4,20,-8,1)
Block(-4,20,-7,1)
Block(-4,20,-6,1)
Block(-4,20,-5,1)
Block(-4,20,-4,1)
Block(-4,20,-3,1)
Block(-4,20,-2,1)
Block(-4,20,-1,1)
Block(-4,20,0,1)
Block(-4,20,1,1)
Block(-4,20,2,1)
Block(-4,20,3,1)
Block(-4,20,4,1)
Block(-4,20,5,1)
Block(-4,20,6,1)
Block(-4,20,7,1)
Block(-4,21,-8,1)
Block(-4,21,-7,1)
Block(-4,21,-6,1)
Block(-4,21,-5,1)
Block(-4,21,-4,1)
Block(-4,21,-3,1)
Block(-4,21,-2,1)
Block(-4,21,-1,1)
Block(-4,21,0,1)
Block(-4,21,1,1)
Block(-4,21,2,1)
Block(-4,21,3,1)
Block(-4,21,4,1)
Block(-4,21,5,1)
Block(-4,21,6,1)
Block(-4,21,7,1)
Block(-4,21,8,1)
Block(-4,22,-7,1)
Block(-4,22,-6,1)
Block(-4,22,-5,1)
Block(-4,22,-4,1)
Block(-4,22,-3,1)
Block(-4,22,-2,1)
Block(-4,22,-1,1)
Block(-4,22,0,1)
Block(-4,22,1,1)
Block(-4,22,2,1)
Block(-4,22,3,1)
Block(-4,22,4,1)
Block(-4,22,5,1)
Block(-4,22,6,1)
Block(-4,22,7,1)
Block(-4,22,8,1)
Block(-4,23,-6,1)
Block(-4,23,-5,1)
Block(-4,23,-4,1)
Block(-4,23,-3,1)
Block(-4,23,-2,1)
Block(-4,23,-1,1)
Block(-4,23,0,1)
Block(-4,23,1,1)
Block(-4,23,2,1)
Block(-4,23,3,1)
Block(-4,23,4,1)
Block(-4,23,5,1)
Block(-4,23,6,1)
Block(-4,23,7,1)
Block(-4,23,8,1)
Block(-4,24,-6,1)
Block(-4,24,-5,1)
Block(-4,24,-4,1)
Block(-4,24,-3,1)
Block(-4,24,-2,1)
Block(-4,24,-1,1)
Block(-4,24,0,1)
Block(-4,24,1,1)
Block(-4,24,2,1)
Block(-4,24,3,1)
Block(-4,24,4,1)
Block(-4,24,5,1)
Block(-4,24,6,1)
Block(-4,24,7,1)
Block(-4,24,8,1)
Block(-4,25,-5,1)
Block(-4,25,-4,1)
Block(-4,25,-3,1)
Block(-4,25,-2,1)
Block(-4,25,-1,1)
Block(-4,25,0,1)
Block(-4,25,1,1)
Block(-4,25,2,1)
Block(-4,25,3,1)
Block(-4,25,4,1)
Block(-4,25,5,1)
Block(-4,25,6,1)
Block(-4,25,7,1)
Block(-4,26,-5,1)
Block(-4,26,-4,1)
Block(-4,26,-3,1)
Block(-4,26,-2,1)
Block(-4,26,-1,1)
Block(-4,26,0,1)
Block(-4,26,1,1)
Block(-4,26,2,1)
Block(-4,26,3,1)
Block(-4,26,4,1)
Block(-4,26,5,1)
Block(-4,26,6,1)
Block(-4,26,7,1)
Block(-4,27,-5,1)
Block(-4,27,-4,1)
Block(-4,27,-3,1)
Block(-4,27,-2,1)
Block(-4,27,-1,1)
Block(-4,27,0,1)
Block(-4,27,1,1)
Block(-4,27,2,1)
Block(-4,27,3,1)
Block(-4,27,4,1)
Block(-4,27,5,1)
Block(-4,27,6,1)
Block(-4,27,7,1)
Block(-4,28,-5,1)
Block(-4,28,-4,1)
Block(-4,28,-3,1)
Block(-4,28,-2,1)
Block(-4,28,-1,1)
Block(-4,28,0,1)
Block(-4,28,1,1)
Block(-4,28,2,1)
Block(-4,28,3,1)
Block(-4,28,4,1)
Block(-4,28,5,1)
Block(-4,28,6,1)
Block(-4,28,7,1)
Block(-4,28,8,1)
Block(-4,29,-5,1)
Block(-4,29,-4,1)
Block(-4,29,-3,1)
Block(-4,29,-2,1)
Block(-4,29,-1,1)
Block(-4,29,0,1)
Block(-4,29,1,1)
Block(-4,29,2,1)
Block(-4,29,3,1)
Block(-4,29,4,1)
Block(-4,29,5,1)
Block(-4,29,6,1)
Block(-4,29,7,1)
Block(-4,29,8,1)
Block(-4,30,-5,1)
Block(-4,30,-4,1)
Block(-4,30,-3,1)
Block(-4,30,-2,1)
Block(-4,30,-1,1)
Block(-4,30,0,1)
Block(-4,30,1,1)
Block(-4,30,2,1)
Block(-4,30,3,1)
Block(-4,30,4,1)
Block(-4,30,5,1)
Block(-4,30,6,1)
Block(-4,30,7,1)
Block(-4,30,8,1)
Block(-4,30,9,1)
Block(-4,31,-4,1)
Block(-4,31,-3,1)
Block(-4,31,-2,1)
Block(-4,31,-1,1)
Block(-4,31,0,1)
Block(-4,31,1,1)
Block(-4,31,2,1)
Block(-4,31,3,1)
Block(-4,31,4,1)
Block(-4,31,5,1)
Block(-4,31,6,1)
Block(-4,31,7,1)
Block(-4,31,8,1)
Block(-4,31,9,1)
Block(-4,31,10,1)
Block(-4,32,-4,1)
Block(-4,32,-3,1)
Block(-4,32,-2,1)
Block(-4,32,-1,1)
Block(-4,32,0,1)
Block(-4,32,1,1)
Block(-4,32,2,1)
Block(-4,32,3,1)
Block(-4,32,4,1)
Block(-4,32,5,1)
Block(-4,32,6,1)
Block(-4,32,7,1)
Block(-4,32,8,1)
Block(-4,32,9,1)
Block(-4,32,10,1)
Block(-4,33,-4,1)
Block(-4,33,-3,1)
Block(-4,33,-2,1)
Block(-4,33,-1,1)
Block(-4,33,0,1)
Block(-4,33,1,1)
Block(-4,33,2,1)
Block(-4,33,3,1)
Block(-4,33,4,1)
Block(-4,33,5,1)
Block(-4,33,6,1)
Block(-4,33,7,1)
Block(-4,33,8,1)
Block(-4,33,9,1)
Block(-4,34,-4,1)
Block(-4,34,-3,1)
Block(-4,34,-2,1)
Block(-4,34,-1,1)
Block(-4,34,0,1)
Block(-4,34,1,1)
Block(-4,34,2,1)
Block(-4,34,3,1)
Block(-4,34,4,1)
Block(-4,34,5,1)
Block(-4,34,6,1)
Block(-4,34,7,1)
Block(-4,34,8,1)
Block(-4,34,9,1)
Block(-4,35,-4,1)
Block(-4,35,-3,1)
Block(-4,35,-2,1)
Block(-4,35,-1,1)
Block(-4,35,0,1)
Block(-4,35,1,1)
Block(-4,35,2,1)
Block(-4,35,3,1)
Block(-4,35,4,1)
Block(-4,35,5,1)
Block(-4,35,6,1)
Block(-4,35,7,1)
Block(-4,35,8,1)
Block(-4,35,9,1)
Block(-4,36,-5,1)
Block(-4,36,-4,1)
Block(-4,36,-3,1)
Block(-4,36,-2,1)
Block(-4,36,-1,1)
Block(-4,36,0,1)
Block(-4,36,1,1)
Block(-4,36,2,1)
Block(-4,36,3,1)
Block(-4,36,4,1)
Block(-4,36,5,1)
Block(-4,36,6,1)
Block(-4,36,7,1)
Block(-4,36,8,1)
Block(-4,37,-6,1)
Block(-4,37,-5,1)
Block(-4,37,-4,1)
Block(-4,37,-3,1)
Block(-4,37,-2,1)
Block(-4,37,-1,1)
Block(-4,37,0,1)
Block(-4,37,1,1)
Block(-4,37,2,1)
Block(-4,37,3,1)
Block(-4,37,4,1)
Block(-4,37,5,1)
Block(-4,37,6,1)
Block(-4,37,7,1)
Block(-4,37,8,1)
Block(-4,38,-6,1)
Block(-4,38,-5,1)
Block(-4,38,-4,1)
Block(-4,38,-3,1)
Block(-4,38,-2,1)
Block(-4,38,-1,1)
Block(-4,38,0,1)
Block(-4,38,1,1)
Block(-4,38,2,1)
Block(-4,38,3,1)
Block(-4,38,4,1)
Block(-4,38,5,1)
Block(-4,38,6,1)
Block(-4,38,7,1)
Block(-4,38,8,1)
Block(-4,39,-7,1)
Block(-4,39,-6,1)
Block(-4,39,-5,1)
Block(-4,39,-4,1)
Block(-4,39,-3,1)
Block(-4,39,-2,1)
Block(-4,39,-1,1)
Block(-4,39,0,1)
Block(-4,39,1,1)
Block(-4,39,2,1)
Block(-4,39,3,1)
Block(-4,39,4,1)
Block(-4,39,5,1)
Block(-4,39,6,1)
Block(-4,39,7,1)
Block(-4,39,8,1)
Block(-4,39,9,1)
Block(-4,40,-7,1)
Block(-4,40,-6,1)
Block(-4,40,-5,1)
Block(-4,40,-4,1)
Block(-4,40,-3,1)
Block(-4,40,-2,1)
Block(-4,40,-1,1)
Block(-4,40,0,1)
Block(-4,40,1,1)
Block(-4,40,2,1)
Block(-4,40,3,1)
Block(-4,40,4,1)
Block(-4,40,5,1)
Block(-4,40,6,1)
Block(-4,40,7,1)
Block(-4,40,8,1)
Block(-4,40,9,1)
Block(-4,41,-7,1)
Block(-4,41,-6,1)
Block(-4,41,-5,1)
Block(-4,41,-4,1)
Block(-4,41,-3,1)
Block(-4,41,-2,1)
Block(-4,41,-1,1)
Block(-4,41,0,1)
Block(-4,41,1,1)
Block(-4,41,2,1)
Block(-4,41,3,1)
Block(-4,41,4,1)
Block(-4,41,5,1)
Block(-4,41,6,1)
Block(-4,41,7,1)
Block(-4,41,8,1)
Block(-4,41,9,1)
Block(-4,42,-7,1)
Block(-4,42,-6,1)
Block(-4,42,-5,1)
Block(-4,42,-4,1)
Block(-4,42,-3,1)
Block(-4,42,-2,1)
Block(-4,42,-1,1)
Block(-4,42,0,1)
Block(-4,42,1,1)
Block(-4,42,2,1)
Block(-4,42,3,1)
Block(-4,42,4,1)
Block(-4,42,5,1)
Block(-4,42,6,1)
Block(-4,42,7,1)
Block(-4,42,8,1)
Block(-4,43,-7,1)
Block(-4,43,-6,1)
Block(-4,43,-5,1)
Block(-4,43,-4,1)
Block(-4,43,-3,1)
Block(-4,43,-2,1)
Block(-4,43,-1,1)
Block(-4,43,0,1)
Block(-4,43,1,1)
Block(-4,43,2,1)
Block(-4,43,3,1)
Block(-4,43,4,1)
Block(-4,43,5,1)
Block(-4,43,6,1)
Block(-4,43,7,1)
Block(-4,43,8,1)
Block(-4,44,-6,1)
Block(-4,44,-5,1)
Block(-4,44,-4,1)
Block(-4,44,-3,1)
Block(-4,44,-2,1)
Block(-4,44,-1,1)
Block(-4,44,0,1)
Block(-4,44,1,1)
Block(-4,44,2,1)
Block(-4,44,3,1)
Block(-4,44,4,1)
Block(-4,44,5,1)
Block(-4,44,6,1)
Block(-4,44,7,1)
Block(-4,45,-5,1)
Block(-4,45,-4,1)
Block(-4,45,-3,1)
Block(-4,45,-2,1)
Block(-4,45,-1,1)
Block(-4,45,0,1)
Block(-4,45,1,1)
Block(-4,45,2,1)
Block(-4,45,3,1)
Block(-4,45,4,1)
Block(-4,45,5,1)
Block(-4,45,6,1)
Block(-4,46,-5,1)
Block(-4,46,-4,1)
Block(-4,46,-3,1)
Block(-4,46,-2,1)
Block(-4,46,-1,1)
Block(-4,46,0,1)
Block(-4,46,1,1)
Block(-4,46,2,1)
Block(-4,46,3,1)
Block(-4,46,4,1)
Block(-4,46,5,1)
Block(-4,46,6,1)
Block(-4,47,-5,1)
Block(-4,47,-4,1)
Block(-4,47,-3,1)
Block(-4,47,-2,1)
Block(-4,47,-1,1)
Block(-4,47,0,1)
Block(-4,47,1,1)
Block(-4,47,2,1)
Block(-4,47,3,1)
Block(-4,47,4,1)
Block(-4,47,5,1)
Block(-4,47,6,1)
Block(-4,48,-6,1)
Block(-4,48,-5,1)
Block(-4,48,-4,1)
Block(-4,48,-3,1)
Block(-4,48,-2,1)
Block(-4,48,-1,1)
Block(-4,48,0,1)
Block(-4,48,1,1)
Block(-4,48,2,1)
Block(-4,48,3,1)
Block(-4,48,4,1)
Block(-4,48,5,1)
Block(-4,48,6,1)
Block(-4,48,7,1)
Block(-4,49,-6,1)
Block(-4,49,-5,1)
Block(-4,49,-4,1)
Block(-4,49,-3,1)
Block(-4,49,-2,1)
Block(-4,49,-1,1)
Block(-4,49,0,1)
Block(-4,49,1,1)
Block(-4,49,2,1)
Block(-4,49,3,1)
Block(-4,49,4,1)
Block(-4,49,5,1)
Block(-4,49,6,1)
Block(-4,49,7,1)
Block(-4,49,8,1)
Block(-4,50,-7,1)
Block(-4,50,-6,1)
Block(-4,50,-5,1)
Block(-4,50,-4,1)
Block(-4,50,-3,1)
Block(-4,50,-2,1)
Block(-4,50,-1,1)
Block(-4,50,0,1)
Block(-4,50,1,1)
Block(-4,50,2,1)
Block(-4,50,3,1)
Block(-4,50,4,1)
Block(-4,50,5,1)
Block(-4,50,6,1)
Block(-4,50,7,1)
Block(-4,50,8,1)
Block(-4,51,-7,1)
Block(-4,51,-6,1)
Block(-4,51,-5,1)
Block(-4,51,-4,1)
Block(-4,51,-3,1)
Block(-4,51,-2,1)
Block(-4,51,-1,1)
Block(-4,51,0,1)
Block(-4,51,1,1)
Block(-4,51,2,1)
Block(-4,51,3,1)
Block(-4,51,4,1)
Block(-4,51,5,1)
Block(-4,51,6,1)
Block(-4,51,7,1)
Block(-4,51,8,1)
Block(-4,51,9,1)
Block(-4,52,-7,1)
Block(-4,52,-6,1)
Block(-4,52,-5,1)
Block(-4,52,-4,1)
Block(-4,52,-3,1)
Block(-4,52,-2,1)
Block(-4,52,-1,1)
Block(-4,52,0,1)
Block(-4,52,1,1)
Block(-4,52,2,1)
Block(-4,52,3,1)
Block(-4,52,4,1)
Block(-4,52,5,1)
Block(-4,52,6,1)
Block(-4,52,7,1)
Block(-4,52,8,1)
Block(-4,52,9,1)
Block(-4,53,-7,1)
Block(-4,53,-6,1)
Block(-4,53,-5,1)
Block(-4,53,-4,1)
Block(-4,53,-3,1)
Block(-4,53,-2,1)
Block(-4,53,-1,1)
Block(-4,53,0,1)
Block(-4,53,1,1)
Block(-4,53,2,1)
Block(-4,53,3,1)
Block(-4,53,4,1)
Block(-4,53,5,1)
Block(-4,53,6,1)
Block(-4,53,7,1)
Block(-4,53,8,1)
Block(-4,53,9,1)
Block(-4,54,-6,1)
Block(-4,54,-5,1)
Block(-4,54,-4,1)
Block(-4,54,-3,1)
Block(-4,54,-2,1)
Block(-4,54,-1,1)
Block(-4,54,0,1)
Block(-4,54,1,1)
Block(-4,54,2,1)
Block(-4,54,3,1)
Block(-4,54,4,1)
Block(-4,54,5,1)
Block(-4,54,6,1)
Block(-4,54,7,1)
Block(-4,54,8,1)
Block(-4,54,9,1)
Block(-4,55,-6,1)
Block(-4,55,-5,1)
Block(-4,55,-4,1)
Block(-4,55,-3,1)
Block(-4,55,-2,1)
Block(-4,55,-1,1)
Block(-4,55,0,1)
Block(-4,55,1,1)
Block(-4,55,2,1)
Block(-4,55,3,1)
Block(-4,55,4,1)
Block(-4,55,5,1)
Block(-4,55,6,1)
Block(-4,55,7,1)
Block(-4,55,8,1)
Block(-4,56,-6,1)
Block(-4,56,-5,1)
Block(-4,56,-4,1)
Block(-4,56,-3,1)
Block(-4,56,-2,1)
Block(-4,56,-1,1)
Block(-4,56,0,1)
Block(-4,56,1,1)
Block(-4,56,2,1)
Block(-4,56,3,1)
Block(-4,56,4,1)
Block(-4,56,5,1)
Block(-4,56,6,1)
Block(-4,56,7,1)
Block(-4,56,8,1)
Block(-4,57,-7,1)
Block(-4,57,-6,1)
Block(-4,57,-5,1)
Block(-4,57,-4,1)
Block(-4,57,-3,1)
Block(-4,57,-2,1)
Block(-4,57,-1,1)
Block(-4,57,0,1)
Block(-4,57,1,1)
Block(-4,57,2,1)
Block(-4,57,3,1)
Block(-4,57,4,1)
Block(-4,57,5,1)
Block(-4,57,6,1)
Block(-4,57,7,1)
Block(-4,57,8,1)
Block(-4,57,9,1)
Block(-4,58,-8,1)
Block(-4,58,-7,1)
Block(-4,58,-6,1)
Block(-4,58,-5,1)
Block(-4,58,-4,1)
Block(-4,58,-3,1)
Block(-4,58,-2,1)
Block(-4,58,-1,1)
Block(-4,58,0,1)
Block(-4,58,1,1)
Block(-4,58,2,1)
Block(-4,58,3,1)
Block(-4,58,4,1)
Block(-4,58,5,1)
Block(-4,58,6,1)
Block(-4,58,7,1)
Block(-4,58,8,1)
Block(-4,58,9,1)
Block(-4,59,-8,1)
Block(-4,59,-7,1)
Block(-4,59,-6,1)
Block(-4,59,-5,1)
Block(-4,59,-4,1)
Block(-4,59,-3,1)
Block(-4,59,-2,1)
Block(-4,59,-1,1)
Block(-4,59,0,1)
Block(-4,59,1,1)
Block(-4,59,2,1)
Block(-4,59,3,1)
Block(-4,59,4,1)
Block(-4,59,5,1)
Block(-4,59,6,1)
Block(-4,59,7,1)
Block(-4,59,8,1)
Block(-4,59,9,1)
Block(-4,59,10,1)
Block(-4,60,-9,1)
Block(-4,60,-8,1)
Block(-4,60,-7,1)
Block(-4,60,-6,1)
Block(-4,60,-5,1)
Block(-4,60,-4,1)
Block(-4,60,-3,1)
Block(-4,60,-2,1)
Block(-4,60,-1,1)
Block(-4,60,0,1)
Block(-4,60,1,1)
Block(-4,60,2,1)
Block(-4,60,3,1)
Block(-4,60,4,1)
Block(-4,60,5,1)
Block(-4,60,6,1)
Block(-4,60,7,1)
Block(-4,60,8,1)
Block(-4,60,9,1)
Block(-4,60,10,1)
Block(-4,61,-9,1)
Block(-4,61,-8,1)
Block(-4,61,-7,1)
Block(-4,61,-6,1)
Block(-4,61,-5,1)
Block(-4,61,-4,1)
Block(-4,61,-3,1)
Block(-4,61,-2,1)
Block(-4,61,-1,1)
Block(-4,61,0,1)
Block(-4,61,1,1)
Block(-4,61,2,1)
Block(-4,61,3,1)
Block(-4,61,4,1)
Block(-4,61,5,1)
Block(-4,61,6,1)
Block(-4,61,7,1)
Block(-4,61,8,1)
Block(-4,61,9,1)
Block(-4,61,10,1)
Block(-4,62,-9,1)
Block(-4,62,-8,1)
Block(-4,62,-7,1)
Block(-4,62,-6,1)
Block(-4,62,-5,1)
Block(-4,62,-4,1)
Block(-4,62,-3,1)
Block(-4,62,-2,1)
Block(-4,62,-1,1)
Block(-4,62,0,1)
Block(-4,62,1,1)
Block(-4,62,2,1)
Block(-4,62,3,1)
Block(-4,62,4,1)
Block(-4,62,5,1)
Block(-4,62,6,1)
Block(-4,62,7,1)
Block(-4,62,8,1)
Block(-4,62,9,1)
Block(-4,63,-9,1)
Block(-4,63,-8,1)
Block(-4,63,-7,1)
Block(-4,63,-6,1)
Block(-4,63,-5,1)
Block(-4,63,-4,1)
Block(-4,63,-3,1)
Block(-4,63,-2,1)
Block(-4,63,-1,1)
Block(-4,63,0,1)
Block(-4,63,1,1)
Block(-4,63,2,1)
Block(-4,63,3,1)
Block(-4,63,4,1)
Block(-4,63,5,1)
Block(-4,63,6,1)
Block(-4,63,7,1)
Block(-4,63,8,1)
Block(-4,63,9,1)
Block(-4,64,-8,1)
Block(-4,64,-7,1)
Block(-4,64,-6,1)
Block(-4,64,-5,1)
Block(-4,64,-4,1)
Block(-4,64,-3,1)
Block(-4,64,-2,1)
Block(-4,64,-1,1)
Block(-4,64,0,1)
Block(-4,64,1,1)
Block(-4,64,2,1)
Block(-4,64,3,1)
Block(-4,64,4,1)
Block(-4,64,5,1)
Block(-4,64,6,1)
Block(-4,64,7,1)
Block(-4,64,8,1)
Block(-4,65,-7,1)
Block(-4,65,-6,1)
Block(-4,65,-5,1)
Block(-4,65,-4,1)
Block(-4,65,-3,1)
Block(-4,65,-2,1)
Block(-4,65,-1,1)
Block(-4,65,0,1)
Block(-4,65,1,1)
Block(-4,65,2,1)
Block(-4,65,3,1)
Block(-4,65,4,1)
Block(-4,65,5,1)
Block(-4,65,6,1)
Block(-4,65,7,1)
Block(-4,65,8,1)
Block(-4,66,-7,1)
Block(-4,66,-6,1)
Block(-4,66,-5,1)
Block(-4,66,-4,1)
Block(-4,66,-3,1)
Block(-4,66,-2,1)
Block(-4,66,-1,1)
Block(-4,66,0,1)
Block(-4,66,1,1)
Block(-4,66,2,1)
Block(-4,66,3,1)
Block(-4,66,4,1)
Block(-4,66,5,1)
Block(-4,66,6,1)
Block(-4,66,7,1)
Block(-4,66,8,1)
Block(-4,67,-7,1)
Block(-4,67,-6,1)
Block(-4,67,-5,1)
Block(-4,67,-4,1)
Block(-4,67,-3,1)
Block(-4,67,-2,1)
Block(-4,67,-1,1)
Block(-4,67,0,1)
Block(-4,67,1,1)
Block(-4,67,2,1)
Block(-4,67,3,1)
Block(-4,67,4,1)
Block(-4,67,5,1)
Block(-4,67,6,1)
Block(-4,67,7,1)
Block(-4,68,-7,1)
Block(-4,68,-6,1)
Block(-4,68,-5,1)
Block(-4,68,-4,1)
Block(-4,68,-3,1)
Block(-4,68,-2,1)
Block(-4,68,-1,1)
Block(-4,68,0,1)
Block(-4,68,1,1)
Block(-4,68,2,1)
Block(-4,68,3,1)
Block(-4,68,4,1)
Block(-4,68,5,1)
Block(-4,68,6,1)
Block(-4,68,7,1)
Block(-4,69,-7,1)
Block(-4,69,-6,1)
Block(-4,69,-5,1)
Block(-4,69,-4,1)
Block(-4,69,-3,1)
Block(-4,69,-2,1)
Block(-4,69,-1,1)
Block(-4,69,0,1)
Block(-4,69,1,1)
Block(-4,69,2,1)
Block(-4,69,3,1)
Block(-4,69,4,1)
Block(-4,69,5,1)
Block(-4,69,6,1)
Block(-4,69,7,1)
Block(-4,70,-7,1)
Block(-4,70,-6,1)
Block(-4,70,-5,1)
Block(-4,70,-4,1)
Block(-4,70,-3,1)
Block(-4,70,-2,1)
Block(-4,70,-1,1)
Block(-4,70,0,1)
Block(-4,70,1,1)
Block(-4,70,2,1)
Block(-4,70,3,1)
Block(-4,70,4,1)
Block(-4,70,5,1)
Block(-4,70,6,1)
Block(-4,70,7,1)
Block(-4,70,8,1)
Block(-4,71,-7,1)
Block(-4,71,-6,1)
Block(-4,71,-5,1)
Block(-4,71,-4,1)
Block(-4,71,-3,1)
Block(-4,71,-2,1)
Block(-4,71,-1,1)
Block(-4,71,0,1)
Block(-4,71,1,1)
Block(-4,71,2,1)
Block(-4,71,3,1)
Block(-4,71,4,1)
Block(-4,71,5,1)
Block(-4,71,6,1)
Block(-4,71,7,1)
Block(-4,71,8,1)
Block(-4,72,-7,1)
Block(-4,72,-6,1)
Block(-4,72,-5,1)
Block(-4,72,-4,1)
Block(-4,72,-3,1)
Block(-4,72,-2,1)
Block(-4,72,-1,1)
Block(-4,72,0,1)
Block(-4,72,1,1)
Block(-4,72,2,1)
Block(-4,72,3,1)
Block(-4,72,4,1)
Block(-4,72,5,1)
Block(-4,72,6,1)
Block(-4,72,7,1)
Block(-4,72,8,1)
Block(-4,73,-7,1)
Block(-4,73,-6,1)
Block(-4,73,-5,1)
Block(-4,73,-4,1)
Block(-4,73,-3,1)
Block(-4,73,-2,1)
Block(-4,73,-1,1)
Block(-4,73,0,1)
Block(-4,73,1,1)
Block(-4,73,2,1)
Block(-4,73,3,1)
Block(-4,73,4,1)
Block(-4,73,5,1)
Block(-4,73,6,1)
Block(-4,73,7,1)
Block(-4,73,8,1)
Block(-4,74,-7,1)
Block(-4,74,-6,1)
Block(-4,74,-5,1)
Block(-4,74,-4,1)
Block(-4,74,-3,1)
Block(-4,74,-2,1)
Block(-4,74,-1,1)
Block(-4,74,0,1)
Block(-4,74,1,1)
Block(-4,74,2,1)
Block(-4,74,3,1)
Block(-4,74,4,1)
Block(-4,74,5,1)
Block(-4,74,6,1)
Block(-4,74,7,1)
Block(-4,74,8,1)
Block(-4,75,-6,1)
Block(-4,75,-5,1)
Block(-4,75,-4,1)
Block(-4,75,-3,1)
Block(-4,75,-2,1)
Block(-4,75,-1,1)
Block(-4,75,0,1)
Block(-4,75,1,1)
Block(-4,75,2,1)
Block(-4,75,3,1)
Block(-4,75,4,1)
Block(-4,75,5,1)
Block(-4,75,6,1)
Block(-4,75,7,1)
Block(-4,76,-6,1)
Block(-4,76,-5,1)
Block(-4,76,-4,1)
Block(-4,76,-3,1)
Block(-4,76,-2,1)
Block(-4,76,-1,1)
Block(-4,76,0,1)
Block(-4,76,1,1)
Block(-4,76,2,1)
Block(-4,76,3,1)
Block(-4,76,4,1)
Block(-4,76,5,1)
Block(-4,76,6,1)
Block(-4,76,7,1)
Block(-4,77,-5,1)
Block(-4,77,-4,1)
Block(-4,77,-3,1)
Block(-4,77,-2,1)
Block(-4,77,-1,1)
Block(-4,77,0,1)
Block(-4,77,1,1)
Block(-4,77,2,1)
Block(-4,77,3,1)
Block(-4,77,4,1)
Block(-4,77,5,1)
Block(-4,77,6,1)
Block(-4,78,-5,1)
Block(-4,78,-4,1)
Block(-4,78,-3,1)
Block(-4,78,-2,1)
Block(-4,78,-1,1)
Block(-4,78,0,1)
Block(-4,78,1,1)
Block(-4,78,2,1)
Block(-4,78,3,1)
Block(-4,78,4,1)
Block(-4,78,5,1)
Block(-4,79,-5,1)
Block(-4,79,-4,1)
Block(-4,79,-3,1)
Block(-4,79,-2,1)
Block(-4,79,-1,1)
Block(-4,79,0,1)
Block(-4,79,1,1)
Block(-4,79,2,1)
Block(-4,79,3,1)
Block(-4,79,4,1)
Block(-4,79,5,1)
Block(-4,80,-5,1)
Block(-4,80,-4,1)
Block(-4,80,-3,1)
Block(-4,80,-2,1)
Block(-4,80,-1,1)
Block(-4,80,0,1)
Block(-4,80,1,1)
Block(-4,80,2,1)
Block(-4,80,3,1)
Block(-4,80,4,1)
Block(-4,80,5,1)
Block(-4,81,-5,1)
Block(-4,81,-4,1)
Block(-4,81,-3,1)
Block(-4,81,-2,1)
Block(-4,81,-1,1)
Block(-4,81,0,1)
Block(-4,81,1,1)
Block(-4,81,2,1)
Block(-4,81,3,1)
Block(-4,81,4,1)
Block(-4,81,5,1)
Block(-4,81,6,1)
Block(-4,82,-5,1)
Block(-4,82,-4,1)
Block(-4,82,-3,1)
Block(-4,82,-2,1)
Block(-4,82,-1,1)
Block(-4,82,0,1)
Block(-4,82,1,1)
Block(-4,82,2,1)
Block(-4,82,3,1)
Block(-4,82,4,1)
Block(-4,82,5,1)
Block(-4,82,6,1)
Block(-4,82,7,1)
Block(-4,83,-6,1)
Block(-4,83,-5,1)
Block(-4,83,-4,1)
Block(-4,83,-3,1)
Block(-4,83,-2,1)
Block(-4,83,-1,1)
Block(-4,83,0,1)
Block(-4,83,1,1)
Block(-4,83,2,1)
Block(-4,83,3,1)
Block(-4,83,4,1)
Block(-4,83,5,1)
Block(-4,83,6,1)
Block(-4,83,7,1)
Block(-4,84,-6,1)
Block(-4,84,-5,1)
Block(-4,84,-4,3)
Block(-4,84,-3,1)
Block(-4,84,-2,1)
Block(-4,84,-1,1)
Block(-4,84,0,1)
Block(-4,84,1,1)
Block(-4,84,2,1)
Block(-4,84,3,1)
Block(-4,84,4,1)
Block(-4,84,5,1)
Block(-4,84,6,1)
Block(-4,84,7,1)
Block(-4,85,-5,1)
Block(-4,85,-4,3)
Block(-4,85,-3,1)
Block(-4,85,-2,1)
Block(-4,85,-1,1)
Block(-4,85,0,1)
Block(-4,85,1,1)
Block(-4,85,2,1)
Block(-4,85,3,1)
Block(-4,85,4,1)
Block(-4,85,5,1)
Block(-4,85,6,1)
Block(-4,85,7,1)
Block(-4,86,-5,1)
Block(-4,86,-4,1)
Block(-4,86,-3,3)
Block(-4,86,-2,1)
Block(-4,86,-1,1)
Block(-4,86,0,1)
Block(-4,86,1,1)
Block(-4,86,2,1)
Block(-4,86,3,1)
Block(-4,86,4,1)
Block(-4,86,5,1)
Block(-4,86,6,3)
Block(-4,86,7,1)
Block(-4,87,-4,1)
Block(-4,87,-3,3)
Block(-4,87,-2,3)
Block(-4,87,-1,1)
Block(-4,87,0,1)
Block(-4,87,1,1)
Block(-4,87,2,1)
Block(-4,87,3,1)
Block(-4,87,4,1)
Block(-4,87,5,3)
Block(-4,87,6,3)
Block(-4,87,7,1)
Block(-4,88,-3,1)
Block(-4,88,-2,3)
Block(-4,88,-1,3)
Block(-4,88,0,1)
Block(-4,88,1,1)
Block(-4,88,2,1)
Block(-4,88,3,3)
Block(-4,88,4,3)
Block(-4,88,5,3)
Block(-4,88,6,1)
Block(-4,88,7,1)
Block(-4,89,-3,1)
Block(-4,89,-2,1)
Block(-4,89,-1,3)
Block(-4,89,0,3)
Block(-4,89,1,3)
Block(-4,89,2,3)
Block(-4,89,3,3)
Block(-4,89,4,3)
Block(-4,89,5,3)
Block(-4,89,6,1)
Block(-4,90,-2,1)
Block(-4,90,-1,1)
Block(-4,90,0,3)
Block(-4,90,1,3)
Block(-4,90,2,3)
Block(-4,90,3,3)
Block(-4,90,4,1)
Block(-4,90,5,1)
Block(-4,91,-1,1)
Block(-4,91,0,1)
Block(-4,91,1,1)
Block(-4,91,2,1)
Block(-4,91,3,1)
Block(-4,91,4,1)
Block(-4,92,0,1)
Block(-4,92,1,1)
Block(-4,92,2,1)
Block(-3,0,-9,1)
Block(-3,0,-8,1)
Block(-3,0,-7,1)
Block(-3,0,-6,1)
Block(-3,0,-5,1)
Block(-3,0,-4,1)
Block(-3,0,-3,1)
Block(-3,0,-2,1)
Block(-3,0,-1,1)
Block(-3,0,0,1)
Block(-3,0,1,1)
Block(-3,0,2,1)
Block(-3,0,3,1)
Block(-3,0,4,1)
Block(-3,0,5,1)
Block(-3,0,6,1)
Block(-3,0,7,1)
Block(-3,0,8,1)
Block(-3,1,-8,1)
Block(-3,1,-7,1)
Block(-3,1,-6,1)
Block(-3,1,-5,1)
Block(-3,1,-4,1)
Block(-3,1,-3,1)
Block(-3,1,-2,1)
Block(-3,1,-1,1)
Block(-3,1,0,1)
Block(-3,1,1,1)
Block(-3,1,2,1)
Block(-3,1,3,1)
Block(-3,1,4,1)
Block(-3,1,5,1)
Block(-3,1,6,1)
Block(-3,1,7,1)
Block(-3,1,8,1)
Block(-3,2,-8,1)
Block(-3,2,-7,1)
Block(-3,2,-6,1)
Block(-3,2,-5,1)
Block(-3,2,-4,1)
Block(-3,2,-3,1)
Block(-3,2,-2,1)
Block(-3,2,-1,1)
Block(-3,2,0,1)
Block(-3,2,1,1)
Block(-3,2,2,1)
Block(-3,2,3,1)
Block(-3,2,4,1)
Block(-3,2,5,1)
Block(-3,2,6,1)
Block(-3,2,7,1)
Block(-3,2,8,1)
Block(-3,3,-8,1)
Block(-3,3,-7,1)
Block(-3,3,-6,1)
Block(-3,3,-5,1)
Block(-3,3,-4,1)
Block(-3,3,-3,1)
Block(-3,3,-2,1)
Block(-3,3,-1,1)
Block(-3,3,0,1)
Block(-3,3,1,1)
Block(-3,3,2,1)
Block(-3,3,3,1)
Block(-3,3,4,1)
Block(-3,3,5,1)
Block(-3,3,6,1)
Block(-3,3,7,1)
Block(-3,3,8,1)
Block(-3,3,9,1)
Block(-3,4,-7,1)
Block(-3,4,-6,1)
Block(-3,4,-5,1)
Block(-3,4,-4,1)
Block(-3,4,-3,1)
Block(-3,4,-2,1)
Block(-3,4,-1,1)
Block(-3,4,0,1)
Block(-3,4,1,1)
Block(-3,4,2,1)
Block(-3,4,3,1)
Block(-3,4,4,1)
Block(-3,4,5,1)
Block(-3,4,6,1)
Block(-3,4,7,1)
Block(-3,4,8,1)
Block(-3,4,9,1)
Block(-3,5,-7,1)
Block(-3,5,-6,1)
Block(-3,5,-5,1)
Block(-3,5,-4,1)
Block(-3,5,-3,1)
Block(-3,5,-2,1)
Block(-3,5,-1,1)
Block(-3,5,0,1)
Block(-3,5,1,1)
Block(-3,5,2,1)
Block(-3,5,3,1)
Block(-3,5,4,1)
Block(-3,5,5,1)
Block(-3,5,6,1)
Block(-3,5,7,1)
Block(-3,5,8,1)
Block(-3,5,9,1)
Block(-3,6,-6,1)
Block(-3,6,-5,1)
Block(-3,6,-4,1)
Block(-3,6,-3,1)
Block(-3,6,-2,1)
Block(-3,6,-1,1)
Block(-3,6,0,1)
Block(-3,6,1,1)
Block(-3,6,2,1)
Block(-3,6,3,1)
Block(-3,6,4,1)
Block(-3,6,5,1)
Block(-3,6,6,1)
Block(-3,6,7,1)
Block(-3,6,8,1)
Block(-3,6,9,1)
Block(-3,6,10,1)
Block(-3,7,-6,1)
Block(-3,7,-5,1)
Block(-3,7,-4,1)
Block(-3,7,-3,1)
Block(-3,7,-2,1)
Block(-3,7,-1,1)
Block(-3,7,0,1)
Block(-3,7,1,1)
Block(-3,7,2,1)
Block(-3,7,3,1)
Block(-3,7,4,1)
Block(-3,7,5,1)
Block(-3,7,6,1)
Block(-3,7,7,1)
Block(-3,7,8,1)
Block(-3,7,9,1)
Block(-3,7,10,1)
Block(-3,8,-7,1)
Block(-3,8,-6,1)
Block(-3,8,-5,1)
Block(-3,8,-4,1)
Block(-3,8,-3,1)
Block(-3,8,-2,1)
Block(-3,8,-1,1)
Block(-3,8,0,1)
Block(-3,8,1,1)
Block(-3,8,2,1)
Block(-3,8,3,1)
Block(-3,8,4,1)
Block(-3,8,5,1)
Block(-3,8,6,1)
Block(-3,8,7,1)
Block(-3,8,8,1)
Block(-3,8,9,1)
Block(-3,8,10,1)
Block(-3,9,-7,1)
Block(-3,9,-6,1)
Block(-3,9,-5,1)
Block(-3,9,-4,1)
Block(-3,9,-3,1)
Block(-3,9,-2,1)
Block(-3,9,-1,1)
Block(-3,9,0,1)
Block(-3,9,1,1)
Block(-3,9,2,1)
Block(-3,9,3,1)
Block(-3,9,4,1)
Block(-3,9,5,1)
Block(-3,9,6,1)
Block(-3,9,7,1)
Block(-3,9,8,1)
Block(-3,9,9,1)
Block(-3,9,10,1)
Block(-3,10,-7,1)
Block(-3,10,-6,1)
Block(-3,10,-5,1)
Block(-3,10,-4,1)
Block(-3,10,-3,1)
Block(-3,10,-2,1)
Block(-3,10,-1,1)
Block(-3,10,0,1)
Block(-3,10,1,1)
Block(-3,10,2,1)
Block(-3,10,3,1)
Block(-3,10,4,1)
Block(-3,10,5,1)
Block(-3,10,6,1)
Block(-3,10,7,1)
Block(-3,10,8,1)
Block(-3,10,9,1)
Block(-3,10,10,1)
Block(-3,11,-7,1)
Block(-3,11,-6,1)
Block(-3,11,-5,1)
Block(-3,11,-4,1)
Block(-3,11,-3,1)
Block(-3,11,-2,1)
Block(-3,11,-1,1)
Block(-3,11,0,1)
Block(-3,11,1,1)
Block(-3,11,2,1)
Block(-3,11,3,1)
Block(-3,11,4,1)
Block(-3,11,5,1)
Block(-3,11,6,1)
Block(-3,11,7,1)
Block(-3,11,8,1)
Block(-3,11,9,1)
Block(-3,11,10,1)
Block(-3,12,-7,1)
Block(-3,12,-6,1)
Block(-3,12,-5,1)
Block(-3,12,-4,1)
Block(-3,12,-3,1)
Block(-3,12,-2,1)
Block(-3,12,-1,1)
Block(-3,12,0,1)
Block(-3,12,1,1)
Block(-3,12,2,1)
Block(-3,12,3,1)
Block(-3,12,4,1)
Block(-3,12,5,1)
Block(-3,12,6,1)
Block(-3,12,7,1)
Block(-3,12,8,1)
Block(-3,12,9,1)
Block(-3,12,10,1)
Block(-3,13,-7,1)
Block(-3,13,-6,1)
Block(-3,13,-5,1)
Block(-3,13,-4,1)
Block(-3,13,-3,1)
Block(-3,13,-2,1)
Block(-3,13,-1,1)
Block(-3,13,0,1)
Block(-3,13,1,1)
Block(-3,13,2,1)
Block(-3,13,3,1)
Block(-3,13,4,1)
Block(-3,13,5,1)
Block(-3,13,6,1)
Block(-3,13,7,1)
Block(-3,13,8,1)
Block(-3,13,9,1)
Block(-3,13,10,1)
Block(-3,14,-7,1)
Block(-3,14,-6,1)
Block(-3,14,-5,1)
Block(-3,14,-4,1)
Block(-3,14,-3,1)
Block(-3,14,-2,1)
Block(-3,14,-1,1)
Block(-3,14,0,1)
Block(-3,14,1,1)
Block(-3,14,2,1)
Block(-3,14,3,1)
Block(-3,14,4,1)
Block(-3,14,5,1)
Block(-3,14,6,1)
Block(-3,14,7,1)
Block(-3,14,8,1)
Block(-3,14,9,1)
Block(-3,14,10,1)
Block(-3,15,-7,1)
Block(-3,15,-6,1)
Block(-3,15,-5,1)
Block(-3,15,-4,1)
Block(-3,15,-3,1)
Block(-3,15,-2,1)
Block(-3,15,-1,1)
Block(-3,15,0,1)
Block(-3,15,1,1)
Block(-3,15,2,1)
Block(-3,15,3,1)
Block(-3,15,4,1)
Block(-3,15,5,1)
Block(-3,15,6,1)
Block(-3,15,7,1)
Block(-3,15,8,1)
Block(-3,15,9,1)
Block(-3,16,-7,1)
Block(-3,16,-6,1)
Block(-3,16,-5,1)
Block(-3,16,-4,1)
Block(-3,16,-3,1)
Block(-3,16,-2,1)
Block(-3,16,-1,1)
Block(-3,16,0,1)
Block(-3,16,1,1)
Block(-3,16,2,1)
Block(-3,16,3,1)
Block(-3,16,4,1)
Block(-3,16,5,1)
Block(-3,16,6,1)
Block(-3,16,7,1)
Block(-3,16,8,1)
Block(-3,17,-8,1)
Block(-3,17,-7,1)
Block(-3,17,-6,1)
Block(-3,17,-5,1)
Block(-3,17,-4,1)
Block(-3,17,-3,1)
Block(-3,17,-2,1)
Block(-3,17,-1,1)
Block(-3,17,0,1)
Block(-3,17,1,1)
Block(-3,17,2,1)
Block(-3,17,3,1)
Block(-3,17,4,1)
Block(-3,17,5,1)
Block(-3,17,6,1)
Block(-3,17,7,1)
Block(-3,18,-8,1)
Block(-3,18,-7,1)
Block(-3,18,-6,1)
Block(-3,18,-5,1)
Block(-3,18,-4,1)
Block(-3,18,-3,1)
Block(-3,18,-2,1)
Block(-3,18,-1,1)
Block(-3,18,0,1)
Block(-3,18,1,1)
Block(-3,18,2,1)
Block(-3,18,3,1)
Block(-3,18,4,1)
Block(-3,18,5,1)
Block(-3,18,6,1)
Block(-3,18,7,1)
Block(-3,19,-8,1)
Block(-3,19,-7,1)
Block(-3,19,-6,1)
Block(-3,19,-5,1)
Block(-3,19,-4,1)
Block(-3,19,-3,1)
Block(-3,19,-2,1)
Block(-3,19,-1,1)
Block(-3,19,0,1)
Block(-3,19,1,1)
Block(-3,19,2,1)
Block(-3,19,3,1)
Block(-3,19,4,1)
Block(-3,19,5,1)
Block(-3,19,6,1)
Block(-3,19,7,1)
Block(-3,19,8,1)
Block(-3,20,-9,1)
Block(-3,20,-8,1)
Block(-3,20,-7,1)
Block(-3,20,-6,1)
Block(-3,20,-5,1)
Block(-3,20,-4,1)
Block(-3,20,-3,1)
Block(-3,20,-2,1)
Block(-3,20,-1,1)
Block(-3,20,0,1)
Block(-3,20,1,1)
Block(-3,20,2,1)
Block(-3,20,3,1)
Block(-3,20,4,1)
Block(-3,20,5,1)
Block(-3,20,6,1)
Block(-3,20,7,1)
Block(-3,20,8,1)
Block(-3,21,-9,1)
Block(-3,21,-8,1)
Block(-3,21,-7,1)
Block(-3,21,-6,1)
Block(-3,21,-5,1)
Block(-3,21,-4,1)
Block(-3,21,-3,1)
Block(-3,21,-2,1)
Block(-3,21,-1,1)
Block(-3,21,0,1)
Block(-3,21,1,1)
Block(-3,21,2,1)
Block(-3,21,3,1)
Block(-3,21,4,1)
Block(-3,21,5,1)
Block(-3,21,6,1)
Block(-3,21,7,1)
Block(-3,21,8,1)
Block(-3,21,9,1)
Block(-3,22,-9,1)
Block(-3,22,-8,1)
Block(-3,22,-7,1)
Block(-3,22,-6,1)
Block(-3,22,-5,1)
Block(-3,22,-4,1)
Block(-3,22,-3,1)
Block(-3,22,-2,1)
Block(-3,22,-1,1)
Block(-3,22,0,1)
Block(-3,22,1,1)
Block(-3,22,2,1)
Block(-3,22,3,1)
Block(-3,22,4,1)
Block(-3,22,5,1)
Block(-3,22,6,1)
Block(-3,22,7,1)
Block(-3,22,8,1)
Block(-3,22,9,1)
Block(-3,23,-9,1)
Block(-3,23,-8,1)
Block(-3,23,-7,1)
Block(-3,23,-6,1)
Block(-3,23,-5,1)
Block(-3,23,-4,1)
Block(-3,23,-3,1)
Block(-3,23,-2,1)
Block(-3,23,-1,1)
Block(-3,23,0,1)
Block(-3,23,1,1)
Block(-3,23,2,1)
Block(-3,23,3,1)
Block(-3,23,4,1)
Block(-3,23,5,1)
Block(-3,23,6,1)
Block(-3,23,7,1)
Block(-3,23,8,1)
Block(-3,23,9,1)
Block(-3,24,-8,1)
Block(-3,24,-7,1)
Block(-3,24,-6,1)
Block(-3,24,-5,1)
Block(-3,24,-4,1)
Block(-3,24,-3,1)
Block(-3,24,-2,1)
Block(-3,24,-1,1)
Block(-3,24,0,1)
Block(-3,24,1,1)
Block(-3,24,2,1)
Block(-3,24,3,1)
Block(-3,24,4,1)
Block(-3,24,5,1)
Block(-3,24,6,1)
Block(-3,24,7,1)
Block(-3,24,8,1)
Block(-3,24,9,1)
Block(-3,25,-7,1)
Block(-3,25,-6,1)
Block(-3,25,-5,1)
Block(-3,25,-4,1)
Block(-3,25,-3,1)
Block(-3,25,-2,1)
Block(-3,25,-1,1)
Block(-3,25,0,1)
Block(-3,25,1,1)
Block(-3,25,2,1)
Block(-3,25,3,1)
Block(-3,25,4,1)
Block(-3,25,5,1)
Block(-3,25,6,1)
Block(-3,25,7,1)
Block(-3,25,8,1)
Block(-3,25,9,1)
Block(-3,26,-6,1)
Block(-3,26,-5,1)
Block(-3,26,-4,1)
Block(-3,26,-3,1)
Block(-3,26,-2,1)
Block(-3,26,-1,1)
Block(-3,26,0,1)
Block(-3,26,1,1)
Block(-3,26,2,1)
Block(-3,26,3,1)
Block(-3,26,4,1)
Block(-3,26,5,1)
Block(-3,26,6,1)
Block(-3,26,7,1)
Block(-3,26,8,1)
Block(-3,26,9,1)
Block(-3,27,-6,1)
Block(-3,27,-5,1)
Block(-3,27,-4,1)
Block(-3,27,-3,1)
Block(-3,27,-2,1)
Block(-3,27,-1,1)
Block(-3,27,0,1)
Block(-3,27,1,1)
Block(-3,27,2,1)
Block(-3,27,3,1)
Block(-3,27,4,1)
Block(-3,27,5,1)
Block(-3,27,6,1)
Block(-3,27,7,1)
Block(-3,27,8,1)
Block(-3,27,9,1)
Block(-3,28,-6,1)
Block(-3,28,-5,1)
Block(-3,28,-4,1)
Block(-3,28,-3,1)
Block(-3,28,-2,1)
Block(-3,28,-1,1)
Block(-3,28,0,1)
Block(-3,28,1,1)
Block(-3,28,2,1)
Block(-3,28,3,1)
Block(-3,28,4,1)
Block(-3,28,5,1)
Block(-3,28,6,1)
Block(-3,28,7,1)
Block(-3,28,8,1)
Block(-3,28,9,1)
Block(-3,28,10,1)
Block(-3,29,-6,1)
Block(-3,29,-5,1)
Block(-3,29,-4,1)
Block(-3,29,-3,1)
Block(-3,29,-2,1)
Block(-3,29,-1,1)
Block(-3,29,0,1)
Block(-3,29,1,1)
Block(-3,29,2,1)
Block(-3,29,3,1)
Block(-3,29,4,1)
Block(-3,29,5,1)
Block(-3,29,6,1)
Block(-3,29,7,1)
Block(-3,29,8,1)
Block(-3,29,9,1)
Block(-3,29,10,1)
Block(-3,29,11,1)
Block(-3,30,-6,1)
Block(-3,30,-5,1)
Block(-3,30,-4,1)
Block(-3,30,-3,1)
Block(-3,30,-2,1)
Block(-3,30,-1,1)
Block(-3,30,0,1)
Block(-3,30,1,1)
Block(-3,30,2,1)
Block(-3,30,3,1)
Block(-3,30,4,1)
Block(-3,30,5,1)
Block(-3,30,6,1)
Block(-3,30,7,1)
Block(-3,30,8,1)
Block(-3,30,9,1)
Block(-3,30,10,1)
Block(-3,30,11,1)
Block(-3,31,-5,1)
Block(-3,31,-4,1)
Block(-3,31,-3,1)
Block(-3,31,-2,1)
Block(-3,31,-1,1)
Block(-3,31,0,1)
Block(-3,31,1,1)
Block(-3,31,2,1)
Block(-3,31,3,1)
Block(-3,31,4,1)
Block(-3,31,5,1)
Block(-3,31,6,1)
Block(-3,31,7,1)
Block(-3,31,8,1)
Block(-3,31,9,1)
Block(-3,31,10,1)
Block(-3,31,11,1)
Block(-3,32,-5,1)
Block(-3,32,-4,1)
Block(-3,32,-3,1)
Block(-3,32,-2,1)
Block(-3,32,-1,1)
Block(-3,32,0,1)
Block(-3,32,1,1)
Block(-3,32,2,1)
Block(-3,32,3,1)
Block(-3,32,4,1)
Block(-3,32,5,1)
Block(-3,32,6,1)
Block(-3,32,7,1)
Block(-3,32,8,1)
Block(-3,32,9,1)
Block(-3,32,10,1)
Block(-3,33,-5,1)
Block(-3,33,-4,1)
Block(-3,33,-3,1)
Block(-3,33,-2,1)
Block(-3,33,-1,1)
Block(-3,33,0,1)
Block(-3,33,1,1)
Block(-3,33,2,1)
Block(-3,33,3,1)
Block(-3,33,4,1)
Block(-3,33,5,1)
Block(-3,33,6,1)
Block(-3,33,7,1)
Block(-3,33,8,1)
Block(-3,33,9,1)
Block(-3,33,10,1)
Block(-3,34,-5,1)
Block(-3,34,-4,1)
Block(-3,34,-3,1)
Block(-3,34,-2,1)
Block(-3,34,-1,1)
Block(-3,34,0,1)
Block(-3,34,1,1)
Block(-3,34,2,1)
Block(-3,34,3,1)
Block(-3,34,4,1)
Block(-3,34,5,1)
Block(-3,34,6,1)
Block(-3,34,7,1)
Block(-3,34,8,1)
Block(-3,34,9,1)
Block(-3,35,-5,1)
Block(-3,35,-4,1)
Block(-3,35,-3,1)
Block(-3,35,-2,1)
Block(-3,35,-1,1)
Block(-3,35,0,1)
Block(-3,35,1,1)
Block(-3,35,2,1)
Block(-3,35,3,1)
Block(-3,35,4,1)
Block(-3,35,5,1)
Block(-3,35,6,1)
Block(-3,35,7,1)
Block(-3,35,8,1)
Block(-3,35,9,1)
Block(-3,36,-6,1)
Block(-3,36,-5,1)
Block(-3,36,-4,1)
Block(-3,36,-3,1)
Block(-3,36,-2,1)
Block(-3,36,-1,1)
Block(-3,36,0,1)
Block(-3,36,1,1)
Block(-3,36,2,1)
Block(-3,36,3,1)
Block(-3,36,4,1)
Block(-3,36,5,1)
Block(-3,36,6,1)
Block(-3,36,7,1)
Block(-3,36,8,1)
Block(-3,36,9,1)
Block(-3,37,-7,1)
Block(-3,37,-6,1)
Block(-3,37,-5,1)
Block(-3,37,-4,1)
Block(-3,37,-3,1)
Block(-3,37,-2,1)
Block(-3,37,-1,1)
Block(-3,37,0,1)
Block(-3,37,1,1)
Block(-3,37,2,1)
Block(-3,37,3,1)
Block(-3,37,4,1)
Block(-3,37,5,1)
Block(-3,37,6,1)
Block(-3,37,7,1)
Block(-3,37,8,1)
Block(-3,37,9,1)
Block(-3,38,-7,1)
Block(-3,38,-6,1)
Block(-3,38,-5,1)
Block(-3,38,-4,1)
Block(-3,38,-3,1)
Block(-3,38,-2,1)
Block(-3,38,-1,1)
Block(-3,38,0,1)
Block(-3,38,1,1)
Block(-3,38,2,1)
Block(-3,38,3,1)
Block(-3,38,4,1)
Block(-3,38,5,1)
Block(-3,38,6,1)
Block(-3,38,7,1)
Block(-3,38,8,1)
Block(-3,38,9,1)
Block(-3,39,-8,1)
Block(-3,39,-7,1)
Block(-3,39,-6,1)
Block(-3,39,-5,1)
Block(-3,39,-4,1)
Block(-3,39,-3,1)
Block(-3,39,-2,1)
Block(-3,39,-1,1)
Block(-3,39,0,1)
Block(-3,39,1,1)
Block(-3,39,2,1)
Block(-3,39,3,1)
Block(-3,39,4,1)
Block(-3,39,5,1)
Block(-3,39,6,1)
Block(-3,39,7,1)
Block(-3,39,8,1)
Block(-3,39,9,1)
Block(-3,39,10,1)
Block(-3,40,-8,1)
Block(-3,40,-7,1)
Block(-3,40,-6,1)
Block(-3,40,-5,1)
Block(-3,40,-4,1)
Block(-3,40,-3,1)
Block(-3,40,-2,1)
Block(-3,40,-1,1)
Block(-3,40,0,1)
Block(-3,40,1,1)
Block(-3,40,2,1)
Block(-3,40,3,1)
Block(-3,40,4,1)
Block(-3,40,5,1)
Block(-3,40,6,1)
Block(-3,40,7,1)
Block(-3,40,8,1)
Block(-3,40,9,1)
Block(-3,40,10,1)
Block(-3,41,-9,1)
Block(-3,41,-8,1)
Block(-3,41,-7,1)
Block(-3,41,-6,1)
Block(-3,41,-5,1)
Block(-3,41,-4,1)
Block(-3,41,-3,1)
Block(-3,41,-2,1)
Block(-3,41,-1,1)
Block(-3,41,0,1)
Block(-3,41,1,1)
Block(-3,41,2,1)
Block(-3,41,3,1)
Block(-3,41,4,1)
Block(-3,41,5,1)
Block(-3,41,6,1)
Block(-3,41,7,1)
Block(-3,41,8,1)
Block(-3,41,9,1)
Block(-3,41,10,1)
Block(-3,42,-8,1)
Block(-3,42,-7,1)
Block(-3,42,-6,1)
Block(-3,42,-5,1)
Block(-3,42,-4,1)
Block(-3,42,-3,1)
Block(-3,42,-2,1)
Block(-3,42,-1,1)
Block(-3,42,0,1)
Block(-3,42,1,1)
Block(-3,42,2,1)
Block(-3,42,3,1)
Block(-3,42,4,1)
Block(-3,42,5,1)
Block(-3,42,6,1)
Block(-3,42,7,1)
Block(-3,42,8,1)
Block(-3,42,9,1)
Block(-3,43,-8,1)
Block(-3,43,-7,1)
Block(-3,43,-6,1)
Block(-3,43,-5,1)
Block(-3,43,-4,1)
Block(-3,43,-3,1)
Block(-3,43,-2,1)
Block(-3,43,-1,1)
Block(-3,43,0,1)
Block(-3,43,1,1)
Block(-3,43,2,1)
Block(-3,43,3,1)
Block(-3,43,4,1)
Block(-3,43,5,1)
Block(-3,43,6,1)
Block(-3,43,7,1)
Block(-3,43,8,1)
Block(-3,44,-7,1)
Block(-3,44,-6,1)
Block(-3,44,-5,1)
Block(-3,44,-4,1)
Block(-3,44,-3,1)
Block(-3,44,-2,1)
Block(-3,44,-1,1)
Block(-3,44,0,1)
Block(-3,44,1,1)
Block(-3,44,2,1)
Block(-3,44,3,1)
Block(-3,44,4,1)
Block(-3,44,5,1)
Block(-3,44,6,1)
Block(-3,44,7,1)
Block(-3,44,8,1)
Block(-3,45,-6,1)
Block(-3,45,-5,1)
Block(-3,45,-4,1)
Block(-3,45,-3,1)
Block(-3,45,-2,1)
Block(-3,45,-1,1)
Block(-3,45,0,1)
Block(-3,45,1,1)
Block(-3,45,2,1)
Block(-3,45,3,1)
Block(-3,45,4,1)
Block(-3,45,5,1)
Block(-3,45,6,1)
Block(-3,45,7,1)
Block(-3,46,-6,1)
Block(-3,46,-5,1)
Block(-3,46,-4,1)
Block(-3,46,-3,1)
Block(-3,46,-2,1)
Block(-3,46,-1,1)
Block(-3,46,0,1)
Block(-3,46,1,1)
Block(-3,46,2,1)
Block(-3,46,3,1)
Block(-3,46,4,1)
Block(-3,46,5,1)
Block(-3,46,6,1)
Block(-3,46,7,1)
Block(-3,47,-6,1)
Block(-3,47,-5,1)
Block(-3,47,-4,1)
Block(-3,47,-3,1)
Block(-3,47,-2,1)
Block(-3,47,-1,1)
Block(-3,47,0,1)
Block(-3,47,1,1)
Block(-3,47,2,1)
Block(-3,47,3,1)
Block(-3,47,4,1)
Block(-3,47,5,1)
Block(-3,47,6,1)
Block(-3,47,7,1)
Block(-3,48,-7,1)
Block(-3,48,-6,1)
Block(-3,48,-5,1)
Block(-3,48,-4,1)
Block(-3,48,-3,1)
Block(-3,48,-2,1)
Block(-3,48,-1,1)
Block(-3,48,0,1)
Block(-3,48,1,1)
Block(-3,48,2,1)
Block(-3,48,3,1)
Block(-3,48,4,1)
Block(-3,48,5,1)
Block(-3,48,6,1)
Block(-3,48,7,1)
Block(-3,48,8,1)
Block(-3,49,-7,1)
Block(-3,49,-6,1)
Block(-3,49,-5,1)
Block(-3,49,-4,1)
Block(-3,49,-3,1)
Block(-3,49,-2,1)
Block(-3,49,-1,1)
Block(-3,49,0,1)
Block(-3,49,1,1)
Block(-3,49,2,1)
Block(-3,49,3,1)
Block(-3,49,4,1)
Block(-3,49,5,1)
Block(-3,49,6,1)
Block(-3,49,7,1)
Block(-3,49,8,1)
Block(-3,49,9,1)
Block(-3,50,-8,1)
Block(-3,50,-7,1)
Block(-3,50,-6,1)
Block(-3,50,-5,1)
Block(-3,50,-4,1)
Block(-3,50,-3,1)
Block(-3,50,-2,1)
Block(-3,50,-1,1)
Block(-3,50,0,1)
Block(-3,50,1,1)
Block(-3,50,2,1)
Block(-3,50,3,1)
Block(-3,50,4,1)
Block(-3,50,5,1)
Block(-3,50,6,1)
Block(-3,50,7,1)
Block(-3,50,8,1)
Block(-3,50,9,1)
Block(-3,50,10,1)
Block(-3,51,-9,1)
Block(-3,51,-8,1)
Block(-3,51,-7,1)
Block(-3,51,-6,1)
Block(-3,51,-5,1)
Block(-3,51,-4,1)
Block(-3,51,-3,1)
Block(-3,51,-2,1)
Block(-3,51,-1,1)
Block(-3,51,0,1)
Block(-3,51,1,1)
Block(-3,51,2,1)
Block(-3,51,3,1)
Block(-3,51,4,1)
Block(-3,51,5,1)
Block(-3,51,6,1)
Block(-3,51,7,1)
Block(-3,51,8,1)
Block(-3,51,9,1)
Block(-3,51,10,1)
Block(-3,52,-9,1)
Block(-3,52,-8,1)
Block(-3,52,-7,1)
Block(-3,52,-6,1)
Block(-3,52,-5,1)
Block(-3,52,-4,1)
Block(-3,52,-3,1)
Block(-3,52,-2,1)
Block(-3,52,-1,1)
Block(-3,52,0,1)
Block(-3,52,1,1)
Block(-3,52,2,1)
Block(-3,52,3,1)
Block(-3,52,4,1)
Block(-3,52,5,1)
Block(-3,52,6,1)
Block(-3,52,7,1)
Block(-3,52,8,1)
Block(-3,52,9,1)
Block(-3,52,10,1)
Block(-3,53,-8,1)
Block(-3,53,-7,1)
Block(-3,53,-6,1)
Block(-3,53,-5,1)
Block(-3,53,-4,1)
Block(-3,53,-3,1)
Block(-3,53,-2,1)
Block(-3,53,-1,1)
Block(-3,53,0,1)
Block(-3,53,1,1)
Block(-3,53,2,1)
Block(-3,53,3,1)
Block(-3,53,4,1)
Block(-3,53,5,1)
Block(-3,53,6,1)
Block(-3,53,7,1)
Block(-3,53,8,1)
Block(-3,53,9,1)
Block(-3,53,10,1)
Block(-3,54,-7,1)
Block(-3,54,-6,1)
Block(-3,54,-5,1)
Block(-3,54,-4,1)
Block(-3,54,-3,1)
Block(-3,54,-2,1)
Block(-3,54,-1,1)
Block(-3,54,0,1)
Block(-3,54,1,1)
Block(-3,54,2,1)
Block(-3,54,3,1)
Block(-3,54,4,1)
Block(-3,54,5,1)
Block(-3,54,6,1)
Block(-3,54,7,1)
Block(-3,54,8,1)
Block(-3,54,9,1)
Block(-3,55,-7,1)
Block(-3,55,-6,1)
Block(-3,55,-5,1)
Block(-3,55,-4,1)
Block(-3,55,-3,1)
Block(-3,55,-2,1)
Block(-3,55,-1,1)
Block(-3,55,0,1)
Block(-3,55,1,1)
Block(-3,55,2,1)
Block(-3,55,3,1)
Block(-3,55,4,1)
Block(-3,55,5,1)
Block(-3,55,6,1)
Block(-3,55,7,1)
Block(-3,55,8,1)
Block(-3,55,9,1)
Block(-3,56,-8,1)
Block(-3,56,-7,1)
Block(-3,56,-6,1)
Block(-3,56,-5,1)
Block(-3,56,-4,1)
Block(-3,56,-3,1)
Block(-3,56,-2,1)
Block(-3,56,-1,1)
Block(-3,56,0,1)
Block(-3,56,1,1)
Block(-3,56,2,1)
Block(-3,56,3,1)
Block(-3,56,4,1)
Block(-3,56,5,1)
Block(-3,56,6,1)
Block(-3,56,7,1)
Block(-3,56,8,1)
Block(-3,56,9,1)
Block(-3,57,-8,1)
Block(-3,57,-7,1)
Block(-3,57,-6,1)
Block(-3,57,-5,1)
Block(-3,57,-4,1)
Block(-3,57,-3,1)
Block(-3,57,-2,1)
Block(-3,57,-1,1)
Block(-3,57,0,1)
Block(-3,57,1,1)
Block(-3,57,2,1)
Block(-3,57,3,1)
Block(-3,57,4,1)
Block(-3,57,5,1)
Block(-3,57,6,1)
Block(-3,57,7,1)
Block(-3,57,8,1)
Block(-3,57,9,1)
Block(-3,58,-9,1)
Block(-3,58,-8,1)
Block(-3,58,-7,1)
Block(-3,58,-6,1)
Block(-3,58,-5,1)
Block(-3,58,-4,1)
Block(-3,58,-3,1)
Block(-3,58,-2,1)
Block(-3,58,-1,1)
Block(-3,58,0,1)
Block(-3,58,1,1)
Block(-3,58,2,1)
Block(-3,58,3,1)
Block(-3,58,4,1)
Block(-3,58,5,1)
Block(-3,58,6,1)
Block(-3,58,7,1)
Block(-3,58,8,1)
Block(-3,58,9,1)
Block(-3,58,10,1)
Block(-3,59,-9,1)
Block(-3,59,-8,1)
Block(-3,59,-7,1)
Block(-3,59,-6,1)
Block(-3,59,-5,1)
Block(-3,59,-4,1)
Block(-3,59,-3,1)
Block(-3,59,-2,1)
Block(-3,59,-1,1)
Block(-3,59,0,1)
Block(-3,59,1,1)
Block(-3,59,2,1)
Block(-3,59,3,1)
Block(-3,59,4,1)
Block(-3,59,5,1)
Block(-3,59,6,1)
Block(-3,59,7,1)
Block(-3,59,8,1)
Block(-3,59,9,1)
Block(-3,59,10,1)
Block(-3,60,-9,1)
Block(-3,60,-8,1)
Block(-3,60,-7,1)
Block(-3,60,-6,1)
Block(-3,60,-5,1)
Block(-3,60,-4,1)
Block(-3,60,-3,1)
Block(-3,60,-2,1)
Block(-3,60,-1,1)
Block(-3,60,0,1)
Block(-3,60,1,1)
Block(-3,60,2,1)
Block(-3,60,3,1)
Block(-3,60,4,1)
Block(-3,60,5,1)
Block(-3,60,6,1)
Block(-3,60,7,1)
Block(-3,60,8,1)
Block(-3,60,9,1)
Block(-3,60,10,1)
Block(-3,61,-9,1)
Block(-3,61,-8,1)
Block(-3,61,-7,1)
Block(-3,61,-6,1)
Block(-3,61,-5,1)
Block(-3,61,-4,1)
Block(-3,61,-3,1)
Block(-3,61,-2,1)
Block(-3,61,-1,1)
Block(-3,61,0,1)
Block(-3,61,1,1)
Block(-3,61,2,1)
Block(-3,61,3,1)
Block(-3,61,4,1)
Block(-3,61,5,1)
Block(-3,61,6,1)
Block(-3,61,7,1)
Block(-3,61,8,1)
Block(-3,61,9,1)
Block(-3,61,10,1)
Block(-3,62,-10,1)
Block(-3,62,-9,1)
Block(-3,62,-8,1)
Block(-3,62,-7,1)
Block(-3,62,-6,1)
Block(-3,62,-5,1)
Block(-3,62,-4,1)
Block(-3,62,-3,1)
Block(-3,62,-2,1)
Block(-3,62,-1,1)
Block(-3,62,0,1)
Block(-3,62,1,1)
Block(-3,62,2,1)
Block(-3,62,3,1)
Block(-3,62,4,1)
Block(-3,62,5,1)
Block(-3,62,6,1)
Block(-3,62,7,1)
Block(-3,62,8,1)
Block(-3,62,9,1)
Block(-3,62,10,1)
Block(-3,63,-9,1)
Block(-3,63,-8,1)
Block(-3,63,-7,1)
Block(-3,63,-6,1)
Block(-3,63,-5,1)
Block(-3,63,-4,1)
Block(-3,63,-3,1)
Block(-3,63,-2,1)
Block(-3,63,-1,1)
Block(-3,63,0,1)
Block(-3,63,1,1)
Block(-3,63,2,1)
Block(-3,63,3,1)
Block(-3,63,4,1)
Block(-3,63,5,1)
Block(-3,63,6,1)
Block(-3,63,7,1)
Block(-3,63,8,1)
Block(-3,63,9,1)
Block(-3,64,-9,1)
Block(-3,64,-8,1)
Block(-3,64,-7,1)
Block(-3,64,-6,1)
Block(-3,64,-5,1)
Block(-3,64,-4,1)
Block(-3,64,-3,1)
Block(-3,64,-2,1)
Block(-3,64,-1,1)
Block(-3,64,0,1)
Block(-3,64,1,1)
Block(-3,64,2,1)
Block(-3,64,3,1)
Block(-3,64,4,1)
Block(-3,64,5,1)
Block(-3,64,6,1)
Block(-3,64,7,1)
Block(-3,64,8,1)
Block(-3,64,9,1)
Block(-3,65,-9,1)
Block(-3,65,-8,1)
Block(-3,65,-7,1)
Block(-3,65,-6,1)
Block(-3,65,-5,1)
Block(-3,65,-4,1)
Block(-3,65,-3,1)
Block(-3,65,-2,1)
Block(-3,65,-1,1)
Block(-3,65,0,1)
Block(-3,65,1,1)
Block(-3,65,2,1)
Block(-3,65,3,1)
Block(-3,65,4,1)
Block(-3,65,5,1)
Block(-3,65,6,1)
Block(-3,65,7,1)
Block(-3,65,8,1)
Block(-3,66,-8,1)
Block(-3,66,-7,1)
Block(-3,66,-6,1)
Block(-3,66,-5,1)
Block(-3,66,-4,1)
Block(-3,66,-3,1)
Block(-3,66,-2,1)
Block(-3,66,-1,1)
Block(-3,66,0,1)
Block(-3,66,1,1)
Block(-3,66,2,1)
Block(-3,66,3,1)
Block(-3,66,4,1)
Block(-3,66,5,1)
Block(-3,66,6,1)
Block(-3,66,7,1)
Block(-3,66,8,1)
Block(-3,67,-8,1)
Block(-3,67,-7,1)
Block(-3,67,-6,1)
Block(-3,67,-5,1)
Block(-3,67,-4,1)
Block(-3,67,-3,1)
Block(-3,67,-2,1)
Block(-3,67,-1,1)
Block(-3,67,0,1)
Block(-3,67,1,1)
Block(-3,67,2,1)
Block(-3,67,3,1)
Block(-3,67,4,1)
Block(-3,67,5,1)
Block(-3,67,6,1)
Block(-3,67,7,1)
Block(-3,67,8,1)
Block(-3,68,-8,1)
Block(-3,68,-7,1)
Block(-3,68,-6,1)
Block(-3,68,-5,1)
Block(-3,68,-4,1)
Block(-3,68,-3,1)
Block(-3,68,-2,1)
Block(-3,68,-1,1)
Block(-3,68,0,1)
Block(-3,68,1,1)
Block(-3,68,2,1)
Block(-3,68,3,1)
Block(-3,68,4,1)
Block(-3,68,5,1)
Block(-3,68,6,1)
Block(-3,68,7,1)
Block(-3,68,8,1)
Block(-3,69,-8,1)
Block(-3,69,-7,1)
Block(-3,69,-6,1)
Block(-3,69,-5,1)
Block(-3,69,-4,1)
Block(-3,69,-3,1)
Block(-3,69,-2,1)
Block(-3,69,-1,1)
Block(-3,69,0,1)
Block(-3,69,1,1)
Block(-3,69,2,1)
Block(-3,69,3,1)
Block(-3,69,4,1)
Block(-3,69,5,1)
Block(-3,69,6,1)
Block(-3,69,7,1)
Block(-3,69,8,1)
Block(-3,70,-8,1)
Block(-3,70,-7,1)
Block(-3,70,-6,1)
Block(-3,70,-5,1)
Block(-3,70,-4,1)
Block(-3,70,-3,1)
Block(-3,70,-2,1)
Block(-3,70,-1,1)
Block(-3,70,0,1)
Block(-3,70,1,1)
Block(-3,70,2,1)
Block(-3,70,3,1)
Block(-3,70,4,1)
Block(-3,70,5,1)
Block(-3,70,6,1)
Block(-3,70,7,1)
Block(-3,70,8,1)
Block(-3,70,9,1)
Block(-3,71,-8,1)
Block(-3,71,-7,1)
Block(-3,71,-6,1)
Block(-3,71,-5,1)
Block(-3,71,-4,1)
Block(-3,71,-3,1)
Block(-3,71,-2,1)
Block(-3,71,-1,1)
Block(-3,71,0,1)
Block(-3,71,1,1)
Block(-3,71,2,1)
Block(-3,71,3,1)
Block(-3,71,4,1)
Block(-3,71,5,1)
Block(-3,71,6,1)
Block(-3,71,7,1)
Block(-3,71,8,1)
Block(-3,71,9,1)
Block(-3,72,-8,1)
Block(-3,72,-7,1)
Block(-3,72,-6,1)
Block(-3,72,-5,1)
Block(-3,72,-4,1)
Block(-3,72,-3,1)
Block(-3,72,-2,1)
Block(-3,72,-1,1)
Block(-3,72,0,1)
Block(-3,72,1,1)
Block(-3,72,2,1)
Block(-3,72,3,1)
Block(-3,72,4,1)
Block(-3,72,5,1)
Block(-3,72,6,1)
Block(-3,72,7,1)
Block(-3,72,8,1)
Block(-3,72,9,1)
Block(-3,73,-8,1)
Block(-3,73,-7,1)
Block(-3,73,-6,1)
Block(-3,73,-5,1)
Block(-3,73,-4,1)
Block(-3,73,-3,1)
Block(-3,73,-2,1)
Block(-3,73,-1,1)
Block(-3,73,0,1)
Block(-3,73,1,1)
Block(-3,73,2,1)
Block(-3,73,3,1)
Block(-3,73,4,1)
Block(-3,73,5,1)
Block(-3,73,6,1)
Block(-3,73,7,1)
Block(-3,73,8,1)
Block(-3,73,9,1)
Block(-3,74,-8,1)
Block(-3,74,-7,1)
Block(-3,74,-6,1)
Block(-3,74,-5,1)
Block(-3,74,-4,1)
Block(-3,74,-3,1)
Block(-3,74,-2,1)
Block(-3,74,-1,1)
Block(-3,74,0,1)
Block(-3,74,1,1)
Block(-3,74,2,1)
Block(-3,74,3,1)
Block(-3,74,4,1)
Block(-3,74,5,1)
Block(-3,74,6,1)
Block(-3,74,7,1)
Block(-3,74,8,1)
Block(-3,74,9,1)
Block(-3,75,-7,1)
Block(-3,75,-6,1)
Block(-3,75,-5,1)
Block(-3,75,-4,1)
Block(-3,75,-3,1)
Block(-3,75,-2,1)
Block(-3,75,-1,1)
Block(-3,75,0,1)
Block(-3,75,1,1)
Block(-3,75,2,1)
Block(-3,75,3,1)
Block(-3,75,4,1)
Block(-3,75,5,1)
Block(-3,75,6,1)
Block(-3,75,7,1)
Block(-3,75,8,1)
Block(-3,76,-7,1)
Block(-3,76,-6,1)
Block(-3,76,-5,1)
Block(-3,76,-4,1)
Block(-3,76,-3,1)
Block(-3,76,-2,1)
Block(-3,76,-1,1)
Block(-3,76,0,1)
Block(-3,76,1,1)
Block(-3,76,2,1)
Block(-3,76,3,1)
Block(-3,76,4,1)
Block(-3,76,5,1)
Block(-3,76,6,1)
Block(-3,76,7,1)
Block(-3,77,-7,1)
Block(-3,77,-6,1)
Block(-3,77,-5,1)
Block(-3,77,-4,1)
Block(-3,77,-3,1)
Block(-3,77,-2,1)
Block(-3,77,-1,1)
Block(-3,77,0,1)
Block(-3,77,1,1)
Block(-3,77,2,1)
Block(-3,77,3,1)
Block(-3,77,4,1)
Block(-3,77,5,1)
Block(-3,77,6,1)
Block(-3,77,7,1)
Block(-3,78,-6,1)
Block(-3,78,-5,1)
Block(-3,78,-4,1)
Block(-3,78,-3,1)
Block(-3,78,-2,1)
Block(-3,78,-1,1)
Block(-3,78,0,1)
Block(-3,78,1,1)
Block(-3,78,2,1)
Block(-3,78,3,1)
Block(-3,78,4,1)
Block(-3,78,5,1)
Block(-3,78,6,1)
Block(-3,79,-6,1)
Block(-3,79,-5,1)
Block(-3,79,-4,1)
Block(-3,79,-3,1)
Block(-3,79,-2,1)
Block(-3,79,-1,1)
Block(-3,79,0,1)
Block(-3,79,1,1)
Block(-3,79,2,1)
Block(-3,79,3,1)
Block(-3,79,4,1)
Block(-3,79,5,1)
Block(-3,79,6,1)
Block(-3,80,-6,1)
Block(-3,80,-5,1)
Block(-3,80,-4,1)
Block(-3,80,-3,1)
Block(-3,80,-2,1)
Block(-3,80,-1,1)
Block(-3,80,0,1)
Block(-3,80,1,1)
Block(-3,80,2,1)
Block(-3,80,3,1)
Block(-3,80,4,1)
Block(-3,80,5,1)
Block(-3,80,6,1)
Block(-3,80,7,1)
Block(-3,81,-6,1)
Block(-3,81,-5,1)
Block(-3,81,-4,1)
Block(-3,81,-3,1)
Block(-3,81,-2,1)
Block(-3,81,-1,1)
Block(-3,81,0,1)
Block(-3,81,1,1)
Block(-3,81,2,1)
Block(-3,81,3,1)
Block(-3,81,4,1)
Block(-3,81,5,1)
Block(-3,81,6,1)
Block(-3,81,7,1)
Block(-3,81,8,1)
Block(-3,82,-6,1)
Block(-3,82,-5,1)
Block(-3,82,-4,1)
Block(-3,82,-3,1)
Block(-3,82,-2,1)
Block(-3,82,-1,1)
Block(-3,82,0,1)
Block(-3,82,1,1)
Block(-3,82,2,1)
Block(-3,82,3,1)
Block(-3,82,4,1)
Block(-3,82,5,1)
Block(-3,82,6,1)
Block(-3,82,7,1)
Block(-3,82,8,1)
Block(-3,83,-7,1)
Block(-3,83,-6,3)
Block(-3,83,-5,1)
Block(-3,83,-4,1)
Block(-3,83,-3,1)
Block(-3,83,-2,1)
Block(-3,83,-1,1)
Block(-3,83,0,1)
Block(-3,83,1,1)
Block(-3,83,2,1)
Block(-3,83,3,1)
Block(-3,83,4,1)
Block(-3,83,5,1)
Block(-3,83,6,1)
Block(-3,83,7,1)
Block(-3,83,8,1)
Block(-3,84,-7,1)
Block(-3,84,-6,3)
Block(-3,84,-5,3)
Block(-3,84,-4,1)
Block(-3,84,-3,1)
Block(-3,84,-2,1)
Block(-3,84,-1,1)
Block(-3,84,0,1)
Block(-3,84,1,1)
Block(-3,84,2,1)
Block(-3,84,3,1)
Block(-3,84,4,1)
Block(-3,84,5,1)
Block(-3,84,6,1)
Block(-3,84,7,1)
Block(-3,84,8,1)
Block(-3,85,-6,1)
Block(-3,85,-5,3)
Block(-3,85,-4,1)
Block(-3,85,-3,1)
Block(-3,85,-2,1)
Block(-3,85,-1,1)
Block(-3,85,0,1)
Block(-3,85,1,1)
Block(-3,85,2,1)
Block(-3,85,3,1)
Block(-3,85,4,1)
Block(-3,85,5,1)
Block(-3,85,6,1)
Block(-3,85,7,1)
Block(-3,85,8,1)
Block(-3,86,-6,1)
Block(-3,86,-5,3)
Block(-3,86,-4,3)
Block(-3,86,-3,1)
Block(-3,86,-2,1)
Block(-3,86,-1,1)
Block(-3,86,0,1)
Block(-3,86,1,1)
Block(-3,86,2,1)
Block(-3,86,3,1)
Block(-3,86,4,1)
Block(-3,86,5,1)
Block(-3,86,6,1)
Block(-3,86,7,1)
Block(-3,86,8,1)
Block(-3,87,-5,1)
Block(-3,87,-4,3)
Block(-3,87,-3,3)
Block(-3,87,-2,1)
Block(-3,87,-1,1)
Block(-3,87,0,1)
Block(-3,87,1,1)
Block(-3,87,2,1)
Block(-3,87,3,1)
Block(-3,87,4,1)
Block(-3,87,5,1)
Block(-3,87,6,1)
Block(-3,87,7,3)
Block(-3,87,8,1)
Block(-3,88,-4,1)
Block(-3,88,-3,3)
Block(-3,88,-2,3)
Block(-3,88,-1,1)
Block(-3,88,0,1)
Block(-3,88,1,1)
Block(-3,88,2,1)
Block(-3,88,3,1)
Block(-3,88,4,1)
Block(-3,88,5,3)
Block(-3,88,6,3)
Block(-3,88,7,1)
Block(-3,89,-4,1)
Block(-3,89,-3,3)
Block(-3,89,-2,3)
Block(-3,89,-1,3)
Block(-3,89,0,1)
Block(-3,89,1,1)
Block(-3,89,2,1)
Block(-3,89,3,3)
Block(-3,89,4,3)
Block(-3,89,5,3)
Block(-3,89,6,3)
Block(-3,89,7,1)
Block(-3,90,-3,1)
Block(-3,90,-2,3)
Block(-3,90,-1,3)
Block(-3,90,0,3)
Block(-3,90,1,3)
Block(-3,90,2,3)
Block(-3,90,3,3)
Block(-3,90,4,3)
Block(-3,90,5,3)
Block(-3,90,6,1)
Block(-3,90,7,1)
Block(-3,91,-2,1)
Block(-3,91,-1,3)
Block(-3,91,0,3)
Block(-3,91,1,3)
Block(-3,91,2,3)
Block(-3,91,3,3)
Block(-3,91,4,3)
Block(-3,91,5,2)
Block(-3,91,6,1)
Block(-3,92,-1,2)
Block(-3,92,0,3)
Block(-3,92,1,3)
Block(-3,92,2,3)
Block(-3,92,3,2)
Block(-3,92,4,2)
Block(-3,93,0,2)
Block(-3,93,1,2)
Block(-3,93,2,2)
Block(-2,0,-9,1)
Block(-2,0,-8,1)
Block(-2,0,-7,1)
Block(-2,0,-6,1)
Block(-2,0,-5,1)
Block(-2,0,-4,1)
Block(-2,0,-3,1)
Block(-2,0,-2,1)
Block(-2,0,-1,1)
Block(-2,0,0,1)
Block(-2,0,1,1)
Block(-2,0,2,1)
Block(-2,0,3,1)
Block(-2,0,4,1)
Block(-2,0,5,1)
Block(-2,0,6,1)
Block(-2,0,7,1)
Block(-2,0,8,1)
Block(-2,0,9,1)
Block(-2,1,-9,1)
Block(-2,1,-8,1)
Block(-2,1,-7,1)
Block(-2,1,-6,1)
Block(-2,1,-5,1)
Block(-2,1,-4,1)
Block(-2,1,-3,1)
Block(-2,1,-2,1)
Block(-2,1,-1,1)
Block(-2,1,0,1)
Block(-2,1,1,1)
Block(-2,1,2,1)
Block(-2,1,3,1)
Block(-2,1,4,1)
Block(-2,1,5,1)
Block(-2,1,6,1)
Block(-2,1,7,1)
Block(-2,1,8,1)
Block(-2,1,9,1)
Block(-2,2,-9,1)
Block(-2,2,-8,1)
Block(-2,2,-7,1)
Block(-2,2,-6,1)
Block(-2,2,-5,1)
Block(-2,2,-4,1)
Block(-2,2,-3,1)
Block(-2,2,-2,1)
Block(-2,2,-1,1)
Block(-2,2,0,1)
Block(-2,2,1,1)
Block(-2,2,2,1)
Block(-2,2,3,1)
Block(-2,2,4,1)
Block(-2,2,5,1)
Block(-2,2,6,1)
Block(-2,2,7,1)
Block(-2,2,8,1)
Block(-2,2,9,1)
Block(-2,3,-9,1)
Block(-2,3,-8,1)
Block(-2,3,-7,1)
Block(-2,3,-6,1)
Block(-2,3,-5,1)
Block(-2,3,-4,1)
Block(-2,3,-3,1)
Block(-2,3,-2,1)
Block(-2,3,-1,1)
Block(-2,3,0,1)
Block(-2,3,1,1)
Block(-2,3,2,1)
Block(-2,3,3,1)
Block(-2,3,4,1)
Block(-2,3,5,1)
Block(-2,3,6,1)
Block(-2,3,7,1)
Block(-2,3,8,1)
Block(-2,3,9,1)
Block(-2,3,10,1)
Block(-2,4,-8,1)
Block(-2,4,-7,1)
Block(-2,4,-6,1)
Block(-2,4,-5,1)
Block(-2,4,-4,1)
Block(-2,4,-3,1)
Block(-2,4,-2,1)
Block(-2,4,-1,1)
Block(-2,4,0,1)
Block(-2,4,1,1)
Block(-2,4,2,1)
Block(-2,4,3,1)
Block(-2,4,4,1)
Block(-2,4,5,1)
Block(-2,4,6,1)
Block(-2,4,7,1)
Block(-2,4,8,1)
Block(-2,4,9,1)
Block(-2,4,10,1)
Block(-2,5,-8,1)
Block(-2,5,-7,1)
Block(-2,5,-6,1)
Block(-2,5,-5,1)
Block(-2,5,-4,1)
Block(-2,5,-3,1)
Block(-2,5,-2,1)
Block(-2,5,-1,1)
Block(-2,5,0,1)
Block(-2,5,1,1)
Block(-2,5,2,1)
Block(-2,5,3,1)
Block(-2,5,4,1)
Block(-2,5,5,1)
Block(-2,5,6,1)
Block(-2,5,7,1)
Block(-2,5,8,1)
Block(-2,5,9,1)
Block(-2,5,10,1)
Block(-2,5,11,1)
Block(-2,6,-7,1)
Block(-2,6,-6,1)
Block(-2,6,-5,1)
Block(-2,6,-4,1)
Block(-2,6,-3,1)
Block(-2,6,-2,1)
Block(-2,6,-1,1)
Block(-2,6,0,1)
Block(-2,6,1,1)
Block(-2,6,2,1)
Block(-2,6,3,1)
Block(-2,6,4,1)
Block(-2,6,5,1)
Block(-2,6,6,1)
Block(-2,6,7,1)
Block(-2,6,8,1)
Block(-2,6,9,1)
Block(-2,6,10,1)
Block(-2,6,11,1)
Block(-2,7,-7,1)
Block(-2,7,-6,1)
Block(-2,7,-5,1)
Block(-2,7,-4,1)
Block(-2,7,-3,1)
Block(-2,7,-2,1)
Block(-2,7,-1,1)
Block(-2,7,0,1)
Block(-2,7,1,1)
Block(-2,7,2,1)
Block(-2,7,3,1)
Block(-2,7,4,1)
Block(-2,7,5,1)
Block(-2,7,6,1)
Block(-2,7,7,1)
Block(-2,7,8,1)
Block(-2,7,9,1)
Block(-2,7,10,1)
Block(-2,7,11,1)
Block(-2,8,-8,1)
Block(-2,8,-7,1)
Block(-2,8,-6,1)
Block(-2,8,-5,1)
Block(-2,8,-4,1)
Block(-2,8,-3,1)
Block(-2,8,-2,1)
Block(-2,8,-1,1)
Block(-2,8,0,1)
Block(-2,8,1,1)
Block(-2,8,2,1)
Block(-2,8,3,1)
Block(-2,8,4,1)
Block(-2,8,5,1)
Block(-2,8,6,1)
Block(-2,8,7,1)
Block(-2,8,8,1)
Block(-2,8,9,1)
Block(-2,8,10,1)
Block(-2,8,11,1)
Block(-2,9,-8,1)
Block(-2,9,-7,1)
Block(-2,9,-6,1)
Block(-2,9,-5,1)
Block(-2,9,-4,1)
Block(-2,9,-3,1)
Block(-2,9,-2,1)
Block(-2,9,-1,1)
Block(-2,9,0,1)
Block(-2,9,1,1)
Block(-2,9,2,1)
Block(-2,9,3,1)
Block(-2,9,4,1)
Block(-2,9,5,1)
Block(-2,9,6,1)
Block(-2,9,7,1)
Block(-2,9,8,1)
Block(-2,9,9,1)
Block(-2,9,10,1)
Block(-2,9,11,1)
Block(-2,10,-9,1)
Block(-2,10,-8,1)
Block(-2,10,-7,1)
Block(-2,10,-6,1)
Block(-2,10,-5,1)
Block(-2,10,-4,1)
Block(-2,10,-3,1)
Block(-2,10,-2,1)
Block(-2,10,-1,1)
Block(-2,10,0,1)
Block(-2,10,1,1)
Block(-2,10,2,1)
Block(-2,10,3,1)
Block(-2,10,4,1)
Block(-2,10,5,1)
Block(-2,10,6,1)
Block(-2,10,7,1)
Block(-2,10,8,1)
Block(-2,10,9,1)
Block(-2,10,10,1)
Block(-2,10,11,1)
Block(-2,11,-8,1)
Block(-2,11,-7,1)
Block(-2,11,-6,1)
Block(-2,11,-5,1)
Block(-2,11,-4,1)
Block(-2,11,-3,1)
Block(-2,11,-2,1)
Block(-2,11,-1,1)
Block(-2,11,0,1)
Block(-2,11,1,1)
Block(-2,11,2,1)
Block(-2,11,3,1)
Block(-2,11,4,1)
Block(-2,11,5,1)
Block(-2,11,6,1)
Block(-2,11,7,1)
Block(-2,11,8,1)
Block(-2,11,9,1)
Block(-2,11,10,1)
Block(-2,11,11,1)
Block(-2,11,12,1)
Block(-2,12,-8,1)
Block(-2,12,-7,1)
Block(-2,12,-6,1)
Block(-2,12,-5,1)
Block(-2,12,-4,1)
Block(-2,12,-3,1)
Block(-2,12,-2,1)
Block(-2,12,-1,1)
Block(-2,12,0,1)
Block(-2,12,1,1)
Block(-2,12,2,1)
Block(-2,12,3,1)
Block(-2,12,4,1)
Block(-2,12,5,1)
Block(-2,12,6,1)
Block(-2,12,7,1)
Block(-2,12,8,1)
Block(-2,12,9,1)
Block(-2,12,10,1)
Block(-2,12,11,1)
Block(-2,13,-7,1)
Block(-2,13,-6,1)
Block(-2,13,-5,1)
Block(-2,13,-4,1)
Block(-2,13,-3,1)
Block(-2,13,-2,1)
Block(-2,13,-1,1)
Block(-2,13,0,1)
Block(-2,13,1,1)
Block(-2,13,2,1)
