#######################################################################
# +-----------------------------------------------------------------+ #
# |                            BO3 object                           | #
# +-----------------------------------------------------------------+ #
#######################################################################

# The descriptions in this file are accurate only for TerrainControl and OTG.
# For MCW and OTG+ these descriptions are only accurate if the BO3 is used as a CustomObject.
# MCW and OTG+ completely reimplemented CustomStructure, check the MCW/OTG+ documentation for more information.

# This is the config file of a custom object.
# If you add this object correctly to your BiomeConfigs, it will spawn in the world.

# This is the creator of this BO3 object
Author: Unknown

# A short description of this BO3 object
Description: This BO3 was converted from a schematic using OTGEdit. The author and description information of the schematic could not be found. If you know who the author of the schematic is then please add this information.

# The BO3 version, don't change this! It can be used by external applications to do a version check.
Version: 3

# The settings mode, WriteAll, WriteWithoutComments or WriteDisable. See WorldConfig.
SettingsMode: WriteDisable

#######################################################################
# +-----------------------------------------------------------------+ #
# |                          Main settings                          | #
# +-----------------------------------------------------------------+ #
#######################################################################

# This needs to be set to true to spawn the object in the Tree and Sapling resources.
Tree: false

# The frequency of the BO3 from 1 to 200. Tries this many times to spawn this BO3 when using the CustomObject(...) resource.
# Ignored by Tree(..), Sapling(..) and CustomStructure(..)
Frequency: 40

# The rarity of the BO3 from 0 to 100. Each spawn attempt has rarity% chance to succeed when using the CustomObject(...) resource.
# Ignored by Tree(..), Sapling(..) and CustomStructure(..)
Rarity: 100.0

# If you set this to true, the BO3 will be placed with a random rotation.
RotateRandomly: false

# The spawn height of the BO3 - randomY, highestBlock or highestSolidBlock.
SpawnHeight: highestBlock

# The height limits for the BO3.
MinHeight: 0

MaxHeight: 256

# Objects can have other objects attached to it: branches. Branches can also
# have branches attached to it, which can also have branches, etc. This is the
# maximum branch depth for this objects.
MaxBranchDepth: 10

# When spawned with the UseWorld keyword, this BO3 should NOT spawn in the following biomes.
# If you writer.write the BO3 name directly in the BiomeConfigs, this will be ignored.
ExcludedBiomes: All

# To optimise this BO3 for faster loading times you can use Notepad++ to find/replace comments and abbreviate things.
# Notepad++ find/replace with regex:
# Find: ^[#;].* replace to nothing removes all lines starting with # 
# Find: ^\s*$ replace to nothing removes most empty lines 
# Notepad++ find/replace without regex:
# *Warning: This will only work for OTG 1.10.2 v21 / OTG 1.11.2 v6 or higher. B( is not recognised by lower versions.
# Find: Block( replace to B(

#######################################################################
# +-----------------------------------------------------------------+ #
# |                      Source block settings                      | #
# +-----------------------------------------------------------------+ #
#######################################################################

# The block(s) the BO3 should spawn in.
SourceBlocks: AIR

# The maximum percentage of the BO3 that can be outside the SourceBlock.
# The BO3 won't be placed on a location with more blocks outside the SourceBlock than this percentage.
MaxPercentageOutsideSourceBlock: 100

# What to do when a block is about to be placed outside the SourceBlock? (dontPlace, placeAnyway)
OutsideSourceBlock: placeAnyway

#######################################################################
# +-----------------------------------------------------------------+ #
# |                              Blocks                             | #
# +-----------------------------------------------------------------+ #
#######################################################################

# All the blocks used in the BO3 are listed here. Possible blocks:
# Block(x,y,z,id[.data][,nbtfile.nbt) or B(x,y,z,id[.data][,nbtfile.nbt)
# RandomBlock(x,y,z,id[:data][,nbtfile.nbt],chance[,id[:data][,nbtfile.nbt],chance[,...]])
# So RandomBlock(0,0,0,CHEST,chest.nbt,50,CHEST,anotherchest.nbt,100) will spawn a chest at
# the BO3 origin, and give it a 50% chance to have the contents of chest.nbt, or, if that
# fails, a 100% percent chance to have the contents of anotherchest.nbt.

Block(-13,27,1,1)
Block(-13,28,-1,1)
Block(-13,28,0,1)
Block(-13,28,1,1)
Block(-13,28,2,1)
Block(-13,29,-1,1)
Block(-13,29,0,1)
Block(-13,29,1,1)
Block(-13,29,2,1)
Block(-13,30,-2,1)
Block(-13,30,-1,1)
Block(-13,30,0,1)
Block(-13,30,1,1)
Block(-13,30,2,1)
Block(-13,30,3,1)
Block(-13,31,-1,1)
Block(-13,31,0,1)
Block(-13,31,1,1)
Block(-13,31,2,1)
Block(-13,31,3,1)
Block(-13,32,-1,1)
Block(-13,32,0,1)
Block(-13,32,1,1)
Block(-13,32,2,1)
Block(-13,33,0,1)
Block(-12,0,-3,1)
Block(-12,0,-2,1)
Block(-12,0,-1,1)
Block(-12,0,0,1)
Block(-12,1,-3,1)
Block(-12,1,-2,1)
Block(-12,1,-1,1)
Block(-12,1,0,1)
Block(-12,2,-2,1)
Block(-12,2,-1,1)
Block(-12,2,0,1)
Block(-12,3,-1,1)
Block(-12,26,0,1)
Block(-12,26,1,1)
Block(-12,27,-1,1)
Block(-12,27,0,1)
Block(-12,27,1,1)
Block(-12,27,2,1)
Block(-12,28,-2,1)
Block(-12,28,-1,1)
Block(-12,28,0,1)
Block(-12,28,1,1)
Block(-12,28,2,1)
Block(-12,28,3,1)
Block(-12,29,-3,1)
Block(-12,29,-2,1)
Block(-12,29,-1,1)
Block(-12,29,0,1)
Block(-12,29,1,1)
Block(-12,29,2,1)
Block(-12,29,3,1)
Block(-12,30,-3,1)
Block(-12,30,-2,1)
Block(-12,30,-1,1)
Block(-12,30,0,1)
Block(-12,30,1,1)
Block(-12,30,2,1)
Block(-12,30,3,1)
Block(-12,30,4,1)
Block(-12,31,-2,1)
Block(-12,31,-1,1)
Block(-12,31,0,1)
Block(-12,31,1,1)
Block(-12,31,2,1)
Block(-12,31,3,1)
Block(-12,31,4,1)
Block(-12,32,-2,1)
Block(-12,32,-1,1)
Block(-12,32,0,1)
Block(-12,32,1,1)
Block(-12,32,2,1)
Block(-12,32,3,1)
Block(-12,33,-1,1)
Block(-12,33,0,1)
Block(-12,33,1,1)
Block(-12,33,2,1)
Block(-12,34,0,1)
Block(-12,89,0,1)
Block(-11,0,-5,1)
Block(-11,0,-4,1)
Block(-11,0,-3,1)
Block(-11,0,-2,1)
Block(-11,0,-1,1)
Block(-11,0,0,1)
Block(-11,0,1,1)
Block(-11,0,2,1)
Block(-11,1,-4,1)
Block(-11,1,-3,1)
Block(-11,1,-2,1)
Block(-11,1,-1,1)
Block(-11,1,0,1)
Block(-11,1,1,1)
Block(-11,1,2,1)
Block(-11,2,-4,1)
Block(-11,2,-3,1)
Block(-11,2,-2,1)
Block(-11,2,-1,1)
Block(-11,2,0,1)
Block(-11,2,1,1)
Block(-11,2,2,1)
Block(-11,3,-3,1)
Block(-11,3,-2,1)
Block(-11,3,-1,1)
Block(-11,3,0,1)
Block(-11,3,1,1)
Block(-11,3,2,1)
Block(-11,4,-3,1)
Block(-11,4,-2,1)
Block(-11,4,-1,1)
Block(-11,4,0,1)
Block(-11,4,1,1)
Block(-11,5,-2,1)
Block(-11,5,-1,1)
Block(-11,5,0,1)
Block(-11,5,1,1)
Block(-11,6,-2,1)
Block(-11,6,-1,1)
Block(-11,6,0,1)
Block(-11,6,1,1)
Block(-11,7,-1,1)
Block(-11,7,0,1)
Block(-11,7,1,1)
Block(-11,7,2,1)
Block(-11,8,0,1)
Block(-11,8,1,1)
Block(-11,8,2,1)
Block(-11,9,0,1)
Block(-11,9,1,1)
Block(-11,9,2,1)
Block(-11,10,0,1)
Block(-11,10,1,1)
Block(-11,10,2,1)
Block(-11,11,1,1)
Block(-11,11,2,1)
Block(-11,11,3,1)
Block(-11,12,1,1)
Block(-11,12,2,1)
Block(-11,12,3,1)
Block(-11,13,2,1)
Block(-11,13,3,1)
Block(-11,14,2,1)
Block(-11,14,3,1)
Block(-11,14,4,1)
Block(-11,15,2,1)
Block(-11,15,3,1)
Block(-11,15,4,1)
Block(-11,16,2,1)
Block(-11,16,3,1)
Block(-11,16,4,1)
Block(-11,17,1,1)
Block(-11,17,2,1)
Block(-11,17,3,1)
Block(-11,17,4,1)
Block(-11,18,1,1)
Block(-11,18,2,1)
Block(-11,18,3,1)
Block(-11,18,4,1)
Block(-11,19,1,1)
Block(-11,19,2,1)
Block(-11,19,3,1)
Block(-11,25,0,1)
Block(-11,25,1,1)
Block(-11,26,-1,1)
Block(-11,26,0,1)
Block(-11,26,1,1)
Block(-11,26,2,1)
Block(-11,27,-2,1)
Block(-11,27,-1,1)
Block(-11,27,0,1)
Block(-11,27,1,1)
Block(-11,27,2,1)
Block(-11,27,3,1)
Block(-11,28,-3,1)
Block(-11,28,-2,1)
Block(-11,28,-1,1)
Block(-11,28,0,1)
Block(-11,28,1,1)
Block(-11,28,2,1)
Block(-11,28,3,1)
Block(-11,28,4,1)
Block(-11,29,-4,1)
Block(-11,29,-3,1)
Block(-11,29,-2,1)
Block(-11,29,-1,1)
Block(-11,29,0,1)
Block(-11,29,1,1)
Block(-11,29,2,1)
Block(-11,29,3,1)
Block(-11,29,4,1)
Block(-11,30,-4,1)
Block(-11,30,-3,1)
Block(-11,30,-2,1)
Block(-11,30,-1,1)
Block(-11,30,0,1)
Block(-11,30,1,1)
Block(-11,30,2,1)
Block(-11,30,3,1)
Block(-11,30,4,1)
Block(-11,30,5,1)
Block(-11,31,-3,1)
Block(-11,31,-2,1)
Block(-11,31,-1,1)
Block(-11,31,0,1)
Block(-11,31,1,1)
Block(-11,31,2,1)
Block(-11,31,3,1)
Block(-11,31,4,1)
Block(-11,31,5,1)
Block(-11,32,-3,1)
Block(-11,32,-2,1)
Block(-11,32,-1,1)
Block(-11,32,0,1)
Block(-11,32,1,1)
Block(-11,32,2,1)
Block(-11,32,3,1)
Block(-11,32,4,1)
Block(-11,32,5,1)
Block(-11,33,-2,1)
Block(-11,33,-1,1)
Block(-11,33,0,1)
Block(-11,33,1,1)
Block(-11,33,2,1)
Block(-11,33,3,1)
Block(-11,33,4,1)
Block(-11,34,-2,1)
Block(-11,34,-1,1)
Block(-11,34,0,1)
Block(-11,34,1,1)
Block(-11,35,-1,1)
Block(-11,35,0,1)
Block(-11,75,0,1)
Block(-11,75,1,1)
Block(-11,76,0,1)
Block(-11,76,1,1)
Block(-11,76,2,1)
Block(-11,77,0,1)
Block(-11,77,1,1)
Block(-11,77,2,1)
Block(-11,78,1,1)
Block(-11,87,-1,1)
Block(-11,87,0,1)
Block(-11,88,-1,1)
Block(-11,88,0,1)
Block(-11,88,1,1)
Block(-11,88,2,1)
Block(-11,89,-1,1)
Block(-11,89,0,3)
Block(-11,89,1,1)
Block(-11,89,2,1)
Block(-11,89,3,1)
Block(-11,90,-1,1)
Block(-11,90,0,1)
Block(-11,90,1,1)
Block(-11,90,2,1)
Block(-11,90,3,1)
Block(-11,91,-1,1)
Block(-11,91,0,1)
Block(-11,91,1,1)
Block(-11,91,2,1)
Block(-10,0,-6,1)
Block(-10,0,-5,1)
Block(-10,0,-4,1)
Block(-10,0,-3,1)
Block(-10,0,-2,1)
Block(-10,0,-1,1)
Block(-10,0,0,1)
Block(-10,0,1,1)
Block(-10,0,2,1)
Block(-10,0,3,1)
Block(-10,1,-5,1)
Block(-10,1,-4,1)
Block(-10,1,-3,1)
Block(-10,1,-2,1)
Block(-10,1,-1,1)
Block(-10,1,0,1)
Block(-10,1,1,1)
Block(-10,1,2,1)
Block(-10,1,3,1)
Block(-10,2,-5,1)
Block(-10,2,-4,1)
Block(-10,2,-3,1)
Block(-10,2,-2,1)
Block(-10,2,-1,1)
Block(-10,2,0,1)
Block(-10,2,1,1)
Block(-10,2,2,1)
Block(-10,2,3,1)
Block(-10,3,-4,1)
Block(-10,3,-3,1)
Block(-10,3,-2,1)
Block(-10,3,-1,1)
Block(-10,3,0,1)
Block(-10,3,1,1)
Block(-10,3,2,1)
Block(-10,3,3,1)
Block(-10,4,-4,1)
Block(-10,4,-3,1)
Block(-10,4,-2,1)
Block(-10,4,-1,1)
Block(-10,4,0,1)
Block(-10,4,1,1)
Block(-10,4,2,1)
Block(-10,4,3,1)
Block(-10,5,-4,1)
Block(-10,5,-3,1)
Block(-10,5,-2,1)
Block(-10,5,-1,1)
Block(-10,5,0,1)
Block(-10,5,1,1)
Block(-10,5,2,1)
Block(-10,5,3,1)
Block(-10,6,-3,1)
Block(-10,6,-2,1)
Block(-10,6,-1,1)
Block(-10,6,0,1)
Block(-10,6,1,1)
Block(-10,6,2,1)
Block(-10,6,3,1)
Block(-10,7,-3,1)
Block(-10,7,-2,1)
Block(-10,7,-1,1)
Block(-10,7,0,1)
Block(-10,7,1,1)
Block(-10,7,2,1)
Block(-10,7,3,1)
Block(-10,8,-2,1)
Block(-10,8,-1,1)
Block(-10,8,0,1)
Block(-10,8,1,1)
Block(-10,8,2,1)
Block(-10,8,3,1)
Block(-10,9,-2,1)
Block(-10,9,-1,1)
Block(-10,9,0,1)
Block(-10,9,1,1)
Block(-10,9,2,1)
Block(-10,9,3,1)
Block(-10,10,-2,1)
Block(-10,10,-1,1)
Block(-10,10,0,1)
Block(-10,10,1,1)
Block(-10,10,2,1)
Block(-10,10,3,1)
Block(-10,10,4,1)
Block(-10,11,-1,1)
Block(-10,11,0,1)
Block(-10,11,1,1)
Block(-10,11,2,1)
Block(-10,11,3,1)
Block(-10,11,4,1)
Block(-10,12,-1,1)
Block(-10,12,0,1)
Block(-10,12,1,1)
Block(-10,12,2,1)
Block(-10,12,3,1)
Block(-10,12,4,1)
Block(-10,13,0,1)
Block(-10,13,1,1)
Block(-10,13,2,1)
Block(-10,13,3,1)
Block(-10,13,4,1)
Block(-10,13,5,1)
Block(-10,14,0,1)
Block(-10,14,1,1)
Block(-10,14,2,1)
Block(-10,14,3,1)
Block(-10,14,4,1)
Block(-10,14,5,1)
Block(-10,15,0,1)
Block(-10,15,1,1)
Block(-10,15,2,1)
Block(-10,15,3,1)
Block(-10,15,4,1)
Block(-10,15,5,1)
Block(-10,16,0,1)
Block(-10,16,1,1)
Block(-10,16,2,1)
Block(-10,16,3,1)
Block(-10,16,4,1)
Block(-10,16,5,1)
Block(-10,17,0,1)
Block(-10,17,1,1)
Block(-10,17,2,1)
Block(-10,17,3,1)
Block(-10,17,4,1)
Block(-10,17,5,1)
Block(-10,17,6,1)
Block(-10,18,-1,1)
Block(-10,18,0,1)
Block(-10,18,1,1)
Block(-10,18,2,1)
Block(-10,18,3,1)
Block(-10,18,4,1)
Block(-10,18,5,1)
Block(-10,18,6,1)
Block(-10,19,-1,1)
Block(-10,19,0,1)
Block(-10,19,1,1)
Block(-10,19,2,1)
Block(-10,19,3,1)
Block(-10,19,4,1)
Block(-10,19,5,1)
Block(-10,19,6,1)
Block(-10,20,-2,1)
Block(-10,20,-1,1)
Block(-10,20,0,1)
Block(-10,20,1,1)
Block(-10,20,2,1)
Block(-10,20,3,1)
Block(-10,20,4,1)
Block(-10,20,5,1)
Block(-10,21,-2,1)
Block(-10,21,-1,1)
Block(-10,21,0,1)
Block(-10,21,1,1)
Block(-10,21,2,1)
Block(-10,21,3,1)
Block(-10,21,4,1)
Block(-10,22,-1,1)
Block(-10,22,0,1)
Block(-10,22,1,1)
Block(-10,22,2,1)
Block(-10,22,3,1)
Block(-10,23,0,1)
Block(-10,23,1,1)
Block(-10,23,2,1)
Block(-10,24,0,1)
Block(-10,24,1,1)
Block(-10,24,2,1)
Block(-10,25,-1,1)
Block(-10,25,0,1)
Block(-10,25,1,1)
Block(-10,25,2,1)
Block(-10,25,3,1)
Block(-10,26,-2,1)
Block(-10,26,-1,1)
Block(-10,26,0,1)
Block(-10,26,1,1)
Block(-10,26,2,1)
Block(-10,26,3,1)
Block(-10,27,-3,1)
Block(-10,27,-2,1)
Block(-10,27,-1,1)
Block(-10,27,0,1)
Block(-10,27,1,1)
Block(-10,27,2,1)
Block(-10,27,3,1)
Block(-10,27,4,1)
Block(-10,28,-4,1)
Block(-10,28,-3,1)
Block(-10,28,-2,1)
Block(-10,28,-1,1)
Block(-10,28,0,1)
Block(-10,28,1,1)
Block(-10,28,2,1)
Block(-10,28,3,1)
Block(-10,28,4,1)
Block(-10,29,-5,1)
Block(-10,29,-4,1)
Block(-10,29,-3,1)
Block(-10,29,-2,1)
Block(-10,29,-1,1)
Block(-10,29,0,1)
Block(-10,29,1,1)
Block(-10,29,2,1)
Block(-10,29,3,1)
Block(-10,29,4,1)
Block(-10,29,5,1)
Block(-10,30,-5,1)
Block(-10,30,-4,1)
Block(-10,30,-3,1)
Block(-10,30,-2,1)
Block(-10,30,-1,1)
Block(-10,30,0,1)
Block(-10,30,1,1)
Block(-10,30,2,1)
Block(-10,30,3,1)
Block(-10,30,4,1)
Block(-10,30,5,1)
Block(-10,30,6,1)
Block(-10,31,-4,1)
Block(-10,31,-3,1)
Block(-10,31,-2,1)
Block(-10,31,-1,1)
Block(-10,31,0,1)
Block(-10,31,1,1)
Block(-10,31,2,1)
Block(-10,31,3,1)
Block(-10,31,4,1)
Block(-10,31,5,1)
Block(-10,31,6,1)
Block(-10,32,-4,1)
Block(-10,32,-3,1)
Block(-10,32,-2,1)
Block(-10,32,-1,1)
Block(-10,32,0,1)
Block(-10,32,1,1)
Block(-10,32,2,1)
Block(-10,32,3,1)
Block(-10,32,4,1)
Block(-10,32,5,1)
Block(-10,32,6,1)
Block(-10,33,-3,1)
Block(-10,33,-2,1)
Block(-10,33,-1,1)
Block(-10,33,0,1)
Block(-10,33,1,1)
Block(-10,33,2,1)
Block(-10,33,3,1)
Block(-10,33,4,1)
Block(-10,33,5,1)
Block(-10,34,-3,1)
Block(-10,34,-2,1)
Block(-10,34,-1,1)
Block(-10,34,0,1)
Block(-10,34,1,1)
Block(-10,34,2,1)
Block(-10,34,3,1)
Block(-10,34,4,1)
Block(-10,35,-2,1)
Block(-10,35,-1,1)
Block(-10,35,0,1)
Block(-10,35,1,1)
Block(-10,36,-1,1)
Block(-10,36,0,1)
Block(-10,50,2,1)
Block(-10,50,3,1)
Block(-10,50,4,1)
Block(-10,51,1,1)
Block(-10,51,2,1)
Block(-10,51,3,1)
Block(-10,51,4,1)
Block(-10,51,5,1)
Block(-10,52,-1,1)
Block(-10,52,0,1)
Block(-10,52,1,1)
Block(-10,52,2,1)
Block(-10,52,3,1)
Block(-10,52,4,1)
Block(-10,52,5,1)
Block(-10,52,6,1)
Block(-10,53,-2,1)
Block(-10,53,-1,1)
Block(-10,53,0,1)
Block(-10,53,1,1)
Block(-10,53,2,1)
Block(-10,53,3,1)
Block(-10,53,4,1)
Block(-10,53,5,1)
Block(-10,53,6,1)
Block(-10,54,-4,1)
Block(-10,54,-3,1)
Block(-10,54,-2,1)
Block(-10,54,-1,1)
Block(-10,54,0,1)
Block(-10,54,1,1)
Block(-10,54,2,1)
Block(-10,54,3,1)
Block(-10,54,4,1)
Block(-10,54,5,1)
Block(-10,55,-4,1)
Block(-10,55,-3,1)
Block(-10,55,-2,1)
Block(-10,55,-1,1)
Block(-10,55,0,1)
Block(-10,72,4,1)
Block(-10,72,5,1)
Block(-10,73,0,1)
Block(-10,73,1,1)
Block(-10,73,2,1)
Block(-10,73,3,1)
Block(-10,73,4,1)
Block(-10,73,5,1)
Block(-10,74,-1,1)
Block(-10,74,0,1)
Block(-10,74,1,1)
Block(-10,74,2,1)
Block(-10,74,3,1)
Block(-10,74,4,1)
Block(-10,74,5,1)
Block(-10,74,6,1)
Block(-10,75,-3,1)
Block(-10,75,-2,1)
Block(-10,75,-1,1)
Block(-10,75,0,1)
Block(-10,75,1,1)
Block(-10,75,2,1)
Block(-10,75,3,1)
Block(-10,75,4,1)
Block(-10,75,5,1)
Block(-10,75,6,1)
Block(-10,76,-2,1)
Block(-10,76,-1,1)
Block(-10,76,0,1)
Block(-10,76,1,1)
Block(-10,76,2,1)
Block(-10,76,3,1)
Block(-10,76,4,1)
Block(-10,76,5,1)
Block(-10,76,6,1)
Block(-10,77,-2,1)
Block(-10,77,-1,1)
Block(-10,77,0,1)
Block(-10,77,1,1)
Block(-10,77,2,1)
Block(-10,77,3,1)
Block(-10,77,4,1)
Block(-10,77,5,1)
Block(-10,78,-1,1)
Block(-10,78,0,1)
Block(-10,78,1,1)
Block(-10,78,2,1)
Block(-10,78,3,1)
Block(-10,78,4,1)
Block(-10,78,5,1)
Block(-10,79,0,1)
Block(-10,79,1,1)
Block(-10,79,2,1)
Block(-10,79,3,1)
Block(-10,79,4,1)
Block(-10,79,5,1)
Block(-10,80,0,1)
Block(-10,80,1,1)
Block(-10,80,2,1)
Block(-10,80,3,1)
Block(-10,80,4,1)
Block(-10,80,5,1)
Block(-10,81,1,1)
Block(-10,81,2,1)
Block(-10,81,3,1)
Block(-10,81,4,1)
Block(-10,82,2,1)
Block(-10,82,3,1)
Block(-10,82,4,1)
Block(-10,84,-3,1)
Block(-10,84,-2,1)
Block(-10,85,-3,1)
Block(-10,85,-2,1)
Block(-10,85,-1,1)
Block(-10,86,-3,1)
Block(-10,86,-2,1)
Block(-10,86,-1,1)
Block(-10,86,0,1)
Block(-10,86,1,1)
Block(-10,87,-3,1)
Block(-10,87,-2,1)
Block(-10,87,-1,1)
Block(-10,87,0,1)
Block(-10,87,1,1)
Block(-10,87,2,1)
Block(-10,87,3,1)
Block(-10,87,4,1)
Block(-10,88,-3,1)
Block(-10,88,-2,1)
Block(-10,88,-1,1)
Block(-10,88,0,1)
Block(-10,88,1,1)
Block(-10,88,2,1)
Block(-10,88,3,1)
Block(-10,88,4,1)
Block(-10,88,5,1)
Block(-10,88,6,1)
Block(-10,89,-2,1)
Block(-10,89,-1,1)
Block(-10,89,0,1)
Block(-10,89,1,1)
Block(-10,89,2,1)
Block(-10,89,3,1)
Block(-10,89,4,1)
Block(-10,89,5,1)
Block(-10,89,6,1)
Block(-10,89,7,1)
Block(-10,90,-2,1)
Block(-10,90,-1,1)
Block(-10,90,0,1)
Block(-10,90,1,1)
Block(-10,90,2,1)
Block(-10,90,3,1)
Block(-10,90,4,1)
Block(-10,90,5,1)
Block(-10,90,6,1)
Block(-10,91,-2,1)
Block(-10,91,-1,1)
Block(-10,91,0,1)
Block(-10,91,1,1)
Block(-10,91,2,1)
Block(-10,91,3,1)
Block(-10,91,4,1)
Block(-10,91,5,1)
Block(-10,92,-1,1)
Block(-10,92,0,1)
Block(-10,92,1,1)
Block(-10,92,2,1)
Block(-10,92,3,1)
Block(-10,93,-1,1)
Block(-10,93,0,1)
Block(-10,93,1,1)
Block(-10,93,2,1)
Block(-10,94,-1,1)
Block(-10,94,0,1)
Block(-10,96,2,1)
Block(-10,96,3,1)
Block(-10,97,0,1)
Block(-10,97,1,1)
Block(-10,97,2,1)
Block(-10,97,3,1)
Block(-10,98,-2,1)
Block(-10,98,-1,1)
Block(-10,98,0,1)
Block(-10,98,1,1)
Block(-10,98,2,1)
Block(-10,98,3,1)
Block(-10,99,-2,1)
Block(-10,99,-1,1)
Block(-10,99,0,1)
Block(-10,99,1,1)
Block(-10,99,2,1)
Block(-10,100,0,1)
Block(-10,100,1,1)
Block(-10,100,2,1)
Block(-9,0,-6,1)
Block(-9,0,-5,1)
Block(-9,0,-4,1)
Block(-9,0,-3,1)
Block(-9,0,-2,1)
Block(-9,0,-1,1)
Block(-9,0,0,1)
Block(-9,0,1,1)
Block(-9,0,2,1)
Block(-9,0,3,1)
Block(-9,0,4,1)
Block(-9,1,-6,1)
Block(-9,1,-5,1)
Block(-9,1,-4,1)
Block(-9,1,-3,1)
Block(-9,1,-2,1)
Block(-9,1,-1,1)
Block(-9,1,0,1)
Block(-9,1,1,1)
Block(-9,1,2,1)
Block(-9,1,3,1)
Block(-9,1,4,1)
Block(-9,2,-6,1)
Block(-9,2,-5,1)
Block(-9,2,-4,1)
Block(-9,2,-3,1)
Block(-9,2,-2,1)
Block(-9,2,-1,1)
Block(-9,2,0,1)
Block(-9,2,1,1)
Block(-9,2,2,1)
Block(-9,2,3,1)
Block(-9,2,4,1)
Block(-9,3,-5,1)
Block(-9,3,-4,1)
Block(-9,3,-3,1)
Block(-9,3,-2,1)
Block(-9,3,-1,1)
Block(-9,3,0,1)
Block(-9,3,1,1)
Block(-9,3,2,1)
Block(-9,3,3,1)
Block(-9,3,4,1)
Block(-9,4,-5,1)
Block(-9,4,-4,1)
Block(-9,4,-3,1)
Block(-9,4,-2,1)
Block(-9,4,-1,1)
Block(-9,4,0,1)
Block(-9,4,1,1)
Block(-9,4,2,1)
Block(-9,4,3,1)
Block(-9,4,4,1)
Block(-9,5,-5,1)
Block(-9,5,-4,1)
Block(-9,5,-3,1)
Block(-9,5,-2,1)
Block(-9,5,-1,1)
Block(-9,5,0,1)
Block(-9,5,1,1)
Block(-9,5,2,1)
Block(-9,5,3,1)
Block(-9,5,4,1)
Block(-9,6,-5,1)
Block(-9,6,-4,1)
Block(-9,6,-3,1)
Block(-9,6,-2,1)
Block(-9,6,-1,1)
Block(-9,6,0,1)
Block(-9,6,1,1)
Block(-9,6,2,1)
Block(-9,6,3,1)
Block(-9,6,4,1)
Block(-9,7,-4,1)
Block(-9,7,-3,1)
Block(-9,7,-2,1)
Block(-9,7,-1,1)
Block(-9,7,0,1)
Block(-9,7,1,1)
Block(-9,7,2,1)
Block(-9,7,3,1)
Block(-9,7,4,1)
Block(-9,8,-4,1)
Block(-9,8,-3,1)
Block(-9,8,-2,1)
Block(-9,8,-1,1)
Block(-9,8,0,1)
Block(-9,8,1,1)
Block(-9,8,2,1)
Block(-9,8,3,1)
Block(-9,8,4,1)
Block(-9,9,-4,1)
Block(-9,9,-3,1)
Block(-9,9,-2,1)
Block(-9,9,-1,1)
Block(-9,9,0,1)
Block(-9,9,1,1)
Block(-9,9,2,1)
Block(-9,9,3,1)
Block(-9,9,4,1)
Block(-9,9,5,1)
Block(-9,10,-4,1)
Block(-9,10,-3,1)
Block(-9,10,-2,1)
Block(-9,10,-1,1)
Block(-9,10,0,1)
Block(-9,10,1,1)
Block(-9,10,2,1)
Block(-9,10,3,1)
Block(-9,10,4,1)
Block(-9,10,5,1)
Block(-9,11,-3,1)
Block(-9,11,-2,1)
Block(-9,11,-1,1)
Block(-9,11,0,1)
Block(-9,11,1,1)
Block(-9,11,2,1)
Block(-9,11,3,1)
Block(-9,11,4,1)
Block(-9,11,5,1)
Block(-9,12,-3,1)
Block(-9,12,-2,1)
Block(-9,12,-1,1)
Block(-9,12,0,1)
Block(-9,12,1,1)
Block(-9,12,2,1)
Block(-9,12,3,1)
Block(-9,12,4,1)
Block(-9,12,5,1)
Block(-9,12,6,1)
Block(-9,13,-3,1)
Block(-9,13,-2,1)
Block(-9,13,-1,1)
Block(-9,13,0,1)
Block(-9,13,1,1)
Block(-9,13,2,1)
Block(-9,13,3,1)
Block(-9,13,4,1)
Block(-9,13,5,1)
Block(-9,13,6,1)
Block(-9,14,-2,1)
Block(-9,14,-1,1)
Block(-9,14,0,1)
Block(-9,14,1,1)
Block(-9,14,2,1)
Block(-9,14,3,1)
Block(-9,14,4,1)
Block(-9,14,5,1)
Block(-9,14,6,1)
Block(-9,15,-2,1)
Block(-9,15,-1,1)
Block(-9,15,0,1)
Block(-9,15,1,1)
Block(-9,15,2,1)
Block(-9,15,3,1)
Block(-9,15,4,1)
Block(-9,15,5,1)
Block(-9,15,6,1)
Block(-9,16,-2,1)
Block(-9,16,-1,1)
Block(-9,16,0,1)
Block(-9,16,1,1)
Block(-9,16,2,1)
Block(-9,16,3,1)
Block(-9,16,4,1)
Block(-9,16,5,1)
Block(-9,16,6,1)
Block(-9,16,7,1)
Block(-9,17,-2,1)
Block(-9,17,-1,1)
Block(-9,17,0,1)
Block(-9,17,1,1)
Block(-9,17,2,1)
Block(-9,17,3,1)
Block(-9,17,4,1)
Block(-9,17,5,1)
Block(-9,17,6,1)
Block(-9,17,7,1)
Block(-9,18,-2,1)
Block(-9,18,-1,1)
Block(-9,18,0,1)
Block(-9,18,1,1)
Block(-9,18,2,1)
Block(-9,18,3,1)
Block(-9,18,4,1)
Block(-9,18,5,1)
Block(-9,18,6,1)
Block(-9,18,7,1)
Block(-9,19,-3,1)
Block(-9,19,-2,1)
Block(-9,19,-1,1)
Block(-9,19,0,1)
Block(-9,19,1,1)
Block(-9,19,2,1)
Block(-9,19,3,1)
Block(-9,19,4,1)
Block(-9,19,5,1)
Block(-9,19,6,1)
Block(-9,19,7,1)
Block(-9,20,-3,1)
Block(-9,20,-2,1)
Block(-9,20,-1,1)
Block(-9,20,0,1)
Block(-9,20,1,1)
Block(-9,20,2,1)
Block(-9,20,3,1)
Block(-9,20,4,1)
Block(-9,20,5,1)
Block(-9,20,6,1)
Block(-9,20,7,1)
Block(-9,21,-4,1)
Block(-9,21,-3,1)
Block(-9,21,-2,1)
Block(-9,21,-1,1)
Block(-9,21,0,1)
Block(-9,21,1,1)
Block(-9,21,2,1)
Block(-9,21,3,1)
Block(-9,21,4,1)
Block(-9,21,5,1)
Block(-9,21,6,1)
Block(-9,21,7,1)
Block(-9,22,-4,1)
Block(-9,22,-3,1)
Block(-9,22,-2,1)
Block(-9,22,-1,1)
Block(-9,22,0,1)
Block(-9,22,1,1)
Block(-9,22,2,1)
Block(-9,22,3,1)
Block(-9,22,4,1)
Block(-9,22,5,1)
Block(-9,22,6,1)
Block(-9,22,7,1)
Block(-9,23,-4,1)
Block(-9,23,-3,1)
Block(-9,23,-2,1)
Block(-9,23,-1,1)
Block(-9,23,0,1)
Block(-9,23,1,1)
Block(-9,23,2,1)
Block(-9,23,3,1)
Block(-9,23,4,1)
Block(-9,23,5,1)
Block(-9,23,6,1)
Block(-9,23,7,1)
Block(-9,24,-4,1)
Block(-9,24,-3,1)
Block(-9,24,-2,1)
Block(-9,24,-1,1)
Block(-9,24,0,1)
Block(-9,24,1,1)
Block(-9,24,2,1)
Block(-9,24,3,1)
Block(-9,24,4,1)
Block(-9,25,-3,1)
Block(-9,25,-2,1)
Block(-9,25,-1,1)
Block(-9,25,0,1)
Block(-9,25,1,1)
Block(-9,25,2,1)
Block(-9,25,3,1)
Block(-9,25,4,1)
Block(-9,26,-3,1)
Block(-9,26,-2,1)
Block(-9,26,-1,1)
Block(-9,26,0,1)
Block(-9,26,1,1)
Block(-9,26,2,1)
Block(-9,26,3,1)
Block(-9,26,4,1)
Block(-9,27,-4,1)
Block(-9,27,-3,1)
Block(-9,27,-2,1)
Block(-9,27,-1,1)
Block(-9,27,0,1)
Block(-9,27,1,1)
Block(-9,27,2,1)
Block(-9,27,3,1)
Block(-9,27,4,1)
Block(-9,28,-5,1)
Block(-9,28,-4,1)
Block(-9,28,-3,1)
Block(-9,28,-2,1)
Block(-9,28,-1,1)
Block(-9,28,0,1)
Block(-9,28,1,1)
Block(-9,28,2,1)
Block(-9,28,3,1)
Block(-9,28,4,1)
Block(-9,28,5,1)
Block(-9,29,-6,1)
Block(-9,29,-5,1)
Block(-9,29,-4,1)
Block(-9,29,-3,1)
Block(-9,29,-2,1)
Block(-9,29,-1,1)
Block(-9,29,0,1)
Block(-9,29,1,1)
Block(-9,29,2,1)
Block(-9,29,3,1)
Block(-9,29,4,1)
Block(-9,29,5,1)
Block(-9,29,6,1)
Block(-9,30,-6,1)
Block(-9,30,-5,1)
Block(-9,30,-4,1)
Block(-9,30,-3,1)
Block(-9,30,-2,1)
Block(-9,30,-1,1)
Block(-9,30,0,1)
Block(-9,30,1,1)
Block(-9,30,2,1)
Block(-9,30,3,1)
Block(-9,30,4,1)
Block(-9,30,5,1)
Block(-9,30,6,1)
Block(-9,31,-5,1)
Block(-9,31,-4,1)
Block(-9,31,-3,1)
Block(-9,31,-2,1)
Block(-9,31,-1,1)
Block(-9,31,0,1)
Block(-9,31,1,1)
Block(-9,31,2,1)
Block(-9,31,3,1)
Block(-9,31,4,1)
Block(-9,31,5,1)
Block(-9,31,6,1)
Block(-9,31,7,1)
Block(-9,32,-4,1)
Block(-9,32,-3,1)
Block(-9,32,-2,1)
Block(-9,32,-1,1)
Block(-9,32,0,1)
Block(-9,32,1,1)
Block(-9,32,2,1)
Block(-9,32,3,1)
Block(-9,32,4,1)
Block(-9,32,5,1)
Block(-9,32,6,1)
Block(-9,32,7,1)
Block(-9,33,-4,1)
Block(-9,33,-3,1)
Block(-9,33,-2,1)
Block(-9,33,-1,1)
Block(-9,33,0,1)
Block(-9,33,1,1)
Block(-9,33,2,1)
Block(-9,33,3,1)
Block(-9,33,4,1)
Block(-9,33,5,1)
Block(-9,33,6,1)
Block(-9,34,-4,1)
Block(-9,34,-3,1)
Block(-9,34,-2,1)
Block(-9,34,-1,1)
Block(-9,34,0,1)
Block(-9,34,1,1)
Block(-9,34,2,1)
Block(-9,34,3,1)
Block(-9,34,4,1)
Block(-9,34,5,1)
Block(-9,35,-4,1)
Block(-9,35,-3,1)
Block(-9,35,-2,1)
Block(-9,35,-1,1)
Block(-9,35,0,1)
Block(-9,35,1,1)
Block(-9,35,2,1)
Block(-9,35,3,1)
Block(-9,36,-3,1)
Block(-9,36,-2,1)
Block(-9,36,-1,1)
Block(-9,36,0,1)
Block(-9,36,1,1)
Block(-9,36,2,1)
Block(-9,37,-2,1)
Block(-9,37,-1,1)
Block(-9,37,0,1)
Block(-9,38,-5,1)
Block(-9,38,-3,1)
Block(-9,38,-2,1)
Block(-9,38,-1,1)
Block(-9,39,-7,1)
Block(-9,39,-6,1)
Block(-9,39,-5,1)
Block(-9,39,-4,1)
Block(-9,39,-3,1)
Block(-9,39,-2,1)
Block(-9,39,-1,1)
Block(-9,40,-7,1)
Block(-9,40,-6,1)
Block(-9,40,-5,1)
Block(-9,40,-4,1)
Block(-9,40,-3,1)
Block(-9,40,-2,1)
Block(-9,40,-1,1)
Block(-9,41,-7,1)
Block(-9,41,-6,1)
Block(-9,41,-5,1)
Block(-9,41,-4,1)
Block(-9,41,-3,1)
Block(-9,41,-2,1)
Block(-9,41,-1,1)
Block(-9,41,0,1)
Block(-9,42,-6,1)
Block(-9,42,-5,1)
Block(-9,42,-4,1)
Block(-9,42,-3,1)
Block(-9,42,-2,1)
Block(-9,42,-1,1)
Block(-9,42,0,1)
Block(-9,42,1,1)
Block(-9,43,-4,1)
Block(-9,43,-3,1)
Block(-9,43,-2,1)
Block(-9,43,-1,1)
Block(-9,43,0,1)
Block(-9,43,1,1)
Block(-9,43,2,1)
Block(-9,44,-3,1)
Block(-9,44,-2,1)
Block(-9,44,-1,1)
Block(-9,44,0,1)
Block(-9,44,1,1)
Block(-9,44,2,1)
Block(-9,44,3,1)
Block(-9,45,-2,1)
Block(-9,45,-1,1)
Block(-9,45,0,1)
Block(-9,45,1,1)
Block(-9,45,2,1)
Block(-9,45,3,1)
Block(-9,45,4,1)
Block(-9,46,0,1)
Block(-9,46,1,1)
Block(-9,46,2,1)
Block(-9,46,3,1)
Block(-9,46,4,1)
Block(-9,47,1,1)
Block(-9,47,2,1)
Block(-9,47,3,1)
Block(-9,47,4,1)
Block(-9,48,1,1)
Block(-9,48,2,1)
Block(-9,48,3,1)
Block(-9,48,4,1)
Block(-9,48,5,1)
Block(-9,49,1,1)
Block(-9,49,2,1)
Block(-9,49,3,1)
Block(-9,49,4,1)
Block(-9,49,5,1)
Block(-9,50,0,1)
Block(-9,50,1,1)
Block(-9,50,2,1)
Block(-9,50,3,1)
Block(-9,50,4,1)
Block(-9,50,5,1)
Block(-9,50,6,1)
Block(-9,51,-2,1)
Block(-9,51,-1,1)
Block(-9,51,0,1)
Block(-9,51,1,1)
Block(-9,51,2,1)
Block(-9,51,3,1)
Block(-9,51,4,1)
Block(-9,51,5,1)
Block(-9,51,6,1)
Block(-9,51,7,1)
Block(-9,52,-3,1)
Block(-9,52,-2,1)
Block(-9,52,-1,1)
Block(-9,52,0,1)
Block(-9,52,1,1)
Block(-9,52,2,1)
Block(-9,52,3,1)
Block(-9,52,4,1)
Block(-9,52,5,1)
Block(-9,52,6,1)
Block(-9,52,7,1)
Block(-9,53,-5,1)
Block(-9,53,-4,1)
Block(-9,53,-3,1)
Block(-9,53,-2,1)
Block(-9,53,-1,1)
Block(-9,53,0,1)
Block(-9,53,1,1)
Block(-9,53,2,1)
Block(-9,53,3,1)
Block(-9,53,4,1)
Block(-9,53,5,1)
Block(-9,53,6,1)
Block(-9,53,7,1)
Block(-9,54,-6,1)
Block(-9,54,-5,1)
Block(-9,54,-4,1)
Block(-9,54,-3,1)
Block(-9,54,-2,1)
Block(-9,54,-1,1)
Block(-9,54,0,1)
Block(-9,54,1,1)
Block(-9,54,2,1)
Block(-9,54,3,1)
Block(-9,54,4,1)
Block(-9,54,5,1)
Block(-9,54,6,1)
Block(-9,54,7,1)
Block(-9,55,-7,1)
Block(-9,55,-6,1)
Block(-9,55,-5,1)
Block(-9,55,-4,1)
Block(-9,55,-3,1)
Block(-9,55,-2,1)
Block(-9,55,-1,1)
Block(-9,55,0,1)
Block(-9,55,1,1)
Block(-9,55,2,1)
Block(-9,55,3,1)
Block(-9,55,4,1)
Block(-9,55,5,1)
Block(-9,55,6,1)
Block(-9,56,-6,1)
Block(-9,56,-5,1)
Block(-9,56,-4,1)
Block(-9,56,-3,1)
Block(-9,56,-2,1)
Block(-9,56,-1,1)
Block(-9,56,0,1)
Block(-9,56,1,1)
Block(-9,56,2,1)
Block(-9,56,3,1)
Block(-9,56,4,1)
Block(-9,56,5,1)
Block(-9,57,-6,1)
Block(-9,57,-5,1)
Block(-9,57,-4,1)
Block(-9,57,-3,1)
Block(-9,57,-2,1)
Block(-9,57,-1,1)
Block(-9,57,0,1)
Block(-9,57,1,1)
Block(-9,57,2,1)
Block(-9,57,3,1)
Block(-9,57,4,1)
Block(-9,58,-5,1)
Block(-9,58,-4,1)
Block(-9,58,-3,1)
Block(-9,58,-2,1)
Block(-9,58,-1,1)
Block(-9,58,0,1)
Block(-9,58,1,1)
Block(-9,58,2,1)
Block(-9,58,3,1)
Block(-9,58,4,1)
Block(-9,59,-1,1)
Block(-9,59,0,1)
Block(-9,59,1,1)
Block(-9,59,2,1)
Block(-9,59,3,1)
Block(-9,59,4,1)
Block(-9,60,0,1)
Block(-9,60,1,1)
Block(-9,60,2,1)
Block(-9,60,3,1)
Block(-9,60,4,1)
Block(-9,61,1,1)
Block(-9,61,2,1)
Block(-9,61,3,1)
Block(-9,61,4,1)
Block(-9,62,2,1)
Block(-9,62,3,1)
Block(-9,62,4,1)
Block(-9,62,5,1)
Block(-9,63,2,1)
Block(-9,63,3,1)
Block(-9,63,4,1)
Block(-9,63,5,1)
Block(-9,63,6,1)
Block(-9,64,1,1)
Block(-9,64,2,1)
Block(-9,64,3,1)
Block(-9,64,4,1)
Block(-9,64,5,1)
Block(-9,64,6,1)
Block(-9,65,1,1)
Block(-9,65,2,1)
Block(-9,65,3,1)
Block(-9,65,4,1)
Block(-9,65,5,1)
Block(-9,65,6,1)
Block(-9,65,7,1)
Block(-9,66,2,1)
Block(-9,66,3,1)
Block(-9,66,4,1)
Block(-9,66,5,1)
Block(-9,66,6,1)
Block(-9,66,7,1)
Block(-9,67,4,1)
Block(-9,67,5,1)
Block(-9,67,6,1)
Block(-9,68,5,1)
Block(-9,68,6,1)
Block(-9,69,5,1)
Block(-9,70,4,1)
Block(-9,70,5,1)
Block(-9,71,2,1)
Block(-9,71,3,1)
Block(-9,71,4,1)
Block(-9,71,5,1)
Block(-9,71,6,1)
Block(-9,72,-1,1)
Block(-9,72,0,1)
Block(-9,72,1,1)
Block(-9,72,2,1)
Block(-9,72,3,1)
Block(-9,72,4,1)
Block(-9,72,5,1)
Block(-9,72,6,1)
Block(-9,73,-3,1)
Block(-9,73,-2,1)
Block(-9,73,-1,1)
Block(-9,73,0,1)
Block(-9,73,1,1)
Block(-9,73,2,1)
Block(-9,73,3,1)
Block(-9,73,4,1)
Block(-9,73,5,1)
Block(-9,73,6,1)
Block(-9,73,7,1)
Block(-9,74,-4,1)
Block(-9,74,-3,1)
Block(-9,74,-2,1)
Block(-9,74,-1,1)
Block(-9,74,0,1)
Block(-9,74,1,1)
Block(-9,74,2,1)
Block(-9,74,3,1)
Block(-9,74,4,1)
Block(-9,74,5,1)
Block(-9,74,6,1)
Block(-9,74,7,1)
Block(-9,75,-4,1)
Block(-9,75,-3,1)
Block(-9,75,-2,1)
Block(-9,75,-1,1)
Block(-9,75,0,1)
Block(-9,75,1,1)
Block(-9,75,2,1)
Block(-9,75,3,1)
Block(-9,75,4,1)
Block(-9,75,5,1)
Block(-9,75,6,1)
Block(-9,75,7,1)
Block(-9,76,-4,1)
Block(-9,76,-3,1)
Block(-9,76,-2,1)
Block(-9,76,-1,1)
Block(-9,76,0,1)
Block(-9,76,1,1)
Block(-9,76,2,1)
Block(-9,76,3,1)
Block(-9,76,4,1)
Block(-9,76,5,1)
Block(-9,76,6,1)
Block(-9,76,7,1)
Block(-9,76,8,1)
Block(-9,77,-3,1)
Block(-9,77,-2,1)
Block(-9,77,-1,1)
Block(-9,77,0,1)
Block(-9,77,1,1)
Block(-9,77,2,1)
Block(-9,77,3,1)
Block(-9,77,4,1)
Block(-9,77,5,1)
Block(-9,77,6,1)
Block(-9,77,7,1)
Block(-9,77,8,1)
Block(-9,78,-3,1)
Block(-9,78,-2,1)
Block(-9,78,-1,1)
Block(-9,78,0,1)
Block(-9,78,1,1)
Block(-9,78,2,1)
Block(-9,78,3,1)
Block(-9,78,4,1)
Block(-9,78,5,1)
Block(-9,78,6,1)
Block(-9,78,7,1)
Block(-9,78,8,1)
Block(-9,79,-2,1)
Block(-9,79,-1,1)
Block(-9,79,0,1)
Block(-9,79,1,1)
Block(-9,79,2,1)
Block(-9,79,3,1)
Block(-9,79,4,1)
Block(-9,79,5,1)
Block(-9,79,6,1)
Block(-9,79,7,1)
Block(-9,80,-1,1)
Block(-9,80,0,1)
Block(-9,80,1,1)
Block(-9,80,2,1)
Block(-9,80,3,1)
Block(-9,80,4,1)
Block(-9,80,5,1)
Block(-9,80,6,1)
Block(-9,80,7,1)
Block(-9,81,-2,1)
Block(-9,81,-1,1)
Block(-9,81,0,1)
Block(-9,81,1,1)
Block(-9,81,2,1)
Block(-9,81,3,1)
Block(-9,81,4,1)
Block(-9,81,5,1)
Block(-9,81,6,1)
Block(-9,82,-5,1)
Block(-9,82,-4,1)
Block(-9,82,-3,1)
Block(-9,82,-2,1)
Block(-9,82,-1,1)
Block(-9,82,0,1)
Block(-9,82,1,1)
Block(-9,82,2,1)
Block(-9,82,3,1)
Block(-9,82,4,1)
Block(-9,82,5,1)
Block(-9,83,-6,1)
Block(-9,83,-5,1)
Block(-9,83,-4,1)
Block(-9,83,-3,1)
Block(-9,83,-2,1)
Block(-9,83,-1,1)
Block(-9,83,0,1)
Block(-9,83,1,1)
Block(-9,83,2,1)
Block(-9,83,3,1)
Block(-9,83,4,1)
Block(-9,84,-5,1)
Block(-9,84,-4,1)
Block(-9,84,-3,1)
Block(-9,84,-2,1)
Block(-9,84,-1,1)
Block(-9,84,0,1)
Block(-9,84,1,1)
Block(-9,84,2,1)
Block(-9,84,3,1)
Block(-9,85,-5,1)
Block(-9,85,-4,1)
Block(-9,85,-3,1)
Block(-9,85,-2,1)
Block(-9,85,-1,1)
Block(-9,85,0,1)
Block(-9,85,1,1)
Block(-9,85,2,1)
Block(-9,85,3,1)
Block(-9,86,-5,1)
Block(-9,86,-4,1)
Block(-9,86,-3,1)
Block(-9,86,-2,1)
Block(-9,86,-1,1)
Block(-9,86,0,1)
Block(-9,86,1,1)
Block(-9,86,2,1)
Block(-9,86,3,1)
Block(-9,86,4,1)
Block(-9,86,5,1)
Block(-9,87,-4,1)
Block(-9,87,-3,1)
Block(-9,87,-2,1)
Block(-9,87,-1,1)
Block(-9,87,0,1)
Block(-9,87,1,1)
Block(-9,87,2,1)
Block(-9,87,3,1)
Block(-9,87,4,1)
Block(-9,87,5,1)
Block(-9,87,6,1)
Block(-9,87,7,1)
Block(-9,88,-4,1)
Block(-9,88,-3,1)
Block(-9,88,-2,1)
Block(-9,88,-1,1)
Block(-9,88,0,1)
Block(-9,88,1,1)
Block(-9,88,2,1)
Block(-9,88,3,1)
Block(-9,88,4,1)
Block(-9,88,5,1)
Block(-9,88,6,1)
Block(-9,88,7,1)
Block(-9,88,8,1)
Block(-9,89,-4,1)
Block(-9,89,-3,1)
Block(-9,89,-2,1)
Block(-9,89,-1,1)
Block(-9,89,0,1)
Block(-9,89,1,1)
Block(-9,89,2,1)
Block(-9,89,3,1)
Block(-9,89,4,1)
Block(-9,89,5,1)
Block(-9,89,6,1)
Block(-9,89,7,3)
Block(-9,89,8,1)
Block(-9,90,-3,1)
Block(-9,90,-2,1)
Block(-9,90,-1,1)
Block(-9,90,0,1)
Block(-9,90,1,1)
Block(-9,90,2,1)
Block(-9,90,3,1)
Block(-9,90,4,1)
Block(-9,90,5,1)
Block(-9,90,6,3)
Block(-9,90,7,1)
Block(-9,90,8,1)
Block(-9,91,-3,1)
Block(-9,91,-2,1)
Block(-9,91,-1,1)
Block(-9,91,0,1)
Block(-9,91,1,1)
Block(-9,91,2,1)
Block(-9,91,3,1)
Block(-9,91,4,1)
Block(-9,91,5,3)
Block(-9,91,6,1)
Block(-9,91,7,1)
Block(-9,92,-3,1)
Block(-9,92,-2,1)
Block(-9,92,-1,1)
Block(-9,92,0,1)
Block(-9,92,1,1)
Block(-9,92,2,1)
Block(-9,92,3,1)
Block(-9,92,4,1)
Block(-9,92,5,1)
Block(-9,92,6,1)
Block(-9,93,-2,1)
Block(-9,93,-1,1)
Block(-9,93,0,1)
Block(-9,93,1,1)
Block(-9,93,2,1)
Block(-9,93,3,1)
Block(-9,93,4,1)
Block(-9,93,5,1)
Block(-9,93,6,1)
Block(-9,94,-2,1)
Block(-9,94,-1,1)
Block(-9,94,0,1)
Block(-9,94,1,1)
Block(-9,94,2,1)
Block(-9,94,3,1)
Block(-9,94,4,1)
Block(-9,94,5,1)
Block(-9,95,-2,1)
Block(-9,95,-1,1)
Block(-9,95,0,1)
Block(-9,95,1,1)
Block(-9,95,2,1)
Block(-9,95,3,1)
Block(-9,95,4,1)
Block(-9,96,-3,1)
Block(-9,96,-2,1)
Block(-9,96,-1,1)
Block(-9,96,0,1)
Block(-9,96,1,1)
Block(-9,96,2,1)
Block(-9,96,3,1)
Block(-9,96,4,1)
Block(-9,97,-4,1)
Block(-9,97,-3,1)
Block(-9,97,-2,1)
Block(-9,97,-1,1)
Block(-9,97,0,1)
Block(-9,97,1,1)
Block(-9,97,2,1)
Block(-9,97,3,1)
Block(-9,97,4,1)
Block(-9,98,-5,1)
Block(-9,98,-4,1)
Block(-9,98,-3,1)
Block(-9,98,-2,3)
Block(-9,98,-1,1)
Block(-9,98,0,1)
Block(-9,98,1,1)
Block(-9,98,2,1)
Block(-9,98,3,3)
Block(-9,98,4,1)
Block(-9,99,-5,1)
Block(-9,99,-4,1)
Block(-9,99,-3,1)
Block(-9,99,-2,3)
Block(-9,99,-1,3)
Block(-9,99,0,3)
Block(-9,99,1,1)
Block(-9,99,2,1)
Block(-9,99,3,1)
Block(-9,100,-4,1)
Block(-9,100,-3,1)
Block(-9,100,-2,1)
Block(-9,100,-1,1)
Block(-9,100,0,3)
Block(-9,100,1,3)
Block(-9,100,2,3)
Block(-9,100,3,1)
Block(-9,101,-2,1)
Block(-9,101,-1,1)
Block(-9,101,0,1)
Block(-9,101,1,1)
Block(-9,101,2,1)
Block(-9,101,3,1)
Block(-9,102,-1,1)
Block(-9,102,0,1)
Block(-9,102,1,1)
Block(-9,102,2,1)
Block(-9,103,1,1)
Block(-9,103,2,1)
Block(-8,0,-7,1)
Block(-8,0,-6,1)
Block(-8,0,-5,1)
Block(-8,0,-4,1)
Block(-8,0,-3,1)
Block(-8,0,-2,1)
Block(-8,0,-1,1)
Block(-8,0,0,1)
Block(-8,0,1,1)
Block(-8,0,2,1)
Block(-8,0,3,1)
Block(-8,0,4,1)
Block(-8,0,5,1)
Block(-8,0,6,1)
Block(-8,1,-7,1)
Block(-8,1,-6,1)
Block(-8,1,-5,1)
Block(-8,1,-4,1)
Block(-8,1,-3,1)
Block(-8,1,-2,1)
Block(-8,1,-1,1)
Block(-8,1,0,1)
Block(-8,1,1,1)
Block(-8,1,2,1)
Block(-8,1,3,1)
Block(-8,1,4,1)
Block(-8,1,5,1)
Block(-8,1,6,1)
Block(-8,2,-6,1)
Block(-8,2,-5,1)
Block(-8,2,-4,1)
Block(-8,2,-3,1)
Block(-8,2,-2,1)
Block(-8,2,-1,1)
Block(-8,2,0,1)
Block(-8,2,1,1)
Block(-8,2,2,1)
Block(-8,2,3,1)
Block(-8,2,4,1)
Block(-8,2,5,1)
Block(-8,2,6,1)
Block(-8,3,-6,1)
Block(-8,3,-5,1)
Block(-8,3,-4,1)
Block(-8,3,-3,1)
Block(-8,3,-2,1)
Block(-8,3,-1,1)
Block(-8,3,0,1)
Block(-8,3,1,1)
Block(-8,3,2,1)
Block(-8,3,3,1)
Block(-8,3,4,1)
Block(-8,3,5,1)
Block(-8,3,6,1)
Block(-8,4,-6,1)
Block(-8,4,-5,1)
Block(-8,4,-4,1)
Block(-8,4,-3,1)
Block(-8,4,-2,1)
Block(-8,4,-1,1)
Block(-8,4,0,1)
Block(-8,4,1,1)
Block(-8,4,2,1)
Block(-8,4,3,1)
Block(-8,4,4,1)
Block(-8,4,5,1)
Block(-8,5,-6,1)
Block(-8,5,-5,1)
Block(-8,5,-4,1)
Block(-8,5,-3,1)
Block(-8,5,-2,1)
Block(-8,5,-1,1)
Block(-8,5,0,1)
Block(-8,5,1,1)
Block(-8,5,2,1)
Block(-8,5,3,1)
Block(-8,5,4,1)
Block(-8,5,5,1)
Block(-8,6,-6,1)
Block(-8,6,-5,1)
Block(-8,6,-4,1)
Block(-8,6,-3,1)
Block(-8,6,-2,1)
Block(-8,6,-1,1)
Block(-8,6,0,1)
Block(-8,6,1,1)
Block(-8,6,2,1)
Block(-8,6,3,1)
Block(-8,6,4,1)
Block(-8,6,5,1)
Block(-8,7,-6,1)
Block(-8,7,-5,1)
Block(-8,7,-4,1)
Block(-8,7,-3,1)
Block(-8,7,-2,1)
Block(-8,7,-1,1)
Block(-8,7,0,1)
Block(-8,7,1,1)
Block(-8,7,2,1)
Block(-8,7,3,1)
Block(-8,7,4,1)
Block(-8,7,5,1)
Block(-8,8,-6,1)
Block(-8,8,-5,1)
Block(-8,8,-4,1)
Block(-8,8,-3,1)
Block(-8,8,-2,1)
Block(-8,8,-1,1)
Block(-8,8,0,1)
Block(-8,8,1,1)
Block(-8,8,2,1)
Block(-8,8,3,1)
Block(-8,8,4,1)
Block(-8,8,5,1)
Block(-8,8,6,1)
Block(-8,9,-6,1)
Block(-8,9,-5,1)
Block(-8,9,-4,1)
Block(-8,9,-3,1)
Block(-8,9,-2,1)
Block(-8,9,-1,1)
Block(-8,9,0,1)
Block(-8,9,1,1)
Block(-8,9,2,1)
Block(-8,9,3,1)
Block(-8,9,4,1)
Block(-8,9,5,1)
Block(-8,9,6,1)
Block(-8,10,-5,1)
Block(-8,10,-4,1)
Block(-8,10,-3,1)
Block(-8,10,-2,1)
Block(-8,10,-1,1)
Block(-8,10,0,1)
Block(-8,10,1,1)
Block(-8,10,2,1)
Block(-8,10,3,1)
Block(-8,10,4,1)
Block(-8,10,5,1)
Block(-8,10,6,1)
Block(-8,11,-5,1)
Block(-8,11,-4,1)
Block(-8,11,-3,1)
Block(-8,11,-2,1)
Block(-8,11,-1,1)
Block(-8,11,0,1)
Block(-8,11,1,1)
Block(-8,11,2,1)
Block(-8,11,3,1)
Block(-8,11,4,1)
Block(-8,11,5,1)
Block(-8,11,6,1)
Block(-8,11,7,1)
Block(-8,12,-5,1)
Block(-8,12,-4,1)
Block(-8,12,-3,1)
Block(-8,12,-2,1)
Block(-8,12,-1,1)
Block(-8,12,0,1)
Block(-8,12,1,1)
Block(-8,12,2,1)
Block(-8,12,3,1)
Block(-8,12,4,1)
Block(-8,12,5,1)
Block(-8,12,6,1)
Block(-8,12,7,1)
Block(-8,13,-4,1)
Block(-8,13,-3,1)
Block(-8,13,-2,1)
Block(-8,13,-1,1)
Block(-8,13,0,1)
Block(-8,13,1,1)
Block(-8,13,2,1)
Block(-8,13,3,1)
Block(-8,13,4,1)
Block(-8,13,5,1)
Block(-8,13,6,1)
Block(-8,13,7,1)
Block(-8,14,-4,1)
Block(-8,14,-3,1)
Block(-8,14,-2,1)
Block(-8,14,-1,1)
Block(-8,14,0,1)
Block(-8,14,1,1)
Block(-8,14,2,1)
Block(-8,14,3,1)
Block(-8,14,4,1)
Block(-8,14,5,1)
Block(-8,14,6,1)
Block(-8,14,7,1)
Block(-8,15,-4,1)
Block(-8,15,-3,1)
Block(-8,15,-2,1)
Block(-8,15,-1,1)
Block(-8,15,0,1)
Block(-8,15,1,1)
Block(-8,15,2,1)
Block(-8,15,3,1)
Block(-8,15,4,1)
Block(-8,15,5,1)
Block(-8,15,6,1)
Block(-8,15,7,1)
Block(-8,15,8,1)
Block(-8,16,-3,1)
Block(-8,16,-2,1)
Block(-8,16,-1,1)
Block(-8,16,0,1)
Block(-8,16,1,1)
Block(-8,16,2,1)
Block(-8,16,3,1)
Block(-8,16,4,1)
Block(-8,16,5,1)
Block(-8,16,6,1)
Block(-8,16,7,1)
Block(-8,16,8,1)
Block(-8,17,-3,1)
Block(-8,17,-2,1)
Block(-8,17,-1,1)
Block(-8,17,0,1)
Block(-8,17,1,1)
Block(-8,17,2,1)
Block(-8,17,3,1)
Block(-8,17,4,1)
Block(-8,17,5,1)
Block(-8,17,6,1)
Block(-8,17,7,1)
Block(-8,18,-4,1)
Block(-8,18,-3,1)
Block(-8,18,-2,1)
Block(-8,18,-1,1)
Block(-8,18,0,1)
Block(-8,18,1,1)
Block(-8,18,2,1)
Block(-8,18,3,1)
Block(-8,18,4,1)
Block(-8,18,5,1)
Block(-8,18,6,1)
Block(-8,18,7,1)
Block(-8,19,-4,1)
Block(-8,19,-3,1)
Block(-8,19,-2,1)
Block(-8,19,-1,1)
Block(-8,19,0,1)
Block(-8,19,1,1)
Block(-8,19,2,1)
Block(-8,19,3,1)
Block(-8,19,4,1)
Block(-8,19,5,1)
Block(-8,19,6,1)
Block(-8,19,7,1)
Block(-8,20,-5,1)
Block(-8,20,-4,1)
Block(-8,20,-3,1)
Block(-8,20,-2,1)
Block(-8,20,-1,1)
Block(-8,20,0,1)
Block(-8,20,1,1)
Block(-8,20,2,1)
Block(-8,20,3,1)
Block(-8,20,4,1)
Block(-8,20,5,1)
Block(-8,20,6,1)
Block(-8,20,7,1)
Block(-8,20,8,1)
Block(-8,21,-5,1)
Block(-8,21,-4,1)
Block(-8,21,-3,1)
Block(-8,21,-2,1)
Block(-8,21,-1,1)
Block(-8,21,0,1)
Block(-8,21,1,1)
Block(-8,21,2,1)
Block(-8,21,3,1)
Block(-8,21,4,1)
Block(-8,21,5,1)
Block(-8,21,6,1)
Block(-8,21,7,1)
Block(-8,21,8,1)
Block(-8,22,-6,1)
Block(-8,22,-5,1)
Block(-8,22,-4,1)
Block(-8,22,-3,1)
Block(-8,22,-2,1)
Block(-8,22,-1,1)
Block(-8,22,0,1)
Block(-8,22,1,1)
Block(-8,22,2,1)
Block(-8,22,3,1)
Block(-8,22,4,1)
Block(-8,22,5,1)
Block(-8,22,6,1)
Block(-8,22,7,1)
Block(-8,22,8,1)
Block(-8,23,-6,1)
Block(-8,23,-5,1)
Block(-8,23,-4,1)
Block(-8,23,-3,1)
Block(-8,23,-2,1)
Block(-8,23,-1,1)
Block(-8,23,0,1)
Block(-8,23,1,1)
Block(-8,23,2,1)
Block(-8,23,3,1)
Block(-8,23,4,1)
Block(-8,23,5,1)
Block(-8,23,6,1)
Block(-8,23,7,1)
Block(-8,23,8,1)
Block(-8,24,-5,1)
Block(-8,24,-4,1)
Block(-8,24,-3,1)
Block(-8,24,-2,1)
Block(-8,24,-1,1)
Block(-8,24,0,1)
Block(-8,24,1,1)
Block(-8,24,2,1)
Block(-8,24,3,1)
Block(-8,24,4,1)
Block(-8,24,5,1)
Block(-8,24,6,1)
Block(-8,24,7,1)
Block(-8,24,8,1)
Block(-8,25,-4,1)
Block(-8,25,-3,1)
Block(-8,25,-2,1)
Block(-8,25,-1,1)
Block(-8,25,0,1)
Block(-8,25,1,1)
Block(-8,25,2,1)
Block(-8,25,3,1)
Block(-8,25,4,1)
Block(-8,25,5,1)
Block(-8,25,6,1)
Block(-8,26,-4,1)
Block(-8,26,-3,1)
Block(-8,26,-2,1)
Block(-8,26,-1,1)
Block(-8,26,0,1)
Block(-8,26,1,1)
Block(-8,26,2,1)
Block(-8,26,3,1)
Block(-8,26,4,1)
Block(-8,26,5,1)
Block(-8,27,-5,1)
Block(-8,27,-4,1)
Block(-8,27,-3,1)
Block(-8,27,-2,1)
Block(-8,27,-1,1)
Block(-8,27,0,1)
Block(-8,27,1,1)
Block(-8,27,2,1)
Block(-8,27,3,1)
Block(-8,27,4,1)
Block(-8,27,5,1)
Block(-8,28,-6,1)
Block(-8,28,-5,1)
Block(-8,28,-4,1)
Block(-8,28,-3,1)
Block(-8,28,-2,1)
Block(-8,28,-1,1)
Block(-8,28,0,1)
Block(-8,28,1,1)
Block(-8,28,2,1)
Block(-8,28,3,1)
Block(-8,28,4,1)
Block(-8,28,5,1)
Block(-8,28,6,1)
Block(-8,29,-6,1)
Block(-8,29,-5,1)
Block(-8,29,-4,1)
Block(-8,29,-3,1)
Block(-8,29,-2,1)
Block(-8,29,-1,1)
Block(-8,29,0,1)
Block(-8,29,1,1)
Block(-8,29,2,1)
Block(-8,29,3,1)
Block(-8,29,4,1)
Block(-8,29,5,1)
Block(-8,29,6,1)
Block(-8,30,-6,1)
Block(-8,30,-5,1)
Block(-8,30,-4,1)
Block(-8,30,-3,1)
Block(-8,30,-2,1)
Block(-8,30,-1,1)
Block(-8,30,0,1)
Block(-8,30,1,1)
Block(-8,30,2,1)
Block(-8,30,3,1)
Block(-8,30,4,1)
Block(-8,30,5,1)
Block(-8,30,6,1)
Block(-8,30,7,1)
Block(-8,31,-6,1)
Block(-8,31,-5,1)
Block(-8,31,-4,1)
Block(-8,31,-3,1)
Block(-8,31,-2,1)
Block(-8,31,-1,1)
Block(-8,31,0,1)
Block(-8,31,1,1)
Block(-8,31,2,1)
Block(-8,31,3,1)
Block(-8,31,4,1)
Block(-8,31,5,1)
Block(-8,31,6,1)
Block(-8,31,7,1)
Block(-8,31,8,1)
Block(-8,32,-5,1)
Block(-8,32,-4,1)
Block(-8,32,-3,1)
Block(-8,32,-2,1)
Block(-8,32,-1,1)
Block(-8,32,0,1)
Block(-8,32,1,1)
Block(-8,32,2,1)
Block(-8,32,3,1)
Block(-8,32,4,1)
Block(-8,32,5,1)
Block(-8,32,6,1)
Block(-8,32,7,1)
Block(-8,32,8,1)
Block(-8,33,-5,1)
Block(-8,33,-4,1)
Block(-8,33,-3,1)
Block(-8,33,-2,1)
Block(-8,33,-1,1)
Block(-8,33,0,1)
Block(-8,33,1,1)
Block(-8,33,2,1)
Block(-8,33,3,1)
Block(-8,33,4,1)
Block(-8,33,5,1)
Block(-8,33,6,1)
Block(-8,33,7,1)
Block(-8,33,8,1)
Block(-8,34,-5,1)
Block(-8,34,-4,1)
Block(-8,34,-3,1)
Block(-8,34,-2,1)
Block(-8,34,-1,1)
Block(-8,34,0,1)
Block(-8,34,1,1)
Block(-8,34,2,1)
Block(-8,34,3,1)
Block(-8,34,4,1)
Block(-8,34,5,1)
Block(-8,34,6,1)
Block(-8,34,7,1)
Block(-8,35,-5,1)
Block(-8,35,-4,1)
Block(-8,35,-3,1)
Block(-8,35,-2,1)
Block(-8,35,-1,1)
Block(-8,35,0,1)
Block(-8,35,1,1)
Block(-8,35,2,1)
Block(-8,35,3,1)
Block(-8,35,4,1)
Block(-8,35,5,1)
Block(-8,36,-5,1)
Block(-8,36,-4,1)
Block(-8,36,-3,1)
Block(-8,36,-2,1)
Block(-8,36,-1,1)
Block(-8,36,0,1)
Block(-8,36,1,1)
Block(-8,36,2,1)
Block(-8,36,3,1)
Block(-8,37,-6,1)
Block(-8,37,-5,1)
Block(-8,37,-4,1)
Block(-8,37,-3,1)
Block(-8,37,-2,1)
Block(-8,37,-1,1)
Block(-8,37,0,1)
Block(-8,37,1,1)
Block(-8,37,2,1)
Block(-8,38,-7,1)
Block(-8,38,-6,1)
Block(-8,38,-5,1)
Block(-8,38,-4,1)
Block(-8,38,-3,1)
Block(-8,38,-2,1)
Block(-8,38,-1,1)
Block(-8,38,0,1)
Block(-8,38,1,1)
Block(-8,39,-8,1)
Block(-8,39,-7,1)
Block(-8,39,-6,1)
Block(-8,39,-5,1)
Block(-8,39,-4,1)
Block(-8,39,-3,1)
Block(-8,39,-2,1)
Block(-8,39,-1,1)
Block(-8,39,0,1)
Block(-8,39,1,1)
Block(-8,40,-8,1)
Block(-8,40,-7,1)
Block(-8,40,-6,1)
Block(-8,40,-5,1)
Block(-8,40,-4,1)
Block(-8,40,-3,1)
Block(-8,40,-2,1)
Block(-8,40,-1,1)
Block(-8,40,0,1)
Block(-8,40,1,1)
Block(-8,40,2,1)
Block(-8,41,-8,1)
Block(-8,41,-7,1)
Block(-8,41,-6,1)
Block(-8,41,-5,1)
Block(-8,41,-4,1)
Block(-8,41,-3,1)
Block(-8,41,-2,1)
Block(-8,41,-1,1)
Block(-8,41,0,1)
Block(-8,41,1,1)
Block(-8,41,2,1)
Block(-8,41,3,1)
Block(-8,42,-7,1)
Block(-8,42,-6,1)
Block(-8,42,-5,1)
Block(-8,42,-4,1)
Block(-8,42,-3,1)
Block(-8,42,-2,1)
Block(-8,42,-1,1)
Block(-8,42,0,1)
Block(-8,42,1,1)
Block(-8,42,2,1)
Block(-8,42,3,1)
Block(-8,42,4,1)
Block(-8,42,5,1)
Block(-8,43,-6,1)
Block(-8,43,-5,1)
Block(-8,43,-4,1)
Block(-8,43,-3,1)
Block(-8,43,-2,1)
Block(-8,43,-1,1)
Block(-8,43,0,1)
Block(-8,43,1,1)
Block(-8,43,2,1)
Block(-8,43,3,1)
Block(-8,43,4,1)
Block(-8,43,5,1)
Block(-8,43,6,1)
Block(-8,44,-5,1)
Block(-8,44,-4,1)
Block(-8,44,-3,1)
Block(-8,44,-2,1)
Block(-8,44,-1,1)
Block(-8,44,0,1)
Block(-8,44,1,1)
Block(-8,44,2,1)
Block(-8,44,3,1)
Block(-8,44,4,1)
Block(-8,44,5,1)
Block(-8,44,6,1)
Block(-8,45,-3,1)
Block(-8,45,-2,1)
Block(-8,45,-1,1)
Block(-8,45,0,1)
Block(-8,45,1,1)
Block(-8,45,2,1)
Block(-8,45,3,1)
Block(-8,45,4,1)
Block(-8,45,5,1)
Block(-8,45,6,1)
Block(-8,46,-2,1)
Block(-8,46,-1,1)
Block(-8,46,0,1)
Block(-8,46,1,1)
Block(-8,46,2,1)
Block(-8,46,3,1)
Block(-8,46,4,1)
Block(-8,46,5,1)
Block(-8,46,6,1)
Block(-8,47,-1,1)
Block(-8,47,0,1)
Block(-8,47,1,1)
Block(-8,47,2,1)
Block(-8,47,3,1)
Block(-8,47,4,1)
Block(-8,47,5,1)
Block(-8,47,6,1)
Block(-8,48,-1,1)
Block(-8,48,0,1)
Block(-8,48,1,1)
Block(-8,48,2,1)
Block(-8,48,3,1)
Block(-8,48,4,1)
Block(-8,48,5,1)
Block(-8,48,6,1)
Block(-8,49,-1,1)
Block(-8,49,0,1)
Block(-8,49,1,1)
Block(-8,49,2,1)
Block(-8,49,3,1)
Block(-8,49,4,1)
Block(-8,49,5,1)
Block(-8,49,6,1)
Block(-8,49,7,1)
Block(-8,50,-2,1)
Block(-8,50,-1,1)
Block(-8,50,0,1)
Block(-8,50,1,1)
Block(-8,50,2,1)
Block(-8,50,3,1)
Block(-8,50,4,1)
Block(-8,50,5,1)
Block(-8,50,6,1)
Block(-8,50,7,1)
Block(-8,51,-4,1)
Block(-8,51,-3,1)
Block(-8,51,-2,1)
Block(-8,51,-1,1)
Block(-8,51,0,1)
Block(-8,51,1,1)
Block(-8,51,2,1)
Block(-8,51,3,1)
Block(-8,51,4,1)
Block(-8,51,5,1)
Block(-8,51,6,1)
Block(-8,51,7,1)
Block(-8,51,8,1)
Block(-8,52,-5,1)
Block(-8,52,-4,1)
Block(-8,52,-3,1)
Block(-8,52,-2,1)
Block(-8,52,-1,1)
Block(-8,52,0,1)
Block(-8,52,1,1)
Block(-8,52,2,1)
Block(-8,52,3,1)
Block(-8,52,4,1)
Block(-8,52,5,1)
Block(-8,52,6,1)
Block(-8,52,7,1)
Block(-8,52,8,1)
Block(-8,53,-7,1)
Block(-8,53,-6,1)
Block(-8,53,-5,1)
Block(-8,53,-4,1)
Block(-8,53,-3,1)
Block(-8,53,-2,1)
Block(-8,53,-1,1)
Block(-8,53,0,1)
Block(-8,53,1,1)
Block(-8,53,2,1)
Block(-8,53,3,1)
Block(-8,53,4,1)
Block(-8,53,5,1)
Block(-8,53,6,1)
Block(-8,53,7,1)
Block(-8,53,8,1)
Block(-8,54,-8,1)
Block(-8,54,-7,1)
Block(-8,54,-6,1)
Block(-8,54,-5,1)
Block(-8,54,-4,1)
Block(-8,54,-3,1)
Block(-8,54,-2,1)
Block(-8,54,-1,1)
Block(-8,54,0,1)
Block(-8,54,1,1)
Block(-8,54,2,1)
Block(-8,54,3,1)
Block(-8,54,4,1)
Block(-8,54,5,1)
Block(-8,54,6,1)
Block(-8,54,7,1)
Block(-8,54,8,1)
Block(-8,55,-8,1)
Block(-8,55,-7,1)
Block(-8,55,-6,1)
Block(-8,55,-5,1)
Block(-8,55,-4,1)
Block(-8,55,-3,1)
Block(-8,55,-2,1)
Block(-8,55,-1,1)
Block(-8,55,0,1)
Block(-8,55,1,1)
Block(-8,55,2,1)
Block(-8,55,3,1)
Block(-8,55,4,1)
Block(-8,55,5,1)
Block(-8,55,6,1)
Block(-8,55,7,1)
Block(-8,55,8,1)
Block(-8,56,-8,1)
Block(-8,56,-7,1)
Block(-8,56,-6,1)
Block(-8,56,-5,1)
Block(-8,56,-4,1)
Block(-8,56,-3,1)
Block(-8,56,-2,1)
Block(-8,56,-1,1)
Block(-8,56,0,1)
Block(-8,56,1,1)
Block(-8,56,2,1)
Block(-8,56,3,1)
Block(-8,56,4,1)
Block(-8,56,5,1)
Block(-8,56,6,1)
Block(-8,56,7,1)
Block(-8,57,-7,1)
Block(-8,57,-6,1)
Block(-8,57,-5,1)
Block(-8,57,-4,1)
Block(-8,57,-3,1)
Block(-8,57,-2,1)
Block(-8,57,-1,1)
Block(-8,57,0,1)
Block(-8,57,1,1)
Block(-8,57,2,1)
Block(-8,57,3,1)
Block(-8,57,4,1)
Block(-8,57,5,1)
Block(-8,57,6,1)
Block(-8,58,-7,1)
Block(-8,58,-6,1)
Block(-8,58,-5,1)
Block(-8,58,-4,1)
Block(-8,58,-3,1)
Block(-8,58,-2,1)
Block(-8,58,-1,1)
Block(-8,58,0,1)
Block(-8,58,1,1)
Block(-8,58,2,1)
Block(-8,58,3,1)
Block(-8,58,4,1)
Block(-8,58,5,1)
Block(-8,59,-6,1)
Block(-8,59,-5,1)
Block(-8,59,-4,1)
Block(-8,59,-3,1)
Block(-8,59,-2,1)
Block(-8,59,-1,1)
Block(-8,59,0,1)
Block(-8,59,1,1)
Block(-8,59,2,1)
Block(-8,59,3,1)
Block(-8,59,4,1)
Block(-8,59,5,1)
Block(-8,60,-6,1)
Block(-8,60,-5,1)
Block(-8,60,-4,1)
Block(-8,60,-3,1)
Block(-8,60,-2,1)
Block(-8,60,-1,1)
Block(-8,60,0,1)
Block(-8,60,1,1)
Block(-8,60,2,1)
Block(-8,60,3,1)
Block(-8,60,4,1)
Block(-8,60,5,1)
Block(-8,61,-6,1)
Block(-8,61,-5,1)
Block(-8,61,-4,1)
Block(-8,61,-3,1)
Block(-8,61,-2,1)
Block(-8,61,-1,1)
Block(-8,61,0,1)
Block(-8,61,1,1)
Block(-8,61,2,1)
Block(-8,61,3,1)
Block(-8,61,4,1)
Block(-8,61,5,1)
Block(-8,61,6,1)
Block(-8,62,-6,1)
Block(-8,62,-5,1)
Block(-8,62,-4,1)
Block(-8,62,-3,1)
Block(-8,62,-2,1)
Block(-8,62,-1,1)
Block(-8,62,0,1)
Block(-8,62,1,1)
Block(-8,62,2,1)
Block(-8,62,3,1)
Block(-8,62,4,1)
Block(-8,62,5,1)
Block(-8,62,6,1)
Block(-8,63,-6,1)
Block(-8,63,-5,1)
Block(-8,63,-4,1)
Block(-8,63,-3,1)
Block(-8,63,-2,1)
Block(-8,63,-1,1)
Block(-8,63,0,1)
Block(-8,63,1,1)
Block(-8,63,2,1)
Block(-8,63,3,1)
Block(-8,63,4,1)
Block(-8,63,5,1)
Block(-8,63,6,1)
Block(-8,63,7,1)
Block(-8,64,-6,1)
Block(-8,64,-5,1)
Block(-8,64,-4,1)
Block(-8,64,-3,1)
Block(-8,64,-2,1)
Block(-8,64,-1,1)
Block(-8,64,0,1)
Block(-8,64,1,1)
Block(-8,64,2,1)
Block(-8,64,3,1)
Block(-8,64,4,1)
Block(-8,64,5,1)
Block(-8,64,6,1)
Block(-8,64,7,1)
Block(-8,64,8,1)
Block(-8,65,-6,1)
Block(-8,65,-5,1)
Block(-8,65,-4,1)
Block(-8,65,-3,1)
Block(-8,65,-2,1)
Block(-8,65,-1,1)
Block(-8,65,0,1)
Block(-8,65,1,1)
Block(-8,65,2,1)
Block(-8,65,3,1)
Block(-8,65,4,1)
Block(-8,65,5,1)
Block(-8,65,6,1)
Block(-8,65,7,1)
Block(-8,65,8,1)
Block(-8,66,-6,1)
Block(-8,66,-5,1)
Block(-8,66,-4,1)
Block(-8,66,-3,1)
Block(-8,66,-2,1)
Block(-8,66,-1,1)
Block(-8,66,0,1)
Block(-8,66,1,1)
Block(-8,66,2,1)
Block(-8,66,3,1)
Block(-8,66,4,1)
Block(-8,66,5,1)
Block(-8,66,6,1)
Block(-8,66,7,1)
Block(-8,66,8,1)
Block(-8,67,-6,1)
Block(-8,67,-5,1)
Block(-8,67,-4,1)
Block(-8,67,-3,1)
Block(-8,67,-2,1)
Block(-8,67,-1,1)
Block(-8,67,0,1)
Block(-8,67,1,1)
Block(-8,67,2,1)
Block(-8,67,3,1)
Block(-8,67,4,1)
Block(-8,67,5,1)
Block(-8,67,6,1)
Block(-8,67,7,1)
Block(-8,67,8,1)
Block(-8,68,-5,1)
Block(-8,68,-4,1)
Block(-8,68,-3,1)
Block(-8,68,-2,1)
Block(-8,68,-1,1)
Block(-8,68,0,1)
Block(-8,68,1,1)
Block(-8,68,2,1)
Block(-8,68,3,1)
Block(-8,68,4,1)
Block(-8,68,5,1)
Block(-8,68,6,1)
Block(-8,68,7,1)
Block(-8,69,-4,1)
Block(-8,69,-3,1)
Block(-8,69,-2,1)
Block(-8,69,-1,1)
Block(-8,69,0,1)
Block(-8,69,1,1)
Block(-8,69,2,1)
Block(-8,69,3,1)
Block(-8,69,4,1)
Block(-8,69,5,1)
Block(-8,69,6,1)
Block(-8,69,7,1)
Block(-8,70,-4,1)
Block(-8,70,-3,1)
Block(-8,70,-2,1)
Block(-8,70,-1,1)
Block(-8,70,0,1)
Block(-8,70,1,1)
Block(-8,70,2,1)
Block(-8,70,3,1)
Block(-8,70,4,1)
Block(-8,70,5,1)
Block(-8,70,6,1)
Block(-8,71,-4,1)
Block(-8,71,-3,1)
Block(-8,71,-2,1)
Block(-8,71,-1,1)
Block(-8,71,0,1)
Block(-8,71,1,1)
Block(-8,71,2,1)
Block(-8,71,3,1)
Block(-8,71,4,1)
Block(-8,71,5,1)
Block(-8,71,6,1)
Block(-8,72,-4,1)
Block(-8,72,-3,1)
Block(-8,72,-2,1)
Block(-8,72,-1,1)
Block(-8,72,0,1)
Block(-8,72,1,1)
Block(-8,72,2,1)
Block(-8,72,3,1)
Block(-8,72,4,1)
Block(-8,72,5,1)
Block(-8,72,6,1)
Block(-8,72,7,1)
Block(-8,73,-5,1)
Block(-8,73,-4,1)
Block(-8,73,-3,1)
Block(-8,73,-2,1)
Block(-8,73,-1,1)
Block(-8,73,0,1)
Block(-8,73,1,1)
Block(-8,73,2,1)
Block(-8,73,3,1)
Block(-8,73,4,1)
Block(-8,73,5,1)
Block(-8,73,6,1)
Block(-8,73,7,1)
Block(-8,74,-5,1)
Block(-8,74,-4,1)
Block(-8,74,-3,1)
Block(-8,74,-2,1)
Block(-8,74,-1,1)
Block(-8,74,0,1)
Block(-8,74,1,1)
Block(-8,74,2,1)
Block(-8,74,3,1)
Block(-8,74,4,1)
Block(-8,74,5,1)
Block(-8,74,6,1)
Block(-8,74,7,1)
Block(-8,74,8,1)
Block(-8,75,-5,1)
Block(-8,75,-4,1)
Block(-8,75,-3,1)
Block(-8,75,-2,1)
Block(-8,75,-1,1)
Block(-8,75,0,1)
Block(-8,75,1,1)
Block(-8,75,2,1)
Block(-8,75,3,1)
Block(-8,75,4,1)
Block(-8,75,5,1)
Block(-8,75,6,1)
Block(-8,75,7,1)
Block(-8,75,8,1)
Block(-8,76,-5,1)
Block(-8,76,-4,1)
Block(-8,76,-3,1)
Block(-8,76,-2,1)
Block(-8,76,-1,1)
Block(-8,76,0,1)
Block(-8,76,1,1)
Block(-8,76,2,1)
Block(-8,76,3,1)
Block(-8,76,4,1)
Block(-8,76,5,1)
Block(-8,76,6,1)
Block(-8,76,7,1)
Block(-8,76,8,1)
Block(-8,76,9,1)
Block(-8,77,-5,1)
Block(-8,77,-4,1)
Block(-8,77,-3,1)
Block(-8,77,-2,1)
Block(-8,77,-1,1)
Block(-8,77,0,1)
Block(-8,77,1,1)
Block(-8,77,2,1)
Block(-8,77,3,1)
Block(-8,77,4,1)
Block(-8,77,5,1)
Block(-8,77,6,1)
Block(-8,77,7,1)
Block(-8,77,8,1)
Block(-8,77,9,1)
Block(-8,78,-4,1)
Block(-8,78,-3,1)
Block(-8,78,-2,1)
Block(-8,78,-1,1)
Block(-8,78,0,1)
Block(-8,78,1,1)
Block(-8,78,2,1)
Block(-8,78,3,1)
Block(-8,78,4,1)
Block(-8,78,5,1)
Block(-8,78,6,1)
Block(-8,78,7,1)
Block(-8,78,8,1)
Block(-8,78,9,1)
Block(-8,79,-4,1)
Block(-8,79,-3,1)
Block(-8,79,-2,1)
Block(-8,79,-1,1)
Block(-8,79,0,1)
Block(-8,79,1,1)
Block(-8,79,2,1)
Block(-8,79,3,1)
Block(-8,79,4,1)
Block(-8,79,5,1)
Block(-8,79,6,1)
Block(-8,79,7,1)
Block(-8,79,8,1)
Block(-8,79,9,1)
Block(-8,80,-4,1)
Block(-8,80,-3,1)
Block(-8,80,-2,1)
Block(-8,80,-1,1)
Block(-8,80,0,1)
Block(-8,80,1,1)
Block(-8,80,2,1)
Block(-8,80,3,1)
Block(-8,80,4,1)
Block(-8,80,5,1)
Block(-8,80,6,1)
Block(-8,80,7,1)
Block(-8,80,8,1)
Block(-8,81,-5,1)
Block(-8,81,-4,1)
Block(-8,81,-3,1)
Block(-8,81,-2,1)
Block(-8,81,-1,1)
Block(-8,81,0,1)
Block(-8,81,1,1)
Block(-8,81,2,1)
Block(-8,81,3,1)
Block(-8,81,4,1)
Block(-8,81,5,1)
Block(-8,81,6,1)
Block(-8,81,7,1)
Block(-8,82,-6,1)
Block(-8,82,-5,1)
Block(-8,82,-4,1)
Block(-8,82,-3,1)
Block(-8,82,-2,1)
Block(-8,82,-1,1)
Block(-8,82,0,1)
Block(-8,82,1,1)
Block(-8,82,2,1)
Block(-8,82,3,1)
Block(-8,82,4,1)
Block(-8,82,5,1)
Block(-8,82,6,1)
Block(-8,83,-7,1)
Block(-8,83,-6,1)
Block(-8,83,-5,1)
Block(-8,83,-4,1)
Block(-8,83,-3,1)
Block(-8,83,-2,1)
Block(-8,83,-1,1)
Block(-8,83,0,1)
Block(-8,83,1,1)
Block(-8,83,2,1)
Block(-8,83,3,1)
Block(-8,83,4,1)
Block(-8,83,5,1)
Block(-8,84,-7,1)
Block(-8,84,-6,1)
Block(-8,84,-5,1)
Block(-8,84,-4,1)
Block(-8,84,-3,1)
Block(-8,84,-2,1)
Block(-8,84,-1,1)
Block(-8,84,0,1)
Block(-8,84,1,1)
Block(-8,84,2,1)
Block(-8,84,3,1)
Block(-8,84,4,1)
Block(-8,85,-6,1)
Block(-8,85,-5,1)
Block(-8,85,-4,1)
Block(-8,85,-3,1)
Block(-8,85,-2,1)
Block(-8,85,-1,1)
Block(-8,85,0,1)
Block(-8,85,1,1)
Block(-8,85,2,1)
Block(-8,85,3,1)
Block(-8,85,4,1)
Block(-8,85,5,1)
Block(-8,85,6,1)
Block(-8,86,-6,1)
Block(-8,86,-5,1)
Block(-8,86,-4,1)
Block(-8,86,-3,1)
Block(-8,86,-2,1)
Block(-8,86,-1,1)
Block(-8,86,0,1)
Block(-8,86,1,1)
Block(-8,86,2,1)
Block(-8,86,3,1)
Block(-8,86,4,1)
Block(-8,86,5,1)
Block(-8,86,6,1)
Block(-8,86,7,1)
Block(-8,86,8,1)
Block(-8,87,-6,1)
Block(-8,87,-5,1)
Block(-8,87,-4,1)
Block(-8,87,-3,1)
Block(-8,87,-2,1)
Block(-8,87,-1,1)
Block(-8,87,0,1)
Block(-8,87,1,1)
Block(-8,87,2,1)
Block(-8,87,3,1)
Block(-8,87,4,1)
Block(-8,87,5,1)
Block(-8,87,6,1)
Block(-8,87,7,1)
Block(-8,87,8,1)
Block(-8,87,9,1)
Block(-8,88,-5,1)
Block(-8,88,-4,1)
Block(-8,88,-3,1)
Block(-8,88,-2,1)
Block(-8,88,-1,1)
Block(-8,88,0,1)
Block(-8,88,1,1)
Block(-8,88,2,1)
Block(-8,88,3,1)
Block(-8,88,4,1)
Block(-8,88,5,1)
Block(-8,88,6,1)
Block(-8,88,7,1)
Block(-8,88,8,1)
Block(-8,89,-5,1)
Block(-8,89,-4,1)
Block(-8,89,-3,1)
Block(-8,89,-2,1)
Block(-8,89,-1,1)
Block(-8,89,0,1)
Block(-8,89,1,1)
Block(-8,89,2,1)
Block(-8,89,3,1)
Block(-8,89,4,1)
Block(-8,89,5,1)
Block(-8,89,6,1)
Block(-8,89,7,1)
Block(-8,89,8,1)
Block(-8,90,-4,1)
Block(-8,90,-3,1)
Block(-8,90,-2,1)
Block(-8,90,-1,1)
Block(-8,90,0,1)
Block(-8,90,1,1)
Block(-8,90,2,1)
Block(-8,90,3,1)
Block(-8,90,4,1)
Block(-8,90,5,1)
Block(-8,90,6,1)
Block(-8,90,7,3)
Block(-8,90,8,1)
Block(-8,91,-4,1)
Block(-8,91,-3,1)
Block(-8,91,-2,1)
Block(-8,91,-1,1)
Block(-8,91,0,1)
Block(-8,91,1,1)
Block(-8,91,2,1)
Block(-8,91,3,1)
Block(-8,91,4,1)
Block(-8,91,5,1)
Block(-8,91,6,1)
Block(-8,91,7,3)
Block(-8,91,8,1)
Block(-8,92,-4,1)
Block(-8,92,-3,1)
Block(-8,92,-2,1)
Block(-8,92,-1,1)
Block(-8,92,0,1)
Block(-8,92,1,1)
Block(-8,92,2,1)
Block(-8,92,3,1)
Block(-8,92,4,1)
Block(-8,92,5,1)
Block(-8,92,6,3)
Block(-8,92,7,1)
Block(-8,93,-4,1)
Block(-8,93,-3,1)
Block(-8,93,-2,1)
Block(-8,93,-1,1)
Block(-8,93,0,1)
Block(-8,93,1,1)
Block(-8,93,2,1)
Block(-8,93,3,1)
Block(-8,93,4,1)
Block(-8,93,5,1)
Block(-8,93,6,3)
Block(-8,93,7,1)
Block(-8,94,-4,1)
Block(-8,94,-3,1)
Block(-8,94,-2,1)
Block(-8,94,-1,1)
Block(-8,94,0,1)
Block(-8,94,1,1)
Block(-8,94,2,1)
Block(-8,94,3,1)
Block(-8,94,4,1)
Block(-8,94,5,1)
Block(-8,94,6,1)
Block(-8,95,-4,1)
Block(-8,95,-3,1)
Block(-8,95,-2,1)
Block(-8,95,-1,1)
Block(-8,95,0,1)
Block(-8,95,1,1)
Block(-8,95,2,1)
Block(-8,95,3,1)
Block(-8,95,4,1)
Block(-8,95,5,1)
Block(-8,95,6,1)
Block(-8,96,-6,1)
Block(-8,96,-5,1)
Block(-8,96,-4,1)
Block(-8,96,-3,1)
Block(-8,96,-2,1)
Block(-8,96,-1,1)
Block(-8,96,0,1)
Block(-8,96,1,1)
Block(-8,96,2,1)
Block(-8,96,3,1)
Block(-8,96,4,1)
Block(-8,96,5,1)
Block(-8,97,-6,1)
Block(-8,97,-5,1)
Block(-8,97,-4,1)
Block(-8,97,-3,1)
Block(-8,97,-2,1)
Block(-8,97,-1,1)
Block(-8,97,0,1)
Block(-8,97,1,1)
Block(-8,97,2,1)
Block(-8,97,3,1)
Block(-8,97,4,1)
Block(-8,97,5,1)
Block(-8,98,-6,1)
Block(-8,98,-5,1)
Block(-8,98,-4,1)
Block(-8,98,-3,1)
Block(-8,98,-2,1)
Block(-8,98,-1,1)
Block(-8,98,0,1)
Block(-8,98,1,1)
Block(-8,98,2,1)
Block(-8,98,3,1)
Block(-8,98,4,3)
Block(-8,98,5,1)
Block(-8,99,-6,1)
Block(-8,99,-5,3)
Block(-8,99,-4,3)
Block(-8,99,-3,1)
Block(-8,99,-2,1)
Block(-8,99,-1,1)
Block(-8,99,0,1)
Block(-8,99,1,1)
Block(-8,99,2,1)
Block(-8,99,3,1)
Block(-8,99,4,1)
Block(-8,100,-5,1)
Block(-8,100,-4,3)
Block(-8,100,-3,3)
Block(-8,100,-2,1)
Block(-8,100,-1,1)
Block(-8,100,0,1)
Block(-8,100,1,1)
Block(-8,100,2,1)
Block(-8,100,3,1)
Block(-8,100,4,1)
Block(-8,101,-5,1)
Block(-8,101,-4,1)
Block(-8,101,-3,1)
Block(-8,101,-2,3)
Block(-8,101,-1,3)
Block(-8,101,0,3)
Block(-8,101,1,1)
Block(-8,101,2,1)
Block(-8,101,3,3)
Block(-8,101,4,1)
Block(-8,102,-5,1)
Block(-8,102,-4,1)
Block(-8,102,-3,1)
Block(-8,102,-2,1)
Block(-8,102,-1,3)
Block(-8,102,0,3)
Block(-8,102,1,3)
Block(-8,102,2,3)
Block(-8,102,3,1)
Block(-8,103,-3,1)
Block(-8,103,-2,1)
Block(-8,103,-1,1)
Block(-8,103,0,1)
Block(-8,103,1,3)
Block(-8,103,2,3)
Block(-8,103,3,1)
Block(-8,104,-2,1)
Block(-8,104,-1,1)
Block(-8,104,0,1)
Block(-8,104,1,1)
Block(-8,104,2,1)
Block(-8,104,3,1)
Block(-8,105,1,1)
Block(-8,105,2,1)
Block(-7,0,-8,1)
Block(-7,0,-7,1)
Block(-7,0,-6,1)
Block(-7,0,-5,1)
Block(-7,0,-4,1)
Block(-7,0,-3,1)
Block(-7,0,-2,1)
Block(-7,0,-1,1)
Block(-7,0,0,1)
Block(-7,0,1,1)
Block(-7,0,2,1)
Block(-7,0,3,1)
Block(-7,0,4,1)
Block(-7,0,5,1)
Block(-7,0,6,1)
Block(-7,0,7,1)
Block(-7,1,-7,1)
Block(-7,1,-6,1)
Block(-7,1,-5,1)
Block(-7,1,-4,1)
Block(-7,1,-3,1)
Block(-7,1,-2,1)
Block(-7,1,-1,1)
Block(-7,1,0,1)
Block(-7,1,1,1)
Block(-7,1,2,1)
Block(-7,1,3,1)
Block(-7,1,4,1)
Block(-7,1,5,1)
Block(-7,1,6,1)
Block(-7,1,7,1)
Block(-7,2,-7,1)
Block(-7,2,-6,1)
Block(-7,2,-5,1)
Block(-7,2,-4,1)
Block(-7,2,-3,1)
Block(-7,2,-2,1)
Block(-7,2,-1,1)
Block(-7,2,0,1)
Block(-7,2,1,1)
Block(-7,2,2,1)
Block(-7,2,3,1)
Block(-7,2,4,1)
Block(-7,2,5,1)
Block(-7,2,6,1)
Block(-7,2,7,1)
Block(-7,3,-6,1)
Block(-7,3,-5,1)
Block(-7,3,-4,1)
Block(-7,3,-3,1)
Block(-7,3,-2,1)
Block(-7,3,-1,1)
Block(-7,3,0,1)
Block(-7,3,1,1)
Block(-7,3,2,1)
Block(-7,3,3,1)
Block(-7,3,4,1)
Block(-7,3,5,1)
Block(-7,3,6,1)
Block(-7,3,7,1)
Block(-7,4,-6,1)
Block(-7,4,-5,1)
Block(-7,4,-4,1)
Block(-7,4,-3,1)
Block(-7,4,-2,1)
Block(-7,4,-1,1)
Block(-7,4,0,1)
Block(-7,4,1,1)
Block(-7,4,2,1)
Block(-7,4,3,1)
Block(-7,4,4,1)
Block(-7,4,5,1)
Block(-7,4,6,1)
Block(-7,4,7,1)
Block(-7,5,-7,1)
Block(-7,5,-6,1)
Block(-7,5,-5,1)
Block(-7,5,-4,1)
Block(-7,5,-3,1)
Block(-7,5,-2,1)
Block(-7,5,-1,1)
Block(-7,5,0,1)
Block(-7,5,1,1)
Block(-7,5,2,1)
Block(-7,5,3,1)
Block(-7,5,4,1)
Block(-7,5,5,1)
Block(-7,5,6,1)
Block(-7,6,-7,1)
Block(-7,6,-6,1)
Block(-7,6,-5,1)
Block(-7,6,-4,1)
Block(-7,6,-3,1)
Block(-7,6,-2,1)
Block(-7,6,-1,1)
Block(-7,6,0,1)
Block(-7,6,1,1)
Block(-7,6,2,1)
Block(-7,6,3,1)
Block(-7,6,4,1)
Block(-7,6,5,1)
Block(-7,6,6,1)
Block(-7,7,-7,1)
Block(-7,7,-6,1)
Block(-7,7,-5,1)
Block(-7,7,-4,1)
Block(-7,7,-3,1)
Block(-7,7,-2,1)
Block(-7,7,-1,1)
Block(-7,7,0,1)
Block(-7,7,1,1)
Block(-7,7,2,1)
Block(-7,7,3,1)
Block(-7,7,4,1)
Block(-7,7,5,1)
Block(-7,7,6,1)
Block(-7,7,7,1)
Block(-7,8,-7,1)
Block(-7,8,-6,1)
Block(-7,8,-5,1)
Block(-7,8,-4,1)
Block(-7,8,-3,1)
Block(-7,8,-2,1)
Block(-7,8,-1,1)
Block(-7,8,0,1)
Block(-7,8,1,1)
Block(-7,8,2,1)
Block(-7,8,3,1)
Block(-7,8,4,1)
Block(-7,8,5,1)
Block(-7,8,6,1)
Block(-7,8,7,1)
Block(-7,9,-7,1)
Block(-7,9,-6,1)
Block(-7,9,-5,1)
Block(-7,9,-4,1)
Block(-7,9,-3,1)
Block(-7,9,-2,1)
Block(-7,9,-1,1)
Block(-7,9,0,1)
Block(-7,9,1,1)
Block(-7,9,2,1)
Block(-7,9,3,1)
Block(-7,9,4,1)
Block(-7,9,5,1)
Block(-7,9,6,1)
Block(-7,9,7,1)
Block(-7,10,-7,1)
Block(-7,10,-6,1)
Block(-7,10,-5,1)
Block(-7,10,-4,1)
Block(-7,10,-3,1)
Block(-7,10,-2,1)
Block(-7,10,-1,1)
Block(-7,10,0,1)
Block(-7,10,1,1)
Block(-7,10,2,1)
Block(-7,10,3,1)
Block(-7,10,4,1)
Block(-7,10,5,1)
Block(-7,10,6,1)
Block(-7,10,7,1)
Block(-7,10,8,1)
Block(-7,11,-7,1)
Block(-7,11,-6,1)
Block(-7,11,-5,1)
Block(-7,11,-4,1)
Block(-7,11,-3,1)
Block(-7,11,-2,1)
Block(-7,11,-1,1)
Block(-7,11,0,1)
Block(-7,11,1,1)
Block(-7,11,2,1)
Block(-7,11,3,1)
Block(-7,11,4,1)
Block(-7,11,5,1)
Block(-7,11,6,1)
Block(-7,11,7,1)
Block(-7,11,8,1)
Block(-7,12,-6,1)
Block(-7,12,-5,1)
Block(-7,12,-4,1)
Block(-7,12,-3,1)
Block(-7,12,-2,1)
Block(-7,12,-1,1)
Block(-7,12,0,1)
Block(-7,12,1,1)
Block(-7,12,2,1)
Block(-7,12,3,1)
Block(-7,12,4,1)
Block(-7,12,5,1)
Block(-7,12,6,1)
Block(-7,12,7,1)
Block(-7,12,8,1)
Block(-7,13,-6,1)
Block(-7,13,-5,1)
Block(-7,13,-4,1)
Block(-7,13,-3,1)
Block(-7,13,-2,1)
Block(-7,13,-1,1)
Block(-7,13,0,1)
Block(-7,13,1,1)
Block(-7,13,2,1)
Block(-7,13,3,1)
Block(-7,13,4,1)
Block(-7,13,5,1)
Block(-7,13,6,1)
Block(-7,13,7,1)
Block(-7,13,8,1)
Block(-7,14,-6,1)
Block(-7,14,-5,1)
Block(-7,14,-4,1)
Block(-7,14,-3,1)
Block(-7,14,-2,1)
Block(-7,14,-1,1)
Block(-7,14,0,1)
Block(-7,14,1,1)
Block(-7,14,2,1)
Block(-7,14,3,1)
Block(-7,14,4,1)
Block(-7,14,5,1)
Block(-7,14,6,1)
Block(-7,14,7,1)
Block(-7,14,8,1)
Block(-7,14,9,1)
Block(-7,15,-6,1)
Block(-7,15,-5,1)
Block(-7,15,-4,1)
Block(-7,15,-3,1)
Block(-7,15,-2,1)
Block(-7,15,-1,1)
Block(-7,15,0,1)
Block(-7,15,1,1)
Block(-7,15,2,1)
Block(-7,15,3,1)
Block(-7,15,4,1)
Block(-7,15,5,1)
Block(-7,15,6,1)
Block(-7,15,7,1)
Block(-7,15,8,1)
Block(-7,15,9,1)
Block(-7,16,-5,1)
Block(-7,16,-4,1)
Block(-7,16,-3,1)
Block(-7,16,-2,1)
Block(-7,16,-1,1)
Block(-7,16,0,1)
Block(-7,16,1,1)
Block(-7,16,2,1)
Block(-7,16,3,1)
Block(-7,16,4,1)
Block(-7,16,5,1)
Block(-7,16,6,1)
Block(-7,16,7,1)
Block(-7,16,8,1)
Block(-7,17,-5,1)
Block(-7,17,-4,1)
Block(-7,17,-3,1)
Block(-7,17,-2,1)
Block(-7,17,-1,1)
Block(-7,17,0,1)
Block(-7,17,1,1)
Block(-7,17,2,1)
Block(-7,17,3,1)
Block(-7,17,4,1)
Block(-7,17,5,1)
Block(-7,17,6,1)
Block(-7,17,7,1)
Block(-7,17,8,1)
Block(-7,18,-5,1)
Block(-7,18,-4,1)
Block(-7,18,-3,1)
Block(-7,18,-2,1)
Block(-7,18,-1,1)
Block(-7,18,0,1)
Block(-7,18,1,1)
Block(-7,18,2,1)
Block(-7,18,3,1)
Block(-7,18,4,1)
Block(-7,18,5,1)
Block(-7,18,6,1)
Block(-7,18,7,1)
Block(-7,18,8,1)
Block(-7,19,-5,1)
Block(-7,19,-4,1)
Block(-7,19,-3,1)
Block(-7,19,-2,1)
Block(-7,19,-1,1)
Block(-7,19,0,1)
Block(-7,19,1,1)
Block(-7,19,2,1)
Block(-7,19,3,1)
Block(-7,19,4,1)
Block(-7,19,5,1)
Block(-7,19,6,1)
Block(-7,19,7,1)
Block(-7,19,8,1)
Block(-7,20,-6,1)
Block(-7,20,-5,1)
Block(-7,20,-4,1)
Block(-7,20,-3,1)
Block(-7,20,-2,1)
Block(-7,20,-1,1)
Block(-7,20,0,1)
Block(-7,20,1,1)
Block(-7,20,2,1)
Block(-7,20,3,1)
Block(-7,20,4,1)
Block(-7,20,5,1)
Block(-7,20,6,1)
Block(-7,20,7,1)
Block(-7,20,8,1)
Block(-7,20,9,1)
Block(-7,21,-7,1)
Block(-7,21,-6,1)
Block(-7,21,-5,1)
Block(-7,21,-4,1)
Block(-7,21,-3,1)
Block(-7,21,-2,1)
Block(-7,21,-1,1)
Block(-7,21,0,1)
Block(-7,21,1,1)
Block(-7,21,2,1)
Block(-7,21,3,1)
Block(-7,21,4,1)
Block(-7,21,5,1)
Block(-7,21,6,1)
Block(-7,21,7,1)
Block(-7,21,8,1)
Block(-7,21,9,1)
Block(-7,22,-7,1)
Block(-7,22,-6,1)
Block(-7,22,-5,1)
Block(-7,22,-4,1)
Block(-7,22,-3,1)
Block(-7,22,-2,1)
Block(-7,22,-1,1)
Block(-7,22,0,1)
Block(-7,22,1,1)
Block(-7,22,2,1)
Block(-7,22,3,1)
Block(-7,22,4,1)
Block(-7,22,5,1)
Block(-7,22,6,1)
Block(-7,22,7,1)
Block(-7,22,8,1)
Block(-7,22,9,1)
Block(-7,22,10,1)
Block(-7,23,-7,1)
Block(-7,23,-6,1)
Block(-7,23,-5,1)
Block(-7,23,-4,1)
Block(-7,23,-3,1)
Block(-7,23,-2,1)
Block(-7,23,-1,1)
Block(-7,23,0,1)
Block(-7,23,1,1)
Block(-7,23,2,1)
Block(-7,23,3,1)
Block(-7,23,4,1)
Block(-7,23,5,1)
Block(-7,23,6,1)
Block(-7,23,7,1)
Block(-7,23,8,1)
Block(-7,23,9,1)
Block(-7,23,10,1)
Block(-7,24,-6,1)
Block(-7,24,-5,1)
Block(-7,24,-4,1)
Block(-7,24,-3,1)
Block(-7,24,-2,1)
Block(-7,24,-1,1)
Block(-7,24,0,1)
Block(-7,24,1,1)
Block(-7,24,2,1)
Block(-7,24,3,1)
Block(-7,24,4,1)
Block(-7,24,5,1)
Block(-7,24,6,1)
Block(-7,24,7,1)
Block(-7,24,8,1)
Block(-7,24,9,1)
Block(-7,25,-6,1)
Block(-7,25,-5,1)
Block(-7,25,-4,1)
Block(-7,25,-3,1)
Block(-7,25,-2,1)
Block(-7,25,-1,1)
Block(-7,25,0,1)
Block(-7,25,1,1)
Block(-7,25,2,1)
Block(-7,25,3,1)
Block(-7,25,4,1)
Block(-7,25,5,1)
Block(-7,25,6,1)
Block(-7,25,7,1)
Block(-7,25,8,1)
Block(-7,26,-6,1)
Block(-7,26,-5,1)
Block(-7,26,-4,1)
Block(-7,26,-3,1)
Block(-7,26,-2,1)
Block(-7,26,-1,1)
Block(-7,26,0,1)
Block(-7,26,1,1)
Block(-7,26,2,1)
Block(-7,26,3,1)
Block(-7,26,4,1)
Block(-7,26,5,1)
Block(-7,26,6,1)
Block(-7,26,7,1)
Block(-7,27,-6,1)
Block(-7,27,-5,1)
Block(-7,27,-4,1)
Block(-7,27,-3,1)
Block(-7,27,-2,1)
Block(-7,27,-1,1)
Block(-7,27,0,1)
Block(-7,27,1,1)
Block(-7,27,2,1)
Block(-7,27,3,1)
Block(-7,27,4,1)
Block(-7,27,5,1)
Block(-7,27,6,1)
Block(-7,28,-7,1)
Block(-7,28,-6,1)
Block(-7,28,-5,1)
Block(-7,28,-4,1)
Block(-7,28,-3,1)
Block(-7,28,-2,1)
Block(-7,28,-1,1)
Block(-7,28,0,1)
Block(-7,28,1,1)
Block(-7,28,2,1)
Block(-7,28,3,1)
Block(-7,28,4,1)
Block(-7,28,5,1)
Block(-7,28,6,1)
Block(-7,29,-7,1)
Block(-7,29,-6,1)
Block(-7,29,-5,1)
Block(-7,29,-4,1)
Block(-7,29,-3,1)
Block(-7,29,-2,1)
Block(-7,29,-1,1)
Block(-7,29,0,1)
Block(-7,29,1,1)
Block(-7,29,2,1)
Block(-7,29,3,1)
Block(-7,29,4,1)
Block(-7,29,5,1)
Block(-7,29,6,1)
Block(-7,29,7,1)
Block(-7,30,-7,1)
Block(-7,30,-6,1)
Block(-7,30,-5,1)
Block(-7,30,-4,1)
Block(-7,30,-3,1)
Block(-7,30,-2,1)
Block(-7,30,-1,1)
Block(-7,30,0,1)
Block(-7,30,1,1)
Block(-7,30,2,1)
Block(-7,30,3,1)
Block(-7,30,4,1)
Block(-7,30,5,1)
Block(-7,30,6,1)
Block(-7,30,7,1)
Block(-7,30,8,1)
Block(-7,31,-7,1)
Block(-7,31,-6,1)
Block(-7,31,-5,1)
Block(-7,31,-4,1)
Block(-7,31,-3,1)
Block(-7,31,-2,1)
Block(-7,31,-1,1)
Block(-7,31,0,1)
Block(-7,31,1,1)
Block(-7,31,2,1)
Block(-7,31,3,1)
Block(-7,31,4,1)
Block(-7,31,5,1)
Block(-7,31,6,1)
Block(-7,31,7,1)
Block(-7,31,8,1)
Block(-7,31,9,1)
Block(-7,32,-6,1)
Block(-7,32,-5,1)
Block(-7,32,-4,1)
Block(-7,32,-3,1)
Block(-7,32,-2,1)
Block(-7,32,-1,1)
Block(-7,32,0,1)
Block(-7,32,1,1)
Block(-7,32,2,1)
Block(-7,32,3,1)
Block(-7,32,4,1)
Block(-7,32,5,1)
Block(-7,32,6,1)
Block(-7,32,7,1)
Block(-7,32,8,1)
Block(-7,32,9,1)
Block(-7,33,-6,1)
Block(-7,33,-5,1)
Block(-7,33,-4,1)
Block(-7,33,-3,1)
Block(-7,33,-2,1)
Block(-7,33,-1,1)
Block(-7,33,0,1)
Block(-7,33,1,1)
Block(-7,33,2,1)
Block(-7,33,3,1)
Block(-7,33,4,1)
Block(-7,33,5,1)
Block(-7,33,6,1)
Block(-7,33,7,1)
Block(-7,33,8,1)
Block(-7,33,9,1)
Block(-7,34,-6,1)
Block(-7,34,-5,1)
Block(-7,34,-4,1)
Block(-7,34,-3,1)
Block(-7,34,-2,1)
Block(-7,34,-1,1)
Block(-7,34,0,1)
Block(-7,34,1,1)
Block(-7,34,2,1)
Block(-7,34,3,1)
Block(-7,34,4,1)
Block(-7,34,5,1)
Block(-7,34,6,1)
Block(-7,34,7,1)
Block(-7,34,8,1)
Block(-7,35,-6,1)
Block(-7,35,-5,1)
Block(-7,35,-4,1)
Block(-7,35,-3,1)
Block(-7,35,-2,1)
Block(-7,35,-1,1)
Block(-7,35,0,1)
Block(-7,35,1,1)
Block(-7,35,2,1)
Block(-7,35,3,1)
Block(-7,35,4,1)
Block(-7,35,5,1)
Block(-7,35,6,1)
Block(-7,35,7,1)
Block(-7,36,-6,1)
Block(-7,36,-5,1)
Block(-7,36,-4,1)
Block(-7,36,-3,1)
Block(-7,36,-2,1)
Block(-7,36,-1,1)
Block(-7,36,0,1)
Block(-7,36,1,1)
Block(-7,36,2,1)
Block(-7,36,3,1)
Block(-7,36,4,1)
Block(-7,36,5,1)
Block(-7,37,-7,1)
Block(-7,37,-6,1)
Block(-7,37,-5,1)
Block(-7,37,-4,1)
Block(-7,37,-3,1)
Block(-7,37,-2,1)
Block(-7,37,-1,1)
Block(-7,37,0,1)
Block(-7,37,1,1)
Block(-7,37,2,1)
Block(-7,37,3,1)
Block(-7,37,4,1)
Block(-7,38,-8,1)
Block(-7,38,-7,1)
Block(-7,38,-6,1)
Block(-7,38,-5,1)
Block(-7,38,-4,1)
Block(-7,38,-3,1)
Block(-7,38,-2,1)
Block(-7,38,-1,1)
Block(-7,38,0,1)
Block(-7,38,1,1)
Block(-7,38,2,1)
Block(-7,38,3,1)
Block(-7,38,4,1)
Block(-7,39,-8,1)
Block(-7,39,-7,1)
Block(-7,39,-6,1)
Block(-7,39,-5,1)
Block(-7,39,-4,1)
Block(-7,39,-3,1)
Block(-7,39,-2,1)
Block(-7,39,-1,1)
Block(-7,39,0,1)
Block(-7,39,1,1)
Block(-7,39,2,1)
Block(-7,39,3,1)
Block(-7,39,4,1)
Block(-7,40,-9,1)
Block(-7,40,-8,1)
Block(-7,40,-7,1)
Block(-7,40,-6,1)
Block(-7,40,-5,1)
Block(-7,40,-4,1)
Block(-7,40,-3,1)
Block(-7,40,-2,1)
Block(-7,40,-1,1)
Block(-7,40,0,1)
Block(-7,40,1,1)
Block(-7,40,2,1)
Block(-7,40,3,1)
Block(-7,40,4,1)
Block(-7,40,5,1)
Block(-7,41,-8,1)
Block(-7,41,-7,1)
Block(-7,41,-6,1)
Block(-7,41,-5,1)
Block(-7,41,-4,1)
Block(-7,41,-3,1)
Block(-7,41,-2,1)
Block(-7,41,-1,1)
Block(-7,41,0,1)
Block(-7,41,1,1)
Block(-7,41,2,1)
Block(-7,41,3,1)
Block(-7,41,4,1)
Block(-7,41,5,1)
Block(-7,41,6,1)
Block(-7,41,7,1)
Block(-7,42,-8,1)
Block(-7,42,-7,1)
Block(-7,42,-6,1)
Block(-7,42,-5,1)
Block(-7,42,-4,1)
Block(-7,42,-3,1)
Block(-7,42,-2,1)
Block(-7,42,-1,1)
Block(-7,42,0,1)
Block(-7,42,1,1)
Block(-7,42,2,1)
Block(-7,42,3,1)
Block(-7,42,4,1)
Block(-7,42,5,1)
Block(-7,42,6,1)
Block(-7,42,7,1)
Block(-7,42,8,1)
Block(-7,43,-8,1)
Block(-7,43,-7,1)
Block(-7,43,-6,1)
Block(-7,43,-5,1)
Block(-7,43,-4,1)
Block(-7,43,-3,1)
Block(-7,43,-2,1)
Block(-7,43,-1,1)
Block(-7,43,0,1)
Block(-7,43,1,1)
Block(-7,43,2,1)
Block(-7,43,3,1)
Block(-7,43,4,1)
Block(-7,43,5,1)
Block(-7,43,6,1)
Block(-7,43,7,1)
Block(-7,43,8,1)
Block(-7,44,-7,1)
Block(-7,44,-6,1)
Block(-7,44,-5,1)
Block(-7,44,-4,1)
Block(-7,44,-3,1)
Block(-7,44,-2,1)
Block(-7,44,-1,1)
Block(-7,44,0,1)
Block(-7,44,1,1)
Block(-7,44,2,1)
Block(-7,44,3,1)
Block(-7,44,4,1)
Block(-7,44,5,1)
Block(-7,44,6,1)
Block(-7,44,7,1)
Block(-7,44,8,1)
Block(-7,45,-6,1)
Block(-7,45,-5,1)
Block(-7,45,-4,1)
Block(-7,45,-3,1)
Block(-7,45,-2,1)
Block(-7,45,-1,1)
Block(-7,45,0,1)
Block(-7,45,1,1)
Block(-7,45,2,1)
Block(-7,45,3,1)
Block(-7,45,4,1)
Block(-7,45,5,1)
Block(-7,45,6,1)
Block(-7,45,7,1)
Block(-7,46,-4,1)
Block(-7,46,-3,1)
Block(-7,46,-2,1)
Block(-7,46,-1,1)
Block(-7,46,0,1)
Block(-7,46,1,1)
Block(-7,46,2,1)
Block(-7,46,3,1)
Block(-7,46,4,1)
Block(-7,46,5,1)
Block(-7,46,6,1)
Block(-7,46,7,1)
Block(-7,47,-3,1)
Block(-7,47,-2,1)
Block(-7,47,-1,1)
Block(-7,47,0,1)
Block(-7,47,1,1)
Block(-7,47,2,1)
Block(-7,47,3,1)
Block(-7,47,4,1)
Block(-7,47,5,1)
Block(-7,47,6,1)
Block(-7,47,7,1)
Block(-7,48,-3,1)
Block(-7,48,-2,1)
Block(-7,48,-1,1)
Block(-7,48,0,1)
Block(-7,48,1,1)
Block(-7,48,2,1)
Block(-7,48,3,1)
Block(-7,48,4,1)
Block(-7,48,5,1)
Block(-7,48,6,1)
Block(-7,48,7,1)
Block(-7,49,-3,1)
Block(-7,49,-2,1)
Block(-7,49,-1,1)
Block(-7,49,0,1)
Block(-7,49,1,1)
Block(-7,49,2,1)
Block(-7,49,3,1)
Block(-7,49,4,1)
Block(-7,49,5,1)
Block(-7,49,6,1)
Block(-7,49,7,1)
Block(-7,49,8,1)
Block(-7,50,-5,1)
Block(-7,50,-4,1)
Block(-7,50,-3,1)
Block(-7,50,-2,1)
Block(-7,50,-1,1)
Block(-7,50,0,1)
Block(-7,50,1,1)
Block(-7,50,2,1)
Block(-7,50,3,1)
Block(-7,50,4,1)
Block(-7,50,5,1)
Block(-7,50,6,1)
Block(-7,50,7,1)
Block(-7,50,8,1)
Block(-7,51,-6,1)
Block(-7,51,-5,1)
Block(-7,51,-4,1)
Block(-7,51,-3,1)
Block(-7,51,-2,1)
Block(-7,51,-1,1)
Block(-7,51,0,1)
Block(-7,51,1,1)
Block(-7,51,2,1)
Block(-7,51,3,1)
Block(-7,51,4,1)
Block(-7,51,5,1)
Block(-7,51,6,1)
Block(-7,51,7,1)
Block(-7,51,8,1)
Block(-7,52,-7,1)
Block(-7,52,-6,1)
Block(-7,52,-5,1)
Block(-7,52,-4,1)
Block(-7,52,-3,1)
Block(-7,52,-2,1)
Block(-7,52,-1,1)
Block(-7,52,0,1)
Block(-7,52,1,1)
Block(-7,52,2,1)
Block(-7,52,3,1)
Block(-7,52,4,1)
Block(-7,52,5,1)
Block(-7,52,6,1)
Block(-7,52,7,1)
Block(-7,52,8,1)
Block(-7,52,9,1)
Block(-7,53,-8,1)
Block(-7,53,-7,1)
Block(-7,53,-6,1)
Block(-7,53,-5,1)
Block(-7,53,-4,1)
Block(-7,53,-3,1)
Block(-7,53,-2,1)
Block(-7,53,-1,1)
Block(-7,53,0,1)
Block(-7,53,1,1)
Block(-7,53,2,1)
Block(-7,53,3,1)
Block(-7,53,4,1)
Block(-7,53,5,1)
Block(-7,53,6,1)
Block(-7,53,7,1)
Block(-7,53,8,1)
Block(-7,53,9,1)
Block(-7,54,-9,1)
Block(-7,54,-8,1)
Block(-7,54,-7,1)
Block(-7,54,-6,1)
Block(-7,54,-5,1)
Block(-7,54,-4,1)
Block(-7,54,-3,1)
Block(-7,54,-2,1)
Block(-7,54,-1,1)
Block(-7,54,0,1)
Block(-7,54,1,1)
Block(-7,54,2,1)
Block(-7,54,3,1)
Block(-7,54,4,1)
Block(-7,54,5,1)
Block(-7,54,6,1)
Block(-7,54,7,1)
Block(-7,54,8,1)
Block(-7,54,9,1)
Block(-7,55,-9,1)
Block(-7,55,-8,1)
Block(-7,55,-7,1)
Block(-7,55,-6,1)
Block(-7,55,-5,1)
Block(-7,55,-4,1)
Block(-7,55,-3,1)
Block(-7,55,-2,1)
Block(-7,55,-1,1)
Block(-7,55,0,1)
Block(-7,55,1,1)
Block(-7,55,2,1)
Block(-7,55,3,1)
Block(-7,55,4,1)
Block(-7,55,5,1)
Block(-7,55,6,1)
Block(-7,55,7,1)
Block(-7,55,8,1)
Block(-7,56,-9,1)
Block(-7,56,-8,1)
Block(-7,56,-7,1)
Block(-7,56,-6,1)
Block(-7,56,-5,1)
Block(-7,56,-4,1)
Block(-7,56,-3,1)
Block(-7,56,-2,1)
Block(-7,56,-1,1)
Block(-7,56,0,1)
Block(-7,56,1,1)
Block(-7,56,2,1)
Block(-7,56,3,1)
Block(-7,56,4,1)
Block(-7,56,5,1)
Block(-7,56,6,1)
Block(-7,56,7,1)
Block(-7,56,8,1)
Block(-7,57,-8,1)
Block(-7,57,-7,1)
Block(-7,57,-6,1)
Block(-7,57,-5,1)
Block(-7,57,-4,1)
Block(-7,57,-3,1)
Block(-7,57,-2,1)
Block(-7,57,-1,1)
Block(-7,57,0,1)
Block(-7,57,1,1)
Block(-7,57,2,1)
Block(-7,57,3,1)
Block(-7,57,4,1)
Block(-7,57,5,1)
Block(-7,57,6,1)
Block(-7,57,7,1)
Block(-7,58,-8,1)
Block(-7,58,-7,1)
Block(-7,58,-6,1)
Block(-7,58,-5,1)
Block(-7,58,-4,1)
Block(-7,58,-3,1)
Block(-7,58,-2,1)
Block(-7,58,-1,1)
Block(-7,58,0,1)
Block(-7,58,1,1)
Block(-7,58,2,1)
Block(-7,58,3,1)
Block(-7,58,4,1)
Block(-7,58,5,1)
Block(-7,58,6,1)
Block(-7,58,7,1)
Block(-7,59,-7,1)
Block(-7,59,-6,1)
Block(-7,59,-5,1)
Block(-7,59,-4,1)
Block(-7,59,-3,1)
Block(-7,59,-2,1)
Block(-7,59,-1,1)
Block(-7,59,0,1)
Block(-7,59,1,1)
Block(-7,59,2,1)
Block(-7,59,3,1)
Block(-7,59,4,1)
Block(-7,59,5,1)
Block(-7,59,6,1)
Block(-7,60,-7,1)
Block(-7,60,-6,1)
Block(-7,60,-5,1)
Block(-7,60,-4,1)
Block(-7,60,-3,1)
Block(-7,60,-2,1)
Block(-7,60,-1,1)
Block(-7,60,0,1)
Block(-7,60,1,1)
Block(-7,60,2,1)
Block(-7,60,3,1)
Block(-7,60,4,1)
Block(-7,60,5,1)
Block(-7,60,6,1)
Block(-7,61,-7,1)
Block(-7,61,-6,1)
Block(-7,61,-5,1)
Block(-7,61,-4,1)
Block(-7,61,-3,1)
Block(-7,61,-2,1)
Block(-7,61,-1,1)
Block(-7,61,0,1)
Block(-7,61,1,1)
Block(-7,61,2,1)
Block(-7,61,3,1)
Block(-7,61,4,1)
Block(-7,61,5,1)
Block(-7,61,6,1)
Block(-7,61,7,1)
Block(-7,62,-7,1)
Block(-7,62,-6,1)
Block(-7,62,-5,1)
Block(-7,62,-4,1)
Block(-7,62,-3,1)
Block(-7,62,-2,1)
Block(-7,62,-1,1)
Block(-7,62,0,1)
Block(-7,62,1,1)
Block(-7,62,2,1)
Block(-7,62,3,1)
Block(-7,62,4,1)
Block(-7,62,5,1)
Block(-7,62,6,1)
Block(-7,62,7,1)
Block(-7,63,-7,1)
Block(-7,63,-6,1)
Block(-7,63,-5,1)
Block(-7,63,-4,1)
Block(-7,63,-3,1)
Block(-7,63,-2,1)
Block(-7,63,-1,1)
Block(-7,63,0,1)
Block(-7,63,1,1)
Block(-7,63,2,1)
Block(-7,63,3,1)
Block(-7,63,4,1)
Block(-7,63,5,1)
Block(-7,63,6,1)
Block(-7,63,7,1)
Block(-7,63,8,1)
Block(-7,64,-7,1)
Block(-7,64,-6,1)
Block(-7,64,-5,1)
Block(-7,64,-4,1)
Block(-7,64,-3,1)
Block(-7,64,-2,1)
Block(-7,64,-1,1)
Block(-7,64,0,1)
Block(-7,64,1,1)
Block(-7,64,2,1)
Block(-7,64,3,1)
Block(-7,64,4,1)
Block(-7,64,5,1)
Block(-7,64,6,1)
Block(-7,64,7,1)
Block(-7,64,8,1)
Block(-7,65,-7,1)
Block(-7,65,-6,1)
Block(-7,65,-5,1)
Block(-7,65,-4,1)
Block(-7,65,-3,1)
Block(-7,65,-2,1)
Block(-7,65,-1,1)
Block(-7,65,0,1)
Block(-7,65,1,1)
Block(-7,65,2,1)
Block(-7,65,3,1)
Block(-7,65,4,1)
Block(-7,65,5,1)
Block(-7,65,6,1)
Block(-7,65,7,1)
Block(-7,65,8,1)
Block(-7,65,9,1)
Block(-7,66,-7,1)
Block(-7,66,-6,1)
Block(-7,66,-5,1)
Block(-7,66,-4,1)
Block(-7,66,-3,1)
Block(-7,66,-2,1)
Block(-7,66,-1,1)
Block(-7,66,0,1)
Block(-7,66,1,1)
Block(-7,66,2,1)
Block(-7,66,3,1)
Block(-7,66,4,1)
Block(-7,66,5,1)
Block(-7,66,6,1)
Block(-7,66,7,1)
Block(-7,66,8,1)
Block(-7,66,9,1)
Block(-7,67,-7,1)
Block(-7,67,-6,1)
Block(-7,67,-5,1)
Block(-7,67,-4,1)
Block(-7,67,-3,1)
Block(-7,67,-2,1)
Block(-7,67,-1,1)
Block(-7,67,0,1)
Block(-7,67,1,1)
Block(-7,67,2,1)
Block(-7,67,3,1)
Block(-7,67,4,1)
Block(-7,67,5,1)
Block(-7,67,6,1)
Block(-7,67,7,1)
Block(-7,67,8,1)
Block(-7,67,9,1)
Block(-7,68,-7,1)
Block(-7,68,-6,1)
Block(-7,68,-5,1)
Block(-7,68,-4,1)
Block(-7,68,-3,1)
Block(-7,68,-2,1)
Block(-7,68,-1,1)
Block(-7,68,0,1)
Block(-7,68,1,1)
Block(-7,68,2,1)
Block(-7,68,3,1)
Block(-7,68,4,1)
Block(-7,68,5,1)
Block(-7,68,6,1)
Block(-7,68,7,1)
Block(-7,68,8,1)
Block(-7,69,-6,1)
Block(-7,69,-5,1)
Block(-7,69,-4,1)
Block(-7,69,-3,1)
Block(-7,69,-2,1)
Block(-7,69,-1,1)
Block(-7,69,0,1)
Block(-7,69,1,1)
Block(-7,69,2,1)
Block(-7,69,3,1)
Block(-7,69,4,1)
Block(-7,69,5,1)
Block(-7,69,6,1)
Block(-7,69,7,1)
Block(-7,69,8,1)
Block(-7,70,-5,1)
Block(-7,70,-4,1)
Block(-7,70,-3,1)
Block(-7,70,-2,1)
Block(-7,70,-1,1)
Block(-7,70,0,1)
Block(-7,70,1,1)
Block(-7,70,2,1)
Block(-7,70,3,1)
Block(-7,70,4,1)
Block(-7,70,5,1)
Block(-7,70,6,1)
Block(-7,70,7,1)
Block(-7,71,-5,1)
Block(-7,71,-4,1)
Block(-7,71,-3,1)
Block(-7,71,-2,1)
Block(-7,71,-1,1)
Block(-7,71,0,1)
Block(-7,71,1,1)
Block(-7,71,2,1)
Block(-7,71,3,1)
Block(-7,71,4,1)
Block(-7,71,5,1)
Block(-7,71,6,1)
Block(-7,71,7,1)
Block(-7,72,-5,1)
Block(-7,72,-4,1)
Block(-7,72,-3,1)
Block(-7,72,-2,1)
Block(-7,72,-1,1)
Block(-7,72,0,1)
Block(-7,72,1,1)
Block(-7,72,2,1)
Block(-7,72,3,1)
Block(-7,72,4,1)
Block(-7,72,5,1)
Block(-7,72,6,1)
Block(-7,72,7,1)
Block(-7,73,-6,1)
Block(-7,73,-5,1)
Block(-7,73,-4,1)
Block(-7,73,-3,1)
Block(-7,73,-2,1)
Block(-7,73,-1,1)
Block(-7,73,0,1)
Block(-7,73,1,1)
Block(-7,73,2,1)
Block(-7,73,3,1)
Block(-7,73,4,1)
Block(-7,73,5,1)
Block(-7,73,6,1)
Block(-7,73,7,1)
Block(-7,73,8,1)
Block(-7,74,-6,1)
Block(-7,74,-5,1)
Block(-7,74,-4,1)
Block(-7,74,-3,1)
Block(-7,74,-2,1)
Block(-7,74,-1,1)
Block(-7,74,0,1)
Block(-7,74,1,1)
Block(-7,74,2,1)
Block(-7,74,3,1)
Block(-7,74,4,1)
Block(-7,74,5,1)
Block(-7,74,6,1)
Block(-7,74,7,1)
Block(-7,74,8,1)
Block(-7,74,9,1)
Block(-7,75,-6,1)
Block(-7,75,-5,1)
Block(-7,75,-4,1)
Block(-7,75,-3,1)
Block(-7,75,-2,1)
Block(-7,75,-1,1)
Block(-7,75,0,1)
Block(-7,75,1,1)
Block(-7,75,2,1)
Block(-7,75,3,1)
Block(-7,75,4,1)
Block(-7,75,5,1)
Block(-7,75,6,1)
Block(-7,75,7,1)
Block(-7,75,8,1)
Block(-7,75,9,1)
Block(-7,76,-6,1)
Block(-7,76,-5,1)
Block(-7,76,-4,1)
Block(-7,76,-3,1)
Block(-7,76,-2,1)
Block(-7,76,-1,1)
Block(-7,76,0,1)
Block(-7,76,1,1)
Block(-7,76,2,1)
Block(-7,76,3,1)
Block(-7,76,4,1)
Block(-7,76,5,1)
Block(-7,76,6,1)
Block(-7,76,7,1)
Block(-7,76,8,1)
Block(-7,76,9,1)
Block(-7,77,-6,1)
Block(-7,77,-5,1)
Block(-7,77,-4,1)
Block(-7,77,-3,1)
Block(-7,77,-2,1)
Block(-7,77,-1,1)
Block(-7,77,0,1)
Block(-7,77,1,1)
Block(-7,77,2,1)
Block(-7,77,3,1)
Block(-7,77,4,1)
Block(-7,77,5,1)
Block(-7,77,6,1)
Block(-7,77,7,1)
Block(-7,77,8,1)
Block(-7,77,9,1)
Block(-7,78,-5,1)
Block(-7,78,-4,1)
Block(-7,78,-3,1)
Block(-7,78,-2,1)
Block(-7,78,-1,1)
Block(-7,78,0,1)
Block(-7,78,1,1)
Block(-7,78,2,1)
Block(-7,78,3,1)
Block(-7,78,4,1)
Block(-7,78,5,1)
Block(-7,78,6,1)
Block(-7,78,7,1)
Block(-7,78,8,1)
Block(-7,78,9,1)
Block(-7,78,10,1)
Block(-7,79,-5,1)
Block(-7,79,-4,1)
Block(-7,79,-3,1)
Block(-7,79,-2,1)
Block(-7,79,-1,1)
Block(-7,79,0,1)
Block(-7,79,1,1)
Block(-7,79,2,1)
Block(-7,79,3,1)
Block(-7,79,4,1)
Block(-7,79,5,1)
Block(-7,79,6,1)
Block(-7,79,7,1)
Block(-7,79,8,1)
Block(-7,79,9,1)
Block(-7,79,10,1)
Block(-7,80,-5,1)
Block(-7,80,-4,1)
Block(-7,80,-3,1)
Block(-7,80,-2,1)
Block(-7,80,-1,1)
Block(-7,80,0,1)
Block(-7,80,1,1)
Block(-7,80,2,1)
Block(-7,80,3,1)
Block(-7,80,4,1)
Block(-7,80,5,1)
Block(-7,80,6,1)
Block(-7,80,7,1)
Block(-7,80,8,1)
Block(-7,80,9,1)
Block(-7,81,-6,1)
Block(-7,81,-5,1)
Block(-7,81,-4,1)
Block(-7,81,-3,1)
Block(-7,81,-2,1)
Block(-7,81,-1,1)
Block(-7,81,0,1)
Block(-7,81,1,1)
Block(-7,81,2,1)
Block(-7,81,3,1)
Block(-7,81,4,1)
Block(-7,81,5,1)
Block(-7,81,6,1)
Block(-7,81,7,1)
Block(-7,81,8,1)
Block(-7,82,-7,1)
Block(-7,82,-6,1)
Block(-7,82,-5,1)
Block(-7,82,-4,1)
Block(-7,82,-3,1)
Block(-7,82,-2,1)
Block(-7,82,-1,1)
Block(-7,82,0,1)
Block(-7,82,1,1)
Block(-7,82,2,1)
Block(-7,82,3,1)
Block(-7,82,4,1)
Block(-7,82,5,1)
Block(-7,82,6,1)
Block(-7,82,7,1)
Block(-7,83,-8,1)
Block(-7,83,-7,1)
Block(-7,83,-6,1)
Block(-7,83,-5,1)
Block(-7,83,-4,1)
Block(-7,83,-3,1)
Block(-7,83,-2,1)
Block(-7,83,-1,1)
Block(-7,83,0,1)
Block(-7,83,1,1)
Block(-7,83,2,1)
Block(-7,83,3,1)
Block(-7,83,4,1)
Block(-7,83,5,1)
Block(-7,83,6,1)
Block(-7,83,7,1)
Block(-7,84,-8,1)
Block(-7,84,-7,1)
Block(-7,84,-6,1)
Block(-7,84,-5,1)
Block(-7,84,-4,1)
Block(-7,84,-3,1)
Block(-7,84,-2,1)
Block(-7,84,-1,1)
Block(-7,84,0,1)
Block(-7,84,1,1)
Block(-7,84,2,1)
Block(-7,84,3,1)
Block(-7,84,4,1)
Block(-7,84,5,1)
Block(-7,84,6,1)
Block(-7,84,7,1)
Block(-7,85,-7,1)
Block(-7,85,-6,1)
Block(-7,85,-5,1)
Block(-7,85,-4,1)
Block(-7,85,-3,1)
Block(-7,85,-2,1)
Block(-7,85,-1,1)
Block(-7,85,0,1)
Block(-7,85,1,1)
Block(-7,85,2,1)
Block(-7,85,3,1)
Block(-7,85,4,1)
Block(-7,85,5,1)
Block(-7,85,6,1)
Block(-7,85,7,1)
Block(-7,85,8,1)
Block(-7,85,9,1)
Block(-7,86,-7,1)
Block(-7,86,-6,1)
Block(-7,86,-5,1)
Block(-7,86,-4,1)
Block(-7,86,-3,1)
Block(-7,86,-2,1)
Block(-7,86,-1,1)
Block(-7,86,0,1)
Block(-7,86,1,1)
Block(-7,86,2,1)
Block(-7,86,3,1)
Block(-7,86,4,1)
Block(-7,86,5,1)
Block(-7,86,6,1)
Block(-7,86,7,1)
Block(-7,86,8,1)
Block(-7,86,9,1)
Block(-7,87,-7,1)
Block(-7,87,-6,1)
Block(-7,87,-5,1)
Block(-7,87,-4,1)
Block(-7,87,-3,1)
Block(-7,87,-2,1)
Block(-7,87,-1,1)
Block(-7,87,0,1)
Block(-7,87,1,1)
Block(-7,87,2,1)
Block(-7,87,3,1)
Block(-7,87,4,1)
Block(-7,87,5,1)
Block(-7,87,6,1)
Block(-7,87,7,1)
Block(-7,87,8,1)
Block(-7,87,9,1)
Block(-7,88,-6,1)
Block(-7,88,-5,1)
Block(-7,88,-4,1)
Block(-7,88,-3,1)
Block(-7,88,-2,1)
Block(-7,88,-1,1)
Block(-7,88,0,1)
Block(-7,88,1,1)
Block(-7,88,2,1)
Block(-7,88,3,1)
Block(-7,88,4,1)
Block(-7,88,5,1)
Block(-7,88,6,1)
Block(-7,88,7,1)
Block(-7,88,8,1)
Block(-7,88,9,1)
Block(-7,89,-6,1)
Block(-7,89,-5,1)
Block(-7,89,-4,1)
Block(-7,89,-3,1)
Block(-7,89,-2,1)
Block(-7,89,-1,1)
Block(-7,89,0,1)
Block(-7,89,1,1)
Block(-7,89,2,1)
Block(-7,89,3,1)
Block(-7,89,4,1)
Block(-7,89,5,1)
Block(-7,89,6,1)
Block(-7,89,7,1)
Block(-7,89,8,1)
Block(-7,90,-6,1)
Block(-7,90,-5,1)
Block(-7,90,-4,1)
Block(-7,90,-3,1)
Block(-7,90,-2,1)
Block(-7,90,-1,1)
Block(-7,90,0,1)
Block(-7,90,1,1)
Block(-7,90,2,1)
Block(-7,90,3,1)
Block(-7,90,4,1)
Block(-7,90,5,1)
Block(-7,90,6,1)
Block(-7,90,7,1)
Block(-7,90,8,1)
Block(-7,91,-5,1)
Block(-7,91,-4,1)
Block(-7,91,-3,1)
Block(-7,91,-2,1)
Block(-7,91,-1,1)
Block(-7,91,0,1)
Block(-7,91,1,1)
Block(-7,91,2,1)
Block(-7,91,3,1)
Block(-7,91,4,1)
Block(-7,91,5,1)
Block(-7,91,6,1)
Block(-7,91,7,1)
Block(-7,91,8,1)
Block(-7,92,-5,1)
Block(-7,92,-4,1)
Block(-7,92,-3,1)
Block(-7,92,-2,1)
Block(-7,92,-1,1)
Block(-7,92,0,1)
Block(-7,92,1,1)
Block(-7,92,2,1)
Block(-7,92,3,1)
Block(-7,92,4,1)
Block(-7,92,5,1)
Block(-7,92,6,1)
Block(-7,92,7,3)
Block(-7,92,8,1)
Block(-7,93,-5,1)
Block(-7,93,-4,1)
Block(-7,93,-3,1)
Block(-7,93,-2,1)
Block(-7,93,-1,1)
Block(-7,93,0,1)
Block(-7,93,1,1)
Block(-7,93,2,1)
Block(-7,93,3,1)
Block(-7,93,4,1)
Block(-7,93,5,1)
Block(-7,93,6,1)
Block(-7,93,7,3)
Block(-7,93,8,1)
Block(-7,94,-5,1)
Block(-7,94,-4,1)
Block(-7,94,-3,1)
Block(-7,94,-2,1)
Block(-7,94,-1,1)
Block(-7,94,0,1)
Block(-7,94,1,1)
Block(-7,94,2,1)
Block(-7,94,3,1)
Block(-7,94,4,1)
Block(-7,94,5,1)
Block(-7,94,6,1)
Block(-7,94,7,1)
Block(-7,95,-6,1)
Block(-7,95,-5,1)
Block(-7,95,-4,1)
Block(-7,95,-3,1)
Block(-7,95,-2,1)
Block(-7,95,-1,1)
Block(-7,95,0,1)
Block(-7,95,1,1)
Block(-7,95,2,1)
Block(-7,95,3,1)
Block(-7,95,4,1)
Block(-7,95,5,1)
Block(-7,95,6,3)
Block(-7,95,7,1)
Block(-7,96,-7,1)
Block(-7,96,-6,1)
Block(-7,96,-5,1)
Block(-7,96,-4,1)
Block(-7,96,-3,1)
Block(-7,96,-2,1)
Block(-7,96,-1,1)
Block(-7,96,0,1)
Block(-7,96,1,1)
Block(-7,96,2,1)
Block(-7,96,3,1)
Block(-7,96,4,1)
Block(-7,96,5,1)
Block(-7,96,6,1)
Block(-7,97,-7,1)
Block(-7,97,-6,1)
Block(-7,97,-5,1)
Block(-7,97,-4,1)
Block(-7,97,-3,1)
Block(-7,97,-2,1)
Block(-7,97,-1,1)
Block(-7,97,0,1)
Block(-7,97,1,1)
Block(-7,97,2,1)
Block(-7,97,3,1)
Block(-7,97,4,1)
Block(-7,97,5,1)
Block(-7,97,6,1)
Block(-7,98,-7,1)
Block(-7,98,-6,1)
Block(-7,98,-5,1)
Block(-7,98,-4,1)
Block(-7,98,-3,1)
Block(-7,98,-2,1)
Block(-7,98,-1,1)
Block(-7,98,0,1)
Block(-7,98,1,1)
Block(-7,98,2,1)
Block(-7,98,3,1)
Block(-7,98,4,1)
Block(-7,98,5,3)
Block(-7,98,6,1)
Block(-7,99,-7,1)
Block(-7,99,-6,1)
Block(-7,99,-5,1)
Block(-7,99,-4,1)
Block(-7,99,-3,1)
Block(-7,99,-2,1)
Block(-7,99,-1,1)
Block(-7,99,0,1)
Block(-7,99,1,1)
Block(-7,99,2,1)
Block(-7,99,3,1)
Block(-7,99,4,1)
Block(-7,99,5,1)
Block(-7,100,-6,1)
Block(-7,100,-5,1)
Block(-7,100,-4,1)
Block(-7,100,-3,1)
Block(-7,100,-2,1)
Block(-7,100,-1,1)
Block(-7,100,0,1)
Block(-7,100,1,1)
Block(-7,100,2,1)
Block(-7,100,3,1)
Block(-7,100,4,1)
Block(-7,100,5,1)
Block(-7,101,-6,1)
Block(-7,101,-5,3)
Block(-7,101,-4,3)
Block(-7,101,-3,1)
Block(-7,101,-2,1)
Block(-7,101,-1,1)
Block(-7,101,0,1)
Block(-7,101,1,1)
Block(-7,101,2,1)
Block(-7,101,3,1)
Block(-7,101,4,3)
Block(-7,101,5,1)
Block(-7,102,-6,1)
Block(-7,102,-5,3)
Block(-7,102,-4,3)
Block(-7,102,-3,3)
Block(-7,102,-2,3)
Block(-7,102,-1,3)
Block(-7,102,0,3)
Block(-7,102,1,1)
Block(-7,102,2,1)
Block(-7,102,3,3)
Block(-7,102,4,1)
Block(-7,103,-6,1)
Block(-7,103,-5,1)
Block(-7,103,-4,1)
Block(-7,103,-3,3)
Block(-7,103,-2,3)
Block(-7,103,-1,3)
Block(-7,103,0,3)
Block(-7,103,1,3)
Block(-7,103,2,3)
Block(-7,103,3,3)
Block(-7,103,4,1)
Block(-7,104,-5,1)
Block(-7,104,-4,1)
Block(-7,104,-3,1)
Block(-7,104,-2,3)
Block(-7,104,-1,3)
Block(-7,104,0,3)
Block(-7,104,1,3)
Block(-7,104,2,3)
Block(-7,104,3,3)
Block(-7,104,4,1)
Block(-7,105,-3,1)
Block(-7,105,-2,2)
Block(-7,105,-1,2)
Block(-7,105,0,2)
Block(-7,105,1,3)
Block(-7,105,2,3)
Block(-7,105,3,1)
Block(-7,106,1,2)
Block(-7,106,2,2)
Block(-6,0,-8,1)
Block(-6,0,-7,1)
Block(-6,0,-6,1)
Block(-6,0,-5,1)
Block(-6,0,-4,1)
Block(-6,0,-3,1)
Block(-6,0,-2,1)
Block(-6,0,-1,1)
Block(-6,0,0,1)
Block(-6,0,1,1)
Block(-6,0,2,1)
Block(-6,0,3,1)
Block(-6,0,4,1)
Block(-6,0,5,1)
Block(-6,0,6,1)
Block(-6,0,7,1)
Block(-6,0,8,1)
Block(-6,1,-8,1)
Block(-6,1,-7,1)
Block(-6,1,-6,1)
Block(-6,1,-5,1)
Block(-6,1,-4,1)
Block(-6,1,-3,1)
Block(-6,1,-2,1)
Block(-6,1,-1,1)
Block(-6,1,0,1)
Block(-6,1,1,1)
Block(-6,1,2,1)
Block(-6,1,3,1)
Block(-6,1,4,1)
Block(-6,1,5,1)
Block(-6,1,6,1)
Block(-6,1,7,1)
Block(-6,1,8,1)
Block(-6,2,-7,1)
Block(-6,2,-6,1)
Block(-6,2,-5,1)
Block(-6,2,-4,1)
Block(-6,2,-3,1)
Block(-6,2,-2,1)
Block(-6,2,-1,1)
Block(-6,2,0,1)
Block(-6,2,1,1)
Block(-6,2,2,1)
Block(-6,2,3,1)
Block(-6,2,4,1)
Block(-6,2,5,1)
Block(-6,2,6,1)
Block(-6,2,7,1)
Block(-6,2,8,1)
Block(-6,2,9,1)
Block(-6,3,-7,1)
Block(-6,3,-6,1)
Block(-6,3,-5,1)
Block(-6,3,-4,1)
Block(-6,3,-3,1)
Block(-6,3,-2,1)
Block(-6,3,-1,1)
Block(-6,3,0,1)
Block(-6,3,1,1)
Block(-6,3,2,1)
Block(-6,3,3,1)
Block(-6,3,4,1)
Block(-6,3,5,1)
Block(-6,3,6,1)
Block(-6,3,7,1)
Block(-6,3,8,1)
Block(-6,3,9,1)
Block(-6,4,-7,1)
Block(-6,4,-6,1)
Block(-6,4,-5,1)
Block(-6,4,-4,1)
Block(-6,4,-3,1)
Block(-6,4,-2,1)
Block(-6,4,-1,1)
Block(-6,4,0,1)
Block(-6,4,1,1)
Block(-6,4,2,1)
Block(-6,4,3,1)
Block(-6,4,4,1)
Block(-6,4,5,1)
Block(-6,4,6,1)
Block(-6,4,7,1)
Block(-6,4,8,1)
Block(-6,5,-7,1)
Block(-6,5,-6,1)
Block(-6,5,-5,1)
Block(-6,5,-4,1)
Block(-6,5,-3,1)
Block(-6,5,-2,1)
Block(-6,5,-1,1)
Block(-6,5,0,1)
Block(-6,5,1,1)
Block(-6,5,2,1)
Block(-6,5,3,1)
Block(-6,5,4,1)
Block(-6,5,5,1)
Block(-6,5,6,1)
Block(-6,5,7,1)
Block(-6,5,8,1)
Block(-6,6,-8,1)
Block(-6,6,-7,1)
Block(-6,6,-6,1)
Block(-6,6,-5,1)
Block(-6,6,-4,1)
Block(-6,6,-3,1)
Block(-6,6,-2,1)
Block(-6,6,-1,1)
Block(-6,6,0,1)
Block(-6,6,1,1)
Block(-6,6,2,1)
Block(-6,6,3,1)
Block(-6,6,4,1)
Block(-6,6,5,1)
Block(-6,6,6,1)
Block(-6,6,7,1)
Block(-6,6,8,1)
Block(-6,7,-8,1)
Block(-6,7,-7,1)
Block(-6,7,-6,1)
Block(-6,7,-5,1)
Block(-6,7,-4,1)
Block(-6,7,-3,1)
Block(-6,7,-2,1)
Block(-6,7,-1,1)
Block(-6,7,0,1)
Block(-6,7,1,1)
Block(-6,7,2,1)
Block(-6,7,3,1)
Block(-6,7,4,1)
Block(-6,7,5,1)
Block(-6,7,6,1)
Block(-6,7,7,1)
Block(-6,7,8,1)
Block(-6,8,-9,1)
Block(-6,8,-8,1)
Block(-6,8,-7,1)
Block(-6,8,-6,1)
Block(-6,8,-5,1)
Block(-6,8,-4,1)
Block(-6,8,-3,1)
Block(-6,8,-2,1)
Block(-6,8,-1,1)
Block(-6,8,0,1)
Block(-6,8,1,1)
Block(-6,8,2,1)
Block(-6,8,3,1)
Block(-6,8,4,1)
Block(-6,8,5,1)
Block(-6,8,6,1)
Block(-6,8,7,1)
Block(-6,8,8,1)
Block(-6,9,-9,1)
Block(-6,9,-8,1)
Block(-6,9,-7,1)
Block(-6,9,-6,1)
Block(-6,9,-5,1)
Block(-6,9,-4,1)
Block(-6,9,-3,1)
Block(-6,9,-2,1)
Block(-6,9,-1,1)
Block(-6,9,0,1)
Block(-6,9,1,1)
Block(-6,9,2,1)
Block(-6,9,3,1)
Block(-6,9,4,1)
Block(-6,9,5,1)
Block(-6,9,6,1)
Block(-6,9,7,1)
Block(-6,9,8,1)
Block(-6,10,-9,1)
Block(-6,10,-8,1)
Block(-6,10,-7,1)
Block(-6,10,-6,1)
Block(-6,10,-5,1)
Block(-6,10,-4,1)
Block(-6,10,-3,1)
Block(-6,10,-2,1)
Block(-6,10,-1,1)
Block(-6,10,0,1)
Block(-6,10,1,1)
Block(-6,10,2,1)
Block(-6,10,3,1)
Block(-6,10,4,1)
Block(-6,10,5,1)
Block(-6,10,6,1)
Block(-6,10,7,1)
Block(-6,10,8,1)
Block(-6,10,9,1)
Block(-6,11,-8,1)
Block(-6,11,-7,1)
Block(-6,11,-6,1)
Block(-6,11,-5,1)
Block(-6,11,-4,1)
Block(-6,11,-3,1)
Block(-6,11,-2,1)
Block(-6,11,-1,1)
Block(-6,11,0,1)
Block(-6,11,1,1)
Block(-6,11,2,1)
Block(-6,11,3,1)
Block(-6,11,4,1)
Block(-6,11,5,1)
Block(-6,11,6,1)
Block(-6,11,7,1)
Block(-6,11,8,1)
Block(-6,11,9,1)
Block(-6,12,-8,1)
Block(-6,12,-7,1)
Block(-6,12,-6,1)
Block(-6,12,-5,1)
Block(-6,12,-4,1)
Block(-6,12,-3,1)
Block(-6,12,-2,1)
Block(-6,12,-1,1)
Block(-6,12,0,1)
Block(-6,12,1,1)
Block(-6,12,2,1)
Block(-6,12,3,1)
Block(-6,12,4,1)
Block(-6,12,5,1)
Block(-6,12,6,1)
Block(-6,12,7,1)
Block(-6,12,8,1)
Block(-6,12,9,1)
Block(-6,13,-8,1)
Block(-6,13,-7,1)
Block(-6,13,-6,1)
Block(-6,13,-5,1)
Block(-6,13,-4,1)
Block(-6,13,-3,1)
Block(-6,13,-2,1)
Block(-6,13,-1,1)
Block(-6,13,0,1)
Block(-6,13,1,1)
Block(-6,13,2,1)
Block(-6,13,3,1)
Block(-6,13,4,1)
Block(-6,13,5,1)
Block(-6,13,6,1)
Block(-6,13,7,1)
Block(-6,13,8,1)
Block(-6,13,9,1)
Block(-6,14,-7,1)
Block(-6,14,-6,1)
Block(-6,14,-5,1)
Block(-6,14,-4,1)
Block(-6,14,-3,1)
Block(-6,14,-2,1)
Block(-6,14,-1,1)
Block(-6,14,0,1)
Block(-6,14,1,1)
Block(-6,14,2,1)
Block(-6,14,3,1)
Block(-6,14,4,1)
Block(-6,14,5,1)
Block(-6,14,6,1)
Block(-6,14,7,1)
Block(-6,14,8,1)
Block(-6,14,9,1)
Block(-6,15,-7,1)
Block(-6,15,-6,1)
Block(-6,15,-5,1)
Block(-6,15,-4,1)
Block(-6,15,-3,1)
Block(-6,15,-2,1)
Block(-6,15,-1,1)
Block(-6,15,0,1)
Block(-6,15,1,1)
Block(-6,15,2,1)
Block(-6,15,3,1)
Block(-6,15,4,1)
Block(-6,15,5,1)
Block(-6,15,6,1)
Block(-6,15,7,1)
Block(-6,15,8,1)
Block(-6,15,9,1)
Block(-6,16,-7,1)
Block(-6,16,-6,1)
Block(-6,16,-5,1)
Block(-6,16,-4,1)
Block(-6,16,-3,1)
Block(-6,16,-2,1)
Block(-6,16,-1,1)
Block(-6,16,0,1)
Block(-6,16,1,1)
Block(-6,16,2,1)
Block(-6,16,3,1)
Block(-6,16,4,1)
Block(-6,16,5,1)
Block(-6,16,6,1)
Block(-6,16,7,1)
Block(-6,16,8,1)
Block(-6,16,9,1)
Block(-6,17,-6,1)
Block(-6,17,-5,1)
Block(-6,17,-4,1)
Block(-6,17,-3,1)
Block(-6,17,-2,1)
Block(-6,17,-1,1)
Block(-6,17,0,1)
Block(-6,17,1,1)
Block(-6,17,2,1)
Block(-6,17,3,1)
Block(-6,17,4,1)
Block(-6,17,5,1)
Block(-6,17,6,1)
Block(-6,17,7,1)
Block(-6,17,8,1)
Block(-6,17,9,1)
Block(-6,18,-6,1)
Block(-6,18,-5,1)
Block(-6,18,-4,1)
Block(-6,18,-3,1)
Block(-6,18,-2,1)
Block(-6,18,-1,1)
Block(-6,18,0,1)
Block(-6,18,1,1)
Block(-6,18,2,1)
Block(-6,18,3,1)
Block(-6,18,4,1)
Block(-6,18,5,1)
Block(-6,18,6,1)
Block(-6,18,7,1)
Block(-6,18,8,1)
Block(-6,18,9,1)
Block(-6,19,-7,1)
Block(-6,19,-6,1)
Block(-6,19,-5,1)
Block(-6,19,-4,1)
Block(-6,19,-3,1)
Block(-6,19,-2,1)
Block(-6,19,-1,1)
Block(-6,19,0,1)
Block(-6,19,1,1)
Block(-6,19,2,1)
Block(-6,19,3,1)
Block(-6,19,4,1)
Block(-6,19,5,1)
Block(-6,19,6,1)
Block(-6,19,7,1)
Block(-6,19,8,1)
Block(-6,19,9,1)
Block(-6,19,10,1)
Block(-6,20,-7,1)
Block(-6,20,-6,1)
Block(-6,20,-5,1)
Block(-6,20,-4,1)
Block(-6,20,-3,1)
Block(-6,20,-2,1)
Block(-6,20,-1,1)
Block(-6,20,0,1)
Block(-6,20,1,1)
Block(-6,20,2,1)
Block(-6,20,3,1)
Block(-6,20,4,1)
Block(-6,20,5,1)
Block(-6,20,6,1)
Block(-6,20,7,1)
Block(-6,20,8,1)
Block(-6,20,9,1)
Block(-6,20,10,1)
Block(-6,21,-8,1)
Block(-6,21,-7,1)
Block(-6,21,-6,1)
Block(-6,21,-5,1)
Block(-6,21,-4,1)
Block(-6,21,-3,1)
Block(-6,21,-2,1)
Block(-6,21,-1,1)
Block(-6,21,0,1)
Block(-6,21,1,1)
Block(-6,21,2,1)
Block(-6,21,3,1)
Block(-6,21,4,1)
Block(-6,21,5,1)
Block(-6,21,6,1)
Block(-6,21,7,1)
Block(-6,21,8,1)
Block(-6,21,9,1)
Block(-6,21,10,1)
Block(-6,22,-8,1)
Block(-6,22,-7,1)
Block(-6,22,-6,1)
Block(-6,22,-5,1)
Block(-6,22,-4,1)
Block(-6,22,-3,1)
Block(-6,22,-2,1)
Block(-6,22,-1,1)
Block(-6,22,0,1)
Block(-6,22,1,1)
Block(-6,22,2,1)
Block(-6,22,3,1)
Block(-6,22,4,1)
Block(-6,22,5,1)
Block(-6,22,6,1)
Block(-6,22,7,1)
Block(-6,22,8,1)
Block(-6,22,9,1)
Block(-6,22,10,1)
Block(-6,22,11,1)
Block(-6,23,-7,1)
Block(-6,23,-6,1)
Block(-6,23,-5,1)
Block(-6,23,-4,1)
Block(-6,23,-3,1)
Block(-6,23,-2,1)
Block(-6,23,-1,1)
Block(-6,23,0,1)
Block(-6,23,1,1)
Block(-6,23,2,1)
Block(-6,23,3,1)
Block(-6,23,4,1)
Block(-6,23,5,1)
Block(-6,23,6,1)
Block(-6,23,7,1)
Block(-6,23,8,1)
Block(-6,23,9,1)
Block(-6,23,10,1)
Block(-6,24,-7,1)
Block(-6,24,-6,1)
Block(-6,24,-5,1)
Block(-6,24,-4,1)
Block(-6,24,-3,1)
Block(-6,24,-2,1)
Block(-6,24,-1,1)
Block(-6,24,0,1)
Block(-6,24,1,1)
Block(-6,24,2,1)
Block(-6,24,3,1)
Block(-6,24,4,1)
Block(-6,24,5,1)
Block(-6,24,6,1)
Block(-6,24,7,1)
Block(-6,24,8,1)
Block(-6,24,9,1)
Block(-6,24,10,1)
Block(-6,25,-6,1)
Block(-6,25,-5,1)
Block(-6,25,-4,1)
Block(-6,25,-3,1)
Block(-6,25,-2,1)
Block(-6,25,-1,1)
Block(-6,25,0,1)
Block(-6,25,1,1)
Block(-6,25,2,1)
Block(-6,25,3,1)
Block(-6,25,4,1)
Block(-6,25,5,1)
Block(-6,25,6,1)
Block(-6,25,7,1)
Block(-6,25,8,1)
Block(-6,25,9,1)
Block(-6,26,-7,1)
Block(-6,26,-6,1)
Block(-6,26,-5,1)
Block(-6,26,-4,1)
Block(-6,26,-3,1)
Block(-6,26,-2,1)
Block(-6,26,-1,1)
Block(-6,26,0,1)
Block(-6,26,1,1)
Block(-6,26,2,1)
Block(-6,26,3,1)
Block(-6,26,4,1)
Block(-6,26,5,1)
Block(-6,26,6,1)
Block(-6,26,7,1)
Block(-6,26,8,1)
Block(-6,27,-8,1)
Block(-6,27,-7,1)
Block(-6,27,-6,1)
Block(-6,27,-5,1)
Block(-6,27,-4,1)
Block(-6,27,-3,1)
Block(-6,27,-2,1)
Block(-6,27,-1,1)
Block(-6,27,0,1)
Block(-6,27,1,1)
Block(-6,27,2,1)
Block(-6,27,3,1)
Block(-6,27,4,1)
Block(-6,27,5,1)
Block(-6,27,6,1)
Block(-6,27,7,1)
Block(-6,28,-8,1)
Block(-6,28,-7,1)
Block(-6,28,-6,1)
Block(-6,28,-5,1)
Block(-6,28,-4,1)
Block(-6,28,-3,1)
Block(-6,28,-2,1)
Block(-6,28,-1,1)
Block(-6,28,0,1)
Block(-6,28,1,1)
Block(-6,28,2,1)
Block(-6,28,3,1)
Block(-6,28,4,1)
Block(-6,28,5,1)
Block(-6,28,6,1)
Block(-6,28,7,1)
Block(-6,29,-8,1)
Block(-6,29,-7,1)
Block(-6,29,-6,1)
Block(-6,29,-5,1)
Block(-6,29,-4,1)
Block(-6,29,-3,1)
Block(-6,29,-2,1)
Block(-6,29,-1,1)
Block(-6,29,0,1)
Block(-6,29,1,1)
Block(-6,29,2,1)
Block(-6,29,3,1)
Block(-6,29,4,1)
Block(-6,29,5,1)
Block(-6,29,6,1)
Block(-6,29,7,1)
Block(-6,29,8,1)
Block(-6,30,-8,1)
Block(-6,30,-7,1)
Block(-6,30,-6,1)
Block(-6,30,-5,1)
Block(-6,30,-4,1)
Block(-6,30,-3,1)
Block(-6,30,-2,1)
Block(-6,30,-1,1)
Block(-6,30,0,1)
Block(-6,30,1,1)
Block(-6,30,2,1)
Block(-6,30,3,1)
Block(-6,30,4,1)
Block(-6,30,5,1)
Block(-6,30,6,1)
Block(-6,30,7,1)
Block(-6,30,8,1)
Block(-6,30,9,1)
Block(-6,31,-8,1)
Block(-6,31,-7,1)
Block(-6,31,-6,1)
Block(-6,31,-5,1)
Block(-6,31,-4,1)
Block(-6,31,-3,1)
Block(-6,31,-2,1)
Block(-6,31,-1,1)
Block(-6,31,0,1)
Block(-6,31,1,1)
Block(-6,31,2,1)
Block(-6,31,3,1)
Block(-6,31,4,1)
Block(-6,31,5,1)
Block(-6,31,6,1)
Block(-6,31,7,1)
Block(-6,31,8,1)
Block(-6,31,9,1)
Block(-6,32,-7,1)
Block(-6,32,-6,1)
Block(-6,32,-5,1)
Block(-6,32,-4,1)
Block(-6,32,-3,1)
Block(-6,32,-2,1)
Block(-6,32,-1,1)
Block(-6,32,0,1)
Block(-6,32,1,1)
Block(-6,32,2,1)
Block(-6,32,3,1)
Block(-6,32,4,1)
Block(-6,32,5,1)
Block(-6,32,6,1)
Block(-6,32,7,1)
Block(-6,32,8,1)
Block(-6,32,9,1)
Block(-6,32,10,1)
Block(-6,33,-7,1)
Block(-6,33,-6,1)
Block(-6,33,-5,1)
Block(-6,33,-4,1)
Block(-6,33,-3,1)
Block(-6,33,-2,1)
Block(-6,33,-1,1)
Block(-6,33,0,1)
Block(-6,33,1,1)
Block(-6,33,2,1)
Block(-6,33,3,1)
Block(-6,33,4,1)
Block(-6,33,5,1)
Block(-6,33,6,1)
Block(-6,33,7,1)
Block(-6,33,8,1)
Block(-6,33,9,1)
Block(-6,33,10,1)
Block(-6,34,-7,1)
Block(-6,34,-6,1)
Block(-6,34,-5,1)
Block(-6,34,-4,1)
Block(-6,34,-3,1)
Block(-6,34,-2,1)
Block(-6,34,-1,1)
Block(-6,34,0,1)
Block(-6,34,1,1)
Block(-6,34,2,1)
Block(-6,34,3,1)
Block(-6,34,4,1)
Block(-6,34,5,1)
Block(-6,34,6,1)
Block(-6,34,7,1)
Block(-6,34,8,1)
Block(-6,34,9,1)
Block(-6,35,-6,1)
Block(-6,35,-5,1)
Block(-6,35,-4,1)
Block(-6,35,-3,1)
Block(-6,35,-2,1)
Block(-6,35,-1,1)
Block(-6,35,0,1)
Block(-6,35,1,1)
Block(-6,35,2,1)
Block(-6,35,3,1)
Block(-6,35,4,1)
Block(-6,35,5,1)
Block(-6,35,6,1)
Block(-6,35,7,1)
Block(-6,35,8,1)
Block(-6,36,-7,1)
Block(-6,36,-6,1)
Block(-6,36,-5,1)
Block(-6,36,-4,1)
Block(-6,36,-3,1)
Block(-6,36,-2,1)
Block(-6,36,-1,1)
Block(-6,36,0,1)
Block(-6,36,1,1)
Block(-6,36,2,1)
Block(-6,36,3,1)
Block(-6,36,4,1)
Block(-6,36,5,1)
Block(-6,36,6,1)
Block(-6,36,7,1)
Block(-6,37,-8,1)
Block(-6,37,-7,1)
Block(-6,37,-6,1)
Block(-6,37,-5,1)
Block(-6,37,-4,1)
Block(-6,37,-3,1)
Block(-6,37,-2,1)
Block(-6,37,-1,1)
Block(-6,37,0,1)
Block(-6,37,1,1)
Block(-6,37,2,1)
Block(-6,37,3,1)
Block(-6,37,4,1)
Block(-6,37,5,1)
Block(-6,37,6,1)
Block(-6,38,-8,1)
Block(-6,38,-7,1)
Block(-6,38,-6,1)
Block(-6,38,-5,1)
Block(-6,38,-4,1)
Block(-6,38,-3,1)
Block(-6,38,-2,1)
Block(-6,38,-1,1)
Block(-6,38,0,1)
Block(-6,38,1,1)
Block(-6,38,2,1)
Block(-6,38,3,1)
Block(-6,38,4,1)
Block(-6,38,5,1)
Block(-6,38,6,1)
Block(-6,39,-9,1)
Block(-6,39,-8,1)
Block(-6,39,-7,1)
Block(-6,39,-6,1)
Block(-6,39,-5,1)
Block(-6,39,-4,1)
Block(-6,39,-3,1)
Block(-6,39,-2,1)
Block(-6,39,-1,1)
Block(-6,39,0,1)
Block(-6,39,1,1)
Block(-6,39,2,1)
Block(-6,39,3,1)
Block(-6,39,4,1)
Block(-6,39,5,1)
Block(-6,39,6,1)
Block(-6,39,7,1)
Block(-6,40,-9,1)
Block(-6,40,-8,1)
Block(-6,40,-7,1)
Block(-6,40,-6,1)
Block(-6,40,-5,1)
Block(-6,40,-4,1)
Block(-6,40,-3,1)
Block(-6,40,-2,1)
Block(-6,40,-1,1)
Block(-6,40,0,1)
Block(-6,40,1,1)
Block(-6,40,2,1)
Block(-6,40,3,1)
Block(-6,40,4,1)
Block(-6,40,5,1)
Block(-6,40,6,1)
Block(-6,40,7,1)
Block(-6,40,8,1)
Block(-6,41,-9,1)
Block(-6,41,-8,1)
Block(-6,41,-7,1)
Block(-6,41,-6,1)
Block(-6,41,-5,1)
Block(-6,41,-4,1)
Block(-6,41,-3,1)
Block(-6,41,-2,1)
Block(-6,41,-1,1)
Block(-6,41,0,1)
Block(-6,41,1,1)
Block(-6,41,2,1)
Block(-6,41,3,1)
Block(-6,41,4,1)
Block(-6,41,5,1)
Block(-6,41,6,1)
Block(-6,41,7,1)
Block(-6,41,8,1)
Block(-6,41,9,1)
Block(-6,42,-9,1)
Block(-6,42,-8,1)
Block(-6,42,-7,1)
Block(-6,42,-6,1)
Block(-6,42,-5,1)
Block(-6,42,-4,1)
Block(-6,42,-3,1)
Block(-6,42,-2,1)
Block(-6,42,-1,1)
Block(-6,42,0,1)
Block(-6,42,1,1)
Block(-6,42,2,1)
Block(-6,42,3,1)
Block(-6,42,4,1)
Block(-6,42,5,1)
Block(-6,42,6,1)
Block(-6,42,7,1)
Block(-6,42,8,1)
Block(-6,42,9,1)
Block(-6,43,-8,1)
Block(-6,43,-7,1)
Block(-6,43,-6,1)
Block(-6,43,-5,1)
Block(-6,43,-4,1)
Block(-6,43,-3,1)
Block(-6,43,-2,1)
Block(-6,43,-1,1)
Block(-6,43,0,1)
Block(-6,43,1,1)
Block(-6,43,2,1)
Block(-6,43,3,1)
Block(-6,43,4,1)
Block(-6,43,5,1)
Block(-6,43,6,1)
Block(-6,43,7,1)
Block(-6,43,8,1)
Block(-6,43,9,1)
Block(-6,44,-8,1)
Block(-6,44,-7,1)
Block(-6,44,-6,1)
Block(-6,44,-5,1)
Block(-6,44,-4,1)
Block(-6,44,-3,1)
Block(-6,44,-2,1)
Block(-6,44,-1,1)
Block(-6,44,0,1)
Block(-6,44,1,1)
Block(-6,44,2,1)
Block(-6,44,3,1)
Block(-6,44,4,1)
Block(-6,44,5,1)
Block(-6,44,6,1)
Block(-6,44,7,1)
Block(-6,44,8,1)
Block(-6,44,9,1)
Block(-6,45,-7,1)
Block(-6,45,-6,1)
Block(-6,45,-5,1)
Block(-6,45,-4,1)
Block(-6,45,-3,1)
Block(-6,45,-2,1)
Block(-6,45,-1,1)
Block(-6,45,0,1)
Block(-6,45,1,1)
Block(-6,45,2,1)
Block(-6,45,3,1)
Block(-6,45,4,1)
Block(-6,45,5,1)
Block(-6,45,6,1)
Block(-6,45,7,1)
Block(-6,45,8,1)
Block(-6,45,9,1)
Block(-6,46,-6,1)
Block(-6,46,-5,1)
Block(-6,46,-4,1)
Block(-6,46,-3,1)
Block(-6,46,-2,1)
Block(-6,46,-1,1)
Block(-6,46,0,1)
Block(-6,46,1,1)
Block(-6,46,2,1)
Block(-6,46,3,1)
Block(-6,46,4,1)
Block(-6,46,5,1)
Block(-6,46,6,1)
Block(-6,46,7,1)
Block(-6,46,8,1)
Block(-6,47,-5,1)
Block(-6,47,-4,1)
Block(-6,47,-3,1)
Block(-6,47,-2,1)
Block(-6,47,-1,1)
Block(-6,47,0,1)
Block(-6,47,1,1)
Block(-6,47,2,1)
Block(-6,47,3,1)
Block(-6,47,4,1)
Block(-6,47,5,1)
Block(-6,47,6,1)
Block(-6,47,7,1)
Block(-6,47,8,1)
Block(-6,48,-5,1)
Block(-6,48,-4,1)
Block(-6,48,-3,1)
Block(-6,48,-2,1)
Block(-6,48,-1,1)
Block(-6,48,0,1)
Block(-6,48,1,1)
Block(-6,48,2,1)
Block(-6,48,3,1)
Block(-6,48,4,1)
Block(-6,48,5,1)
Block(-6,48,6,1)
Block(-6,48,7,1)
Block(-6,48,8,1)
Block(-6,49,-6,1)
Block(-6,49,-5,1)
Block(-6,49,-4,1)
Block(-6,49,-3,1)
Block(-6,49,-2,1)
Block(-6,49,-1,1)
Block(-6,49,0,1)
Block(-6,49,1,1)
Block(-6,49,2,1)
Block(-6,49,3,1)
Block(-6,49,4,1)
Block(-6,49,5,1)
Block(-6,49,6,1)
Block(-6,49,7,1)
Block(-6,49,8,1)
Block(-6,49,9,1)
Block(-6,50,-7,1)
Block(-6,50,-6,1)
Block(-6,50,-5,1)
Block(-6,50,-4,1)
Block(-6,50,-3,1)
Block(-6,50,-2,1)
Block(-6,50,-1,1)
Block(-6,50,0,1)
Block(-6,50,1,1)
Block(-6,50,2,1)
Block(-6,50,3,1)
Block(-6,50,4,1)
Block(-6,50,5,1)
Block(-6,50,6,1)
Block(-6,50,7,1)
Block(-6,50,8,1)
Block(-6,50,9,1)
Block(-6,51,-8,1)
Block(-6,51,-7,1)
Block(-6,51,-6,1)
Block(-6,51,-5,1)
Block(-6,51,-4,1)
Block(-6,51,-3,1)
Block(-6,51,-2,1)
Block(-6,51,-1,1)
Block(-6,51,0,1)
Block(-6,51,1,1)
Block(-6,51,2,1)
Block(-6,51,3,1)
Block(-6,51,4,1)
Block(-6,51,5,1)
Block(-6,51,6,1)
Block(-6,51,7,1)
Block(-6,51,8,1)
Block(-6,51,9,1)
Block(-6,52,-9,1)
Block(-6,52,-8,1)
Block(-6,52,-7,1)
Block(-6,52,-6,1)
Block(-6,52,-5,1)
Block(-6,52,-4,1)
Block(-6,52,-3,1)
Block(-6,52,-2,1)
Block(-6,52,-1,1)
Block(-6,52,0,1)
Block(-6,52,1,1)
Block(-6,52,2,1)
Block(-6,52,3,1)
Block(-6,52,4,1)
Block(-6,52,5,1)
Block(-6,52,6,1)
Block(-6,52,7,1)
Block(-6,52,8,1)
Block(-6,52,9,1)
Block(-6,53,-9,1)
Block(-6,53,-8,1)
Block(-6,53,-7,1)
Block(-6,53,-6,1)
Block(-6,53,-5,1)
Block(-6,53,-4,1)
Block(-6,53,-3,1)
Block(-6,53,-2,1)
Block(-6,53,-1,1)
Block(-6,53,0,1)
