#######################################################################
# +-----------------------------------------------------------------+ #
# |                            BO3 object                           | #
# +-----------------------------------------------------------------+ #
#######################################################################

# The descriptions in this file are accurate only for TerrainControl and OTG.
# For MCW and OTG+ these descriptions are only accurate if the BO3 is used as a CustomObject.
# MCW and OTG+ completely reimplemented CustomStructure, check the MCW/OTG+ documentation for more information.

# This is the config file of a custom object.
# If you add this object correctly to your BiomeConfigs, it will spawn in the world.

# This is the creator of this BO3 object
Author: Unknown

# A short description of this BO3 object
Description: This BO3 was converted from a schematic using OTGEdit. The author and description information of the schematic could not be found. If you know who the author of the schematic is then please add this information.

# The BO3 version, don't change this! It can be used by external applications to do a version check.
Version: 3

# The settings mode, WriteAll, WriteWithoutComments or WriteDisable. See WorldConfig.
SettingsMode: WriteDisable

#######################################################################
# +-----------------------------------------------------------------+ #
# |                          Main settings                          | #
# +-----------------------------------------------------------------+ #
#######################################################################

# This needs to be set to true to spawn the object in the Tree and Sapling resources.
Tree: false

# The frequency of the BO3 from 1 to 200. Tries this many times to spawn this BO3 when using the CustomObject(...) resource.
# Ignored by Tree(..), Sapling(..) and CustomStructure(..)
Frequency: 40

# The rarity of the BO3 from 0 to 100. Each spawn attempt has rarity% chance to succeed when using the CustomObject(...) resource.
# Ignored by Tree(..), Sapling(..) and CustomStructure(..)
Rarity: 100.0

# If you set this to true, the BO3 will be placed with a random rotation.
RotateRandomly: false

# The spawn height of the BO3 - randomY, highestBlock or highestSolidBlock.
SpawnHeight: highestBlock

# The height limits for the BO3.
MinHeight: 0

MaxHeight: 256

# Objects can have other objects attached to it: branches. Branches can also
# have branches attached to it, which can also have branches, etc. This is the
# maximum branch depth for this objects.
MaxBranchDepth: 10

# When spawned with the UseWorld keyword, this BO3 should NOT spawn in the following biomes.
# If you writer.write the BO3 name directly in the BiomeConfigs, this will be ignored.
ExcludedBiomes: All

# To optimise this BO3 for faster loading times you can use Notepad++ to find/replace comments and abbreviate things.
# Notepad++ find/replace with regex:
# Find: ^[#;].* replace to nothing removes all lines starting with # 
# Find: ^\s*$ replace to nothing removes most empty lines 
# Notepad++ find/replace without regex:
# *Warning: This will only work for OTG 1.10.2 v21 / OTG 1.11.2 v6 or higher. B( is not recognised by lower versions.
# Find: Block( replace to B(

#######################################################################
# +-----------------------------------------------------------------+ #
# |                      Source block settings                      | #
# +-----------------------------------------------------------------+ #
#######################################################################

# The block(s) the BO3 should spawn in.
SourceBlocks: AIR

# The maximum percentage of the BO3 that can be outside the SourceBlock.
# The BO3 won't be placed on a location with more blocks outside the SourceBlock than this percentage.
MaxPercentageOutsideSourceBlock: 100

# What to do when a block is about to be placed outside the SourceBlock? (dontPlace, placeAnyway)
OutsideSourceBlock: placeAnyway

#######################################################################
# +-----------------------------------------------------------------+ #
# |                              Blocks                             | #
# +-----------------------------------------------------------------+ #
#######################################################################

# All the blocks used in the BO3 are listed here. Possible blocks:
# Block(x,y,z,id[.data][,nbtfile.nbt) or B(x,y,z,id[.data][,nbtfile.nbt)
# RandomBlock(x,y,z,id[:data][,nbtfile.nbt],chance[,id[:data][,nbtfile.nbt],chance[,...]])
# So RandomBlock(0,0,0,CHEST,chest.nbt,50,CHEST,anotherchest.nbt,100) will spawn a chest at
# the BO3 origin, and give it a 50% chance to have the contents of chest.nbt, or, if that
# fails, a 100% percent chance to have the contents of anotherchest.nbt.

Block(-9,6,3,1)
Block(-9,6,4,1)
Block(-9,6,5,1)
Block(-9,7,1,1)
Block(-9,7,2,1)
Block(-9,7,3,1)
Block(-9,7,4,1)
Block(-9,7,5,1)
Block(-9,8,1,1)
Block(-9,8,2,1)
Block(-9,8,3,1)
Block(-9,8,4,1)
Block(-9,8,5,1)
Block(-9,9,1,1)
Block(-9,9,2,1)
Block(-9,9,3,1)
Block(-9,9,4,1)
Block(-9,9,5,1)
Block(-9,10,1,1)
Block(-9,10,2,1)
Block(-9,10,3,1)
Block(-9,10,4,1)
Block(-9,11,2,1)
Block(-9,11,3,1)
Block(-9,11,4,1)
Block(-9,12,2,1)
Block(-9,12,3,1)
Block(-9,13,2,1)
Block(-9,13,3,1)
Block(-9,15,0,1)
Block(-9,16,0,1)
Block(-9,17,0,1)
Block(-9,17,1,1)
Block(-9,18,0,1)
Block(-9,18,1,1)
Block(-9,19,0,1)
Block(-9,19,1,1)
Block(-9,20,0,1)
Block(-9,20,1,1)
Block(-9,20,2,1)
Block(-9,21,0,1)
Block(-9,21,1,1)
Block(-9,21,2,1)
Block(-9,22,0,1)
Block(-9,22,1,1)
Block(-9,22,2,1)
Block(-9,22,3,1)
Block(-9,23,0,1)
Block(-9,23,1,1)
Block(-9,23,2,1)
Block(-9,23,3,1)
Block(-9,24,1,1)
Block(-9,24,2,1)
Block(-9,28,7,1)
Block(-9,29,6,1)
Block(-9,29,7,1)
Block(-9,29,8,1)
Block(-9,30,6,1)
Block(-9,30,7,1)
Block(-9,84,3,1)
Block(-9,84,4,1)
Block(-9,84,5,1)
Block(-9,84,6,1)
Block(-9,84,7,1)
Block(-9,85,3,1)
Block(-9,85,4,1)
Block(-9,85,5,1)
Block(-9,85,6,1)
Block(-9,85,7,1)
Block(-9,86,3,1)
Block(-9,86,4,1)
Block(-9,86,5,1)
Block(-9,86,6,1)
Block(-9,86,7,1)
Block(-9,87,4,1)
Block(-9,87,5,1)
Block(-8,0,2,1)
Block(-8,0,3,1)
Block(-8,0,4,1)
Block(-8,0,5,1)
Block(-8,5,4,1)
Block(-8,5,5,1)
Block(-8,5,6,1)
Block(-8,5,7,1)
Block(-8,6,-1,1)
Block(-8,6,0,1)
Block(-8,6,1,1)
Block(-8,6,2,1)
Block(-8,6,3,1)
Block(-8,6,4,1)
Block(-8,6,5,1)
Block(-8,6,6,1)
Block(-8,6,7,1)
Block(-8,7,-2,1)
Block(-8,7,-1,1)
Block(-8,7,0,1)
Block(-8,7,1,1)
Block(-8,7,2,1)
Block(-8,7,3,1)
Block(-8,7,4,1)
Block(-8,7,5,1)
Block(-8,7,6,1)
Block(-8,7,7,1)
Block(-8,8,-2,1)
Block(-8,8,-1,1)
Block(-8,8,0,1)
Block(-8,8,1,1)
Block(-8,8,2,1)
Block(-8,8,3,1)
Block(-8,8,4,1)
Block(-8,8,5,1)
Block(-8,8,6,1)
Block(-8,8,7,1)
Block(-8,9,-1,1)
Block(-8,9,0,1)
Block(-8,9,1,1)
Block(-8,9,2,1)
Block(-8,9,3,1)
Block(-8,9,4,1)
Block(-8,9,5,1)
Block(-8,9,6,1)
Block(-8,9,7,1)
Block(-8,10,-1,1)
Block(-8,10,0,1)
Block(-8,10,1,1)
Block(-8,10,2,1)
Block(-8,10,3,1)
Block(-8,10,4,1)
Block(-8,10,5,1)
Block(-8,10,6,1)
Block(-8,11,-1,1)
Block(-8,11,0,1)
Block(-8,11,1,1)
Block(-8,11,2,1)
Block(-8,11,3,1)
Block(-8,11,4,1)
Block(-8,11,5,1)
Block(-8,12,-2,1)
Block(-8,12,-1,1)
Block(-8,12,0,1)
Block(-8,12,1,1)
Block(-8,12,2,1)
Block(-8,12,3,1)
Block(-8,12,4,1)
Block(-8,12,5,1)
Block(-8,13,-2,1)
Block(-8,13,-1,1)
Block(-8,13,0,1)
Block(-8,13,1,1)
Block(-8,13,2,1)
Block(-8,13,3,1)
Block(-8,13,4,1)
Block(-8,13,5,1)
Block(-8,14,-2,1)
Block(-8,14,-1,1)
Block(-8,14,0,1)
Block(-8,14,1,1)
Block(-8,14,2,1)
Block(-8,14,3,1)
Block(-8,14,4,1)
Block(-8,14,5,1)
Block(-8,15,-1,1)
Block(-8,15,0,1)
Block(-8,15,1,1)
Block(-8,15,2,1)
Block(-8,15,3,1)
Block(-8,15,4,1)
Block(-8,16,-1,1)
Block(-8,16,0,1)
Block(-8,16,1,1)
Block(-8,16,2,1)
Block(-8,16,3,1)
Block(-8,16,4,1)
Block(-8,17,-1,1)
Block(-8,17,0,1)
Block(-8,17,1,1)
Block(-8,17,2,1)
Block(-8,17,3,1)
Block(-8,17,4,1)
Block(-8,18,-1,1)
Block(-8,18,0,1)
Block(-8,18,1,1)
Block(-8,18,2,1)
Block(-8,18,3,1)
Block(-8,18,4,1)
Block(-8,19,-1,1)
Block(-8,19,0,1)
Block(-8,19,1,1)
Block(-8,19,2,1)
Block(-8,19,3,1)
Block(-8,19,4,1)
Block(-8,20,-1,1)
Block(-8,20,0,1)
Block(-8,20,1,1)
Block(-8,20,2,1)
Block(-8,20,3,1)
Block(-8,20,4,1)
Block(-8,20,5,1)
Block(-8,21,-1,1)
Block(-8,21,0,1)
Block(-8,21,1,1)
Block(-8,21,2,1)
Block(-8,21,3,1)
Block(-8,21,4,1)
Block(-8,21,5,1)
Block(-8,22,-1,1)
Block(-8,22,0,1)
Block(-8,22,1,1)
Block(-8,22,2,1)
Block(-8,22,3,1)
Block(-8,22,4,1)
Block(-8,22,5,1)
Block(-8,22,6,1)
Block(-8,23,-1,1)
Block(-8,23,0,1)
Block(-8,23,1,1)
Block(-8,23,2,1)
Block(-8,23,3,1)
Block(-8,23,4,1)
Block(-8,23,5,1)
Block(-8,23,6,1)
Block(-8,23,7,1)
Block(-8,24,0,1)
Block(-8,24,1,1)
Block(-8,24,2,1)
Block(-8,24,3,1)
Block(-8,24,4,1)
Block(-8,24,5,1)
Block(-8,24,6,1)
Block(-8,24,7,1)
Block(-8,24,8,1)
Block(-8,25,0,1)
Block(-8,25,1,1)
Block(-8,25,2,1)
Block(-8,25,3,1)
Block(-8,25,4,1)
Block(-8,25,5,1)
Block(-8,25,6,1)
Block(-8,25,7,1)
Block(-8,25,8,1)
Block(-8,26,2,1)
Block(-8,26,3,1)
Block(-8,26,4,1)
Block(-8,26,5,1)
Block(-8,26,6,1)
Block(-8,26,7,1)
Block(-8,26,8,1)
Block(-8,27,3,1)
Block(-8,27,4,1)
Block(-8,27,5,1)
Block(-8,27,6,1)
Block(-8,27,7,1)
Block(-8,27,8,1)
Block(-8,27,9,1)
Block(-8,28,3,1)
Block(-8,28,4,1)
Block(-8,28,5,1)
Block(-8,28,6,1)
Block(-8,28,7,1)
Block(-8,28,8,1)
Block(-8,28,9,1)
Block(-8,29,3,1)
Block(-8,29,4,1)
Block(-8,29,5,1)
Block(-8,29,6,1)
Block(-8,29,7,1)
Block(-8,29,8,1)
Block(-8,29,9,1)
Block(-8,30,3,1)
Block(-8,30,4,1)
Block(-8,30,5,1)
Block(-8,30,6,1)
Block(-8,30,7,1)
Block(-8,30,8,1)
Block(-8,30,9,1)
Block(-8,31,3,1)
Block(-8,31,4,1)
Block(-8,31,5,1)
Block(-8,31,6,1)
Block(-8,31,7,1)
Block(-8,31,8,1)
Block(-8,32,3,1)
Block(-8,32,4,1)
Block(-8,32,5,1)
Block(-8,32,6,1)
Block(-8,32,7,1)
Block(-8,33,4,1)
Block(-8,33,5,1)
Block(-8,33,6,1)
Block(-8,41,7,1)
Block(-8,41,8,1)
Block(-8,42,6,1)
Block(-8,42,7,1)
Block(-8,42,8,1)
Block(-8,42,9,1)
Block(-8,43,6,1)
Block(-8,43,7,1)
Block(-8,43,8,1)
Block(-8,67,2,1)
Block(-8,67,3,1)
Block(-8,68,-2,1)
Block(-8,68,-1,1)
Block(-8,68,0,1)
Block(-8,68,1,1)
Block(-8,68,2,1)
Block(-8,68,3,1)
Block(-8,68,4,1)
Block(-8,69,-3,1)
Block(-8,69,-2,1)
Block(-8,69,-1,1)
Block(-8,69,0,1)
Block(-8,69,1,1)
Block(-8,69,2,1)
Block(-8,69,3,1)
Block(-8,69,4,1)
Block(-8,70,-4,1)
Block(-8,70,-3,1)
Block(-8,70,-2,1)
Block(-8,70,-1,1)
Block(-8,70,0,1)
Block(-8,70,1,1)
Block(-8,70,2,1)
Block(-8,70,3,1)
Block(-8,71,-3,1)
Block(-8,71,-2,1)
Block(-8,71,-1,1)
Block(-8,71,0,1)
Block(-8,71,1,1)
Block(-8,71,2,1)
Block(-8,72,-3,1)
Block(-8,72,-2,1)
Block(-8,72,-1,1)
Block(-8,72,0,1)
Block(-8,72,1,1)
Block(-8,72,2,1)
Block(-8,73,-3,1)
Block(-8,73,-2,1)
Block(-8,73,-1,1)
Block(-8,73,0,1)
Block(-8,73,1,1)
Block(-8,74,-2,1)
Block(-8,74,-1,1)
Block(-8,82,0,1)
Block(-8,82,1,1)
Block(-8,82,2,1)
Block(-8,82,3,1)
Block(-8,82,4,1)
Block(-8,82,5,1)
Block(-8,82,6,1)
Block(-8,82,7,1)
Block(-8,82,8,1)
Block(-8,83,0,1)
Block(-8,83,1,1)
Block(-8,83,2,1)
Block(-8,83,3,1)
Block(-8,83,4,1)
Block(-8,83,5,1)
Block(-8,83,6,1)
Block(-8,83,7,1)
Block(-8,83,8,1)
Block(-8,83,9,1)
Block(-8,84,0,1)
Block(-8,84,1,1)
Block(-8,84,2,1)
Block(-8,84,3,1)
Block(-8,84,4,1)
Block(-8,84,5,1)
Block(-8,84,6,1)
Block(-8,84,7,3)
Block(-8,84,8,1)
Block(-8,84,9,1)
Block(-8,85,1,1)
Block(-8,85,2,1)
Block(-8,85,3,3)
Block(-8,85,4,3)
Block(-8,85,5,3)
Block(-8,85,6,3)
Block(-8,85,7,3)
Block(-8,85,8,1)
Block(-8,85,9,1)
Block(-8,86,1,1)
Block(-8,86,2,1)
Block(-8,86,3,3)
Block(-8,86,4,3)
Block(-8,86,5,3)
Block(-8,86,6,3)
Block(-8,86,7,3)
Block(-8,86,8,1)
Block(-8,87,2,1)
Block(-8,87,3,1)
Block(-8,87,4,3)
Block(-8,87,5,3)
Block(-8,87,6,1)
Block(-8,87,7,1)
Block(-8,87,8,1)
Block(-8,88,3,1)
Block(-8,88,4,1)
Block(-8,88,5,1)
Block(-8,88,6,1)
Block(-7,0,0,1)
Block(-7,0,1,1)
Block(-7,0,2,1)
Block(-7,0,3,1)
Block(-7,0,4,1)
Block(-7,0,5,1)
Block(-7,0,6,1)
Block(-7,1,0,1)
Block(-7,1,1,1)
Block(-7,1,2,1)
Block(-7,1,3,1)
Block(-7,1,4,1)
Block(-7,1,5,1)
Block(-7,2,0,1)
Block(-7,2,1,1)
Block(-7,2,2,1)
Block(-7,2,3,1)
Block(-7,2,4,1)
Block(-7,3,0,1)
Block(-7,3,1,1)
Block(-7,3,2,1)
Block(-7,3,3,1)
Block(-7,4,-1,1)
Block(-7,4,0,1)
Block(-7,4,1,1)
Block(-7,4,2,1)
Block(-7,4,3,1)
Block(-7,4,4,1)
Block(-7,4,5,1)
Block(-7,4,6,1)
Block(-7,4,7,1)
Block(-7,4,8,1)
Block(-7,4,9,1)
Block(-7,5,-2,1)
Block(-7,5,-1,1)
Block(-7,5,0,1)
Block(-7,5,1,1)
Block(-7,5,2,1)
Block(-7,5,3,1)
Block(-7,5,4,1)
Block(-7,5,5,1)
Block(-7,5,6,1)
Block(-7,5,7,1)
Block(-7,5,8,1)
Block(-7,5,9,1)
Block(-7,6,-3,1)
Block(-7,6,-2,1)
Block(-7,6,-1,1)
Block(-7,6,0,1)
Block(-7,6,1,1)
Block(-7,6,2,1)
Block(-7,6,3,1)
Block(-7,6,4,1)
Block(-7,6,5,1)
Block(-7,6,6,1)
Block(-7,6,7,1)
Block(-7,6,8,1)
Block(-7,6,9,1)
Block(-7,7,-3,1)
Block(-7,7,-2,1)
Block(-7,7,-1,1)
Block(-7,7,0,1)
Block(-7,7,1,1)
Block(-7,7,2,1)
Block(-7,7,3,1)
Block(-7,7,4,1)
Block(-7,7,5,1)
Block(-7,7,6,1)
Block(-7,7,7,1)
Block(-7,7,8,1)
Block(-7,7,9,1)
Block(-7,8,-3,1)
Block(-7,8,-2,1)
Block(-7,8,-1,1)
Block(-7,8,0,1)
Block(-7,8,1,1)
Block(-7,8,2,1)
Block(-7,8,3,1)
Block(-7,8,4,1)
Block(-7,8,5,1)
Block(-7,8,6,1)
Block(-7,8,7,1)
Block(-7,8,8,1)
Block(-7,9,-3,1)
Block(-7,9,-2,1)
Block(-7,9,-1,1)
Block(-7,9,0,1)
Block(-7,9,1,1)
Block(-7,9,2,1)
Block(-7,9,3,1)
Block(-7,9,4,1)
Block(-7,9,5,1)
Block(-7,9,6,1)
Block(-7,9,7,1)
Block(-7,9,8,1)
Block(-7,10,-3,1)
Block(-7,10,-2,1)
Block(-7,10,-1,1)
Block(-7,10,0,1)
Block(-7,10,1,1)
Block(-7,10,2,1)
Block(-7,10,3,1)
Block(-7,10,4,1)
Block(-7,10,5,1)
Block(-7,10,6,1)
Block(-7,10,7,1)
Block(-7,10,8,1)
Block(-7,11,-3,1)
Block(-7,11,-2,1)
Block(-7,11,-1,1)
Block(-7,11,0,1)
Block(-7,11,1,1)
Block(-7,11,2,1)
Block(-7,11,3,1)
Block(-7,11,4,1)
Block(-7,11,5,1)
Block(-7,11,6,1)
Block(-7,11,7,1)
Block(-7,12,-3,1)
Block(-7,12,-2,1)
Block(-7,12,-1,1)
Block(-7,12,0,1)
Block(-7,12,1,1)
Block(-7,12,2,1)
Block(-7,12,3,1)
Block(-7,12,4,1)
Block(-7,12,5,1)
Block(-7,12,6,1)
Block(-7,12,7,1)
Block(-7,13,-3,1)
Block(-7,13,-2,1)
Block(-7,13,-1,1)
Block(-7,13,0,1)
Block(-7,13,1,1)
Block(-7,13,2,1)
Block(-7,13,3,1)
Block(-7,13,4,1)
Block(-7,13,5,1)
Block(-7,13,6,1)
Block(-7,14,-3,1)
Block(-7,14,-2,1)
Block(-7,14,-1,1)
Block(-7,14,0,1)
Block(-7,14,1,1)
Block(-7,14,2,1)
Block(-7,14,3,1)
Block(-7,14,4,1)
Block(-7,14,5,1)
Block(-7,14,6,1)
Block(-7,15,-2,1)
Block(-7,15,-1,1)
Block(-7,15,0,1)
Block(-7,15,1,1)
Block(-7,15,2,1)
Block(-7,15,3,1)
Block(-7,15,4,1)
Block(-7,15,5,1)
Block(-7,15,6,1)
Block(-7,16,-2,1)
Block(-7,16,-1,1)
Block(-7,16,0,1)
Block(-7,16,1,1)
Block(-7,16,2,1)
Block(-7,16,3,1)
Block(-7,16,4,1)
Block(-7,16,5,1)
Block(-7,16,6,1)
Block(-7,17,-2,1)
Block(-7,17,-1,1)
Block(-7,17,0,1)
Block(-7,17,1,1)
Block(-7,17,2,1)
Block(-7,17,3,1)
Block(-7,17,4,1)
Block(-7,17,5,1)
Block(-7,17,6,1)
Block(-7,18,-2,1)
Block(-7,18,-1,1)
Block(-7,18,0,1)
Block(-7,18,1,1)
Block(-7,18,2,1)
Block(-7,18,3,1)
Block(-7,18,4,1)
Block(-7,18,5,1)
Block(-7,18,6,1)
Block(-7,18,7,1)
Block(-7,19,-2,1)
Block(-7,19,-1,1)
Block(-7,19,0,1)
Block(-7,19,1,1)
Block(-7,19,2,1)
Block(-7,19,3,1)
Block(-7,19,4,1)
Block(-7,19,5,1)
Block(-7,19,6,1)
Block(-7,19,7,1)
Block(-7,20,-2,1)
Block(-7,20,-1,1)
Block(-7,20,0,1)
Block(-7,20,1,1)
Block(-7,20,2,1)
Block(-7,20,3,1)
Block(-7,20,4,1)
Block(-7,20,5,1)
Block(-7,20,6,1)
Block(-7,20,7,1)
Block(-7,21,-2,1)
Block(-7,21,-1,1)
Block(-7,21,0,1)
Block(-7,21,1,1)
Block(-7,21,2,1)
Block(-7,21,3,1)
Block(-7,21,4,1)
Block(-7,21,5,1)
Block(-7,21,6,1)
Block(-7,21,7,1)
Block(-7,21,8,1)
Block(-7,22,-2,1)
Block(-7,22,-1,1)
Block(-7,22,0,1)
Block(-7,22,1,1)
Block(-7,22,2,1)
Block(-7,22,3,1)
Block(-7,22,4,1)
Block(-7,22,5,1)
Block(-7,22,6,1)
Block(-7,22,7,1)
Block(-7,22,8,1)
Block(-7,22,9,1)
Block(-7,23,-2,1)
Block(-7,23,-1,1)
Block(-7,23,0,1)
Block(-7,23,1,1)
Block(-7,23,2,1)
Block(-7,23,3,1)
Block(-7,23,4,1)
Block(-7,23,5,1)
Block(-7,23,6,1)
Block(-7,23,7,1)
Block(-7,23,8,1)
Block(-7,23,9,1)
Block(-7,24,-1,1)
Block(-7,24,0,1)
Block(-7,24,1,1)
Block(-7,24,2,1)
Block(-7,24,3,1)
Block(-7,24,4,1)
Block(-7,24,5,1)
Block(-7,24,6,1)
Block(-7,24,7,1)
Block(-7,24,8,1)
Block(-7,24,9,1)
Block(-7,25,-1,1)
Block(-7,25,0,1)
Block(-7,25,1,1)
Block(-7,25,2,1)
Block(-7,25,3,1)
Block(-7,25,4,1)
Block(-7,25,5,1)
Block(-7,25,6,1)
Block(-7,25,7,1)
Block(-7,25,8,1)
Block(-7,25,9,1)
Block(-7,25,10,1)
Block(-7,26,-1,1)
Block(-7,26,0,1)
Block(-7,26,1,1)
Block(-7,26,2,1)
Block(-7,26,3,1)
Block(-7,26,4,1)
Block(-7,26,5,1)
Block(-7,26,6,1)
Block(-7,26,7,1)
Block(-7,26,8,1)
Block(-7,26,9,1)
Block(-7,26,10,1)
Block(-7,27,0,1)
Block(-7,27,1,1)
Block(-7,27,2,1)
Block(-7,27,3,1)
Block(-7,27,4,1)
Block(-7,27,5,1)
Block(-7,27,6,1)
Block(-7,27,7,1)
Block(-7,27,8,1)
Block(-7,27,9,1)
Block(-7,27,10,1)
Block(-7,28,1,1)
Block(-7,28,2,1)
Block(-7,28,3,1)
Block(-7,28,4,1)
Block(-7,28,5,1)
Block(-7,28,6,1)
Block(-7,28,7,1)
Block(-7,28,8,1)
Block(-7,28,9,1)
Block(-7,28,10,1)
Block(-7,29,1,1)
Block(-7,29,2,1)
Block(-7,29,3,1)
Block(-7,29,4,1)
Block(-7,29,5,1)
Block(-7,29,6,1)
Block(-7,29,7,1)
Block(-7,29,8,1)
Block(-7,29,9,1)
Block(-7,29,10,1)
Block(-7,30,1,1)
Block(-7,30,2,1)
Block(-7,30,3,1)
Block(-7,30,4,1)
Block(-7,30,5,1)
Block(-7,30,6,1)
Block(-7,30,7,1)
Block(-7,30,8,1)
Block(-7,30,9,1)
Block(-7,30,10,1)
Block(-7,31,0,1)
Block(-7,31,1,1)
Block(-7,31,2,1)
Block(-7,31,3,1)
Block(-7,31,4,1)
Block(-7,31,5,1)
Block(-7,31,6,1)
Block(-7,31,7,1)
Block(-7,31,8,1)
Block(-7,31,9,1)
Block(-7,31,10,1)
Block(-7,32,0,1)
Block(-7,32,1,1)
Block(-7,32,2,1)
Block(-7,32,3,1)
Block(-7,32,4,1)
Block(-7,32,5,1)
Block(-7,32,6,1)
Block(-7,32,7,1)
Block(-7,32,8,1)
Block(-7,32,9,1)
Block(-7,33,0,1)
Block(-7,33,1,1)
Block(-7,33,2,1)
Block(-7,33,3,1)
Block(-7,33,4,1)
Block(-7,33,5,1)
Block(-7,33,6,1)
Block(-7,33,7,1)
Block(-7,33,8,1)
Block(-7,34,0,1)
Block(-7,34,1,1)
Block(-7,34,2,1)
Block(-7,34,3,1)
Block(-7,34,4,1)
Block(-7,34,5,1)
Block(-7,34,6,1)
Block(-7,34,7,1)
Block(-7,35,0,1)
Block(-7,35,1,1)
Block(-7,35,2,1)
Block(-7,35,3,1)
Block(-7,35,4,1)
Block(-7,35,5,1)
Block(-7,36,0,1)
Block(-7,36,1,1)
Block(-7,36,2,1)
Block(-7,36,3,1)
Block(-7,36,4,1)
Block(-7,37,1,1)
Block(-7,37,2,1)
Block(-7,37,3,1)
Block(-7,37,4,1)
Block(-7,37,6,1)
Block(-7,37,7,1)
Block(-7,37,8,1)
Block(-7,37,9,1)
Block(-7,38,1,1)
Block(-7,38,2,1)
Block(-7,38,3,1)
Block(-7,38,4,1)
Block(-7,38,5,1)
Block(-7,38,6,1)
Block(-7,38,7,1)
Block(-7,38,8,1)
Block(-7,38,9,1)
Block(-7,38,10,1)
Block(-7,39,1,1)
Block(-7,39,2,1)
Block(-7,39,3,1)
Block(-7,39,4,1)
Block(-7,39,5,1)
Block(-7,39,6,1)
Block(-7,39,7,1)
Block(-7,39,8,1)
Block(-7,39,9,1)
Block(-7,39,10,1)
Block(-7,39,11,1)
Block(-7,40,0,1)
Block(-7,40,1,1)
Block(-7,40,2,1)
Block(-7,40,3,1)
Block(-7,40,4,1)
Block(-7,40,5,1)
Block(-7,40,6,1)
Block(-7,40,7,1)
Block(-7,40,8,1)
Block(-7,40,9,1)
Block(-7,40,10,1)
Block(-7,40,11,1)
Block(-7,41,0,1)
Block(-7,41,1,1)
Block(-7,41,2,1)
Block(-7,41,3,1)
Block(-7,41,4,1)
Block(-7,41,5,1)
Block(-7,41,6,1)
Block(-7,41,7,1)
Block(-7,41,8,1)
Block(-7,41,9,1)
Block(-7,41,10,1)
Block(-7,42,0,1)
Block(-7,42,1,1)
Block(-7,42,2,1)
Block(-7,42,3,1)
Block(-7,42,4,1)
Block(-7,42,5,1)
Block(-7,42,6,1)
Block(-7,42,7,1)
Block(-7,42,8,1)
Block(-7,42,9,1)
Block(-7,42,10,1)
Block(-7,43,0,1)
Block(-7,43,1,1)
Block(-7,43,2,1)
Block(-7,43,3,1)
Block(-7,43,4,1)
Block(-7,43,5,1)
Block(-7,43,6,1)
Block(-7,43,7,1)
Block(-7,43,8,1)
Block(-7,43,9,1)
Block(-7,43,10,1)
Block(-7,44,1,1)
Block(-7,44,2,1)
Block(-7,44,3,1)
Block(-7,44,4,1)
Block(-7,44,5,1)
Block(-7,44,6,1)
Block(-7,44,7,1)
Block(-7,44,8,1)
Block(-7,44,9,1)
Block(-7,45,4,1)
Block(-7,45,5,1)
Block(-7,45,6,1)
Block(-7,45,7,1)
Block(-7,45,8,1)
Block(-7,46,5,1)
Block(-7,46,6,1)
Block(-7,46,7,1)
Block(-7,46,8,1)
Block(-7,47,5,1)
Block(-7,47,6,1)
Block(-7,47,7,1)
Block(-7,47,8,1)
Block(-7,47,9,1)
Block(-7,48,4,1)
Block(-7,48,5,1)
Block(-7,48,6,1)
Block(-7,48,7,1)
Block(-7,48,8,1)
Block(-7,48,9,1)
Block(-7,49,3,1)
Block(-7,49,4,1)
Block(-7,49,5,1)
Block(-7,49,6,1)
Block(-7,49,7,1)
Block(-7,49,8,1)
Block(-7,49,9,1)
Block(-7,50,2,1)
Block(-7,50,3,1)
Block(-7,50,4,1)
Block(-7,50,5,1)
Block(-7,50,6,1)
Block(-7,50,7,1)
Block(-7,50,8,1)
Block(-7,51,2,1)
Block(-7,51,3,1)
Block(-7,51,4,1)
Block(-7,51,5,1)
Block(-7,51,6,1)
Block(-7,51,7,1)
Block(-7,51,8,1)
Block(-7,52,2,1)
Block(-7,52,3,1)
Block(-7,52,4,1)
Block(-7,52,5,1)
Block(-7,52,6,1)
Block(-7,52,7,1)
Block(-7,53,2,1)
Block(-7,53,3,1)
Block(-7,53,4,1)
Block(-7,53,5,1)
Block(-7,53,6,1)
Block(-7,53,7,1)
Block(-7,54,1,1)
Block(-7,54,2,1)
Block(-7,54,3,1)
Block(-7,54,4,1)
Block(-7,54,5,1)
Block(-7,54,6,1)
Block(-7,55,1,1)
Block(-7,55,2,1)
Block(-7,55,3,1)
Block(-7,55,4,1)
Block(-7,55,5,1)
Block(-7,55,6,1)
Block(-7,56,0,1)
Block(-7,56,1,1)
Block(-7,56,2,1)
Block(-7,56,3,1)
Block(-7,56,4,1)
Block(-7,56,5,1)
Block(-7,57,0,1)
Block(-7,57,1,1)
Block(-7,57,2,1)
Block(-7,57,3,1)
Block(-7,57,4,1)
Block(-7,58,-1,1)
Block(-7,58,0,1)
Block(-7,58,1,1)
Block(-7,58,2,1)
Block(-7,58,3,1)
Block(-7,58,4,1)
Block(-7,59,-1,1)
Block(-7,59,0,1)
Block(-7,59,1,1)
Block(-7,59,2,1)
Block(-7,59,3,1)
Block(-7,59,4,1)
Block(-7,60,-1,1)
Block(-7,60,0,1)
Block(-7,60,1,1)
Block(-7,60,2,1)
Block(-7,60,3,1)
Block(-7,60,4,1)
Block(-7,61,-1,1)
Block(-7,61,0,1)
Block(-7,61,1,1)
Block(-7,61,2,1)
Block(-7,61,3,1)
Block(-7,61,4,1)
Block(-7,61,5,1)
Block(-7,62,0,1)
Block(-7,62,1,1)
Block(-7,62,2,1)
Block(-7,62,3,1)
Block(-7,62,4,1)
Block(-7,62,5,1)
Block(-7,62,6,1)
Block(-7,63,1,1)
Block(-7,63,2,1)
Block(-7,63,3,1)
Block(-7,63,4,1)
Block(-7,63,5,1)
Block(-7,63,6,1)
Block(-7,64,2,1)
Block(-7,64,3,1)
Block(-7,64,4,1)
Block(-7,64,5,1)
Block(-7,64,6,1)
Block(-7,64,7,1)
Block(-7,65,2,1)
Block(-7,65,3,1)
Block(-7,65,4,1)
Block(-7,65,5,1)
Block(-7,65,6,1)
Block(-7,65,7,1)
Block(-7,66,1,1)
Block(-7,66,2,1)
Block(-7,66,3,1)
Block(-7,66,4,1)
Block(-7,66,5,1)
Block(-7,66,6,1)
Block(-7,66,7,1)
Block(-7,67,-3,1)
Block(-7,67,-2,1)
Block(-7,67,-1,1)
Block(-7,67,0,1)
Block(-7,67,1,1)
Block(-7,67,2,1)
Block(-7,67,3,1)
Block(-7,67,4,1)
Block(-7,67,5,1)
Block(-7,67,6,1)
Block(-7,67,7,1)
Block(-7,68,-4,1)
Block(-7,68,-3,1)
Block(-7,68,-2,1)
Block(-7,68,-1,1)
Block(-7,68,0,1)
Block(-7,68,1,1)
Block(-7,68,2,1)
Block(-7,68,3,1)
Block(-7,68,4,1)
Block(-7,68,5,1)
Block(-7,68,6,1)
Block(-7,68,7,1)
Block(-7,69,-5,1)
Block(-7,69,-4,1)
Block(-7,69,-3,1)
Block(-7,69,-2,1)
Block(-7,69,-1,1)
Block(-7,69,0,1)
Block(-7,69,1,1)
Block(-7,69,2,1)
Block(-7,69,3,1)
Block(-7,69,4,1)
Block(-7,69,5,1)
Block(-7,69,6,1)
Block(-7,69,7,1)
Block(-7,70,-5,1)
Block(-7,70,-4,1)
Block(-7,70,-3,1)
Block(-7,70,-2,1)
Block(-7,70,-1,1)
Block(-7,70,0,1)
Block(-7,70,1,1)
Block(-7,70,2,1)
Block(-7,70,3,1)
Block(-7,70,4,1)
Block(-7,70,5,1)
Block(-7,70,6,1)
Block(-7,71,-5,1)
Block(-7,71,-4,1)
Block(-7,71,-3,1)
Block(-7,71,-2,1)
Block(-7,71,-1,1)
Block(-7,71,0,1)
Block(-7,71,1,1)
Block(-7,71,2,1)
Block(-7,71,3,1)
Block(-7,71,4,1)
Block(-7,71,5,1)
Block(-7,72,-4,1)
Block(-7,72,-3,3)
Block(-7,72,-2,1)
Block(-7,72,-1,1)
Block(-7,72,0,1)
Block(-7,72,1,1)
Block(-7,72,2,1)
Block(-7,72,3,1)
Block(-7,72,4,1)
Block(-7,73,-4,1)
Block(-7,73,-3,3)
Block(-7,73,-2,1)
Block(-7,73,-1,1)
Block(-7,73,0,1)
Block(-7,73,1,1)
Block(-7,73,2,1)
Block(-7,73,3,1)
Block(-7,74,-4,1)
Block(-7,74,-3,1)
Block(-7,74,-2,1)
Block(-7,74,-1,1)
Block(-7,74,0,1)
Block(-7,74,1,1)
Block(-7,74,2,1)
Block(-7,75,-3,1)
Block(-7,75,-2,1)
Block(-7,75,-1,1)
Block(-7,75,0,1)
Block(-7,76,-2,1)
Block(-7,76,-1,1)
Block(-7,79,4,1)
Block(-7,79,5,1)
Block(-7,79,6,1)
Block(-7,79,7,1)
Block(-7,79,8,1)
Block(-7,79,9,1)
Block(-7,80,-1,1)
Block(-7,80,0,1)
Block(-7,80,1,1)
Block(-7,80,2,1)
Block(-7,80,3,1)
Block(-7,80,4,1)
Block(-7,80,5,1)
Block(-7,80,6,1)
Block(-7,80,7,1)
Block(-7,80,8,1)
Block(-7,80,9,1)
Block(-7,81,-2,1)
Block(-7,81,-1,1)
Block(-7,81,0,1)
Block(-7,81,1,1)
Block(-7,81,2,1)
Block(-7,81,3,1)
Block(-7,81,4,1)
Block(-7,81,5,1)
Block(-7,81,6,1)
Block(-7,81,7,1)
Block(-7,81,8,1)
Block(-7,81,9,1)
Block(-7,81,10,1)
Block(-7,82,-2,1)
Block(-7,82,-1,1)
Block(-7,82,0,1)
Block(-7,82,1,1)
Block(-7,82,2,1)
Block(-7,82,3,1)
Block(-7,82,4,1)
Block(-7,82,5,1)
Block(-7,82,6,1)
Block(-7,82,7,1)
Block(-7,82,8,1)
Block(-7,82,9,1)
Block(-7,82,10,1)
Block(-7,83,-1,1)
Block(-7,83,0,3)
Block(-7,83,1,1)
Block(-7,83,2,1)
Block(-7,83,3,1)
Block(-7,83,4,1)
Block(-7,83,5,1)
Block(-7,83,6,1)
Block(-7,83,7,1)
Block(-7,83,8,1)
Block(-7,83,9,1)
Block(-7,83,10,1)
Block(-7,84,-1,1)
Block(-7,84,0,3)
Block(-7,84,1,3)
Block(-7,84,2,1)
Block(-7,84,3,1)
Block(-7,84,4,1)
Block(-7,84,5,1)
Block(-7,84,6,1)
Block(-7,84,7,1)
Block(-7,84,8,1)
Block(-7,84,9,3)
Block(-7,84,10,1)
Block(-7,85,-1,1)
Block(-7,85,0,1)
Block(-7,85,1,3)
Block(-7,85,2,1)
Block(-7,85,3,1)
Block(-7,85,4,1)
Block(-7,85,5,1)
Block(-7,85,6,1)
Block(-7,85,7,1)
Block(-7,85,8,3)
Block(-7,85,9,3)
Block(-7,85,10,1)
Block(-7,86,0,1)
Block(-7,86,1,3)
Block(-7,86,2,3)
Block(-7,86,3,3)
Block(-7,86,4,1)
Block(-7,86,5,3)
Block(-7,86,6,3)
Block(-7,86,7,3)
Block(-7,86,8,3)
Block(-7,86,9,1)
Block(-7,87,1,1)
Block(-7,87,2,3)
Block(-7,87,3,3)
Block(-7,87,4,3)
Block(-7,87,5,3)
Block(-7,87,6,3)
Block(-7,87,7,3)
Block(-7,87,8,3)
Block(-7,87,9,1)
Block(-7,88,2,1)
Block(-7,88,3,3)
Block(-7,88,4,3)
Block(-7,88,5,3)
Block(-7,88,6,3)
Block(-7,88,7,1)
Block(-7,88,8,1)
Block(-7,89,2,1)
Block(-7,89,3,1)
Block(-7,89,4,1)
Block(-7,89,5,2)
Block(-7,89,6,2)
Block(-7,89,7,1)
Block(-7,90,4,1)
Block(-6,0,-1,1)
Block(-6,0,0,1)
Block(-6,0,1,1)
Block(-6,0,2,1)
Block(-6,0,3,1)
Block(-6,0,4,1)
Block(-6,0,5,1)
Block(-6,0,6,1)
Block(-6,0,7,1)
Block(-6,0,8,1)
Block(-6,0,9,1)
Block(-6,0,10,1)
Block(-6,1,-1,1)
Block(-6,1,0,1)
Block(-6,1,1,1)
Block(-6,1,2,1)
Block(-6,1,3,1)
Block(-6,1,4,1)
Block(-6,1,5,1)
Block(-6,1,6,1)
Block(-6,1,7,1)
Block(-6,1,8,1)
Block(-6,1,9,1)
Block(-6,2,-1,1)
Block(-6,2,0,1)
Block(-6,2,1,1)
Block(-6,2,2,1)
Block(-6,2,3,1)
Block(-6,2,4,1)
Block(-6,2,5,1)
Block(-6,2,6,1)
Block(-6,2,7,1)
Block(-6,2,8,1)
Block(-6,2,9,1)
Block(-6,3,-1,1)
Block(-6,3,0,1)
Block(-6,3,1,1)
Block(-6,3,2,1)
Block(-6,3,3,1)
Block(-6,3,4,1)
Block(-6,3,5,1)
Block(-6,3,6,1)
Block(-6,3,7,1)
Block(-6,3,8,1)
Block(-6,3,9,1)
Block(-6,3,10,1)
Block(-6,3,11,1)
Block(-6,4,-3,1)
Block(-6,4,-2,1)
Block(-6,4,-1,1)
Block(-6,4,0,1)
Block(-6,4,1,1)
Block(-6,4,2,1)
Block(-6,4,3,1)
Block(-6,4,4,1)
Block(-6,4,5,1)
Block(-6,4,6,1)
Block(-6,4,7,1)
Block(-6,4,8,1)
Block(-6,4,9,1)
Block(-6,4,10,1)
Block(-6,4,11,1)
Block(-6,5,-3,1)
Block(-6,5,-2,1)
Block(-6,5,-1,1)
Block(-6,5,0,1)
Block(-6,5,1,1)
Block(-6,5,2,1)
Block(-6,5,3,1)
Block(-6,5,4,1)
Block(-6,5,5,1)
Block(-6,5,6,1)
Block(-6,5,7,1)
Block(-6,5,8,1)
Block(-6,5,9,1)
Block(-6,5,10,1)
Block(-6,5,11,1)
Block(-6,6,-4,1)
Block(-6,6,-3,1)
Block(-6,6,-2,1)
Block(-6,6,-1,1)
Block(-6,6,0,1)
Block(-6,6,1,1)
Block(-6,6,2,1)
Block(-6,6,3,1)
Block(-6,6,4,1)
Block(-6,6,5,1)
Block(-6,6,6,1)
Block(-6,6,7,1)
Block(-6,6,8,1)
Block(-6,6,9,1)
Block(-6,6,10,1)
Block(-6,7,-4,1)
Block(-6,7,-3,1)
Block(-6,7,-2,1)
Block(-6,7,-1,1)
Block(-6,7,0,1)
Block(-6,7,1,1)
Block(-6,7,2,1)
Block(-6,7,3,1)
Block(-6,7,4,1)
Block(-6,7,5,1)
Block(-6,7,6,1)
Block(-6,7,7,1)
Block(-6,7,8,1)
Block(-6,7,9,1)
Block(-6,7,10,1)
Block(-6,8,-4,1)
Block(-6,8,-3,1)
Block(-6,8,-2,1)
Block(-6,8,-1,1)
Block(-6,8,0,1)
Block(-6,8,1,1)
Block(-6,8,2,1)
Block(-6,8,3,1)
Block(-6,8,4,1)
Block(-6,8,5,1)
Block(-6,8,6,1)
Block(-6,8,7,1)
Block(-6,8,8,1)
Block(-6,8,9,1)
Block(-6,8,10,1)
Block(-6,9,-4,1)
Block(-6,9,-3,1)
Block(-6,9,-2,1)
Block(-6,9,-1,1)
Block(-6,9,0,1)
Block(-6,9,1,1)
Block(-6,9,2,1)
Block(-6,9,3,1)
Block(-6,9,4,1)
Block(-6,9,5,1)
Block(-6,9,6,1)
Block(-6,9,7,1)
Block(-6,9,8,1)
Block(-6,9,9,1)
Block(-6,10,-4,1)
Block(-6,10,-3,1)
Block(-6,10,-2,1)
Block(-6,10,-1,1)
Block(-6,10,0,1)
Block(-6,10,1,1)
Block(-6,10,2,1)
Block(-6,10,3,1)
Block(-6,10,4,1)
Block(-6,10,5,1)
Block(-6,10,6,1)
Block(-6,10,7,1)
Block(-6,10,8,1)
Block(-6,10,9,1)
Block(-6,11,-4,1)
Block(-6,11,-3,1)
Block(-6,11,-2,1)
Block(-6,11,-1,1)
Block(-6,11,0,1)
Block(-6,11,1,1)
Block(-6,11,2,1)
Block(-6,11,3,1)
Block(-6,11,4,1)
Block(-6,11,5,1)
Block(-6,11,6,1)
Block(-6,11,7,1)
Block(-6,11,8,1)
Block(-6,11,9,1)
Block(-6,12,-4,1)
Block(-6,12,-3,1)
Block(-6,12,-2,1)
Block(-6,12,-1,1)
Block(-6,12,0,1)
Block(-6,12,1,1)
Block(-6,12,2,1)
Block(-6,12,3,1)
Block(-6,12,4,1)
Block(-6,12,5,1)
Block(-6,12,6,1)
Block(-6,12,7,1)
Block(-6,12,8,1)
Block(-6,13,-4,1)
Block(-6,13,-3,1)
Block(-6,13,-2,1)
Block(-6,13,-1,1)
Block(-6,13,0,1)
Block(-6,13,1,1)
Block(-6,13,2,1)
Block(-6,13,3,1)
Block(-6,13,4,1)
Block(-6,13,5,1)
Block(-6,13,6,1)
Block(-6,13,7,1)
Block(-6,13,8,1)
Block(-6,14,-4,1)
Block(-6,14,-3,1)
Block(-6,14,-2,1)
Block(-6,14,-1,1)
Block(-6,14,0,1)
Block(-6,14,1,1)
Block(-6,14,2,1)
Block(-6,14,3,1)
Block(-6,14,4,1)
Block(-6,14,5,1)
Block(-6,14,6,1)
Block(-6,14,7,1)
Block(-6,14,8,1)
Block(-6,15,-3,1)
Block(-6,15,-2,1)
Block(-6,15,-1,1)
Block(-6,15,0,1)
Block(-6,15,1,1)
Block(-6,15,2,1)
Block(-6,15,3,1)
Block(-6,15,4,1)
Block(-6,15,5,1)
Block(-6,15,6,1)
Block(-6,15,7,1)
Block(-6,15,8,1)
Block(-6,16,-3,1)
Block(-6,16,-2,1)
Block(-6,16,-1,1)
Block(-6,16,0,1)
Block(-6,16,1,1)
Block(-6,16,2,1)
Block(-6,16,3,1)
Block(-6,16,4,1)
Block(-6,16,5,1)
Block(-6,16,6,1)
Block(-6,16,7,1)
Block(-6,16,8,1)
Block(-6,16,9,1)
Block(-6,17,-3,1)
Block(-6,17,-2,1)
Block(-6,17,-1,1)
Block(-6,17,0,1)
Block(-6,17,1,1)
Block(-6,17,2,1)
Block(-6,17,3,1)
Block(-6,17,4,1)
Block(-6,17,5,1)
Block(-6,17,6,1)
Block(-6,17,7,1)
Block(-6,17,8,1)
Block(-6,17,9,1)
Block(-6,18,-3,1)
Block(-6,18,-2,1)
Block(-6,18,-1,1)
Block(-6,18,0,1)
Block(-6,18,1,1)
Block(-6,18,2,1)
Block(-6,18,3,1)
Block(-6,18,4,1)
Block(-6,18,5,1)
Block(-6,18,6,1)
Block(-6,18,7,1)
Block(-6,18,8,1)
Block(-6,18,9,1)
Block(-6,19,-3,1)
Block(-6,19,-2,1)
Block(-6,19,-1,1)
Block(-6,19,0,1)
Block(-6,19,1,1)
Block(-6,19,2,1)
Block(-6,19,3,1)
Block(-6,19,4,1)
Block(-6,19,5,1)
Block(-6,19,6,1)
Block(-6,19,7,1)
Block(-6,19,8,1)
Block(-6,19,9,1)
Block(-6,20,-3,1)
Block(-6,20,-2,1)
Block(-6,20,-1,1)
Block(-6,20,0,1)
Block(-6,20,1,1)
Block(-6,20,2,1)
Block(-6,20,3,1)
Block(-6,20,4,1)
Block(-6,20,5,1)
Block(-6,20,6,1)
Block(-6,20,7,1)
Block(-6,20,8,1)
Block(-6,20,9,1)
Block(-6,20,10,1)
Block(-6,21,-3,1)
Block(-6,21,-2,1)
Block(-6,21,-1,1)
Block(-6,21,0,1)
Block(-6,21,1,1)
Block(-6,21,2,1)
Block(-6,21,3,1)
Block(-6,21,4,1)
Block(-6,21,5,1)
Block(-6,21,6,1)
Block(-6,21,7,1)
Block(-6,21,8,1)
Block(-6,21,9,1)
Block(-6,21,10,1)
Block(-6,21,11,1)
Block(-6,22,-3,1)
Block(-6,22,-2,1)
Block(-6,22,-1,1)
Block(-6,22,0,1)
Block(-6,22,1,1)
Block(-6,22,2,1)
Block(-6,22,3,1)
Block(-6,22,4,1)
Block(-6,22,5,1)
Block(-6,22,6,1)
Block(-6,22,7,1)
Block(-6,22,8,1)
Block(-6,22,9,1)
Block(-6,22,10,1)
Block(-6,22,11,1)
Block(-6,23,-3,1)
Block(-6,23,-2,1)
Block(-6,23,-1,1)
Block(-6,23,0,1)
Block(-6,23,1,1)
Block(-6,23,2,1)
Block(-6,23,3,1)
Block(-6,23,4,1)
Block(-6,23,5,1)
Block(-6,23,6,1)
Block(-6,23,7,1)
Block(-6,23,8,1)
Block(-6,23,9,1)
Block(-6,23,10,1)
Block(-6,23,11,1)
Block(-6,24,-2,1)
Block(-6,24,-1,1)
Block(-6,24,0,1)
Block(-6,24,1,1)
Block(-6,24,2,1)
Block(-6,24,3,1)
Block(-6,24,4,1)
Block(-6,24,5,1)
Block(-6,24,6,1)
Block(-6,24,7,1)
Block(-6,24,8,1)
Block(-6,24,9,1)
Block(-6,24,10,1)
Block(-6,24,11,1)
Block(-6,25,-2,1)
Block(-6,25,-1,1)
Block(-6,25,0,1)
Block(-6,25,1,1)
Block(-6,25,2,1)
Block(-6,25,3,1)
Block(-6,25,4,1)
Block(-6,25,5,1)
Block(-6,25,6,1)
Block(-6,25,7,1)
Block(-6,25,8,1)
Block(-6,25,9,1)
Block(-6,25,10,1)
Block(-6,25,11,1)
Block(-6,26,-2,1)
Block(-6,26,-1,1)
Block(-6,26,0,1)
Block(-6,26,1,1)
Block(-6,26,2,1)
Block(-6,26,3,1)
Block(-6,26,4,1)
Block(-6,26,5,1)
Block(-6,26,6,1)
Block(-6,26,7,1)
Block(-6,26,8,1)
Block(-6,26,9,1)
Block(-6,26,10,1)
Block(-6,26,11,1)
Block(-6,27,-2,1)
Block(-6,27,-1,1)
Block(-6,27,0,1)
Block(-6,27,1,1)
Block(-6,27,2,1)
Block(-6,27,3,1)
Block(-6,27,4,1)
Block(-6,27,5,1)
Block(-6,27,6,1)
Block(-6,27,7,1)
Block(-6,27,8,1)
Block(-6,27,9,1)
Block(-6,27,10,1)
Block(-6,27,11,1)
Block(-6,28,-2,1)
Block(-6,28,-1,1)
Block(-6,28,0,1)
Block(-6,28,1,1)
Block(-6,28,2,1)
Block(-6,28,3,1)
Block(-6,28,4,1)
Block(-6,28,5,1)
Block(-6,28,6,1)
Block(-6,28,7,1)
Block(-6,28,8,1)
Block(-6,28,9,1)
Block(-6,28,10,1)
Block(-6,28,11,1)
Block(-6,29,-2,1)
Block(-6,29,-1,1)
Block(-6,29,0,1)
Block(-6,29,1,1)
Block(-6,29,2,1)
Block(-6,29,3,1)
Block(-6,29,4,1)
Block(-6,29,5,1)
Block(-6,29,6,1)
Block(-6,29,7,1)
Block(-6,29,8,1)
Block(-6,29,9,1)
Block(-6,29,10,1)
Block(-6,29,11,1)
Block(-6,29,12,1)
Block(-6,30,-2,1)
Block(-6,30,-1,1)
Block(-6,30,0,1)
Block(-6,30,1,1)
Block(-6,30,2,1)
Block(-6,30,3,1)
Block(-6,30,4,1)
Block(-6,30,5,1)
Block(-6,30,6,1)
Block(-6,30,7,1)
Block(-6,30,8,1)
Block(-6,30,9,1)
Block(-6,30,10,1)
Block(-6,30,11,1)
Block(-6,31,-2,1)
Block(-6,31,-1,1)
Block(-6,31,0,1)
Block(-6,31,1,1)
Block(-6,31,2,1)
Block(-6,31,3,1)
Block(-6,31,4,1)
Block(-6,31,5,1)
Block(-6,31,6,1)
Block(-6,31,7,1)
Block(-6,31,8,1)
Block(-6,31,9,1)
Block(-6,31,10,1)
Block(-6,31,11,1)
Block(-6,32,-2,1)
Block(-6,32,-1,1)
Block(-6,32,0,1)
Block(-6,32,1,1)
Block(-6,32,2,1)
Block(-6,32,3,1)
Block(-6,32,4,1)
Block(-6,32,5,1)
Block(-6,32,6,1)
Block(-6,32,7,1)
Block(-6,32,8,1)
Block(-6,32,9,1)
Block(-6,32,10,1)
Block(-6,33,-2,1)
Block(-6,33,-1,1)
Block(-6,33,0,1)
Block(-6,33,1,1)
Block(-6,33,2,1)
Block(-6,33,3,1)
Block(-6,33,4,1)
Block(-6,33,5,1)
Block(-6,33,6,1)
Block(-6,33,7,1)
Block(-6,33,8,1)
Block(-6,33,9,1)
Block(-6,34,-2,1)
Block(-6,34,-1,1)
Block(-6,34,0,1)
Block(-6,34,1,1)
Block(-6,34,2,1)
Block(-6,34,3,1)
Block(-6,34,4,1)
Block(-6,34,5,1)
Block(-6,34,6,1)
Block(-6,34,7,1)
Block(-6,34,8,1)
Block(-6,34,9,1)
Block(-6,35,-3,1)
Block(-6,35,-2,1)
Block(-6,35,-1,1)
Block(-6,35,0,1)
Block(-6,35,1,1)
Block(-6,35,2,1)
Block(-6,35,3,1)
Block(-6,35,4,1)
Block(-6,35,5,1)
Block(-6,35,6,1)
Block(-6,35,7,1)
Block(-6,35,8,1)
Block(-6,35,9,1)
Block(-6,36,-3,1)
Block(-6,36,-2,1)
Block(-6,36,-1,1)
Block(-6,36,0,1)
Block(-6,36,1,1)
Block(-6,36,2,1)
Block(-6,36,3,1)
Block(-6,36,4,1)
Block(-6,36,5,1)
Block(-6,36,6,1)
Block(-6,36,7,1)
Block(-6,36,8,1)
Block(-6,36,9,1)
Block(-6,36,10,1)
Block(-6,37,-3,1)
Block(-6,37,-2,1)
Block(-6,37,-1,1)
Block(-6,37,0,1)
Block(-6,37,1,1)
Block(-6,37,2,1)
Block(-6,37,3,1)
Block(-6,37,4,1)
Block(-6,37,5,1)
Block(-6,37,6,1)
Block(-6,37,7,1)
Block(-6,37,8,1)
Block(-6,37,9,1)
Block(-6,37,10,1)
Block(-6,37,11,1)
Block(-6,38,-2,1)
Block(-6,38,-1,1)
Block(-6,38,0,1)
Block(-6,38,1,1)
Block(-6,38,2,1)
Block(-6,38,3,1)
Block(-6,38,4,1)
Block(-6,38,5,1)
Block(-6,38,6,1)
Block(-6,38,7,1)
Block(-6,38,8,1)
Block(-6,38,9,1)
Block(-6,38,10,1)
Block(-6,38,11,1)
Block(-6,38,12,1)
Block(-6,39,-2,1)
Block(-6,39,-1,1)
Block(-6,39,0,1)
Block(-6,39,1,1)
Block(-6,39,2,1)
Block(-6,39,3,1)
Block(-6,39,4,1)
Block(-6,39,5,1)
Block(-6,39,6,1)
Block(-6,39,7,1)
Block(-6,39,8,1)
Block(-6,39,9,1)
Block(-6,39,10,1)
Block(-6,39,11,1)
Block(-6,39,12,1)
Block(-6,40,-2,1)
Block(-6,40,-1,1)
Block(-6,40,0,1)
Block(-6,40,1,1)
Block(-6,40,2,1)
Block(-6,40,3,1)
Block(-6,40,4,1)
Block(-6,40,5,1)
Block(-6,40,6,1)
Block(-6,40,7,1)
Block(-6,40,8,1)
Block(-6,40,9,1)
Block(-6,40,10,1)
Block(-6,40,11,1)
Block(-6,40,12,1)
Block(-6,41,-2,1)
Block(-6,41,-1,1)
Block(-6,41,0,1)
Block(-6,41,1,1)
Block(-6,41,2,1)
Block(-6,41,3,1)
Block(-6,41,4,1)
Block(-6,41,5,1)
Block(-6,41,6,1)
Block(-6,41,7,1)
Block(-6,41,8,1)
Block(-6,41,9,1)
Block(-6,41,10,1)
Block(-6,41,11,1)
Block(-6,41,12,1)
Block(-6,42,-1,1)
Block(-6,42,0,1)
Block(-6,42,1,1)
Block(-6,42,2,1)
Block(-6,42,3,1)
Block(-6,42,4,1)
Block(-6,42,5,1)
Block(-6,42,6,1)
Block(-6,42,7,1)
Block(-6,42,8,1)
Block(-6,42,9,1)
Block(-6,42,10,1)
Block(-6,42,11,1)
Block(-6,43,-1,1)
Block(-6,43,0,1)
Block(-6,43,1,1)
Block(-6,43,2,1)
Block(-6,43,3,1)
Block(-6,43,4,1)
Block(-6,43,5,1)
Block(-6,43,6,1)
Block(-6,43,7,1)
Block(-6,43,8,1)
Block(-6,43,9,1)
Block(-6,43,10,1)
Block(-6,43,11,1)
Block(-6,44,-1,1)
Block(-6,44,0,1)
Block(-6,44,1,1)
Block(-6,44,2,1)
Block(-6,44,3,1)
Block(-6,44,4,1)
Block(-6,44,5,1)
Block(-6,44,6,1)
Block(-6,44,7,1)
Block(-6,44,8,1)
Block(-6,44,9,1)
Block(-6,44,10,1)
Block(-6,44,11,1)
Block(-6,45,0,1)
Block(-6,45,1,1)
Block(-6,45,2,1)
Block(-6,45,3,1)
Block(-6,45,4,1)
Block(-6,45,5,1)
Block(-6,45,6,1)
Block(-6,45,7,1)
Block(-6,45,8,1)
Block(-6,45,9,1)
Block(-6,45,10,1)
Block(-6,46,1,1)
Block(-6,46,2,1)
Block(-6,46,3,1)
Block(-6,46,4,1)
Block(-6,46,5,1)
Block(-6,46,6,1)
Block(-6,46,7,1)
Block(-6,46,8,1)
Block(-6,46,9,1)
Block(-6,46,10,1)
Block(-6,47,1,1)
Block(-6,47,2,1)
Block(-6,47,3,1)
Block(-6,47,4,1)
Block(-6,47,5,1)
Block(-6,47,6,1)
Block(-6,47,7,1)
Block(-6,47,8,1)
Block(-6,47,9,1)
Block(-6,47,10,1)
Block(-6,48,0,1)
Block(-6,48,1,1)
Block(-6,48,2,1)
Block(-6,48,3,1)
Block(-6,48,4,1)
Block(-6,48,5,1)
Block(-6,48,6,1)
Block(-6,48,7,1)
Block(-6,48,8,1)
Block(-6,48,9,1)
Block(-6,48,10,1)
Block(-6,49,-1,1)
Block(-6,49,0,1)
Block(-6,49,1,1)
Block(-6,49,2,1)
Block(-6,49,3,1)
Block(-6,49,4,1)
Block(-6,49,5,1)
Block(-6,49,6,1)
Block(-6,49,7,1)
Block(-6,49,8,1)
Block(-6,49,9,1)
Block(-6,49,10,1)
Block(-6,50,-2,1)
Block(-6,50,-1,1)
Block(-6,50,0,1)
Block(-6,50,1,1)
Block(-6,50,2,1)
Block(-6,50,3,1)
Block(-6,50,4,1)
Block(-6,50,5,1)
Block(-6,50,6,1)
Block(-6,50,7,1)
Block(-6,50,8,1)
Block(-6,50,9,1)
Block(-6,50,10,1)
Block(-6,51,-2,1)
Block(-6,51,-1,1)
Block(-6,51,0,1)
Block(-6,51,1,1)
Block(-6,51,2,1)
Block(-6,51,3,1)
Block(-6,51,4,1)
Block(-6,51,5,1)
Block(-6,51,6,1)
Block(-6,51,7,1)
Block(-6,51,8,1)
Block(-6,51,9,1)
Block(-6,52,-3,1)
Block(-6,52,-2,1)
Block(-6,52,-1,1)
Block(-6,52,0,1)
Block(-6,52,1,1)
Block(-6,52,2,1)
Block(-6,52,3,1)
Block(-6,52,4,1)
Block(-6,52,5,1)
Block(-6,52,6,1)
Block(-6,52,7,1)
Block(-6,52,8,1)
Block(-6,52,9,1)
Block(-6,53,-3,1)
Block(-6,53,-2,1)
Block(-6,53,-1,1)
Block(-6,53,0,1)
Block(-6,53,1,1)
Block(-6,53,2,1)
Block(-6,53,3,1)
Block(-6,53,4,1)
Block(-6,53,5,1)
Block(-6,53,6,1)
Block(-6,53,7,1)
Block(-6,53,8,1)
Block(-6,54,-2,1)
Block(-6,54,-1,1)
Block(-6,54,0,1)
Block(-6,54,1,1)
Block(-6,54,2,1)
Block(-6,54,3,1)
Block(-6,54,4,1)
Block(-6,54,5,1)
Block(-6,54,6,1)
Block(-6,54,7,1)
Block(-6,55,-2,1)
Block(-6,55,-1,1)
Block(-6,55,0,1)
Block(-6,55,1,1)
Block(-6,55,2,1)
Block(-6,55,3,1)
Block(-6,55,4,1)
Block(-6,55,5,1)
Block(-6,55,6,1)
Block(-6,55,7,1)
Block(-6,56,-2,1)
Block(-6,56,-1,1)
Block(-6,56,0,1)
Block(-6,56,1,1)
Block(-6,56,2,1)
Block(-6,56,3,1)
Block(-6,56,4,1)
Block(-6,56,5,1)
Block(-6,56,6,1)
Block(-6,56,7,1)
Block(-6,57,-2,1)
Block(-6,57,-1,1)
Block(-6,57,0,1)
Block(-6,57,1,1)
Block(-6,57,2,1)
Block(-6,57,3,1)
Block(-6,57,4,1)
Block(-6,57,5,1)
Block(-6,57,6,1)
Block(-6,58,-2,1)
Block(-6,58,-1,1)
Block(-6,58,0,1)
Block(-6,58,1,1)
Block(-6,58,2,1)
Block(-6,58,3,1)
Block(-6,58,4,1)
Block(-6,58,5,1)
Block(-6,58,6,1)
Block(-6,59,-3,1)
Block(-6,59,-2,1)
Block(-6,59,-1,1)
Block(-6,59,0,1)
Block(-6,59,1,1)
Block(-6,59,2,1)
Block(-6,59,3,1)
Block(-6,59,4,1)
Block(-6,59,5,1)
Block(-6,59,6,1)
Block(-6,60,-3,1)
Block(-6,60,-2,1)
Block(-6,60,-1,1)
Block(-6,60,0,1)
Block(-6,60,1,1)
Block(-6,60,2,1)
Block(-6,60,3,1)
Block(-6,60,4,1)
Block(-6,60,5,1)
Block(-6,60,6,1)
Block(-6,60,7,1)
Block(-6,61,-3,1)
Block(-6,61,-2,1)
Block(-6,61,-1,1)
Block(-6,61,0,1)
Block(-6,61,1,1)
Block(-6,61,2,1)
Block(-6,61,3,1)
Block(-6,61,4,1)
Block(-6,61,5,1)
Block(-6,61,6,1)
Block(-6,61,7,1)
Block(-6,62,-2,1)
Block(-6,62,-1,1)
Block(-6,62,0,1)
Block(-6,62,1,1)
Block(-6,62,2,1)
Block(-6,62,3,1)
Block(-6,62,4,1)
Block(-6,62,5,1)
Block(-6,62,6,1)
Block(-6,62,7,1)
Block(-6,62,8,1)
Block(-6,63,-1,1)
Block(-6,63,0,1)
Block(-6,63,1,1)
Block(-6,63,2,1)
Block(-6,63,3,1)
Block(-6,63,4,1)
Block(-6,63,5,1)
Block(-6,63,6,1)
Block(-6,63,7,1)
Block(-6,63,8,1)
Block(-6,64,-1,1)
Block(-6,64,0,1)
Block(-6,64,1,1)
Block(-6,64,2,1)
Block(-6,64,3,1)
Block(-6,64,4,1)
Block(-6,64,5,1)
Block(-6,64,6,1)
Block(-6,64,7,1)
Block(-6,64,8,1)
Block(-6,65,-2,1)
Block(-6,65,-1,1)
Block(-6,65,0,1)
Block(-6,65,1,1)
Block(-6,65,2,1)
Block(-6,65,3,1)
Block(-6,65,4,1)
Block(-6,65,5,1)
Block(-6,65,6,1)
Block(-6,65,7,1)
Block(-6,65,8,1)
Block(-6,66,-3,1)
Block(-6,66,-2,1)
Block(-6,66,-1,1)
Block(-6,66,0,1)
Block(-6,66,1,1)
Block(-6,66,2,1)
Block(-6,66,3,1)
Block(-6,66,4,1)
Block(-6,66,5,1)
Block(-6,66,6,1)
Block(-6,66,7,1)
Block(-6,66,8,1)
Block(-6,67,-5,1)
Block(-6,67,-4,1)
Block(-6,67,-3,1)
Block(-6,67,-2,1)
Block(-6,67,-1,1)
Block(-6,67,0,1)
Block(-6,67,1,1)
Block(-6,67,2,1)
Block(-6,67,3,1)
Block(-6,67,4,1)
Block(-6,67,5,1)
Block(-6,67,6,1)
Block(-6,67,7,1)
Block(-6,67,8,1)
Block(-6,68,-5,1)
Block(-6,68,-4,1)
Block(-6,68,-3,1)
Block(-6,68,-2,1)
Block(-6,68,-1,1)
Block(-6,68,0,1)
Block(-6,68,1,1)
Block(-6,68,2,1)
Block(-6,68,3,1)
Block(-6,68,4,1)
Block(-6,68,5,1)
Block(-6,68,6,1)
Block(-6,68,7,1)
Block(-6,68,8,1)
Block(-6,68,9,1)
Block(-6,69,-6,1)
Block(-6,69,-5,1)
Block(-6,69,-4,1)
Block(-6,69,-3,1)
Block(-6,69,-2,1)
Block(-6,69,-1,1)
Block(-6,69,0,1)
Block(-6,69,1,1)
Block(-6,69,2,1)
Block(-6,69,3,1)
Block(-6,69,4,1)
Block(-6,69,5,1)
Block(-6,69,6,1)
Block(-6,69,7,1)
Block(-6,69,8,1)
Block(-6,69,9,1)
Block(-6,70,-6,1)
Block(-6,70,-5,1)
Block(-6,70,-4,1)
Block(-6,70,-3,1)
Block(-6,70,-2,1)
Block(-6,70,-1,1)
Block(-6,70,0,1)
Block(-6,70,1,1)
Block(-6,70,2,1)
Block(-6,70,3,1)
Block(-6,70,4,1)
Block(-6,70,5,1)
Block(-6,70,6,1)
Block(-6,70,7,1)
Block(-6,70,8,1)
Block(-6,71,-6,1)
Block(-6,71,-5,3)
Block(-6,71,-4,1)
Block(-6,71,-3,1)
Block(-6,71,-2,1)
Block(-6,71,-1,1)
Block(-6,71,0,1)
Block(-6,71,1,1)
Block(-6,71,2,1)
Block(-6,71,3,1)
Block(-6,71,4,1)
Block(-6,71,5,1)
Block(-6,71,6,1)
Block(-6,71,7,1)
Block(-6,71,8,1)
Block(-6,72,-6,1)
Block(-6,72,-5,1)
Block(-6,72,-4,1)
Block(-6,72,-3,1)
Block(-6,72,-2,1)
Block(-6,72,-1,1)
Block(-6,72,0,1)
Block(-6,72,1,1)
Block(-6,72,2,1)
Block(-6,72,3,1)
Block(-6,72,4,1)
Block(-6,72,5,1)
Block(-6,72,6,1)
Block(-6,72,7,1)
Block(-6,73,-5,1)
Block(-6,73,-4,1)
Block(-6,73,-3,1)
Block(-6,73,-2,1)
Block(-6,73,-1,1)
Block(-6,73,0,1)
Block(-6,73,1,1)
Block(-6,73,2,1)
Block(-6,73,3,1)
Block(-6,73,4,1)
Block(-6,73,5,1)
Block(-6,73,6,1)
Block(-6,74,-5,1)
Block(-6,74,-4,1)
Block(-6,74,-3,1)
Block(-6,74,-2,1)
Block(-6,74,-1,1)
Block(-6,74,0,1)
Block(-6,74,1,1)
Block(-6,74,2,1)
Block(-6,74,3,1)
Block(-6,74,4,1)
Block(-6,74,5,1)
Block(-6,75,-4,1)
Block(-6,75,-3,1)
Block(-6,75,-2,1)
Block(-6,75,-1,1)
Block(-6,75,0,1)
Block(-6,75,1,1)
Block(-6,75,2,1)
Block(-6,75,3,1)
Block(-6,75,4,1)
Block(-6,75,5,1)
Block(-6,76,-3,1)
Block(-6,76,-2,1)
Block(-6,76,-1,1)
Block(-6,76,0,1)
Block(-6,76,1,1)
Block(-6,76,2,1)
Block(-6,76,3,1)
Block(-6,76,4,1)
Block(-6,76,5,1)
Block(-6,77,-3,1)
Block(-6,77,-2,1)
Block(-6,77,-1,1)
Block(-6,77,0,1)
Block(-6,77,1,1)
Block(-6,77,2,1)
Block(-6,77,3,1)
Block(-6,77,4,1)
Block(-6,77,5,1)
Block(-6,77,6,1)
Block(-6,77,7,1)
Block(-6,77,8,1)
Block(-6,78,-3,1)
Block(-6,78,-2,1)
Block(-6,78,-1,1)
Block(-6,78,0,1)
Block(-6,78,1,1)
Block(-6,78,2,1)
Block(-6,78,3,1)
Block(-6,78,4,1)
Block(-6,78,5,1)
Block(-6,78,6,1)
Block(-6,78,7,1)
Block(-6,78,8,1)
Block(-6,78,9,1)
Block(-6,79,-3,1)
Block(-6,79,-2,1)
Block(-6,79,-1,1)
Block(-6,79,0,1)
Block(-6,79,1,1)
Block(-6,79,2,1)
Block(-6,79,3,1)
Block(-6,79,4,1)
Block(-6,79,5,1)
Block(-6,79,6,1)
Block(-6,79,7,1)
Block(-6,79,8,1)
Block(-6,79,9,1)
Block(-6,79,10,1)
Block(-6,80,-3,1)
Block(-6,80,-2,1)
Block(-6,80,-1,1)
Block(-6,80,0,1)
Block(-6,80,1,1)
Block(-6,80,2,1)
Block(-6,80,3,1)
Block(-6,80,4,1)
Block(-6,80,5,1)
Block(-6,80,6,1)
Block(-6,80,7,1)
Block(-6,80,8,1)
Block(-6,80,9,1)
Block(-6,80,10,1)
Block(-6,81,-4,1)
Block(-6,81,-3,1)
Block(-6,81,-2,1)
Block(-6,81,-1,1)
Block(-6,81,0,1)
Block(-6,81,1,1)
Block(-6,81,2,1)
Block(-6,81,3,1)
Block(-6,81,4,1)
Block(-6,81,5,1)
Block(-6,81,6,1)
Block(-6,81,7,1)
Block(-6,81,8,1)
Block(-6,81,9,1)
Block(-6,81,10,1)
Block(-6,82,-3,1)
Block(-6,82,-2,3)
Block(-6,82,-1,1)
Block(-6,82,0,1)
Block(-6,82,1,1)
Block(-6,82,2,1)
Block(-6,82,3,1)
Block(-6,82,4,1)
Block(-6,82,5,1)
Block(-6,82,6,1)
Block(-6,82,7,1)
Block(-6,82,8,1)
Block(-6,82,9,1)
Block(-6,82,10,1)
Block(-6,83,-3,1)
Block(-6,83,-2,1)
Block(-6,83,-1,3)
Block(-6,83,0,1)
Block(-6,83,1,1)
Block(-6,83,2,1)
Block(-6,83,3,1)
Block(-6,83,4,1)
Block(-6,83,5,1)
Block(-6,83,6,1)
Block(-6,83,7,1)
Block(-6,83,8,1)
Block(-6,83,9,1)
Block(-6,83,10,1)
Block(-6,84,-2,1)
Block(-6,84,-1,3)
Block(-6,84,0,3)
Block(-6,84,1,1)
Block(-6,84,2,1)
Block(-6,84,3,1)
Block(-6,84,4,1)
Block(-6,84,5,1)
Block(-6,84,6,1)
Block(-6,84,7,1)
Block(-6,84,8,1)
Block(-6,84,9,1)
Block(-6,84,10,1)
Block(-6,85,-2,1)
Block(-6,85,-1,3)
Block(-6,85,0,3)
Block(-6,85,1,1)
Block(-6,85,2,1)
Block(-6,85,3,1)
Block(-6,85,4,1)
Block(-6,85,5,1)
Block(-6,85,6,1)
Block(-6,85,7,1)
Block(-6,85,8,1)
Block(-6,85,9,1)
Block(-6,85,10,1)
Block(-6,86,-1,1)
Block(-6,86,0,3)
Block(-6,86,1,3)
Block(-6,86,2,1)
Block(-6,86,3,1)
Block(-6,86,4,1)
Block(-6,86,5,1)
Block(-6,86,6,1)
Block(-6,86,7,1)
Block(-6,86,8,3)
Block(-6,86,9,3)
Block(-6,86,10,1)
Block(-6,87,0,1)
Block(-6,87,1,3)
Block(-6,87,2,3)
Block(-6,87,3,3)
Block(-6,87,4,1)
Block(-6,87,5,3)
Block(-6,87,6,3)
Block(-6,87,7,3)
Block(-6,87,8,3)
Block(-6,87,9,3)
Block(-6,87,10,1)
Block(-6,88,1,1)
Block(-6,88,2,3)
Block(-6,88,3,3)
Block(-6,88,4,3)
Block(-6,88,5,3)
Block(-6,88,6,3)
Block(-6,88,7,3)
Block(-6,88,8,3)
Block(-6,88,9,1)
Block(-6,88,10,1)
Block(-6,89,1,1)
Block(-6,89,2,3)
Block(-6,89,3,3)
Block(-6,89,4,3)
Block(-6,89,5,3)
Block(-6,89,6,3)
Block(-6,89,7,3)
Block(-6,89,8,1)
Block(-6,89,9,1)
Block(-6,90,2,1)
Block(-6,90,3,2)
Block(-6,90,4,3)
Block(-6,90,5,2)
Block(-6,90,6,2)
Block(-6,90,7,2)
Block(-6,91,4,2)
Block(-5,0,-3,1)
Block(-5,0,-2,1)
Block(-5,0,-1,1)
Block(-5,0,0,1)
Block(-5,0,1,1)
Block(-5,0,2,1)
Block(-5,0,3,1)
Block(-5,0,4,1)
Block(-5,0,5,1)
Block(-5,0,6,1)
Block(-5,0,7,1)
Block(-5,0,8,1)
Block(-5,0,9,1)
Block(-5,0,10,1)
Block(-5,0,11,1)
Block(-5,1,-3,1)
Block(-5,1,-2,1)
Block(-5,1,-1,1)
Block(-5,1,0,1)
Block(-5,1,1,1)
Block(-5,1,2,1)
Block(-5,1,3,1)
Block(-5,1,4,1)
Block(-5,1,5,1)
Block(-5,1,6,1)
Block(-5,1,7,1)
Block(-5,1,8,1)
Block(-5,1,9,1)
Block(-5,1,10,1)
Block(-5,1,11,1)
Block(-5,2,-3,1)
Block(-5,2,-2,1)
Block(-5,2,-1,1)
Block(-5,2,0,1)
Block(-5,2,1,1)
Block(-5,2,2,1)
Block(-5,2,3,1)
Block(-5,2,4,1)
Block(-5,2,5,1)
Block(-5,2,6,1)
Block(-5,2,7,1)
Block(-5,2,8,1)
Block(-5,2,9,1)
Block(-5,2,10,1)
Block(-5,2,11,1)
Block(-5,3,-3,1)
Block(-5,3,-2,1)
Block(-5,3,-1,1)
Block(-5,3,0,1)
Block(-5,3,1,1)
Block(-5,3,2,1)
Block(-5,3,3,1)
Block(-5,3,4,1)
Block(-5,3,5,1)
Block(-5,3,6,1)
Block(-5,3,7,1)
Block(-5,3,8,1)
Block(-5,3,9,1)
Block(-5,3,10,1)
Block(-5,3,11,1)
Block(-5,3,12,1)
Block(-5,4,-4,1)
Block(-5,4,-3,1)
Block(-5,4,-2,1)
Block(-5,4,-1,1)
Block(-5,4,0,1)
Block(-5,4,1,1)
Block(-5,4,2,1)
Block(-5,4,3,1)
Block(-5,4,4,1)
Block(-5,4,5,1)
Block(-5,4,6,1)
Block(-5,4,7,1)
Block(-5,4,8,1)
Block(-5,4,9,1)
Block(-5,4,10,1)
Block(-5,4,11,1)
Block(-5,4,12,1)
Block(-5,5,-4,1)
Block(-5,5,-3,1)
Block(-5,5,-2,1)
Block(-5,5,-1,1)
Block(-5,5,0,1)
Block(-5,5,1,1)
Block(-5,5,2,1)
Block(-5,5,3,1)
Block(-5,5,4,1)
Block(-5,5,5,1)
Block(-5,5,6,1)
Block(-5,5,7,1)
Block(-5,5,8,1)
Block(-5,5,9,1)
Block(-5,5,10,1)
Block(-5,5,11,1)
Block(-5,5,12,1)
Block(-5,6,-4,1)
Block(-5,6,-3,1)
Block(-5,6,-2,1)
Block(-5,6,-1,1)
Block(-5,6,0,1)
Block(-5,6,1,1)
Block(-5,6,2,1)
Block(-5,6,3,1)
Block(-5,6,4,1)
Block(-5,6,5,1)
Block(-5,6,6,1)
Block(-5,6,7,1)
Block(-5,6,8,1)
Block(-5,6,9,1)
Block(-5,6,10,1)
Block(-5,6,11,1)
Block(-5,6,12,1)
Block(-5,7,-4,1)
Block(-5,7,-3,1)
Block(-5,7,-2,1)
Block(-5,7,-1,1)
Block(-5,7,0,1)
Block(-5,7,1,1)
Block(-5,7,2,1)
Block(-5,7,3,1)
Block(-5,7,4,1)
Block(-5,7,5,1)
Block(-5,7,6,1)
Block(-5,7,7,1)
Block(-5,7,8,1)
Block(-5,7,9,1)
Block(-5,7,10,1)
Block(-5,7,11,1)
Block(-5,7,12,1)
Block(-5,8,-4,1)
Block(-5,8,-3,1)
Block(-5,8,-2,1)
Block(-5,8,-1,1)
Block(-5,8,0,1)
Block(-5,8,1,1)
Block(-5,8,2,1)
Block(-5,8,3,1)
Block(-5,8,4,1)
Block(-5,8,5,1)
Block(-5,8,6,1)
Block(-5,8,7,1)
Block(-5,8,8,1)
Block(-5,8,9,1)
Block(-5,8,10,1)
Block(-5,8,11,1)
Block(-5,9,-4,1)
Block(-5,9,-3,1)
Block(-5,9,-2,1)
Block(-5,9,-1,1)
Block(-5,9,0,1)
Block(-5,9,1,1)
Block(-5,9,2,1)
Block(-5,9,3,1)
Block(-5,9,4,1)
Block(-5,9,5,1)
Block(-5,9,6,1)
Block(-5,9,7,1)
Block(-5,9,8,1)
Block(-5,9,9,1)
Block(-5,9,10,1)
Block(-5,9,11,1)
Block(-5,10,-5,1)
Block(-5,10,-4,1)
Block(-5,10,-3,1)
Block(-5,10,-2,1)
Block(-5,10,-1,1)
Block(-5,10,0,1)
Block(-5,10,1,1)
Block(-5,10,2,1)
Block(-5,10,3,1)
Block(-5,10,4,1)
Block(-5,10,5,1)
Block(-5,10,6,1)
Block(-5,10,7,1)
Block(-5,10,8,1)
Block(-5,10,9,1)
Block(-5,10,10,1)
Block(-5,11,-5,1)
Block(-5,11,-4,1)
Block(-5,11,-3,1)
Block(-5,11,-2,1)
Block(-5,11,-1,1)
Block(-5,11,0,1)
Block(-5,11,1,1)
Block(-5,11,2,1)
Block(-5,11,3,1)
Block(-5,11,4,1)
Block(-5,11,5,1)
Block(-5,11,6,1)
Block(-5,11,7,1)
Block(-5,11,8,1)
Block(-5,11,9,1)
Block(-5,11,10,1)
Block(-5,12,-5,1)
Block(-5,12,-4,1)
Block(-5,12,-3,1)
Block(-5,12,-2,1)
Block(-5,12,-1,1)
Block(-5,12,0,1)
Block(-5,12,1,1)
Block(-5,12,2,1)
Block(-5,12,3,1)
Block(-5,12,4,1)
Block(-5,12,5,1)
Block(-5,12,6,1)
Block(-5,12,7,1)
Block(-5,12,8,1)
Block(-5,12,9,1)
Block(-5,12,10,1)
Block(-5,13,-5,1)
Block(-5,13,-4,1)
Block(-5,13,-3,1)
Block(-5,13,-2,1)
Block(-5,13,-1,1)
Block(-5,13,0,1)
Block(-5,13,1,1)
Block(-5,13,2,1)
Block(-5,13,3,1)
Block(-5,13,4,1)
Block(-5,13,5,1)
Block(-5,13,6,1)
Block(-5,13,7,1)
Block(-5,13,8,1)
Block(-5,13,9,1)
Block(-5,13,10,1)
Block(-5,14,-5,1)
Block(-5,14,-4,1)
Block(-5,14,-3,1)
Block(-5,14,-2,1)
Block(-5,14,-1,1)
Block(-5,14,0,1)
Block(-5,14,1,1)
Block(-5,14,2,1)
Block(-5,14,3,1)
Block(-5,14,4,1)
Block(-5,14,5,1)
Block(-5,14,6,1)
Block(-5,14,7,1)
Block(-5,14,8,1)
Block(-5,14,9,1)
Block(-5,14,10,1)
Block(-5,14,11,1)
Block(-5,15,-4,1)
Block(-5,15,-3,1)
Block(-5,15,-2,1)
Block(-5,15,-1,1)
Block(-5,15,0,1)
Block(-5,15,1,1)
Block(-5,15,2,1)
Block(-5,15,3,1)
Block(-5,15,4,1)
Block(-5,15,5,1)
Block(-5,15,6,1)
Block(-5,15,7,1)
Block(-5,15,8,1)
Block(-5,15,9,1)
Block(-5,15,10,1)
Block(-5,15,11,1)
Block(-5,16,-4,1)
Block(-5,16,-3,1)
Block(-5,16,-2,1)
Block(-5,16,-1,1)
Block(-5,16,0,1)
Block(-5,16,1,1)
Block(-5,16,2,1)
Block(-5,16,3,1)
Block(-5,16,4,1)
Block(-5,16,5,1)
Block(-5,16,6,1)
Block(-5,16,7,1)
Block(-5,16,8,1)
Block(-5,16,9,1)
Block(-5,16,10,1)
Block(-5,16,11,1)
Block(-5,17,-4,1)
Block(-5,17,-3,1)
Block(-5,17,-2,1)
Block(-5,17,-1,1)
Block(-5,17,0,1)
Block(-5,17,1,1)
Block(-5,17,2,1)
Block(-5,17,3,1)
Block(-5,17,4,1)
Block(-5,17,5,1)
Block(-5,17,6,1)
Block(-5,17,7,1)
Block(-5,17,8,1)
Block(-5,17,9,1)
Block(-5,17,10,1)
Block(-5,17,11,1)
Block(-5,18,-3,1)
Block(-5,18,-2,1)
Block(-5,18,-1,1)
Block(-5,18,0,1)
Block(-5,18,1,1)
Block(-5,18,2,1)
Block(-5,18,3,1)
Block(-5,18,4,1)
Block(-5,18,5,1)
Block(-5,18,6,1)
Block(-5,18,7,1)
Block(-5,18,8,1)
Block(-5,18,9,1)
Block(-5,18,10,1)
Block(-5,18,11,1)
Block(-5,18,12,1)
Block(-5,19,-3,1)
Block(-5,19,-2,1)
Block(-5,19,-1,1)
Block(-5,19,0,1)
Block(-5,19,1,1)
Block(-5,19,2,1)
Block(-5,19,3,1)
Block(-5,19,4,1)
Block(-5,19,5,1)
Block(-5,19,6,1)
Block(-5,19,7,1)
Block(-5,19,8,1)
Block(-5,19,9,1)
Block(-5,19,10,1)
Block(-5,19,11,1)
Block(-5,19,12,1)
Block(-5,20,-4,1)
Block(-5,20,-3,1)
Block(-5,20,-2,1)
Block(-5,20,-1,1)
Block(-5,20,0,1)
Block(-5,20,1,1)
Block(-5,20,2,1)
Block(-5,20,3,1)
Block(-5,20,4,1)
Block(-5,20,5,1)
Block(-5,20,6,1)
Block(-5,20,7,1)
Block(-5,20,8,1)
Block(-5,20,9,1)
Block(-5,20,10,1)
Block(-5,20,11,1)
Block(-5,20,12,1)
Block(-5,20,13,1)
Block(-5,21,-4,1)
Block(-5,21,-3,1)
Block(-5,21,-2,1)
Block(-5,21,-1,1)
Block(-5,21,0,1)
Block(-5,21,1,1)
Block(-5,21,2,1)
Block(-5,21,3,1)
Block(-5,21,4,1)
Block(-5,21,5,1)
Block(-5,21,6,1)
Block(-5,21,7,1)
Block(-5,21,8,1)
Block(-5,21,9,1)
Block(-5,21,10,1)
Block(-5,21,11,1)
Block(-5,21,12,1)
Block(-5,22,-4,1)
Block(-5,22,-3,1)
Block(-5,22,-2,1)
Block(-5,22,-1,1)
Block(-5,22,0,1)
Block(-5,22,1,1)
Block(-5,22,2,1)
Block(-5,22,3,1)
Block(-5,22,4,1)
Block(-5,22,5,1)
Block(-5,22,6,1)
Block(-5,22,7,1)
Block(-5,22,8,1)
Block(-5,22,9,1)
Block(-5,22,10,1)
Block(-5,22,11,1)
Block(-5,22,12,1)
Block(-5,23,-4,1)
Block(-5,23,-3,1)
Block(-5,23,-2,1)
Block(-5,23,-1,1)
Block(-5,23,0,1)
Block(-5,23,1,1)
Block(-5,23,2,1)
Block(-5,23,3,1)
Block(-5,23,4,1)
Block(-5,23,5,1)
Block(-5,23,6,1)
Block(-5,23,7,1)
Block(-5,23,8,1)
Block(-5,23,9,1)
Block(-5,23,10,1)
Block(-5,23,11,1)
Block(-5,23,12,1)
Block(-5,24,-4,1)
Block(-5,24,-3,1)
Block(-5,24,-2,1)
Block(-5,24,-1,1)
Block(-5,24,0,1)
Block(-5,24,1,1)
Block(-5,24,2,1)
Block(-5,24,3,1)
Block(-5,24,4,1)
Block(-5,24,5,1)
Block(-5,24,6,1)
Block(-5,24,7,1)
Block(-5,24,8,1)
Block(-5,24,9,1)
Block(-5,24,10,1)
Block(-5,24,11,1)
Block(-5,24,12,1)
Block(-5,25,-4,1)
Block(-5,25,-3,1)
Block(-5,25,-2,1)
Block(-5,25,-1,1)
Block(-5,25,0,1)
Block(-5,25,1,1)
Block(-5,25,2,1)
Block(-5,25,3,1)
Block(-5,25,4,1)
Block(-5,25,5,1)
Block(-5,25,6,1)
Block(-5,25,7,1)
Block(-5,25,8,1)
Block(-5,25,9,1)
Block(-5,25,10,1)
Block(-5,25,11,1)
Block(-5,25,12,1)
Block(-5,26,-4,1)
Block(-5,26,-3,1)
Block(-5,26,-2,1)
Block(-5,26,-1,1)
Block(-5,26,0,1)
Block(-5,26,1,1)
Block(-5,26,2,1)
Block(-5,26,3,1)
Block(-5,26,4,1)
Block(-5,26,5,1)
Block(-5,26,6,1)
Block(-5,26,7,1)
Block(-5,26,8,1)
Block(-5,26,9,1)
Block(-5,26,10,1)
Block(-5,26,11,1)
Block(-5,26,12,1)
Block(-5,27,-4,1)
Block(-5,27,-3,1)
Block(-5,27,-2,1)
Block(-5,27,-1,1)
Block(-5,27,0,1)
Block(-5,27,1,1)
Block(-5,27,2,1)
Block(-5,27,3,1)
Block(-5,27,4,1)
Block(-5,27,5,1)
Block(-5,27,6,1)
Block(-5,27,7,1)
Block(-5,27,8,1)
Block(-5,27,9,1)
Block(-5,27,10,1)
Block(-5,27,11,1)
Block(-5,27,12,1)
Block(-5,28,-4,1)
Block(-5,28,-3,1)
Block(-5,28,-2,1)
Block(-5,28,-1,1)
Block(-5,28,0,1)
Block(-5,28,1,1)
Block(-5,28,2,1)
Block(-5,28,3,1)
Block(-5,28,4,1)
Block(-5,28,5,1)
Block(-5,28,6,1)
Block(-5,28,7,1)
Block(-5,28,8,1)
Block(-5,28,9,1)
Block(-5,28,10,1)
Block(-5,28,11,1)
Block(-5,28,12,1)
Block(-5,29,-4,1)
Block(-5,29,-3,1)
Block(-5,29,-2,1)
Block(-5,29,-1,1)
Block(-5,29,0,1)
Block(-5,29,1,1)
Block(-5,29,2,1)
Block(-5,29,3,1)
Block(-5,29,4,1)
Block(-5,29,5,1)
Block(-5,29,6,1)
Block(-5,29,7,1)
Block(-5,29,8,1)
Block(-5,29,9,1)
Block(-5,29,10,1)
Block(-5,29,11,1)
Block(-5,29,12,1)
Block(-5,30,-4,1)
Block(-5,30,-3,1)
Block(-5,30,-2,1)
Block(-5,30,-1,1)
Block(-5,30,0,1)
Block(-5,30,1,1)
Block(-5,30,2,1)
Block(-5,30,3,1)
Block(-5,30,4,1)
Block(-5,30,5,1)
Block(-5,30,6,1)
Block(-5,30,7,1)
Block(-5,30,8,1)
Block(-5,30,9,1)
Block(-5,30,10,1)
Block(-5,30,11,1)
Block(-5,30,12,1)
Block(-5,31,-4,1)
Block(-5,31,-3,1)
Block(-5,31,-2,1)
Block(-5,31,-1,1)
Block(-5,31,0,1)
Block(-5,31,1,1)
Block(-5,31,2,1)
Block(-5,31,3,1)
Block(-5,31,4,1)
Block(-5,31,5,1)
Block(-5,31,6,1)
Block(-5,31,7,1)
Block(-5,31,8,1)
Block(-5,31,9,1)
Block(-5,31,10,1)
Block(-5,31,11,1)
Block(-5,31,12,1)
Block(-5,32,-5,1)
Block(-5,32,-4,1)
Block(-5,32,-3,1)
Block(-5,32,-2,1)
Block(-5,32,-1,1)
Block(-5,32,0,1)
Block(-5,32,1,1)
Block(-5,32,2,1)
Block(-5,32,3,1)
Block(-5,32,4,1)
Block(-5,32,5,1)
Block(-5,32,6,1)
Block(-5,32,7,1)
Block(-5,32,8,1)
Block(-5,32,9,1)
Block(-5,32,10,1)
Block(-5,32,11,1)
Block(-5,33,-5,1)
Block(-5,33,-4,1)
Block(-5,33,-3,1)
Block(-5,33,-2,1)
Block(-5,33,-1,1)
Block(-5,33,0,1)
Block(-5,33,1,1)
Block(-5,33,2,1)
Block(-5,33,3,1)
Block(-5,33,4,1)
Block(-5,33,5,1)
Block(-5,33,6,1)
Block(-5,33,7,1)
Block(-5,33,8,1)
Block(-5,33,9,1)
Block(-5,33,10,1)
Block(-5,34,-4,1)
Block(-5,34,-3,1)
Block(-5,34,-2,1)
Block(-5,34,-1,1)
Block(-5,34,0,1)
Block(-5,34,1,1)
Block(-5,34,2,1)
Block(-5,34,3,1)
Block(-5,34,4,1)
Block(-5,34,5,1)
Block(-5,34,6,1)
Block(-5,34,7,1)
Block(-5,34,8,1)
Block(-5,34,9,1)
Block(-5,34,10,1)
Block(-5,35,-4,1)
Block(-5,35,-3,1)
Block(-5,35,-2,1)
Block(-5,35,-1,1)
Block(-5,35,0,1)
Block(-5,35,1,1)
Block(-5,35,2,1)
Block(-5,35,3,1)
Block(-5,35,4,1)
Block(-5,35,5,1)
Block(-5,35,6,1)
Block(-5,35,7,1)
Block(-5,35,8,1)
Block(-5,35,9,1)
Block(-5,35,10,1)
Block(-5,36,-4,1)
Block(-5,36,-3,1)
Block(-5,36,-2,1)
Block(-5,36,-1,1)
Block(-5,36,0,1)
Block(-5,36,1,1)
Block(-5,36,2,1)
Block(-5,36,3,1)
Block(-5,36,4,1)
Block(-5,36,5,1)
Block(-5,36,6,1)
Block(-5,36,7,1)
Block(-5,36,8,1)
Block(-5,36,9,1)
Block(-5,36,10,1)
Block(-5,36,11,1)
Block(-5,37,-4,1)
Block(-5,37,-3,1)
Block(-5,37,-2,1)
Block(-5,37,-1,1)
Block(-5,37,0,1)
Block(-5,37,1,1)
Block(-5,37,2,1)
Block(-5,37,3,1)
Block(-5,37,4,1)
Block(-5,37,5,1)
Block(-5,37,6,1)
Block(-5,37,7,1)
Block(-5,37,8,1)
Block(-5,37,9,1)
Block(-5,37,10,1)
Block(-5,37,11,1)
Block(-5,37,12,1)
Block(-5,38,-3,1)
Block(-5,38,-2,1)
Block(-5,38,-1,1)
Block(-5,38,0,1)
Block(-5,38,1,1)
Block(-5,38,2,1)
Block(-5,38,3,1)
Block(-5,38,4,1)
Block(-5,38,5,1)
Block(-5,38,6,1)
Block(-5,38,7,1)
Block(-5,38,8,1)
Block(-5,38,9,1)
Block(-5,38,10,1)
Block(-5,38,11,1)
Block(-5,38,12,1)
Block(-5,38,13,1)
Block(-5,39,-3,1)
Block(-5,39,-2,1)
Block(-5,39,-1,1)
Block(-5,39,0,1)
Block(-5,39,1,1)
Block(-5,39,2,1)
Block(-5,39,3,1)
Block(-5,39,4,1)
Block(-5,39,5,1)
Block(-5,39,6,1)
Block(-5,39,7,1)
Block(-5,39,8,1)
Block(-5,39,9,1)
Block(-5,39,10,1)
Block(-5,39,11,1)
Block(-5,39,12,1)
Block(-5,39,13,1)
Block(-5,40,-3,1)
Block(-5,40,-2,1)
Block(-5,40,-1,1)
Block(-5,40,0,1)
Block(-5,40,1,1)
Block(-5,40,2,1)
Block(-5,40,3,1)
Block(-5,40,4,1)
Block(-5,40,5,1)
Block(-5,40,6,1)
Block(-5,40,7,1)
Block(-5,40,8,1)
Block(-5,40,9,1)
Block(-5,40,10,1)
Block(-5,40,11,1)
Block(-5,40,12,1)
Block(-5,40,13,1)
Block(-5,41,-3,1)
Block(-5,41,-2,1)
Block(-5,41,-1,1)
Block(-5,41,0,1)
Block(-5,41,1,1)
Block(-5,41,2,1)
Block(-5,41,3,1)
Block(-5,41,4,1)
Block(-5,41,5,1)
Block(-5,41,6,1)
Block(-5,41,7,1)
Block(-5,41,8,1)
Block(-5,41,9,1)
Block(-5,41,10,1)
Block(-5,41,11,1)
Block(-5,41,12,1)
Block(-5,41,13,1)
Block(-5,42,-3,1)
Block(-5,42,-2,1)
Block(-5,42,-1,1)
Block(-5,42,0,1)
Block(-5,42,1,1)
Block(-5,42,2,1)
Block(-5,42,3,1)
Block(-5,42,4,1)
Block(-5,42,5,1)
Block(-5,42,6,1)
Block(-5,42,7,1)
Block(-5,42,8,1)
Block(-5,42,9,1)
Block(-5,42,10,1)
Block(-5,42,11,1)
Block(-5,42,12,1)
Block(-5,43,-2,1)
Block(-5,43,-1,1)
Block(-5,43,0,1)
Block(-5,43,1,1)
Block(-5,43,2,1)
Block(-5,43,3,1)
Block(-5,43,4,1)
Block(-5,43,5,1)
Block(-5,43,6,1)
Block(-5,43,7,1)
Block(-5,43,8,1)
Block(-5,43,9,1)
Block(-5,43,10,1)
Block(-5,43,11,1)
Block(-5,43,12,1)
Block(-5,44,-2,1)
Block(-5,44,-1,1)
Block(-5,44,0,1)
Block(-5,44,1,1)
Block(-5,44,2,1)
Block(-5,44,3,1)
Block(-5,44,4,1)
Block(-5,44,5,1)
Block(-5,44,6,1)
Block(-5,44,7,1)
Block(-5,44,8,1)
Block(-5,44,9,1)
Block(-5,44,10,1)
Block(-5,44,11,1)
Block(-5,44,12,1)
Block(-5,45,-3,1)
Block(-5,45,-2,1)
Block(-5,45,-1,1)
Block(-5,45,0,1)
Block(-5,45,1,1)
Block(-5,45,2,1)
Block(-5,45,3,1)
Block(-5,45,4,1)
Block(-5,45,5,1)
Block(-5,45,6,1)
Block(-5,45,7,1)
Block(-5,45,8,1)
Block(-5,45,9,1)
Block(-5,45,10,1)
Block(-5,45,11,1)
Block(-5,46,-3,1)
Block(-5,46,-2,1)
Block(-5,46,-1,1)
Block(-5,46,0,1)
Block(-5,46,1,1)
Block(-5,46,2,1)
Block(-5,46,3,1)
Block(-5,46,4,1)
Block(-5,46,5,1)
Block(-5,46,6,1)
Block(-5,46,7,1)
Block(-5,46,8,1)
Block(-5,46,9,1)
Block(-5,46,10,1)
Block(-5,46,11,1)
Block(-5,47,-4,1)
Block(-5,47,-3,1)
Block(-5,47,-2,1)
Block(-5,47,-1,1)
Block(-5,47,0,1)
Block(-5,47,1,1)
Block(-5,47,2,1)
Block(-5,47,3,1)
Block(-5,47,4,1)
Block(-5,47,5,1)
Block(-5,47,6,1)
Block(-5,47,7,1)
Block(-5,47,8,1)
Block(-5,47,9,1)
Block(-5,47,10,1)
Block(-5,47,11,1)
Block(-5,48,-4,1)
Block(-5,48,-3,1)
Block(-5,48,-2,1)
Block(-5,48,-1,1)
Block(-5,48,0,1)
Block(-5,48,1,1)
Block(-5,48,2,1)
Block(-5,48,3,1)
Block(-5,48,4,1)
Block(-5,48,5,1)
Block(-5,48,6,1)
Block(-5,48,7,1)
Block(-5,48,8,1)
Block(-5,48,9,1)
Block(-5,48,10,1)
Block(-5,48,11,1)
Block(-5,49,-4,1)
Block(-5,49,-3,1)
Block(-5,49,-2,1)
Block(-5,49,-1,1)
Block(-5,49,0,1)
Block(-5,49,1,1)
Block(-5,49,2,1)
Block(-5,49,3,1)
Block(-5,49,4,1)
Block(-5,49,5,1)
Block(-5,49,6,1)
Block(-5,49,7,1)
Block(-5,49,8,1)
Block(-5,49,9,1)
Block(-5,49,10,1)
Block(-5,49,11,1)
Block(-5,50,-5,1)
Block(-5,50,-4,1)
Block(-5,50,-3,1)
Block(-5,50,-2,1)
Block(-5,50,-1,1)
Block(-5,50,0,1)
Block(-5,50,1,1)
Block(-5,50,2,1)
Block(-5,50,3,1)
Block(-5,50,4,1)
Block(-5,50,5,1)
Block(-5,50,6,1)
Block(-5,50,7,1)
Block(-5,50,8,1)
Block(-5,50,9,1)
Block(-5,50,10,1)
Block(-5,50,11,1)
Block(-5,51,-4,1)
Block(-5,51,-3,1)
Block(-5,51,-2,1)
Block(-5,51,-1,1)
Block(-5,51,0,1)
Block(-5,51,1,1)
Block(-5,51,2,1)
Block(-5,51,3,1)
Block(-5,51,4,1)
Block(-5,51,5,1)
Block(-5,51,6,1)
Block(-5,51,7,1)
Block(-5,51,8,1)
Block(-5,51,9,1)
Block(-5,51,10,1)
Block(-5,52,-4,1)
Block(-5,52,-3,1)
Block(-5,52,-2,1)
Block(-5,52,-1,1)
Block(-5,52,0,1)
Block(-5,52,1,1)
Block(-5,52,2,1)
Block(-5,52,3,1)
Block(-5,52,4,1)
Block(-5,52,5,1)
Block(-5,52,6,1)
Block(-5,52,7,1)
Block(-5,52,8,1)
Block(-5,52,9,1)
Block(-5,52,10,1)
Block(-5,53,-4,1)
Block(-5,53,-3,1)
Block(-5,53,-2,1)
Block(-5,53,-1,1)
Block(-5,53,0,1)
Block(-5,53,1,1)
Block(-5,53,2,1)
Block(-5,53,3,1)
Block(-5,53,4,1)
Block(-5,53,5,1)
Block(-5,53,6,1)
Block(-5,53,7,1)
Block(-5,53,8,1)
Block(-5,53,9,1)
Block(-5,54,-4,1)
Block(-5,54,-3,1)
Block(-5,54,-2,1)
Block(-5,54,-1,1)
Block(-5,54,0,1)
Block(-5,54,1,1)
Block(-5,54,2,1)
Block(-5,54,3,1)
Block(-5,54,4,1)
Block(-5,54,5,1)
Block(-5,54,6,1)
Block(-5,54,7,1)
Block(-5,54,8,1)
Block(-5,55,-3,1)
Block(-5,55,-2,1)
Block(-5,55,-1,1)
Block(-5,55,0,1)
Block(-5,55,1,1)
Block(-5,55,2,1)
Block(-5,55,3,1)
Block(-5,55,4,1)
Block(-5,55,5,1)
Block(-5,55,6,1)
Block(-5,55,7,1)
Block(-5,55,8,1)
Block(-5,56,-3,1)
Block(-5,56,-2,1)
Block(-5,56,-1,1)
Block(-5,56,0,1)
Block(-5,56,1,1)
Block(-5,56,2,1)
Block(-5,56,3,1)
Block(-5,56,4,1)
Block(-5,56,5,1)
Block(-5,56,6,1)
Block(-5,56,7,1)
Block(-5,56,8,1)
Block(-5,57,-3,1)
Block(-5,57,-2,1)
Block(-5,57,-1,1)
Block(-5,57,0,1)
Block(-5,57,1,1)
Block(-5,57,2,1)
Block(-5,57,3,1)
Block(-5,57,4,1)
Block(-5,57,5,1)
Block(-5,57,6,1)
Block(-5,57,7,1)
Block(-5,57,8,1)
Block(-5,58,-4,1)
Block(-5,58,-3,1)
Block(-5,58,-2,1)
Block(-5,58,-1,1)
Block(-5,58,0,1)
Block(-5,58,1,1)
Block(-5,58,2,1)
Block(-5,58,3,1)
Block(-5,58,4,1)
Block(-5,58,5,1)
Block(-5,58,6,1)
Block(-5,58,7,1)
Block(-5,58,8,1)
Block(-5,59,-4,1)
Block(-5,59,-3,1)
Block(-5,59,-2,1)
Block(-5,59,-1,1)
Block(-5,59,0,1)
Block(-5,59,1,1)
Block(-5,59,2,1)
Block(-5,59,3,1)
Block(-5,59,4,1)
Block(-5,59,5,1)
Block(-5,59,6,1)
Block(-5,59,7,1)
Block(-5,59,8,1)
Block(-5,60,-4,1)
Block(-5,60,-3,1)
Block(-5,60,-2,1)
Block(-5,60,-1,1)
Block(-5,60,0,1)
Block(-5,60,1,1)
Block(-5,60,2,1)
Block(-5,60,3,1)
Block(-5,60,4,1)
Block(-5,60,5,1)
Block(-5,60,6,1)
Block(-5,60,7,1)
Block(-5,60,8,1)
Block(-5,60,9,1)
Block(-5,61,-4,1)
Block(-5,61,-3,1)
Block(-5,61,-2,1)
Block(-5,61,-1,1)
Block(-5,61,0,1)
Block(-5,61,1,1)
Block(-5,61,2,1)
Block(-5,61,3,1)
Block(-5,61,4,1)
Block(-5,61,5,1)
Block(-5,61,6,1)
Block(-5,61,7,1)
Block(-5,61,8,1)
Block(-5,61,9,1)
Block(-5,61,10,1)
Block(-5,62,-4,1)
Block(-5,62,-3,1)
Block(-5,62,-2,1)
Block(-5,62,-1,1)
Block(-5,62,0,1)
Block(-5,62,1,1)
Block(-5,62,2,1)
Block(-5,62,3,1)
Block(-5,62,4,1)
Block(-5,62,5,1)
Block(-5,62,6,1)
Block(-5,62,7,1)
Block(-5,62,8,1)
Block(-5,62,9,1)
Block(-5,62,10,1)
Block(-5,63,-3,1)
Block(-5,63,-2,1)
Block(-5,63,-1,1)
Block(-5,63,0,1)
Block(-5,63,1,1)
Block(-5,63,2,1)
Block(-5,63,3,1)
Block(-5,63,4,1)
Block(-5,63,5,1)
Block(-5,63,6,1)
Block(-5,63,7,1)
Block(-5,63,8,1)
Block(-5,63,9,1)
Block(-5,64,-3,1)
Block(-5,64,-2,1)
Block(-5,64,-1,1)
Block(-5,64,0,1)
Block(-5,64,1,1)
Block(-5,64,2,1)
Block(-5,64,3,1)
Block(-5,64,4,1)
Block(-5,64,5,1)
Block(-5,64,6,1)
Block(-5,64,7,1)
Block(-5,64,8,1)
Block(-5,64,9,1)
Block(-5,65,-4,1)
Block(-5,65,-3,1)
Block(-5,65,-2,1)
Block(-5,65,-1,1)
Block(-5,65,0,1)
Block(-5,65,1,1)
Block(-5,65,2,1)
Block(-5,65,3,1)
Block(-5,65,4,1)
Block(-5,65,5,1)
Block(-5,65,6,1)
Block(-5,65,7,1)
Block(-5,65,8,1)
Block(-5,65,9,1)
Block(-5,66,-5,1)
Block(-5,66,-4,1)
Block(-5,66,-3,1)
Block(-5,66,-2,1)
Block(-5,66,-1,1)
Block(-5,66,0,1)
Block(-5,66,1,1)
Block(-5,66,2,1)
Block(-5,66,3,1)
Block(-5,66,4,1)
Block(-5,66,5,1)
Block(-5,66,6,1)
Block(-5,66,7,1)
Block(-5,66,8,1)
Block(-5,66,9,1)
Block(-5,67,-6,1)
Block(-5,67,-5,1)
Block(-5,67,-4,1)
Block(-5,67,-3,1)
Block(-5,67,-2,1)
Block(-5,67,-1,1)
Block(-5,67,0,1)
Block(-5,67,1,1)
Block(-5,67,2,1)
Block(-5,67,3,1)
Block(-5,67,4,1)
Block(-5,67,5,1)
Block(-5,67,6,1)
Block(-5,67,7,1)
Block(-5,67,8,1)
Block(-5,67,9,1)
Block(-5,67,10,1)
Block(-5,68,-6,1)
Block(-5,68,-5,1)
Block(-5,68,-4,1)
Block(-5,68,-3,1)
Block(-5,68,-2,1)
Block(-5,68,-1,1)
Block(-5,68,0,1)
Block(-5,68,1,1)
Block(-5,68,2,1)
Block(-5,68,3,1)
Block(-5,68,4,1)
Block(-5,68,5,1)
Block(-5,68,6,1)
Block(-5,68,7,1)
Block(-5,68,8,1)
Block(-5,68,9,1)
Block(-5,68,10,1)
Block(-5,69,-7,1)
Block(-5,69,-6,1)
Block(-5,69,-5,1)
Block(-5,69,-4,1)
Block(-5,69,-3,1)
Block(-5,69,-2,1)
Block(-5,69,-1,1)
Block(-5,69,0,1)
Block(-5,69,1,1)
Block(-5,69,2,1)
Block(-5,69,3,1)
Block(-5,69,4,1)
Block(-5,69,5,1)
Block(-5,69,6,1)
Block(-5,69,7,1)
Block(-5,69,8,1)
Block(-5,69,9,1)
Block(-5,69,10,1)
Block(-5,70,-7,1)
Block(-5,70,-6,1)
Block(-5,70,-5,1)
Block(-5,70,-4,1)
Block(-5,70,-3,1)
Block(-5,70,-2,1)
Block(-5,70,-1,1)
Block(-5,70,0,1)
Block(-5,70,1,1)
Block(-5,70,2,1)
Block(-5,70,3,1)
Block(-5,70,4,1)
Block(-5,70,5,1)
Block(-5,70,6,1)
Block(-5,70,7,1)
Block(-5,70,8,1)
Block(-5,70,9,1)
Block(-5,70,10,1)
Block(-5,71,-7,1)
Block(-5,71,-6,3)
Block(-5,71,-5,1)
Block(-5,71,-4,1)
Block(-5,71,-3,1)
Block(-5,71,-2,1)
Block(-5,71,-1,1)
Block(-5,71,0,1)
Block(-5,71,1,1)
Block(-5,71,2,1)
Block(-5,71,3,1)
Block(-5,71,4,1)
Block(-5,71,5,1)
Block(-5,71,6,1)
Block(-5,71,7,1)
Block(-5,71,8,1)
Block(-5,71,9,1)
Block(-5,72,-6,1)
Block(-5,72,-5,1)
Block(-5,72,-4,1)
Block(-5,72,-3,1)
Block(-5,72,-2,1)
Block(-5,72,-1,1)
Block(-5,72,0,1)
Block(-5,72,1,1)
Block(-5,72,2,1)
Block(-5,72,3,1)
Block(-5,72,4,1)
Block(-5,72,5,1)
Block(-5,72,6,1)
Block(-5,72,7,1)
Block(-5,72,8,1)
Block(-5,72,9,1)
Block(-5,73,-6,1)
Block(-5,73,-5,1)
Block(-5,73,-4,1)
Block(-5,73,-3,1)
Block(-5,73,-2,1)
Block(-5,73,-1,1)
Block(-5,73,0,1)
Block(-5,73,1,1)
Block(-5,73,2,1)
Block(-5,73,3,1)
Block(-5,73,4,1)
Block(-5,73,5,1)
Block(-5,73,6,1)
Block(-5,73,7,1)
Block(-5,73,8,1)
Block(-5,74,-6,1)
Block(-5,74,-5,1)
Block(-5,74,-4,1)
Block(-5,74,-3,1)
Block(-5,74,-2,1)
Block(-5,74,-1,1)
Block(-5,74,0,1)
Block(-5,74,1,1)
Block(-5,74,2,1)
Block(-5,74,3,1)
Block(-5,74,4,1)
Block(-5,74,5,1)
Block(-5,74,6,1)
Block(-5,74,7,1)
Block(-5,74,8,1)
Block(-5,75,-5,1)
Block(-5,75,-4,1)
Block(-5,75,-3,1)
Block(-5,75,-2,1)
Block(-5,75,-1,1)
Block(-5,75,0,1)
Block(-5,75,1,1)
Block(-5,75,2,1)
Block(-5,75,3,1)
Block(-5,75,4,1)
Block(-5,75,5,1)
Block(-5,75,6,1)
Block(-5,75,7,1)
Block(-5,75,8,1)
Block(-5,76,-4,1)
Block(-5,76,-3,1)
Block(-5,76,-2,1)
Block(-5,76,-1,1)
Block(-5,76,0,1)
Block(-5,76,1,1)
Block(-5,76,2,1)
Block(-5,76,3,1)
Block(-5,76,4,1)
Block(-5,76,5,1)
Block(-5,76,6,1)
Block(-5,76,7,1)
Block(-5,76,8,1)
Block(-5,76,9,1)
Block(-5,77,-4,1)
Block(-5,77,-3,1)
Block(-5,77,-2,1)
Block(-5,77,-1,1)
Block(-5,77,0,1)
Block(-5,77,1,1)
Block(-5,77,2,1)
Block(-5,77,3,1)
Block(-5,77,4,1)
Block(-5,77,5,1)
Block(-5,77,6,1)
Block(-5,77,7,1)
Block(-5,77,8,1)
Block(-5,77,9,1)
Block(-5,77,10,1)
Block(-5,78,-4,1)
Block(-5,78,-3,1)
Block(-5,78,-2,1)
Block(-5,78,-1,1)
Block(-5,78,0,1)
Block(-5,78,1,1)
Block(-5,78,2,1)
Block(-5,78,3,1)
Block(-5,78,4,1)
Block(-5,78,5,1)
Block(-5,78,6,1)
Block(-5,78,7,1)
Block(-5,78,8,1)
Block(-5,78,9,1)
Block(-5,78,10,1)
Block(-5,78,11,1)
Block(-5,79,-4,1)
Block(-5,79,-3,1)
Block(-5,79,-2,1)
Block(-5,79,-1,1)
Block(-5,79,0,1)
Block(-5,79,1,1)
Block(-5,79,2,1)
Block(-5,79,3,1)
Block(-5,79,4,1)
Block(-5,79,5,1)
Block(-5,79,6,1)
Block(-5,79,7,1)
Block(-5,79,8,1)
Block(-5,79,9,1)
Block(-5,79,10,1)
Block(-5,79,11,1)
Block(-5,80,-4,1)
Block(-5,80,-3,1)
Block(-5,80,-2,1)
Block(-5,80,-1,1)
Block(-5,80,0,1)
Block(-5,80,1,1)
Block(-5,80,2,1)
Block(-5,80,3,1)
Block(-5,80,4,1)
Block(-5,80,5,1)
Block(-5,80,6,1)
Block(-5,80,7,1)
Block(-5,80,8,1)
Block(-5,80,9,1)
Block(-5,80,10,1)
Block(-5,80,11,1)
Block(-5,81,-5,1)
Block(-5,81,-4,3)
Block(-5,81,-3,3)
Block(-5,81,-2,1)
Block(-5,81,-1,1)
Block(-5,81,0,1)
Block(-5,81,1,1)
Block(-5,81,2,1)
Block(-5,81,3,1)
Block(-5,81,4,1)
Block(-5,81,5,1)
Block(-5,81,6,1)
Block(-5,81,7,1)
Block(-5,81,8,1)
Block(-5,81,9,1)
Block(-5,81,10,1)
Block(-5,81,11,1)
Block(-5,82,-4,1)
Block(-5,82,-3,3)
Block(-5,82,-2,1)
Block(-5,82,-1,1)
Block(-5,82,0,1)
Block(-5,82,1,1)
Block(-5,82,2,1)
Block(-5,82,3,1)
Block(-5,82,4,1)
Block(-5,82,5,1)
Block(-5,82,6,1)
Block(-5,82,7,1)
Block(-5,82,8,1)
Block(-5,82,9,1)
Block(-5,82,10,1)
Block(-5,82,11,1)
Block(-5,83,-4,1)
Block(-5,83,-3,3)
Block(-5,83,-2,3)
Block(-5,83,-1,1)
Block(-5,83,0,1)
Block(-5,83,1,1)
Block(-5,83,2,1)
Block(-5,83,3,1)
Block(-5,83,4,1)
Block(-5,83,5,1)
Block(-5,83,6,1)
Block(-5,83,7,1)
Block(-5,83,8,1)
Block(-5,83,9,1)
Block(-5,83,10,1)
Block(-5,83,11,1)
Block(-5,84,-3,1)
Block(-5,84,-2,3)
Block(-5,84,-1,3)
Block(-5,84,0,1)
Block(-5,84,1,1)
Block(-5,84,2,1)
Block(-5,84,3,1)
Block(-5,84,4,1)
Block(-5,84,5,1)
Block(-5,84,6,1)
Block(-5,84,7,1)
Block(-5,84,8,1)
Block(-5,84,9,1)
Block(-5,84,10,1)
Block(-5,84,11,1)
Block(-5,85,-2,1)
Block(-5,85,-1,3)
Block(-5,85,0,3)
Block(-5,85,1,1)
Block(-5,85,2,1)
Block(-5,85,3,1)
Block(-5,85,4,1)
Block(-5,85,5,1)
Block(-5,85,6,1)
Block(-5,85,7,1)
Block(-5,85,8,1)
Block(-5,85,9,1)
Block(-5,85,10,1)
Block(-5,85,11,1)
Block(-5,86,-2,1)
Block(-5,86,-1,3)
Block(-5,86,0,3)
Block(-5,86,1,1)
Block(-5,86,2,1)
Block(-5,86,3,1)
Block(-5,86,4,1)
Block(-5,86,5,1)
Block(-5,86,6,1)
Block(-5,86,7,1)
Block(-5,86,8,1)
Block(-5,86,9,1)
Block(-5,86,10,3)
Block(-5,86,11,1)
Block(-5,87,-1,1)
Block(-5,87,0,3)
Block(-5,87,1,3)
Block(-5,87,2,1)
Block(-5,87,3,1)
Block(-5,87,4,1)
Block(-5,87,5,1)
Block(-5,87,6,1)
Block(-5,87,7,1)
Block(-5,87,8,3)
Block(-5,87,9,3)
Block(-5,87,10,3)
Block(-5,87,11,1)
Block(-5,88,0,1)
Block(-5,88,1,3)
Block(-5,88,2,3)
Block(-5,88,3,3)
Block(-5,88,4,3)
Block(-5,88,5,3)
Block(-5,88,6,3)
Block(-5,88,7,3)
Block(-5,88,8,3)
Block(-5,88,9,3)
Block(-5,88,10,1)
Block(-5,89,1,1)
Block(-5,89,2,3)
Block(-5,89,3,3)
Block(-5,89,4,3)
Block(-5,89,5,3)
Block(-5,89,6,3)
Block(-5,89,7,3)
Block(-5,89,8,3)
Block(-5,89,9,3)
Block(-5,89,10,1)
Block(-5,90,1,1)
Block(-5,90,2,3)
Block(-5,90,3,3)
Block(-5,90,4,3)
Block(-5,90,5,3)
Block(-5,90,6,3)
Block(-5,90,7,3)
Block(-5,90,8,2)
Block(-5,90,9,2)
Block(-5,91,2,2)
Block(-5,91,3,2)
Block(-5,91,4,2)
Block(-5,91,5,2)
Block(-5,91,6,2)
Block(-5,91,7,2)
Block(-4,0,-4,1)
Block(-4,0,-3,1)
Block(-4,0,-2,1)
Block(-4,0,-1,1)
Block(-4,0,0,1)
Block(-4,0,1,1)
Block(-4,0,2,1)
Block(-4,0,3,1)
Block(-4,0,4,1)
Block(-4,0,5,1)
Block(-4,0,6,1)
Block(-4,0,7,1)
Block(-4,0,8,1)
Block(-4,0,9,1)
Block(-4,0,10,1)
Block(-4,0,11,1)
Block(-4,0,12,1)
Block(-4,0,13,1)
Block(-4,1,-4,1)
Block(-4,1,-3,1)
Block(-4,1,-2,1)
Block(-4,1,-1,1)
Block(-4,1,0,1)
Block(-4,1,1,1)
Block(-4,1,2,1)
Block(-4,1,3,1)
Block(-4,1,4,1)
Block(-4,1,5,1)
Block(-4,1,6,1)
Block(-4,1,7,1)
Block(-4,1,8,1)
Block(-4,1,9,1)
Block(-4,1,10,1)
Block(-4,1,11,1)
Block(-4,1,12,1)
Block(-4,2,-4,1)
Block(-4,2,-3,1)
Block(-4,2,-2,1)
Block(-4,2,-1,1)
Block(-4,2,0,1)
Block(-4,2,1,1)
Block(-4,2,2,1)
Block(-4,2,3,1)
Block(-4,2,4,1)
Block(-4,2,5,1)
Block(-4,2,6,1)
Block(-4,2,7,1)
Block(-4,2,8,1)
Block(-4,2,9,1)
Block(-4,2,10,1)
Block(-4,2,11,1)
Block(-4,2,12,1)
Block(-4,3,-4,1)
Block(-4,3,-3,1)
Block(-4,3,-2,1)
Block(-4,3,-1,1)
Block(-4,3,0,1)
Block(-4,3,1,1)
Block(-4,3,2,1)
Block(-4,3,3,1)
Block(-4,3,4,1)
Block(-4,3,5,1)
Block(-4,3,6,1)
Block(-4,3,7,1)
Block(-4,3,8,1)
Block(-4,3,9,1)
Block(-4,3,10,1)
Block(-4,3,11,1)
Block(-4,3,12,1)
Block(-4,4,-4,1)
Block(-4,4,-3,1)
Block(-4,4,-2,1)
Block(-4,4,-1,1)
Block(-4,4,0,1)
Block(-4,4,1,1)
Block(-4,4,2,1)
Block(-4,4,3,1)
Block(-4,4,4,1)
Block(-4,4,5,1)
Block(-4,4,6,1)
Block(-4,4,7,1)
Block(-4,4,8,1)
Block(-4,4,9,1)
Block(-4,4,10,1)
Block(-4,4,11,1)
Block(-4,4,12,1)
Block(-4,4,13,1)
Block(-4,5,-4,1)
Block(-4,5,-3,1)
Block(-4,5,-2,1)
Block(-4,5,-1,1)
Block(-4,5,0,1)
Block(-4,5,1,1)
Block(-4,5,2,1)
Block(-4,5,3,1)
Block(-4,5,4,1)
Block(-4,5,5,1)
Block(-4,5,6,1)
Block(-4,5,7,1)
Block(-4,5,8,1)
Block(-4,5,9,1)
Block(-4,5,10,1)
Block(-4,5,11,1)
Block(-4,5,12,1)
Block(-4,5,13,1)
Block(-4,6,-4,1)
Block(-4,6,-3,1)
Block(-4,6,-2,1)
Block(-4,6,-1,1)
Block(-4,6,0,1)
Block(-4,6,1,1)
Block(-4,6,2,1)
Block(-4,6,3,1)
Block(-4,6,4,1)
Block(-4,6,5,1)
Block(-4,6,6,1)
Block(-4,6,7,1)
Block(-4,6,8,1)
Block(-4,6,9,1)
Block(-4,6,10,1)
Block(-4,6,11,1)
Block(-4,6,12,1)
Block(-4,6,13,1)
Block(-4,7,-4,1)
Block(-4,7,-3,1)
Block(-4,7,-2,1)
Block(-4,7,-1,1)
Block(-4,7,0,1)
Block(-4,7,1,1)
Block(-4,7,2,1)
Block(-4,7,3,1)
Block(-4,7,4,1)
Block(-4,7,5,1)
Block(-4,7,6,1)
Block(-4,7,7,1)
Block(-4,7,8,1)
Block(-4,7,9,1)
Block(-4,7,10,1)
Block(-4,7,11,1)
Block(-4,7,12,1)
Block(-4,7,13,1)
Block(-4,8,-4,1)
Block(-4,8,-3,1)
Block(-4,8,-2,1)
Block(-4,8,-1,1)
Block(-4,8,0,1)
Block(-4,8,1,1)
Block(-4,8,2,1)
Block(-4,8,3,1)
Block(-4,8,4,1)
Block(-4,8,5,1)
Block(-4,8,6,1)
Block(-4,8,7,1)
Block(-4,8,8,1)
Block(-4,8,9,1)
Block(-4,8,10,1)
Block(-4,8,11,1)
Block(-4,8,12,1)
Block(-4,8,13,1)
Block(-4,9,-5,1)
Block(-4,9,-4,1)
Block(-4,9,-3,1)
Block(-4,9,-2,1)
Block(-4,9,-1,1)
Block(-4,9,0,1)
Block(-4,9,1,1)
Block(-4,9,2,1)
Block(-4,9,3,1)
Block(-4,9,4,1)
Block(-4,9,5,1)
Block(-4,9,6,1)
Block(-4,9,7,1)
Block(-4,9,8,1)
Block(-4,9,9,1)
Block(-4,9,10,1)
Block(-4,9,11,1)
Block(-4,9,12,1)
Block(-4,10,-5,1)
Block(-4,10,-4,1)
Block(-4,10,-3,1)
Block(-4,10,-2,1)
Block(-4,10,-1,1)
Block(-4,10,0,1)
Block(-4,10,1,1)
Block(-4,10,2,1)
Block(-4,10,3,1)
Block(-4,10,4,1)
Block(-4,10,5,1)
Block(-4,10,6,1)
Block(-4,10,7,1)
Block(-4,10,8,1)
Block(-4,10,9,1)
Block(-4,10,10,1)
Block(-4,10,11,1)
Block(-4,10,12,1)
Block(-4,11,-5,1)
Block(-4,11,-4,1)
Block(-4,11,-3,1)
Block(-4,11,-2,1)
Block(-4,11,-1,1)
Block(-4,11,0,1)
Block(-4,11,1,1)
Block(-4,11,2,1)
Block(-4,11,3,1)
Block(-4,11,4,1)
Block(-4,11,5,1)
Block(-4,11,6,1)
Block(-4,11,7,1)
Block(-4,11,8,1)
Block(-4,11,9,1)
Block(-4,11,10,1)
Block(-4,11,11,1)
Block(-4,12,-5,1)
Block(-4,12,-4,1)
Block(-4,12,-3,1)
Block(-4,12,-2,1)
Block(-4,12,-1,1)
Block(-4,12,0,1)
Block(-4,12,1,1)
Block(-4,12,2,1)
Block(-4,12,3,1)
Block(-4,12,4,1)
Block(-4,12,5,1)
Block(-4,12,6,1)
Block(-4,12,7,1)
Block(-4,12,8,1)
Block(-4,12,9,1)
Block(-4,12,10,1)
Block(-4,12,11,1)
Block(-4,13,-5,1)
Block(-4,13,-4,1)
Block(-4,13,-3,1)
Block(-4,13,-2,1)
Block(-4,13,-1,1)
Block(-4,13,0,1)
Block(-4,13,1,1)
Block(-4,13,2,1)
Block(-4,13,3,1)
Block(-4,13,4,1)
Block(-4,13,5,1)
Block(-4,13,6,1)
Block(-4,13,7,1)
Block(-4,13,8,1)
Block(-4,13,9,1)
Block(-4,13,10,1)
Block(-4,13,11,1)
Block(-4,13,12,1)
Block(-4,14,-5,1)
Block(-4,14,-4,1)
Block(-4,14,-3,1)
Block(-4,14,-2,1)
Block(-4,14,-1,1)
Block(-4,14,0,1)
Block(-4,14,1,1)
Block(-4,14,2,1)
Block(-4,14,3,1)
Block(-4,14,4,1)
Block(-4,14,5,1)
Block(-4,14,6,1)
Block(-4,14,7,1)
Block(-4,14,8,1)
Block(-4,14,9,1)
Block(-4,14,10,1)
Block(-4,14,11,1)
Block(-4,14,12,1)
Block(-4,15,-5,1)
Block(-4,15,-4,1)
Block(-4,15,-3,1)
Block(-4,15,-2,1)
Block(-4,15,-1,1)
Block(-4,15,0,1)
Block(-4,15,1,1)
Block(-4,15,2,1)
Block(-4,15,3,1)
Block(-4,15,4,1)
Block(-4,15,5,1)
Block(-4,15,6,1)
Block(-4,15,7,1)
Block(-4,15,8,1)
Block(-4,15,9,1)
Block(-4,15,10,1)
Block(-4,15,11,1)
Block(-4,15,12,1)
Block(-4,16,-4,1)
Block(-4,16,-3,1)
Block(-4,16,-2,1)
Block(-4,16,-1,1)
Block(-4,16,0,1)
Block(-4,16,1,1)
Block(-4,16,2,1)
Block(-4,16,3,1)
Block(-4,16,4,1)
Block(-4,16,5,1)
Block(-4,16,6,1)
Block(-4,16,7,1)
Block(-4,16,8,1)
Block(-4,16,9,1)
Block(-4,16,10,1)
Block(-4,16,11,1)
Block(-4,16,12,1)
Block(-4,17,-4,1)
Block(-4,17,-3,1)
Block(-4,17,-2,1)
Block(-4,17,-1,1)
Block(-4,17,0,1)
Block(-4,17,1,1)
Block(-4,17,2,1)
Block(-4,17,3,1)
Block(-4,17,4,1)
Block(-4,17,5,1)
Block(-4,17,6,1)
Block(-4,17,7,1)
Block(-4,17,8,1)
Block(-4,17,9,1)
Block(-4,17,10,1)
Block(-4,17,11,1)
Block(-4,17,12,1)
Block(-4,17,13,1)
Block(-4,18,-4,1)
Block(-4,18,-3,1)
Block(-4,18,-2,1)
Block(-4,18,-1,1)
Block(-4,18,0,1)
Block(-4,18,1,1)
Block(-4,18,2,1)
Block(-4,18,3,1)
Block(-4,18,4,1)
Block(-4,18,5,1)
Block(-4,18,6,1)
Block(-4,18,7,1)
Block(-4,18,8,1)
Block(-4,18,9,1)
Block(-4,18,10,1)
Block(-4,18,11,1)
Block(-4,18,12,1)
Block(-4,18,13,1)
Block(-4,19,-4,1)
Block(-4,19,-3,1)
Block(-4,19,-2,1)
Block(-4,19,-1,1)
Block(-4,19,0,1)
Block(-4,19,1,1)
Block(-4,19,2,1)
Block(-4,19,3,1)
Block(-4,19,4,1)
Block(-4,19,5,1)
Block(-4,19,6,1)
Block(-4,19,7,1)
Block(-4,19,8,1)
Block(-4,19,9,1)
Block(-4,19,10,1)
Block(-4,19,11,1)
Block(-4,19,12,1)
Block(-4,19,13,1)
Block(-4,20,-5,1)
Block(-4,20,-4,1)
Block(-4,20,-3,1)
Block(-4,20,-2,1)
Block(-4,20,-1,1)
Block(-4,20,0,1)
Block(-4,20,1,1)
Block(-4,20,2,1)
Block(-4,20,3,1)
Block(-4,20,4,1)
Block(-4,20,5,1)
Block(-4,20,6,1)
Block(-4,20,7,1)
Block(-4,20,8,1)
Block(-4,20,9,1)
Block(-4,20,10,1)
Block(-4,20,11,1)
Block(-4,20,12,1)
Block(-4,20,13,1)
Block(-4,20,14,1)
Block(-4,21,-5,1)
Block(-4,21,-4,1)
Block(-4,21,-3,1)
Block(-4,21,-2,1)
Block(-4,21,-1,1)
Block(-4,21,0,1)
Block(-4,21,1,1)
Block(-4,21,2,1)
Block(-4,21,3,1)
Block(-4,21,4,1)
Block(-4,21,5,1)
Block(-4,21,6,1)
Block(-4,21,7,1)
Block(-4,21,8,1)
Block(-4,21,9,1)
Block(-4,21,10,1)
Block(-4,21,11,1)
Block(-4,21,12,1)
Block(-4,21,13,1)
Block(-4,22,-5,1)
Block(-4,22,-4,1)
Block(-4,22,-3,1)
Block(-4,22,-2,1)
Block(-4,22,-1,1)
Block(-4,22,0,1)
Block(-4,22,1,1)
Block(-4,22,2,1)
Block(-4,22,3,1)
Block(-4,22,4,1)
Block(-4,22,5,1)
Block(-4,22,6,1)
Block(-4,22,7,1)
Block(-4,22,8,1)
Block(-4,22,9,1)
Block(-4,22,10,1)
Block(-4,22,11,1)
Block(-4,22,12,1)
Block(-4,22,13,1)
Block(-4,23,-6,1)
Block(-4,23,-5,1)
Block(-4,23,-4,1)
Block(-4,23,-3,1)
Block(-4,23,-2,1)
Block(-4,23,-1,1)
Block(-4,23,0,1)
Block(-4,23,1,1)
Block(-4,23,2,1)
Block(-4,23,3,1)
Block(-4,23,4,1)
Block(-4,23,5,1)
Block(-4,23,6,1)
Block(-4,23,7,1)
Block(-4,23,8,1)
Block(-4,23,9,1)
Block(-4,23,10,1)
Block(-4,23,11,1)
Block(-4,23,12,1)
Block(-4,23,13,1)
Block(-4,24,-6,1)
Block(-4,24,-5,1)
Block(-4,24,-4,1)
Block(-4,24,-3,1)
Block(-4,24,-2,1)
Block(-4,24,-1,1)
Block(-4,24,0,1)
Block(-4,24,1,1)
Block(-4,24,2,1)
Block(-4,24,3,1)
Block(-4,24,4,1)
Block(-4,24,5,1)
Block(-4,24,6,1)
Block(-4,24,7,1)
Block(-4,24,8,1)
Block(-4,24,9,1)
Block(-4,24,10,1)
Block(-4,24,11,1)
Block(-4,24,12,1)
Block(-4,25,-6,1)
Block(-4,25,-5,1)
Block(-4,25,-4,1)
Block(-4,25,-3,1)
Block(-4,25,-2,1)
Block(-4,25,-1,1)
Block(-4,25,0,1)
Block(-4,25,1,1)
Block(-4,25,2,1)
Block(-4,25,3,1)
Block(-4,25,4,1)
Block(-4,25,5,1)
Block(-4,25,6,1)
Block(-4,25,7,1)
Block(-4,25,8,1)
Block(-4,25,9,1)
Block(-4,25,10,1)
Block(-4,25,11,1)
Block(-4,25,12,1)
Block(-4,26,-6,1)
Block(-4,26,-5,1)
Block(-4,26,-4,1)
Block(-4,26,-3,1)
Block(-4,26,-2,1)
Block(-4,26,-1,1)
Block(-4,26,0,1)
Block(-4,26,1,1)
Block(-4,26,2,1)
Block(-4,26,3,1)
Block(-4,26,4,1)
Block(-4,26,5,1)
Block(-4,26,6,1)
Block(-4,26,7,1)
Block(-4,26,8,1)
Block(-4,26,9,1)
Block(-4,26,10,1)
Block(-4,26,11,1)
Block(-4,26,12,1)
Block(-4,27,-6,1)
Block(-4,27,-5,1)
Block(-4,27,-4,1)
Block(-4,27,-3,1)
Block(-4,27,-2,1)
Block(-4,27,-1,1)
Block(-4,27,0,1)
Block(-4,27,1,1)
Block(-4,27,2,1)
Block(-4,27,3,1)
Block(-4,27,4,1)
Block(-4,27,5,1)
Block(-4,27,6,1)
Block(-4,27,7,1)
Block(-4,27,8,1)
Block(-4,27,9,1)
Block(-4,27,10,1)
Block(-4,27,11,1)
Block(-4,27,12,1)
Block(-4,28,-6,1)
Block(-4,28,-5,1)
Block(-4,28,-4,1)
Block(-4,28,-3,1)
Block(-4,28,-2,1)
Block(-4,28,-1,1)
Block(-4,28,0,1)
Block(-4,28,1,1)
Block(-4,28,2,1)
Block(-4,28,3,1)
Block(-4,28,4,1)
Block(-4,28,5,1)
Block(-4,28,6,1)
Block(-4,28,7,1)
Block(-4,28,8,1)
Block(-4,28,9,1)
Block(-4,28,10,1)
Block(-4,28,11,1)
Block(-4,28,12,1)
Block(-4,28,13,1)
Block(-4,29,-6,1)
Block(-4,29,-5,1)
Block(-4,29,-4,1)
Block(-4,29,-3,1)
Block(-4,29,-2,1)
Block(-4,29,-1,1)
Block(-4,29,0,1)
Block(-4,29,1,1)
Block(-4,29,2,1)
Block(-4,29,3,1)
Block(-4,29,4,1)
Block(-4,29,5,1)
Block(-4,29,6,1)
Block(-4,29,7,1)
Block(-4,29,8,1)
Block(-4,29,9,1)
Block(-4,29,10,1)
Block(-4,29,11,1)
Block(-4,29,12,1)
Block(-4,29,13,1)
Block(-4,30,-6,1)
Block(-4,30,-5,1)
Block(-4,30,-4,1)
Block(-4,30,-3,1)
Block(-4,30,-2,1)
Block(-4,30,-1,1)
Block(-4,30,0,1)
Block(-4,30,1,1)
Block(-4,30,2,1)
Block(-4,30,3,1)
Block(-4,30,4,1)
Block(-4,30,5,1)
Block(-4,30,6,1)
Block(-4,30,7,1)
Block(-4,30,8,1)
Block(-4,30,9,1)
Block(-4,30,10,1)
Block(-4,30,11,1)
Block(-4,30,12,1)
Block(-4,30,13,1)
Block(-4,31,-6,1)
Block(-4,31,-5,1)
Block(-4,31,-4,1)
Block(-4,31,-3,1)
Block(-4,31,-2,1)
Block(-4,31,-1,1)
Block(-4,31,0,1)
Block(-4,31,1,1)
Block(-4,31,2,1)
Block(-4,31,3,1)
Block(-4,31,4,1)
Block(-4,31,5,1)
Block(-4,31,6,1)
Block(-4,31,7,1)
Block(-4,31,8,1)
Block(-4,31,9,1)
Block(-4,31,10,1)
Block(-4,31,11,1)
Block(-4,31,12,1)
Block(-4,32,-6,1)
Block(-4,32,-5,1)
Block(-4,32,-4,1)
Block(-4,32,-3,1)
Block(-4,32,-2,1)
Block(-4,32,-1,1)
Block(-4,32,0,1)
Block(-4,32,1,1)
Block(-4,32,2,1)
Block(-4,32,3,1)
Block(-4,32,4,1)
Block(-4,32,5,1)
Block(-4,32,6,1)
Block(-4,32,7,1)
Block(-4,32,8,1)
Block(-4,32,9,1)
Block(-4,32,10,1)
Block(-4,32,11,1)
Block(-4,32,12,1)
Block(-4,33,-6,1)
Block(-4,33,-5,1)
Block(-4,33,-4,1)
Block(-4,33,-3,1)
Block(-4,33,-2,1)
Block(-4,33,-1,1)
Block(-4,33,0,1)
Block(-4,33,1,1)
Block(-4,33,2,1)
Block(-4,33,3,1)
Block(-4,33,4,1)
Block(-4,33,5,1)
Block(-4,33,6,1)
Block(-4,33,7,1)
Block(-4,33,8,1)
Block(-4,33,9,1)
Block(-4,33,10,1)
Block(-4,33,11,1)
Block(-4,34,-5,1)
Block(-4,34,-4,1)
Block(-4,34,-3,1)
Block(-4,34,-2,1)
Block(-4,34,-1,1)
Block(-4,34,0,1)
Block(-4,34,1,1)
Block(-4,34,2,1)
Block(-4,34,3,1)
Block(-4,34,4,1)
Block(-4,34,5,1)
Block(-4,34,6,1)
Block(-4,34,7,1)
Block(-4,34,8,1)
Block(-4,34,9,1)
Block(-4,34,10,1)
Block(-4,34,11,1)
Block(-4,35,-5,1)
Block(-4,35,-4,1)
Block(-4,35,-3,1)
Block(-4,35,-2,1)
Block(-4,35,-1,1)
Block(-4,35,0,1)
Block(-4,35,1,1)
Block(-4,35,2,1)
Block(-4,35,3,1)
Block(-4,35,4,1)
Block(-4,35,5,1)
Block(-4,35,6,1)
Block(-4,35,7,1)
Block(-4,35,8,1)
Block(-4,35,9,1)
Block(-4,35,10,1)
Block(-4,35,11,1)
Block(-4,36,-5,1)
Block(-4,36,-4,1)
Block(-4,36,-3,1)
Block(-4,36,-2,1)
Block(-4,36,-1,1)
Block(-4,36,0,1)
Block(-4,36,1,1)
Block(-4,36,2,1)
Block(-4,36,3,1)
Block(-4,36,4,1)
Block(-4,36,5,1)
Block(-4,36,6,1)
Block(-4,36,7,1)
Block(-4,36,8,1)
Block(-4,36,9,1)
Block(-4,36,10,1)
Block(-4,36,11,1)
Block(-4,36,12,1)
Block(-4,37,-5,1)
Block(-4,37,-4,1)
Block(-4,37,-3,1)
Block(-4,37,-2,1)
Block(-4,37,-1,1)
Block(-4,37,0,1)
Block(-4,37,1,1)
Block(-4,37,2,1)
Block(-4,37,3,1)
Block(-4,37,4,1)
Block(-4,37,5,1)
Block(-4,37,6,1)
Block(-4,37,7,1)
Block(-4,37,8,1)
Block(-4,37,9,1)
Block(-4,37,10,1)
Block(-4,37,11,1)
Block(-4,37,12,1)
Block(-4,37,13,1)
Block(-4,38,-4,1)
Block(-4,38,-3,1)
Block(-4,38,-2,1)
Block(-4,38,-1,1)
Block(-4,38,0,1)
Block(-4,38,1,1)
Block(-4,38,2,1)
Block(-4,38,3,1)
Block(-4,38,4,1)
Block(-4,38,5,1)
Block(-4,38,6,1)
Block(-4,38,7,1)
Block(-4,38,8,1)
Block(-4,38,9,1)
Block(-4,38,10,1)
Block(-4,38,11,1)
Block(-4,38,12,1)
Block(-4,38,13,1)
Block(-4,39,-4,1)
Block(-4,39,-3,1)
Block(-4,39,-2,1)
Block(-4,39,-1,1)
Block(-4,39,0,1)
Block(-4,39,1,1)
Block(-4,39,2,1)
Block(-4,39,3,1)
Block(-4,39,4,1)
Block(-4,39,5,1)
Block(-4,39,6,1)
Block(-4,39,7,1)
Block(-4,39,8,1)
Block(-4,39,9,1)
Block(-4,39,10,1)
Block(-4,39,11,1)
Block(-4,39,12,1)
Block(-4,39,13,1)
Block(-4,39,14,1)
Block(-4,40,-4,1)
Block(-4,40,-3,1)
Block(-4,40,-2,1)
Block(-4,40,-1,1)
Block(-4,40,0,1)
Block(-4,40,1,1)
Block(-4,40,2,1)
Block(-4,40,3,1)
Block(-4,40,4,1)
Block(-4,40,5,1)
Block(-4,40,6,1)
Block(-4,40,7,1)
Block(-4,40,8,1)
Block(-4,40,9,1)
Block(-4,40,10,1)
Block(-4,40,11,1)
Block(-4,40,12,1)
Block(-4,40,13,1)
Block(-4,40,14,1)
Block(-4,41,-4,1)
Block(-4,41,-3,1)
Block(-4,41,-2,1)
Block(-4,41,-1,1)
Block(-4,41,0,1)
Block(-4,41,1,1)
Block(-4,41,2,1)
Block(-4,41,3,1)
Block(-4,41,4,1)
Block(-4,41,5,1)
Block(-4,41,6,1)
Block(-4,41,7,1)
Block(-4,41,8,1)
Block(-4,41,9,1)
Block(-4,41,10,1)
Block(-4,41,11,1)
Block(-4,41,12,1)
Block(-4,41,13,1)
Block(-4,42,-4,1)
Block(-4,42,-3,1)
Block(-4,42,-2,1)
Block(-4,42,-1,1)
Block(-4,42,0,1)
Block(-4,42,1,1)
Block(-4,42,2,1)
Block(-4,42,3,1)
Block(-4,42,4,1)
Block(-4,42,5,1)
Block(-4,42,6,1)
Block(-4,42,7,1)
Block(-4,42,8,1)
Block(-4,42,9,1)
Block(-4,42,10,1)
Block(-4,42,11,1)
Block(-4,42,12,1)
Block(-4,42,13,1)
Block(-4,43,-4,1)
Block(-4,43,-3,1)
Block(-4,43,-2,1)
Block(-4,43,-1,1)
Block(-4,43,0,1)
Block(-4,43,1,1)
Block(-4,43,2,1)
Block(-4,43,3,1)
Block(-4,43,4,1)
Block(-4,43,5,1)
Block(-4,43,6,1)
Block(-4,43,7,1)
Block(-4,43,8,1)
Block(-4,43,9,1)
Block(-4,43,10,1)
Block(-4,43,11,1)
Block(-4,43,12,1)
Block(-4,43,13,1)
Block(-4,44,-5,1)
Block(-4,44,-4,1)
Block(-4,44,-3,1)
Block(-4,44,-2,1)
Block(-4,44,-1,1)
Block(-4,44,0,1)
Block(-4,44,1,1)
Block(-4,44,2,1)
Block(-4,44,3,1)
Block(-4,44,4,1)
Block(-4,44,5,1)
Block(-4,44,6,1)
Block(-4,44,7,1)
Block(-4,44,8,1)
Block(-4,44,9,1)
Block(-4,44,10,1)
Block(-4,44,11,1)
Block(-4,44,12,1)
Block(-4,45,-6,1)
Block(-4,45,-5,1)
Block(-4,45,-4,1)
Block(-4,45,-3,1)
Block(-4,45,-2,1)
Block(-4,45,-1,1)
Block(-4,45,0,1)
Block(-4,45,1,1)
Block(-4,45,2,1)
Block(-4,45,3,1)
Block(-4,45,4,1)
Block(-4,45,5,1)
Block(-4,45,6,1)
Block(-4,45,7,1)
Block(-4,45,8,1)
Block(-4,45,9,1)
Block(-4,45,10,1)
Block(-4,45,11,1)
Block(-4,45,12,1)
Block(-4,46,-6,1)
Block(-4,46,-5,1)
Block(-4,46,-4,1)
Block(-4,46,-3,1)
Block(-4,46,-2,1)
Block(-4,46,-1,1)
Block(-4,46,0,1)
Block(-4,46,1,1)
Block(-4,46,2,1)
Block(-4,46,3,1)
Block(-4,46,4,1)
Block(-4,46,5,1)
Block(-4,46,6,1)
Block(-4,46,7,1)
Block(-4,46,8,1)
Block(-4,46,9,1)
Block(-4,46,10,1)
Block(-4,46,11,1)
Block(-4,46,12,1)
Block(-4,47,-6,1)
Block(-4,47,-5,1)
Block(-4,47,-4,1)
Block(-4,47,-3,1)
Block(-4,47,-2,1)
Block(-4,47,-1,1)
Block(-4,47,0,1)
Block(-4,47,1,1)
Block(-4,47,2,1)
Block(-4,47,3,1)
Block(-4,47,4,1)
Block(-4,47,5,1)
Block(-4,47,6,1)
Block(-4,47,7,1)
Block(-4,47,8,1)
Block(-4,47,9,1)
Block(-4,47,10,1)
Block(-4,47,11,1)
Block(-4,47,12,1)
Block(-4,48,-6,1)
Block(-4,48,-5,1)
Block(-4,48,-4,1)
Block(-4,48,-3,1)
Block(-4,48,-2,1)
Block(-4,48,-1,1)
Block(-4,48,0,1)
Block(-4,48,1,1)
Block(-4,48,2,1)
Block(-4,48,3,1)
Block(-4,48,4,1)
Block(-4,48,5,1)
Block(-4,48,6,1)
Block(-4,48,7,1)
Block(-4,48,8,1)
Block(-4,48,9,1)
Block(-4,48,10,1)
Block(-4,48,11,1)
Block(-4,48,12,1)
Block(-4,49,-6,1)
Block(-4,49,-5,1)
Block(-4,49,-4,1)
Block(-4,49,-3,1)
Block(-4,49,-2,1)
Block(-4,49,-1,1)
Block(-4,49,0,1)
Block(-4,49,1,1)
Block(-4,49,2,1)
Block(-4,49,3,1)
Block(-4,49,4,1)
Block(-4,49,5,1)
Block(-4,49,6,1)
Block(-4,49,7,1)
Block(-4,49,8,1)
Block(-4,49,9,1)
Block(-4,49,10,1)
Block(-4,49,11,1)
Block(-4,49,12,1)
Block(-4,50,-6,1)
Block(-4,50,-5,1)
Block(-4,50,-4,1)
Block(-4,50,-3,1)
Block(-4,50,-2,1)
Block(-4,50,-1,1)
Block(-4,50,0,1)
Block(-4,50,1,1)
Block(-4,50,2,1)
Block(-4,50,3,1)
Block(-4,50,4,1)
Block(-4,50,5,1)
Block(-4,50,6,1)
Block(-4,50,7,1)
Block(-4,50,8,1)
Block(-4,50,9,1)
Block(-4,50,10,1)
Block(-4,50,11,1)
Block(-4,50,12,1)
Block(-4,51,-5,1)
Block(-4,51,-4,1)
Block(-4,51,-3,1)
Block(-4,51,-2,1)
Block(-4,51,-1,1)
Block(-4,51,0,1)
Block(-4,51,1,1)
Block(-4,51,2,1)
Block(-4,51,3,1)
Block(-4,51,4,1)
Block(-4,51,5,1)
Block(-4,51,6,1)
Block(-4,51,7,1)
Block(-4,51,8,1)
Block(-4,51,9,1)
Block(-4,51,10,1)
Block(-4,51,11,1)
Block(-4,52,-5,1)
Block(-4,52,-4,1)
Block(-4,52,-3,1)
Block(-4,52,-2,1)
Block(-4,52,-1,1)
Block(-4,52,0,1)
Block(-4,52,1,1)
Block(-4,52,2,1)
Block(-4,52,3,1)
Block(-4,52,4,1)
Block(-4,52,5,1)
Block(-4,52,6,1)
Block(-4,52,7,1)
Block(-4,52,8,1)
Block(-4,52,9,1)
Block(-4,52,10,1)
Block(-4,53,-5,1)
Block(-4,53,-4,1)
Block(-4,53,-3,1)
Block(-4,53,-2,1)
Block(-4,53,-1,1)
Block(-4,53,0,1)
Block(-4,53,1,1)
Block(-4,53,2,1)
Block(-4,53,3,1)
Block(-4,53,4,1)
Block(-4,53,5,1)
Block(-4,53,6,1)
Block(-4,53,7,1)
Block(-4,53,8,1)
Block(-4,53,9,1)
Block(-4,53,10,1)
Block(-4,54,-5,1)
Block(-4,54,-4,1)
Block(-4,54,-3,1)
Block(-4,54,-2,1)
Block(-4,54,-1,1)
Block(-4,54,0,1)
Block(-4,54,1,1)
Block(-4,54,2,1)
Block(-4,54,3,1)
Block(-4,54,4,1)
Block(-4,54,5,1)
Block(-4,54,6,1)
Block(-4,54,7,1)
Block(-4,54,8,1)
Block(-4,54,9,1)
Block(-4,54,10,1)
Block(-4,55,-4,1)
Block(-4,55,-3,1)
Block(-4,55,-2,1)
Block(-4,55,-1,1)
Block(-4,55,0,1)
Block(-4,55,1,1)
Block(-4,55,2,1)
Block(-4,55,3,1)
Block(-4,55,4,1)
Block(-4,55,5,1)
Block(-4,55,6,1)
Block(-4,55,7,1)
Block(-4,55,8,1)
Block(-4,55,9,1)
Block(-4,56,-4,1)
Block(-4,56,-3,1)
Block(-4,56,-2,1)
Block(-4,56,-1,1)
Block(-4,56,0,1)
Block(-4,56,1,1)
Block(-4,56,2,1)
Block(-4,56,3,1)
Block(-4,56,4,1)
Block(-4,56,5,1)
Block(-4,56,6,1)
Block(-4,56,7,1)
Block(-4,56,8,1)
Block(-4,56,9,1)
Block(-4,57,-4,1)
Block(-4,57,-3,1)
Block(-4,57,-2,1)
Block(-4,57,-1,1)
Block(-4,57,0,1)
Block(-4,57,1,1)
Block(-4,57,2,1)
Block(-4,57,3,1)
Block(-4,57,4,1)
Block(-4,57,5,1)
Block(-4,57,6,1)
Block(-4,57,7,1)
Block(-4,57,8,1)
Block(-4,57,9,1)
Block(-4,58,-5,1)
Block(-4,58,-4,1)
Block(-4,58,-3,1)
Block(-4,58,-2,1)
Block(-4,58,-1,1)
Block(-4,58,0,1)
Block(-4,58,1,1)
Block(-4,58,2,1)
Block(-4,58,3,1)
Block(-4,58,4,1)
Block(-4,58,5,1)
Block(-4,58,6,1)
Block(-4,58,7,1)
Block(-4,58,8,1)
Block(-4,58,9,1)
Block(-4,58,10,1)
Block(-4,59,-5,1)
Block(-4,59,-4,1)
Block(-4,59,-3,1)
Block(-4,59,-2,1)
Block(-4,59,-1,1)
Block(-4,59,0,1)
Block(-4,59,1,1)
Block(-4,59,2,1)
Block(-4,59,3,1)
Block(-4,59,4,1)
Block(-4,59,5,1)
Block(-4,59,6,1)
Block(-4,59,7,1)
Block(-4,59,8,1)
Block(-4,59,9,1)
Block(-4,59,10,1)
Block(-4,60,-5,1)
Block(-4,60,-4,1)
Block(-4,60,-3,1)
Block(-4,60,-2,1)
Block(-4,60,-1,1)
Block(-4,60,0,1)
Block(-4,60,1,1)
Block(-4,60,2,1)
Block(-4,60,3,1)
Block(-4,60,4,1)
Block(-4,60,5,1)
Block(-4,60,6,1)
Block(-4,60,7,1)
Block(-4,60,8,1)
Block(-4,60,9,1)
Block(-4,60,10,1)
Block(-4,60,11,1)
Block(-4,61,-5,1)
Block(-4,61,-4,1)
Block(-4,61,-3,1)
Block(-4,61,-2,1)
Block(-4,61,-1,1)
Block(-4,61,0,1)
Block(-4,61,1,1)
Block(-4,61,2,1)
Block(-4,61,3,1)
Block(-4,61,4,1)
Block(-4,61,5,1)
Block(-4,61,6,1)
Block(-4,61,7,1)
Block(-4,61,8,1)
Block(-4,61,9,1)
Block(-4,61,10,1)
Block(-4,61,11,1)
Block(-4,62,-5,1)
Block(-4,62,-4,1)
Block(-4,62,-3,1)
Block(-4,62,-2,1)
Block(-4,62,-1,1)
Block(-4,62,0,1)
Block(-4,62,1,1)
Block(-4,62,2,1)
Block(-4,62,3,1)
Block(-4,62,4,1)
Block(-4,62,5,1)
Block(-4,62,6,1)
Block(-4,62,7,1)
Block(-4,62,8,1)
Block(-4,62,9,1)
Block(-4,62,10,1)
Block(-4,62,11,1)
Block(-4,63,-5,1)
Block(-4,63,-4,1)
Block(-4,63,-3,1)
Block(-4,63,-2,1)
Block(-4,63,-1,1)
Block(-4,63,0,1)
Block(-4,63,1,1)
Block(-4,63,2,1)
Block(-4,63,3,1)
Block(-4,63,4,1)
Block(-4,63,5,1)
Block(-4,63,6,1)
Block(-4,63,7,1)
Block(-4,63,8,1)
Block(-4,63,9,1)
Block(-4,63,10,1)
Block(-4,63,11,1)
Block(-4,64,-5,1)
Block(-4,64,-4,1)
Block(-4,64,-3,1)
Block(-4,64,-2,1)
Block(-4,64,-1,1)
Block(-4,64,0,1)
Block(-4,64,1,1)
Block(-4,64,2,1)
Block(-4,64,3,1)
Block(-4,64,4,1)
Block(-4,64,5,1)
Block(-4,64,6,1)
Block(-4,64,7,1)
Block(-4,64,8,1)
Block(-4,64,9,1)
Block(-4,64,10,1)
Block(-4,65,-5,1)
Block(-4,65,-4,1)
Block(-4,65,-3,1)
Block(-4,65,-2,1)
Block(-4,65,-1,1)
Block(-4,65,0,1)
Block(-4,65,1,1)
Block(-4,65,2,1)
Block(-4,65,3,1)
Block(-4,65,4,1)
Block(-4,65,5,1)
Block(-4,65,6,1)
Block(-4,65,7,1)
Block(-4,65,8,1)
Block(-4,65,9,1)
Block(-4,65,10,1)
Block(-4,66,-6,1)
Block(-4,66,-5,1)
Block(-4,66,-4,1)
Block(-4,66,-3,1)
Block(-4,66,-2,1)
Block(-4,66,-1,1)
Block(-4,66,0,1)
Block(-4,66,1,1)
Block(-4,66,2,1)
Block(-4,66,3,1)
Block(-4,66,4,1)
Block(-4,66,5,1)
Block(-4,66,6,1)
Block(-4,66,7,1)
Block(-4,66,8,1)
Block(-4,66,9,1)
Block(-4,66,10,1)
Block(-4,67,-6,1)
Block(-4,67,-5,1)
Block(-4,67,-4,1)
Block(-4,67,-3,1)
Block(-4,67,-2,1)
Block(-4,67,-1,1)
Block(-4,67,0,1)
Block(-4,67,1,1)
Block(-4,67,2,1)
Block(-4,67,3,1)
Block(-4,67,4,1)
Block(-4,67,5,1)
Block(-4,67,6,1)
Block(-4,67,7,1)
Block(-4,67,8,1)
Block(-4,67,9,1)
Block(-4,67,10,1)
Block(-4,67,11,1)
Block(-4,68,-7,1)
Block(-4,68,-6,1)
Block(-4,68,-5,1)
Block(-4,68,-4,1)
Block(-4,68,-3,1)
Block(-4,68,-2,1)
Block(-4,68,-1,1)
Block(-4,68,0,1)
Block(-4,68,1,1)
Block(-4,68,2,1)
Block(-4,68,3,1)
Block(-4,68,4,1)
Block(-4,68,5,1)
Block(-4,68,6,1)
Block(-4,68,7,1)
Block(-4,68,8,1)
Block(-4,68,9,1)
Block(-4,68,10,1)
Block(-4,68,11,1)
Block(-4,69,-7,1)
Block(-4,69,-6,1)
Block(-4,69,-5,1)
Block(-4,69,-4,1)
Block(-4,69,-3,1)
Block(-4,69,-2,1)
Block(-4,69,-1,1)
Block(-4,69,0,1)
Block(-4,69,1,1)
Block(-4,69,2,1)
Block(-4,69,3,1)
Block(-4,69,4,1)
Block(-4,69,5,1)
Block(-4,69,6,1)
Block(-4,69,7,1)
Block(-4,69,8,1)
Block(-4,69,9,1)
Block(-4,69,10,1)
Block(-4,69,11,1)
Block(-4,70,-7,1)
Block(-4,70,-6,1)
Block(-4,70,-5,1)
Block(-4,70,-4,1)
Block(-4,70,-3,1)
Block(-4,70,-2,1)
Block(-4,70,-1,1)
Block(-4,70,0,1)
Block(-4,70,1,1)
Block(-4,70,2,1)
Block(-4,70,3,1)
Block(-4,70,4,1)
Block(-4,70,5,1)
Block(-4,70,6,1)
Block(-4,70,7,1)
Block(-4,70,8,1)
Block(-4,70,9,1)
Block(-4,70,10,1)
Block(-4,70,11,1)
Block(-4,71,-7,1)
Block(-4,71,-6,1)
Block(-4,71,-5,1)
Block(-4,71,-4,1)
Block(-4,71,-3,1)
Block(-4,71,-2,1)
Block(-4,71,-1,1)
Block(-4,71,0,1)
Block(-4,71,1,1)
Block(-4,71,2,1)
Block(-4,71,3,1)
Block(-4,71,4,1)
Block(-4,71,5,1)
Block(-4,71,6,1)
Block(-4,71,7,1)
Block(-4,71,8,1)
Block(-4,71,9,1)
Block(-4,71,10,1)
Block(-4,71,11,1)
Block(-4,72,-7,1)
Block(-4,72,-6,3)
Block(-4,72,-5,1)
Block(-4,72,-4,1)
Block(-4,72,-3,1)
Block(-4,72,-2,1)
Block(-4,72,-1,1)
Block(-4,72,0,1)
Block(-4,72,1,1)
Block(-4,72,2,1)
Block(-4,72,3,1)
Block(-4,72,4,1)
Block(-4,72,5,1)
Block(-4,72,6,1)
Block(-4,72,7,1)
Block(-4,72,8,1)
Block(-4,72,9,1)
Block(-4,72,10,1)
Block(-4,73,-7,1)
Block(-4,73,-6,3)
Block(-4,73,-5,1)
Block(-4,73,-4,1)
Block(-4,73,-3,1)
Block(-4,73,-2,1)
Block(-4,73,-1,1)
Block(-4,73,0,1)
Block(-4,73,1,1)
Block(-4,73,2,1)
Block(-4,73,3,1)
Block(-4,73,4,1)
Block(-4,73,5,1)
Block(-4,73,6,1)
Block(-4,73,7,1)
Block(-4,73,8,1)
Block(-4,73,9,1)
Block(-4,73,10,1)
Block(-4,74,-6,1)
Block(-4,74,-5,1)
Block(-4,74,-4,1)
Block(-4,74,-3,1)
Block(-4,74,-2,1)
Block(-4,74,-1,1)
Block(-4,74,0,1)
Block(-4,74,1,1)
Block(-4,74,2,1)
Block(-4,74,3,1)
Block(-4,74,4,1)
Block(-4,74,5,1)
Block(-4,74,6,1)
Block(-4,74,7,1)
Block(-4,74,8,1)
Block(-4,74,9,1)
Block(-4,74,10,1)
Block(-4,75,-6,1)
Block(-4,75,-5,1)
Block(-4,75,-4,1)
Block(-4,75,-3,1)
Block(-4,75,-2,1)
Block(-4,75,-1,1)
Block(-4,75,0,1)
Block(-4,75,1,1)
Block(-4,75,2,1)
Block(-4,75,3,1)
Block(-4,75,4,1)
Block(-4,75,5,1)
Block(-4,75,6,1)
Block(-4,75,7,1)
Block(-4,75,8,1)
Block(-4,75,9,1)
Block(-4,75,10,1)
Block(-4,76,-5,1)
Block(-4,76,-4,1)
Block(-4,76,-3,1)
Block(-4,76,-2,1)
Block(-4,76,-1,1)
Block(-4,76,0,1)
Block(-4,76,1,1)
Block(-4,76,2,1)
Block(-4,76,3,1)
Block(-4,76,4,1)
Block(-4,76,5,1)
Block(-4,76,6,1)
Block(-4,76,7,1)
Block(-4,76,8,1)
Block(-4,76,9,1)
Block(-4,76,10,1)
Block(-4,77,-5,1)
Block(-4,77,-4,1)
Block(-4,77,-3,1)
Block(-4,77,-2,1)
Block(-4,77,-1,1)
Block(-4,77,0,1)
Block(-4,77,1,1)
Block(-4,77,2,1)
Block(-4,77,3,1)
Block(-4,77,4,1)
Block(-4,77,5,1)
Block(-4,77,6,1)
Block(-4,77,7,1)
Block(-4,77,8,1)
Block(-4,77,9,1)
Block(-4,77,10,1)
Block(-4,77,11,1)
Block(-4,78,-5,1)
Block(-4,78,-4,1)
Block(-4,78,-3,1)
Block(-4,78,-2,1)
Block(-4,78,-1,1)
Block(-4,78,0,1)
Block(-4,78,1,1)
Block(-4,78,2,1)
Block(-4,78,3,1)
Block(-4,78,4,1)
Block(-4,78,5,1)
Block(-4,78,6,1)
Block(-4,78,7,1)
Block(-4,78,8,1)
Block(-4,78,9,1)
Block(-4,78,10,1)
Block(-4,78,11,1)
Block(-4,79,-5,1)
Block(-4,79,-4,1)
Block(-4,79,-3,1)
Block(-4,79,-2,1)
Block(-4,79,-1,1)
Block(-4,79,0,1)
Block(-4,79,1,1)
Block(-4,79,2,1)
Block(-4,79,3,1)
Block(-4,79,4,1)
Block(-4,79,5,1)
Block(-4,79,6,1)
Block(-4,79,7,1)
Block(-4,79,8,1)
Block(-4,79,9,1)
Block(-4,79,10,1)
Block(-4,79,11,1)
Block(-4,79,12,1)
Block(-4,80,-5,1)
Block(-4,80,-4,1)
Block(-4,80,-3,1)
Block(-4,80,-2,1)
Block(-4,80,-1,1)
Block(-4,80,0,1)
Block(-4,80,1,1)
Block(-4,80,2,1)
Block(-4,80,3,1)
Block(-4,80,4,1)
Block(-4,80,5,1)
Block(-4,80,6,1)
Block(-4,80,7,1)
Block(-4,80,8,1)
Block(-4,80,9,1)
Block(-4,80,10,1)
Block(-4,80,11,1)
Block(-4,80,12,1)
Block(-4,81,-5,1)
Block(-4,81,-4,3)
Block(-4,81,-3,1)
Block(-4,81,-2,1)
Block(-4,81,-1,1)
Block(-4,81,0,1)
Block(-4,81,1,1)
Block(-4,81,2,1)
Block(-4,81,3,1)
Block(-4,81,4,1)
Block(-4,81,5,1)
Block(-4,81,6,1)
Block(-4,81,7,1)
Block(-4,81,8,1)
Block(-4,81,9,1)
Block(-4,81,10,1)
Block(-4,81,11,1)
Block(-4,81,12,1)
Block(-4,82,-5,1)
Block(-4,82,-4,3)
Block(-4,82,-3,3)
Block(-4,82,-2,1)
Block(-4,82,-1,1)
Block(-4,82,0,1)
Block(-4,82,1,1)
Block(-4,82,2,1)
Block(-4,82,3,1)
Block(-4,82,4,1)
Block(-4,82,5,1)
Block(-4,82,6,1)
Block(-4,82,7,1)
Block(-4,82,8,1)
Block(-4,82,9,1)
Block(-4,82,10,1)
Block(-4,82,11,1)
Block(-4,83,-5,1)
Block(-4,83,-4,3)
Block(-4,83,-3,3)
Block(-4,83,-2,1)
Block(-4,83,-1,1)
Block(-4,83,0,1)
Block(-4,83,1,1)
Block(-4,83,2,1)
Block(-4,83,3,1)
Block(-4,83,4,1)
Block(-4,83,5,1)
Block(-4,83,6,1)
Block(-4,83,7,1)
Block(-4,83,8,1)
Block(-4,83,9,1)
Block(-4,83,10,1)
Block(-4,83,11,1)
Block(-4,84,-4,1)
Block(-4,84,-3,3)
Block(-4,84,-2,3)
Block(-4,84,-1,1)
Block(-4,84,0,1)
Block(-4,84,1,1)
Block(-4,84,2,1)
Block(-4,84,3,1)
Block(-4,84,4,1)
Block(-4,84,5,1)
Block(-4,84,6,1)
Block(-4,84,7,1)
Block(-4,84,8,1)
Block(-4,84,9,1)
Block(-4,84,10,1)
Block(-4,84,11,1)
Block(-4,85,-3,1)
Block(-4,85,-2,3)
Block(-4,85,-1,3)
Block(-4,85,0,1)
Block(-4,85,1,1)
Block(-4,85,2,1)
Block(-4,85,3,1)
Block(-4,85,4,1)
Block(-4,85,5,1)
Block(-4,85,6,1)
Block(-4,85,7,1)
Block(-4,85,8,1)
Block(-4,85,9,1)
Block(-4,85,10,1)
Block(-4,85,11,1)
Block(-4,86,-2,1)
Block(-4,86,-1,3)
Block(-4,86,0,3)
Block(-4,86,1,1)
Block(-4,86,2,1)
Block(-4,86,3,1)
Block(-4,86,4,1)
Block(-4,86,5,1)
Block(-4,86,6,1)
Block(-4,86,7,1)
Block(-4,86,8,1)
Block(-4,86,9,1)
Block(-4,86,10,3)
Block(-4,86,11,1)
Block(-4,87,-2,1)
Block(-4,87,-1,3)
Block(-4,87,0,3)
Block(-4,87,1,1)
Block(-4,87,2,1)
Block(-4,87,3,1)
Block(-4,87,4,1)
Block(-4,87,5,1)
Block(-4,87,6,1)
Block(-4,87,7,1)
Block(-4,87,8,1)
Block(-4,87,9,3)
Block(-4,87,10,3)
Block(-4,87,11,1)
Block(-4,88,-1,1)
Block(-4,88,0,3)
Block(-4,88,1,3)
Block(-4,88,2,3)
Block(-4,88,3,1)
Block(-4,88,4,1)
Block(-4,88,5,3)
Block(-4,88,6,3)
Block(-4,88,7,3)
Block(-4,88,8,3)
Block(-4,88,9,3)
Block(-4,88,10,3)
Block(-4,88,11,1)
Block(-4,89,0,1)
Block(-4,89,1,3)
Block(-4,89,2,3)
Block(-4,89,3,3)
Block(-4,89,4,3)
Block(-4,89,5,3)
Block(-4,89,6,3)
Block(-4,89,7,3)
Block(-4,89,8,3)
Block(-4,89,9,3)
Block(-4,89,10,2)
Block(-4,90,1,1)
Block(-4,90,2,3)
Block(-4,90,3,3)
Block(-4,90,4,3)
Block(-4,90,5,3)
Block(-4,90,6,3)
Block(-4,90,7,3)
Block(-4,90,8,3)
Block(-4,90,9,2)
Block(-4,91,1,1)
Block(-4,91,2,2)
Block(-4,91,3,3)
Block(-4,91,4,3)
Block(-4,91,5,2)
Block(-4,91,6,2)
Block(-4,91,7,2)
Block(-4,91,8,2)
Block(-4,92,3,2)
Block(-4,92,4,2)
Block(-3,0,-6,1)
Block(-3,0,-5,1)
Block(-3,0,-4,1)
Block(-3,0,-3,1)
Block(-3,0,-2,1)
Block(-3,0,-1,1)
Block(-3,0,0,1)
Block(-3,0,1,1)
Block(-3,0,2,1)
Block(-3,0,3,1)
Block(-3,0,4,1)
Block(-3,0,5,1)
Block(-3,0,6,1)
Block(-3,0,7,1)
Block(-3,0,8,1)
Block(-3,0,9,1)
Block(-3,0,10,1)
Block(-3,0,11,1)
Block(-3,0,12,1)
Block(-3,0,13,1)
Block(-3,1,-5,1)
Block(-3,1,-4,1)
Block(-3,1,-3,1)
Block(-3,1,-2,1)
Block(-3,1,-1,1)
Block(-3,1,0,1)
Block(-3,1,1,1)
Block(-3,1,2,1)
Block(-3,1,3,1)
Block(-3,1,4,1)
Block(-3,1,5,1)
Block(-3,1,6,1)
Block(-3,1,7,1)
Block(-3,1,8,1)
Block(-3,1,9,1)
Block(-3,1,10,1)
Block(-3,1,11,1)
Block(-3,1,12,1)
Block(-3,1,13,1)
Block(-3,2,-5,1)
Block(-3,2,-4,1)
Block(-3,2,-3,1)
Block(-3,2,-2,1)
Block(-3,2,-1,1)
Block(-3,2,0,1)
Block(-3,2,1,1)
Block(-3,2,2,1)
Block(-3,2,3,1)
Block(-3,2,4,1)
Block(-3,2,5,1)
Block(-3,2,6,1)
Block(-3,2,7,1)
Block(-3,2,8,1)
Block(-3,2,9,1)
Block(-3,2,10,1)
Block(-3,2,11,1)
Block(-3,2,12,1)
Block(-3,2,13,1)
Block(-3,3,-5,1)
Block(-3,3,-4,1)
Block(-3,3,-3,1)
Block(-3,3,-2,1)
Block(-3,3,-1,1)
Block(-3,3,0,1)
Block(-3,3,1,1)
Block(-3,3,2,1)
Block(-3,3,3,1)
Block(-3,3,4,1)
Block(-3,3,5,1)
Block(-3,3,6,1)
Block(-3,3,7,1)
Block(-3,3,8,1)
Block(-3,3,9,1)
Block(-3,3,10,1)
Block(-3,3,11,1)
Block(-3,3,12,1)
Block(-3,3,13,1)
Block(-3,4,-5,1)
Block(-3,4,-4,1)
Block(-3,4,-3,1)
Block(-3,4,-2,1)
Block(-3,4,-1,1)
Block(-3,4,0,1)
Block(-3,4,1,1)
Block(-3,4,2,1)
Block(-3,4,3,1)
Block(-3,4,4,1)
Block(-3,4,5,1)
Block(-3,4,6,1)
Block(-3,4,7,1)
Block(-3,4,8,1)
Block(-3,4,9,1)
Block(-3,4,10,1)
Block(-3,4,11,1)
Block(-3,4,12,1)
Block(-3,4,13,1)
Block(-3,5,-5,1)
Block(-3,5,-4,1)
Block(-3,5,-3,1)
Block(-3,5,-2,1)
Block(-3,5,-1,1)
Block(-3,5,0,1)
Block(-3,5,1,1)
Block(-3,5,2,1)
Block(-3,5,3,1)
Block(-3,5,4,1)
Block(-3,5,5,1)
Block(-3,5,6,1)
Block(-3,5,7,1)
Block(-3,5,8,1)
Block(-3,5,9,1)
Block(-3,5,10,1)
Block(-3,5,11,1)
Block(-3,5,12,1)
Block(-3,5,13,1)
Block(-3,5,14,1)
Block(-3,6,-5,1)
Block(-3,6,-4,1)
Block(-3,6,-3,1)
Block(-3,6,-2,1)
Block(-3,6,-1,1)
Block(-3,6,0,1)
Block(-3,6,1,1)
Block(-3,6,2,1)
Block(-3,6,3,1)
Block(-3,6,4,1)
Block(-3,6,5,1)
Block(-3,6,6,1)
Block(-3,6,7,1)
Block(-3,6,8,1)
Block(-3,6,9,1)
Block(-3,6,10,1)
Block(-3,6,11,1)
Block(-3,6,12,1)
Block(-3,6,13,1)
Block(-3,6,14,1)
Block(-3,7,-5,1)
Block(-3,7,-4,1)
Block(-3,7,-3,1)
Block(-3,7,-2,1)
Block(-3,7,-1,1)
Block(-3,7,0,1)
Block(-3,7,1,1)
Block(-3,7,2,1)
Block(-3,7,3,1)
Block(-3,7,4,1)
Block(-3,7,5,1)
Block(-3,7,6,1)
Block(-3,7,7,1)
Block(-3,7,8,1)
Block(-3,7,9,1)
Block(-3,7,10,1)
Block(-3,7,11,1)
Block(-3,7,12,1)
Block(-3,7,13,1)
Block(-3,7,14,1)
Block(-3,8,-5,1)
Block(-3,8,-4,1)
Block(-3,8,-3,1)
Block(-3,8,-2,1)
Block(-3,8,-1,1)
Block(-3,8,0,1)
Block(-3,8,1,1)
Block(-3,8,2,1)
Block(-3,8,3,1)
Block(-3,8,4,1)
Block(-3,8,5,1)
Block(-3,8,6,1)
Block(-3,8,7,1)
Block(-3,8,8,1)
Block(-3,8,9,1)
Block(-3,8,10,1)
Block(-3,8,11,1)
Block(-3,8,12,1)
Block(-3,8,13,1)
Block(-3,8,14,1)
Block(-3,9,-5,1)
Block(-3,9,-4,1)
Block(-3,9,-3,1)
Block(-3,9,-2,1)
Block(-3,9,-1,1)
Block(-3,9,0,1)
Block(-3,9,1,1)
Block(-3,9,2,1)
