#######################################################################
# +-----------------------------------------------------------------+ #
# |                            BO3 object                           | #
# +-----------------------------------------------------------------+ #
#######################################################################

# The descriptions in this file are accurate only for TerrainControl and OTG.
# For MCW and OTG+ these descriptions are only accurate if the BO3 is used as a CustomObject.
# MCW and OTG+ completely reimplemented CustomStructure, check the MCW/OTG+ documentation for more information.

# This is the config file of a custom object.
# If you add this object correctly to your BiomeConfigs, it will spawn in the world.

# This is the creator of this BO3 object
Author: Unknown

# A short description of this BO3 object
Description: This BO3 was converted from a schematic using OTGEdit. The author and description information of the schematic could not be found. If you know who the author of the schematic is then please add this information.

# The BO3 version, don't change this! It can be used by external applications to do a version check.
Version: 3

# The settings mode, WriteAll, WriteWithoutComments or WriteDisable. See WorldConfig.
SettingsMode: WriteDisable

#######################################################################
# +-----------------------------------------------------------------+ #
# |                          Main settings                          | #
# +-----------------------------------------------------------------+ #
#######################################################################

# This needs to be set to true to spawn the object in the Tree and Sapling resources.
Tree: false

# The frequency of the BO3 from 1 to 200. Tries this many times to spawn this BO3 when using the CustomObject(...) resource.
# Ignored by Tree(..), Sapling(..) and CustomStructure(..)
Frequency: 40

# The rarity of the BO3 from 0 to 100. Each spawn attempt has rarity% chance to succeed when using the CustomObject(...) resource.
# Ignored by Tree(..), Sapling(..) and CustomStructure(..)
Rarity: 100.0

# If you set this to true, the BO3 will be placed with a random rotation.
RotateRandomly: false

# The spawn height of the BO3 - randomY, highestBlock or highestSolidBlock.
SpawnHeight: highestBlock

# The height limits for the BO3.
MinHeight: 0

MaxHeight: 256

# Objects can have other objects attached to it: branches. Branches can also
# have branches attached to it, which can also have branches, etc. This is the
# maximum branch depth for this objects.
MaxBranchDepth: 10

# When spawned with the UseWorld keyword, this BO3 should NOT spawn in the following biomes.
# If you writer.write the BO3 name directly in the BiomeConfigs, this will be ignored.
ExcludedBiomes: All

# To optimise this BO3 for faster loading times you can use Notepad++ to find/replace comments and abbreviate things.
# Notepad++ find/replace with regex:
# Find: ^[#;].* replace to nothing removes all lines starting with # 
# Find: ^\s*$ replace to nothing removes most empty lines 
# Notepad++ find/replace without regex:
# *Warning: This will only work for OTG 1.10.2 v21 / OTG 1.11.2 v6 or higher. B( is not recognised by lower versions.
# Find: Block( replace to B(

#######################################################################
# +-----------------------------------------------------------------+ #
# |                      Source block settings                      | #
# +-----------------------------------------------------------------+ #
#######################################################################

# The block(s) the BO3 should spawn in.
SourceBlocks: AIR

# The maximum percentage of the BO3 that can be outside the SourceBlock.
# The BO3 won't be placed on a location with more blocks outside the SourceBlock than this percentage.
MaxPercentageOutsideSourceBlock: 100

# What to do when a block is about to be placed outside the SourceBlock? (dontPlace, placeAnyway)
OutsideSourceBlock: placeAnyway

#######################################################################
# +-----------------------------------------------------------------+ #
# |                              Blocks                             | #
# +-----------------------------------------------------------------+ #
#######################################################################

# All the blocks used in the BO3 are listed here. Possible blocks:
# Block(x,y,z,id[.data][,nbtfile.nbt) or B(x,y,z,id[.data][,nbtfile.nbt)
# RandomBlock(x,y,z,id[:data][,nbtfile.nbt],chance[,id[:data][,nbtfile.nbt],chance[,...]])
# So RandomBlock(0,0,0,CHEST,chest.nbt,50,CHEST,anotherchest.nbt,100) will spawn a chest at
# the BO3 origin, and give it a 50% chance to have the contents of chest.nbt, or, if that
# fails, a 100% percent chance to have the contents of anotherchest.nbt.

Block(-13,39,1,1)
Block(-13,39,2,1)
Block(-13,40,1,1)
Block(-13,40,2,1)
Block(-13,41,0,1)
Block(-13,41,1,1)
Block(-13,41,2,1)
Block(-13,42,-1,1)
Block(-13,42,0,1)
Block(-13,42,1,1)
Block(-13,42,2,1)
Block(-13,43,-1,1)
Block(-13,43,0,1)
Block(-13,43,1,1)
Block(-12,25,0,1)
Block(-12,25,1,1)
Block(-12,25,2,1)
Block(-12,26,0,1)
Block(-12,26,1,1)
Block(-12,26,2,1)
Block(-12,27,0,1)
Block(-12,27,1,1)
Block(-12,27,2,1)
Block(-12,28,1,1)
Block(-12,28,2,1)
Block(-12,29,1,1)
Block(-12,38,1,1)
Block(-12,38,2,1)
Block(-12,39,0,1)
Block(-12,39,1,1)
Block(-12,39,2,1)
Block(-12,39,3,1)
Block(-12,40,0,1)
Block(-12,40,1,1)
Block(-12,40,2,1)
Block(-12,40,3,1)
Block(-12,40,4,1)
Block(-12,41,-1,1)
Block(-12,41,0,1)
Block(-12,41,1,1)
Block(-12,41,2,1)
Block(-12,41,3,1)
Block(-12,41,4,1)
Block(-12,42,-2,1)
Block(-12,42,-1,1)
Block(-12,42,0,1)
Block(-12,42,1,1)
Block(-12,42,2,1)
Block(-12,42,3,1)
Block(-12,42,4,1)
Block(-12,42,5,1)
Block(-12,43,-2,1)
Block(-12,43,-1,1)
Block(-12,43,0,1)
Block(-12,43,1,1)
Block(-12,43,2,1)
Block(-12,43,3,1)
Block(-12,43,4,1)
Block(-12,44,-1,1)
Block(-12,44,0,1)
Block(-12,44,1,1)
Block(-12,44,2,1)
Block(-12,44,3,1)
Block(-12,45,2,1)
Block(-12,45,3,1)
Block(-11,0,-2,1)
Block(-11,0,-1,1)
Block(-11,0,0,1)
Block(-11,0,1,1)
Block(-11,0,2,1)
Block(-11,1,-1,1)
Block(-11,1,0,1)
Block(-11,1,1,1)
Block(-11,1,2,1)
Block(-11,1,3,1)
Block(-11,2,0,1)
Block(-11,2,1,1)
Block(-11,2,2,1)
Block(-11,3,1,1)
Block(-11,3,2,1)
Block(-11,8,1,1)
Block(-11,8,2,1)
Block(-11,8,3,1)
Block(-11,9,1,1)
Block(-11,9,2,1)
Block(-11,9,3,1)
Block(-11,9,4,1)
Block(-11,10,2,1)
Block(-11,10,3,1)
Block(-11,10,4,1)
Block(-11,11,3,1)
Block(-11,20,5,1)
Block(-11,21,4,1)
Block(-11,22,3,1)
Block(-11,22,4,1)
Block(-11,23,-1,1)
Block(-11,23,0,1)
Block(-11,23,1,1)
Block(-11,23,2,1)
Block(-11,23,3,1)
Block(-11,23,4,1)
Block(-11,24,-2,1)
Block(-11,24,-1,1)
Block(-11,24,0,1)
Block(-11,24,1,1)
Block(-11,24,2,1)
Block(-11,24,3,1)
Block(-11,24,4,1)
Block(-11,25,-2,1)
Block(-11,25,-1,1)
Block(-11,25,0,1)
Block(-11,25,1,1)
Block(-11,25,2,1)
Block(-11,25,3,1)
Block(-11,25,4,1)
Block(-11,26,-1,1)
Block(-11,26,0,1)
Block(-11,26,1,1)
Block(-11,26,2,1)
Block(-11,26,3,1)
Block(-11,26,4,1)
Block(-11,27,-1,1)
Block(-11,27,0,1)
Block(-11,27,1,1)
Block(-11,27,2,1)
Block(-11,27,3,1)
Block(-11,28,-1,1)
Block(-11,28,0,1)
Block(-11,28,1,1)
Block(-11,28,2,1)
Block(-11,28,3,1)
Block(-11,29,-1,1)
Block(-11,29,0,1)
Block(-11,29,1,1)
Block(-11,29,2,1)
Block(-11,29,3,1)
Block(-11,30,0,1)
Block(-11,30,1,1)
Block(-11,30,2,1)
Block(-11,31,0,1)
Block(-11,31,1,1)
Block(-11,31,2,1)
Block(-11,32,0,1)
Block(-11,32,1,1)
Block(-11,32,2,1)
Block(-11,33,0,1)
Block(-11,33,1,1)
Block(-11,33,2,1)
Block(-11,36,1,1)
Block(-11,37,0,1)
Block(-11,37,1,1)
Block(-11,37,2,1)
Block(-11,38,0,1)
Block(-11,38,1,1)
Block(-11,38,2,1)
Block(-11,38,3,1)
Block(-11,39,-1,1)
Block(-11,39,0,1)
Block(-11,39,1,1)
Block(-11,39,2,1)
Block(-11,39,3,1)
Block(-11,39,4,1)
Block(-11,40,-1,1)
Block(-11,40,0,1)
Block(-11,40,1,1)
Block(-11,40,2,1)
Block(-11,40,3,1)
Block(-11,40,4,1)
Block(-11,40,5,1)
Block(-11,41,-2,1)
Block(-11,41,-1,1)
Block(-11,41,0,1)
Block(-11,41,1,1)
Block(-11,41,2,1)
Block(-11,41,3,1)
Block(-11,41,4,1)
Block(-11,41,5,1)
Block(-11,41,6,1)
Block(-11,42,-3,1)
Block(-11,42,-2,1)
Block(-11,42,-1,1)
Block(-11,42,0,1)
Block(-11,42,1,1)
Block(-11,42,2,1)
Block(-11,42,3,1)
Block(-11,42,4,1)
Block(-11,42,5,1)
Block(-11,42,6,1)
Block(-11,43,-3,1)
Block(-11,43,-2,1)
Block(-11,43,-1,1)
Block(-11,43,0,1)
Block(-11,43,1,1)
Block(-11,43,2,1)
Block(-11,43,3,1)
Block(-11,43,4,1)
Block(-11,43,5,1)
Block(-11,44,-3,1)
Block(-11,44,-2,1)
Block(-11,44,-1,1)
Block(-11,44,0,1)
Block(-11,44,1,1)
Block(-11,44,2,1)
Block(-11,44,3,1)
Block(-11,44,4,1)
Block(-11,44,5,1)
Block(-11,45,-2,1)
Block(-11,45,-1,1)
Block(-11,45,0,1)
Block(-11,45,1,1)
Block(-11,45,2,1)
Block(-11,45,3,1)
Block(-11,45,4,1)
Block(-11,46,1,1)
Block(-11,46,2,1)
Block(-11,46,3,1)
Block(-11,55,1,1)
Block(-11,55,2,1)
Block(-11,56,0,1)
Block(-11,56,1,1)
Block(-11,56,2,1)
Block(-11,57,0,1)
Block(-11,57,1,1)
Block(-11,57,2,1)
Block(-11,58,-1,1)
Block(-11,58,0,1)
Block(-11,58,1,1)
Block(-11,58,2,1)
Block(-11,59,-1,1)
Block(-11,59,0,1)
Block(-11,59,1,1)
Block(-11,59,2,1)
Block(-11,60,-1,1)
Block(-11,60,0,1)
Block(-11,60,1,1)
Block(-11,60,2,1)
Block(-11,61,0,1)
Block(-11,61,1,1)
Block(-11,61,2,1)
Block(-11,70,-1,1)
Block(-11,70,0,1)
Block(-11,70,1,1)
Block(-11,71,-2,1)
Block(-11,71,-1,1)
Block(-11,71,0,1)
Block(-11,71,1,1)
Block(-11,71,2,1)
Block(-11,72,-3,1)
Block(-11,72,-2,1)
Block(-11,72,-1,1)
Block(-11,72,0,1)
Block(-11,72,1,1)
Block(-11,73,-3,1)
Block(-11,73,-2,1)
Block(-11,73,-1,1)
Block(-11,73,0,1)
Block(-11,73,1,1)
Block(-11,74,-2,1)
Block(-11,74,-1,1)
Block(-11,74,0,1)
Block(-11,74,1,1)
Block(-11,75,-2,1)
Block(-11,75,-1,1)
Block(-11,75,0,1)
Block(-11,76,-1,1)
Block(-11,76,0,1)
Block(-10,0,-4,1)
Block(-10,0,-3,1)
Block(-10,0,-2,1)
Block(-10,0,-1,1)
Block(-10,0,0,1)
Block(-10,0,1,1)
Block(-10,0,2,1)
Block(-10,0,3,1)
Block(-10,0,4,1)
Block(-10,0,5,1)
Block(-10,1,-3,1)
Block(-10,1,-2,1)
Block(-10,1,-1,1)
Block(-10,1,0,1)
Block(-10,1,1,1)
Block(-10,1,2,1)
Block(-10,1,3,1)
Block(-10,1,4,1)
Block(-10,2,-2,1)
Block(-10,2,-1,1)
Block(-10,2,0,1)
Block(-10,2,1,1)
Block(-10,2,2,1)
Block(-10,2,3,1)
Block(-10,2,4,1)
Block(-10,3,-1,1)
Block(-10,3,0,1)
Block(-10,3,1,1)
Block(-10,3,2,1)
Block(-10,3,3,1)
Block(-10,4,-1,1)
Block(-10,4,0,1)
Block(-10,4,1,1)
Block(-10,4,2,1)
Block(-10,4,3,1)
Block(-10,5,-1,1)
Block(-10,5,0,1)
Block(-10,5,1,1)
Block(-10,5,2,1)
Block(-10,5,3,1)
Block(-10,6,-1,1)
Block(-10,6,0,1)
Block(-10,6,1,1)
Block(-10,6,2,1)
Block(-10,6,3,1)
Block(-10,7,-2,1)
Block(-10,7,-1,1)
Block(-10,7,0,1)
Block(-10,7,1,1)
Block(-10,7,2,1)
Block(-10,7,3,1)
Block(-10,7,4,1)
Block(-10,8,-2,1)
Block(-10,8,-1,1)
Block(-10,8,0,1)
Block(-10,8,1,1)
Block(-10,8,2,1)
Block(-10,8,3,1)
Block(-10,8,4,1)
Block(-10,8,5,1)
Block(-10,9,-1,1)
Block(-10,9,0,1)
Block(-10,9,1,1)
Block(-10,9,2,1)
Block(-10,9,3,1)
Block(-10,9,4,1)
Block(-10,9,5,1)
Block(-10,10,0,1)
Block(-10,10,1,1)
Block(-10,10,2,1)
Block(-10,10,3,1)
Block(-10,10,4,1)
Block(-10,10,5,1)
Block(-10,11,0,1)
Block(-10,11,1,1)
Block(-10,11,2,1)
Block(-10,11,3,1)
Block(-10,11,4,1)
Block(-10,11,5,1)
Block(-10,12,1,1)
Block(-10,12,2,1)
Block(-10,12,3,1)
Block(-10,12,4,1)
Block(-10,12,5,1)
Block(-10,13,2,1)
Block(-10,13,3,1)
Block(-10,13,4,1)
Block(-10,13,5,1)
Block(-10,14,3,1)
Block(-10,14,4,1)
Block(-10,14,5,1)
Block(-10,15,3,1)
Block(-10,15,4,1)
Block(-10,16,3,1)
Block(-10,16,4,1)
Block(-10,17,2,1)
Block(-10,17,3,1)
Block(-10,17,4,1)
Block(-10,18,2,1)
Block(-10,18,3,1)
Block(-10,18,4,1)
Block(-10,18,5,1)
Block(-10,19,2,1)
Block(-10,19,3,1)
Block(-10,19,4,1)
Block(-10,19,5,1)
Block(-10,19,6,1)
Block(-10,20,1,1)
Block(-10,20,2,1)
Block(-10,20,3,1)
Block(-10,20,4,1)
Block(-10,20,5,1)
Block(-10,20,6,1)
Block(-10,21,1,1)
Block(-10,21,2,1)
Block(-10,21,3,1)
Block(-10,21,4,1)
Block(-10,21,5,1)
Block(-10,21,6,1)
Block(-10,22,-2,1)
Block(-10,22,-1,1)
Block(-10,22,0,1)
Block(-10,22,1,1)
Block(-10,22,2,1)
Block(-10,22,3,1)
Block(-10,22,4,1)
Block(-10,22,5,1)
Block(-10,23,-3,1)
Block(-10,23,-2,1)
Block(-10,23,-1,1)
Block(-10,23,0,1)
Block(-10,23,1,1)
Block(-10,23,2,1)
Block(-10,23,3,1)
Block(-10,23,4,1)
Block(-10,23,5,1)
Block(-10,24,-3,1)
Block(-10,24,-2,1)
Block(-10,24,-1,1)
Block(-10,24,0,1)
Block(-10,24,1,1)
Block(-10,24,2,1)
Block(-10,24,3,1)
Block(-10,24,4,1)
Block(-10,24,5,1)
Block(-10,25,-3,1)
Block(-10,25,-2,1)
Block(-10,25,-1,1)
Block(-10,25,0,1)
Block(-10,25,1,1)
Block(-10,25,2,1)
Block(-10,25,3,1)
Block(-10,25,4,1)
Block(-10,25,5,1)
Block(-10,26,-3,1)
Block(-10,26,-2,1)
Block(-10,26,-1,1)
Block(-10,26,0,1)
Block(-10,26,1,1)
Block(-10,26,2,1)
Block(-10,26,3,1)
Block(-10,26,4,1)
Block(-10,26,5,1)
Block(-10,27,-2,1)
Block(-10,27,-1,1)
Block(-10,27,0,1)
Block(-10,27,1,1)
Block(-10,27,2,1)
Block(-10,27,3,1)
Block(-10,27,4,1)
Block(-10,27,5,1)
Block(-10,28,-2,1)
Block(-10,28,-1,1)
Block(-10,28,0,1)
Block(-10,28,1,1)
Block(-10,28,2,1)
Block(-10,28,3,1)
Block(-10,28,4,1)
Block(-10,29,-2,1)
Block(-10,29,-1,1)
Block(-10,29,0,1)
Block(-10,29,1,1)
Block(-10,29,2,1)
Block(-10,29,3,1)
Block(-10,29,4,1)
Block(-10,30,-2,1)
Block(-10,30,-1,1)
Block(-10,30,0,1)
Block(-10,30,1,1)
Block(-10,30,2,1)
Block(-10,30,3,1)
Block(-10,30,4,1)
Block(-10,31,-1,1)
Block(-10,31,0,1)
Block(-10,31,1,1)
Block(-10,31,2,1)
Block(-10,31,3,1)
Block(-10,31,4,1)
Block(-10,32,-1,1)
Block(-10,32,0,1)
Block(-10,32,1,1)
Block(-10,32,2,1)
Block(-10,32,3,1)
Block(-10,33,-1,1)
Block(-10,33,0,1)
Block(-10,33,1,1)
Block(-10,33,2,1)
Block(-10,33,3,1)
Block(-10,34,0,1)
Block(-10,34,1,1)
Block(-10,34,2,1)
Block(-10,34,3,1)
Block(-10,35,0,1)
Block(-10,35,1,1)
Block(-10,35,2,1)
Block(-10,35,3,1)
Block(-10,36,0,1)
Block(-10,36,1,1)
Block(-10,36,2,1)
Block(-10,37,-1,1)
Block(-10,37,0,1)
Block(-10,37,1,1)
Block(-10,37,2,1)
Block(-10,37,3,1)
Block(-10,38,-1,1)
Block(-10,38,0,1)
Block(-10,38,1,1)
Block(-10,38,2,1)
Block(-10,38,3,1)
Block(-10,38,4,1)
Block(-10,39,-2,1)
Block(-10,39,-1,1)
Block(-10,39,0,1)
Block(-10,39,1,1)
Block(-10,39,2,1)
Block(-10,39,3,1)
Block(-10,39,4,1)
Block(-10,39,5,1)
Block(-10,40,-3,1)
Block(-10,40,-2,1)
Block(-10,40,-1,1)
Block(-10,40,0,1)
Block(-10,40,1,1)
Block(-10,40,2,1)
Block(-10,40,3,1)
Block(-10,40,4,1)
Block(-10,40,5,1)
Block(-10,40,6,1)
Block(-10,41,-4,1)
Block(-10,41,-3,1)
Block(-10,41,-2,1)
Block(-10,41,-1,1)
Block(-10,41,0,1)
Block(-10,41,1,1)
Block(-10,41,2,1)
Block(-10,41,3,1)
Block(-10,41,4,1)
Block(-10,41,5,1)
Block(-10,41,6,1)
Block(-10,41,7,1)
Block(-10,42,-4,1)
Block(-10,42,-3,1)
Block(-10,42,-2,1)
Block(-10,42,-1,1)
Block(-10,42,0,1)
Block(-10,42,1,1)
Block(-10,42,2,1)
Block(-10,42,3,1)
Block(-10,42,4,1)
Block(-10,42,5,1)
Block(-10,42,6,1)
Block(-10,42,7,1)
Block(-10,43,-4,1)
Block(-10,43,-3,1)
Block(-10,43,-2,1)
Block(-10,43,-1,1)
Block(-10,43,0,1)
Block(-10,43,1,1)
Block(-10,43,2,1)
Block(-10,43,3,1)
Block(-10,43,4,1)
Block(-10,43,5,1)
Block(-10,43,6,1)
Block(-10,44,-4,1)
Block(-10,44,-3,1)
Block(-10,44,-2,1)
Block(-10,44,-1,1)
Block(-10,44,0,1)
Block(-10,44,1,1)
Block(-10,44,2,1)
Block(-10,44,3,1)
Block(-10,44,4,1)
Block(-10,44,5,1)
Block(-10,45,-3,1)
Block(-10,45,-2,1)
Block(-10,45,-1,1)
Block(-10,45,0,1)
Block(-10,45,1,1)
Block(-10,45,2,1)
Block(-10,45,3,1)
Block(-10,45,4,1)
Block(-10,45,5,1)
Block(-10,46,-2,1)
Block(-10,46,-1,1)
Block(-10,46,0,1)
Block(-10,46,1,1)
Block(-10,46,2,1)
Block(-10,46,3,1)
Block(-10,46,4,1)
Block(-10,47,0,1)
Block(-10,47,1,1)
Block(-10,47,2,1)
Block(-10,47,3,1)
Block(-10,47,4,1)
Block(-10,48,1,1)
Block(-10,48,2,1)
Block(-10,48,3,1)
Block(-10,49,2,1)
Block(-10,49,3,1)
Block(-10,50,1,1)
Block(-10,50,2,1)
Block(-10,50,3,1)
Block(-10,51,0,1)
Block(-10,51,1,1)
Block(-10,51,2,1)
Block(-10,51,3,1)
Block(-10,52,0,1)
Block(-10,52,1,1)
Block(-10,52,2,1)
Block(-10,52,3,1)
Block(-10,53,0,1)
Block(-10,53,1,1)
Block(-10,53,2,1)
Block(-10,53,3,1)
Block(-10,54,0,1)
Block(-10,54,1,1)
Block(-10,54,2,1)
Block(-10,54,3,1)
Block(-10,55,-1,1)
Block(-10,55,0,1)
Block(-10,55,1,1)
Block(-10,55,2,1)
Block(-10,55,3,1)
Block(-10,56,-2,1)
Block(-10,56,-1,1)
Block(-10,56,0,1)
Block(-10,56,1,1)
Block(-10,56,2,1)
Block(-10,56,3,1)
Block(-10,57,-3,1)
Block(-10,57,-2,1)
Block(-10,57,-1,1)
Block(-10,57,0,1)
Block(-10,57,1,1)
Block(-10,57,2,1)
Block(-10,57,3,1)
Block(-10,58,-3,1)
Block(-10,58,-2,1)
Block(-10,58,-1,1)
Block(-10,58,0,1)
Block(-10,58,1,1)
Block(-10,58,2,1)
Block(-10,58,3,1)
Block(-10,59,-3,1)
Block(-10,59,-2,1)
Block(-10,59,-1,1)
Block(-10,59,0,1)
Block(-10,59,1,1)
Block(-10,59,2,1)
Block(-10,59,3,1)
Block(-10,59,4,1)
Block(-10,60,-2,1)
Block(-10,60,-1,1)
Block(-10,60,0,1)
Block(-10,60,1,1)
Block(-10,60,2,1)
Block(-10,60,3,1)
Block(-10,60,4,1)
Block(-10,61,-2,1)
Block(-10,61,-1,1)
Block(-10,61,0,1)
Block(-10,61,1,1)
Block(-10,61,2,1)
Block(-10,61,3,1)
Block(-10,61,4,1)
Block(-10,62,-1,1)
Block(-10,62,0,1)
Block(-10,62,1,1)
Block(-10,62,2,1)
Block(-10,62,3,1)
Block(-10,63,0,1)
Block(-10,63,1,1)
Block(-10,63,2,1)
Block(-10,64,0,1)
Block(-10,64,1,1)
Block(-10,64,2,1)
Block(-10,65,1,1)
Block(-10,65,2,1)
Block(-10,66,1,1)
Block(-10,66,2,1)
Block(-10,67,0,1)
Block(-10,67,1,1)
Block(-10,67,2,1)
Block(-10,68,-1,1)
Block(-10,68,0,1)
Block(-10,68,1,1)
Block(-10,68,2,1)
Block(-10,68,3,1)
Block(-10,69,-2,1)
Block(-10,69,-1,1)
Block(-10,69,0,1)
Block(-10,69,1,1)
Block(-10,69,2,1)
Block(-10,69,3,1)
Block(-10,70,-3,1)
Block(-10,70,-2,1)
Block(-10,70,-1,1)
Block(-10,70,0,1)
Block(-10,70,1,1)
Block(-10,70,2,1)
Block(-10,70,3,1)
Block(-10,70,4,1)
Block(-10,71,-4,1)
Block(-10,71,-3,1)
Block(-10,71,-2,1)
Block(-10,71,-1,1)
Block(-10,71,0,1)
Block(-10,71,1,1)
Block(-10,71,2,1)
Block(-10,71,3,1)
Block(-10,71,4,1)
Block(-10,72,-5,1)
Block(-10,72,-4,1)
Block(-10,72,-3,3)
Block(-10,72,-2,1)
Block(-10,72,-1,1)
Block(-10,72,0,1)
Block(-10,72,1,1)
Block(-10,72,2,1)
Block(-10,72,3,1)
Block(-10,73,-4,1)
Block(-10,73,-3,3)
Block(-10,73,-2,1)
Block(-10,73,-1,1)
Block(-10,73,0,1)
Block(-10,73,1,1)
Block(-10,73,2,1)
Block(-10,73,3,1)
Block(-10,74,-4,1)
Block(-10,74,-3,1)
Block(-10,74,-2,3)
Block(-10,74,-1,1)
Block(-10,74,0,1)
Block(-10,74,1,1)
Block(-10,74,2,1)
Block(-10,75,-3,1)
Block(-10,75,-2,3)
Block(-10,75,-1,3)
Block(-10,75,0,3)
Block(-10,75,1,1)
Block(-10,75,2,1)
Block(-10,76,-2,1)
Block(-10,76,-1,3)
Block(-10,76,0,3)
Block(-10,76,1,1)
Block(-10,76,2,1)
Block(-10,77,-2,1)
Block(-10,77,-1,1)
Block(-10,77,0,1)
Block(-10,77,1,1)
Block(-10,77,2,1)
Block(-10,78,-1,1)
Block(-10,78,0,1)
Block(-10,78,1,1)
Block(-10,78,2,1)
Block(-10,79,1,1)
Block(-9,0,-5,1)
Block(-9,0,-4,1)
Block(-9,0,-3,1)
Block(-9,0,-2,1)
Block(-9,0,-1,1)
Block(-9,0,0,1)
Block(-9,0,1,1)
Block(-9,0,2,1)
Block(-9,0,3,1)
Block(-9,0,4,1)
Block(-9,0,5,1)
Block(-9,0,6,1)
Block(-9,1,-4,1)
Block(-9,1,-3,1)
Block(-9,1,-2,1)
Block(-9,1,-1,1)
Block(-9,1,0,1)
Block(-9,1,1,1)
Block(-9,1,2,1)
Block(-9,1,3,1)
Block(-9,1,4,1)
Block(-9,1,5,1)
Block(-9,2,-3,1)
Block(-9,2,-2,1)
Block(-9,2,-1,1)
Block(-9,2,0,1)
Block(-9,2,1,1)
Block(-9,2,2,1)
Block(-9,2,3,1)
Block(-9,2,4,1)
Block(-9,3,-2,1)
Block(-9,3,-1,1)
Block(-9,3,0,1)
Block(-9,3,1,1)
Block(-9,3,2,1)
Block(-9,3,3,1)
Block(-9,3,4,1)
Block(-9,4,-2,1)
Block(-9,4,-1,1)
Block(-9,4,0,1)
Block(-9,4,1,1)
Block(-9,4,2,1)
Block(-9,4,3,1)
Block(-9,4,4,1)
Block(-9,5,-2,1)
Block(-9,5,-1,1)
Block(-9,5,0,1)
Block(-9,5,1,1)
Block(-9,5,2,1)
Block(-9,5,3,1)
Block(-9,5,4,1)
Block(-9,6,-4,1)
Block(-9,6,-3,1)
Block(-9,6,-2,1)
Block(-9,6,-1,1)
Block(-9,6,0,1)
Block(-9,6,1,1)
Block(-9,6,2,1)
Block(-9,6,3,1)
Block(-9,6,4,1)
Block(-9,6,5,1)
Block(-9,7,-4,1)
Block(-9,7,-3,1)
Block(-9,7,-2,1)
Block(-9,7,-1,1)
Block(-9,7,0,1)
Block(-9,7,1,1)
Block(-9,7,2,1)
Block(-9,7,3,1)
Block(-9,7,4,1)
Block(-9,7,5,1)
Block(-9,8,-4,1)
Block(-9,8,-3,1)
Block(-9,8,-2,1)
Block(-9,8,-1,1)
Block(-9,8,0,1)
Block(-9,8,1,1)
Block(-9,8,2,1)
Block(-9,8,3,1)
Block(-9,8,4,1)
Block(-9,8,5,1)
Block(-9,8,6,1)
Block(-9,9,-4,1)
Block(-9,9,-3,1)
Block(-9,9,-2,1)
Block(-9,9,-1,1)
Block(-9,9,0,1)
Block(-9,9,1,1)
Block(-9,9,2,1)
Block(-9,9,3,1)
Block(-9,9,4,1)
Block(-9,9,5,1)
Block(-9,9,6,1)
Block(-9,10,-3,1)
Block(-9,10,-2,1)
Block(-9,10,-1,1)
Block(-9,10,0,1)
Block(-9,10,1,1)
Block(-9,10,2,1)
Block(-9,10,3,1)
Block(-9,10,4,1)
Block(-9,10,5,1)
Block(-9,10,6,1)
Block(-9,11,-2,1)
Block(-9,11,-1,1)
Block(-9,11,0,1)
Block(-9,11,1,1)
Block(-9,11,2,1)
Block(-9,11,3,1)
Block(-9,11,4,1)
Block(-9,11,5,1)
Block(-9,11,6,1)
Block(-9,12,-1,1)
Block(-9,12,0,1)
Block(-9,12,1,1)
Block(-9,12,2,1)
Block(-9,12,3,1)
Block(-9,12,4,1)
Block(-9,12,5,1)
Block(-9,12,6,1)
Block(-9,12,7,1)
Block(-9,13,-1,1)
Block(-9,13,0,1)
Block(-9,13,1,1)
Block(-9,13,2,1)
Block(-9,13,3,1)
Block(-9,13,4,1)
Block(-9,13,5,1)
Block(-9,13,6,1)
Block(-9,13,7,1)
Block(-9,14,0,1)
Block(-9,14,1,1)
Block(-9,14,2,1)
Block(-9,14,3,1)
Block(-9,14,4,1)
Block(-9,14,5,1)
Block(-9,14,6,1)
Block(-9,14,7,1)
Block(-9,15,0,1)
Block(-9,15,1,1)
Block(-9,15,2,1)
Block(-9,15,3,1)
Block(-9,15,4,1)
Block(-9,15,5,1)
Block(-9,15,6,1)
Block(-9,16,0,1)
Block(-9,16,1,1)
Block(-9,16,2,1)
Block(-9,16,3,1)
Block(-9,16,4,1)
Block(-9,16,5,1)
Block(-9,16,6,1)
Block(-9,17,0,1)
Block(-9,17,1,1)
Block(-9,17,2,1)
Block(-9,17,3,1)
Block(-9,17,4,1)
Block(-9,17,5,1)
Block(-9,17,6,1)
Block(-9,18,-1,1)
Block(-9,18,0,1)
Block(-9,18,1,1)
Block(-9,18,2,1)
Block(-9,18,3,1)
Block(-9,18,4,1)
Block(-9,18,5,1)
Block(-9,18,6,1)
Block(-9,18,7,1)
Block(-9,19,-1,1)
Block(-9,19,0,1)
Block(-9,19,1,1)
Block(-9,19,2,1)
Block(-9,19,3,1)
Block(-9,19,4,1)
Block(-9,19,5,1)
Block(-9,19,6,1)
Block(-9,19,7,1)
Block(-9,20,-2,1)
Block(-9,20,-1,1)
Block(-9,20,0,1)
Block(-9,20,1,1)
Block(-9,20,2,1)
Block(-9,20,3,1)
Block(-9,20,4,1)
Block(-9,20,5,1)
Block(-9,20,6,1)
Block(-9,20,7,1)
Block(-9,21,-3,1)
Block(-9,21,-2,1)
Block(-9,21,-1,1)
Block(-9,21,0,1)
Block(-9,21,1,1)
Block(-9,21,2,1)
Block(-9,21,3,1)
Block(-9,21,4,1)
Block(-9,21,5,1)
Block(-9,21,6,1)
Block(-9,21,7,1)
Block(-9,22,-4,1)
Block(-9,22,-3,1)
Block(-9,22,-2,1)
Block(-9,22,-1,1)
Block(-9,22,0,1)
Block(-9,22,1,1)
Block(-9,22,2,1)
Block(-9,22,3,1)
Block(-9,22,4,1)
Block(-9,22,5,1)
Block(-9,22,6,1)
Block(-9,23,-4,1)
Block(-9,23,-3,1)
Block(-9,23,-2,1)
Block(-9,23,-1,1)
Block(-9,23,0,1)
Block(-9,23,1,1)
Block(-9,23,2,1)
Block(-9,23,3,1)
Block(-9,23,4,1)
Block(-9,23,5,1)
Block(-9,23,6,1)
Block(-9,24,-4,1)
Block(-9,24,-3,1)
Block(-9,24,-2,1)
Block(-9,24,-1,1)
Block(-9,24,0,1)
Block(-9,24,1,1)
Block(-9,24,2,1)
Block(-9,24,3,1)
Block(-9,24,4,1)
Block(-9,24,5,1)
Block(-9,24,6,1)
Block(-9,25,-5,1)
Block(-9,25,-4,1)
Block(-9,25,-3,1)
Block(-9,25,-2,1)
Block(-9,25,-1,1)
Block(-9,25,0,1)
Block(-9,25,1,1)
Block(-9,25,2,1)
Block(-9,25,3,1)
Block(-9,25,4,1)
Block(-9,25,5,1)
Block(-9,25,6,1)
Block(-9,26,-4,1)
Block(-9,26,-3,1)
Block(-9,26,-2,1)
Block(-9,26,-1,1)
Block(-9,26,0,1)
Block(-9,26,1,1)
Block(-9,26,2,1)
Block(-9,26,3,1)
Block(-9,26,4,1)
Block(-9,26,5,1)
Block(-9,26,6,1)
Block(-9,27,-4,1)
Block(-9,27,-3,1)
Block(-9,27,-2,1)
Block(-9,27,-1,1)
Block(-9,27,0,1)
Block(-9,27,1,1)
Block(-9,27,2,1)
Block(-9,27,3,1)
Block(-9,27,4,1)
Block(-9,27,5,1)
Block(-9,27,6,1)
Block(-9,28,-4,1)
Block(-9,28,-3,1)
Block(-9,28,-2,1)
Block(-9,28,-1,1)
Block(-9,28,0,1)
Block(-9,28,1,1)
Block(-9,28,2,1)
Block(-9,28,3,1)
Block(-9,28,4,1)
Block(-9,28,5,1)
Block(-9,28,6,1)
Block(-9,29,-3,1)
Block(-9,29,-2,1)
Block(-9,29,-1,1)
Block(-9,29,0,1)
Block(-9,29,1,1)
Block(-9,29,2,1)
Block(-9,29,3,1)
Block(-9,29,4,1)
Block(-9,29,5,1)
Block(-9,29,6,1)
Block(-9,30,-3,1)
Block(-9,30,-2,1)
Block(-9,30,-1,1)
Block(-9,30,0,1)
Block(-9,30,1,1)
Block(-9,30,2,1)
Block(-9,30,3,1)
Block(-9,30,4,1)
Block(-9,30,5,1)
Block(-9,31,-3,1)
Block(-9,31,-2,1)
Block(-9,31,-1,1)
Block(-9,31,0,1)
Block(-9,31,1,1)
Block(-9,31,2,1)
Block(-9,31,3,1)
Block(-9,31,4,1)
Block(-9,31,5,1)
Block(-9,32,-2,1)
Block(-9,32,-1,1)
Block(-9,32,0,1)
Block(-9,32,1,1)
Block(-9,32,2,1)
Block(-9,32,3,1)
Block(-9,32,4,1)
Block(-9,32,5,1)
Block(-9,33,-2,1)
Block(-9,33,-1,1)
Block(-9,33,0,1)
Block(-9,33,1,1)
Block(-9,33,2,1)
Block(-9,33,3,1)
Block(-9,33,4,1)
Block(-9,34,-2,1)
Block(-9,34,-1,1)
Block(-9,34,0,1)
Block(-9,34,1,1)
Block(-9,34,2,1)
Block(-9,34,3,1)
Block(-9,34,4,1)
Block(-9,35,-2,1)
Block(-9,35,-1,1)
Block(-9,35,0,1)
Block(-9,35,1,1)
Block(-9,35,2,1)
Block(-9,35,3,1)
Block(-9,35,4,1)
Block(-9,36,-2,1)
Block(-9,36,-1,1)
Block(-9,36,0,1)
Block(-9,36,1,1)
Block(-9,36,2,1)
Block(-9,36,3,1)
Block(-9,36,4,1)
Block(-9,37,-2,1)
Block(-9,37,-1,1)
Block(-9,37,0,1)
Block(-9,37,1,1)
Block(-9,37,2,1)
Block(-9,37,3,1)
Block(-9,37,4,1)
Block(-9,38,-2,1)
Block(-9,38,-1,1)
Block(-9,38,0,1)
Block(-9,38,1,1)
Block(-9,38,2,1)
Block(-9,38,3,1)
Block(-9,38,4,1)
Block(-9,38,5,1)
Block(-9,39,-3,1)
Block(-9,39,-2,1)
Block(-9,39,-1,1)
Block(-9,39,0,1)
Block(-9,39,1,1)
Block(-9,39,2,1)
Block(-9,39,3,1)
Block(-9,39,4,1)
Block(-9,39,5,1)
Block(-9,39,6,1)
Block(-9,40,-4,1)
Block(-9,40,-3,1)
Block(-9,40,-2,1)
Block(-9,40,-1,1)
Block(-9,40,0,1)
Block(-9,40,1,1)
Block(-9,40,2,1)
Block(-9,40,3,1)
Block(-9,40,4,1)
Block(-9,40,5,1)
Block(-9,40,6,1)
Block(-9,40,7,1)
Block(-9,41,-5,1)
Block(-9,41,-4,1)
Block(-9,41,-3,1)
Block(-9,41,-2,1)
Block(-9,41,-1,1)
Block(-9,41,0,1)
Block(-9,41,1,1)
Block(-9,41,2,1)
Block(-9,41,3,1)
Block(-9,41,4,1)
Block(-9,41,5,1)
Block(-9,41,6,1)
Block(-9,41,7,1)
Block(-9,41,8,1)
Block(-9,42,-6,1)
Block(-9,42,-5,1)
Block(-9,42,-4,1)
Block(-9,42,-3,1)
Block(-9,42,-2,1)
Block(-9,42,-1,1)
Block(-9,42,0,1)
Block(-9,42,1,1)
Block(-9,42,2,1)
Block(-9,42,3,1)
Block(-9,42,4,1)
Block(-9,42,5,1)
Block(-9,42,6,1)
Block(-9,42,7,1)
Block(-9,42,8,1)
Block(-9,43,-6,1)
Block(-9,43,-5,1)
Block(-9,43,-4,1)
Block(-9,43,-3,1)
Block(-9,43,-2,1)
Block(-9,43,-1,1)
Block(-9,43,0,1)
Block(-9,43,1,1)
Block(-9,43,2,1)
Block(-9,43,3,1)
Block(-9,43,4,1)
Block(-9,43,5,1)
Block(-9,43,6,1)
Block(-9,43,7,1)
Block(-9,44,-5,1)
Block(-9,44,-4,1)
Block(-9,44,-3,1)
Block(-9,44,-2,1)
Block(-9,44,-1,1)
Block(-9,44,0,1)
Block(-9,44,1,1)
Block(-9,44,2,1)
Block(-9,44,3,1)
Block(-9,44,4,1)
Block(-9,44,5,1)
Block(-9,44,6,1)
Block(-9,45,-4,1)
Block(-9,45,-3,1)
Block(-9,45,-2,1)
Block(-9,45,-1,1)
Block(-9,45,0,1)
Block(-9,45,1,1)
Block(-9,45,2,1)
Block(-9,45,3,1)
Block(-9,45,4,1)
Block(-9,45,5,1)
Block(-9,45,6,1)
Block(-9,46,-3,1)
Block(-9,46,-2,1)
Block(-9,46,-1,1)
Block(-9,46,0,1)
Block(-9,46,1,1)
Block(-9,46,2,1)
Block(-9,46,3,1)
Block(-9,46,4,1)
Block(-9,46,5,1)
Block(-9,47,-2,1)
Block(-9,47,-1,1)
Block(-9,47,0,1)
Block(-9,47,1,1)
Block(-9,47,2,1)
Block(-9,47,3,1)
Block(-9,47,4,1)
Block(-9,47,5,1)
Block(-9,48,-1,1)
Block(-9,48,0,1)
Block(-9,48,1,1)
Block(-9,48,2,1)
Block(-9,48,3,1)
Block(-9,48,4,1)
Block(-9,49,-1,1)
Block(-9,49,0,1)
Block(-9,49,1,1)
Block(-9,49,2,1)
Block(-9,49,3,1)
Block(-9,49,4,1)
Block(-9,50,-1,1)
Block(-9,50,0,1)
Block(-9,50,1,1)
Block(-9,50,2,1)
Block(-9,50,3,1)
Block(-9,50,4,1)
Block(-9,51,-1,1)
Block(-9,51,0,1)
Block(-9,51,1,1)
Block(-9,51,2,1)
Block(-9,51,3,1)
Block(-9,51,4,1)
Block(-9,52,-1,1)
Block(-9,52,0,1)
Block(-9,52,1,1)
Block(-9,52,2,1)
Block(-9,52,3,1)
Block(-9,52,4,1)
Block(-9,53,-2,1)
Block(-9,53,-1,1)
Block(-9,53,0,1)
Block(-9,53,1,1)
Block(-9,53,2,1)
Block(-9,53,3,1)
Block(-9,53,4,1)
Block(-9,54,-3,1)
Block(-9,54,-2,1)
Block(-9,54,-1,1)
Block(-9,54,0,1)
Block(-9,54,1,1)
Block(-9,54,2,1)
Block(-9,54,3,1)
Block(-9,54,4,1)
Block(-9,55,-3,1)
Block(-9,55,-2,1)
Block(-9,55,-1,1)
Block(-9,55,0,1)
Block(-9,55,1,1)
Block(-9,55,2,1)
Block(-9,55,3,1)
Block(-9,55,4,1)
Block(-9,56,-4,1)
Block(-9,56,-3,1)
Block(-9,56,-2,1)
Block(-9,56,-1,1)
Block(-9,56,0,1)
Block(-9,56,1,1)
Block(-9,56,2,1)
Block(-9,56,3,1)
Block(-9,56,4,1)
Block(-9,57,-4,1)
Block(-9,57,-3,1)
Block(-9,57,-2,1)
Block(-9,57,-1,1)
Block(-9,57,0,1)
Block(-9,57,1,1)
Block(-9,57,2,1)
Block(-9,57,3,1)
Block(-9,57,4,1)
Block(-9,58,-4,1)
Block(-9,58,-3,1)
Block(-9,58,-2,1)
Block(-9,58,-1,1)
Block(-9,58,0,1)
Block(-9,58,1,1)
Block(-9,58,2,1)
Block(-9,58,3,1)
Block(-9,58,4,1)
Block(-9,58,5,1)
Block(-9,59,-4,1)
Block(-9,59,-3,1)
Block(-9,59,-2,1)
Block(-9,59,-1,1)
Block(-9,59,0,1)
Block(-9,59,1,1)
Block(-9,59,2,1)
Block(-9,59,3,1)
Block(-9,59,4,1)
Block(-9,59,5,1)
Block(-9,60,-3,1)
Block(-9,60,-2,1)
Block(-9,60,-1,1)
Block(-9,60,0,1)
Block(-9,60,1,1)
Block(-9,60,2,1)
Block(-9,60,3,1)
Block(-9,60,4,1)
Block(-9,60,5,1)
Block(-9,61,-3,1)
Block(-9,61,-2,1)
Block(-9,61,-1,1)
Block(-9,61,0,1)
Block(-9,61,1,1)
Block(-9,61,2,1)
Block(-9,61,3,1)
Block(-9,61,4,1)
Block(-9,61,5,1)
Block(-9,62,-2,1)
Block(-9,62,-1,1)
Block(-9,62,0,1)
Block(-9,62,1,1)
Block(-9,62,2,1)
Block(-9,62,3,1)
Block(-9,62,4,1)
Block(-9,63,-2,1)
Block(-9,63,-1,1)
Block(-9,63,0,1)
Block(-9,63,1,1)
Block(-9,63,2,1)
Block(-9,63,3,1)
Block(-9,63,4,1)
Block(-9,64,-1,1)
Block(-9,64,0,1)
Block(-9,64,1,1)
Block(-9,64,2,1)
Block(-9,64,3,1)
Block(-9,64,4,1)
Block(-9,65,-1,1)
Block(-9,65,0,1)
Block(-9,65,1,1)
Block(-9,65,2,1)
Block(-9,65,3,1)
Block(-9,65,4,1)
Block(-9,66,-2,1)
Block(-9,66,-1,1)
Block(-9,66,0,1)
Block(-9,66,1,1)
Block(-9,66,2,1)
Block(-9,66,3,1)
Block(-9,66,4,1)
Block(-9,67,-2,1)
Block(-9,67,-1,1)
Block(-9,67,0,1)
Block(-9,67,1,1)
Block(-9,67,2,1)
Block(-9,67,3,1)
Block(-9,67,4,1)
Block(-9,68,-3,1)
Block(-9,68,-2,1)
Block(-9,68,-1,1)
Block(-9,68,0,1)
Block(-9,68,1,1)
Block(-9,68,2,1)
Block(-9,68,3,1)
Block(-9,68,4,1)
Block(-9,69,-4,1)
Block(-9,69,-3,1)
Block(-9,69,-2,1)
Block(-9,69,-1,1)
Block(-9,69,0,1)
Block(-9,69,1,1)
Block(-9,69,2,1)
Block(-9,69,3,1)
Block(-9,69,4,1)
Block(-9,69,5,1)
Block(-9,70,-5,1)
Block(-9,70,-4,1)
Block(-9,70,-3,1)
Block(-9,70,-2,1)
Block(-9,70,-1,1)
Block(-9,70,0,1)
Block(-9,70,1,1)
Block(-9,70,2,1)
Block(-9,70,3,1)
Block(-9,70,4,1)
Block(-9,70,5,1)
Block(-9,71,-6,1)
Block(-9,71,-5,1)
Block(-9,71,-4,1)
Block(-9,71,-3,1)
Block(-9,71,-2,1)
Block(-9,71,-1,1)
Block(-9,71,0,1)
Block(-9,71,1,1)
Block(-9,71,2,1)
Block(-9,71,3,1)
Block(-9,71,4,1)
Block(-9,71,5,1)
Block(-9,72,-6,1)
Block(-9,72,-5,3)
Block(-9,72,-4,3)
Block(-9,72,-3,1)
Block(-9,72,-2,1)
Block(-9,72,-1,1)
Block(-9,72,0,1)
Block(-9,72,1,1)
Block(-9,72,2,1)
Block(-9,72,3,1)
Block(-9,72,4,1)
Block(-9,72,5,1)
Block(-9,73,-6,1)
Block(-9,73,-5,1)
Block(-9,73,-4,3)
Block(-9,73,-3,1)
Block(-9,73,-2,1)
Block(-9,73,-1,1)
Block(-9,73,0,1)
Block(-9,73,1,1)
Block(-9,73,2,1)
Block(-9,73,3,1)
Block(-9,73,4,1)
Block(-9,74,-5,1)
Block(-9,74,-4,3)
Block(-9,74,-3,3)
Block(-9,74,-2,1)
Block(-9,74,-1,1)
Block(-9,74,0,1)
Block(-9,74,1,1)
Block(-9,74,2,1)
Block(-9,74,3,1)
Block(-9,74,4,1)
Block(-9,75,-4,1)
Block(-9,75,-3,3)
Block(-9,75,-2,3)
Block(-9,75,-1,1)
Block(-9,75,0,1)
Block(-9,75,1,1)
Block(-9,75,2,1)
Block(-9,75,3,1)
Block(-9,75,4,1)
Block(-9,76,-3,1)
Block(-9,76,-2,3)
Block(-9,76,-1,3)
Block(-9,76,0,1)
Block(-9,76,1,1)
Block(-9,76,2,1)
Block(-9,76,3,1)
Block(-9,76,4,1)
Block(-9,77,-3,1)
Block(-9,77,-2,3)
Block(-9,77,-1,3)
Block(-9,77,0,3)
Block(-9,77,1,1)
Block(-9,77,2,1)
Block(-9,77,3,1)
Block(-9,77,4,1)
Block(-9,78,-2,1)
Block(-9,78,-1,3)
Block(-9,78,0,3)
Block(-9,78,1,3)
Block(-9,78,2,3)
Block(-9,78,3,1)
Block(-9,79,-1,1)
Block(-9,79,0,1)
Block(-9,79,1,3)
Block(-9,79,2,1)
Block(-9,79,3,1)
Block(-9,80,0,1)
Block(-9,80,1,1)
Block(-9,80,2,1)
Block(-9,80,3,1)
Block(-9,81,1,1)
Block(-9,81,2,1)
Block(-8,0,-6,1)
Block(-8,0,-5,1)
Block(-8,0,-4,1)
Block(-8,0,-3,1)
Block(-8,0,-2,1)
Block(-8,0,-1,1)
Block(-8,0,0,1)
Block(-8,0,1,1)
Block(-8,0,2,1)
Block(-8,0,3,1)
Block(-8,0,4,1)
Block(-8,0,5,1)
Block(-8,0,6,1)
Block(-8,0,7,1)
Block(-8,1,-5,1)
Block(-8,1,-4,1)
Block(-8,1,-3,1)
Block(-8,1,-2,1)
Block(-8,1,-1,1)
Block(-8,1,0,1)
Block(-8,1,1,1)
Block(-8,1,2,1)
Block(-8,1,3,1)
Block(-8,1,4,1)
Block(-8,1,5,1)
Block(-8,1,6,1)
Block(-8,2,-4,1)
Block(-8,2,-3,1)
Block(-8,2,-2,1)
Block(-8,2,-1,1)
Block(-8,2,0,1)
Block(-8,2,1,1)
Block(-8,2,2,1)
Block(-8,2,3,1)
Block(-8,2,4,1)
Block(-8,2,5,1)
Block(-8,3,-3,1)
Block(-8,3,-2,1)
Block(-8,3,-1,1)
Block(-8,3,0,1)
Block(-8,3,1,1)
Block(-8,3,2,1)
Block(-8,3,3,1)
Block(-8,3,4,1)
Block(-8,3,5,1)
Block(-8,4,-3,1)
Block(-8,4,-2,1)
Block(-8,4,-1,1)
Block(-8,4,0,1)
Block(-8,4,1,1)
Block(-8,4,2,1)
Block(-8,4,3,1)
Block(-8,4,4,1)
Block(-8,4,5,1)
Block(-8,5,-4,1)
Block(-8,5,-3,1)
Block(-8,5,-2,1)
Block(-8,5,-1,1)
Block(-8,5,0,1)
Block(-8,5,1,1)
Block(-8,5,2,1)
Block(-8,5,3,1)
Block(-8,5,4,1)
Block(-8,5,5,1)
Block(-8,6,-5,1)
Block(-8,6,-4,1)
Block(-8,6,-3,1)
Block(-8,6,-2,1)
Block(-8,6,-1,1)
Block(-8,6,0,1)
Block(-8,6,1,1)
Block(-8,6,2,1)
Block(-8,6,3,1)
Block(-8,6,4,1)
Block(-8,6,5,1)
Block(-8,6,6,1)
Block(-8,7,-5,1)
Block(-8,7,-4,1)
Block(-8,7,-3,1)
Block(-8,7,-2,1)
Block(-8,7,-1,1)
Block(-8,7,0,1)
Block(-8,7,1,1)
Block(-8,7,2,1)
Block(-8,7,3,1)
Block(-8,7,4,1)
Block(-8,7,5,1)
Block(-8,7,6,1)
Block(-8,8,-6,1)
Block(-8,8,-5,1)
Block(-8,8,-4,1)
Block(-8,8,-3,1)
Block(-8,8,-2,1)
Block(-8,8,-1,1)
Block(-8,8,0,1)
Block(-8,8,1,1)
Block(-8,8,2,1)
Block(-8,8,3,1)
Block(-8,8,4,1)
Block(-8,8,5,1)
Block(-8,8,6,1)
Block(-8,9,-6,1)
Block(-8,9,-5,1)
Block(-8,9,-4,1)
Block(-8,9,-3,1)
Block(-8,9,-2,1)
Block(-8,9,-1,1)
Block(-8,9,0,1)
Block(-8,9,1,1)
Block(-8,9,2,1)
Block(-8,9,3,1)
Block(-8,9,4,1)
Block(-8,9,5,1)
Block(-8,9,6,1)
Block(-8,9,7,1)
Block(-8,10,-6,1)
Block(-8,10,-5,1)
Block(-8,10,-4,1)
Block(-8,10,-3,1)
Block(-8,10,-2,1)
Block(-8,10,-1,1)
Block(-8,10,0,1)
Block(-8,10,1,1)
Block(-8,10,2,1)
Block(-8,10,3,1)
Block(-8,10,4,1)
Block(-8,10,5,1)
Block(-8,10,6,1)
Block(-8,10,7,1)
Block(-8,11,-5,1)
Block(-8,11,-4,1)
Block(-8,11,-3,1)
Block(-8,11,-2,1)
Block(-8,11,-1,1)
Block(-8,11,0,1)
Block(-8,11,1,1)
Block(-8,11,2,1)
Block(-8,11,3,1)
Block(-8,11,4,1)
Block(-8,11,5,1)
Block(-8,11,6,1)
Block(-8,11,7,1)
Block(-8,11,8,1)
Block(-8,12,-4,1)
Block(-8,12,-3,1)
Block(-8,12,-2,1)
Block(-8,12,-1,1)
Block(-8,12,0,1)
Block(-8,12,1,1)
Block(-8,12,2,1)
Block(-8,12,3,1)
Block(-8,12,4,1)
Block(-8,12,5,1)
Block(-8,12,6,1)
Block(-8,12,7,1)
Block(-8,12,8,1)
Block(-8,13,-3,1)
Block(-8,13,-2,1)
Block(-8,13,-1,1)
Block(-8,13,0,1)
Block(-8,13,1,1)
Block(-8,13,2,1)
Block(-8,13,3,1)
Block(-8,13,4,1)
Block(-8,13,5,1)
Block(-8,13,6,1)
Block(-8,13,7,1)
Block(-8,13,8,1)
Block(-8,14,-3,1)
Block(-8,14,-2,1)
Block(-8,14,-1,1)
Block(-8,14,0,1)
Block(-8,14,1,1)
Block(-8,14,2,1)
Block(-8,14,3,1)
Block(-8,14,4,1)
Block(-8,14,5,1)
Block(-8,14,6,1)
Block(-8,14,7,1)
Block(-8,14,8,1)
Block(-8,15,-3,1)
Block(-8,15,-2,1)
Block(-8,15,-1,1)
Block(-8,15,0,1)
Block(-8,15,1,1)
Block(-8,15,2,1)
Block(-8,15,3,1)
Block(-8,15,4,1)
Block(-8,15,5,1)
Block(-8,15,6,1)
Block(-8,15,7,1)
Block(-8,16,-3,1)
Block(-8,16,-2,1)
Block(-8,16,-1,1)
Block(-8,16,0,1)
Block(-8,16,1,1)
Block(-8,16,2,1)
Block(-8,16,3,1)
Block(-8,16,4,1)
Block(-8,16,5,1)
Block(-8,16,6,1)
Block(-8,16,7,1)
Block(-8,17,-3,1)
Block(-8,17,-2,1)
Block(-8,17,-1,1)
Block(-8,17,0,1)
Block(-8,17,1,1)
Block(-8,17,2,1)
Block(-8,17,3,1)
Block(-8,17,4,1)
Block(-8,17,5,1)
Block(-8,17,6,1)
Block(-8,17,7,1)
Block(-8,18,-3,1)
Block(-8,18,-2,1)
Block(-8,18,-1,1)
Block(-8,18,0,1)
Block(-8,18,1,1)
Block(-8,18,2,1)
Block(-8,18,3,1)
Block(-8,18,4,1)
Block(-8,18,5,1)
Block(-8,18,6,1)
Block(-8,18,7,1)
Block(-8,18,8,1)
Block(-8,19,-4,1)
Block(-8,19,-3,1)
Block(-8,19,-2,1)
Block(-8,19,-1,1)
Block(-8,19,0,1)
Block(-8,19,1,1)
Block(-8,19,2,1)
Block(-8,19,3,1)
Block(-8,19,4,1)
Block(-8,19,5,1)
Block(-8,19,6,1)
Block(-8,19,7,1)
Block(-8,19,8,1)
Block(-8,20,-5,1)
Block(-8,20,-4,1)
Block(-8,20,-3,1)
Block(-8,20,-2,1)
Block(-8,20,-1,1)
Block(-8,20,0,1)
Block(-8,20,1,1)
Block(-8,20,2,1)
Block(-8,20,3,1)
Block(-8,20,4,1)
Block(-8,20,5,1)
Block(-8,20,6,1)
Block(-8,20,7,1)
Block(-8,20,8,1)
Block(-8,21,-5,1)
Block(-8,21,-4,1)
Block(-8,21,-3,1)
Block(-8,21,-2,1)
Block(-8,21,-1,1)
Block(-8,21,0,1)
Block(-8,21,1,1)
Block(-8,21,2,1)
Block(-8,21,3,1)
Block(-8,21,4,1)
Block(-8,21,5,1)
Block(-8,21,6,1)
Block(-8,21,7,1)
Block(-8,22,-5,1)
Block(-8,22,-4,1)
Block(-8,22,-3,1)
Block(-8,22,-2,1)
Block(-8,22,-1,1)
Block(-8,22,0,1)
Block(-8,22,1,1)
Block(-8,22,2,1)
Block(-8,22,3,1)
Block(-8,22,4,1)
Block(-8,22,5,1)
Block(-8,22,6,1)
Block(-8,22,7,1)
Block(-8,23,-6,1)
Block(-8,23,-5,1)
Block(-8,23,-4,1)
Block(-8,23,-3,1)
Block(-8,23,-2,1)
Block(-8,23,-1,1)
Block(-8,23,0,1)
Block(-8,23,1,1)
Block(-8,23,2,1)
Block(-8,23,3,1)
Block(-8,23,4,1)
Block(-8,23,5,1)
Block(-8,23,6,1)
Block(-8,23,7,1)
Block(-8,24,-6,1)
Block(-8,24,-5,1)
Block(-8,24,-4,1)
Block(-8,24,-3,1)
Block(-8,24,-2,1)
Block(-8,24,-1,1)
Block(-8,24,0,1)
Block(-8,24,1,1)
Block(-8,24,2,1)
Block(-8,24,3,1)
Block(-8,24,4,1)
Block(-8,24,5,1)
Block(-8,24,6,1)
Block(-8,24,7,1)
Block(-8,25,-6,1)
Block(-8,25,-5,1)
Block(-8,25,-4,1)
Block(-8,25,-3,1)
Block(-8,25,-2,1)
Block(-8,25,-1,1)
Block(-8,25,0,1)
Block(-8,25,1,1)
Block(-8,25,2,1)
Block(-8,25,3,1)
Block(-8,25,4,1)
Block(-8,25,5,1)
Block(-8,25,6,1)
Block(-8,25,7,1)
Block(-8,25,8,1)
Block(-8,26,-6,1)
Block(-8,26,-5,1)
Block(-8,26,-4,1)
Block(-8,26,-3,1)
Block(-8,26,-2,1)
Block(-8,26,-1,1)
Block(-8,26,0,1)
Block(-8,26,1,1)
Block(-8,26,2,1)
Block(-8,26,3,1)
Block(-8,26,4,1)
Block(-8,26,5,1)
Block(-8,26,6,1)
Block(-8,26,7,1)
Block(-8,26,8,1)
Block(-8,27,-5,1)
Block(-8,27,-4,1)
Block(-8,27,-3,1)
Block(-8,27,-2,1)
Block(-8,27,-1,1)
Block(-8,27,0,1)
Block(-8,27,1,1)
Block(-8,27,2,1)
Block(-8,27,3,1)
Block(-8,27,4,1)
Block(-8,27,5,1)
Block(-8,27,6,1)
Block(-8,27,7,1)
Block(-8,27,8,1)
Block(-8,28,-5,1)
Block(-8,28,-4,1)
Block(-8,28,-3,1)
Block(-8,28,-2,1)
Block(-8,28,-1,1)
Block(-8,28,0,1)
Block(-8,28,1,1)
Block(-8,28,2,1)
Block(-8,28,3,1)
Block(-8,28,4,1)
Block(-8,28,5,1)
Block(-8,28,6,1)
Block(-8,28,7,1)
Block(-8,29,-5,1)
Block(-8,29,-4,1)
Block(-8,29,-3,1)
Block(-8,29,-2,1)
Block(-8,29,-1,1)
Block(-8,29,0,1)
Block(-8,29,1,1)
Block(-8,29,2,1)
Block(-8,29,3,1)
Block(-8,29,4,1)
Block(-8,29,5,1)
Block(-8,29,6,1)
Block(-8,29,7,1)
Block(-8,30,-4,1)
Block(-8,30,-3,1)
Block(-8,30,-2,1)
Block(-8,30,-1,1)
Block(-8,30,0,1)
Block(-8,30,1,1)
Block(-8,30,2,1)
Block(-8,30,3,1)
Block(-8,30,4,1)
Block(-8,30,5,1)
Block(-8,30,6,1)
Block(-8,30,7,1)
Block(-8,31,-4,1)
Block(-8,31,-3,1)
Block(-8,31,-2,1)
Block(-8,31,-1,1)
Block(-8,31,0,1)
Block(-8,31,1,1)
Block(-8,31,2,1)
Block(-8,31,3,1)
Block(-8,31,4,1)
Block(-8,31,5,1)
Block(-8,31,6,1)
Block(-8,32,-4,1)
Block(-8,32,-3,1)
Block(-8,32,-2,1)
Block(-8,32,-1,1)
Block(-8,32,0,1)
Block(-8,32,1,1)
Block(-8,32,2,1)
Block(-8,32,3,1)
Block(-8,32,4,1)
Block(-8,32,5,1)
Block(-8,32,6,1)
Block(-8,33,-3,1)
Block(-8,33,-2,1)
Block(-8,33,-1,1)
Block(-8,33,0,1)
Block(-8,33,1,1)
Block(-8,33,2,1)
Block(-8,33,3,1)
Block(-8,33,4,1)
Block(-8,33,5,1)
Block(-8,33,6,1)
Block(-8,34,-3,1)
Block(-8,34,-2,1)
Block(-8,34,-1,1)
Block(-8,34,0,1)
Block(-8,34,1,1)
Block(-8,34,2,1)
Block(-8,34,3,1)
Block(-8,34,4,1)
Block(-8,34,5,1)
Block(-8,34,6,1)
Block(-8,35,-3,1)
Block(-8,35,-2,1)
Block(-8,35,-1,1)
Block(-8,35,0,1)
Block(-8,35,1,1)
Block(-8,35,2,1)
Block(-8,35,3,1)
Block(-8,35,4,1)
Block(-8,35,5,1)
Block(-8,36,-3,1)
Block(-8,36,-2,1)
Block(-8,36,-1,1)
Block(-8,36,0,1)
Block(-8,36,1,1)
Block(-8,36,2,1)
Block(-8,36,3,1)
Block(-8,36,4,1)
Block(-8,36,5,1)
Block(-8,37,-3,1)
Block(-8,37,-2,1)
Block(-8,37,-1,1)
Block(-8,37,0,1)
Block(-8,37,1,1)
Block(-8,37,2,1)
Block(-8,37,3,1)
Block(-8,37,4,1)
Block(-8,37,5,1)
Block(-8,38,-4,1)
Block(-8,38,-3,1)
Block(-8,38,-2,1)
Block(-8,38,-1,1)
Block(-8,38,0,1)
Block(-8,38,1,1)
Block(-8,38,2,1)
Block(-8,38,3,1)
Block(-8,38,4,1)
Block(-8,38,5,1)
Block(-8,38,6,1)
Block(-8,39,-5,1)
Block(-8,39,-4,1)
Block(-8,39,-3,1)
Block(-8,39,-2,1)
Block(-8,39,-1,1)
Block(-8,39,0,1)
Block(-8,39,1,1)
Block(-8,39,2,1)
Block(-8,39,3,1)
Block(-8,39,4,1)
Block(-8,39,5,1)
Block(-8,39,6,1)
Block(-8,39,7,1)
Block(-8,40,-6,1)
Block(-8,40,-5,1)
Block(-8,40,-4,1)
Block(-8,40,-3,1)
Block(-8,40,-2,1)
Block(-8,40,-1,1)
Block(-8,40,0,1)
Block(-8,40,1,1)
Block(-8,40,2,1)
Block(-8,40,3,1)
Block(-8,40,4,1)
Block(-8,40,5,1)
Block(-8,40,6,1)
Block(-8,40,7,1)
Block(-8,40,8,1)
Block(-8,41,-7,1)
Block(-8,41,-6,1)
Block(-8,41,-5,1)
Block(-8,41,-4,1)
Block(-8,41,-3,1)
Block(-8,41,-2,1)
Block(-8,41,-1,1)
Block(-8,41,0,1)
Block(-8,41,1,1)
Block(-8,41,2,1)
Block(-8,41,3,1)
Block(-8,41,4,1)
Block(-8,41,5,1)
Block(-8,41,6,1)
Block(-8,41,7,1)
Block(-8,41,8,1)
Block(-8,42,-7,1)
Block(-8,42,-6,1)
Block(-8,42,-5,1)
Block(-8,42,-4,1)
Block(-8,42,-3,1)
Block(-8,42,-2,1)
Block(-8,42,-1,1)
Block(-8,42,0,1)
Block(-8,42,1,1)
Block(-8,42,2,1)
Block(-8,42,3,1)
Block(-8,42,4,1)
Block(-8,42,5,1)
Block(-8,42,6,1)
Block(-8,42,7,1)
Block(-8,42,8,1)
Block(-8,43,-7,1)
Block(-8,43,-6,1)
Block(-8,43,-5,1)
Block(-8,43,-4,1)
Block(-8,43,-3,1)
Block(-8,43,-2,1)
Block(-8,43,-1,1)
Block(-8,43,0,1)
Block(-8,43,1,1)
Block(-8,43,2,1)
Block(-8,43,3,1)
Block(-8,43,4,1)
Block(-8,43,5,1)
Block(-8,43,6,1)
Block(-8,43,7,1)
Block(-8,43,8,1)
Block(-8,44,-7,1)
Block(-8,44,-6,1)
Block(-8,44,-5,1)
Block(-8,44,-4,1)
Block(-8,44,-3,1)
Block(-8,44,-2,1)
Block(-8,44,-1,1)
Block(-8,44,0,1)
Block(-8,44,1,1)
Block(-8,44,2,1)
Block(-8,44,3,1)
Block(-8,44,4,1)
Block(-8,44,5,1)
Block(-8,44,6,1)
Block(-8,44,7,1)
Block(-8,45,-5,1)
Block(-8,45,-4,1)
Block(-8,45,-3,1)
Block(-8,45,-2,1)
Block(-8,45,-1,1)
Block(-8,45,0,1)
Block(-8,45,1,1)
Block(-8,45,2,1)
Block(-8,45,3,1)
Block(-8,45,4,1)
Block(-8,45,5,1)
Block(-8,45,6,1)
Block(-8,46,-4,1)
Block(-8,46,-3,1)
Block(-8,46,-2,1)
Block(-8,46,-1,1)
Block(-8,46,0,1)
Block(-8,46,1,1)
Block(-8,46,2,1)
Block(-8,46,3,1)
Block(-8,46,4,1)
Block(-8,46,5,1)
Block(-8,46,6,1)
Block(-8,47,-3,1)
Block(-8,47,-2,1)
Block(-8,47,-1,1)
Block(-8,47,0,1)
Block(-8,47,1,1)
Block(-8,47,2,1)
Block(-8,47,3,1)
Block(-8,47,4,1)
Block(-8,47,5,1)
Block(-8,48,-3,1)
Block(-8,48,-2,1)
Block(-8,48,-1,1)
Block(-8,48,0,1)
Block(-8,48,1,1)
Block(-8,48,2,1)
Block(-8,48,3,1)
Block(-8,48,4,1)
Block(-8,48,5,1)
Block(-8,49,-3,1)
Block(-8,49,-2,1)
Block(-8,49,-1,1)
Block(-8,49,0,1)
Block(-8,49,1,1)
Block(-8,49,2,1)
Block(-8,49,3,1)
Block(-8,49,4,1)
Block(-8,49,5,1)
Block(-8,50,-3,1)
Block(-8,50,-2,1)
Block(-8,50,-1,1)
Block(-8,50,0,1)
Block(-8,50,1,1)
Block(-8,50,2,1)
Block(-8,50,3,1)
Block(-8,50,4,1)
Block(-8,50,5,1)
Block(-8,51,-3,1)
Block(-8,51,-2,1)
Block(-8,51,-1,1)
Block(-8,51,0,1)
Block(-8,51,1,1)
Block(-8,51,2,1)
Block(-8,51,3,1)
Block(-8,51,4,1)
Block(-8,51,5,1)
Block(-8,52,-3,1)
Block(-8,52,-2,1)
Block(-8,52,-1,1)
Block(-8,52,0,1)
Block(-8,52,1,1)
Block(-8,52,2,1)
Block(-8,52,3,1)
Block(-8,52,4,1)
Block(-8,52,5,1)
Block(-8,53,-4,1)
Block(-8,53,-3,1)
Block(-8,53,-2,1)
Block(-8,53,-1,1)
Block(-8,53,0,1)
Block(-8,53,1,1)
Block(-8,53,2,1)
Block(-8,53,3,1)
Block(-8,53,4,1)
Block(-8,53,5,1)
Block(-8,54,-5,1)
Block(-8,54,-4,1)
Block(-8,54,-3,1)
Block(-8,54,-2,1)
Block(-8,54,-1,1)
Block(-8,54,0,1)
Block(-8,54,1,1)
Block(-8,54,2,1)
Block(-8,54,3,1)
Block(-8,54,4,1)
Block(-8,54,5,1)
Block(-8,55,-5,1)
Block(-8,55,-4,1)
Block(-8,55,-3,1)
Block(-8,55,-2,1)
Block(-8,55,-1,1)
Block(-8,55,0,1)
Block(-8,55,1,1)
Block(-8,55,2,1)
Block(-8,55,3,1)
Block(-8,55,4,1)
Block(-8,55,5,1)
Block(-8,56,-6,1)
Block(-8,56,-5,1)
Block(-8,56,-4,1)
Block(-8,56,-3,1)
Block(-8,56,-2,1)
Block(-8,56,-1,1)
Block(-8,56,0,1)
Block(-8,56,1,1)
Block(-8,56,2,1)
Block(-8,56,3,1)
Block(-8,56,4,1)
Block(-8,56,5,1)
Block(-8,57,-6,1)
Block(-8,57,-5,1)
Block(-8,57,-4,1)
Block(-8,57,-3,1)
Block(-8,57,-2,1)
Block(-8,57,-1,1)
Block(-8,57,0,1)
Block(-8,57,1,1)
Block(-8,57,2,1)
Block(-8,57,3,1)
Block(-8,57,4,1)
Block(-8,57,5,1)
Block(-8,57,6,1)
Block(-8,58,-5,1)
Block(-8,58,-4,1)
Block(-8,58,-3,1)
Block(-8,58,-2,1)
Block(-8,58,-1,1)
Block(-8,58,0,1)
Block(-8,58,1,1)
Block(-8,58,2,1)
Block(-8,58,3,1)
Block(-8,58,4,1)
Block(-8,58,5,1)
Block(-8,58,6,1)
Block(-8,59,-5,1)
Block(-8,59,-4,1)
Block(-8,59,-3,1)
Block(-8,59,-2,1)
Block(-8,59,-1,1)
Block(-8,59,0,1)
Block(-8,59,1,1)
Block(-8,59,2,1)
Block(-8,59,3,1)
Block(-8,59,4,1)
Block(-8,59,5,1)
Block(-8,59,6,1)
Block(-8,60,-4,1)
Block(-8,60,-3,1)
Block(-8,60,-2,1)
Block(-8,60,-1,1)
Block(-8,60,0,1)
Block(-8,60,1,1)
Block(-8,60,2,1)
Block(-8,60,3,1)
Block(-8,60,4,1)
Block(-8,60,5,1)
Block(-8,60,6,1)
Block(-8,61,-4,1)
Block(-8,61,-3,1)
Block(-8,61,-2,1)
Block(-8,61,-1,1)
Block(-8,61,0,1)
Block(-8,61,1,1)
Block(-8,61,2,1)
Block(-8,61,3,1)
Block(-8,61,4,1)
Block(-8,61,5,1)
Block(-8,61,6,1)
Block(-8,62,-3,1)
Block(-8,62,-2,1)
Block(-8,62,-1,1)
Block(-8,62,0,1)
Block(-8,62,1,1)
Block(-8,62,2,1)
Block(-8,62,3,1)
Block(-8,62,4,1)
Block(-8,62,5,1)
Block(-8,63,-3,1)
Block(-8,63,-2,1)
Block(-8,63,-1,1)
Block(-8,63,0,1)
Block(-8,63,1,1)
Block(-8,63,2,1)
Block(-8,63,3,1)
Block(-8,63,4,1)
Block(-8,63,5,1)
Block(-8,64,-3,1)
Block(-8,64,-2,1)
Block(-8,64,-1,1)
Block(-8,64,0,1)
Block(-8,64,1,1)
Block(-8,64,2,1)
Block(-8,64,3,1)
Block(-8,64,4,1)
Block(-8,64,5,1)
Block(-8,65,-3,1)
Block(-8,65,-2,1)
Block(-8,65,-1,1)
Block(-8,65,0,1)
Block(-8,65,1,1)
Block(-8,65,2,1)
Block(-8,65,3,1)
Block(-8,65,4,1)
Block(-8,65,5,1)
Block(-8,66,-3,1)
Block(-8,66,-2,1)
Block(-8,66,-1,1)
Block(-8,66,0,1)
Block(-8,66,1,1)
Block(-8,66,2,1)
Block(-8,66,3,1)
Block(-8,66,4,1)
Block(-8,66,5,1)
Block(-8,67,-4,1)
Block(-8,67,-3,1)
Block(-8,67,-2,1)
Block(-8,67,-1,1)
Block(-8,67,0,1)
Block(-8,67,1,1)
Block(-8,67,2,1)
Block(-8,67,3,1)
Block(-8,67,4,1)
Block(-8,67,5,1)
Block(-8,68,-5,1)
Block(-8,68,-4,1)
Block(-8,68,-3,1)
Block(-8,68,-2,1)
Block(-8,68,-1,1)
Block(-8,68,0,1)
Block(-8,68,1,1)
Block(-8,68,2,1)
Block(-8,68,3,1)
Block(-8,68,4,1)
Block(-8,68,5,1)
Block(-8,68,6,1)
Block(-8,69,-5,1)
Block(-8,69,-4,1)
Block(-8,69,-3,1)
Block(-8,69,-2,1)
Block(-8,69,-1,1)
Block(-8,69,0,1)
Block(-8,69,1,1)
Block(-8,69,2,1)
Block(-8,69,3,1)
Block(-8,69,4,1)
Block(-8,69,5,1)
Block(-8,69,6,1)
Block(-8,70,-6,1)
Block(-8,70,-5,1)
Block(-8,70,-4,1)
Block(-8,70,-3,1)
Block(-8,70,-2,1)
Block(-8,70,-1,1)
Block(-8,70,0,1)
Block(-8,70,1,1)
Block(-8,70,2,1)
Block(-8,70,3,1)
Block(-8,70,4,1)
Block(-8,70,5,1)
Block(-8,70,6,1)
Block(-8,70,7,1)
Block(-8,71,-6,1)
Block(-8,71,-5,1)
Block(-8,71,-4,1)
Block(-8,71,-3,1)
Block(-8,71,-2,1)
Block(-8,71,-1,1)
Block(-8,71,0,1)
Block(-8,71,1,1)
Block(-8,71,2,1)
Block(-8,71,3,1)
Block(-8,71,4,1)
Block(-8,71,5,1)
Block(-8,71,6,1)
Block(-8,71,7,1)
Block(-8,72,-7,1)
Block(-8,72,-6,3)
Block(-8,72,-5,3)
Block(-8,72,-4,1)
Block(-8,72,-3,1)
Block(-8,72,-2,1)
Block(-8,72,-1,1)
Block(-8,72,0,1)
Block(-8,72,1,1)
Block(-8,72,2,1)
Block(-8,72,3,1)
Block(-8,72,4,1)
Block(-8,72,5,1)
Block(-8,72,6,1)
Block(-8,72,7,1)
Block(-8,73,-7,1)
Block(-8,73,-6,3)
Block(-8,73,-5,3)
Block(-8,73,-4,1)
Block(-8,73,-3,1)
Block(-8,73,-2,1)
Block(-8,73,-1,1)
Block(-8,73,0,1)
Block(-8,73,1,1)
Block(-8,73,2,1)
Block(-8,73,3,1)
Block(-8,73,4,1)
Block(-8,73,5,1)
Block(-8,73,6,1)
Block(-8,74,-6,1)
Block(-8,74,-5,3)
Block(-8,74,-4,3)
Block(-8,74,-3,1)
Block(-8,74,-2,1)
Block(-8,74,-1,1)
Block(-8,74,0,1)
Block(-8,74,1,1)
Block(-8,74,2,1)
Block(-8,74,3,1)
Block(-8,74,4,1)
Block(-8,74,5,1)
Block(-8,74,6,1)
Block(-8,75,-5,1)
Block(-8,75,-4,3)
Block(-8,75,-3,3)
Block(-8,75,-2,1)
Block(-8,75,-1,1)
Block(-8,75,0,1)
Block(-8,75,1,1)
Block(-8,75,2,1)
Block(-8,75,3,1)
Block(-8,75,4,1)
Block(-8,75,5,1)
Block(-8,75,6,1)
Block(-8,76,-4,1)
Block(-8,76,-3,3)
Block(-8,76,-2,3)
Block(-8,76,-1,1)
Block(-8,76,0,1)
Block(-8,76,1,1)
Block(-8,76,2,1)
Block(-8,76,3,1)
Block(-8,76,4,1)
Block(-8,76,5,1)
Block(-8,76,6,1)
Block(-8,77,-4,1)
Block(-8,77,-3,3)
Block(-8,77,-2,3)
Block(-8,77,-1,3)
Block(-8,77,0,1)
Block(-8,77,1,1)
Block(-8,77,2,1)
Block(-8,77,3,1)
Block(-8,77,4,1)
Block(-8,77,5,1)
Block(-8,78,-3,1)
Block(-8,78,-2,3)
Block(-8,78,-1,3)
Block(-8,78,0,1)
Block(-8,78,1,1)
Block(-8,78,2,1)
Block(-8,78,3,1)
Block(-8,78,4,1)
Block(-8,78,5,1)
Block(-8,79,-2,1)
Block(-8,79,-1,3)
Block(-8,79,0,3)
Block(-8,79,1,3)
Block(-8,79,2,3)
Block(-8,79,3,3)
Block(-8,79,4,1)
Block(-8,79,5,1)
Block(-8,80,-1,1)
Block(-8,80,0,3)
Block(-8,80,1,3)
Block(-8,80,2,3)
Block(-8,80,3,3)
Block(-8,80,4,1)
Block(-8,80,5,1)
Block(-8,81,0,1)
Block(-8,81,1,3)
Block(-8,81,2,3)
Block(-8,81,3,1)
Block(-8,81,4,1)
Block(-8,82,0,1)
Block(-8,82,1,2)
Block(-8,82,2,2)
Block(-8,82,3,1)
Block(-7,0,-7,1)
Block(-7,0,-6,1)
Block(-7,0,-5,1)
Block(-7,0,-4,1)
Block(-7,0,-3,1)
Block(-7,0,-2,1)
Block(-7,0,-1,1)
Block(-7,0,0,1)
Block(-7,0,1,1)
Block(-7,0,2,1)
Block(-7,0,3,1)
Block(-7,0,4,1)
Block(-7,0,5,1)
Block(-7,0,6,1)
Block(-7,0,7,1)
Block(-7,0,8,1)
Block(-7,1,-6,1)
Block(-7,1,-5,1)
Block(-7,1,-4,1)
Block(-7,1,-3,1)
Block(-7,1,-2,1)
Block(-7,1,-1,1)
Block(-7,1,0,1)
Block(-7,1,1,1)
Block(-7,1,2,1)
Block(-7,1,3,1)
Block(-7,1,4,1)
Block(-7,1,5,1)
Block(-7,1,6,1)
Block(-7,1,7,1)
Block(-7,2,-5,1)
Block(-7,2,-4,1)
Block(-7,2,-3,1)
Block(-7,2,-2,1)
Block(-7,2,-1,1)
Block(-7,2,0,1)
Block(-7,2,1,1)
Block(-7,2,2,1)
Block(-7,2,3,1)
Block(-7,2,4,1)
Block(-7,2,5,1)
Block(-7,2,6,1)
Block(-7,3,-4,1)
Block(-7,3,-3,1)
Block(-7,3,-2,1)
Block(-7,3,-1,1)
Block(-7,3,0,1)
Block(-7,3,1,1)
Block(-7,3,2,1)
Block(-7,3,3,1)
Block(-7,3,4,1)
Block(-7,3,5,1)
Block(-7,3,6,1)
Block(-7,4,-4,1)
Block(-7,4,-3,1)
Block(-7,4,-2,1)
Block(-7,4,-1,1)
Block(-7,4,0,1)
Block(-7,4,1,1)
Block(-7,4,2,1)
Block(-7,4,3,1)
Block(-7,4,4,1)
Block(-7,4,5,1)
Block(-7,4,6,1)
Block(-7,5,-5,1)
Block(-7,5,-4,1)
Block(-7,5,-3,1)
Block(-7,5,-2,1)
Block(-7,5,-1,1)
Block(-7,5,0,1)
Block(-7,5,1,1)
Block(-7,5,2,1)
Block(-7,5,3,1)
Block(-7,5,4,1)
Block(-7,5,5,1)
Block(-7,5,6,1)
Block(-7,6,-5,1)
Block(-7,6,-4,1)
Block(-7,6,-3,1)
Block(-7,6,-2,1)
Block(-7,6,-1,1)
Block(-7,6,0,1)
Block(-7,6,1,1)
Block(-7,6,2,1)
Block(-7,6,3,1)
Block(-7,6,4,1)
Block(-7,6,5,1)
Block(-7,6,6,1)
Block(-7,6,7,1)
Block(-7,7,-6,1)
Block(-7,7,-5,1)
Block(-7,7,-4,1)
Block(-7,7,-3,1)
Block(-7,7,-2,1)
Block(-7,7,-1,1)
Block(-7,7,0,1)
Block(-7,7,1,1)
Block(-7,7,2,1)
Block(-7,7,3,1)
Block(-7,7,4,1)
Block(-7,7,5,1)
Block(-7,7,6,1)
Block(-7,7,7,1)
Block(-7,8,-6,1)
Block(-7,8,-5,1)
Block(-7,8,-4,1)
Block(-7,8,-3,1)
Block(-7,8,-2,1)
Block(-7,8,-1,1)
Block(-7,8,0,1)
Block(-7,8,1,1)
Block(-7,8,2,1)
Block(-7,8,3,1)
Block(-7,8,4,1)
Block(-7,8,5,1)
Block(-7,8,6,1)
Block(-7,8,7,1)
Block(-7,9,-7,1)
Block(-7,9,-6,1)
Block(-7,9,-5,1)
Block(-7,9,-4,1)
Block(-7,9,-3,1)
Block(-7,9,-2,1)
Block(-7,9,-1,1)
Block(-7,9,0,1)
Block(-7,9,1,1)
Block(-7,9,2,1)
Block(-7,9,3,1)
Block(-7,9,4,1)
Block(-7,9,5,1)
Block(-7,9,6,1)
Block(-7,9,7,1)
Block(-7,9,8,1)
Block(-7,10,-7,1)
Block(-7,10,-6,1)
Block(-7,10,-5,1)
Block(-7,10,-4,1)
Block(-7,10,-3,1)
Block(-7,10,-2,1)
Block(-7,10,-1,1)
Block(-7,10,0,1)
Block(-7,10,1,1)
Block(-7,10,2,1)
Block(-7,10,3,1)
Block(-7,10,4,1)
Block(-7,10,5,1)
Block(-7,10,6,1)
Block(-7,10,7,1)
Block(-7,10,8,1)
Block(-7,11,-7,1)
Block(-7,11,-6,1)
Block(-7,11,-5,1)
Block(-7,11,-4,1)
Block(-7,11,-3,1)
Block(-7,11,-2,1)
Block(-7,11,-1,1)
Block(-7,11,0,1)
Block(-7,11,1,1)
Block(-7,11,2,1)
Block(-7,11,3,1)
Block(-7,11,4,1)
Block(-7,11,5,1)
Block(-7,11,6,1)
Block(-7,11,7,1)
Block(-7,11,8,1)
Block(-7,11,9,1)
Block(-7,12,-7,1)
Block(-7,12,-6,1)
Block(-7,12,-5,1)
Block(-7,12,-4,1)
Block(-7,12,-3,1)
Block(-7,12,-2,1)
Block(-7,12,-1,1)
Block(-7,12,0,1)
Block(-7,12,1,1)
Block(-7,12,2,1)
Block(-7,12,3,1)
Block(-7,12,4,1)
Block(-7,12,5,1)
Block(-7,12,6,1)
Block(-7,12,7,1)
Block(-7,12,8,1)
Block(-7,12,9,1)
Block(-7,13,-6,1)
Block(-7,13,-5,1)
Block(-7,13,-4,1)
Block(-7,13,-3,1)
Block(-7,13,-2,1)
Block(-7,13,-1,1)
Block(-7,13,0,1)
Block(-7,13,1,1)
Block(-7,13,2,1)
Block(-7,13,3,1)
Block(-7,13,4,1)
Block(-7,13,5,1)
Block(-7,13,6,1)
Block(-7,13,7,1)
Block(-7,13,8,1)
Block(-7,13,9,1)
Block(-7,14,-6,1)
Block(-7,14,-5,1)
Block(-7,14,-4,1)
Block(-7,14,-3,1)
Block(-7,14,-2,1)
Block(-7,14,-1,1)
Block(-7,14,0,1)
Block(-7,14,1,1)
Block(-7,14,2,1)
Block(-7,14,3,1)
Block(-7,14,4,1)
Block(-7,14,5,1)
Block(-7,14,6,1)
Block(-7,14,7,1)
Block(-7,14,8,1)
Block(-7,14,9,1)
Block(-7,15,-6,1)
Block(-7,15,-5,1)
Block(-7,15,-4,1)
Block(-7,15,-3,1)
Block(-7,15,-2,1)
Block(-7,15,-1,1)
Block(-7,15,0,1)
Block(-7,15,1,1)
Block(-7,15,2,1)
Block(-7,15,3,1)
Block(-7,15,4,1)
Block(-7,15,5,1)
Block(-7,15,6,1)
Block(-7,15,7,1)
Block(-7,15,8,1)
Block(-7,16,-6,1)
Block(-7,16,-5,1)
Block(-7,16,-4,1)
Block(-7,16,-3,1)
Block(-7,16,-2,1)
Block(-7,16,-1,1)
Block(-7,16,0,1)
Block(-7,16,1,1)
Block(-7,16,2,1)
Block(-7,16,3,1)
Block(-7,16,4,1)
Block(-7,16,5,1)
Block(-7,16,6,1)
Block(-7,16,7,1)
Block(-7,16,8,1)
Block(-7,17,-6,1)
Block(-7,17,-5,1)
Block(-7,17,-4,1)
Block(-7,17,-3,1)
Block(-7,17,-2,1)
Block(-7,17,-1,1)
Block(-7,17,0,1)
Block(-7,17,1,1)
Block(-7,17,2,1)
Block(-7,17,3,1)
Block(-7,17,4,1)
Block(-7,17,5,1)
Block(-7,17,6,1)
Block(-7,17,7,1)
Block(-7,17,8,1)
Block(-7,17,9,1)
Block(-7,18,-6,1)
Block(-7,18,-5,1)
Block(-7,18,-4,1)
Block(-7,18,-3,1)
Block(-7,18,-2,1)
Block(-7,18,-1,1)
Block(-7,18,0,1)
Block(-7,18,1,1)
Block(-7,18,2,1)
Block(-7,18,3,1)
Block(-7,18,4,1)
Block(-7,18,5,1)
Block(-7,18,6,1)
Block(-7,18,7,1)
Block(-7,18,8,1)
Block(-7,18,9,1)
Block(-7,19,-7,1)
Block(-7,19,-6,1)
Block(-7,19,-5,1)
Block(-7,19,-4,1)
Block(-7,19,-3,1)
Block(-7,19,-2,1)
Block(-7,19,-1,1)
Block(-7,19,0,1)
Block(-7,19,1,1)
Block(-7,19,2,1)
Block(-7,19,3,1)
Block(-7,19,4,1)
Block(-7,19,5,1)
Block(-7,19,6,1)
Block(-7,19,7,1)
Block(-7,19,8,1)
Block(-7,19,9,1)
Block(-7,20,-7,1)
Block(-7,20,-6,1)
Block(-7,20,-5,1)
Block(-7,20,-4,1)
Block(-7,20,-3,1)
Block(-7,20,-2,1)
Block(-7,20,-1,1)
Block(-7,20,0,1)
Block(-7,20,1,1)
Block(-7,20,2,1)
Block(-7,20,3,1)
Block(-7,20,4,1)
Block(-7,20,5,1)
Block(-7,20,6,1)
Block(-7,20,7,1)
Block(-7,20,8,1)
Block(-7,20,9,1)
Block(-7,21,-7,1)
Block(-7,21,-6,1)
Block(-7,21,-5,1)
Block(-7,21,-4,1)
Block(-7,21,-3,1)
Block(-7,21,-2,1)
Block(-7,21,-1,1)
Block(-7,21,0,1)
Block(-7,21,1,1)
Block(-7,21,2,1)
Block(-7,21,3,1)
Block(-7,21,4,1)
Block(-7,21,5,1)
Block(-7,21,6,1)
Block(-7,21,7,1)
Block(-7,21,8,1)
Block(-7,22,-7,1)
Block(-7,22,-6,1)
Block(-7,22,-5,1)
Block(-7,22,-4,1)
Block(-7,22,-3,1)
Block(-7,22,-2,1)
Block(-7,22,-1,1)
Block(-7,22,0,1)
Block(-7,22,1,1)
Block(-7,22,2,1)
Block(-7,22,3,1)
Block(-7,22,4,1)
Block(-7,22,5,1)
Block(-7,22,6,1)
Block(-7,22,7,1)
Block(-7,22,8,1)
Block(-7,23,-7,1)
Block(-7,23,-6,1)
Block(-7,23,-5,1)
Block(-7,23,-4,1)
Block(-7,23,-3,1)
Block(-7,23,-2,1)
Block(-7,23,-1,1)
Block(-7,23,0,1)
Block(-7,23,1,1)
Block(-7,23,2,1)
Block(-7,23,3,1)
Block(-7,23,4,1)
Block(-7,23,5,1)
Block(-7,23,6,1)
Block(-7,23,7,1)
Block(-7,23,8,1)
Block(-7,24,-7,1)
Block(-7,24,-6,1)
Block(-7,24,-5,1)
Block(-7,24,-4,1)
Block(-7,24,-3,1)
Block(-7,24,-2,1)
Block(-7,24,-1,1)
Block(-7,24,0,1)
Block(-7,24,1,1)
Block(-7,24,2,1)
Block(-7,24,3,1)
Block(-7,24,4,1)
Block(-7,24,5,1)
Block(-7,24,6,1)
Block(-7,24,7,1)
Block(-7,24,8,1)
Block(-7,25,-7,1)
Block(-7,25,-6,1)
Block(-7,25,-5,1)
Block(-7,25,-4,1)
Block(-7,25,-3,1)
Block(-7,25,-2,1)
Block(-7,25,-1,1)
Block(-7,25,0,1)
Block(-7,25,1,1)
Block(-7,25,2,1)
Block(-7,25,3,1)
Block(-7,25,4,1)
Block(-7,25,5,1)
Block(-7,25,6,1)
Block(-7,25,7,1)
Block(-7,25,8,1)
Block(-7,25,9,1)
Block(-7,26,-7,1)
Block(-7,26,-6,1)
Block(-7,26,-5,1)
Block(-7,26,-4,1)
Block(-7,26,-3,1)
Block(-7,26,-2,1)
Block(-7,26,-1,1)
Block(-7,26,0,1)
Block(-7,26,1,1)
Block(-7,26,2,1)
Block(-7,26,3,1)
Block(-7,26,4,1)
Block(-7,26,5,1)
Block(-7,26,6,1)
Block(-7,26,7,1)
Block(-7,26,8,1)
Block(-7,26,9,1)
Block(-7,27,-7,1)
Block(-7,27,-6,1)
Block(-7,27,-5,1)
Block(-7,27,-4,1)
Block(-7,27,-3,1)
Block(-7,27,-2,1)
Block(-7,27,-1,1)
Block(-7,27,0,1)
Block(-7,27,1,1)
Block(-7,27,2,1)
Block(-7,27,3,1)
Block(-7,27,4,1)
Block(-7,27,5,1)
Block(-7,27,6,1)
Block(-7,27,7,1)
Block(-7,27,8,1)
Block(-7,27,9,1)
Block(-7,28,-6,1)
Block(-7,28,-5,1)
Block(-7,28,-4,1)
Block(-7,28,-3,1)
Block(-7,28,-2,1)
Block(-7,28,-1,1)
Block(-7,28,0,1)
Block(-7,28,1,1)
Block(-7,28,2,1)
Block(-7,28,3,1)
Block(-7,28,4,1)
Block(-7,28,5,1)
Block(-7,28,6,1)
Block(-7,28,7,1)
Block(-7,28,8,1)
Block(-7,28,9,1)
Block(-7,29,-6,1)
Block(-7,29,-5,1)
Block(-7,29,-4,1)
Block(-7,29,-3,1)
Block(-7,29,-2,1)
Block(-7,29,-1,1)
Block(-7,29,0,1)
Block(-7,29,1,1)
Block(-7,29,2,1)
Block(-7,29,3,1)
Block(-7,29,4,1)
Block(-7,29,5,1)
Block(-7,29,6,1)
Block(-7,29,7,1)
Block(-7,29,8,1)
Block(-7,29,9,1)
Block(-7,30,-5,1)
Block(-7,30,-4,1)
Block(-7,30,-3,1)
Block(-7,30,-2,1)
Block(-7,30,-1,1)
Block(-7,30,0,1)
Block(-7,30,1,1)
Block(-7,30,2,1)
Block(-7,30,3,1)
Block(-7,30,4,1)
Block(-7,30,5,1)
Block(-7,30,6,1)
Block(-7,30,7,1)
Block(-7,30,8,1)
Block(-7,31,-5,1)
Block(-7,31,-4,1)
Block(-7,31,-3,1)
Block(-7,31,-2,1)
Block(-7,31,-1,1)
Block(-7,31,0,1)
Block(-7,31,1,1)
Block(-7,31,2,1)
Block(-7,31,3,1)
Block(-7,31,4,1)
Block(-7,31,5,1)
Block(-7,31,6,1)
Block(-7,31,7,1)
Block(-7,31,8,1)
Block(-7,32,-5,1)
Block(-7,32,-4,1)
Block(-7,32,-3,1)
Block(-7,32,-2,1)
Block(-7,32,-1,1)
Block(-7,32,0,1)
Block(-7,32,1,1)
Block(-7,32,2,1)
Block(-7,32,3,1)
Block(-7,32,4,1)
Block(-7,32,5,1)
Block(-7,32,6,1)
Block(-7,32,7,1)
Block(-7,32,8,1)
Block(-7,33,-5,1)
Block(-7,33,-4,1)
Block(-7,33,-3,1)
Block(-7,33,-2,1)
Block(-7,33,-1,1)
Block(-7,33,0,1)
Block(-7,33,1,1)
Block(-7,33,2,1)
Block(-7,33,3,1)
Block(-7,33,4,1)
Block(-7,33,5,1)
Block(-7,33,6,1)
Block(-7,33,7,1)
Block(-7,34,-5,1)
Block(-7,34,-4,1)
Block(-7,34,-3,1)
Block(-7,34,-2,1)
Block(-7,34,-1,1)
Block(-7,34,0,1)
Block(-7,34,1,1)
Block(-7,34,2,1)
Block(-7,34,3,1)
Block(-7,34,4,1)
Block(-7,34,5,1)
Block(-7,34,6,1)
Block(-7,34,7,1)
Block(-7,35,-4,1)
Block(-7,35,-3,1)
Block(-7,35,-2,1)
Block(-7,35,-1,1)
Block(-7,35,0,1)
Block(-7,35,1,1)
Block(-7,35,2,1)
Block(-7,35,3,1)
Block(-7,35,4,1)
Block(-7,35,5,1)
Block(-7,35,6,1)
Block(-7,35,7,1)
Block(-7,36,-4,1)
Block(-7,36,-3,1)
Block(-7,36,-2,1)
Block(-7,36,-1,1)
Block(-7,36,0,1)
Block(-7,36,1,1)
Block(-7,36,2,1)
Block(-7,36,3,1)
Block(-7,36,4,1)
Block(-7,36,5,1)
Block(-7,36,6,1)
Block(-7,36,7,1)
Block(-7,37,-4,1)
Block(-7,37,-3,1)
Block(-7,37,-2,1)
Block(-7,37,-1,1)
Block(-7,37,0,1)
Block(-7,37,1,1)
Block(-7,37,2,1)
Block(-7,37,3,1)
Block(-7,37,4,1)
Block(-7,37,5,1)
Block(-7,37,6,1)
Block(-7,37,7,1)
Block(-7,38,-5,1)
Block(-7,38,-4,1)
Block(-7,38,-3,1)
Block(-7,38,-2,1)
Block(-7,38,-1,1)
Block(-7,38,0,1)
Block(-7,38,1,1)
Block(-7,38,2,1)
Block(-7,38,3,1)
Block(-7,38,4,1)
Block(-7,38,5,1)
Block(-7,38,6,1)
Block(-7,38,7,1)
Block(-7,39,-6,1)
Block(-7,39,-5,1)
Block(-7,39,-4,1)
Block(-7,39,-3,1)
Block(-7,39,-2,1)
Block(-7,39,-1,1)
Block(-7,39,0,1)
Block(-7,39,1,1)
Block(-7,39,2,1)
Block(-7,39,3,1)
Block(-7,39,4,1)
Block(-7,39,5,1)
Block(-7,39,6,1)
Block(-7,39,7,1)
Block(-7,39,8,1)
Block(-7,40,-7,1)
Block(-7,40,-6,1)
Block(-7,40,-5,1)
Block(-7,40,-4,1)
Block(-7,40,-3,1)
Block(-7,40,-2,1)
Block(-7,40,-1,1)
Block(-7,40,0,1)
Block(-7,40,1,1)
Block(-7,40,2,1)
Block(-7,40,3,1)
Block(-7,40,4,1)
Block(-7,40,5,1)
Block(-7,40,6,1)
Block(-7,40,7,1)
Block(-7,40,8,1)
Block(-7,40,9,1)
Block(-7,41,-8,1)
Block(-7,41,-7,1)
Block(-7,41,-6,1)
Block(-7,41,-5,1)
Block(-7,41,-4,1)
Block(-7,41,-3,1)
Block(-7,41,-2,1)
Block(-7,41,-1,1)
Block(-7,41,0,1)
Block(-7,41,1,1)
Block(-7,41,2,1)
Block(-7,41,3,1)
Block(-7,41,4,1)
Block(-7,41,5,1)
Block(-7,41,6,1)
Block(-7,41,7,1)
Block(-7,41,8,1)
Block(-7,41,9,1)
Block(-7,42,-8,1)
Block(-7,42,-7,1)
Block(-7,42,-6,1)
Block(-7,42,-5,1)
Block(-7,42,-4,1)
Block(-7,42,-3,1)
Block(-7,42,-2,1)
Block(-7,42,-1,1)
Block(-7,42,0,1)
Block(-7,42,1,1)
Block(-7,42,2,1)
Block(-7,42,3,1)
Block(-7,42,4,1)
Block(-7,42,5,1)
Block(-7,42,6,1)
Block(-7,42,7,1)
Block(-7,42,8,1)
Block(-7,42,9,1)
Block(-7,43,-8,1)
Block(-7,43,-7,1)
Block(-7,43,-6,1)
Block(-7,43,-5,1)
Block(-7,43,-4,1)
Block(-7,43,-3,1)
Block(-7,43,-2,1)
Block(-7,43,-1,1)
Block(-7,43,0,1)
Block(-7,43,1,1)
Block(-7,43,2,1)
Block(-7,43,3,1)
Block(-7,43,4,1)
Block(-7,43,5,1)
Block(-7,43,6,1)
Block(-7,43,7,1)
Block(-7,43,8,1)
Block(-7,44,-8,1)
Block(-7,44,-7,1)
Block(-7,44,-6,1)
Block(-7,44,-5,1)
Block(-7,44,-4,1)
Block(-7,44,-3,1)
Block(-7,44,-2,1)
Block(-7,44,-1,1)
Block(-7,44,0,1)
Block(-7,44,1,1)
Block(-7,44,2,1)
Block(-7,44,3,1)
Block(-7,44,4,1)
Block(-7,44,5,1)
Block(-7,44,6,1)
Block(-7,44,7,1)
Block(-7,44,8,1)
Block(-7,45,-7,1)
Block(-7,45,-6,1)
Block(-7,45,-5,1)
Block(-7,45,-4,1)
Block(-7,45,-3,1)
Block(-7,45,-2,1)
Block(-7,45,-1,1)
Block(-7,45,0,1)
Block(-7,45,1,1)
Block(-7,45,2,1)
Block(-7,45,3,1)
Block(-7,45,4,1)
Block(-7,45,5,1)
Block(-7,45,6,1)
Block(-7,45,7,1)
Block(-7,46,-5,1)
Block(-7,46,-4,1)
Block(-7,46,-3,1)
Block(-7,46,-2,1)
Block(-7,46,-1,1)
Block(-7,46,0,1)
Block(-7,46,1,1)
Block(-7,46,2,1)
Block(-7,46,3,1)
Block(-7,46,4,1)
Block(-7,46,5,1)
Block(-7,46,6,1)
Block(-7,47,-4,1)
Block(-7,47,-3,1)
Block(-7,47,-2,1)
Block(-7,47,-1,1)
Block(-7,47,0,1)
Block(-7,47,1,1)
Block(-7,47,2,1)
Block(-7,47,3,1)
Block(-7,47,4,1)
Block(-7,47,5,1)
Block(-7,47,6,1)
Block(-7,48,-4,1)
Block(-7,48,-3,1)
Block(-7,48,-2,1)
Block(-7,48,-1,1)
Block(-7,48,0,1)
Block(-7,48,1,1)
Block(-7,48,2,1)
Block(-7,48,3,1)
Block(-7,48,4,1)
Block(-7,48,5,1)
Block(-7,48,6,1)
Block(-7,49,-4,1)
Block(-7,49,-3,1)
Block(-7,49,-2,1)
Block(-7,49,-1,1)
Block(-7,49,0,1)
Block(-7,49,1,1)
Block(-7,49,2,1)
Block(-7,49,3,1)
Block(-7,49,4,1)
Block(-7,49,5,1)
Block(-7,49,6,1)
Block(-7,50,-4,1)
Block(-7,50,-3,1)
Block(-7,50,-2,1)
Block(-7,50,-1,1)
Block(-7,50,0,1)
Block(-7,50,1,1)
Block(-7,50,2,1)
Block(-7,50,3,1)
Block(-7,50,4,1)
Block(-7,50,5,1)
Block(-7,50,6,1)
Block(-7,51,-5,1)
Block(-7,51,-4,1)
Block(-7,51,-3,1)
Block(-7,51,-2,1)
Block(-7,51,-1,1)
Block(-7,51,0,1)
Block(-7,51,1,1)
Block(-7,51,2,1)
Block(-7,51,3,1)
Block(-7,51,4,1)
Block(-7,51,5,1)
Block(-7,51,6,1)
Block(-7,52,-6,1)
Block(-7,52,-5,1)
Block(-7,52,-4,1)
Block(-7,52,-3,1)
Block(-7,52,-2,1)
Block(-7,52,-1,1)
Block(-7,52,0,1)
Block(-7,52,1,1)
Block(-7,52,2,1)
Block(-7,52,3,1)
Block(-7,52,4,1)
Block(-7,52,5,1)
Block(-7,52,6,1)
Block(-7,53,-7,1)
Block(-7,53,-6,1)
Block(-7,53,-5,1)
Block(-7,53,-4,1)
Block(-7,53,-3,1)
Block(-7,53,-2,1)
Block(-7,53,-1,1)
Block(-7,53,0,1)
Block(-7,53,1,1)
Block(-7,53,2,1)
Block(-7,53,3,1)
Block(-7,53,4,1)
Block(-7,53,5,1)
Block(-7,53,6,1)
Block(-7,54,-7,1)
Block(-7,54,-6,1)
Block(-7,54,-5,1)
Block(-7,54,-4,1)
Block(-7,54,-3,1)
Block(-7,54,-2,1)
Block(-7,54,-1,1)
Block(-7,54,0,1)
Block(-7,54,1,1)
Block(-7,54,2,1)
Block(-7,54,3,1)
Block(-7,54,4,1)
Block(-7,54,5,1)
Block(-7,54,6,1)
Block(-7,55,-7,1)
Block(-7,55,-6,1)
Block(-7,55,-5,1)
Block(-7,55,-4,1)
Block(-7,55,-3,1)
Block(-7,55,-2,1)
Block(-7,55,-1,1)
Block(-7,55,0,1)
Block(-7,55,1,1)
Block(-7,55,2,1)
Block(-7,55,3,1)
Block(-7,55,4,1)
Block(-7,55,5,1)
Block(-7,55,6,1)
Block(-7,56,-7,1)
Block(-7,56,-6,1)
Block(-7,56,-5,1)
Block(-7,56,-4,1)
Block(-7,56,-3,1)
Block(-7,56,-2,1)
Block(-7,56,-1,1)
Block(-7,56,0,1)
Block(-7,56,1,1)
Block(-7,56,2,1)
Block(-7,56,3,1)
Block(-7,56,4,1)
Block(-7,56,5,1)
Block(-7,56,6,1)
Block(-7,56,7,1)
Block(-7,57,-7,1)
Block(-7,57,-6,1)
Block(-7,57,-5,1)
Block(-7,57,-4,1)
Block(-7,57,-3,1)
Block(-7,57,-2,1)
Block(-7,57,-1,1)
Block(-7,57,0,1)
Block(-7,57,1,1)
Block(-7,57,2,1)
Block(-7,57,3,1)
Block(-7,57,4,1)
Block(-7,57,5,1)
Block(-7,57,6,1)
Block(-7,57,7,1)
Block(-7,58,-6,1)
Block(-7,58,-5,1)
Block(-7,58,-4,1)
Block(-7,58,-3,1)
Block(-7,58,-2,1)
Block(-7,58,-1,1)
Block(-7,58,0,1)
Block(-7,58,1,1)
Block(-7,58,2,1)
Block(-7,58,3,1)
Block(-7,58,4,1)
Block(-7,58,5,1)
Block(-7,58,6,1)
Block(-7,58,7,1)
Block(-7,59,-6,1)
Block(-7,59,-5,1)
Block(-7,59,-4,1)
Block(-7,59,-3,1)
Block(-7,59,-2,1)
Block(-7,59,-1,1)
Block(-7,59,0,1)
Block(-7,59,1,1)
Block(-7,59,2,1)
Block(-7,59,3,1)
Block(-7,59,4,1)
Block(-7,59,5,1)
Block(-7,59,6,1)
Block(-7,59,7,1)
Block(-7,60,-5,1)
Block(-7,60,-4,1)
Block(-7,60,-3,1)
Block(-7,60,-2,1)
Block(-7,60,-1,1)
Block(-7,60,0,1)
Block(-7,60,1,1)
Block(-7,60,2,1)
Block(-7,60,3,1)
Block(-7,60,4,1)
Block(-7,60,5,1)
Block(-7,60,6,1)
Block(-7,60,7,1)
Block(-7,61,-5,1)
Block(-7,61,-4,1)
Block(-7,61,-3,1)
Block(-7,61,-2,1)
Block(-7,61,-1,1)
Block(-7,61,0,1)
Block(-7,61,1,1)
Block(-7,61,2,1)
Block(-7,61,3,1)
Block(-7,61,4,1)
Block(-7,61,5,1)
Block(-7,61,6,1)
Block(-7,61,7,1)
Block(-7,62,-5,1)
Block(-7,62,-4,1)
Block(-7,62,-3,1)
Block(-7,62,-2,1)
Block(-7,62,-1,1)
Block(-7,62,0,1)
Block(-7,62,1,1)
Block(-7,62,2,1)
Block(-7,62,3,1)
Block(-7,62,4,1)
Block(-7,62,5,1)
Block(-7,62,6,1)
Block(-7,62,7,1)
Block(-7,63,-4,1)
Block(-7,63,-3,1)
Block(-7,63,-2,1)
Block(-7,63,-1,1)
Block(-7,63,0,1)
Block(-7,63,1,1)
Block(-7,63,2,1)
Block(-7,63,3,1)
Block(-7,63,4,1)
Block(-7,63,5,1)
Block(-7,63,6,1)
Block(-7,64,-4,1)
Block(-7,64,-3,1)
Block(-7,64,-2,1)
Block(-7,64,-1,1)
Block(-7,64,0,1)
Block(-7,64,1,1)
Block(-7,64,2,1)
Block(-7,64,3,1)
Block(-7,64,4,1)
Block(-7,64,5,1)
Block(-7,64,6,1)
Block(-7,65,-4,1)
Block(-7,65,-3,1)
Block(-7,65,-2,1)
Block(-7,65,-1,1)
Block(-7,65,0,1)
Block(-7,65,1,1)
Block(-7,65,2,1)
Block(-7,65,3,1)
Block(-7,65,4,1)
Block(-7,65,5,1)
Block(-7,65,6,1)
Block(-7,66,-4,1)
Block(-7,66,-3,1)
Block(-7,66,-2,1)
Block(-7,66,-1,1)
Block(-7,66,0,1)
Block(-7,66,1,1)
Block(-7,66,2,1)
Block(-7,66,3,1)
Block(-7,66,4,1)
Block(-7,66,5,1)
Block(-7,66,6,1)
Block(-7,66,7,1)
Block(-7,67,-5,1)
Block(-7,67,-4,1)
Block(-7,67,-3,1)
Block(-7,67,-2,1)
Block(-7,67,-1,1)
Block(-7,67,0,1)
Block(-7,67,1,1)
Block(-7,67,2,1)
Block(-7,67,3,1)
Block(-7,67,4,1)
Block(-7,67,5,1)
Block(-7,67,6,1)
Block(-7,67,7,1)
Block(-7,68,-5,1)
Block(-7,68,-4,1)
Block(-7,68,-3,1)
Block(-7,68,-2,1)
Block(-7,68,-1,1)
Block(-7,68,0,1)
Block(-7,68,1,1)
Block(-7,68,2,1)
Block(-7,68,3,1)
Block(-7,68,4,1)
Block(-7,68,5,1)
Block(-7,68,6,1)
Block(-7,68,7,1)
Block(-7,69,-6,1)
Block(-7,69,-5,1)
Block(-7,69,-4,1)
Block(-7,69,-3,1)
Block(-7,69,-2,1)
Block(-7,69,-1,1)
Block(-7,69,0,1)
Block(-7,69,1,1)
Block(-7,69,2,1)
Block(-7,69,3,1)
Block(-7,69,4,1)
Block(-7,69,5,1)
Block(-7,69,6,1)
Block(-7,69,7,1)
Block(-7,69,8,1)
Block(-7,70,-6,1)
Block(-7,70,-5,1)
Block(-7,70,-4,1)
Block(-7,70,-3,1)
Block(-7,70,-2,1)
Block(-7,70,-1,1)
Block(-7,70,0,1)
Block(-7,70,1,1)
Block(-7,70,2,1)
Block(-7,70,3,1)
Block(-7,70,4,1)
Block(-7,70,5,1)
Block(-7,70,6,1)
Block(-7,70,7,1)
Block(-7,70,8,1)
Block(-7,70,9,1)
Block(-7,71,-7,1)
Block(-7,71,-6,1)
Block(-7,71,-5,1)
Block(-7,71,-4,1)
Block(-7,71,-3,1)
Block(-7,71,-2,1)
Block(-7,71,-1,1)
Block(-7,71,0,1)
Block(-7,71,1,1)
Block(-7,71,2,1)
Block(-7,71,3,1)
Block(-7,71,4,1)
Block(-7,71,5,1)
Block(-7,71,6,1)
Block(-7,71,7,1)
Block(-7,71,8,1)
Block(-7,71,9,1)
Block(-7,72,-7,1)
Block(-7,72,-6,1)
Block(-7,72,-5,1)
Block(-7,72,-4,1)
Block(-7,72,-3,1)
Block(-7,72,-2,1)
Block(-7,72,-1,1)
Block(-7,72,0,1)
Block(-7,72,1,1)
Block(-7,72,2,1)
Block(-7,72,3,1)
Block(-7,72,4,1)
Block(-7,72,5,1)
Block(-7,72,6,1)
Block(-7,72,7,1)
Block(-7,72,8,1)
Block(-7,73,-7,1)
Block(-7,73,-6,3)
Block(-7,73,-5,1)
Block(-7,73,-4,1)
Block(-7,73,-3,1)
Block(-7,73,-2,1)
Block(-7,73,-1,1)
Block(-7,73,0,1)
Block(-7,73,1,1)
Block(-7,73,2,1)
Block(-7,73,3,1)
Block(-7,73,4,1)
Block(-7,73,5,1)
Block(-7,73,6,1)
Block(-7,73,7,1)
Block(-7,73,8,1)
Block(-7,74,-7,1)
Block(-7,74,-6,3)
Block(-7,74,-5,3)
Block(-7,74,-4,1)
Block(-7,74,-3,1)
Block(-7,74,-2,1)
Block(-7,74,-1,1)
Block(-7,74,0,1)
Block(-7,74,1,1)
Block(-7,74,2,1)
Block(-7,74,3,1)
Block(-7,74,4,1)
Block(-7,74,5,1)
Block(-7,74,6,1)
Block(-7,74,7,1)
Block(-7,74,8,1)
Block(-7,75,-6,1)
Block(-7,75,-5,3)
Block(-7,75,-4,3)
Block(-7,75,-3,1)
Block(-7,75,-2,1)
Block(-7,75,-1,1)
Block(-7,75,0,1)
Block(-7,75,1,1)
Block(-7,75,2,1)
Block(-7,75,3,1)
Block(-7,75,4,1)
Block(-7,75,5,1)
Block(-7,75,6,1)
Block(-7,75,7,1)
Block(-7,75,8,1)
Block(-7,76,-6,1)
Block(-7,76,-5,1)
Block(-7,76,-4,3)
Block(-7,76,-3,3)
Block(-7,76,-2,1)
Block(-7,76,-1,1)
Block(-7,76,0,1)
Block(-7,76,1,1)
Block(-7,76,2,1)
Block(-7,76,3,1)
Block(-7,76,4,1)
Block(-7,76,5,1)
Block(-7,76,6,1)
Block(-7,76,7,1)
Block(-7,76,8,1)
Block(-7,77,-5,1)
Block(-7,77,-4,3)
Block(-7,77,-3,3)
Block(-7,77,-2,3)
Block(-7,77,-1,1)
Block(-7,77,0,1)
Block(-7,77,1,1)
Block(-7,77,2,1)
Block(-7,77,3,1)
Block(-7,77,4,1)
Block(-7,77,5,1)
Block(-7,77,6,1)
Block(-7,77,7,1)
Block(-7,78,-4,1)
Block(-7,78,-3,3)
Block(-7,78,-2,3)
Block(-7,78,-1,1)
Block(-7,78,0,1)
Block(-7,78,1,1)
Block(-7,78,2,1)
Block(-7,78,3,1)
Block(-7,78,4,1)
Block(-7,78,5,1)
Block(-7,78,6,1)
Block(-7,78,7,1)
Block(-7,79,-3,1)
Block(-7,79,-2,3)
Block(-7,79,-1,3)
Block(-7,79,0,1)
Block(-7,79,1,1)
Block(-7,79,2,1)
Block(-7,79,3,1)
Block(-7,79,4,3)
Block(-7,79,5,3)
Block(-7,79,6,1)
Block(-7,80,-2,1)
Block(-7,80,-1,3)
Block(-7,80,0,3)
Block(-7,80,1,3)
Block(-7,80,2,3)
Block(-7,80,3,3)
Block(-7,80,4,3)
Block(-7,80,5,3)
Block(-7,80,6,1)
Block(-7,81,-1,1)
Block(-7,81,0,3)
Block(-7,81,1,3)
Block(-7,81,2,3)
Block(-7,81,3,3)
Block(-7,81,4,3)
Block(-7,81,5,1)
Block(-7,81,6,1)
Block(-7,82,-1,1)
Block(-7,82,0,3)
Block(-7,82,1,3)
Block(-7,82,2,3)
Block(-7,82,3,3)
Block(-7,82,4,2)
Block(-7,82,5,1)
Block(-7,83,0,1)
Block(-7,83,1,2)
Block(-7,83,2,2)
Block(-7,83,3,2)
Block(-6,0,-8,1)
Block(-6,0,-7,1)
Block(-6,0,-6,1)
Block(-6,0,-5,1)
Block(-6,0,-4,1)
Block(-6,0,-3,1)
Block(-6,0,-2,1)
Block(-6,0,-1,1)
Block(-6,0,0,1)
Block(-6,0,1,1)
Block(-6,0,2,1)
Block(-6,0,3,1)
Block(-6,0,4,1)
Block(-6,0,5,1)
Block(-6,0,6,1)
Block(-6,0,7,1)
Block(-6,0,8,1)
Block(-6,0,9,1)
Block(-6,1,-7,1)
Block(-6,1,-6,1)
Block(-6,1,-5,1)
Block(-6,1,-4,1)
Block(-6,1,-3,1)
Block(-6,1,-2,1)
Block(-6,1,-1,1)
Block(-6,1,0,1)
Block(-6,1,1,1)
Block(-6,1,2,1)
Block(-6,1,3,1)
Block(-6,1,4,1)
Block(-6,1,5,1)
Block(-6,1,6,1)
Block(-6,1,7,1)
Block(-6,1,8,1)
Block(-6,2,-6,1)
Block(-6,2,-5,1)
Block(-6,2,-4,1)
Block(-6,2,-3,1)
Block(-6,2,-2,1)
Block(-6,2,-1,1)
Block(-6,2,0,1)
Block(-6,2,1,1)
Block(-6,2,2,1)
Block(-6,2,3,1)
Block(-6,2,4,1)
Block(-6,2,5,1)
Block(-6,2,6,1)
Block(-6,2,7,1)
Block(-6,3,-5,1)
Block(-6,3,-4,1)
Block(-6,3,-3,1)
Block(-6,3,-2,1)
Block(-6,3,-1,1)
Block(-6,3,0,1)
Block(-6,3,1,1)
Block(-6,3,2,1)
Block(-6,3,3,1)
Block(-6,3,4,1)
Block(-6,3,5,1)
Block(-6,3,6,1)
Block(-6,3,7,1)
Block(-6,4,-5,1)
Block(-6,4,-4,1)
Block(-6,4,-3,1)
Block(-6,4,-2,1)
Block(-6,4,-1,1)
Block(-6,4,0,1)
Block(-6,4,1,1)
Block(-6,4,2,1)
Block(-6,4,3,1)
Block(-6,4,4,1)
Block(-6,4,5,1)
Block(-6,4,6,1)
Block(-6,4,7,1)
Block(-6,5,-5,1)
Block(-6,5,-4,1)
Block(-6,5,-3,1)
Block(-6,5,-2,1)
Block(-6,5,-1,1)
Block(-6,5,0,1)
Block(-6,5,1,1)
Block(-6,5,2,1)
Block(-6,5,3,1)
Block(-6,5,4,1)
Block(-6,5,5,1)
Block(-6,5,6,1)
Block(-6,5,7,1)
Block(-6,6,-6,1)
Block(-6,6,-5,1)
Block(-6,6,-4,1)
Block(-6,6,-3,1)
Block(-6,6,-2,1)
Block(-6,6,-1,1)
Block(-6,6,0,1)
Block(-6,6,1,1)
Block(-6,6,2,1)
Block(-6,6,3,1)
Block(-6,6,4,1)
Block(-6,6,5,1)
Block(-6,6,6,1)
Block(-6,6,7,1)
Block(-6,6,8,1)
Block(-6,7,-6,1)
Block(-6,7,-5,1)
Block(-6,7,-4,1)
Block(-6,7,-3,1)
Block(-6,7,-2,1)
Block(-6,7,-1,1)
Block(-6,7,0,1)
Block(-6,7,1,1)
Block(-6,7,2,1)
Block(-6,7,3,1)
Block(-6,7,4,1)
Block(-6,7,5,1)
Block(-6,7,6,1)
Block(-6,7,7,1)
Block(-6,7,8,1)
Block(-6,8,-7,1)
Block(-6,8,-6,1)
Block(-6,8,-5,1)
Block(-6,8,-4,1)
Block(-6,8,-3,1)
Block(-6,8,-2,1)
Block(-6,8,-1,1)
Block(-6,8,0,1)
Block(-6,8,1,1)
Block(-6,8,2,1)
Block(-6,8,3,1)
Block(-6,8,4,1)
Block(-6,8,5,1)
Block(-6,8,6,1)
Block(-6,8,7,1)
Block(-6,8,8,1)
Block(-6,9,-7,1)
Block(-6,9,-6,1)
Block(-6,9,-5,1)
Block(-6,9,-4,1)
Block(-6,9,-3,1)
Block(-6,9,-2,1)
Block(-6,9,-1,1)
Block(-6,9,0,1)
Block(-6,9,1,1)
Block(-6,9,2,1)
Block(-6,9,3,1)
Block(-6,9,4,1)
Block(-6,9,5,1)
Block(-6,9,6,1)
Block(-6,9,7,1)
Block(-6,9,8,1)
Block(-6,9,9,1)
Block(-6,10,-7,1)
Block(-6,10,-6,1)
Block(-6,10,-5,1)
Block(-6,10,-4,1)
Block(-6,10,-3,1)
Block(-6,10,-2,1)
Block(-6,10,-1,1)
Block(-6,10,0,1)
Block(-6,10,1,1)
Block(-6,10,2,1)
Block(-6,10,3,1)
Block(-6,10,4,1)
Block(-6,10,5,1)
Block(-6,10,6,1)
Block(-6,10,7,1)
Block(-6,10,8,1)
Block(-6,10,9,1)
Block(-6,11,-8,1)
Block(-6,11,-7,1)
Block(-6,11,-6,1)
Block(-6,11,-5,1)
Block(-6,11,-4,1)
Block(-6,11,-3,1)
Block(-6,11,-2,1)
Block(-6,11,-1,1)
Block(-6,11,0,1)
Block(-6,11,1,1)
Block(-6,11,2,1)
Block(-6,11,3,1)
Block(-6,11,4,1)
Block(-6,11,5,1)
Block(-6,11,6,1)
Block(-6,11,7,1)
Block(-6,11,8,1)
Block(-6,11,9,1)
Block(-6,11,10,1)
Block(-6,12,-8,1)
Block(-6,12,-7,1)
Block(-6,12,-6,1)
Block(-6,12,-5,1)
Block(-6,12,-4,1)
Block(-6,12,-3,1)
Block(-6,12,-2,1)
Block(-6,12,-1,1)
Block(-6,12,0,1)
Block(-6,12,1,1)
Block(-6,12,2,1)
Block(-6,12,3,1)
Block(-6,12,4,1)
Block(-6,12,5,1)
Block(-6,12,6,1)
Block(-6,12,7,1)
Block(-6,12,8,1)
Block(-6,12,9,1)
Block(-6,12,10,1)
Block(-6,13,-8,1)
Block(-6,13,-7,1)
Block(-6,13,-6,1)
Block(-6,13,-5,1)
Block(-6,13,-4,1)
Block(-6,13,-3,1)
Block(-6,13,-2,1)
Block(-6,13,-1,1)
Block(-6,13,0,1)
Block(-6,13,1,1)
Block(-6,13,2,1)
Block(-6,13,3,1)
Block(-6,13,4,1)
Block(-6,13,5,1)
Block(-6,13,6,1)
Block(-6,13,7,1)
Block(-6,13,8,1)
Block(-6,13,9,1)
Block(-6,13,10,1)
Block(-6,14,-7,1)
Block(-6,14,-6,1)
Block(-6,14,-5,1)
Block(-6,14,-4,1)
Block(-6,14,-3,1)
Block(-6,14,-2,1)
Block(-6,14,-1,1)
Block(-6,14,0,1)
Block(-6,14,1,1)
Block(-6,14,2,1)
Block(-6,14,3,1)
Block(-6,14,4,1)
Block(-6,14,5,1)
Block(-6,14,6,1)
Block(-6,14,7,1)
Block(-6,14,8,1)
Block(-6,14,9,1)
Block(-6,14,10,1)
Block(-6,15,-7,1)
Block(-6,15,-6,1)
Block(-6,15,-5,1)
Block(-6,15,-4,1)
Block(-6,15,-3,1)
Block(-6,15,-2,1)
Block(-6,15,-1,1)
Block(-6,15,0,1)
Block(-6,15,1,1)
Block(-6,15,2,1)
Block(-6,15,3,1)
Block(-6,15,4,1)
Block(-6,15,5,1)
Block(-6,15,6,1)
Block(-6,15,7,1)
Block(-6,15,8,1)
Block(-6,15,9,1)
Block(-6,15,10,1)
Block(-6,16,-7,1)
Block(-6,16,-6,1)
Block(-6,16,-5,1)
Block(-6,16,-4,1)
Block(-6,16,-3,1)
Block(-6,16,-2,1)
Block(-6,16,-1,1)
Block(-6,16,0,1)
Block(-6,16,1,1)
Block(-6,16,2,1)
Block(-6,16,3,1)
Block(-6,16,4,1)
Block(-6,16,5,1)
Block(-6,16,6,1)
Block(-6,16,7,1)
Block(-6,16,8,1)
Block(-6,16,9,1)
Block(-6,16,10,1)
Block(-6,17,-7,1)
Block(-6,17,-6,1)
Block(-6,17,-5,1)
Block(-6,17,-4,1)
Block(-6,17,-3,1)
Block(-6,17,-2,1)
Block(-6,17,-1,1)
Block(-6,17,0,1)
Block(-6,17,1,1)
Block(-6,17,2,1)
Block(-6,17,3,1)
Block(-6,17,4,1)
Block(-6,17,5,1)
Block(-6,17,6,1)
Block(-6,17,7,1)
Block(-6,17,8,1)
Block(-6,17,9,1)
Block(-6,17,10,1)
Block(-6,18,-8,1)
Block(-6,18,-7,1)
Block(-6,18,-6,1)
Block(-6,18,-5,1)
Block(-6,18,-4,1)
Block(-6,18,-3,1)
Block(-6,18,-2,1)
Block(-6,18,-1,1)
Block(-6,18,0,1)
Block(-6,18,1,1)
Block(-6,18,2,1)
Block(-6,18,3,1)
Block(-6,18,4,1)
Block(-6,18,5,1)
Block(-6,18,6,1)
Block(-6,18,7,1)
Block(-6,18,8,1)
Block(-6,18,9,1)
Block(-6,18,10,1)
Block(-6,19,-8,1)
Block(-6,19,-7,1)
Block(-6,19,-6,1)
Block(-6,19,-5,1)
Block(-6,19,-4,1)
Block(-6,19,-3,1)
Block(-6,19,-2,1)
Block(-6,19,-1,1)
Block(-6,19,0,1)
Block(-6,19,1,1)
Block(-6,19,2,1)
Block(-6,19,3,1)
Block(-6,19,4,1)
Block(-6,19,5,1)
Block(-6,19,6,1)
Block(-6,19,7,1)
Block(-6,19,8,1)
Block(-6,19,9,1)
Block(-6,19,10,1)
Block(-6,20,-8,1)
Block(-6,20,-7,1)
Block(-6,20,-6,1)
Block(-6,20,-5,1)
Block(-6,20,-4,1)
Block(-6,20,-3,1)
Block(-6,20,-2,1)
Block(-6,20,-1,1)
Block(-6,20,0,1)
Block(-6,20,1,1)
Block(-6,20,2,1)
Block(-6,20,3,1)
Block(-6,20,4,1)
Block(-6,20,5,1)
Block(-6,20,6,1)
Block(-6,20,7,1)
Block(-6,20,8,1)
Block(-6,20,9,1)
Block(-6,20,10,1)
Block(-6,21,-8,1)
Block(-6,21,-7,1)
Block(-6,21,-6,1)
Block(-6,21,-5,1)
Block(-6,21,-4,1)
Block(-6,21,-3,1)
Block(-6,21,-2,1)
Block(-6,21,-1,1)
Block(-6,21,0,1)
Block(-6,21,1,1)
Block(-6,21,2,1)
Block(-6,21,3,1)
Block(-6,21,4,1)
Block(-6,21,5,1)
Block(-6,21,6,1)
Block(-6,21,7,1)
Block(-6,21,8,1)
Block(-6,21,9,1)
Block(-6,22,-7,1)
Block(-6,22,-6,1)
Block(-6,22,-5,1)
Block(-6,22,-4,1)
Block(-6,22,-3,1)
Block(-6,22,-2,1)
Block(-6,22,-1,1)
Block(-6,22,0,1)
Block(-6,22,1,1)
Block(-6,22,2,1)
Block(-6,22,3,1)
Block(-6,22,4,1)
Block(-6,22,5,1)
Block(-6,22,6,1)
Block(-6,22,7,1)
Block(-6,22,8,1)
Block(-6,22,9,1)
Block(-6,23,-7,1)
Block(-6,23,-6,1)
Block(-6,23,-5,1)
Block(-6,23,-4,1)
Block(-6,23,-3,1)
Block(-6,23,-2,1)
Block(-6,23,-1,1)
Block(-6,23,0,1)
Block(-6,23,1,1)
Block(-6,23,2,1)
Block(-6,23,3,1)
Block(-6,23,4,1)
Block(-6,23,5,1)
Block(-6,23,6,1)
Block(-6,23,7,1)
Block(-6,23,8,1)
Block(-6,24,-7,1)
Block(-6,24,-6,1)
Block(-6,24,-5,1)
Block(-6,24,-4,1)
Block(-6,24,-3,1)
Block(-6,24,-2,1)
Block(-6,24,-1,1)
Block(-6,24,0,1)
Block(-6,24,1,1)
Block(-6,24,2,1)
Block(-6,24,3,1)
Block(-6,24,4,1)
Block(-6,24,5,1)
Block(-6,24,6,1)
Block(-6,24,7,1)
Block(-6,24,8,1)
Block(-6,24,9,1)
Block(-6,25,-7,1)
Block(-6,25,-6,1)
Block(-6,25,-5,1)
Block(-6,25,-4,1)
Block(-6,25,-3,1)
Block(-6,25,-2,1)
Block(-6,25,-1,1)
Block(-6,25,0,1)
Block(-6,25,1,1)
Block(-6,25,2,1)
Block(-6,25,3,1)
Block(-6,25,4,1)
Block(-6,25,5,1)
Block(-6,25,6,1)
Block(-6,25,7,1)
Block(-6,25,8,1)
Block(-6,25,9,1)
Block(-6,26,-8,1)
Block(-6,26,-7,1)
Block(-6,26,-6,1)
Block(-6,26,-5,1)
Block(-6,26,-4,1)
Block(-6,26,-3,1)
Block(-6,26,-2,1)
Block(-6,26,-1,1)
Block(-6,26,0,1)
Block(-6,26,1,1)
Block(-6,26,2,1)
Block(-6,26,3,1)
Block(-6,26,4,1)
Block(-6,26,5,1)
Block(-6,26,6,1)
Block(-6,26,7,1)
Block(-6,26,8,1)
Block(-6,26,9,1)
Block(-6,26,10,1)
Block(-6,27,-8,1)
Block(-6,27,-7,1)
Block(-6,27,-6,1)
Block(-6,27,-5,1)
Block(-6,27,-4,1)
Block(-6,27,-3,1)
Block(-6,27,-2,1)
Block(-6,27,-1,1)
Block(-6,27,0,1)
Block(-6,27,1,1)
Block(-6,27,2,1)
Block(-6,27,3,1)
Block(-6,27,4,1)
Block(-6,27,5,1)
Block(-6,27,6,1)
Block(-6,27,7,1)
Block(-6,27,8,1)
Block(-6,27,9,1)
Block(-6,27,10,1)
Block(-6,28,-7,1)
Block(-6,28,-6,1)
Block(-6,28,-5,1)
Block(-6,28,-4,1)
Block(-6,28,-3,1)
Block(-6,28,-2,1)
Block(-6,28,-1,1)
Block(-6,28,0,1)
Block(-6,28,1,1)
Block(-6,28,2,1)
Block(-6,28,3,1)
Block(-6,28,4,1)
Block(-6,28,5,1)
Block(-6,28,6,1)
Block(-6,28,7,1)
Block(-6,28,8,1)
Block(-6,28,9,1)
Block(-6,28,10,1)
Block(-6,29,-7,1)
Block(-6,29,-6,1)
Block(-6,29,-5,1)
Block(-6,29,-4,1)
Block(-6,29,-3,1)
Block(-6,29,-2,1)
Block(-6,29,-1,1)
Block(-6,29,0,1)
Block(-6,29,1,1)
Block(-6,29,2,1)
Block(-6,29,3,1)
Block(-6,29,4,1)
Block(-6,29,5,1)
Block(-6,29,6,1)
Block(-6,29,7,1)
Block(-6,29,8,1)
Block(-6,29,9,1)
Block(-6,29,10,1)
Block(-6,30,-7,1)
Block(-6,30,-6,1)
Block(-6,30,-5,1)
Block(-6,30,-4,1)
Block(-6,30,-3,1)
Block(-6,30,-2,1)
Block(-6,30,-1,1)
Block(-6,30,0,1)
Block(-6,30,1,1)
Block(-6,30,2,1)
Block(-6,30,3,1)
Block(-6,30,4,1)
Block(-6,30,5,1)
Block(-6,30,6,1)
Block(-6,30,7,1)
Block(-6,30,8,1)
Block(-6,30,9,1)
Block(-6,30,10,1)
Block(-6,31,-7,1)
Block(-6,31,-6,1)
Block(-6,31,-5,1)
Block(-6,31,-4,1)
Block(-6,31,-3,1)
Block(-6,31,-2,1)
Block(-6,31,-1,1)
Block(-6,31,0,1)
Block(-6,31,1,1)
Block(-6,31,2,1)
Block(-6,31,3,1)
Block(-6,31,4,1)
Block(-6,31,5,1)
Block(-6,31,6,1)
Block(-6,31,7,1)
Block(-6,31,8,1)
Block(-6,31,9,1)
Block(-6,32,-6,1)
Block(-6,32,-5,1)
Block(-6,32,-4,1)
Block(-6,32,-3,1)
Block(-6,32,-2,1)
Block(-6,32,-1,1)
Block(-6,32,0,1)
Block(-6,32,1,1)
Block(-6,32,2,1)
Block(-6,32,3,1)
Block(-6,32,4,1)
Block(-6,32,5,1)
Block(-6,32,6,1)
Block(-6,32,7,1)
Block(-6,32,8,1)
Block(-6,32,9,1)
Block(-6,33,-6,1)
Block(-6,33,-5,1)
Block(-6,33,-4,1)
Block(-6,33,-3,1)
Block(-6,33,-2,1)
Block(-6,33,-1,1)
Block(-6,33,0,1)
Block(-6,33,1,1)
Block(-6,33,2,1)
Block(-6,33,3,1)
Block(-6,33,4,1)
Block(-6,33,5,1)
Block(-6,33,6,1)
Block(-6,33,7,1)
Block(-6,33,8,1)
Block(-6,33,9,1)
Block(-6,34,-6,1)
Block(-6,34,-5,1)
Block(-6,34,-4,1)
Block(-6,34,-3,1)
Block(-6,34,-2,1)
Block(-6,34,-1,1)
Block(-6,34,0,1)
Block(-6,34,1,1)
Block(-6,34,2,1)
Block(-6,34,3,1)
Block(-6,34,4,1)
Block(-6,34,5,1)
Block(-6,34,6,1)
Block(-6,34,7,1)
Block(-6,34,8,1)
Block(-6,34,9,1)
Block(-6,35,-6,1)
Block(-6,35,-5,1)
Block(-6,35,-4,1)
Block(-6,35,-3,1)
Block(-6,35,-2,1)
Block(-6,35,-1,1)
Block(-6,35,0,1)
Block(-6,35,1,1)
Block(-6,35,2,1)
Block(-6,35,3,1)
Block(-6,35,4,1)
Block(-6,35,5,1)
Block(-6,35,6,1)
Block(-6,35,7,1)
Block(-6,35,8,1)
Block(-6,36,-6,1)
Block(-6,36,-5,1)
Block(-6,36,-4,1)
Block(-6,36,-3,1)
Block(-6,36,-2,1)
Block(-6,36,-1,1)
Block(-6,36,0,1)
Block(-6,36,1,1)
Block(-6,36,2,1)
Block(-6,36,3,1)
Block(-6,36,4,1)
Block(-6,36,5,1)
Block(-6,36,6,1)
Block(-6,36,7,1)
Block(-6,36,8,1)
Block(-6,37,-6,1)
Block(-6,37,-5,1)
Block(-6,37,-4,1)
Block(-6,37,-3,1)
Block(-6,37,-2,1)
Block(-6,37,-1,1)
Block(-6,37,0,1)
Block(-6,37,1,1)
Block(-6,37,2,1)
Block(-6,37,3,1)
Block(-6,37,4,1)
Block(-6,37,5,1)
Block(-6,37,6,1)
Block(-6,37,7,1)
Block(-6,37,8,1)
Block(-6,38,-6,1)
Block(-6,38,-5,1)
Block(-6,38,-4,1)
Block(-6,38,-3,1)
Block(-6,38,-2,1)
Block(-6,38,-1,1)
Block(-6,38,0,1)
Block(-6,38,1,1)
Block(-6,38,2,1)
Block(-6,38,3,1)
Block(-6,38,4,1)
Block(-6,38,5,1)
Block(-6,38,6,1)
Block(-6,38,7,1)
Block(-6,38,8,1)
Block(-6,38,9,1)
Block(-6,39,-7,1)
Block(-6,39,-6,1)
Block(-6,39,-5,1)
Block(-6,39,-4,1)
Block(-6,39,-3,1)
Block(-6,39,-2,1)
Block(-6,39,-1,1)
Block(-6,39,0,1)
Block(-6,39,1,1)
Block(-6,39,2,1)
Block(-6,39,3,1)
Block(-6,39,4,1)
Block(-6,39,5,1)
Block(-6,39,6,1)
Block(-6,39,7,1)
Block(-6,39,8,1)
Block(-6,39,9,1)
Block(-6,40,-8,1)
Block(-6,40,-7,1)
Block(-6,40,-6,1)
Block(-6,40,-5,1)
Block(-6,40,-4,1)
Block(-6,40,-3,1)
Block(-6,40,-2,1)
Block(-6,40,-1,1)
Block(-6,40,0,1)
Block(-6,40,1,1)
Block(-6,40,2,1)
Block(-6,40,3,1)
Block(-6,40,4,1)
Block(-6,40,5,1)
Block(-6,40,6,1)
Block(-6,40,7,1)
Block(-6,40,8,1)
Block(-6,40,9,1)
Block(-6,41,-8,1)
Block(-6,41,-7,1)
Block(-6,41,-6,1)
Block(-6,41,-5,1)
Block(-6,41,-4,1)
Block(-6,41,-3,1)
Block(-6,41,-2,1)
Block(-6,41,-1,1)
Block(-6,41,0,1)
Block(-6,41,1,1)
Block(-6,41,2,1)
Block(-6,41,3,1)
Block(-6,41,4,1)
Block(-6,41,5,1)
Block(-6,41,6,1)
Block(-6,41,7,1)
Block(-6,41,8,1)
Block(-6,41,9,1)
Block(-6,42,-9,1)
Block(-6,42,-8,1)
Block(-6,42,-7,1)
Block(-6,42,-6,1)
Block(-6,42,-5,1)
Block(-6,42,-4,1)
Block(-6,42,-3,1)
Block(-6,42,-2,1)
Block(-6,42,-1,1)
Block(-6,42,0,1)
Block(-6,42,1,1)
Block(-6,42,2,1)
Block(-6,42,3,1)
Block(-6,42,4,1)
Block(-6,42,5,1)
Block(-6,42,6,1)
Block(-6,42,7,1)
Block(-6,42,8,1)
Block(-6,42,9,1)
Block(-6,43,-10,1)
Block(-6,43,-9,1)
Block(-6,43,-8,1)
Block(-6,43,-7,1)
Block(-6,43,-6,1)
Block(-6,43,-5,1)
Block(-6,43,-4,1)
Block(-6,43,-3,1)
Block(-6,43,-2,1)
Block(-6,43,-1,1)
Block(-6,43,0,1)
Block(-6,43,1,1)
Block(-6,43,2,1)
Block(-6,43,3,1)
Block(-6,43,4,1)
Block(-6,43,5,1)
Block(-6,43,6,1)
Block(-6,43,7,1)
Block(-6,43,8,1)
Block(-6,43,9,1)
Block(-6,44,-10,1)
Block(-6,44,-9,1)
Block(-6,44,-8,1)
Block(-6,44,-7,1)
Block(-6,44,-6,1)
Block(-6,44,-5,1)
Block(-6,44,-4,1)
Block(-6,44,-3,1)
Block(-6,44,-2,1)
Block(-6,44,-1,1)
Block(-6,44,0,1)
Block(-6,44,1,1)
Block(-6,44,2,1)
Block(-6,44,3,1)
Block(-6,44,4,1)
Block(-6,44,5,1)
Block(-6,44,6,1)
Block(-6,44,7,1)
Block(-6,44,8,1)
Block(-6,45,-9,1)
Block(-6,45,-8,1)
Block(-6,45,-7,1)
Block(-6,45,-6,1)
Block(-6,45,-5,1)
Block(-6,45,-4,1)
Block(-6,45,-3,1)
Block(-6,45,-2,1)
Block(-6,45,-1,1)
Block(-6,45,0,1)
Block(-6,45,1,1)
Block(-6,45,2,1)
Block(-6,45,3,1)
Block(-6,45,4,1)
Block(-6,45,5,1)
Block(-6,45,6,1)
Block(-6,45,7,1)
Block(-6,45,8,1)
Block(-6,46,-7,1)
Block(-6,46,-6,1)
Block(-6,46,-5,1)
Block(-6,46,-4,1)
Block(-6,46,-3,1)
Block(-6,46,-2,1)
Block(-6,46,-1,1)
Block(-6,46,0,1)
Block(-6,46,1,1)
Block(-6,46,2,1)
Block(-6,46,3,1)
Block(-6,46,4,1)
Block(-6,46,5,1)
Block(-6,46,6,1)
Block(-6,46,7,1)
Block(-6,47,-6,1)
Block(-6,47,-5,1)
Block(-6,47,-4,1)
Block(-6,47,-3,1)
Block(-6,47,-2,1)
Block(-6,47,-1,1)
Block(-6,47,0,1)
Block(-6,47,1,1)
Block(-6,47,2,1)
Block(-6,47,3,1)
Block(-6,47,4,1)
Block(-6,47,5,1)
Block(-6,47,6,1)
Block(-6,47,7,1)
Block(-6,48,-6,1)
Block(-6,48,-5,1)
Block(-6,48,-4,1)
Block(-6,48,-3,1)
Block(-6,48,-2,1)
Block(-6,48,-1,1)
Block(-6,48,0,1)
Block(-6,48,1,1)
Block(-6,48,2,1)
Block(-6,48,3,1)
Block(-6,48,4,1)
Block(-6,48,5,1)
Block(-6,48,6,1)
Block(-6,48,7,1)
Block(-6,49,-6,1)
Block(-6,49,-5,1)
Block(-6,49,-4,1)
Block(-6,49,-3,1)
Block(-6,49,-2,1)
Block(-6,49,-1,1)
Block(-6,49,0,1)
Block(-6,49,1,1)
Block(-6,49,2,1)
Block(-6,49,3,1)
Block(-6,49,4,1)
Block(-6,49,5,1)
Block(-6,49,6,1)
Block(-6,49,7,1)
Block(-6,50,-6,1)
Block(-6,50,-5,1)
Block(-6,50,-4,1)
Block(-6,50,-3,1)
Block(-6,50,-2,1)
Block(-6,50,-1,1)
Block(-6,50,0,1)
Block(-6,50,1,1)
Block(-6,50,2,1)
Block(-6,50,3,1)
Block(-6,50,4,1)
Block(-6,50,5,1)
Block(-6,50,6,1)
Block(-6,50,7,1)
Block(-6,51,-7,1)
Block(-6,51,-6,1)
Block(-6,51,-5,1)
Block(-6,51,-4,1)
Block(-6,51,-3,1)
Block(-6,51,-2,1)
Block(-6,51,-1,1)
Block(-6,51,0,1)
Block(-6,51,1,1)
Block(-6,51,2,1)
Block(-6,51,3,1)
Block(-6,51,4,1)
Block(-6,51,5,1)
Block(-6,51,6,1)
Block(-6,51,7,1)
Block(-6,52,-8,1)
Block(-6,52,-7,1)
Block(-6,52,-6,1)
Block(-6,52,-5,1)
Block(-6,52,-4,1)
Block(-6,52,-3,1)
Block(-6,52,-2,1)
Block(-6,52,-1,1)
Block(-6,52,0,1)
Block(-6,52,1,1)
Block(-6,52,2,1)
Block(-6,52,3,1)
Block(-6,52,4,1)
Block(-6,52,5,1)
Block(-6,52,6,1)
Block(-6,52,7,1)
Block(-6,53,-8,1)
Block(-6,53,-7,1)
Block(-6,53,-6,1)
Block(-6,53,-5,1)
Block(-6,53,-4,1)
Block(-6,53,-3,1)
Block(-6,53,-2,1)
Block(-6,53,-1,1)
Block(-6,53,0,1)
Block(-6,53,1,1)
Block(-6,53,2,1)
Block(-6,53,3,1)
Block(-6,53,4,1)
Block(-6,53,5,1)
Block(-6,53,6,1)
Block(-6,53,7,1)
Block(-6,54,-8,1)
Block(-6,54,-7,1)
Block(-6,54,-6,1)
Block(-6,54,-5,1)
Block(-6,54,-4,1)
Block(-6,54,-3,1)
Block(-6,54,-2,1)
Block(-6,54,-1,1)
Block(-6,54,0,1)
Block(-6,54,1,1)
Block(-6,54,2,1)
Block(-6,54,3,1)
Block(-6,54,4,1)
Block(-6,54,5,1)
Block(-6,54,6,1)
Block(-6,54,7,1)
Block(-6,55,-8,1)
Block(-6,55,-7,1)
Block(-6,55,-6,1)
Block(-6,55,-5,1)
Block(-6,55,-4,1)
Block(-6,55,-3,1)
Block(-6,55,-2,1)
Block(-6,55,-1,1)
Block(-6,55,0,1)
Block(-6,55,1,1)
Block(-6,55,2,1)
Block(-6,55,3,1)
Block(-6,55,4,1)
Block(-6,55,5,1)
Block(-6,55,6,1)
Block(-6,55,7,1)
Block(-6,55,8,1)
Block(-6,56,-8,1)
Block(-6,56,-7,1)
Block(-6,56,-6,1)
Block(-6,56,-5,1)
Block(-6,56,-4,1)
Block(-6,56,-3,1)
Block(-6,56,-2,1)
Block(-6,56,-1,1)
Block(-6,56,0,1)
Block(-6,56,1,1)
Block(-6,56,2,1)
Block(-6,56,3,1)
Block(-6,56,4,1)
Block(-6,56,5,1)
Block(-6,56,6,1)
Block(-6,56,7,1)
Block(-6,56,8,1)
Block(-6,57,-8,1)
Block(-6,57,-7,1)
Block(-6,57,-6,1)
Block(-6,57,-5,1)
Block(-6,57,-4,1)
Block(-6,57,-3,1)
Block(-6,57,-2,1)
Block(-6,57,-1,1)
Block(-6,57,0,1)
Block(-6,57,1,1)
Block(-6,57,2,1)
Block(-6,57,3,1)
Block(-6,57,4,1)
Block(-6,57,5,1)
Block(-6,57,6,1)
Block(-6,57,7,1)
Block(-6,57,8,1)
Block(-6,58,-7,1)
Block(-6,58,-6,1)
Block(-6,58,-5,1)
Block(-6,58,-4,1)
Block(-6,58,-3,1)
Block(-6,58,-2,1)
Block(-6,58,-1,1)
Block(-6,58,0,1)
Block(-6,58,1,1)
Block(-6,58,2,1)
Block(-6,58,3,1)
Block(-6,58,4,1)
Block(-6,58,5,1)
Block(-6,58,6,1)
Block(-6,58,7,1)
Block(-6,58,8,1)
Block(-6,59,-7,1)
Block(-6,59,-6,1)
Block(-6,59,-5,1)
Block(-6,59,-4,1)
Block(-6,59,-3,1)
Block(-6,59,-2,1)
Block(-6,59,-1,1)
Block(-6,59,0,1)
Block(-6,59,1,1)
Block(-6,59,2,1)
Block(-6,59,3,1)
Block(-6,59,4,1)
Block(-6,59,5,1)
Block(-6,59,6,1)
Block(-6,59,7,1)
Block(-6,59,8,1)
Block(-6,60,-6,1)
Block(-6,60,-5,1)
Block(-6,60,-4,1)
Block(-6,60,-3,1)
Block(-6,60,-2,1)
Block(-6,60,-1,1)
Block(-6,60,0,1)
Block(-6,60,1,1)
Block(-6,60,2,1)
Block(-6,60,3,1)
Block(-6,60,4,1)
Block(-6,60,5,1)
Block(-6,60,6,1)
Block(-6,60,7,1)
Block(-6,60,8,1)
Block(-6,61,-6,1)
Block(-6,61,-5,1)
Block(-6,61,-4,1)
Block(-6,61,-3,1)
Block(-6,61,-2,1)
Block(-6,61,-1,1)
Block(-6,61,0,1)
Block(-6,61,1,1)
Block(-6,61,2,1)
Block(-6,61,3,1)
Block(-6,61,4,1)
Block(-6,61,5,1)
Block(-6,61,6,1)
Block(-6,61,7,1)
Block(-6,61,8,1)
Block(-6,62,-6,1)
Block(-6,62,-5,1)
Block(-6,62,-4,1)
Block(-6,62,-3,1)
Block(-6,62,-2,1)
Block(-6,62,-1,1)
Block(-6,62,0,1)
Block(-6,62,1,1)
Block(-6,62,2,1)
Block(-6,62,3,1)
Block(-6,62,4,1)
Block(-6,62,5,1)
Block(-6,62,6,1)
Block(-6,62,7,1)
Block(-6,62,8,1)
Block(-6,63,-6,1)
Block(-6,63,-5,1)
Block(-6,63,-4,1)
Block(-6,63,-3,1)
Block(-6,63,-2,1)
Block(-6,63,-1,1)
Block(-6,63,0,1)
Block(-6,63,1,1)
Block(-6,63,2,1)
Block(-6,63,3,1)
Block(-6,63,4,1)
Block(-6,63,5,1)
Block(-6,63,6,1)
Block(-6,63,7,1)
Block(-6,63,8,1)
Block(-6,64,-6,1)
Block(-6,64,-5,1)
Block(-6,64,-4,1)
Block(-6,64,-3,1)
Block(-6,64,-2,1)
Block(-6,64,-1,1)
Block(-6,64,0,1)
Block(-6,64,1,1)
Block(-6,64,2,1)
Block(-6,64,3,1)
Block(-6,64,4,1)
Block(-6,64,5,1)
Block(-6,64,6,1)
Block(-6,64,7,1)
Block(-6,64,8,1)
Block(-6,65,-5,1)
Block(-6,65,-4,1)
Block(-6,65,-3,1)
Block(-6,65,-2,1)
Block(-6,65,-1,1)
Block(-6,65,0,1)
Block(-6,65,1,1)
Block(-6,65,2,1)
Block(-6,65,3,1)
Block(-6,65,4,1)
Block(-6,65,5,1)
Block(-6,65,6,1)
Block(-6,65,7,1)
Block(-6,65,8,1)
Block(-6,66,-5,1)
Block(-6,66,-4,1)
Block(-6,66,-3,1)
Block(-6,66,-2,1)
Block(-6,66,-1,1)
Block(-6,66,0,1)
Block(-6,66,1,1)
Block(-6,66,2,1)
Block(-6,66,3,1)
Block(-6,66,4,1)
Block(-6,66,5,1)
Block(-6,66,6,1)
Block(-6,66,7,1)
Block(-6,66,8,1)
Block(-6,67,-5,1)
Block(-6,67,-4,1)
Block(-6,67,-3,1)
Block(-6,67,-2,1)
Block(-6,67,-1,1)
Block(-6,67,0,1)
Block(-6,67,1,1)
Block(-6,67,2,1)
Block(-6,67,3,1)
Block(-6,67,4,1)
Block(-6,67,5,1)
Block(-6,67,6,1)
Block(-6,67,7,1)
Block(-6,67,8,1)
Block(-6,68,-6,1)
Block(-6,68,-5,1)
Block(-6,68,-4,1)
Block(-6,68,-3,1)
Block(-6,68,-2,1)
Block(-6,68,-1,1)
Block(-6,68,0,1)
Block(-6,68,1,1)
Block(-6,68,2,1)
Block(-6,68,3,1)
Block(-6,68,4,1)
Block(-6,68,5,1)
Block(-6,68,6,1)
Block(-6,68,7,1)
Block(-6,68,8,1)
Block(-6,68,9,1)
Block(-6,69,-6,1)
Block(-6,69,-5,1)
Block(-6,69,-4,1)
Block(-6,69,-3,1)
Block(-6,69,-2,1)
Block(-6,69,-1,1)
Block(-6,69,0,1)
Block(-6,69,1,1)
Block(-6,69,2,1)
Block(-6,69,3,1)
Block(-6,69,4,1)
Block(-6,69,5,1)
Block(-6,69,6,1)
Block(-6,69,7,1)
Block(-6,69,8,1)
Block(-6,69,9,1)
Block(-6,69,10,1)
Block(-6,70,-7,1)
Block(-6,70,-6,1)
Block(-6,70,-5,1)
Block(-6,70,-4,1)
Block(-6,70,-3,1)
Block(-6,70,-2,1)
Block(-6,70,-1,1)
Block(-6,70,0,1)
Block(-6,70,1,1)
Block(-6,70,2,1)
Block(-6,70,3,1)
Block(-6,70,4,1)
Block(-6,70,5,1)
Block(-6,70,6,1)
Block(-6,70,7,1)
Block(-6,70,8,1)
Block(-6,70,9,1)
Block(-6,70,10,1)
Block(-6,70,11,1)
Block(-6,71,-7,1)
Block(-6,71,-6,1)
Block(-6,71,-5,1)
Block(-6,71,-4,1)
Block(-6,71,-3,1)
Block(-6,71,-2,1)
Block(-6,71,-1,1)
Block(-6,71,0,1)
Block(-6,71,1,1)
Block(-6,71,2,1)
Block(-6,71,3,1)
Block(-6,71,4,1)
Block(-6,71,5,1)
Block(-6,71,6,1)
Block(-6,71,7,1)
Block(-6,71,8,1)
Block(-6,71,9,1)
Block(-6,71,10,1)
Block(-6,71,11,1)
Block(-6,72,-8,1)
Block(-6,72,-7,1)
Block(-6,72,-6,1)
Block(-6,72,-5,1)
Block(-6,72,-4,1)
Block(-6,72,-3,1)
Block(-6,72,-2,1)
Block(-6,72,-1,1)
Block(-6,72,0,1)
Block(-6,72,1,1)
Block(-6,72,2,1)
Block(-6,72,3,1)
Block(-6,72,4,1)
Block(-6,72,5,1)
Block(-6,72,6,1)
Block(-6,72,7,1)
Block(-6,72,8,1)
Block(-6,72,9,1)
Block(-6,72,10,1)
Block(-6,73,-8,1)
Block(-6,73,-7,3)
Block(-6,73,-6,1)
Block(-6,73,-5,1)
Block(-6,73,-4,1)
Block(-6,73,-3,1)
Block(-6,73,-2,1)
Block(-6,73,-1,1)
Block(-6,73,0,1)
Block(-6,73,1,1)
Block(-6,73,2,1)
Block(-6,73,3,1)
Block(-6,73,4,1)
Block(-6,73,5,1)
Block(-6,73,6,1)
Block(-6,73,7,1)
Block(-6,73,8,1)
Block(-6,73,9,1)
Block(-6,73,10,1)
Block(-6,74,-8,1)
Block(-6,74,-7,3)
Block(-6,74,-6,3)
Block(-6,74,-5,1)
Block(-6,74,-4,1)
Block(-6,74,-3,1)
Block(-6,74,-2,1)
Block(-6,74,-1,1)
Block(-6,74,0,1)
Block(-6,74,1,1)
Block(-6,74,2,1)
Block(-6,74,3,1)
Block(-6,74,4,1)
Block(-6,74,5,1)
Block(-6,74,6,1)
Block(-6,74,7,1)
Block(-6,74,8,1)
Block(-6,74,9,1)
Block(-6,75,-7,1)
Block(-6,75,-6,3)
Block(-6,75,-5,3)
Block(-6,75,-4,1)
Block(-6,75,-3,1)
Block(-6,75,-2,1)
Block(-6,75,-1,1)
Block(-6,75,0,1)
Block(-6,75,1,1)
Block(-6,75,2,1)
Block(-6,75,3,1)
Block(-6,75,4,1)
Block(-6,75,5,1)
Block(-6,75,6,1)
Block(-6,75,7,1)
Block(-6,75,8,1)
Block(-6,75,9,1)
Block(-6,76,-7,1)
Block(-6,76,-6,3)
Block(-6,76,-5,3)
Block(-6,76,-4,3)
Block(-6,76,-3,1)
Block(-6,76,-2,1)
Block(-6,76,-1,1)
Block(-6,76,0,1)
Block(-6,76,1,1)
Block(-6,76,2,1)
Block(-6,76,3,1)
Block(-6,76,4,1)
Block(-6,76,5,1)
Block(-6,76,6,1)
Block(-6,76,7,1)
Block(-6,76,8,1)
Block(-6,76,9,1)
Block(-6,77,-6,1)
Block(-6,77,-5,3)
Block(-6,77,-4,3)
Block(-6,77,-3,1)
Block(-6,77,-2,1)
Block(-6,77,-1,1)
Block(-6,77,0,1)
Block(-6,77,1,1)
Block(-6,77,2,1)
Block(-6,77,3,1)
Block(-6,77,4,1)
Block(-6,77,5,1)
Block(-6,77,6,1)
Block(-6,77,7,1)
Block(-6,77,8,1)
Block(-6,77,9,1)
Block(-6,78,-5,1)
Block(-6,78,-4,3)
Block(-6,78,-3,3)
Block(-6,78,-2,1)
Block(-6,78,-1,1)
Block(-6,78,0,1)
Block(-6,78,1,1)
Block(-6,78,2,1)
Block(-6,78,3,1)
Block(-6,78,4,1)
Block(-6,78,5,1)
Block(-6,78,6,1)
Block(-6,78,7,1)
Block(-6,78,8,1)
Block(-6,78,9,1)
Block(-6,79,-4,1)
Block(-6,79,-3,3)
Block(-6,79,-2,3)
Block(-6,79,-1,1)
Block(-6,79,0,1)
Block(-6,79,1,1)
Block(-6,79,2,1)
Block(-6,79,3,1)
Block(-6,79,4,1)
Block(-6,79,5,3)
Block(-6,79,6,3)
Block(-6,79,7,1)
Block(-6,79,8,1)
Block(-6,80,-3,1)
Block(-6,80,-2,3)
Block(-6,80,-1,3)
Block(-6,80,0,3)
Block(-6,80,1,1)
Block(-6,80,2,3)
Block(-6,80,3,3)
Block(-6,80,4,3)
Block(-6,80,5,3)
Block(-6,80,6,3)
Block(-6,80,7,1)
Block(-6,80,8,1)
Block(-6,81,-3,1)
Block(-6,81,-2,1)
Block(-6,81,-1,3)
Block(-6,81,0,3)
Block(-6,81,1,3)
Block(-6,81,2,3)
Block(-6,81,3,3)
Block(-6,81,4,3)
Block(-6,81,5,3)
Block(-6,81,6,3)
Block(-6,81,7,1)
Block(-6,81,8,1)
Block(-6,82,-2,1)
Block(-6,82,-1,3)
Block(-6,82,0,3)
Block(-6,82,1,3)
Block(-6,82,2,3)
Block(-6,82,3,3)
Block(-6,82,4,3)
Block(-6,82,5,2)
Block(-6,82,6,1)
Block(-6,82,7,1)
Block(-6,83,-1,1)
Block(-6,83,0,2)
Block(-6,83,1,3)
Block(-6,83,2,2)
Block(-6,83,3,2)
Block(-6,83,4,2)
Block(-6,84,1,2)
Block(-5,0,-10,1)
Block(-5,0,-9,1)
Block(-5,0,-8,1)
Block(-5,0,-7,1)
Block(-5,0,-6,1)
Block(-5,0,-5,1)
Block(-5,0,-4,1)
Block(-5,0,-3,1)
Block(-5,0,-2,1)
Block(-5,0,-1,1)
Block(-5,0,0,1)
Block(-5,0,1,1)
Block(-5,0,2,1)
Block(-5,0,3,1)
Block(-5,0,4,1)
Block(-5,0,5,1)
Block(-5,0,6,1)
Block(-5,0,7,1)
Block(-5,0,8,1)
Block(-5,0,9,1)
Block(-5,0,10,1)
Block(-5,1,-9,1)
Block(-5,1,-8,1)
Block(-5,1,-7,1)
Block(-5,1,-6,1)
Block(-5,1,-5,1)
Block(-5,1,-4,1)
Block(-5,1,-3,1)
Block(-5,1,-2,1)
Block(-5,1,-1,1)
Block(-5,1,0,1)
Block(-5,1,1,1)
Block(-5,1,2,1)
Block(-5,1,3,1)
Block(-5,1,4,1)
Block(-5,1,5,1)
Block(-5,1,6,1)
Block(-5,1,7,1)
Block(-5,1,8,1)
Block(-5,1,9,1)
Block(-5,2,-8,1)
Block(-5,2,-7,1)
Block(-5,2,-6,1)
Block(-5,2,-5,1)
Block(-5,2,-4,1)
Block(-5,2,-3,1)
Block(-5,2,-2,1)
Block(-5,2,-1,1)
Block(-5,2,0,1)
Block(-5,2,1,1)
Block(-5,2,2,1)
Block(-5,2,3,1)
Block(-5,2,4,1)
Block(-5,2,5,1)
Block(-5,2,6,1)
Block(-5,2,7,1)
Block(-5,2,8,1)
Block(-5,3,-7,1)
Block(-5,3,-6,1)
Block(-5,3,-5,1)
Block(-5,3,-4,1)
Block(-5,3,-3,1)
Block(-5,3,-2,1)
Block(-5,3,-1,1)
Block(-5,3,0,1)
Block(-5,3,1,1)
Block(-5,3,2,1)
Block(-5,3,3,1)
Block(-5,3,4,1)
Block(-5,3,5,1)
Block(-5,3,6,1)
Block(-5,3,7,1)
Block(-5,3,8,1)
Block(-5,4,-6,1)
Block(-5,4,-5,1)
Block(-5,4,-4,1)
Block(-5,4,-3,1)
Block(-5,4,-2,1)
Block(-5,4,-1,1)
Block(-5,4,0,1)
Block(-5,4,1,1)
Block(-5,4,2,1)
Block(-5,4,3,1)
Block(-5,4,4,1)
Block(-5,4,5,1)
Block(-5,4,6,1)
Block(-5,4,7,1)
Block(-5,4,8,1)
Block(-5,5,-6,1)
Block(-5,5,-5,1)
Block(-5,5,-4,1)
Block(-5,5,-3,1)
Block(-5,5,-2,1)
Block(-5,5,-1,1)
Block(-5,5,0,1)
Block(-5,5,1,1)
Block(-5,5,2,1)
Block(-5,5,3,1)
Block(-5,5,4,1)
Block(-5,5,5,1)
Block(-5,5,6,1)
Block(-5,5,7,1)
Block(-5,5,8,1)
Block(-5,6,-6,1)
Block(-5,6,-5,1)
Block(-5,6,-4,1)
Block(-5,6,-3,1)
Block(-5,6,-2,1)
Block(-5,6,-1,1)
Block(-5,6,0,1)
Block(-5,6,1,1)
Block(-5,6,2,1)
Block(-5,6,3,1)
Block(-5,6,4,1)
Block(-5,6,5,1)
Block(-5,6,6,1)
Block(-5,6,7,1)
Block(-5,6,8,1)
Block(-5,6,9,1)
Block(-5,7,-6,1)
Block(-5,7,-5,1)
Block(-5,7,-4,1)
Block(-5,7,-3,1)
Block(-5,7,-2,1)
Block(-5,7,-1,1)
Block(-5,7,0,1)
Block(-5,7,1,1)
Block(-5,7,2,1)
Block(-5,7,3,1)
Block(-5,7,4,1)
Block(-5,7,5,1)
Block(-5,7,6,1)
Block(-5,7,7,1)
Block(-5,7,8,1)
Block(-5,7,9,1)
Block(-5,8,-7,1)
Block(-5,8,-6,1)
Block(-5,8,-5,1)
Block(-5,8,-4,1)
Block(-5,8,-3,1)
Block(-5,8,-2,1)
Block(-5,8,-1,1)
Block(-5,8,0,1)
Block(-5,8,1,1)
Block(-5,8,2,1)
Block(-5,8,3,1)
Block(-5,8,4,1)
Block(-5,8,5,1)
Block(-5,8,6,1)
Block(-5,8,7,1)
Block(-5,8,8,1)
Block(-5,8,9,1)
Block(-5,9,-7,1)
Block(-5,9,-6,1)
Block(-5,9,-5,1)
Block(-5,9,-4,1)
Block(-5,9,-3,1)
Block(-5,9,-2,1)
Block(-5,9,-1,1)
Block(-5,9,0,1)
Block(-5,9,1,1)
Block(-5,9,2,1)
Block(-5,9,3,1)
Block(-5,9,4,1)
Block(-5,9,5,1)
Block(-5,9,6,1)
Block(-5,9,7,1)
Block(-5,9,8,1)
Block(-5,9,9,1)
Block(-5,9,10,1)
Block(-5,10,-8,1)
Block(-5,10,-7,1)
Block(-5,10,-6,1)
Block(-5,10,-5,1)
Block(-5,10,-4,1)
Block(-5,10,-3,1)
Block(-5,10,-2,1)
Block(-5,10,-1,1)
Block(-5,10,0,1)
Block(-5,10,1,1)
Block(-5,10,2,1)
Block(-5,10,3,1)
Block(-5,10,4,1)
Block(-5,10,5,1)
Block(-5,10,6,1)
Block(-5,10,7,1)
Block(-5,10,8,1)
Block(-5,10,9,1)
Block(-5,10,10,1)
Block(-5,11,-8,1)
Block(-5,11,-7,1)
Block(-5,11,-6,1)
Block(-5,11,-5,1)
Block(-5,11,-4,1)
Block(-5,11,-3,1)
Block(-5,11,-2,1)
Block(-5,11,-1,1)
Block(-5,11,0,1)
Block(-5,11,1,1)
Block(-5,11,2,1)
Block(-5,11,3,1)
Block(-5,11,4,1)
Block(-5,11,5,1)
Block(-5,11,6,1)
Block(-5,11,7,1)
Block(-5,11,8,1)
Block(-5,11,9,1)
Block(-5,11,10,1)
Block(-5,11,11,1)
Block(-5,12,-8,1)
Block(-5,12,-7,1)
Block(-5,12,-6,1)
Block(-5,12,-5,1)
Block(-5,12,-4,1)
Block(-5,12,-3,1)
Block(-5,12,-2,1)
Block(-5,12,-1,1)
Block(-5,12,0,1)
Block(-5,12,1,1)
Block(-5,12,2,1)
Block(-5,12,3,1)
Block(-5,12,4,1)
Block(-5,12,5,1)
Block(-5,12,6,1)
Block(-5,12,7,1)
Block(-5,12,8,1)
Block(-5,12,9,1)
Block(-5,12,10,1)
Block(-5,12,11,1)
Block(-5,13,-8,1)
Block(-5,13,-7,1)
Block(-5,13,-6,1)
Block(-5,13,-5,1)
Block(-5,13,-4,1)
Block(-5,13,-3,1)
Block(-5,13,-2,1)
Block(-5,13,-1,1)
Block(-5,13,0,1)
Block(-5,13,1,1)
Block(-5,13,2,1)
Block(-5,13,3,1)
Block(-5,13,4,1)
Block(-5,13,5,1)
Block(-5,13,6,1)
Block(-5,13,7,1)
Block(-5,13,8,1)
Block(-5,13,9,1)
Block(-5,13,10,1)
Block(-5,13,11,1)
Block(-5,14,-8,1)
Block(-5,14,-7,1)
Block(-5,14,-6,1)
Block(-5,14,-5,1)
Block(-5,14,-4,1)
Block(-5,14,-3,1)
Block(-5,14,-2,1)
Block(-5,14,-1,1)
Block(-5,14,0,1)
Block(-5,14,1,1)
Block(-5,14,2,1)
Block(-5,14,3,1)
Block(-5,14,4,1)
Block(-5,14,5,1)
Block(-5,14,6,1)
Block(-5,14,7,1)
Block(-5,14,8,1)
Block(-5,14,9,1)
Block(-5,14,10,1)
Block(-5,14,11,1)
Block(-5,15,-8,1)
Block(-5,15,-7,1)
Block(-5,15,-6,1)
Block(-5,15,-5,1)
Block(-5,15,-4,1)
Block(-5,15,-3,1)
Block(-5,15,-2,1)
Block(-5,15,-1,1)
Block(-5,15,0,1)
Block(-5,15,1,1)
Block(-5,15,2,1)
Block(-5,15,3,1)
Block(-5,15,4,1)
Block(-5,15,5,1)
Block(-5,15,6,1)
Block(-5,15,7,1)
Block(-5,15,8,1)
Block(-5,15,9,1)
Block(-5,15,10,1)
Block(-5,15,11,1)
Block(-5,16,-8,1)
Block(-5,16,-7,1)
Block(-5,16,-6,1)
Block(-5,16,-5,1)
Block(-5,16,-4,1)
Block(-5,16,-3,1)
Block(-5,16,-2,1)
Block(-5,16,-1,1)
Block(-5,16,0,1)
Block(-5,16,1,1)
Block(-5,16,2,1)
Block(-5,16,3,1)
Block(-5,16,4,1)
Block(-5,16,5,1)
Block(-5,16,6,1)
Block(-5,16,7,1)
Block(-5,16,8,1)
Block(-5,16,9,1)
Block(-5,16,10,1)
Block(-5,16,11,1)
Block(-5,17,-9,1)
Block(-5,17,-8,1)
Block(-5,17,-7,1)
Block(-5,17,-6,1)
Block(-5,17,-5,1)
Block(-5,17,-4,1)
Block(-5,17,-3,1)
Block(-5,17,-2,1)
Block(-5,17,-1,1)
Block(-5,17,0,1)
Block(-5,17,1,1)
Block(-5,17,2,1)
Block(-5,17,3,1)
Block(-5,17,4,1)
Block(-5,17,5,1)
Block(-5,17,6,1)
Block(-5,17,7,1)
Block(-5,17,8,1)
Block(-5,17,9,1)
Block(-5,17,10,1)
Block(-5,17,11,1)
Block(-5,18,-9,1)
Block(-5,18,-8,1)
Block(-5,18,-7,1)
Block(-5,18,-6,1)
Block(-5,18,-5,1)
Block(-5,18,-4,1)
Block(-5,18,-3,1)
Block(-5,18,-2,1)
Block(-5,18,-1,1)
Block(-5,18,0,1)
Block(-5,18,1,1)
Block(-5,18,2,1)
Block(-5,18,3,1)
Block(-5,18,4,1)
Block(-5,18,5,1)
Block(-5,18,6,1)
Block(-5,18,7,1)
Block(-5,18,8,1)
Block(-5,18,9,1)
Block(-5,18,10,1)
Block(-5,18,11,1)
Block(-5,19,-9,1)
Block(-5,19,-8,1)
Block(-5,19,-7,1)
Block(-5,19,-6,1)
Block(-5,19,-5,1)
Block(-5,19,-4,1)
Block(-5,19,-3,1)
Block(-5,19,-2,1)
Block(-5,19,-1,1)
Block(-5,19,0,1)
Block(-5,19,1,1)
Block(-5,19,2,1)
Block(-5,19,3,1)
Block(-5,19,4,1)
Block(-5,19,5,1)
Block(-5,19,6,1)
Block(-5,19,7,1)
Block(-5,19,8,1)
Block(-5,19,9,1)
Block(-5,19,10,1)
Block(-5,19,11,1)
Block(-5,20,-9,1)
Block(-5,20,-8,1)
Block(-5,20,-7,1)
Block(-5,20,-6,1)
Block(-5,20,-5,1)
Block(-5,20,-4,1)
Block(-5,20,-3,1)
Block(-5,20,-2,1)
Block(-5,20,-1,1)
Block(-5,20,0,1)
Block(-5,20,1,1)
Block(-5,20,2,1)
Block(-5,20,3,1)
Block(-5,20,4,1)
Block(-5,20,5,1)
Block(-5,20,6,1)
Block(-5,20,7,1)
Block(-5,20,8,1)
Block(-5,20,9,1)
Block(-5,20,10,1)
Block(-5,20,11,1)
Block(-5,21,-8,1)
Block(-5,21,-7,1)
Block(-5,21,-6,1)
Block(-5,21,-5,1)
Block(-5,21,-4,1)
Block(-5,21,-3,1)
Block(-5,21,-2,1)
Block(-5,21,-1,1)
Block(-5,21,0,1)
Block(-5,21,1,1)
Block(-5,21,2,1)
Block(-5,21,3,1)
Block(-5,21,4,1)
Block(-5,21,5,1)
Block(-5,21,6,1)
Block(-5,21,7,1)
Block(-5,21,8,1)
Block(-5,21,9,1)
Block(-5,21,10,1)
Block(-5,22,-8,1)
Block(-5,22,-7,1)
Block(-5,22,-6,1)
Block(-5,22,-5,1)
Block(-5,22,-4,1)
Block(-5,22,-3,1)
Block(-5,22,-2,1)
Block(-5,22,-1,1)
Block(-5,22,0,1)
Block(-5,22,1,1)
Block(-5,22,2,1)
Block(-5,22,3,1)
Block(-5,22,4,1)
Block(-5,22,5,1)
Block(-5,22,6,1)
Block(-5,22,7,1)
Block(-5,22,8,1)
Block(-5,22,9,1)
Block(-5,22,10,1)
Block(-5,23,-7,1)
Block(-5,23,-6,1)
Block(-5,23,-5,1)
Block(-5,23,-4,1)
Block(-5,23,-3,1)
Block(-5,23,-2,1)
Block(-5,23,-1,1)
Block(-5,23,0,1)
Block(-5,23,1,1)
Block(-5,23,2,1)
Block(-5,23,3,1)
Block(-5,23,4,1)
Block(-5,23,5,1)
Block(-5,23,6,1)
Block(-5,23,7,1)
Block(-5,23,8,1)
Block(-5,23,9,1)
Block(-5,24,-7,1)
Block(-5,24,-6,1)
Block(-5,24,-5,1)
Block(-5,24,-4,1)
Block(-5,24,-3,1)
Block(-5,24,-2,1)
Block(-5,24,-1,1)
Block(-5,24,0,1)
Block(-5,24,1,1)
Block(-5,24,2,1)
Block(-5,24,3,1)
Block(-5,24,4,1)
Block(-5,24,5,1)
Block(-5,24,6,1)
Block(-5,24,7,1)
Block(-5,24,8,1)
Block(-5,24,9,1)
Block(-5,25,-8,1)
Block(-5,25,-7,1)
Block(-5,25,-6,1)
Block(-5,25,-5,1)
Block(-5,25,-4,1)
Block(-5,25,-3,1)
Block(-5,25,-2,1)
Block(-5,25,-1,1)
Block(-5,25,0,1)
Block(-5,25,1,1)
Block(-5,25,2,1)
Block(-5,25,3,1)
Block(-5,25,4,1)
Block(-5,25,5,1)
Block(-5,25,6,1)
Block(-5,25,7,1)
Block(-5,25,8,1)
Block(-5,25,9,1)
Block(-5,25,10,1)
Block(-5,26,-8,1)
Block(-5,26,-7,1)
Block(-5,26,-6,1)
Block(-5,26,-5,1)
Block(-5,26,-4,1)
Block(-5,26,-3,1)
Block(-5,26,-2,1)
Block(-5,26,-1,1)
Block(-5,26,0,1)
Block(-5,26,1,1)
Block(-5,26,2,1)
Block(-5,26,3,1)
Block(-5,26,4,1)
Block(-5,26,5,1)
Block(-5,26,6,1)
Block(-5,26,7,1)
Block(-5,26,8,1)
Block(-5,26,9,1)
Block(-5,26,10,1)
Block(-5,27,-9,1)
Block(-5,27,-8,1)
Block(-5,27,-7,1)
Block(-5,27,-6,1)
Block(-5,27,-5,1)
Block(-5,27,-4,1)
Block(-5,27,-3,1)
Block(-5,27,-2,1)
