
#######################################################################
# +-----------------------------------------------------------------+ #
# |                            BO3 object                           | #
# +-----------------------------------------------------------------+ #
#######################################################################

Author: Unknown

Description: Converted version of the BO2 JungleForest3

Version: 3

SettingsMode: WriteWithoutComments


#######################################################################
# +-----------------------------------------------------------------+ #
# |                          Main settings                          | #
# +-----------------------------------------------------------------+ #
#######################################################################

Tree: true

Frequency: 1

Rarity: 10.0

RotateRandomly: true

SpawnHeight: highestSolidBlock

SpawnHeightOffset: 0

SpawnHeightVariance: 0

##############################
# Height Limits for the BO3. #
##############################

MinHeight: 62

MaxHeight: 210

######################
# Extrusion settings #
######################

ExtrudeMode: None

ExtrudeThroughBlocks: AIR

MaxBranchDepth: 10

ExcludedBiomes: All


#######################################################################
# +-----------------------------------------------------------------+ #
# |                      Source block settings                      | #
# +-----------------------------------------------------------------+ #
#######################################################################

SourceBlocks: STONE:1,STONE:3,STONE:5,DIRT:1,DIRT:0,SAND:0,GRASS:0,DIRT:2,STATIONARY_WATER:0,HARD_CLAY,STAINED_CLAY:0,CLAY,SANDSTONE:0,SAND:1,AIR,STONE:0,GRAVEL,LONG_GRASS:0,LONG_GRASS:1,LONG_GRASS:2,DEAD_BUSH,YELLOW_FLOWER:0,RED_ROSE:0,BROWN_MUSHROOM,RED_MUSHROOM

MaxPercentageOutsideSourceBlock: 0

OutsideSourceBlock: placeAnyway

DoReplaceBlocks: true

IsOTGPlus: false


#######################################################################
# +-----------------------------------------------------------------+ #
# |                              Blocks                             | #
# +-----------------------------------------------------------------+ #
#######################################################################

Block(-3,-1,3,LOG:15)
Block(-3,-3,3,LOG:15)
Block(-3,-2,3,LOG:15)
Block(-2,22,-3,LOG:15)
Block(1,9,-4,LEAVES:3)
Block(-2,19,-3,LEAVES:3)
Block(-2,18,-3,LEAVES:3)
Block(-2,17,-3,LEAVES:3)
Block(-2,16,-3,LOG:15)
Block(-1,24,6,LEAVES:3)
Block(-6,10,0,VINE:1)
Block(-6,11,0,LOG:15)
Block(2,24,4,LEAVES:3)
Block(2,25,4,LEAVES:3)
Block(2,22,4,LEAVES:3)
Block(2,23,4,LEAVES:3)
Block(2,21,4,LOG:15)
Block(2,19,-5,LEAVES:3)
Block(-5,23,7,LEAVES:3)
Block(-8,12,6,LEAVES:3)
Block(-5,24,7,LEAVES:3)
Block(-7,23,-3,LEAVES:3)
Block(-5,22,7,VINE:8)
Block(-6,23,0,LEAVES:3)
Block(5,23,1,LEAVES:3)
Block(-6,24,0,LEAVES:3)
Block(-4,9,1,LOG:15)
Block(-6,25,0,LEAVES:3)
Block(-4,8,1,LOG:15)
Block(-4,23,5,LEAVES:3)
Block(-4,22,5,LEAVES:3)
Block(-4,25,5,LEAVES:3)
Block(-4,24,5,LEAVES:3)
Block(-4,3,1,LOG:15)
Block(-7,13,2,LEAVES:3)
Block(-4,2,1,LOG:15)
Block(-4,1,1,LOG:15)
Block(-7,11,2,LEAVES:3)
Block(-4,0,1,LOG:15)
Block(-7,12,2,LEAVES:3)
Block(-4,7,1,LOG:15)
Block(-4,6,1,LOG:15)
Block(-4,5,1,LOG:15)
Block(-4,4,1,LOG:15)
Block(-5,14,7,LEAVES:3)
Block(-5,12,7,LEAVES:3)
Block(2,23,-5,LEAVES:3)
Block(-3,7,3,LEAVES:3)
Block(-5,13,7,LEAVES:3)
Block(-8,23,6,LEAVES:3)
Block(-3,9,3,LOG:15)
Block(-5,11,7,LEAVES:3)
Block(-3,6,3,LEAVES:3)
Block(4,23,-2,LEAVES:3)
Block(1,10,-1,LEAVES:3)
Block(-3,0,3,LOG:15)
Block(0,19,-6,LEAVES:3)
Block(0,18,-6,LEAVES:3)
Block(-6,12,0,LEAVES:3)
Block(-6,13,0,LEAVES:3)
Block(-4,10,5,LOG:15)
Block(-4,12,5,LEAVES:3)
Block(-4,11,5,LEAVES:3)
Block(-4,13,5,LEAVES:3)
Block(-7,24,2,LEAVES:3)
Block(-7,22,2,LEAVES:3)
Block(-7,23,2,LEAVES:3)
Block(-7,21,2,COCOA:10)
Block(-3,0,-1,LOG:15)
Block(-2,24,-3,LEAVES:3)
Block(-3,4,-1,VINE:1)
Block(-3,5,-1,LEAVES:3)
Block(-2,23,-3,LEAVES:3)
Block(-3,6,-1,LEAVES:3)
Block(-3,7,-1,VINE:1)
Block(0,20,-6,LEAVES:3)
Block(-3,8,-1,VINE:1)
Block(-3,9,-1,VINE:1)
Block(0,23,-6,LEAVES:3)
Block(-6,22,0,LEAVES:3)
Block(-3,15,3,LEAVES:3)
Block(-3,14,3,LEAVES:3)
Block(-3,12,3,LEAVES:3)
Block(-5,23,-4,LEAVES:3)
Block(-3,19,3,VINE:4)
Block(-3,18,3,LOG:15)
Block(-4,22,3,LEAVES:3)
Block(0,6,0,LEAVES:3)
Block(-3,16,3,LEAVES:3)
Block(-4,23,3,LEAVES:3)
Block(2,24,-3,LEAVES:3)
Block(1,8,-2,LEAVES:3)
Block(2,22,-3,LEAVES:3)
Block(1,9,-2,LEAVES:3)
Block(2,23,-3,LEAVES:3)
Block(-5,13,9,LEAVES:3)
Block(-8,23,4,LEAVES:3)
Block(-5,12,9,LEAVES:3)
Block(-8,24,4,LEAVES:3)
Block(-5,11,9,LEAVES:3)
Block(-4,15,3,LEAVES:3)
Block(-3,22,3,LEAVES:3)
Block(-3,21,3,VINE:4)
Block(-3,20,3,VINE:4)
Block(-3,24,3,LEAVES:3)
Block(-3,23,3,LEAVES:3)
Block(-4,5,-1,LEAVES:3)
Block(-4,12,3,LEAVES:3)
Block(-10,12,0,LEAVES:3)
Block(-5,18,-4,LEAVES:3)
Block(-5,19,-4,LEAVES:3)
Block(1,22,2,LEAVES:3)
Block(1,23,2,LEAVES:3)
Block(1,24,2,LEAVES:3)
Block(1,25,2,LEAVES:3)
Block(6,23,3,LEAVES:3)
Block(-3,19,-9,LEAVES:3)
Block(-4,9,3,LOG:15)
Block(3,22,6,VINE:2)
Block(-1,12,6,LEAVES:3)
Block(-1,11,6,LEAVES:3)
Block(-6,19,-8,LEAVES:3)
Block(-2,23,-5,LEAVES:3)
Block(-10,23,0,LEAVES:3)
Block(-2,20,-5,LEAVES:3)
Block(-2,18,-5,LEAVES:3)
Block(-3,9,5,LOG:15)
Block(-2,19,-5,LEAVES:3)
Block(-7,25,0,LEAVES:3)
Block(-7,24,0,LEAVES:3)
Block(-9,23,-2,LEAVES:3)
Block(-7,12,-3,LEAVES:3)
Block(-2,17,-5,LEAVES:3)
Block(3,23,6,LEAVES:3)
Block(-6,12,2,LEAVES:3)
Block(2,23,2,LEAVES:3)
Block(2,22,2,LEAVES:3)
Block(2,25,2,LEAVES:3)
Block(2,24,2,LEAVES:3)
Block(-1,23,6,LEAVES:3)
Block(-2,-3,1,LOG:15)
Block(-1,22,6,LEAVES:3)
Block(-2,-2,1,LOG:15)
Block(-2,-1,1,LOG:15)
Block(-9,12,-2,LEAVES:3)
Block(2,8,-2,LEAVES:3)
Block(0,9,0,LEAVES:3)
Block(-4,24,3,LEAVES:3)
Block(0,8,0,LOG:15)
Block(-1,14,6,LEAVES:3)
Block(-1,13,6,LEAVES:3)
Block(2,9,-2,LEAVES:3)
Block(0,23,9,LEAVES:3)
Block(-2,24,1,LEAVES:3)
Block(-2,21,1,LOG:15)
Block(-1,22,-1,LEAVES:3)
Block(-2,20,1,LOG:15)
Block(-1,23,-1,LEAVES:3)
Block(-2,23,1,LOG:15)
Block(-1,24,-1,LEAVES:3)
Block(-2,22,1,LOG:15)
Block(-1,25,-1,LEAVES:3)
Block(-5,12,5,LEAVES:3)
Block(-5,13,5,LEAVES:3)
Block(-5,11,5,LEAVES:3)
Block(1,12,4,LEAVES:3)
Block(-7,12,-1,LOG:15)
Block(-7,11,-1,LEAVES:3)
Block(3,24,4,LEAVES:3)
Block(0,9,-4,LEAVES:3)
Block(-7,13,-1,LEAVES:3)
Block(3,23,4,LEAVES:3)
Block(3,22,4,LOG:15)
Block(-4,24,1,LEAVES:3)
Block(-4,23,1,LEAVES:3)
Block(-4,22,1,LOG:15)
Block(-3,11,5,LEAVES:3)
Block(-3,12,5,LEAVES:3)
Block(-3,13,5,LEAVES:3)
Block(-5,24,-2,LEAVES:3)
Block(-3,19,5,LOG:15)
Block(-5,23,-2,LEAVES:3)
Block(-9,12,1,LEAVES:3)
Block(-6,25,-1,LEAVES:3)
Block(-3,14,5,LEAVES:3)
Block(-9,11,1,VINE:8)
Block(-5,22,-2,LEAVES:3)
Block(-6,24,-1,LEAVES:3)
Block(-2,20,-1,LOG:15)
Block(-6,23,-1,LEAVES:3)
Block(-6,22,-1,LEAVES:3)
Block(-6,21,-1,COCOA:11)
Block(0,24,0,LEAVES:3)
Block(0,23,0,LEAVES:3)
Block(-1,10,-1,LEAVES:3)
Block(0,22,0,LEAVES:3)
Block(-2,16,-1,LEAVES:3)
Block(-2,15,-1,LOG:15)
Block(-3,22,5,LEAVES:3)
Block(-3,23,5,LEAVES:3)
Block(-3,24,5,LEAVES:3)
Block(-2,18,1,LOG:15)
Block(-3,25,5,LEAVES:3)
Block(-2,17,1,LOG:15)
Block(-2,19,1,LOG:15)
Block(-2,14,1,LOG:15)
Block(-1,15,-1,LEAVES:3)
Block(-2,13,1,LOG:15)
Block(-2,16,1,LOG:15)
Block(-2,15,1,LOG:15)
Block(-2,10,1,LOG:15)
Block(-2,12,1,LOG:15)
Block(-2,11,1,LOG:15)
Block(1,22,4,LEAVES:3)
Block(1,24,4,LEAVES:3)
Block(1,23,4,LEAVES:3)
Block(-7,23,-1,LEAVES:3)
Block(0,15,0,LEAVES:3)
Block(-7,22,-1,LEAVES:3)
Block(-7,24,-1,LEAVES:3)
Block(0,10,0,LEAVES:3)
Block(2,9,-4,LEAVES:3)
Block(-1,12,8,LEAVES:3)
Block(-1,13,8,LEAVES:3)
Block(0,8,-2,LOG:15)
Block(5,23,3,LEAVES:3)
Block(0,9,-2,LEAVES:3)
Block(-2,9,-1,LEAVES:3)
Block(0,24,2,LEAVES:3)
Block(0,25,2,LEAVES:3)
Block(0,19,-8,LEAVES:3)
Block(0,22,2,LEAVES:3)
Block(-4,25,-2,LEAVES:3)
Block(0,23,2,LEAVES:3)
Block(-4,24,-2,LEAVES:3)
Block(-4,23,-2,LEAVES:3)
Block(-4,22,-2,LEAVES:3)
Block(-2,6,-1,LEAVES:3)
Block(-2,5,-1,LEAVES:3)
Block(-1,22,8,LEAVES:3)
Block(-1,23,8,LEAVES:3)
Block(2,21,0,COCOA:11)
Block(2,22,0,LEAVES:3)
Block(-9,24,1,LEAVES:3)
Block(-1,24,8,LEAVES:3)
Block(2,23,0,LEAVES:3)
Block(-9,23,1,LOG:15)
Block(-9,22,1,LEAVES:3)
Block(-2,15,3,LEAVES:3)
Block(-1,19,-3,LEAVES:3)
Block(-7,24,4,LEAVES:3)
Block(-6,13,-1,LEAVES:3)
Block(-7,23,4,LEAVES:3)
Block(2,24,0,LEAVES:3)
Block(-6,12,-1,LEAVES:3)
Block(-6,11,-1,LEAVES:3)
Block(-2,12,3,LEAVES:3)
Block(-2,23,-1,LEAVES:3)
Block(-1,21,-3,COCOA:8)
Block(-2,24,-1,LEAVES:3)
Block(0,19,2,LOG:15)
Block(-1,23,-3,LEAVES:3)
Block(-6,12,9,LEAVES:3)
Block(-1,22,-3,LEAVES:3)
Block(-2,22,-1,LEAVES:3)
Block(-4,19,-2,LEAVES:3)
Block(-2,25,-1,LEAVES:3)
Block(-4,15,-2,LOG:15)
Block(-4,21,1,LOG:15)
Block(-4,20,1,LOG:15)
Block(1,12,6,LEAVES:3)
Block(-4,18,1,LOG:15)
Block(1,13,6,LEAVES:3)
Block(-4,17,1,LOG:15)
Block(-4,16,1,LOG:15)
Block(-4,15,1,LOG:15)
Block(1,11,6,VINE:2)
Block(-4,14,1,LOG:15)
Block(-4,13,1,LOG:15)
Block(-4,12,1,LOG:15)
Block(-4,11,1,LOG:15)
Block(-4,19,1,LOG:15)
Block(-4,10,1,LOG:15)
Block(-5,25,5,LEAVES:3)
Block(-5,23,5,LEAVES:3)
Block(-5,24,5,LEAVES:3)
Block(-5,22,5,LOG:15)
Block(-3,13,7,LEAVES:3)
Block(-3,12,7,LEAVES:3)
Block(-8,12,8,LEAVES:3)
Block(-3,14,7,LEAVES:3)
Block(-3,11,7,LEAVES:3)
Block(-7,13,8,LEAVES:3)
Block(3,9,-3,LEAVES:3)
Block(-6,12,10,LEAVES:3)
Block(-7,12,8,LEAVES:3)
Block(-5,15,2,LEAVES:3)
Block(-5,22,2,LEAVES:3)
Block(-5,23,2,LEAVES:3)
Block(-8,23,0,LEAVES:3)
Block(-8,24,0,LEAVES:3)
Block(-8,22,0,LEAVES:3)
Block(-6,22,5,LEAVES:3)
Block(-6,23,5,LEAVES:3)
Block(-9,22,3,VINE:0)
Block(-9,23,3,LEAVES:3)
Block(-9,24,3,LEAVES:3)
Block(0,23,-1,LEAVES:3)
Block(0,22,-1,LEAVES:3)
Block(-6,24,5,LEAVES:3)
Block(0,24,-1,LEAVES:3)
Block(-1,5,0,LEAVES:3)
Block(-1,7,0,LEAVES:3)
Block(-1,6,0,LEAVES:3)
Block(-1,9,0,LEAVES:3)
Block(-4,19,-7,LEAVES:3)
Block(-6,19,-5,LEAVES:3)
Block(-1,8,0,LEAVES:3)
Block(-6,18,-5,LEAVES:3)
Block(3,9,0,LEAVES:3)
Block(1,23,-5,LEAVES:3)
Block(-6,12,5,LEAVES:3)
Block(-1,0,0,LOG:15)
Block(1,20,-5,LEAVES:3)
Block(-8,12,-3,LEAVES:3)
Block(5,23,-1,LEAVES:3)
Block(-2,24,3,LEAVES:3)
Block(-1,25,-3,LEAVES:3)
Block(-1,24,-3,LEAVES:3)
Block(-2,22,3,LEAVES:3)
Block(-2,23,3,LEAVES:3)
Block(-4,-3,1,LOG:15)
Block(1,24,7,LEAVES:3)
Block(-4,-2,1,LOG:15)
Block(1,23,7,LEAVES:3)
Block(-4,-1,1,LOG:15)
Block(1,22,7,LEAVES:3)
Block(-2,19,-9,LEAVES:3)
Block(-3,13,8,LEAVES:3)
Block(-3,12,8,LEAVES:3)
Block(-3,11,8,LEAVES:3)
Block(-8,23,-3,LEAVES:3)
Block(-1,23,10,LEAVES:3)
Block(-1,9,-2,LEAVES:3)
Block(-1,8,-2,LEAVES:3)
Block(-1,18,2,LOG:7)
Block(4,22,4,LEAVES:3)
Block(-3,19,-3,LEAVES:3)
Block(4,23,4,LOG:15)
Block(1,13,7,VINE:4)
Block(1,12,7,LEAVES:3)
Block(4,24,4,LEAVES:3)
Block(-3,24,8,LEAVES:3)
Block(0,10,-1,LEAVES:3)
Block(-9,12,3,LEAVES:3)
Block(-9,13,3,LEAVES:3)
Block(-3,15,-3,LOG:15)
Block(-3,18,-3,LEAVES:3)
Block(-3,23,8,LEAVES:3)
Block(-1,15,2,LEAVES:3)
Block(-3,22,8,LEAVES:3)
Block(-6,23,-3,LEAVES:3)
Block(-6,24,-3,LEAVES:3)
Block(-6,22,-3,LEAVES:3)
Block(-2,24,5,LEAVES:3)
Block(-8,23,-1,LEAVES:3)
Block(-8,24,-1,LEAVES:3)
Block(-3,23,-3,LEAVES:3)
Block(-3,22,-3,LEAVES:3)
Block(-3,24,-3,LEAVES:3)
Block(-8,22,-1,LEAVES:3)
Block(-4,23,8,LEAVES:3)
Block(-4,24,8,LEAVES:3)
Block(-4,22,8,VINE:4)
Block(-1,6,2,LEAVES:3)
Block(-2,9,0,VINE:1)
Block(-2,8,0,VINE:1)
Block(-2,7,0,LEAVES:3)
Block(-2,6,0,LOG:15)
Block(-2,5,0,LEAVES:3)
Block(4,23,6,LEAVES:3)
Block(-1,15,0,LEAVES:3)
Block(-2,1,0,LOG:15)
Block(-2,0,0,LOG:15)
Block(-1,0,2,LOG:15)
Block(-7,11,6,LEAVES:3)
Block(-7,12,6,LEAVES:3)
Block(1,19,-5,LEAVES:3)
Block(2,23,7,LEAVES:3)
Block(3,23,-3,LEAVES:3)
Block(-2,12,5,LEAVES:3)
Block(-2,11,5,LEAVES:3)
Block(-2,10,5,LOG:15)
Block(2,22,7,VINE:4)
Block(0,22,4,LEAVES:3)
Block(0,23,4,LEAVES:3)
Block(5,23,5,LEAVES:3)
Block(-6,23,7,LEAVES:3)
Block(0,24,4,LEAVES:3)
Block(-1,22,0,LEAVES:3)
Block(-1,23,0,LEAVES:3)
Block(-1,24,0,LEAVES:3)
Block(-7,23,6,LEAVES:3)
Block(-1,19,-5,LEAVES:3)
Block(-1,17,-5,LEAVES:3)
Block(-5,24,2,LEAVES:3)
Block(-1,18,-5,LOG:15)
Block(-2,14,5,LEAVES:3)
Block(-2,13,5,LEAVES:3)
Block(-2,23,5,LEAVES:3)
Block(-1,24,-5,LEAVES:3)
Block(-1,-3,2,LOG:15)
Block(-2,22,5,LEAVES:3)
Block(-1,22,-5,LEAVES:3)
Block(-1,23,-5,LEAVES:3)
Block(-8,12,0,LEAVES:3)
Block(-1,20,-5,LEAVES:3)
Block(-8,13,0,LEAVES:3)
Block(-8,11,0,LEAVES:3)
Block(-6,14,7,VINE:8)
Block(0,12,4,LEAVES:3)
Block(-6,13,7,LEAVES:3)
Block(-6,12,7,LOG:15)
Block(-6,11,7,LEAVES:3)
Block(3,24,1,LEAVES:3)
Block(-1,-2,2,LOG:15)
Block(3,22,1,LEAVES:3)
Block(-1,-1,2,LOG:15)
Block(3,23,1,LEAVES:3)
Block(-3,1,0,LOG:15)
Block(-3,0,0,LOG:15)
Block(1,9,0,LOG:15)
Block(1,8,0,LEAVES:3)
Block(3,22,-1,LEAVES:3)
Block(1,23,9,LEAVES:3)
Block(-2,11,7,LOG:15)
Block(-2,12,7,LEAVES:3)
Block(-2,13,7,LEAVES:3)
Block(1,10,-3,LEAVES:3)
Block(3,23,-1,LEAVES:3)
Block(3,24,-1,LEAVES:3)
Block(-3,7,0,LOG:15)
Block(-3,12,10,LEAVES:3)
Block(-3,6,0,LOG:15)
Block(0,24,6,LEAVES:3)
Block(-3,9,0,LOG:15)
Block(-3,8,0,LOG:15)
Block(-3,3,0,LOG:15)
Block(-3,2,0,LOG:15)
Block(-3,5,0,LOG:15)
Block(0,23,6,LEAVES:3)
Block(-3,4,0,LOG:15)
Block(0,22,6,LEAVES:3)
Block(-3,23,-5,LEAVES:3)
Block(-1,21,4,COCOA:10)
Block(-3,20,-5,LEAVES:3)
Block(-2,9,2,LOG:15)
Block(-2,7,2,LEAVES:3)
Block(-2,6,2,LEAVES:3)
Block(-2,5,2,LEAVES:3)
Block(-2,21,7,LOG:15)
Block(-2,22,7,LEAVES:3)
Block(-1,19,-7,LEAVES:3)
Block(-10,23,1,LEAVES:3)
Block(-2,23,7,LEAVES:3)
Block(-1,18,-7,LEAVES:3)
Block(-2,24,7,LEAVES:3)
Block(-1,20,-7,LEAVES:3)
Block(-1,13,4,LEAVES:3)
Block(-3,23,10,LEAVES:3)
Block(0,13,6,LEAVES:3)
Block(-1,11,4,LEAVES:3)
Block(-1,12,4,LEAVES:3)
Block(-3,19,-5,LEAVES:3)
Block(0,12,6,LEAVES:3)
Block(-3,17,-5,LOG:15)
Block(0,11,6,LEAVES:3)
Block(-3,18,-5,LEAVES:3)
Block(-4,12,8,LEAVES:3)
Block(-4,13,8,LEAVES:3)
Block(-4,11,8,LEAVES:3)
Block(-3,-2,1,LOG:15)
Block(-3,-3,1,LOG:15)
Block(-4,14,8,VINE:4)
Block(-3,-1,1,LOG:15)
Block(4,24,2,LEAVES:3)
Block(4,23,2,LEAVES:3)
Block(-5,-3,0,LOG:15)
Block(4,22,2,LEAVES:3)
Block(-2,23,10,LEAVES:3)
Block(-5,-2,0,LOG:15)
Block(-5,-1,0,LOG:15)
Block(0,22,-3,LOG:15)
Block(-1,24,4,LEAVES:3)
Block(0,23,-3,LEAVES:3)
Block(-9,23,5,LEAVES:3)
Block(-1,22,4,LOG:15)
Block(-1,23,4,LEAVES:3)
Block(-7,19,-7,LEAVES:3)
Block(-6,24,3,LEAVES:3)
Block(-6,25,3,LEAVES:3)
Block(-6,22,3,LEAVES:3)
Block(0,24,-3,LEAVES:3)
Block(-6,23,3,LEAVES:3)
Block(0,25,-3,LEAVES:3)
Block(-4,17,-5,LEAVES:3)
Block(-4,19,-5,LEAVES:3)
Block(-4,18,-5,LEAVES:3)
Block(-6,19,-7,LEAVES:3)
Block(-2,12,10,LEAVES:3)
Block(1,22,-3,LEAVES:3)
Block(1,23,-3,LOG:15)
Block(1,24,-3,LEAVES:3)
Block(-8,12,4,LEAVES:3)
Block(-5,23,9,LEAVES:3)
Block(0,9,2,LEAVES:3)
Block(-4,20,-5,LEAVES:3)
Block(-4,23,-5,LEAVES:3)
Block(-4,11,6,LEAVES:3)
Block(1,9,2,LEAVES:3)
Block(-4,13,6,LEAVES:3)
Block(2,24,5,LEAVES:3)
Block(-4,12,6,LEAVES:3)
Block(2,23,5,LEAVES:3)
Block(2,22,5,LOG:15)
Block(-4,14,6,LEAVES:3)
Block(-5,-3,2,LOG:15)
Block(-4,1,0,LOG:15)
Block(-2,20,-7,LEAVES:3)
Block(-5,-1,2,LOG:15)
Block(-4,6,0,LEAVES:3)
Block(-5,19,-7,LEAVES:3)
Block(-5,-2,2,LOG:15)
Block(-4,5,0,LEAVES:3)
Block(-4,0,0,LOG:15)
Block(-3,9,2,LOG:15)
Block(-3,8,2,LOG:15)
Block(2,9,0,LEAVES:3)
Block(-2,19,-7,LOG:15)
Block(-2,18,-7,LEAVES:3)
Block(-3,5,2,LOG:15)
Block(-3,4,2,LOG:15)
Block(-7,19,-5,LEAVES:3)
Block(-3,7,2,LOG:15)
Block(-1,23,2,LEAVES:3)
Block(-3,6,2,LOG:15)
Block(-1,22,2,LEAVES:3)
Block(-3,1,2,LOG:15)
Block(-3,0,2,LOG:15)
Block(-1,24,2,LEAVES:3)
Block(-3,3,2,LOG:15)
Block(-4,23,10,LEAVES:3)
Block(-3,2,2,LOG:15)
Block(0,19,-3,LEAVES:3)
Block(-5,25,0,LEAVES:3)
Block(1,10,0,LEAVES:3)
Block(-5,24,0,LEAVES:3)
Block(-5,23,0,LEAVES:3)
Block(-5,22,0,LEAVES:3)
Block(2,10,-1,LEAVES:3)
Block(-8,11,2,LEAVES:3)
Block(-8,13,2,LEAVES:3)
Block(-8,12,2,LOG:15)
Block(1,24,-1,LEAVES:3)
Block(1,23,-1,LEAVES:3)
Block(1,22,-1,LEAVES:3)
Block(4,22,-1,LEAVES:3)
Block(0,10,-3,LEAVES:3)
Block(4,23,-1,LEAVES:3)
Block(-4,12,10,LEAVES:3)
Block(-4,11,10,VINE:4)
Block(-3,12,1,LOG:15)
Block(-3,13,1,LOG:15)
Block(-3,10,1,LOG:15)
Block(-3,11,1,LOG:15)
Block(-3,16,1,LOG:15)
Block(-3,17,1,LOG:15)
Block(1,25,0,LEAVES:3)
Block(-3,14,1,LOG:15)
Block(1,24,0,LEAVES:3)
Block(-3,15,1,LOG:15)
Block(1,23,0,LEAVES:3)
Block(-10,12,3,LEAVES:3)
Block(1,22,0,LEAVES:3)
Block(-5,12,0,LEAVES:3)
Block(-3,18,1,LOG:15)
Block(-3,19,1,LOG:15)
Block(2,24,-1,LEAVES:3)
Block(-8,22,2,LEAVES:3)
Block(2,23,-1,LEAVES:3)
Block(2,22,-1,LEAVES:3)
Block(-8,24,2,LEAVES:3)
Block(-5,12,10,LEAVES:3)
Block(-8,23,2,LEAVES:3)
Block(-3,20,1,LOG:15)
Block(-3,23,1,LEAVES:3)
Block(-3,24,1,LEAVES:3)
Block(-3,21,1,LOG:15)
Block(-4,22,6,LEAVES:3)
Block(-3,22,1,LOG:15)
Block(-4,24,6,LEAVES:3)
Block(2,12,5,LEAVES:3)
Block(-4,23,6,LEAVES:3)
Block(-4,25,6,LEAVES:3)
Block(-10,23,3,LEAVES:3)
Block(-5,10,0,LOG:7)
Block(-9,12,7,LEAVES:3)
Block(-9,11,7,VINE:0)
Block(-3,18,-7,LEAVES:3)
Block(6,23,1,LEAVES:3)
Block(-3,19,-7,LEAVES:3)
Block(-4,9,2,VINE:8)
Block(-4,8,2,VINE:8)
Block(-4,7,2,VINE:8)
Block(-2,-3,0,LOG:15)
Block(-2,-2,0,LOG:15)
Block(-4,1,2,LOG:15)
Block(-2,-1,0,LOG:15)
Block(-4,0,2,LOG:15)
Block(-3,9,4,LOG:15)
Block(1,22,1,LEAVES:3)
Block(1,23,1,LEAVES:3)
Block(-4,15,-1,LOG:15)
Block(1,24,1,LEAVES:3)
Block(-4,25,4,LEAVES:3)
Block(1,25,1,LEAVES:3)
Block(-3,10,2,LOG:15)
Block(-3,14,2,LOG:15)
Block(-3,13,2,LOG:15)
Block(-3,12,2,LOG:15)
Block(-3,11,2,LOG:15)
Block(3,23,7,LEAVES:3)
Block(-1,13,7,LEAVES:3)
Block(-3,18,2,LOG:15)
Block(-1,12,7,LEAVES:3)
Block(-3,17,2,LOG:15)
Block(-4,22,4,LEAVES:3)
Block(-1,11,7,LEAVES:3)
Block(-3,16,2,LOG:15)
Block(-5,23,-5,LEAVES:3)
Block(-4,23,4,LEAVES:3)
Block(-3,15,2,LOG:15)
Block(-4,24,4,LEAVES:3)
Block(-7,12,3,LEAVES:3)
Block(-3,19,2,LOG:15)
Block(-3,5,-2,LEAVES:3)
Block(-9,23,-1,LEAVES:3)
Block(0,19,-7,LEAVES:3)
Block(-3,21,2,LOG:15)
Block(-3,20,2,LOG:15)
Block(1,19,1,LOG:15)
Block(-5,18,-5,LOG:15)
Block(2,25,3,LEAVES:3)
Block(-5,17,-5,LEAVES:3)
Block(-3,24,2,LEAVES:3)
Block(-3,23,2,LEAVES:3)
Block(2,23,3,LEAVES:3)
Block(-3,22,2,LOG:15)
Block(2,24,3,LEAVES:3)
Block(-1,24,7,LEAVES:3)
Block(2,22,3,LEAVES:3)
Block(-1,23,7,LEAVES:3)
Block(-1,22,7,LEAVES:3)
Block(-2,12,9,LEAVES:3)
Block(-5,19,-5,LEAVES:3)
Block(1,9,-3,LOG:15)
Block(1,8,-3,LEAVES:3)
Block(-9,13,-1,VINE:8)
Block(-9,11,-1,LEAVES:3)
Block(-9,12,-1,LEAVES:3)
Block(-7,23,-4,LEAVES:3)
Block(-5,20,-5,LEAVES:3)
Block(0,24,8,LEAVES:3)
Block(-3,18,-8,VINE:1)
Block(-3,19,-8,LEAVES:3)
Block(0,23,8,LEAVES:3)
Block(-2,23,9,LOG:15)
Block(-2,22,9,LEAVES:3)
Block(-2,24,9,LEAVES:3)
Block(-1,19,-9,LEAVES:3)
Block(-5,0,0,LOG:15)
Block(-5,5,0,LEAVES:3)
Block(0,12,8,LEAVES:3)
Block(-2,17,0,VINE:7)
Block(-2,16,0,LEAVES:3)
Block(-1,22,5,LEAVES:3)
Block(-2,19,0,VINE:7)
Block(-4,9,4,LOG:15)
Block(-2,18,0,VINE:7)
Block(-7,22,1,LEAVES:3)
Block(4,24,0,LEAVES:3)
Block(-2,13,0,VINE:1)
Block(-7,21,1,LOG:15)
Block(-2,12,0,VINE:1)
Block(-2,15,0,LOG:15)
Block(4,22,0,LOG:15)
Block(-7,24,1,LEAVES:3)
Block(-2,14,0,LEAVES:3)
Block(4,23,0,LOG:15)
Block(-7,23,1,LEAVES:3)
Block(-2,11,0,VINE:1)
Block(-2,10,0,VINE:1)
Block(-7,23,-2,LEAVES:3)
Block(-2,24,-4,LEAVES:3)
Block(0,20,-5,LEAVES:3)
Block(-7,24,-2,LEAVES:3)
Block(-7,22,-2,LEAVES:3)
Block(0,24,-5,LEAVES:3)
Block(-1,12,5,LEAVES:3)
Block(0,23,-5,LEAVES:3)
Block(-1,13,5,LEAVES:3)
Block(0,22,-5,LEAVES:3)
Block(-6,20,1,LOG:15)
Block(-6,23,1,LEAVES:3)
Block(-6,22,1,LEAVES:3)
Block(5,22,0,LEAVES:3)
Block(-4,16,-3,LOG:15)
Block(-4,17,-3,LEAVES:3)
Block(5,23,0,LEAVES:3)
Block(-4,18,-3,LEAVES:3)
Block(-2,20,-4,LEAVES:3)
Block(-2,24,0,LEAVES:3)
Block(-4,19,-3,LEAVES:3)
Block(-2,23,0,LEAVES:3)
Block(-2,22,-4,LEAVES:3)
Block(-2,23,-4,LEAVES:3)
Block(-2,25,0,LEAVES:3)
Block(-2,20,0,VINE:7)
Block(-2,22,0,LEAVES:3)
Block(-2,21,0,VINE:3)
Block(-2,17,-4,LOG:15)
Block(-2,18,-4,LEAVES:3)
Block(-2,19,-4,LEAVES:3)
Block(-7,12,-2,LEAVES:3)
Block(-7,13,-2,LEAVES:3)
Block(-7,11,-2,LEAVES:3)
Block(0,8,1,LEAVES:3)
Block(2,9,-1,LEAVES:3)
Block(-1,23,5,LEAVES:3)
Block(0,9,1,LEAVES:3)
Block(-1,24,5,LEAVES:3)
Block(-6,10,1,LOG:7)
Block(-6,12,1,LEAVES:3)
Block(-4,22,-3,LEAVES:3)
Block(-4,23,-3,LEAVES:3)
Block(-4,24,-3,LEAVES:3)
Block(-4,11,4,LEAVES:3)
Block(6,23,4,LEAVES:3)
Block(-4,12,4,LEAVES:3)
Block(-4,13,4,LEAVES:3)
Block(1,9,-1,LEAVES:3)
Block(1,20,3,LOG:15)
Block(1,23,3,LEAVES:3)
Block(1,8,-1,LEAVES:3)
Block(1,22,3,LEAVES:3)
Block(-5,23,8,LEAVES:3)
Block(1,25,3,LEAVES:3)
Block(1,24,3,LEAVES:3)
Block(-3,12,4,LEAVES:3)
Block(-3,11,4,LEAVES:3)
Block(-6,25,1,LEAVES:3)
Block(-3,15,4,LEAVES:3)
Block(-6,24,1,LEAVES:3)
Block(-5,24,-3,LEAVES:3)
Block(-3,13,4,LEAVES:3)
Block(0,19,-5,LOG:15)
Block(-5,22,-3,LEAVES:3)
Block(4,23,-3,LEAVES:3)
Block(-5,23,-3,LEAVES:3)
Block(-3,18,4,LOG:15)
Block(-7,11,1,LOG:15)
Block(-7,13,1,LEAVES:3)
Block(-7,12,1,LEAVES:3)
Block(2,23,-4,LEAVES:3)
Block(-5,14,8,VINE:4)
Block(-5,13,8,LEAVES:3)
Block(-8,23,5,LEAVES:3)
Block(-5,12,8,LEAVES:3)
Block(-5,11,8,LEAVES:3)
Block(-5,0,2,LOG:15)
Block(0,18,-5,LEAVES:3)
Block(-3,23,4,LEAVES:3)
Block(-3,22,4,LEAVES:3)
Block(-3,21,4,VINE:0)
Block(2,22,1,LEAVES:3)
Block(-1,23,9,LEAVES:3)
Block(-9,24,0,LEAVES:3)
Block(-9,23,0,LEAVES:3)
Block(2,24,1,LEAVES:3)
Block(2,23,1,LEAVES:3)
Block(-3,24,4,LEAVES:3)
Block(-9,22,0,VINE:8)
Block(2,20,1,LOG:15)
Block(-4,11,2,VINE:8)
Block(-6,12,-2,LEAVES:3)
Block(-4,10,2,VINE:8)
Block(-5,19,-3,LEAVES:3)
Block(-7,24,5,LEAVES:3)
Block(-7,23,5,LEAVES:3)
Block(2,25,1,LEAVES:3)
Block(0,15,1,LEAVES:3)
Block(-6,11,8,LEAVES:3)
Block(0,18,1,LOG:7)
Block(-6,12,8,LEAVES:3)
Block(-6,13,8,LEAVES:3)
Block(-9,13,0,LEAVES:3)
Block(-9,12,0,LEAVES:3)
Block(5,23,4,LEAVES:3)
Block(-6,22,-2,LOG:15)
Block(-6,23,-2,LOG:15)
Block(-6,24,-2,LEAVES:3)
Block(-3,-3,-1,LOG:15)
Block(-1,-1,0,LOG:15)
Block(-1,-2,0,LOG:15)
Block(-1,-3,0,LOG:15)
Block(-1,10,-2,LEAVES:3)
Block(-3,-1,-1,LOG:15)
Block(2,9,-3,LEAVES:3)
Block(-3,-2,-1,LOG:15)
Block(-5,23,4,LEAVES:3)
Block(-5,22,4,LEAVES:3)
Block(-5,25,4,LEAVES:3)
Block(-5,24,4,LEAVES:3)
Block(-5,21,4,LOG:15)
Block(-4,24,2,LEAVES:3)
Block(-4,23,2,LOG:15)
Block(-4,22,2,LEAVES:3)
Block(-7,12,5,LEAVES:3)
Block(-8,12,-1,LEAVES:3)
Block(-5,12,4,LEAVES:3)
Block(-4,19,2,LOG:15)
Block(-8,13,-1,LEAVES:3)
Block(-4,18,2,VINE:8)
Block(-4,17,2,VINE:8)
Block(-4,16,2,LEAVES:3)
Block(-4,15,2,LEAVES:3)
Block(-4,14,2,LEAVES:3)
Block(-4,13,2,VINE:8)
Block(-4,12,2,VINE:8)
Block(3,24,5,LEAVES:3)
Block(3,23,5,LEAVES:3)
Block(3,22,5,LEAVES:3)
Block(-6,23,8,LEAVES:3)
Block(-8,11,-1,LEAVES:3)
Block(3,9,-1,LEAVES:3)
Block(1,22,5,LEAVES:3)
Block(1,23,5,LEAVES:3)
Block(-5,24,6,LEAVES:3)
Block(-4,25,0,LEAVES:3)
Block(-5,22,6,LEAVES:3)
Block(-4,23,0,LOG:15)
Block(1,19,-7,LEAVES:3)
Block(-5,23,6,LEAVES:3)
Block(-4,24,0,LEAVES:3)
Block(1,24,5,LEAVES:3)
Block(-4,22,0,LEAVES:3)
Block(-3,11,6,LEAVES:3)
Block(-3,12,6,LEAVES:3)
Block(-9,11,2,LEAVES:3)
Block(-8,12,7,LEAVES:3)
Block(-3,13,6,LEAVES:3)
Block(-9,12,2,LEAVES:3)
Block(-3,14,6,LEAVES:3)
Block(-8,11,7,VINE:8)
Block(-9,13,2,LEAVES:3)
Block(-3,10,6,LOG:15)
Block(-5,23,-1,LEAVES:3)
Block(-5,22,-1,LEAVES:3)
Block(-5,25,-1,LEAVES:3)
Block(-5,24,-1,LEAVES:3)
Block(-5,21,-1,LOG:15)
Block(-4,20,0,LOG:15)
Block(1,12,5,LEAVES:3)
Block(2,19,-6,LEAVES:3)
Block(-5,13,6,LEAVES:3)
Block(-4,14,0,VINE:1)
Block(-4,15,0,LOG:15)
Block(-5,11,6,LOG:15)
Block(-4,12,0,VINE:1)
Block(-5,12,6,LEAVES:3)
Block(-4,13,0,VINE:1)
Block(-4,10,0,LOG:7)
Block(-4,11,0,VINE:1)
Block(-3,22,6,LEAVES:3)
Block(3,23,3,LEAVES:3)
Block(3,22,3,LEAVES:3)
Block(-3,23,6,LEAVES:3)
Block(-3,10,-1,VINE:1)
Block(-3,24,6,LEAVES:3)
Block(-3,11,-1,VINE:1)
Block(-9,23,2,LEAVES:3)
Block(-3,25,6,LEAVES:3)
Block(-3,12,-1,VINE:1)
Block(-9,24,2,LEAVES:3)
Block(-3,13,-1,VINE:1)
Block(-3,14,-1,VINE:1)
Block(-3,15,-1,LOG:15)
Block(-3,20,6,LOG:15)
Block(3,24,3,LEAVES:3)
Block(-5,12,-1,LEAVES:3)
Block(0,9,-3,LEAVES:3)
Block(-2,18,2,LOG:7)
Block(0,8,-3,LEAVES:3)
Block(-2,16,2,LEAVES:3)
Block(-2,17,2,VINE:2)
Block(-2,14,2,LEAVES:3)
Block(-7,23,3,LEAVES:3)
Block(-2,15,2,LEAVES:3)
Block(-7,24,3,LEAVES:3)
Block(-2,12,2,VINE:2)
Block(-7,22,3,LEAVES:3)
Block(-2,13,2,VINE:2)
Block(-2,10,2,VINE:2)
Block(-2,11,2,VINE:2)
Block(-2,25,-2,LEAVES:3)
Block(-2,20,2,LOG:15)
Block(-2,24,-2,LEAVES:3)
Block(-2,9,-2,LEAVES:3)
Block(-1,21,-2,LOG:15)
Block(-2,23,-2,LEAVES:3)
Block(-2,22,-2,LEAVES:3)
Block(-1,22,-2,LEAVES:3)
Block(-3,21,-1,COCOA:8)
Block(-3,22,-1,LEAVES:3)
Block(-3,23,-1,LEAVES:3)
Block(-3,24,-1,LEAVES:3)
Block(-2,5,-2,LEAVES:3)
Block(-1,12,9,LEAVES:3)
Block(5,22,2,VINE:2)
Block(5,23,2,LEAVES:3)
Block(-1,23,-2,LEAVES:3)
Block(-2,23,2,LEAVES:3)
Block(-1,24,-2,LEAVES:3)
Block(-2,24,2,LEAVES:3)
Block(-1,25,-2,LEAVES:3)
Block(-2,22,2,LEAVES:3)
Block(0,25,1,LEAVES:3)
Block(-4,-3,2,LOG:15)
Block(0,24,1,LEAVES:3)
Block(-4,-2,2,LOG:15)
Block(0,23,1,LEAVES:3)
Block(-4,-1,2,LOG:15)
Block(-2,16,-2,LEAVES:3)
Block(-2,15,-2,LOG:15)
Block(-4,25,-1,LEAVES:3)
Block(-4,24,-1,LEAVES:3)
Block(-2,19,-2,LEAVES:3)
Block(-4,23,-1,LEAVES:3)
Block(-4,22,-1,LEAVES:3)
Block(0,22,1,LEAVES:3)
Block(-1,19,-4,LEAVES:3)
Block(-1,18,-4,LEAVES:3)
Block(-2,13,4,LEAVES:3)
Block(-1,17,-4,LEAVES:3)
Block(-2,12,4,LEAVES:3)
Block(-1,16,1,LEAVES:3)
Block(-3,19,-2,LEAVES:3)
Block(-1,22,-4,LEAVES:3)
Block(-2,22,4,LEAVES:3)
Block(-3,18,-2,LEAVES:3)
Block(-1,17,1,VINE:2)
Block(-1,18,1,LOG:7)
Block(-1,24,-4,LEAVES:3)
Block(-1,23,-4,LEAVES:3)
Block(-1,20,-4,LEAVES:3)
Block(-3,24,7,LEAVES:3)
Block(-3,23,7,LEAVES:3)
Block(-1,10,1,VINE:2)
Block(-1,11,1,VINE:2)
Block(-3,15,-2,LOG:15)
Block(-1,12,1,VINE:2)
Block(-1,13,1,VINE:2)
Block(-1,14,1,LEAVES:3)
Block(-3,22,7,LEAVES:3)
Block(-1,15,1,LEAVES:3)
Block(3,23,-4,LEAVES:3)
Block(-1,9,-3,LEAVES:3)
Block(-2,24,4,LEAVES:3)
Block(-2,23,4,LEAVES:3)
Block(-4,-2,0,LOG:15)
Block(1,23,6,LEAVES:3)
Block(-4,-3,0,LOG:15)
Block(1,24,6,LEAVES:3)
Block(-4,-1,0,LOG:15)
Block(1,22,6,LEAVES:3)
Block(0,25,3,LEAVES:3)
Block(-2,19,-8,LEAVES:3)
Block(-3,22,-2,LEAVES:3)
Block(0,22,3,LEAVES:3)
Block(0,23,3,LEAVES:3)
Block(-3,24,-2,LEAVES:3)
Block(-1,21,1,COCOA:9)
Block(-1,22,1,LEAVES:3)
Block(-3,23,-2,LEAVES:3)
Block(0,24,3,LEAVES:3)
Block(-1,23,1,LEAVES:3)
Block(-1,24,1,LEAVES:3)
Block(-7,23,7,LEAVES:3)
Block(3,9,-2,LEAVES:3)
Block(0,9,-1,LEAVES:3)
Block(-6,18,-4,VINE:8)
Block(0,8,-1,LEAVES:3)
Block(-6,19,-4,LEAVES:3)
Block(-10,23,4,LEAVES:3)
Block(-5,23,1,LEAVES:3)
Block(-5,24,1,LEAVES:3)
Block(-5,25,1,LEAVES:3)
Block(1,23,-6,LEAVES:3)
Block(-8,13,1,LEAVES:3)
Block(-8,11,1,LEAVES:3)
Block(-8,12,1,LEAVES:3)
Block(-6,13,6,LEAVES:3)
Block(-6,12,6,LEAVES:3)
Block(3,22,2,LEAVES:3)
Block(-6,11,6,LEAVES:3)
Block(0,12,3,LEAVES:3)
Block(-10,23,-1,LEAVES:3)
Block(6,23,0,LEAVES:3)
Block(3,23,2,LEAVES:3)
Block(3,24,2,LEAVES:3)
Block(-5,16,1,VINE:8)
Block(1,19,-6,LEAVES:3)
Block(-5,17,1,VINE:8)
Block(-5,18,1,VINE:8)
Block(-5,19,1,LOG:7)
Block(-5,12,1,LEAVES:3)
Block(-5,13,1,VINE:8)
Block(-6,23,-4,LEAVES:3)
Block(-5,14,1,VINE:8)
Block(-5,15,1,VINE:8)
Block(-2,11,4,LEAVES:3)
Block(-5,21,1,COCOA:11)
Block(-5,22,1,LEAVES:3)
Block(-8,24,1,LEAVES:3)
Block(-8,22,1,LOG:15)
Block(1,18,-6,VINE:2)
Block(-8,23,1,LEAVES:3)
Block(-10,12,-1,LEAVES:3)
Block(-4,19,-8,LEAVES:3)
Block(-5,25,3,LEAVES:3)
Block(1,23,-4,LEAVES:3)
Block(1,22,-4,LEAVES:3)
Block(1,24,-4,LEAVES:3)
Block(0,13,5,LEAVES:3)
Block(0,12,5,LOG:15)
Block(3,22,0,LEAVES:3)
Block(3,21,0,LOG:15)
Block(0,11,5,LEAVES:3)
Block(3,24,0,LEAVES:3)
Block(3,23,0,LEAVES:3)
Block(-7,12,7,LEAVES:3)
Block(-7,13,7,LEAVES:3)
Block(1,19,-4,LEAVES:3)
Block(-7,11,7,LEAVES:3)
Block(-2,13,6,LEAVES:3)
Block(-5,22,3,LEAVES:3)
Block(-2,12,6,LEAVES:3)
Block(-2,11,6,LEAVES:3)
Block(-5,24,3,LEAVES:3)
Block(-5,23,3,LEAVES:3)
Block(-5,20,3,LOG:15)
Block(2,23,8,LEAVES:3)
Block(-6,24,6,LEAVES:3)
Block(-6,23,6,LOG:15)
Block(-3,12,9,LEAVES:3)
Block(-3,13,9,LEAVES:3)
Block(-3,11,9,LEAVES:3)
Block(-4,23,9,LEAVES:3)
Block(-3,22,-4,LEAVES:3)
Block(-3,20,-4,LEAVES:3)
Block(4,23,5,LEAVES:3)
Block(-5,12,3,LEAVES:3)
Block(-9,12,4,LEAVES:3)
Block(-3,18,-4,LEAVES:3)
Block(-3,23,9,LEAVES:3)
Block(-3,19,-4,LEAVES:3)
Block(-3,24,9,LEAVES:3)
Block(-3,16,-4,LOG:15)
Block(-8,12,-2,LEAVES:3)
Block(-3,17,-4,LEAVES:3)
Block(-4,13,9,LEAVES:3)
Block(-1,6,1,LEAVES:3)
Block(-4,12,9,LEAVES:3)
Block(-1,5,1,LEAVES:3)
Block(-4,11,9,LEAVES:3)
Block(-3,-1,0,LOG:15)
Block(-3,-2,0,LOG:15)
Block(-1,7,1,LEAVES:3)
Block(-1,9,1,LEAVES:3)
Block(-3,-3,0,LOG:15)
Block(1,23,8,LEAVES:3)
Block(-9,23,4,LEAVES:3)
Block(-3,23,-4,LOG:15)
Block(-3,24,-4,LEAVES:3)
Block(-8,23,-2,LEAVES:3)
Block(-4,22,7,LEAVES:3)
Block(-4,23,7,LEAVES:3)
Block(0,19,-4,LEAVES:3)
Block(-4,17,-4,LOG:15)
Block(-4,24,7,LEAVES:3)
Block(-4,18,-4,LEAVES:3)
Block(-4,19,-4,LEAVES:3)
Block(-7,12,0,LEAVES:3)
Block(-7,11,0,LEAVES:3)
Block(-8,12,3,LEAVES:3)
Block(-8,11,3,LEAVES:3)
Block(2,10,-2,LEAVES:3)
Block(-8,13,3,LEAVES:3)
Block(6,23,2,LEAVES:3)
Block(-4,20,-4,LEAVES:3)
Block(-4,11,7,LEAVES:3)
Block(-4,12,7,LEAVES:3)
Block(-4,23,-4,LEAVES:3)
Block(-4,24,-4,LEAVES:3)
Block(-4,13,7,LEAVES:3)
Block(-4,14,7,LEAVES:3)
Block(-7,23,0,LEAVES:3)
Block(4,23,1,LEAVES:3)
Block(-7,22,0,LEAVES:3)
Block(4,24,1,LEAVES:3)
Block(-5,19,-8,LEAVES:3)
Block(4,22,1,LEAVES:3)
Block(2,23,-2,LEAVES:3)
Block(-8,23,3,LEAVES:3)
Block(2,24,-2,LEAVES:3)
Block(-8,22,3,VINE:8)
Block(2,22,-2,LEAVES:3)
Block(-7,13,0,LEAVES:3)
Block(0,20,-4,LEAVES:3)
Block(-8,24,3,LEAVES:3)
Block(0,23,-4,LOG:15)
Block(0,24,-4,LEAVES:3)
Block(0,22,-4,LEAVES:3)
Block(-6,22,2,LEAVES:3)
Block(-7,19,-6,LEAVES:3)
Block(-6,24,2,LEAVES:3)
Block(-6,23,2,LEAVES:3)
Block(1,9,1,LEAVES:3)
Block(0,6,1,LEAVES:3)
Block(2,12,6,LEAVES:3)
Block(-1,18,-6,LEAVES:3)
Block(-1,19,-6,LEAVES:3)
Block(-2,14,6,LEAVES:3)
Block(-8,19,-6,LEAVES:3)
Block(-2,24,6,LEAVES:3)
Block(-2,23,6,LEAVES:3)
Block(-2,22,6,LEAVES:3)
Block(-1,23,-6,LEAVES:3)
Block(-2,21,6,COCOA:8)
Block(-1,20,-6,LEAVES:3)
Block(-3,11,0,LOG:15)
Block(-3,12,0,LOG:15)
Block(-3,10,0,LOG:15)
Block(-3,15,0,LOG:15)
Block(-1,11,5,LOG:15)
Block(-3,16,0,LOG:15)
Block(2,24,6,LEAVES:3)
Block(-3,13,0,LOG:15)
Block(2,23,6,LOG:15)
Block(-3,14,0,LOG:15)
Block(2,22,6,LEAVES:3)
Block(-2,9,1,LOG:15)
Block(-3,19,0,LOG:15)
Block(-2,23,-6,LEAVES:3)
Block(-2,8,1,LOG:15)
Block(-10,12,2,LEAVES:3)
Block(-2,7,1,LOG:15)
Block(-3,17,0,LOG:15)
Block(3,22,-2,LEAVES:3)
Block(-2,6,1,LOG:15)
Block(-3,18,0,LOG:15)
Block(3,23,-2,LEAVES:3)
Block(-2,5,1,LOG:15)
Block(-2,4,1,LOG:15)
Block(-2,3,1,LOG:15)
Block(-2,2,1,LOG:15)
Block(-2,20,-6,LEAVES:3)
Block(-2,1,1,LOG:15)
Block(-2,0,1,LOG:15)
Block(-2,19,-6,LEAVES:3)
Block(-2,18,-6,LEAVES:3)
Block(-2,17,-6,LEAVES:3)
Block(0,24,5,LEAVES:3)
Block(0,23,5,LOG:15)
Block(0,22,5,LEAVES:3)
Block(-3,20,-6,LEAVES:3)
Block(-3,22,0,LOG:15)
Block(-3,23,0,LEAVES:3)
Block(-3,20,0,LOG:15)
Block(-3,21,0,LOG:15)
Block(-6,19,-6,LOG:15)
Block(-3,23,-6,LEAVES:3)
Block(-3,24,0,LEAVES:3)
Block(-10,23,2,LEAVES:3)
Block(-6,18,-6,LEAVES:3)
Block(-2,22,8,LOG:15)
Block(-2,23,8,LEAVES:3)
Block(-2,24,8,LEAVES:3)
Block(-1,19,-8,LEAVES:3)
Block(-5,10,1,LOG:7)
Block(-6,20,-6,LEAVES:3)
Block(-3,17,-6,LEAVES:3)
Block(-6,12,4,LEAVES:3)
Block(-3,19,-6,LEAVES:3)
Block(-3,18,-6,LOG:15)
Block(-1,7,-1,LOG:15)
Block(-1,6,-1,LEAVES:3)
Block(-3,-3,2,LOG:15)
Block(-3,-2,2,LOG:15)
Block(-3,-1,2,LOG:15)
Block(-1,9,-1,LEAVES:3)
Block(-1,8,-1,LEAVES:3)
Block(0,23,7,LEAVES:3)
Block(0,24,7,LEAVES:3)
Block(-3,0,1,LOG:15)
Block(-4,18,-6,LEAVES:3)
Block(-4,17,-6,LEAVES:3)
Block(-4,19,-6,LEAVES:3)
Block(1,9,-5,LEAVES:3)
Block(2,9,1,LEAVES:3)
Block(1,22,-2,LEAVES:3)
Block(-3,9,1,LOG:15)
Block(1,23,-2,LEAVES:3)
Block(1,24,-2,LEAVES:3)
Block(-3,6,1,LOG:15)
Block(-3,5,1,LOG:15)
Block(-3,8,1,LOG:15)
Block(-3,7,1,LOG:15)
Block(0,10,-2,LEAVES:3)
Block(-1,12,3,LEAVES:3)
Block(-3,2,1,LOG:15)
Block(0,12,7,LEAVES:3)
Block(-3,1,1,LOG:15)
Block(0,13,7,LEAVES:3)
Block(-4,20,-6,LEAVES:3)
Block(-3,4,1,LOG:15)
Block(-3,3,1,LOG:15)
Block(-5,19,-6,LEAVES:3)
Block(-5,18,-6,LEAVES:3)
Block(-2,9,3,LOG:15)
Block(-2,6,3,LEAVES:3)
Block(-2,11,8,LEAVES:3)
Block(-2,12,8,LOG:15)
Block(4,24,3,LEAVES:3)
Block(-2,13,8,LEAVES:3)
Block(4,23,3,LEAVES:3)
Block(4,22,3,LEAVES:3)
Block(-7,12,9,LEAVES:3)
Block(1,10,-2,LEAVES:3)
Block(-1,22,3,LEAVES:3)
Block(-1,21,3,LOG:15)
Block(-6,22,4,LEAVES:3)
Block(-5,20,-6,LEAVES:3)
Block(0,22,-2,LEAVES:3)
Block(-1,24,3,LEAVES:3)
Block(-1,23,3,LEAVES:3)
Block(0,21,-2,COCOA:9)
Block(0,24,-2,LEAVES:3)
Block(-6,25,4,LEAVES:3)
Block(0,23,-2,LEAVES:3)
Block(-6,23,4,LEAVES:3)
Block(-6,24,4,LEAVES:3)
Block(0,25,-2,LEAVES:3)

#######################################################################
# +-----------------------------------------------------------------+ #
# |                            BO3 checks                           | #
# +-----------------------------------------------------------------+ #
#######################################################################

BlockCheck(0,-1,0,GRASS:0,DIRT:0,DIRT:2,HARD_CLAY,STAINED_CLAY:0,CLAY,SANDSTONE:0,SAND:1,SAND:0)

#######################################################################
# +-----------------------------------------------------------------+ #
# |                             Branches                            | #
# +-----------------------------------------------------------------+ #
#######################################################################


#######################################################################
# +-----------------------------------------------------------------+ #
# |                             Entities                            | #
# +-----------------------------------------------------------------+ #
#######################################################################


#######################################################################
# +-----------------------------------------------------------------+ #
# |                            Particles                            | #
# +-----------------------------------------------------------------+ #
#######################################################################


#######################################################################
# +-----------------------------------------------------------------+ #
# |                             Spawners                            | #
# +-----------------------------------------------------------------+ #
#######################################################################


#######################################################################
# +-----------------------------------------------------------------+ #
# |                             ModData                             | #
# +-----------------------------------------------------------------+ #
#######################################################################

