
#######################################################################
# +-----------------------------------------------------------------+ #
# |                            BO3 object                           | #
# +-----------------------------------------------------------------+ #
#######################################################################

Author: Unknown

Description: Converted version of the BO2 JungleForest5

Version: 3

SettingsMode: WriteWithoutComments


#######################################################################
# +-----------------------------------------------------------------+ #
# |                          Main settings                          | #
# +-----------------------------------------------------------------+ #
#######################################################################

Tree: true

Frequency: 1

Rarity: 10.0

RotateRandomly: true

SpawnHeight: highestSolidBlock

SpawnHeightOffset: 0

SpawnHeightVariance: 0

##############################
# Height Limits for the BO3. #
##############################

MinHeight: 62

MaxHeight: 210

######################
# Extrusion settings #
######################

ExtrudeMode: None

ExtrudeThroughBlocks: AIR

MaxBranchDepth: 10

ExcludedBiomes: All


#######################################################################
# +-----------------------------------------------------------------+ #
# |                      Source block settings                      | #
# +-----------------------------------------------------------------+ #
#######################################################################

SourceBlocks: STONE:1,STONE:3,STONE:5,DIRT:1,DIRT:0,SAND:0,GRASS:0,DIRT:2,STATIONARY_WATER:0,HARD_CLAY,STAINED_CLAY:0,CLAY,SANDSTONE:0,SAND:1,AIR,STONE:0,GRAVEL,LONG_GRASS:0,LONG_GRASS:1,LONG_GRASS:2,DEAD_BUSH,YELLOW_FLOWER:0,RED_ROSE:0,BROWN_MUSHROOM,RED_MUSHROOM

MaxPercentageOutsideSourceBlock: 0

OutsideSourceBlock: placeAnyway

DoReplaceBlocks: true

IsOTGPlus: false


#######################################################################
# +-----------------------------------------------------------------+ #
# |                              Blocks                             | #
# +-----------------------------------------------------------------+ #
#######################################################################

Block(8,11,0,LEAVES:3)
Block(6,11,-1,LEAVES:3)
Block(-6,9,-6,LEAVES:3)
Block(6,11,5,LEAVES:3)
Block(-2,22,-3,LEAVES:3)
Block(-2,21,-3,LEAVES:3)
Block(-2,20,-3,LEAVES:3)
Block(7,21,-5,LEAVES:3)
Block(-2,8,-7,LEAVES:3)
Block(1,9,-4,LEAVES:3)
Block(-2,9,-7,LEAVES:3)
Block(0,9,-8,LEAVES:3)
Block(2,22,4,LEAVES:3)
Block(2,23,4,LEAVES:3)
Block(2,21,4,LEAVES:3)
Block(-2,10,-3,LEAVES:3)
Block(-8,13,6,LEAVES:3)
Block(-7,22,-3,LEAVES:3)
Block(10,11,-5,LEAVES:3)
Block(8,21,0,LEAVES:3)
Block(5,22,1,LEAVES:3)
Block(1,19,-1,LOG:15)
Block(5,21,1,LEAVES:3)
Block(-4,21,5,LEAVES:3)
Block(1,18,-1,LOG:15)
Block(5,20,1,LOG:15)
Block(-4,20,5,LEAVES:3)
Block(1,17,-1,LOG:15)
Block(4,21,-2,LEAVES:3)
Block(1,16,-1,LOG:15)
Block(4,22,-2,LEAVES:3)
Block(-4,22,5,LEAVES:3)
Block(1,15,-1,LOG:15)
Block(1,14,-1,LOG:15)
Block(4,20,-2,LEAVES:3)
Block(-7,13,2,LEAVES:3)
Block(-5,14,7,LEAVES:3)
Block(-5,12,7,LEAVES:3)
Block(1,10,2,VINE:4)
Block(0,10,-6,LEAVES:3)
Block(-5,13,7,LEAVES:3)
Block(2,22,-5,LEAVES:3)
Block(1,11,2,VINE:4)
Block(2,21,-5,LEAVES:3)
Block(1,12,2,VINE:4)
Block(1,13,2,VINE:4)
Block(1,13,-1,LOG:15)
Block(1,14,2,VINE:4)
Block(1,12,-1,LOG:15)
Block(-4,15,5,LEAVES:3)
Block(1,15,2,VINE:4)
Block(1,11,-1,LOG:15)
Block(1,16,2,LEAVES:3)
Block(4,23,-2,LEAVES:3)
Block(1,10,-1,LOG:15)
Block(1,17,2,LEAVES:3)
Block(1,18,2,LEAVES:3)
Block(5,12,1,LEAVES:3)
Block(5,11,1,LEAVES:3)
Block(-4,12,5,LEAVES:3)
Block(6,22,-1,LEAVES:3)
Block(6,23,-1,LEAVES:3)
Block(-4,14,5,LEAVES:3)
Block(6,20,-1,LEAVES:3)
Block(-4,13,5,LEAVES:3)
Block(6,21,-1,LEAVES:3)
Block(-2,23,-3,LEAVES:3)
Block(-6,22,0,LEAVES:3)
Block(0,1,0,LOG:15)
Block(4,20,-4,LEAVES:3)
Block(0,0,0,LOG:15)
Block(-3,14,3,LEAVES:3)
Block(0,3,0,LOG:15)
Block(-3,13,3,LEAVES:3)
Block(0,2,0,LOG:15)
Block(-3,12,3,LEAVES:3)
Block(0,5,0,LOG:15)
Block(-4,20,3,VINE:8)
Block(0,4,0,LOG:15)
Block(-4,21,3,LEAVES:3)
Block(4,23,-4,LEAVES:3)
Block(0,7,0,LOG:15)
Block(4,22,-4,LEAVES:3)
Block(0,6,0,LOG:15)
Block(4,21,-4,LEAVES:3)
Block(-5,22,-4,LEAVES:3)
Block(-2,9,-5,LEAVES:3)
Block(2,22,-3,LEAVES:3)
Block(1,8,-2,VINE:1)
Block(2,23,-3,LEAVES:3)
Block(2,20,-3,LEAVES:3)
Block(1,6,-2,VINE:1)
Block(2,21,-3,LEAVES:3)
Block(1,7,-2,VINE:1)
Block(-2,7,-5,LOG:15)
Block(-2,8,-5,LEAVES:3)
Block(1,5,-2,VINE:1)
Block(0,8,-6,LEAVES:3)
Block(-4,13,3,LEAVES:3)
Block(-4,14,3,LEAVES:3)
Block(1,0,-2,LOG:15)
Block(9,21,-2,LEAVES:3)
Block(0,9,-6,LEAVES:3)
Block(-3,22,3,LEAVES:3)
Block(-3,21,3,LEAVES:3)
Block(-3,20,3,LEAVES:3)
Block(4,11,-4,LEAVES:3)
Block(-4,11,3,LOG:15)
Block(-4,12,3,LEAVES:3)
Block(6,21,3,LEAVES:3)
Block(9,11,2,LEAVES:3)
Block(7,11,-7,LEAVES:3)
Block(1,20,2,LEAVES:3)
Block(1,21,2,LEAVES:3)
Block(1,22,2,LEAVES:3)
Block(1,23,2,LEAVES:3)
Block(9,11,-2,LEAVES:3)
Block(3,22,6,LEAVES:3)
Block(1,-3,-1,LOG:15)
Block(1,-2,-1,LOG:15)
Block(1,-1,-1,LOG:15)
Block(6,12,-3,LEAVES:3)
Block(6,11,-3,LEAVES:3)
Block(4,17,1,LEAVES:3)
Block(-2,21,-5,LEAVES:3)
Block(2,19,2,LOG:15)
Block(2,16,2,LEAVES:3)
Block(4,11,1,LEAVES:3)
Block(2,15,2,VINE:0)
Block(2,18,2,LEAVES:3)
Block(2,17,2,LOG:15)
Block(-2,20,-5,LOG:15)
Block(10,21,-3,LEAVES:3)
Block(6,10,-3,LEAVES:3)
Block(8,11,2,LEAVES:3)
Block(8,12,2,LEAVES:3)
Block(-6,13,2,LEAVES:3)
Block(-6,12,2,LEAVES:3)
Block(2,23,2,LEAVES:3)
Block(2,22,2,LEAVES:3)
Block(2,21,2,LEAVES:3)
Block(-1,21,6,LEAVES:3)
Block(2,20,2,LEAVES:3)
Block(-2,10,-5,LEAVES:3)
Block(-2,11,-5,LEAVES:3)
Block(0,-3,0,LOG:15)
Block(0,-2,0,LOG:15)
Block(0,-1,0,LOG:15)
Block(0,9,0,LOG:15)
Block(0,8,0,LOG:15)
Block(-4,10,-4,LEAVES:3)
Block(9,21,0,LEAVES:3)
Block(-2,21,1,LEAVES:3)
Block(-1,22,-1,LEAVES:3)
Block(-2,20,1,LEAVES:3)
Block(-1,23,-1,LEAVES:3)
Block(-2,23,1,LEAVES:3)
Block(-2,22,1,LOG:15)
Block(8,11,-2,LEAVES:3)
Block(-5,14,5,LEAVES:3)
Block(-2,9,-3,LEAVES:3)
Block(8,10,-2,LEAVES:3)
Block(-5,15,5,LEAVES:3)
Block(-2,8,-3,LEAVES:3)
Block(-5,12,5,LEAVES:3)
Block(-5,13,5,LEAVES:3)
Block(8,12,-2,LEAVES:3)
Block(0,9,-4,LEAVES:3)
Block(3,22,4,LEAVES:3)
Block(3,21,4,LEAVES:3)
Block(6,23,-3,LEAVES:3)
Block(6,22,-3,LEAVES:3)
Block(-1,9,-7,LEAVES:3)
Block(-1,8,-7,LEAVES:3)
Block(7,11,-3,LEAVES:3)
Block(7,11,0,LEAVES:3)
Block(-4,9,-3,LEAVES:3)
Block(7,10,-3,LEAVES:3)
Block(7,13,-3,LEAVES:3)
Block(7,12,-3,LEAVES:3)
Block(7,12,0,LEAVES:3)
Block(0,-3,2,LOG:15)
Block(8,22,-2,LEAVES:3)
Block(8,21,-2,LEAVES:3)
Block(8,20,-2,LEAVES:3)
Block(0,-1,2,LOG:15)
Block(0,-2,2,LOG:15)
Block(-4,22,1,LEAVES:3)
Block(6,21,-3,LEAVES:3)
Block(6,20,-3,LEAVES:3)
Block(-3,12,5,LEAVES:3)
Block(9,11,-6,LEAVES:3)
Block(-3,13,5,LEAVES:3)
Block(-5,23,-2,LEAVES:3)
Block(-3,14,5,LEAVES:3)
Block(-5,22,-2,LOG:15)
Block(-5,21,-2,LEAVES:3)
Block(0,19,0,LOG:15)
Block(7,22,-3,LEAVES:3)
Block(-2,20,-1,LEAVES:3)
Block(7,21,-3,LOG:15)
Block(-6,23,-1,LEAVES:3)
Block(3,21,-7,LEAVES:3)
Block(-6,22,-1,LEAVES:3)
Block(-6,21,-1,LEAVES:3)
Block(7,20,-3,LEAVES:3)
Block(0,23,0,LEAVES:3)
Block(0,22,0,LOG:15)
Block(-3,21,5,LOG:15)
Block(-3,22,5,LEAVES:3)
Block(-3,23,5,LEAVES:3)
Block(5,10,-4,LEAVES:3)
Block(0,21,0,LOG:15)
Block(0,20,0,LOG:15)
Block(5,12,-4,LEAVES:3)
Block(5,11,-4,LEAVES:3)
Block(-3,20,5,LEAVES:3)
Block(-1,15,-1,LEAVES:3)
Block(-1,16,-1,LEAVES:3)
Block(-2,10,1,LOG:7)
Block(0,14,0,LOG:15)
Block(1,20,4,LEAVES:3)
Block(0,13,0,LOG:15)
Block(0,12,0,LOG:15)
Block(-1,20,-1,LEAVES:3)
Block(1,22,4,LEAVES:3)
Block(0,11,0,LOG:15)
Block(-1,21,-1,LEAVES:3)
Block(1,21,4,LOG:15)
Block(0,18,0,LOG:15)
Block(0,17,0,LOG:15)
Block(1,23,4,LEAVES:3)
Block(0,16,0,LOG:15)
Block(-7,23,-1,LEAVES:3)
Block(0,15,0,LOG:15)
Block(-7,22,-1,LEAVES:3)
Block(5,9,1,LOG:7)
Block(0,10,0,LOG:15)
Block(5,21,-4,LEAVES:3)
Block(5,20,-4,LEAVES:3)
Block(5,22,-4,LEAVES:3)
Block(2,10,0,LOG:15)
Block(0,6,-2,LOG:15)
Block(2,11,0,LOG:15)
Block(2,12,0,LOG:15)
Block(0,7,-2,VINE:1)
Block(2,17,0,LOG:15)
Block(2,18,0,LOG:15)
Block(3,23,-5,LEAVES:3)
Block(-7,14,4,LEAVES:3)
Block(2,19,0,LOG:15)
Block(-7,13,4,LEAVES:3)
Block(-7,12,4,LEAVES:3)
Block(2,13,0,LOG:15)
Block(2,14,0,LOG:15)
Block(2,15,0,LOG:15)
Block(3,22,-5,LEAVES:3)
Block(2,16,0,LOG:15)
Block(3,21,-5,LEAVES:3)
Block(6,10,-5,LEAVES:3)
Block(6,11,-5,LEAVES:3)
Block(6,12,-5,LEAVES:3)
Block(0,20,2,LEAVES:3)
Block(0,21,2,LOG:15)
Block(0,22,2,LEAVES:3)
Block(5,20,3,VINE:4)
Block(5,21,3,LEAVES:3)
Block(0,23,2,LEAVES:3)
Block(-4,23,-2,LEAVES:3)
Block(-4,22,-2,LEAVES:3)
Block(5,11,-6,LEAVES:3)
Block(-4,21,-2,LEAVES:3)
Block(2,20,0,LOG:15)
Block(2,21,0,LOG:15)
Block(2,22,0,LEAVES:3)
Block(2,23,0,LEAVES:3)
Block(5,11,3,LEAVES:3)
Block(5,12,3,LEAVES:3)
Block(5,13,3,LEAVES:3)
Block(-4,8,-5,LEAVES:3)
Block(-2,13,3,LEAVES:3)
Block(-4,9,-5,LEAVES:3)
Block(0,17,2,LEAVES:3)
Block(-2,20,3,LOG:15)
Block(-1,21,-3,LEAVES:3)
Block(-2,23,-1,LEAVES:3)
Block(-1,20,-3,LEAVES:3)
Block(-2,21,3,LEAVES:3)
Block(-2,21,-1,LEAVES:3)
Block(-1,22,-3,LEAVES:3)
Block(-2,22,-1,LEAVES:3)
Block(5,21,-6,LEAVES:3)
Block(4,21,-6,LEAVES:3)
Block(4,22,-6,LEAVES:3)
Block(-4,21,1,LEAVES:3)
Block(7,22,0,LEAVES:3)
Block(7,21,0,LEAVES:3)
Block(7,20,0,LEAVES:3)
Block(8,10,-4,LEAVES:3)
Block(-4,14,1,LEAVES:3)
Block(8,11,-4,LEAVES:3)
Block(-4,13,1,LEAVES:3)
Block(-1,9,-9,LEAVES:3)
Block(8,12,-4,LEAVES:3)
Block(-4,12,1,LEAVES:3)
Block(8,13,-4,LEAVES:3)
Block(9,22,-4,LEAVES:3)
Block(9,21,-4,LEAVES:3)
Block(2,9,-6,LEAVES:3)
Block(7,12,-5,LEAVES:3)
Block(7,10,-5,LEAVES:3)
Block(7,11,-5,LEAVES:3)
Block(8,21,-4,LEAVES:3)
Block(-5,21,5,LEAVES:3)
Block(6,21,-5,LEAVES:3)
Block(8,22,-4,LEAVES:3)
Block(9,11,-4,LEAVES:3)
Block(-3,13,7,LEAVES:3)
Block(9,12,-4,LEAVES:3)
Block(9,10,-4,LEAVES:3)
Block(2,-3,0,LOG:15)
Block(-5,13,2,LEAVES:3)
Block(-5,14,2,LEAVES:3)
Block(2,-1,0,LOG:15)
Block(2,-2,0,LOG:15)
Block(7,20,2,VINE:0)
Block(7,21,2,LEAVES:3)
Block(2,6,2,LEAVES:3)
Block(0,21,-1,LOG:15)
Block(0,20,-1,LEAVES:3)
Block(0,22,-1,LEAVES:3)
Block(3,8,0,LOG:7)
Block(3,6,0,LEAVES:3)
Block(-1,7,0,VINE:8)
Block(-1,6,0,LEAVES:3)
Block(-1,9,0,VINE:8)
Block(-1,8,0,VINE:8)
Block(2,-3,-1,LOG:15)
Block(-4,9,-7,LEAVES:3)
Block(2,-2,-1,LOG:15)
Block(2,-1,-1,LOG:15)
Block(1,21,-5,LEAVES:3)
Block(-5,12,2,LEAVES:3)
Block(6,11,-6,LEAVES:3)
Block(6,10,-6,LEAVES:3)
Block(-6,12,5,LEAVES:3)
Block(-6,15,5,LEAVES:3)
Block(-1,0,0,LOG:15)
Block(-6,13,5,LEAVES:3)
Block(1,20,-5,VINE:2)
Block(-6,14,5,LEAVES:3)
Block(5,21,-1,LEAVES:3)
Block(5,22,-1,LEAVES:3)
Block(5,23,-1,LEAVES:3)
Block(-3,10,-3,LEAVES:3)
Block(-2,22,3,LEAVES:3)
Block(-2,23,3,LEAVES:3)
Block(4,11,4,LEAVES:3)
Block(1,22,7,LEAVES:3)
Block(3,0,0,LOG:15)
Block(5,20,-1,LEAVES:3)
Block(0,16,-1,LEAVES:3)
Block(0,15,-1,LEAVES:3)
Block(0,19,-1,COCOA:11)
Block(-3,21,-3,LEAVES:3)
Block(7,13,2,LEAVES:3)
Block(7,12,2,LEAVES:3)
Block(-2,10,-9,LEAVES:3)
Block(7,11,-1,LEAVES:3)
Block(4,21,4,LEAVES:3)
Block(4,22,4,LEAVES:3)
Block(7,11,2,LEAVES:3)
Block(7,10,2,VINE:2)
Block(0,14,-1,LEAVES:3)
Block(-3,9,-9,LEAVES:3)
Block(5,23,-3,LEAVES:3)
Block(8,11,-6,LEAVES:3)
Block(7,20,-1,LEAVES:3)
Block(7,22,-1,LEAVES:3)
Block(7,21,-1,LEAVES:3)
Block(-6,22,-3,LEAVES:3)
Block(8,12,-6,LEAVES:3)
Block(-3,23,-3,LEAVES:3)
Block(-3,22,-3,LEAVES:3)
Block(5,20,-3,LEAVES:3)
Block(5,22,-3,LEAVES:3)
Block(5,21,-3,LEAVES:3)
Block(-8,22,-1,LEAVES:3)
Block(8,21,-6,LEAVES:3)
Block(-1,15,0,LEAVES:3)
Block(-1,16,0,LEAVES:3)
Block(7,11,4,LEAVES:3)
Block(4,8,0,LOG:7)
Block(-9,13,5,LEAVES:3)
Block(-1,10,0,VINE:8)
Block(-1,11,0,VINE:8)
Block(-1,12,0,VINE:8)
Block(-1,13,0,VINE:8)
Block(-1,14,0,VINE:8)
Block(-7,13,6,LEAVES:3)
Block(-7,14,6,LEAVES:3)
Block(3,22,-3,LEAVES:3)
Block(3,21,-3,LEAVES:3)
Block(3,23,-3,LEAVES:3)
Block(3,20,-3,LEAVES:3)
Block(3,17,1,LEAVES:3)
Block(1,10,-5,LEAVES:3)
Block(3,18,1,LEAVES:3)
Block(-1,11,-5,LEAVES:3)
Block(3,16,1,LEAVES:3)
Block(-1,10,-5,LEAVES:3)
Block(3,19,1,COCOA:9)
Block(2,22,7,LEAVES:3)
Block(0,22,4,LEAVES:3)
Block(0,23,4,LEAVES:3)
Block(-1,20,0,LOG:7)
Block(-1,21,0,LEAVES:3)
Block(-1,22,0,LEAVES:3)
Block(-1,23,0,LEAVES:3)
Block(0,20,4,LEAVES:3)
Block(0,21,4,LEAVES:3)
Block(0,-2,-1,LOG:15)
Block(0,-1,-1,LOG:15)
Block(0,-3,-1,LOG:15)
Block(-1,9,-4,LEAVES:3)
Block(-1,8,-4,LEAVES:3)
Block(-1,7,-4,LOG:15)
Block(-2,13,5,LEAVES:3)
Block(-2,23,5,LEAVES:3)
Block(-2,22,5,LEAVES:3)
Block(-2,21,5,LEAVES:3)
Block(-2,20,5,LEAVES:3)
Block(-1,20,-5,LEAVES:3)
Block(-1,21,-5,LEAVES:3)
Block(3,20,1,LEAVES:3)
Block(-6,13,7,LEAVES:3)
Block(3,21,1,LEAVES:3)
Block(5,11,5,LEAVES:3)
Block(-3,8,-7,LEAVES:3)
Block(-3,9,-7,LEAVES:3)
Block(5,11,-3,LEAVES:3)
Block(3,22,1,LEAVES:3)
Block(3,23,1,LEAVES:3)
Block(0,0,2,LOG:15)
Block(-3,11,-5,LEAVES:3)
Block(1,9,0,LOG:15)
Block(1,8,0,LOG:15)
Block(1,7,0,LOG:15)
Block(-3,10,-5,LEAVES:3)
Block(1,16,-3,LEAVES:3)
Block(3,20,-1,LEAVES:3)
Block(3,21,-1,LEAVES:3)
Block(3,22,-1,LEAVES:3)
Block(1,9,-8,LEAVES:3)
Block(-5,9,-6,LEAVES:3)
Block(3,23,-1,LEAVES:3)
Block(-1,10,-7,LEAVES:3)
Block(1,15,-3,LEAVES:3)
Block(0,22,6,LEAVES:3)
Block(1,-3,0,LOG:15)
Block(1,-2,0,LOG:15)
Block(1,-1,0,LOG:15)
Block(-1,20,4,LEAVES:3)
Block(-3,22,-5,LEAVES:3)
Block(-1,21,4,LEAVES:3)
Block(-3,20,-5,LEAVES:3)
Block(-3,21,-5,LEAVES:3)
Block(-2,21,7,LEAVES:3)
Block(-1,13,4,LEAVES:3)
Block(-4,13,8,LEAVES:3)
Block(6,11,3,LEAVES:3)
Block(6,10,3,VINE:4)
Block(4,22,2,LEAVES:3)
Block(4,21,2,LEAVES:3)
Block(4,20,2,LEAVES:3)
Block(4,8,-2,VINE:1)
Block(6,13,3,LEAVES:3)
Block(0,22,-3,LEAVES:3)
Block(6,12,3,LEAVES:3)
Block(0,20,-3,LEAVES:3)
Block(-1,22,4,LEAVES:3)
Block(0,21,-3,LEAVES:3)
Block(-1,23,4,LEAVES:3)
Block(-4,10,-5,LEAVES:3)
Block(4,17,2,LEAVES:3)
Block(4,11,2,LEAVES:3)
Block(2,15,-3,LEAVES:3)
Block(1,20,-3,LEAVES:3)
Block(1,21,-3,LOG:15)
Block(1,22,-3,LEAVES:3)
Block(-8,12,4,LEAVES:3)
Block(-8,13,4,LEAVES:3)
Block(1,6,0,LOG:15)
Block(1,5,0,LOG:15)
Block(0,6,2,LEAVES:3)
Block(1,4,0,LOG:15)
Block(-3,8,-5,LEAVES:3)
Block(1,3,0,LOG:15)
Block(-3,9,-5,LEAVES:3)
Block(1,2,0,LOG:15)
Block(-6,13,3,LEAVES:3)
Block(1,1,0,LOG:15)
Block(-6,14,3,LEAVES:3)
Block(1,0,0,LOG:15)
Block(-4,22,-5,LEAVES:3)
Block(-6,12,3,LEAVES:3)
Block(1,9,2,VINE:4)
Block(-4,13,6,LEAVES:3)
Block(1,8,2,VINE:4)
Block(1,7,2,LEAVES:3)
Block(-4,12,6,LEAVES:3)
Block(2,23,5,LEAVES:3)
Block(1,6,2,LOG:15)
Block(2,22,5,LEAVES:3)
Block(1,5,2,LEAVES:3)
Block(-4,14,6,LEAVES:3)
Block(2,21,5,LEAVES:3)
Block(1,8,-6,LEAVES:3)
Block(1,9,-6,LEAVES:3)
Block(-5,9,-4,LEAVES:3)
Block(2,7,0,LOG:15)
Block(2,6,0,LOG:15)
Block(2,9,0,LOG:15)
Block(2,8,0,LOG:15)
Block(-1,21,2,LEAVES:3)
Block(6,10,1,VINE:1)
Block(6,11,1,LEAVES:3)
Block(-1,20,2,LOG:7)
Block(6,12,1,LEAVES:3)
Block(-1,23,2,LEAVES:3)
Block(-1,22,2,LEAVES:3)
Block(1,19,0,LOG:15)
Block(5,11,-1,LEAVES:3)
Block(1,18,0,LOG:15)
Block(1,17,0,LOG:15)
Block(1,16,0,LOG:15)
Block(0,18,-3,LOG:15)
Block(1,15,0,LOG:15)
Block(4,20,-1,LEAVES:3)
Block(1,14,0,LOG:15)
Block(4,21,-1,LEAVES:3)
Block(1,13,0,LOG:15)
Block(1,12,0,LOG:15)
Block(1,11,0,LOG:15)
Block(1,10,0,LOG:15)
Block(5,19,-1,LOG:7)
Block(-5,23,0,LEAVES:3)
Block(2,19,-1,LOG:7)
Block(-5,22,0,LEAVES:3)
Block(2,14,-1,LEAVES:3)
Block(-2,11,-7,LEAVES:3)
Block(2,16,-1,LEAVES:3)
Block(-2,10,-7,LEAVES:3)
Block(2,15,-1,LEAVES:3)
Block(1,23,-1,LEAVES:3)
Block(1,22,-1,LOG:15)
Block(4,22,-1,LEAVES:3)
Block(1,21,-1,LOG:15)
Block(4,23,-1,LEAVES:3)
Block(0,15,-3,LEAVES:3)
Block(1,20,-1,LOG:15)
Block(-3,10,-7,LEAVES:3)
Block(-3,13,1,LEAVES:3)
Block(1,23,0,LEAVES:3)
Block(1,22,0,LOG:15)
Block(-5,13,0,LEAVES:3)
Block(1,21,0,LOG:15)
Block(1,20,0,LOG:15)
Block(6,9,-3,LOG:15)
Block(2,21,-1,LEAVES:3)
Block(2,20,-1,LEAVES:3)
Block(2,23,-1,LEAVES:3)
Block(2,22,-1,LEAVES:3)
Block(-5,21,0,LEAVES:3)
Block(-3,23,1,LEAVES:3)
Block(-3,21,1,LEAVES:3)
Block(-4,21,6,LEAVES:3)
Block(-3,22,1,LEAVES:3)
Block(6,20,1,LEAVES:3)
Block(2,3,0,LOG:15)
Block(2,2,0,LOG:15)
Block(2,5,0,LOG:15)
Block(2,4,0,LOG:15)
Block(2,1,0,LOG:15)
Block(2,0,0,LOG:15)
Block(3,16,-1,LEAVES:3)
Block(3,15,-1,LEAVES:3)
Block(6,21,1,LOG:15)
Block(-3,9,-3,LEAVES:3)
Block(6,22,1,LEAVES:3)
Block(5,11,2,LEAVES:3)
Block(5,12,2,LEAVES:3)
Block(1,20,1,LOG:15)
Block(1,21,1,LOG:15)
Block(1,22,1,LOG:15)
Block(1,23,1,LEAVES:3)
Block(-3,10,2,LOG:7)
Block(-3,14,2,LEAVES:3)
Block(-3,13,2,LEAVES:3)
Block(-4,21,4,LEAVES:3)
Block(-3,10,-8,LEAVES:3)
Block(-7,14,3,LEAVES:3)
Block(-7,12,3,LEAVES:3)
Block(-7,13,3,LEAVES:3)
Block(0,10,-7,LEAVES:3)
Block(1,10,1,LOG:15)
Block(1,11,1,LOG:15)
Block(1,12,1,LOG:15)
Block(-3,9,-2,LEAVES:3)
Block(1,13,1,LOG:15)
Block(-4,14,4,LEAVES:3)
Block(9,21,-3,LEAVES:3)
Block(1,14,1,LOG:15)
Block(-4,15,4,LEAVES:3)
Block(9,22,-3,LEAVES:3)
Block(1,15,1,LOG:15)
Block(1,16,1,LOG:15)
Block(1,17,1,LOG:15)
Block(-3,21,2,LEAVES:3)
Block(1,18,1,LOG:15)
Block(-3,20,2,LEAVES:3)
Block(1,19,1,LOG:15)
Block(2,23,3,LEAVES:3)
Block(-3,22,2,LEAVES:3)
Block(2,21,3,LEAVES:3)
Block(2,22,3,LEAVES:3)
Block(-6,9,-5,LEAVES:3)
Block(-1,10,-9,LEAVES:3)
Block(2,20,3,LEAVES:3)
Block(-2,10,-4,LEAVES:3)
Block(7,12,-6,LEAVES:3)
Block(7,11,-6,LEAVES:3)
Block(-2,8,-8,LEAVES:3)
Block(7,10,-6,LEAVES:3)
Block(-2,9,-8,LEAVES:3)
Block(9,11,-3,LEAVES:3)
Block(0,9,-9,LEAVES:3)
Block(8,12,1,LEAVES:3)
Block(1,-1,-2,LOG:15)
Block(1,-2,-2,LOG:15)
Block(1,-3,-2,LOG:15)
Block(7,21,-6,LEAVES:3)
Block(-5,10,-5,LEAVES:3)
Block(10,21,-4,LEAVES:3)
Block(8,11,1,LEAVES:3)
Block(-6,13,1,LEAVES:3)
Block(-1,21,5,LEAVES:3)
Block(-1,22,5,LEAVES:3)
Block(6,23,-2,LEAVES:3)
Block(6,22,-2,LEAVES:3)
Block(-1,20,5,LEAVES:3)
Block(6,21,-2,LEAVES:3)
Block(4,22,0,LOG:15)
Block(4,23,0,LEAVES:3)
Block(4,20,0,LEAVES:3)
Block(4,21,0,LEAVES:3)
Block(0,-1,1,LOG:15)
Block(10,11,-4,LEAVES:3)
Block(0,21,-5,VINE:2)
Block(0,20,-5,LEAVES:3)
Block(0,-3,1,LOG:15)
Block(0,-2,1,LOG:15)
Block(-7,22,-2,LEAVES:3)
Block(6,20,-2,LOG:15)
Block(-1,13,5,LEAVES:3)
Block(8,21,1,LEAVES:3)
Block(-6,22,1,LEAVES:3)
Block(5,22,0,LEAVES:3)
Block(5,21,0,LEAVES:3)
Block(4,19,0,LOG:7)
Block(5,20,0,LEAVES:3)
Block(6,11,-2,LEAVES:3)
Block(-2,20,-4,LEAVES:3)
Block(-2,21,-4,LEAVES:3)
Block(-2,23,0,LEAVES:3)
Block(4,11,0,LEAVES:3)
Block(-2,22,-4,LEAVES:3)
Block(-2,20,0,LOG:7)
Block(-2,22,0,LEAVES:3)
Block(2,17,3,LEAVES:3)
Block(-2,21,0,LEAVES:3)
Block(2,1,-1,LOG:15)
Block(2,0,-1,LOG:15)
Block(2,2,-1,LOG:15)
Block(8,11,-1,LEAVES:3)
Block(0,7,1,LEAVES:3)
Block(2,8,-1,LOG:7)
Block(0,9,1,LOG:7)
Block(5,11,0,LEAVES:3)
Block(-4,21,-3,LEAVES:3)
Block(-4,22,-3,LEAVES:3)
Block(-4,23,-3,LEAVES:3)
Block(-4,11,4,VINE:4)
Block(-4,12,4,LEAVES:3)
Block(-4,13,4,LEAVES:3)
Block(9,11,1,LEAVES:3)
Block(-2,8,-6,LOG:15)
Block(8,21,-1,LEAVES:3)
Block(-2,9,-6,LOG:15)
Block(1,9,-1,LOG:15)
Block(1,21,3,LEAVES:3)
Block(1,20,3,LOG:15)
Block(1,7,-1,LOG:15)
Block(1,23,3,LEAVES:3)
Block(1,8,-1,LOG:15)
Block(1,22,3,LEAVES:3)
Block(1,5,-1,LOG:15)
Block(-8,13,5,LEAVES:3)
Block(1,6,-1,LOG:15)
Block(-8,14,5,LEAVES:3)
Block(8,22,-1,LEAVES:3)
Block(1,3,-1,LOG:15)
Block(1,4,-1,LOG:15)
Block(1,1,-1,LOG:15)
Block(0,9,-7,LEAVES:3)
Block(1,2,-1,LOG:15)
Block(0,8,-7,LEAVES:3)
Block(-3,12,4,LEAVES:3)
Block(1,0,-1,LOG:15)
Block(-3,14,4,LEAVES:3)
Block(-3,13,4,LEAVES:3)
Block(6,11,4,LEAVES:3)
Block(-5,22,-3,LEAVES:3)
Block(4,23,-3,LEAVES:3)
Block(6,12,4,LEAVES:3)
Block(4,22,-3,LEAVES:3)
Block(-5,23,-3,LEAVES:3)
Block(4,21,-3,LOG:15)
Block(4,20,-3,LEAVES:3)
Block(-5,21,-3,LEAVES:3)
Block(2,23,-4,LEAVES:3)
Block(0,10,-5,LEAVES:3)
Block(2,22,-4,LOG:15)
Block(-5,13,8,LEAVES:3)
Block(2,21,-4,LEAVES:3)
Block(1,17,3,LEAVES:3)
Block(9,21,-1,LEAVES:3)
Block(-3,22,4,LEAVES:3)
Block(-3,21,4,LEAVES:3)
Block(-3,20,4,LEAVES:3)
Block(2,22,1,LEAVES:3)
Block(2,21,1,LEAVES:3)
Block(2,23,1,LEAVES:3)
Block(2,20,1,LEAVES:3)
Block(0,13,1,VINE:8)
Block(0,12,1,VINE:8)
Block(0,19,1,COCOA:11)
Block(0,17,1,LEAVES:3)
Block(-1,9,-8,LEAVES:3)
Block(0,16,1,LEAVES:3)
Block(0,11,1,VINE:12)
Block(0,10,1,LOG:7)
Block(4,22,-5,LEAVES:3)
Block(4,20,-5,LEAVES:3)
Block(4,21,-5,LEAVES:3)
Block(-6,22,-2,LEAVES:3)
Block(-6,23,-2,LEAVES:3)
Block(-6,21,-2,LEAVES:3)
Block(-1,-1,0,LOG:15)
Block(-1,-2,0,LOG:15)
Block(-1,-3,0,LOG:15)
Block(5,20,4,VINE:0)
Block(5,21,4,LEAVES:3)
Block(5,10,-5,LEAVES:3)
Block(8,11,3,LEAVES:3)
Block(5,11,-5,LEAVES:3)
Block(4,11,-5,LEAVES:3)
Block(5,12,4,LEAVES:3)
Block(-5,15,4,LEAVES:3)
Block(6,20,-4,VINE:2)
Block(-2,8,-4,LEAVES:3)
Block(6,21,-4,LEAVES:3)
Block(-5,21,4,LEAVES:3)
Block(-2,9,-4,LEAVES:3)
Block(6,22,-4,LEAVES:3)
Block(0,9,-5,LEAVES:3)
Block(0,8,-5,LEAVES:3)
Block(5,11,4,LEAVES:3)
Block(2,11,1,VINE:2)
Block(2,10,1,VINE:2)
Block(2,13,1,VINE:2)
Block(2,12,1,VINE:2)
Block(6,12,-4,LEAVES:3)
Block(2,19,1,LOG:15)
Block(-4,22,2,LEAVES:3)
Block(-1,9,-6,LEAVES:3)
Block(2,18,1,LEAVES:3)
Block(-4,21,2,LEAVES:3)
Block(-1,8,-6,LEAVES:3)
Block(-7,14,5,LEAVES:3)
Block(-7,13,5,LEAVES:3)
Block(2,15,1,VINE:2)
Block(-7,12,5,LEAVES:3)
Block(2,14,1,VINE:2)
Block(2,17,1,LEAVES:3)
Block(2,16,1,LEAVES:3)
Block(-5,12,4,LOG:15)
Block(-5,14,4,LEAVES:3)
Block(-5,13,4,LOG:15)
Block(8,10,-3,LEAVES:3)
Block(-4,14,2,LEAVES:3)
Block(6,10,-4,LEAVES:3)
Block(8,11,-3,LEAVES:3)
Block(-4,13,2,LEAVES:3)
Block(6,11,-4,LEAVES:3)
Block(8,12,-3,LEAVES:3)
Block(-4,12,2,LEAVES:3)
Block(9,21,-5,LEAVES:3)
Block(3,22,5,LEAVES:3)
Block(3,8,-1,LOG:7)
Block(2,21,-6,LEAVES:3)
Block(7,12,1,LEAVES:3)
Block(7,13,-4,LEAVES:3)
Block(7,11,1,LEAVES:3)
Block(7,11,-4,LOG:15)
Block(7,12,-4,LEAVES:3)
Block(7,13,1,LEAVES:3)
Block(1,22,5,LOG:15)
Block(7,10,-4,LOG:15)
Block(1,23,5,LEAVES:3)
Block(3,17,3,LEAVES:3)
Block(1,21,5,LEAVES:3)
Block(-4,23,0,LEAVES:3)
Block(8,21,-3,LEAVES:3)
Block(-4,21,0,LEAVES:3)
Block(8,22,-3,LEAVES:3)
Block(-4,22,0,LEAVES:3)
Block(3,11,3,LEAVES:3)
Block(9,12,-5,LEAVES:3)
Block(-3,12,6,LEAVES:3)
Block(9,11,-5,LEAVES:3)
Block(-3,13,6,LEAVES:3)
Block(9,10,-5,LEAVES:3)
Block(-3,14,6,LEAVES:3)
Block(-5,23,-1,LEAVES:3)
Block(-5,22,-1,LEAVES:3)
Block(-5,21,-1,LEAVES:3)
Block(7,22,-4,LEAVES:3)
Block(-5,15,6,LEAVES:3)
Block(7,21,-4,LEAVES:3)
Block(-5,13,6,LEAVES:3)
Block(7,21,1,LEAVES:3)
Block(-5,14,6,LEAVES:3)
Block(-5,12,6,LEAVES:3)
Block(-4,13,0,LEAVES:3)
Block(-3,22,6,LEAVES:3)
Block(3,22,3,LEAVES:3)
Block(3,21,3,LEAVES:3)
Block(3,20,3,LEAVES:3)
Block(2,9,-5,LEAVES:3)
Block(-3,21,6,LEAVES:3)
Block(0,9,-3,LEAVES:3)
Block(-2,13,2,LEAVES:3)
Block(-1,15,-2,LEAVES:3)
Block(-1,20,-2,LEAVES:3)
Block(-2,20,2,LEAVES:3)
Block(-2,9,-2,LEAVES:3)
Block(-1,21,-2,LEAVES:3)
Block(-2,23,-2,LEAVES:3)
Block(-2,22,-2,LEAVES:3)
Block(-1,22,-2,LOG:15)
Block(-3,20,-1,LOG:7)
Block(-3,21,-1,LEAVES:3)
Block(-3,22,-1,LEAVES:3)
Block(-3,23,-1,LEAVES:3)
Block(5,21,-5,LEAVES:3)
Block(5,22,-5,LEAVES:3)
Block(5,21,2,LEAVES:3)
Block(5,22,2,LEAVES:3)
Block(-1,8,-8,LEAVES:3)
Block(2,-1,1,LOG:15)
Block(-4,9,-4,LEAVES:3)
Block(-2,21,-2,LEAVES:3)
Block(3,22,-6,LEAVES:3)
Block(-1,23,-2,LEAVES:3)
Block(-2,23,2,LEAVES:3)
Block(-2,20,-2,LEAVES:3)
Block(2,-3,1,LOG:15)
Block(-2,21,2,LEAVES:3)
Block(2,-2,1,LOG:15)
Block(3,21,-6,LEAVES:3)
Block(-2,22,2,LEAVES:3)
Block(0,23,1,LEAVES:3)
Block(5,8,-2,LOG:7)
Block(5,20,2,LEAVES:3)
Block(-4,23,-1,LEAVES:3)
Block(-4,22,-1,LEAVES:3)
Block(0,22,1,LEAVES:3)
Block(-4,21,-1,LOG:15)
Block(0,21,1,LEAVES:3)
Block(-4,20,-1,LEAVES:3)
Block(0,20,1,LOG:15)
Block(-3,20,-2,LEAVES:3)
Block(-1,19,-4,LOG:15)
Block(-2,14,4,LEAVES:3)
Block(-2,13,4,LEAVES:3)
Block(-2,12,4,LEAVES:3)
Block(-2,22,4,LEAVES:3)
Block(-1,21,-4,LEAVES:3)
Block(-2,21,4,LEAVES:3)
Block(-2,20,4,LOG:15)
Block(-1,20,-4,LEAVES:3)
Block(-1,10,1,LOG:7)
Block(-3,21,7,LEAVES:3)
Block(5,23,-2,LEAVES:3)
Block(5,22,-2,LEAVES:3)
Block(3,23,-4,LEAVES:3)
Block(2,1,1,LOG:15)
Block(3,22,-4,LEAVES:3)
Block(8,10,-5,LEAVES:3)
Block(-1,9,-3,LEAVES:3)
Block(2,0,1,LOG:15)
Block(-1,7,-3,LOG:15)
Block(3,21,-4,LEAVES:3)
Block(3,20,-4,LEAVES:3)
Block(-2,23,4,LEAVES:3)
Block(1,21,6,LEAVES:3)
Block(3,17,2,LEAVES:3)
Block(1,22,6,LEAVES:3)
Block(8,12,-5,LEAVES:3)
Block(8,11,-5,LEAVES:3)
Block(8,13,-5,LEAVES:3)
Block(0,21,3,LEAVES:3)
Block(-3,22,-2,LEAVES:3)
Block(3,11,2,LEAVES:3)
Block(-1,20,1,LEAVES:3)
Block(-3,21,-2,LEAVES:3)
Block(0,22,3,LEAVES:3)
Block(-1,21,1,LOG:15)
Block(0,23,3,LEAVES:3)
Block(-1,22,1,LEAVES:3)
Block(-3,23,-2,LEAVES:3)
Block(-1,23,1,LEAVES:3)
Block(5,21,-2,LEAVES:3)
Block(5,20,-2,LEAVES:3)
Block(0,20,3,LEAVES:3)
Block(0,5,-1,VINE:8)
Block(0,7,-1,LOG:15)
Block(0,6,-1,LOG:15)
Block(8,21,-5,LEAVES:3)
Block(0,1,-1,LOG:15)
Block(0,0,-1,LOG:15)
Block(7,9,-3,VINE:2)
Block(6,11,-7,LEAVES:3)
Block(8,22,-5,LEAVES:3)
Block(-6,13,6,LEAVES:3)
Block(6,20,0,LEAVES:3)
Block(3,21,2,LEAVES:3)
Block(-6,12,6,LEAVES:3)
Block(6,21,0,LEAVES:3)
Block(3,22,2,LEAVES:3)
Block(6,22,0,LEAVES:3)
Block(3,20,2,LOG:15)
Block(3,23,2,LEAVES:3)
Block(-6,14,6,LEAVES:3)
Block(3,6,1,LEAVES:3)
Block(4,21,-7,LEAVES:3)
Block(3,8,1,LOG:7)
Block(-5,12,1,LEAVES:3)
Block(-5,13,1,LEAVES:3)
Block(-4,9,-6,LEAVES:3)
Block(-4,8,-6,LEAVES:3)
Block(-6,22,-4,LEAVES:3)
Block(-1,10,-4,LEAVES:3)
Block(-5,21,1,LEAVES:3)
Block(-5,22,1,LEAVES:3)
Block(6,11,0,LEAVES:3)
Block(6,12,0,LEAVES:3)
Block(1,21,-4,LEAVES:3)
Block(1,20,-4,LEAVES:3)
Block(1,22,-4,LEAVES:3)
Block(3,20,0,LEAVES:3)
Block(3,22,0,LEAVES:3)
Block(3,21,0,LOG:15)
Block(3,23,0,LEAVES:3)
Block(-7,13,7,LEAVES:3)
Block(-3,10,-4,LEAVES:3)
Block(-3,11,-4,LEAVES:3)
Block(-1,9,-5,LEAVES:3)
Block(-1,8,-5,LEAVES:3)
Block(-5,15,3,LEAVES:3)
Block(-5,14,3,LEAVES:3)
Block(-2,13,6,LEAVES:3)
Block(-1,10,-6,LEAVES:3)
Block(-1,11,-6,LEAVES:3)
Block(-3,9,-8,LEAVES:3)
Block(-3,21,-4,LEAVES:3)
Block(-3,22,-4,LEAVES:3)
Block(-3,20,-4,LEAVES:3)
Block(7,10,-2,LEAVES:3)
Block(7,12,-2,LEAVES:3)
Block(4,21,5,LEAVES:3)
Block(7,11,-2,LEAVES:3)
Block(7,11,3,LEAVES:3)
Block(-5,11,3,VINE:8)
Block(7,12,3,LEAVES:3)
Block(-5,13,3,LEAVES:3)
Block(-5,12,3,LEAVES:3)
Block(7,10,3,VINE:0)
Block(-9,13,4,LEAVES:3)
Block(-1,6,1,LEAVES:3)
Block(-4,9,-8,LEAVES:3)
Block(7,21,-2,LEAVES:3)
Block(7,20,-2,LEAVES:3)
Block(7,23,-2,LEAVES:3)
Block(7,22,-2,LEAVES:3)
Block(-3,23,-4,LEAVES:3)
Block(-8,22,-2,LEAVES:3)
Block(6,21,2,LEAVES:3)
Block(6,20,2,VINE:2)
Block(-2,11,-6,LEAVES:3)
Block(2,16,-2,LEAVES:3)
Block(-2,10,-6,LEAVES:3)
Block(6,9,-2,VINE:4)
Block(2,15,-2,LEAVES:3)
Block(-8,13,3,LEAVES:3)
Block(0,10,-4,LEAVES:3)
Block(-4,21,-4,LEAVES:3)
Block(-4,22,-4,LEAVES:3)
Block(-4,12,7,LEAVES:3)
Block(-6,14,2,LEAVES:3)
Block(6,10,2,LOG:15)
Block(-4,13,7,LEAVES:3)
Block(-4,14,7,LEAVES:3)
Block(4,23,1,LEAVES:3)
Block(-7,22,0,LEAVES:3)
Block(4,21,1,LEAVES:3)
Block(4,22,1,LEAVES:3)
Block(4,20,1,LEAVES:3)
Block(2,23,-2,LEAVES:3)
Block(2,21,-2,LEAVES:3)
Block(2,22,-2,LEAVES:3)
Block(0,20,-4,LOG:15)
Block(2,20,-2,LEAVES:3)
Block(6,12,2,LEAVES:3)
Block(6,11,2,LOG:15)
Block(0,21,-4,LEAVES:3)
Block(-3,8,-6,LEAVES:3)
Block(6,13,2,LEAVES:3)
Block(-3,9,-6,LEAVES:3)
Block(0,0,1,LOG:15)
Block(0,1,1,LOG:15)
Block(1,9,1,LOG:15)
Block(1,8,1,LOG:15)
Block(0,6,1,LEAVES:3)
Block(1,7,1,LOG:15)
Block(0,5,1,LEAVES:3)
Block(1,6,1,LOG:15)
Block(1,9,-7,LEAVES:3)
Block(-5,9,-7,LEAVES:3)
Block(-2,22,6,LEAVES:3)
Block(-2,21,6,LEAVES:3)
Block(-2,20,6,LEAVES:3)
Block(-1,21,-6,VINE:1)
Block(3,15,-2,LEAVES:3)
Block(-1,20,-6,VINE:1)
Block(2,23,6,LEAVES:3)
Block(-3,10,-6,LEAVES:3)
Block(2,22,6,LEAVES:3)
Block(3,20,-2,LOG:15)
Block(3,21,-2,LEAVES:3)
Block(3,22,-2,LEAVES:3)
Block(3,23,-2,LEAVES:3)
Block(-2,21,-6,LEAVES:3)
Block(-2,20,-6,LEAVES:3)
Block(3,17,0,LEAVES:3)
Block(3,16,0,LEAVES:3)
Block(3,19,0,LOG:7)
Block(0,22,5,LEAVES:3)
Block(0,21,5,LEAVES:3)
Block(-3,22,0,LEAVES:3)
Block(-3,23,0,LEAVES:3)
Block(-3,20,0,LEAVES:3)
Block(-3,21,0,LEAVES:3)
Block(6,9,-4,VINE:1)
Block(4,12,3,LEAVES:3)
Block(4,11,3,LEAVES:3)
Block(4,8,-1,LOG:7)
Block(-6,14,4,LEAVES:3)
Block(-6,12,4,LEAVES:3)
Block(-6,13,4,LEAVES:3)
Block(-2,9,-9,LEAVES:3)
Block(1,5,1,LOG:15)
Block(1,4,1,LOG:15)
Block(-3,8,-4,LEAVES:3)
Block(1,-1,1,LOG:15)
Block(1,3,1,LOG:15)
Block(-3,9,-4,LEAVES:3)
Block(1,-2,1,LOG:15)
Block(1,2,1,LOG:15)
Block(1,-3,1,LOG:15)
Block(1,1,1,LOG:15)
Block(-4,10,-6,LEAVES:3)
Block(1,0,1,LOG:15)
Block(0,16,-2,LEAVES:3)
Block(1,6,3,LEAVES:3)
Block(-1,20,3,LEAVES:3)
Block(-2,10,-8,LEAVES:3)
Block(1,9,-5,LEAVES:3)
Block(2,9,1,VINE:2)
Block(-5,8,-5,LEAVES:3)
Block(1,20,-2,LOG:15)
Block(-5,9,-5,LEAVES:3)
Block(1,21,-2,LEAVES:3)
Block(2,6,1,LEAVES:3)
Block(1,22,-2,LEAVES:3)
Block(2,5,1,LEAVES:3)
Block(1,23,-2,LEAVES:3)
Block(2,8,1,LOG:7)
Block(2,7,1,LEAVES:3)
Block(-1,13,3,LEAVES:3)
Block(-1,9,-10,LEAVES:3)
Block(0,15,-2,LEAVES:3)
Block(-2,9,-10,LEAVES:3)
Block(1,15,-2,LOG:15)
Block(1,16,-2,LEAVES:3)
Block(1,18,-2,LOG:15)
Block(4,22,3,LEAVES:3)
Block(4,21,3,LOG:15)
Block(3,-1,0,LOG:15)
Block(4,20,3,LEAVES:3)
Block(3,-3,0,LOG:15)
Block(3,-2,0,LOG:15)
Block(-1,10,-8,LEAVES:3)
Block(1,14,-2,LEAVES:3)
Block(0,20,-2,LEAVES:3)
Block(-1,22,3,LOG:15)
Block(-1,21,3,LEAVES:3)
Block(0,22,-2,LEAVES:3)
Block(0,21,-2,LEAVES:3)
Block(-1,23,3,LEAVES:3)

#######################################################################
# +-----------------------------------------------------------------+ #
# |                            BO3 checks                           | #
# +-----------------------------------------------------------------+ #
#######################################################################

BlockCheck(0,-1,0,GRASS:0,DIRT:0,DIRT:2,HARD_CLAY,STAINED_CLAY:0,CLAY,SANDSTONE:0,SAND:1,SAND:0)

#######################################################################
# +-----------------------------------------------------------------+ #
# |                             Branches                            | #
# +-----------------------------------------------------------------+ #
#######################################################################


#######################################################################
# +-----------------------------------------------------------------+ #
# |                             Entities                            | #
# +-----------------------------------------------------------------+ #
#######################################################################


#######################################################################
# +-----------------------------------------------------------------+ #
# |                            Particles                            | #
# +-----------------------------------------------------------------+ #
#######################################################################


#######################################################################
# +-----------------------------------------------------------------+ #
# |                             Spawners                            | #
# +-----------------------------------------------------------------+ #
#######################################################################


#######################################################################
# +-----------------------------------------------------------------+ #
# |                             ModData                             | #
# +-----------------------------------------------------------------+ #
#######################################################################

