
#######################################################################
# +-----------------------------------------------------------------+ #
# |                            BO3 object                           | #
# +-----------------------------------------------------------------+ #
#######################################################################

Author: LordSmellyPants

Description: Converted version of the BO2 JungleRainforest1

Version: 3

SettingsMode: WriteWithoutComments


#######################################################################
# +-----------------------------------------------------------------+ #
# |                          Main settings                          | #
# +-----------------------------------------------------------------+ #
#######################################################################

Tree: true

Frequency: 1

Rarity: 20.0

RotateRandomly: true

SpawnHeight: highestSolidBlock

SpawnHeightOffset: 0

SpawnHeightVariance: 0

##############################
# Height Limits for the BO3. #
##############################

MinHeight: 63

MaxHeight: 70

######################
# Extrusion settings #
######################

ExtrudeMode: None

ExtrudeThroughBlocks: AIR

MaxBranchDepth: 10

ExcludedBiomes: All


#######################################################################
# +-----------------------------------------------------------------+ #
# |                      Source block settings                      | #
# +-----------------------------------------------------------------+ #
#######################################################################

SourceBlocks: STONE:1,STONE:3,STONE:5,DIRT:1,DIRT:0,SAND:0,GRASS:0,DIRT:2,STATIONARY_WATER:0,HARD_CLAY,STAINED_CLAY:0,CLAY,SANDSTONE:0,SAND:1,AIR,STONE:0,GRAVEL,LONG_GRASS:0,LONG_GRASS:1,LONG_GRASS:2,DEAD_BUSH,YELLOW_FLOWER:0,RED_ROSE:0,BROWN_MUSHROOM,RED_MUSHROOM

MaxPercentageOutsideSourceBlock: 0

OutsideSourceBlock: placeAnyway

DoReplaceBlocks: true

IsOTGPlus: false


#######################################################################
# +-----------------------------------------------------------------+ #
# |                              Blocks                             | #
# +-----------------------------------------------------------------+ #
#######################################################################

Block(8,12,0,LOG:15)
Block(8,11,0,LOG:15)
Block(14,25,-1,LEAVES:3)
Block(8,14,0,LOG:15)
Block(8,13,0,LOG:15)
Block(14,23,-1,LEAVES:3)
Block(6,9,1,LOG:15)
Block(8,15,0,LOG:15)
Block(6,8,1,LOG:15)
Block(7,25,-5,LEAVES:3)
Block(-7,31,2,LEAVES:3)
Block(-7,30,2,LEAVES:3)
Block(-9,31,8,LEAVES:3)
Block(10,23,-5,LEAVES:3)
Block(-7,28,2,LEAVES:3)
Block(-7,29,2,LEAVES:3)
Block(10,25,-5,LEAVES:3)
Block(-7,27,2,LEAVES:3)
Block(-5,30,7,LEAVES:3)
Block(10,22,-5,LEAVES:3)
Block(8,10,0,LOG:15)
Block(8,23,0,LEAVES:3)
Block(8,22,0,LEAVES:3)
Block(8,25,0,LEAVES:3)
Block(-13,30,6,LEAVES:3)
Block(-10,25,9,LEAVES:3)
Block(-8,17,6,LOG:15)
Block(-5,27,7,LEAVES:3)
Block(-8,16,6,LOG:15)
Block(-5,28,7,LEAVES:3)
Block(-8,19,6,LOG:15)
Block(-8,18,6,LOG:15)
Block(-5,26,7,LEAVES:3)
Block(-5,24,7,LEAVES:3)
Block(-8,15,6,LOG:15)
Block(14,18,1,LEAVES:3)
Block(11,25,2,LEAVES:3)
Block(-1,-1,8,LOG:15)
Block(14,19,1,LEAVES:3)
Block(8,21,0,LEAVES:3)
Block(-10,30,9,LEAVES:3)
Block(-4,25,5,LEAVES:3)
Block(-8,28,6,LOG:15)
Block(-8,27,6,LOG:15)
Block(-8,29,6,LEAVES:3)
Block(15,25,-5,LEAVES:3)
Block(15,24,-5,LEAVES:3)
Block(17,24,-4,LEAVES:3)
Block(17,23,-4,LEAVES:3)
Block(9,25,2,LEAVES:3)
Block(-8,20,6,LOG:15)
Block(-1,0,7,LOG:15)
Block(5,10,1,LOG:15)
Block(-4,10,5,LOG:15)
Block(-1,2,7,LOG:15)
Block(-1,1,7,LOG:15)
Block(-4,11,5,LOG:15)
Block(-1,4,7,LOG:15)
Block(-1,3,7,LOG:15)
Block(-2,6,5,LOG:15)
Block(-2,5,5,LOG:15)
Block(17,22,-4,LEAVES:3)
Block(-2,4,5,LOG:15)
Block(-1,5,7,LOG:15)
Block(-2,3,5,LOG:15)
Block(-2,2,5,LOG:15)
Block(-2,1,5,LOG:15)
Block(-2,0,5,LOG:15)
Block(-9,28,8,LEAVES:3)
Block(-8,31,6,LEAVES:3)
Block(-9,29,8,LEAVES:3)
Block(-8,30,6,LEAVES:3)
Block(-8,32,6,LEAVES:3)
Block(12,23,4,LEAVES:3)
Block(12,22,4,LEAVES:3)
Block(13,24,-6,LEAVES:3)
Block(-8,18,4,LOG:15)
Block(-8,19,4,LOG:15)
Block(-8,25,4,LOG:15)
Block(9,26,-2,LEAVES:3)
Block(-8,26,4,LOG:15)
Block(-8,27,4,LOG:15)
Block(-8,28,4,LOG:15)
Block(-8,21,4,LOG:15)
Block(-8,22,4,LOG:15)
Block(-8,23,4,LOG:15)
Block(-8,24,4,LOG:15)
Block(-8,20,4,LOG:15)
Block(9,23,-2,LEAVES:3)
Block(9,25,-2,LEAVES:3)
Block(9,24,-2,LEAVES:3)
Block(-8,28,12,LEAVES:3)
Block(-8,29,12,LEAVES:3)
Block(-3,29,3,LEAVES:3)
Block(-8,29,4,LOG:15)
Block(-8,30,4,LEAVES:3)
Block(-8,31,4,LEAVES:3)
Block(-8,27,12,LEAVES:3)
Block(-3,30,3,LEAVES:3)
Block(-3,-2,5,LOG:15)
Block(-12,31,4,LEAVES:3)
Block(10,24,-3,LEAVES:3)
Block(7,23,-7,LEAVES:3)
Block(10,23,-3,LEAVES:3)
Block(10,26,0,LEAVES:3)
Block(14,20,1,LEAVES:3)
Block(7,22,-7,LEAVES:3)
Block(10,22,-3,LOG:15)
Block(14,21,1,LEAVES:3)
Block(-3,6,5,LOG:15)
Block(14,22,1,LEAVES:3)
Block(-3,5,5,LOG:15)
Block(-3,8,5,LOG:15)
Block(10,23,0,LEAVES:3)
Block(10,26,-3,LEAVES:3)
Block(-3,7,5,LOG:15)
Block(10,24,0,LEAVES:3)
Block(10,25,-3,LEAVES:3)
Block(12,26,-2,LEAVES:3)
Block(-3,2,5,LOG:15)
Block(-4,-1,5,LOG:15)
Block(-3,1,5,LOG:15)
Block(-3,4,5,LOG:15)
Block(-3,3,5,LOG:15)
Block(-3,0,5,LOG:15)
Block(-2,-2,10,LOG:15)
Block(8,24,2,LEAVES:3)
Block(-4,30,3,LEAVES:3)
Block(-1,0,9,LOG:15)
Block(-4,31,3,LEAVES:3)
Block(-2,6,7,LOG:15)
Block(-2,-3,10,LOG:15)
Block(-2,5,7,LOG:15)
Block(-1,1,9,LOG:15)
Block(-2,4,7,LOG:15)
Block(-2,3,7,LOG:15)
Block(12,25,-2,LEAVES:3)
Block(-2,2,7,LOG:15)
Block(12,24,-2,LEAVES:3)
Block(-2,1,7,LOG:15)
Block(12,23,-2,LEAVES:3)
Block(12,22,-2,LOG:15)
Block(10,15,0,LOG:15)
Block(10,16,0,LOG:15)
Block(10,17,0,LOG:15)
Block(11,24,4,LEAVES:3)
Block(11,23,4,LEAVES:3)
Block(14,22,-1,LEAVES:3)
Block(14,21,-1,LEAVES:3)
Block(-2,29,1,LEAVES:3)
Block(-2,28,1,LEAVES:3)
Block(12,18,-6,LEAVES:3)
Block(-2,27,1,LEAVES:3)
Block(-2,26,1,LEAVES:3)
Block(-12,30,6,LEAVES:3)
Block(11,19,-7,LEAVES:3)
Block(-8,29,8,LEAVES:3)
Block(-5,12,5,LOG:15)
Block(-5,13,5,LOG:15)
Block(-5,10,5,LOG:15)
Block(9,25,0,LEAVES:3)
Block(-5,11,5,LOG:15)
Block(9,23,0,LEAVES:3)
Block(-8,28,8,LEAVES:3)
Block(9,24,0,LEAVES:3)
Block(10,25,2,LEAVES:3)
Block(9,25,-6,LEAVES:3)
Block(9,24,-6,LEAVES:3)
Block(-4,-2,3,LOG:15)
Block(7,19,0,LEAVES:3)
Block(-12,27,6,LEAVES:3)
Block(7,18,0,LEAVES:3)
Block(-12,26,6,LEAVES:3)
Block(11,20,-7,LEAVES:3)
Block(7,17,0,LEAVES:3)
Block(-12,25,6,LEAVES:3)
Block(-4,30,1,LEAVES:3)
Block(7,11,0,LOG:15)
Block(7,10,0,LOG:15)
Block(7,13,0,LOG:15)
Block(7,12,0,LOG:15)
Block(-11,23,4,LEAVES:3)
Block(-4,29,1,LEAVES:3)
Block(16,23,-2,LEAVES:3)
Block(-11,24,4,LEAVES:3)
Block(16,24,-2,LEAVES:3)
Block(-11,25,4,LEAVES:3)
Block(8,25,-2,LEAVES:3)
Block(-11,28,4,LEAVES:3)
Block(-6,31,7,LEAVES:3)
Block(8,24,-2,LEAVES:3)
Block(-11,29,4,LEAVES:3)
Block(8,23,-2,LEAVES:3)
Block(-8,32,8,LEAVES:3)
Block(-8,31,8,LEAVES:3)
Block(-11,22,4,LEAVES:3)
Block(-4,7,5,LOG:15)
Block(12,24,2,LEAVES:3)
Block(-7,30,4,LEAVES:3)
Block(-4,6,5,LOG:15)
Block(-4,5,5,LOG:15)
Block(-4,4,5,LOG:15)
Block(12,21,2,LEAVES:3)
Block(-4,9,5,LOG:15)
Block(-4,8,5,LOG:15)
Block(7,25,-3,LEAVES:3)
Block(-4,3,5,LOG:15)
Block(7,22,-3,LEAVES:3)
Block(-4,2,5,LOG:15)
Block(7,21,-3,LEAVES:3)
Block(-4,1,5,LOG:15)
Block(-7,32,4,LEAVES:3)
Block(12,25,2,LEAVES:3)
Block(-7,31,4,LEAVES:3)
Block(-3,7,7,LOG:15)
Block(-3,4,7,LOG:15)
Block(-3,3,7,LOG:15)
Block(-3,6,7,LOG:15)
Block(-3,5,7,LOG:15)
Block(-7,28,4,LOG:15)
Block(-3,0,7,LOG:15)
Block(-3,2,7,LOG:15)
Block(-3,1,7,LOG:15)
Block(12,22,-6,LEAVES:3)
Block(3,6,5,LOG:15)
Block(-10,29,7,LEAVES:3)
Block(12,21,-6,LEAVES:3)
Block(12,20,-6,LEAVES:3)
Block(9,16,0,LOG:15)
Block(4,6,3,LOG:15)
Block(9,14,0,LOG:15)
Block(9,15,0,LOG:15)
Block(4,8,3,LOG:15)
Block(9,12,0,LOG:15)
Block(4,7,3,LOG:15)
Block(9,13,0,LOG:15)
Block(5,9,1,LOG:15)
Block(14,24,-5,LEAVES:3)
Block(5,8,1,LOG:15)
Block(4,9,3,LOG:15)
Block(12,19,-6,LEAVES:3)
Block(14,25,-5,LEAVES:3)
Block(5,23,-4,LEAVES:3)
Block(-3,30,5,LEAVES:3)
Block(5,22,-4,LEAVES:3)
Block(-10,30,7,LEAVES:3)
Block(-10,31,7,LEAVES:3)
Block(-7,16,4,LOG:15)
Block(-7,15,4,LOG:15)
Block(-7,14,4,LOG:15)
Block(-7,13,4,LOG:15)
Block(-7,12,4,LOG:15)
Block(-11,31,2,LEAVES:3)
Block(-11,30,2,LEAVES:3)
Block(7,9,1,LOG:15)
Block(17,23,-2,LEAVES:3)
Block(-9,28,1,LEAVES:3)
Block(-9,27,1,LEAVES:3)
Block(-9,26,1,LEAVES:3)
Block(-9,25,1,LEAVES:3)
Block(-9,24,1,LEAVES:3)
Block(-9,23,1,LEAVES:3)
Block(-7,21,4,LOG:15)
Block(-7,20,4,LOG:15)
Block(-5,6,5,LOG:15)
Block(-5,5,5,LOG:15)
Block(-5,8,5,LOG:15)
Block(-5,7,5,LOG:15)
Block(-7,19,4,LOG:15)
Block(-7,18,4,LOG:15)
Block(-5,9,5,LOG:15)
Block(-7,17,4,LOG:15)
Block(5,21,-6,LEAVES:3)
Block(14,23,-3,LEAVES:3)
Block(-5,0,5,LOG:15)
Block(5,22,-6,LEAVES:3)
Block(8,23,4,LEAVES:3)
Block(8,22,4,LEAVES:3)
Block(5,23,-6,LEAVES:3)
Block(-4,5,7,LOG:15)
Block(13,26,-4,LEAVES:3)
Block(-4,4,7,LOG:15)
Block(13,25,-4,LEAVES:3)
Block(-4,3,7,LOG:15)
Block(-4,2,7,LOG:15)
Block(13,23,-4,LEAVES:3)
Block(-4,9,7,LOG:15)
Block(13,22,-4,LEAVES:3)
Block(14,25,-3,LEAVES:3)
Block(-4,8,7,LOG:15)
Block(14,26,-3,LEAVES:3)
Block(-4,7,7,LOG:15)
Block(4,21,-6,LEAVES:3)
Block(-4,6,7,LOG:15)
Block(7,22,0,LEAVES:3)
Block(-5,29,5,LEAVES:3)
Block(7,21,0,LEAVES:3)
Block(-5,28,5,LEAVES:3)
Block(7,20,0,LEAVES:3)
Block(-5,31,5,LEAVES:3)
Block(9,23,-4,LEAVES:3)
Block(13,19,-4,LEAVES:3)
Block(9,26,-4,LEAVES:3)
Block(13,18,-4,LEAVES:3)
Block(13,17,-4,LEAVES:3)
Block(9,24,-4,LEAVES:3)
Block(6,24,-5,LEAVES:3)
Block(11,25,-5,LEAVES:3)
Block(11,24,-5,LEAVES:3)
Block(6,25,-5,LEAVES:3)
Block(11,23,-5,LEAVES:3)
Block(15,25,-3,LEAVES:3)
Block(8,25,-4,LEAVES:3)
Block(8,26,-4,LEAVES:3)
Block(5,9,3,LOG:15)
Block(8,23,-4,LEAVES:3)
Block(5,8,3,LOG:15)
Block(-6,30,9,LEAVES:3)
Block(5,7,3,LOG:15)
Block(-11,27,2,LEAVES:3)
Block(12,21,0,LEAVES:3)
Block(12,22,0,LEAVES:3)
Block(-6,17,5,LOG:15)
Block(1,7,4,LOG:15)
Block(12,20,0,LEAVES:3)
Block(1,6,4,LOG:15)
Block(1,5,4,LOG:15)
Block(-10,31,3,LEAVES:3)
Block(0,1,6,LOG:15)
Block(1,4,4,LOG:15)
Block(12,25,0,LEAVES:3)
Block(12,23,0,LEAVES:3)
Block(12,24,0,LEAVES:3)
Block(-10,29,3,LEAVES:3)
Block(6,24,-6,LEAVES:3)
Block(6,23,-6,LEAVES:3)
Block(-9,21,3,LEAVES:3)
Block(-9,22,3,LEAVES:3)
Block(-9,23,3,LEAVES:3)
Block(-11,30,6,LEAVES:3)
Block(-11,31,6,LEAVES:3)
Block(-9,26,3,LEAVES:3)
Block(-9,27,3,LEAVES:3)
Block(-9,28,3,LEAVES:3)
Block(-9,29,3,LEAVES:3)
Block(-7,29,8,LEAVES:3)
Block(-7,28,8,LEAVES:3)
Block(-6,9,5,LOG:15)
Block(12,18,0,LEAVES:3)
Block(-6,8,5,LOG:15)
Block(12,17,0,LEAVES:3)
Block(-13,28,1,LEAVES:3)
Block(-6,29,10,LEAVES:3)
Block(-9,30,3,LEAVES:3)
Block(-9,31,3,LEAVES:3)
Block(-6,11,5,LOG:15)
Block(-6,10,5,LOG:15)
Block(-6,15,5,LOG:15)
Block(-6,16,5,LOG:15)
Block(-6,13,5,LOG:15)
Block(-6,14,5,LOG:15)
Block(-6,30,10,LEAVES:3)
Block(-2,28,3,LEAVES:3)
Block(10,24,4,LEAVES:3)
Block(13,24,-3,LEAVES:3)
Block(13,23,-3,LEAVES:3)
Block(-6,29,5,LEAVES:3)
Block(13,20,-3,LEAVES:3)
Block(13,21,-3,LEAVES:3)
Block(7,19,-1,LEAVES:3)
Block(7,18,-1,LEAVES:3)
Block(-2,-1,5,LOG:15)
Block(16,25,-4,LEAVES:3)
Block(16,24,-4,LEAVES:3)
Block(7,11,2,LOG:15)
Block(7,10,2,LOG:15)
Block(-11,28,6,LEAVES:3)
Block(-11,29,6,LEAVES:3)
Block(-14,30,3,LEAVES:3)
Block(-6,30,5,LEAVES:3)
Block(0,3,6,LOG:15)
Block(0,5,6,LOG:15)
Block(13,19,-3,LEAVES:3)
Block(-6,31,5,LEAVES:3)
Block(13,17,-3,LEAVES:3)
Block(0,6,6,LOG:15)
Block(13,18,-3,LEAVES:3)
Block(13,16,-3,LEAVES:3)
Block(18,21,-4,LEAVES:3)
Block(5,23,-3,LEAVES:3)
Block(1,6,6,LOG:15)
Block(1,5,6,LOG:15)
Block(1,4,6,LOG:15)
Block(1,3,6,LOG:15)
Block(7,23,-1,LEAVES:3)
Block(7,20,-1,LEAVES:3)
Block(-7,30,6,LEAVES:3)
Block(16,22,-6,LEAVES:3)
Block(7,22,-1,LEAVES:3)
Block(-7,31,6,LEAVES:3)
Block(7,21,-1,LEAVES:3)
Block(16,23,-6,LEAVES:3)
Block(2,7,4,LOG:15)
Block(2,8,4,LOG:15)
Block(2,5,4,LOG:15)
Block(-14,29,3,LEAVES:3)
Block(-8,31,9,LEAVES:3)
Block(10,21,6,LEAVES:3)
Block(13,21,-1,LEAVES:3)
Block(13,20,-1,LEAVES:3)
Block(13,23,-1,LEAVES:3)
Block(3,8,2,LOG:15)
Block(3,7,2,LOG:15)
Block(15,19,0,LEAVES:3)
Block(11,22,-3,LOG:15)
Block(15,24,-1,LEAVES:3)
Block(11,23,-3,LOG:15)
Block(11,26,-3,LEAVES:3)
Block(-10,29,5,LEAVES:3)
Block(11,24,-3,LOG:15)
Block(-10,28,5,LEAVES:3)
Block(11,25,-3,LEAVES:3)
Block(-10,27,5,LEAVES:3)
Block(8,24,-6,LEAVES:3)
Block(8,25,-6,LEAVES:3)
Block(13,18,-1,LEAVES:3)
Block(13,17,-1,LEAVES:3)
Block(13,19,-1,LEAVES:3)
Block(-9,30,10,LEAVES:3)
Block(13,16,-1,LEAVES:3)
Block(-9,19,5,LOG:15)
Block(18,22,-4,LEAVES:3)
Block(-7,11,6,LOG:15)
Block(-7,12,6,LOG:15)
Block(-7,13,6,LOG:15)
Block(15,19,-1,LEAVES:3)
Block(-13,30,3,LEAVES:3)
Block(-7,14,6,LOG:15)
Block(-7,15,6,LOG:15)
Block(-7,27,12,LEAVES:3)
Block(-7,16,6,LOG:15)
Block(-7,28,12,LEAVES:3)
Block(-13,31,3,LEAVES:3)
Block(-10,32,5,LEAVES:3)
Block(-7,17,6,LOG:15)
Block(15,20,0,LEAVES:3)
Block(-10,31,5,LEAVES:3)
Block(-7,18,6,LOG:15)
Block(-10,30,5,LEAVES:3)
Block(-5,-2,4,LOG:15)
Block(-5,-1,4,LOG:15)
Block(-1,-2,10,LOG:15)
Block(15,20,-1,LEAVES:3)
Block(14,24,-6,LEAVES:3)
Block(-7,29,12,LEAVES:3)
Block(0,-1,10,LOG:15)
Block(13,25,-1,LEAVES:3)
Block(-6,29,7,LEAVES:3)
Block(13,24,-1,LEAVES:3)
Block(-6,28,7,LEAVES:3)
Block(-11,31,4,LEAVES:3)
Block(-7,25,6,LEAVES:3)
Block(-7,26,6,LEAVES:3)
Block(-7,27,6,LEAVES:3)
Block(-7,28,6,LEAVES:3)
Block(-7,29,6,LEAVES:3)
Block(-6,27,12,LEAVES:3)
Block(-6,28,12,LEAVES:3)
Block(-5,31,2,LEAVES:3)
Block(0,1,8,LOG:15)
Block(9,15,-1,LOG:15)
Block(9,14,-1,LOG:15)
Block(11,26,-1,LEAVES:3)
Block(9,17,-1,LOG:15)
Block(9,16,-1,LOG:15)
Block(9,18,-1,LOG:15)
Block(-8,30,10,LEAVES:3)
Block(-8,31,10,LEAVES:3)
Block(9,13,-1,LOG:15)
Block(-1,3,4,LOG:15)
Block(-1,5,4,LOG:15)
Block(-1,4,4,LOG:15)
Block(-10,26,1,LEAVES:3)
Block(-10,25,1,LEAVES:3)
Block(-9,29,10,LEAVES:3)
Block(12,24,-1,LEAVES:3)
Block(12,23,-1,LEAVES:3)
Block(-10,30,1,LEAVES:3)
Block(12,22,-1,LEAVES:3)
Block(12,17,-1,LEAVES:3)
Block(-9,20,5,LOG:15)
Block(12,16,-1,LEAVES:3)
Block(13,19,1,LEAVES:3)
Block(-9,22,5,LOG:15)
Block(13,18,1,LEAVES:3)
Block(-9,21,5,LOG:15)
Block(-9,24,5,LOG:15)
Block(-14,28,1,LEAVES:3)
Block(-9,23,5,LOG:15)
Block(-14,27,1,LEAVES:3)
Block(-9,26,5,LOG:15)
Block(-9,25,5,LOG:15)
Block(-5,30,9,LEAVES:3)
Block(-9,28,5,LOG:15)
Block(-9,27,5,LOG:15)
Block(-9,29,5,LOG:15)
Block(9,21,5,LEAVES:3)
Block(-7,31,10,LEAVES:3)
Block(-7,30,10,LEAVES:3)
Block(9,23,5,LEAVES:3)
Block(9,22,5,LEAVES:3)
Block(11,21,-1,LOG:15)
Block(11,20,-1,LOG:15)
Block(11,23,-1,LOG:15)
Block(11,22,-1,LOG:15)
Block(11,25,-1,LEAVES:3)
Block(11,24,-1,LOG:15)
Block(-8,15,4,LOG:15)
Block(-8,16,4,LOG:15)
Block(11,18,-1,LOG:15)
Block(11,17,-1,LOG:15)
Block(-8,17,4,LOG:15)
Block(13,25,1,LEAVES:3)
Block(-9,31,5,LEAVES:3)
Block(11,19,-1,LOG:15)
Block(-9,30,5,LEAVES:3)
Block(-9,32,5,LEAVES:3)
Block(13,20,1,LEAVES:3)
Block(11,24,0,LEAVES:3)
Block(13,24,1,LEAVES:3)
Block(13,23,1,LEAVES:3)
Block(11,26,0,LEAVES:3)
Block(13,22,1,LEAVES:3)
Block(13,21,1,LEAVES:3)
Block(-4,11,6,LOG:15)
Block(-4,10,6,LOG:15)
Block(-13,30,5,LEAVES:3)
Block(0,3,4,LOG:15)
Block(10,19,-1,LOG:15)
Block(10,18,-1,LOG:15)
Block(10,17,-1,LOG:15)
Block(10,16,-1,LOG:15)
Block(-12,30,2,LEAVES:3)
Block(10,22,-1,LOG:15)
Block(10,21,-1,LOG:15)
Block(10,20,-1,LOG:15)
Block(-9,23,7,LEAVES:3)
Block(10,26,-1,LEAVES:3)
Block(-9,24,7,LEAVES:3)
Block(10,25,-1,LEAVES:3)
Block(10,24,-1,LOG:15)
Block(10,23,-1,LOG:15)
Block(6,10,1,LOG:15)
Block(-9,27,7,LEAVES:3)
Block(6,11,1,LOG:15)
Block(-9,28,7,LEAVES:3)
Block(-9,25,7,LEAVES:3)
Block(-9,26,7,LEAVES:3)
Block(-9,29,7,LEAVES:3)
Block(-6,28,3,LEAVES:3)
Block(-6,29,3,LEAVES:3)
Block(-1,1,6,LOG:15)
Block(-1,0,6,LOG:15)
Block(-1,3,6,LOG:15)
Block(-12,29,2,LEAVES:3)
Block(-1,5,6,LOG:15)
Block(-1,4,6,LOG:15)
Block(-1,6,6,LOG:15)
Block(-13,29,5,LEAVES:3)
Block(-5,29,0,LEAVES:3)
Block(-11,28,8,LEAVES:3)
Block(-9,30,7,LEAVES:3)
Block(-11,27,8,LEAVES:3)
Block(-9,31,7,LEAVES:3)
Block(10,15,-1,LOG:15)
Block(10,14,-1,LOG:15)
Block(-6,31,3,LEAVES:3)
Block(-6,32,3,LEAVES:3)
Block(-11,24,8,LEAVES:3)
Block(-11,23,8,LEAVES:3)
Block(-11,26,8,LEAVES:3)
Block(-11,25,8,LEAVES:3)
Block(-7,31,8,LEAVES:3)
Block(-2,-2,9,LOG:15)
Block(-2,-1,9,LOG:15)
Block(-8,22,2,LEAVES:3)
Block(-8,26,2,LEAVES:3)
Block(-8,25,2,LEAVES:3)
Block(-8,24,2,LEAVES:3)
Block(-8,23,2,LEAVES:3)
Block(-4,28,6,LEAVES:3)
Block(-4,27,6,LEAVES:3)
Block(-4,24,6,LEAVES:3)
Block(-4,23,6,LEAVES:3)
Block(-4,26,6,LEAVES:3)
Block(-4,25,6,LEAVES:3)
Block(-10,23,3,LEAVES:3)
Block(-10,24,3,LEAVES:3)
Block(-8,29,2,LEAVES:3)
Block(-10,21,3,LEAVES:3)
Block(-8,28,2,LEAVES:3)
Block(-3,29,1,LEAVES:3)
Block(-10,22,3,LEAVES:3)
Block(-8,27,2,LEAVES:3)
Block(-10,27,3,LEAVES:3)
Block(-10,28,3,LEAVES:3)
Block(-5,29,10,LEAVES:3)
Block(-10,25,3,LEAVES:3)
Block(-10,26,3,LEAVES:3)
Block(-2,-3,9,LOG:15)
Block(-8,31,2,LEAVES:3)
Block(-8,30,2,LEAVES:3)
Block(0,5,4,LOG:15)
Block(0,4,4,LOG:15)
Block(0,-1,8,LOG:15)
Block(0,6,4,LOG:15)
Block(-3,30,1,LEAVES:3)
Block(12,21,-3,LEAVES:3)
Block(-4,30,4,LEAVES:3)
Block(12,22,-3,LEAVES:3)
Block(-4,31,4,LEAVES:3)
Block(5,10,2,LOG:15)
Block(12,23,-3,LEAVES:3)
Block(12,24,-3,LEAVES:3)
Block(-4,-1,6,LOG:15)
Block(12,26,-3,LEAVES:3)
Block(-3,3,4,LOG:15)
Block(5,22,-7,LEAVES:3)
Block(5,21,-7,LEAVES:3)
Block(-4,27,4,LEAVES:3)
Block(-8,31,5,LEAVES:3)
Block(-3,4,4,LOG:15)
Block(-8,32,5,LEAVES:3)
Block(-3,0,4,LOG:15)
Block(-15,27,2,LEAVES:3)
Block(-15,28,2,LEAVES:3)
Block(-15,26,2,LEAVES:3)
Block(-1,1,8,LOG:15)
Block(-1,0,8,LOG:15)
Block(-2,7,6,LOG:15)
Block(-1,3,8,LOG:15)
Block(-2,6,6,LOG:15)
Block(9,24,3,LEAVES:3)
Block(-1,2,8,LOG:15)
Block(-2,5,6,LOG:15)
Block(9,25,3,LEAVES:3)
Block(-2,4,6,LOG:15)
Block(-2,3,6,LOG:15)
Block(-1,4,8,LOG:15)
Block(-12,31,3,LEAVES:3)
Block(-2,2,6,LOG:15)
Block(-2,1,6,LOG:15)
Block(-2,0,6,LOG:15)
Block(-11,30,1,LEAVES:3)
Block(17,23,-3,LEAVES:3)
Block(17,22,-3,LEAVES:3)
Block(9,21,-3,LEAVES:3)
Block(9,22,-3,LEAVES:3)
Block(9,20,-3,LEAVES:3)
Block(9,26,-3,LEAVES:3)
Block(9,23,-3,LEAVES:3)
Block(9,24,-3,LEAVES:3)
Block(14,19,-2,LEAVES:3)
Block(14,19,0,LEAVES:3)
Block(14,18,0,LEAVES:3)
Block(-3,29,2,LEAVES:3)
Block(9,18,-3,LEAVES:3)
Block(9,19,-3,LEAVES:3)
Block(11,24,3,LEAVES:3)
Block(14,21,-2,LEAVES:3)
Block(14,22,-2,LEAVES:3)
Block(11,25,3,LEAVES:3)
Block(14,23,-2,LEAVES:3)
Block(-3,30,2,LEAVES:3)
Block(8,12,1,LOG:15)
Block(-1,-1,9,LOG:15)
Block(8,13,1,LOG:15)
Block(8,19,1,LEAVES:3)
Block(14,25,-2,LEAVES:3)
Block(-3,-3,4,LOG:15)
Block(14,23,0,LEAVES:3)
Block(14,22,0,LEAVES:3)
Block(14,21,0,LEAVES:3)
Block(10,19,-4,LEAVES:3)
Block(14,20,0,LEAVES:3)
Block(7,24,-6,LEAVES:3)
Block(7,23,-6,LEAVES:3)
Block(10,26,-4,LEAVES:3)
Block(10,22,-4,LEAVES:3)
Block(10,23,-4,LEAVES:3)
Block(10,24,-4,LEAVES:3)
Block(10,25,-4,LEAVES:3)
Block(10,20,-4,LEAVES:3)
Block(10,21,-4,LEAVES:3)
Block(8,10,1,LOG:15)
Block(8,11,1,LOG:15)
Block(8,25,1,LEAVES:3)
Block(-2,-1,11,LOG:15)
Block(8,24,1,LEAVES:3)
Block(6,24,-2,LEAVES:3)
Block(17,21,-5,LEAVES:3)
Block(17,22,-5,LEAVES:3)
Block(-12,28,5,LEAVES:3)
Block(17,23,-5,LEAVES:3)
Block(-12,27,5,LEAVES:3)
Block(-3,9,6,LOG:15)
Block(-3,8,6,LOG:15)
Block(10,17,-4,LEAVES:3)
Block(10,18,-4,LEAVES:3)
Block(-3,4,6,LOG:15)
Block(-3,7,6,LOG:15)
Block(-3,1,6,LOG:15)
Block(-3,0,6,LOG:15)
Block(-3,3,6,LOG:15)
Block(-3,2,6,LOG:15)
Block(8,21,1,LEAVES:3)
Block(8,22,1,LEAVES:3)
Block(8,20,1,LEAVES:3)
Block(-2,28,0,LEAVES:3)
Block(-2,27,0,LEAVES:3)
Block(-2,4,8,LOG:15)
Block(-2,3,8,LOG:15)
Block(-2,1,8,LOG:15)
Block(-2,26,0,LEAVES:3)
Block(-7,30,1,LEAVES:3)
Block(8,14,-1,LOG:15)
Block(-7,26,1,LEAVES:3)
Block(8,13,-1,LOG:15)
Block(-7,25,1,LEAVES:3)
Block(8,12,-1,LOG:15)
Block(12,25,-1,LEAVES:3)
Block(-7,27,1,LEAVES:3)
Block(-4,-1,4,LOG:15)
Block(-4,-2,4,LOG:15)
Block(-5,30,8,LEAVES:3)
Block(8,15,-1,LOG:15)
Block(-8,29,11,LEAVES:3)
Block(-8,15,5,LOG:15)
Block(-8,16,5,LOG:15)
Block(-8,17,5,LOG:15)
Block(-5,27,8,LEAVES:3)
Block(-8,18,5,LOG:15)
Block(-5,26,8,LEAVES:3)
Block(8,25,-1,LEAVES:3)
Block(-5,25,8,LEAVES:3)
Block(8,24,-1,LEAVES:3)
Block(-8,13,5,LOG:15)
Block(8,23,-1,LEAVES:3)
Block(-8,14,5,LOG:15)
Block(-9,27,9,LEAVES:3)
Block(12,24,3,LEAVES:3)
Block(12,23,3,LEAVES:3)
Block(9,23,1,LEAVES:3)
Block(9,22,1,LEAVES:3)
Block(9,21,1,LEAVES:3)
Block(-8,19,5,LOG:15)
Block(15,23,-6,LEAVES:3)
Block(-8,26,5,LOG:15)
Block(9,25,-1,LEAVES:3)
Block(-8,27,5,LOG:15)
Block(-8,28,5,LOG:15)
Block(-9,31,9,LEAVES:3)
Block(-8,29,5,LOG:15)
Block(-9,30,9,LEAVES:3)
Block(-8,22,5,LOG:15)
Block(-8,23,5,LOG:15)
Block(-8,24,5,LOG:15)
Block(9,25,1,LEAVES:3)
Block(-8,25,5,LOG:15)
Block(-8,30,11,LEAVES:3)
Block(-8,20,5,LOG:15)
Block(-6,30,1,LEAVES:3)
Block(-8,21,5,LOG:15)
Block(9,24,-1,LEAVES:3)
Block(-7,20,5,LOG:15)
Block(-9,25,0,LEAVES:3)
Block(-4,5,6,LOG:15)
Block(-4,4,6,LOG:15)
Block(-4,3,6,LOG:15)
Block(-4,9,6,LOG:15)
Block(-3,29,4,LEAVES:3)
Block(-7,28,5,LOG:15)
Block(-10,28,6,LEAVES:3)
Block(-7,27,5,LOG:15)
Block(-10,29,6,LEAVES:3)
Block(-4,2,6,LOG:15)
Block(-7,24,5,LOG:15)
Block(-4,1,6,LOG:15)
Block(-7,23,5,LOG:15)
Block(-10,25,6,LEAVES:3)
Block(-4,0,6,LOG:15)
Block(-7,22,5,LOG:15)
Block(-10,26,6,LEAVES:3)
Block(-7,21,5,LOG:15)
Block(-10,27,6,LEAVES:3)
Block(11,22,5,LEAVES:3)
Block(11,21,5,LEAVES:3)
Block(-3,3,8,LOG:15)
Block(-3,2,8,LOG:15)
Block(-7,19,5,LOG:15)
Block(-7,18,5,LOG:15)
Block(11,23,5,LEAVES:3)
Block(-3,30,4,LEAVES:3)
Block(14,25,-4,LEAVES:3)
Block(-7,31,5,LEAVES:3)
Block(-10,31,6,LEAVES:3)
Block(-7,30,5,LEAVES:3)
Block(13,25,-5,LEAVES:3)
Block(-3,-1,6,LOG:15)
Block(3,8,4,LOG:15)
Block(3,7,4,LOG:15)
Block(13,22,-5,LEAVES:3)
Block(3,6,4,LOG:15)
Block(13,21,-5,LEAVES:3)
Block(3,5,4,LOG:15)
Block(13,20,-5,LEAVES:3)
Block(-10,30,6,LEAVES:3)
Block(-5,29,4,LEAVES:3)
Block(-5,28,4,LEAVES:3)
Block(4,7,2,LOG:15)
Block(4,9,2,LOG:15)
Block(4,8,2,LOG:15)
Block(-5,31,4,LEAVES:3)
Block(-10,30,10,LEAVES:3)
Block(11,22,-6,LEAVES:3)
Block(11,21,-6,LEAVES:3)
Block(11,20,-6,LEAVES:3)
Block(15,25,-2,LEAVES:3)
Block(6,24,-4,LEAVES:3)
Block(6,25,-4,LEAVES:3)
Block(-4,31,2,LEAVES:3)
Block(15,24,-2,LEAVES:3)
Block(-4,30,2,LEAVES:3)
Block(-6,30,8,LEAVES:3)
Block(7,9,2,LOG:15)
Block(-6,31,8,LEAVES:3)
Block(-11,28,3,LEAVES:3)
Block(8,24,3,LEAVES:3)
Block(8,23,3,LEAVES:3)
Block(-7,17,5,LOG:15)
Block(-7,16,5,LOG:15)
Block(-7,13,5,LOG:15)
Block(-7,12,5,LOG:15)
Block(-7,11,5,LOG:15)
Block(-12,31,5,LEAVES:3)
Block(-12,30,5,LEAVES:3)
Block(10,26,1,LEAVES:3)
Block(-11,31,3,LEAVES:3)
Block(10,23,1,LEAVES:3)
Block(10,25,1,LEAVES:3)
Block(-6,27,8,LEAVES:3)
Block(-6,28,8,LEAVES:3)
Block(9,22,-5,LEAVES:3)
Block(9,21,-5,LEAVES:3)
Block(-10,29,10,LEAVES:3)
Block(9,25,-5,LEAVES:3)
Block(-6,26,8,LEAVES:3)
Block(-4,3,8,LOG:15)
Block(15,25,-4,LEAVES:3)
Block(7,12,1,LOG:15)
Block(7,11,1,LOG:15)
Block(7,13,1,LOG:15)
Block(16,24,-3,LEAVES:3)
Block(16,23,-3,LEAVES:3)
Block(8,25,-3,LEAVES:3)
Block(-4,28,0,LEAVES:3)
Block(7,10,1,LOG:15)
Block(8,26,-3,LEAVES:3)
Block(16,25,-3,LEAVES:3)
Block(8,22,-3,LEAVES:3)
Block(8,23,-3,LEAVES:3)
Block(-1,-2,9,LOG:15)
Block(13,26,-3,LEAVES:3)
Block(-4,29,0,LEAVES:3)
Block(12,22,1,LEAVES:3)
Block(12,23,1,LEAVES:3)
Block(12,21,1,LEAVES:3)
Block(11,19,-6,LEAVES:3)
Block(11,18,-6,LEAVES:3)
Block(7,25,-4,LEAVES:3)
Block(12,25,1,LEAVES:3)
Block(-8,29,7,LEAVES:3)
Block(-8,28,7,LEAVES:3)
Block(-5,11,6,LOG:15)
Block(10,25,3,LEAVES:3)
Block(-8,25,7,LEAVES:3)
Block(-5,12,6,LOG:15)
Block(10,24,-6,LEAVES:3)
Block(-8,24,7,LEAVES:3)
Block(4,7,4,LOG:15)
Block(-8,27,7,LEAVES:3)
Block(4,6,4,LOG:15)
Block(5,9,2,LOG:15)
Block(-5,10,6,LOG:15)
Block(-8,26,7,LEAVES:3)
Block(5,8,2,LOG:15)
Block(10,21,-6,LEAVES:3)
Block(5,7,2,LOG:15)
Block(4,8,4,LOG:15)
Block(10,20,-6,LEAVES:3)
Block(-8,23,7,LEAVES:3)
Block(10,22,-6,LEAVES:3)
Block(-9,23,2,LEAVES:3)
Block(-9,24,2,LEAVES:3)
Block(-9,25,2,LEAVES:3)
Block(-9,26,2,LEAVES:3)
Block(12,22,-5,LEAVES:3)
Block(12,21,-5,LEAVES:3)
Block(-10,25,8,LEAVES:3)
Block(12,23,-5,LEAVES:3)
Block(6,9,2,LOG:15)
Block(6,8,2,LOG:15)
Block(12,25,-5,LEAVES:3)
Block(-12,27,7,LEAVES:3)
Block(-12,25,7,LEAVES:3)
Block(-12,26,7,LEAVES:3)
Block(-12,24,7,LEAVES:3)
Block(-10,27,8,LEAVES:3)
Block(-10,26,8,LEAVES:3)
Block(-10,28,8,LEAVES:3)
Block(10,19,-6,LEAVES:3)
Block(-8,32,7,LEAVES:3)
Block(-8,31,7,LEAVES:3)
Block(5,23,-5,LEAVES:3)
Block(-14,29,5,LEAVES:3)
Block(-14,28,5,LEAVES:3)
Block(-8,30,7,LEAVES:3)
Block(5,22,-5,LEAVES:3)
Block(-10,30,8,LEAVES:3)
Block(-2,29,2,LEAVES:3)
Block(-2,27,2,LEAVES:3)
Block(-2,28,2,LEAVES:3)
Block(-7,30,3,LEAVES:3)
Block(-7,31,3,LEAVES:3)
Block(-5,5,6,LOG:15)
Block(-5,4,6,LOG:15)
Block(-5,7,6,LOG:15)
Block(-7,29,3,LEAVES:3)
Block(-5,6,6,LOG:15)
Block(-5,9,6,LOG:15)
Block(-5,8,6,LOG:15)
Block(13,23,-2,LEAVES:3)
Block(13,24,-2,LEAVES:3)
Block(13,21,-2,LEAVES:3)
Block(13,22,-2,LEAVES:3)
Block(11,20,-4,LEAVES:3)
Block(13,20,-2,LEAVES:3)
Block(11,23,-4,LEAVES:3)
Block(11,24,-4,LEAVES:3)
Block(11,21,-4,LEAVES:3)
Block(11,22,-4,LEAVES:3)
Block(11,25,-4,LEAVES:3)
Block(11,19,-4,LEAVES:3)
Block(-6,9,6,LOG:15)
Block(13,18,-2,LEAVES:3)
Block(13,19,-2,LEAVES:3)
Block(13,16,-2,LEAVES:3)
Block(13,17,-2,LEAVES:3)
Block(13,15,-2,LEAVES:3)
Block(16,23,-5,LEAVES:3)
Block(16,24,-5,LEAVES:3)
Block(0,4,7,LOG:15)
Block(0,3,7,LOG:15)
Block(-14,28,4,LEAVES:3)
Block(0,5,7,LOG:15)
Block(-14,29,4,LEAVES:3)
Block(13,25,-2,LEAVES:3)
Block(13,26,-2,LEAVES:3)
Block(-9,28,2,LEAVES:3)
Block(-9,29,2,LEAVES:3)
Block(1,7,5,LOG:15)
Block(1,6,5,LOG:15)
Block(-10,21,4,LEAVES:3)
Block(1,4,5,LOG:15)
Block(1,3,5,LOG:15)
Block(-7,29,7,LEAVES:3)
Block(-10,25,4,LEAVES:3)
Block(-10,23,4,LEAVES:3)
Block(-5,29,1,LEAVES:3)
Block(-10,22,4,LEAVES:3)
Block(-10,29,4,LEAVES:3)
Block(-10,28,4,LEAVES:3)
Block(-10,27,4,LEAVES:3)
Block(-13,29,2,LEAVES:3)
Block(-10,26,4,LEAVES:3)
Block(2,8,3,LOG:15)
Block(-5,30,1,LEAVES:3)
Block(2,7,3,LOG:15)
Block(2,6,3,LOG:15)
Block(8,25,-5,LEAVES:3)
Block(2,5,3,LOG:15)
Block(-9,30,2,LEAVES:3)
Block(-6,13,6,LOG:15)
Block(6,20,0,LEAVES:3)
Block(-9,31,2,LEAVES:3)
Block(-6,12,6,LOG:15)
Block(-6,11,6,LOG:15)
Block(-6,10,6,LOG:15)
Block(-6,15,6,LOG:15)
Block(-6,14,6,LOG:15)
Block(-10,32,4,LEAVES:3)
Block(-7,27,13,LEAVES:3)
Block(-10,30,4,LEAVES:3)
Block(-7,26,13,LEAVES:3)
Block(-12,26,8,LEAVES:3)
Block(-12,24,8,LEAVES:3)
Block(-12,25,8,LEAVES:3)
Block(-7,30,7,LEAVES:3)
Block(-7,31,7,LEAVES:3)
Block(-8,24,1,LEAVES:3)
Block(-8,25,1,LEAVES:3)
Block(-8,23,1,LEAVES:3)
Block(6,10,0,LOG:15)
Block(6,11,0,LOG:15)
Block(-6,29,6,LEAVES:3)
Block(-6,28,11,LEAVES:3)
Block(-5,-1,5,LOG:15)
Block(-11,25,5,LEAVES:3)
Block(-11,26,5,LEAVES:3)
Block(-11,28,5,LEAVES:3)
Block(-6,29,11,LEAVES:3)
Block(-6,31,6,LEAVES:3)
Block(-11,29,5,LEAVES:3)
Block(-9,30,4,LEAVES:3)
Block(-6,30,6,LEAVES:3)
Block(-5,31,3,LEAVES:3)
Block(-9,31,4,LEAVES:3)
Block(-9,32,4,LEAVES:3)
Block(-13,30,2,LEAVES:3)
Block(6,23,-7,LEAVES:3)
Block(6,22,-7,LEAVES:3)
Block(0,0,9,LOG:15)
Block(-11,31,5,LEAVES:3)
Block(9,24,-7,LEAVES:3)
Block(7,19,-2,LEAVES:3)
Block(11,20,-2,LOG:15)
Block(11,22,-2,LOG:15)
Block(11,21,-2,LOG:15)
Block(-2,-1,6,LOG:15)
Block(11,26,-2,LEAVES:3)
Block(11,25,-2,LEAVES:3)
Block(2,6,5,LOG:15)
Block(11,17,-2,LOG:15)
Block(2,5,5,LOG:15)
Block(11,19,-2,LOG:15)
Block(2,7,5,LOG:15)
Block(11,18,-2,LOG:15)
Block(13,24,2,LEAVES:3)
Block(18,21,-5,LEAVES:3)
Block(18,22,-5,LEAVES:3)
Block(-9,28,11,LEAVES:3)
Block(3,8,3,LOG:15)
Block(-9,29,11,LEAVES:3)
Block(3,6,3,LOG:15)
Block(7,25,-2,LEAVES:3)
Block(7,24,-2,LEAVES:3)
Block(7,21,-2,LEAVES:3)
Block(7,20,-2,LEAVES:3)
Block(7,22,-2,LEAVES:3)
Block(-9,21,4,LOG:15)
Block(-9,22,4,LOG:15)
Block(-14,29,2,LEAVES:3)
Block(-9,23,4,LOG:15)
Block(-14,28,2,LEAVES:3)
Block(10,22,5,LEAVES:3)
Block(-9,24,4,LOG:15)
Block(10,23,5,LEAVES:3)
Block(-9,25,4,LOG:15)
Block(-9,26,4,LOG:15)
Block(10,21,5,LEAVES:3)
Block(-9,27,4,LOG:15)
Block(-14,27,2,LEAVES:3)
Block(-9,28,4,LOG:15)
Block(-9,29,4,LEAVES:3)
Block(-4,23,7,LEAVES:3)
Block(-6,28,2,LEAVES:3)
Block(-6,27,2,LEAVES:3)
Block(-4,26,7,LEAVES:3)
Block(-4,27,7,LEAVES:3)
Block(-4,24,7,LEAVES:3)
Block(-4,25,7,LEAVES:3)
Block(8,23,-7,LEAVES:3)
Block(-7,30,11,LEAVES:3)
Block(13,25,0,LEAVES:3)
Block(13,24,0,LEAVES:3)
Block(-6,31,2,LEAVES:3)
Block(13,23,0,LEAVES:3)
Block(6,10,2,LOG:15)
Block(10,19,-2,LOG:15)
Block(10,18,-2,LOG:15)
Block(10,17,-2,LOG:15)
Block(10,23,-2,LOG:15)
Block(10,22,-2,LOG:15)
Block(10,21,-2,LOG:15)
Block(10,20,-2,LOG:15)
Block(10,26,-2,LEAVES:3)
Block(10,25,-2,LEAVES:3)
Block(10,24,-2,LOG:15)
Block(-9,25,6,LEAVES:3)
Block(6,11,2,LOG:15)
Block(-9,24,6,LEAVES:3)
Block(-9,27,6,LEAVES:3)
Block(-9,26,6,LEAVES:3)
Block(-7,29,11,LEAVES:3)
Block(-9,29,6,LEAVES:3)
Block(-9,28,6,LEAVES:3)
Block(-8,29,3,LEAVES:3)
Block(-8,28,3,LEAVES:3)
Block(-8,31,3,LEAVES:3)
Block(10,16,-2,LOG:15)
Block(-8,30,3,LEAVES:3)
Block(-13,30,4,LEAVES:3)
Block(-2,-1,8,LOG:15)
Block(-4,28,7,LEAVES:3)
Block(-15,28,3,LEAVES:3)
Block(9,22,4,LEAVES:3)
Block(-15,27,3,LEAVES:3)
Block(9,23,4,LEAVES:3)
Block(9,24,4,LEAVES:3)
Block(-3,27,0,LEAVES:3)
Block(-8,28,1,LEAVES:3)
Block(-8,26,1,LEAVES:3)
Block(-3,28,0,LEAVES:3)
Block(-8,27,1,LEAVES:3)
Block(-10,26,2,LEAVES:3)
Block(-10,27,2,LEAVES:3)
Block(-10,25,2,LEAVES:3)
Block(11,22,1,LEAVES:3)
Block(-6,11,4,LOG:15)
Block(11,23,1,LEAVES:3)
Block(11,26,1,LEAVES:3)
Block(11,25,1,LEAVES:3)
Block(-6,14,4,LOG:15)
Block(-6,12,4,LOG:15)
Block(-6,13,4,LOG:15)
Block(-4,30,5,LEAVES:3)
Block(-10,30,2,LEAVES:3)
Block(-10,31,2,LEAVES:3)
Block(-7,31,9,LEAVES:3)
Block(-10,28,2,LEAVES:3)
Block(-4,27,5,LEAVES:3)
Block(0,3,5,LOG:15)
Block(-4,26,5,LEAVES:3)
Block(0,6,5,LOG:15)
Block(-4,28,5,LEAVES:3)
Block(-6,29,4,LEAVES:3)
Block(1,6,3,LOG:15)
Block(-11,27,7,LEAVES:3)
Block(-11,29,7,LEAVES:3)
Block(-9,30,6,LEAVES:3)
Block(-11,28,7,LEAVES:3)
Block(-9,31,6,LEAVES:3)
Block(-6,32,4,LEAVES:3)
Block(-6,30,4,LEAVES:3)
Block(-6,31,4,LEAVES:3)
Block(-1,4,5,LOG:15)
Block(-1,3,5,LOG:15)
Block(-1,6,5,LOG:15)
Block(-1,5,5,LOG:15)
Block(13,19,0,LEAVES:3)
Block(-11,30,7,LEAVES:3)
Block(-12,29,1,LEAVES:3)

#######################################################################
# +-----------------------------------------------------------------+ #
# |                            BO3 checks                           | #
# +-----------------------------------------------------------------+ #
#######################################################################

BlockCheck(-1,-1,6,GRASS:0,DIRT:0,SAND:0)

#######################################################################
# +-----------------------------------------------------------------+ #
# |                             Branches                            | #
# +-----------------------------------------------------------------+ #
#######################################################################


#######################################################################
# +-----------------------------------------------------------------+ #
# |                             Entities                            | #
# +-----------------------------------------------------------------+ #
#######################################################################


#######################################################################
# +-----------------------------------------------------------------+ #
# |                            Particles                            | #
# +-----------------------------------------------------------------+ #
#######################################################################


#######################################################################
# +-----------------------------------------------------------------+ #
# |                             Spawners                            | #
# +-----------------------------------------------------------------+ #
#######################################################################


#######################################################################
# +-----------------------------------------------------------------+ #
# |                             ModData                             | #
# +-----------------------------------------------------------------+ #
#######################################################################

