
#######################################################################
# +-----------------------------------------------------------------+ #
# |                            BO3 object                           | #
# +-----------------------------------------------------------------+ #
#######################################################################

Author: Unknown

Description: Converted version of the BO2 OakMangroveTree2

Version: 3

SettingsMode: WriteWithoutComments


#######################################################################
# +-----------------------------------------------------------------+ #
# |                          Main settings                          | #
# +-----------------------------------------------------------------+ #
#######################################################################

Tree: true

Frequency: 1

Rarity: 10.0

RotateRandomly: true

SpawnHeight: highestSolidBlock

SpawnHeightOffset: 0

SpawnHeightVariance: 0

##############################
# Height Limits for the BO3. #
##############################

MinHeight: 57

MaxHeight: 62

######################
# Extrusion settings #
######################

ExtrudeMode: None

ExtrudeThroughBlocks: AIR

MaxBranchDepth: 10

ExcludedBiomes: All


#######################################################################
# +-----------------------------------------------------------------+ #
# |                      Source block settings                      | #
# +-----------------------------------------------------------------+ #
#######################################################################

SourceBlocks: STONE:1,STONE:3,STONE:5,DIRT:1,DIRT:0,SAND:0,GRASS:0,DIRT:2,STATIONARY_WATER:0,HARD_CLAY,STAINED_CLAY:0,CLAY,SANDSTONE:0,SAND:1,AIR,STONE:0,GRAVEL,LONG_GRASS:0,LONG_GRASS:1,LONG_GRASS:2,DEAD_BUSH,YELLOW_FLOWER:0,RED_ROSE:0,BROWN_MUSHROOM,RED_MUSHROOM,WATER_LILY

MaxPercentageOutsideSourceBlock: 0

OutsideSourceBlock: placeAnyway

DoReplaceBlocks: true

IsOTGPlus: false


#######################################################################
# +-----------------------------------------------------------------+ #
# |                              Blocks                             | #
# +-----------------------------------------------------------------+ #
#######################################################################

Block(2,11,4,LEAVES:0)
Block(-2,12,4,LEAVES:0)
Block(-2,12,-3,LEAVES:0)
Block(-3,11,-2,LEAVES:0)
Block(-1,10,1,LOG:12)
Block(-1,11,1,LOG:12)
Block(-3,12,-2,LEAVES:0)
Block(-4,12,-1,LEAVES:0)
Block(-3,10,2,LEAVES:0)
Block(-4,11,-1,LEAVES:0)
Block(-1,12,1,LEAVES:0)
Block(-1,13,1,LEAVES:0)
Block(-6,11,0,LEAVES:0)
Block(-1,4,0,LOG:12)
Block(-3,12,2,LEAVES:0)
Block(-3,11,2,LEAVES:0)
Block(2,-4,-1,LOG:12)
Block(2,-3,-1,LOG:12)
Block(2,-5,-1,LOG:12)
Block(-2,11,-3,LOG:12)
Block(-2,10,-3,LEAVES:0)
Block(2,-2,-1,LOG:12)
Block(2,-1,-1,LOG:12)
Block(1,10,1,LEAVES:0)
Block(1,11,1,LOG:12)
Block(1,12,1,LEAVES:0)
Block(3,10,2,LEAVES:0)
Block(-6,11,5,LEAVES:0)
Block(3,11,2,LEAVES:0)
Block(1,1,3,LOG:12)
Block(1,0,3,LOG:12)
Block(-1,3,0,LOG:12)
Block(3,12,2,LEAVES:0)
Block(-3,10,-3,LEAVES:0)
Block(-4,1,1,LOG:12)
Block(-2,11,-4,LEAVES:0)
Block(-4,0,1,LOG:12)
Block(0,1,-1,LOG:12)
Block(0,2,-1,LOG:12)
Block(-1,-5,3,LOG:12)
Block(-4,-4,1,LOG:12)
Block(-1,-4,3,LOG:12)
Block(-4,-3,1,LOG:12)
Block(-4,-2,1,LOG:12)
Block(-4,-1,1,LOG:12)
Block(1,10,2,LEAVES:0)
Block(1,11,2,LEAVES:0)
Block(1,12,2,LEAVES:0)
Block(1,13,2,LEAVES:0)
Block(0,10,3,LEAVES:0)
Block(0,11,3,LOG:12)
Block(1,12,-1,LEAVES:0)
Block(1,11,-1,LEAVES:0)
Block(0,12,3,LEAVES:0)
Block(-1,-1,3,LOG:12)
Block(-1,-3,3,LOG:12)
Block(-4,-5,1,LOG:12)
Block(-1,-2,3,LOG:12)
Block(4,11,-2,LEAVES:0)
Block(-4,11,5,LEAVES:0)
Block(3,-2,-1,LOG:12)
Block(-1,11,-4,LEAVES:0)
Block(-2,11,4,LEAVES:0)
Block(3,-3,-1,LOG:12)
Block(3,-4,-1,LOG:12)
Block(3,-5,-1,LOG:12)
Block(1,-2,3,LOG:12)
Block(-1,10,2,LEAVES:0)
Block(1,-1,3,LOG:12)
Block(-3,11,-3,LEAVES:0)
Block(1,-4,3,LOG:12)
Block(0,10,-1,LEAVES:0)
Block(-1,12,2,LEAVES:0)
Block(1,-3,3,LOG:12)
Block(-1,11,2,LOG:12)
Block(-3,11,3,LOG:12)
Block(0,12,-1,LEAVES:0)
Block(1,-5,3,LOG:12)
Block(-3,10,3,LEAVES:0)
Block(0,11,-1,LEAVES:0)
Block(-1,13,2,LEAVES:0)
Block(0,3,0,LOG:12)
Block(0,2,0,LOG:12)
Block(-3,12,3,LEAVES:0)
Block(-2,13,0,LEAVES:0)
Block(-2,12,0,LEAVES:0)
Block(-2,11,0,LEAVES:0)
Block(-2,10,0,LEAVES:0)
Block(-1,-2,1,LOG:12)
Block(-1,-3,1,LOG:12)
Block(-1,-4,1,LOG:12)
Block(-1,-5,1,LOG:12)
Block(1,-3,4,LOG:12)
Block(1,-2,4,LOG:12)
Block(1,-5,4,LOG:12)
Block(1,-4,4,LOG:12)
Block(0,11,5,LEAVES:0)
Block(-1,-1,1,LOG:12)
Block(0,10,5,LEAVES:0)
Block(-1,3,2,LOG:12)
Block(-1,2,2,LOG:12)
Block(-4,11,-3,LEAVES:0)
Block(2,12,3,LEAVES:0)
Block(-1,4,2,LOG:12)
Block(-3,11,-4,LEAVES:0)
Block(2,11,3,LEAVES:0)
Block(-4,11,3,LEAVES:0)
Block(-4,12,3,LEAVES:0)
Block(3,11,-3,LEAVES:0)
Block(-2,3,0,LOG:12)
Block(-2,2,0,LOG:12)
Block(2,0,-1,LOG:12)
Block(-2,1,0,LOG:12)
Block(-1,10,0,LEAVES:0)
Block(-1,11,0,LOG:12)
Block(-1,12,0,LEAVES:0)
Block(-1,1,2,LOG:12)
Block(-6,11,1,LEAVES:0)
Block(2,12,2,LEAVES:0)
Block(2,11,2,LEAVES:0)
Block(-4,10,4,LEAVES:0)
Block(-4,11,4,LEAVES:0)
Block(2,10,2,LEAVES:0)
Block(4,11,1,LEAVES:0)
Block(-5,11,3,LEAVES:0)
Block(-2,11,5,LEAVES:0)
Block(-2,-2,-1,LOG:12)
Block(-2,-3,-1,LOG:12)
Block(-2,-1,-1,LOG:12)
Block(-2,-4,-1,LOG:12)
Block(1,1,-1,LOG:12)
Block(-2,-5,-1,LOG:12)
Block(-3,12,4,LEAVES:0)
Block(1,0,-1,LOG:12)
Block(-3,11,4,LOG:12)
Block(-3,10,4,LEAVES:0)
Block(3,11,1,LEAVES:0)
Block(-1,4,1,LOG:12)
Block(-1,3,1,LOG:12)
Block(-1,6,1,LOG:12)
Block(-1,5,1,LOG:12)
Block(-1,8,1,LOG:12)
Block(-1,7,1,LOG:12)
Block(-1,9,1,LOG:12)
Block(-2,11,-5,LEAVES:0)
Block(1,10,3,LEAVES:0)
Block(1,12,3,LEAVES:0)
Block(1,11,3,LEAVES:0)
Block(1,13,3,LEAVES:0)
Block(0,11,4,LOG:12)
Block(-1,0,1,LOG:12)
Block(-1,2,1,LOG:12)
Block(-1,1,1,LOG:12)
Block(0,10,4,LEAVES:0)
Block(-4,11,-4,LEAVES:0)
Block(0,3,2,LOG:12)
Block(-3,11,-5,LEAVES:0)
Block(0,2,2,LOG:12)
Block(-1,10,4,LEAVES:0)
Block(-6,11,-2,LEAVES:0)
Block(-4,11,2,LEAVES:0)
Block(1,11,4,LOG:12)
Block(0,13,1,LEAVES:0)
Block(1,10,4,LEAVES:0)
Block(2,11,-2,LEAVES:0)
Block(0,12,1,LEAVES:0)
Block(-5,11,5,LEAVES:0)
Block(1,12,4,LEAVES:0)
Block(0,11,1,LOG:12)
Block(0,10,1,LEAVES:0)
Block(-2,-5,3,LOG:12)
Block(-2,-3,3,LOG:12)
Block(-2,-4,3,LOG:12)
Block(-2,-2,3,LOG:12)
Block(2,-4,3,LOG:12)
Block(2,-5,3,LOG:12)
Block(2,-2,3,LOG:12)
Block(2,-3,3,LOG:12)
Block(-3,-3,-1,LOG:12)
Block(-3,-4,-1,LOG:12)
Block(-3,-5,-1,LOG:12)
Block(-1,10,-2,LEAVES:0)
Block(-1,11,-2,LOG:12)
Block(-3,11,5,LEAVES:0)
Block(-1,11,4,LEAVES:0)
Block(-1,12,4,LEAVES:0)
Block(-3,-2,-1,LOG:12)
Block(0,11,6,LEAVES:0)
Block(3,11,-2,LEAVES:0)
Block(-2,12,-1,LEAVES:0)
Block(-2,10,-1,LEAVES:0)
Block(-1,10,-1,LEAVES:0)
Block(-2,11,-1,LEAVES:0)
Block(-3,11,0,LOG:12)
Block(2,11,1,LEAVES:0)
Block(-1,1,3,LOG:12)
Block(2,10,1,LEAVES:0)
Block(-3,12,0,LEAVES:0)
Block(-3,10,0,LEAVES:0)
Block(2,12,1,LEAVES:0)
Block(-1,11,5,LEAVES:0)
Block(-5,11,-2,LEAVES:0)
Block(-3,13,0,LEAVES:0)
Block(-2,13,1,LEAVES:0)
Block(-2,10,1,LEAVES:0)
Block(-1,11,-1,LOG:12)
Block(-2,4,1,LOG:12)
Block(4,11,2,LEAVES:0)
Block(-1,12,-1,LEAVES:0)
Block(-2,3,1,LOG:12)
Block(-2,12,1,LEAVES:0)
Block(-2,2,1,LOG:12)
Block(-2,11,1,LOG:12)
Block(-5,11,4,LEAVES:0)
Block(0,13,0,LEAVES:0)
Block(0,12,0,LEAVES:0)
Block(0,11,0,LEAVES:0)
Block(-2,-4,-2,LOG:12)
Block(-2,-3,-2,LOG:12)
Block(-2,-2,-2,LOG:12)
Block(-2,-5,-2,LOG:12)
Block(0,10,0,LEAVES:0)
Block(3,11,0,LEAVES:0)
Block(-1,0,3,LOG:12)
Block(2,11,0,LOG:12)
Block(2,12,0,LEAVES:0)
Block(-2,0,-1,LOG:12)
Block(2,-4,-2,LOG:12)
Block(2,-5,-2,LOG:12)
Block(2,-2,-2,LOG:12)
Block(-2,10,-2,LEAVES:0)
Block(2,-3,-2,LOG:12)
Block(4,11,3,LEAVES:0)
Block(-2,10,3,LEAVES:0)
Block(-1,11,-3,LEAVES:0)
Block(-5,11,1,LEAVES:0)
Block(-3,11,6,LEAVES:0)
Block(3,11,3,LEAVES:0)
Block(-2,1,-1,LOG:12)
Block(1,13,0,LEAVES:0)
Block(1,12,0,LEAVES:0)
Block(1,11,0,LOG:12)
Block(1,10,0,LEAVES:0)
Block(-2,13,3,LEAVES:0)
Block(-2,11,3,LOG:12)
Block(-2,12,3,LEAVES:0)
Block(1,11,5,LEAVES:0)
Block(-1,-5,4,LOG:12)
Block(2,12,-1,LEAVES:0)
Block(2,11,-1,LEAVES:0)
Block(-4,12,0,LEAVES:0)
Block(0,13,2,LEAVES:0)
Block(-4,10,0,LEAVES:0)
Block(-4,11,0,LOG:12)
Block(0,11,-3,LEAVES:0)
Block(0,10,2,LEAVES:0)
Block(-3,11,-1,LEAVES:0)
Block(0,11,2,LEAVES:0)
Block(-3,12,-1,LEAVES:0)
Block(0,12,2,LEAVES:0)
Block(-1,-3,4,LOG:12)
Block(-4,12,-2,LEAVES:0)
Block(-3,13,-1,LEAVES:0)
Block(-1,-4,4,LOG:12)
Block(-4,11,-2,LEAVES:0)
Block(-1,-2,4,LOG:12)
Block(-3,12,1,LEAVES:0)
Block(-5,11,-1,LEAVES:0)
Block(-3,10,1,LEAVES:0)
Block(-3,11,1,LOG:12)
Block(-5,11,0,LEAVES:0)
Block(-1,12,-2,LEAVES:0)
Block(-2,12,2,LEAVES:0)
Block(-2,13,2,LEAVES:0)
Block(-2,10,2,LEAVES:0)
Block(-2,11,2,LEAVES:0)
Block(1,11,6,LEAVES:0)
Block(-4,11,1,LEAVES:0)
Block(-1,11,3,LOG:12)
Block(-1,10,3,LEAVES:0)
Block(0,11,-2,LEAVES:0)
Block(4,11,-1,LEAVES:0)
Block(-1,13,3,LEAVES:0)
Block(-1,12,3,LEAVES:0)
Block(-3,2,1,LOG:12)
Block(-3,1,1,LOG:12)
Block(0,12,-2,LEAVES:0)
Block(2,11,5,LEAVES:0)
Block(-5,-2,1,LOG:12)
Block(-4,10,1,LEAVES:0)
Block(-5,-3,1,LOG:12)
Block(-5,-4,1,LOG:12)
Block(-5,-5,1,LOG:12)
Block(3,11,-1,LEAVES:0)
Block(-4,-5,2,LOG:12)
Block(-4,-4,2,LOG:12)
Block(-4,-3,2,LOG:12)
Block(-2,12,-2,LEAVES:0)
Block(-4,-2,2,LOG:12)
Block(-2,11,-2,LOG:12)
Block(-5,10,0,LEAVES:0)
Block(1,11,-2,LEAVES:0)
Block(3,12,-1,LEAVES:0)
Block(1,2,2,LOG:12)
Block(3,11,4,LEAVES:0)
Block(1,1,2,LOG:12)

#######################################################################
# +-----------------------------------------------------------------+ #
# |                            BO3 checks                           | #
# +-----------------------------------------------------------------+ #
#######################################################################


#######################################################################
# +-----------------------------------------------------------------+ #
# |                             Branches                            | #
# +-----------------------------------------------------------------+ #
#######################################################################


#######################################################################
# +-----------------------------------------------------------------+ #
# |                             Entities                            | #
# +-----------------------------------------------------------------+ #
#######################################################################


#######################################################################
# +-----------------------------------------------------------------+ #
# |                            Particles                            | #
# +-----------------------------------------------------------------+ #
#######################################################################


#######################################################################
# +-----------------------------------------------------------------+ #
# |                             Spawners                            | #
# +-----------------------------------------------------------------+ #
#######################################################################


#######################################################################
# +-----------------------------------------------------------------+ #
# |                             ModData                             | #
# +-----------------------------------------------------------------+ #
#######################################################################

