
#######################################################################
# +-----------------------------------------------------------------+ #
# |                            BO3 object                           | #
# +-----------------------------------------------------------------+ #
#######################################################################

Author: Unknown

Description: Converted version of the BO2 OakMangroveTree8

Version: 3

SettingsMode: WriteWithoutComments


#######################################################################
# +-----------------------------------------------------------------+ #
# |                          Main settings                          | #
# +-----------------------------------------------------------------+ #
#######################################################################

Tree: true

Frequency: 1

Rarity: 10.0

RotateRandomly: true

SpawnHeight: highestSolidBlock

SpawnHeightOffset: 0

SpawnHeightVariance: 0

##############################
# Height Limits for the BO3. #
##############################

MinHeight: 57

MaxHeight: 62

######################
# Extrusion settings #
######################

ExtrudeMode: None

ExtrudeThroughBlocks: AIR

MaxBranchDepth: 10

ExcludedBiomes: All


#######################################################################
# +-----------------------------------------------------------------+ #
# |                      Source block settings                      | #
# +-----------------------------------------------------------------+ #
#######################################################################

SourceBlocks: STONE:1,STONE:3,STONE:5,DIRT:1,DIRT:0,SAND:0,GRASS:0,DIRT:2,STATIONARY_WATER:0,HARD_CLAY,STAINED_CLAY:0,CLAY,SANDSTONE:0,SAND:1,AIR,STONE:0,GRAVEL,LONG_GRASS:0,LONG_GRASS:1,LONG_GRASS:2,DEAD_BUSH,YELLOW_FLOWER:0,RED_ROSE:0,BROWN_MUSHROOM,RED_MUSHROOM,WATER_LILY

MaxPercentageOutsideSourceBlock: 0

OutsideSourceBlock: placeAnyway

DoReplaceBlocks: true

IsOTGPlus: false


#######################################################################
# +-----------------------------------------------------------------+ #
# |                              Blocks                             | #
# +-----------------------------------------------------------------+ #
#######################################################################

Block(-3,1,0,LOG:12)
Block(5,10,2,LEAVES:0)
Block(1,9,0,LEAVES:0)
Block(-4,10,2,LEAVES:0)
Block(1,10,-3,LEAVES:0)
Block(2,10,-2,LEAVES:0)
Block(0,9,-4,LEAVES:0)
Block(-3,10,-2,LEAVES:0)
Block(0,10,-4,LEAVES:0)
Block(-1,10,1,LEAVES:0)
Block(-3,10,2,LOG:12)
Block(-4,10,-1,LEAVES:0)
Block(0,10,1,LEAVES:0)
Block(-1,5,0,LOG:12)
Block(-1,4,0,LOG:12)
Block(-1,7,0,LOG:12)
Block(-1,6,0,LOG:12)
Block(-3,11,2,LEAVES:0)
Block(-1,9,0,LOG:12)
Block(-1,8,0,LOG:12)
Block(3,9,0,LEAVES:0)
Block(-2,9,2,LEAVES:0)
Block(-1,9,-3,LEAVES:0)
Block(-2,10,-3,LEAVES:0)
Block(-2,0,2,LOG:12)
Block(-5,10,2,LEAVES:0)
Block(-1,10,-2,LOG:12)
Block(-1,11,-2,LEAVES:0)
Block(1,10,1,LEAVES:0)
Block(3,10,2,LEAVES:0)
Block(-3,10,5,LEAVES:0)
Block(0,2,1,LOG:12)
Block(0,1,1,LOG:12)
Block(0,9,-1,LEAVES:0)
Block(1,9,1,LEAVES:0)
Block(-3,10,-3,LEAVES:0)
Block(-2,10,-4,LEAVES:0)
Block(3,10,-2,LEAVES:0)
Block(0,1,-1,LOG:12)
Block(0,2,-1,LOG:12)
Block(-2,10,-1,LEAVES:0)
Block(-1,10,-1,LOG:12)
Block(-2,11,-1,LEAVES:0)
Block(1,10,2,LEAVES:0)
Block(0,10,-6,LEAVES:0)
Block(1,11,-1,LEAVES:0)
Block(1,10,-1,LEAVES:0)
Block(-3,11,0,LEAVES:0)
Block(2,11,1,LEAVES:0)
Block(2,10,1,LEAVES:0)
Block(5,10,1,LEAVES:0)
Block(-3,10,0,LEAVES:0)
Block(3,9,1,LEAVES:0)
Block(-2,9,1,LEAVES:0)
Block(-2,10,1,LOG:12)
Block(-1,11,-1,LEAVES:0)
Block(-1,9,-2,LEAVES:0)
Block(-3,0,-1,LOG:12)
Block(4,10,2,LEAVES:0)
Block(-2,11,1,LEAVES:0)
Block(-1,10,-4,LEAVES:0)
Block(0,11,0,LEAVES:0)
Block(2,10,-3,LEAVES:0)
Block(-1,10,2,LEAVES:0)
Block(6,10,0,LEAVES:0)
Block(0,10,-1,LEAVES:0)
Block(0,10,0,LOG:12)
Block(3,11,0,LEAVES:0)
Block(3,10,0,LOG:12)
Block(-3,10,3,LEAVES:0)
Block(0,11,-1,LEAVES:0)
Block(-1,0,3,LOG:12)
Block(2,10,0,LOG:12)
Block(2,11,0,LEAVES:0)
Block(0,9,-2,LEAVES:0)
Block(0,0,-2,LOG:12)
Block(-2,10,-2,LEAVES:0)
Block(-2,11,0,LEAVES:0)
Block(-2,10,0,LOG:12)
Block(4,10,3,LEAVES:0)
Block(-1,10,-3,LOG:12)
Block(-2,10,3,LEAVES:0)
Block(-5,10,1,LEAVES:0)
Block(7,10,1,LEAVES:0)
Block(1,9,-2,LEAVES:0)
Block(-2,9,-1,LEAVES:0)
Block(-1,11,-3,LEAVES:0)
Block(-4,0,0,LOG:12)
Block(-3,9,2,LEAVES:0)
Block(2,9,0,LEAVES:0)
Block(6,10,1,LEAVES:0)
Block(3,10,3,LEAVES:0)
Block(-4,10,-3,LEAVES:0)
Block(-1,2,2,LOG:12)
Block(-1,4,-1,LOG:12)
Block(-1,3,-1,LOG:12)
Block(-3,10,-4,LEAVES:0)
Block(2,10,3,LEAVES:0)
Block(-4,10,3,LEAVES:0)
Block(1,11,0,LEAVES:0)
Block(-2,9,0,LEAVES:0)
Block(3,10,-3,LEAVES:0)
Block(1,10,0,LOG:12)
Block(4,10,0,LEAVES:0)
Block(-2,4,0,LOG:12)
Block(-1,9,-1,LEAVES:0)
Block(-2,3,0,LOG:12)
Block(-2,2,0,LOG:12)
Block(1,10,-4,LEAVES:0)
Block(2,10,-1,LEAVES:0)
Block(2,11,-1,LEAVES:0)
Block(-1,10,-6,LEAVES:0)
Block(-4,10,0,LEAVES:0)
Block(2,9,-1,LEAVES:0)
Block(0,11,-3,LEAVES:0)
Block(-3,10,-1,LEAVES:0)
Block(0,10,2,LEAVES:0)
Block(0,9,1,LEAVES:0)
Block(0,10,-3,LOG:12)
Block(-1,10,0,LOG:12)
Block(-6,10,1,LEAVES:0)
Block(-1,11,0,LEAVES:0)
Block(1,0,1,LOG:12)
Block(-1,1,2,LOG:12)
Block(-4,10,-2,LEAVES:0)
Block(5,10,0,LEAVES:0)
Block(-3,10,1,LOG:12)
Block(-3,11,1,LEAVES:0)
Block(4,10,-1,LEAVES:0)
Block(0,9,-3,LEAVES:0)
Block(2,10,2,LEAVES:0)
Block(4,10,1,LOG:12)
Block(4,11,1,LEAVES:0)
Block(-2,10,2,LEAVES:0)
Block(2,9,1,LEAVES:0)
Block(1,10,-5,LEAVES:0)
Block(-5,10,3,LEAVES:0)
Block(1,9,-1,LEAVES:0)
Block(-3,9,1,LEAVES:0)
Block(-1,10,-5,LEAVES:0)
Block(2,10,-4,LEAVES:0)
Block(3,10,1,LOG:12)
Block(0,11,-2,LEAVES:0)
Block(0,10,-2,LEAVES:0)
Block(1,0,-1,LOG:12)
Block(-6,10,2,LEAVES:0)
Block(-3,10,4,LEAVES:0)
Block(3,11,1,LEAVES:0)
Block(-1,4,1,LOG:12)
Block(-1,3,1,LOG:12)
Block(-1,9,1,LEAVES:0)
Block(-2,10,-5,LEAVES:0)
Block(-4,10,1,LEAVES:0)
Block(3,10,-1,LEAVES:0)
Block(1,10,-2,LEAVES:0)
Block(-2,11,-2,LEAVES:0)
Block(0,10,-5,LEAVES:0)
Block(-5,10,0,LEAVES:0)
Block(1,11,-2,LEAVES:0)
Block(4,9,1,LEAVES:0)
Block(0,9,0,LEAVES:0)
Block(3,10,4,LEAVES:0)

#######################################################################
# +-----------------------------------------------------------------+ #
# |                            BO3 checks                           | #
# +-----------------------------------------------------------------+ #
#######################################################################


#######################################################################
# +-----------------------------------------------------------------+ #
# |                             Branches                            | #
# +-----------------------------------------------------------------+ #
#######################################################################


#######################################################################
# +-----------------------------------------------------------------+ #
# |                             Entities                            | #
# +-----------------------------------------------------------------+ #
#######################################################################


#######################################################################
# +-----------------------------------------------------------------+ #
# |                            Particles                            | #
# +-----------------------------------------------------------------+ #
#######################################################################


#######################################################################
# +-----------------------------------------------------------------+ #
# |                             Spawners                            | #
# +-----------------------------------------------------------------+ #
#######################################################################


#######################################################################
# +-----------------------------------------------------------------+ #
# |                             ModData                             | #
# +-----------------------------------------------------------------+ #
#######################################################################

