
#######################################################################
# +-----------------------------------------------------------------+ #
# |                            BO3 object                           | #
# +-----------------------------------------------------------------+ #
#######################################################################

# This is the config file of a custom object.
# If you add this object correctly to your BiomeConfigs, it will spawn in the world.

# This is the creator of this BO3 object
Author: BO3 BulkEdit (by LanToaster)

# A short description of this BO3 object
Description: This Object was Created with BO3_BulkEdit

# The BO3 version, don't change this! It can be used by external applications to do a version check.
Version: 3

# The settings mode, WriteAll, WriteWithoutComments or WriteDisable. See WorldConfig.
SettingsMode: WriteAll


#######################################################################
# +-----------------------------------------------------------------+ #
# |                          Main settings                          | #
# +-----------------------------------------------------------------+ #
#######################################################################

# This needs to be set to true to spawn the object in the Tree and Sapling resources.
Tree: true

# The frequency of the BO3 from 1 to 200. Tries this many times to spawn this BO3 when using the CustomObject(...) resource.
# Ignored by Tree(..), Sapling(..) and CustomStructure(..)
Frequency: 40

# The rarity of the BO3 from 0 to 100. Each spawn attempt has rarity% chance to succeed when using the CustomObject(...) resource.
# Ignored by Tree(..), Sapling(..) and CustomStructure(..)
Rarity: 100.0

# If you set this to true, the BO3 will be placed with a random rotation.
RotateRandomly: true

# The spawn height of the BO3: randomY, highestBlock or highestSolidBlock.
SpawnHeight: randomY

# The offset from the spawn height to spawn this BO3
# Ex. SpawnHeight = highestSolidBlock, SpawnHeightOffset = 3; This object will spawn 3 blocks above the highest solid block
SpawnHeightOffset: 0

# A random amount to offset the spawn location from the spawn offset height
# Ex. SpawnHeightOffset = 3, SpawnHeightVariance = 3; This object will spawn 3 to 6 blocks above the original spot it would have spawned
SpawnHeightVariance: 0

##############################
# Height Limits for the BO3. #
##############################

# When in randomY mode used as the minimum Y or in atMinY mode as the actual Y to spawn this BO3 at.
MinHeight: 63

# When in randomY mode used as the maximum Y to spawn this BO3 at.
MaxHeight: 255

######################
# Extrusion settings #
######################

# The style of extrusion you wish to use - BottomDown, TopUp, None (Default)
ExtrudeMode: None

# The blocks to extrude your BO3 through
ExtrudeThroughBlocks: AIR

# Objects can have other objects attacthed to it: branches. Branches can also
# have branches attached to it, which can also have branches, etc. This is the
# maximum branch depth for this objects.
MaxBranchDepth: 10

# When spawned with the UseWorld keyword, this BO3 should NOT spawn in the following biomes.
# If you write the BO3 name directly in the BiomeConfigs, this will be ignored.
ExcludedBiomes: All


#######################################################################
# +-----------------------------------------------------------------+ #
# |                      Source block settings                      | #
# +-----------------------------------------------------------------+ #
#######################################################################

# The block(s) the BO3 should spawn in.
SourceBlocks: AIR,GRASS:0,DIRT:0

# The maximum percentage of the BO3 that can be outside the SourceBlock.
# The BO3 won't be placed on a location with more blocks outside the SourceBlock than this percentage.
MaxPercentageOutsideSourceBlock: 5

# What to do when a block is about to be placed outside the SourceBlock? (dontPlace, placeAnyway)
OutsideSourceBlock: dontPlace

# OTG+ settings #
# Legacy setting, rename this file to .BO4 instead. Set this to true to enable the advanced customstructure features of OTG+.
IsOTGPlus: false


#######################################################################
# +-----------------------------------------------------------------+ #
# |                              Blocks                             | #
# +-----------------------------------------------------------------+ #
#######################################################################

# All the blocks used in the BO3 are listed here. Possible blocks:
# Block(x,y,z,id[.data][,nbtfile.nbt)
# RandomBlock(x,y,z,id[:data][,nbtfile.nbt],chance[,id[:data][,nbtfile.nbt],chance[,...]])
#  So RandomBlock(0,0,0,CHEST,chest.nbt,50,CHEST,anotherchest.nbt,100) will spawn a chest at
#  the BO3 origin, and give it a 50% chance to have the contents of chest.nbt, or, if that
#  fails, a 100% percent chance to have the contents of anotherchest.nbt.
# *Note: Unlike Entity() and Spawner(), for Block() .txt files don't work, only .nbt files work.
# MinecraftObject(x,y,z,name) (TODO: This may not work anymore and needs to be tested.
#  Spawns an object in the Mojang NBT structure format. For example, 
#  MinecraftObject(0,0,0,minecraft:igloo/igloo_bottom)
#  spawns the bottom part of an igloo.
Block(-2,0,-4,LOG:3)
Block(-1,0,-4,LOG:3)
Block(0,0,-4,LOG:3)
Block(-3,0,-3,LOG:3)
Block(-2,0,-3,LOG:3)
Block(-1,0,-3,LOG:3)
Block(0,0,-3,LOG:3)
Block(1,0,-3,LOG:3)
Block(-4,0,-2,LOG:3)
Block(-3,0,-2,LOG:3)
Block(-2,0,-2,LOG:3)
Block(-1,0,-2,LOG:3)
Block(0,0,-2,LOG:3)
Block(1,0,-2,LOG:3)
Block(2,0,-2,LOG:3)
Block(-4,0,-1,LOG:3)
Block(-3,0,-1,LOG:3)
Block(-2,0,-1,LOG:3)
Block(-1,0,-1,LOG:3)
Block(0,0,-1,LOG:3)
Block(1,0,-1,LOG:3)
Block(2,0,-1,LOG:3)
Block(3,0,-1,LOG:3)
Block(-4,0,0,LEAVES:3)
Block(-3,0,0,LOG:3)
Block(-2,0,0,LOG:3)
Block(-1,0,0,LOG:3)
Block(0,0,0,LOG:3)
Block(1,0,0,LOG:3)
Block(2,0,0,LOG:3)
Block(3,0,0,LOG:3)
Block(-3,0,1,LOG:3)
Block(-2,0,1,LOG:3)
Block(-1,0,1,LOG:3)
Block(0,0,1,LOG:3)
Block(1,0,1,LOG:3)
Block(2,0,1,LOG:3)
Block(-2,0,2,LOG:3)
Block(-1,0,2,LOG:3)
Block(0,0,2,LOG:3)
Block(1,0,2,LOG:3)
Block(2,0,2,LEAVES:3)
Block(-2,0,3,LOG:3)
Block(-1,0,3,LOG:3)
Block(0,0,3,LOG:3)
Block(1,0,3,LOG:3)
Block(-2,1,-4,LOG:3)
Block(-1,1,-4,LOG:3)
Block(-2,1,-3,LOG:3)
Block(-1,1,-3,LOG:3)
Block(0,1,-3,LOG:3)
Block(-3,1,-2,LOG:3)
Block(-2,1,-2,LOG:3)
Block(-1,1,-2,LOG:3)
Block(0,1,-2,LOG:3)
Block(1,1,-2,LOG:3)
Block(2,1,-2,LOG:3)
Block(-3,1,-1,LOG:3)
Block(-2,1,-1,LOG:3)
Block(-1,1,-1,LOG:3)
Block(0,1,-1,LOG:3)
Block(1,1,-1,LOG:3)
Block(2,1,-1,LOG:3)
Block(-3,1,0,LOG:3)
Block(-2,1,0,LOG:3)
Block(-1,1,0,LOG:3)
Block(0,1,0,LOG:3)
Block(1,1,0,LOG:3)
Block(2,1,0,LOG:3)
Block(-3,1,1,LEAVES:3)
Block(-2,1,1,LOG:3)
Block(-1,1,1,LOG:3)
Block(0,1,1,LOG:3)
Block(1,1,1,LOG:3)
Block(2,1,1,LOG:3)
Block(-1,1,2,LOG:3)
Block(0,1,2,LOG:3)
Block(1,1,2,LOG:3)
Block(2,1,2,LEAVES:3)
Block(-1,1,3,LOG:3)
Block(0,1,3,LOG:3)
Block(-2,2,-3,LOG:3)
Block(-1,2,-3,LOG:3)
Block(0,2,-3,LOG:3)
Block(-2,2,-2,LOG:3)
Block(-1,2,-2,LOG:3)
Block(0,2,-2,LOG:3)
Block(1,2,-2,LOG:3)
Block(-3,2,-1,LOG:3)
Block(-2,2,-1,LOG:3)
Block(-1,2,-1,LOG:3)
Block(0,2,-1,LOG:3)
Block(1,2,-1,LOG:3)
Block(2,2,-1,LOG:3)
Block(-3,2,0,LOG:3)
Block(-2,2,0,LOG:3)
Block(-1,2,0,LOG:3)
Block(0,2,0,LOG:3)
Block(1,2,0,LOG:3)
Block(2,2,0,LOG:3)
Block(-3,2,1,LEAVES:3)
Block(-2,2,1,LOG:3)
Block(-1,2,1,LOG:3)
Block(0,2,1,LOG:3)
Block(1,2,1,LOG:3)
Block(2,2,1,LEAVES:3)
Block(-1,2,2,LOG:3)
Block(0,2,2,LOG:3)
Block(1,2,2,LOG:3)
Block(-1,2,3,LOG:3)
Block(-2,3,-3,LOG:3)
Block(-1,3,-3,LOG:3)
Block(-2,3,-2,LOG:3)
Block(-1,3,-2,LOG:3)
Block(0,3,-2,LOG:3)
Block(1,3,-2,LOG:3)
Block(-3,3,-1,LOG:3)
Block(-2,3,-1,LOG:3)
Block(-1,3,-1,LOG:3)
Block(0,3,-1,LOG:3)
Block(1,3,-1,LOG:3)
Block(2,3,-1,LOG:3)
Block(-4,3,0,LOG:3)
Block(-3,3,0,LOG:3)
Block(-2,3,0,LOG:3)
Block(-1,3,0,LOG:3)
Block(0,3,0,LOG:3)
Block(1,3,0,LOG:3)
Block(2,3,0,LOG:3)
Block(-2,3,1,LOG:3)
Block(-1,3,1,LOG:3)
Block(0,3,1,LOG:3)
Block(1,3,1,LOG:3)
Block(2,3,1,LEAVES:3)
Block(-2,3,2,LEAVES:3)
Block(-1,3,2,LOG:3)
Block(0,3,2,LOG:3)
Block(1,3,2,LOG:3)
Block(-2,4,-5,LEAVES:3)
Block(-2,4,-4,LOG:3)
Block(-1,4,-4,LEAVES:3)
Block(-2,4,-3,LOG:3)
Block(-1,4,-3,LOG:3)
Block(-3,4,-2,LOG:3)
Block(-2,4,-2,LOG:3)
Block(-1,4,-2,LOG:3)
Block(0,4,-2,LOG:3)
Block(-3,4,-1,LOG:3)
Block(-2,4,-1,LOG:3)
Block(-1,4,-1,LOG:3)
Block(0,4,-1,LOG:3)
Block(1,4,-1,LOG:3)
Block(2,4,-1,LOG:3)
Block(-4,4,0,LOG:3)
Block(-3,4,0,LOG:3)
Block(-2,4,0,LOG:3)
Block(-1,4,0,LOG:3)
Block(0,4,0,LOG:3)
Block(1,4,0,LOG:3)
Block(2,4,0,LEAVES:3)
Block(-2,4,1,LOG:3)
Block(-1,4,1,LOG:3)
Block(0,4,1,LOG:3)
Block(1,4,1,LOG:3)
Block(-2,4,2,LOG:3)
Block(-1,4,2,LOG:3)
Block(0,4,2,LOG:3)
Block(-2,4,3,LEAVES:3)
Block(-2,5,-6,LOG:3)
Block(-3,5,-5,LEAVES:3)
Block(-2,5,-5,LOG:3)
Block(-1,5,-5,LOG:3)
Block(-2,5,-4,LOG:3)
Block(-1,5,-4,LOG:3)
Block(0,5,-4,LEAVES:3)
Block(-3,5,-3,LOG:3)
Block(-2,5,-3,LOG:3)
Block(-1,5,-3,LOG:3)
Block(0,5,-3,LOG:3)
Block(-3,5,-2,LOG:3)
Block(-2,5,-2,LOG:3)
Block(-1,5,-2,LOG:3)
Block(0,5,-2,LOG:3)
Block(-4,5,-1,LOG:3)
Block(-3,5,-1,LOG:3)
Block(-2,5,-1,LOG:3)
Block(-1,5,-1,LOG:3)
Block(0,5,-1,LOG:3)
Block(1,5,-1,LOG:3)
Block(-4,5,0,LOG:3)
Block(-3,5,0,LOG:3)
Block(-2,5,0,LOG:3)
Block(-1,5,0,LOG:3)
Block(0,5,0,LOG:3)
Block(1,5,0,LOG:3)
Block(2,5,0,LEAVES:3)
Block(-3,5,1,LOG:3)
Block(-2,5,1,LOG:3)
Block(-1,5,1,LOG:3)
Block(0,5,1,LOG:3)
Block(-2,5,2,LOG:3)
Block(-1,5,2,LOG:3)
Block(0,5,2,LOG:3)
Block(-2,5,3,LEAVES:3)
Block(-1,6,-7,LOG:3)
Block(-3,6,-6,LEAVES:3)
Block(-2,6,-6,LOG:3)
Block(-1,6,-6,LOG:3)
Block(0,6,-6,LOG:3)
Block(-3,6,-5,LOG:3)
Block(-2,6,-5,LOG:3)
Block(-1,6,-5,LOG:3)
Block(0,6,-5,LOG:3)
Block(-3,6,-4,LOG:3)
Block(-2,6,-4,LOG:3)
Block(-1,6,-4,LOG:3)
Block(0,6,-4,LOG:3)
Block(-3,6,-3,LOG:3)
Block(-2,6,-3,LOG:3)
Block(-1,6,-3,LOG:3)
Block(0,6,-3,LOG:3)
Block(1,6,-3,LEAVES:3)
Block(-4,6,-2,LOG:3)
Block(-3,6,-2,LOG:3)
Block(-2,6,-2,LOG:3)
Block(-1,6,-2,LOG:3)
Block(0,6,-2,LOG:3)
Block(-4,6,-1,LOG:3)
Block(-3,6,-1,LOG:3)
Block(-2,6,-1,LOG:3)
Block(-1,6,-1,LOG:3)
Block(0,6,-1,LOG:3)
Block(1,6,-1,LOG:3)
Block(2,6,-1,LEAVES:3)
Block(-4,6,0,LOG:3)
Block(-3,6,0,LOG:3)
Block(-2,6,0,LOG:3)
Block(-1,6,0,LOG:3)
Block(0,6,0,LOG:3)
Block(1,6,0,LOG:3)
Block(-3,6,1,LOG:3)
Block(-2,6,1,LOG:3)
Block(-1,6,1,LOG:3)
Block(0,6,1,LOG:3)
Block(-2,6,2,LOG:3)
Block(-1,6,2,LOG:3)
Block(0,6,2,LOG:3)
Block(-1,6,3,LEAVES:3)
Block(-1,7,-10,LEAVES:3)
Block(0,7,-10,LEAVES:3)
Block(-1,7,-9,LOG:3)
Block(0,7,-9,LOG:3)
Block(-1,7,-8,LOG:3)
Block(0,7,-8,LOG:3)
Block(3,7,-8,LEAVES:3)
Block(-3,7,-7,LEAVES:3)
Block(-2,7,-7,LOG:3)
Block(-1,7,-7,LOG:3)
Block(0,7,-7,LOG:3)
Block(1,7,-7,LOG:3)
Block(-3,7,-6,LOG:3)
Block(-2,7,-6,LOG:3)
Block(-1,7,-6,LOG:3)
Block(0,7,-6,LOG:3)
Block(1,7,-6,LOG:3)
Block(-3,7,-5,LOG:3)
Block(-2,7,-5,LOG:3)
Block(-1,7,-5,LOG:3)
Block(0,7,-5,LOG:3)
Block(1,7,-5,LOG:3)
Block(-3,7,-4,LOG:3)
Block(-2,7,-4,LOG:3)
Block(-1,7,-4,LOG:3)
Block(0,7,-4,LOG:3)
Block(-3,7,-3,LOG:3)
Block(-2,7,-3,LOG:3)
Block(-1,7,-3,LOG:3)
Block(0,7,-3,LOG:3)
Block(-4,7,-2,LOG:3)
Block(-3,7,-2,LOG:3)
Block(-2,7,-2,LOG:3)
Block(-1,7,-2,LOG:3)
Block(0,7,-2,LOG:3)
Block(1,7,-2,LEAVES:3)
Block(-4,7,-1,LOG:3)
Block(-3,7,-1,LOG:3)
Block(-2,7,-1,LOG:3)
Block(-1,7,-1,LOG:3)
Block(0,7,-1,LOG:3)
Block(1,7,-1,LOG:3)
Block(-4,7,0,LOG:3)
Block(-3,7,0,LOG:3)
Block(-2,7,0,LOG:3)
Block(-1,7,0,LOG:3)
Block(0,7,0,LOG:3)
Block(1,7,0,LOG:3)
Block(-4,7,1,LOG:3)
Block(-3,7,1,LOG:3)
Block(-2,7,1,LOG:3)
Block(-1,7,1,LOG:3)
Block(0,7,1,LOG:3)
Block(-3,7,2,LOG:3)
Block(-2,7,2,LOG:3)
Block(-1,7,2,LOG:3)
Block(0,7,2,LOG:3)
Block(0,7,3,LEAVES:3)
Block(0,8,-16,LEAVES:3)
Block(-4,8,-11,LEAVES:3)
Block(0,8,-10,LOG:3)
Block(1,8,-10,LEAVES:3)
Block(-2,8,-9,LEAVES:3)
Block(-1,8,-9,LOG:3)
Block(0,8,-9,LOG:3)
Block(-2,8,-8,LOG:3)
Block(-1,8,-8,LOG:3)
Block(0,8,-8,LOG:3)
Block(1,8,-8,LOG:3)
Block(3,8,-8,LEAVES:3)
Block(-3,8,-7,LEAVES:3)
Block(-2,8,-7,LOG:3)
Block(-1,8,-7,LOG:3)
Block(0,8,-7,LOG:3)
Block(1,8,-7,LOG:3)
Block(-2,8,-6,LOG:3)
Block(-1,8,-6,LOG:3)
Block(0,8,-6,LOG:3)
Block(1,8,-6,LOG:3)
Block(-2,8,-5,LOG:3)
Block(-1,8,-5,LOG:3)
Block(0,8,-5,LOG:3)
Block(-3,8,-4,LOG:3)
Block(-2,8,-4,LOG:3)
Block(-1,8,-4,LOG:3)
Block(-3,8,-3,LOG:3)
Block(-2,8,-3,LOG:3)
Block(-1,8,-3,LOG:3)
Block(-4,8,-2,LOG:3)
Block(-3,8,-2,LOG:3)
Block(-2,8,-2,LOG:3)
Block(-1,8,-2,LOG:3)
Block(0,8,-2,LOG:3)
Block(1,8,-2,LEAVES:3)
Block(-5,8,-1,LOG:3)
Block(-4,8,-1,LOG:3)
Block(-3,8,-1,LOG:3)
Block(-2,8,-1,LOG:3)
Block(-1,8,-1,LOG:3)
Block(0,8,-1,LOG:3)
Block(-4,8,0,LOG:3)
Block(-3,8,0,LOG:3)
Block(-2,8,0,LOG:3)
Block(-1,8,0,LOG:3)
Block(0,8,0,LOG:3)
Block(1,8,0,LOG:3)
Block(-4,8,1,LOG:3)
Block(-3,8,1,LOG:3)
Block(-2,8,1,LOG:3)
Block(-1,8,1,LOG:3)
Block(0,8,1,LOG:3)
Block(-3,8,2,LOG:3)
Block(-2,8,2,LOG:3)
Block(-1,8,2,LOG:3)
Block(0,8,2,LEAVES:3)
Block(0,9,-16,LEAVES:3)
Block(-3,9,-14,LEAVES:3)
Block(3,9,-14,LEAVES:3)
Block(-4,9,-11,LEAVES:3)
Block(0,9,-11,LOG:3)
Block(1,9,-11,LEAVES:3)
Block(4,9,-11,LEAVES:3)
Block(-1,9,-10,LOG:3)
Block(0,9,-10,LOG:3)
Block(1,9,-10,LOG:3)
Block(-2,9,-9,LOG:3)
Block(-1,9,-9,LOG:3)
Block(0,9,-9,LOG:3)
Block(1,9,-9,LOG:3)
Block(-3,9,-8,LEAVES:3)
Block(-2,9,-8,LOG:3)
Block(-1,9,-8,LOG:3)
Block(0,9,-8,LOG:3)
Block(1,9,-8,LOG:3)
Block(3,9,-8,LEAVES:3)
Block(-2,9,-7,LEAVES:3)
Block(-1,9,-7,LOG:3)
Block(0,9,-7,LOG:3)
Block(-1,9,-6,LOG:3)
Block(-2,9,-4,LOG:3)
Block(-3,9,-3,LOG:3)
Block(-2,9,-3,LOG:3)
Block(-1,9,-3,LEAVES:3)
Block(-4,9,-2,LOG:3)
Block(-3,9,-2,LOG:3)
Block(-2,9,-2,LOG:3)
Block(-1,9,-2,LOG:3)
Block(0,9,-2,LEAVES:3)
Block(-5,9,-1,LOG:3)
Block(-4,9,-1,LOG:3)
Block(-3,9,-1,LOG:3)
Block(-2,9,-1,LOG:3)
Block(-1,9,-1,LOG:3)
Block(0,9,-1,LOG:3)
Block(-4,9,0,LOG:3)
Block(-3,9,0,LOG:3)
Block(-2,9,0,LOG:3)
Block(-1,9,0,LOG:3)
Block(0,9,0,LOG:3)
Block(-4,9,1,LOG:3)
Block(-3,9,1,LOG:3)
Block(-2,9,1,LOG:3)
Block(-1,9,1,LOG:3)
Block(0,9,1,LOG:3)
Block(-3,9,2,LOG:3)
Block(-2,9,2,LOG:3)
Block(-1,9,2,LOG:3)
Block(0,9,2,LEAVES:3)
Block(0,10,-16,LEAVES:3)
Block(0,10,-15,LEAVES:3)
Block(-3,10,-14,LEAVES:3)
Block(3,10,-14,LEAVES:3)
Block(-4,10,-11,LEAVES:3)
Block(-1,10,-11,LOG:3)
Block(0,10,-11,LOG:3)
Block(1,10,-11,LOG:3)
Block(2,10,-11,LEAVES:3)
Block(4,10,-11,LEAVES:3)
Block(-1,10,-10,LOG:3)
Block(0,10,-10,LOG:3)
Block(1,10,-10,LOG:3)
Block(-1,10,-9,LOG:3)
Block(0,10,-9,LOG:3)
Block(1,10,-9,LOG:3)
Block(-3,10,-8,LEAVES:3)
Block(-2,10,-8,LEAVES:3)
Block(0,10,-8,LOG:3)
Block(3,10,-8,LEAVES:3)
Block(-3,10,-3,LOG:3)
Block(-2,10,-3,LOG:3)
Block(-1,10,-3,LEAVES:3)
Block(-4,10,-2,LOG:3)
Block(-3,10,-2,LOG:3)
Block(-2,10,-2,LOG:3)
Block(-1,10,-2,LOG:3)
Block(-5,10,-1,LOG:3)
Block(-4,10,-1,LOG:3)
Block(-3,10,-1,LOG:3)
Block(-2,10,-1,LOG:3)
Block(-1,10,-1,LOG:3)
Block(0,10,-1,LOG:3)
Block(-5,10,0,LOG:3)
Block(-4,10,0,LOG:3)
Block(-3,10,0,LOG:3)
Block(-2,10,0,LOG:3)
Block(-1,10,0,LOG:3)
Block(0,10,0,LOG:3)
Block(-4,10,1,LOG:3)
Block(-3,10,1,LOG:3)
Block(-2,10,1,LOG:3)
Block(-1,10,1,LOG:3)
Block(0,10,1,LEAVES:3)
Block(-4,10,2,LOG:3)
Block(-3,10,2,LOG:3)
Block(-2,10,2,LOG:3)
Block(-1,10,2,LOG:3)
Block(0,11,-16,LEAVES:3)
Block(-1,11,-15,LEAVES:3)
Block(0,11,-15,LEAVES:3)
Block(2,11,-15,LEAVES:3)
Block(-3,11,-14,LEAVES:3)
Block(2,11,-14,LEAVES:3)
Block(3,11,-14,LEAVES:3)
Block(0,11,-13,LOG:3)
Block(4,11,-13,LEAVES:3)
Block(0,11,-12,LOG:3)
Block(1,11,-12,LOG:3)
Block(2,11,-12,LEAVES:3)
Block(5,11,-12,LEAVES:3)
Block(-4,11,-11,LEAVES:3)
Block(-1,11,-11,LOG:3)
Block(0,11,-11,LOG:3)
Block(1,11,-11,LOG:3)
Block(4,11,-11,LEAVES:3)
Block(-1,11,-10,LOG:3)
Block(0,11,-10,LOG:3)
Block(4,11,-10,LEAVES:3)
Block(-3,11,-9,LEAVES:3)
Block(0,11,-9,LEAVES:3)
Block(3,11,-9,LEAVES:3)
Block(-2,11,-8,LEAVES:3)
Block(-1,11,-8,LEAVES:3)
Block(0,11,-8,LEAVES:3)
Block(1,11,-8,LEAVES:3)
Block(3,11,-8,LEAVES:3)
Block(0,11,-7,LEAVES:3)
Block(1,11,-7,LEAVES:3)
Block(2,11,-7,LEAVES:3)
Block(-2,11,-4,LEAVES:3)
Block(-3,11,-3,LOG:3)
Block(-2,11,-3,LOG:3)
Block(-5,11,-2,LOG:3)
Block(-4,11,-2,LOG:3)
Block(-3,11,-2,LOG:3)
Block(-2,11,-2,LOG:3)
Block(-1,11,-2,LOG:3)
Block(-5,11,-1,LOG:3)
Block(-4,11,-1,LOG:3)
Block(-3,11,-1,LOG:3)
Block(-2,11,-1,LOG:3)
Block(-1,11,-1,LOG:3)
Block(0,11,-1,LOG:3)
Block(-5,11,0,LOG:3)
Block(-4,11,0,LOG:3)
Block(-3,11,0,LOG:3)
Block(-2,11,0,LOG:3)
Block(-1,11,0,LOG:3)
Block(-4,11,1,LOG:3)
Block(-3,11,1,LOG:3)
Block(-2,11,1,LOG:3)
Block(-1,11,1,LOG:3)
Block(-4,11,2,LOG:3)
Block(-3,11,2,LOG:3)
Block(-2,11,2,LOG:3)
Block(-1,11,2,LEAVES:3)
Block(0,12,-16,LEAVES:3)
Block(-2,12,-15,LEAVES:3)
Block(-1,12,-15,LEAVES:3)
Block(0,12,-15,LEAVES:3)
Block(1,12,-15,LEAVES:3)
Block(2,12,-15,LEAVES:3)
Block(3,12,-15,LEAVES:3)
Block(-3,12,-14,LEAVES:3)
Block(-2,12,-14,LEAVES:3)
Block(-1,12,-14,LEAVES:3)
Block(0,12,-14,LOG:3)
Block(1,12,-14,LEAVES:3)
Block(2,12,-14,LEAVES:3)
Block(3,12,-14,LEAVES:3)
Block(-4,12,-13,LEAVES:3)
Block(-3,12,-13,LEAVES:3)
Block(0,12,-13,LEAVES:3)
Block(1,12,-13,LEAVES:3)
Block(2,12,-13,LEAVES:3)
Block(3,12,-13,LEAVES:3)
Block(4,12,-13,LEAVES:3)
Block(5,12,-13,LEAVES:3)
Block(-4,12,-12,LEAVES:3)
Block(-3,12,-12,LEAVES:3)
Block(0,12,-12,LOG:3)
Block(1,12,-12,LEAVES:3)
Block(2,12,-12,LEAVES:3)
Block(3,12,-12,LEAVES:3)
Block(4,12,-12,LEAVES:3)
Block(5,12,-12,LEAVES:3)
Block(-4,12,-11,LEAVES:3)
Block(-1,12,-11,LOG:3)
Block(0,12,-11,LOG:3)
Block(1,12,-11,LOG:3)
Block(2,12,-11,LOG:3)
Block(4,12,-11,LEAVES:3)
Block(5,12,-11,LEAVES:3)
Block(-4,12,-10,LEAVES:3)
Block(-3,12,-10,LEAVES:3)
Block(0,12,-10,LOG:3)
Block(1,12,-10,LEAVES:3)
Block(3,12,-10,LEAVES:3)
Block(4,12,-10,LEAVES:3)
Block(-4,12,-9,LEAVES:3)
Block(-3,12,-9,LEAVES:3)
Block(-2,12,-9,LEAVES:3)
Block(-1,12,-9,LEAVES:3)
Block(0,12,-9,LEAVES:3)
Block(2,12,-9,LEAVES:3)
Block(3,12,-9,LEAVES:3)
Block(4,12,-9,LEAVES:3)
Block(-3,12,-8,LEAVES:3)
Block(-1,12,-8,LEAVES:3)
Block(0,12,-8,LEAVES:3)
Block(1,12,-8,LEAVES:3)
Block(2,12,-8,LEAVES:3)
Block(-2,12,-7,LEAVES:3)
Block(-1,12,-7,LEAVES:3)
Block(1,12,-7,LEAVES:3)
Block(2,12,-7,LEAVES:3)
Block(3,12,-7,LEAVES:3)
Block(-3,12,-4,LEAVES:3)
Block(-3,12,-3,LOG:3)
Block(-2,12,-3,LOG:3)
Block(-5,12,-2,LOG:3)
Block(-4,12,-2,LOG:3)
Block(-3,12,-2,LOG:3)
Block(-2,12,-2,LOG:3)
Block(-1,12,-2,LOG:3)
Block(-5,12,-1,LOG:3)
Block(-4,12,-1,LOG:3)
Block(-3,12,-1,LOG:3)
Block(-2,12,-1,LOG:3)
Block(-1,12,-1,LOG:3)
Block(0,12,-1,LOG:3)
Block(-5,12,0,LOG:3)
Block(-4,12,0,LOG:3)
Block(-3,12,0,LOG:3)
Block(-2,12,0,LOG:3)
Block(-1,12,0,LOG:3)
Block(-4,12,1,LOG:3)
Block(-3,12,1,LOG:3)
Block(-2,12,1,LOG:3)
Block(-4,12,2,LOG:3)
Block(-3,12,2,LOG:3)
Block(-2,12,2,LEAVES:3)
Block(-1,12,2,LEAVES:3)
Block(0,13,-15,LEAVES:3)
Block(1,13,-15,LEAVES:3)
Block(2,13,-15,LEAVES:3)
Block(-3,13,-14,LEAVES:3)
Block(-2,13,-14,LEAVES:3)
Block(-1,13,-14,LEAVES:3)
Block(0,13,-14,LEAVES:3)
Block(1,13,-14,LEAVES:3)
Block(2,13,-14,LEAVES:3)
Block(3,13,-14,LEAVES:3)
Block(-3,13,-13,LEAVES:3)
Block(-2,13,-13,LEAVES:3)
Block(-1,13,-13,LEAVES:3)
Block(0,13,-13,LEAVES:3)
Block(1,13,-13,LEAVES:3)
Block(2,13,-13,LEAVES:3)
Block(3,13,-13,LEAVES:3)
Block(4,13,-13,LEAVES:3)
Block(-4,13,-12,LEAVES:3)
Block(-3,13,-12,LEAVES:3)
Block(-2,13,-12,LEAVES:3)
Block(-1,13,-12,LEAVES:3)
Block(0,13,-12,LOG:3)
Block(1,13,-12,LEAVES:3)
Block(2,13,-12,LEAVES:3)
Block(3,13,-12,LEAVES:3)
Block(4,13,-12,LEAVES:3)
Block(5,13,-12,LEAVES:3)
Block(-4,13,-11,LEAVES:3)
Block(-3,13,-11,LEAVES:3)
Block(-2,13,-11,LOG:3)
Block(-1,13,-11,LOG:3)
Block(0,13,-11,LOG:3)
Block(1,13,-11,LOG:3)
Block(2,13,-11,LEAVES:3)
Block(3,13,-11,LOG:3)
Block(4,13,-11,LEAVES:3)
Block(-3,13,-10,LEAVES:3)
Block(-2,13,-10,LEAVES:3)
Block(-1,13,-10,LEAVES:3)
Block(0,13,-10,LOG:3)
Block(1,13,-10,LEAVES:3)
Block(3,13,-10,LEAVES:3)
Block(4,13,-10,LEAVES:3)
Block(-3,13,-9,LEAVES:3)
Block(-2,13,-9,LEAVES:3)
Block(-1,13,-9,LEAVES:3)
Block(0,13,-9,LEAVES:3)
Block(1,13,-9,LEAVES:3)
Block(2,13,-9,LEAVES:3)
Block(3,13,-9,LEAVES:3)
Block(-2,13,-8,LEAVES:3)
Block(-1,13,-8,LEAVES:3)
Block(0,13,-8,LEAVES:3)
Block(1,13,-8,LEAVES:3)
Block(2,13,-8,LEAVES:3)
Block(3,13,-8,LEAVES:3)
Block(-1,13,-7,LEAVES:3)
Block(0,13,-7,LEAVES:3)
Block(1,13,-7,LEAVES:3)
Block(2,13,-7,LEAVES:3)
Block(0,13,-6,LEAVES:3)
Block(1,13,-6,LEAVES:3)
Block(-4,13,-4,LEAVES:3)
Block(-4,13,-3,LOG:3)
Block(-3,13,-3,LOG:3)
Block(-2,13,-3,LOG:3)
Block(-5,13,-2,LOG:3)
Block(-4,13,-2,LOG:3)
Block(-3,13,-2,LOG:3)
Block(-2,13,-2,LOG:3)
Block(-1,13,-2,LOG:3)
Block(-6,13,-1,LOG:3)
Block(-5,13,-1,LOG:3)
Block(-4,13,-1,LOG:3)
Block(-3,13,-1,LOG:3)
Block(-2,13,-1,LOG:3)
Block(-1,13,-1,LOG:3)
Block(0,13,-1,LOG:3)
Block(-5,13,0,LOG:3)
Block(-4,13,0,LOG:3)
Block(-3,13,0,LOG:3)
Block(-2,13,0,LOG:3)
Block(-1,13,0,LOG:3)
Block(-4,13,1,LOG:3)
Block(-3,13,1,LOG:3)
Block(-2,13,1,LOG:3)
Block(-4,13,2,LOG:3)
Block(-3,13,2,LOG:3)
Block(-2,13,2,LEAVES:3)
Block(-2,13,3,LEAVES:3)
Block(-2,14,-14,LEAVES:3)
Block(0,14,-14,LEAVES:3)
Block(1,14,-14,LEAVES:3)
Block(-3,14,-13,LEAVES:3)
Block(-1,14,-13,LEAVES:3)
Block(0,14,-13,LEAVES:3)
Block(1,14,-13,LEAVES:3)
Block(2,14,-13,LEAVES:3)
Block(3,14,-13,LEAVES:3)
Block(-2,14,-12,LEAVES:3)
Block(0,14,-12,LEAVES:3)
Block(1,14,-12,LEAVES:3)
Block(2,14,-12,LEAVES:3)
Block(4,14,-12,LEAVES:3)
Block(-3,14,-11,LEAVES:3)
Block(-2,14,-11,LEAVES:3)
Block(-1,14,-11,LEAVES:3)
Block(0,14,-11,LEAVES:3)
Block(1,14,-11,LEAVES:3)
Block(2,14,-11,LEAVES:3)
Block(3,14,-11,LEAVES:3)
Block(4,14,-11,LEAVES:3)
Block(-2,14,-10,LEAVES:3)
Block(0,14,-10,LEAVES:3)
Block(1,14,-10,LEAVES:3)
Block(2,14,-10,LEAVES:3)
Block(3,14,-10,LEAVES:3)
Block(-2,14,-9,LEAVES:3)
Block(-1,14,-9,LEAVES:3)
Block(0,14,-9,LEAVES:3)
Block(2,14,-9,LEAVES:3)
Block(-1,14,-8,LEAVES:3)
Block(0,14,-8,LEAVES:3)
Block(1,14,-8,LEAVES:3)
Block(-5,14,-3,LEAVES:3)
Block(-4,14,-3,LOG:3)
Block(-3,14,-3,LOG:3)
Block(-2,14,-3,LOG:3)
Block(-5,14,-2,LOG:3)
Block(-4,14,-2,LOG:3)
Block(-3,14,-2,LOG:3)
Block(-2,14,-2,LOG:3)
Block(-1,14,-2,LOG:3)
Block(-6,14,-1,LOG:3)
Block(-5,14,-1,LOG:3)
Block(-4,14,-1,LOG:3)
Block(-3,14,-1,LOG:3)
Block(-2,14,-1,LOG:3)
Block(-1,14,-1,LOG:3)
Block(-5,14,0,LOG:3)
Block(-4,14,0,LOG:3)
Block(-3,14,0,LOG:3)
Block(-2,14,0,LOG:3)
Block(-1,14,0,LOG:3)
Block(-5,14,1,LOG:3)
Block(-4,14,1,LOG:3)
Block(-3,14,1,LOG:3)
Block(-2,14,1,LOG:3)
Block(-4,14,2,LEAVES:3)
Block(-3,14,2,LOG:3)
Block(-2,14,2,LOG:3)
Block(-3,14,3,LEAVES:3)
Block(0,15,-14,LEAVES:3)
Block(0,15,-13,LEAVES:3)
Block(1,15,-13,LEAVES:3)
Block(-1,15,-12,LEAVES:3)
Block(0,15,-12,LEAVES:3)
Block(2,15,-12,LEAVES:3)
Block(-2,15,-11,LEAVES:3)
Block(1,15,-11,LEAVES:3)
Block(2,15,-11,LEAVES:3)
Block(-2,15,-10,LEAVES:3)
Block(0,15,-10,LEAVES:3)
Block(1,15,-10,LEAVES:3)
Block(2,15,-10,LEAVES:3)
Block(3,15,-10,LEAVES:3)
Block(-1,15,-9,LEAVES:3)
Block(0,15,-9,LEAVES:3)
Block(-5,15,-3,LEAVES:3)
Block(-4,15,-3,LOG:3)
Block(-3,15,-3,LOG:3)
Block(-2,15,-3,LOG:3)
Block(-5,15,-2,LOG:3)
Block(-4,15,-2,LOG:3)
Block(-3,15,-2,LOG:3)
Block(-2,15,-2,LOG:3)
Block(-1,15,-2,LOG:3)
Block(-6,15,-1,LOG:3)
Block(-5,15,-1,LOG:3)
Block(-4,15,-1,LOG:3)
Block(-3,15,-1,LOG:3)
Block(-2,15,-1,LOG:3)
Block(-1,15,-1,LOG:3)
Block(-6,15,0,LOG:3)
Block(-5,15,0,LOG:3)
Block(-4,15,0,LOG:3)
Block(-3,15,0,LOG:3)
Block(-2,15,0,LOG:3)
Block(-1,15,0,LOG:3)
Block(-5,15,1,LOG:3)
Block(-4,15,1,LOG:3)
Block(-3,15,1,LOG:3)
Block(-2,15,1,LOG:3)
Block(-1,15,1,LOG:3)
Block(-4,15,2,LEAVES:3)
Block(-3,15,2,LOG:3)
Block(-2,15,2,LOG:3)
Block(-5,16,-4,LEAVES:3)
Block(-6,16,-3,LEAVES:3)
Block(-5,16,-3,LOG:3)
Block(-4,16,-3,LOG:3)
Block(-3,16,-3,LOG:3)
Block(-2,16,-3,LOG:3)
Block(-6,16,-2,LOG:3)
Block(-5,16,-2,LOG:3)
Block(-4,16,-2,LOG:3)
Block(-3,16,-2,LOG:3)
Block(-2,16,-2,LOG:3)
Block(-6,16,-1,LOG:3)
Block(-5,16,-1,LOG:3)
Block(-4,16,-1,LOG:3)
Block(-3,16,-1,LOG:3)
Block(-2,16,-1,LOG:3)
Block(-1,16,-1,LOG:3)
Block(-6,16,0,LOG:3)
Block(-5,16,0,LOG:3)
Block(-4,16,0,LOG:3)
Block(-3,16,0,LOG:3)
Block(-2,16,0,LOG:3)
Block(-1,16,0,LOG:3)
Block(-5,16,1,LOG:3)
Block(-4,16,1,LOG:3)
Block(-3,16,1,LOG:3)
Block(-2,16,1,LOG:3)
Block(-1,16,1,LOG:3)
Block(0,16,1,LOG:3)
Block(-5,16,2,LEAVES:3)
Block(-3,16,2,LOG:3)
Block(-2,16,2,LOG:3)
Block(-1,16,2,LOG:3)
Block(0,16,2,LOG:3)
Block(1,16,2,LEAVES:3)
Block(0,16,3,LOG:3)
Block(1,16,3,LEAVES:3)
Block(13,16,4,LEAVES:3)
Block(4,16,10,LEAVES:3)
Block(-4,17,-4,LEAVES:3)
Block(-6,17,-3,LEAVES:3)
Block(-5,17,-3,LOG:3)
Block(-4,17,-3,LOG:3)
Block(-3,17,-3,LOG:3)
Block(-6,17,-2,LOG:3)
Block(-5,17,-2,LOG:3)
Block(-4,17,-2,LOG:3)
Block(-3,17,-2,LOG:3)
Block(-2,17,-2,LOG:3)
Block(-7,17,-1,LOG:3)
Block(-6,17,-1,LOG:3)
Block(-5,17,-1,LOG:3)
Block(-4,17,-1,LOG:3)
Block(-3,17,-1,LOG:3)
Block(-2,17,-1,LOG:3)
Block(-1,17,-1,LOG:3)
Block(-6,17,0,LOG:3)
Block(-5,17,0,LOG:3)
Block(-4,17,0,LOG:3)
Block(-3,17,0,LOG:3)
Block(-2,17,0,LOG:3)
Block(-1,17,0,LOG:3)
Block(0,17,0,LOG:3)
Block(-5,17,1,LOG:3)
Block(-4,17,1,LOG:3)
Block(-3,17,1,LOG:3)
Block(-2,17,1,LOG:3)
Block(-1,17,1,LOG:3)
Block(0,17,1,LOG:3)
Block(1,17,1,LOG:3)
Block(2,17,1,LEAVES:3)
Block(-5,17,2,LEAVES:3)
Block(-2,17,2,LOG:3)
Block(-1,17,2,LOG:3)
Block(0,17,2,LOG:3)
Block(1,17,2,LOG:3)
Block(-1,17,3,LOG:3)
Block(0,17,3,LOG:3)
Block(1,17,3,LOG:3)
Block(0,17,4,LOG:3)
Block(1,17,4,LEAVES:3)
Block(13,17,4,LEAVES:3)
Block(4,17,10,LEAVES:3)
Block(-4,18,-4,LOG:3)
Block(-3,18,-4,LEAVES:3)
Block(-7,18,-3,LEAVES:3)
Block(-6,18,-3,LOG:3)
Block(-5,18,-3,LOG:3)
Block(-4,18,-3,LOG:3)
Block(-3,18,-3,LOG:3)
Block(-6,18,-2,LOG:3)
Block(-5,18,-2,LOG:3)
Block(-4,18,-2,LOG:3)
Block(-3,18,-2,LOG:3)
Block(-2,18,-2,LOG:3)
Block(-7,18,-1,LOG:3)
Block(-6,18,-1,LOG:3)
Block(-5,18,-1,LOG:3)
Block(-4,18,-1,LOG:3)
Block(-3,18,-1,LOG:3)
Block(-2,18,-1,LOG:3)
Block(-1,18,-1,LOG:3)
Block(-6,18,0,LOG:3)
Block(-5,18,0,LOG:3)
Block(-4,18,0,LOG:3)
Block(-3,18,0,LOG:3)
Block(-2,18,0,LOG:3)
Block(-1,18,0,LOG:3)
Block(1,18,0,LEAVES:3)
Block(-6,18,1,LEAVES:3)
Block(-4,18,1,LOG:3)
Block(-3,18,1,LOG:3)
Block(-2,18,1,LOG:3)
Block(-1,18,1,LOG:3)
Block(0,18,1,LOG:3)
Block(1,18,1,LOG:3)
Block(-1,18,2,LOG:3)
Block(0,18,2,LOG:3)
Block(1,18,2,LOG:3)
Block(-1,18,3,LOG:3)
Block(0,18,3,LOG:3)
Block(1,18,3,LOG:3)
Block(2,18,3,LOG:3)
Block(-1,18,4,LOG:3)
Block(0,18,4,LOG:3)
Block(1,18,4,LOG:3)
Block(2,18,4,LOG:3)
Block(13,18,4,LEAVES:3)
Block(2,18,5,LOG:3)
Block(4,18,6,LEAVES:3)
Block(4,18,7,LEAVES:3)
Block(4,18,10,LEAVES:3)
Block(8,18,15,LEAVES:3)
Block(-5,19,-4,LOG:3)
Block(-4,19,-4,LOG:3)
Block(-3,19,-4,LEAVES:3)
Block(-7,19,-3,LEAVES:3)
Block(-6,19,-3,LOG:3)
Block(-5,19,-3,LOG:3)
Block(-4,19,-3,LOG:3)
Block(-3,19,-3,LOG:3)
Block(-2,19,-3,LOG:3)
Block(-7,19,-2,LOG:3)
Block(-6,19,-2,LOG:3)
Block(-5,19,-2,LOG:3)
Block(-4,19,-2,LOG:3)
Block(-3,19,-2,LOG:3)
Block(-2,19,-2,LOG:3)
Block(-7,19,-1,LOG:3)
Block(-6,19,-1,LOG:3)
Block(-5,19,-1,LOG:3)
Block(-4,19,-1,LOG:3)
Block(-3,19,-1,LOG:3)
Block(-2,19,-1,LOG:3)
Block(-6,19,0,LOG:3)
Block(-5,19,0,LOG:3)
Block(-4,19,0,LOG:3)
Block(-3,19,0,LOG:3)
Block(-2,19,0,LOG:3)
Block(-1,19,0,LOG:3)
Block(0,19,0,LEAVES:3)
Block(-7,19,1,LEAVES:3)
Block(-6,19,1,LEAVES:3)
Block(-2,19,1,LOG:3)
Block(-1,19,1,LOG:3)
Block(0,19,1,LOG:3)
Block(-1,19,2,LOG:3)
Block(0,19,2,LOG:3)
Block(1,19,2,LOG:3)
Block(2,19,2,LOG:3)
Block(7,19,2,LEAVES:3)
Block(10,19,2,LEAVES:3)
Block(-1,19,3,LOG:3)
Block(0,19,3,LOG:3)
Block(1,19,3,LOG:3)
Block(2,19,3,LOG:3)
Block(0,19,4,LOG:3)
Block(1,19,4,LOG:3)
Block(2,19,4,LOG:3)
Block(13,19,4,LEAVES:3)
Block(1,19,5,LOG:3)
Block(2,19,5,LOG:3)
Block(3,19,5,LOG:3)
Block(2,19,6,LOG:3)
Block(3,19,6,LOG:3)
Block(4,19,6,LOG:3)
Block(5,19,6,LEAVES:3)
Block(14,19,6,LEAVES:3)
Block(3,19,7,LOG:3)
Block(4,19,7,LOG:3)
Block(5,19,7,LOG:3)
Block(3,19,8,LEAVES:3)
Block(4,19,8,LOG:3)
Block(5,19,8,LOG:3)
Block(4,19,10,LEAVES:3)
Block(7,19,10,LEAVES:3)
Block(14,19,11,LEAVES:3)
Block(5,19,13,LEAVES:3)
Block(8,19,15,LEAVES:3)
Block(-5,20,-4,LOG:3)
Block(-4,20,-4,LOG:3)
Block(-3,20,-4,LOG:3)
Block(-2,20,-4,LEAVES:3)
Block(-6,20,-3,LOG:3)
Block(-5,20,-3,LOG:3)
Block(-4,20,-3,LOG:3)
Block(-3,20,-3,LOG:3)
Block(-2,20,-3,LOG:3)
Block(-8,20,-2,LEAVES:3)
Block(-7,20,-2,LOG:3)
Block(-6,20,-2,LOG:3)
Block(-5,20,-2,LOG:3)
Block(-4,20,-2,LOG:3)
Block(-3,20,-2,LOG:3)
Block(-2,20,-2,LOG:3)
Block(-7,20,-1,LOG:3)
Block(-6,20,-1,LOG:3)
Block(-5,20,-1,LOG:3)
Block(-4,20,-1,LOG:3)
Block(-3,20,-1,LOG:3)
Block(-2,20,-1,LOG:3)
Block(-1,20,-1,LEAVES:3)
Block(-8,20,0,LOG:3)
Block(-7,20,0,LOG:3)
Block(-6,20,0,LOG:3)
Block(-5,20,0,LOG:3)
Block(-4,20,0,LOG:3)
Block(-3,20,0,LOG:3)
Block(-1,20,0,LEAVES:3)
Block(-8,20,1,LOG:3)
Block(-7,20,1,LOG:3)
Block(-6,20,1,LOG:3)
Block(-8,20,2,LEAVES:3)
Block(-7,20,2,LOG:3)
Block(7,20,2,LEAVES:3)
Block(10,20,2,LEAVES:3)
Block(0,20,3,LOG:3)
Block(1,20,3,LOG:3)
Block(2,20,3,LOG:3)
Block(1,20,4,LOG:3)
Block(2,20,4,LOG:3)
Block(3,20,4,LOG:3)
Block(13,20,4,LEAVES:3)
Block(1,20,5,LOG:3)
Block(2,20,5,LOG:3)
Block(3,20,5,LOG:3)
Block(4,20,5,LOG:3)
Block(1,20,6,LOG:3)
Block(2,20,6,LOG:3)
Block(3,20,6,LOG:3)
Block(4,20,6,LOG:3)
Block(5,20,6,LOG:3)
Block(6,20,6,LEAVES:3)
Block(11,20,6,LEAVES:3)
Block(14,20,6,LEAVES:3)
Block(2,20,7,LOG:3)
Block(3,20,7,LOG:3)
Block(4,20,7,LOG:3)
Block(5,20,7,LOG:3)
Block(6,20,7,LOG:3)
Block(2,20,8,LEAVES:3)
Block(3,20,8,LOG:3)
Block(4,20,8,LOG:3)
Block(5,20,8,LOG:3)
Block(6,20,8,LOG:3)
Block(7,20,8,LOG:3)
Block(3,20,9,LEAVES:3)
Block(4,20,9,LOG:3)
Block(5,20,9,LOG:3)
Block(15,20,9,LEAVES:3)
Block(4,20,10,LEAVES:3)
Block(7,20,10,LEAVES:3)
Block(14,20,11,LEAVES:3)
Block(5,20,13,LEAVES:3)
Block(12,20,14,LEAVES:3)
Block(8,20,15,LEAVES:3)
Block(-4,21,-5,LOG:3)
Block(-5,21,-4,LOG:3)
Block(-4,21,-4,LOG:3)
Block(-3,21,-4,LOG:3)
Block(-2,21,-4,LOG:3)
Block(-1,21,-4,LEAVES:3)
Block(-6,21,-3,LOG:3)
Block(-5,21,-3,LOG:3)
Block(-4,21,-3,LOG:3)
Block(-3,21,-3,LOG:3)
Block(-2,21,-3,LOG:3)
Block(-6,21,-2,LOG:3)
Block(-5,21,-2,LOG:3)
Block(-4,21,-2,LOG:3)
Block(-3,21,-2,LOG:3)
Block(-2,21,-2,LOG:3)
Block(-8,21,-1,LEAVES:3)
Block(-7,21,-1,LOG:3)
Block(-6,21,-1,LOG:3)
Block(-5,21,-1,LOG:3)
Block(-4,21,-1,LOG:3)
Block(-3,21,-1,LOG:3)
Block(-2,21,-1,LEAVES:3)
Block(-8,21,0,LOG:3)
Block(-7,21,0,LOG:3)
Block(-6,21,0,LOG:3)
Block(-5,21,0,LOG:3)
Block(-4,21,0,LOG:3)
Block(-9,21,1,LEAVES:3)
Block(-8,21,1,LOG:3)
Block(-7,21,1,LOG:3)
Block(-6,21,1,LOG:3)
Block(-5,21,1,LOG:3)
Block(-9,21,2,LOG:3)
Block(-8,21,2,LOG:3)
Block(-7,21,2,LOG:3)
Block(-6,21,2,LOG:3)
Block(7,21,2,LEAVES:3)
Block(10,21,2,LEAVES:3)
Block(-8,21,3,LOG:3)
Block(2,21,4,LOG:3)
Block(13,21,4,LEAVES:3)
Block(2,21,5,LOG:3)
Block(3,21,5,LOG:3)
Block(2,21,6,LOG:3)
Block(3,21,6,LOG:3)
Block(4,21,6,LOG:3)
Block(5,21,6,LEAVES:3)
Block(11,21,6,LEAVES:3)
Block(14,21,6,LEAVES:3)
Block(3,21,7,LOG:3)
Block(4,21,7,LOG:3)
Block(5,21,7,LOG:3)
Block(6,21,7,LOG:3)
Block(7,21,7,LOG:3)
Block(3,21,8,LEAVES:3)
Block(4,21,8,LOG:3)
Block(5,21,8,LOG:3)
Block(6,21,8,LOG:3)
Block(7,21,8,LOG:3)
Block(8,21,8,LOG:3)
Block(5,21,9,LOG:3)
Block(6,21,9,LOG:3)
Block(7,21,9,LOG:3)
Block(15,21,9,LEAVES:3)
Block(4,21,10,LEAVES:3)
Block(7,21,10,LEAVES:3)
Block(14,21,11,LEAVES:3)
Block(5,21,13,LEAVES:3)
Block(12,21,14,LEAVES:3)
Block(8,21,15,LEAVES:3)
Block(-4,22,-5,LOG:3)
Block(-3,22,-5,LOG:3)
Block(-5,22,-4,LOG:3)
Block(-4,22,-4,LOG:3)
Block(-3,22,-4,LOG:3)
Block(-2,22,-4,LOG:3)
Block(-1,22,-4,LEAVES:3)
Block(-6,22,-3,LOG:3)
Block(-5,22,-3,LOG:3)
Block(-4,22,-3,LOG:3)
Block(-3,22,-3,LOG:3)
Block(-2,22,-3,LOG:3)
Block(-1,22,-3,LOG:3)
Block(-6,22,-2,LOG:3)
Block(-5,22,-2,LOG:3)
Block(-4,22,-2,LOG:3)
Block(-3,22,-2,LOG:3)
Block(-2,22,-2,LOG:3)
Block(-8,22,-1,LEAVES:3)
Block(-6,22,-1,LOG:3)
Block(-5,22,-1,LOG:3)
Block(-4,22,-1,LOG:3)
Block(-3,22,-1,LOG:3)
Block(-9,22,0,LOG:3)
Block(-8,22,0,LOG:3)
Block(-7,22,0,LOG:3)
Block(-6,22,0,LOG:3)
Block(-5,22,0,LOG:3)
Block(-10,22,1,LEAVES:3)
Block(-9,22,1,LOG:3)
Block(-8,22,1,LOG:3)
Block(-7,22,1,LOG:3)
Block(-6,22,1,LOG:3)
Block(8,22,1,LEAVES:3)
Block(-9,22,2,LOG:3)
Block(-8,22,2,LOG:3)
Block(-7,22,2,LOG:3)
Block(6,22,2,LEAVES:3)
Block(7,22,2,LEAVES:3)
Block(8,22,2,LEAVES:3)
Block(9,22,2,LEAVES:3)
Block(10,22,2,LEAVES:3)
Block(-10,22,3,LOG:3)
Block(-9,22,3,LOG:3)
Block(-8,22,3,LOG:3)
Block(-7,22,3,LOG:3)
Block(5,22,3,LEAVES:3)
Block(6,22,3,LEAVES:3)
Block(7,22,3,LEAVES:3)
Block(8,22,3,LEAVES:3)
Block(11,22,3,LEAVES:3)
Block(-9,22,4,LOG:3)
Block(-8,22,4,LOG:3)
Block(5,22,4,LEAVES:3)
Block(6,22,4,LEAVES:3)
Block(8,22,4,LEAVES:3)
Block(9,22,4,LEAVES:3)
Block(12,22,4,LEAVES:3)
Block(13,22,4,LEAVES:3)
Block(3,22,5,LEAVES:3)
Block(4,22,5,LEAVES:3)
Block(11,22,5,LEAVES:3)
Block(12,22,5,LEAVES:3)
Block(13,22,5,LEAVES:3)
Block(14,22,5,LEAVES:3)
Block(4,22,6,LEAVES:3)
Block(11,22,6,LEAVES:3)
Block(13,22,6,LEAVES:3)
Block(14,22,6,LEAVES:3)
Block(-13,22,7,LEAVES:3)
Block(3,22,7,LEAVES:3)
Block(4,22,7,LEAVES:3)
Block(5,22,7,LEAVES:3)
Block(6,22,7,LOG:3)
Block(7,22,7,LOG:3)
Block(8,22,7,LOG:3)
Block(13,22,7,LEAVES:3)
Block(14,22,7,LEAVES:3)
Block(15,22,7,LEAVES:3)
Block(4,22,8,LEAVES:3)
Block(5,22,8,LOG:3)
Block(6,22,8,LOG:3)
Block(7,22,8,LOG:3)
Block(8,22,8,LOG:3)
Block(9,22,8,LOG:3)
Block(14,22,8,LEAVES:3)
Block(3,22,9,LEAVES:3)
Block(4,22,9,LEAVES:3)
Block(5,22,9,LEAVES:3)
Block(6,22,9,LOG:3)
Block(7,22,9,LOG:3)
Block(8,22,9,LOG:3)
Block(10,22,9,LEAVES:3)
Block(15,22,9,LEAVES:3)
Block(4,22,10,LEAVES:3)
Block(5,22,10,LEAVES:3)
Block(7,22,10,LEAVES:3)
Block(10,22,10,LEAVES:3)
Block(15,22,10,LEAVES:3)
Block(4,22,11,LEAVES:3)
Block(5,22,11,LEAVES:3)
Block(12,22,11,LEAVES:3)
Block(13,22,11,LEAVES:3)
Block(14,22,11,LEAVES:3)
Block(5,22,12,LEAVES:3)
Block(12,22,12,LEAVES:3)
Block(4,22,13,LEAVES:3)
Block(5,22,13,LEAVES:3)
Block(6,22,13,LEAVES:3)
Block(11,22,13,LEAVES:3)
Block(5,22,14,LEAVES:3)
Block(6,22,14,LEAVES:3)
Block(7,22,14,LEAVES:3)
Block(9,22,14,LEAVES:3)
Block(10,22,14,LEAVES:3)
Block(12,22,14,LEAVES:3)
Block(8,22,15,LEAVES:3)
Block(9,22,15,LEAVES:3)
Block(-4,23,-6,LOG:3)
Block(-5,23,-5,LOG:3)
Block(-4,23,-5,LOG:3)
Block(-3,23,-5,LOG:3)
Block(-2,23,-5,LOG:3)
Block(-6,23,-4,LOG:3)
Block(-5,23,-4,LOG:3)
Block(-4,23,-4,LOG:3)
Block(-3,23,-4,LOG:3)
Block(-2,23,-4,LOG:3)
Block(0,23,-4,LEAVES:3)
Block(-6,23,-3,LOG:3)
Block(-5,23,-3,LOG:3)
Block(-4,23,-3,LOG:3)
Block(-3,23,-3,LOG:3)
Block(-2,23,-3,LOG:3)
Block(-1,23,-3,LOG:3)
Block(-6,23,-2,LOG:3)
Block(-5,23,-2,LOG:3)
Block(-4,23,-2,LOG:3)
Block(-3,23,-2,LOG:3)
Block(-2,23,-2,LOG:3)
Block(-1,23,-2,LOG:3)
Block(-6,23,-1,LOG:3)
Block(-5,23,-1,LOG:3)
Block(-4,23,-1,LOG:3)
Block(-3,23,-1,LOG:3)
Block(-2,23,-1,LOG:3)
Block(-9,23,0,LEAVES:3)
Block(-8,23,0,LOG:3)
Block(-7,23,0,LEAVES:3)
Block(-6,23,0,LEAVES:3)
Block(-9,23,1,LOG:3)
Block(-8,23,1,LOG:3)
Block(-7,23,1,LOG:3)
Block(7,23,1,LEAVES:3)
Block(8,23,1,LEAVES:3)
Block(9,23,1,LEAVES:3)
Block(-10,23,2,LOG:3)
Block(-9,23,2,LOG:3)
Block(-8,23,2,LOG:3)
Block(-7,23,2,LOG:3)
Block(5,23,2,LEAVES:3)
Block(6,23,2,LEAVES:3)
Block(7,23,2,LEAVES:3)
Block(9,23,2,LEAVES:3)
Block(10,23,2,LEAVES:3)
Block(11,23,2,LEAVES:3)
Block(-10,23,3,LOG:3)
Block(-9,23,3,LOG:3)
Block(-8,23,3,LOG:3)
Block(-7,23,3,LOG:3)
Block(5,23,3,LEAVES:3)
Block(6,23,3,LEAVES:3)
Block(7,23,3,LEAVES:3)
Block(8,23,3,LEAVES:3)
Block(9,23,3,LEAVES:3)
Block(10,23,3,LEAVES:3)
Block(11,23,3,LEAVES:3)
Block(12,23,3,LEAVES:3)
Block(13,23,3,LEAVES:3)
Block(-10,23,4,LOG:3)
Block(-9,23,4,LOG:3)
Block(-8,23,4,LOG:3)
Block(-7,23,4,LOG:3)
Block(4,23,4,LEAVES:3)
Block(5,23,4,LEAVES:3)
Block(6,23,4,LEAVES:3)
Block(7,23,4,LOG:3)
Block(8,23,4,LOG:3)
Block(9,23,4,LEAVES:3)
Block(10,23,4,LEAVES:3)
Block(11,23,4,LEAVES:3)
Block(13,23,4,LEAVES:3)
Block(14,23,4,LEAVES:3)
Block(-10,23,5,LEAVES:3)
Block(-9,23,5,LOG:3)
Block(4,23,5,LEAVES:3)
Block(5,23,5,LEAVES:3)
Block(7,23,5,LOG:3)
Block(9,23,5,LEAVES:3)
Block(10,23,5,LEAVES:3)
Block(11,23,5,LEAVES:3)
Block(12,23,5,LEAVES:3)
Block(13,23,5,LEAVES:3)
Block(14,23,5,LEAVES:3)
Block(-9,23,6,LEAVES:3)
Block(3,23,6,LEAVES:3)
Block(4,23,6,LEAVES:3)
Block(7,23,6,LOG:3)
Block(11,23,6,LEAVES:3)
Block(13,23,6,LEAVES:3)
Block(14,23,6,LEAVES:3)
Block(-13,23,7,LEAVES:3)
Block(3,23,7,LEAVES:3)
Block(4,23,7,LEAVES:3)
Block(5,23,7,LEAVES:3)
Block(6,23,7,LEAVES:3)
Block(7,23,7,LEAVES:3)
Block(8,23,7,LOG:3)
Block(12,23,7,LEAVES:3)
Block(13,23,7,LEAVES:3)
Block(14,23,7,LEAVES:3)
Block(15,23,7,LEAVES:3)
Block(3,23,8,LEAVES:3)
Block(4,23,8,LEAVES:3)
Block(5,23,8,LEAVES:3)
Block(6,23,8,LEAVES:3)
Block(7,23,8,LEAVES:3)
Block(8,23,8,LEAVES:3)
Block(9,23,8,LOG:3)
Block(10,23,8,LOG:3)
Block(13,23,8,LEAVES:3)
Block(14,23,8,LEAVES:3)
Block(15,23,8,LEAVES:3)
Block(3,23,9,LEAVES:3)
Block(4,23,9,LEAVES:3)
Block(5,23,9,LEAVES:3)
Block(6,23,9,LEAVES:3)
Block(7,23,9,LEAVES:3)
Block(8,23,9,LEAVES:3)
Block(9,23,9,LEAVES:3)
Block(10,23,9,LEAVES:3)
Block(14,23,9,LEAVES:3)
Block(15,23,9,LEAVES:3)
Block(3,23,10,LEAVES:3)
Block(4,23,10,LEAVES:3)
Block(5,23,10,LEAVES:3)
Block(6,23,10,LEAVES:3)
Block(7,23,10,LEAVES:3)
Block(8,23,10,LEAVES:3)
Block(10,23,10,LEAVES:3)
Block(12,23,10,LEAVES:3)
Block(13,23,10,LEAVES:3)
Block(14,23,10,LEAVES:3)
Block(15,23,10,LEAVES:3)
Block(-9,23,11,LEAVES:3)
Block(4,23,11,LEAVES:3)
Block(5,23,11,LEAVES:3)
Block(6,23,11,LEAVES:3)
Block(13,23,11,LEAVES:3)
Block(14,23,11,LEAVES:3)
Block(15,23,11,LEAVES:3)
Block(4,23,12,LEAVES:3)
Block(5,23,12,LEAVES:3)
Block(6,23,12,LEAVES:3)
Block(7,23,12,LEAVES:3)
Block(11,23,12,LEAVES:3)
Block(12,23,12,LEAVES:3)
Block(13,23,12,LEAVES:3)
Block(14,23,12,LEAVES:3)
Block(4,23,13,LEAVES:3)
Block(5,23,13,LEAVES:3)
Block(6,23,13,LEAVES:3)
Block(7,23,13,LEAVES:3)
Block(8,23,13,LEAVES:3)
Block(10,23,13,LEAVES:3)
Block(11,23,13,LEAVES:3)
Block(12,23,13,LEAVES:3)
Block(13,23,13,LEAVES:3)
Block(4,23,14,LEAVES:3)
Block(6,23,14,LEAVES:3)
Block(7,23,14,LEAVES:3)
Block(8,23,14,LEAVES:3)
Block(9,23,14,LEAVES:3)
Block(10,23,14,LEAVES:3)
Block(11,23,14,LEAVES:3)
Block(12,23,14,LEAVES:3)
Block(6,23,15,LEAVES:3)
Block(7,23,15,LEAVES:3)
Block(8,23,15,LEAVES:3)
Block(9,23,15,LEAVES:3)
Block(10,23,15,LEAVES:3)
Block(11,23,15,LEAVES:3)
Block(-4,24,-6,LOG:3)
Block(-3,24,-6,LOG:3)
Block(-5,24,-5,LOG:3)
Block(-4,24,-5,LOG:3)
Block(-3,24,-5,LOG:3)
Block(-2,24,-5,LOG:3)
Block(-6,24,-4,LOG:3)
Block(-5,24,-4,LOG:3)
Block(-4,24,-4,LOG:3)
Block(-3,24,-4,LOG:3)
Block(-2,24,-4,LOG:3)
Block(-1,24,-4,LOG:3)
Block(0,24,-4,LEAVES:3)
Block(-6,24,-3,LOG:3)
Block(-5,24,-3,LOG:3)
Block(-4,24,-3,LOG:3)
Block(-3,24,-3,LOG:3)
Block(-2,24,-3,LOG:3)
Block(-1,24,-3,LOG:3)
Block(0,24,-3,LOG:3)
Block(-6,24,-2,LOG:3)
Block(-5,24,-2,LOG:3)
Block(-4,24,-2,LOG:3)
Block(-3,24,-2,LOG:3)
Block(-2,24,-2,LOG:3)
Block(-1,24,-2,LOG:3)
Block(-6,24,-1,LEAVES:3)
Block(-5,24,-1,LOG:3)
Block(-4,24,-1,LOG:3)
Block(-3,24,-1,LOG:3)
Block(-2,24,-1,LOG:3)
Block(-5,24,0,LEAVES:3)
Block(-11,24,1,LEAVES:3)
Block(8,24,1,LEAVES:3)
Block(-10,24,2,LOG:3)
Block(-9,24,2,LOG:3)
Block(-8,24,2,LOG:3)
Block(6,24,2,LEAVES:3)
Block(7,24,2,LEAVES:3)
Block(8,24,2,LEAVES:3)
Block(9,24,2,LEAVES:3)
Block(-10,24,3,LOG:3)
Block(-9,24,3,LOG:3)
Block(-8,24,3,LOG:3)
Block(-7,24,3,LOG:3)
Block(5,24,3,LEAVES:3)
Block(6,24,3,LEAVES:3)
Block(7,24,3,LEAVES:3)
Block(8,24,3,LEAVES:3)
Block(9,24,3,LEAVES:3)
Block(10,24,3,LEAVES:3)
Block(11,24,3,LEAVES:3)
Block(-10,24,4,LOG:3)
Block(-9,24,4,LOG:3)
Block(-8,24,4,LOG:3)
Block(6,24,4,LEAVES:3)
Block(7,24,4,LEAVES:3)
Block(9,24,4,LEAVES:3)
Block(10,24,4,LEAVES:3)
Block(11,24,4,LEAVES:3)
Block(12,24,4,LEAVES:3)
Block(-15,24,5,LEAVES:3)
Block(-11,24,5,LEAVES:3)
Block(-10,24,5,LOG:3)
Block(-9,24,5,LOG:3)
Block(-8,24,5,LOG:3)
Block(4,24,5,LEAVES:3)
Block(5,24,5,LEAVES:3)
Block(6,24,5,LEAVES:3)
Block(7,24,5,LEAVES:3)
Block(8,24,5,LEAVES:3)
Block(9,24,5,LEAVES:3)
Block(10,24,5,LEAVES:3)
Block(11,24,5,LEAVES:3)
Block(12,24,5,LEAVES:3)
Block(13,24,5,LEAVES:3)
Block(14,24,5,LEAVES:3)
Block(-9,24,6,LOG:3)
Block(-8,24,6,LEAVES:3)
Block(4,24,6,LEAVES:3)
Block(5,24,6,LEAVES:3)
Block(6,24,6,LEAVES:3)
Block(7,24,6,LEAVES:3)
Block(8,24,6,LEAVES:3)
Block(9,24,6,LEAVES:3)
Block(10,24,6,LEAVES:3)
Block(11,24,6,LEAVES:3)
Block(13,24,6,LEAVES:3)
Block(14,24,6,LEAVES:3)
Block(-13,24,7,LEAVES:3)
Block(-6,24,7,LEAVES:3)
Block(3,24,7,LEAVES:3)
Block(4,24,7,LEAVES:3)
Block(5,24,7,LEAVES:3)
Block(6,24,7,LEAVES:3)
Block(7,24,7,LEAVES:3)
Block(8,24,7,LOG:3)
Block(9,24,7,LEAVES:3)
Block(10,24,7,LEAVES:3)
Block(11,24,7,LEAVES:3)
Block(12,24,7,LEAVES:3)
Block(13,24,7,LEAVES:3)
Block(14,24,7,LEAVES:3)
Block(3,24,8,LEAVES:3)
Block(4,24,8,LEAVES:3)
Block(5,24,8,LEAVES:3)
Block(6,24,8,LEAVES:3)
Block(7,24,8,LOG:3)
Block(8,24,8,LOG:3)
Block(9,24,8,LOG:3)
Block(10,24,8,LEAVES:3)
Block(11,24,8,LOG:3)
Block(12,24,8,LOG:3)
Block(14,24,8,LEAVES:3)
Block(15,24,8,LEAVES:3)
Block(3,24,9,LEAVES:3)
Block(4,24,9,LEAVES:3)
Block(5,24,9,LEAVES:3)
Block(6,24,9,LEAVES:3)
Block(7,24,9,LEAVES:3)
Block(8,24,9,LOG:3)
Block(9,24,9,LEAVES:3)
Block(10,24,9,LEAVES:3)
Block(11,24,9,LEAVES:3)
Block(12,24,9,LOG:3)
Block(13,24,9,LEAVES:3)
Block(14,24,9,LEAVES:3)
Block(15,24,9,LEAVES:3)
Block(-11,24,10,LEAVES:3)
Block(-7,24,10,LEAVES:3)
Block(4,24,10,LEAVES:3)
Block(5,24,10,LEAVES:3)
Block(6,24,10,LEAVES:3)
Block(7,24,10,LEAVES:3)
Block(8,24,10,LEAVES:3)
Block(9,24,10,LEAVES:3)
Block(10,24,10,LEAVES:3)
Block(11,24,10,LEAVES:3)
Block(12,24,10,LEAVES:3)
Block(13,24,10,LEAVES:3)
Block(14,24,10,LEAVES:3)
Block(15,24,10,LEAVES:3)
Block(-9,24,11,LEAVES:3)
Block(4,24,11,LEAVES:3)
Block(5,24,11,LEAVES:3)
Block(6,24,11,LEAVES:3)
Block(7,24,11,LEAVES:3)
Block(8,24,11,LEAVES:3)
Block(10,24,11,LEAVES:3)
Block(12,24,11,LEAVES:3)
Block(13,24,11,LEAVES:3)
Block(14,24,11,LEAVES:3)
Block(4,24,12,LEAVES:3)
Block(5,24,12,LEAVES:3)
Block(7,24,12,LEAVES:3)
Block(8,24,12,LEAVES:3)
Block(10,24,12,LEAVES:3)
Block(11,24,12,LEAVES:3)
Block(12,24,12,LEAVES:3)
Block(13,24,12,LEAVES:3)
Block(14,24,12,LEAVES:3)
Block(4,24,13,LEAVES:3)
Block(5,24,13,LEAVES:3)
Block(6,24,13,LEAVES:3)
Block(7,24,13,LEAVES:3)
Block(8,24,13,LEAVES:3)
Block(9,24,13,LEAVES:3)
Block(10,24,13,LEAVES:3)
Block(12,24,13,LEAVES:3)
Block(13,24,13,LEAVES:3)
Block(5,24,14,LEAVES:3)
Block(6,24,14,LEAVES:3)
Block(7,24,14,LEAVES:3)
Block(8,24,14,LEAVES:3)
Block(9,24,14,LEAVES:3)
Block(10,24,14,LEAVES:3)
Block(7,24,15,LEAVES:3)
Block(8,24,15,LEAVES:3)
Block(9,24,15,LEAVES:3)
Block(-4,25,-6,LOG:3)
Block(-3,25,-6,LOG:3)
Block(-5,25,-5,LOG:3)
Block(-4,25,-5,LOG:3)
Block(-3,25,-5,LOG:3)
Block(-2,25,-5,LOG:3)
Block(-1,25,-5,LOG:3)
Block(-6,25,-4,LOG:3)
Block(-5,25,-4,LOG:3)
Block(-4,25,-4,LOG:3)
Block(-3,25,-4,LOG:3)
Block(-2,25,-4,LOG:3)
Block(-1,25,-4,LOG:3)
Block(1,25,-4,LEAVES:3)
Block(-6,25,-3,LOG:3)
Block(-5,25,-3,LOG:3)
Block(-4,25,-3,LOG:3)
Block(-3,25,-3,LOG:3)
Block(-2,25,-3,LOG:3)
Block(-1,25,-3,LOG:3)
Block(0,25,-3,LOG:3)
Block(1,25,-3,LOG:3)
Block(2,25,-3,LEAVES:3)
Block(-6,25,-2,LEAVES:3)
Block(-5,25,-2,LOG:3)
Block(-4,25,-2,LOG:3)
Block(-3,25,-2,LOG:3)
Block(-2,25,-2,LOG:3)
Block(-1,25,-2,LOG:3)
Block(0,25,-2,LOG:3)
Block(-4,25,-1,LOG:3)
Block(-3,25,-1,LOG:3)
Block(-2,25,-1,LOG:3)
Block(-4,25,0,LEAVES:3)
Block(-11,25,1,LEAVES:3)
Block(-9,25,2,LOG:3)
Block(-13,25,3,LEAVES:3)
Block(-10,25,3,LOG:3)
Block(-9,25,3,LOG:3)
Block(7,25,3,LEAVES:3)
Block(8,25,3,LEAVES:3)
Block(9,25,3,LEAVES:3)
Block(10,25,3,LEAVES:3)
Block(-11,25,4,LEAVES:3)
Block(-10,25,4,LOG:3)
Block(-9,25,4,LOG:3)
Block(-8,25,4,LOG:3)
Block(-6,25,4,LEAVES:3)
Block(6,25,4,LEAVES:3)
Block(8,25,4,LEAVES:3)
Block(9,25,4,LEAVES:3)
Block(11,25,4,LEAVES:3)
Block(-15,25,5,LEAVES:3)
Block(-11,25,5,LOG:3)
Block(-10,25,5,LOG:3)
Block(-9,25,5,LOG:3)
Block(-8,25,5,LOG:3)
Block(6,25,5,LEAVES:3)
Block(7,25,5,LEAVES:3)
Block(8,25,5,LEAVES:3)
Block(9,25,5,LEAVES:3)
Block(10,25,5,LEAVES:3)
Block(11,25,5,LEAVES:3)
Block(12,25,5,LEAVES:3)
Block(-10,25,6,LOG:3)
Block(-9,25,6,LOG:3)
Block(-8,25,6,LOG:3)
Block(5,25,6,LEAVES:3)
Block(7,25,6,LEAVES:3)
Block(8,25,6,LEAVES:3)
Block(9,25,6,LEAVES:3)
Block(10,25,6,LEAVES:3)
Block(12,25,6,LEAVES:3)
Block(13,25,6,LEAVES:3)
Block(-13,25,7,LEAVES:3)
Block(-8,25,7,LEAVES:3)
Block(-6,25,7,LEAVES:3)
Block(5,25,7,LEAVES:3)
Block(6,25,7,LEAVES:3)
Block(7,25,7,LEAVES:3)
Block(8,25,7,LEAVES:3)
Block(9,25,7,LEAVES:3)
Block(10,25,7,LEAVES:3)
Block(11,25,7,LEAVES:3)
Block(13,25,7,LEAVES:3)
Block(3,25,8,LEAVES:3)
Block(4,25,8,LEAVES:3)
Block(6,25,8,LEAVES:3)
Block(7,25,8,LEAVES:3)
Block(8,25,8,LEAVES:3)
Block(9,25,8,LEAVES:3)
Block(10,25,8,LEAVES:3)
Block(11,25,8,LEAVES:3)
Block(12,25,8,LEAVES:3)
Block(14,25,8,LEAVES:3)
Block(5,25,9,LEAVES:3)
Block(6,25,9,LEAVES:3)
Block(7,25,9,LEAVES:3)
Block(8,25,9,LEAVES:3)
Block(9,25,9,LEAVES:3)
Block(10,25,9,LEAVES:3)
Block(11,25,9,LEAVES:3)
Block(12,25,9,LEAVES:3)
Block(13,25,9,LEAVES:3)
Block(14,25,9,LEAVES:3)
Block(-11,25,10,LEAVES:3)
Block(-7,25,10,LEAVES:3)
Block(4,25,10,LEAVES:3)
Block(7,25,10,LEAVES:3)
Block(8,25,10,LEAVES:3)
Block(9,25,10,LEAVES:3)
Block(10,25,10,LEAVES:3)
Block(12,25,10,LEAVES:3)
Block(13,25,10,LEAVES:3)
Block(-9,25,11,LEAVES:3)
Block(5,25,11,LEAVES:3)
Block(6,25,11,LEAVES:3)
Block(7,25,11,LEAVES:3)
Block(8,25,11,LEAVES:3)
Block(9,25,11,LEAVES:3)
Block(10,25,11,LEAVES:3)
Block(11,25,11,LEAVES:3)
Block(12,25,11,LEAVES:3)
Block(13,25,11,LEAVES:3)
Block(14,25,11,LEAVES:3)
Block(5,25,12,LEAVES:3)
Block(7,25,12,LEAVES:3)
Block(8,25,12,LEAVES:3)
Block(9,25,12,LEAVES:3)
Block(10,25,12,LEAVES:3)
Block(11,25,12,LEAVES:3)
Block(12,25,12,LEAVES:3)
Block(13,25,12,LEAVES:3)
Block(5,25,13,LEAVES:3)
Block(6,25,13,LEAVES:3)
Block(7,25,13,LEAVES:3)
Block(9,25,13,LEAVES:3)
Block(12,25,13,LEAVES:3)
Block(7,25,14,LEAVES:3)
Block(8,25,14,LEAVES:3)
Block(-4,26,-6,LOG:3)
Block(-3,26,-6,LOG:3)
Block(-5,26,-5,LOG:3)
Block(-4,26,-5,LOG:3)
Block(-3,26,-5,LOG:3)
Block(-2,26,-5,LOG:3)
Block(-1,26,-5,LOG:3)
Block(0,26,-5,LOG:3)
Block(1,26,-5,LEAVES:3)
Block(-6,26,-4,LOG:3)
Block(-5,26,-4,LOG:3)
Block(-4,26,-4,LOG:3)
Block(-3,26,-4,LOG:3)
Block(-2,26,-4,LOG:3)
Block(-1,26,-4,LOG:3)
Block(0,26,-4,LOG:3)
Block(1,26,-4,LOG:3)
Block(-6,26,-3,LEAVES:3)
Block(-5,26,-3,LOG:3)
Block(-4,26,-3,LOG:3)
Block(-3,26,-3,LOG:3)
Block(-2,26,-3,LOG:3)
Block(-1,26,-3,LOG:3)
Block(0,26,-3,LOG:3)
Block(1,26,-3,LOG:3)
Block(2,26,-3,LOG:3)
Block(3,26,-3,LOG:3)
Block(-5,26,-2,LOG:3)
Block(-4,26,-2,LOG:3)
Block(-3,26,-2,LOG:3)
Block(-2,26,-2,LOG:3)
Block(-1,26,-2,LOG:3)
Block(0,26,-2,LOG:3)
Block(1,26,-2,LEAVES:3)
Block(-4,26,-1,LEAVES:3)
Block(-3,26,-1,LOG:3)
Block(-2,26,-1,LOG:3)
Block(-11,26,1,LEAVES:3)
Block(-8,26,1,LEAVES:3)
Block(-13,26,3,LEAVES:3)
Block(-12,26,4,LEAVES:3)
Block(-11,26,4,LOG:3)
Block(-10,26,4,LOG:3)
Block(-9,26,4,LOG:3)
Block(-6,26,4,LEAVES:3)
Block(8,26,4,LEAVES:3)
Block(9,26,4,LEAVES:3)
Block(-15,26,5,LEAVES:3)
Block(-11,26,5,LOG:3)
Block(-10,26,5,LOG:3)
Block(-9,26,5,LOG:3)
Block(-8,26,5,LOG:3)
Block(7,26,5,LEAVES:3)
Block(8,26,5,LEAVES:3)
Block(9,26,5,LEAVES:3)
Block(10,26,5,LEAVES:3)
Block(11,26,5,LEAVES:3)
Block(-11,26,6,LOG:3)
Block(-10,26,6,LOG:3)
Block(-9,26,6,LOG:3)
Block(-8,26,6,LOG:3)
Block(7,26,6,LEAVES:3)
Block(8,26,6,LEAVES:3)
Block(10,26,6,LEAVES:3)
Block(11,26,6,LEAVES:3)
Block(12,26,6,LEAVES:3)
Block(-13,26,7,LEAVES:3)
Block(-9,26,7,LOG:3)
Block(-8,26,7,LEAVES:3)
Block(-6,26,7,LEAVES:3)
Block(6,26,7,LEAVES:3)
Block(8,26,7,LEAVES:3)
Block(9,26,7,LEAVES:3)
Block(10,26,7,LEAVES:3)
Block(12,26,7,LEAVES:3)
Block(5,26,8,LEAVES:3)
Block(6,26,8,LEAVES:3)
Block(7,26,8,LEAVES:3)
Block(8,26,8,LEAVES:3)
Block(9,26,8,LEAVES:3)
Block(10,26,8,LEAVES:3)
Block(11,26,8,LEAVES:3)
Block(12,26,8,LEAVES:3)
Block(13,26,8,LEAVES:3)
Block(5,26,9,LEAVES:3)
Block(6,26,9,LEAVES:3)
Block(7,26,9,LEAVES:3)
Block(9,26,9,LEAVES:3)
Block(10,26,9,LEAVES:3)
Block(12,26,9,LEAVES:3)
Block(13,26,9,LEAVES:3)
Block(-11,26,10,LEAVES:3)
Block(-7,26,10,LEAVES:3)
Block(6,26,10,LEAVES:3)
Block(7,26,10,LEAVES:3)
Block(8,26,10,LEAVES:3)
Block(9,26,10,LEAVES:3)
Block(10,26,10,LEAVES:3)
Block(11,26,10,LEAVES:3)
Block(12,26,10,LEAVES:3)
Block(-10,26,11,LEAVES:3)
Block(-9,26,11,LEAVES:3)
Block(6,26,11,LEAVES:3)
Block(8,26,11,LEAVES:3)
Block(9,26,11,LEAVES:3)
Block(10,26,11,LEAVES:3)
Block(11,26,11,LEAVES:3)
Block(13,26,11,LEAVES:3)
Block(7,26,12,LEAVES:3)
Block(8,26,12,LEAVES:3)
Block(11,26,12,LEAVES:3)
Block(12,26,12,LEAVES:3)
Block(9,26,13,LEAVES:3)
Block(10,26,13,LEAVES:3)
Block(-4,27,-6,LOG:3)
Block(-3,27,-6,LOG:3)
Block(-2,27,-6,LOG:3)
Block(-5,27,-5,LOG:3)
Block(-4,27,-5,LOG:3)
Block(-3,27,-5,LOG:3)
Block(-2,27,-5,LOG:3)
Block(-1,27,-5,LOG:3)
Block(0,27,-5,LOG:3)
Block(1,27,-5,LEAVES:3)
Block(-6,27,-4,LEAVES:3)
Block(-5,27,-4,LOG:3)
Block(-4,27,-4,LOG:3)
Block(-3,27,-4,LOG:3)
Block(-2,27,-4,LOG:3)
Block(-1,27,-4,LOG:3)
Block(0,27,-4,LOG:3)
Block(1,27,-4,LOG:3)
Block(2,27,-4,LOG:3)
Block(3,27,-4,LOG:3)
Block(-5,27,-3,LOG:3)
Block(-4,27,-3,LOG:3)
Block(-3,27,-3,LOG:3)
Block(-2,27,-3,LOG:3)
Block(-1,27,-3,LOG:3)
Block(0,27,-3,LOG:3)
Block(1,27,-3,LOG:3)
Block(2,27,-3,LOG:3)
Block(3,27,-3,LOG:3)
Block(4,27,-3,LOG:3)
Block(-4,27,-2,LOG:3)
Block(-3,27,-2,LOG:3)
Block(-2,27,-2,LOG:3)
Block(-1,27,-2,LOG:3)
Block(0,27,-2,LOG:3)
Block(1,27,-2,LOG:3)
Block(2,27,-2,LOG:3)
Block(3,27,-2,LOG:3)
Block(4,27,-2,LOG:3)
Block(5,27,-2,LOG:3)
Block(-4,27,-1,LEAVES:3)
Block(-3,27,-1,LOG:3)
Block(1,27,-1,LEAVES:3)
Block(4,27,-1,LOG:3)
Block(-11,27,1,LEAVES:3)
Block(-9,27,1,LEAVES:3)
Block(-8,27,1,LEAVES:3)
Block(-12,27,2,LEAVES:3)
Block(-10,27,2,LEAVES:3)
Block(-14,27,3,LEAVES:3)
Block(-13,27,3,LEAVES:3)
Block(-10,27,3,LEAVES:3)
Block(-9,27,3,LEAVES:3)
Block(-8,27,3,LEAVES:3)
Block(-7,27,3,LEAVES:3)
Block(-14,27,4,LEAVES:3)
Block(-12,27,4,LEAVES:3)
Block(-11,27,4,LEAVES:3)
Block(-10,27,4,LOG:3)
Block(-8,27,4,LEAVES:3)
Block(-6,27,4,LEAVES:3)
Block(-15,27,5,LEAVES:3)
Block(-14,27,5,LEAVES:3)
Block(-11,27,5,LOG:3)
Block(-10,27,5,LOG:3)
Block(-9,27,5,LOG:3)
Block(-8,27,5,LEAVES:3)
Block(-6,27,5,LEAVES:3)
Block(-5,27,5,LEAVES:3)
Block(8,27,5,LEAVES:3)
Block(-14,27,6,LEAVES:3)
Block(-11,27,6,LOG:3)
Block(-10,27,6,LOG:3)
Block(-9,27,6,LOG:3)
Block(-8,27,6,LOG:3)
Block(-6,27,6,LEAVES:3)
Block(-5,27,6,LEAVES:3)
Block(1,27,6,LEAVES:3)
Block(9,27,6,LEAVES:3)
Block(10,27,6,LEAVES:3)
Block(-13,27,7,LEAVES:3)
Block(-10,27,7,LOG:3)
Block(-9,27,7,LOG:3)
Block(-6,27,7,LEAVES:3)
Block(8,27,7,LEAVES:3)
Block(9,27,7,LEAVES:3)
Block(-12,27,8,LEAVES:3)
Block(-9,27,8,LEAVES:3)
Block(-7,27,8,LEAVES:3)
Block(7,27,8,LEAVES:3)
Block(9,27,8,LEAVES:3)
Block(12,27,8,LEAVES:3)
Block(-13,27,9,LEAVES:3)
Block(-12,27,9,LEAVES:3)
Block(-11,27,9,LEAVES:3)
Block(-9,27,9,LEAVES:3)
Block(-8,27,9,LEAVES:3)
Block(-7,27,9,LEAVES:3)
Block(7,27,9,LEAVES:3)
Block(10,27,9,LEAVES:3)
Block(12,27,9,LEAVES:3)
Block(-12,27,10,LEAVES:3)
Block(-11,27,10,LEAVES:3)
Block(-10,27,10,LEAVES:3)
Block(-7,27,10,LEAVES:3)
Block(8,27,10,LEAVES:3)
Block(9,27,10,LEAVES:3)
Block(10,27,10,LEAVES:3)
Block(11,27,10,LEAVES:3)
Block(-11,27,11,LEAVES:3)
Block(-10,27,11,LEAVES:3)
Block(-9,27,11,LEAVES:3)
Block(9,27,11,LEAVES:3)
Block(10,27,11,LEAVES:3)
Block(8,28,-11,LEAVES:3)
Block(-4,28,-6,LOG:3)
Block(-3,28,-6,LOG:3)
Block(-2,28,-6,LOG:3)
Block(-5,28,-5,LEAVES:3)
Block(-4,28,-5,LOG:3)
Block(-3,28,-5,LOG:3)
Block(-2,28,-5,LOG:3)
Block(-1,28,-5,LOG:3)
Block(0,28,-5,LOG:3)
Block(1,28,-5,LOG:3)
Block(2,28,-5,LEAVES:3)
Block(-5,28,-4,LOG:3)
Block(-4,28,-4,LOG:3)
Block(-3,28,-4,LOG:3)
Block(-2,28,-4,LOG:3)
Block(-1,28,-4,LOG:3)
Block(0,28,-4,LOG:3)
Block(1,28,-4,LOG:3)
Block(2,28,-4,LOG:3)
Block(3,28,-4,LOG:3)
Block(4,28,-4,LOG:3)
Block(-5,28,-3,LOG:3)
Block(-4,28,-3,LOG:3)
Block(-3,28,-3,LOG:3)
Block(-2,28,-3,LOG:3)
Block(-1,28,-3,LOG:3)
Block(0,28,-3,LOG:3)
Block(1,28,-3,LOG:3)
Block(2,28,-3,LOG:3)
Block(3,28,-3,LOG:3)
Block(4,28,-3,LOG:3)
Block(5,28,-3,LOG:3)
Block(6,28,-3,LEAVES:3)
Block(-4,28,-2,LOG:3)
Block(-3,28,-2,LOG:3)
Block(-2,28,-2,LOG:3)
Block(-1,28,-2,LOG:3)
Block(0,28,-2,LOG:3)
Block(1,28,-2,LOG:3)
Block(2,28,-2,LOG:3)
Block(3,28,-2,LOG:3)
Block(4,28,-2,LOG:3)
Block(5,28,-2,LOG:3)
Block(6,28,-2,LOG:3)
Block(7,28,-2,LEAVES:3)
Block(14,28,-2,LEAVES:3)
Block(-3,28,-1,LEAVES:3)
Block(1,28,-1,LEAVES:3)
Block(3,28,-1,LOG:3)
Block(4,28,-1,LOG:3)
Block(5,28,-1,LOG:3)
Block(-12,28,1,LEAVES:3)
Block(-11,28,1,LEAVES:3)
Block(-10,28,1,LEAVES:3)
Block(-9,28,1,LEAVES:3)
Block(-13,28,2,LEAVES:3)
Block(-12,28,2,LEAVES:3)
Block(-11,28,2,LEAVES:3)
Block(-10,28,2,LEAVES:3)
Block(-9,28,2,LEAVES:3)
Block(-8,28,2,LEAVES:3)
Block(-7,28,2,LEAVES:3)
Block(-14,28,3,LEAVES:3)
Block(-13,28,3,LEAVES:3)
Block(-12,28,3,LEAVES:3)
Block(-11,28,3,LEAVES:3)
Block(-10,28,3,LEAVES:3)
Block(-9,28,3,LEAVES:3)
Block(-8,28,3,LEAVES:3)
Block(-7,28,3,LEAVES:3)
Block(-6,28,3,LEAVES:3)
Block(-15,28,4,LEAVES:3)
Block(-13,28,4,LEAVES:3)
Block(-12,28,4,LEAVES:3)
Block(-11,28,4,LEAVES:3)
Block(-10,28,4,LEAVES:3)
Block(-9,28,4,LEAVES:3)
Block(-8,28,4,LEAVES:3)
Block(-7,28,4,LEAVES:3)
Block(-6,28,4,LEAVES:3)
Block(-5,28,4,LEAVES:3)
Block(-15,28,5,LEAVES:3)
Block(-14,28,5,LOG:3)
Block(-13,28,5,LOG:3)
Block(-11,28,5,LEAVES:3)
Block(-10,28,5,LEAVES:3)
Block(-9,28,5,LEAVES:3)
Block(-8,28,5,LEAVES:3)
Block(-7,28,5,LEAVES:3)
Block(-5,28,5,LEAVES:3)
Block(-15,28,6,LEAVES:3)
Block(-14,28,6,LEAVES:3)
Block(-13,28,6,LOG:3)
Block(-12,28,6,LOG:3)
Block(-11,28,6,LOG:3)
Block(-10,28,6,LOG:3)
Block(-9,28,6,LOG:3)
Block(-8,28,6,LEAVES:3)
Block(-6,28,6,LEAVES:3)
Block(-5,28,6,LEAVES:3)
Block(1,28,6,LEAVES:3)
Block(-15,28,7,LEAVES:3)
Block(-14,28,7,LEAVES:3)
Block(-13,28,7,LEAVES:3)
Block(-11,28,7,LOG:3)
Block(-10,28,7,LOG:3)
Block(-9,28,7,LEAVES:3)
Block(-8,28,7,LEAVES:3)
Block(-7,28,7,LEAVES:3)
Block(-6,28,7,LEAVES:3)
Block(-5,28,7,LEAVES:3)
Block(-14,28,8,LEAVES:3)
Block(-13,28,8,LEAVES:3)
Block(-11,28,8,LEAVES:3)
Block(-9,28,8,LOG:3)
Block(-8,28,8,LOG:3)
Block(-7,28,8,LEAVES:3)
Block(-6,28,8,LEAVES:3)
Block(-5,28,8,LEAVES:3)
Block(-14,28,9,LEAVES:3)
Block(-13,28,9,LEAVES:3)
Block(-12,28,9,LEAVES:3)
Block(-11,28,9,LEAVES:3)
Block(-10,28,9,LEAVES:3)
Block(-9,28,9,LEAVES:3)
Block(-8,28,9,LEAVES:3)
Block(-7,28,9,LEAVES:3)
Block(-6,28,9,LEAVES:3)
Block(-13,28,10,LEAVES:3)
Block(-12,28,10,LEAVES:3)
Block(-11,28,10,LEAVES:3)
Block(-10,28,10,LEAVES:3)
Block(-9,28,10,LEAVES:3)
Block(-8,28,10,LEAVES:3)
Block(-7,28,10,LEAVES:3)
Block(-12,28,11,LEAVES:3)
Block(-11,28,11,LEAVES:3)
Block(-10,28,11,LEAVES:3)
Block(-9,28,11,LEAVES:3)
Block(-8,28,11,LEAVES:3)
Block(5,29,-12,LEAVES:3)
Block(8,29,-11,LEAVES:3)
Block(-3,29,-6,LOG:3)
Block(-2,29,-6,LOG:3)
Block(-1,29,-6,LOG:3)
Block(12,29,-6,LEAVES:3)
Block(-5,29,-5,LEAVES:3)
Block(-4,29,-5,LOG:3)
Block(-3,29,-5,LOG:3)
Block(-2,29,-5,LOG:3)
Block(-1,29,-5,LOG:3)
Block(0,29,-5,LOG:3)
Block(1,29,-5,LOG:3)
Block(3,29,-5,LEAVES:3)
Block(-5,29,-4,LOG:3)
Block(-4,29,-4,LOG:3)
Block(-3,29,-4,LOG:3)
Block(-2,29,-4,LOG:3)
Block(-1,29,-4,LOG:3)
Block(0,29,-4,LOG:3)
Block(1,29,-4,LOG:3)
Block(2,29,-4,LOG:3)
Block(3,29,-4,LOG:3)
Block(4,29,-4,LEAVES:3)
Block(6,29,-4,LEAVES:3)
Block(-4,29,-3,LOG:3)
Block(-3,29,-3,LOG:3)
Block(-2,29,-3,LOG:3)
Block(-1,29,-3,LOG:3)
Block(0,29,-3,LOG:3)
Block(1,29,-3,LOG:3)
Block(2,29,-3,LOG:3)
Block(3,29,-3,LOG:3)
Block(4,29,-3,LOG:3)
Block(5,29,-3,LOG:3)
Block(6,29,-3,LOG:3)
Block(-4,29,-2,LOG:3)
Block(-3,29,-2,LOG:3)
Block(-2,29,-2,LOG:3)
Block(-1,29,-2,LOG:3)
Block(0,29,-2,LOG:3)
Block(1,29,-2,LEAVES:3)
Block(3,29,-2,LOG:3)
Block(4,29,-2,LOG:3)
Block(5,29,-2,LOG:3)
Block(6,29,-2,LOG:3)
Block(7,29,-2,LOG:3)
Block(14,29,-2,LEAVES:3)
Block(-3,29,-1,LEAVES:3)
Block(4,29,-1,LOG:3)
Block(5,29,-1,LOG:3)
Block(6,29,-1,LOG:3)
Block(7,29,-1,LEAVES:3)
Block(-11,29,1,LEAVES:3)
Block(-13,29,2,LEAVES:3)
Block(-12,29,2,LEAVES:3)
Block(-11,29,2,LEAVES:3)
Block(-10,29,2,LEAVES:3)
Block(-9,29,2,LEAVES:3)
Block(-8,29,2,LEAVES:3)
Block(-13,29,3,LEAVES:3)
Block(-12,29,3,LEAVES:3)
Block(-11,29,3,LEAVES:3)
Block(-10,29,3,LEAVES:3)
Block(-8,29,3,LEAVES:3)
Block(-7,29,3,LEAVES:3)
Block(-14,29,4,LEAVES:3)
Block(-13,29,4,LEAVES:3)
Block(-12,29,4,LEAVES:3)
Block(-11,29,4,LEAVES:3)
Block(-10,29,4,LEAVES:3)
Block(-9,29,4,LEAVES:3)
Block(-8,29,4,LEAVES:3)
Block(-7,29,4,LEAVES:3)
Block(-6,29,4,LEAVES:3)
Block(-15,29,5,LEAVES:3)
Block(-14,29,5,LEAVES:3)
Block(-13,29,5,LEAVES:3)
Block(-12,29,5,LEAVES:3)
Block(-11,29,5,LEAVES:3)
Block(-10,29,5,LOG:3)
Block(-9,29,5,LEAVES:3)
Block(-8,29,5,LEAVES:3)
Block(-7,29,5,LEAVES:3)
Block(-6,29,5,LEAVES:3)
Block(-5,29,5,LEAVES:3)
Block(-15,29,6,LEAVES:3)
Block(-14,29,6,LEAVES:3)
Block(-13,29,6,LEAVES:3)
Block(-12,29,6,LEAVES:3)
Block(-11,29,6,LEAVES:3)
Block(-10,29,6,LOG:3)
Block(-9,29,6,LOG:3)
Block(-8,29,6,LEAVES:3)
Block(-7,29,6,LEAVES:3)
Block(-6,29,6,LEAVES:3)
Block(1,29,6,LEAVES:3)
Block(-15,29,7,LEAVES:3)
Block(-14,29,7,LEAVES:3)
Block(-13,29,7,LEAVES:3)
Block(-12,29,7,LEAVES:3)
Block(-11,29,7,LEAVES:3)
Block(-10,29,7,LEAVES:3)
Block(-9,29,7,LEAVES:3)
Block(-8,29,7,LEAVES:3)
Block(-6,29,7,LEAVES:3)
Block(-13,29,8,LEAVES:3)
Block(-12,29,8,LEAVES:3)
Block(-11,29,8,LEAVES:3)
Block(-10,29,8,LEAVES:3)
Block(-9,29,8,LEAVES:3)
Block(-8,29,8,LOG:3)
Block(-7,29,8,LEAVES:3)
Block(-13,29,9,LEAVES:3)
Block(-12,29,9,LEAVES:3)
Block(-11,29,9,LEAVES:3)
Block(-10,29,9,LEAVES:3)
Block(-9,29,9,LEAVES:3)
Block(-8,29,9,LEAVES:3)
Block(-7,29,9,LEAVES:3)
Block(-12,29,10,LEAVES:3)
Block(-11,29,10,LEAVES:3)
Block(-10,29,10,LEAVES:3)
Block(-9,29,10,LEAVES:3)
Block(-8,29,10,LEAVES:3)
Block(-10,29,11,LEAVES:3)
Block(5,30,-12,LEAVES:3)
Block(8,30,-11,LEAVES:3)
Block(-4,30,-6,LEAVES:3)
Block(-3,30,-6,LOG:3)
Block(-2,30,-6,LOG:3)
Block(-1,30,-6,LOG:3)
Block(12,30,-6,LEAVES:3)
Block(-4,30,-5,LOG:3)
Block(-3,30,-5,LOG:3)
Block(-2,30,-5,LOG:3)
Block(-1,30,-5,LOG:3)
Block(0,30,-5,LOG:3)
Block(1,30,-5,LOG:3)
Block(-10,30,-4,LEAVES:3)
Block(-4,30,-4,LOG:3)
Block(-3,30,-4,LOG:3)
Block(-2,30,-4,LOG:3)
Block(-1,30,-4,LOG:3)
Block(0,30,-4,LOG:3)
Block(1,30,-4,LOG:3)
Block(2,30,-4,LOG:3)
Block(5,30,-4,LEAVES:3)
Block(15,30,-4,LEAVES:3)
Block(-4,30,-3,LOG:3)
Block(-3,30,-3,LOG:3)
Block(-2,30,-3,LOG:3)
Block(-1,30,-3,LOG:3)
Block(0,30,-3,LOG:3)
Block(1,30,-3,LOG:3)
Block(5,30,-3,LOG:3)
Block(6,30,-3,LOG:3)
Block(7,30,-3,LOG:3)
Block(-3,30,-2,LOG:3)
Block(-2,30,-2,LOG:3)
Block(-1,30,-2,LOG:3)
Block(0,30,-2,LEAVES:3)
Block(4,30,-2,LOG:3)
Block(5,30,-2,LOG:3)
Block(6,30,-2,LOG:3)
Block(7,30,-2,LOG:3)
Block(14,30,-2,LEAVES:3)
Block(-2,30,-1,LEAVES:3)
Block(4,30,-1,LOG:3)
Block(5,30,-1,LOG:3)
Block(6,30,-1,LOG:3)
Block(7,30,-1,LOG:3)
Block(6,30,0,LEAVES:3)
Block(15,30,0,LEAVES:3)
Block(-10,30,2,LEAVES:3)
Block(-13,30,3,LEAVES:3)
Block(-12,30,3,LEAVES:3)
Block(-11,30,3,LEAVES:3)
Block(-10,30,3,LEAVES:3)
Block(-8,30,3,LEAVES:3)
Block(-14,30,4,LEAVES:3)
Block(-13,30,4,LEAVES:3)
Block(-12,30,4,LEAVES:3)
Block(-11,30,4,LEAVES:3)
Block(-10,30,4,LEAVES:3)
Block(-9,30,4,LEAVES:3)
Block(-8,30,4,LEAVES:3)
Block(-7,30,4,LEAVES:3)
Block(-14,30,5,LEAVES:3)
Block(-12,30,5,LEAVES:3)
Block(-11,30,5,LEAVES:3)
Block(-10,30,5,LEAVES:3)
Block(-9,30,5,LEAVES:3)
Block(-8,30,5,LEAVES:3)
Block(9,30,5,LEAVES:3)
Block(-14,30,6,LEAVES:3)
Block(-13,30,6,LEAVES:3)
Block(-12,30,6,LEAVES:3)
Block(-11,30,6,LEAVES:3)
Block(-10,30,6,LEAVES:3)
Block(-9,30,6,LEAVES:3)
Block(-8,30,6,LEAVES:3)
Block(-7,30,6,LEAVES:3)
Block(-6,30,6,LEAVES:3)
Block(1,30,6,LEAVES:3)
Block(-14,30,7,LEAVES:3)
Block(-13,30,7,LEAVES:3)
Block(-12,30,7,LEAVES:3)
Block(-11,30,7,LEAVES:3)
Block(-10,30,7,LEAVES:3)
Block(-9,30,7,LEAVES:3)
Block(-8,30,7,LEAVES:3)
Block(-7,30,7,LEAVES:3)
Block(3,30,7,LEAVES:3)
Block(-13,30,8,LEAVES:3)
Block(-12,30,8,LEAVES:3)
Block(-11,30,8,LEAVES:3)
Block(-10,30,8,LEAVES:3)
Block(-9,30,8,LEAVES:3)
Block(-8,30,8,LEAVES:3)
Block(-12,30,9,LEAVES:3)
Block(-11,30,9,LEAVES:3)
Block(-10,30,9,LEAVES:3)
Block(-11,30,10,LEAVES:3)
Block(-9,30,10,LEAVES:3)
Block(3,31,-14,LEAVES:3)
Block(1,31,-12,LEAVES:3)
Block(5,31,-12,LEAVES:3)
Block(8,31,-11,LEAVES:3)
Block(10,31,-8,LEAVES:3)
Block(-4,31,-6,LEAVES:3)
Block(-3,31,-6,LOG:3)
Block(-2,31,-6,LOG:3)
Block(-1,31,-6,LOG:3)
Block(12,31,-6,LEAVES:3)
Block(-3,31,-5,LOG:3)
Block(-2,31,-5,LOG:3)
Block(-1,31,-5,LOG:3)
Block(0,31,-5,LOG:3)
Block(1,31,-5,LOG:3)
Block(-10,31,-4,LEAVES:3)
Block(-4,31,-4,LOG:3)
Block(-3,31,-4,LOG:3)
Block(-2,31,-4,LOG:3)
Block(-1,31,-4,LOG:3)
Block(0,31,-4,LOG:3)
Block(1,31,-4,LOG:3)
Block(6,31,-4,LEAVES:3)
Block(15,31,-4,LEAVES:3)
Block(-4,31,-3,LOG:3)
Block(-3,31,-3,LOG:3)
Block(-2,31,-3,LOG:3)
Block(-1,31,-3,LOG:3)
Block(0,31,-3,LOG:3)
Block(1,31,-3,LOG:3)
Block(5,31,-3,LOG:3)
Block(6,31,-3,LOG:3)
Block(7,31,-3,LOG:3)
Block(-3,31,-2,LOG:3)
Block(-2,31,-2,LOG:3)
Block(-1,31,-2,LOG:3)
Block(0,31,-2,LEAVES:3)
Block(4,31,-2,LOG:3)
Block(5,31,-2,LOG:3)
Block(6,31,-2,LOG:3)
Block(7,31,-2,LOG:3)
Block(8,31,-2,LOG:3)
Block(14,31,-2,LEAVES:3)
Block(-1,31,-1,LEAVES:3)
Block(5,31,-1,LOG:3)
Block(6,31,-1,LOG:3)
Block(7,31,-1,LOG:3)
Block(6,31,0,LEAVES:3)
Block(15,31,0,LEAVES:3)
Block(13,31,2,LEAVES:3)
Block(-12,31,3,LEAVES:3)
Block(-10,31,3,LEAVES:3)
Block(6,31,3,LEAVES:3)
Block(-12,31,4,LEAVES:3)
Block(-11,31,4,LEAVES:3)
Block(-10,31,4,LEAVES:3)
Block(-9,31,4,LEAVES:3)
Block(11,31,4,LEAVES:3)
Block(-13,31,5,LEAVES:3)
Block(-10,31,5,LEAVES:3)
Block(-9,31,5,LEAVES:3)
Block(9,31,5,LEAVES:3)
Block(-13,31,6,LEAVES:3)
Block(-11,31,6,LEAVES:3)
Block(-9,31,6,LEAVES:3)
Block(-8,31,6,LEAVES:3)
Block(1,31,6,LEAVES:3)
Block(7,31,6,LEAVES:3)
Block(-13,31,7,LEAVES:3)
Block(-12,31,7,LEAVES:3)
Block(-11,31,7,LEAVES:3)
Block(-10,31,7,LEAVES:3)
Block(-9,31,7,LEAVES:3)
Block(3,31,7,LEAVES:3)
Block(-12,31,8,LEAVES:3)
Block(-10,31,8,LEAVES:3)
Block(5,31,8,LEAVES:3)
Block(3,32,-14,LEAVES:3)
Block(-3,32,-13,LEAVES:3)
Block(1,32,-12,LEAVES:3)
Block(5,32,-12,LEAVES:3)
Block(-5,32,-11,LEAVES:3)
Block(8,32,-11,LEAVES:3)
Block(-8,32,-9,LEAVES:3)
Block(10,32,-8,LEAVES:3)
Block(-3,32,-6,LEAVES:3)
Block(-2,32,-6,LOG:3)
Block(-1,32,-6,LOG:3)
Block(0,32,-6,LOG:3)
Block(6,32,-6,LEAVES:3)
Block(12,32,-6,LEAVES:3)
Block(-3,32,-5,LOG:3)
Block(-2,32,-5,LOG:3)
Block(-1,32,-5,LOG:3)
Block(0,32,-5,LOG:3)
Block(1,32,-5,LOG:3)
Block(-10,32,-4,LEAVES:3)
Block(-4,32,-4,LOG:3)
Block(-3,32,-4,LOG:3)
Block(-2,32,-4,LOG:3)
Block(-1,32,-4,LOG:3)
Block(0,32,-4,LOG:3)
Block(1,32,-4,LOG:3)
Block(6,32,-4,LEAVES:3)
Block(7,32,-4,LEAVES:3)
Block(15,32,-4,LEAVES:3)
Block(-4,32,-3,LOG:3)
Block(-3,32,-3,LOG:3)
Block(-2,32,-3,LOG:3)
Block(-1,32,-3,LOG:3)
Block(0,32,-3,LOG:3)
Block(1,32,-3,LOG:3)
Block(6,32,-3,LOG:3)
Block(7,32,-3,LOG:3)
Block(-10,32,-2,LEAVES:3)
Block(-2,32,-2,LOG:3)
Block(-1,32,-2,LOG:3)
Block(0,32,-2,LOG:3)
Block(5,32,-2,LOG:3)
Block(6,32,-2,LOG:3)
Block(7,32,-2,LOG:3)
Block(8,32,-2,LOG:3)
Block(14,32,-2,LEAVES:3)
Block(-1,32,-1,LEAVES:3)
Block(0,32,-1,LEAVES:3)
Block(5,32,-1,LOG:3)
Block(6,32,-1,LOG:3)
Block(7,32,-1,LOG:3)
Block(6,32,0,LEAVES:3)
Block(15,32,0,LEAVES:3)
Block(4,32,1,LEAVES:3)
Block(13,32,2,LEAVES:3)
Block(-6,32,3,LEAVES:3)
Block(6,32,3,LEAVES:3)
Block(11,32,4,LEAVES:3)
Block(9,32,5,LEAVES:3)
Block(-4,32,6,LEAVES:3)
Block(1,32,6,LEAVES:3)
Block(7,32,6,LEAVES:3)
Block(3,32,7,LEAVES:3)
Block(-2,32,8,LEAVES:3)
Block(5,32,8,LEAVES:3)
Block(1,33,-14,LEAVES:3)
Block(3,33,-14,LEAVES:3)
Block(-3,33,-13,LEAVES:3)
Block(1,33,-12,LEAVES:3)
Block(5,33,-12,LEAVES:3)
Block(-5,33,-11,LEAVES:3)
Block(8,33,-11,LEAVES:3)
Block(5,33,-10,LEAVES:3)
Block(-8,33,-9,LEAVES:3)
Block(-2,33,-9,LEAVES:3)
Block(10,33,-8,LEAVES:3)
Block(-6,33,-7,LEAVES:3)
Block(-3,33,-7,LEAVES:3)
Block(-9,33,-6,LEAVES:3)
Block(-2,33,-6,LOG:3)
Block(-1,33,-6,LOG:3)
Block(0,33,-6,LOG:3)
Block(2,33,-6,LEAVES:3)
Block(6,33,-6,LEAVES:3)
Block(11,33,-6,LEAVES:3)
Block(12,33,-6,LEAVES:3)
Block(-3,33,-5,LOG:3)
Block(-2,33,-5,LOG:3)
Block(-1,33,-5,LOG:3)
Block(0,33,-5,LOG:3)
Block(1,33,-5,LOG:3)
Block(10,33,-5,LEAVES:3)
Block(11,33,-5,LEAVES:3)
Block(12,33,-5,LEAVES:3)
Block(13,33,-5,LEAVES:3)
Block(-10,33,-4,LEAVES:3)
Block(-4,33,-4,LOG:3)
Block(-3,33,-4,LOG:3)
Block(-2,33,-4,LOG:3)
Block(-1,33,-4,LOG:3)
Block(0,33,-4,LOG:3)
Block(1,33,-4,LOG:3)
Block(7,33,-4,LEAVES:3)
Block(12,33,-4,LEAVES:3)
Block(13,33,-4,LEAVES:3)
Block(14,33,-4,LEAVES:3)
Block(15,33,-4,LEAVES:3)
Block(-3,33,-3,LOG:3)
Block(-2,33,-3,LOG:3)
Block(-1,33,-3,LOG:3)
Block(0,33,-3,LOG:3)
Block(1,33,-3,LOG:3)
Block(6,33,-3,LOG:3)
Block(7,33,-3,LOG:3)
Block(8,33,-3,LOG:3)
Block(13,33,-3,LEAVES:3)
Block(14,33,-3,LEAVES:3)
Block(15,33,-3,LEAVES:3)
Block(-10,33,-2,LEAVES:3)
Block(-2,33,-2,LOG:3)
Block(-1,33,-2,LOG:3)
Block(0,33,-2,LOG:3)
Block(5,33,-2,LOG:3)
Block(6,33,-2,LOG:3)
Block(7,33,-2,LOG:3)
Block(8,33,-2,LOG:3)
Block(12,33,-2,LEAVES:3)
Block(13,33,-2,LEAVES:3)
Block(14,33,-2,LEAVES:3)
Block(0,33,-1,LEAVES:3)
Block(6,33,-1,LOG:3)
Block(7,33,-1,LOG:3)
Block(13,33,-1,LEAVES:3)
Block(14,33,-1,LEAVES:3)
Block(15,33,-1,LEAVES:3)
Block(7,33,0,LEAVES:3)
Block(12,33,0,LEAVES:3)
Block(13,33,0,LEAVES:3)
Block(14,33,0,LEAVES:3)
Block(15,33,0,LEAVES:3)
Block(-9,33,1,LEAVES:3)
Block(-4,33,1,LEAVES:3)
Block(4,33,1,LEAVES:3)
Block(11,33,1,LEAVES:3)
Block(12,33,1,LEAVES:3)
Block(13,33,1,LEAVES:3)
Block(11,33,2,LEAVES:3)
Block(12,33,2,LEAVES:3)
Block(13,33,2,LEAVES:3)
Block(-6,33,3,LEAVES:3)
Block(1,33,3,LEAVES:3)
Block(6,33,3,LEAVES:3)
Block(11,33,3,LEAVES:3)
Block(12,33,3,LEAVES:3)
Block(10,33,4,LEAVES:3)
Block(11,33,4,LEAVES:3)
Block(9,33,5,LEAVES:3)
Block(10,33,5,LEAVES:3)
Block(-4,33,6,LEAVES:3)
Block(1,33,6,LEAVES:3)
Block(7,33,6,LEAVES:3)
Block(3,33,7,LEAVES:3)
Block(-2,33,8,LEAVES:3)
Block(0,33,8,LEAVES:3)
Block(5,33,8,LEAVES:3)
Block(1,34,-14,LEAVES:3)
Block(3,34,-14,LEAVES:3)
Block(-3,34,-13,LEAVES:3)
Block(1,34,-12,LEAVES:3)
Block(5,34,-12,LEAVES:3)
Block(-5,34,-11,LEAVES:3)
Block(8,34,-11,LEAVES:3)
Block(5,34,-10,LEAVES:3)
Block(-8,34,-9,LEAVES:3)
Block(-2,34,-9,LEAVES:3)
Block(10,34,-8,LEAVES:3)
Block(11,34,-8,LEAVES:3)
Block(-6,34,-7,LEAVES:3)
Block(-2,34,-7,LEAVES:3)
Block(-1,34,-7,LOG:3)
Block(9,34,-7,LEAVES:3)
Block(10,34,-7,LEAVES:3)
Block(11,34,-7,LEAVES:3)
Block(-9,34,-6,LEAVES:3)
Block(-2,34,-6,LOG:3)
Block(-1,34,-6,LOG:3)
Block(0,34,-6,LOG:3)
Block(2,34,-6,LEAVES:3)
Block(6,34,-6,LEAVES:3)
Block(10,34,-6,LEAVES:3)
Block(12,34,-6,LEAVES:3)
Block(13,34,-6,LEAVES:3)
Block(-3,34,-5,LOG:3)
Block(-2,34,-5,LOG:3)
Block(-1,34,-5,LOG:3)
Block(0,34,-5,LOG:3)
Block(1,34,-5,LOG:3)
Block(2,34,-5,LEAVES:3)
Block(3,34,-5,LEAVES:3)
Block(9,34,-5,LEAVES:3)
Block(10,34,-5,LEAVES:3)
Block(11,34,-5,LEAVES:3)
Block(13,34,-5,LEAVES:3)
Block(14,34,-5,LEAVES:3)
Block(15,34,-5,LEAVES:3)
Block(-10,34,-4,LEAVES:3)
Block(-4,34,-4,LOG:3)
Block(-3,34,-4,LOG:3)
Block(-2,34,-4,LOG:3)
Block(-1,34,-4,LOG:3)
Block(0,34,-4,LOG:3)
Block(1,34,-4,LOG:3)
Block(2,34,-4,LEAVES:3)
Block(7,34,-4,LOG:3)
Block(8,34,-4,LEAVES:3)
Block(10,34,-4,LEAVES:3)
Block(11,34,-4,LEAVES:3)
Block(12,34,-4,LEAVES:3)
Block(13,34,-4,LEAVES:3)
Block(14,34,-4,LEAVES:3)
Block(15,34,-4,LEAVES:3)
Block(-3,34,-3,LOG:3)
Block(-2,34,-3,LOG:3)
Block(-1,34,-3,LOG:3)
Block(0,34,-3,LOG:3)
Block(1,34,-3,LOG:3)
Block(6,34,-3,LOG:3)
Block(7,34,-3,LOG:3)
Block(8,34,-3,LOG:3)
Block(13,34,-3,LEAVES:3)
Block(14,34,-3,LEAVES:3)
Block(-10,34,-2,LEAVES:3)
Block(-1,34,-2,LOG:3)
Block(0,34,-2,LOG:3)
Block(1,34,-2,LEAVES:3)
Block(6,34,-2,LOG:3)
Block(7,34,-2,LOG:3)
Block(8,34,-2,LOG:3)
Block(11,34,-2,LEAVES:3)
Block(12,34,-2,LEAVES:3)
Block(13,34,-2,LEAVES:3)
Block(14,34,-2,LEAVES:3)
Block(15,34,-2,LEAVES:3)
Block(6,34,-1,LOG:3)
Block(7,34,-1,LOG:3)
Block(8,34,-1,LOG:3)
Block(12,34,-1,LEAVES:3)
Block(13,34,-1,LEAVES:3)
Block(14,34,-1,LEAVES:3)
Block(15,34,-1,LEAVES:3)
Block(7,34,0,LOG:3)
Block(8,34,0,LEAVES:3)
Block(11,34,0,LEAVES:3)
Block(12,34,0,LEAVES:3)
Block(13,34,0,LEAVES:3)
Block(14,34,0,LEAVES:3)
Block(-9,34,1,LEAVES:3)
Block(-4,34,1,LEAVES:3)
Block(4,34,1,LEAVES:3)
Block(7,34,1,LEAVES:3)
Block(10,34,1,LEAVES:3)
Block(11,34,1,LEAVES:3)
Block(12,34,1,LEAVES:3)
Block(13,34,1,LEAVES:3)
Block(14,34,1,LEAVES:3)
Block(11,34,2,LEAVES:3)
Block(12,34,2,LEAVES:3)
Block(13,34,2,LEAVES:3)
Block(-6,34,3,LEAVES:3)
Block(1,34,3,LEAVES:3)
Block(6,34,3,LEAVES:3)
Block(9,34,3,LEAVES:3)
Block(10,34,3,LEAVES:3)
Block(11,34,3,LEAVES:3)
Block(12,34,3,LEAVES:3)
Block(13,34,3,LEAVES:3)
Block(7,34,4,LEAVES:3)
Block(8,34,4,LEAVES:3)
Block(9,34,4,LEAVES:3)
Block(10,34,4,LEAVES:3)
Block(11,34,4,LEAVES:3)
Block(6,34,5,LEAVES:3)
Block(7,34,5,LEAVES:3)
Block(8,34,5,LEAVES:3)
Block(9,34,5,LEAVES:3)
Block(10,34,5,LEAVES:3)
Block(11,34,5,LEAVES:3)
Block(-4,34,6,LEAVES:3)
Block(1,34,6,LEAVES:3)
Block(7,34,6,LEAVES:3)
Block(3,34,7,LEAVES:3)
Block(-2,34,8,LEAVES:3)
Block(0,34,8,LEAVES:3)
Block(5,34,8,LEAVES:3)
Block(2,35,-15,LEAVES:3)
Block(-1,35,-14,LEAVES:3)
Block(1,35,-14,LEAVES:3)
Block(2,35,-14,LEAVES:3)
Block(3,35,-14,LEAVES:3)
Block(5,35,-14,LEAVES:3)
Block(-3,35,-13,LEAVES:3)
Block(-2,35,-13,LEAVES:3)
Block(-1,35,-13,LEAVES:3)
Block(0,35,-13,LEAVES:3)
Block(1,35,-13,LEAVES:3)
Block(2,35,-13,LEAVES:3)
Block(4,35,-13,LEAVES:3)
Block(5,35,-13,LEAVES:3)
Block(-5,35,-12,LEAVES:3)
Block(-4,35,-12,LEAVES:3)
Block(-3,35,-12,LEAVES:3)
Block(-2,35,-12,LEAVES:3)
Block(-1,35,-12,LEAVES:3)
Block(1,35,-12,LEAVES:3)
Block(5,35,-12,LEAVES:3)
Block(6,35,-12,LEAVES:3)
Block(7,35,-12,LEAVES:3)
Block(-6,35,-11,LEAVES:3)
Block(-5,35,-11,LEAVES:3)
Block(-4,35,-11,LEAVES:3)
Block(-3,35,-11,LEAVES:3)
Block(6,35,-11,LEAVES:3)
Block(7,35,-11,LEAVES:3)
Block(8,35,-11,LEAVES:3)
Block(-8,35,-10,LEAVES:3)
Block(-7,35,-10,LEAVES:3)
Block(-5,35,-10,LEAVES:3)
Block(5,35,-10,LEAVES:3)
Block(7,35,-10,LEAVES:3)
Block(8,35,-10,LEAVES:3)
Block(9,35,-10,LEAVES:3)
Block(-9,35,-9,LEAVES:3)
Block(-8,35,-9,LEAVES:3)
Block(-7,35,-9,LEAVES:3)
Block(-6,35,-9,LEAVES:3)
Block(-2,35,-9,LEAVES:3)
Block(8,35,-9,LEAVES:3)
Block(10,35,-9,LEAVES:3)
Block(-8,35,-8,LEAVES:3)
Block(-7,35,-8,LEAVES:3)
Block(-1,35,-8,LOG:3)
Block(9,35,-8,LEAVES:3)
Block(10,35,-8,LEAVES:3)
Block(11,35,-8,LEAVES:3)
Block(12,35,-8,LEAVES:3)
Block(-9,35,-7,LEAVES:3)
Block(-6,35,-7,LEAVES:3)
Block(-1,35,-7,LOG:3)
Block(9,35,-7,LEAVES:3)
Block(10,35,-7,LEAVES:3)
Block(11,35,-7,LEAVES:3)
Block(12,35,-7,LEAVES:3)
Block(13,35,-7,LEAVES:3)
Block(-10,35,-6,LEAVES:3)
Block(-9,35,-6,LEAVES:3)
Block(-8,35,-6,LEAVES:3)
Block(-2,35,-6,LOG:3)
Block(-1,35,-6,LOG:3)
Block(0,35,-6,LOG:3)
Block(1,35,-6,LOG:3)
Block(2,35,-6,LOG:3)
Block(3,35,-6,LEAVES:3)
Block(6,35,-6,LEAVES:3)
Block(9,35,-6,LEAVES:3)
Block(10,35,-6,LEAVES:3)
Block(11,35,-6,LEAVES:3)
Block(12,35,-6,LEAVES:3)
Block(13,35,-6,LEAVES:3)
Block(-9,35,-5,LEAVES:3)
Block(-3,35,-5,LOG:3)
Block(-2,35,-5,LOG:3)
Block(-1,35,-5,LOG:3)
Block(0,35,-5,LOG:3)
Block(1,35,-5,LOG:3)
Block(2,35,-5,LOG:3)
Block(3,35,-5,LEAVES:3)
Block(6,35,-5,LEAVES:3)
Block(7,35,-5,LEAVES:3)
Block(8,35,-5,LEAVES:3)
Block(9,35,-5,LEAVES:3)
Block(10,35,-5,LEAVES:3)
Block(11,35,-5,LEAVES:3)
Block(12,35,-5,LEAVES:3)
Block(13,35,-5,LEAVES:3)
Block(14,35,-5,LEAVES:3)
Block(-10,35,-4,LEAVES:3)
Block(-9,35,-4,LEAVES:3)
Block(-8,35,-4,LEAVES:3)
Block(-3,35,-4,LOG:3)
Block(-2,35,-4,LOG:3)
Block(-1,35,-4,LOG:3)
Block(0,35,-4,LOG:3)
Block(1,35,-4,LOG:3)
Block(2,35,-4,LOG:3)
Block(3,35,-4,LEAVES:3)
Block(5,35,-4,LEAVES:3)
Block(6,35,-4,LEAVES:3)
Block(7,35,-4,LEAVES:3)
Block(8,35,-4,LEAVES:3)
Block(9,35,-4,LEAVES:3)
Block(10,35,-4,LEAVES:3)
Block(11,35,-4,LEAVES:3)
Block(12,35,-4,LEAVES:3)
Block(13,35,-4,LEAVES:3)
Block(14,35,-4,LEAVES:3)
Block(15,35,-4,LEAVES:3)
Block(-9,35,-3,LEAVES:3)
Block(-3,35,-3,LOG:3)
Block(-2,35,-3,LOG:3)
Block(-1,35,-3,LOG:3)
Block(0,35,-3,LOG:3)
Block(1,35,-3,LOG:3)
Block(2,35,-3,LOG:3)
Block(5,35,-3,LEAVES:3)
Block(6,35,-3,LEAVES:3)
Block(7,35,-3,LEAVES:3)
Block(8,35,-3,LEAVES:3)
Block(9,35,-3,LEAVES:3)
Block(10,35,-3,LEAVES:3)
Block(11,35,-3,LEAVES:3)
Block(12,35,-3,LEAVES:3)
Block(13,35,-3,LEAVES:3)
Block(15,35,-3,LEAVES:3)
Block(-10,35,-2,LEAVES:3)
Block(-9,35,-2,LEAVES:3)
Block(-1,35,-2,LOG:3)
Block(0,35,-2,LOG:3)
Block(1,35,-2,LOG:3)
Block(2,35,-2,LEAVES:3)
Block(5,35,-2,LEAVES:3)
Block(6,35,-2,LEAVES:3)
Block(7,35,-2,LEAVES:3)
Block(8,35,-2,LOG:3)
Block(9,35,-2,LOG:3)
Block(10,35,-2,LOG:3)
Block(11,35,-2,LOG:3)
Block(12,35,-2,LEAVES:3)
Block(13,35,-2,LEAVES:3)
Block(14,35,-2,LEAVES:3)
Block(15,35,-2,LEAVES:3)
Block(-9,35,-1,LEAVES:3)
Block(1,35,-1,LEAVES:3)
Block(4,35,-1,LEAVES:3)
Block(5,35,-1,LEAVES:3)
Block(6,35,-1,LEAVES:3)
Block(7,35,-1,LOG:3)
Block(10,35,-1,LEAVES:3)
Block(11,35,-1,LOG:3)
Block(12,35,-1,LEAVES:3)
Block(13,35,-1,LEAVES:3)
Block(14,35,-1,LEAVES:3)
Block(-8,35,0,LEAVES:3)
Block(4,35,0,LEAVES:3)
Block(5,35,0,LEAVES:3)
Block(6,35,0,LOG:3)
Block(7,35,0,LOG:3)
Block(8,35,0,LEAVES:3)
Block(9,35,0,LEAVES:3)
Block(10,35,0,LEAVES:3)
Block(11,35,0,LEAVES:3)
Block(12,35,0,LEAVES:3)
Block(13,35,0,LEAVES:3)
Block(14,35,0,LEAVES:3)
Block(-9,35,1,LEAVES:3)
Block(-8,35,1,LEAVES:3)
Block(-7,35,1,LEAVES:3)
Block(-4,35,1,LEAVES:3)
Block(4,35,1,LEAVES:3)
Block(5,35,1,LEAVES:3)
Block(6,35,1,LEAVES:3)
Block(7,35,1,LOG:3)
Block(8,35,1,LOG:3)
Block(9,35,1,LEAVES:3)
Block(10,35,1,LEAVES:3)
Block(11,35,1,LEAVES:3)
Block(12,35,1,LEAVES:3)
Block(13,35,1,LEAVES:3)
Block(-8,35,2,LEAVES:3)
Block(-7,35,2,LEAVES:3)
Block(5,35,2,LEAVES:3)
Block(6,35,2,LEAVES:3)
Block(7,35,2,LEAVES:3)
Block(8,35,2,LOG:3)
Block(9,35,2,LEAVES:3)
Block(10,35,2,LEAVES:3)
Block(11,35,2,LEAVES:3)
Block(12,35,2,LEAVES:3)
Block(13,35,2,LEAVES:3)
Block(-8,35,3,LEAVES:3)
Block(-7,35,3,LEAVES:3)
Block(-6,35,3,LEAVES:3)
Block(1,35,3,LEAVES:3)
Block(6,35,3,LEAVES:3)
Block(7,35,3,LEAVES:3)
Block(8,35,3,LOG:3)
Block(9,35,3,LEAVES:3)
Block(10,35,3,LEAVES:3)
Block(12,35,3,LEAVES:3)
Block(-7,35,4,LEAVES:3)
Block(-5,35,4,LEAVES:3)
Block(6,35,4,LEAVES:3)
Block(7,35,4,LEAVES:3)
Block(8,35,4,LEAVES:3)
Block(9,35,4,LEAVES:3)
Block(10,35,4,LEAVES:3)
Block(11,35,4,LEAVES:3)
Block(-6,35,5,LEAVES:3)
Block(-5,35,5,LEAVES:3)
Block(-4,35,5,LEAVES:3)
Block(6,35,5,LEAVES:3)
Block(7,35,5,LEAVES:3)
Block(8,35,5,LEAVES:3)
Block(9,35,5,LEAVES:3)
Block(10,35,5,LEAVES:3)
Block(-5,35,6,LEAVES:3)
Block(-4,35,6,LEAVES:3)
Block(-3,35,6,LEAVES:3)
Block(-2,35,6,LEAVES:3)
Block(1,35,6,LEAVES:3)
Block(2,35,6,LEAVES:3)
Block(4,35,6,LEAVES:3)
Block(5,35,6,LEAVES:3)
Block(6,35,6,LEAVES:3)
Block(7,35,6,LEAVES:3)
Block(8,35,6,LEAVES:3)
Block(-4,35,7,LEAVES:3)
Block(-3,35,7,LEAVES:3)
Block(-2,35,7,LEAVES:3)
Block(-1,35,7,LEAVES:3)
Block(0,35,7,LEAVES:3)
Block(1,35,7,LEAVES:3)
Block(2,35,7,LEAVES:3)
Block(3,35,7,LEAVES:3)
Block(4,35,7,LEAVES:3)
Block(5,35,7,LEAVES:3)
Block(7,35,7,LEAVES:3)
Block(-2,35,8,LEAVES:3)
Block(-1,35,8,LEAVES:3)
Block(0,35,8,LEAVES:3)
Block(1,35,8,LEAVES:3)
Block(3,35,8,LEAVES:3)
Block(4,35,8,LEAVES:3)
Block(5,35,8,LEAVES:3)
Block(6,35,8,LEAVES:3)
Block(2,35,9,LEAVES:3)
Block(3,35,9,LEAVES:3)
Block(4,35,9,LEAVES:3)
Block(1,36,-15,LEAVES:3)
Block(2,36,-15,LEAVES:3)
Block(3,36,-15,LEAVES:3)
Block(4,36,-15,LEAVES:3)
Block(-2,36,-14,LEAVES:3)
Block(-1,36,-14,LEAVES:3)
Block(0,36,-14,LEAVES:3)
Block(1,36,-14,LEAVES:3)
Block(2,36,-14,LEAVES:3)
Block(3,36,-14,LEAVES:3)
Block(4,36,-14,LEAVES:3)
Block(5,36,-14,LEAVES:3)
Block(6,36,-14,LEAVES:3)
Block(-4,36,-13,LEAVES:3)
Block(-3,36,-13,LEAVES:3)
Block(-2,36,-13,LEAVES:3)
Block(-1,36,-13,LEAVES:3)
Block(0,36,-13,LEAVES:3)
Block(1,36,-13,LEAVES:3)
Block(2,36,-13,LEAVES:3)
Block(3,36,-13,LEAVES:3)
Block(4,36,-13,LEAVES:3)
Block(5,36,-13,LEAVES:3)
Block(6,36,-13,LEAVES:3)
Block(-6,36,-12,LEAVES:3)
Block(-5,36,-12,LEAVES:3)
Block(-4,36,-12,LEAVES:3)
Block(-3,36,-12,LEAVES:3)
Block(-2,36,-12,LEAVES:3)
Block(-1,36,-12,LEAVES:3)
Block(0,36,-12,LOG:3)
Block(1,36,-12,LEAVES:3)
Block(2,36,-12,LEAVES:3)
Block(3,36,-12,LEAVES:3)
Block(4,36,-12,LEAVES:3)
Block(5,36,-12,LEAVES:3)
Block(6,36,-12,LEAVES:3)
Block(7,36,-12,LEAVES:3)
Block(8,36,-12,LEAVES:3)
Block(-6,36,-11,LEAVES:3)
Block(-5,36,-11,LEAVES:3)
Block(-4,36,-11,LEAVES:3)
Block(-3,36,-11,LEAVES:3)
Block(-2,36,-11,LEAVES:3)
Block(-1,36,-11,LEAVES:3)
Block(0,36,-11,LOG:3)
Block(1,36,-11,LEAVES:3)
Block(2,36,-11,LEAVES:3)
Block(3,36,-11,LEAVES:3)
Block(4,36,-11,LEAVES:3)
Block(5,36,-11,LEAVES:3)
Block(6,36,-11,LEAVES:3)
Block(7,36,-11,LEAVES:3)
Block(8,36,-11,LEAVES:3)
Block(9,36,-11,LEAVES:3)
Block(-9,36,-10,LEAVES:3)
Block(-8,36,-10,LEAVES:3)
Block(-7,36,-10,LEAVES:3)
Block(-6,36,-10,LEAVES:3)
Block(-5,36,-10,LEAVES:3)
Block(-4,36,-10,LEAVES:3)
Block(-3,36,-10,LEAVES:3)
Block(-2,36,-10,LEAVES:3)
Block(-1,36,-10,LEAVES:3)
Block(0,36,-10,LOG:3)
Block(2,36,-10,LEAVES:3)
Block(3,36,-10,LEAVES:3)
Block(4,36,-10,LEAVES:3)
Block(5,36,-10,LEAVES:3)
Block(6,36,-10,LEAVES:3)
Block(7,36,-10,LEAVES:3)
Block(8,36,-10,LEAVES:3)
Block(9,36,-10,LEAVES:3)
Block(-8,36,-9,LEAVES:3)
Block(-7,36,-9,LEAVES:3)
Block(-6,36,-9,LEAVES:3)
Block(-5,36,-9,LEAVES:3)
Block(-4,36,-9,LEAVES:3)
Block(-3,36,-9,LEAVES:3)
Block(-2,36,-9,LEAVES:3)
Block(-1,36,-9,LOG:3)
Block(0,36,-9,LOG:3)
Block(4,36,-9,LEAVES:3)
Block(5,36,-9,LEAVES:3)
Block(6,36,-9,LEAVES:3)
Block(7,36,-9,LEAVES:3)
Block(8,36,-9,LEAVES:3)
Block(9,36,-9,LEAVES:3)
Block(11,36,-9,LEAVES:3)
Block(-9,36,-8,LEAVES:3)
Block(-8,36,-8,LEAVES:3)
Block(-7,36,-8,LEAVES:3)
Block(-6,36,-8,LEAVES:3)
Block(-5,36,-8,LEAVES:3)
Block(-3,36,-8,LEAVES:3)
Block(-1,36,-8,LOG:3)
Block(0,36,-8,LEAVES:3)
Block(6,36,-8,LOG:3)
Block(7,36,-8,LEAVES:3)
Block(8,36,-8,LEAVES:3)
Block(9,36,-8,LEAVES:3)
Block(10,36,-8,LEAVES:3)
Block(11,36,-8,LEAVES:3)
Block(-10,36,-7,LEAVES:3)
Block(-9,36,-7,LEAVES:3)
Block(-8,36,-7,LEAVES:3)
Block(-7,36,-7,LEAVES:3)
Block(-6,36,-7,LEAVES:3)
Block(0,36,-7,LEAVES:3)
Block(1,36,-7,LEAVES:3)
Block(2,36,-7,LOG:3)
Block(3,36,-7,LOG:3)
Block(4,36,-7,LOG:3)
Block(7,36,-7,LEAVES:3)
Block(8,36,-7,LEAVES:3)
Block(9,36,-7,LEAVES:3)
Block(10,36,-7,LEAVES:3)
Block(11,36,-7,LEAVES:3)
Block(12,36,-7,LEAVES:3)
Block(-10,36,-6,LEAVES:3)
Block(-9,36,-6,LEAVES:3)
Block(-8,36,-6,LEAVES:3)
Block(-7,36,-6,LEAVES:3)
Block(-6,36,-6,LEAVES:3)
Block(-3,36,-6,LOG:3)
Block(-2,36,-6,LOG:3)
Block(-1,36,-6,LEAVES:3)
Block(0,36,-6,LEAVES:3)
Block(1,36,-6,LEAVES:3)
Block(2,36,-6,LEAVES:3)
Block(3,36,-6,LEAVES:3)
Block(6,36,-6,LEAVES:3)
Block(7,36,-6,LEAVES:3)
Block(8,36,-6,LEAVES:3)
Block(9,36,-6,LEAVES:3)
Block(10,36,-6,LEAVES:3)
Block(11,36,-6,LEAVES:3)
Block(12,36,-6,LEAVES:3)
Block(13,36,-6,LEAVES:3)
Block(-10,36,-5,LEAVES:3)
Block(-9,36,-5,LEAVES:3)
Block(-8,36,-5,LEAVES:3)
Block(-7,36,-5,LEAVES:3)
Block(-4,36,-5,LOG:3)
Block(-3,36,-5,LEAVES:3)
Block(-2,36,-5,LEAVES:3)
Block(-1,36,-5,LEAVES:3)
Block(0,36,-5,LEAVES:3)
Block(1,36,-5,LEAVES:3)
Block(2,36,-5,LEAVES:3)
Block(3,36,-5,LEAVES:3)
Block(5,36,-5,LEAVES:3)
Block(6,36,-5,LEAVES:3)
Block(7,36,-5,LEAVES:3)
Block(8,36,-5,LEAVES:3)
Block(9,36,-5,LEAVES:3)
Block(10,36,-5,LEAVES:3)
Block(11,36,-5,LEAVES:3)
Block(12,36,-5,LEAVES:3)
Block(-10,36,-4,LEAVES:3)
Block(-9,36,-4,LEAVES:3)
Block(-8,36,-4,LEAVES:3)
Block(-7,36,-4,LEAVES:3)
Block(-4,36,-4,LOG:3)
Block(-3,36,-4,LEAVES:3)
Block(-2,36,-4,LEAVES:3)
Block(-1,36,-4,LEAVES:3)
Block(0,36,-4,LEAVES:3)
Block(1,36,-4,LEAVES:3)
Block(3,36,-4,LEAVES:3)
Block(4,36,-4,LEAVES:3)
Block(5,36,-4,LEAVES:3)
Block(6,36,-4,LEAVES:3)
Block(8,36,-4,LEAVES:3)
Block(9,36,-4,LEAVES:3)
Block(10,36,-4,LEAVES:3)
Block(11,36,-4,LEAVES:3)
Block(12,36,-4,LEAVES:3)
Block(13,36,-4,LEAVES:3)
Block(-10,36,-3,LEAVES:3)
Block(-8,36,-3,LEAVES:3)
Block(-7,36,-3,LOG:3)
Block(-6,36,-3,LOG:3)
Block(-5,36,-3,LOG:3)
Block(-4,36,-3,LOG:3)
Block(-3,36,-3,LEAVES:3)
Block(-2,36,-3,LEAVES:3)
Block(-1,36,-3,LEAVES:3)
Block(0,36,-3,LEAVES:3)
Block(1,36,-3,LEAVES:3)
Block(2,36,-3,LEAVES:3)
Block(3,36,-3,LOG:3)
Block(4,36,-3,LOG:3)
Block(5,36,-3,LEAVES:3)
Block(6,36,-3,LEAVES:3)
Block(7,36,-3,LEAVES:3)
Block(8,36,-3,LEAVES:3)
Block(9,36,-3,LEAVES:3)
Block(10,36,-3,LEAVES:3)
Block(11,36,-3,LEAVES:3)
Block(12,36,-3,LEAVES:3)
Block(13,36,-3,LEAVES:3)
Block(14,36,-3,LEAVES:3)
Block(-10,36,-2,LEAVES:3)
Block(-9,36,-2,LEAVES:3)
Block(-8,36,-2,LOG:3)
Block(-7,36,-2,LOG:3)
Block(-6,36,-2,LEAVES:3)
Block(-4,36,-2,LOG:3)
Block(-3,36,-2,LOG:3)
Block(-2,36,-2,LOG:3)
Block(-1,36,-2,LEAVES:3)
Block(0,36,-2,LOG:3)
Block(1,36,-2,LEAVES:3)
Block(2,36,-2,LOG:3)
Block(3,36,-2,LEAVES:3)
Block(4,36,-2,LEAVES:3)
Block(5,36,-2,LEAVES:3)
Block(6,36,-2,LEAVES:3)
Block(7,36,-2,LEAVES:3)
Block(8,36,-2,LEAVES:3)
Block(9,36,-2,LEAVES:3)
Block(10,36,-2,LEAVES:3)
Block(11,36,-2,LEAVES:3)
Block(12,36,-2,LEAVES:3)
Block(13,36,-2,LEAVES:3)
Block(-10,36,-1,LEAVES:3)
Block(-9,36,-1,LEAVES:3)
Block(-8,36,-1,LEAVES:3)
Block(-7,36,-1,LEAVES:3)
Block(-6,36,-1,LEAVES:3)
Block(-4,36,-1,LOG:3)
Block(-1,36,-1,LOG:3)
Block(0,36,-1,LOG:3)
Block(1,36,-1,LOG:3)
Block(2,36,-1,LEAVES:3)
Block(3,36,-1,LEAVES:3)
Block(4,36,-1,LEAVES:3)
Block(5,36,-1,LEAVES:3)
Block(7,36,-1,LEAVES:3)
Block(10,36,-1,LEAVES:3)
Block(12,36,-1,LEAVES:3)
Block(13,36,-1,LEAVES:3)
Block(14,36,-1,LEAVES:3)
Block(-9,36,0,LEAVES:3)
Block(-8,36,0,LEAVES:3)
Block(-7,36,0,LEAVES:3)
Block(-6,36,0,LEAVES:3)
Block(2,36,0,LEAVES:3)
Block(3,36,0,LEAVES:3)
Block(4,36,0,LEAVES:3)
Block(5,36,0,LEAVES:3)
Block(6,36,0,LEAVES:3)
Block(7,36,0,LEAVES:3)
Block(8,36,0,LEAVES:3)
Block(10,36,0,LEAVES:3)
Block(11,36,0,LEAVES:3)
Block(13,36,0,LEAVES:3)
Block(-9,36,1,LEAVES:3)
Block(-8,36,1,LEAVES:3)
Block(-7,36,1,LEAVES:3)
Block(-6,36,1,LEAVES:3)
Block(-5,36,1,LEAVES:3)
Block(-4,36,1,LEAVES:3)
Block(3,36,1,LEAVES:3)
Block(4,36,1,LEAVES:3)
Block(5,36,1,LEAVES:3)
Block(6,36,1,LEAVES:3)
Block(7,36,1,LEAVES:3)
Block(8,36,1,LEAVES:3)
Block(9,36,1,LEAVES:3)
Block(10,36,1,LEAVES:3)
Block(11,36,1,LEAVES:3)
Block(12,36,1,LEAVES:3)
Block(-9,36,2,LEAVES:3)
Block(-8,36,2,LEAVES:3)
Block(-7,36,2,LEAVES:3)
Block(-6,36,2,LEAVES:3)
Block(-5,36,2,LEAVES:3)
Block(-4,36,2,LEAVES:3)
Block(3,36,2,LEAVES:3)
Block(4,36,2,LEAVES:3)
Block(5,36,2,LEAVES:3)
Block(6,36,2,LEAVES:3)
Block(7,36,2,LEAVES:3)
Block(8,36,2,LEAVES:3)
Block(9,36,2,LEAVES:3)
Block(10,36,2,LEAVES:3)
Block(11,36,2,LEAVES:3)
Block(-8,36,3,LEAVES:3)
Block(-7,36,3,LEAVES:3)
Block(-6,36,3,LEAVES:3)
Block(-5,36,3,LEAVES:3)
Block(1,36,3,LEAVES:3)
Block(4,36,3,LEAVES:3)
Block(5,36,3,LEAVES:3)
Block(6,36,3,LEAVES:3)
Block(7,36,3,LEAVES:3)
Block(8,36,3,LEAVES:3)
Block(9,36,3,LEAVES:3)
Block(10,36,3,LEAVES:3)
Block(-8,36,4,LEAVES:3)
Block(-7,36,4,LEAVES:3)
Block(-6,36,4,LEAVES:3)
Block(-5,36,4,LEAVES:3)
Block(-4,36,4,LEAVES:3)
Block(-3,36,4,LEAVES:3)
Block(1,36,4,LEAVES:3)
Block(2,36,4,LEAVES:3)
Block(3,36,4,LEAVES:3)
Block(4,36,4,LEAVES:3)
Block(5,36,4,LEAVES:3)
Block(6,36,4,LEAVES:3)
Block(7,36,4,LEAVES:3)
Block(8,36,4,LEAVES:3)
Block(9,36,4,LEAVES:3)
Block(10,36,4,LEAVES:3)
Block(-6,36,5,LEAVES:3)
Block(-5,36,5,LEAVES:3)
Block(-4,36,5,LEAVES:3)
Block(-3,36,5,LEAVES:3)
Block(-1,36,5,LEAVES:3)
Block(0,36,5,LEAVES:3)
Block(1,36,5,LEAVES:3)
Block(2,36,5,LEAVES:3)
Block(3,36,5,LEAVES:3)
Block(4,36,5,LEAVES:3)
Block(5,36,5,LEAVES:3)
Block(6,36,5,LEAVES:3)
Block(7,36,5,LEAVES:3)
Block(8,36,5,LEAVES:3)
Block(9,36,5,LEAVES:3)
Block(-6,36,6,LEAVES:3)
Block(-5,36,6,LEAVES:3)
Block(-4,36,6,LEAVES:3)
Block(-3,36,6,LEAVES:3)
Block(-2,36,6,LEAVES:3)
Block(-1,36,6,LEAVES:3)
Block(0,36,6,LEAVES:3)
Block(2,36,6,LEAVES:3)
Block(3,36,6,LEAVES:3)
Block(4,36,6,LEAVES:3)
Block(5,36,6,LEAVES:3)
Block(6,36,6,LEAVES:3)
Block(7,36,6,LEAVES:3)
Block(-5,36,7,LEAVES:3)
Block(-4,36,7,LEAVES:3)
Block(-3,36,7,LEAVES:3)
Block(-2,36,7,LEAVES:3)
Block(-1,36,7,LEAVES:3)
Block(0,36,7,LEAVES:3)
Block(1,36,7,LEAVES:3)
Block(3,36,7,LEAVES:3)
Block(4,36,7,LEAVES:3)
Block(5,36,7,LEAVES:3)
Block(6,36,7,LEAVES:3)
Block(7,36,7,LEAVES:3)
Block(8,36,7,LEAVES:3)
Block(-2,36,8,LEAVES:3)
Block(-1,36,8,LEAVES:3)
Block(0,36,8,LEAVES:3)
Block(1,36,8,LEAVES:3)
Block(2,36,8,LEAVES:3)
Block(3,36,8,LEAVES:3)
Block(4,36,8,LEAVES:3)
Block(5,36,8,LEAVES:3)
Block(6,36,8,LEAVES:3)
Block(7,36,8,LEAVES:3)
Block(1,36,9,LEAVES:3)
Block(2,36,9,LEAVES:3)
Block(3,36,9,LEAVES:3)
Block(4,36,9,LEAVES:3)
Block(5,36,9,LEAVES:3)
Block(2,37,-15,LEAVES:3)
Block(3,37,-15,LEAVES:3)
Block(4,37,-15,LEAVES:3)
Block(-1,37,-14,LEAVES:3)
Block(1,37,-14,LEAVES:3)
Block(2,37,-14,LEAVES:3)
Block(3,37,-14,LEAVES:3)
Block(4,37,-14,LEAVES:3)
Block(5,37,-14,LEAVES:3)
Block(-3,37,-13,LEAVES:3)
Block(-2,37,-13,LEAVES:3)
Block(-1,37,-13,LEAVES:3)
Block(0,37,-13,LEAVES:3)
Block(1,37,-13,LEAVES:3)
Block(2,37,-13,LEAVES:3)
Block(3,37,-13,LEAVES:3)
Block(4,37,-13,LEAVES:3)
Block(5,37,-13,LEAVES:3)
Block(6,37,-13,LEAVES:3)
Block(-5,37,-12,LEAVES:3)
Block(-4,37,-12,LEAVES:3)
Block(-3,37,-12,LEAVES:3)
Block(-2,37,-12,LEAVES:3)
Block(-1,37,-12,LEAVES:3)
Block(0,37,-12,LEAVES:3)
Block(1,37,-12,LEAVES:3)
Block(2,37,-12,LEAVES:3)
Block(3,37,-12,LEAVES:3)
Block(4,37,-12,LEAVES:3)
Block(5,37,-12,LEAVES:3)
Block(6,37,-12,LEAVES:3)
Block(7,37,-12,LEAVES:3)
Block(-6,37,-11,LEAVES:3)
Block(-5,37,-11,LEAVES:3)
Block(-4,37,-11,LEAVES:3)
Block(-3,37,-11,LEAVES:3)
Block(-2,37,-11,LEAVES:3)
Block(-1,37,-11,LEAVES:3)
Block(0,37,-11,LEAVES:3)
Block(1,37,-11,LEAVES:3)
Block(2,37,-11,LEAVES:3)
Block(3,37,-11,LEAVES:3)
Block(4,37,-11,LEAVES:3)
Block(5,37,-11,LEAVES:3)
Block(6,37,-11,LEAVES:3)
Block(7,37,-11,LEAVES:3)
Block(8,37,-11,LEAVES:3)
Block(-8,37,-10,LEAVES:3)
Block(-7,37,-10,LEAVES:3)
Block(-6,37,-10,LEAVES:3)
Block(-5,37,-10,LEAVES:3)
Block(-4,37,-10,LEAVES:3)
Block(-3,37,-10,LEAVES:3)
Block(-2,37,-10,LEAVES:3)
Block(-1,37,-10,LEAVES:3)
Block(0,37,-10,LEAVES:3)
Block(1,37,-10,LEAVES:3)
Block(2,37,-10,LEAVES:3)
Block(3,37,-10,LEAVES:3)
Block(4,37,-10,LEAVES:3)
Block(5,37,-10,LEAVES:3)
Block(6,37,-10,LEAVES:3)
Block(7,37,-10,LEAVES:3)
Block(8,37,-10,LEAVES:3)
Block(9,37,-10,LEAVES:3)
Block(-9,37,-9,LEAVES:3)
Block(-8,37,-9,LEAVES:3)
Block(-7,37,-9,LEAVES:3)
Block(-6,37,-9,LEAVES:3)
Block(-5,37,-9,LEAVES:3)
Block(-4,37,-9,LEAVES:3)
Block(-3,37,-9,LEAVES:3)
Block(-2,37,-9,LEAVES:3)
Block(-1,37,-9,LEAVES:3)
Block(0,37,-9,LEAVES:3)
Block(1,37,-9,LEAVES:3)
Block(2,37,-9,LEAVES:3)
Block(3,37,-9,LEAVES:3)
Block(4,37,-9,LEAVES:3)
Block(5,37,-9,LEAVES:3)
Block(6,37,-9,LEAVES:3)
Block(7,37,-9,LEAVES:3)
Block(8,37,-9,LEAVES:3)
Block(9,37,-9,LEAVES:3)
Block(10,37,-9,LEAVES:3)
Block(-8,37,-8,LEAVES:3)
Block(-7,37,-8,LEAVES:3)
Block(-6,37,-8,LEAVES:3)
Block(-5,37,-8,LEAVES:3)
Block(-4,37,-8,LEAVES:3)
Block(-3,37,-8,LEAVES:3)
Block(-2,37,-8,LEAVES:3)
Block(0,37,-8,LEAVES:3)
Block(1,37,-8,LEAVES:3)
Block(2,37,-8,LEAVES:3)
Block(3,37,-8,LEAVES:3)
Block(4,37,-8,LOG:3)
Block(5,37,-8,LOG:3)
Block(7,37,-8,LEAVES:3)
Block(8,37,-8,LEAVES:3)
Block(9,37,-8,LEAVES:3)
Block(10,37,-8,LEAVES:3)
Block(11,37,-8,LEAVES:3)
Block(-9,37,-7,LEAVES:3)
Block(-8,37,-7,LEAVES:3)
Block(-7,37,-7,LEAVES:3)
Block(-6,37,-7,LEAVES:3)
Block(-5,37,-7,LEAVES:3)
Block(-4,37,-7,LEAVES:3)
Block(-3,37,-7,LEAVES:3)
Block(0,37,-7,LEAVES:3)
Block(1,37,-7,LEAVES:3)
Block(2,37,-7,LEAVES:3)
Block(3,37,-7,LEAVES:3)
Block(4,37,-7,LEAVES:3)
Block(5,37,-7,LEAVES:3)
Block(6,37,-7,LEAVES:3)
Block(7,37,-7,LEAVES:3)
Block(9,37,-7,LEAVES:3)
Block(10,37,-7,LEAVES:3)
Block(11,37,-7,LEAVES:3)
Block(-10,37,-6,LEAVES:3)
Block(-9,37,-6,LEAVES:3)
Block(-8,37,-6,LEAVES:3)
Block(-7,37,-6,LEAVES:3)
Block(-6,37,-6,LEAVES:3)
Block(-5,37,-6,LEAVES:3)
Block(-4,37,-6,LEAVES:3)
Block(-3,37,-6,LEAVES:3)
Block(-2,37,-6,LEAVES:3)
Block(-1,37,-6,LEAVES:3)
Block(1,37,-6,LEAVES:3)
Block(2,37,-6,LEAVES:3)
Block(3,37,-6,LEAVES:3)
Block(4,37,-6,LEAVES:3)
Block(5,37,-6,LEAVES:3)
Block(6,37,-6,LEAVES:3)
Block(7,37,-6,LEAVES:3)
Block(8,37,-6,LEAVES:3)
Block(9,37,-6,LEAVES:3)
Block(10,37,-6,LEAVES:3)
Block(11,37,-6,LEAVES:3)
Block(12,37,-6,LEAVES:3)
Block(-9,37,-5,LEAVES:3)
Block(-8,37,-5,LEAVES:3)
Block(-7,37,-5,LEAVES:3)
Block(-6,37,-5,LEAVES:3)
Block(-5,37,-5,LEAVES:3)
Block(-4,37,-5,LEAVES:3)
Block(-3,37,-5,LEAVES:3)
Block(-2,37,-5,LEAVES:3)
Block(-1,37,-5,LEAVES:3)
Block(0,37,-5,LEAVES:3)
Block(1,37,-5,LEAVES:3)
Block(2,37,-5,LEAVES:3)
Block(3,37,-5,LEAVES:3)
Block(4,37,-5,LEAVES:3)
Block(5,37,-5,LEAVES:3)
Block(6,37,-5,LEAVES:3)
Block(7,37,-5,LEAVES:3)
Block(8,37,-5,LEAVES:3)
Block(9,37,-5,LEAVES:3)
Block(10,37,-5,LEAVES:3)
Block(11,37,-5,LEAVES:3)
Block(-10,37,-4,LEAVES:3)
Block(-9,37,-4,LEAVES:3)
Block(-8,37,-4,LEAVES:3)
Block(-7,37,-4,LEAVES:3)
Block(-6,37,-4,LEAVES:3)
Block(-5,37,-4,LEAVES:3)
Block(-4,37,-4,LEAVES:3)
Block(-3,37,-4,LEAVES:3)
Block(-2,37,-4,LEAVES:3)
Block(-1,37,-4,LEAVES:3)
Block(0,37,-4,LEAVES:3)
Block(1,37,-4,LEAVES:3)
Block(2,37,-4,LEAVES:3)
Block(3,37,-4,LEAVES:3)
Block(4,37,-4,LEAVES:3)
Block(5,37,-4,LEAVES:3)
Block(6,37,-4,LEAVES:3)
Block(7,37,-4,LEAVES:3)
Block(8,37,-4,LEAVES:3)
Block(9,37,-4,LEAVES:3)
Block(10,37,-4,LEAVES:3)
Block(11,37,-4,LEAVES:3)
Block(12,37,-4,LEAVES:3)
Block(-10,37,-3,LEAVES:3)
Block(-9,37,-3,LEAVES:3)
Block(-8,37,-3,LEAVES:3)
Block(-7,37,-3,LEAVES:3)
Block(-5,37,-3,LEAVES:3)
Block(-4,37,-3,LEAVES:3)
Block(-3,37,-3,LEAVES:3)
Block(-2,37,-3,LEAVES:3)
Block(-1,37,-3,LEAVES:3)
Block(0,37,-3,LEAVES:3)
Block(1,37,-3,LEAVES:3)
Block(2,37,-3,LEAVES:3)
Block(3,37,-3,LEAVES:3)
Block(4,37,-3,LEAVES:3)
Block(5,37,-3,LEAVES:3)
Block(6,37,-3,LEAVES:3)
Block(7,37,-3,LEAVES:3)
Block(8,37,-3,LEAVES:3)
Block(9,37,-3,LEAVES:3)
Block(10,37,-3,LEAVES:3)
Block(11,37,-3,LEAVES:3)
Block(13,37,-3,LEAVES:3)
Block(-10,37,-2,LEAVES:3)
Block(-9,37,-2,LEAVES:3)
Block(-8,37,-2,LEAVES:3)
Block(-7,37,-2,LEAVES:3)
Block(-6,37,-2,LEAVES:3)
Block(-5,37,-2,LEAVES:3)
Block(-4,37,-2,LEAVES:3)
Block(-3,37,-2,LEAVES:3)
Block(-2,37,-2,LEAVES:3)
Block(-1,37,-2,LEAVES:3)
Block(0,37,-2,LEAVES:3)
Block(1,37,-2,LEAVES:3)
Block(2,37,-2,LEAVES:3)
Block(3,37,-2,LEAVES:3)
Block(4,37,-2,LEAVES:3)
Block(5,37,-2,LEAVES:3)
Block(6,37,-2,LEAVES:3)
Block(7,37,-2,LEAVES:3)
Block(8,37,-2,LEAVES:3)
Block(9,37,-2,LEAVES:3)
Block(10,37,-2,LEAVES:3)
Block(11,37,-2,LEAVES:3)
Block(12,37,-2,LEAVES:3)
Block(13,37,-2,LEAVES:3)
Block(-9,37,-1,LEAVES:3)
Block(-8,37,-1,LEAVES:3)
Block(-6,37,-1,LEAVES:3)
Block(-5,37,-1,LEAVES:3)
Block(-4,37,-1,LEAVES:3)
Block(-3,37,-1,LEAVES:3)
Block(-2,37,-1,LEAVES:3)
Block(-1,37,-1,LEAVES:3)
Block(0,37,-1,LEAVES:3)
Block(2,37,-1,LEAVES:3)
Block(3,37,-1,LEAVES:3)
Block(4,37,-1,LEAVES:3)
Block(5,37,-1,LEAVES:3)
Block(6,37,-1,LEAVES:3)
Block(7,37,-1,LEAVES:3)
Block(8,37,-1,LEAVES:3)
Block(9,37,-1,LEAVES:3)
Block(10,37,-1,LEAVES:3)
Block(11,37,-1,LEAVES:3)
Block(12,37,-1,LEAVES:3)
Block(-9,37,0,LEAVES:3)
Block(-8,37,0,LEAVES:3)
Block(-7,37,0,LEAVES:3)
Block(-6,37,0,LEAVES:3)
Block(-5,37,0,LOG:3)
Block(-4,37,0,LOG:3)
Block(-3,37,0,LEAVES:3)
Block(-2,37,0,LEAVES:3)
Block(-1,37,0,LOG:3)
Block(0,37,0,LOG:3)
Block(1,37,0,LEAVES:3)
Block(2,37,0,LEAVES:3)
Block(3,37,0,LEAVES:3)
Block(4,37,0,LEAVES:3)
Block(5,37,0,LEAVES:3)
Block(6,37,0,LEAVES:3)
Block(7,37,0,LEAVES:3)
Block(8,37,0,LEAVES:3)
Block(9,37,0,LEAVES:3)
Block(10,37,0,LEAVES:3)
Block(11,37,0,LEAVES:3)
Block(-9,37,1,LEAVES:3)
Block(-8,37,1,LEAVES:3)
Block(-7,37,1,LEAVES:3)
Block(-6,37,1,LEAVES:3)
Block(-5,37,1,LEAVES:3)
Block(-4,37,1,LEAVES:3)
Block(-3,37,1,LEAVES:3)
Block(-2,37,1,LEAVES:3)
Block(0,37,1,LOG:3)
Block(1,37,1,LEAVES:3)
Block(2,37,1,LEAVES:3)
Block(3,37,1,LEAVES:3)
Block(4,37,1,LEAVES:3)
Block(5,37,1,LEAVES:3)
Block(6,37,1,LEAVES:3)
Block(7,37,1,LEAVES:3)
Block(8,37,1,LEAVES:3)
Block(9,37,1,LEAVES:3)
Block(10,37,1,LEAVES:3)
Block(11,37,1,LEAVES:3)
Block(-8,37,2,LEAVES:3)
Block(-7,37,2,LEAVES:3)
Block(-6,37,2,LEAVES:3)
Block(-5,37,2,LEAVES:3)
Block(-4,37,2,LEAVES:3)
Block(-3,37,2,LEAVES:3)
Block(-2,37,2,LEAVES:3)
Block(-1,37,2,LEAVES:3)
Block(0,37,2,LOG:3)
Block(2,37,2,LEAVES:3)
Block(3,37,2,LEAVES:3)
Block(4,37,2,LEAVES:3)
Block(5,37,2,LEAVES:3)
Block(6,37,2,LEAVES:3)
Block(7,37,2,LEAVES:3)
Block(8,37,2,LEAVES:3)
Block(9,37,2,LEAVES:3)
Block(-8,37,3,LEAVES:3)
Block(-7,37,3,LEAVES:3)
Block(-6,37,3,LEAVES:3)
Block(-5,37,3,LEAVES:3)
Block(-4,37,3,LEAVES:3)
Block(-3,37,3,LEAVES:3)
Block(-2,37,3,LEAVES:3)
Block(-1,37,3,LOG:3)
Block(0,37,3,LOG:3)
Block(1,37,3,LEAVES:3)
Block(2,37,3,LEAVES:3)
Block(3,37,3,LEAVES:3)
Block(4,37,3,LEAVES:3)
Block(5,37,3,LEAVES:3)
Block(6,37,3,LEAVES:3)
Block(7,37,3,LEAVES:3)
Block(8,37,3,LEAVES:3)
Block(9,37,3,LEAVES:3)
Block(10,37,3,LEAVES:3)
Block(-7,37,4,LEAVES:3)
Block(-6,37,4,LEAVES:3)
Block(-5,37,4,LEAVES:3)
Block(-4,37,4,LEAVES:3)
Block(-3,37,4,LEAVES:3)
Block(-2,37,4,LEAVES:3)
Block(-1,37,4,LOG:3)
Block(0,37,4,LEAVES:3)
Block(1,37,4,LEAVES:3)
Block(2,37,4,LEAVES:3)
Block(3,37,4,LEAVES:3)
Block(4,37,4,LEAVES:3)
Block(5,37,4,LEAVES:3)
Block(6,37,4,LEAVES:3)
Block(7,37,4,LEAVES:3)
Block(8,37,4,LEAVES:3)
Block(9,37,4,LEAVES:3)
Block(-6,37,5,LEAVES:3)
Block(-5,37,5,LEAVES:3)
Block(-4,37,5,LEAVES:3)
Block(-3,37,5,LEAVES:3)
Block(-2,37,5,LEAVES:3)
Block(-1,37,5,LEAVES:3)
Block(0,37,5,LEAVES:3)
Block(1,37,5,LEAVES:3)
Block(2,37,5,LEAVES:3)
Block(3,37,5,LEAVES:3)
Block(4,37,5,LEAVES:3)
Block(5,37,5,LEAVES:3)
Block(6,37,5,LEAVES:3)
Block(7,37,5,LEAVES:3)
Block(8,37,5,LEAVES:3)
Block(-5,37,6,LEAVES:3)
Block(-4,37,6,LEAVES:3)
Block(-3,37,6,LEAVES:3)
Block(-2,37,6,LEAVES:3)
Block(-1,37,6,LEAVES:3)
Block(0,37,6,LEAVES:3)
Block(1,37,6,LEAVES:3)
Block(2,37,6,LEAVES:3)
Block(3,37,6,LEAVES:3)
Block(4,37,6,LEAVES:3)
Block(5,37,6,LEAVES:3)
Block(6,37,6,LEAVES:3)
Block(7,37,6,LEAVES:3)
Block(8,37,6,LEAVES:3)
Block(-2,37,7,LEAVES:3)
Block(-1,37,7,LEAVES:3)
Block(0,37,7,LEAVES:3)
Block(1,37,7,LEAVES:3)
Block(2,37,7,LEAVES:3)
Block(3,37,7,LEAVES:3)
Block(4,37,7,LEAVES:3)
Block(5,37,7,LEAVES:3)
Block(6,37,7,LEAVES:3)
Block(7,37,7,LEAVES:3)
Block(-1,37,8,LEAVES:3)
Block(0,37,8,LEAVES:3)
Block(1,37,8,LEAVES:3)
Block(3,37,8,LEAVES:3)
Block(5,37,8,LEAVES:3)
Block(6,37,8,LEAVES:3)
Block(2,37,9,LEAVES:3)
Block(4,37,9,LEAVES:3)
Block(2,38,-14,LEAVES:3)
Block(3,38,-14,LEAVES:3)
Block(-1,38,-13,LEAVES:3)
Block(1,38,-13,LEAVES:3)
Block(2,38,-13,LEAVES:3)
Block(3,38,-13,LEAVES:3)
Block(4,38,-13,LEAVES:3)
Block(5,38,-13,LEAVES:3)
Block(-3,38,-12,LEAVES:3)
Block(-2,38,-12,LEAVES:3)
Block(0,38,-12,LEAVES:3)
Block(1,38,-12,LEAVES:3)
Block(2,38,-12,LEAVES:3)
Block(3,38,-12,LEAVES:3)
Block(4,38,-12,LEAVES:3)
Block(6,38,-12,LEAVES:3)
Block(-5,38,-11,LEAVES:3)
Block(-4,38,-11,LEAVES:3)
Block(-3,38,-11,LEAVES:3)
Block(-2,38,-11,LEAVES:3)
Block(-1,38,-11,LEAVES:3)
Block(1,38,-11,LEAVES:3)
Block(2,38,-11,LEAVES:3)
Block(3,38,-11,LEAVES:3)
Block(5,38,-11,LEAVES:3)
Block(6,38,-11,LEAVES:3)
Block(7,38,-11,LEAVES:3)
Block(-6,38,-10,LEAVES:3)
Block(-5,38,-10,LEAVES:3)
Block(-4,38,-10,LEAVES:3)
Block(-2,38,-10,LEAVES:3)
Block(-1,38,-10,LEAVES:3)
Block(0,38,-10,LEAVES:3)
Block(1,38,-10,LEAVES:3)
Block(3,38,-10,LEAVES:3)
Block(4,38,-10,LEAVES:3)
Block(6,38,-10,LEAVES:3)
Block(8,38,-10,LEAVES:3)
Block(-7,38,-9,LEAVES:3)
Block(-6,38,-9,LEAVES:3)
Block(-5,38,-9,LEAVES:3)
Block(-4,38,-9,LEAVES:3)
Block(-3,38,-9,LEAVES:3)
Block(-2,38,-9,LEAVES:3)
Block(0,38,-9,LEAVES:3)
Block(1,38,-9,LEAVES:3)
Block(2,38,-9,LEAVES:3)
Block(3,38,-9,LEAVES:3)
Block(4,38,-9,LEAVES:3)
Block(5,38,-9,LEAVES:3)
Block(6,38,-9,LEAVES:3)
Block(7,38,-9,LEAVES:3)
Block(8,38,-9,LEAVES:3)
Block(9,38,-9,LEAVES:3)
Block(-8,38,-8,LEAVES:3)
Block(-7,38,-8,LEAVES:3)
Block(-6,38,-8,LEAVES:3)
Block(-5,38,-8,LEAVES:3)
Block(-4,38,-8,LEAVES:3)
Block(-3,38,-8,LEAVES:3)
Block(-2,38,-8,LEAVES:3)
Block(0,38,-8,LEAVES:3)
Block(1,38,-8,LEAVES:3)
Block(3,38,-8,LEAVES:3)
Block(4,38,-8,LEAVES:3)
Block(5,38,-8,LEAVES:3)
Block(6,38,-8,LEAVES:3)
Block(7,38,-8,LEAVES:3)
Block(8,38,-8,LEAVES:3)
Block(9,38,-8,LEAVES:3)
Block(-8,38,-7,LEAVES:3)
Block(-7,38,-7,LEAVES:3)
Block(-6,38,-7,LEAVES:3)
Block(-5,38,-7,LEAVES:3)
Block(-4,38,-7,LEAVES:3)
Block(-3,38,-7,LEAVES:3)
Block(-2,38,-7,LEAVES:3)
Block(0,38,-7,LEAVES:3)
Block(1,38,-7,LEAVES:3)
Block(2,38,-7,LEAVES:3)
Block(3,38,-7,LEAVES:3)
Block(4,38,-7,LEAVES:3)
Block(5,38,-7,LEAVES:3)
Block(6,38,-7,LEAVES:3)
Block(7,38,-7,LEAVES:3)
Block(9,38,-7,LEAVES:3)
Block(10,38,-7,LEAVES:3)
Block(-9,38,-6,LEAVES:3)
Block(-8,38,-6,LEAVES:3)
Block(-7,38,-6,LEAVES:3)
Block(-6,38,-6,LEAVES:3)
Block(-5,38,-6,LEAVES:3)
Block(-4,38,-6,LEAVES:3)
Block(-3,38,-6,LEAVES:3)
Block(-2,38,-6,LEAVES:3)
Block(-1,38,-6,LEAVES:3)
Block(0,38,-6,LEAVES:3)
Block(1,38,-6,LEAVES:3)
Block(3,38,-6,LEAVES:3)
Block(4,38,-6,LEAVES:3)
Block(5,38,-6,LEAVES:3)
Block(6,38,-6,LEAVES:3)
Block(7,38,-6,LEAVES:3)
Block(9,38,-6,LEAVES:3)
Block(10,38,-6,LEAVES:3)
Block(-8,38,-5,LEAVES:3)
Block(-7,38,-5,LEAVES:3)
Block(-6,38,-5,LEAVES:3)
Block(-5,38,-5,LEAVES:3)
Block(-4,38,-5,LEAVES:3)
Block(-3,38,-5,LEAVES:3)
Block(-2,38,-5,LEAVES:3)
Block(-1,38,-5,LEAVES:3)
Block(0,38,-5,LEAVES:3)
Block(1,38,-5,LEAVES:3)
Block(2,38,-5,LEAVES:3)
Block(3,38,-5,LEAVES:3)
Block(4,38,-5,LEAVES:3)
Block(5,38,-5,LEAVES:3)
Block(6,38,-5,LEAVES:3)
Block(7,38,-5,LEAVES:3)
Block(8,38,-5,LEAVES:3)
Block(10,38,-5,LEAVES:3)
Block(11,38,-5,LEAVES:3)
Block(-9,38,-4,LEAVES:3)
Block(-8,38,-4,LEAVES:3)
Block(-7,38,-4,LEAVES:3)
Block(-6,38,-4,LEAVES:3)
Block(-5,38,-4,LEAVES:3)
Block(-4,38,-4,LEAVES:3)
Block(-3,38,-4,LEAVES:3)
Block(-2,38,-4,LEAVES:3)
Block(-1,38,-4,LEAVES:3)
Block(0,38,-4,LEAVES:3)
Block(1,38,-4,LEAVES:3)
Block(2,38,-4,LEAVES:3)
Block(3,38,-4,LEAVES:3)
Block(4,38,-4,LEAVES:3)
Block(5,38,-4,LEAVES:3)
Block(6,38,-4,LEAVES:3)
Block(7,38,-4,LEAVES:3)
Block(8,38,-4,LEAVES:3)
Block(9,38,-4,LEAVES:3)
Block(10,38,-4,LEAVES:3)
Block(-10,38,-3,LEAVES:3)
Block(-9,38,-3,LEAVES:3)
Block(-8,38,-3,LEAVES:3)
Block(-7,38,-3,LEAVES:3)
Block(-6,38,-3,LEAVES:3)
Block(-5,38,-3,LEAVES:3)
Block(-4,38,-3,LEAVES:3)
Block(-3,38,-3,LEAVES:3)
Block(-2,38,-3,LEAVES:3)
Block(-1,38,-3,LEAVES:3)
Block(0,38,-3,LEAVES:3)
Block(1,38,-3,LEAVES:3)
Block(2,38,-3,LEAVES:3)
Block(3,38,-3,LEAVES:3)
Block(4,38,-3,LEAVES:3)
Block(5,38,-3,LEAVES:3)
Block(6,38,-3,LEAVES:3)
Block(7,38,-3,LEAVES:3)
Block(8,38,-3,LEAVES:3)
Block(9,38,-3,LEAVES:3)
Block(10,38,-3,LEAVES:3)
Block(-9,38,-2,LEAVES:3)
Block(-8,38,-2,LEAVES:3)
Block(-7,38,-2,LEAVES:3)
Block(-6,38,-2,LEAVES:3)
Block(-5,38,-2,LEAVES:3)
Block(-4,38,-2,LEAVES:3)
Block(-3,38,-2,LEAVES:3)
Block(-2,38,-2,LEAVES:3)
Block(-1,38,-2,LEAVES:3)
Block(0,38,-2,LEAVES:3)
Block(1,38,-2,LEAVES:3)
Block(2,38,-2,LEAVES:3)
Block(3,38,-2,LEAVES:3)
Block(4,38,-2,LEAVES:3)
Block(5,38,-2,LEAVES:3)
Block(6,38,-2,LEAVES:3)
Block(7,38,-2,LEAVES:3)
Block(8,38,-2,LEAVES:3)
Block(9,38,-2,LEAVES:3)
Block(11,38,-2,LEAVES:3)
Block(-9,38,-1,LEAVES:3)
Block(-8,38,-1,LEAVES:3)
Block(-7,38,-1,LEAVES:3)
Block(-6,38,-1,LEAVES:3)
Block(-5,38,-1,LEAVES:3)
Block(-4,38,-1,LEAVES:3)
Block(-3,38,-1,LEAVES:3)
Block(-2,38,-1,LEAVES:3)
Block(-1,38,-1,LEAVES:3)
Block(0,38,-1,LEAVES:3)
Block(1,38,-1,LEAVES:3)
Block(2,38,-1,LEAVES:3)
Block(3,38,-1,LEAVES:3)
Block(4,38,-1,LEAVES:3)
Block(5,38,-1,LEAVES:3)
Block(6,38,-1,LEAVES:3)
Block(7,38,-1,LEAVES:3)
Block(8,38,-1,LEAVES:3)
Block(9,38,-1,LEAVES:3)
Block(-8,38,0,LEAVES:3)
Block(-7,38,0,LEAVES:3)
Block(-6,38,0,LEAVES:3)
Block(-5,38,0,LEAVES:3)
Block(-4,38,0,LEAVES:3)
Block(-3,38,0,LEAVES:3)
Block(-2,38,0,LEAVES:3)
Block(-1,38,0,LEAVES:3)
Block(0,38,0,LEAVES:3)
Block(1,38,0,LEAVES:3)
Block(2,38,0,LEAVES:3)
Block(3,38,0,LEAVES:3)
Block(4,38,0,LEAVES:3)
Block(5,38,0,LEAVES:3)
Block(6,38,0,LEAVES:3)
Block(8,38,0,LEAVES:3)
Block(9,38,0,LEAVES:3)
Block(10,38,0,LEAVES:3)
Block(11,38,0,LEAVES:3)
Block(-7,38,1,LEAVES:3)
Block(-6,38,1,LEAVES:3)
Block(-5,38,1,LEAVES:3)
Block(-4,38,1,LEAVES:3)
Block(-3,38,1,LEAVES:3)
Block(-2,38,1,LEAVES:3)
Block(-1,38,1,LEAVES:3)
Block(0,38,1,LEAVES:3)
Block(1,38,1,LEAVES:3)
Block(2,38,1,LEAVES:3)
Block(3,38,1,LEAVES:3)
Block(4,38,1,LEAVES:3)
Block(5,38,1,LEAVES:3)
Block(6,38,1,LEAVES:3)
Block(7,38,1,LEAVES:3)
Block(8,38,1,LEAVES:3)
Block(10,38,1,LEAVES:3)
Block(-6,38,2,LEAVES:3)
Block(-5,38,2,LEAVES:3)
Block(-4,38,2,LEAVES:3)
Block(-3,38,2,LEAVES:3)
Block(-2,38,2,LEAVES:3)
Block(-1,38,2,LEAVES:3)
Block(0,38,2,LEAVES:3)
Block(1,38,2,LEAVES:3)
Block(2,38,2,LEAVES:3)
Block(3,38,2,LEAVES:3)
Block(4,38,2,LEAVES:3)
Block(5,38,2,LEAVES:3)
Block(6,38,2,LEAVES:3)
Block(7,38,2,LEAVES:3)
Block(8,38,2,LEAVES:3)
Block(9,38,2,LEAVES:3)
Block(-7,38,3,LEAVES:3)
Block(-6,38,3,LEAVES:3)
Block(-5,38,3,LEAVES:3)
Block(-4,38,3,LEAVES:3)
Block(-3,38,3,LEAVES:3)
Block(-2,38,3,LEAVES:3)
Block(-1,38,3,LEAVES:3)
Block(0,38,3,LEAVES:3)
Block(1,38,3,LEAVES:3)
Block(2,38,3,LEAVES:3)
Block(4,38,3,LEAVES:3)
Block(5,38,3,LEAVES:3)
Block(6,38,3,LEAVES:3)
Block(7,38,3,LEAVES:3)
Block(8,38,3,LEAVES:3)
Block(-5,38,4,LEAVES:3)
Block(-4,38,4,LEAVES:3)
Block(-3,38,4,LEAVES:3)
Block(-2,38,4,LEAVES:3)
Block(-1,38,4,LEAVES:3)
Block(0,38,4,LEAVES:3)
Block(1,38,4,LEAVES:3)
Block(2,38,4,LEAVES:3)
Block(3,38,4,LEAVES:3)
Block(4,38,4,LEAVES:3)
Block(5,38,4,LEAVES:3)
Block(6,38,4,LEAVES:3)
Block(7,38,4,LEAVES:3)
Block(-5,38,5,LEAVES:3)
Block(-3,38,5,LEAVES:3)
Block(-2,38,5,LEAVES:3)
Block(-1,38,5,LEAVES:3)
Block(0,38,5,LEAVES:3)
Block(1,38,5,LEAVES:3)
Block(2,38,5,LEAVES:3)
Block(3,38,5,LEAVES:3)
Block(4,38,5,LEAVES:3)
Block(5,38,5,LEAVES:3)
Block(7,38,5,LEAVES:3)
Block(8,38,5,LEAVES:3)
Block(-4,38,6,LEAVES:3)
Block(-1,38,6,LEAVES:3)
Block(0,38,6,LEAVES:3)
Block(1,38,6,LEAVES:3)
Block(2,38,6,LEAVES:3)
Block(3,38,6,LEAVES:3)
Block(7,38,6,LEAVES:3)
Block(-1,38,7,LEAVES:3)
Block(3,38,7,LEAVES:3)
Block(4,38,7,LEAVES:3)
Block(6,38,7,LEAVES:3)
Block(1,38,8,LEAVES:3)
Block(3,39,-13,LEAVES:3)
Block(2,39,-12,LEAVES:3)
Block(3,39,-12,LEAVES:3)
Block(-1,39,-11,LEAVES:3)
Block(1,39,-11,LEAVES:3)
Block(2,39,-11,LEAVES:3)
Block(3,39,-11,LEAVES:3)
Block(5,39,-11,LEAVES:3)
Block(-5,39,-10,LEAVES:3)
Block(-2,39,-10,LEAVES:3)
Block(0,39,-10,LEAVES:3)
Block(1,39,-10,LEAVES:3)
Block(2,39,-10,LEAVES:3)
Block(3,39,-10,LEAVES:3)
Block(4,39,-10,LEAVES:3)
Block(6,39,-10,LEAVES:3)
Block(-6,39,-9,LEAVES:3)
Block(-4,39,-9,LEAVES:3)
Block(-3,39,-9,LEAVES:3)
Block(-2,39,-9,LEAVES:3)
Block(0,39,-9,LEAVES:3)
Block(1,39,-9,LEAVES:3)
Block(2,39,-9,LEAVES:3)
Block(3,39,-9,LEAVES:3)
