
#######################################################################
# +-----------------------------------------------------------------+ #
# |                            BO3 object                           | #
# +-----------------------------------------------------------------+ #
#######################################################################

# This is the config file of a custom object.
# If you add this object correctly to your BiomeConfigs, it will spawn in the world.

# This is the creator of this BO3 object
Author: BO3 BulkEdit (by LanToaster)

# A short description of this BO3 object
Description: This Object was Created with BO3_BulkEdit

# The BO3 version, don't change this! It can be used by external applications to do a version check.
Version: 3

# The settings mode, WriteAll, WriteWithoutComments or WriteDisable. See WorldConfig.
SettingsMode: WriteAll


#######################################################################
# +-----------------------------------------------------------------+ #
# |                          Main settings                          | #
# +-----------------------------------------------------------------+ #
#######################################################################

# This needs to be set to true to spawn the object in the Tree and Sapling resources.
Tree: true

# The frequency of the BO3 from 1 to 200. Tries this many times to spawn this BO3 when using the CustomObject(...) resource.
# Ignored by Tree(..), Sapling(..) and CustomStructure(..)
Frequency: 40

# The rarity of the BO3 from 0 to 100. Each spawn attempt has rarity% chance to succeed when using the CustomObject(...) resource.
# Ignored by Tree(..), Sapling(..) and CustomStructure(..)
Rarity: 100.0

# If you set this to true, the BO3 will be placed with a random rotation.
RotateRandomly: true

# The spawn height of the BO3: randomY, highestBlock or highestSolidBlock.
SpawnHeight: randomY

# The offset from the spawn height to spawn this BO3
# Ex. SpawnHeight = highestSolidBlock, SpawnHeightOffset = 3; This object will spawn 3 blocks above the highest solid block
SpawnHeightOffset: 0

# A random amount to offset the spawn location from the spawn offset height
# Ex. SpawnHeightOffset = 3, SpawnHeightVariance = 3; This object will spawn 3 to 6 blocks above the original spot it would have spawned
SpawnHeightVariance: 0

##############################
# Height Limits for the BO3. #
##############################

# When in randomY mode used as the minimum Y or in atMinY mode as the actual Y to spawn this BO3 at.
MinHeight: 63

# When in randomY mode used as the maximum Y to spawn this BO3 at.
MaxHeight: 255

######################
# Extrusion settings #
######################

# The style of extrusion you wish to use - BottomDown, TopUp, None (Default)
ExtrudeMode: None

# The blocks to extrude your BO3 through
ExtrudeThroughBlocks: AIR

# Objects can have other objects attacthed to it: branches. Branches can also
# have branches attached to it, which can also have branches, etc. This is the
# maximum branch depth for this objects.
MaxBranchDepth: 10

# When spawned with the UseWorld keyword, this BO3 should NOT spawn in the following biomes.
# If you write the BO3 name directly in the BiomeConfigs, this will be ignored.
ExcludedBiomes: All


#######################################################################
# +-----------------------------------------------------------------+ #
# |                      Source block settings                      | #
# +-----------------------------------------------------------------+ #
#######################################################################

# The block(s) the BO3 should spawn in.
SourceBlocks: AIR,GRASS:0,DIRT:0

# The maximum percentage of the BO3 that can be outside the SourceBlock.
# The BO3 won't be placed on a location with more blocks outside the SourceBlock than this percentage.
MaxPercentageOutsideSourceBlock: 5

# What to do when a block is about to be placed outside the SourceBlock? (dontPlace, placeAnyway)
OutsideSourceBlock: dontPlace

# OTG+ settings #
# Legacy setting, rename this file to .BO4 instead. Set this to true to enable the advanced customstructure features of OTG+.
IsOTGPlus: false


#######################################################################
# +-----------------------------------------------------------------+ #
# |                              Blocks                             | #
# +-----------------------------------------------------------------+ #
#######################################################################

# All the blocks used in the BO3 are listed here. Possible blocks:
# Block(x,y,z,id[.data][,nbtfile.nbt)
# RandomBlock(x,y,z,id[:data][,nbtfile.nbt],chance[,id[:data][,nbtfile.nbt],chance[,...]])
#  So RandomBlock(0,0,0,CHEST,chest.nbt,50,CHEST,anotherchest.nbt,100) will spawn a chest at
#  the BO3 origin, and give it a 50% chance to have the contents of chest.nbt, or, if that
#  fails, a 100% percent chance to have the contents of anotherchest.nbt.
# *Note: Unlike Entity() and Spawner(), for Block() .txt files don't work, only .nbt files work.
# MinecraftObject(x,y,z,name) (TODO: This may not work anymore and needs to be tested.
#  Spawns an object in the Mojang NBT structure format. For example, 
#  MinecraftObject(0,0,0,minecraft:igloo/igloo_bottom)
#  spawns the bottom part of an igloo.
Block(1,0,-7,LOG:3)
Block(2,0,-7,LOG:3)
Block(-1,0,-6,LEAVES:3)
Block(0,0,-6,LOG:3)
Block(1,0,-6,LOG:3)
Block(2,0,-6,LOG:3)
Block(3,0,-6,LOG:3)
Block(4,0,-6,LOG:3)
Block(5,0,-6,LOG:3)
Block(-1,0,-5,LOG:3)
Block(0,0,-5,LOG:3)
Block(1,0,-5,LOG:3)
Block(2,0,-5,LOG:3)
Block(3,0,-5,LOG:3)
Block(4,0,-5,LOG:3)
Block(5,0,-5,LOG:3)
Block(6,0,-5,LOG:3)
Block(-1,0,-4,LOG:3)
Block(0,0,-4,LOG:3)
Block(1,0,-4,LOG:3)
Block(2,0,-4,LOG:3)
Block(3,0,-4,LOG:3)
Block(4,0,-4,LOG:3)
Block(5,0,-4,LOG:3)
Block(6,0,-4,LOG:3)
Block(7,0,-4,LOG:3)
Block(-2,0,-3,LOG:3)
Block(-1,0,-3,LOG:3)
Block(0,0,-3,LOG:3)
Block(1,0,-3,LOG:3)
Block(2,0,-3,LOG:3)
Block(3,0,-3,LOG:3)
Block(4,0,-3,LOG:3)
Block(5,0,-3,LOG:3)
Block(6,0,-3,LOG:3)
Block(7,0,-3,LOG:3)
Block(-2,0,-2,LOG:3)
Block(-1,0,-2,LOG:3)
Block(0,0,-2,LOG:3)
Block(1,0,-2,LOG:3)
Block(2,0,-2,LOG:3)
Block(3,0,-2,LOG:3)
Block(4,0,-2,LOG:3)
Block(5,0,-2,LOG:3)
Block(6,0,-2,LOG:3)
Block(-1,0,-1,LOG:3)
Block(0,0,-1,LOG:3)
Block(1,0,-1,LOG:3)
Block(2,0,-1,LOG:3)
Block(3,0,-1,LOG:3)
Block(4,0,-1,LOG:3)
Block(5,0,-1,LOG:3)
Block(6,0,-1,LOG:3)
Block(1,0,0,LOG:3)
Block(2,0,0,LOG:3)
Block(3,0,0,LOG:3)
Block(4,0,0,LOG:3)
Block(5,0,0,LOG:3)
Block(6,0,0,LEAVES:3)
Block(1,0,1,LEAVES:3)
Block(2,0,1,LOG:3)
Block(3,0,1,LOG:3)
Block(1,1,-6,LOG:3)
Block(2,1,-6,LOG:3)
Block(3,1,-6,LOG:3)
Block(-1,1,-5,LEAVES:3)
Block(0,1,-5,LOG:3)
Block(1,1,-5,LOG:3)
Block(2,1,-5,LOG:3)
Block(3,1,-5,LOG:3)
Block(4,1,-5,LOG:3)
Block(-1,1,-4,LOG:3)
Block(0,1,-4,LOG:3)
Block(1,1,-4,LOG:3)
Block(2,1,-4,LOG:3)
Block(3,1,-4,LOG:3)
Block(4,1,-4,LOG:3)
Block(5,1,-4,LOG:3)
Block(-1,1,-3,LOG:3)
Block(0,1,-3,LOG:3)
Block(1,1,-3,LOG:3)
Block(2,1,-3,LOG:3)
Block(3,1,-3,LOG:3)
Block(4,1,-3,LOG:3)
Block(5,1,-3,LOG:3)
Block(-1,1,-2,LOG:3)
Block(0,1,-2,LOG:3)
Block(1,1,-2,LOG:3)
Block(2,1,-2,LOG:3)
Block(3,1,-2,LOG:3)
Block(4,1,-2,LOG:3)
Block(5,1,-2,LOG:3)
Block(0,1,-1,LEAVES:3)
Block(1,1,-1,LOG:3)
Block(2,1,-1,LOG:3)
Block(3,1,-1,LOG:3)
Block(4,1,-1,LOG:3)
Block(5,1,-1,LEAVES:3)
Block(1,1,0,LEAVES:3)
Block(2,1,0,LOG:3)
Block(3,1,0,LOG:3)
Block(0,2,-6,LEAVES:3)
Block(1,2,-6,LOG:3)
Block(2,2,-6,LOG:3)
Block(3,2,-6,LOG:3)
Block(-1,2,-5,LOG:3)
Block(0,2,-5,LOG:3)
Block(1,2,-5,LOG:3)
Block(2,2,-5,LOG:3)
Block(3,2,-5,LOG:3)
Block(4,2,-5,LOG:3)
Block(-1,2,-4,LOG:3)
Block(0,2,-4,LOG:3)
Block(1,2,-4,LOG:3)
Block(2,2,-4,LOG:3)
Block(3,2,-4,LOG:3)
Block(4,2,-4,LOG:3)
Block(5,2,-4,LOG:3)
Block(-1,2,-3,LOG:3)
Block(0,2,-3,LOG:3)
Block(1,2,-3,LOG:3)
Block(2,2,-3,LOG:3)
Block(3,2,-3,LOG:3)
Block(4,2,-3,LOG:3)
Block(5,2,-3,LOG:3)
Block(-1,2,-2,LOG:3)
Block(0,2,-2,LOG:3)
Block(1,2,-2,LOG:3)
Block(2,2,-2,LOG:3)
Block(3,2,-2,LOG:3)
Block(4,2,-2,LOG:3)
Block(0,2,-1,LEAVES:3)
Block(1,2,-1,LOG:3)
Block(2,2,-1,LOG:3)
Block(3,2,-1,LOG:3)
Block(4,2,-1,LOG:3)
Block(5,2,-1,LEAVES:3)
Block(2,2,0,LOG:3)
Block(0,3,-7,LEAVES:3)
Block(0,3,-6,LOG:3)
Block(1,3,-6,LOG:3)
Block(2,3,-6,LOG:3)
Block(-1,3,-5,LOG:3)
Block(0,3,-5,LOG:3)
Block(1,3,-5,LOG:3)
Block(2,3,-5,LOG:3)
Block(3,3,-5,LOG:3)
Block(-2,3,-4,LOG:3)
Block(-1,3,-4,LOG:3)
Block(0,3,-4,LOG:3)
Block(1,3,-4,LOG:3)
Block(2,3,-4,LOG:3)
Block(3,3,-4,LOG:3)
Block(4,3,-4,LOG:3)
Block(-1,3,-3,LOG:3)
Block(0,3,-3,LOG:3)
Block(1,3,-3,LOG:3)
Block(2,3,-3,LOG:3)
Block(3,3,-3,LOG:3)
Block(4,3,-3,LOG:3)
Block(0,3,-2,LOG:3)
Block(1,3,-2,LOG:3)
Block(2,3,-2,LOG:3)
Block(3,3,-2,LOG:3)
Block(4,3,-2,LOG:3)
Block(0,3,-1,LEAVES:3)
Block(1,3,-1,LOG:3)
Block(2,3,-1,LOG:3)
Block(3,3,-1,LOG:3)
Block(4,3,-1,LEAVES:3)
Block(-5,4,-15,LEAVES:3)
Block(-2,4,-7,LOG:3)
Block(-1,4,-7,LOG:3)
Block(0,4,-7,LEAVES:3)
Block(-2,4,-6,LOG:3)
Block(-1,4,-6,LOG:3)
Block(0,4,-6,LOG:3)
Block(1,4,-6,LOG:3)
Block(-2,4,-5,LOG:3)
Block(-1,4,-5,LOG:3)
Block(0,4,-5,LOG:3)
Block(1,4,-5,LOG:3)
Block(2,4,-5,LOG:3)
Block(3,4,-5,LOG:3)
Block(-2,4,-4,LOG:3)
Block(-1,4,-4,LOG:3)
Block(0,4,-4,LOG:3)
Block(1,4,-4,LOG:3)
Block(2,4,-4,LOG:3)
Block(3,4,-4,LOG:3)
Block(-1,4,-3,LOG:3)
Block(0,4,-3,LOG:3)
Block(1,4,-3,LOG:3)
Block(2,4,-3,LOG:3)
Block(3,4,-3,LOG:3)
Block(4,4,-3,LOG:3)
Block(-1,4,-2,LEAVES:3)
Block(0,4,-2,LOG:3)
Block(1,4,-2,LOG:3)
Block(2,4,-2,LOG:3)
Block(3,4,-2,LOG:3)
Block(4,4,-2,LOG:3)
Block(1,4,-1,LOG:3)
Block(2,4,-1,LOG:3)
Block(3,4,-1,LOG:3)
Block(4,4,-1,LEAVES:3)
Block(-5,5,-15,LEAVES:3)
Block(-2,5,-12,LEAVES:3)
Block(-10,5,-10,LEAVES:3)
Block(-6,5,-8,LEAVES:3)
Block(-3,5,-8,LOG:3)
Block(-3,5,-7,LOG:3)
Block(-2,5,-7,LOG:3)
Block(-1,5,-7,LOG:3)
Block(0,5,-7,LOG:3)
Block(1,5,-7,LEAVES:3)
Block(-3,5,-6,LOG:3)
Block(-2,5,-6,LOG:3)
Block(-1,5,-6,LOG:3)
Block(0,5,-6,LOG:3)
Block(1,5,-6,LOG:3)
Block(-2,5,-5,LOG:3)
Block(-1,5,-5,LOG:3)
Block(0,5,-5,LOG:3)
Block(1,5,-5,LOG:3)
Block(2,5,-5,LOG:3)
Block(-2,5,-4,LOG:3)
Block(-1,5,-4,LOG:3)
Block(0,5,-4,LOG:3)
Block(1,5,-4,LOG:3)
Block(2,5,-4,LOG:3)
Block(3,5,-4,LOG:3)
Block(-1,5,-3,LOG:3)
Block(0,5,-3,LOG:3)
Block(1,5,-3,LOG:3)
Block(2,5,-3,LOG:3)
Block(3,5,-3,LOG:3)
Block(-1,5,-2,LEAVES:3)
Block(0,5,-2,LOG:3)
Block(1,5,-2,LOG:3)
Block(2,5,-2,LOG:3)
Block(3,5,-2,LOG:3)
Block(4,5,-2,LOG:3)
Block(0,5,-1,LOG:3)
Block(1,5,-1,LOG:3)
Block(2,5,-1,LOG:3)
Block(3,5,-1,LOG:3)
Block(4,5,-1,LOG:3)
Block(2,5,0,LOG:3)
Block(3,5,0,LEAVES:3)
Block(-8,6,-15,LEAVES:3)
Block(-5,6,-15,LEAVES:3)
Block(-2,6,-12,LEAVES:3)
Block(-5,6,-11,LOG:3)
Block(-10,6,-10,LEAVES:3)
Block(-6,6,-10,LOG:3)
Block(-5,6,-10,LOG:3)
Block(-4,6,-10,LOG:3)
Block(-5,6,-9,LOG:3)
Block(-4,6,-9,LOG:3)
Block(-3,6,-9,LOG:3)
Block(-6,6,-8,LEAVES:3)
Block(-4,6,-8,LOG:3)
Block(-3,6,-8,LOG:3)
Block(-2,6,-8,LOG:3)
Block(-8,6,-7,LEAVES:3)
Block(-4,6,-7,LOG:3)
Block(-3,6,-7,LOG:3)
Block(-2,6,-7,LOG:3)
Block(-1,6,-7,LOG:3)
Block(-4,6,-6,LOG:3)
Block(-3,6,-6,LOG:3)
Block(-2,6,-6,LOG:3)
Block(-1,6,-6,LOG:3)
Block(0,6,-6,LOG:3)
Block(1,6,-6,LEAVES:3)
Block(-3,6,-5,LOG:3)
Block(-2,6,-5,LOG:3)
Block(-1,6,-5,LOG:3)
Block(0,6,-5,LOG:3)
Block(1,6,-5,LOG:3)
Block(2,6,-5,LOG:3)
Block(-2,6,-4,LOG:3)
Block(-1,6,-4,LOG:3)
Block(0,6,-4,LOG:3)
Block(1,6,-4,LOG:3)
Block(2,6,-4,LOG:3)
Block(-2,6,-3,LOG:3)
Block(-1,6,-3,LOG:3)
Block(0,6,-3,LOG:3)
Block(1,6,-3,LOG:3)
Block(2,6,-3,LOG:3)
Block(3,6,-3,LOG:3)
Block(-2,6,-2,LEAVES:3)
Block(-1,6,-2,LOG:3)
Block(0,6,-2,LOG:3)
Block(1,6,-2,LOG:3)
Block(2,6,-2,LOG:3)
Block(3,6,-2,LOG:3)
Block(4,6,-2,LOG:3)
Block(-1,6,-1,LEAVES:3)
Block(0,6,-1,LOG:3)
Block(1,6,-1,LOG:3)
Block(2,6,-1,LOG:3)
Block(3,6,-1,LOG:3)
Block(4,6,-1,LOG:3)
Block(2,6,0,LOG:3)
Block(3,6,0,LOG:3)
Block(4,6,0,LEAVES:3)
Block(-8,7,-15,LEAVES:3)
Block(-5,7,-15,LEAVES:3)
Block(-5,7,-14,LEAVES:3)
Block(-9,7,-12,LEAVES:3)
Block(-6,7,-12,LOG:3)
Block(-5,7,-12,LOG:3)
Block(-2,7,-12,LEAVES:3)
Block(-7,7,-11,LOG:3)
Block(-6,7,-11,LOG:3)
Block(-5,7,-11,LOG:3)
Block(-4,7,-11,LOG:3)
Block(-10,7,-10,LEAVES:3)
Block(-6,7,-10,LOG:3)
Block(-5,7,-10,LOG:3)
Block(-4,7,-10,LOG:3)
Block(-3,7,-10,LOG:3)
Block(-5,7,-9,LOG:3)
Block(-4,7,-9,LOG:3)
Block(-3,7,-9,LOG:3)
Block(-10,7,-8,LEAVES:3)
Block(-6,7,-8,LEAVES:3)
Block(-5,7,-8,LOG:3)
Block(-4,7,-8,LOG:3)
Block(-3,7,-8,LOG:3)
Block(-8,7,-7,LEAVES:3)
Block(-4,7,-7,LOG:3)
Block(-3,7,-7,LOG:3)
Block(-2,7,-7,LOG:3)
Block(-3,7,-6,LOG:3)
Block(-2,7,-6,LOG:3)
Block(-1,7,-6,LOG:3)
Block(1,7,-6,LEAVES:3)
Block(-3,7,-5,LOG:3)
Block(-2,7,-5,LOG:3)
Block(0,7,-5,LOG:3)
Block(1,7,-5,LOG:3)
Block(-3,7,-4,LOG:3)
Block(-2,7,-4,LOG:3)
Block(-1,7,-4,LOG:3)
Block(0,7,-4,LOG:3)
Block(1,7,-4,LOG:3)
Block(2,7,-4,LOG:3)
Block(-2,7,-3,LOG:3)
Block(-1,7,-3,LOG:3)
Block(0,7,-3,LOG:3)
Block(1,7,-3,LOG:3)
Block(2,7,-3,LOG:3)
Block(3,7,-3,LOG:3)
Block(-2,7,-2,LEAVES:3)
Block(-1,7,-2,LOG:3)
Block(0,7,-2,LOG:3)
Block(1,7,-2,LOG:3)
Block(2,7,-2,LOG:3)
Block(3,7,-2,LOG:3)
Block(0,7,-1,LOG:3)
Block(1,7,-1,LOG:3)
Block(2,7,-1,LOG:3)
Block(3,7,-1,LOG:3)
Block(4,7,-1,LOG:3)
Block(0,7,0,LEAVES:3)
Block(1,7,0,LOG:3)
Block(2,7,0,LOG:3)
Block(3,7,0,LOG:3)
Block(4,7,0,LOG:3)
Block(5,7,0,LEAVES:3)
Block(2,7,1,LOG:3)
Block(3,7,1,LOG:3)
Block(4,7,1,LOG:3)
Block(3,7,2,LOG:3)
Block(4,7,2,LOG:3)
Block(5,7,2,LOG:3)
Block(4,7,3,LOG:3)
Block(5,7,3,LOG:3)
Block(-8,8,-15,LEAVES:3)
Block(-5,8,-15,LEAVES:3)
Block(-7,8,-14,LEAVES:3)
Block(-6,8,-14,LEAVES:3)
Block(-5,8,-14,LOG:3)
Block(-4,8,-14,LEAVES:3)
Block(-8,8,-13,LEAVES:3)
Block(-7,8,-13,LEAVES:3)
Block(-6,8,-13,LEAVES:3)
Block(-5,8,-13,LOG:3)
Block(-3,8,-13,LEAVES:3)
Block(-9,8,-12,LEAVES:3)
Block(-7,8,-12,LOG:3)
Block(-6,8,-12,LOG:3)
Block(-5,8,-12,LOG:3)
Block(-4,8,-12,LOG:3)
Block(-3,8,-12,LEAVES:3)
Block(-2,8,-12,LEAVES:3)
Block(-10,8,-11,LEAVES:3)
Block(-9,8,-11,LEAVES:3)
Block(-8,8,-11,LEAVES:3)
Block(-7,8,-11,LOG:3)
Block(-6,8,-11,LOG:3)
Block(-5,8,-11,LOG:3)
Block(-4,8,-11,LOG:3)
Block(-3,8,-11,LEAVES:3)
Block(-2,8,-11,LEAVES:3)
Block(-10,8,-10,LEAVES:3)
Block(-9,8,-10,LEAVES:3)
Block(-7,8,-10,LOG:3)
Block(-6,8,-10,LOG:3)
Block(-5,8,-10,LOG:3)
Block(-4,8,-10,LOG:3)
Block(-3,8,-10,LEAVES:3)
Block(-11,8,-9,LEAVES:3)
Block(-10,8,-9,LEAVES:3)
Block(-9,8,-9,LEAVES:3)
Block(-6,8,-9,LOG:3)
Block(-5,8,-9,LOG:3)
Block(-10,8,-8,LEAVES:3)
Block(-9,8,-8,LEAVES:3)
Block(-8,8,-8,LEAVES:3)
Block(-7,8,-8,LEAVES:3)
Block(-6,8,-8,LEAVES:3)
Block(-5,8,-8,LOG:3)
Block(-9,8,-7,LEAVES:3)
Block(-8,8,-7,LEAVES:3)
Block(-7,8,-7,LEAVES:3)
Block(-6,8,-7,LEAVES:3)
Block(-7,8,-6,LEAVES:3)
Block(-2,8,-6,LOG:3)
Block(-1,8,-6,LOG:3)
Block(-3,8,-5,LOG:3)
Block(-2,8,-5,LOG:3)
Block(-1,8,-5,LOG:3)
Block(0,8,-5,LOG:3)
Block(1,8,-5,LOG:3)
Block(2,8,-5,LEAVES:3)
Block(-2,8,-4,LOG:3)
Block(-1,8,-4,LOG:3)
Block(0,8,-4,LOG:3)
Block(1,8,-4,LOG:3)
Block(2,8,-4,LOG:3)
Block(-2,8,-3,LOG:3)
Block(-1,8,-3,LOG:3)
Block(0,8,-3,LOG:3)
Block(1,8,-3,LOG:3)
Block(2,8,-3,LOG:3)
Block(-3,8,-2,LEAVES:3)
Block(-2,8,-2,LOG:3)
Block(-1,8,-2,LOG:3)
Block(0,8,-2,LOG:3)
Block(1,8,-2,LOG:3)
Block(2,8,-2,LOG:3)
Block(3,8,-2,LOG:3)
Block(-1,8,-1,LOG:3)
Block(0,8,-1,LOG:3)
Block(1,8,-1,LOG:3)
Block(2,8,-1,LOG:3)
Block(3,8,-1,LOG:3)
Block(0,8,0,LEAVES:3)
Block(1,8,0,LOG:3)
Block(2,8,0,LOG:3)
Block(3,8,0,LOG:3)
Block(4,8,0,LOG:3)
Block(5,8,0,LEAVES:3)
Block(2,8,1,LOG:3)
Block(3,8,1,LOG:3)
Block(4,8,1,LOG:3)
Block(5,8,1,LOG:3)
Block(2,8,2,LOG:3)
Block(3,8,2,LOG:3)
Block(4,8,2,LOG:3)
Block(5,8,2,LOG:3)
Block(3,8,3,LOG:3)
Block(4,8,3,LOG:3)
Block(5,8,3,LOG:3)
Block(4,8,4,LOG:3)
Block(5,8,4,LOG:3)
Block(6,8,4,LOG:3)
Block(5,8,5,LOG:3)
Block(6,8,5,LOG:3)
Block(6,8,6,LEAVES:3)
Block(-8,9,-15,LEAVES:3)
Block(-7,9,-15,LEAVES:3)
Block(-6,9,-15,LEAVES:3)
Block(-5,9,-15,LEAVES:3)
Block(-4,9,-15,LEAVES:3)
Block(-9,9,-14,LEAVES:3)
Block(-8,9,-14,LEAVES:3)
Block(-7,9,-14,LEAVES:3)
Block(-6,9,-14,LEAVES:3)
Block(-5,9,-14,LEAVES:3)
Block(-4,9,-14,LEAVES:3)
Block(-3,9,-14,LEAVES:3)
Block(-10,9,-13,LEAVES:3)
Block(-9,9,-13,LEAVES:3)
Block(-8,9,-13,LEAVES:3)
Block(-7,9,-13,LEAVES:3)
Block(-6,9,-13,LEAVES:3)
Block(-5,9,-13,LEAVES:3)
Block(-4,9,-13,LEAVES:3)
Block(-3,9,-13,LEAVES:3)
Block(-2,9,-13,LEAVES:3)
Block(-10,9,-12,LEAVES:3)
Block(-9,9,-12,LEAVES:3)
Block(-8,9,-12,LEAVES:3)
Block(-7,9,-12,LEAVES:3)
Block(-6,9,-12,LEAVES:3)
Block(-5,9,-12,LEAVES:3)
Block(-4,9,-12,LEAVES:3)
Block(-3,9,-12,LEAVES:3)
Block(-10,9,-11,LEAVES:3)
Block(-9,9,-11,LEAVES:3)
Block(-8,9,-11,LEAVES:3)
Block(-7,9,-11,LEAVES:3)
Block(-6,9,-11,LEAVES:3)
Block(-5,9,-11,LEAVES:3)
Block(-4,9,-11,LEAVES:3)
Block(-3,9,-11,LEAVES:3)
Block(-2,9,-11,LEAVES:3)
Block(-11,9,-10,LEAVES:3)
Block(-10,9,-10,LEAVES:3)
Block(-9,9,-10,LEAVES:3)
Block(-8,9,-10,LEAVES:3)
Block(-7,9,-10,LEAVES:3)
Block(-6,9,-10,LEAVES:3)
Block(-5,9,-10,LEAVES:3)
Block(-4,9,-10,LEAVES:3)
Block(-3,9,-10,LEAVES:3)
Block(-11,9,-9,LEAVES:3)
Block(-10,9,-9,LEAVES:3)
Block(-9,9,-9,LEAVES:3)
Block(-8,9,-9,LEAVES:3)
Block(-7,9,-9,LEAVES:3)
Block(-6,9,-9,LEAVES:3)
Block(-5,9,-9,LEAVES:3)
Block(-4,9,-9,LEAVES:3)
Block(-3,9,-9,LEAVES:3)
Block(-2,9,-9,LEAVES:3)
Block(-11,9,-8,LEAVES:3)
Block(-10,9,-8,LEAVES:3)
Block(-9,9,-8,LEAVES:3)
Block(-8,9,-8,LEAVES:3)
Block(-7,9,-8,LEAVES:3)
Block(-6,9,-8,LEAVES:3)
Block(-5,9,-8,LEAVES:3)
Block(-4,9,-8,LEAVES:3)
Block(-3,9,-8,LEAVES:3)
Block(-10,9,-7,LEAVES:3)
Block(-9,9,-7,LEAVES:3)
Block(-8,9,-7,LEAVES:3)
Block(-7,9,-7,LEAVES:3)
Block(-6,9,-7,LEAVES:3)
Block(-4,9,-7,LEAVES:3)
Block(-8,9,-6,LEAVES:3)
Block(-7,9,-6,LEAVES:3)
Block(-6,9,-6,LEAVES:3)
Block(-2,9,-5,LOG:3)
Block(-1,9,-5,LOG:3)
Block(0,9,-5,LOG:3)
Block(1,9,-5,LOG:3)
Block(2,9,-5,LEAVES:3)
Block(-2,9,-4,LOG:3)
Block(-1,9,-4,LOG:3)
Block(0,9,-4,LOG:3)
Block(1,9,-4,LOG:3)
Block(2,9,-4,LOG:3)
Block(-2,9,-3,LOG:3)
Block(-1,9,-3,LOG:3)
Block(0,9,-3,LOG:3)
Block(1,9,-3,LOG:3)
Block(2,9,-3,LOG:3)
Block(-3,9,-2,LEAVES:3)
Block(-2,9,-2,LOG:3)
Block(-1,9,-2,LOG:3)
Block(0,9,-2,LOG:3)
Block(1,9,-2,LOG:3)
Block(2,9,-2,LOG:3)
Block(-1,9,-1,LOG:3)
Block(0,9,-1,LOG:3)
Block(1,9,-1,LOG:3)
Block(2,9,-1,LOG:3)
Block(3,9,-1,LOG:3)
Block(1,9,0,LEAVES:3)
Block(2,9,0,LOG:3)
Block(3,9,0,LOG:3)
Block(2,9,1,LOG:3)
Block(3,9,1,LOG:3)
Block(4,9,1,LOG:3)
Block(5,9,1,LEAVES:3)
Block(2,9,2,LOG:3)
Block(3,9,2,LOG:3)
Block(4,9,2,LOG:3)
Block(5,9,2,LOG:3)
Block(7,9,2,LEAVES:3)
Block(2,9,3,LOG:3)
Block(3,9,3,LOG:3)
Block(4,9,3,LOG:3)
Block(5,9,3,LOG:3)
Block(6,9,3,LOG:3)
Block(3,9,4,LOG:3)
Block(4,9,4,LOG:3)
Block(5,9,4,LOG:3)
Block(6,9,4,LOG:3)
Block(4,9,5,LOG:3)
Block(5,9,5,LOG:3)
Block(6,9,5,LOG:3)
Block(7,9,5,LEAVES:3)
Block(2,9,6,LEAVES:3)
Block(5,9,6,LOG:3)
Block(6,9,6,LOG:3)
Block(10,9,6,LEAVES:3)
Block(5,9,7,LEAVES:3)
Block(-5,10,-15,LEAVES:3)
Block(-9,10,-14,LEAVES:3)
Block(-8,10,-14,LEAVES:3)
Block(-7,10,-14,LEAVES:3)
Block(-6,10,-14,LEAVES:3)
Block(-5,10,-14,LEAVES:3)
Block(-4,10,-14,LEAVES:3)
Block(-9,10,-13,LEAVES:3)
Block(-8,10,-13,LEAVES:3)
Block(-7,10,-13,LEAVES:3)
Block(-6,10,-13,LEAVES:3)
Block(-5,10,-13,LEAVES:3)
Block(-4,10,-13,LEAVES:3)
Block(-10,10,-12,LEAVES:3)
Block(-9,10,-12,LEAVES:3)
Block(-8,10,-12,LEAVES:3)
Block(-6,10,-12,LEAVES:3)
Block(-5,10,-12,LEAVES:3)
Block(-4,10,-12,LEAVES:3)
Block(-3,10,-12,LEAVES:3)
Block(-10,10,-11,LEAVES:3)
Block(-8,10,-11,LEAVES:3)
Block(-6,10,-11,LEAVES:3)
Block(-5,10,-11,LEAVES:3)
Block(-4,10,-11,LEAVES:3)
Block(-3,10,-11,LEAVES:3)
Block(-2,10,-11,LEAVES:3)
Block(-10,10,-10,LEAVES:3)
Block(-9,10,-10,LEAVES:3)
Block(-8,10,-10,LEAVES:3)
Block(-7,10,-10,LEAVES:3)
Block(-6,10,-10,LEAVES:3)
Block(-5,10,-10,LEAVES:3)
Block(-4,10,-10,LEAVES:3)
Block(-3,10,-10,LEAVES:3)
Block(-11,10,-9,LEAVES:3)
Block(-10,10,-9,LEAVES:3)
Block(-9,10,-9,LEAVES:3)
Block(-8,10,-9,LEAVES:3)
Block(-7,10,-9,LEAVES:3)
Block(-6,10,-9,LEAVES:3)
Block(-5,10,-9,LEAVES:3)
Block(-4,10,-9,LEAVES:3)
Block(-3,10,-9,LEAVES:3)
Block(-10,10,-8,LEAVES:3)
Block(-9,10,-8,LEAVES:3)
Block(-8,10,-8,LEAVES:3)
Block(-7,10,-8,LEAVES:3)
Block(-6,10,-8,LEAVES:3)
Block(-5,10,-8,LEAVES:3)
Block(-4,10,-8,LEAVES:3)
Block(-3,10,-8,LEAVES:3)
Block(-9,10,-7,LEAVES:3)
Block(-8,10,-7,LEAVES:3)
Block(-7,10,-7,LEAVES:3)
Block(-6,10,-7,LEAVES:3)
Block(-5,10,-7,LEAVES:3)
Block(-4,10,-7,LEAVES:3)
Block(-7,10,-6,LEAVES:3)
Block(-6,10,-6,LEAVES:3)
Block(-5,10,-6,LEAVES:3)
Block(0,10,-6,LOG:3)
Block(1,10,-6,LOG:3)
Block(-1,10,-5,LOG:3)
Block(0,10,-5,LOG:3)
Block(1,10,-5,LOG:3)
Block(2,10,-5,LOG:3)
Block(3,10,-5,LEAVES:3)
Block(-2,10,-4,LOG:3)
Block(-1,10,-4,LOG:3)
Block(0,10,-4,LOG:3)
Block(1,10,-4,LOG:3)
Block(2,10,-4,LOG:3)
Block(-3,10,-3,LEAVES:3)
Block(-2,10,-3,LOG:3)
Block(-1,10,-3,LOG:3)
Block(0,10,-3,LOG:3)
Block(1,10,-3,LOG:3)
Block(2,10,-3,LOG:3)
Block(-2,10,-2,LOG:3)
Block(-1,10,-2,LOG:3)
Block(0,10,-2,LOG:3)
Block(1,10,-2,LOG:3)
Block(2,10,-2,LOG:3)
Block(-2,10,-1,LOG:3)
Block(-1,10,-1,LOG:3)
Block(0,10,-1,LOG:3)
Block(1,10,-1,LOG:3)
Block(2,10,-1,LOG:3)
Block(1,10,0,LEAVES:3)
Block(2,10,0,LOG:3)
Block(3,10,0,LOG:3)
Block(2,10,1,LOG:3)
Block(3,10,1,LOG:3)
Block(4,10,1,LEAVES:3)
Block(3,10,2,LOG:3)
Block(4,10,2,LOG:3)
Block(7,10,2,LEAVES:3)
Block(3,10,3,LOG:3)
Block(4,10,3,LOG:3)
Block(5,10,3,LOG:3)
Block(4,10,4,LOG:3)
Block(5,10,4,LOG:3)
Block(6,10,4,LOG:3)
Block(7,10,4,LEAVES:3)
Block(4,10,5,LOG:3)
Block(5,10,5,LOG:3)
Block(6,10,5,LOG:3)
Block(7,10,5,LOG:3)
Block(2,10,6,LEAVES:3)
Block(4,10,6,LOG:3)
Block(5,10,6,LOG:3)
Block(6,10,6,LOG:3)
Block(10,10,6,LEAVES:3)
Block(4,10,7,LEAVES:3)
Block(5,10,7,LOG:3)
Block(4,10,9,LEAVES:3)
Block(6,10,10,LEAVES:3)
Block(-8,11,-14,LEAVES:3)
Block(-6,11,-14,LEAVES:3)
Block(-8,11,-13,LEAVES:3)
Block(-7,11,-13,LEAVES:3)
Block(-6,11,-13,LEAVES:3)
Block(-5,11,-13,LEAVES:3)
Block(-9,11,-12,LEAVES:3)
Block(-6,11,-12,LEAVES:3)
Block(-9,11,-11,LEAVES:3)
Block(-7,11,-11,LEAVES:3)
Block(-6,11,-11,LEAVES:3)
Block(-5,11,-11,LEAVES:3)
Block(-4,11,-11,LEAVES:3)
Block(-3,11,-11,LEAVES:3)
Block(-10,11,-10,LEAVES:3)
Block(-9,11,-10,LEAVES:3)
Block(-8,11,-10,LEAVES:3)
Block(-7,11,-10,LEAVES:3)
Block(-6,11,-10,LEAVES:3)
Block(-5,11,-10,LEAVES:3)
Block(-4,11,-10,LEAVES:3)
Block(-9,11,-9,LEAVES:3)
Block(-7,11,-9,LEAVES:3)
Block(-6,11,-9,LEAVES:3)
Block(-5,11,-9,LEAVES:3)
Block(-4,11,-9,LEAVES:3)
Block(-3,11,-9,LEAVES:3)
Block(-8,11,-8,LEAVES:3)
Block(-7,11,-8,LEAVES:3)
Block(-6,11,-8,LEAVES:3)
Block(-5,11,-8,LEAVES:3)
Block(-4,11,-8,LEAVES:3)
Block(-7,11,-7,LEAVES:3)
Block(-6,11,-7,LEAVES:3)
Block(-5,11,-7,LEAVES:3)
Block(-6,11,-6,LEAVES:3)
Block(-1,11,-6,LOG:3)
Block(0,11,-6,LOG:3)
Block(1,11,-6,LOG:3)
Block(2,11,-6,LOG:3)
Block(-1,11,-5,LOG:3)
Block(0,11,-5,LOG:3)
Block(1,11,-5,LOG:3)
Block(2,11,-5,LOG:3)
Block(-1,11,-4,LOG:3)
Block(0,11,-4,LOG:3)
Block(1,11,-4,LOG:3)
Block(2,11,-4,LOG:3)
Block(3,11,-4,LEAVES:3)
Block(-3,11,-3,LEAVES:3)
Block(-2,11,-3,LOG:3)
Block(-1,11,-3,LOG:3)
Block(0,11,-3,LOG:3)
Block(1,11,-3,LOG:3)
Block(2,11,-3,LOG:3)
Block(-3,11,-2,LOG:3)
Block(-2,11,-2,LOG:3)
Block(-1,11,-2,LOG:3)
Block(0,11,-2,LOG:3)
Block(1,11,-2,LOG:3)
Block(2,11,-2,LOG:3)
Block(-3,11,-1,LOG:3)
Block(-2,11,-1,LOG:3)
Block(-1,11,-1,LOG:3)
Block(0,11,-1,LOG:3)
Block(1,11,-1,LOG:3)
Block(2,11,-1,LEAVES:3)
Block(-4,11,0,LOG:3)
Block(-3,11,0,LOG:3)
Block(0,11,0,LEAVES:3)
Block(3,11,2,LEAVES:3)
Block(4,11,2,LEAVES:3)
Block(7,11,2,LEAVES:3)
Block(4,11,3,LEAVES:3)
Block(9,11,3,LEAVES:3)
Block(5,11,4,LOG:3)
Block(6,11,4,LOG:3)
Block(7,11,4,LOG:3)
Block(8,11,4,LEAVES:3)
Block(4,11,5,LOG:3)
Block(5,11,5,LOG:3)
Block(6,11,5,LOG:3)
Block(7,11,5,LOG:3)
Block(2,11,6,LEAVES:3)
Block(4,11,6,LOG:3)
Block(5,11,6,LOG:3)
Block(6,11,6,LOG:3)
Block(7,11,6,LOG:3)
Block(10,11,6,LEAVES:3)
Block(4,11,7,LEAVES:3)
Block(5,11,7,LOG:3)
Block(6,11,7,LOG:3)
Block(10,11,8,LEAVES:3)
Block(4,11,9,LEAVES:3)
Block(6,11,10,LEAVES:3)
Block(8,11,10,LEAVES:3)
Block(-7,12,-13,LEAVES:3)
Block(-8,12,-12,LEAVES:3)
Block(-7,12,-12,LEAVES:3)
Block(-6,12,-12,LEAVES:3)
Block(-7,12,-11,LEAVES:3)
Block(-5,12,-11,LEAVES:3)
Block(-4,12,-11,LEAVES:3)
Block(-9,12,-10,LEAVES:3)
Block(-8,12,-10,LEAVES:3)
Block(-6,12,-10,LEAVES:3)
Block(-7,12,-9,LEAVES:3)
Block(-6,12,-9,LEAVES:3)
Block(-5,12,-9,LEAVES:3)
Block(-4,12,-9,LEAVES:3)
Block(-7,12,-8,LEAVES:3)
Block(-6,12,-8,LEAVES:3)
Block(-5,12,-8,LEAVES:3)
Block(-6,12,-7,LEAVES:3)
Block(2,12,-7,LOG:3)
Block(0,12,-6,LOG:3)
Block(1,12,-6,LOG:3)
Block(2,12,-6,LOG:3)
Block(3,12,-6,LOG:3)
Block(-1,12,-5,LOG:3)
Block(0,12,-5,LOG:3)
Block(1,12,-5,LOG:3)
Block(2,12,-5,LOG:3)
Block(3,12,-5,LOG:3)
Block(-2,12,-4,LEAVES:3)
Block(-1,12,-4,LOG:3)
Block(0,12,-4,LOG:3)
Block(1,12,-4,LOG:3)
Block(2,12,-4,LOG:3)
Block(3,12,-4,LEAVES:3)
Block(-3,12,-3,LOG:3)
Block(-2,12,-3,LOG:3)
Block(-1,12,-3,LOG:3)
Block(0,12,-3,LOG:3)
Block(1,12,-3,LOG:3)
Block(2,12,-3,LOG:3)
Block(-3,12,-2,LOG:3)
Block(-2,12,-2,LOG:3)
Block(-1,12,-2,LOG:3)
Block(0,12,-2,LOG:3)
Block(1,12,-2,LOG:3)
Block(2,12,-2,LOG:3)
Block(-4,12,-1,LOG:3)
Block(-3,12,-1,LOG:3)
Block(-2,12,-1,LOG:3)
Block(-1,12,-1,LOG:3)
Block(0,12,-1,LOG:3)
Block(1,12,-1,LOG:3)
Block(2,12,-1,LEAVES:3)
Block(-5,12,0,LOG:3)
Block(-4,12,0,LOG:3)
Block(-3,12,0,LOG:3)
Block(-2,12,0,LOG:3)
Block(0,12,0,LEAVES:3)
Block(-5,12,1,LOG:3)
Block(-4,12,1,LOG:3)
Block(5,12,2,LEAVES:3)
Block(7,12,2,LEAVES:3)
Block(3,12,3,LEAVES:3)
Block(4,12,3,LEAVES:3)
Block(5,12,3,LEAVES:3)
Block(6,12,3,LEAVES:3)
Block(7,12,3,LEAVES:3)
Block(9,12,3,LEAVES:3)
Block(3,12,4,LEAVES:3)
Block(4,12,4,LEAVES:3)
Block(5,12,4,LEAVES:3)
Block(6,12,4,LOG:3)
Block(7,12,4,LOG:3)
Block(8,12,4,LEAVES:3)
Block(4,12,5,LEAVES:3)
Block(5,12,5,LOG:3)
Block(6,12,5,LOG:3)
Block(7,12,5,LOG:3)
Block(8,12,5,LOG:3)
Block(9,12,5,LEAVES:3)
Block(2,12,6,LEAVES:3)
Block(3,12,6,LEAVES:3)
Block(4,12,6,LEAVES:3)
Block(5,12,6,LOG:3)
Block(6,12,6,LOG:3)
Block(7,12,6,LOG:3)
Block(8,12,6,LOG:3)
Block(9,12,6,LOG:3)
Block(10,12,6,LEAVES:3)
Block(3,12,7,LEAVES:3)
Block(4,12,7,LEAVES:3)
Block(5,12,7,LEAVES:3)
Block(6,12,7,LOG:3)
Block(7,12,7,LOG:3)
Block(9,12,7,LEAVES:3)
Block(4,12,8,LEAVES:3)
Block(5,12,8,LEAVES:3)
Block(10,12,8,LEAVES:3)
Block(4,12,9,LEAVES:3)
Block(5,12,10,LEAVES:3)
Block(6,12,10,LEAVES:3)
Block(8,12,10,LEAVES:3)
Block(3,13,-11,LEAVES:3)
Block(2,13,-7,LOG:3)
Block(3,13,-7,LOG:3)
Block(1,13,-6,LOG:3)
Block(2,13,-6,LOG:3)
Block(3,13,-6,LOG:3)
Block(4,13,-6,LOG:3)
Block(-1,13,-5,LOG:3)
Block(0,13,-5,LOG:3)
Block(1,13,-5,LOG:3)
Block(2,13,-5,LOG:3)
Block(3,13,-5,LOG:3)
Block(4,13,-5,LOG:3)
Block(-2,13,-4,LEAVES:3)
Block(-1,13,-4,LOG:3)
Block(0,13,-4,LOG:3)
Block(1,13,-4,LOG:3)
Block(2,13,-4,LOG:3)
Block(3,13,-4,LOG:3)
Block(4,13,-4,LEAVES:3)
Block(-3,13,-3,LOG:3)
Block(-2,13,-3,LOG:3)
Block(-1,13,-3,LOG:3)
Block(0,13,-3,LOG:3)
Block(1,13,-3,LOG:3)
Block(2,13,-3,LOG:3)
Block(-4,13,-2,LOG:3)
Block(-3,13,-2,LOG:3)
Block(-2,13,-2,LOG:3)
Block(-1,13,-2,LOG:3)
Block(0,13,-2,LOG:3)
Block(1,13,-2,LOG:3)
Block(2,13,-2,LOG:3)
Block(-5,13,-1,LOG:3)
Block(-4,13,-1,LOG:3)
Block(-3,13,-1,LOG:3)
Block(-2,13,-1,LOG:3)
Block(-1,13,-1,LOG:3)
Block(0,13,-1,LOG:3)
Block(1,13,-1,LOG:3)
Block(2,13,-1,LEAVES:3)
Block(-6,13,0,LOG:3)
Block(-5,13,0,LOG:3)
Block(-4,13,0,LOG:3)
Block(-3,13,0,LOG:3)
Block(-2,13,0,LOG:3)
Block(-1,13,0,LEAVES:3)
Block(-8,13,1,LEAVES:3)
Block(-7,13,1,LOG:3)
Block(-6,13,1,LOG:3)
Block(-5,13,1,LOG:3)
Block(-4,13,1,LOG:3)
Block(-3,13,1,LOG:3)
Block(4,13,1,LEAVES:3)
Block(5,13,1,LEAVES:3)
Block(6,13,1,LEAVES:3)
Block(7,13,1,LEAVES:3)
Block(8,13,1,LEAVES:3)
Block(-14,13,2,LEAVES:3)
Block(-7,13,2,LEAVES:3)
Block(-5,13,2,LOG:3)
Block(-4,13,2,LOG:3)
Block(4,13,2,LEAVES:3)
Block(5,13,2,LEAVES:3)
Block(6,13,2,LEAVES:3)
Block(7,13,2,LEAVES:3)
Block(8,13,2,LEAVES:3)
Block(5,13,3,LEAVES:3)
Block(6,13,3,LEAVES:3)
Block(7,13,3,LEAVES:3)
Block(8,13,3,LEAVES:3)
Block(9,13,3,LEAVES:3)
Block(2,13,4,LEAVES:3)
Block(3,13,4,LEAVES:3)
Block(4,13,4,LEAVES:3)
Block(5,13,4,LEAVES:3)
Block(6,13,4,LEAVES:3)
Block(7,13,4,LEAVES:3)
Block(8,13,4,LEAVES:3)
Block(9,13,4,LEAVES:3)
Block(10,13,4,LEAVES:3)
Block(2,13,5,LEAVES:3)
Block(3,13,5,LEAVES:3)
Block(4,13,5,LEAVES:3)
Block(5,13,5,LEAVES:3)
Block(6,13,5,LEAVES:3)
Block(7,13,5,LOG:3)
Block(8,13,5,LEAVES:3)
Block(9,13,5,LEAVES:3)
Block(10,13,5,LEAVES:3)
Block(3,13,6,LEAVES:3)
Block(4,13,6,LEAVES:3)
Block(5,13,6,LEAVES:3)
Block(6,13,6,LOG:3)
Block(7,13,6,LOG:3)
Block(8,13,6,LOG:3)
Block(9,13,6,LEAVES:3)
Block(10,13,6,LEAVES:3)
Block(2,13,7,LEAVES:3)
Block(3,13,7,LEAVES:3)
Block(4,13,7,LEAVES:3)
Block(5,13,7,LEAVES:3)
Block(6,13,7,LEAVES:3)
Block(7,13,7,LOG:3)
Block(9,13,7,LEAVES:3)
Block(10,13,7,LEAVES:3)
Block(2,13,8,LEAVES:3)
Block(3,13,8,LEAVES:3)
Block(4,13,8,LEAVES:3)
Block(5,13,8,LEAVES:3)
Block(6,13,8,LEAVES:3)
Block(7,13,8,LOG:3)
Block(9,13,8,LEAVES:3)
Block(10,13,8,LEAVES:3)
Block(3,13,9,LEAVES:3)
Block(4,13,9,LEAVES:3)
Block(5,13,9,LEAVES:3)
Block(6,13,9,LEAVES:3)
Block(7,13,9,LOG:3)
Block(8,13,9,LEAVES:3)
Block(9,13,9,LEAVES:3)
Block(4,13,10,LEAVES:3)
Block(5,13,10,LEAVES:3)
Block(6,13,10,LEAVES:3)
Block(7,13,10,LEAVES:3)
Block(8,13,10,LEAVES:3)
Block(3,14,-11,LEAVES:3)
Block(8,14,-10,LEAVES:3)
Block(3,14,-7,LOG:3)
Block(4,14,-7,LOG:3)
Block(5,14,-7,LEAVES:3)
Block(2,14,-6,LOG:3)
Block(3,14,-6,LOG:3)
Block(4,14,-6,LOG:3)
Block(5,14,-6,LOG:3)
Block(-1,14,-5,LOG:3)
Block(0,14,-5,LOG:3)
Block(1,14,-5,LOG:3)
Block(2,14,-5,LOG:3)
Block(3,14,-5,LOG:3)
Block(4,14,-5,LOG:3)
Block(5,14,-5,LEAVES:3)
Block(-2,14,-4,LEAVES:3)
Block(-1,14,-4,LOG:3)
Block(0,14,-4,LOG:3)
Block(1,14,-4,LOG:3)
Block(2,14,-4,LOG:3)
Block(3,14,-4,LOG:3)
Block(4,14,-4,LOG:3)
Block(-12,14,-3,LEAVES:3)
Block(-7,14,-3,LEAVES:3)
Block(-2,14,-3,LOG:3)
Block(-1,14,-3,LOG:3)
Block(0,14,-3,LOG:3)
Block(1,14,-3,LOG:3)
Block(2,14,-3,LOG:3)
Block(3,14,-3,LOG:3)
Block(-3,14,-2,LOG:3)
Block(-2,14,-2,LOG:3)
Block(-1,14,-2,LOG:3)
Block(0,14,-2,LOG:3)
Block(1,14,-2,LOG:3)
Block(2,14,-2,LOG:3)
Block(-6,14,-1,LOG:3)
Block(-5,14,-1,LOG:3)
Block(-4,14,-1,LOG:3)
Block(-3,14,-1,LOG:3)
Block(-2,14,-1,LOG:3)
Block(-1,14,-1,LOG:3)
Block(0,14,-1,LOG:3)
Block(1,14,-1,LOG:3)
Block(2,14,-1,LOG:3)
Block(3,14,-1,LEAVES:3)
Block(-8,14,0,LEAVES:3)
Block(-7,14,0,LOG:3)
Block(-6,14,0,LOG:3)
Block(-5,14,0,LOG:3)
Block(-4,14,0,LOG:3)
Block(-3,14,0,LOG:3)
Block(-8,14,1,LOG:3)
Block(-7,14,1,LOG:3)
Block(-6,14,1,LOG:3)
Block(-5,14,1,LOG:3)
Block(-4,14,1,LOG:3)
Block(6,14,1,LEAVES:3)
Block(7,14,1,LEAVES:3)
Block(-14,14,2,LEAVES:3)
Block(-7,14,2,LOG:3)
Block(-6,14,2,LOG:3)
Block(-5,14,2,LOG:3)
Block(5,14,2,LEAVES:3)
Block(7,14,2,LEAVES:3)
Block(8,14,2,LEAVES:3)
Block(-7,14,3,LEAVES:3)
Block(4,14,3,LEAVES:3)
Block(5,14,3,LEAVES:3)
Block(6,14,3,LEAVES:3)
Block(7,14,3,LEAVES:3)
Block(8,14,3,LEAVES:3)
Block(3,14,4,LEAVES:3)
Block(4,14,4,LEAVES:3)
Block(6,14,4,LEAVES:3)
Block(7,14,4,LEAVES:3)
Block(8,14,4,LEAVES:3)
Block(9,14,4,LEAVES:3)
Block(-5,14,5,LEAVES:3)
Block(5,14,5,LEAVES:3)
Block(6,14,5,LEAVES:3)
Block(7,14,5,LEAVES:3)
Block(8,14,5,LEAVES:3)
Block(9,14,5,LEAVES:3)
Block(2,14,6,LEAVES:3)
Block(3,14,6,LEAVES:3)
Block(4,14,6,LEAVES:3)
Block(5,14,6,LEAVES:3)
Block(6,14,6,LEAVES:3)
Block(7,14,6,LOG:3)
Block(8,14,6,LEAVES:3)
Block(9,14,6,LEAVES:3)
Block(10,14,6,LEAVES:3)
Block(2,14,7,LEAVES:3)
Block(3,14,7,LEAVES:3)
Block(4,14,7,LEAVES:3)
Block(5,14,7,LEAVES:3)
Block(6,14,7,LEAVES:3)
Block(7,14,7,LEAVES:3)
Block(9,14,7,LEAVES:3)
Block(10,14,7,LEAVES:3)
Block(-11,14,8,LEAVES:3)
Block(3,14,8,LEAVES:3)
Block(4,14,8,LEAVES:3)
Block(6,14,8,LEAVES:3)
Block(7,14,8,LEAVES:3)
Block(8,14,8,LEAVES:3)
Block(9,14,8,LEAVES:3)
Block(10,14,8,LEAVES:3)
Block(4,14,9,LEAVES:3)
Block(5,14,9,LEAVES:3)
Block(7,14,9,LEAVES:3)
Block(8,14,9,LEAVES:3)
Block(5,14,10,LEAVES:3)
Block(6,14,10,LEAVES:3)
Block(3,15,-11,LEAVES:3)
Block(8,15,-10,LEAVES:3)
Block(3,15,-8,LOG:3)
Block(4,15,-8,LOG:3)
Block(5,15,-8,LEAVES:3)
Block(3,15,-7,LOG:3)
Block(4,15,-7,LOG:3)
Block(5,15,-7,LOG:3)
Block(3,15,-6,LOG:3)
Block(4,15,-6,LOG:3)
Block(5,15,-6,LOG:3)
Block(6,15,-6,LEAVES:3)
Block(-1,15,-5,LOG:3)
Block(0,15,-5,LOG:3)
Block(1,15,-5,LOG:3)
Block(2,15,-5,LOG:3)
Block(3,15,-5,LOG:3)
Block(4,15,-5,LOG:3)
Block(5,15,-5,LOG:3)
Block(-2,15,-4,LOG:3)
Block(-1,15,-4,LOG:3)
Block(0,15,-4,LOG:3)
Block(1,15,-4,LOG:3)
Block(2,15,-4,LOG:3)
Block(3,15,-4,LOG:3)
Block(7,15,-4,LEAVES:3)
Block(-12,15,-3,LEAVES:3)
Block(-7,15,-3,LEAVES:3)
Block(-2,15,-3,LOG:3)
Block(-1,15,-3,LOG:3)
Block(0,15,-3,LOG:3)
Block(1,15,-3,LOG:3)
Block(2,15,-3,LOG:3)
Block(-2,15,-2,LOG:3)
Block(-1,15,-2,LOG:3)
Block(0,15,-2,LOG:3)
Block(1,15,-2,LOG:3)
Block(2,15,-2,LOG:3)
Block(3,15,-2,LEAVES:3)
Block(-13,15,-1,LEAVES:3)
Block(-7,15,-1,LOG:3)
Block(-6,15,-1,LOG:3)
Block(-5,15,-1,LOG:3)
Block(-1,15,-1,LOG:3)
Block(0,15,-1,LOG:3)
Block(1,15,-1,LOG:3)
Block(2,15,-1,LOG:3)
Block(-9,15,0,LEAVES:3)
Block(-8,15,0,LOG:3)
Block(-7,15,0,LOG:3)
Block(-6,15,0,LOG:3)
Block(-5,15,0,LOG:3)
Block(-4,15,0,LOG:3)
Block(1,15,0,LOG:3)
Block(-9,15,1,LOG:3)
Block(-8,15,1,LOG:3)
Block(-7,15,1,LOG:3)
Block(-6,15,1,LOG:3)
Block(-5,15,1,LOG:3)
Block(-14,15,2,LEAVES:3)
Block(-8,15,2,LOG:3)
Block(-7,15,2,LOG:3)
Block(-6,15,2,LOG:3)
Block(-6,15,3,LEAVES:3)
Block(6,15,3,LEAVES:3)
Block(7,15,3,LEAVES:3)
Block(-15,15,4,LEAVES:3)
Block(-3,15,4,LEAVES:3)
Block(6,15,4,LEAVES:3)
Block(8,15,4,LEAVES:3)
Block(-5,15,5,LEAVES:3)
Block(5,15,5,LEAVES:3)
Block(6,15,5,LEAVES:3)
Block(7,15,5,LEAVES:3)
Block(8,15,5,LEAVES:3)
Block(9,15,5,LEAVES:3)
Block(-13,15,6,LEAVES:3)
Block(3,15,6,LEAVES:3)
Block(5,15,6,LEAVES:3)
Block(6,15,6,LEAVES:3)
Block(7,15,6,LEAVES:3)
Block(9,15,6,LEAVES:3)
Block(-7,15,7,LEAVES:3)
Block(3,15,7,LEAVES:3)
Block(4,15,7,LEAVES:3)
Block(5,15,7,LEAVES:3)
Block(6,15,7,LEAVES:3)
Block(7,15,7,LEAVES:3)
Block(8,15,7,LEAVES:3)
Block(9,15,7,LEAVES:3)
Block(10,15,7,LEAVES:3)
Block(-11,15,8,LEAVES:3)
Block(4,15,8,LEAVES:3)
Block(6,15,8,LEAVES:3)
Block(8,15,8,LEAVES:3)
Block(9,15,8,LEAVES:3)
Block(7,15,9,LEAVES:3)
Block(5,16,-12,LEAVES:3)
Block(3,16,-11,LEAVES:3)
Block(8,16,-10,LEAVES:3)
Block(4,16,-9,LEAVES:3)
Block(3,16,-8,LOG:3)
Block(4,16,-8,LOG:3)
Block(5,16,-8,LOG:3)
Block(3,16,-7,LOG:3)
Block(4,16,-7,LOG:3)
Block(5,16,-7,LOG:3)
Block(6,16,-7,LOG:3)
Block(10,16,-7,LEAVES:3)
Block(3,16,-6,LOG:3)
Block(4,16,-6,LOG:3)
Block(5,16,-6,LOG:3)
Block(6,16,-6,LOG:3)
Block(7,16,-6,LEAVES:3)
Block(-3,16,-5,LEAVES:3)
Block(-2,16,-5,LOG:3)
Block(-1,16,-5,LOG:3)
Block(0,16,-5,LOG:3)
Block(1,16,-5,LOG:3)
Block(4,16,-5,LOG:3)
Block(5,16,-5,LOG:3)
Block(-10,16,-4,LEAVES:3)
Block(-3,16,-4,LOG:3)
Block(-2,16,-4,LOG:3)
Block(-1,16,-4,LOG:3)
Block(0,16,-4,LOG:3)
Block(1,16,-4,LOG:3)
Block(2,16,-4,LOG:3)
Block(7,16,-4,LEAVES:3)
Block(-12,16,-3,LEAVES:3)
Block(-7,16,-3,LEAVES:3)
Block(-3,16,-3,LOG:3)
Block(-2,16,-3,LOG:3)
Block(-1,16,-3,LOG:3)
Block(0,16,-3,LOG:3)
Block(1,16,-3,LOG:3)
Block(2,16,-3,LOG:3)
Block(5,16,-3,LEAVES:3)
Block(-3,16,-2,LOG:3)
Block(-2,16,-2,LOG:3)
Block(-1,16,-2,LOG:3)
Block(0,16,-2,LOG:3)
Block(1,16,-2,LOG:3)
Block(2,16,-2,LOG:3)
Block(3,16,-2,LEAVES:3)
Block(-13,16,-1,LEAVES:3)
Block(-9,16,-1,LEAVES:3)
Block(-2,16,-1,LOG:3)
Block(-1,16,-1,LOG:3)
Block(0,16,-1,LOG:3)
Block(1,16,-1,LOG:3)
Block(2,16,-1,LOG:3)
Block(3,16,-1,LOG:3)
Block(-9,16,0,LOG:3)
Block(-8,16,0,LOG:3)
Block(-7,16,0,LOG:3)
Block(-6,16,0,LOG:3)
Block(-5,16,0,LOG:3)
Block(0,16,0,LOG:3)
Block(1,16,0,LOG:3)
Block(2,16,0,LOG:3)
Block(3,16,0,LOG:3)
Block(4,16,0,LOG:3)
Block(-10,16,1,LOG:3)
Block(-9,16,1,LOG:3)
Block(-8,16,1,LOG:3)
Block(-7,16,1,LOG:3)
Block(-6,16,1,LOG:3)
Block(2,16,1,LOG:3)
Block(3,16,1,LOG:3)
Block(4,16,1,LOG:3)
Block(5,16,1,LOG:3)
Block(-14,16,2,LEAVES:3)
Block(-9,16,2,LOG:3)
Block(-8,16,2,LOG:3)
Block(-7,16,2,LOG:3)
Block(3,16,2,LOG:3)
Block(4,16,2,LOG:3)
Block(5,16,2,LOG:3)
Block(-8,16,3,LOG:3)
Block(-6,16,3,LEAVES:3)
Block(4,16,3,LOG:3)
Block(-15,16,4,LEAVES:3)
Block(-3,16,4,LEAVES:3)
Block(-5,16,5,LEAVES:3)
Block(-13,16,6,LEAVES:3)
Block(-11,16,6,LEAVES:3)
Block(7,16,6,LEAVES:3)
Block(-7,16,7,LEAVES:3)
Block(6,16,7,LEAVES:3)
Block(7,16,7,LEAVES:3)
Block(-11,16,8,LEAVES:3)
Block(7,16,8,LEAVES:3)
Block(8,16,8,LEAVES:3)
Block(5,17,-12,LEAVES:3)
Block(3,17,-11,LEAVES:3)
Block(8,17,-10,LEAVES:3)
Block(1,17,-9,LEAVES:3)
Block(4,17,-9,LEAVES:3)
Block(5,17,-9,LOG:3)
Block(4,17,-8,LOG:3)
Block(5,17,-8,LOG:3)
Block(6,17,-8,LOG:3)
Block(3,17,-7,LOG:3)
Block(4,17,-7,LOG:3)
Block(5,17,-7,LOG:3)
Block(6,17,-7,LOG:3)
Block(7,17,-7,LOG:3)
Block(10,17,-7,LEAVES:3)
Block(-1,17,-6,LOG:3)
Block(4,17,-6,LOG:3)
Block(5,17,-6,LOG:3)
Block(6,17,-6,LOG:3)
Block(7,17,-6,LEAVES:3)
Block(-3,17,-5,LEAVES:3)
Block(-2,17,-5,LOG:3)
Block(-1,17,-5,LOG:3)
Block(0,17,-5,LOG:3)
Block(5,17,-5,LOG:3)
Block(9,17,-5,LEAVES:3)
Block(-10,17,-4,LEAVES:3)
Block(-3,17,-4,LOG:3)
Block(-2,17,-4,LOG:3)
Block(-1,17,-4,LOG:3)
Block(0,17,-4,LOG:3)
Block(1,17,-4,LOG:3)
Block(7,17,-4,LEAVES:3)
Block(-12,17,-3,LEAVES:3)
Block(-10,17,-3,LEAVES:3)
Block(-8,17,-3,LEAVES:3)
Block(-7,17,-3,LEAVES:3)
Block(-3,17,-3,LOG:3)
Block(-2,17,-3,LOG:3)
Block(-1,17,-3,LOG:3)
Block(0,17,-3,LOG:3)
Block(1,17,-3,LOG:3)
Block(2,17,-3,LOG:3)
Block(5,17,-3,LEAVES:3)
Block(-12,17,-2,LEAVES:3)
Block(-11,17,-2,LEAVES:3)
Block(-10,17,-2,LEAVES:3)
Block(-9,17,-2,LEAVES:3)
Block(-8,17,-2,LEAVES:3)
Block(-7,17,-2,LEAVES:3)
Block(-3,17,-2,LOG:3)
Block(-2,17,-2,LOG:3)
Block(-1,17,-2,LOG:3)
Block(0,17,-2,LOG:3)
Block(1,17,-2,LOG:3)
Block(2,17,-2,LOG:3)
Block(3,17,-2,LEAVES:3)
Block(-13,17,-1,LEAVES:3)
Block(-12,17,-1,LEAVES:3)
Block(-11,17,-1,LEAVES:3)
Block(-10,17,-1,LEAVES:3)
Block(-8,17,-1,LEAVES:3)
Block(-6,17,-1,LEAVES:3)
Block(-2,17,-1,LOG:3)
Block(-1,17,-1,LOG:3)
Block(0,17,-1,LOG:3)
Block(1,17,-1,LOG:3)
Block(2,17,-1,LOG:3)
Block(3,17,-1,LOG:3)
Block(-14,17,0,LEAVES:3)
Block(-12,17,0,LEAVES:3)
Block(-9,17,0,LOG:3)
Block(-8,17,0,LOG:3)
Block(-7,17,0,LEAVES:3)
Block(-6,17,0,LEAVES:3)
Block(-5,17,0,LEAVES:3)
Block(0,17,0,LOG:3)
Block(1,17,0,LOG:3)
Block(2,17,0,LOG:3)
Block(3,17,0,LOG:3)
Block(4,17,0,LOG:3)
Block(-13,17,1,LEAVES:3)
Block(-11,17,1,LEAVES:3)
Block(-10,17,1,LOG:3)
Block(-9,17,1,LOG:3)
Block(-8,17,1,LOG:3)
Block(-7,17,1,LOG:3)
Block(-6,17,1,LEAVES:3)
Block(1,17,1,LOG:3)
Block(2,17,1,LOG:3)
Block(3,17,1,LOG:3)
Block(4,17,1,LOG:3)
Block(5,17,1,LOG:3)
Block(-14,17,2,LEAVES:3)
Block(-13,17,2,LEAVES:3)
Block(-11,17,2,LOG:3)
Block(-10,17,2,LOG:3)
Block(-9,17,2,LOG:3)
Block(-8,17,2,LOG:3)
Block(-7,17,2,LOG:3)
Block(-5,17,2,LEAVES:3)
Block(2,17,2,LOG:3)
Block(3,17,2,LOG:3)
Block(4,17,2,LOG:3)
Block(5,17,2,LOG:3)
Block(-14,17,3,LEAVES:3)
Block(-13,17,3,LEAVES:3)
Block(-9,17,3,LOG:3)
Block(-8,17,3,LOG:3)
Block(-7,17,3,LOG:3)
Block(-6,17,3,LEAVES:3)
Block(-4,17,3,LEAVES:3)
Block(3,17,3,LOG:3)
Block(4,17,3,LOG:3)
Block(5,17,3,LOG:3)
Block(-15,17,4,LEAVES:3)
Block(-13,17,4,LEAVES:3)
Block(-9,17,4,LOG:3)
Block(-8,17,4,LEAVES:3)
Block(-6,17,4,LEAVES:3)
Block(-5,17,4,LEAVES:3)
Block(-3,17,4,LEAVES:3)
Block(4,17,4,LOG:3)
Block(5,17,4,LOG:3)
Block(6,17,4,LOG:3)
Block(-14,17,5,LEAVES:3)
Block(-13,17,5,LEAVES:3)
Block(-12,17,5,LEAVES:3)
Block(-9,17,5,LEAVES:3)
Block(-7,17,5,LEAVES:3)
Block(-6,17,5,LEAVES:3)
Block(-5,17,5,LEAVES:3)
Block(5,17,5,LOG:3)
Block(-13,17,6,LEAVES:3)
Block(-11,17,6,LEAVES:3)
Block(-9,17,6,LEAVES:3)
Block(-8,17,6,LEAVES:3)
Block(-6,17,6,LEAVES:3)
Block(-9,17,7,LEAVES:3)
Block(-7,17,7,LEAVES:3)
Block(-12,17,8,LEAVES:3)
Block(-11,17,8,LEAVES:3)
Block(-10,17,8,LEAVES:3)
Block(5,18,-12,LEAVES:3)
Block(3,18,-11,LEAVES:3)
Block(8,18,-10,LEAVES:3)
Block(1,18,-9,LEAVES:3)
Block(5,18,-9,LOG:3)
Block(6,18,-9,LOG:3)
Block(4,18,-8,LEAVES:3)
Block(5,18,-8,LOG:3)
Block(6,18,-8,LOG:3)
Block(7,18,-8,LOG:3)
Block(4,18,-7,LOG:3)
Block(5,18,-7,LOG:3)
Block(6,18,-7,LOG:3)
Block(7,18,-7,LOG:3)
Block(8,18,-7,LOG:3)
Block(9,18,-7,LEAVES:3)
Block(10,18,-7,LEAVES:3)
Block(-3,18,-6,LEAVES:3)
Block(-2,18,-6,LOG:3)
Block(-1,18,-6,LOG:3)
Block(5,18,-6,LOG:3)
Block(6,18,-6,LOG:3)
Block(8,18,-6,LEAVES:3)
Block(-3,18,-5,LOG:3)
Block(-2,18,-5,LOG:3)
Block(-1,18,-5,LOG:3)
Block(0,18,-5,LOG:3)
Block(1,18,-5,LOG:3)
Block(9,18,-5,LEAVES:3)
Block(-11,18,-4,LEAVES:3)
Block(-10,18,-4,LEAVES:3)
Block(-9,18,-4,LEAVES:3)
Block(-3,18,-4,LOG:3)
Block(-2,18,-4,LOG:3)
Block(-1,18,-4,LOG:3)
Block(0,18,-4,LOG:3)
Block(1,18,-4,LOG:3)
Block(7,18,-4,LEAVES:3)
Block(-13,18,-3,LEAVES:3)
Block(-12,18,-3,LEAVES:3)
Block(-11,18,-3,LEAVES:3)
Block(-10,18,-3,LEAVES:3)
Block(-9,18,-3,LEAVES:3)
Block(-8,18,-3,LEAVES:3)
Block(-7,18,-3,LEAVES:3)
Block(-6,18,-3,LEAVES:3)
Block(-3,18,-3,LOG:3)
Block(-2,18,-3,LOG:3)
Block(-1,18,-3,LOG:3)
Block(0,18,-3,LOG:3)
Block(1,18,-3,LOG:3)
Block(5,18,-3,LEAVES:3)
Block(-14,18,-2,LEAVES:3)
Block(-13,18,-2,LEAVES:3)
Block(-12,18,-2,LEAVES:3)
Block(-11,18,-2,LEAVES:3)
Block(-10,18,-2,LEAVES:3)
Block(-9,18,-2,LEAVES:3)
Block(-8,18,-2,LEAVES:3)
Block(-7,18,-2,LEAVES:3)
Block(-6,18,-2,LEAVES:3)
Block(-5,18,-2,LEAVES:3)
Block(-3,18,-2,LOG:3)
Block(-2,18,-2,LOG:3)
Block(-1,18,-2,LOG:3)
Block(0,18,-2,LOG:3)
Block(1,18,-2,LOG:3)
Block(2,18,-2,LOG:3)
Block(-14,18,-1,LEAVES:3)
Block(-13,18,-1,LEAVES:3)
Block(-12,18,-1,LEAVES:3)
Block(-11,18,-1,LEAVES:3)
Block(-10,18,-1,LEAVES:3)
Block(-9,18,-1,LEAVES:3)
Block(-8,18,-1,LEAVES:3)
Block(-7,18,-1,LEAVES:3)
Block(-6,18,-1,LEAVES:3)
Block(-5,18,-1,LEAVES:3)
Block(-1,18,-1,LOG:3)
Block(0,18,-1,LOG:3)
Block(1,18,-1,LOG:3)
Block(2,18,-1,LOG:3)
Block(3,18,-1,LEAVES:3)
Block(-15,18,0,LEAVES:3)
Block(-14,18,0,LEAVES:3)
Block(-13,18,0,LEAVES:3)
Block(-11,18,0,LEAVES:3)
Block(-10,18,0,LEAVES:3)
Block(-9,18,0,LEAVES:3)
Block(-8,18,0,LEAVES:3)
Block(-7,18,0,LEAVES:3)
Block(-6,18,0,LEAVES:3)
Block(-5,18,0,LEAVES:3)
Block(-4,18,0,LEAVES:3)
Block(1,18,0,LOG:3)
Block(2,18,0,LOG:3)
Block(3,18,0,LOG:3)
Block(-15,18,1,LEAVES:3)
Block(-14,18,1,LEAVES:3)
Block(-13,18,1,LEAVES:3)
Block(-11,18,1,LEAVES:3)
Block(-10,18,1,LEAVES:3)
Block(-9,18,1,LEAVES:3)
Block(-8,18,1,LEAVES:3)
Block(-7,18,1,LEAVES:3)
Block(-6,18,1,LEAVES:3)
Block(-5,18,1,LEAVES:3)
Block(-4,18,1,LEAVES:3)
Block(2,18,1,LOG:3)
Block(3,18,1,LOG:3)
Block(4,18,1,LOG:3)
Block(-15,18,2,LEAVES:3)
Block(-14,18,2,LEAVES:3)
Block(-13,18,2,LEAVES:3)
Block(-12,18,2,LOG:3)
Block(-11,18,2,LEAVES:3)
Block(-10,18,2,LEAVES:3)
Block(-9,18,2,LEAVES:3)
Block(-8,18,2,LEAVES:3)
Block(-7,18,2,LEAVES:3)
Block(-6,18,2,LEAVES:3)
Block(-5,18,2,LEAVES:3)
Block(-4,18,2,LEAVES:3)
Block(-3,18,2,LEAVES:3)
Block(3,18,2,LOG:3)
Block(4,18,2,LOG:3)
Block(5,18,2,LOG:3)
Block(6,18,2,LOG:3)
Block(-15,18,3,LEAVES:3)
Block(-14,18,3,LEAVES:3)
Block(-13,18,3,LEAVES:3)
Block(-12,18,3,LEAVES:3)
Block(-11,18,3,LEAVES:3)
Block(-10,18,3,LEAVES:3)
Block(-9,18,3,LEAVES:3)
Block(-8,18,3,LEAVES:3)
Block(-7,18,3,LEAVES:3)
Block(-6,18,3,LEAVES:3)
Block(-5,18,3,LEAVES:3)
Block(-4,18,3,LEAVES:3)
Block(-3,18,3,LEAVES:3)
Block(3,18,3,LOG:3)
Block(4,18,3,LOG:3)
Block(5,18,3,LOG:3)
Block(6,18,3,LOG:3)
Block(7,18,3,LOG:3)
Block(-15,18,4,LEAVES:3)
Block(-14,18,4,LEAVES:3)
Block(-13,18,4,LEAVES:3)
Block(-12,18,4,LEAVES:3)
Block(-11,18,4,LEAVES:3)
Block(-10,18,4,LOG:3)
Block(-9,18,4,LEAVES:3)
Block(-8,18,4,LEAVES:3)
Block(-7,18,4,LEAVES:3)
Block(-6,18,4,LEAVES:3)
Block(-5,18,4,LEAVES:3)
Block(-4,18,4,LEAVES:3)
Block(-3,18,4,LEAVES:3)
Block(3,18,4,LOG:3)
Block(4,18,4,LOG:3)
Block(5,18,4,LOG:3)
Block(6,18,4,LOG:3)
Block(7,18,4,LOG:3)
Block(-14,18,5,LEAVES:3)
Block(-13,18,5,LEAVES:3)
Block(-12,18,5,LEAVES:3)
Block(-11,18,5,LEAVES:3)
Block(-10,18,5,LOG:3)
Block(-9,18,5,LEAVES:3)
Block(-8,18,5,LEAVES:3)
Block(-7,18,5,LEAVES:3)
Block(-6,18,5,LEAVES:3)
Block(-5,18,5,LEAVES:3)
Block(-4,18,5,LEAVES:3)
Block(4,18,5,LOG:3)
Block(5,18,5,LOG:3)
Block(6,18,5,LOG:3)
Block(-14,18,6,LEAVES:3)
Block(-13,18,6,LEAVES:3)
Block(-12,18,6,LEAVES:3)
Block(-11,18,6,LEAVES:3)
Block(-10,18,6,LOG:3)
Block(-9,18,6,LEAVES:3)
Block(-8,18,6,LEAVES:3)
Block(-7,18,6,LEAVES:3)
Block(-6,18,6,LEAVES:3)
Block(-5,18,6,LEAVES:3)
Block(-4,18,6,LEAVES:3)
Block(12,18,6,LEAVES:3)
Block(-13,18,7,LEAVES:3)
Block(-12,18,7,LEAVES:3)
Block(-11,18,7,LEAVES:3)
Block(-10,18,7,LEAVES:3)
Block(-9,18,7,LEAVES:3)
Block(-8,18,7,LEAVES:3)
Block(-7,18,7,LEAVES:3)
Block(-6,18,7,LEAVES:3)
Block(-5,18,7,LEAVES:3)
Block(7,18,7,LEAVES:3)
Block(8,18,7,LEAVES:3)
Block(-11,18,8,LEAVES:3)
Block(-10,18,8,LEAVES:3)
Block(-9,18,8,LEAVES:3)
Block(-8,18,8,LEAVES:3)
Block(4,18,11,LEAVES:3)
Block(4,19,-12,LEAVES:3)
Block(5,19,-12,LEAVES:3)
Block(3,19,-11,LEAVES:3)
Block(4,19,-11,LEAVES:3)
Block(5,19,-11,LEAVES:3)
Block(6,19,-11,LEAVES:3)
Block(2,19,-10,LEAVES:3)
Block(3,19,-10,LEAVES:3)
Block(8,19,-10,LEAVES:3)
Block(1,19,-9,LEAVES:3)
Block(2,19,-9,LEAVES:3)
Block(5,19,-9,LOG:3)
Block(6,19,-9,LOG:3)
Block(7,19,-9,LOG:3)
Block(8,19,-9,LEAVES:3)
Block(9,19,-9,LEAVES:3)
Block(1,19,-8,LEAVES:3)
Block(4,19,-8,LEAVES:3)
Block(5,19,-8,LOG:3)
Block(6,19,-8,LOG:3)
Block(7,19,-8,LOG:3)
Block(8,19,-8,LOG:3)
Block(-2,19,-7,LEAVES:3)
Block(1,19,-7,LEAVES:3)
Block(2,19,-7,LEAVES:3)
Block(4,19,-7,LOG:3)
Block(5,19,-7,LOG:3)
Block(6,19,-7,LOG:3)
Block(7,19,-7,LOG:3)
Block(8,19,-7,LOG:3)
Block(9,19,-7,LEAVES:3)
Block(10,19,-7,LEAVES:3)
Block(-2,19,-6,LOG:3)
Block(-1,19,-6,LOG:3)
Block(0,19,-6,LOG:3)
Block(2,19,-6,LEAVES:3)
Block(5,19,-6,LOG:3)
Block(6,19,-6,LOG:3)
Block(7,19,-6,LOG:3)
Block(10,19,-6,LEAVES:3)
Block(-3,19,-5,LOG:3)
Block(-2,19,-5,LOG:3)
Block(-1,19,-5,LOG:3)
Block(0,19,-5,LOG:3)
Block(1,19,-5,LOG:3)
Block(2,19,-5,LEAVES:3)
Block(9,19,-5,LEAVES:3)
Block(-11,19,-4,LEAVES:3)
Block(-4,19,-4,LOG:3)
Block(-3,19,-4,LOG:3)
Block(-2,19,-4,LOG:3)
Block(-1,19,-4,LOG:3)
Block(0,19,-4,LOG:3)
Block(1,19,-4,LOG:3)
Block(3,19,-4,LEAVES:3)
Block(6,19,-4,LEAVES:3)
Block(7,19,-4,LEAVES:3)
Block(8,19,-4,LEAVES:3)
Block(-12,19,-3,LEAVES:3)
Block(-11,19,-3,LEAVES:3)
Block(-10,19,-3,LEAVES:3)
Block(-9,19,-3,LEAVES:3)
Block(-8,19,-3,LEAVES:3)
Block(-3,19,-3,LOG:3)
Block(-2,19,-3,LOG:3)
Block(-1,19,-3,LOG:3)
Block(0,19,-3,LOG:3)
Block(1,19,-3,LOG:3)
Block(5,19,-3,LEAVES:3)
Block(7,19,-3,LEAVES:3)
Block(-13,19,-2,LEAVES:3)
Block(-12,19,-2,LEAVES:3)
Block(-11,19,-2,LEAVES:3)
Block(-10,19,-2,LEAVES:3)
Block(-9,19,-2,LEAVES:3)
Block(-8,19,-2,LEAVES:3)
Block(-7,19,-2,LEAVES:3)
Block(-6,19,-2,LEAVES:3)
Block(-5,19,-2,LEAVES:3)
Block(-2,19,-2,LOG:3)
Block(-1,19,-2,LOG:3)
Block(0,19,-2,LOG:3)
Block(1,19,-2,LOG:3)
Block(-13,19,-1,LEAVES:3)
Block(-12,19,-1,LEAVES:3)
Block(-11,19,-1,LEAVES:3)
Block(-10,19,-1,LEAVES:3)
Block(-9,19,-1,LEAVES:3)
Block(-8,19,-1,LEAVES:3)
Block(-7,19,-1,LEAVES:3)
Block(-6,19,-1,LEAVES:3)
Block(-5,19,-1,LEAVES:3)
Block(-14,19,0,LEAVES:3)
Block(-13,19,0,LEAVES:3)
Block(-12,19,0,LEAVES:3)
Block(-11,19,0,LEAVES:3)
Block(-10,19,0,LEAVES:3)
Block(-9,19,0,LEAVES:3)
Block(-8,19,0,LEAVES:3)
Block(-7,19,0,LEAVES:3)
Block(-6,19,0,LEAVES:3)
Block(-5,19,0,LEAVES:3)
Block(2,19,0,LEAVES:3)
Block(-14,19,1,LEAVES:3)
Block(-13,19,1,LEAVES:3)
Block(-12,19,1,LEAVES:3)
Block(-11,19,1,LEAVES:3)
Block(-10,19,1,LEAVES:3)
Block(-9,19,1,LEAVES:3)
Block(-8,19,1,LEAVES:3)
Block(-7,19,1,LEAVES:3)
Block(2,19,1,LEAVES:3)
Block(3,19,1,LOG:3)
Block(-15,19,2,LEAVES:3)
Block(-14,19,2,LEAVES:3)
Block(-13,19,2,LEAVES:3)
Block(-12,19,2,LEAVES:3)
Block(-10,19,2,LEAVES:3)
Block(-9,19,2,LEAVES:3)
Block(-8,19,2,LEAVES:3)
Block(-5,19,2,LEAVES:3)
Block(3,19,2,LOG:3)
Block(4,19,2,LOG:3)
Block(5,19,2,LOG:3)
Block(-15,19,3,LEAVES:3)
Block(-14,19,3,LEAVES:3)
Block(-13,19,3,LEAVES:3)
Block(-12,19,3,LEAVES:3)
Block(-11,19,3,LEAVES:3)
Block(-10,19,3,LEAVES:3)
Block(-9,19,3,LEAVES:3)
Block(-8,19,3,LEAVES:3)
Block(-7,19,3,LEAVES:3)
Block(-5,19,3,LEAVES:3)
Block(-4,19,3,LEAVES:3)
Block(3,19,3,LOG:3)
Block(4,19,3,LOG:3)
Block(5,19,3,LOG:3)
Block(6,19,3,LOG:3)
Block(7,19,3,LOG:3)
Block(-15,19,4,LEAVES:3)
Block(-14,19,4,LEAVES:3)
Block(-13,19,4,LEAVES:3)
Block(-12,19,4,LEAVES:3)
Block(-11,19,4,LEAVES:3)
Block(-10,19,4,LEAVES:3)
Block(-9,19,4,LEAVES:3)
Block(-8,19,4,LEAVES:3)
Block(-7,19,4,LEAVES:3)
Block(-6,19,4,LEAVES:3)
Block(-5,19,4,LEAVES:3)
Block(-4,19,4,LEAVES:3)
Block(4,19,4,LOG:3)
Block(5,19,4,LOG:3)
Block(6,19,4,LOG:3)
Block(7,19,4,LOG:3)
Block(10,19,4,LEAVES:3)
Block(-14,19,5,LEAVES:3)
Block(-13,19,5,LEAVES:3)
Block(-12,19,5,LEAVES:3)
Block(-11,19,5,LEAVES:3)
Block(-10,19,5,LEAVES:3)
Block(-9,19,5,LEAVES:3)
Block(-8,19,5,LEAVES:3)
Block(-7,19,5,LEAVES:3)
Block(-6,19,5,LEAVES:3)
Block(-5,19,5,LEAVES:3)
Block(5,19,5,LOG:3)
Block(6,19,5,LOG:3)
Block(7,19,5,LOG:3)
Block(-13,19,6,LEAVES:3)
Block(-12,19,6,LEAVES:3)
Block(-11,19,6,LEAVES:3)
Block(-10,19,6,LEAVES:3)
Block(-9,19,6,LEAVES:3)
Block(-8,19,6,LEAVES:3)
Block(-7,19,6,LEAVES:3)
Block(-6,19,6,LEAVES:3)
Block(6,19,6,LOG:3)
Block(7,19,6,LOG:3)
Block(8,19,6,LOG:3)
Block(12,19,6,LEAVES:3)
Block(-12,19,7,LEAVES:3)
Block(-11,19,7,LEAVES:3)
Block(-10,19,7,LEAVES:3)
Block(-9,19,7,LEAVES:3)
Block(-8,19,7,LEAVES:3)
Block(-7,19,7,LEAVES:3)
Block(6,19,7,LEAVES:3)
Block(7,19,7,LOG:3)
Block(8,19,7,LOG:3)
Block(9,19,7,LEAVES:3)
Block(-10,19,8,LEAVES:3)
Block(-9,19,8,LEAVES:3)
Block(8,19,8,LOG:3)
Block(14,19,10,LEAVES:3)
Block(4,19,11,LEAVES:3)
Block(9,19,13,LEAVES:3)
Block(3,20,-12,LEAVES:3)
Block(4,20,-12,LEAVES:3)
Block(5,20,-12,LEAVES:3)
Block(6,20,-12,LEAVES:3)
Block(3,20,-11,LEAVES:3)
Block(5,20,-11,LEAVES:3)
Block(6,20,-11,LEAVES:3)
Block(7,20,-11,LEAVES:3)
Block(1,20,-10,LEAVES:3)
Block(2,20,-10,LEAVES:3)
Block(3,20,-10,LEAVES:3)
Block(4,20,-10,LEAVES:3)
Block(5,20,-10,LEAVES:3)
Block(6,20,-10,LEAVES:3)
Block(7,20,-10,LEAVES:3)
Block(8,20,-10,LEAVES:3)
Block(9,20,-10,LEAVES:3)
Block(1,20,-9,LEAVES:3)
Block(2,20,-9,LEAVES:3)
Block(3,20,-9,LEAVES:3)
Block(4,20,-9,LEAVES:3)
Block(5,20,-9,LEAVES:3)
Block(6,20,-9,LEAVES:3)
Block(7,20,-9,LEAVES:3)
Block(8,20,-9,LEAVES:3)
Block(9,20,-9,LEAVES:3)
Block(10,20,-9,LEAVES:3)
Block(0,20,-8,LEAVES:3)
Block(1,20,-8,LEAVES:3)
Block(2,20,-8,LEAVES:3)
Block(4,20,-8,LEAVES:3)
Block(5,20,-8,LOG:3)
Block(6,20,-8,LOG:3)
Block(7,20,-8,LEAVES:3)
Block(8,20,-8,LEAVES:3)
Block(9,20,-8,LEAVES:3)
Block(10,20,-8,LEAVES:3)
Block(-2,20,-7,LEAVES:3)
Block(1,20,-7,LEAVES:3)
Block(2,20,-7,LEAVES:3)
Block(3,20,-7,LEAVES:3)
Block(4,20,-7,LEAVES:3)
Block(5,20,-7,LEAVES:3)
Block(6,20,-7,LOG:3)
Block(7,20,-7,LEAVES:3)
Block(8,20,-7,LEAVES:3)
Block(9,20,-7,LEAVES:3)
Block(10,20,-7,LEAVES:3)
Block(-3,20,-6,LOG:3)
Block(-2,20,-6,LOG:3)
Block(-1,20,-6,LOG:3)
Block(0,20,-6,LOG:3)
Block(1,20,-6,LEAVES:3)
Block(2,20,-6,LEAVES:3)
Block(3,20,-6,LEAVES:3)
Block(4,20,-6,LEAVES:3)
Block(5,20,-6,LEAVES:3)
Block(6,20,-6,LEAVES:3)
Block(7,20,-6,LEAVES:3)
Block(8,20,-6,LEAVES:3)
Block(9,20,-6,LEAVES:3)
Block(10,20,-6,LEAVES:3)
Block(-3,20,-5,LOG:3)
Block(-2,20,-5,LOG:3)
Block(-1,20,-5,LOG:3)
Block(0,20,-5,LOG:3)
Block(1,20,-5,LEAVES:3)
Block(2,20,-5,LEAVES:3)
Block(3,20,-5,LEAVES:3)
Block(4,20,-5,LEAVES:3)
Block(5,20,-5,LEAVES:3)
Block(6,20,-5,LEAVES:3)
Block(7,20,-5,LEAVES:3)
Block(8,20,-5,LEAVES:3)
Block(9,20,-5,LEAVES:3)
Block(-4,20,-4,LOG:3)
Block(-3,20,-4,LOG:3)
Block(-2,20,-4,LOG:3)
Block(-1,20,-4,LOG:3)
Block(0,20,-4,LOG:3)
Block(1,20,-4,LOG:3)
Block(2,20,-4,LEAVES:3)
Block(3,20,-4,LEAVES:3)
Block(4,20,-4,LEAVES:3)
Block(5,20,-4,LEAVES:3)
Block(6,20,-4,LEAVES:3)
Block(7,20,-4,LEAVES:3)
Block(8,20,-4,LEAVES:3)
Block(-11,20,-3,LEAVES:3)
Block(-10,20,-3,LEAVES:3)
Block(-9,20,-3,LEAVES:3)
Block(-3,20,-3,LOG:3)
Block(-2,20,-3,LOG:3)
Block(-1,20,-3,LOG:3)
Block(0,20,-3,LOG:3)
Block(1,20,-3,LOG:3)
Block(3,20,-3,LEAVES:3)
Block(4,20,-3,LEAVES:3)
Block(5,20,-3,LEAVES:3)
Block(6,20,-3,LEAVES:3)
Block(7,20,-3,LEAVES:3)
Block(8,20,-3,LEAVES:3)
Block(-13,20,-2,LEAVES:3)
Block(-12,20,-2,LEAVES:3)
Block(-10,20,-2,LEAVES:3)
Block(-9,20,-2,LEAVES:3)
Block(-8,20,-2,LEAVES:3)
Block(-6,20,-2,LEAVES:3)
Block(-2,20,-2,LOG:3)
Block(-1,20,-2,LOG:3)
Block(0,20,-2,LOG:3)
Block(-12,20,-1,LEAVES:3)
Block(-11,20,-1,LEAVES:3)
Block(-10,20,-1,LEAVES:3)
Block(-9,20,-1,LEAVES:3)
Block(-8,20,-1,LEAVES:3)
Block(-7,20,-1,LEAVES:3)
Block(-6,20,-1,LEAVES:3)
Block(-5,20,-1,LEAVES:3)
Block(-13,20,0,LEAVES:3)
Block(-12,20,0,LEAVES:3)
Block(-11,20,0,LEAVES:3)
Block(-10,20,0,LEAVES:3)
Block(-9,20,0,LEAVES:3)
Block(-8,20,0,LEAVES:3)
Block(-7,20,0,LEAVES:3)
Block(-6,20,0,LEAVES:3)
Block(-14,20,1,LEAVES:3)
Block(-13,20,1,LEAVES:3)
Block(-12,20,1,LEAVES:3)
Block(-11,20,1,LEAVES:3)
Block(-10,20,1,LEAVES:3)
Block(-9,20,1,LEAVES:3)
Block(-8,20,1,LEAVES:3)
Block(-7,20,1,LEAVES:3)
Block(-5,20,1,LEAVES:3)
Block(-14,20,2,LEAVES:3)
Block(-13,20,2,LEAVES:3)
Block(-12,20,2,LEAVES:3)
Block(-11,20,2,LEAVES:3)
Block(-10,20,2,LEAVES:3)
Block(-9,20,2,LEAVES:3)
Block(-8,20,2,LEAVES:3)
Block(-7,20,2,LEAVES:3)
Block(-6,20,2,LEAVES:3)
Block(-5,20,2,LEAVES:3)
Block(3,20,2,LEAVES:3)
Block(4,20,2,LEAVES:3)
Block(-15,20,3,LEAVES:3)
Block(-14,20,3,LEAVES:3)
Block(-13,20,3,LEAVES:3)
Block(-12,20,3,LEAVES:3)
Block(-11,20,3,LEAVES:3)
Block(-10,20,3,LEAVES:3)
Block(-9,20,3,LEAVES:3)
Block(-8,20,3,LEAVES:3)
Block(-7,20,3,LEAVES:3)
Block(-6,20,3,LEAVES:3)
Block(4,20,3,LOG:3)
Block(5,20,3,LOG:3)
Block(6,20,3,LOG:3)
Block(-14,20,4,LEAVES:3)
Block(-13,20,4,LEAVES:3)
Block(-12,20,4,LEAVES:3)
Block(-11,20,4,LEAVES:3)
Block(-10,20,4,LEAVES:3)
Block(-9,20,4,LEAVES:3)
Block(-8,20,4,LEAVES:3)
Block(-7,20,4,LEAVES:3)
Block(-6,20,4,LEAVES:3)
Block(-5,20,4,LEAVES:3)
Block(5,20,4,LOG:3)
Block(6,20,4,LOG:3)
Block(7,20,4,LOG:3)
Block(10,20,4,LEAVES:3)
Block(-13,20,5,LEAVES:3)
Block(-12,20,5,LEAVES:3)
Block(-11,20,5,LEAVES:3)
Block(-10,20,5,LEAVES:3)
Block(-9,20,5,LEAVES:3)
Block(-8,20,5,LEAVES:3)
Block(-6,20,5,LEAVES:3)
Block(5,20,5,LOG:3)
Block(6,20,5,LOG:3)
Block(7,20,5,LOG:3)
Block(8,20,5,LOG:3)
Block(-12,20,6,LEAVES:3)
Block(-11,20,6,LEAVES:3)
Block(-10,20,6,LEAVES:3)
Block(-9,20,6,LEAVES:3)
Block(-8,20,6,LEAVES:3)
Block(-7,20,6,LEAVES:3)
Block(5,20,6,LOG:3)
Block(6,20,6,LOG:3)
Block(7,20,6,LOG:3)
Block(8,20,6,LOG:3)
Block(9,20,6,LOG:3)
Block(12,20,6,LEAVES:3)
Block(-11,20,7,LEAVES:3)
Block(-10,20,7,LEAVES:3)
Block(-8,20,7,LEAVES:3)
Block(5,20,7,LEAVES:3)
Block(6,20,7,LOG:3)
Block(7,20,7,LOG:3)
Block(8,20,7,LOG:3)
Block(9,20,7,LOG:3)
Block(3,20,8,LEAVES:3)
Block(7,20,8,LOG:3)
Block(8,20,8,LOG:3)
Block(9,20,8,LOG:3)
Block(10,20,8,LEAVES:3)
Block(14,20,10,LEAVES:3)
Block(4,20,11,LEAVES:3)
Block(6,20,13,LEAVES:3)
Block(9,20,13,LEAVES:3)
Block(5,21,-12,LEAVES:3)
Block(3,21,-11,LEAVES:3)
Block(4,21,-11,LEAVES:3)
Block(5,21,-11,LEAVES:3)
Block(7,21,-11,LEAVES:3)
Block(2,21,-10,LEAVES:3)
Block(3,21,-10,LEAVES:3)
Block(4,21,-10,LEAVES:3)
Block(5,21,-10,LEAVES:3)
Block(6,21,-10,LEAVES:3)
Block(7,21,-10,LEAVES:3)
Block(8,21,-10,LEAVES:3)
Block(1,21,-9,LEAVES:3)
Block(2,21,-9,LEAVES:3)
Block(3,21,-9,LEAVES:3)
Block(4,21,-9,LEAVES:3)
Block(5,21,-9,LEAVES:3)
Block(6,21,-9,LEAVES:3)
Block(7,21,-9,LEAVES:3)
Block(8,21,-9,LEAVES:3)
Block(9,21,-9,LEAVES:3)
Block(2,21,-8,LEAVES:3)
Block(3,21,-8,LEAVES:3)
Block(4,21,-8,LEAVES:3)
Block(5,21,-8,LEAVES:3)
Block(6,21,-8,LEAVES:3)
Block(7,21,-8,LEAVES:3)
Block(8,21,-8,LEAVES:3)
Block(9,21,-8,LEAVES:3)
Block(10,21,-8,LEAVES:3)
Block(-1,21,-7,LEAVES:3)
Block(2,21,-7,LEAVES:3)
Block(3,21,-7,LEAVES:3)
Block(4,21,-7,LEAVES:3)
Block(5,21,-7,LEAVES:3)
Block(6,21,-7,LEAVES:3)
Block(7,21,-7,LEAVES:3)
Block(8,21,-7,LEAVES:3)
Block(9,21,-7,LEAVES:3)
Block(10,21,-7,LEAVES:3)
Block(-3,21,-6,LOG:3)
Block(-2,21,-6,LOG:3)
Block(-1,21,-6,LOG:3)
Block(3,21,-6,LEAVES:3)
Block(4,21,-6,LEAVES:3)
Block(5,21,-6,LEAVES:3)
Block(6,21,-6,LEAVES:3)
Block(7,21,-6,LEAVES:3)
Block(9,21,-6,LEAVES:3)
Block(-4,21,-5,LOG:3)
Block(-3,21,-5,LOG:3)
Block(-2,21,-5,LOG:3)
Block(-1,21,-5,LOG:3)
Block(0,21,-5,LOG:3)
Block(2,21,-5,LEAVES:3)
Block(3,21,-5,LEAVES:3)
Block(4,21,-5,LEAVES:3)
Block(5,21,-5,LEAVES:3)
Block(6,21,-5,LEAVES:3)
Block(7,21,-5,LEAVES:3)
Block(8,21,-5,LEAVES:3)
Block(-4,21,-4,LOG:3)
Block(-3,21,-4,LOG:3)
Block(-2,21,-4,LOG:3)
Block(-1,21,-4,LOG:3)
Block(0,21,-4,LOG:3)
Block(3,21,-4,LEAVES:3)
Block(4,21,-4,LEAVES:3)
Block(5,21,-4,LEAVES:3)
Block(6,21,-4,LEAVES:3)
Block(7,21,-4,LEAVES:3)
Block(8,21,-4,LEAVES:3)
Block(-3,21,-3,LOG:3)
Block(-2,21,-3,LOG:3)
Block(-1,21,-3,LOG:3)
Block(0,21,-3,LOG:3)
Block(5,21,-3,LEAVES:3)
Block(6,21,-3,LEAVES:3)
Block(-11,21,-2,LEAVES:3)
Block(-10,21,-2,LEAVES:3)
Block(-9,21,-2,LEAVES:3)
Block(-3,21,-2,LOG:3)
Block(-2,21,-2,LOG:3)
Block(-1,21,-2,LOG:3)
Block(-10,21,-1,LEAVES:3)
Block(-9,21,-1,LEAVES:3)
Block(-8,21,-1,LEAVES:3)
Block(-12,21,0,LEAVES:3)
Block(-11,21,0,LEAVES:3)
Block(-8,21,0,LEAVES:3)
Block(-7,21,0,LEAVES:3)
Block(-12,21,1,LEAVES:3)
Block(-11,21,1,LEAVES:3)
Block(-10,21,1,LEAVES:3)
Block(-9,21,1,LEAVES:3)
Block(-7,21,1,LEAVES:3)
Block(-6,21,1,LEAVES:3)
Block(-13,21,2,LEAVES:3)
Block(-12,21,2,LEAVES:3)
Block(-10,21,2,LEAVES:3)
Block(-9,21,2,LEAVES:3)
Block(-8,21,2,LEAVES:3)
Block(-7,21,2,LEAVES:3)
Block(-6,21,2,LEAVES:3)
Block(-13,21,3,LEAVES:3)
Block(-11,21,3,LEAVES:3)
Block(-9,21,3,LEAVES:3)
Block(-7,21,3,LEAVES:3)
Block(-6,21,3,LEAVES:3)
Block(5,21,3,LEAVES:3)
Block(-13,21,4,LEAVES:3)
Block(-12,21,4,LEAVES:3)
Block(-11,21,4,LEAVES:3)
Block(-9,21,4,LEAVES:3)
Block(-8,21,4,LEAVES:3)
Block(-7,21,4,LEAVES:3)
Block(6,21,4,LOG:3)
Block(10,21,4,LEAVES:3)
Block(-12,21,5,LEAVES:3)
Block(-11,21,5,LEAVES:3)
Block(-10,21,5,LEAVES:3)
Block(-9,21,5,LEAVES:3)
Block(-8,21,5,LEAVES:3)
Block(6,21,5,LOG:3)
Block(7,21,5,LOG:3)
Block(-10,21,6,LEAVES:3)
Block(-9,21,6,LEAVES:3)
Block(6,21,6,LOG:3)
Block(7,21,6,LOG:3)
Block(8,21,6,LOG:3)
Block(12,21,6,LEAVES:3)
Block(5,21,7,LEAVES:3)
Block(6,21,7,LOG:3)
Block(7,21,7,LOG:3)
Block(8,21,7,LOG:3)
Block(9,21,7,LOG:3)
Block(3,21,8,LEAVES:3)
Block(7,21,8,LOG:3)
Block(8,21,8,LOG:3)
Block(9,21,8,LOG:3)
Block(10,21,8,LOG:3)
Block(9,21,9,LOG:3)
Block(10,21,9,LEAVES:3)
Block(14,21,10,LEAVES:3)
Block(4,21,11,LEAVES:3)
Block(11,21,12,LEAVES:3)
Block(6,21,13,LEAVES:3)
Block(9,21,13,LEAVES:3)
Block(5,22,-11,LEAVES:3)
Block(6,22,-11,LEAVES:3)
Block(3,22,-10,LEAVES:3)
Block(5,22,-10,LEAVES:3)
Block(6,22,-10,LEAVES:3)
Block(7,22,-10,LEAVES:3)
Block(3,22,-9,LEAVES:3)
Block(4,22,-9,LEAVES:3)
Block(6,22,-9,LEAVES:3)
Block(7,22,-9,LEAVES:3)
Block(8,22,-9,LEAVES:3)
Block(2,22,-8,LEAVES:3)
Block(3,22,-8,LEAVES:3)
Block(4,22,-8,LEAVES:3)
Block(5,22,-8,LEAVES:3)
Block(8,22,-8,LEAVES:3)
Block(9,22,-8,LEAVES:3)
Block(-1,22,-7,LEAVES:3)
Block(2,22,-7,LEAVES:3)
Block(3,22,-7,LEAVES:3)
Block(5,22,-7,LEAVES:3)
Block(7,22,-7,LEAVES:3)
Block(8,22,-7,LEAVES:3)
Block(-3,22,-6,LOG:3)
Block(-2,22,-6,LOG:3)
Block(-1,22,-6,LOG:3)
Block(2,22,-6,LEAVES:3)
Block(3,22,-6,LEAVES:3)
Block(4,22,-6,LEAVES:3)
Block(5,22,-6,LEAVES:3)
Block(6,22,-6,LEAVES:3)
Block(7,22,-6,LEAVES:3)
Block(8,22,-6,LEAVES:3)
Block(-4,22,-5,LOG:3)
Block(-3,22,-5,LOG:3)
Block(-2,22,-5,LOG:3)
Block(-1,22,-5,LOG:3)
Block(0,22,-5,LOG:3)
Block(4,22,-5,LEAVES:3)
Block(5,22,-5,LEAVES:3)
Block(7,22,-5,LEAVES:3)
Block(-4,22,-4,LOG:3)
Block(-3,22,-4,LOG:3)
Block(-2,22,-4,LOG:3)
Block(-1,22,-4,LOG:3)
Block(0,22,-4,LOG:3)
Block(5,22,-4,LEAVES:3)
Block(6,22,-4,LEAVES:3)
Block(-3,22,-3,LOG:3)
Block(-2,22,-3,LOG:3)
Block(-1,22,-3,LOG:3)
Block(0,22,-3,LOG:3)
Block(-3,22,-2,LOG:3)
Block(-2,22,-2,LOG:3)
Block(-1,22,-2,LOG:3)
Block(-2,22,-1,LOG:3)
Block(6,22,3,LEAVES:3)
Block(8,22,3,LEAVES:3)
Block(6,22,4,LEAVES:3)
Block(7,22,4,LEAVES:3)
Block(8,22,4,LEAVES:3)
Block(9,22,4,LEAVES:3)
Block(10,22,4,LEAVES:3)
Block(5,22,5,LEAVES:3)
Block(6,22,5,LEAVES:3)
Block(7,22,5,LEAVES:3)
Block(8,22,5,LEAVES:3)
Block(9,22,5,LEAVES:3)
Block(10,22,5,LEAVES:3)
Block(11,22,5,LEAVES:3)
Block(5,22,6,LEAVES:3)
Block(6,22,6,LEAVES:3)
Block(7,22,6,LEAVES:3)
Block(8,22,6,LEAVES:3)
Block(10,22,6,LEAVES:3)
Block(12,22,6,LEAVES:3)
Block(3,22,7,LEAVES:3)
Block(6,22,7,LEAVES:3)
Block(7,22,7,LEAVES:3)
Block(8,22,7,LOG:3)
Block(9,22,7,LOG:3)
Block(10,22,7,LOG:3)
Block(12,22,7,LEAVES:3)
Block(13,22,7,LEAVES:3)
Block(3,22,8,LEAVES:3)
Block(4,22,8,LEAVES:3)
Block(7,22,8,LOG:3)
Block(8,22,8,LOG:3)
Block(9,22,8,LOG:3)
Block(10,22,8,LOG:3)
Block(12,22,8,LEAVES:3)
Block(3,22,9,LEAVES:3)
Block(5,22,9,LEAVES:3)
Block(8,22,9,LOG:3)
Block(9,22,9,LOG:3)
Block(10,22,9,LOG:3)
Block(11,22,9,LEAVES:3)
Block(13,22,9,LEAVES:3)
Block(4,22,10,LEAVES:3)
Block(9,22,10,LOG:3)
Block(13,22,10,LEAVES:3)
Block(14,22,10,LEAVES:3)
Block(4,22,11,LEAVES:3)
Block(5,22,11,LEAVES:3)
Block(6,22,11,LEAVES:3)
Block(13,22,11,LEAVES:3)
Block(5,22,12,LEAVES:3)
Block(6,22,12,LEAVES:3)
Block(7,22,12,LEAVES:3)
Block(8,22,12,LEAVES:3)
Block(9,22,12,LEAVES:3)
Block(10,22,12,LEAVES:3)
Block(11,22,12,LEAVES:3)
Block(6,22,13,LEAVES:3)
Block(7,22,13,LEAVES:3)
Block(8,22,13,LEAVES:3)
Block(9,22,13,LEAVES:3)
Block(10,22,13,LEAVES:3)
Block(8,22,14,LEAVES:3)
Block(-2,23,-7,LEAVES:3)
Block(-3,23,-6,LOG:3)
Block(-2,23,-6,LOG:3)
Block(-1,23,-6,LOG:3)
Block(0,23,-6,LEAVES:3)
Block(-4,23,-5,LOG:3)
Block(-3,23,-5,LOG:3)
Block(-2,23,-5,LOG:3)
Block(-1,23,-5,LOG:3)
Block(0,23,-5,LOG:3)
Block(-4,23,-4,LOG:3)
Block(-3,23,-4,LOG:3)
Block(-2,23,-4,LOG:3)
Block(-1,23,-4,LOG:3)
Block(0,23,-4,LOG:3)
Block(-4,23,-3,LOG:3)
Block(-3,23,-3,LOG:3)
Block(-2,23,-3,LOG:3)
Block(-1,23,-3,LOG:3)
Block(0,23,-3,LOG:3)
Block(-3,23,-2,LOG:3)
Block(-2,23,-2,LOG:3)
Block(-1,23,-2,LOG:3)
Block(-2,23,-1,LOG:3)
Block(7,23,3,LEAVES:3)
Block(8,23,3,LEAVES:3)
Block(9,23,3,LEAVES:3)
Block(10,23,3,LEAVES:3)
Block(5,23,4,LEAVES:3)
Block(6,23,4,LEAVES:3)
Block(7,23,4,LEAVES:3)
Block(8,23,4,LEAVES:3)
Block(9,23,4,LEAVES:3)
Block(10,23,4,LEAVES:3)
Block(11,23,4,LEAVES:3)
Block(4,23,5,LEAVES:3)
Block(5,23,5,LEAVES:3)
Block(6,23,5,LEAVES:3)
Block(7,23,5,LEAVES:3)
Block(8,23,5,LEAVES:3)
Block(9,23,5,LEAVES:3)
Block(10,23,5,LEAVES:3)
Block(11,23,5,LEAVES:3)
Block(12,23,5,LEAVES:3)
Block(3,23,6,LEAVES:3)
Block(4,23,6,LEAVES:3)
Block(5,23,6,LEAVES:3)
Block(6,23,6,LEAVES:3)
Block(7,23,6,LEAVES:3)
Block(8,23,6,LEAVES:3)
Block(9,23,6,LEAVES:3)
Block(10,23,6,LEAVES:3)
Block(11,23,6,LEAVES:3)
Block(12,23,6,LEAVES:3)
Block(13,23,6,LEAVES:3)
Block(3,23,7,LEAVES:3)
Block(4,23,7,LEAVES:3)
Block(5,23,7,LEAVES:3)
Block(6,23,7,LEAVES:3)
Block(7,23,7,LEAVES:3)
Block(8,23,7,LEAVES:3)
Block(9,23,7,LEAVES:3)
Block(10,23,7,LEAVES:3)
Block(12,23,7,LEAVES:3)
Block(13,23,7,LEAVES:3)
Block(3,23,8,LEAVES:3)
Block(4,23,8,LEAVES:3)
Block(5,23,8,LEAVES:3)
Block(6,23,8,LOG:3)
Block(7,23,8,LOG:3)
Block(8,23,8,LOG:3)
Block(9,23,8,LEAVES:3)
Block(10,23,8,LEAVES:3)
Block(12,23,8,LEAVES:3)
Block(13,23,8,LEAVES:3)
Block(4,23,9,LEAVES:3)
Block(5,23,9,LEAVES:3)
Block(6,23,9,LOG:3)
Block(7,23,9,LEAVES:3)
Block(8,23,9,LOG:3)
Block(9,23,9,LEAVES:3)
Block(10,23,9,LOG:3)
Block(11,23,9,LOG:3)
Block(12,23,9,LOG:3)
Block(13,23,9,LEAVES:3)
Block(14,23,9,LEAVES:3)
Block(3,23,10,LEAVES:3)
Block(4,23,10,LEAVES:3)
Block(5,23,10,LOG:3)
Block(6,23,10,LOG:3)
Block(9,23,10,LOG:3)
Block(11,23,10,LEAVES:3)
Block(12,23,10,LOG:3)
Block(13,23,10,LEAVES:3)
Block(14,23,10,LEAVES:3)
Block(4,23,11,LEAVES:3)
Block(5,23,11,LEAVES:3)
Block(6,23,11,LEAVES:3)
Block(7,23,11,LEAVES:3)
Block(8,23,11,LEAVES:3)
Block(9,23,11,LOG:3)
Block(11,23,11,LEAVES:3)
Block(12,23,11,LEAVES:3)
Block(13,23,11,LEAVES:3)
Block(14,23,11,LEAVES:3)
Block(4,23,12,LEAVES:3)
Block(5,23,12,LEAVES:3)
Block(6,23,12,LEAVES:3)
Block(7,23,12,LEAVES:3)
Block(8,23,12,LEAVES:3)
Block(9,23,12,LEAVES:3)
Block(10,23,12,LEAVES:3)
Block(11,23,12,LEAVES:3)
Block(12,23,12,LEAVES:3)
Block(13,23,12,LEAVES:3)
Block(5,23,13,LEAVES:3)
Block(6,23,13,LEAVES:3)
Block(7,23,13,LEAVES:3)
Block(8,23,13,LEAVES:3)
Block(9,23,13,LEAVES:3)
Block(10,23,13,LEAVES:3)
Block(11,23,13,LEAVES:3)
Block(6,23,14,LEAVES:3)
Block(7,23,14,LEAVES:3)
Block(8,23,14,LEAVES:3)
Block(9,23,14,LEAVES:3)
Block(10,24,-8,LEAVES:3)
Block(-3,24,-6,LEAVES:3)
Block(-2,24,-6,LOG:3)
Block(-1,24,-6,LOG:3)
Block(-9,24,-5,LEAVES:3)
Block(-4,24,-5,LOG:3)
Block(-3,24,-5,LOG:3)
Block(-2,24,-5,LOG:3)
Block(-1,24,-5,LOG:3)
Block(1,24,-5,LEAVES:3)
Block(-4,24,-4,LOG:3)
Block(-3,24,-4,LOG:3)
Block(-2,24,-4,LOG:3)
Block(-1,24,-4,LOG:3)
Block(0,24,-4,LOG:3)
Block(-4,24,-3,LOG:3)
Block(-3,24,-3,LOG:3)
Block(-2,24,-3,LOG:3)
Block(-1,24,-3,LOG:3)
Block(0,24,-3,LOG:3)
Block(-2,24,-2,LOG:3)
Block(-1,24,-2,LOG:3)
Block(0,24,-2,LOG:3)
Block(-2,24,-1,LOG:3)
Block(-1,24,-1,LOG:3)
Block(7,24,3,LEAVES:3)
Block(6,24,4,LEAVES:3)
Block(7,24,4,LEAVES:3)
Block(8,24,4,LEAVES:3)
Block(9,24,4,LEAVES:3)
Block(10,24,4,LEAVES:3)
Block(5,24,5,LEAVES:3)
Block(6,24,5,LEAVES:3)
Block(7,24,5,LEAVES:3)
Block(8,24,5,LEAVES:3)
Block(9,24,5,LEAVES:3)
Block(10,24,5,LEAVES:3)
Block(11,24,5,LEAVES:3)
Block(4,24,6,LEAVES:3)
Block(5,24,6,LEAVES:3)
Block(6,24,6,LEAVES:3)
Block(7,24,6,LEAVES:3)
Block(8,24,6,LEAVES:3)
Block(9,24,6,LEAVES:3)
Block(10,24,6,LEAVES:3)
Block(11,24,6,LEAVES:3)
Block(12,24,6,LEAVES:3)
Block(4,24,7,LEAVES:3)
Block(6,24,7,LEAVES:3)
Block(7,24,7,LEAVES:3)
Block(8,24,7,LEAVES:3)
Block(9,24,7,LEAVES:3)
Block(10,24,7,LEAVES:3)
Block(11,24,7,LEAVES:3)
Block(12,24,7,LEAVES:3)
Block(13,24,7,LEAVES:3)
Block(3,24,8,LEAVES:3)
Block(4,24,8,LEAVES:3)
Block(5,24,8,LEAVES:3)
Block(6,24,8,LEAVES:3)
Block(7,24,8,LEAVES:3)
Block(8,24,8,LEAVES:3)
Block(9,24,8,LEAVES:3)
Block(10,24,8,LEAVES:3)
Block(11,24,8,LEAVES:3)
Block(12,24,8,LEAVES:3)
Block(-5,24,9,LEAVES:3)
Block(3,24,9,LEAVES:3)
Block(4,24,9,LEAVES:3)
Block(5,24,9,LEAVES:3)
Block(6,24,9,LEAVES:3)
Block(7,24,9,LEAVES:3)
Block(8,24,9,LEAVES:3)
Block(9,24,9,LEAVES:3)
Block(10,24,9,LEAVES:3)
Block(11,24,9,LEAVES:3)
Block(12,24,9,LEAVES:3)
Block(13,24,9,LEAVES:3)
Block(4,24,10,LEAVES:3)
Block(5,24,10,LEAVES:3)
Block(6,24,10,LEAVES:3)
Block(7,24,10,LEAVES:3)
Block(8,24,10,LEAVES:3)
Block(9,24,10,LEAVES:3)
Block(10,24,10,LEAVES:3)
Block(11,24,10,LEAVES:3)
Block(12,24,10,LEAVES:3)
Block(13,24,10,LEAVES:3)
Block(14,24,10,LEAVES:3)
Block(4,24,11,LEAVES:3)
Block(5,24,11,LEAVES:3)
Block(6,24,11,LEAVES:3)
Block(7,24,11,LEAVES:3)
Block(8,24,11,LEAVES:3)
Block(9,24,11,LEAVES:3)
Block(10,24,11,LEAVES:3)
Block(11,24,11,LEAVES:3)
Block(12,24,11,LEAVES:3)
Block(13,24,11,LEAVES:3)
Block(5,24,12,LEAVES:3)
Block(6,24,12,LEAVES:3)
Block(7,24,12,LEAVES:3)
Block(8,24,12,LEAVES:3)
Block(9,24,12,LEAVES:3)
Block(10,24,12,LEAVES:3)
Block(11,24,12,LEAVES:3)
Block(6,24,13,LEAVES:3)
Block(7,24,13,LEAVES:3)
Block(8,24,13,LEAVES:3)
Block(9,24,13,LEAVES:3)
Block(10,24,13,LEAVES:3)
Block(7,24,14,LEAVES:3)
Block(8,24,14,LEAVES:3)
Block(10,25,-8,LEAVES:3)
Block(-3,25,-6,LEAVES:3)
Block(-2,25,-6,LOG:3)
Block(-1,25,-6,LOG:3)
Block(-9,25,-5,LEAVES:3)
Block(-3,25,-5,LOG:3)
Block(-2,25,-5,LOG:3)
Block(-1,25,-5,LOG:3)
Block(-4,25,-4,LOG:3)
Block(-3,25,-4,LOG:3)
Block(-2,25,-4,LOG:3)
Block(-1,25,-4,LOG:3)
Block(0,25,-4,LOG:3)
Block(1,25,-4,LEAVES:3)
Block(-4,25,-3,LOG:3)
Block(-3,25,-3,LOG:3)
Block(-2,25,-3,LOG:3)
Block(-1,25,-3,LOG:3)
Block(0,25,-3,LOG:3)
Block(-2,25,-2,LOG:3)
Block(-1,25,-2,LOG:3)
Block(0,25,-2,LOG:3)
Block(-2,25,-1,LOG:3)
Block(-1,25,-1,LOG:3)
Block(0,25,-1,LOG:3)
Block(1,25,-1,LOG:3)
Block(-1,25,0,LOG:3)
Block(0,25,0,LOG:3)
Block(1,25,0,LOG:3)
Block(2,25,0,LOG:3)
Block(0,25,1,LOG:3)
Block(1,25,1,LOG:3)
Block(8,25,4,LEAVES:3)
Block(7,25,5,LEAVES:3)
Block(8,25,5,LEAVES:3)
Block(9,25,5,LEAVES:3)
Block(10,25,5,LEAVES:3)
Block(6,25,6,LEAVES:3)
Block(7,25,6,LEAVES:3)
Block(9,25,6,LEAVES:3)
Block(10,25,6,LEAVES:3)
Block(11,25,6,LEAVES:3)
Block(5,25,7,LEAVES:3)
Block(6,25,7,LEAVES:3)
Block(7,25,7,LEAVES:3)
Block(8,25,7,LEAVES:3)
Block(11,25,7,LEAVES:3)
Block(6,25,8,LEAVES:3)
Block(8,25,8,LEAVES:3)
Block(11,25,8,LEAVES:3)
Block(12,25,8,LEAVES:3)
Block(-5,25,9,LEAVES:3)
Block(4,25,9,LEAVES:3)
Block(5,25,9,LEAVES:3)
Block(7,25,9,LEAVES:3)
Block(8,25,9,LEAVES:3)
Block(9,25,9,LEAVES:3)
Block(10,25,9,LEAVES:3)
Block(11,25,9,LEAVES:3)
Block(12,25,9,LEAVES:3)
Block(4,25,10,LEAVES:3)
Block(5,25,10,LEAVES:3)
Block(6,25,10,LEAVES:3)
Block(7,25,10,LEAVES:3)
Block(8,25,10,LEAVES:3)
Block(10,25,10,LEAVES:3)
Block(11,25,10,LEAVES:3)
Block(2,25,11,LEAVES:3)
Block(5,25,11,LEAVES:3)
Block(6,25,11,LEAVES:3)
Block(7,25,11,LEAVES:3)
Block(8,25,11,LEAVES:3)
Block(9,25,11,LEAVES:3)
Block(10,25,11,LEAVES:3)
Block(12,25,11,LEAVES:3)
Block(6,25,12,LEAVES:3)
Block(7,25,12,LEAVES:3)
Block(8,25,12,LEAVES:3)
Block(10,25,12,LEAVES:3)
Block(10,26,-8,LEAVES:3)
Block(-2,26,-6,LOG:3)
Block(-1,26,-6,LOG:3)
Block(-9,26,-5,LEAVES:3)
Block(-4,26,-5,LEAVES:3)
Block(-3,26,-5,LOG:3)
Block(-2,26,-5,LOG:3)
Block(-1,26,-5,LOG:3)
Block(-4,26,-4,LOG:3)
Block(-3,26,-4,LOG:3)
Block(-2,26,-4,LOG:3)
Block(-1,26,-4,LOG:3)
Block(0,26,-4,LOG:3)
Block(4,26,-4,LEAVES:3)
Block(-4,26,-3,LOG:3)
Block(-3,26,-3,LOG:3)
Block(-2,26,-3,LOG:3)
Block(-1,26,-3,LOG:3)
Block(0,26,-3,LOG:3)
Block(1,26,-3,LOG:3)
Block(2,26,-3,LEAVES:3)
Block(-3,26,-2,LOG:3)
Block(-2,26,-2,LOG:3)
Block(-1,26,-2,LOG:3)
Block(0,26,-2,LOG:3)
Block(1,26,-2,LOG:3)
Block(-2,26,-1,LOG:3)
Block(-1,26,-1,LOG:3)
Block(0,26,-1,LOG:3)
Block(1,26,-1,LOG:3)
Block(2,26,-1,LOG:3)
Block(-2,26,0,LOG:3)
Block(-1,26,0,LOG:3)
Block(0,26,0,LOG:3)
Block(1,26,0,LOG:3)
Block(2,26,0,LOG:3)
Block(3,26,0,LOG:3)
Block(0,26,1,LOG:3)
Block(1,26,1,LOG:3)
Block(2,26,1,LOG:3)
Block(3,26,1,LOG:3)
Block(1,26,2,LOG:3)
Block(2,26,2,LOG:3)
Block(3,26,2,LOG:3)
Block(3,26,3,LEAVES:3)
Block(-5,26,9,LEAVES:3)
Block(2,26,11,LEAVES:3)
Block(-5,27,-11,LEAVES:3)
Block(8,27,-10,LEAVES:3)
Block(10,27,-8,LEAVES:3)
Block(-2,27,-7,LEAVES:3)
Block(-2,27,-6,LOG:3)
Block(-1,27,-6,LOG:3)
Block(-9,27,-5,LEAVES:3)
Block(-4,27,-5,LOG:3)
Block(-3,27,-5,LOG:3)
Block(-2,27,-5,LOG:3)
Block(-1,27,-5,LOG:3)
Block(0,27,-5,LOG:3)
Block(-5,27,-4,LEAVES:3)
Block(-4,27,-4,LOG:3)
Block(-3,27,-4,LOG:3)
Block(-2,27,-4,LOG:3)
Block(-1,27,-4,LOG:3)
Block(0,27,-4,LOG:3)
Block(4,27,-4,LEAVES:3)
Block(-4,27,-3,LOG:3)
Block(-3,27,-3,LOG:3)
Block(-2,27,-3,LOG:3)
Block(-1,27,-3,LOG:3)
Block(0,27,-3,LOG:3)
Block(-3,27,-2,LOG:3)
Block(-2,27,-2,LOG:3)
Block(-1,27,-2,LOG:3)
Block(0,27,-2,LOG:3)
Block(1,27,-2,LOG:3)
Block(2,27,-2,LEAVES:3)
Block(-3,27,-1,LOG:3)
Block(-2,27,-1,LOG:3)
Block(-1,27,-1,LOG:3)
Block(0,27,-1,LOG:3)
Block(1,27,-1,LOG:3)
Block(-2,27,0,LOG:3)
Block(-1,27,0,LOG:3)
Block(0,27,0,LOG:3)
Block(1,27,0,LOG:3)
Block(2,27,0,LOG:3)
Block(3,27,0,LOG:3)
Block(-1,27,1,LOG:3)
Block(0,27,1,LOG:3)
Block(1,27,1,LOG:3)
Block(2,27,1,LOG:3)
Block(3,27,1,LOG:3)
Block(4,27,1,LOG:3)
Block(0,27,2,LOG:3)
Block(1,27,2,LOG:3)
Block(2,27,2,LOG:3)
Block(3,27,2,LOG:3)
Block(4,27,2,LEAVES:3)
Block(1,27,3,LOG:3)
Block(2,27,3,LOG:3)
Block(3,27,3,LOG:3)
Block(2,27,4,LEAVES:3)
Block(-8,27,6,LEAVES:3)
Block(-5,27,9,LEAVES:3)
Block(8,27,9,LEAVES:3)
Block(-1,27,10,LEAVES:3)
Block(2,27,11,LEAVES:3)
Block(5,27,11,LEAVES:3)
Block(-5,28,-11,LEAVES:3)
Block(8,28,-10,LEAVES:3)
Block(10,28,-8,LEAVES:3)
Block(-2,28,-7,LEAVES:3)
Block(-1,28,-7,LEAVES:3)
Block(-2,28,-6,LOG:3)
Block(-1,28,-6,LOG:3)
Block(0,28,-6,LOG:3)
Block(-9,28,-5,LEAVES:3)
Block(-4,28,-5,LOG:3)
Block(-3,28,-5,LOG:3)
Block(-2,28,-5,LOG:3)
Block(-1,28,-5,LOG:3)
Block(0,28,-5,LOG:3)
Block(-5,28,-4,LEAVES:3)
Block(-4,28,-4,LOG:3)
Block(-3,28,-4,LOG:3)
Block(-2,28,-4,LOG:3)
Block(-1,28,-4,LOG:3)
Block(0,28,-4,LOG:3)
Block(4,28,-4,LEAVES:3)
Block(-4,28,-3,LOG:3)
Block(-3,28,-3,LOG:3)
Block(-2,28,-3,LOG:3)
Block(-1,28,-3,LOG:3)
Block(0,28,-3,LOG:3)
Block(-3,28,-2,LOG:3)
Block(-2,28,-2,LOG:3)
Block(-1,28,-2,LOG:3)
Block(0,28,-2,LOG:3)
Block(-2,28,-1,LOG:3)
Block(-1,28,-1,LOG:3)
Block(0,28,-1,LOG:3)
Block(1,28,-1,LEAVES:3)
Block(-1,28,0,LOG:3)
Block(0,28,0,LOG:3)
Block(1,28,0,LOG:3)
Block(2,28,0,LOG:3)
Block(9,28,0,LEAVES:3)
Block(0,28,1,LOG:3)
Block(1,28,1,LOG:3)
Block(2,28,1,LOG:3)
Block(3,28,1,LOG:3)
Block(4,28,1,LOG:3)
Block(1,28,2,LOG:3)
Block(2,28,2,LOG:3)
Block(3,28,2,LOG:3)
Block(4,28,2,LOG:3)
Block(5,28,2,LEAVES:3)
Block(2,28,3,LOG:3)
Block(3,28,3,LOG:3)
Block(4,28,3,LOG:3)
Block(10,28,3,LEAVES:3)
Block(1,28,4,LEAVES:3)
Block(2,28,4,LOG:3)
Block(3,28,4,LOG:3)
Block(7,28,5,LEAVES:3)
Block(-8,28,6,LEAVES:3)
Block(-5,28,9,LEAVES:3)
Block(8,28,9,LEAVES:3)
Block(-1,28,10,LEAVES:3)
Block(2,28,11,LEAVES:3)
Block(5,28,11,LEAVES:3)
Block(-1,29,-13,LEAVES:3)
Block(-5,29,-11,LEAVES:3)
Block(4,29,-11,LEAVES:3)
Block(8,29,-10,LEAVES:3)
Block(10,29,-8,LEAVES:3)
Block(-3,29,-7,LEAVES:3)
Block(-1,29,-7,LOG:3)
Block(0,29,-7,LEAVES:3)
Block(-3,29,-6,LOG:3)
Block(-2,29,-6,LOG:3)
Block(-1,29,-6,LOG:3)
Block(0,29,-6,LOG:3)
Block(-9,29,-5,LEAVES:3)
Block(-4,29,-5,LOG:3)
Block(-3,29,-5,LOG:3)
Block(-2,29,-5,LOG:3)
Block(-1,29,-5,LOG:3)
Block(0,29,-5,LOG:3)
Block(1,29,-5,LOG:3)
Block(11,29,-5,LEAVES:3)
Block(-4,29,-4,LOG:3)
Block(-3,29,-4,LOG:3)
Block(-2,29,-4,LOG:3)
Block(-1,29,-4,LOG:3)
Block(0,29,-4,LOG:3)
Block(4,29,-4,LEAVES:3)
Block(-4,29,-3,LEAVES:3)
Block(-3,29,-3,LOG:3)
Block(-2,29,-3,LOG:3)
Block(-1,29,-3,LOG:3)
Block(0,29,-3,LOG:3)
Block(6,29,-3,LEAVES:3)
Block(-2,29,-2,LOG:3)
Block(-1,29,-2,LOG:3)
Block(-1,29,-1,LEAVES:3)
Block(0,29,-1,LEAVES:3)
Block(13,29,-1,LEAVES:3)
Block(9,29,0,LEAVES:3)
Block(3,29,1,LOG:3)
Block(6,29,1,LEAVES:3)
Block(2,29,2,LOG:3)
Block(3,29,2,LOG:3)
Block(4,29,2,LOG:3)
Block(5,29,2,LEAVES:3)
Block(2,29,3,LOG:3)
Block(3,29,3,LOG:3)
Block(4,29,3,LOG:3)
Block(10,29,3,LEAVES:3)
Block(-9,29,4,LEAVES:3)
Block(1,29,4,LEAVES:3)
Block(2,29,4,LOG:3)
Block(3,29,4,LOG:3)
Block(4,29,4,LOG:3)
Block(3,29,5,LOG:3)
Block(7,29,5,LEAVES:3)
Block(-8,29,6,LEAVES:3)
Block(9,29,6,LEAVES:3)
Block(-5,29,9,LEAVES:3)
Block(8,29,9,LEAVES:3)
Block(-1,29,10,LEAVES:3)
Block(2,29,11,LEAVES:3)
Block(5,29,11,LEAVES:3)
Block(-1,30,-13,LEAVES:3)
Block(-5,30,-11,LEAVES:3)
Block(4,30,-11,LEAVES:3)
Block(8,30,-10,LEAVES:3)
Block(-7,30,-8,LEAVES:3)
Block(10,30,-8,LEAVES:3)
Block(-2,30,-7,LOG:3)
Block(-1,30,-7,LOG:3)
Block(0,30,-7,LEAVES:3)
Block(-4,30,-6,LEAVES:3)
Block(-3,30,-6,LOG:3)
Block(-2,30,-6,LOG:3)
Block(-1,30,-6,LOG:3)
Block(0,30,-6,LOG:3)
Block(-9,30,-5,LEAVES:3)
Block(-4,30,-5,LOG:3)
Block(-3,30,-5,LOG:3)
Block(-2,30,-5,LOG:3)
Block(-1,30,-5,LOG:3)
Block(0,30,-5,LOG:3)
Block(1,30,-5,LOG:3)
Block(11,30,-5,LEAVES:3)
Block(-4,30,-4,LOG:3)
Block(-3,30,-4,LOG:3)
Block(-2,30,-4,LOG:3)
Block(-1,30,-4,LOG:3)
Block(0,30,-4,LOG:3)
Block(1,30,-4,LOG:3)
Block(4,30,-4,LEAVES:3)
Block(-4,30,-3,LEAVES:3)
Block(-3,30,-3,LOG:3)
Block(-2,30,-3,LOG:3)
Block(-1,30,-3,LOG:3)
Block(0,30,-3,LOG:3)
Block(6,30,-3,LEAVES:3)
Block(-10,30,-2,LEAVES:3)
Block(-2,30,-2,LOG:3)
Block(-1,30,-2,LEAVES:3)
Block(13,30,-1,LEAVES:3)
Block(9,30,0,LEAVES:3)
Block(-11,30,1,LEAVES:3)
Block(6,30,1,LEAVES:3)
Block(3,30,2,LOG:3)
Block(1,30,3,LEAVES:3)
Block(2,30,3,LOG:3)
Block(3,30,3,LOG:3)
Block(4,30,3,LOG:3)
Block(10,30,3,LEAVES:3)
Block(-9,30,4,LEAVES:3)
Block(1,30,4,LOG:3)
Block(2,30,4,LOG:3)
Block(3,30,4,LOG:3)
Block(4,30,4,LOG:3)
Block(2,30,5,LOG:3)
Block(3,30,5,LOG:3)
Block(4,30,5,LOG:3)
Block(7,30,5,LEAVES:3)
Block(-8,30,6,LEAVES:3)
Block(3,30,6,LOG:3)
Block(9,30,6,LEAVES:3)
Block(-5,30,9,LEAVES:3)
Block(8,30,9,LEAVES:3)
Block(-1,30,10,LEAVES:3)
Block(2,30,11,LEAVES:3)
Block(5,30,11,LEAVES:3)
Block(-1,31,-13,LEAVES:3)
Block(2,31,-12,LEAVES:3)
Block(-5,31,-11,LEAVES:3)
Block(4,31,-11,LEAVES:3)
Block(8,31,-10,LEAVES:3)
Block(-7,31,-8,LEAVES:3)
Block(1,31,-8,LEAVES:3)
Block(10,31,-8,LEAVES:3)
Block(-2,31,-7,LOG:3)
Block(-1,31,-7,LOG:3)
Block(0,31,-7,LOG:3)
Block(-4,31,-6,LEAVES:3)
Block(-3,31,-6,LOG:3)
Block(-2,31,-6,LOG:3)
Block(-1,31,-6,LOG:3)
Block(0,31,-6,LOG:3)
Block(1,31,-6,LOG:3)
Block(-9,31,-5,LEAVES:3)
Block(-4,31,-5,LOG:3)
Block(-3,31,-5,LOG:3)
Block(-2,31,-5,LOG:3)
Block(-1,31,-5,LOG:3)
Block(0,31,-5,LOG:3)
Block(1,31,-5,LOG:3)
Block(2,31,-5,LOG:3)
Block(11,31,-5,LEAVES:3)
Block(-4,31,-4,LOG:3)
Block(-3,31,-4,LOG:3)
Block(-2,31,-4,LOG:3)
Block(-1,31,-4,LOG:3)
Block(0,31,-4,LOG:3)
Block(1,31,-4,LOG:3)
Block(3,31,-4,LEAVES:3)
Block(4,31,-4,LEAVES:3)
Block(5,31,-4,LEAVES:3)
Block(-2,31,-3,LOG:3)
Block(-1,31,-3,LOG:3)
Block(0,31,-3,LOG:3)
Block(2,31,-3,LEAVES:3)
Block(3,31,-3,LEAVES:3)
Block(4,31,-3,LEAVES:3)
Block(5,31,-3,LEAVES:3)
Block(-10,31,-2,LEAVES:3)
Block(-3,31,-2,LEAVES:3)
Block(-1,31,-2,LEAVES:3)
Block(3,31,-2,LEAVES:3)
Block(5,31,-2,LEAVES:3)
Block(6,31,-2,LEAVES:3)
Block(7,31,-2,LEAVES:3)
Block(8,31,-2,LEAVES:3)
Block(-2,31,-1,LEAVES:3)
Block(-1,31,-1,LEAVES:3)
Block(0,31,-1,LEAVES:3)
Block(8,31,-1,LEAVES:3)
Block(9,31,-1,LEAVES:3)
Block(10,31,-1,LEAVES:3)
Block(13,31,-1,LEAVES:3)
Block(-3,31,0,LEAVES:3)
Block(-2,31,0,LEAVES:3)
Block(-1,31,0,LEAVES:3)
Block(9,31,0,LEAVES:3)
Block(10,31,0,LEAVES:3)
Block(-11,31,1,LEAVES:3)
Block(-3,31,1,LEAVES:3)
Block(6,31,1,LEAVES:3)
Block(9,31,1,LEAVES:3)
Block(-4,31,2,LEAVES:3)
Block(-3,31,2,LEAVES:3)
Block(-5,31,3,LEAVES:3)
Block(-4,31,3,LEAVES:3)
Block(0,31,3,LEAVES:3)
Block(3,31,3,LOG:3)
Block(4,31,3,LOG:3)
Block(8,31,3,LEAVES:3)
Block(9,31,3,LEAVES:3)
Block(10,31,3,LEAVES:3)
Block(-9,31,4,LEAVES:3)
Block(-5,31,4,LEAVES:3)
Block(1,31,4,LOG:3)
Block(2,31,4,LOG:3)
Block(3,31,4,LOG:3)
Block(4,31,4,LOG:3)
Block(6,31,4,LEAVES:3)
Block(9,31,4,LEAVES:3)
Block(10,31,4,LEAVES:3)
Block(-5,31,5,LEAVES:3)
Block(1,31,5,LOG:3)
Block(2,31,5,LOG:3)
Block(3,31,5,LOG:3)
Block(7,31,5,LEAVES:3)
Block(9,31,5,LEAVES:3)
Block(10,31,5,LEAVES:3)
Block(11,31,5,LEAVES:3)
Block(-8,31,6,LEAVES:3)
Block(-4,31,6,LEAVES:3)
Block(2,31,6,LOG:3)
Block(3,31,6,LOG:3)
Block(7,31,6,LEAVES:3)
Block(8,31,6,LEAVES:3)
Block(9,31,6,LEAVES:3)
Block(10,31,6,LEAVES:3)
Block(-4,31,7,LEAVES:3)
Block(8,31,7,LEAVES:3)
Block(9,31,7,LEAVES:3)
Block(-3,31,8,LEAVES:3)
Block(-2,31,8,LEAVES:3)
Block(7,31,8,LEAVES:3)
Block(8,31,8,LEAVES:3)
Block(9,31,8,LEAVES:3)
Block(-5,31,9,LEAVES:3)
Block(-2,31,9,LEAVES:3)
Block(-1,31,9,LEAVES:3)
Block(0,31,9,LEAVES:3)
Block(6,31,9,LEAVES:3)
Block(7,31,9,LEAVES:3)
Block(8,31,9,LEAVES:3)
Block(-1,31,10,LEAVES:3)
Block(0,31,10,LEAVES:3)
Block(1,31,10,LEAVES:3)
Block(2,31,10,LEAVES:3)
Block(5,31,10,LEAVES:3)
Block(6,31,10,LEAVES:3)
Block(7,31,10,LEAVES:3)
Block(2,31,11,LEAVES:3)
Block(3,31,11,LEAVES:3)
Block(4,31,11,LEAVES:3)
Block(5,31,11,LEAVES:3)
Block(3,31,12,LEAVES:3)
Block(-1,32,-13,LEAVES:3)
Block(2,32,-12,LEAVES:3)
Block(-5,32,-11,LEAVES:3)
Block(4,32,-11,LEAVES:3)
Block(8,32,-10,LEAVES:3)
Block(2,32,-9,LEAVES:3)
Block(-7,32,-8,LEAVES:3)
Block(-1,32,-8,LOG:3)
Block(1,32,-8,LEAVES:3)
Block(10,32,-8,LEAVES:3)
Block(-2,32,-7,LOG:3)
Block(-1,32,-7,LOG:3)
Block(0,32,-7,LOG:3)
Block(10,32,-7,LEAVES:3)
Block(-5,32,-6,LEAVES:3)
Block(-3,32,-6,LOG:3)
Block(-2,32,-6,LOG:3)
Block(-1,32,-6,LOG:3)
Block(0,32,-6,LOG:3)
Block(1,32,-6,LOG:3)
Block(-9,32,-5,LEAVES:3)
Block(-6,32,-5,LOG:3)
Block(-5,32,-5,LOG:3)
Block(-4,32,-5,LOG:3)
Block(-3,32,-5,LOG:3)
Block(-2,32,-5,LOG:3)
Block(-1,32,-5,LOG:3)
Block(0,32,-5,LOG:3)
Block(1,32,-5,LOG:3)
Block(2,32,-5,LOG:3)
Block(11,32,-5,LEAVES:3)
Block(-3,32,-4,LOG:3)
Block(-2,32,-4,LOG:3)
Block(-1,32,-4,LOG:3)
Block(0,32,-4,LOG:3)
Block(1,32,-4,LOG:3)
Block(2,32,-4,LOG:3)
Block(3,32,-4,LEAVES:3)
Block(4,32,-4,LEAVES:3)
Block(5,32,-4,LEAVES:3)
Block(6,32,-4,LEAVES:3)
Block(-2,32,-3,LOG:3)
Block(-1,32,-3,LOG:3)
Block(0,32,-3,LOG:3)
Block(1,32,-3,LEAVES:3)
Block(2,32,-3,LEAVES:3)
Block(3,32,-3,LEAVES:3)
Block(4,32,-3,LEAVES:3)
Block(5,32,-3,LEAVES:3)
Block(6,32,-3,LEAVES:3)
Block(7,32,-3,LEAVES:3)
Block(-10,32,-2,LEAVES:3)
Block(-3,32,-2,LEAVES:3)
Block(-2,32,-2,LEAVES:3)
Block(-1,32,-2,LEAVES:3)
Block(0,32,-2,LEAVES:3)
Block(1,32,-2,LEAVES:3)
Block(2,32,-2,LEAVES:3)
Block(3,32,-2,LEAVES:3)
Block(4,32,-2,LEAVES:3)
Block(5,32,-2,LEAVES:3)
Block(6,32,-2,LEAVES:3)
Block(7,32,-2,LEAVES:3)
Block(8,32,-2,LEAVES:3)
Block(9,32,-2,LEAVES:3)
Block(-3,32,-1,LEAVES:3)
Block(-2,32,-1,LEAVES:3)
Block(-1,32,-1,LEAVES:3)
Block(0,32,-1,LEAVES:3)
Block(1,32,-1,LEAVES:3)
Block(2,32,-1,LEAVES:3)
Block(3,32,-1,LEAVES:3)
Block(4,32,-1,LEAVES:3)
Block(5,32,-1,LEAVES:3)
Block(6,32,-1,LEAVES:3)
Block(8,32,-1,LEAVES:3)
Block(9,32,-1,LEAVES:3)
Block(10,32,-1,LEAVES:3)
Block(13,32,-1,LEAVES:3)
Block(-3,32,0,LEAVES:3)
Block(-2,32,0,LEAVES:3)
Block(-1,32,0,LEAVES:3)
Block(0,32,0,LEAVES:3)
Block(4,32,0,LEAVES:3)
Block(5,32,0,LEAVES:3)
Block(8,32,0,LEAVES:3)
Block(9,32,0,LEAVES:3)
Block(10,32,0,LEAVES:3)
Block(-11,32,1,LEAVES:3)
Block(-4,32,1,LEAVES:3)
Block(-3,32,1,LEAVES:3)
Block(-2,32,1,LEAVES:3)
Block(-1,32,1,LEAVES:3)
Block(3,32,1,LEAVES:3)
Block(4,32,1,LEAVES:3)
Block(6,32,1,LEAVES:3)
Block(8,32,1,LEAVES:3)
Block(9,32,1,LEAVES:3)
Block(10,32,1,LEAVES:3)
Block(-5,32,2,LEAVES:3)
Block(-4,32,2,LEAVES:3)
Block(-3,32,2,LEAVES:3)
Block(-2,32,2,LEAVES:3)
Block(-1,32,2,LEAVES:3)
Block(0,32,2,LEAVES:3)
Block(1,32,2,LEAVES:3)
Block(3,32,2,LEAVES:3)
Block(4,32,2,LEAVES:3)
Block(5,32,2,LEAVES:3)
Block(7,32,2,LEAVES:3)
Block(8,32,2,LEAVES:3)
Block(9,32,2,LEAVES:3)
Block(10,32,2,LEAVES:3)
Block(-5,32,3,LEAVES:3)
Block(-3,32,3,LEAVES:3)
Block(-2,32,3,LEAVES:3)
Block(0,32,3,LEAVES:3)
Block(1,32,3,LEAVES:3)
Block(3,32,3,LEAVES:3)
Block(4,32,3,LEAVES:3)
Block(5,32,3,LEAVES:3)
Block(6,32,3,LEAVES:3)
Block(7,32,3,LEAVES:3)
Block(8,32,3,LEAVES:3)
Block(9,32,3,LEAVES:3)
Block(10,32,3,LEAVES:3)
Block(-9,32,4,LEAVES:3)
Block(-5,32,4,LEAVES:3)
Block(-4,32,4,LEAVES:3)
Block(-3,32,4,LEAVES:3)
Block(1,32,4,LEAVES:3)
Block(3,32,4,LEAVES:3)
Block(4,32,4,LEAVES:3)
Block(5,32,4,LEAVES:3)
Block(6,32,4,LEAVES:3)
Block(7,32,4,LEAVES:3)
Block(8,32,4,LEAVES:3)
Block(9,32,4,LEAVES:3)
Block(10,32,4,LEAVES:3)
Block(11,32,4,LEAVES:3)
Block(-5,32,5,LEAVES:3)
Block(-4,32,5,LEAVES:3)
Block(-3,32,5,LEAVES:3)
Block(0,32,5,LOG:3)
Block(1,32,5,LEAVES:3)
Block(2,32,5,LEAVES:3)
Block(3,32,5,LEAVES:3)
Block(4,32,5,LEAVES:3)
Block(6,32,5,LEAVES:3)
Block(7,32,5,LEAVES:3)
Block(8,32,5,LEAVES:3)
Block(9,32,5,LEAVES:3)
Block(10,32,5,LEAVES:3)
Block(11,32,5,LEAVES:3)
Block(-8,32,6,LEAVES:3)
Block(-5,32,6,LEAVES:3)
Block(-4,32,6,LEAVES:3)
Block(-3,32,6,LEAVES:3)
Block(-2,32,6,LEAVES:3)
Block(-1,32,6,LEAVES:3)
Block(0,32,6,LEAVES:3)
Block(1,32,6,LEAVES:3)
Block(3,32,6,LEAVES:3)
Block(4,32,6,LOG:3)
Block(7,32,6,LEAVES:3)
Block(8,32,6,LEAVES:3)
Block(9,32,6,LEAVES:3)
Block(10,32,6,LEAVES:3)
Block(11,32,6,LEAVES:3)
Block(-4,32,7,LEAVES:3)
Block(-3,32,7,LEAVES:3)
Block(-2,32,7,LEAVES:3)
Block(-1,32,7,LEAVES:3)
Block(0,32,7,LEAVES:3)
Block(1,32,7,LEAVES:3)
Block(2,32,7,LOG:3)
Block(3,32,7,LEAVES:3)
Block(4,32,7,LOG:3)
Block(7,32,7,LEAVES:3)
Block(8,32,7,LEAVES:3)
Block(9,32,7,LEAVES:3)
Block(10,32,7,LEAVES:3)
Block(-4,32,8,LEAVES:3)
Block(-3,32,8,LEAVES:3)
Block(-2,32,8,LEAVES:3)
Block(-1,32,8,LEAVES:3)
Block(0,32,8,LEAVES:3)
Block(1,32,8,LOG:3)
Block(2,32,8,LOG:3)
Block(3,32,8,LEAVES:3)
Block(6,32,8,LEAVES:3)
Block(7,32,8,LEAVES:3)
Block(8,32,8,LEAVES:3)
Block(-5,32,9,LEAVES:3)
Block(-2,32,9,LEAVES:3)
Block(-1,32,9,LEAVES:3)
Block(0,32,9,LEAVES:3)
Block(2,32,9,LEAVES:3)
Block(3,32,9,LEAVES:3)
Block(4,32,9,LEAVES:3)
Block(6,32,9,LEAVES:3)
Block(7,32,9,LEAVES:3)
Block(8,32,9,LEAVES:3)
Block(9,32,9,LEAVES:3)
Block(-2,32,10,LEAVES:3)
Block(-1,32,10,LEAVES:3)
Block(0,32,10,LEAVES:3)
Block(1,32,10,LEAVES:3)
Block(2,32,10,LEAVES:3)
Block(3,32,10,LEAVES:3)
Block(4,32,10,LEAVES:3)
Block(5,32,10,LEAVES:3)
Block(6,32,10,LEAVES:3)
Block(7,32,10,LEAVES:3)
Block(8,32,10,LEAVES:3)
Block(0,32,11,LEAVES:3)
Block(1,32,11,LEAVES:3)
Block(2,32,11,LEAVES:3)
Block(3,32,11,LEAVES:3)
Block(4,32,11,LEAVES:3)
Block(5,32,11,LEAVES:3)
Block(6,32,11,LEAVES:3)
Block(3,32,12,LEAVES:3)
Block(4,32,12,LEAVES:3)
Block(-2,33,-13,LEAVES:3)
Block(-1,33,-13,LEAVES:3)
Block(1,33,-13,LEAVES:3)
Block(-4,33,-12,LEAVES:3)
Block(-3,33,-12,LEAVES:3)
Block(-2,33,-12,LEAVES:3)
Block(-1,33,-12,LEAVES:3)
Block(0,33,-12,LEAVES:3)
Block(1,33,-12,LEAVES:3)
Block(2,33,-12,LEAVES:3)
Block(3,33,-12,LEAVES:3)
Block(5,33,-12,LEAVES:3)
Block(-5,33,-11,LEAVES:3)
Block(-4,33,-11,LEAVES:3)
Block(-3,33,-11,LEAVES:3)
Block(-2,33,-11,LEAVES:3)
Block(2,33,-11,LEAVES:3)
Block(3,33,-11,LEAVES:3)
Block(4,33,-11,LEAVES:3)
Block(5,33,-11,LEAVES:3)
Block(6,33,-11,LEAVES:3)
Block(7,33,-11,LEAVES:3)
Block(-6,33,-10,LEAVES:3)
Block(-4,33,-10,LEAVES:3)
Block(3,33,-10,LEAVES:3)
Block(5,33,-10,LEAVES:3)
Block(6,33,-10,LEAVES:3)
Block(7,33,-10,LEAVES:3)
Block(8,33,-10,LEAVES:3)
Block(-7,33,-9,LEAVES:3)
Block(-6,33,-9,LEAVES:3)
Block(-5,33,-9,LEAVES:3)
Block(-1,33,-9,LOG:3)
Block(2,33,-9,LEAVES:3)
Block(7,33,-9,LEAVES:3)
Block(8,33,-9,LEAVES:3)
Block(-8,33,-8,LEAVES:3)
Block(-7,33,-8,LEAVES:3)
Block(-6,33,-8,LEAVES:3)
Block(-1,33,-8,LOG:3)
Block(0,33,-8,LOG:3)
Block(7,33,-8,LEAVES:3)
Block(8,33,-8,LEAVES:3)
Block(9,33,-8,LEAVES:3)
Block(10,33,-8,LEAVES:3)
Block(-9,33,-7,LEAVES:3)
Block(-8,33,-7,LEAVES:3)
Block(-7,33,-7,LEAVES:3)
Block(-2,33,-7,LOG:3)
Block(-1,33,-7,LOG:3)
Block(0,33,-7,LOG:3)
Block(8,33,-7,LEAVES:3)
Block(9,33,-7,LEAVES:3)
Block(10,33,-7,LEAVES:3)
Block(11,33,-7,LEAVES:3)
Block(-9,33,-6,LEAVES:3)
Block(-8,33,-6,LEAVES:3)
Block(-6,33,-6,LEAVES:3)
Block(-3,33,-6,LOG:3)
Block(-2,33,-6,LOG:3)
Block(-1,33,-6,LOG:3)
Block(0,33,-6,LOG:3)
Block(1,33,-6,LOG:3)
Block(2,33,-6,LOG:3)
Block(10,33,-6,LEAVES:3)
Block(-10,33,-5,LEAVES:3)
Block(-9,33,-5,LEAVES:3)
Block(-8,33,-5,LOG:3)
Block(-7,33,-5,LOG:3)
Block(-6,33,-5,LOG:3)
Block(-3,33,-5,LOG:3)
Block(-2,33,-5,LOG:3)
Block(-1,33,-5,LOG:3)
Block(0,33,-5,LOG:3)
Block(1,33,-5,LOG:3)
Block(2,33,-5,LOG:3)
Block(3,33,-5,LOG:3)
Block(9,33,-5,LEAVES:3)
Block(10,33,-5,LEAVES:3)
Block(11,33,-5,LEAVES:3)
Block(-9,33,-4,LEAVES:3)
Block(-8,33,-4,LOG:3)
Block(-3,33,-4,LOG:3)
Block(-2,33,-4,LOG:3)
Block(-1,33,-4,LOG:3)
Block(0,33,-4,LOG:3)
Block(1,33,-4,LOG:3)
Block(2,33,-4,LOG:3)
Block(3,33,-4,LEAVES:3)
Block(5,33,-4,LEAVES:3)
Block(6,33,-4,LEAVES:3)
Block(11,33,-4,LEAVES:3)
Block(12,33,-4,LEAVES:3)
Block(-10,33,-3,LEAVES:3)
Block(-3,33,-3,LOG:3)
Block(-2,33,-3,LOG:3)
Block(-1,33,-3,LOG:3)
Block(0,33,-3,LOG:3)
Block(1,33,-3,LOG:3)
Block(2,33,-3,LOG:3)
Block(3,33,-3,LEAVES:3)
Block(4,33,-3,LEAVES:3)
Block(5,33,-3,LEAVES:3)
Block(6,33,-3,LEAVES:3)
Block(12,33,-3,LEAVES:3)
Block(13,33,-3,LEAVES:3)
Block(-11,33,-2,LEAVES:3)
Block(-10,33,-2,LEAVES:3)
Block(-9,33,-2,LEAVES:3)
Block(-4,33,-2,LOG:3)
Block(-3,33,-2,LOG:3)
Block(-1,33,-2,LOG:3)
Block(0,33,-2,LOG:3)
Block(1,33,-2,LOG:3)
Block(3,33,-2,LEAVES:3)
Block(5,33,-2,LEAVES:3)
Block(6,33,-2,LEAVES:3)
Block(12,33,-2,LEAVES:3)
Block(13,33,-2,LEAVES:3)
Block(-11,33,-1,LEAVES:3)
Block(-4,33,-1,LOG:3)
Block(-2,33,-1,LEAVES:3)
Block(-1,33,-1,LEAVES:3)
Block(0,33,-1,LEAVES:3)
Block(6,33,-1,LEAVES:3)
Block(7,33,-1,LEAVES:3)
Block(9,33,-1,LEAVES:3)
Block(12,33,-1,LEAVES:3)
Block(13,33,-1,LEAVES:3)
Block(-11,33,0,LEAVES:3)
Block(-10,33,0,LEAVES:3)
Block(-3,33,0,LEAVES:3)
Block(-2,33,0,LEAVES:3)
Block(-1,33,0,LEAVES:3)
Block(1,33,0,LEAVES:3)
Block(2,33,0,LEAVES:3)
Block(3,33,0,LEAVES:3)
Block(6,33,0,LEAVES:3)
Block(7,33,0,LEAVES:3)
Block(8,33,0,LEAVES:3)
Block(9,33,0,LEAVES:3)
Block(10,33,0,LEAVES:3)
Block(12,33,0,LEAVES:3)
Block(-11,33,1,LEAVES:3)
Block(-10,33,1,LEAVES:3)
Block(-9,33,1,LEAVES:3)
Block(-3,33,1,LEAVES:3)
Block(-1,33,1,LEAVES:3)
Block(0,33,1,LEAVES:3)
Block(1,33,1,LEAVES:3)
Block(2,33,1,LEAVES:3)
Block(3,33,1,LEAVES:3)
Block(5,33,1,LEAVES:3)
Block(6,33,1,LEAVES:3)
Block(7,33,1,LEAVES:3)
Block(9,33,1,LEAVES:3)
Block(12,33,1,LEAVES:3)
Block(-10,33,2,LEAVES:3)
Block(-9,33,2,LEAVES:3)
Block(-4,33,2,LEAVES:3)
Block(-3,33,2,LEAVES:3)
Block(-2,33,2,LEAVES:3)
Block(0,33,2,LEAVES:3)
Block(6,33,2,LEAVES:3)
Block(9,33,2,LEAVES:3)
Block(11,33,2,LEAVES:3)
Block(12,33,2,LEAVES:3)
Block(13,33,2,LEAVES:3)
Block(-10,33,3,LEAVES:3)
Block(-9,33,3,LEAVES:3)
Block(-5,33,3,LEAVES:3)
Block(-4,33,3,LEAVES:3)
Block(-3,33,3,LEAVES:3)
Block(-1,33,3,LEAVES:3)
Block(0,33,3,LEAVES:3)
Block(8,33,3,LEAVES:3)
Block(9,33,3,LEAVES:3)
Block(10,33,3,LEAVES:3)
Block(12,33,3,LEAVES:3)
Block(-9,33,4,LEAVES:3)
Block(-8,33,4,LEAVES:3)
Block(-4,33,4,LEAVES:3)
Block(-2,33,4,LEAVES:3)
Block(-1,33,4,LEAVES:3)
Block(0,33,4,LEAVES:3)
Block(9,33,4,LEAVES:3)
Block(10,33,4,LEAVES:3)
Block(11,33,4,LEAVES:3)
Block(-8,33,5,LEAVES:3)
Block(-7,33,5,LEAVES:3)
Block(-5,33,5,LEAVES:3)
Block(-4,33,5,LEAVES:3)
Block(-3,33,5,LEAVES:3)
Block(-2,33,5,LOG:3)
Block(-1,33,5,LOG:3)
Block(5,33,5,LEAVES:3)
Block(9,33,5,LEAVES:3)
Block(10,33,5,LEAVES:3)
Block(11,33,5,LEAVES:3)
Block(-9,33,6,LEAVES:3)
Block(-8,33,6,LEAVES:3)
Block(-7,33,6,LEAVES:3)
Block(-6,33,6,LEAVES:3)
Block(-4,33,6,LEAVES:3)
Block(-3,33,6,LEAVES:3)
Block(2,33,6,LEAVES:3)
Block(4,33,6,LEAVES:3)
Block(5,33,6,LEAVES:3)
Block(6,33,6,LEAVES:3)
Block(7,33,6,LEAVES:3)
Block(8,33,6,LEAVES:3)
Block(9,33,6,LEAVES:3)
Block(10,33,6,LEAVES:3)
Block(-8,33,7,LEAVES:3)
Block(-7,33,7,LEAVES:3)
Block(-6,33,7,LEAVES:3)
Block(-5,33,7,LEAVES:3)
Block(-4,33,7,LEAVES:3)
Block(-3,33,7,LEAVES:3)
Block(-2,33,7,LEAVES:3)
Block(2,33,7,LEAVES:3)
Block(3,33,7,LEAVES:3)
Block(4,33,7,LEAVES:3)
Block(5,33,7,LOG:3)
Block(6,33,7,LOG:3)
Block(7,33,7,LEAVES:3)
Block(8,33,7,LEAVES:3)
Block(9,33,7,LEAVES:3)
Block(10,33,7,LEAVES:3)
Block(-6,33,8,LEAVES:3)
Block(-5,33,8,LEAVES:3)
Block(-4,33,8,LEAVES:3)
Block(-3,33,8,LEAVES:3)
Block(-2,33,8,LEAVES:3)
Block(-1,33,8,LEAVES:3)
Block(4,33,8,LEAVES:3)
Block(5,33,8,LOG:3)
Block(7,33,8,LEAVES:3)
Block(8,33,8,LEAVES:3)
Block(9,33,8,LEAVES:3)
Block(-5,33,9,LEAVES:3)
Block(-3,33,9,LEAVES:3)
Block(-2,33,9,LEAVES:3)
Block(-1,33,9,LEAVES:3)
Block(0,33,9,LEAVES:3)
Block(1,33,9,LOG:3)
Block(2,33,9,LEAVES:3)
Block(3,33,9,LEAVES:3)
Block(4,33,9,LEAVES:3)
Block(5,33,9,LEAVES:3)
Block(6,33,9,LEAVES:3)
Block(7,33,9,LEAVES:3)
Block(8,33,9,LEAVES:3)
Block(-3,33,10,LEAVES:3)
Block(-2,33,10,LEAVES:3)
Block(-1,33,10,LEAVES:3)
Block(0,33,10,LEAVES:3)
Block(1,33,10,LEAVES:3)
Block(2,33,10,LEAVES:3)
Block(3,33,10,LEAVES:3)
Block(4,33,10,LEAVES:3)
Block(5,33,10,LEAVES:3)
Block(6,33,10,LEAVES:3)
Block(7,33,10,LEAVES:3)
Block(-1,33,11,LEAVES:3)
Block(0,33,11,LEAVES:3)
Block(1,33,11,LEAVES:3)
Block(2,33,11,LEAVES:3)
Block(3,33,11,LEAVES:3)
Block(4,33,11,LEAVES:3)
Block(5,33,11,LEAVES:3)
Block(3,33,12,LEAVES:3)
Block(-3,34,-13,LEAVES:3)
Block(-2,34,-13,LEAVES:3)
Block(-1,34,-13,LEAVES:3)
Block(0,34,-13,LEAVES:3)
Block(1,34,-13,LEAVES:3)
Block(2,34,-13,LEAVES:3)
Block(-5,34,-12,LEAVES:3)
Block(-4,34,-12,LEAVES:3)
Block(-3,34,-12,LEAVES:3)
Block(-2,34,-12,LEAVES:3)
Block(-1,34,-12,LEAVES:3)
Block(0,34,-12,LEAVES:3)
Block(1,34,-12,LEAVES:3)
Block(2,34,-12,LEAVES:3)
Block(3,34,-12,LEAVES:3)
Block(4,34,-12,LEAVES:3)
Block(5,34,-12,LEAVES:3)
Block(6,34,-12,LEAVES:3)
Block(-5,34,-11,LEAVES:3)
Block(-4,34,-11,LEAVES:3)
Block(-3,34,-11,LEAVES:3)
Block(-2,34,-11,LEAVES:3)
Block(-1,34,-11,LOG:3)
Block(0,34,-11,LEAVES:3)
Block(1,34,-11,LEAVES:3)
Block(2,34,-11,LEAVES:3)
Block(3,34,-11,LEAVES:3)
Block(4,34,-11,LEAVES:3)
Block(5,34,-11,LEAVES:3)
Block(6,34,-11,LEAVES:3)
Block(8,34,-11,LEAVES:3)
Block(-7,34,-10,LEAVES:3)
Block(-6,34,-10,LEAVES:3)
Block(-5,34,-10,LEAVES:3)
Block(-4,34,-10,LEAVES:3)
Block(-3,34,-10,LEAVES:3)
Block(-2,34,-10,LEAVES:3)
Block(-1,34,-10,LOG:3)
Block(0,34,-10,LEAVES:3)
Block(1,34,-10,LEAVES:3)
Block(2,34,-10,LEAVES:3)
Block(3,34,-10,LEAVES:3)
Block(4,34,-10,LEAVES:3)
Block(5,34,-10,LEAVES:3)
Block(6,34,-10,LEAVES:3)
Block(7,34,-10,LEAVES:3)
Block(-7,34,-9,LEAVES:3)
Block(-6,34,-9,LEAVES:3)
Block(-5,34,-9,LEAVES:3)
Block(-4,34,-9,LEAVES:3)
Block(-3,34,-9,LEAVES:3)
Block(-2,34,-9,LOG:3)
Block(-1,34,-9,LEAVES:3)
Block(2,34,-9,LEAVES:3)
Block(5,34,-9,LEAVES:3)
Block(6,34,-9,LEAVES:3)
Block(7,34,-9,LEAVES:3)
Block(9,34,-9,LEAVES:3)
Block(-9,34,-8,LEAVES:3)
Block(-8,34,-8,LEAVES:3)
Block(-7,34,-8,LEAVES:3)
Block(-6,34,-8,LEAVES:3)
Block(-2,34,-8,LEAVES:3)
Block(-1,34,-8,LOG:3)
Block(0,34,-8,LOG:3)
Block(6,34,-8,LEAVES:3)
Block(7,34,-8,LEAVES:3)
Block(8,34,-8,LEAVES:3)
Block(9,34,-8,LEAVES:3)
Block(10,34,-8,LEAVES:3)
Block(11,34,-8,LEAVES:3)
Block(-9,34,-7,LEAVES:3)
Block(-8,34,-7,LEAVES:3)
Block(-7,34,-7,LEAVES:3)
Block(-6,34,-7,LEAVES:3)
Block(-5,34,-7,LEAVES:3)
Block(-2,34,-7,LOG:3)
Block(-1,34,-7,LEAVES:3)
Block(0,34,-7,LEAVES:3)
Block(1,34,-7,LEAVES:3)
Block(3,34,-7,LEAVES:3)
Block(4,34,-7,LOG:3)
Block(5,34,-7,LOG:3)
Block(6,34,-7,LEAVES:3)
Block(7,34,-7,LEAVES:3)
Block(8,34,-7,LEAVES:3)
Block(9,34,-7,LEAVES:3)
Block(10,34,-7,LEAVES:3)
Block(11,34,-7,LEAVES:3)
Block(-10,34,-6,LEAVES:3)
Block(-9,34,-6,LEAVES:3)
Block(-8,34,-6,LEAVES:3)
Block(-7,34,-6,LEAVES:3)
Block(-6,34,-6,LEAVES:3)
Block(-3,34,-6,LOG:3)
Block(-2,34,-6,LEAVES:3)
Block(-1,34,-6,LEAVES:3)
Block(0,34,-6,LEAVES:3)
Block(1,34,-6,LEAVES:3)
Block(2,34,-6,LOG:3)
Block(3,34,-6,LOG:3)
Block(4,34,-6,LOG:3)
Block(5,34,-6,LEAVES:3)
Block(8,34,-6,LEAVES:3)
Block(9,34,-6,LEAVES:3)
Block(10,34,-6,LEAVES:3)
Block(11,34,-6,LEAVES:3)
Block(-10,34,-5,LEAVES:3)
Block(-9,34,-5,LEAVES:3)
Block(-8,34,-5,LEAVES:3)
Block(-7,34,-5,LEAVES:3)
Block(-6,34,-5,LEAVES:3)
Block(-3,34,-5,LEAVES:3)
Block(-2,34,-5,LEAVES:3)
Block(-1,34,-5,LEAVES:3)
Block(0,34,-5,LEAVES:3)
Block(1,34,-5,LEAVES:3)
Block(2,34,-5,LOG:3)
Block(3,34,-5,LEAVES:3)
Block(4,34,-5,LEAVES:3)
Block(8,34,-5,LEAVES:3)
Block(9,34,-5,LEAVES:3)
Block(10,34,-5,LEAVES:3)
Block(11,34,-5,LEAVES:3)
Block(-10,34,-4,LEAVES:3)
Block(-9,34,-4,LEAVES:3)
Block(-8,34,-4,LEAVES:3)
Block(-7,34,-4,LEAVES:3)
Block(-3,34,-4,LEAVES:3)
Block(-2,34,-4,LEAVES:3)
Block(-1,34,-4,LEAVES:3)
Block(0,34,-4,LEAVES:3)
Block(1,34,-4,LEAVES:3)
Block(2,34,-4,LEAVES:3)
Block(3,34,-4,LEAVES:3)
Block(4,34,-4,LEAVES:3)
Block(5,34,-4,LEAVES:3)
Block(9,34,-4,LEAVES:3)
Block(10,34,-4,LEAVES:3)
Block(11,34,-4,LEAVES:3)
Block(12,34,-4,LEAVES:3)
Block(13,34,-4,LEAVES:3)
Block(-11,34,-3,LEAVES:3)
Block(-10,34,-3,LEAVES:3)
Block(-9,34,-3,LEAVES:3)
Block(-8,34,-3,LEAVES:3)
Block(-3,34,-3,LOG:3)
Block(-2,34,-3,LEAVES:3)
Block(-1,34,-3,LEAVES:3)
Block(0,34,-3,LEAVES:3)
Block(1,34,-3,LEAVES:3)
Block(2,34,-3,LEAVES:3)
Block(3,34,-3,LEAVES:3)
Block(4,34,-3,LEAVES:3)
Block(5,34,-3,LEAVES:3)
Block(6,34,-3,LEAVES:3)
Block(10,34,-3,LEAVES:3)
Block(11,34,-3,LEAVES:3)
Block(12,34,-3,LEAVES:3)
Block(13,34,-3,LEAVES:3)
Block(-11,34,-2,LEAVES:3)
Block(-10,34,-2,LEAVES:3)
Block(-9,34,-2,LEAVES:3)
Block(-8,34,-2,LEAVES:3)
Block(-4,34,-2,LEAVES:3)
Block(-3,34,-2,LEAVES:3)
Block(-2,34,-2,LEAVES:3)
Block(-1,34,-2,LEAVES:3)
Block(0,34,-2,LEAVES:3)
Block(1,34,-2,LEAVES:3)
Block(2,34,-2,LEAVES:3)
Block(3,34,-2,LEAVES:3)
Block(4,34,-2,LEAVES:3)
Block(5,34,-2,LEAVES:3)
Block(6,34,-2,LEAVES:3)
Block(8,34,-2,LEAVES:3)
Block(9,34,-2,LEAVES:3)
Block(11,34,-2,LEAVES:3)
Block(12,34,-2,LEAVES:3)
Block(13,34,-2,LEAVES:3)
Block(-11,34,-1,LEAVES:3)
Block(-10,34,-1,LEAVES:3)
Block(-9,34,-1,LEAVES:3)
Block(-5,34,-1,LOG:3)
Block(-4,34,-1,LOG:3)
Block(-3,34,-1,LEAVES:3)
Block(-2,34,-1,LEAVES:3)
Block(-1,34,-1,LEAVES:3)
Block(0,34,-1,LEAVES:3)
Block(1,34,-1,LEAVES:3)
Block(2,34,-1,LEAVES:3)
Block(3,34,-1,LEAVES:3)
Block(4,34,-1,LEAVES:3)
Block(5,34,-1,LEAVES:3)
Block(6,34,-1,LEAVES:3)
Block(7,34,-1,LEAVES:3)
Block(8,34,-1,LEAVES:3)
Block(9,34,-1,LEAVES:3)
Block(10,34,-1,LEAVES:3)
Block(11,34,-1,LEAVES:3)
Block(12,34,-1,LEAVES:3)
Block(13,34,-1,LEAVES:3)
Block(-11,34,0,LEAVES:3)
Block(-10,34,0,LEAVES:3)
Block(-9,34,0,LEAVES:3)
Block(-8,34,0,LEAVES:3)
Block(-7,34,0,LEAVES:3)
Block(-6,34,0,LOG:3)
Block(-5,34,0,LOG:3)
Block(-2,34,0,LEAVES:3)
Block(-1,34,0,LEAVES:3)
Block(0,34,0,LEAVES:3)
Block(1,34,0,LEAVES:3)
Block(2,34,0,LEAVES:3)
Block(3,34,0,LEAVES:3)
Block(4,34,0,LEAVES:3)
Block(5,34,0,LEAVES:3)
Block(6,34,0,LEAVES:3)
Block(7,34,0,LEAVES:3)
Block(8,34,0,LEAVES:3)
Block(9,34,0,LEAVES:3)
Block(10,34,0,LEAVES:3)
Block(11,34,0,LEAVES:3)
Block(12,34,0,LEAVES:3)
Block(13,34,0,LEAVES:3)
Block(-11,34,1,LEAVES:3)
Block(-10,34,1,LEAVES:3)
Block(-9,34,1,LEAVES:3)
Block(-8,34,1,LEAVES:3)
Block(-6,34,1,LOG:3)
Block(-3,34,1,LEAVES:3)
Block(-2,34,1,LEAVES:3)
Block(-1,34,1,LEAVES:3)
Block(0,34,1,LEAVES:3)
Block(1,34,1,LEAVES:3)
Block(2,34,1,LEAVES:3)
Block(3,34,1,LEAVES:3)
Block(4,34,1,LEAVES:3)
Block(5,34,1,LEAVES:3)
Block(6,34,1,LEAVES:3)
Block(7,34,1,LEAVES:3)
Block(8,34,1,LEAVES:3)
Block(9,34,1,LEAVES:3)
Block(10,34,1,LEAVES:3)
Block(11,34,1,LEAVES:3)
Block(12,34,1,LEAVES:3)
Block(13,34,1,LEAVES:3)
Block(-11,34,2,LEAVES:3)
Block(-10,34,2,LEAVES:3)
Block(-9,34,2,LEAVES:3)
Block(-8,34,2,LEAVES:3)
Block(-5,34,2,LEAVES:3)
Block(-4,34,2,LEAVES:3)
Block(-3,34,2,LEAVES:3)
Block(-2,34,2,LEAVES:3)
Block(-1,34,2,LEAVES:3)
Block(1,34,2,LEAVES:3)
Block(2,34,2,LEAVES:3)
Block(3,34,2,LEAVES:3)
Block(4,34,2,LEAVES:3)
Block(5,34,2,LEAVES:3)
Block(6,34,2,LEAVES:3)
Block(7,34,2,LEAVES:3)
Block(8,34,2,LEAVES:3)
Block(9,34,2,LEAVES:3)
Block(10,34,2,LEAVES:3)
Block(11,34,2,LEAVES:3)
Block(12,34,2,LEAVES:3)
Block(13,34,2,LEAVES:3)
Block(-10,34,3,LEAVES:3)
Block(-9,34,3,LEAVES:3)
Block(-8,34,3,LEAVES:3)
Block(-6,34,3,LEAVES:3)
Block(-5,34,3,LEAVES:3)
Block(-4,34,3,LEAVES:3)
Block(-3,34,3,LEAVES:3)
Block(-2,34,3,LEAVES:3)
Block(-1,34,3,LEAVES:3)
Block(0,34,3,LEAVES:3)
Block(1,34,3,LEAVES:3)
Block(2,34,3,LEAVES:3)
Block(3,34,3,LEAVES:3)
Block(4,34,3,LEAVES:3)
Block(5,34,3,LEAVES:3)
Block(7,34,3,LEAVES:3)
Block(8,34,3,LEAVES:3)
Block(9,34,3,LEAVES:3)
Block(10,34,3,LEAVES:3)
Block(11,34,3,LEAVES:3)
Block(12,34,3,LEAVES:3)
Block(13,34,3,LEAVES:3)
Block(-10,34,4,LEAVES:3)
Block(-9,34,4,LEAVES:3)
Block(-8,34,4,LEAVES:3)
Block(-7,34,4,LEAVES:3)
Block(-6,34,4,LEAVES:3)
Block(-5,34,4,LEAVES:3)
Block(-4,34,4,LEAVES:3)
Block(-3,34,4,LEAVES:3)
Block(-2,34,4,LEAVES:3)
Block(-1,34,4,LEAVES:3)
Block(0,34,4,LEAVES:3)
Block(1,34,4,LEAVES:3)
Block(3,34,4,LEAVES:3)
Block(4,34,4,LEAVES:3)
Block(5,34,4,LEAVES:3)
Block(6,34,4,LEAVES:3)
Block(7,34,4,LEAVES:3)
Block(9,34,4,LEAVES:3)
Block(10,34,4,LEAVES:3)
Block(11,34,4,LEAVES:3)
Block(12,34,4,LEAVES:3)
Block(-9,34,5,LEAVES:3)
Block(-8,34,5,LEAVES:3)
Block(-7,34,5,LEAVES:3)
Block(-6,34,5,LEAVES:3)
Block(-5,34,5,LEAVES:3)
Block(-4,34,5,LEAVES:3)
Block(-3,34,5,LEAVES:3)
Block(-2,34,5,LEAVES:3)
Block(-1,34,5,LEAVES:3)
Block(0,34,5,LEAVES:3)
Block(1,34,5,LEAVES:3)
Block(3,34,5,LEAVES:3)
Block(4,34,5,LEAVES:3)
Block(5,34,5,LEAVES:3)
Block(6,34,5,LEAVES:3)
Block(7,34,5,LEAVES:3)
Block(8,34,5,LEAVES:3)
Block(9,34,5,LEAVES:3)
Block(10,34,5,LEAVES:3)
Block(11,34,5,LEAVES:3)
Block(12,34,5,LEAVES:3)
Block(-9,34,6,LEAVES:3)
Block(-8,34,6,LEAVES:3)
Block(-7,34,6,LEAVES:3)
Block(-6,34,6,LEAVES:3)
Block(-5,34,6,LEAVES:3)
Block(-4,34,6,LEAVES:3)
Block(-3,34,6,LEAVES:3)
Block(-2,34,6,LEAVES:3)
Block(-1,34,6,LEAVES:3)
Block(0,34,6,LEAVES:3)
Block(1,34,6,LEAVES:3)
Block(3,34,6,LEAVES:3)
Block(4,34,6,LEAVES:3)
Block(5,34,6,LEAVES:3)
Block(7,34,6,LEAVES:3)
Block(9,34,6,LEAVES:3)
Block(10,34,6,LEAVES:3)
Block(-9,34,7,LEAVES:3)
Block(-8,34,7,LEAVES:3)
Block(-7,34,7,LEAVES:3)
Block(-6,34,7,LEAVES:3)
Block(-5,34,7,LEAVES:3)
Block(-4,34,7,LEAVES:3)
Block(-3,34,7,LEAVES:3)
Block(-2,34,7,LEAVES:3)
Block(-1,34,7,LEAVES:3)
Block(0,34,7,LEAVES:3)
Block(1,34,7,LEAVES:3)
Block(2,34,7,LEAVES:3)
Block(3,34,7,LEAVES:3)
Block(4,34,7,LEAVES:3)
Block(5,34,7,LEAVES:3)
Block(6,34,7,LEAVES:3)
Block(7,34,7,LEAVES:3)
Block(8,34,7,LEAVES:3)
Block(9,34,7,LEAVES:3)
Block(10,34,7,LEAVES:3)
Block(-7,34,8,LEAVES:3)
Block(-6,34,8,LEAVES:3)
Block(-5,34,8,LEAVES:3)
Block(-4,34,8,LEAVES:3)
Block(-3,34,8,LEAVES:3)
Block(-2,34,8,LEAVES:3)
Block(-1,34,8,LEAVES:3)
Block(0,34,8,LEAVES:3)
Block(1,34,8,LEAVES:3)
Block(2,34,8,LEAVES:3)
Block(3,34,8,LEAVES:3)
Block(4,34,8,LEAVES:3)
Block(5,34,8,LEAVES:3)
Block(6,34,8,LEAVES:3)
Block(7,34,8,LEAVES:3)
Block(8,34,8,LEAVES:3)
Block(9,34,8,LEAVES:3)
Block(-5,34,9,LEAVES:3)
Block(-4,34,9,LEAVES:3)
Block(-2,34,9,LEAVES:3)
Block(-1,34,9,LEAVES:3)
Block(0,34,9,LEAVES:3)
Block(1,34,9,LEAVES:3)
Block(2,34,9,LEAVES:3)
Block(3,34,9,LEAVES:3)
Block(4,34,9,LEAVES:3)
Block(5,34,9,LEAVES:3)
Block(6,34,9,LEAVES:3)
Block(7,34,9,LEAVES:3)
Block(-2,34,10,LEAVES:3)
Block(-1,34,10,LEAVES:3)
Block(0,34,10,LEAVES:3)
Block(1,34,10,LEAVES:3)
Block(2,34,10,LEAVES:3)
Block(3,34,10,LEAVES:3)
Block(4,34,10,LEAVES:3)
Block(5,34,10,LEAVES:3)
Block(-1,34,11,LEAVES:3)
Block(0,34,11,LEAVES:3)
Block(1,34,11,LEAVES:3)
Block(2,34,11,LEAVES:3)
Block(3,34,11,LEAVES:3)
Block(4,34,11,LEAVES:3)
Block(-1,35,-13,LEAVES:3)
Block(0,35,-13,LEAVES:3)
Block(1,35,-13,LEAVES:3)
Block(-3,35,-12,LEAVES:3)
Block(-2,35,-12,LEAVES:3)
Block(-1,35,-12,LEAVES:3)
Block(0,35,-12,LEAVES:3)
Block(1,35,-12,LEAVES:3)
Block(2,35,-12,LEAVES:3)
Block(4,35,-12,LEAVES:3)
Block(-5,35,-11,LEAVES:3)
Block(-4,35,-11,LEAVES:3)
Block(-3,35,-11,LEAVES:3)
Block(-2,35,-11,LEAVES:3)
Block(-1,35,-11,LEAVES:3)
Block(0,35,-11,LEAVES:3)
Block(1,35,-11,LEAVES:3)
Block(2,35,-11,LEAVES:3)
Block(3,35,-11,LEAVES:3)
Block(4,35,-11,LEAVES:3)
Block(5,35,-11,LEAVES:3)
Block(-6,35,-10,LEAVES:3)
Block(-5,35,-10,LEAVES:3)
Block(-4,35,-10,LEAVES:3)
Block(-3,35,-10,LEAVES:3)
Block(-2,35,-10,LEAVES:3)
Block(-1,35,-10,LEAVES:3)
Block(0,35,-10,LEAVES:3)
Block(1,35,-10,LEAVES:3)
Block(2,35,-10,LEAVES:3)
Block(3,35,-10,LEAVES:3)
Block(4,35,-10,LEAVES:3)
Block(5,35,-10,LEAVES:3)
Block(6,35,-10,LEAVES:3)
Block(7,35,-10,LEAVES:3)
Block(-7,35,-9,LEAVES:3)
Block(-6,35,-9,LEAVES:3)
Block(-5,35,-9,LEAVES:3)
Block(-4,35,-9,LEAVES:3)
Block(-3,35,-9,LEAVES:3)
Block(-2,35,-9,LEAVES:3)
Block(-1,35,-9,LEAVES:3)
Block(0,35,-9,LEAVES:3)
Block(2,35,-9,LEAVES:3)
Block(3,35,-9,LEAVES:3)
Block(4,35,-9,LEAVES:3)
Block(5,35,-9,LEAVES:3)
Block(6,35,-9,LEAVES:3)
Block(7,35,-9,LEAVES:3)
Block(8,35,-9,LEAVES:3)
Block(-7,35,-8,LEAVES:3)
Block(-6,35,-8,LEAVES:3)
Block(-5,35,-8,LEAVES:3)
Block(-4,35,-8,LEAVES:3)
Block(-3,35,-8,LEAVES:3)
Block(-2,35,-8,LEAVES:3)
Block(-1,35,-8,LEAVES:3)
Block(0,35,-8,LEAVES:3)
Block(1,35,-8,LEAVES:3)
Block(2,35,-8,LEAVES:3)
Block(4,35,-8,LEAVES:3)
Block(5,35,-8,LEAVES:3)
Block(7,35,-8,LEAVES:3)
Block(8,35,-8,LEAVES:3)
Block(9,35,-8,LEAVES:3)
Block(-8,35,-7,LEAVES:3)
Block(-7,35,-7,LEAVES:3)
Block(-6,35,-7,LEAVES:3)
