
#######################################################################
# +-----------------------------------------------------------------+ #
# |                            BO3 object                           | #
# +-----------------------------------------------------------------+ #
#######################################################################

Author: MC_Pitman

Description: No description given

Version: 3

SettingsMode: WriteWithoutComments


#######################################################################
# +-----------------------------------------------------------------+ #
# |                          Main settings                          | #
# +-----------------------------------------------------------------+ #
#######################################################################

Tree: true

Frequency: 1

Rarity: 1.0

RotateRandomly: true

SpawnHeight: highestSolidBlock

SpawnHeightOffset: 0

SpawnHeightVariance: 0

##############################
# Height Limits for the BO3. #
##############################

MinHeight: 62

MaxHeight: 63

######################
# Extrusion settings #
######################

ExtrudeMode: None

ExtrudeThroughBlocks: AIR

MaxBranchDepth: 10

ExcludedBiomes: All


#######################################################################
# +-----------------------------------------------------------------+ #
# |                      Source block settings                      | #
# +-----------------------------------------------------------------+ #
#######################################################################

SourceBlocks: STONE:1,STONE:3,STONE:5,DIRT:1,DIRT:0,SAND:0,GRASS:0,DIRT:2,STATIONARY_WATER:0,HARD_CLAY,STAINED_CLAY:0,CLAY,SANDSTONE:0,SAND:1,AIR,STONE:0,GRAVEL,LONG_GRASS:0,LONG_GRASS:1,LONG_GRASS:2,DEAD_BUSH,YELLOW_FLOWER:0,RED_ROSE:0,BROWN_MUSHROOM,RED_MUSHROOM

MaxPercentageOutsideSourceBlock: 0

OutsideSourceBlock: placeAnyway

DoReplaceBlocks: true

IsOTGPlus: false


#######################################################################
# +-----------------------------------------------------------------+ #
# |                              Blocks                             | #
# +-----------------------------------------------------------------+ #
#######################################################################

Block(-6,-1,-2,LOG:1)
Block(-6,-1,0,LOG:5)
Block(-6,-1,1,DIRT:1)
Block(-5,-1,-1,LOG:9)
Block(-5,-1,0,LOG:13)
Block(-5,-1,1,LOG:13)
Block(-5,-1,2,DIRT:0)
Block(-5,-1,3,DIRT:1)
Block(-5,0,1,LOG:13)
Block(-5,0,2,GRASS:0)
Block(-4,-1,-4,LOG:1)
Block(-4,-1,-2,DIRT:1)
Block(-4,-1,-1,GRASS:0)
Block(-4,-1,0,DIRT:0)
Block(-4,-1,1,LOG:13)
Block(-4,-1,2,LOG:13)
Block(-4,-1,3,LOG:1)
Block(-4,-1,4,GRASS:0)
Block(-4,0,0,DIRT:1)
Block(-4,0,1,LOG:13)
Block(-4,0,2,LOG:13)
Block(-4,0,3,DIRT:1)
Block(-4,0,4,LONG_GRASS:1)
Block(-4,1,1,LOG:13)
Block(-4,1,2,GRASS:0)
Block(-3,-1,-3,LOG:5)
Block(-3,-1,-2,GRASS:0)
Block(-3,-1,-1,LOG:13)
Block(-3,-1,2,LOG:13)
Block(-3,-1,3,LOG:9)
Block(-3,-1,4,LOG:9)
Block(-3,0,0,LOG:13)
Block(-3,0,1,LOG:13)
Block(-3,0,2,LOG:13)
Block(-3,0,3,LOG:13)
Block(-3,1,0,LOG:13)
Block(-3,1,1,LOG:13)
Block(-3,1,2,LOG:13)
Block(-3,2,1,LOG:13)
Block(-3,2,2,LOG:13)
Block(-3,3,1,LOG:13)
Block(-3,3,2,LOG:13)
Block(-3,4,1,LOG:13)
Block(-3,5,1,LOG:1)
Block(-2,-1,-5,LOG:13)
Block(-2,-1,-4,DIRT:1)
Block(-2,-1,-3,LOG:5)
Block(-2,-1,-2,LOG:13)
Block(-2,-1,3,LOG:13)
Block(-2,-1,4,LOG:13)
Block(-2,-1,6,LOG:13)
Block(-2,-1,7,LOG:9)
Block(-2,0,-2,GRASS:0)
Block(-2,0,-1,GRASS:0)
Block(-2,0,0,LOG:13)
Block(-2,0,2,LOG:13)
Block(-2,0,3,LOG:13)
Block(-2,0,4,LOG:1)
Block(-2,1,0,LOG:1)
Block(-2,1,1,LOG:13)
Block(-2,1,2,LOG:13)
Block(-2,1,3,LOG:13)
Block(-2,2,2,LOG:13)
Block(-2,2,3,LOG:1)
Block(-2,3,1,LOG:13)
Block(-2,3,2,LOG:13)
Block(-2,3,3,LOG:1)
Block(-2,4,1,LOG:13)
Block(-2,4,2,LOG:13)
Block(-2,4,3,LOG:1)
Block(-2,5,1,LOG:1)
Block(-2,5,2,LOG:13)
Block(-2,6,1,LOG:1)
Block(-2,6,2,LOG:13)
Block(-2,7,2,LOG:1)
Block(-1,-1,-4,LOG:9)
Block(-1,-1,-3,LOG:13)
Block(-1,-1,5,LOG:13)
Block(-1,-1,6,LOG:13)
Block(-1,0,-4,DIRT:1)
Block(-1,0,-3,LOG:13)
Block(-1,0,-2,LOG:13)
Block(-1,0,-1,GRASS:0)
Block(-1,0,0,DIRT:1)
Block(-1,0,1,DIRT:1)
Block(-1,0,2,LOG:1)
Block(-1,0,3,LOG:13)
Block(-1,0,4,LOG:13)
Block(-1,1,1,GRASS:0)
Block(-1,1,2,DIRT:0)
Block(-1,1,3,LOG:13)
Block(-1,1,4,LOG:13)
Block(-1,2,1,LONG_GRASS:1)
Block(-1,2,2,LOG:13)
Block(-1,2,3,LOG:13)
Block(-1,2,4,LOG:13)
Block(-1,3,2,LOG:13)
Block(-1,3,3,LOG:13)
Block(-1,3,4,LOG:13)
Block(-1,4,1,LOG:13)
Block(-1,4,2,LOG:13)
Block(-1,4,3,LOG:13)
Block(-1,4,4,LOG:13)
Block(-1,5,1,LOG:13)
Block(-1,5,2,LOG:13)
Block(-1,5,3,LOG:13)
Block(-1,5,4,LOG:1)
Block(-1,6,2,LOG:13)
Block(-1,6,3,LOG:13)
Block(-1,7,3,LOG:13)
Block(-1,8,3,LOG:1)
Block(0,-1,-5,DIRT:1)
Block(0,-1,-4,LOG:13)
Block(0,-1,-3,LOG:13)
Block(0,-1,5,LOG:5)
Block(0,-1,6,LOG:13)
Block(0,-1,7,LOG:13)
Block(0,0,-4,LOG:13)
Block(0,0,-3,LOG:13)
Block(0,0,-2,LOG:13)
Block(0,0,-1,LOG:9)
Block(0,0,0,LOG:1)
Block(0,0,1,LOG:1)
Block(0,0,4,LOG:13)
Block(0,0,5,LOG:13)
Block(0,0,6,LOG:13)
Block(0,1,-3,LOG:13)
Block(0,1,-2,LOG:13)
Block(0,1,0,DIRT:1)
Block(0,1,1,GRASS:0)
Block(0,1,2,LOG:13)
Block(0,1,3,LOG:13)
Block(0,1,4,LOG:13)
Block(0,1,5,LOG:13)
Block(0,2,-3,LOG:13)
Block(0,2,-2,LOG:13)
Block(0,2,1,LONG_GRASS:1)
Block(0,2,2,LOG:13)
Block(0,2,3,LOG:13)
Block(0,2,4,LOG:13)
Block(0,2,5,LOG:13)
Block(0,3,-2,LOG:13)
Block(0,3,3,LOG:13)
Block(0,3,4,LOG:13)
Block(0,4,-2,LOG:13)
Block(0,4,2,LOG:13)
Block(0,4,3,LOG:13)
Block(0,4,4,LOG:13)
Block(0,5,-2,LOG:1)
Block(0,5,2,LOG:13)
Block(0,5,3,LOG:13)
Block(0,5,4,LOG:13)
Block(0,6,2,LOG:13)
Block(0,6,3,LOG:13)
Block(0,6,4,LOG:13)
Block(0,7,2,LOG:13)
Block(0,7,3,LOG:13)
Block(1,-1,-5,LOG:13)
Block(1,-1,-3,LOG:13)
Block(1,-1,-2,LOG:1)
Block(1,-1,-1,LOG:13)
Block(1,-1,5,LOG:13)
Block(1,-1,6,LOG:13)
Block(1,0,-4,LOG:13)
Block(1,0,-3,LOG:13)
Block(1,0,-2,LOG:1)
Block(1,0,-1,LOG:9)
Block(1,0,0,LOG:9)
Block(1,0,1,LOG:1)
Block(1,0,2,DIRT:1)
Block(1,0,3,DIRT:1)
Block(1,0,4,LOG:13)
Block(1,0,5,LOG:13)
Block(1,1,-3,LOG:13)
Block(1,1,-2,LOG:1)
Block(1,1,-1,GRASS:0)
Block(1,1,0,LOG:1)
Block(1,1,1,LOG:1)
Block(1,1,2,DIRT:0)
Block(1,1,3,LOG:13)
Block(1,1,4,LOG:13)
Block(1,2,-3,LOG:13)
Block(1,2,-2,GRASS:0)
Block(1,2,-1,LONG_GRASS:1)
Block(1,2,1,GRASS:0)
Block(1,2,2,GRASS:0)
Block(1,2,3,LOG:13)
Block(1,2,4,LOG:13)
Block(1,3,-3,LOG:13)
Block(1,3,2,LONG_GRASS:1)
Block(1,3,3,LOG:13)
Block(1,3,4,LOG:13)
Block(1,4,-3,LOG:13)
Block(1,4,-2,LOG:1)
Block(1,4,3,LOG:13)
Block(1,4,4,LOG:13)
Block(1,5,-3,LOG:13)
Block(1,5,-2,LOG:13)
Block(1,5,3,LOG:13)
Block(1,5,4,LOG:13)
Block(1,6,-3,LOG:1)
Block(1,6,-2,LOG:13)
Block(1,6,3,LOG:13)
Block(1,6,4,LOG:13)
Block(1,7,3,LOG:13)
Block(1,7,4,LOG:13)
Block(1,8,3,LOG:13)
Block(1,9,3,LOG:1)
Block(2,-1,-4,LOG:13)
Block(2,-1,-3,LOG:13)
Block(2,-1,-2,LOG:13)
Block(2,-1,-1,LOG:1)
Block(2,-1,0,LOG:13)
Block(2,-1,1,LOG:1)
Block(2,-1,2,LOG:13)
Block(2,-1,5,LOG:1)
Block(2,0,-3,LOG:13)
Block(2,0,-2,LOG:13)
Block(2,0,-1,LOG:1)
Block(2,0,0,LOG:9)
Block(2,0,1,LOG:1)
Block(2,0,2,LOG:13)
Block(2,0,3,LOG:13)
Block(2,0,4,LOG:13)
Block(2,1,-3,LOG:13)
Block(2,1,-2,LOG:13)
Block(2,1,-1,LOG:5)
Block(2,1,0,LOG:1)
Block(2,1,1,LOG:1)
Block(2,1,3,LOG:13)
Block(2,2,-2,LOG:13)
Block(2,2,-1,LOG:1)
Block(2,2,1,LOG:1)
Block(2,2,2,LOG:13)
Block(2,2,3,LOG:13)
Block(2,3,-2,LOG:13)
Block(2,3,-1,LOG:1)
Block(2,3,1,LOG:1)
Block(2,3,2,LOG:13)
Block(2,3,3,LOG:13)
Block(2,4,-2,LOG:13)
Block(2,4,1,LOG:1)
Block(2,4,2,LOG:13)
Block(2,4,3,LOG:13)
Block(2,5,-2,LOG:13)
Block(2,5,2,LOG:13)
Block(2,5,3,LOG:13)
Block(2,6,-2,LOG:13)
Block(2,6,2,LOG:13)
Block(2,6,3,LOG:13)
Block(2,7,-2,LOG:13)
Block(2,7,2,LOG:1)
Block(2,7,3,LOG:13)
Block(2,8,-2,LOG:13)
Block(2,8,3,LOG:13)
Block(2,9,-2,LOG:1)
Block(3,-1,-5,LOG:9)
Block(3,-1,-4,LOG:9)
Block(3,-1,-3,LOG:13)
Block(3,-1,-2,LOG:13)
Block(3,-1,-1,LOG:13)
Block(3,-1,0,LOG:5)
Block(3,-1,1,LOG:13)
Block(3,-1,2,LOG:13)
Block(3,-1,3,LOG:13)
Block(3,-1,4,LOG:13)
Block(3,0,-3,LOG:13)
Block(3,0,-2,LOG:13)
Block(3,0,-1,LOG:13)
Block(3,0,0,LOG:1)
Block(3,0,1,LOG:9)
Block(3,0,2,LOG:13)
Block(3,0,3,LOG:13)
Block(3,1,-2,LOG:13)
Block(3,1,-1,LOG:13)
Block(3,1,0,LOG:1)
Block(3,1,1,LOG:1)
Block(3,1,2,LOG:13)
Block(3,1,3,LOG:13)
Block(3,2,-2,LOG:13)
Block(3,2,-1,LOG:13)
Block(3,2,0,LOG:1)
Block(3,2,1,LOG:1)
Block(3,2,2,LOG:13)
Block(3,3,-1,LOG:13)
Block(3,3,0,LOG:1)
Block(3,3,1,LOG:1)
Block(3,3,2,LOG:13)
Block(3,4,-1,LOG:13)
Block(3,4,0,LOG:13)
Block(3,4,1,LOG:13)
Block(3,4,2,LOG:13)
Block(3,5,-1,LOG:13)
Block(3,5,0,LOG:13)
Block(3,5,1,LOG:13)
Block(3,6,-1,LOG:1)
Block(3,6,0,LOG:13)
Block(3,6,1,LOG:13)
Block(3,7,0,LOG:1)
Block(3,7,1,LOG:13)
Block(3,8,1,LOG:13)
Block(3,9,1,LOG:1)
Block(4,-1,-3,LOG:5)
Block(4,-1,-2,LOG:13)
Block(4,-1,-1,LOG:13)
Block(4,-1,0,LOG:13)
Block(4,-1,1,LOG:13)
Block(4,-1,2,LOG:1)
Block(4,0,-2,LOG:13)
Block(4,0,-1,LOG:13)
Block(4,0,0,LOG:13)
Block(4,0,1,LOG:13)
Block(4,0,2,LOG:13)
Block(4,1,-1,LOG:13)
Block(4,1,0,LOG:13)
Block(4,1,1,LOG:13)
Block(4,2,0,LOG:13)
Block(4,2,1,LOG:13)
Block(4,3,0,LOG:13)
Block(4,3,1,LOG:13)
Block(4,4,0,LOG:1)
Block(4,5,0,LOG:1)
Block(5,-1,-1,LOG:5)
Block(5,-1,0,LOG:13)
Block(5,-1,2,LOG:13)
Block(5,0,-1,LOG:13)
Block(6,-1,-2,LOG:9)
Block(6,-1,-1,LOG:5)

#######################################################################
# +-----------------------------------------------------------------+ #
# |                            BO3 checks                           | #
# +-----------------------------------------------------------------+ #
#######################################################################


#######################################################################
# +-----------------------------------------------------------------+ #
# |                             Branches                            | #
# +-----------------------------------------------------------------+ #
#######################################################################


#######################################################################
# +-----------------------------------------------------------------+ #
# |                             Entities                            | #
# +-----------------------------------------------------------------+ #
#######################################################################


#######################################################################
# +-----------------------------------------------------------------+ #
# |                            Particles                            | #
# +-----------------------------------------------------------------+ #
#######################################################################


#######################################################################
# +-----------------------------------------------------------------+ #
# |                             Spawners                            | #
# +-----------------------------------------------------------------+ #
#######################################################################


#######################################################################
# +-----------------------------------------------------------------+ #
# |                             ModData                             | #
# +-----------------------------------------------------------------+ #
#######################################################################

