
#######################################################################
# +-----------------------------------------------------------------+ #
# |                            BO3 object                           | #
# +-----------------------------------------------------------------+ #
#######################################################################

# This is the config file of a custom object.
# If you add this object correctly to your BiomeConfigs, it will spawn in the world.

# This is the creator of this BO3 object
Author: Unknown

# A short description of this BO3 object
Description: No description given

# The BO3 version, don't change this! It can be used by external applications to do a version check.
Version: 3

# The settings mode, WriteAll, WriteWithoutComments or WriteDisable. See WorldConfig.
SettingsMode: WriteAll


#######################################################################
# +-----------------------------------------------------------------+ #
# |                          Main settings                          | #
# +-----------------------------------------------------------------+ #
#######################################################################

# This needs to be set to true to spawn the object in the Tree and Sapling resources.
Tree: true

# The frequency of the BO3 from 1 to 200. Tries this many times to spawn this BO3 when using the CustomObject(...) resource.
# Ignored by Tree(..), Sapling(..) and CustomStructure(..)
Frequency: 3

# The rarity of the BO3 from 0 to 100. Each spawn attempt has rarity% chance to succeed when using the CustomObject(...) resource.
# Ignored by Tree(..), Sapling(..) and CustomStructure(..)
Rarity: 66.0

# If you set this to true, the BO3 will be placed with a random rotation.
RotateRandomly: true

# The spawn height of the BO3: randomY, highestBlock or highestSolidBlock.
SpawnHeight: highestSolidBlock

# The offset from the spawn height to spawn this BO3
# Ex. SpawnHeight = highestSolidBlock, SpawnHeightOffset = 3; This object will spawn 3 blocks above the highest solid block
SpawnHeightOffset: -20

# A random amount to offset the spawn location from the spawn offset height
# Ex. SpawnHeightOffset = 3, SpawnHeightVariance = 3; This object will spawn 3 to 6 blocks above the original spot it would have spawned
SpawnHeightVariance: 0

##############################
# Height Limits for the BO3. #
##############################

# When in randomY mode used as the minimum Y or in atMinY mode as the actual Y to spawn this BO3 at.
MinHeight: 62

# When in randomY mode used as the maximum Y to spawn this BO3 at.
MaxHeight: 130

######################
# Extrusion settings #
######################

# The style of extrusion you wish to use - BottomDown, TopUp, None (Default)
ExtrudeMode: BottomDown

# The blocks to extrude your BO3 through
ExtrudeThroughBlocks: AIR,GRASS

# Objects can have other objects attacthed to it: branches. Branches can also
# have branches attached to it, which can also have branches, etc. This is the
# maximum branch depth for this objects.
MaxBranchDepth: 10

# When spawned with the UseWorld keyword, this BO3 should NOT spawn in the following biomes.
# If you write the BO3 name directly in the BiomeConfigs, this will be ignored.
ExcludedBiomes: All


#######################################################################
# +-----------------------------------------------------------------+ #
# |                      Source block settings                      | #
# +-----------------------------------------------------------------+ #
#######################################################################

# The block(s) the BO3 should spawn in.
SourceBlocks: AIR

# The maximum percentage of the BO3 that can be outside the SourceBlock.
# The BO3 won't be placed on a location with more blocks outside the SourceBlock than this percentage.
MaxPercentageOutsideSourceBlock: 100

# What to do when a block is about to be placed outside the SourceBlock? (dontPlace, placeAnyway)
OutsideSourceBlock: placeAnyway

# Disable doReplaceBlocks to make this BO3 ignore any ReplacedBlocks settings in biome configs, improves performance.
DoReplaceBlocks: true

# OTG+ settings #
# Legacy setting, rename this file to .BO4 instead. Set this to true to enable the advanced customstructure features of OTG+.
IsOTGPlus: false


#######################################################################
# +-----------------------------------------------------------------+ #
# |                              Blocks                             | #
# +-----------------------------------------------------------------+ #
#######################################################################

# All the blocks used in the BO3 are listed here. Possible blocks:
# Block(x,y,z,id[.data][,nbtfile.nbt)
# RandomBlock(x,y,z,id[:data][,nbtfile.nbt],chance[,id[:data][,nbtfile.nbt],chance[,...]])
#  So RandomBlock(0,0,0,CHEST,chest.nbt,50,CHEST,anotherchest.nbt,100) will spawn a chest at
#  the BO3 origin, and give it a 50% chance to have the contents of chest.nbt, or, if that
#  fails, a 100% percent chance to have the contents of anotherchest.nbt.
# *Note: Unlike Entity() and Spawner(), for Block() .txt files don't work, only .nbt files work.
# MinecraftObject(x,y,z,name) (TODO: This may not work anymore and needs to be tested.
#  Spawns an object in the Mojang NBT structure format. For example, 
#  MinecraftObject(0,0,0,minecraft:igloo/igloo_bottom)
#  spawns the bottom part of an igloo.
Block(-13,0,-4,STONE:0)
Block(-13,0,-3,STONE:0)
Block(-13,0,-2,STONE:0)
Block(-13,0,-1,STONE:0)
Block(-13,0,0,STONE:0)
Block(-13,0,1,STONE:0)
Block(-13,1,-4,STONE:0)
Block(-13,1,-3,STONE:0)
Block(-13,1,-2,STONE:0)
Block(-13,1,-1,STONE:0)
Block(-13,1,0,STONE:0)
Block(-13,1,1,STONE:0)
Block(-13,2,-3,STONE:0)
Block(-13,2,-2,STONE:0)
Block(-13,2,-1,STONE:0)
Block(-13,2,0,STONE:0)
Block(-13,3,-3,STONE:0)
Block(-13,3,-2,STONE:0)
Block(-13,3,-1,STONE:0)
Block(-13,3,0,STONE:0)
Block(-13,4,-3,STONE:0)
Block(-13,4,-2,STONE:0)
Block(-13,4,-1,STONE:0)
Block(-13,4,0,STONE:0)
Block(-13,5,-3,STONE:0)
Block(-13,5,-2,STONE:0)
Block(-13,5,-1,STONE:0)
Block(-13,5,0,STONE:0)
Block(-13,6,-3,STONE:0)
Block(-13,6,-2,STONE:0)
Block(-13,6,-1,STONE:0)
Block(-13,6,0,STONE:0)
Block(-13,7,-2,STONE:0)
Block(-13,7,-1,STONE:0)
Block(-13,8,-2,STONE:0)
Block(-12,0,-5,STONE:0)
Block(-12,0,-4,STONE:0)
Block(-12,0,-3,STONE:0)
Block(-12,0,-2,STONE:0)
Block(-12,0,-1,STONE:0)
Block(-12,0,0,STONE:0)
Block(-12,0,1,STONE:0)
Block(-12,0,2,STONE:0)
Block(-12,0,3,STONE:0)
Block(-12,0,4,STONE:0)
Block(-12,1,-5,STONE:0)
Block(-12,1,-4,STONE:0)
Block(-12,1,-3,STONE:0)
Block(-12,1,-2,STONE:0)
Block(-12,1,-1,STONE:0)
Block(-12,1,0,STONE:0)
Block(-12,1,1,STONE:0)
Block(-12,1,2,STONE:0)
Block(-12,1,3,STONE:0)
Block(-12,1,4,STONE:0)
Block(-12,2,-5,STONE:0)
Block(-12,2,-4,STONE:0)
Block(-12,2,-3,STONE:0)
Block(-12,2,-2,STONE:0)
Block(-12,2,-1,STONE:0)
Block(-12,2,0,STONE:0)
Block(-12,2,1,STONE:0)
Block(-12,2,2,STONE:0)
Block(-12,2,3,STONE:0)
Block(-12,2,4,STONE:0)
Block(-12,3,-5,STONE:0)
Block(-12,3,-4,STONE:0)
Block(-12,3,-3,STONE:0)
Block(-12,3,-2,STONE:0)
Block(-12,3,-1,STONE:0)
Block(-12,3,0,STONE:0)
Block(-12,3,1,STONE:0)
Block(-12,3,2,STONE:0)
Block(-12,3,3,STONE:0)
Block(-12,3,4,STONE:0)
Block(-12,4,-4,STONE:0)
Block(-12,4,-3,STONE:0)
Block(-12,4,-2,STONE:0)
Block(-12,4,-1,STONE:0)
Block(-12,4,0,STONE:0)
Block(-12,4,1,STONE:0)
Block(-12,4,2,STONE:0)
Block(-12,4,3,STONE:0)
Block(-12,5,-4,STONE:0)
Block(-12,5,-3,STONE:0)
Block(-12,5,-2,STONE:0)
Block(-12,5,-1,STONE:0)
Block(-12,5,0,STONE:0)
Block(-12,5,1,STONE:0)
Block(-12,5,2,STONE:0)
Block(-12,5,3,STONE:0)
Block(-12,6,-4,STONE:0)
Block(-12,6,-3,STONE:0)
Block(-12,6,-2,STONE:0)
Block(-12,6,-1,STONE:0)
Block(-12,6,0,STONE:0)
Block(-12,6,1,STONE:0)
Block(-12,6,2,STONE:0)
Block(-12,6,3,STONE:0)
Block(-12,7,-4,STONE:0)
Block(-12,7,-3,STONE:0)
Block(-12,7,-2,STONE:0)
Block(-12,7,-1,STONE:0)
Block(-12,7,0,STONE:0)
Block(-12,7,1,STONE:0)
Block(-12,7,2,STONE:0)
Block(-12,7,3,STONE:0)
Block(-12,8,-4,STONE:0)
Block(-12,8,-3,STONE:0)
Block(-12,8,-2,STONE:0)
Block(-12,8,-1,STONE:0)
Block(-12,8,0,STONE:0)
Block(-12,8,1,STONE:0)
Block(-12,8,2,STONE:0)
Block(-12,8,3,STONE:0)
Block(-12,9,-4,STONE:0)
Block(-12,9,-3,STONE:0)
Block(-12,9,-2,STONE:0)
Block(-12,9,-1,STONE:0)
Block(-12,9,0,STONE:0)
Block(-12,9,1,STONE:0)
Block(-12,9,2,STONE:0)
Block(-12,9,3,STONE:0)
Block(-12,10,-4,STONE:0)
Block(-12,10,-3,STONE:0)
Block(-12,10,-2,STONE:0)
Block(-12,10,-1,STONE:0)
Block(-12,10,0,STONE:0)
Block(-12,10,1,STONE:0)
Block(-12,10,2,STONE:0)
Block(-12,11,-3,STONE:0)
Block(-12,11,-2,STONE:0)
Block(-12,11,-1,STONE:0)
Block(-12,11,0,STONE:0)
Block(-12,11,1,STONE:0)
Block(-12,11,2,STONE:0)
Block(-12,12,-3,STONE:0)
Block(-12,12,-2,STONE:0)
Block(-12,12,-1,STONE:0)
Block(-12,12,0,STONE:0)
Block(-12,12,1,STONE:0)
Block(-12,13,-3,STONE:0)
Block(-12,13,-2,STONE:0)
Block(-12,13,-1,STONE:0)
Block(-12,13,0,STONE:0)
Block(-12,13,1,STONE:0)
Block(-12,14,-2,STONE:0)
Block(-12,14,-1,STONE:0)
Block(-12,14,1,STONE:0)
Block(-12,15,1,STONE:0)
Block(-11,0,-9,STONE:0)
Block(-11,0,-8,STONE:0)
Block(-11,0,-7,STONE:0)
Block(-11,0,-6,STONE:0)
Block(-11,0,-5,STONE:0)
Block(-11,0,-4,STONE:0)
Block(-11,0,-3,STONE:0)
Block(-11,0,-2,STONE:0)
Block(-11,0,-1,STONE:0)
Block(-11,0,0,STONE:0)
Block(-11,0,1,STONE:0)
Block(-11,0,2,STONE:0)
Block(-11,0,3,STONE:0)
Block(-11,0,4,STONE:0)
Block(-11,0,5,STONE:0)
Block(-11,0,6,STONE:0)
Block(-11,1,-9,STONE:0)
Block(-11,1,-8,STONE:0)
Block(-11,1,-7,STONE:0)
Block(-11,1,-6,STONE:0)
Block(-11,1,-5,STONE:0)
Block(-11,1,-4,STONE:0)
Block(-11,1,-3,STONE:0)
Block(-11,1,-2,STONE:0)
Block(-11,1,-1,STONE:0)
Block(-11,1,0,STONE:0)
Block(-11,1,1,STONE:0)
Block(-11,1,2,STONE:0)
Block(-11,1,3,STONE:0)
Block(-11,1,4,STONE:0)
Block(-11,1,5,STONE:0)
Block(-11,1,6,STONE:0)
Block(-11,2,-9,STONE:0)
Block(-11,2,-8,STONE:0)
Block(-11,2,-7,STONE:0)
Block(-11,2,-6,STONE:0)
Block(-11,2,-5,STONE:0)
Block(-11,2,-4,STONE:0)
Block(-11,2,-3,STONE:0)
Block(-11,2,-2,STONE:0)
Block(-11,2,-1,STONE:0)
Block(-11,2,0,STONE:0)
Block(-11,2,1,STONE:0)
Block(-11,2,2,STONE:0)
Block(-11,2,3,STONE:0)
Block(-11,2,4,STONE:0)
Block(-11,2,5,STONE:0)
Block(-11,3,-8,STONE:0)
Block(-11,3,-7,STONE:0)
Block(-11,3,-6,STONE:0)
Block(-11,3,-5,STONE:0)
Block(-11,3,-4,STONE:0)
Block(-11,3,-3,STONE:0)
Block(-11,3,-2,STONE:0)
Block(-11,3,-1,STONE:0)
Block(-11,3,0,STONE:0)
Block(-11,3,1,STONE:0)
Block(-11,3,2,STONE:0)
Block(-11,3,3,STONE:0)
Block(-11,3,4,STONE:0)
Block(-11,3,5,STONE:0)
Block(-11,4,-7,STONE:0)
Block(-11,4,-6,STONE:0)
Block(-11,4,-5,STONE:0)
Block(-11,4,-4,STONE:0)
Block(-11,4,-3,STONE:0)
Block(-11,4,-2,STONE:0)
Block(-11,4,-1,STONE:0)
Block(-11,4,0,STONE:0)
Block(-11,4,1,STONE:0)
Block(-11,4,2,STONE:0)
Block(-11,4,3,STONE:0)
Block(-11,4,4,STONE:0)
Block(-11,4,5,STONE:0)
Block(-11,5,-6,STONE:0)
Block(-11,5,-5,STONE:0)
Block(-11,5,-4,STONE:0)
Block(-11,5,-3,STONE:0)
Block(-11,5,-2,STONE:0)
Block(-11,5,-1,STONE:0)
Block(-11,5,0,STONE:0)
Block(-11,5,1,STONE:0)
Block(-11,5,2,STONE:0)
Block(-11,5,3,STONE:0)
Block(-11,5,4,STONE:0)
Block(-11,5,5,STONE:0)
Block(-11,6,-5,STONE:0)
Block(-11,6,-4,STONE:0)
Block(-11,6,-3,STONE:0)
Block(-11,6,-2,STONE:0)
Block(-11,6,-1,STONE:0)
Block(-11,6,0,STONE:0)
Block(-11,6,1,STONE:0)
Block(-11,6,2,STONE:0)
Block(-11,6,3,STONE:0)
Block(-11,6,4,STONE:0)
Block(-11,6,5,STONE:0)
Block(-11,7,-5,STONE:0)
Block(-11,7,-4,STONE:0)
Block(-11,7,-3,STONE:0)
Block(-11,7,-2,STONE:0)
Block(-11,7,-1,STONE:0)
Block(-11,7,0,STONE:0)
Block(-11,7,1,STONE:0)
Block(-11,7,2,STONE:0)
Block(-11,7,3,STONE:0)
Block(-11,7,4,STONE:0)
Block(-11,8,-5,STONE:0)
Block(-11,8,-4,STONE:0)
Block(-11,8,-3,STONE:0)
Block(-11,8,-2,STONE:0)
Block(-11,8,-1,STONE:0)
Block(-11,8,0,STONE:0)
Block(-11,8,1,STONE:0)
Block(-11,8,2,STONE:0)
Block(-11,8,3,STONE:0)
Block(-11,8,4,STONE:0)
Block(-11,9,-4,STONE:0)
Block(-11,9,-3,STONE:0)
Block(-11,9,-2,STONE:0)
Block(-11,9,-1,STONE:0)
Block(-11,9,0,STONE:0)
Block(-11,9,1,STONE:0)
Block(-11,9,2,STONE:0)
Block(-11,9,3,STONE:0)
Block(-11,9,4,STONE:0)
Block(-11,10,-4,STONE:0)
Block(-11,10,-3,STONE:0)
Block(-11,10,-2,STONE:0)
Block(-11,10,-1,STONE:0)
Block(-11,10,0,STONE:0)
Block(-11,10,1,STONE:0)
Block(-11,10,2,STONE:0)
Block(-11,10,3,STONE:0)
Block(-11,10,4,STONE:0)
Block(-11,11,-4,STONE:0)
Block(-11,11,-3,STONE:0)
Block(-11,11,-2,STONE:0)
Block(-11,11,-1,STONE:0)
Block(-11,11,0,STONE:0)
Block(-11,11,1,STONE:0)
Block(-11,11,2,STONE:0)
Block(-11,11,3,STONE:0)
Block(-11,11,4,STONE:0)
Block(-11,12,-4,STONE:0)
Block(-11,12,-3,STONE:0)
Block(-11,12,-2,STONE:0)
Block(-11,12,-1,STONE:0)
Block(-11,12,0,STONE:0)
Block(-11,12,1,STONE:0)
Block(-11,12,2,STONE:0)
Block(-11,12,3,STONE:0)
Block(-11,13,-3,STONE:0)
Block(-11,13,-2,STONE:0)
Block(-11,13,-1,STONE:0)
Block(-11,13,0,STONE:0)
Block(-11,13,1,STONE:0)
Block(-11,13,2,STONE:0)
Block(-11,13,3,STONE:0)
Block(-11,14,-3,STONE:0)
Block(-11,14,-2,STONE:0)
Block(-11,14,-1,STONE:0)
Block(-11,14,0,STONE:0)
Block(-11,14,1,STONE:0)
Block(-11,14,2,STONE:0)
Block(-11,14,3,STONE:0)
Block(-11,15,-3,STONE:0)
Block(-11,15,-2,STONE:0)
Block(-11,15,-1,STONE:0)
Block(-11,15,0,STONE:0)
Block(-11,15,1,STONE:0)
Block(-11,15,2,STONE:0)
Block(-11,16,-3,STONE:0)
Block(-11,16,-2,STONE:0)
Block(-11,16,-1,STONE:0)
Block(-11,16,0,STONE:0)
Block(-11,16,1,STONE:0)
Block(-11,16,2,STONE:0)
Block(-11,17,-3,STONE:0)
Block(-11,17,-2,STONE:0)
Block(-11,17,-1,STONE:0)
Block(-11,17,0,STONE:0)
Block(-11,17,1,STONE:0)
Block(-11,17,2,STONE:0)
Block(-11,18,-3,STONE:0)
Block(-11,18,-2,STONE:0)
Block(-11,18,-1,STONE:0)
Block(-11,18,0,STONE:0)
Block(-11,18,1,STONE:0)
Block(-11,18,2,STONE:0)
Block(-11,19,-3,STONE:0)
Block(-11,19,-2,STONE:0)
Block(-11,19,-1,STONE:0)
Block(-11,19,0,STONE:0)
Block(-11,19,1,STONE:0)
Block(-11,20,-2,STONE:0)
Block(-11,20,-1,STONE:0)
Block(-11,20,0,STONE:0)
Block(-11,20,1,STONE:0)
Block(-11,21,-2,STONE:0)
Block(-11,21,-1,STONE:0)
Block(-11,21,0,STONE:0)
Block(-11,21,1,STONE:0)
Block(-11,22,-2,STONE:0)
Block(-11,22,-1,STONE:0)
Block(-11,22,0,STONE:0)
Block(-11,23,-2,STONE:0)
Block(-11,23,-1,STONE:0)
Block(-11,24,-2,STONE:0)
Block(-11,24,-1,STONE:0)
Block(-11,25,-2,STONE:0)
Block(-11,25,-1,STONE:0)
Block(-11,26,-2,STONE:0)
Block(-11,26,-1,STONE:0)
Block(-11,27,-1,STONE:0)
Block(-11,28,-1,STONE:0)
Block(-10,0,-10,STONE:0)
Block(-10,0,-9,STONE:0)
Block(-10,0,-8,STONE:0)
Block(-10,0,-7,STONE:0)
Block(-10,0,-6,STONE:0)
Block(-10,0,-5,STONE:0)
Block(-10,0,-4,STONE:0)
Block(-10,0,-3,STONE:0)
Block(-10,0,-2,STONE:0)
Block(-10,0,-1,STONE:0)
Block(-10,0,0,STONE:0)
Block(-10,0,1,STONE:0)
Block(-10,0,2,STONE:0)
Block(-10,0,3,STONE:0)
Block(-10,0,4,STONE:0)
Block(-10,0,5,STONE:0)
Block(-10,0,6,STONE:0)
Block(-10,0,7,STONE:0)
Block(-10,1,-10,STONE:0)
Block(-10,1,-9,STONE:0)
Block(-10,1,-8,STONE:0)
Block(-10,1,-7,STONE:0)
Block(-10,1,-6,STONE:0)
Block(-10,1,-5,STONE:0)
Block(-10,1,-4,STONE:0)
Block(-10,1,-3,STONE:0)
Block(-10,1,-2,STONE:0)
Block(-10,1,-1,STONE:0)
Block(-10,1,0,STONE:0)
Block(-10,1,1,STONE:0)
Block(-10,1,2,STONE:0)
Block(-10,1,3,STONE:0)
Block(-10,1,4,STONE:0)
Block(-10,1,5,STONE:0)
Block(-10,1,6,STONE:0)
Block(-10,1,7,STONE:0)
Block(-10,2,-10,STONE:0)
Block(-10,2,-9,STONE:0)
Block(-10,2,-8,STONE:0)
Block(-10,2,-7,STONE:0)
Block(-10,2,-6,STONE:0)
Block(-10,2,-5,STONE:0)
Block(-10,2,-4,STONE:0)
Block(-10,2,-3,STONE:0)
Block(-10,2,-2,STONE:0)
Block(-10,2,-1,STONE:0)
Block(-10,2,0,STONE:0)
Block(-10,2,1,STONE:0)
Block(-10,2,2,STONE:0)
Block(-10,2,3,STONE:0)
Block(-10,2,4,STONE:0)
Block(-10,2,5,STONE:0)
Block(-10,2,6,STONE:0)
Block(-10,3,-9,STONE:0)
Block(-10,3,-8,STONE:0)
Block(-10,3,-7,STONE:0)
Block(-10,3,-6,STONE:0)
Block(-10,3,-5,STONE:0)
Block(-10,3,-4,STONE:0)
Block(-10,3,-3,STONE:0)
Block(-10,3,-2,STONE:0)
Block(-10,3,-1,STONE:0)
Block(-10,3,0,STONE:0)
Block(-10,3,1,STONE:0)
Block(-10,3,2,STONE:0)
Block(-10,3,3,STONE:0)
Block(-10,3,4,STONE:0)
Block(-10,3,5,STONE:0)
Block(-10,3,6,STONE:0)
Block(-10,4,-9,STONE:0)
Block(-10,4,-8,STONE:0)
Block(-10,4,-7,STONE:0)
Block(-10,4,-6,STONE:0)
Block(-10,4,-5,STONE:0)
Block(-10,4,-4,STONE:0)
Block(-10,4,-3,STONE:0)
Block(-10,4,-2,STONE:0)
Block(-10,4,-1,STONE:0)
Block(-10,4,0,STONE:0)
Block(-10,4,1,STONE:0)
Block(-10,4,2,STONE:0)
Block(-10,4,3,STONE:0)
Block(-10,4,4,STONE:0)
Block(-10,4,5,STONE:0)
Block(-10,4,6,STONE:0)
Block(-10,5,-9,STONE:0)
Block(-10,5,-8,STONE:0)
Block(-10,5,-7,STONE:0)
Block(-10,5,-6,STONE:0)
Block(-10,5,-5,STONE:0)
Block(-10,5,-4,STONE:0)
Block(-10,5,-3,STONE:0)
Block(-10,5,-2,STONE:0)
Block(-10,5,-1,STONE:0)
Block(-10,5,0,STONE:0)
Block(-10,5,1,STONE:0)
Block(-10,5,2,STONE:0)
Block(-10,5,3,STONE:0)
Block(-10,5,4,STONE:0)
Block(-10,5,5,STONE:0)
Block(-10,5,6,STONE:0)
Block(-10,6,-9,STONE:0)
Block(-10,6,-8,STONE:0)
Block(-10,6,-7,STONE:0)
Block(-10,6,-6,STONE:0)
Block(-10,6,-5,STONE:0)
Block(-10,6,-4,STONE:0)
Block(-10,6,-3,STONE:0)
Block(-10,6,-2,STONE:0)
Block(-10,6,-1,STONE:0)
Block(-10,6,0,STONE:0)
Block(-10,6,1,STONE:0)
Block(-10,6,2,STONE:0)
Block(-10,6,3,STONE:0)
Block(-10,6,4,STONE:0)
Block(-10,6,5,STONE:0)
Block(-10,6,6,STONE:0)
Block(-10,7,-9,STONE:0)
Block(-10,7,-8,STONE:0)
Block(-10,7,-7,STONE:0)
Block(-10,7,-6,STONE:0)
Block(-10,7,-5,STONE:0)
Block(-10,7,-4,STONE:0)
Block(-10,7,-3,STONE:0)
Block(-10,7,-2,STONE:0)
Block(-10,7,-1,STONE:0)
Block(-10,7,0,STONE:0)
Block(-10,7,1,STONE:0)
Block(-10,7,2,STONE:0)
Block(-10,7,3,STONE:0)
Block(-10,7,4,STONE:0)
Block(-10,7,5,STONE:0)
Block(-10,8,-9,STONE:0)
Block(-10,8,-8,STONE:0)
Block(-10,8,-7,STONE:0)
Block(-10,8,-6,STONE:0)
Block(-10,8,-5,STONE:0)
Block(-10,8,-4,STONE:0)
Block(-10,8,-3,STONE:0)
Block(-10,8,-2,STONE:0)
Block(-10,8,-1,STONE:0)
Block(-10,8,0,STONE:0)
Block(-10,8,1,STONE:0)
Block(-10,8,2,STONE:0)
Block(-10,8,3,STONE:0)
Block(-10,8,4,STONE:0)
Block(-10,8,5,STONE:0)
Block(-10,9,-9,STONE:0)
Block(-10,9,-8,STONE:0)
Block(-10,9,-7,STONE:0)
Block(-10,9,-6,STONE:0)
Block(-10,9,-5,STONE:0)
Block(-10,9,-4,STONE:0)
Block(-10,9,-3,STONE:0)
Block(-10,9,-2,STONE:0)
Block(-10,9,-1,STONE:0)
Block(-10,9,0,STONE:0)
Block(-10,9,1,STONE:0)
Block(-10,9,2,STONE:0)
Block(-10,9,3,STONE:0)
Block(-10,9,4,STONE:0)
Block(-10,9,5,STONE:0)
Block(-10,10,-8,STONE:0)
Block(-10,10,-7,STONE:0)
Block(-10,10,-6,STONE:0)
Block(-10,10,-5,STONE:0)
Block(-10,10,-4,STONE:0)
Block(-10,10,-3,STONE:0)
Block(-10,10,-2,STONE:0)
Block(-10,10,-1,STONE:0)
Block(-10,10,0,STONE:0)
Block(-10,10,1,STONE:0)
Block(-10,10,2,STONE:0)
Block(-10,10,3,STONE:0)
Block(-10,10,4,STONE:0)
Block(-10,10,5,STONE:0)
Block(-10,11,-8,STONE:0)
Block(-10,11,-7,STONE:0)
Block(-10,11,-6,STONE:0)
Block(-10,11,-5,STONE:0)
Block(-10,11,-4,STONE:0)
Block(-10,11,-3,STONE:0)
Block(-10,11,-2,STONE:0)
Block(-10,11,-1,STONE:0)
Block(-10,11,0,STONE:0)
Block(-10,11,1,STONE:0)
Block(-10,11,2,STONE:0)
Block(-10,11,3,STONE:0)
Block(-10,11,4,STONE:0)
Block(-10,11,5,STONE:0)
Block(-10,12,-8,STONE:0)
Block(-10,12,-7,STONE:0)
Block(-10,12,-6,STONE:0)
Block(-10,12,-5,STONE:0)
Block(-10,12,-4,STONE:0)
Block(-10,12,-3,STONE:0)
Block(-10,12,-2,STONE:0)
Block(-10,12,-1,STONE:0)
Block(-10,12,0,STONE:0)
Block(-10,12,1,STONE:0)
Block(-10,12,2,STONE:0)
Block(-10,12,3,STONE:0)
Block(-10,12,4,STONE:0)
Block(-10,12,5,STONE:0)
Block(-10,13,-7,STONE:0)
Block(-10,13,-6,STONE:0)
Block(-10,13,-5,STONE:0)
Block(-10,13,-4,STONE:0)
Block(-10,13,-3,STONE:0)
Block(-10,13,-2,STONE:0)
Block(-10,13,-1,STONE:0)
Block(-10,13,0,STONE:0)
Block(-10,13,1,STONE:0)
Block(-10,13,2,STONE:0)
Block(-10,13,3,STONE:0)
Block(-10,13,4,STONE:0)
Block(-10,14,-6,STONE:0)
Block(-10,14,-5,STONE:0)
Block(-10,14,-4,STONE:0)
Block(-10,14,-3,STONE:0)
Block(-10,14,-2,STONE:0)
Block(-10,14,-1,STONE:0)
Block(-10,14,0,STONE:0)
Block(-10,14,1,STONE:0)
Block(-10,14,2,STONE:0)
Block(-10,14,3,STONE:0)
Block(-10,14,4,STONE:0)
Block(-10,15,-6,STONE:0)
Block(-10,15,-5,STONE:0)
Block(-10,15,-4,STONE:0)
Block(-10,15,-3,STONE:0)
Block(-10,15,-2,STONE:0)
Block(-10,15,-1,STONE:0)
Block(-10,15,0,STONE:0)
Block(-10,15,1,STONE:0)
Block(-10,15,2,STONE:0)
Block(-10,15,3,STONE:0)
Block(-10,15,4,STONE:0)
Block(-10,16,-5,STONE:0)
Block(-10,16,-4,STONE:0)
Block(-10,16,-3,STONE:0)
Block(-10,16,-2,STONE:0)
Block(-10,16,-1,STONE:0)
Block(-10,16,0,STONE:0)
Block(-10,16,1,STONE:0)
Block(-10,16,2,STONE:0)
Block(-10,16,3,STONE:0)
Block(-10,17,-5,STONE:0)
Block(-10,17,-4,STONE:0)
Block(-10,17,-3,STONE:0)
Block(-10,17,-2,STONE:0)
Block(-10,17,-1,STONE:0)
Block(-10,17,0,STONE:0)
Block(-10,17,1,STONE:0)
Block(-10,17,2,STONE:0)
Block(-10,17,3,STONE:0)
Block(-10,18,-5,STONE:0)
Block(-10,18,-4,STONE:0)
Block(-10,18,-3,STONE:0)
Block(-10,18,-2,STONE:0)
Block(-10,18,-1,STONE:0)
Block(-10,18,0,STONE:0)
Block(-10,18,1,STONE:0)
Block(-10,18,2,STONE:0)
Block(-10,18,3,STONE:0)
Block(-10,19,-5,STONE:0)
Block(-10,19,-4,STONE:0)
Block(-10,19,-3,STONE:0)
Block(-10,19,-2,STONE:0)
Block(-10,19,-1,STONE:0)
Block(-10,19,0,STONE:0)
Block(-10,19,1,STONE:0)
Block(-10,19,2,STONE:0)
Block(-10,20,-5,STONE:0)
Block(-10,20,-4,STONE:0)
Block(-10,20,-3,STONE:0)
Block(-10,20,-2,STONE:0)
Block(-10,20,-1,STONE:0)
Block(-10,20,0,STONE:0)
Block(-10,20,1,STONE:0)
Block(-10,20,2,STONE:0)
Block(-10,21,-5,STONE:0)
Block(-10,21,-4,STONE:0)
Block(-10,21,-3,STONE:0)
Block(-10,21,-2,STONE:0)
Block(-10,21,-1,STONE:0)
Block(-10,21,0,STONE:0)
Block(-10,21,1,STONE:0)
Block(-10,21,2,STONE:0)
Block(-10,22,-4,STONE:0)
Block(-10,22,-3,STONE:0)
Block(-10,22,-2,STONE:0)
Block(-10,22,-1,STONE:0)
Block(-10,22,0,STONE:0)
Block(-10,22,1,STONE:0)
Block(-10,22,2,STONE:0)
Block(-10,23,-4,STONE:0)
Block(-10,23,-3,STONE:0)
Block(-10,23,-2,STONE:0)
Block(-10,23,-1,STONE:0)
Block(-10,23,0,STONE:0)
Block(-10,23,1,STONE:0)
Block(-10,23,2,STONE:0)
Block(-10,24,-4,STONE:0)
Block(-10,24,-3,STONE:0)
Block(-10,24,-2,STONE:0)
Block(-10,24,-1,STONE:0)
Block(-10,24,0,STONE:0)
Block(-10,24,1,STONE:0)
Block(-10,24,2,STONE:0)
Block(-10,25,-4,STONE:0)
Block(-10,25,-3,STONE:0)
Block(-10,25,-2,STONE:0)
Block(-10,25,-1,STONE:0)
Block(-10,25,0,STONE:0)
Block(-10,25,1,STONE:0)
Block(-10,26,-4,STONE:0)
Block(-10,26,-3,STONE:0)
Block(-10,26,-2,STONE:0)
Block(-10,26,-1,STONE:0)
Block(-10,26,0,STONE:0)
Block(-10,26,1,STONE:0)
Block(-10,27,-4,STONE:0)
Block(-10,27,-3,STONE:0)
Block(-10,27,-2,STONE:0)
Block(-10,27,-1,STONE:0)
Block(-10,27,0,STONE:0)
Block(-10,27,1,STONE:0)
Block(-10,28,-4,STONE:0)
Block(-10,28,-3,STONE:0)
Block(-10,28,-2,STONE:0)
Block(-10,28,-1,STONE:0)
Block(-10,28,0,STONE:0)
Block(-10,28,1,STONE:0)
Block(-10,29,-4,STONE:0)
Block(-10,29,-3,STONE:0)
Block(-10,29,-2,STONE:0)
Block(-10,29,-1,STONE:0)
Block(-10,29,0,STONE:0)
Block(-10,29,1,STONE:0)
Block(-10,30,-4,STONE:0)
Block(-10,30,-3,STONE:0)
Block(-10,30,-2,STONE:0)
Block(-10,30,-1,STONE:0)
Block(-10,30,0,STONE:0)
Block(-10,30,1,STONE:0)
Block(-10,31,-4,STONE:0)
Block(-10,31,-3,STONE:0)
Block(-10,31,-2,STONE:0)
Block(-10,31,-1,STONE:0)
Block(-10,31,0,STONE:0)
Block(-10,31,1,STONE:0)
Block(-10,32,-4,STONE:0)
Block(-10,32,-3,STONE:0)
Block(-10,32,-2,STONE:0)
Block(-10,32,-1,STONE:0)
Block(-10,32,0,STONE:0)
Block(-10,32,1,STONE:0)
Block(-10,33,-4,STONE:0)
Block(-10,33,-3,STONE:0)
Block(-10,33,-2,STONE:0)
Block(-10,33,-1,STONE:0)
Block(-10,33,0,STONE:0)
Block(-10,33,1,STONE:0)
Block(-10,34,-4,STONE:0)
Block(-10,34,-3,STONE:0)
Block(-10,34,-2,STONE:0)
Block(-10,34,-1,STONE:0)
Block(-10,34,0,STONE:0)
Block(-10,34,1,STONE:0)
Block(-10,35,-3,STONE:0)
Block(-10,35,-2,STONE:0)
Block(-10,35,-1,STONE:0)
Block(-10,35,0,STONE:0)
Block(-10,35,1,STONE:0)
Block(-10,36,-3,STONE:0)
Block(-10,36,-2,STONE:0)
Block(-10,36,0,STONE:0)
Block(-10,37,-3,STONE:0)
Block(-10,37,-2,STONE:0)
Block(-10,37,0,STONE:0)
Block(-10,38,0,STONE:0)
Block(-10,39,0,STONE:0)
Block(-10,40,0,STONE:0)
Block(-10,41,0,STONE:0)
Block(-10,42,0,STONE:0)
Block(-9,0,-10,STONE:0)
Block(-9,0,-9,STONE:0)
Block(-9,0,-8,STONE:0)
Block(-9,0,-7,STONE:0)
Block(-9,0,-6,STONE:0)
Block(-9,0,-5,STONE:0)
Block(-9,0,-4,STONE:0)
Block(-9,0,-3,STONE:0)
Block(-9,0,-2,STONE:0)
Block(-9,0,-1,STONE:0)
Block(-9,0,0,STONE:0)
Block(-9,0,1,STONE:0)
Block(-9,0,2,STONE:0)
Block(-9,0,3,STONE:0)
Block(-9,0,4,STONE:0)
Block(-9,0,5,STONE:0)
Block(-9,0,6,STONE:0)
Block(-9,0,7,STONE:0)
Block(-9,0,8,STONE:0)
Block(-9,1,-10,STONE:0)
Block(-9,1,-9,STONE:0)
Block(-9,1,-8,STONE:0)
Block(-9,1,-7,STONE:0)
Block(-9,1,-6,STONE:0)
Block(-9,1,-5,STONE:0)
Block(-9,1,-4,STONE:0)
Block(-9,1,-3,STONE:0)
Block(-9,1,-2,STONE:0)
Block(-9,1,-1,STONE:0)
Block(-9,1,0,STONE:0)
Block(-9,1,1,STONE:0)
Block(-9,1,2,STONE:0)
Block(-9,1,3,STONE:0)
Block(-9,1,4,STONE:0)
Block(-9,1,5,STONE:0)
Block(-9,1,6,STONE:0)
Block(-9,1,7,STONE:0)
Block(-9,1,8,STONE:0)
Block(-9,2,-10,STONE:0)
Block(-9,2,-9,STONE:0)
Block(-9,2,-8,STONE:0)
Block(-9,2,-7,STONE:0)
Block(-9,2,-6,STONE:0)
Block(-9,2,-5,STONE:0)
Block(-9,2,-4,STONE:0)
Block(-9,2,-3,STONE:0)
Block(-9,2,-2,STONE:0)
Block(-9,2,-1,STONE:0)
Block(-9,2,0,STONE:0)
Block(-9,2,1,STONE:0)
Block(-9,2,2,STONE:0)
Block(-9,2,3,STONE:0)
Block(-9,2,4,STONE:0)
Block(-9,2,5,STONE:0)
Block(-9,2,6,STONE:0)
Block(-9,2,7,STONE:0)
Block(-9,3,-10,STONE:0)
Block(-9,3,-9,STONE:0)
Block(-9,3,-8,STONE:0)
Block(-9,3,-7,STONE:0)
Block(-9,3,-6,STONE:0)
Block(-9,3,-5,STONE:0)
Block(-9,3,-4,STONE:0)
Block(-9,3,-3,STONE:0)
Block(-9,3,-2,STONE:0)
Block(-9,3,-1,STONE:0)
Block(-9,3,0,STONE:0)
Block(-9,3,1,STONE:0)
Block(-9,3,2,STONE:0)
Block(-9,3,3,STONE:0)
Block(-9,3,4,STONE:0)
Block(-9,3,5,STONE:0)
Block(-9,3,6,STONE:0)
Block(-9,3,7,STONE:0)
Block(-9,4,-10,STONE:0)
Block(-9,4,-9,STONE:0)
Block(-9,4,-8,STONE:0)
Block(-9,4,-7,STONE:0)
Block(-9,4,-6,STONE:0)
Block(-9,4,-5,STONE:0)
Block(-9,4,-4,STONE:0)
Block(-9,4,-3,STONE:0)
Block(-9,4,-2,STONE:0)
Block(-9,4,-1,STONE:0)
Block(-9,4,0,STONE:0)
Block(-9,4,1,STONE:0)
Block(-9,4,2,STONE:0)
Block(-9,4,3,STONE:0)
Block(-9,4,4,STONE:0)
Block(-9,4,5,STONE:0)
Block(-9,4,6,STONE:0)
Block(-9,4,7,STONE:0)
Block(-9,5,-10,STONE:0)
Block(-9,5,-9,STONE:0)
Block(-9,5,-8,STONE:0)
Block(-9,5,-7,STONE:0)
Block(-9,5,-6,STONE:0)
Block(-9,5,-5,STONE:0)
Block(-9,5,-4,STONE:0)
Block(-9,5,-3,STONE:0)
Block(-9,5,-2,STONE:0)
Block(-9,5,-1,STONE:0)
Block(-9,5,0,STONE:0)
Block(-9,5,1,STONE:0)
Block(-9,5,2,STONE:0)
Block(-9,5,3,STONE:0)
Block(-9,5,4,STONE:0)
Block(-9,5,5,STONE:0)
Block(-9,5,6,STONE:0)
Block(-9,5,7,STONE:0)
Block(-9,6,-9,STONE:0)
Block(-9,6,-8,STONE:0)
Block(-9,6,-7,STONE:0)
Block(-9,6,-6,STONE:0)
Block(-9,6,-5,STONE:0)
Block(-9,6,-4,STONE:0)
Block(-9,6,-3,STONE:0)
Block(-9,6,-2,STONE:0)
Block(-9,6,-1,STONE:0)
Block(-9,6,0,STONE:0)
Block(-9,6,1,STONE:0)
Block(-9,6,2,STONE:0)
Block(-9,6,3,STONE:0)
Block(-9,6,4,STONE:0)
Block(-9,6,5,STONE:0)
Block(-9,6,6,STONE:0)
Block(-9,7,-9,STONE:0)
Block(-9,7,-8,STONE:0)
Block(-9,7,-7,STONE:0)
Block(-9,7,-6,STONE:0)
Block(-9,7,-5,STONE:0)
Block(-9,7,-4,STONE:0)
Block(-9,7,-3,STONE:0)
Block(-9,7,-2,STONE:0)
Block(-9,7,-1,STONE:0)
Block(-9,7,0,STONE:0)
Block(-9,7,1,STONE:0)
Block(-9,7,2,STONE:0)
Block(-9,7,3,STONE:0)
Block(-9,7,4,STONE:0)
Block(-9,7,5,STONE:0)
Block(-9,7,6,STONE:0)
Block(-9,8,-9,STONE:0)
Block(-9,8,-8,STONE:0)
Block(-9,8,-7,STONE:0)
Block(-9,8,-6,STONE:0)
Block(-9,8,-5,STONE:0)
Block(-9,8,-4,STONE:0)
Block(-9,8,-3,STONE:0)
Block(-9,8,-2,STONE:0)
Block(-9,8,-1,STONE:0)
Block(-9,8,0,STONE:0)
Block(-9,8,1,STONE:0)
Block(-9,8,2,STONE:0)
Block(-9,8,3,STONE:0)
Block(-9,8,4,STONE:0)
Block(-9,8,5,STONE:0)
Block(-9,8,6,STONE:0)
Block(-9,9,-9,STONE:0)
Block(-9,9,-8,STONE:0)
Block(-9,9,-7,STONE:0)
Block(-9,9,-6,STONE:0)
Block(-9,9,-5,STONE:0)
Block(-9,9,-4,STONE:0)
Block(-9,9,-3,STONE:0)
Block(-9,9,-2,STONE:0)
Block(-9,9,-1,STONE:0)
Block(-9,9,0,STONE:0)
Block(-9,9,1,STONE:0)
Block(-9,9,2,STONE:0)
Block(-9,9,3,STONE:0)
Block(-9,9,4,STONE:0)
Block(-9,9,5,STONE:0)
Block(-9,9,6,STONE:0)
Block(-9,10,-9,STONE:0)
Block(-9,10,-8,STONE:0)
Block(-9,10,-7,STONE:0)
Block(-9,10,-6,STONE:0)
Block(-9,10,-5,STONE:0)
Block(-9,10,-4,STONE:0)
Block(-9,10,-3,STONE:0)
Block(-9,10,-2,STONE:0)
Block(-9,10,-1,STONE:0)
Block(-9,10,0,STONE:0)
Block(-9,10,1,STONE:0)
Block(-9,10,2,STONE:0)
Block(-9,10,3,STONE:0)
Block(-9,10,4,STONE:0)
Block(-9,10,5,STONE:0)
Block(-9,10,6,STONE:0)
Block(-9,11,-9,STONE:0)
Block(-9,11,-8,STONE:0)
Block(-9,11,-7,STONE:0)
Block(-9,11,-6,STONE:0)
Block(-9,11,-5,STONE:0)
Block(-9,11,-4,STONE:0)
Block(-9,11,-3,STONE:0)
Block(-9,11,-2,STONE:0)
Block(-9,11,-1,STONE:0)
Block(-9,11,0,STONE:0)
Block(-9,11,1,STONE:0)
Block(-9,11,2,STONE:0)
Block(-9,11,3,STONE:0)
Block(-9,11,4,STONE:0)
Block(-9,11,5,STONE:0)
Block(-9,12,-8,STONE:0)
Block(-9,12,-7,STONE:0)
Block(-9,12,-6,STONE:0)
Block(-9,12,-5,STONE:0)
Block(-9,12,-4,STONE:0)
Block(-9,12,-3,STONE:0)
Block(-9,12,-2,STONE:0)
Block(-9,12,-1,STONE:0)
Block(-9,12,0,STONE:0)
Block(-9,12,1,STONE:0)
Block(-9,12,2,STONE:0)
Block(-9,12,3,STONE:0)
Block(-9,12,4,STONE:0)
Block(-9,12,5,STONE:0)
Block(-9,13,-8,STONE:0)
Block(-9,13,-7,STONE:0)
Block(-9,13,-6,STONE:0)
Block(-9,13,-5,STONE:0)
Block(-9,13,-4,STONE:0)
Block(-9,13,-3,STONE:0)
Block(-9,13,-2,STONE:0)
Block(-9,13,-1,STONE:0)
Block(-9,13,0,STONE:0)
Block(-9,13,1,STONE:0)
Block(-9,13,2,STONE:0)
Block(-9,13,3,STONE:0)
Block(-9,13,4,STONE:0)
Block(-9,13,5,STONE:0)
Block(-9,14,-7,STONE:0)
Block(-9,14,-6,STONE:0)
Block(-9,14,-5,STONE:0)
Block(-9,14,-4,STONE:0)
Block(-9,14,-3,STONE:0)
Block(-9,14,-2,STONE:0)
Block(-9,14,-1,STONE:0)
Block(-9,14,0,STONE:0)
Block(-9,14,1,STONE:0)
Block(-9,14,2,STONE:0)
Block(-9,14,3,STONE:0)
Block(-9,14,4,STONE:0)
Block(-9,15,-7,STONE:0)
Block(-9,15,-6,STONE:0)
Block(-9,15,-5,STONE:0)
Block(-9,15,-4,STONE:0)
Block(-9,15,-3,STONE:0)
Block(-9,15,-2,STONE:0)
Block(-9,15,-1,STONE:0)
Block(-9,15,0,STONE:0)
Block(-9,15,1,STONE:0)
Block(-9,15,2,STONE:0)
Block(-9,15,3,STONE:0)
Block(-9,15,4,STONE:0)
Block(-9,16,-7,STONE:0)
Block(-9,16,-6,STONE:0)
Block(-9,16,-5,STONE:0)
Block(-9,16,-4,STONE:0)
Block(-9,16,-3,STONE:0)
Block(-9,16,-2,STONE:0)
Block(-9,16,-1,STONE:0)
Block(-9,16,0,STONE:0)
Block(-9,16,1,STONE:0)
Block(-9,16,2,STONE:0)
Block(-9,16,3,STONE:0)
Block(-9,16,4,STONE:0)
Block(-9,17,-7,STONE:0)
Block(-9,17,-6,STONE:0)
Block(-9,17,-5,STONE:0)
Block(-9,17,-4,STONE:0)
Block(-9,17,-3,STONE:0)
Block(-9,17,-2,STONE:0)
Block(-9,17,-1,STONE:0)
Block(-9,17,0,STONE:0)
Block(-9,17,1,STONE:0)
Block(-9,17,2,STONE:0)
Block(-9,17,3,STONE:0)
Block(-9,17,4,STONE:0)
Block(-9,18,-6,STONE:0)
Block(-9,18,-5,STONE:0)
Block(-9,18,-4,STONE:0)
Block(-9,18,-3,STONE:0)
Block(-9,18,-2,STONE:0)
Block(-9,18,-1,STONE:0)
Block(-9,18,0,STONE:0)
Block(-9,18,1,STONE:0)
Block(-9,18,2,STONE:0)
Block(-9,18,3,STONE:0)
Block(-9,19,-6,STONE:0)
Block(-9,19,-5,STONE:0)
Block(-9,19,-4,STONE:0)
Block(-9,19,-3,STONE:0)
Block(-9,19,-2,STONE:0)
Block(-9,19,-1,STONE:0)
Block(-9,19,0,STONE:0)
Block(-9,19,1,STONE:0)
Block(-9,19,2,STONE:0)
Block(-9,19,3,STONE:0)
Block(-9,20,-6,STONE:0)
Block(-9,20,-5,STONE:0)
Block(-9,20,-4,STONE:0)
Block(-9,20,-3,STONE:0)
Block(-9,20,-2,STONE:0)
Block(-9,20,-1,STONE:0)
Block(-9,20,0,STONE:0)
Block(-9,20,1,STONE:0)
Block(-9,20,2,STONE:0)
Block(-9,20,3,STONE:0)
Block(-9,21,-6,STONE:0)
Block(-9,21,-5,STONE:0)
Block(-9,21,-4,STONE:0)
Block(-9,21,-3,STONE:0)
Block(-9,21,-2,STONE:0)
Block(-9,21,-1,STONE:0)
Block(-9,21,0,STONE:0)
Block(-9,21,1,STONE:0)
Block(-9,21,2,STONE:0)
Block(-9,21,3,STONE:0)
Block(-9,22,-6,STONE:0)
Block(-9,22,-5,STONE:0)
Block(-9,22,-4,STONE:0)
Block(-9,22,-3,STONE:0)
Block(-9,22,-2,STONE:0)
Block(-9,22,-1,STONE:0)
Block(-9,22,0,STONE:0)
Block(-9,22,1,STONE:0)
Block(-9,22,2,STONE:0)
Block(-9,22,3,STONE:0)
Block(-9,23,-6,STONE:0)
Block(-9,23,-5,STONE:0)
Block(-9,23,-4,STONE:0)
Block(-9,23,-3,STONE:0)
Block(-9,23,-2,STONE:0)
Block(-9,23,-1,STONE:0)
Block(-9,23,0,STONE:0)
Block(-9,23,1,STONE:0)
Block(-9,23,2,STONE:0)
Block(-9,23,3,STONE:0)
Block(-9,24,-6,STONE:0)
Block(-9,24,-5,STONE:0)
Block(-9,24,-4,STONE:0)
Block(-9,24,-3,STONE:0)
Block(-9,24,-2,STONE:0)
Block(-9,24,-1,STONE:0)
Block(-9,24,0,STONE:0)
Block(-9,24,1,STONE:0)
Block(-9,24,2,STONE:0)
Block(-9,25,-6,STONE:0)
Block(-9,25,-5,STONE:0)
Block(-9,25,-4,STONE:0)
Block(-9,25,-3,STONE:0)
Block(-9,25,-2,STONE:0)
Block(-9,25,-1,STONE:0)
Block(-9,25,0,STONE:0)
Block(-9,25,1,STONE:0)
Block(-9,25,2,STONE:0)
Block(-9,26,-6,STONE:0)
Block(-9,26,-5,STONE:0)
Block(-9,26,-4,STONE:0)
Block(-9,26,-3,STONE:0)
Block(-9,26,-2,STONE:0)
Block(-9,26,-1,STONE:0)
Block(-9,26,0,STONE:0)
Block(-9,26,1,STONE:0)
Block(-9,26,2,STONE:0)
Block(-9,27,-5,STONE:0)
Block(-9,27,-4,STONE:0)
Block(-9,27,-3,STONE:0)
Block(-9,27,-2,STONE:0)
Block(-9,27,-1,STONE:0)
Block(-9,27,0,STONE:0)
Block(-9,27,1,STONE:0)
Block(-9,27,2,STONE:0)
Block(-9,28,-5,STONE:0)
Block(-9,28,-4,STONE:0)
Block(-9,28,-3,STONE:0)
Block(-9,28,-2,STONE:0)
Block(-9,28,-1,STONE:0)
Block(-9,28,0,STONE:0)
Block(-9,28,1,STONE:0)
Block(-9,28,2,STONE:0)
Block(-9,29,-5,STONE:0)
Block(-9,29,-4,STONE:0)
Block(-9,29,-3,STONE:0)
Block(-9,29,-2,STONE:0)
Block(-9,29,-1,STONE:0)
Block(-9,29,0,STONE:0)
Block(-9,29,1,STONE:0)
Block(-9,29,2,STONE:0)
Block(-9,30,-5,STONE:0)
Block(-9,30,-4,STONE:0)
Block(-9,30,-3,STONE:0)
Block(-9,30,-2,STONE:0)
Block(-9,30,-1,STONE:0)
Block(-9,30,0,STONE:0)
Block(-9,30,1,STONE:0)
Block(-9,30,2,STONE:0)
Block(-9,31,-5,STONE:0)
Block(-9,31,-4,STONE:0)
Block(-9,31,-3,STONE:0)
Block(-9,31,-2,STONE:0)
Block(-9,31,-1,STONE:0)
Block(-9,31,0,STONE:0)
Block(-9,31,1,STONE:0)
Block(-9,31,2,STONE:0)
Block(-9,32,-5,STONE:0)
Block(-9,32,-4,STONE:0)
Block(-9,32,-3,STONE:0)
Block(-9,32,-2,STONE:0)
Block(-9,32,-1,STONE:0)
Block(-9,32,0,STONE:0)
Block(-9,32,1,STONE:0)
Block(-9,32,2,STONE:0)
Block(-9,33,-4,STONE:0)
Block(-9,33,-3,STONE:0)
Block(-9,33,-2,STONE:0)
Block(-9,33,-1,STONE:0)
Block(-9,33,0,STONE:0)
Block(-9,33,1,STONE:0)
Block(-9,33,2,STONE:0)
Block(-9,34,-4,STONE:0)
Block(-9,34,-3,STONE:0)
Block(-9,34,-2,STONE:0)
Block(-9,34,-1,STONE:0)
Block(-9,34,0,STONE:0)
Block(-9,34,1,STONE:0)
Block(-9,34,2,STONE:0)
Block(-9,35,-4,STONE:0)
Block(-9,35,-3,STONE:0)
Block(-9,35,-2,STONE:0)
Block(-9,35,-1,STONE:0)
Block(-9,35,0,STONE:0)
Block(-9,35,1,STONE:0)
Block(-9,35,2,STONE:0)
Block(-9,36,-4,STONE:0)
Block(-9,36,-3,STONE:0)
Block(-9,36,-2,STONE:0)
Block(-9,36,-1,STONE:0)
Block(-9,36,0,STONE:0)
Block(-9,36,1,STONE:0)
Block(-9,36,2,STONE:0)
Block(-9,37,-4,STONE:0)
Block(-9,37,-3,STONE:0)
Block(-9,37,-2,STONE:0)
Block(-9,37,-1,STONE:0)
Block(-9,37,0,STONE:0)
Block(-9,37,1,STONE:0)
Block(-9,38,-4,STONE:0)
Block(-9,38,-3,STONE:0)
Block(-9,38,-2,STONE:0)
Block(-9,38,-1,STONE:0)
Block(-9,38,0,STONE:0)
Block(-9,38,1,STONE:0)
Block(-9,39,-4,STONE:0)
Block(-9,39,-3,STONE:0)
Block(-9,39,-2,STONE:0)
Block(-9,39,-1,STONE:0)
Block(-9,39,0,STONE:0)
Block(-9,39,1,STONE:0)
Block(-9,40,-4,STONE:0)
Block(-9,40,-3,STONE:0)
Block(-9,40,-2,STONE:0)
Block(-9,40,-1,STONE:0)
Block(-9,40,0,STONE:0)
Block(-9,40,1,STONE:0)
Block(-9,41,-4,STONE:0)
Block(-9,41,-3,STONE:0)
Block(-9,41,-2,STONE:0)
Block(-9,41,-1,STONE:0)
Block(-9,41,0,STONE:0)
Block(-9,41,1,STONE:0)
Block(-9,42,-4,STONE:0)
Block(-9,42,-3,STONE:0)
Block(-9,42,-2,STONE:0)
Block(-9,42,-1,STONE:0)
Block(-9,42,0,STONE:0)
Block(-9,42,1,STONE:0)
Block(-9,43,-3,STONE:0)
Block(-9,43,-2,STONE:0)
Block(-9,43,-1,STONE:0)
Block(-9,43,0,STONE:0)
Block(-9,43,1,STONE:0)
Block(-9,44,-3,STONE:0)
Block(-9,44,-2,STONE:0)
Block(-9,44,-1,STONE:0)
Block(-9,44,0,STONE:0)
Block(-9,44,1,STONE:0)
Block(-9,45,-3,STONE:0)
Block(-9,45,-2,STONE:0)
Block(-9,45,-1,STONE:0)
Block(-9,45,0,STONE:0)
Block(-9,45,1,STONE:0)
Block(-8,0,-11,STONE:0)
Block(-8,0,-10,STONE:0)
Block(-8,0,-9,STONE:0)
Block(-8,0,-8,STONE:0)
Block(-8,0,-7,STONE:0)
Block(-8,0,-6,STONE:0)
Block(-8,0,-5,STONE:0)
Block(-8,0,-4,STONE:0)
Block(-8,0,-3,STONE:0)
Block(-8,0,-2,STONE:0)
Block(-8,0,-1,STONE:0)
Block(-8,0,0,STONE:0)
Block(-8,0,1,STONE:0)
Block(-8,0,2,STONE:0)
Block(-8,0,3,STONE:0)
Block(-8,0,4,STONE:0)
Block(-8,0,5,STONE:0)
Block(-8,0,6,STONE:0)
Block(-8,0,7,STONE:0)
Block(-8,0,8,STONE:0)
Block(-8,0,9,STONE:0)
Block(-8,0,10,STONE:0)
Block(-8,1,-10,STONE:0)
Block(-8,1,-9,STONE:0)
Block(-8,1,-8,STONE:0)
Block(-8,1,-7,STONE:0)
Block(-8,1,-6,STONE:0)
Block(-8,1,-5,STONE:0)
Block(-8,1,-4,STONE:0)
Block(-8,1,-3,STONE:0)
Block(-8,1,-2,STONE:0)
Block(-8,1,-1,STONE:0)
Block(-8,1,0,STONE:0)
Block(-8,1,1,STONE:0)
Block(-8,1,2,STONE:0)
Block(-8,1,3,STONE:0)
Block(-8,1,4,STONE:0)
Block(-8,1,5,STONE:0)
Block(-8,1,6,STONE:0)
Block(-8,1,7,STONE:0)
Block(-8,1,8,STONE:0)
Block(-8,1,9,STONE:0)
Block(-8,2,-10,STONE:0)
Block(-8,2,-9,STONE:0)
Block(-8,2,-8,STONE:0)
Block(-8,2,-7,STONE:0)
Block(-8,2,-6,STONE:0)
Block(-8,2,-5,STONE:0)
Block(-8,2,-4,STONE:0)
Block(-8,2,-3,STONE:0)
Block(-8,2,-2,STONE:0)
Block(-8,2,-1,STONE:0)
Block(-8,2,0,STONE:0)
Block(-8,2,1,STONE:0)
Block(-8,2,2,STONE:0)
Block(-8,2,3,STONE:0)
Block(-8,2,4,STONE:0)
Block(-8,2,5,STONE:0)
Block(-8,2,6,STONE:0)
Block(-8,2,7,STONE:0)
Block(-8,2,8,STONE:0)
Block(-8,3,-10,STONE:0)
Block(-8,3,-9,STONE:0)
Block(-8,3,-8,STONE:0)
Block(-8,3,-7,STONE:0)
Block(-8,3,-6,STONE:0)
Block(-8,3,-5,STONE:0)
Block(-8,3,-4,STONE:0)
Block(-8,3,-3,STONE:0)
Block(-8,3,-2,STONE:0)
Block(-8,3,-1,STONE:0)
Block(-8,3,0,STONE:0)
Block(-8,3,1,STONE:0)
Block(-8,3,2,STONE:0)
Block(-8,3,3,STONE:0)
Block(-8,3,4,STONE:0)
Block(-8,3,5,STONE:0)
Block(-8,3,6,STONE:0)
Block(-8,3,7,STONE:0)
Block(-8,3,8,STONE:0)
Block(-8,4,-10,STONE:0)
Block(-8,4,-9,STONE:0)
Block(-8,4,-8,STONE:0)
Block(-8,4,-7,STONE:0)
Block(-8,4,-6,STONE:0)
Block(-8,4,-5,STONE:0)
Block(-8,4,-4,STONE:0)
Block(-8,4,-3,STONE:0)
Block(-8,4,-2,STONE:0)
Block(-8,4,-1,STONE:0)
Block(-8,4,0,STONE:0)
Block(-8,4,1,STONE:0)
Block(-8,4,2,STONE:0)
Block(-8,4,3,STONE:0)
Block(-8,4,4,STONE:0)
Block(-8,4,5,STONE:0)
Block(-8,4,6,STONE:0)
Block(-8,4,7,STONE:0)
Block(-8,4,8,STONE:0)
Block(-8,5,-10,STONE:0)
Block(-8,5,-9,STONE:0)
Block(-8,5,-8,STONE:0)
Block(-8,5,-7,STONE:0)
Block(-8,5,-6,STONE:0)
Block(-8,5,-5,STONE:0)
Block(-8,5,-4,STONE:0)
Block(-8,5,-3,STONE:0)
Block(-8,5,-2,STONE:0)
Block(-8,5,-1,STONE:0)
Block(-8,5,0,STONE:0)
Block(-8,5,1,STONE:0)
Block(-8,5,2,STONE:0)
Block(-8,5,3,STONE:0)
Block(-8,5,4,STONE:0)
Block(-8,5,5,STONE:0)
Block(-8,5,6,STONE:0)
Block(-8,5,7,STONE:0)
Block(-8,6,-9,STONE:0)
Block(-8,6,-8,STONE:0)
Block(-8,6,-7,STONE:0)
Block(-8,6,-6,STONE:0)
Block(-8,6,-5,STONE:0)
Block(-8,6,-4,STONE:0)
Block(-8,6,-3,STONE:0)
Block(-8,6,-2,STONE:0)
Block(-8,6,-1,STONE:0)
Block(-8,6,0,STONE:0)
Block(-8,6,1,STONE:0)
Block(-8,6,2,STONE:0)
Block(-8,6,3,STONE:0)
Block(-8,6,4,STONE:0)
Block(-8,6,5,STONE:0)
Block(-8,6,6,STONE:0)
Block(-8,6,7,STONE:0)
Block(-8,7,-9,STONE:0)
Block(-8,7,-8,STONE:0)
Block(-8,7,-7,STONE:0)
Block(-8,7,-6,STONE:0)
Block(-8,7,-5,STONE:0)
Block(-8,7,-4,STONE:0)
Block(-8,7,-3,STONE:0)
Block(-8,7,-2,STONE:0)
Block(-8,7,-1,STONE:0)
Block(-8,7,0,STONE:0)
Block(-8,7,1,STONE:0)
Block(-8,7,2,STONE:0)
Block(-8,7,3,STONE:0)
Block(-8,7,4,STONE:0)
Block(-8,7,5,STONE:0)
Block(-8,7,6,STONE:0)
Block(-8,7,7,STONE:0)
Block(-8,8,-9,STONE:0)
Block(-8,8,-8,STONE:0)
Block(-8,8,-7,STONE:0)
Block(-8,8,-6,STONE:0)
Block(-8,8,-5,STONE:0)
Block(-8,8,-4,STONE:0)
Block(-8,8,-3,STONE:0)
Block(-8,8,-2,STONE:0)
Block(-8,8,-1,STONE:0)
Block(-8,8,0,STONE:0)
Block(-8,8,1,STONE:0)
Block(-8,8,2,STONE:0)
Block(-8,8,3,STONE:0)
Block(-8,8,4,STONE:0)
Block(-8,8,5,STONE:0)
Block(-8,8,6,STONE:0)
Block(-8,8,7,STONE:0)
Block(-8,9,-9,STONE:0)
Block(-8,9,-8,STONE:0)
Block(-8,9,-7,STONE:0)
Block(-8,9,-6,STONE:0)
Block(-8,9,-5,STONE:0)
Block(-8,9,-4,STONE:0)
Block(-8,9,-3,STONE:0)
Block(-8,9,-2,STONE:0)
Block(-8,9,-1,STONE:0)
Block(-8,9,0,STONE:0)
Block(-8,9,1,STONE:0)
Block(-8,9,2,STONE:0)
Block(-8,9,3,STONE:0)
Block(-8,9,4,STONE:0)
Block(-8,9,5,STONE:0)
Block(-8,9,6,STONE:0)
Block(-8,9,7,STONE:0)
Block(-8,10,-9,STONE:0)
Block(-8,10,-8,STONE:0)
Block(-8,10,-7,STONE:0)
Block(-8,10,-6,STONE:0)
Block(-8,10,-5,STONE:0)
Block(-8,10,-4,STONE:0)
Block(-8,10,-3,STONE:0)
Block(-8,10,-2,STONE:0)
Block(-8,10,-1,STONE:0)
Block(-8,10,0,STONE:0)
Block(-8,10,1,STONE:0)
Block(-8,10,2,STONE:0)
Block(-8,10,3,STONE:0)
Block(-8,10,4,STONE:0)
Block(-8,10,5,STONE:0)
Block(-8,10,6,STONE:0)
Block(-8,11,-9,STONE:0)
Block(-8,11,-8,STONE:0)
Block(-8,11,-7,STONE:0)
Block(-8,11,-6,STONE:0)
Block(-8,11,-5,STONE:0)
Block(-8,11,-4,STONE:0)
Block(-8,11,-3,STONE:0)
Block(-8,11,-2,STONE:0)
Block(-8,11,-1,STONE:0)
Block(-8,11,0,STONE:0)
Block(-8,11,1,STONE:0)
Block(-8,11,2,STONE:0)
Block(-8,11,3,STONE:0)
Block(-8,11,4,STONE:0)
Block(-8,11,5,STONE:0)
Block(-8,11,6,STONE:0)
Block(-8,12,-8,STONE:0)
Block(-8,12,-7,STONE:0)
Block(-8,12,-6,STONE:0)
Block(-8,12,-5,STONE:0)
Block(-8,12,-4,STONE:0)
Block(-8,12,-3,STONE:0)
Block(-8,12,-2,STONE:0)
Block(-8,12,-1,STONE:0)
Block(-8,12,0,STONE:0)
Block(-8,12,1,STONE:0)
Block(-8,12,2,STONE:0)
Block(-8,12,3,STONE:0)
Block(-8,12,4,STONE:0)
Block(-8,12,5,STONE:0)
Block(-8,12,6,STONE:0)
Block(-8,13,-8,STONE:0)
Block(-8,13,-7,STONE:0)
Block(-8,13,-6,STONE:0)
Block(-8,13,-5,STONE:0)
Block(-8,13,-4,STONE:0)
Block(-8,13,-3,STONE:0)
Block(-8,13,-2,STONE:0)
Block(-8,13,-1,STONE:0)
Block(-8,13,0,STONE:0)
Block(-8,13,1,STONE:0)
Block(-8,13,2,STONE:0)
Block(-8,13,3,STONE:0)
Block(-8,13,4,STONE:0)
Block(-8,13,5,STONE:0)
Block(-8,13,6,STONE:0)
Block(-8,14,-8,STONE:0)
Block(-8,14,-7,STONE:0)
Block(-8,14,-6,STONE:0)
Block(-8,14,-5,STONE:0)
Block(-8,14,-4,STONE:0)
Block(-8,14,-3,STONE:0)
Block(-8,14,-2,STONE:0)
Block(-8,14,-1,STONE:0)
Block(-8,14,0,STONE:0)
Block(-8,14,1,STONE:0)
Block(-8,14,2,STONE:0)
Block(-8,14,3,STONE:0)
Block(-8,14,4,STONE:0)
Block(-8,14,5,STONE:0)
Block(-8,15,-8,STONE:0)
Block(-8,15,-7,STONE:0)
Block(-8,15,-6,STONE:0)
Block(-8,15,-5,STONE:0)
Block(-8,15,-4,STONE:0)
Block(-8,15,-3,STONE:0)
Block(-8,15,-2,STONE:0)
Block(-8,15,-1,STONE:0)
Block(-8,15,0,STONE:0)
Block(-8,15,1,STONE:0)
Block(-8,15,2,STONE:0)
Block(-8,15,3,STONE:0)
Block(-8,15,4,STONE:0)
Block(-8,15,5,STONE:0)
Block(-8,16,-8,STONE:0)
Block(-8,16,-7,STONE:0)
Block(-8,16,-6,STONE:0)
Block(-8,16,-5,STONE:0)
Block(-8,16,-4,STONE:0)
Block(-8,16,-3,STONE:0)
Block(-8,16,-2,STONE:0)
Block(-8,16,-1,STONE:0)
Block(-8,16,0,STONE:0)
Block(-8,16,1,STONE:0)
Block(-8,16,2,STONE:0)
Block(-8,16,3,STONE:0)
Block(-8,16,4,STONE:0)
Block(-8,16,5,STONE:0)
Block(-8,17,-7,STONE:0)
Block(-8,17,-6,STONE:0)
Block(-8,17,-5,STONE:0)
Block(-8,17,-4,STONE:0)
Block(-8,17,-3,STONE:0)
Block(-8,17,-2,STONE:0)
Block(-8,17,-1,STONE:0)
Block(-8,17,0,STONE:0)
Block(-8,17,1,STONE:0)
Block(-8,17,2,STONE:0)
Block(-8,17,3,STONE:0)
Block(-8,17,4,STONE:0)
Block(-8,17,5,STONE:0)
Block(-8,18,-7,STONE:0)
Block(-8,18,-6,STONE:0)
Block(-8,18,-5,STONE:0)
Block(-8,18,-4,STONE:0)
Block(-8,18,-3,STONE:0)
Block(-8,18,-2,STONE:0)
Block(-8,18,-1,STONE:0)
Block(-8,18,0,STONE:0)
Block(-8,18,1,STONE:0)
Block(-8,18,2,STONE:0)
Block(-8,18,3,STONE:0)
Block(-8,18,4,STONE:0)
Block(-8,19,-7,STONE:0)
Block(-8,19,-6,STONE:0)
Block(-8,19,-5,STONE:0)
Block(-8,19,-4,STONE:0)
Block(-8,19,-3,STONE:0)
Block(-8,19,-2,STONE:0)
Block(-8,19,-1,STONE:0)
Block(-8,19,0,STONE:0)
Block(-8,19,1,STONE:0)
Block(-8,19,2,STONE:0)
Block(-8,19,3,STONE:0)
Block(-8,19,4,STONE:0)
Block(-8,20,-7,STONE:0)
Block(-8,20,-6,STONE:0)
Block(-8,20,-5,STONE:0)
Block(-8,20,-4,STONE:0)
Block(-8,20,-3,STONE:0)
Block(-8,20,-2,STONE:0)
Block(-8,20,-1,STONE:0)
Block(-8,20,0,STONE:0)
Block(-8,20,1,STONE:0)
Block(-8,20,2,STONE:0)
Block(-8,20,3,STONE:0)
Block(-8,20,4,STONE:0)
Block(-8,21,-7,STONE:0)
Block(-8,21,-6,STONE:0)
Block(-8,21,-5,STONE:0)
Block(-8,21,-4,STONE:0)
Block(-8,21,-3,STONE:0)
Block(-8,21,-2,STONE:0)
Block(-8,21,-1,STONE:0)
Block(-8,21,0,STONE:0)
Block(-8,21,1,STONE:0)
Block(-8,21,2,STONE:0)
Block(-8,21,3,STONE:0)
Block(-8,21,4,STONE:0)
Block(-8,22,-7,STONE:0)
Block(-8,22,-6,STONE:0)
Block(-8,22,-5,STONE:0)
Block(-8,22,-4,STONE:0)
Block(-8,22,-3,STONE:0)
Block(-8,22,-2,STONE:0)
Block(-8,22,-1,STONE:0)
Block(-8,22,0,STONE:0)
Block(-8,22,1,STONE:0)
Block(-8,22,2,STONE:0)
Block(-8,22,3,STONE:0)
Block(-8,23,-7,STONE:0)
Block(-8,23,-6,STONE:0)
Block(-8,23,-5,STONE:0)
Block(-8,23,-4,STONE:0)
Block(-8,23,-3,STONE:0)
Block(-8,23,-2,STONE:0)
Block(-8,23,-1,STONE:0)
Block(-8,23,0,STONE:0)
Block(-8,23,1,STONE:0)
Block(-8,23,2,STONE:0)
Block(-8,23,3,STONE:0)
Block(-8,24,-7,STONE:0)
Block(-8,24,-6,STONE:0)
Block(-8,24,-5,STONE:0)
Block(-8,24,-4,STONE:0)
Block(-8,24,-3,STONE:0)
Block(-8,24,-2,STONE:0)
Block(-8,24,-1,STONE:0)
Block(-8,24,0,STONE:0)
Block(-8,24,1,STONE:0)
Block(-8,24,2,STONE:0)
Block(-8,24,3,STONE:0)
Block(-8,25,-6,STONE:0)
Block(-8,25,-5,STONE:0)
Block(-8,25,-4,STONE:0)
Block(-8,25,-3,STONE:0)
Block(-8,25,-2,STONE:0)
Block(-8,25,-1,STONE:0)
Block(-8,25,0,STONE:0)
Block(-8,25,1,STONE:0)
Block(-8,25,2,STONE:0)
Block(-8,25,3,STONE:0)
Block(-8,26,-6,STONE:0)
Block(-8,26,-5,STONE:0)
Block(-8,26,-4,STONE:0)
Block(-8,26,-3,STONE:0)
Block(-8,26,-2,STONE:0)
Block(-8,26,-1,STONE:0)
Block(-8,26,0,STONE:0)
Block(-8,26,1,STONE:0)
Block(-8,26,2,STONE:0)
Block(-8,26,3,STONE:0)
Block(-8,27,-6,STONE:0)
Block(-8,27,-5,STONE:0)
Block(-8,27,-4,STONE:0)
Block(-8,27,-3,STONE:0)
Block(-8,27,-2,STONE:0)
Block(-8,27,-1,STONE:0)
Block(-8,27,0,STONE:0)
Block(-8,27,1,STONE:0)
Block(-8,27,2,STONE:0)
Block(-8,27,3,STONE:0)
Block(-8,28,-6,STONE:0)
Block(-8,28,-5,STONE:0)
Block(-8,28,-4,STONE:0)
Block(-8,28,-3,STONE:0)
Block(-8,28,-2,STONE:0)
Block(-8,28,-1,STONE:0)
Block(-8,28,0,STONE:0)
Block(-8,28,1,STONE:0)
Block(-8,28,2,STONE:0)
Block(-8,28,3,STONE:0)
Block(-8,29,-6,STONE:0)
Block(-8,29,-5,STONE:0)
Block(-8,29,-4,STONE:0)
Block(-8,29,-3,STONE:0)
Block(-8,29,-2,STONE:0)
Block(-8,29,-1,STONE:0)
Block(-8,29,0,STONE:0)
Block(-8,29,1,STONE:0)
Block(-8,29,2,STONE:0)
Block(-8,29,3,STONE:0)
Block(-8,30,-6,STONE:0)
Block(-8,30,-5,STONE:0)
Block(-8,30,-4,STONE:0)
Block(-8,30,-3,STONE:0)
Block(-8,30,-2,STONE:0)
Block(-8,30,-1,STONE:0)
Block(-8,30,0,STONE:0)
Block(-8,30,1,STONE:0)
Block(-8,30,2,STONE:0)
Block(-8,30,3,STONE:0)
Block(-8,31,-6,STONE:0)
Block(-8,31,-5,STONE:0)
Block(-8,31,-4,STONE:0)
Block(-8,31,-3,STONE:0)
Block(-8,31,-2,STONE:0)
Block(-8,31,-1,STONE:0)
Block(-8,31,0,STONE:0)
Block(-8,31,1,STONE:0)
Block(-8,31,2,STONE:0)
Block(-8,32,-6,STONE:0)
Block(-8,32,-5,STONE:0)
Block(-8,32,-4,STONE:0)
Block(-8,32,-3,STONE:0)
Block(-8,32,-2,STONE:0)
Block(-8,32,-1,STONE:0)
Block(-8,32,0,STONE:0)
Block(-8,32,1,STONE:0)
Block(-8,32,2,STONE:0)
Block(-8,33,-6,STONE:0)
Block(-8,33,-5,STONE:0)
Block(-8,33,-4,STONE:0)
Block(-8,33,-3,STONE:0)
Block(-8,33,-2,STONE:0)
Block(-8,33,-1,STONE:0)
Block(-8,33,0,STONE:0)
Block(-8,33,1,STONE:0)
Block(-8,33,2,STONE:0)
Block(-8,34,-6,STONE:0)
Block(-8,34,-5,STONE:0)
Block(-8,34,-4,STONE:0)
Block(-8,34,-3,STONE:0)
Block(-8,34,-2,STONE:0)
Block(-8,34,-1,STONE:0)
Block(-8,34,0,STONE:0)
Block(-8,34,1,STONE:0)
Block(-8,34,2,STONE:0)
Block(-8,35,-6,STONE:0)
Block(-8,35,-5,STONE:0)
Block(-8,35,-4,STONE:0)
Block(-8,35,-3,STONE:0)
Block(-8,35,-2,STONE:0)
Block(-8,35,-1,STONE:0)
Block(-8,35,0,STONE:0)
Block(-8,35,1,STONE:0)
Block(-8,35,2,STONE:0)
Block(-8,36,-6,STONE:0)
Block(-8,36,-5,STONE:0)
Block(-8,36,-4,STONE:0)
Block(-8,36,-3,STONE:0)
Block(-8,36,-2,STONE:0)
Block(-8,36,-1,STONE:0)
Block(-8,36,0,STONE:0)
Block(-8,36,1,STONE:0)
Block(-8,36,2,STONE:0)
Block(-8,37,-5,STONE:0)
Block(-8,37,-4,STONE:0)
Block(-8,37,-3,STONE:0)
Block(-8,37,-2,STONE:0)
Block(-8,37,-1,STONE:0)
Block(-8,37,0,STONE:0)
Block(-8,37,1,STONE:0)
Block(-8,37,2,STONE:0)
Block(-8,38,-5,STONE:0)
Block(-8,38,-4,STONE:0)
Block(-8,38,-3,STONE:0)
Block(-8,38,-2,STONE:0)
Block(-8,38,-1,STONE:0)
Block(-8,38,0,STONE:0)
Block(-8,38,1,STONE:0)
Block(-8,38,2,STONE:0)
Block(-8,39,-5,STONE:0)
Block(-8,39,-4,STONE:0)
Block(-8,39,-3,STONE:0)
Block(-8,39,-2,STONE:0)
Block(-8,39,-1,STONE:0)
Block(-8,39,0,STONE:0)
Block(-8,39,1,STONE:0)
Block(-8,39,2,STONE:0)
Block(-8,40,-5,STONE:0)
Block(-8,40,-4,STONE:0)
Block(-8,40,-3,STONE:0)
Block(-8,40,-2,STONE:0)
Block(-8,40,-1,STONE:0)
Block(-8,40,0,STONE:0)
Block(-8,40,1,STONE:0)
Block(-8,40,2,STONE:0)
Block(-8,41,-5,STONE:0)
Block(-8,41,-4,STONE:0)
Block(-8,41,-3,STONE:0)
Block(-8,41,-2,STONE:0)
Block(-8,41,-1,STONE:0)
Block(-8,41,0,STONE:0)
Block(-8,41,1,STONE:0)
Block(-8,41,2,STONE:0)
Block(-8,42,-5,STONE:0)
Block(-8,42,-4,STONE:0)
Block(-8,42,-3,STONE:0)
Block(-8,42,-2,STONE:0)
Block(-8,42,-1,STONE:0)
Block(-8,42,0,STONE:0)
Block(-8,42,1,STONE:0)
Block(-8,42,2,STONE:0)
Block(-8,43,-5,STONE:0)
Block(-8,43,-4,STONE:0)
Block(-8,43,-3,STONE:0)
Block(-8,43,-2,STONE:0)
Block(-8,43,-1,STONE:0)
Block(-8,43,0,STONE:0)
Block(-8,43,1,STONE:0)
Block(-8,43,2,STONE:0)
Block(-8,44,-5,STONE:0)
Block(-8,44,-4,STONE:0)
Block(-8,44,-3,STONE:0)
Block(-8,44,-2,STONE:0)
Block(-8,44,-1,STONE:0)
Block(-8,44,0,STONE:0)
Block(-8,44,1,STONE:0)
Block(-8,45,-5,STONE:0)
Block(-8,45,-4,STONE:0)
Block(-8,45,-3,STONE:0)
Block(-8,45,-2,GRASS:0)
Block(-8,45,-1,GRASS:0)
Block(-8,45,0,GRASS:0)
Block(-8,45,1,STONE:0)
Block(-7,0,-13,STONE:0)
Block(-7,0,-12,STONE:0)
Block(-7,0,-11,STONE:0)
Block(-7,0,-10,STONE:0)
Block(-7,0,-9,STONE:0)
Block(-7,0,-8,STONE:0)
Block(-7,0,-7,STONE:0)
Block(-7,0,-6,STONE:0)
Block(-7,0,-5,STONE:0)
Block(-7,0,-4,STONE:0)
Block(-7,0,-3,STONE:0)
Block(-7,0,-2,STONE:0)
Block(-7,0,-1,STONE:0)
Block(-7,0,0,STONE:0)
Block(-7,0,1,STONE:0)
Block(-7,0,2,STONE:0)
Block(-7,0,3,STONE:0)
Block(-7,0,4,STONE:0)
Block(-7,0,5,STONE:0)
Block(-7,0,6,STONE:0)
Block(-7,0,7,STONE:0)
Block(-7,0,8,STONE:0)
Block(-7,0,9,STONE:0)
Block(-7,0,10,STONE:0)
Block(-7,0,11,STONE:0)
Block(-7,1,-13,STONE:0)
Block(-7,1,-12,STONE:0)
Block(-7,1,-11,STONE:0)
Block(-7,1,-10,STONE:0)
Block(-7,1,-9,STONE:0)
Block(-7,1,-8,STONE:0)
Block(-7,1,-7,STONE:0)
Block(-7,1,-6,STONE:0)
Block(-7,1,-5,STONE:0)
Block(-7,1,-4,STONE:0)
Block(-7,1,-3,STONE:0)
Block(-7,1,-2,STONE:0)
Block(-7,1,-1,STONE:0)
Block(-7,1,0,STONE:0)
Block(-7,1,1,STONE:0)
Block(-7,1,2,STONE:0)
Block(-7,1,3,STONE:0)
Block(-7,1,4,STONE:0)
Block(-7,1,5,STONE:0)
Block(-7,1,6,STONE:0)
Block(-7,1,7,STONE:0)
Block(-7,1,8,STONE:0)
Block(-7,1,9,STONE:0)
Block(-7,1,10,STONE:0)
Block(-7,2,-13,STONE:0)
Block(-7,2,-12,STONE:0)
Block(-7,2,-11,STONE:0)
Block(-7,2,-10,STONE:0)
Block(-7,2,-9,STONE:0)
Block(-7,2,-8,STONE:0)
Block(-7,2,-7,STONE:0)
Block(-7,2,-6,STONE:0)
Block(-7,2,-5,STONE:0)
Block(-7,2,-4,STONE:0)
Block(-7,2,-3,STONE:0)
Block(-7,2,-2,STONE:0)
Block(-7,2,-1,STONE:0)
Block(-7,2,0,STONE:0)
Block(-7,2,1,STONE:0)
Block(-7,2,2,STONE:0)
Block(-7,2,3,STONE:0)
Block(-7,2,4,STONE:0)
Block(-7,2,5,STONE:0)
Block(-7,2,6,STONE:0)
Block(-7,2,7,STONE:0)
Block(-7,2,8,STONE:0)
Block(-7,2,9,STONE:0)
Block(-7,2,10,STONE:0)
Block(-7,3,-12,STONE:0)
Block(-7,3,-11,STONE:0)
Block(-7,3,-10,STONE:0)
Block(-7,3,-9,STONE:0)
Block(-7,3,-8,STONE:0)
Block(-7,3,-7,STONE:0)
Block(-7,3,-6,STONE:0)
Block(-7,3,-5,STONE:0)
Block(-7,3,-4,STONE:0)
Block(-7,3,-3,STONE:0)
Block(-7,3,-2,STONE:0)
Block(-7,3,-1,STONE:0)
Block(-7,3,0,STONE:0)
Block(-7,3,1,STONE:0)
Block(-7,3,2,STONE:0)
Block(-7,3,3,STONE:0)
Block(-7,3,4,STONE:0)
Block(-7,3,5,STONE:0)
Block(-7,3,6,STONE:0)
Block(-7,3,7,STONE:0)
Block(-7,3,8,STONE:0)
Block(-7,3,9,STONE:0)
Block(-7,3,10,STONE:0)
Block(-7,4,-12,STONE:0)
Block(-7,4,-11,STONE:0)
Block(-7,4,-10,STONE:0)
Block(-7,4,-9,STONE:0)
Block(-7,4,-8,STONE:0)
Block(-7,4,-7,STONE:0)
Block(-7,4,-6,STONE:0)
Block(-7,4,-5,STONE:0)
Block(-7,4,-4,STONE:0)
Block(-7,4,-3,STONE:0)
Block(-7,4,-2,STONE:0)
Block(-7,4,-1,STONE:0)
Block(-7,4,0,STONE:0)
Block(-7,4,1,STONE:0)
Block(-7,4,2,STONE:0)
Block(-7,4,3,STONE:0)
Block(-7,4,4,STONE:0)
Block(-7,4,5,STONE:0)
Block(-7,4,6,STONE:0)
Block(-7,4,7,STONE:0)
Block(-7,4,8,STONE:0)
Block(-7,4,9,STONE:0)
Block(-7,4,10,STONE:0)
Block(-7,5,-12,STONE:0)
Block(-7,5,-11,STONE:0)
Block(-7,5,-10,STONE:0)
Block(-7,5,-9,STONE:0)
Block(-7,5,-8,STONE:0)
Block(-7,5,-7,STONE:0)
Block(-7,5,-6,STONE:0)
Block(-7,5,-5,STONE:0)
Block(-7,5,-4,STONE:0)
Block(-7,5,-3,STONE:0)
Block(-7,5,-2,STONE:0)
Block(-7,5,-1,STONE:0)
Block(-7,5,0,STONE:0)
Block(-7,5,1,STONE:0)
Block(-7,5,2,STONE:0)
Block(-7,5,3,STONE:0)
Block(-7,5,4,STONE:0)
Block(-7,5,5,STONE:0)
Block(-7,5,6,STONE:0)
Block(-7,5,7,STONE:0)
Block(-7,5,8,STONE:0)
Block(-7,5,9,STONE:0)
Block(-7,6,-12,STONE:0)
Block(-7,6,-11,STONE:0)
Block(-7,6,-10,STONE:0)
Block(-7,6,-9,STONE:0)
Block(-7,6,-8,STONE:0)
Block(-7,6,-7,STONE:0)
Block(-7,6,-6,STONE:0)
Block(-7,6,-5,STONE:0)
Block(-7,6,-4,STONE:0)
Block(-7,6,-3,STONE:0)
Block(-7,6,-2,STONE:0)
Block(-7,6,-1,STONE:0)
Block(-7,6,0,STONE:0)
Block(-7,6,1,STONE:0)
Block(-7,6,2,STONE:0)
Block(-7,6,3,STONE:0)
Block(-7,6,4,STONE:0)
Block(-7,6,5,STONE:0)
Block(-7,6,6,STONE:0)
Block(-7,6,7,STONE:0)
Block(-7,6,8,STONE:0)
Block(-7,6,9,STONE:0)
Block(-7,7,-11,STONE:0)
Block(-7,7,-10,STONE:0)
Block(-7,7,-9,STONE:0)
Block(-7,7,-8,STONE:0)
Block(-7,7,-7,STONE:0)
Block(-7,7,-6,STONE:0)
Block(-7,7,-5,STONE:0)
Block(-7,7,-4,STONE:0)
Block(-7,7,-3,STONE:0)
Block(-7,7,-2,STONE:0)
Block(-7,7,-1,STONE:0)
Block(-7,7,0,STONE:0)
Block(-7,7,1,STONE:0)
Block(-7,7,2,STONE:0)
Block(-7,7,3,STONE:0)
Block(-7,7,4,STONE:0)
Block(-7,7,5,STONE:0)
Block(-7,7,6,STONE:0)
Block(-7,7,7,STONE:0)
Block(-7,7,8,STONE:0)
Block(-7,7,9,STONE:0)
Block(-7,8,-11,STONE:0)
Block(-7,8,-10,STONE:0)
Block(-7,8,-9,STONE:0)
Block(-7,8,-8,STONE:0)
Block(-7,8,-7,STONE:0)
Block(-7,8,-6,STONE:0)
Block(-7,8,-5,STONE:0)
Block(-7,8,-4,STONE:0)
Block(-7,8,-3,STONE:0)
Block(-7,8,-2,STONE:0)
Block(-7,8,-1,STONE:0)
Block(-7,8,0,STONE:0)
Block(-7,8,1,STONE:0)
Block(-7,8,2,STONE:0)
Block(-7,8,3,STONE:0)
Block(-7,8,4,STONE:0)
Block(-7,8,5,STONE:0)
Block(-7,8,6,STONE:0)
Block(-7,8,7,STONE:0)
Block(-7,8,8,STONE:0)
Block(-7,9,-10,STONE:0)
Block(-7,9,-9,STONE:0)
Block(-7,9,-8,STONE:0)
Block(-7,9,-7,STONE:0)
Block(-7,9,-6,STONE:0)
Block(-7,9,-5,STONE:0)
Block(-7,9,-4,STONE:0)
Block(-7,9,-3,STONE:0)
Block(-7,9,-2,STONE:0)
Block(-7,9,-1,STONE:0)
Block(-7,9,0,STONE:0)
Block(-7,9,1,STONE:0)
Block(-7,9,2,STONE:0)
Block(-7,9,3,STONE:0)
Block(-7,9,4,STONE:0)
Block(-7,9,5,STONE:0)
Block(-7,9,6,STONE:0)
Block(-7,9,7,STONE:0)
Block(-7,9,8,STONE:0)
Block(-7,10,-10,STONE:0)
Block(-7,10,-9,STONE:0)
Block(-7,10,-8,STONE:0)
Block(-7,10,-7,STONE:0)
Block(-7,10,-6,STONE:0)
Block(-7,10,-5,STONE:0)
Block(-7,10,-4,STONE:0)
Block(-7,10,-3,STONE:0)
Block(-7,10,-2,STONE:0)
Block(-7,10,-1,STONE:0)
Block(-7,10,0,STONE:0)
Block(-7,10,1,STONE:0)
Block(-7,10,2,STONE:0)
Block(-7,10,3,STONE:0)
Block(-7,10,4,STONE:0)
Block(-7,10,5,STONE:0)
Block(-7,10,6,STONE:0)
Block(-7,10,7,STONE:0)
Block(-7,11,-10,STONE:0)
Block(-7,11,-9,STONE:0)
Block(-7,11,-8,STONE:0)
Block(-7,11,-7,STONE:0)
Block(-7,11,-6,STONE:0)
Block(-7,11,-5,STONE:0)
Block(-7,11,-4,STONE:0)
Block(-7,11,-3,STONE:0)
Block(-7,11,-2,STONE:0)
Block(-7,11,-1,STONE:0)
Block(-7,11,0,STONE:0)
Block(-7,11,1,STONE:0)
Block(-7,11,2,STONE:0)
Block(-7,11,3,STONE:0)
Block(-7,11,4,STONE:0)
Block(-7,11,5,STONE:0)
Block(-7,11,6,STONE:0)
Block(-7,11,7,STONE:0)
Block(-7,12,-9,STONE:0)
Block(-7,12,-8,STONE:0)
Block(-7,12,-7,STONE:0)
Block(-7,12,-6,STONE:0)
Block(-7,12,-5,STONE:0)
Block(-7,12,-4,STONE:0)
Block(-7,12,-3,STONE:0)
Block(-7,12,-2,STONE:0)
Block(-7,12,-1,STONE:0)
Block(-7,12,0,STONE:0)
Block(-7,12,1,STONE:0)
Block(-7,12,2,STONE:0)
Block(-7,12,3,STONE:0)
Block(-7,12,4,STONE:0)
Block(-7,12,5,STONE:0)
Block(-7,12,6,STONE:0)
Block(-7,13,-9,STONE:0)
Block(-7,13,-8,STONE:0)
Block(-7,13,-7,STONE:0)
Block(-7,13,-6,STONE:0)
Block(-7,13,-5,STONE:0)
Block(-7,13,-4,STONE:0)
Block(-7,13,-3,STONE:0)
Block(-7,13,-2,STONE:0)
Block(-7,13,-1,STONE:0)
Block(-7,13,0,STONE:0)
Block(-7,13,1,STONE:0)
Block(-7,13,2,STONE:0)
Block(-7,13,3,STONE:0)
Block(-7,13,4,STONE:0)
Block(-7,13,5,STONE:0)
Block(-7,13,6,STONE:0)
Block(-7,14,-9,STONE:0)
Block(-7,14,-8,STONE:0)
Block(-7,14,-7,STONE:0)
Block(-7,14,-6,STONE:0)
Block(-7,14,-5,STONE:0)
Block(-7,14,-4,STONE:0)
Block(-7,14,-3,STONE:0)
Block(-7,14,-2,STONE:0)
Block(-7,14,-1,STONE:0)
Block(-7,14,0,STONE:0)
Block(-7,14,1,STONE:0)
Block(-7,14,2,STONE:0)
Block(-7,14,3,STONE:0)
Block(-7,14,4,STONE:0)
Block(-7,14,5,STONE:0)
Block(-7,14,6,STONE:0)
Block(-7,15,-9,STONE:0)
Block(-7,15,-8,STONE:0)
Block(-7,15,-7,STONE:0)
Block(-7,15,-6,STONE:0)
Block(-7,15,-5,STONE:0)
Block(-7,15,-4,STONE:0)
Block(-7,15,-3,STONE:0)
Block(-7,15,-2,STONE:0)
Block(-7,15,-1,STONE:0)
Block(-7,15,0,STONE:0)
Block(-7,15,1,STONE:0)
Block(-7,15,2,STONE:0)
Block(-7,15,3,STONE:0)
Block(-7,15,4,STONE:0)
Block(-7,15,5,STONE:0)
Block(-7,15,6,STONE:0)
Block(-7,16,-8,STONE:0)
Block(-7,16,-7,STONE:0)
Block(-7,16,-6,STONE:0)
Block(-7,16,-5,STONE:0)
Block(-7,16,-4,STONE:0)
Block(-7,16,-3,STONE:0)
Block(-7,16,-2,STONE:0)
Block(-7,16,-1,STONE:0)
Block(-7,16,0,STONE:0)
Block(-7,16,1,STONE:0)
Block(-7,16,2,STONE:0)
Block(-7,16,3,STONE:0)
Block(-7,16,4,STONE:0)
Block(-7,16,5,STONE:0)
Block(-7,16,6,STONE:0)
Block(-7,17,-8,STONE:0)
Block(-7,17,-7,STONE:0)
Block(-7,17,-6,STONE:0)
Block(-7,17,-5,STONE:0)
Block(-7,17,-4,STONE:0)
Block(-7,17,-3,STONE:0)
Block(-7,17,-2,STONE:0)
Block(-7,17,-1,STONE:0)
Block(-7,17,0,STONE:0)
Block(-7,17,1,STONE:0)
Block(-7,17,2,STONE:0)
Block(-7,17,3,STONE:0)
Block(-7,17,4,STONE:0)
Block(-7,17,5,STONE:0)
Block(-7,18,-8,STONE:0)
Block(-7,18,-7,STONE:0)
Block(-7,18,-6,STONE:0)
Block(-7,18,-5,STONE:0)
Block(-7,18,-4,STONE:0)
Block(-7,18,-3,STONE:0)
Block(-7,18,-2,STONE:0)
Block(-7,18,-1,STONE:0)
Block(-7,18,0,STONE:0)
Block(-7,18,1,STONE:0)
Block(-7,18,2,STONE:0)
Block(-7,18,3,STONE:0)
Block(-7,18,4,STONE:0)
Block(-7,18,5,STONE:0)
Block(-7,19,-8,STONE:0)
Block(-7,19,-7,STONE:0)
Block(-7,19,-6,STONE:0)
Block(-7,19,-5,STONE:0)
Block(-7,19,-4,STONE:0)
Block(-7,19,-3,STONE:0)
Block(-7,19,-2,STONE:0)
Block(-7,19,-1,STONE:0)
Block(-7,19,0,STONE:0)
Block(-7,19,1,STONE:0)
Block(-7,19,2,STONE:0)
Block(-7,19,3,STONE:0)
Block(-7,19,4,STONE:0)
Block(-7,19,5,STONE:0)
Block(-7,20,-8,STONE:0)
Block(-7,20,-7,STONE:0)
Block(-7,20,-6,STONE:0)
Block(-7,20,-5,STONE:0)
Block(-7,20,-4,STONE:0)
Block(-7,20,-3,STONE:0)
Block(-7,20,-2,STONE:0)
Block(-7,20,-1,STONE:0)
Block(-7,20,0,STONE:0)
Block(-7,20,1,STONE:0)
Block(-7,20,2,STONE:0)
Block(-7,20,3,STONE:0)
Block(-7,20,4,STONE:0)
Block(-7,20,5,STONE:0)
Block(-7,21,-8,STONE:0)
Block(-7,21,-7,STONE:0)
Block(-7,21,-6,STONE:0)
Block(-7,21,-5,STONE:0)
Block(-7,21,-4,STONE:0)
Block(-7,21,-3,STONE:0)
Block(-7,21,-2,STONE:0)
Block(-7,21,-1,STONE:0)
Block(-7,21,0,STONE:0)
Block(-7,21,1,STONE:0)
Block(-7,21,2,STONE:0)
Block(-7,21,3,STONE:0)
Block(-7,21,4,STONE:0)
Block(-7,21,5,STONE:0)
Block(-7,22,-7,STONE:0)
Block(-7,22,-6,STONE:0)
Block(-7,22,-5,STONE:0)
Block(-7,22,-4,STONE:0)
Block(-7,22,-3,STONE:0)
Block(-7,22,-2,STONE:0)
Block(-7,22,-1,STONE:0)
Block(-7,22,0,STONE:0)
Block(-7,22,1,STONE:0)
Block(-7,22,2,STONE:0)
Block(-7,22,3,STONE:0)
Block(-7,22,4,STONE:0)
Block(-7,22,5,STONE:0)
Block(-7,23,-7,STONE:0)
Block(-7,23,-6,STONE:0)
Block(-7,23,-5,STONE:0)
Block(-7,23,-4,STONE:0)
Block(-7,23,-3,STONE:0)
Block(-7,23,-2,STONE:0)
Block(-7,23,-1,STONE:0)
Block(-7,23,0,STONE:0)
Block(-7,23,1,STONE:0)
Block(-7,23,2,STONE:0)
Block(-7,23,3,STONE:0)
Block(-7,23,4,STONE:0)
Block(-7,23,5,STONE:0)
Block(-7,24,-7,STONE:0)
Block(-7,24,-6,STONE:0)
Block(-7,24,-5,STONE:0)
Block(-7,24,-4,STONE:0)
Block(-7,24,-3,STONE:0)
Block(-7,24,-2,STONE:0)
Block(-7,24,-1,STONE:0)
Block(-7,24,0,STONE:0)
Block(-7,24,1,STONE:0)
Block(-7,24,2,STONE:0)
Block(-7,24,3,STONE:0)
Block(-7,24,4,STONE:0)
Block(-7,24,5,STONE:0)
Block(-7,25,-7,STONE:0)
Block(-7,25,-6,STONE:0)
Block(-7,25,-5,STONE:0)
Block(-7,25,-4,STONE:0)
Block(-7,25,-3,STONE:0)
Block(-7,25,-2,STONE:0)
Block(-7,25,-1,STONE:0)
Block(-7,25,0,STONE:0)
Block(-7,25,1,STONE:0)
Block(-7,25,2,STONE:0)
Block(-7,25,3,STONE:0)
Block(-7,25,4,STONE:0)
Block(-7,26,-7,STONE:0)
Block(-7,26,-6,STONE:0)
Block(-7,26,-5,STONE:0)
Block(-7,26,-4,STONE:0)
Block(-7,26,-3,STONE:0)
Block(-7,26,-2,STONE:0)
Block(-7,26,-1,STONE:0)
Block(-7,26,0,STONE:0)
Block(-7,26,1,STONE:0)
Block(-7,26,2,STONE:0)
Block(-7,26,3,STONE:0)
Block(-7,26,4,STONE:0)
Block(-7,27,-7,STONE:0)
Block(-7,27,-6,STONE:0)
Block(-7,27,-5,STONE:0)
Block(-7,27,-4,STONE:0)
Block(-7,27,-3,STONE:0)
Block(-7,27,-2,STONE:0)
Block(-7,27,-1,STONE:0)
Block(-7,27,0,STONE:0)
Block(-7,27,1,STONE:0)
Block(-7,27,2,STONE:0)
Block(-7,27,3,STONE:0)
Block(-7,27,4,STONE:0)
Block(-7,28,-7,STONE:0)
Block(-7,28,-6,STONE:0)
Block(-7,28,-5,STONE:0)
Block(-7,28,-4,STONE:0)
Block(-7,28,-3,STONE:0)
Block(-7,28,-2,STONE:0)
Block(-7,28,-1,STONE:0)
Block(-7,28,0,STONE:0)
Block(-7,28,1,STONE:0)
Block(-7,28,2,STONE:0)
Block(-7,28,3,STONE:0)
Block(-7,28,4,STONE:0)
Block(-7,29,-7,STONE:0)
Block(-7,29,-6,STONE:0)
Block(-7,29,-5,STONE:0)
Block(-7,29,-4,STONE:0)
Block(-7,29,-3,STONE:0)
Block(-7,29,-2,STONE:0)
Block(-7,29,-1,STONE:0)
Block(-7,29,0,STONE:0)
Block(-7,29,1,STONE:0)
Block(-7,29,2,STONE:0)
Block(-7,29,3,STONE:0)
Block(-7,29,4,STONE:0)
Block(-7,30,-6,STONE:0)
Block(-7,30,-5,STONE:0)
Block(-7,30,-4,STONE:0)
Block(-7,30,-3,STONE:0)
Block(-7,30,-2,STONE:0)
Block(-7,30,-1,STONE:0)
Block(-7,30,0,STONE:0)
Block(-7,30,1,STONE:0)
Block(-7,30,2,STONE:0)
Block(-7,30,3,STONE:0)
Block(-7,30,4,STONE:0)
Block(-7,31,-6,STONE:0)
Block(-7,31,-5,STONE:0)
Block(-7,31,-4,STONE:0)
Block(-7,31,-3,STONE:0)
Block(-7,31,-2,STONE:0)
Block(-7,31,-1,STONE:0)
Block(-7,31,0,STONE:0)
Block(-7,31,1,STONE:0)
Block(-7,31,2,STONE:0)
Block(-7,31,3,STONE:0)
Block(-7,31,4,STONE:0)
Block(-7,32,-6,STONE:0)
Block(-7,32,-5,STONE:0)
Block(-7,32,-4,STONE:0)
Block(-7,32,-3,STONE:0)
Block(-7,32,-2,STONE:0)
Block(-7,32,-1,STONE:0)
Block(-7,32,0,STONE:0)
Block(-7,32,1,STONE:0)
Block(-7,32,2,STONE:0)
Block(-7,32,3,STONE:0)
Block(-7,33,-6,STONE:0)
Block(-7,33,-5,STONE:0)
Block(-7,33,-4,STONE:0)
Block(-7,33,-3,STONE:0)
Block(-7,33,-2,STONE:0)
Block(-7,33,-1,STONE:0)
Block(-7,33,0,STONE:0)
Block(-7,33,1,STONE:0)
Block(-7,33,2,STONE:0)
Block(-7,33,3,STONE:0)
Block(-7,34,-6,STONE:0)
Block(-7,34,-5,STONE:0)
Block(-7,34,-4,STONE:0)
Block(-7,34,-3,STONE:0)
Block(-7,34,-2,STONE:0)
Block(-7,34,-1,STONE:0)
Block(-7,34,0,STONE:0)
Block(-7,34,1,STONE:0)
Block(-7,34,2,STONE:0)
Block(-7,34,3,STONE:0)
Block(-7,35,-6,STONE:0)
Block(-7,35,-5,STONE:0)
Block(-7,35,-4,STONE:0)
Block(-7,35,-3,STONE:0)
Block(-7,35,-2,STONE:0)
Block(-7,35,-1,STONE:0)
Block(-7,35,0,STONE:0)
Block(-7,35,1,STONE:0)
Block(-7,35,2,STONE:0)
Block(-7,35,3,STONE:0)
Block(-7,36,-6,STONE:0)
Block(-7,36,-5,STONE:0)
Block(-7,36,-4,STONE:0)
Block(-7,36,-3,STONE:0)
Block(-7,36,-2,STONE:0)
Block(-7,36,-1,STONE:0)
Block(-7,36,0,STONE:0)
Block(-7,36,1,STONE:0)
Block(-7,36,2,STONE:0)
Block(-7,37,-6,STONE:0)
Block(-7,37,-5,STONE:0)
Block(-7,37,-4,STONE:0)
Block(-7,37,-3,STONE:0)
Block(-7,37,-2,STONE:0)
Block(-7,37,-1,STONE:0)
Block(-7,37,0,STONE:0)
Block(-7,37,1,STONE:0)
Block(-7,37,2,STONE:0)
Block(-7,38,-6,STONE:0)
Block(-7,38,-5,STONE:0)
Block(-7,38,-4,STONE:0)
Block(-7,38,-3,STONE:0)
Block(-7,38,-2,STONE:0)
Block(-7,38,-1,STONE:0)
Block(-7,38,0,STONE:0)
Block(-7,38,1,STONE:0)
Block(-7,38,2,STONE:0)
Block(-7,39,-6,STONE:0)
Block(-7,39,-5,STONE:0)
Block(-7,39,-4,STONE:0)
Block(-7,39,-3,STONE:0)
Block(-7,39,-2,STONE:0)
Block(-7,39,-1,STONE:0)
Block(-7,39,0,STONE:0)
Block(-7,39,1,STONE:0)
Block(-7,39,2,STONE:0)
Block(-7,40,-6,STONE:0)
Block(-7,40,-5,STONE:0)
Block(-7,40,-4,STONE:0)
Block(-7,40,-3,STONE:0)
Block(-7,40,-2,STONE:0)
Block(-7,40,-1,STONE:0)
Block(-7,40,0,STONE:0)
Block(-7,40,1,STONE:0)
Block(-7,40,2,STONE:0)
Block(-7,41,-6,STONE:0)
Block(-7,41,-5,STONE:0)
Block(-7,41,-4,STONE:0)
Block(-7,41,-3,STONE:0)
Block(-7,41,-2,STONE:0)
Block(-7,41,-1,STONE:0)
Block(-7,41,0,STONE:0)
Block(-7,41,1,STONE:0)
Block(-7,41,2,STONE:0)
Block(-7,42,-6,STONE:0)
Block(-7,42,-5,STONE:0)
Block(-7,42,-4,STONE:0)
Block(-7,42,-3,STONE:0)
Block(-7,42,-2,STONE:0)
Block(-7,42,-1,STONE:0)
Block(-7,42,0,STONE:0)
Block(-7,42,1,STONE:0)
Block(-7,42,2,STONE:0)
Block(-7,43,-6,STONE:0)
Block(-7,43,-5,STONE:0)
Block(-7,43,-4,STONE:0)
Block(-7,43,-3,STONE:0)
Block(-7,43,-2,STONE:0)
Block(-7,43,-1,STONE:0)
Block(-7,43,0,STONE:0)
Block(-7,43,1,STONE:0)
Block(-7,44,-5,STONE:0)
Block(-7,44,-4,STONE:0)
Block(-7,44,-3,STONE:0)
Block(-7,44,-2,STONE:0)
Block(-7,44,-1,STONE:0)
Block(-7,44,0,STONE:0)
Block(-7,44,1,STONE:0)
Block(-7,45,-5,STONE:0)
Block(-7,45,-4,GRASS:0)
Block(-7,45,-3,GRASS:0)
Block(-7,45,-2,GRASS:0)
Block(-7,45,-1,GRASS:0)
Block(-7,45,0,GRASS:0)
Block(-7,45,1,STONE:0)
Block(-6,0,-13,STONE:0)
Block(-6,0,-12,STONE:0)
Block(-6,0,-11,STONE:0)
Block(-6,0,-10,STONE:0)
Block(-6,0,-9,STONE:0)
Block(-6,0,-8,STONE:0)
Block(-6,0,-7,STONE:0)
Block(-6,0,-6,STONE:0)
Block(-6,0,-5,STONE:0)
Block(-6,0,-4,STONE:0)
Block(-6,0,-3,STONE:0)
Block(-6,0,-2,STONE:0)
Block(-6,0,-1,STONE:0)
Block(-6,0,0,STONE:0)
Block(-6,0,1,STONE:0)
Block(-6,0,2,STONE:0)
Block(-6,0,3,STONE:0)
Block(-6,0,4,STONE:0)
Block(-6,0,5,STONE:0)
Block(-6,0,6,STONE:0)
Block(-6,0,7,STONE:0)
Block(-6,0,8,STONE:0)
Block(-6,0,9,STONE:0)
Block(-6,0,10,STONE:0)
Block(-6,0,11,STONE:0)
Block(-6,0,12,STONE:0)
Block(-6,0,13,STONE:0)
Block(-6,1,-13,STONE:0)
Block(-6,1,-12,STONE:0)
Block(-6,1,-11,STONE:0)
Block(-6,1,-10,STONE:0)
Block(-6,1,-9,STONE:0)
Block(-6,1,-8,STONE:0)
Block(-6,1,-7,STONE:0)
Block(-6,1,-6,STONE:0)
Block(-6,1,-5,STONE:0)
Block(-6,1,-4,STONE:0)
Block(-6,1,-3,STONE:0)
Block(-6,1,-2,STONE:0)
Block(-6,1,-1,STONE:0)
Block(-6,1,0,STONE:0)
Block(-6,1,1,STONE:0)
Block(-6,1,2,STONE:0)
Block(-6,1,3,STONE:0)
Block(-6,1,4,STONE:0)
Block(-6,1,5,STONE:0)
Block(-6,1,6,STONE:0)
Block(-6,1,7,STONE:0)
Block(-6,1,8,STONE:0)
Block(-6,1,9,STONE:0)
Block(-6,1,10,STONE:0)
Block(-6,1,11,STONE:0)
Block(-6,1,12,STONE:0)
Block(-6,2,-13,STONE:0)
Block(-6,2,-12,STONE:0)
Block(-6,2,-11,STONE:0)
Block(-6,2,-10,STONE:0)
Block(-6,2,-9,STONE:0)
Block(-6,2,-8,STONE:0)
Block(-6,2,-7,STONE:0)
Block(-6,2,-6,STONE:0)
Block(-6,2,-5,STONE:0)
Block(-6,2,-4,STONE:0)
Block(-6,2,-3,STONE:0)
Block(-6,2,-2,STONE:0)
Block(-6,2,-1,STONE:0)
Block(-6,2,0,STONE:0)
Block(-6,2,1,STONE:0)
Block(-6,2,2,STONE:0)
Block(-6,2,3,STONE:0)
Block(-6,2,4,STONE:0)
Block(-6,2,5,STONE:0)
Block(-6,2,6,STONE:0)
Block(-6,2,7,STONE:0)
Block(-6,2,8,STONE:0)
Block(-6,2,9,STONE:0)
Block(-6,2,10,STONE:0)
Block(-6,2,11,STONE:0)
Block(-6,2,12,STONE:0)
Block(-6,3,-12,STONE:0)
Block(-6,3,-11,STONE:0)
Block(-6,3,-10,STONE:0)
Block(-6,3,-9,STONE:0)
Block(-6,3,-8,STONE:0)
Block(-6,3,-7,STONE:0)
Block(-6,3,-6,STONE:0)
Block(-6,3,-5,STONE:0)
Block(-6,3,-4,STONE:0)
Block(-6,3,-3,STONE:0)
Block(-6,3,-2,STONE:0)
Block(-6,3,-1,STONE:0)
Block(-6,3,0,STONE:0)
Block(-6,3,1,STONE:0)
Block(-6,3,2,STONE:0)
Block(-6,3,3,STONE:0)
Block(-6,3,4,STONE:0)
Block(-6,3,5,STONE:0)
Block(-6,3,6,STONE:0)
Block(-6,3,7,STONE:0)
Block(-6,3,8,STONE:0)
Block(-6,3,9,STONE:0)
Block(-6,3,10,STONE:0)
Block(-6,3,11,STONE:0)
Block(-6,3,12,STONE:0)
Block(-6,4,-12,STONE:0)
Block(-6,4,-11,STONE:0)
Block(-6,4,-10,STONE:0)
Block(-6,4,-9,STONE:0)
Block(-6,4,-8,STONE:0)
Block(-6,4,-7,STONE:0)
Block(-6,4,-6,STONE:0)
Block(-6,4,-5,STONE:0)
Block(-6,4,-4,STONE:0)
Block(-6,4,-3,STONE:0)
Block(-6,4,-2,STONE:0)
Block(-6,4,-1,STONE:0)
Block(-6,4,0,STONE:0)
Block(-6,4,1,STONE:0)
Block(-6,4,2,STONE:0)
Block(-6,4,3,STONE:0)
Block(-6,4,4,STONE:0)
Block(-6,4,5,STONE:0)
Block(-6,4,6,STONE:0)
Block(-6,4,7,STONE:0)
Block(-6,4,8,STONE:0)
Block(-6,4,9,STONE:0)
Block(-6,4,10,STONE:0)
Block(-6,4,11,STONE:0)
Block(-6,4,12,STONE:0)
Block(-6,5,-12,STONE:0)
Block(-6,5,-11,STONE:0)
Block(-6,5,-10,STONE:0)
Block(-6,5,-9,STONE:0)
Block(-6,5,-8,STONE:0)
Block(-6,5,-7,STONE:0)
Block(-6,5,-6,STONE:0)
Block(-6,5,-5,STONE:0)
Block(-6,5,-4,STONE:0)
Block(-6,5,-3,STONE:0)
Block(-6,5,-2,STONE:0)
Block(-6,5,-1,STONE:0)
Block(-6,5,0,STONE:0)
Block(-6,5,1,STONE:0)
Block(-6,5,2,STONE:0)
Block(-6,5,3,STONE:0)
Block(-6,5,4,STONE:0)
Block(-6,5,5,STONE:0)
Block(-6,5,6,STONE:0)
Block(-6,5,7,STONE:0)
Block(-6,5,8,STONE:0)
Block(-6,5,9,STONE:0)
Block(-6,5,10,STONE:0)
Block(-6,5,11,STONE:0)
Block(-6,6,-12,STONE:0)
Block(-6,6,-11,STONE:0)
Block(-6,6,-10,STONE:0)
Block(-6,6,-9,STONE:0)
Block(-6,6,-8,STONE:0)
Block(-6,6,-7,STONE:0)
Block(-6,6,-6,STONE:0)
Block(-6,6,-5,STONE:0)
Block(-6,6,-4,STONE:0)
Block(-6,6,-3,STONE:0)
Block(-6,6,-2,STONE:0)
Block(-6,6,-1,STONE:0)
Block(-6,6,0,STONE:0)
Block(-6,6,1,STONE:0)
Block(-6,6,2,STONE:0)
Block(-6,6,3,STONE:0)
Block(-6,6,4,STONE:0)
Block(-6,6,5,STONE:0)
Block(-6,6,6,STONE:0)
Block(-6,6,7,STONE:0)
Block(-6,6,8,STONE:0)
Block(-6,6,9,STONE:0)
Block(-6,6,10,STONE:0)
Block(-6,6,11,STONE:0)
Block(-6,7,-12,STONE:0)
Block(-6,7,-11,STONE:0)
Block(-6,7,-10,STONE:0)
Block(-6,7,-9,STONE:0)
Block(-6,7,-8,STONE:0)
Block(-6,7,-7,STONE:0)
Block(-6,7,-6,STONE:0)
Block(-6,7,-5,STONE:0)
Block(-6,7,-4,STONE:0)
Block(-6,7,-3,STONE:0)
Block(-6,7,-2,STONE:0)
Block(-6,7,-1,STONE:0)
Block(-6,7,0,STONE:0)
Block(-6,7,1,STONE:0)
Block(-6,7,2,STONE:0)
Block(-6,7,3,STONE:0)
Block(-6,7,4,STONE:0)
Block(-6,7,5,STONE:0)
Block(-6,7,6,STONE:0)
Block(-6,7,7,STONE:0)
Block(-6,7,8,STONE:0)
Block(-6,7,9,STONE:0)
Block(-6,7,10,STONE:0)
Block(-6,7,11,STONE:0)
Block(-6,8,-12,STONE:0)
Block(-6,8,-11,STONE:0)
Block(-6,8,-10,STONE:0)
Block(-6,8,-9,STONE:0)
Block(-6,8,-8,STONE:0)
Block(-6,8,-7,STONE:0)
Block(-6,8,-6,STONE:0)
Block(-6,8,-5,STONE:0)
Block(-6,8,-4,STONE:0)
Block(-6,8,-3,STONE:0)
Block(-6,8,-2,STONE:0)
Block(-6,8,-1,STONE:0)
Block(-6,8,0,STONE:0)
Block(-6,8,1,STONE:0)
Block(-6,8,2,STONE:0)
Block(-6,8,3,STONE:0)
Block(-6,8,4,STONE:0)
Block(-6,8,5,STONE:0)
Block(-6,8,6,STONE:0)
Block(-6,8,7,STONE:0)
Block(-6,8,8,STONE:0)
Block(-6,8,9,STONE:0)
Block(-6,8,10,STONE:0)
Block(-6,8,11,STONE:0)
Block(-6,9,-12,STONE:0)
Block(-6,9,-11,STONE:0)
Block(-6,9,-10,STONE:0)
Block(-6,9,-9,STONE:0)
Block(-6,9,-8,STONE:0)
Block(-6,9,-7,STONE:0)
Block(-6,9,-6,STONE:0)
Block(-6,9,-5,STONE:0)
Block(-6,9,-4,STONE:0)
Block(-6,9,-3,STONE:0)
Block(-6,9,-2,STONE:0)
Block(-6,9,-1,STONE:0)
Block(-6,9,0,STONE:0)
Block(-6,9,1,STONE:0)
Block(-6,9,2,STONE:0)
Block(-6,9,3,STONE:0)
Block(-6,9,4,STONE:0)
Block(-6,9,5,STONE:0)
Block(-6,9,6,STONE:0)
Block(-6,9,7,STONE:0)
Block(-6,9,8,STONE:0)
Block(-6,9,9,STONE:0)
Block(-6,9,10,STONE:0)
Block(-6,9,11,STONE:0)
Block(-6,10,-12,STONE:0)
Block(-6,10,-11,STONE:0)
Block(-6,10,-10,STONE:0)
Block(-6,10,-9,STONE:0)
Block(-6,10,-8,STONE:0)
Block(-6,10,-7,STONE:0)
Block(-6,10,-6,STONE:0)
Block(-6,10,-5,STONE:0)
Block(-6,10,-4,STONE:0)
Block(-6,10,-3,STONE:0)
Block(-6,10,-2,STONE:0)
Block(-6,10,-1,STONE:0)
Block(-6,10,0,STONE:0)
Block(-6,10,1,STONE:0)
Block(-6,10,2,STONE:0)
Block(-6,10,3,STONE:0)
Block(-6,10,4,STONE:0)
Block(-6,10,5,STONE:0)
Block(-6,10,6,STONE:0)
Block(-6,10,7,STONE:0)
Block(-6,10,8,STONE:0)
Block(-6,10,9,STONE:0)
Block(-6,10,10,STONE:0)
Block(-6,11,-12,STONE:0)
Block(-6,11,-11,STONE:0)
Block(-6,11,-10,STONE:0)
Block(-6,11,-9,STONE:0)
Block(-6,11,-8,STONE:0)
Block(-6,11,-7,STONE:0)
Block(-6,11,-6,STONE:0)
Block(-6,11,-5,STONE:0)
Block(-6,11,-4,STONE:0)
Block(-6,11,-3,STONE:0)
Block(-6,11,-2,STONE:0)
Block(-6,11,-1,STONE:0)
Block(-6,11,0,STONE:0)
Block(-6,11,1,STONE:0)
Block(-6,11,2,STONE:0)
Block(-6,11,3,STONE:0)
Block(-6,11,4,STONE:0)
Block(-6,11,5,STONE:0)
Block(-6,11,6,STONE:0)
Block(-6,11,7,STONE:0)
Block(-6,11,8,STONE:0)
Block(-6,11,9,STONE:0)
Block(-6,11,10,STONE:0)
Block(-6,12,-11,STONE:0)
Block(-6,12,-10,STONE:0)
Block(-6,12,-9,STONE:0)
Block(-6,12,-8,STONE:0)
Block(-6,12,-7,STONE:0)
Block(-6,12,-6,STONE:0)
Block(-6,12,-5,STONE:0)
Block(-6,12,-4,STONE:0)
Block(-6,12,-3,STONE:0)
Block(-6,12,-2,STONE:0)
Block(-6,12,-1,STONE:0)
Block(-6,12,0,STONE:0)
Block(-6,12,1,STONE:0)
Block(-6,12,2,STONE:0)
Block(-6,12,3,STONE:0)
Block(-6,12,4,STONE:0)
Block(-6,12,5,STONE:0)
Block(-6,12,6,STONE:0)
Block(-6,12,7,STONE:0)
Block(-6,12,8,STONE:0)
Block(-6,12,9,STONE:0)
Block(-6,13,-11,STONE:0)
Block(-6,13,-10,STONE:0)
Block(-6,13,-9,STONE:0)
Block(-6,13,-8,STONE:0)
Block(-6,13,-7,STONE:0)
Block(-6,13,-6,STONE:0)
Block(-6,13,-5,STONE:0)
Block(-6,13,-4,STONE:0)
Block(-6,13,-3,STONE:0)
Block(-6,13,-2,STONE:0)
Block(-6,13,-1,STONE:0)
Block(-6,13,0,STONE:0)
Block(-6,13,1,STONE:0)
Block(-6,13,2,STONE:0)
Block(-6,13,3,STONE:0)
Block(-6,13,4,STONE:0)
Block(-6,13,5,STONE:0)
Block(-6,13,6,STONE:0)
Block(-6,13,7,STONE:0)
Block(-6,13,8,STONE:0)
Block(-6,14,-11,STONE:0)
Block(-6,14,-10,STONE:0)
Block(-6,14,-9,STONE:0)
Block(-6,14,-8,STONE:0)
Block(-6,14,-7,STONE:0)
Block(-6,14,-6,STONE:0)
Block(-6,14,-5,STONE:0)
Block(-6,14,-4,STONE:0)
Block(-6,14,-3,STONE:0)
Block(-6,14,-2,STONE:0)
Block(-6,14,-1,STONE:0)
Block(-6,14,0,STONE:0)
Block(-6,14,1,STONE:0)
Block(-6,14,2,STONE:0)
Block(-6,14,3,STONE:0)
Block(-6,14,4,STONE:0)
Block(-6,14,5,STONE:0)
Block(-6,14,6,STONE:0)
Block(-6,14,7,STONE:0)
Block(-6,15,-10,STONE:0)
Block(-6,15,-9,STONE:0)
Block(-6,15,-8,STONE:0)
Block(-6,15,-7,STONE:0)
Block(-6,15,-6,STONE:0)
Block(-6,15,-5,STONE:0)
Block(-6,15,-4,STONE:0)
Block(-6,15,-3,STONE:0)
Block(-6,15,-2,STONE:0)
Block(-6,15,-1,STONE:0)
Block(-6,15,0,STONE:0)
Block(-6,15,1,STONE:0)
Block(-6,15,2,STONE:0)
Block(-6,15,3,STONE:0)
Block(-6,15,4,STONE:0)
Block(-6,15,5,STONE:0)
Block(-6,15,6,STONE:0)
Block(-6,15,7,STONE:0)
Block(-6,16,-9,STONE:0)
Block(-6,16,-8,STONE:0)
Block(-6,16,-7,STONE:0)
Block(-6,16,-6,STONE:0)
Block(-6,16,-5,STONE:0)
Block(-6,16,-4,STONE:0)
Block(-6,16,-3,STONE:0)
Block(-6,16,-2,STONE:0)
Block(-6,16,-1,STONE:0)
Block(-6,16,0,STONE:0)
Block(-6,16,1,STONE:0)
Block(-6,16,2,STONE:0)
Block(-6,16,3,STONE:0)
Block(-6,16,4,STONE:0)
Block(-6,16,5,STONE:0)
Block(-6,16,6,STONE:0)
Block(-6,17,-9,STONE:0)
Block(-6,17,-8,STONE:0)
Block(-6,17,-7,STONE:0)
Block(-6,17,-6,STONE:0)
Block(-6,17,-5,STONE:0)
Block(-6,17,-4,STONE:0)
Block(-6,17,-3,STONE:0)
Block(-6,17,-2,STONE:0)
Block(-6,17,-1,STONE:0)
Block(-6,17,0,STONE:0)
Block(-6,17,1,STONE:0)
Block(-6,17,2,STONE:0)
Block(-6,17,3,STONE:0)
Block(-6,17,4,STONE:0)
Block(-6,17,5,STONE:0)
Block(-6,17,6,STONE:0)
Block(-6,18,-9,STONE:0)
Block(-6,18,-8,STONE:0)
Block(-6,18,-7,STONE:0)
Block(-6,18,-6,STONE:0)
Block(-6,18,-5,STONE:0)
Block(-6,18,-4,STONE:0)
Block(-6,18,-3,STONE:0)
Block(-6,18,-2,STONE:0)
Block(-6,18,-1,STONE:0)
Block(-6,18,0,STONE:0)
Block(-6,18,1,STONE:0)
Block(-6,18,2,STONE:0)
Block(-6,18,3,STONE:0)
Block(-6,18,4,STONE:0)
Block(-6,18,5,STONE:0)
Block(-6,18,6,STONE:0)
Block(-6,19,-8,STONE:0)
Block(-6,19,-7,STONE:0)
Block(-6,19,-6,STONE:0)
Block(-6,19,-5,STONE:0)
Block(-6,19,-4,STONE:0)
Block(-6,19,-3,STONE:0)
Block(-6,19,-2,STONE:0)
Block(-6,19,-1,STONE:0)
Block(-6,19,0,STONE:0)
Block(-6,19,1,STONE:0)
Block(-6,19,2,STONE:0)
Block(-6,19,3,STONE:0)
Block(-6,19,4,STONE:0)
Block(-6,19,5,STONE:0)
Block(-6,19,6,STONE:0)
Block(-6,20,-8,STONE:0)
Block(-6,20,-7,STONE:0)
Block(-6,20,-6,STONE:0)
Block(-6,20,-5,STONE:0)
Block(-6,20,-4,STONE:0)
Block(-6,20,-3,STONE:0)
Block(-6,20,-2,STONE:0)
Block(-6,20,-1,STONE:0)
Block(-6,20,0,STONE:0)
Block(-6,20,1,STONE:0)
Block(-6,20,2,STONE:0)
Block(-6,20,3,STONE:0)
Block(-6,20,4,STONE:0)
Block(-6,20,5,STONE:0)
Block(-6,20,6,STONE:0)
Block(-6,21,-8,STONE:0)
Block(-6,21,-7,STONE:0)
Block(-6,21,-6,STONE:0)
Block(-6,21,-5,STONE:0)
Block(-6,21,-4,STONE:0)
Block(-6,21,-3,STONE:0)
Block(-6,21,-2,STONE:0)
Block(-6,21,-1,STONE:0)
Block(-6,21,0,STONE:0)
Block(-6,21,1,STONE:0)
Block(-6,21,2,STONE:0)
Block(-6,21,3,STONE:0)
Block(-6,21,4,STONE:0)
Block(-6,21,5,STONE:0)
Block(-6,22,-8,STONE:0)
Block(-6,22,-7,STONE:0)
Block(-6,22,-6,STONE:0)
Block(-6,22,-5,STONE:0)
Block(-6,22,-4,STONE:0)
Block(-6,22,-3,STONE:0)
Block(-6,22,-2,STONE:0)
Block(-6,22,-1,STONE:0)
Block(-6,22,0,STONE:0)
Block(-6,22,1,STONE:0)
Block(-6,22,2,STONE:0)
Block(-6,22,3,STONE:0)
Block(-6,22,4,STONE:0)
Block(-6,22,5,STONE:0)
Block(-6,23,-8,STONE:0)
Block(-6,23,-7,STONE:0)
Block(-6,23,-6,STONE:0)
Block(-6,23,-5,STONE:0)
Block(-6,23,-4,STONE:0)
Block(-6,23,-3,STONE:0)
Block(-6,23,-2,STONE:0)
Block(-6,23,-1,STONE:0)
Block(-6,23,0,STONE:0)
Block(-6,23,1,STONE:0)
Block(-6,23,2,STONE:0)
Block(-6,23,3,STONE:0)
Block(-6,23,4,STONE:0)
Block(-6,23,5,STONE:0)
Block(-6,24,-8,STONE:0)
Block(-6,24,-7,STONE:0)
Block(-6,24,-6,STONE:0)
Block(-6,24,-5,STONE:0)
Block(-6,24,-4,STONE:0)
Block(-6,24,-3,STONE:0)
Block(-6,24,-2,STONE:0)
Block(-6,24,-1,STONE:0)
Block(-6,24,0,STONE:0)
Block(-6,24,1,STONE:0)
Block(-6,24,2,STONE:0)
Block(-6,24,3,STONE:0)
Block(-6,24,4,STONE:0)
Block(-6,24,5,STONE:0)
Block(-6,25,-8,STONE:0)
Block(-6,25,-7,STONE:0)
Block(-6,25,-6,STONE:0)
Block(-6,25,-5,STONE:0)
Block(-6,25,-4,STONE:0)
Block(-6,25,-3,STONE:0)
Block(-6,25,-2,STONE:0)
Block(-6,25,-1,STONE:0)
Block(-6,25,0,STONE:0)
Block(-6,25,1,STONE:0)
Block(-6,25,2,STONE:0)
Block(-6,25,3,STONE:0)
Block(-6,25,4,STONE:0)
Block(-6,25,5,STONE:0)
Block(-6,26,-8,STONE:0)
Block(-6,26,-7,STONE:0)
Block(-6,26,-6,STONE:0)
Block(-6,26,-5,STONE:0)
Block(-6,26,-4,STONE:0)
Block(-6,26,-3,STONE:0)
Block(-6,26,-2,STONE:0)
Block(-6,26,-1,STONE:0)
Block(-6,26,0,STONE:0)
Block(-6,26,1,STONE:0)
Block(-6,26,2,STONE:0)
Block(-6,26,3,STONE:0)
Block(-6,26,4,STONE:0)
Block(-6,26,5,STONE:0)
Block(-6,27,-8,STONE:0)
Block(-6,27,-7,STONE:0)
Block(-6,27,-6,STONE:0)
Block(-6,27,-5,STONE:0)
Block(-6,27,-4,STONE:0)
Block(-6,27,-3,STONE:0)
Block(-6,27,-2,STONE:0)
Block(-6,27,-1,STONE:0)
Block(-6,27,0,STONE:0)
Block(-6,27,1,STONE:0)
Block(-6,27,2,STONE:0)
Block(-6,27,3,STONE:0)
Block(-6,27,4,STONE:0)
Block(-6,27,5,STONE:0)
Block(-6,28,-8,STONE:0)
Block(-6,28,-7,STONE:0)
Block(-6,28,-6,STONE:0)
Block(-6,28,-5,STONE:0)
Block(-6,28,-4,STONE:0)
Block(-6,28,-3,STONE:0)
Block(-6,28,-2,STONE:0)
Block(-6,28,-1,STONE:0)
Block(-6,28,0,STONE:0)
Block(-6,28,1,STONE:0)
Block(-6,28,2,STONE:0)
Block(-6,28,3,STONE:0)
Block(-6,28,4,STONE:0)
Block(-6,28,5,STONE:0)
Block(-6,29,-8,STONE:0)
Block(-6,29,-7,STONE:0)
Block(-6,29,-6,STONE:0)
Block(-6,29,-5,STONE:0)
Block(-6,29,-4,STONE:0)
Block(-6,29,-3,STONE:0)
Block(-6,29,-2,STONE:0)
Block(-6,29,-1,STONE:0)
Block(-6,29,0,STONE:0)
Block(-6,29,1,STONE:0)
Block(-6,29,2,STONE:0)
Block(-6,29,3,STONE:0)
Block(-6,29,4,STONE:0)
Block(-6,29,5,STONE:0)
Block(-6,30,-8,STONE:0)
Block(-6,30,-7,STONE:0)
Block(-6,30,-6,STONE:0)
Block(-6,30,-5,STONE:0)
Block(-6,30,-4,STONE:0)
Block(-6,30,-3,STONE:0)
Block(-6,30,-2,STONE:0)
Block(-6,30,-1,STONE:0)
Block(-6,30,0,STONE:0)
Block(-6,30,1,STONE:0)
Block(-6,30,2,STONE:0)
Block(-6,30,3,STONE:0)
Block(-6,30,4,STONE:0)
Block(-6,31,-7,STONE:0)
Block(-6,31,-6,STONE:0)
Block(-6,31,-5,STONE:0)
Block(-6,31,-4,STONE:0)
Block(-6,31,-3,STONE:0)
Block(-6,31,-2,STONE:0)
Block(-6,31,-1,STONE:0)
Block(-6,31,0,STONE:0)
Block(-6,31,1,STONE:0)
Block(-6,31,2,STONE:0)
Block(-6,31,3,STONE:0)
Block(-6,31,4,STONE:0)
Block(-6,32,-7,STONE:0)
Block(-6,32,-6,STONE:0)
Block(-6,32,-5,STONE:0)
Block(-6,32,-4,STONE:0)
Block(-6,32,-3,STONE:0)
Block(-6,32,-2,STONE:0)
Block(-6,32,-1,STONE:0)
Block(-6,32,0,STONE:0)
Block(-6,32,1,STONE:0)
Block(-6,32,2,STONE:0)
Block(-6,32,3,STONE:0)
Block(-6,32,4,STONE:0)
Block(-6,33,-7,STONE:0)
Block(-6,33,-6,STONE:0)
Block(-6,33,-5,STONE:0)
Block(-6,33,-4,STONE:0)
Block(-6,33,-3,STONE:0)
Block(-6,33,-2,STONE:0)
Block(-6,33,-1,STONE:0)
Block(-6,33,0,STONE:0)
Block(-6,33,1,STONE:0)
Block(-6,33,2,STONE:0)
Block(-6,33,3,STONE:0)
Block(-6,33,4,STONE:0)
Block(-6,34,-7,STONE:0)
Block(-6,34,-6,STONE:0)
Block(-6,34,-5,STONE:0)
Block(-6,34,-4,STONE:0)
Block(-6,34,-3,STONE:0)
Block(-6,34,-2,STONE:0)
Block(-6,34,-1,STONE:0)
Block(-6,34,0,STONE:0)
Block(-6,34,1,STONE:0)
Block(-6,34,2,STONE:0)
Block(-6,34,3,STONE:0)
Block(-6,34,4,STONE:0)
Block(-6,35,-7,STONE:0)
Block(-6,35,-6,STONE:0)
Block(-6,35,-5,STONE:0)
Block(-6,35,-4,STONE:0)
Block(-6,35,-3,STONE:0)
Block(-6,35,-2,STONE:0)
Block(-6,35,-1,STONE:0)
Block(-6,35,0,STONE:0)
Block(-6,35,1,STONE:0)
Block(-6,35,2,STONE:0)
Block(-6,35,3,STONE:0)
Block(-6,35,4,STONE:0)
Block(-6,36,-7,STONE:0)
Block(-6,36,-6,STONE:0)
Block(-6,36,-5,STONE:0)
Block(-6,36,-4,STONE:0)
Block(-6,36,-3,STONE:0)
Block(-6,36,-2,STONE:0)
Block(-6,36,-1,STONE:0)
Block(-6,36,0,STONE:0)
Block(-6,36,1,STONE:0)
Block(-6,36,2,STONE:0)
Block(-6,36,3,STONE:0)
Block(-6,36,4,STONE:0)
Block(-6,37,-7,STONE:0)
Block(-6,37,-6,STONE:0)
Block(-6,37,-5,STONE:0)
Block(-6,37,-4,STONE:0)
Block(-6,37,-3,STONE:0)
Block(-6,37,-2,STONE:0)
Block(-6,37,-1,STONE:0)
Block(-6,37,0,STONE:0)
Block(-6,37,1,STONE:0)
Block(-6,37,2,STONE:0)
Block(-6,37,3,STONE:0)
Block(-6,37,4,STONE:0)
Block(-6,38,-7,STONE:0)
Block(-6,38,-6,STONE:0)
Block(-6,38,-5,STONE:0)
Block(-6,38,-4,STONE:0)
Block(-6,38,-3,STONE:0)
Block(-6,38,-2,STONE:0)
Block(-6,38,-1,STONE:0)
Block(-6,38,0,STONE:0)
Block(-6,38,1,STONE:0)
Block(-6,38,2,STONE:0)
Block(-6,38,3,STONE:0)
Block(-6,38,4,STONE:0)
Block(-6,39,-6,STONE:0)
Block(-6,39,-5,STONE:0)
Block(-6,39,-4,STONE:0)
Block(-6,39,-3,STONE:0)
Block(-6,39,-2,STONE:0)
Block(-6,39,-1,STONE:0)
Block(-6,39,0,STONE:0)
Block(-6,39,1,STONE:0)
Block(-6,39,2,STONE:0)
Block(-6,39,3,STONE:0)
Block(-6,39,4,STONE:0)
Block(-6,40,-6,STONE:0)
Block(-6,40,-5,STONE:0)
Block(-6,40,-4,STONE:0)
Block(-6,40,-3,STONE:0)
Block(-6,40,-2,STONE:0)
Block(-6,40,-1,STONE:0)
Block(-6,40,0,STONE:0)
Block(-6,40,1,STONE:0)
Block(-6,40,2,STONE:0)
Block(-6,40,3,STONE:0)
Block(-6,40,4,STONE:0)
Block(-6,41,-6,STONE:0)
Block(-6,41,-5,STONE:0)
Block(-6,41,-4,STONE:0)
Block(-6,41,-3,STONE:0)
Block(-6,41,-2,STONE:0)
Block(-6,41,-1,STONE:0)
Block(-6,41,0,STONE:0)
Block(-6,41,1,STONE:0)
Block(-6,41,2,STONE:0)
Block(-6,41,3,STONE:0)
Block(-6,42,-6,STONE:0)
Block(-6,42,-5,STONE:0)
Block(-6,42,-4,STONE:0)
Block(-6,42,-3,STONE:0)
Block(-6,42,-2,STONE:0)
Block(-6,42,-1,STONE:0)
Block(-6,42,0,STONE:0)
Block(-6,42,1,STONE:0)
Block(-6,42,2,STONE:0)
Block(-6,43,-6,STONE:0)
Block(-6,43,-5,STONE:0)
Block(-6,43,-4,STONE:0)
Block(-6,43,-3,STONE:0)
Block(-6,43,-2,STONE:0)
Block(-6,43,-1,STONE:0)
Block(-6,43,0,STONE:0)
Block(-6,43,1,STONE:0)
Block(-6,43,2,STONE:0)
Block(-6,44,-6,STONE:0)
Block(-6,44,-5,STONE:0)
Block(-6,44,-4,STONE:0)
Block(-6,44,-3,STONE:0)
Block(-6,44,-2,STONE:0)
Block(-6,44,-1,STONE:0)
Block(-6,44,0,STONE:0)
Block(-6,44,1,STONE:0)
Block(-6,44,2,STONE:0)
Block(-6,45,-6,STONE:0)
Block(-6,45,-5,STONE:0)
Block(-6,45,-4,GRASS:0)
Block(-6,45,-3,GRASS:0)
Block(-6,45,-2,GRASS:0)
Block(-6,45,-1,GRASS:0)
Block(-6,45,0,GRASS:0)
Block(-6,45,1,STONE:0)
Block(-6,45,2,STONE:0)
Block(-5,0,-13,STONE:0)
Block(-5,0,-12,STONE:0)
Block(-5,0,-11,STONE:0)
Block(-5,0,-10,STONE:0)
Block(-5,0,-9,STONE:0)
Block(-5,0,-8,STONE:0)
Block(-5,0,-7,STONE:0)
Block(-5,0,-6,STONE:0)
Block(-5,0,-5,STONE:0)
Block(-5,0,-4,STONE:0)
Block(-5,0,-3,STONE:0)
Block(-5,0,-2,STONE:0)
Block(-5,0,-1,STONE:0)
Block(-5,0,0,STONE:0)
Block(-5,0,1,STONE:0)
Block(-5,0,2,STONE:0)
Block(-5,0,3,STONE:0)
Block(-5,0,4,STONE:0)
Block(-5,0,5,STONE:0)
Block(-5,0,6,STONE:0)
Block(-5,0,7,STONE:0)
Block(-5,0,8,STONE:0)
Block(-5,0,9,STONE:0)
Block(-5,0,10,STONE:0)
Block(-5,0,11,STONE:0)
Block(-5,0,12,STONE:0)
Block(-5,0,13,STONE:0)
Block(-5,0,14,STONE:0)
Block(-5,1,-13,STONE:0)
Block(-5,1,-12,STONE:0)
Block(-5,1,-11,STONE:0)
Block(-5,1,-10,STONE:0)
Block(-5,1,-9,STONE:0)
Block(-5,1,-8,STONE:0)
Block(-5,1,-7,STONE:0)
Block(-5,1,-6,STONE:0)
Block(-5,1,-5,STONE:0)
Block(-5,1,-4,STONE:0)
Block(-5,1,-3,STONE:0)
Block(-5,1,-2,STONE:0)
Block(-5,1,-1,STONE:0)
Block(-5,1,0,STONE:0)
Block(-5,1,1,STONE:0)
Block(-5,1,2,STONE:0)
Block(-5,1,3,STONE:0)
Block(-5,1,4,STONE:0)
Block(-5,1,5,STONE:0)
Block(-5,1,6,STONE:0)
Block(-5,1,7,STONE:0)
Block(-5,1,8,STONE:0)
Block(-5,1,9,STONE:0)
Block(-5,1,10,STONE:0)
Block(-5,1,11,STONE:0)
Block(-5,1,12,STONE:0)
Block(-5,1,13,STONE:0)
Block(-5,1,14,STONE:0)
Block(-5,2,-13,STONE:0)
Block(-5,2,-12,STONE:0)
Block(-5,2,-11,STONE:0)
Block(-5,2,-10,STONE:0)
Block(-5,2,-9,STONE:0)
Block(-5,2,-8,STONE:0)
Block(-5,2,-7,STONE:0)
Block(-5,2,-6,STONE:0)
Block(-5,2,-5,STONE:0)
Block(-5,2,-4,STONE:0)
Block(-5,2,-3,STONE:0)
Block(-5,2,-2,STONE:0)
Block(-5,2,-1,STONE:0)
Block(-5,2,0,STONE:0)
Block(-5,2,1,STONE:0)
Block(-5,2,2,STONE:0)
Block(-5,2,3,STONE:0)
Block(-5,2,4,STONE:0)
Block(-5,2,5,STONE:0)
Block(-5,2,6,STONE:0)
Block(-5,2,7,STONE:0)
Block(-5,2,8,STONE:0)
Block(-5,2,9,STONE:0)
Block(-5,2,10,STONE:0)
Block(-5,2,11,STONE:0)
Block(-5,2,12,STONE:0)
Block(-5,2,13,STONE:0)
Block(-5,2,14,STONE:0)
Block(-5,3,-13,STONE:0)
Block(-5,3,-12,STONE:0)
Block(-5,3,-11,STONE:0)
Block(-5,3,-10,STONE:0)
Block(-5,3,-9,STONE:0)
Block(-5,3,-8,STONE:0)
Block(-5,3,-7,STONE:0)
Block(-5,3,-6,STONE:0)
Block(-5,3,-5,STONE:0)
Block(-5,3,-4,STONE:0)
Block(-5,3,-3,STONE:0)
Block(-5,3,-2,STONE:0)
Block(-5,3,-1,STONE:0)
Block(-5,3,0,STONE:0)
Block(-5,3,1,STONE:0)
Block(-5,3,2,STONE:0)
Block(-5,3,3,STONE:0)
Block(-5,3,4,STONE:0)
Block(-5,3,5,STONE:0)
Block(-5,3,6,STONE:0)
Block(-5,3,7,STONE:0)
Block(-5,3,8,STONE:0)
Block(-5,3,9,STONE:0)
Block(-5,3,10,STONE:0)
Block(-5,3,11,STONE:0)
Block(-5,3,12,STONE:0)
Block(-5,3,13,STONE:0)
Block(-5,3,14,STONE:0)
Block(-5,4,-13,STONE:0)
Block(-5,4,-12,STONE:0)
Block(-5,4,-11,STONE:0)
Block(-5,4,-10,STONE:0)
Block(-5,4,-9,STONE:0)
Block(-5,4,-8,STONE:0)
Block(-5,4,-7,STONE:0)
Block(-5,4,-6,STONE:0)
Block(-5,4,-5,STONE:0)
Block(-5,4,-4,STONE:0)
Block(-5,4,-3,STONE:0)
Block(-5,4,-2,STONE:0)
Block(-5,4,-1,STONE:0)
Block(-5,4,0,STONE:0)
Block(-5,4,1,STONE:0)
Block(-5,4,2,STONE:0)
Block(-5,4,3,STONE:0)
Block(-5,4,4,STONE:0)
Block(-5,4,5,STONE:0)
Block(-5,4,6,STONE:0)
Block(-5,4,7,STONE:0)
Block(-5,4,8,STONE:0)
Block(-5,4,9,STONE:0)
Block(-5,4,10,STONE:0)
Block(-5,4,11,STONE:0)
Block(-5,4,12,STONE:0)
Block(-5,4,13,STONE:0)
Block(-5,5,-13,STONE:0)
Block(-5,5,-12,STONE:0)
Block(-5,5,-11,STONE:0)
Block(-5,5,-10,STONE:0)
Block(-5,5,-9,STONE:0)
Block(-5,5,-8,STONE:0)
Block(-5,5,-7,STONE:0)
Block(-5,5,-6,STONE:0)
Block(-5,5,-5,STONE:0)
Block(-5,5,-4,STONE:0)
Block(-5,5,-3,STONE:0)
Block(-5,5,-2,STONE:0)
Block(-5,5,-1,STONE:0)
Block(-5,5,0,STONE:0)
Block(-5,5,1,STONE:0)
Block(-5,5,2,STONE:0)
Block(-5,5,3,STONE:0)
Block(-5,5,4,STONE:0)
Block(-5,5,5,STONE:0)
Block(-5,5,6,STONE:0)
Block(-5,5,7,STONE:0)
Block(-5,5,8,STONE:0)
Block(-5,5,9,STONE:0)
Block(-5,5,10,STONE:0)
Block(-5,5,11,STONE:0)
Block(-5,5,12,STONE:0)
Block(-5,5,13,STONE:0)
Block(-5,6,-13,STONE:0)
Block(-5,6,-12,STONE:0)
Block(-5,6,-11,STONE:0)
Block(-5,6,-10,STONE:0)
Block(-5,6,-9,STONE:0)
Block(-5,6,-8,STONE:0)
Block(-5,6,-7,STONE:0)
Block(-5,6,-6,STONE:0)
Block(-5,6,-5,STONE:0)
Block(-5,6,-4,STONE:0)
Block(-5,6,-3,STONE:0)
Block(-5,6,-2,STONE:0)
Block(-5,6,-1,STONE:0)
Block(-5,6,0,STONE:0)
Block(-5,6,1,STONE:0)
Block(-5,6,2,STONE:0)
Block(-5,6,3,STONE:0)
Block(-5,6,4,STONE:0)
Block(-5,6,5,STONE:0)
Block(-5,6,6,STONE:0)
Block(-5,6,7,STONE:0)
Block(-5,6,8,STONE:0)
Block(-5,6,9,STONE:0)
Block(-5,6,10,STONE:0)
Block(-5,6,11,STONE:0)
Block(-5,6,12,STONE:0)
Block(-5,6,13,STONE:0)
Block(-5,7,-13,STONE:0)
Block(-5,7,-12,STONE:0)
Block(-5,7,-11,STONE:0)
Block(-5,7,-10,STONE:0)
Block(-5,7,-9,STONE:0)
Block(-5,7,-8,STONE:0)
Block(-5,7,-7,STONE:0)
Block(-5,7,-6,STONE:0)
Block(-5,7,-5,STONE:0)
Block(-5,7,-4,STONE:0)
Block(-5,7,-3,STONE:0)
Block(-5,7,-2,STONE:0)
Block(-5,7,-1,STONE:0)
Block(-5,7,0,STONE:0)
Block(-5,7,1,STONE:0)
Block(-5,7,2,STONE:0)
Block(-5,7,3,STONE:0)
Block(-5,7,4,STONE:0)
Block(-5,7,5,STONE:0)
Block(-5,7,6,STONE:0)
Block(-5,7,7,STONE:0)
Block(-5,7,8,STONE:0)
Block(-5,7,9,STONE:0)
Block(-5,7,10,STONE:0)
Block(-5,7,11,STONE:0)
Block(-5,7,12,STONE:0)
Block(-5,8,-13,STONE:0)
Block(-5,8,-12,STONE:0)
Block(-5,8,-11,STONE:0)
Block(-5,8,-10,STONE:0)
Block(-5,8,-9,STONE:0)
Block(-5,8,-8,STONE:0)
Block(-5,8,-7,STONE:0)
Block(-5,8,-6,STONE:0)
Block(-5,8,-5,STONE:0)
Block(-5,8,-4,STONE:0)
Block(-5,8,-3,STONE:0)
Block(-5,8,-2,STONE:0)
Block(-5,8,-1,STONE:0)
Block(-5,8,0,STONE:0)
Block(-5,8,1,STONE:0)
Block(-5,8,2,STONE:0)
Block(-5,8,3,STONE:0)
Block(-5,8,4,STONE:0)
Block(-5,8,5,STONE:0)
Block(-5,8,6,STONE:0)
Block(-5,8,7,STONE:0)
Block(-5,8,8,STONE:0)
Block(-5,8,9,STONE:0)
Block(-5,8,10,STONE:0)
Block(-5,8,11,STONE:0)
Block(-5,8,12,STONE:0)
Block(-5,9,-12,STONE:0)
Block(-5,9,-11,STONE:0)
Block(-5,9,-10,STONE:0)
Block(-5,9,-9,STONE:0)
Block(-5,9,-8,STONE:0)
Block(-5,9,-7,STONE:0)
Block(-5,9,-6,STONE:0)
Block(-5,9,-5,STONE:0)
Block(-5,9,-4,STONE:0)
Block(-5,9,-3,STONE:0)
Block(-5,9,-2,STONE:0)
Block(-5,9,-1,STONE:0)
Block(-5,9,0,STONE:0)
Block(-5,9,1,STONE:0)
Block(-5,9,2,STONE:0)
Block(-5,9,3,STONE:0)
Block(-5,9,4,STONE:0)
Block(-5,9,5,STONE:0)
Block(-5,9,6,STONE:0)
Block(-5,9,7,STONE:0)
Block(-5,9,8,STONE:0)
Block(-5,9,9,STONE:0)
Block(-5,9,10,STONE:0)
Block(-5,9,11,STONE:0)
Block(-5,9,12,STONE:0)
Block(-5,10,-12,STONE:0)
Block(-5,10,-11,STONE:0)
Block(-5,10,-10,STONE:0)
Block(-5,10,-9,STONE:0)
Block(-5,10,-8,STONE:0)
Block(-5,10,-7,STONE:0)
Block(-5,10,-6,STONE:0)
Block(-5,10,-5,STONE:0)
Block(-5,10,-4,STONE:0)
Block(-5,10,-3,STONE:0)
Block(-5,10,-2,STONE:0)
Block(-5,10,-1,STONE:0)
Block(-5,10,0,STONE:0)
Block(-5,10,1,STONE:0)
Block(-5,10,2,STONE:0)
Block(-5,10,3,STONE:0)
Block(-5,10,4,STONE:0)
Block(-5,10,5,STONE:0)
Block(-5,10,6,STONE:0)
Block(-5,10,7,STONE:0)
Block(-5,10,8,STONE:0)
Block(-5,10,9,STONE:0)
Block(-5,10,10,STONE:0)
Block(-5,10,11,STONE:0)
Block(-5,10,12,STONE:0)
Block(-5,11,-12,STONE:0)
Block(-5,11,-11,STONE:0)
Block(-5,11,-10,STONE:0)
Block(-5,11,-9,STONE:0)
Block(-5,11,-8,STONE:0)
Block(-5,11,-7,STONE:0)
Block(-5,11,-6,STONE:0)
Block(-5,11,-5,STONE:0)
Block(-5,11,-4,STONE:0)
Block(-5,11,-3,STONE:0)
Block(-5,11,-2,STONE:0)
Block(-5,11,-1,STONE:0)
Block(-5,11,0,STONE:0)
Block(-5,11,1,STONE:0)
Block(-5,11,2,STONE:0)
Block(-5,11,3,STONE:0)
Block(-5,11,4,STONE:0)
Block(-5,11,5,STONE:0)
Block(-5,11,6,STONE:0)
Block(-5,11,7,STONE:0)
Block(-5,11,8,STONE:0)
Block(-5,11,9,STONE:0)
Block(-5,11,10,STONE:0)
Block(-5,11,11,STONE:0)
Block(-5,12,-12,STONE:0)
Block(-5,12,-11,STONE:0)
Block(-5,12,-10,STONE:0)
Block(-5,12,-9,STONE:0)
Block(-5,12,-8,STONE:0)
Block(-5,12,-7,STONE:0)
Block(-5,12,-6,STONE:0)
Block(-5,12,-5,STONE:0)
Block(-5,12,-4,STONE:0)
Block(-5,12,-3,STONE:0)
Block(-5,12,-2,STONE:0)
Block(-5,12,-1,STONE:0)
Block(-5,12,0,STONE:0)
Block(-5,12,1,STONE:0)
Block(-5,12,2,STONE:0)
Block(-5,12,3,STONE:0)
Block(-5,12,4,STONE:0)
Block(-5,12,5,STONE:0)
Block(-5,12,6,STONE:0)
Block(-5,12,7,STONE:0)
Block(-5,12,8,STONE:0)
Block(-5,12,9,STONE:0)
Block(-5,12,10,STONE:0)
Block(-5,12,11,STONE:0)
Block(-5,13,-12,STONE:0)
Block(-5,13,-11,STONE:0)
Block(-5,13,-10,STONE:0)
Block(-5,13,-9,STONE:0)
Block(-5,13,-8,STONE:0)
Block(-5,13,-7,STONE:0)
Block(-5,13,-6,STONE:0)
Block(-5,13,-5,STONE:0)
Block(-5,13,-4,STONE:0)
Block(-5,13,-3,STONE:0)
Block(-5,13,-2,STONE:0)
Block(-5,13,-1,STONE:0)
Block(-5,13,0,STONE:0)
Block(-5,13,1,STONE:0)
Block(-5,13,2,STONE:0)
Block(-5,13,3,STONE:0)
Block(-5,13,4,STONE:0)
Block(-5,13,5,STONE:0)
Block(-5,13,6,STONE:0)
Block(-5,13,7,STONE:0)
Block(-5,13,8,STONE:0)
Block(-5,13,9,STONE:0)
Block(-5,13,10,STONE:0)
Block(-5,13,11,STONE:0)
Block(-5,14,-12,STONE:0)
Block(-5,14,-11,STONE:0)
Block(-5,14,-10,STONE:0)
Block(-5,14,-9,STONE:0)
Block(-5,14,-8,STONE:0)
Block(-5,14,-7,STONE:0)
Block(-5,14,-6,STONE:0)
Block(-5,14,-5,STONE:0)
Block(-5,14,-4,STONE:0)
Block(-5,14,-3,STONE:0)
Block(-5,14,-2,STONE:0)
Block(-5,14,-1,STONE:0)
Block(-5,14,0,STONE:0)
Block(-5,14,1,STONE:0)
Block(-5,14,2,STONE:0)
Block(-5,14,3,STONE:0)
Block(-5,14,4,STONE:0)
Block(-5,14,5,STONE:0)
Block(-5,14,6,STONE:0)
Block(-5,14,7,STONE:0)
Block(-5,14,8,STONE:0)
Block(-5,14,9,STONE:0)
Block(-5,14,10,STONE:0)
Block(-5,14,11,STONE:0)
Block(-5,15,-12,STONE:0)
Block(-5,15,-11,STONE:0)
Block(-5,15,-10,STONE:0)
Block(-5,15,-9,STONE:0)
Block(-5,15,-8,STONE:0)
Block(-5,15,-7,STONE:0)
Block(-5,15,-6,STONE:0)
Block(-5,15,-5,STONE:0)
Block(-5,15,-4,STONE:0)
Block(-5,15,-3,STONE:0)
Block(-5,15,-2,STONE:0)
Block(-5,15,-1,STONE:0)
Block(-5,15,0,STONE:0)
Block(-5,15,1,STONE:0)
Block(-5,15,2,STONE:0)
Block(-5,15,3,STONE:0)
Block(-5,15,4,STONE:0)
Block(-5,15,5,STONE:0)
Block(-5,15,6,STONE:0)
Block(-5,15,7,STONE:0)
Block(-5,15,8,STONE:0)
Block(-5,15,9,STONE:0)
Block(-5,16,-11,STONE:0)
Block(-5,16,-10,STONE:0)
Block(-5,16,-9,STONE:0)
Block(-5,16,-8,STONE:0)
Block(-5,16,-7,STONE:0)
Block(-5,16,-6,STONE:0)
Block(-5,16,-5,STONE:0)
Block(-5,16,-4,STONE:0)
Block(-5,16,-3,STONE:0)
Block(-5,16,-2,STONE:0)
Block(-5,16,-1,STONE:0)
Block(-5,16,0,STONE:0)
Block(-5,16,1,STONE:0)
Block(-5,16,2,STONE:0)
Block(-5,16,3,STONE:0)
Block(-5,16,4,STONE:0)
Block(-5,16,5,STONE:0)
Block(-5,16,6,STONE:0)
Block(-5,16,7,STONE:0)
Block(-5,16,8,STONE:0)
Block(-5,17,-10,STONE:0)
Block(-5,17,-9,STONE:0)
Block(-5,17,-8,STONE:0)
Block(-5,17,-7,STONE:0)
Block(-5,17,-6,STONE:0)
Block(-5,17,-5,STONE:0)
Block(-5,17,-4,STONE:0)
Block(-5,17,-3,STONE:0)
Block(-5,17,-2,STONE:0)
Block(-5,17,-1,STONE:0)
Block(-5,17,0,STONE:0)
Block(-5,17,1,STONE:0)
Block(-5,17,2,STONE:0)
Block(-5,17,3,STONE:0)
Block(-5,17,4,STONE:0)
Block(-5,17,5,STONE:0)
Block(-5,17,6,STONE:0)
Block(-5,17,7,STONE:0)
Block(-5,18,-10,STONE:0)
Block(-5,18,-9,STONE:0)
Block(-5,18,-8,STONE:0)
Block(-5,18,-7,STONE:0)
Block(-5,18,-6,STONE:0)
Block(-5,18,-5,STONE:0)
Block(-5,18,-4,STONE:0)
Block(-5,18,-3,STONE:0)
Block(-5,18,-2,STONE:0)
Block(-5,18,-1,STONE:0)
Block(-5,18,0,STONE:0)
Block(-5,18,1,STONE:0)
Block(-5,18,2,STONE:0)
Block(-5,18,3,STONE:0)
Block(-5,18,4,STONE:0)
Block(-5,18,5,STONE:0)
Block(-5,18,6,STONE:0)
Block(-5,18,7,STONE:0)
Block(-5,19,-10,STONE:0)
Block(-5,19,-9,STONE:0)
Block(-5,19,-8,STONE:0)
Block(-5,19,-7,STONE:0)
Block(-5,19,-6,STONE:0)
Block(-5,19,-5,STONE:0)
Block(-5,19,-4,STONE:0)
Block(-5,19,-3,STONE:0)
Block(-5,19,-2,STONE:0)
Block(-5,19,-1,STONE:0)
Block(-5,19,0,STONE:0)
Block(-5,19,1,STONE:0)
Block(-5,19,2,STONE:0)
Block(-5,19,3,STONE:0)
Block(-5,19,4,STONE:0)
Block(-5,19,5,STONE:0)
Block(-5,19,6,STONE:0)
Block(-5,19,7,STONE:0)
Block(-5,20,-9,STONE:0)
Block(-5,20,-8,STONE:0)
Block(-5,20,-7,STONE:0)
Block(-5,20,-6,STONE:0)
Block(-5,20,-5,STONE:0)
Block(-5,20,-4,STONE:0)
Block(-5,20,-3,STONE:0)
Block(-5,20,-2,STONE:0)
Block(-5,20,-1,STONE:0)
Block(-5,20,0,STONE:0)
Block(-5,20,1,STONE:0)
Block(-5,20,2,STONE:0)
Block(-5,20,3,STONE:0)
Block(-5,20,4,STONE:0)
Block(-5,20,5,STONE:0)
Block(-5,20,6,STONE:0)
Block(-5,20,7,STONE:0)
Block(-5,21,-9,STONE:0)
Block(-5,21,-8,STONE:0)
Block(-5,21,-7,STONE:0)
Block(-5,21,-6,STONE:0)
Block(-5,21,-5,STONE:0)
Block(-5,21,-4,STONE:0)
Block(-5,21,-3,STONE:0)
Block(-5,21,-2,STONE:0)
Block(-5,21,-1,STONE:0)
Block(-5,21,0,STONE:0)
Block(-5,21,1,STONE:0)
Block(-5,21,2,STONE:0)
Block(-5,21,3,STONE:0)
Block(-5,21,4,STONE:0)
Block(-5,21,5,STONE:0)
Block(-5,21,6,STONE:0)
Block(-5,21,7,STONE:0)
Block(-5,22,-9,STONE:0)
Block(-5,22,-8,STONE:0)
Block(-5,22,-7,STONE:0)
Block(-5,22,-6,STONE:0)
Block(-5,22,-5,STONE:0)
Block(-5,22,-4,STONE:0)
Block(-5,22,-3,STONE:0)
Block(-5,22,-2,STONE:0)
Block(-5,22,-1,STONE:0)
Block(-5,22,0,STONE:0)
Block(-5,22,1,STONE:0)
Block(-5,22,2,STONE:0)
Block(-5,22,3,STONE:0)
Block(-5,22,4,STONE:0)
Block(-5,22,5,STONE:0)
Block(-5,22,6,STONE:0)
Block(-5,23,-9,STONE:0)
Block(-5,23,-8,STONE:0)
Block(-5,23,-7,STONE:0)
Block(-5,23,-6,STONE:0)
Block(-5,23,-5,STONE:0)
Block(-5,23,-4,STONE:0)
Block(-5,23,-3,STONE:0)
Block(-5,23,-2,STONE:0)
Block(-5,23,-1,STONE:0)
Block(-5,23,0,STONE:0)
Block(-5,23,1,STONE:0)
Block(-5,23,2,STONE:0)
Block(-5,23,3,STONE:0)
Block(-5,23,4,STONE:0)
Block(-5,23,5,STONE:0)
Block(-5,23,6,STONE:0)
Block(-5,24,-9,STONE:0)
Block(-5,24,-8,STONE:0)
Block(-5,24,-7,STONE:0)
Block(-5,24,-6,STONE:0)
Block(-5,24,-5,STONE:0)
Block(-5,24,-4,STONE:0)
Block(-5,24,-3,STONE:0)
Block(-5,24,-2,STONE:0)
Block(-5,24,-1,STONE:0)
Block(-5,24,0,STONE:0)
Block(-5,24,1,STONE:0)
Block(-5,24,2,STONE:0)
Block(-5,24,3,STONE:0)
Block(-5,24,4,STONE:0)
Block(-5,24,5,STONE:0)
Block(-5,24,6,STONE:0)
Block(-5,25,-9,STONE:0)
Block(-5,25,-8,STONE:0)
Block(-5,25,-7,STONE:0)
Block(-5,25,-6,STONE:0)
Block(-5,25,-5,STONE:0)
Block(-5,25,-4,STONE:0)
Block(-5,25,-3,STONE:0)
Block(-5,25,-2,STONE:0)
Block(-5,25,-1,STONE:0)
Block(-5,25,0,STONE:0)
Block(-5,25,1,STONE:0)
Block(-5,25,2,STONE:0)
Block(-5,25,3,STONE:0)
Block(-5,25,4,STONE:0)
Block(-5,25,5,STONE:0)
Block(-5,25,6,STONE:0)
Block(-5,26,-9,STONE:0)
Block(-5,26,-8,STONE:0)
Block(-5,26,-7,STONE:0)
Block(-5,26,-6,STONE:0)
Block(-5,26,-5,STONE:0)
Block(-5,26,-4,STONE:0)
Block(-5,26,-3,STONE:0)
Block(-5,26,-2,STONE:0)
Block(-5,26,-1,STONE:0)
Block(-5,26,0,STONE:0)
Block(-5,26,1,STONE:0)
Block(-5,26,2,STONE:0)
Block(-5,26,3,STONE:0)
Block(-5,26,4,STONE:0)
Block(-5,26,5,STONE:0)
Block(-5,26,6,STONE:0)
Block(-5,27,-9,STONE:0)
Block(-5,27,-8,STONE:0)
Block(-5,27,-7,STONE:0)
Block(-5,27,-6,STONE:0)
Block(-5,27,-5,STONE:0)
Block(-5,27,-4,STONE:0)
Block(-5,27,-3,STONE:0)
Block(-5,27,-2,STONE:0)
Block(-5,27,-1,STONE:0)
Block(-5,27,0,STONE:0)
Block(-5,27,1,STONE:0)
Block(-5,27,2,STONE:0)
Block(-5,27,3,STONE:0)
Block(-5,27,4,STONE:0)
Block(-5,27,5,STONE:0)
Block(-5,27,6,STONE:0)
Block(-5,28,-9,STONE:0)
Block(-5,28,-8,STONE:0)
Block(-5,28,-7,STONE:0)
Block(-5,28,-6,STONE:0)
Block(-5,28,-5,STONE:0)
Block(-5,28,-4,STONE:0)
Block(-5,28,-3,STONE:0)
Block(-5,28,-2,STONE:0)
Block(-5,28,-1,STONE:0)
Block(-5,28,0,STONE:0)
Block(-5,28,1,STONE:0)
Block(-5,28,2,STONE:0)
Block(-5,28,3,STONE:0)
Block(-5,28,4,STONE:0)
Block(-5,28,5,STONE:0)
Block(-5,28,6,STONE:0)
Block(-5,29,-9,STONE:0)
Block(-5,29,-8,STONE:0)
Block(-5,29,-7,STONE:0)
Block(-5,29,-6,STONE:0)
Block(-5,29,-5,STONE:0)
Block(-5,29,-4,STONE:0)
Block(-5,29,-3,STONE:0)
Block(-5,29,-2,STONE:0)
Block(-5,29,-1,STONE:0)
Block(-5,29,0,STONE:0)
Block(-5,29,1,STONE:0)
Block(-5,29,2,STONE:0)
Block(-5,29,3,STONE:0)
Block(-5,29,4,STONE:0)
Block(-5,29,5,STONE:0)
Block(-5,29,6,STONE:0)
Block(-5,30,-9,STONE:0)
Block(-5,30,-8,STONE:0)
Block(-5,30,-7,STONE:0)
Block(-5,30,-6,STONE:0)
Block(-5,30,-5,STONE:0)
Block(-5,30,-4,STONE:0)
Block(-5,30,-3,STONE:0)
Block(-5,30,-2,STONE:0)
Block(-5,30,-1,STONE:0)
Block(-5,30,0,STONE:0)
Block(-5,30,1,STONE:0)
Block(-5,30,2,STONE:0)
Block(-5,30,3,STONE:0)
Block(-5,30,4,STONE:0)
Block(-5,30,5,STONE:0)
Block(-5,30,6,STONE:0)
Block(-5,31,-9,STONE:0)
Block(-5,31,-8,STONE:0)
Block(-5,31,-7,STONE:0)
Block(-5,31,-6,STONE:0)
Block(-5,31,-5,STONE:0)
Block(-5,31,-4,STONE:0)
Block(-5,31,-3,STONE:0)
Block(-5,31,-2,STONE:0)
Block(-5,31,-1,STONE:0)
Block(-5,31,0,STONE:0)
Block(-5,31,1,STONE:0)
Block(-5,31,2,STONE:0)
Block(-5,31,3,STONE:0)
Block(-5,31,4,STONE:0)
Block(-5,31,5,STONE:0)
Block(-5,32,-8,STONE:0)
Block(-5,32,-7,STONE:0)
Block(-5,32,-6,STONE:0)
Block(-5,32,-5,STONE:0)
Block(-5,32,-4,STONE:0)
Block(-5,32,-3,STONE:0)
Block(-5,32,-2,STONE:0)
Block(-5,32,-1,STONE:0)
Block(-5,32,0,STONE:0)
Block(-5,32,1,STONE:0)
Block(-5,32,2,STONE:0)
Block(-5,32,3,STONE:0)
Block(-5,32,4,STONE:0)
Block(-5,32,5,STONE:0)
Block(-5,33,-8,STONE:0)
Block(-5,33,-7,STONE:0)
Block(-5,33,-6,STONE:0)
Block(-5,33,-5,STONE:0)
Block(-5,33,-4,STONE:0)
Block(-5,33,-3,STONE:0)
Block(-5,33,-2,STONE:0)
Block(-5,33,-1,STONE:0)
Block(-5,33,0,STONE:0)
Block(-5,33,1,STONE:0)
Block(-5,33,2,STONE:0)
Block(-5,33,3,STONE:0)
Block(-5,33,4,STONE:0)
Block(-5,33,5,STONE:0)
Block(-5,34,-8,STONE:0)
Block(-5,34,-7,STONE:0)
Block(-5,34,-6,STONE:0)
Block(-5,34,-5,STONE:0)
Block(-5,34,-4,STONE:0)
Block(-5,34,-3,STONE:0)
Block(-5,34,-2,STONE:0)
Block(-5,34,-1,STONE:0)
Block(-5,34,0,STONE:0)
Block(-5,34,1,STONE:0)
Block(-5,34,2,STONE:0)
Block(-5,34,3,STONE:0)
Block(-5,34,4,STONE:0)
Block(-5,34,5,STONE:0)
Block(-5,35,-8,STONE:0)
Block(-5,35,-7,STONE:0)
Block(-5,35,-6,STONE:0)
Block(-5,35,-5,STONE:0)
Block(-5,35,-4,STONE:0)
Block(-5,35,-3,STONE:0)
Block(-5,35,-2,STONE:0)
Block(-5,35,-1,STONE:0)
Block(-5,35,0,STONE:0)
Block(-5,35,1,STONE:0)
Block(-5,35,2,STONE:0)
Block(-5,35,3,STONE:0)
Block(-5,35,4,STONE:0)
Block(-5,35,5,STONE:0)
Block(-5,36,-8,STONE:0)
Block(-5,36,-7,STONE:0)
Block(-5,36,-6,STONE:0)
Block(-5,36,-5,STONE:0)
Block(-5,36,-4,STONE:0)
Block(-5,36,-3,STONE:0)
Block(-5,36,-2,STONE:0)
Block(-5,36,-1,STONE:0)
Block(-5,36,0,STONE:0)
Block(-5,36,1,STONE:0)
Block(-5,36,2,STONE:0)
Block(-5,36,3,STONE:0)
Block(-5,36,4,STONE:0)
Block(-5,36,5,STONE:0)
Block(-5,37,-8,STONE:0)
Block(-5,37,-7,STONE:0)
Block(-5,37,-6,STONE:0)
Block(-5,37,-5,STONE:0)
Block(-5,37,-4,STONE:0)
Block(-5,37,-3,STONE:0)
Block(-5,37,-2,STONE:0)
Block(-5,37,-1,STONE:0)
Block(-5,37,0,STONE:0)
Block(-5,37,1,STONE:0)
Block(-5,37,2,STONE:0)
Block(-5,37,3,STONE:0)
Block(-5,37,4,STONE:0)
Block(-5,37,5,STONE:0)
Block(-5,38,-7,STONE:0)
Block(-5,38,-6,STONE:0)
Block(-5,38,-5,STONE:0)
Block(-5,38,-4,STONE:0)
Block(-5,38,-3,STONE:0)
Block(-5,38,-2,STONE:0)
Block(-5,38,-1,STONE:0)
Block(-5,38,0,STONE:0)
Block(-5,38,1,STONE:0)
Block(-5,38,2,STONE:0)
Block(-5,38,3,STONE:0)
Block(-5,38,4,STONE:0)
Block(-5,38,5,STONE:0)
Block(-5,39,-7,STONE:0)
Block(-5,39,-6,STONE:0)
Block(-5,39,-5,STONE:0)
Block(-5,39,-4,STONE:0)
Block(-5,39,-3,STONE:0)
Block(-5,39,-2,STONE:0)
Block(-5,39,-1,STONE:0)
Block(-5,39,0,STONE:0)
Block(-5,39,1,STONE:0)
Block(-5,39,2,STONE:0)
Block(-5,39,3,STONE:0)
Block(-5,39,4,STONE:0)
Block(-5,39,5,STONE:0)
Block(-5,40,-7,STONE:0)
Block(-5,40,-6,STONE:0)
Block(-5,40,-5,STONE:0)
Block(-5,40,-4,STONE:0)
Block(-5,40,-3,STONE:0)
Block(-5,40,-2,STONE:0)
Block(-5,40,-1,STONE:0)
Block(-5,40,0,STONE:0)
Block(-5,40,1,STONE:0)
Block(-5,40,2,STONE:0)
Block(-5,40,3,STONE:0)
Block(-5,40,4,STONE:0)
Block(-5,40,5,STONE:0)
Block(-5,41,-7,STONE:0)
Block(-5,41,-6,STONE:0)
Block(-5,41,-5,STONE:0)
Block(-5,41,-4,STONE:0)
Block(-5,41,-3,STONE:0)
Block(-5,41,-2,STONE:0)
