
#######################################################################
# +-----------------------------------------------------------------+ #
# |                            BO3 object                           | #
# +-----------------------------------------------------------------+ #
#######################################################################

# This is the config file of a custom object.
# If you add this object correctly to your BiomeConfigs, it will spawn in the world.

# This is the creator of this BO3 object
Author: Unknown

# A short description of this BO3 object
Description: No description given

# The BO3 version, don't change this! It can be used by external applications to do a version check.
Version: 3

# The settings mode, WriteAll, WriteWithoutComments or WriteDisable. See WorldConfig.
SettingsMode: WriteAll


#######################################################################
# +-----------------------------------------------------------------+ #
# |                          Main settings                          | #
# +-----------------------------------------------------------------+ #
#######################################################################

# This needs to be set to true to spawn the object in the Tree and Sapling resources.
Tree: true

# The frequency of the BO3 from 1 to 200. Tries this many times to spawn this BO3 when using the CustomObject(...) resource.
# Ignored by Tree(..), Sapling(..) and CustomStructure(..)
Frequency: 3

# The rarity of the BO3 from 0 to 100. Each spawn attempt has rarity% chance to succeed when using the CustomObject(...) resource.
# Ignored by Tree(..), Sapling(..) and CustomStructure(..)
Rarity: 66.0

# If you set this to true, the BO3 will be placed with a random rotation.
RotateRandomly: true

# The spawn height of the BO3: randomY, highestBlock or highestSolidBlock.
SpawnHeight: highestSolidBlock

# The offset from the spawn height to spawn this BO3
# Ex. SpawnHeight = highestSolidBlock, SpawnHeightOffset = 3; This object will spawn 3 blocks above the highest solid block
SpawnHeightOffset: -20

# A random amount to offset the spawn location from the spawn offset height
# Ex. SpawnHeightOffset = 3, SpawnHeightVariance = 3; This object will spawn 3 to 6 blocks above the original spot it would have spawned
SpawnHeightVariance: 0

##############################
# Height Limits for the BO3. #
##############################

# When in randomY mode used as the minimum Y or in atMinY mode as the actual Y to spawn this BO3 at.
MinHeight: 62

# When in randomY mode used as the maximum Y to spawn this BO3 at.
MaxHeight: 130

######################
# Extrusion settings #
######################

# The style of extrusion you wish to use - BottomDown, TopUp, None (Default)
ExtrudeMode: BottomDown

# The blocks to extrude your BO3 through
ExtrudeThroughBlocks: AIR,GRASS

# Objects can have other objects attacthed to it: branches. Branches can also
# have branches attached to it, which can also have branches, etc. This is the
# maximum branch depth for this objects.
MaxBranchDepth: 10

# When spawned with the UseWorld keyword, this BO3 should NOT spawn in the following biomes.
# If you write the BO3 name directly in the BiomeConfigs, this will be ignored.
ExcludedBiomes: All


#######################################################################
# +-----------------------------------------------------------------+ #
# |                      Source block settings                      | #
# +-----------------------------------------------------------------+ #
#######################################################################

# The block(s) the BO3 should spawn in.
SourceBlocks: AIR

# The maximum percentage of the BO3 that can be outside the SourceBlock.
# The BO3 won't be placed on a location with more blocks outside the SourceBlock than this percentage.
MaxPercentageOutsideSourceBlock: 100

# What to do when a block is about to be placed outside the SourceBlock? (dontPlace, placeAnyway)
OutsideSourceBlock: placeAnyway

# Disable doReplaceBlocks to make this BO3 ignore any ReplacedBlocks settings in biome configs, improves performance.
DoReplaceBlocks: true

# OTG+ settings #
# Legacy setting, rename this file to .BO4 instead. Set this to true to enable the advanced customstructure features of OTG+.
IsOTGPlus: false


#######################################################################
# +-----------------------------------------------------------------+ #
# |                              Blocks                             | #
# +-----------------------------------------------------------------+ #
#######################################################################

# All the blocks used in the BO3 are listed here. Possible blocks:
# Block(x,y,z,id[.data][,nbtfile.nbt)
# RandomBlock(x,y,z,id[:data][,nbtfile.nbt],chance[,id[:data][,nbtfile.nbt],chance[,...]])
#  So RandomBlock(0,0,0,CHEST,chest.nbt,50,CHEST,anotherchest.nbt,100) will spawn a chest at
#  the BO3 origin, and give it a 50% chance to have the contents of chest.nbt, or, if that
#  fails, a 100% percent chance to have the contents of anotherchest.nbt.
# *Note: Unlike Entity() and Spawner(), for Block() .txt files don't work, only .nbt files work.
# MinecraftObject(x,y,z,name) (TODO: This may not work anymore and needs to be tested.
#  Spawns an object in the Mojang NBT structure format. For example, 
#  MinecraftObject(0,0,0,minecraft:igloo/igloo_bottom)
#  spawns the bottom part of an igloo.
Block(-18,0,-6,STONE:0)
Block(-18,0,-5,STONE:0)
Block(-18,0,-4,STONE:0)
Block(-18,0,-3,STONE:0)
Block(-18,0,-2,STONE:0)
Block(-18,0,-1,STONE:0)
Block(-18,1,-5,STONE:0)
Block(-18,1,-4,STONE:0)
Block(-18,1,-3,STONE:0)
Block(-18,1,-2,STONE:0)
Block(-18,2,-5,STONE:0)
Block(-18,2,-4,STONE:0)
Block(-18,2,-3,STONE:0)
Block(-18,3,-4,STONE:0)
Block(-17,0,-10,STONE:0)
Block(-17,0,-9,STONE:0)
Block(-17,0,-8,STONE:0)
Block(-17,0,-7,STONE:0)
Block(-17,0,-6,STONE:0)
Block(-17,0,-5,STONE:0)
Block(-17,0,-4,STONE:0)
Block(-17,0,-3,STONE:0)
Block(-17,0,-2,STONE:0)
Block(-17,0,-1,STONE:0)
Block(-17,0,0,STONE:0)
Block(-17,0,1,STONE:0)
Block(-17,1,-10,STONE:0)
Block(-17,1,-9,STONE:0)
Block(-17,1,-8,STONE:0)
Block(-17,1,-7,STONE:0)
Block(-17,1,-6,STONE:0)
Block(-17,1,-5,STONE:0)
Block(-17,1,-4,STONE:0)
Block(-17,1,-3,STONE:0)
Block(-17,1,-2,STONE:0)
Block(-17,1,-1,STONE:0)
Block(-17,1,0,STONE:0)
Block(-17,1,1,STONE:0)
Block(-17,2,-10,STONE:0)
Block(-17,2,-9,STONE:0)
Block(-17,2,-8,STONE:0)
Block(-17,2,-7,STONE:0)
Block(-17,2,-6,STONE:0)
Block(-17,2,-5,STONE:0)
Block(-17,2,-4,STONE:0)
Block(-17,2,-3,STONE:0)
Block(-17,2,-2,STONE:0)
Block(-17,2,-1,STONE:0)
Block(-17,2,0,STONE:0)
Block(-17,2,1,STONE:0)
Block(-17,3,-9,STONE:0)
Block(-17,3,-8,STONE:0)
Block(-17,3,-7,STONE:0)
Block(-17,3,-6,STONE:0)
Block(-17,3,-5,STONE:0)
Block(-17,3,-4,STONE:0)
Block(-17,3,-3,STONE:0)
Block(-17,3,-2,STONE:0)
Block(-17,3,-1,STONE:0)
Block(-17,3,0,STONE:0)
Block(-17,3,1,STONE:0)
Block(-17,4,-9,STONE:0)
Block(-17,4,-8,STONE:0)
Block(-17,4,-7,STONE:0)
Block(-17,4,-6,STONE:0)
Block(-17,4,-5,STONE:0)
Block(-17,4,-4,STONE:0)
Block(-17,4,-3,STONE:0)
Block(-17,4,-2,STONE:0)
Block(-17,4,-1,STONE:0)
Block(-17,4,0,STONE:0)
Block(-17,5,-9,STONE:0)
Block(-17,5,-8,STONE:0)
Block(-17,5,-7,STONE:0)
Block(-17,5,-6,STONE:0)
Block(-17,5,-5,STONE:0)
Block(-17,5,-4,STONE:0)
Block(-17,5,-3,STONE:0)
Block(-17,5,-2,STONE:0)
Block(-17,5,-1,STONE:0)
Block(-17,5,0,STONE:0)
Block(-17,6,-9,STONE:0)
Block(-17,6,-8,STONE:0)
Block(-17,6,-7,STONE:0)
Block(-17,6,-6,STONE:0)
Block(-17,6,-5,STONE:0)
Block(-17,6,-4,STONE:0)
Block(-17,6,-3,STONE:0)
Block(-17,6,-2,STONE:0)
Block(-17,6,-1,STONE:0)
Block(-17,6,0,STONE:0)
Block(-17,7,-9,STONE:0)
Block(-17,7,-8,STONE:0)
Block(-17,7,-7,STONE:0)
Block(-17,7,-6,STONE:0)
Block(-17,7,-5,STONE:0)
Block(-17,7,-4,STONE:0)
Block(-17,7,-3,STONE:0)
Block(-17,7,-2,STONE:0)
Block(-17,7,-1,STONE:0)
Block(-17,7,0,STONE:0)
Block(-17,8,-9,STONE:0)
Block(-17,8,-8,STONE:0)
Block(-17,8,-7,STONE:0)
Block(-17,8,-6,STONE:0)
Block(-17,8,-5,STONE:0)
Block(-17,8,-4,STONE:0)
Block(-17,8,-3,STONE:0)
Block(-17,8,-2,STONE:0)
Block(-17,8,-1,STONE:0)
Block(-17,8,0,STONE:0)
Block(-17,9,-8,STONE:0)
Block(-17,9,-7,STONE:0)
Block(-17,9,-6,STONE:0)
Block(-17,9,-5,STONE:0)
Block(-17,9,-4,STONE:0)
Block(-17,9,-3,STONE:0)
Block(-17,9,-2,STONE:0)
Block(-17,9,-1,STONE:0)
Block(-17,9,0,STONE:0)
Block(-17,10,-8,STONE:0)
Block(-17,10,-7,STONE:0)
Block(-17,10,-6,STONE:0)
Block(-17,10,-5,STONE:0)
Block(-17,10,-4,STONE:0)
Block(-17,10,-3,STONE:0)
Block(-17,10,-2,STONE:0)
Block(-17,10,-1,STONE:0)
Block(-17,10,0,STONE:0)
Block(-17,11,-8,STONE:0)
Block(-17,11,-7,STONE:0)
Block(-17,11,-6,STONE:0)
Block(-17,11,-5,STONE:0)
Block(-17,11,-4,STONE:0)
Block(-17,11,-3,STONE:0)
Block(-17,11,-2,STONE:0)
Block(-17,11,-1,STONE:0)
Block(-17,12,-8,STONE:0)
Block(-17,12,-7,STONE:0)
Block(-17,12,-6,STONE:0)
Block(-17,12,-5,STONE:0)
Block(-17,12,-4,STONE:0)
Block(-17,12,-3,STONE:0)
Block(-17,12,-2,STONE:0)
Block(-17,12,-1,STONE:0)
Block(-17,13,-8,STONE:0)
Block(-17,13,-7,STONE:0)
Block(-17,13,-6,STONE:0)
Block(-17,13,-5,STONE:0)
Block(-17,13,-4,STONE:0)
Block(-17,13,-3,STONE:0)
Block(-17,13,-2,STONE:0)
Block(-17,13,-1,STONE:0)
Block(-17,14,-8,STONE:0)
Block(-17,14,-7,STONE:0)
Block(-17,14,-6,STONE:0)
Block(-17,14,-5,STONE:0)
Block(-17,14,-4,STONE:0)
Block(-17,14,-3,STONE:0)
Block(-17,14,-2,STONE:0)
Block(-17,14,-1,STONE:0)
Block(-17,15,-8,STONE:0)
Block(-17,15,-7,STONE:0)
Block(-17,15,-6,STONE:0)
Block(-17,15,-5,STONE:0)
Block(-17,15,-4,STONE:0)
Block(-17,15,-3,STONE:0)
Block(-17,15,-2,STONE:0)
Block(-17,15,-1,STONE:0)
Block(-17,16,-7,STONE:0)
Block(-17,16,-6,STONE:0)
Block(-17,16,-5,STONE:0)
Block(-17,16,-4,STONE:0)
Block(-17,16,-3,STONE:0)
Block(-17,16,-2,STONE:0)
Block(-17,16,-1,STONE:0)
Block(-17,17,-7,STONE:0)
Block(-17,17,-6,STONE:0)
Block(-17,17,-5,STONE:0)
Block(-17,17,-4,STONE:0)
Block(-17,17,-3,STONE:0)
Block(-17,17,-2,STONE:0)
Block(-17,17,-1,STONE:0)
Block(-17,18,-7,STONE:0)
Block(-17,18,-6,STONE:0)
Block(-17,18,-5,STONE:0)
Block(-17,18,-4,STONE:0)
Block(-17,18,-3,STONE:0)
Block(-17,18,-2,STONE:0)
Block(-17,19,-7,STONE:0)
Block(-17,19,-6,STONE:0)
Block(-17,19,-5,STONE:0)
Block(-17,19,-4,STONE:0)
Block(-17,19,-3,STONE:0)
Block(-17,19,-2,STONE:0)
Block(-17,20,-7,STONE:0)
Block(-17,20,-6,STONE:0)
Block(-17,20,-5,STONE:0)
Block(-17,20,-4,STONE:0)
Block(-17,20,-3,STONE:0)
Block(-17,20,-2,STONE:0)
Block(-17,21,-6,STONE:0)
Block(-17,21,-5,STONE:0)
Block(-17,21,-4,STONE:0)
Block(-17,21,-3,STONE:0)
Block(-17,21,-2,STONE:0)
Block(-17,22,-6,STONE:0)
Block(-17,22,-5,STONE:0)
Block(-17,23,-6,STONE:0)
Block(-16,0,-11,STONE:0)
Block(-16,0,-10,STONE:0)
Block(-16,0,-9,STONE:0)
Block(-16,0,-8,STONE:0)
Block(-16,0,-7,STONE:0)
Block(-16,0,-6,STONE:0)
Block(-16,0,-5,STONE:0)
Block(-16,0,-4,STONE:0)
Block(-16,0,-3,STONE:0)
Block(-16,0,-2,STONE:0)
Block(-16,0,-1,STONE:0)
Block(-16,0,0,STONE:0)
Block(-16,0,1,STONE:0)
Block(-16,0,2,STONE:0)
Block(-16,1,-11,STONE:0)
Block(-16,1,-10,STONE:0)
Block(-16,1,-9,STONE:0)
Block(-16,1,-8,STONE:0)
Block(-16,1,-7,STONE:0)
Block(-16,1,-6,STONE:0)
Block(-16,1,-5,STONE:0)
Block(-16,1,-4,STONE:0)
Block(-16,1,-3,STONE:0)
Block(-16,1,-2,STONE:0)
Block(-16,1,-1,STONE:0)
Block(-16,1,0,STONE:0)
Block(-16,1,1,STONE:0)
Block(-16,1,2,STONE:0)
Block(-16,2,-11,STONE:0)
Block(-16,2,-10,STONE:0)
Block(-16,2,-9,STONE:0)
Block(-16,2,-8,STONE:0)
Block(-16,2,-7,STONE:0)
Block(-16,2,-6,STONE:0)
Block(-16,2,-5,STONE:0)
Block(-16,2,-4,STONE:0)
Block(-16,2,-3,STONE:0)
Block(-16,2,-2,STONE:0)
Block(-16,2,-1,STONE:0)
Block(-16,2,0,STONE:0)
Block(-16,2,1,STONE:0)
Block(-16,2,2,STONE:0)
Block(-16,3,-11,STONE:0)
Block(-16,3,-10,STONE:0)
Block(-16,3,-9,STONE:0)
Block(-16,3,-8,STONE:0)
Block(-16,3,-7,STONE:0)
Block(-16,3,-6,STONE:0)
Block(-16,3,-5,STONE:0)
Block(-16,3,-4,STONE:0)
Block(-16,3,-3,STONE:0)
Block(-16,3,-2,STONE:0)
Block(-16,3,-1,STONE:0)
Block(-16,3,0,STONE:0)
Block(-16,3,1,STONE:0)
Block(-16,4,-11,STONE:0)
Block(-16,4,-10,STONE:0)
Block(-16,4,-9,STONE:0)
Block(-16,4,-8,STONE:0)
Block(-16,4,-7,STONE:0)
Block(-16,4,-6,STONE:0)
Block(-16,4,-5,STONE:0)
Block(-16,4,-4,STONE:0)
Block(-16,4,-3,STONE:0)
Block(-16,4,-2,STONE:0)
Block(-16,4,-1,STONE:0)
Block(-16,4,0,STONE:0)
Block(-16,4,1,STONE:0)
Block(-16,5,-10,STONE:0)
Block(-16,5,-9,STONE:0)
Block(-16,5,-8,STONE:0)
Block(-16,5,-7,STONE:0)
Block(-16,5,-6,STONE:0)
Block(-16,5,-5,STONE:0)
Block(-16,5,-4,STONE:0)
Block(-16,5,-3,STONE:0)
Block(-16,5,-2,STONE:0)
Block(-16,5,-1,STONE:0)
Block(-16,5,0,STONE:0)
Block(-16,5,1,STONE:0)
Block(-16,6,-10,STONE:0)
Block(-16,6,-9,STONE:0)
Block(-16,6,-8,STONE:0)
Block(-16,6,-7,STONE:0)
Block(-16,6,-6,STONE:0)
Block(-16,6,-5,STONE:0)
Block(-16,6,-4,STONE:0)
Block(-16,6,-3,STONE:0)
Block(-16,6,-2,STONE:0)
Block(-16,6,-1,STONE:0)
Block(-16,6,0,STONE:0)
Block(-16,6,1,STONE:0)
Block(-16,7,-10,STONE:0)
Block(-16,7,-9,STONE:0)
Block(-16,7,-8,STONE:0)
Block(-16,7,-7,STONE:0)
Block(-16,7,-6,STONE:0)
Block(-16,7,-5,STONE:0)
Block(-16,7,-4,STONE:0)
Block(-16,7,-3,STONE:0)
Block(-16,7,-2,STONE:0)
Block(-16,7,-1,STONE:0)
Block(-16,7,0,STONE:0)
Block(-16,7,1,STONE:0)
Block(-16,8,-10,STONE:0)
Block(-16,8,-9,STONE:0)
Block(-16,8,-8,STONE:0)
Block(-16,8,-7,STONE:0)
Block(-16,8,-6,STONE:0)
Block(-16,8,-5,STONE:0)
Block(-16,8,-4,STONE:0)
Block(-16,8,-3,STONE:0)
Block(-16,8,-2,STONE:0)
Block(-16,8,-1,STONE:0)
Block(-16,8,0,STONE:0)
Block(-16,8,1,STONE:0)
Block(-16,9,-10,STONE:0)
Block(-16,9,-9,STONE:0)
Block(-16,9,-8,STONE:0)
Block(-16,9,-7,STONE:0)
Block(-16,9,-6,STONE:0)
Block(-16,9,-5,STONE:0)
Block(-16,9,-4,STONE:0)
Block(-16,9,-3,STONE:0)
Block(-16,9,-2,STONE:0)
Block(-16,9,-1,STONE:0)
Block(-16,9,0,STONE:0)
Block(-16,9,1,STONE:0)
Block(-16,10,-10,STONE:0)
Block(-16,10,-9,STONE:0)
Block(-16,10,-8,STONE:0)
Block(-16,10,-7,STONE:0)
Block(-16,10,-6,STONE:0)
Block(-16,10,-5,STONE:0)
Block(-16,10,-4,STONE:0)
Block(-16,10,-3,STONE:0)
Block(-16,10,-2,STONE:0)
Block(-16,10,-1,STONE:0)
Block(-16,10,0,STONE:0)
Block(-16,11,-10,STONE:0)
Block(-16,11,-9,STONE:0)
Block(-16,11,-8,STONE:0)
Block(-16,11,-7,STONE:0)
Block(-16,11,-6,STONE:0)
Block(-16,11,-5,STONE:0)
Block(-16,11,-4,STONE:0)
Block(-16,11,-3,STONE:0)
Block(-16,11,-2,STONE:0)
Block(-16,11,-1,STONE:0)
Block(-16,11,0,STONE:0)
Block(-16,12,-10,STONE:0)
Block(-16,12,-9,STONE:0)
Block(-16,12,-8,STONE:0)
Block(-16,12,-7,STONE:0)
Block(-16,12,-6,STONE:0)
Block(-16,12,-5,STONE:0)
Block(-16,12,-4,STONE:0)
Block(-16,12,-3,STONE:0)
Block(-16,12,-2,STONE:0)
Block(-16,12,-1,STONE:0)
Block(-16,12,0,STONE:0)
Block(-16,13,-10,STONE:0)
Block(-16,13,-9,STONE:0)
Block(-16,13,-8,STONE:0)
Block(-16,13,-7,STONE:0)
Block(-16,13,-6,STONE:0)
Block(-16,13,-5,STONE:0)
Block(-16,13,-4,STONE:0)
Block(-16,13,-3,STONE:0)
Block(-16,13,-2,STONE:0)
Block(-16,13,-1,STONE:0)
Block(-16,13,0,STONE:0)
Block(-16,14,-10,STONE:0)
Block(-16,14,-9,STONE:0)
Block(-16,14,-8,STONE:0)
Block(-16,14,-7,STONE:0)
Block(-16,14,-6,STONE:0)
Block(-16,14,-5,STONE:0)
Block(-16,14,-4,STONE:0)
Block(-16,14,-3,STONE:0)
Block(-16,14,-2,STONE:0)
Block(-16,14,-1,STONE:0)
Block(-16,14,0,STONE:0)
Block(-16,15,-9,STONE:0)
Block(-16,15,-8,STONE:0)
Block(-16,15,-7,STONE:0)
Block(-16,15,-6,STONE:0)
Block(-16,15,-5,STONE:0)
Block(-16,15,-4,STONE:0)
Block(-16,15,-3,STONE:0)
Block(-16,15,-2,STONE:0)
Block(-16,15,-1,STONE:0)
Block(-16,15,0,STONE:0)
Block(-16,16,-9,STONE:0)
Block(-16,16,-8,STONE:0)
Block(-16,16,-7,STONE:0)
Block(-16,16,-6,STONE:0)
Block(-16,16,-5,STONE:0)
Block(-16,16,-4,STONE:0)
Block(-16,16,-3,STONE:0)
Block(-16,16,-2,STONE:0)
Block(-16,16,-1,STONE:0)
Block(-16,16,0,STONE:0)
Block(-16,17,-9,STONE:0)
Block(-16,17,-8,STONE:0)
Block(-16,17,-7,STONE:0)
Block(-16,17,-6,STONE:0)
Block(-16,17,-5,STONE:0)
Block(-16,17,-4,STONE:0)
Block(-16,17,-3,STONE:0)
Block(-16,17,-2,STONE:0)
Block(-16,17,-1,STONE:0)
Block(-16,17,0,STONE:0)
Block(-16,18,-9,STONE:0)
Block(-16,18,-8,STONE:0)
Block(-16,18,-7,STONE:0)
Block(-16,18,-6,STONE:0)
Block(-16,18,-5,STONE:0)
Block(-16,18,-4,STONE:0)
Block(-16,18,-3,STONE:0)
Block(-16,18,-2,STONE:0)
Block(-16,18,-1,STONE:0)
Block(-16,18,0,STONE:0)
Block(-16,19,-9,STONE:0)
Block(-16,19,-8,STONE:0)
Block(-16,19,-7,STONE:0)
Block(-16,19,-6,STONE:0)
Block(-16,19,-5,STONE:0)
Block(-16,19,-4,STONE:0)
Block(-16,19,-3,STONE:0)
Block(-16,19,-2,STONE:0)
Block(-16,19,-1,STONE:0)
Block(-16,19,0,STONE:0)
Block(-16,20,-9,STONE:0)
Block(-16,20,-8,STONE:0)
Block(-16,20,-7,STONE:0)
Block(-16,20,-6,STONE:0)
Block(-16,20,-5,STONE:0)
Block(-16,20,-4,STONE:0)
Block(-16,20,-3,STONE:0)
Block(-16,20,-2,STONE:0)
Block(-16,20,-1,STONE:0)
Block(-16,20,0,STONE:0)
Block(-16,21,-9,STONE:0)
Block(-16,21,-8,STONE:0)
Block(-16,21,-7,STONE:0)
Block(-16,21,-6,STONE:0)
Block(-16,21,-5,STONE:0)
Block(-16,21,-4,STONE:0)
Block(-16,21,-3,STONE:0)
Block(-16,21,-2,STONE:0)
Block(-16,21,-1,STONE:0)
Block(-16,22,-9,STONE:0)
Block(-16,22,-8,STONE:0)
Block(-16,22,-7,STONE:0)
Block(-16,22,-6,STONE:0)
Block(-16,22,-5,STONE:0)
Block(-16,22,-4,STONE:0)
Block(-16,22,-3,STONE:0)
Block(-16,22,-2,STONE:0)
Block(-16,22,-1,STONE:0)
Block(-16,23,-9,STONE:0)
Block(-16,23,-8,STONE:0)
Block(-16,23,-7,STONE:0)
Block(-16,23,-6,STONE:0)
Block(-16,23,-5,STONE:0)
Block(-16,23,-4,STONE:0)
Block(-16,23,-3,STONE:0)
Block(-16,23,-2,STONE:0)
Block(-16,23,-1,STONE:0)
Block(-16,24,-9,STONE:0)
Block(-16,24,-8,STONE:0)
Block(-16,24,-7,STONE:0)
Block(-16,24,-6,STONE:0)
Block(-16,24,-5,STONE:0)
Block(-16,24,-4,STONE:0)
Block(-16,24,-3,STONE:0)
Block(-16,24,-2,STONE:0)
Block(-16,24,-1,STONE:0)
Block(-16,25,-9,STONE:0)
Block(-16,25,-8,STONE:0)
Block(-16,25,-7,STONE:0)
Block(-16,25,-6,STONE:0)
Block(-16,25,-5,STONE:0)
Block(-16,25,-4,STONE:0)
Block(-16,25,-3,STONE:0)
Block(-16,25,-2,STONE:0)
Block(-16,25,-1,STONE:0)
Block(-16,26,-9,STONE:0)
Block(-16,26,-8,STONE:0)
Block(-16,26,-7,STONE:0)
Block(-16,26,-6,STONE:0)
Block(-16,26,-5,STONE:0)
Block(-16,26,-4,STONE:0)
Block(-16,26,-3,STONE:0)
Block(-16,26,-2,STONE:0)
Block(-16,26,-1,STONE:0)
Block(-16,27,-8,STONE:0)
Block(-16,27,-7,STONE:0)
Block(-16,27,-6,STONE:0)
Block(-16,27,-5,STONE:0)
Block(-16,27,-4,STONE:0)
Block(-16,27,-3,STONE:0)
Block(-16,27,-2,STONE:0)
Block(-16,27,-1,STONE:0)
Block(-16,28,-8,STONE:0)
Block(-16,28,-7,STONE:0)
Block(-16,28,-6,STONE:0)
Block(-16,28,-5,STONE:0)
Block(-16,28,-4,STONE:0)
Block(-16,28,-3,STONE:0)
Block(-16,28,-2,STONE:0)
Block(-16,28,-1,STONE:0)
Block(-16,29,-8,STONE:0)
Block(-16,29,-7,STONE:0)
Block(-16,29,-6,STONE:0)
Block(-16,29,-5,STONE:0)
Block(-16,29,-4,STONE:0)
Block(-16,29,-3,STONE:0)
Block(-16,29,-2,STONE:0)
Block(-16,29,-1,STONE:0)
Block(-16,30,-8,STONE:0)
Block(-16,30,-7,STONE:0)
Block(-16,30,-6,STONE:0)
Block(-16,30,-5,STONE:0)
Block(-16,30,-4,STONE:0)
Block(-16,30,-3,STONE:0)
Block(-16,30,-2,STONE:0)
Block(-16,31,-8,STONE:0)
Block(-16,31,-7,STONE:0)
Block(-16,31,-6,STONE:0)
Block(-16,31,-5,STONE:0)
Block(-16,31,-4,STONE:0)
Block(-16,31,-3,STONE:0)
Block(-16,31,-2,STONE:0)
Block(-16,32,-8,STONE:0)
Block(-16,32,-7,STONE:0)
Block(-16,32,-6,STONE:0)
Block(-16,32,-5,STONE:0)
Block(-16,32,-4,STONE:0)
Block(-16,32,-3,STONE:0)
Block(-16,32,-2,STONE:0)
Block(-16,33,-8,STONE:0)
Block(-16,33,-7,STONE:0)
Block(-16,33,-6,STONE:0)
Block(-16,33,-5,STONE:0)
Block(-16,33,-4,STONE:0)
Block(-16,33,-3,STONE:0)
Block(-16,33,-2,STONE:0)
Block(-16,34,-7,STONE:0)
Block(-16,34,-6,STONE:0)
Block(-16,34,-5,STONE:0)
Block(-16,34,-4,STONE:0)
Block(-16,34,-3,STONE:0)
Block(-16,34,-2,STONE:0)
Block(-16,35,-7,STONE:0)
Block(-16,35,-6,STONE:0)
Block(-16,35,-5,STONE:0)
Block(-16,35,-4,STONE:0)
Block(-16,35,-3,STONE:0)
Block(-16,36,-7,STONE:0)
Block(-16,36,-6,STONE:0)
Block(-16,36,-5,STONE:0)
Block(-16,36,-4,STONE:0)
Block(-16,36,-3,STONE:0)
Block(-16,37,-7,STONE:0)
Block(-16,37,-6,STONE:0)
Block(-16,37,-5,STONE:0)
Block(-16,37,-4,STONE:0)
Block(-16,38,-7,STONE:0)
Block(-16,38,-6,STONE:0)
Block(-16,38,-5,STONE:0)
Block(-16,38,-4,STONE:0)
Block(-16,39,-7,STONE:0)
Block(-16,39,-6,STONE:0)
Block(-16,39,-5,STONE:0)
Block(-16,39,-4,STONE:0)
Block(-16,40,-6,STONE:0)
Block(-16,40,-5,STONE:0)
Block(-16,41,-6,STONE:0)
Block(-16,41,-5,STONE:0)
Block(-16,42,-6,STONE:0)
Block(-16,42,-5,STONE:0)
Block(-15,0,-12,STONE:0)
Block(-15,0,-11,STONE:0)
Block(-15,0,-10,STONE:0)
Block(-15,0,-9,STONE:0)
Block(-15,0,-8,STONE:0)
Block(-15,0,-7,STONE:0)
Block(-15,0,-6,STONE:0)
Block(-15,0,-5,STONE:0)
Block(-15,0,-4,STONE:0)
Block(-15,0,-3,STONE:0)
Block(-15,0,-2,STONE:0)
Block(-15,0,-1,STONE:0)
Block(-15,0,0,STONE:0)
Block(-15,0,1,STONE:0)
Block(-15,0,2,STONE:0)
Block(-15,0,3,STONE:0)
Block(-15,1,-12,STONE:0)
Block(-15,1,-11,STONE:0)
Block(-15,1,-10,STONE:0)
Block(-15,1,-9,STONE:0)
Block(-15,1,-8,STONE:0)
Block(-15,1,-7,STONE:0)
Block(-15,1,-6,STONE:0)
Block(-15,1,-5,STONE:0)
Block(-15,1,-4,STONE:0)
Block(-15,1,-3,STONE:0)
Block(-15,1,-2,STONE:0)
Block(-15,1,-1,STONE:0)
Block(-15,1,0,STONE:0)
Block(-15,1,1,STONE:0)
Block(-15,1,2,STONE:0)
Block(-15,1,3,STONE:0)
Block(-15,2,-12,STONE:0)
Block(-15,2,-11,STONE:0)
Block(-15,2,-10,STONE:0)
Block(-15,2,-9,STONE:0)
Block(-15,2,-8,STONE:0)
Block(-15,2,-7,STONE:0)
Block(-15,2,-6,STONE:0)
Block(-15,2,-5,STONE:0)
Block(-15,2,-4,STONE:0)
Block(-15,2,-3,STONE:0)
Block(-15,2,-2,STONE:0)
Block(-15,2,-1,STONE:0)
Block(-15,2,0,STONE:0)
Block(-15,2,1,STONE:0)
Block(-15,2,2,STONE:0)
Block(-15,3,-11,STONE:0)
Block(-15,3,-10,STONE:0)
Block(-15,3,-9,STONE:0)
Block(-15,3,-8,STONE:0)
Block(-15,3,-7,STONE:0)
Block(-15,3,-6,STONE:0)
Block(-15,3,-5,STONE:0)
Block(-15,3,-4,STONE:0)
Block(-15,3,-3,STONE:0)
Block(-15,3,-2,STONE:0)
Block(-15,3,-1,STONE:0)
Block(-15,3,0,STONE:0)
Block(-15,3,1,STONE:0)
Block(-15,3,2,STONE:0)
Block(-15,4,-11,STONE:0)
Block(-15,4,-10,STONE:0)
Block(-15,4,-9,STONE:0)
Block(-15,4,-8,STONE:0)
Block(-15,4,-7,STONE:0)
Block(-15,4,-6,STONE:0)
Block(-15,4,-5,STONE:0)
Block(-15,4,-4,STONE:0)
Block(-15,4,-3,STONE:0)
Block(-15,4,-2,STONE:0)
Block(-15,4,-1,STONE:0)
Block(-15,4,0,STONE:0)
Block(-15,4,1,STONE:0)
Block(-15,4,2,STONE:0)
Block(-15,5,-11,STONE:0)
Block(-15,5,-10,STONE:0)
Block(-15,5,-9,STONE:0)
Block(-15,5,-8,STONE:0)
Block(-15,5,-7,STONE:0)
Block(-15,5,-6,STONE:0)
Block(-15,5,-5,STONE:0)
Block(-15,5,-4,STONE:0)
Block(-15,5,-3,STONE:0)
Block(-15,5,-2,STONE:0)
Block(-15,5,-1,STONE:0)
Block(-15,5,0,STONE:0)
Block(-15,5,1,STONE:0)
Block(-15,5,2,STONE:0)
Block(-15,6,-11,STONE:0)
Block(-15,6,-10,STONE:0)
Block(-15,6,-9,STONE:0)
Block(-15,6,-8,STONE:0)
Block(-15,6,-7,STONE:0)
Block(-15,6,-6,STONE:0)
Block(-15,6,-5,STONE:0)
Block(-15,6,-4,STONE:0)
Block(-15,6,-3,STONE:0)
Block(-15,6,-2,STONE:0)
Block(-15,6,-1,STONE:0)
Block(-15,6,0,STONE:0)
Block(-15,6,1,STONE:0)
Block(-15,6,2,STONE:0)
Block(-15,7,-11,STONE:0)
Block(-15,7,-10,STONE:0)
Block(-15,7,-9,STONE:0)
Block(-15,7,-8,STONE:0)
Block(-15,7,-7,STONE:0)
Block(-15,7,-6,STONE:0)
Block(-15,7,-5,STONE:0)
Block(-15,7,-4,STONE:0)
Block(-15,7,-3,STONE:0)
Block(-15,7,-2,STONE:0)
Block(-15,7,-1,STONE:0)
Block(-15,7,0,STONE:0)
Block(-15,7,1,STONE:0)
Block(-15,7,2,STONE:0)
Block(-15,8,-11,STONE:0)
Block(-15,8,-10,STONE:0)
Block(-15,8,-9,STONE:0)
Block(-15,8,-8,STONE:0)
Block(-15,8,-7,STONE:0)
Block(-15,8,-6,STONE:0)
Block(-15,8,-5,STONE:0)
Block(-15,8,-4,STONE:0)
Block(-15,8,-3,STONE:0)
Block(-15,8,-2,STONE:0)
Block(-15,8,-1,STONE:0)
Block(-15,8,0,STONE:0)
Block(-15,8,1,STONE:0)
Block(-15,9,-11,STONE:0)
Block(-15,9,-10,STONE:0)
Block(-15,9,-9,STONE:0)
Block(-15,9,-8,STONE:0)
Block(-15,9,-7,STONE:0)
Block(-15,9,-6,STONE:0)
Block(-15,9,-5,STONE:0)
Block(-15,9,-4,STONE:0)
Block(-15,9,-3,STONE:0)
Block(-15,9,-2,STONE:0)
Block(-15,9,-1,STONE:0)
Block(-15,9,0,STONE:0)
Block(-15,9,1,STONE:0)
Block(-15,10,-11,STONE:0)
Block(-15,10,-10,STONE:0)
Block(-15,10,-9,STONE:0)
Block(-15,10,-8,STONE:0)
Block(-15,10,-7,STONE:0)
Block(-15,10,-6,STONE:0)
Block(-15,10,-5,STONE:0)
Block(-15,10,-4,STONE:0)
Block(-15,10,-3,STONE:0)
Block(-15,10,-2,STONE:0)
Block(-15,10,-1,STONE:0)
Block(-15,10,0,STONE:0)
Block(-15,10,1,STONE:0)
Block(-15,11,-11,STONE:0)
Block(-15,11,-10,STONE:0)
Block(-15,11,-9,STONE:0)
Block(-15,11,-8,STONE:0)
Block(-15,11,-7,STONE:0)
Block(-15,11,-6,STONE:0)
Block(-15,11,-5,STONE:0)
Block(-15,11,-4,STONE:0)
Block(-15,11,-3,STONE:0)
Block(-15,11,-2,STONE:0)
Block(-15,11,-1,STONE:0)
Block(-15,11,0,STONE:0)
Block(-15,11,1,STONE:0)
Block(-15,12,-11,STONE:0)
Block(-15,12,-10,STONE:0)
Block(-15,12,-9,STONE:0)
Block(-15,12,-8,STONE:0)
Block(-15,12,-7,STONE:0)
Block(-15,12,-6,STONE:0)
Block(-15,12,-5,STONE:0)
Block(-15,12,-4,STONE:0)
Block(-15,12,-3,STONE:0)
Block(-15,12,-2,STONE:0)
Block(-15,12,-1,STONE:0)
Block(-15,12,0,STONE:0)
Block(-15,12,1,STONE:0)
Block(-15,13,-11,STONE:0)
Block(-15,13,-10,STONE:0)
Block(-15,13,-9,STONE:0)
Block(-15,13,-8,STONE:0)
Block(-15,13,-7,STONE:0)
Block(-15,13,-6,STONE:0)
Block(-15,13,-5,STONE:0)
Block(-15,13,-4,STONE:0)
Block(-15,13,-3,STONE:0)
Block(-15,13,-2,STONE:0)
Block(-15,13,-1,STONE:0)
Block(-15,13,0,STONE:0)
Block(-15,13,1,STONE:0)
Block(-15,14,-11,STONE:0)
Block(-15,14,-10,STONE:0)
Block(-15,14,-9,STONE:0)
Block(-15,14,-8,STONE:0)
Block(-15,14,-7,STONE:0)
Block(-15,14,-6,STONE:0)
Block(-15,14,-5,STONE:0)
Block(-15,14,-4,STONE:0)
Block(-15,14,-3,STONE:0)
Block(-15,14,-2,STONE:0)
Block(-15,14,-1,STONE:0)
Block(-15,14,0,STONE:0)
Block(-15,14,1,STONE:0)
Block(-15,15,-11,STONE:0)
Block(-15,15,-10,STONE:0)
Block(-15,15,-9,STONE:0)
Block(-15,15,-8,STONE:0)
Block(-15,15,-7,STONE:0)
Block(-15,15,-6,STONE:0)
Block(-15,15,-5,STONE:0)
Block(-15,15,-4,STONE:0)
Block(-15,15,-3,STONE:0)
Block(-15,15,-2,STONE:0)
Block(-15,15,-1,STONE:0)
Block(-15,15,0,STONE:0)
Block(-15,15,1,STONE:0)
Block(-15,16,-10,STONE:0)
Block(-15,16,-9,STONE:0)
Block(-15,16,-8,STONE:0)
Block(-15,16,-7,STONE:0)
Block(-15,16,-6,STONE:0)
Block(-15,16,-5,STONE:0)
Block(-15,16,-4,STONE:0)
Block(-15,16,-3,STONE:0)
Block(-15,16,-2,STONE:0)
Block(-15,16,-1,STONE:0)
Block(-15,16,0,STONE:0)
Block(-15,16,1,STONE:0)
Block(-15,17,-10,STONE:0)
Block(-15,17,-9,STONE:0)
Block(-15,17,-8,STONE:0)
Block(-15,17,-7,STONE:0)
Block(-15,17,-6,STONE:0)
Block(-15,17,-5,STONE:0)
Block(-15,17,-4,STONE:0)
Block(-15,17,-3,STONE:0)
Block(-15,17,-2,STONE:0)
Block(-15,17,-1,STONE:0)
Block(-15,17,0,STONE:0)
Block(-15,17,1,STONE:0)
Block(-15,18,-10,STONE:0)
Block(-15,18,-9,STONE:0)
Block(-15,18,-8,STONE:0)
Block(-15,18,-7,STONE:0)
Block(-15,18,-6,STONE:0)
Block(-15,18,-5,STONE:0)
Block(-15,18,-4,STONE:0)
Block(-15,18,-3,STONE:0)
Block(-15,18,-2,STONE:0)
Block(-15,18,-1,STONE:0)
Block(-15,18,0,STONE:0)
Block(-15,18,1,STONE:0)
Block(-15,19,-10,STONE:0)
Block(-15,19,-9,STONE:0)
Block(-15,19,-8,STONE:0)
Block(-15,19,-7,STONE:0)
Block(-15,19,-6,STONE:0)
Block(-15,19,-5,STONE:0)
Block(-15,19,-4,STONE:0)
Block(-15,19,-3,STONE:0)
Block(-15,19,-2,STONE:0)
Block(-15,19,-1,STONE:0)
Block(-15,19,0,STONE:0)
Block(-15,20,-10,STONE:0)
Block(-15,20,-9,STONE:0)
Block(-15,20,-8,STONE:0)
Block(-15,20,-7,STONE:0)
Block(-15,20,-6,STONE:0)
Block(-15,20,-5,STONE:0)
Block(-15,20,-4,STONE:0)
Block(-15,20,-3,STONE:0)
Block(-15,20,-2,STONE:0)
Block(-15,20,-1,STONE:0)
Block(-15,20,0,STONE:0)
Block(-15,21,-10,STONE:0)
Block(-15,21,-9,STONE:0)
Block(-15,21,-8,STONE:0)
Block(-15,21,-7,STONE:0)
Block(-15,21,-6,STONE:0)
Block(-15,21,-5,STONE:0)
Block(-15,21,-4,STONE:0)
Block(-15,21,-3,STONE:0)
Block(-15,21,-2,STONE:0)
Block(-15,21,-1,STONE:0)
Block(-15,21,0,STONE:0)
Block(-15,22,-10,STONE:0)
Block(-15,22,-9,STONE:0)
Block(-15,22,-8,STONE:0)
Block(-15,22,-7,STONE:0)
Block(-15,22,-6,STONE:0)
Block(-15,22,-5,STONE:0)
Block(-15,22,-4,STONE:0)
Block(-15,22,-3,STONE:0)
Block(-15,22,-2,STONE:0)
Block(-15,22,-1,STONE:0)
Block(-15,22,0,STONE:0)
Block(-15,23,-10,STONE:0)
Block(-15,23,-9,STONE:0)
Block(-15,23,-8,STONE:0)
Block(-15,23,-7,STONE:0)
Block(-15,23,-6,STONE:0)
Block(-15,23,-5,STONE:0)
Block(-15,23,-4,STONE:0)
Block(-15,23,-3,STONE:0)
Block(-15,23,-2,STONE:0)
Block(-15,23,-1,STONE:0)
Block(-15,23,0,STONE:0)
Block(-15,24,-10,STONE:0)
Block(-15,24,-9,STONE:0)
Block(-15,24,-8,STONE:0)
Block(-15,24,-7,STONE:0)
Block(-15,24,-6,STONE:0)
Block(-15,24,-5,STONE:0)
Block(-15,24,-4,STONE:0)
Block(-15,24,-3,STONE:0)
Block(-15,24,-2,STONE:0)
Block(-15,24,-1,STONE:0)
Block(-15,24,0,STONE:0)
Block(-15,25,-10,STONE:0)
Block(-15,25,-9,STONE:0)
Block(-15,25,-8,STONE:0)
Block(-15,25,-7,STONE:0)
Block(-15,25,-6,STONE:0)
Block(-15,25,-5,STONE:0)
Block(-15,25,-4,STONE:0)
Block(-15,25,-3,STONE:0)
Block(-15,25,-2,STONE:0)
Block(-15,25,-1,STONE:0)
Block(-15,25,0,STONE:0)
Block(-15,26,-10,STONE:0)
Block(-15,26,-9,STONE:0)
Block(-15,26,-8,STONE:0)
Block(-15,26,-7,STONE:0)
Block(-15,26,-6,STONE:0)
Block(-15,26,-5,STONE:0)
Block(-15,26,-4,STONE:0)
Block(-15,26,-3,STONE:0)
Block(-15,26,-2,STONE:0)
Block(-15,26,-1,STONE:0)
Block(-15,26,0,STONE:0)
Block(-15,27,-10,STONE:0)
Block(-15,27,-9,STONE:0)
Block(-15,27,-8,STONE:0)
Block(-15,27,-7,STONE:0)
Block(-15,27,-6,STONE:0)
Block(-15,27,-5,STONE:0)
Block(-15,27,-4,STONE:0)
Block(-15,27,-3,STONE:0)
Block(-15,27,-2,STONE:0)
Block(-15,27,-1,STONE:0)
Block(-15,27,0,STONE:0)
Block(-15,28,-10,STONE:0)
Block(-15,28,-9,STONE:0)
Block(-15,28,-8,STONE:0)
Block(-15,28,-7,STONE:0)
Block(-15,28,-6,STONE:0)
Block(-15,28,-5,STONE:0)
Block(-15,28,-4,STONE:0)
Block(-15,28,-3,STONE:0)
Block(-15,28,-2,STONE:0)
Block(-15,28,-1,STONE:0)
Block(-15,28,0,STONE:0)
Block(-15,29,-9,STONE:0)
Block(-15,29,-8,STONE:0)
Block(-15,29,-7,STONE:0)
Block(-15,29,-6,STONE:0)
Block(-15,29,-5,STONE:0)
Block(-15,29,-4,STONE:0)
Block(-15,29,-3,STONE:0)
Block(-15,29,-2,STONE:0)
Block(-15,29,-1,STONE:0)
Block(-15,29,0,STONE:0)
Block(-15,30,-9,STONE:0)
Block(-15,30,-8,STONE:0)
Block(-15,30,-7,STONE:0)
Block(-15,30,-6,STONE:0)
Block(-15,30,-5,STONE:0)
Block(-15,30,-4,STONE:0)
Block(-15,30,-3,STONE:0)
Block(-15,30,-2,STONE:0)
Block(-15,30,-1,STONE:0)
Block(-15,30,0,STONE:0)
Block(-15,31,-9,STONE:0)
Block(-15,31,-8,STONE:0)
Block(-15,31,-7,STONE:0)
Block(-15,31,-6,STONE:0)
Block(-15,31,-5,STONE:0)
Block(-15,31,-4,STONE:0)
Block(-15,31,-3,STONE:0)
Block(-15,31,-2,STONE:0)
Block(-15,31,-1,STONE:0)
Block(-15,31,0,STONE:0)
Block(-15,32,-9,STONE:0)
Block(-15,32,-8,STONE:0)
Block(-15,32,-7,STONE:0)
Block(-15,32,-6,STONE:0)
Block(-15,32,-5,STONE:0)
Block(-15,32,-4,STONE:0)
Block(-15,32,-3,STONE:0)
Block(-15,32,-2,STONE:0)
Block(-15,32,-1,STONE:0)
Block(-15,33,-9,STONE:0)
Block(-15,33,-8,STONE:0)
Block(-15,33,-7,STONE:0)
Block(-15,33,-6,STONE:0)
Block(-15,33,-5,STONE:0)
Block(-15,33,-4,STONE:0)
Block(-15,33,-3,STONE:0)
Block(-15,33,-2,STONE:0)
Block(-15,33,-1,STONE:0)
Block(-15,34,-9,STONE:0)
Block(-15,34,-8,STONE:0)
Block(-15,34,-7,STONE:0)
Block(-15,34,-6,STONE:0)
Block(-15,34,-5,STONE:0)
Block(-15,34,-4,STONE:0)
Block(-15,34,-3,STONE:0)
Block(-15,34,-2,STONE:0)
Block(-15,34,-1,STONE:0)
Block(-15,35,-9,STONE:0)
Block(-15,35,-8,STONE:0)
Block(-15,35,-7,STONE:0)
Block(-15,35,-6,STONE:0)
Block(-15,35,-5,STONE:0)
Block(-15,35,-4,STONE:0)
Block(-15,35,-3,STONE:0)
Block(-15,35,-2,STONE:0)
Block(-15,35,-1,STONE:0)
Block(-15,36,-8,STONE:0)
Block(-15,36,-7,STONE:0)
Block(-15,36,-6,STONE:0)
Block(-15,36,-5,STONE:0)
Block(-15,36,-4,STONE:0)
Block(-15,36,-3,STONE:0)
Block(-15,36,-2,STONE:0)
Block(-15,36,-1,STONE:0)
Block(-15,37,-8,STONE:0)
Block(-15,37,-7,STONE:0)
Block(-15,37,-6,STONE:0)
Block(-15,37,-5,STONE:0)
Block(-15,37,-4,STONE:0)
Block(-15,37,-3,STONE:0)
Block(-15,37,-2,STONE:0)
Block(-15,37,-1,STONE:0)
Block(-15,38,-8,STONE:0)
Block(-15,38,-7,STONE:0)
Block(-15,38,-6,STONE:0)
Block(-15,38,-5,STONE:0)
Block(-15,38,-4,STONE:0)
Block(-15,38,-3,STONE:0)
Block(-15,38,-2,STONE:0)
Block(-15,38,-1,STONE:0)
Block(-15,39,-8,STONE:0)
Block(-15,39,-7,STONE:0)
Block(-15,39,-6,STONE:0)
Block(-15,39,-5,STONE:0)
Block(-15,39,-4,STONE:0)
Block(-15,39,-3,STONE:0)
Block(-15,39,-2,STONE:0)
Block(-15,39,-1,STONE:0)
Block(-15,40,-8,STONE:0)
Block(-15,40,-7,STONE:0)
Block(-15,40,-6,STONE:0)
Block(-15,40,-5,STONE:0)
Block(-15,40,-4,STONE:0)
Block(-15,40,-3,STONE:0)
Block(-15,40,-2,STONE:0)
Block(-15,40,-1,STONE:0)
Block(-15,41,-8,STONE:0)
Block(-15,41,-7,STONE:0)
Block(-15,41,-6,STONE:0)
Block(-15,41,-5,STONE:0)
Block(-15,41,-4,STONE:0)
Block(-15,41,-3,STONE:0)
Block(-15,41,-2,STONE:0)
Block(-15,42,-8,STONE:0)
Block(-15,42,-7,STONE:0)
Block(-15,42,-6,STONE:0)
Block(-15,42,-5,STONE:0)
Block(-15,42,-4,STONE:0)
Block(-15,42,-3,STONE:0)
Block(-15,42,-2,STONE:0)
Block(-14,0,-12,STONE:0)
Block(-14,0,-11,STONE:0)
Block(-14,0,-10,STONE:0)
Block(-14,0,-9,STONE:0)
Block(-14,0,-8,STONE:0)
Block(-14,0,-7,STONE:0)
Block(-14,0,-6,STONE:0)
Block(-14,0,-5,STONE:0)
Block(-14,0,-4,STONE:0)
Block(-14,0,-3,STONE:0)
Block(-14,0,-2,STONE:0)
Block(-14,0,-1,STONE:0)
Block(-14,0,0,STONE:0)
Block(-14,0,1,STONE:0)
Block(-14,0,2,STONE:0)
Block(-14,0,3,STONE:0)
Block(-14,0,4,STONE:0)
Block(-14,1,-12,STONE:0)
Block(-14,1,-11,STONE:0)
Block(-14,1,-10,STONE:0)
Block(-14,1,-9,STONE:0)
Block(-14,1,-8,STONE:0)
Block(-14,1,-7,STONE:0)
Block(-14,1,-6,STONE:0)
Block(-14,1,-5,STONE:0)
Block(-14,1,-4,STONE:0)
Block(-14,1,-3,STONE:0)
Block(-14,1,-2,STONE:0)
Block(-14,1,-1,STONE:0)
Block(-14,1,0,STONE:0)
Block(-14,1,1,STONE:0)
Block(-14,1,2,STONE:0)
Block(-14,1,3,STONE:0)
Block(-14,2,-12,STONE:0)
Block(-14,2,-11,STONE:0)
Block(-14,2,-10,STONE:0)
Block(-14,2,-9,STONE:0)
Block(-14,2,-8,STONE:0)
Block(-14,2,-7,STONE:0)
Block(-14,2,-6,STONE:0)
Block(-14,2,-5,STONE:0)
Block(-14,2,-4,STONE:0)
Block(-14,2,-3,STONE:0)
Block(-14,2,-2,STONE:0)
Block(-14,2,-1,STONE:0)
Block(-14,2,0,STONE:0)
Block(-14,2,1,STONE:0)
Block(-14,2,2,STONE:0)
Block(-14,2,3,STONE:0)
Block(-14,3,-12,STONE:0)
Block(-14,3,-11,STONE:0)
Block(-14,3,-10,STONE:0)
Block(-14,3,-9,STONE:0)
Block(-14,3,-8,STONE:0)
Block(-14,3,-7,STONE:0)
Block(-14,3,-6,STONE:0)
Block(-14,3,-5,STONE:0)
Block(-14,3,-4,STONE:0)
Block(-14,3,-3,STONE:0)
Block(-14,3,-2,STONE:0)
Block(-14,3,-1,STONE:0)
Block(-14,3,0,STONE:0)
Block(-14,3,1,STONE:0)
Block(-14,3,2,STONE:0)
Block(-14,4,-12,STONE:0)
Block(-14,4,-11,STONE:0)
Block(-14,4,-10,STONE:0)
Block(-14,4,-9,STONE:0)
Block(-14,4,-8,STONE:0)
Block(-14,4,-7,STONE:0)
Block(-14,4,-6,STONE:0)
Block(-14,4,-5,STONE:0)
Block(-14,4,-4,STONE:0)
Block(-14,4,-3,STONE:0)
Block(-14,4,-2,STONE:0)
Block(-14,4,-1,STONE:0)
Block(-14,4,0,STONE:0)
Block(-14,4,1,STONE:0)
Block(-14,4,2,STONE:0)
Block(-14,5,-12,STONE:0)
Block(-14,5,-11,STONE:0)
Block(-14,5,-10,STONE:0)
Block(-14,5,-9,STONE:0)
Block(-14,5,-8,STONE:0)
Block(-14,5,-7,STONE:0)
Block(-14,5,-6,STONE:0)
Block(-14,5,-5,STONE:0)
Block(-14,5,-4,STONE:0)
Block(-14,5,-3,STONE:0)
Block(-14,5,-2,STONE:0)
Block(-14,5,-1,STONE:0)
Block(-14,5,0,STONE:0)
Block(-14,5,1,STONE:0)
Block(-14,5,2,STONE:0)
Block(-14,6,-12,STONE:0)
Block(-14,6,-11,STONE:0)
Block(-14,6,-10,STONE:0)
Block(-14,6,-9,STONE:0)
Block(-14,6,-8,STONE:0)
Block(-14,6,-7,STONE:0)
Block(-14,6,-6,STONE:0)
Block(-14,6,-5,STONE:0)
Block(-14,6,-4,STONE:0)
Block(-14,6,-3,STONE:0)
Block(-14,6,-2,STONE:0)
Block(-14,6,-1,STONE:0)
Block(-14,6,0,STONE:0)
Block(-14,6,1,STONE:0)
Block(-14,6,2,STONE:0)
Block(-14,7,-12,STONE:0)
Block(-14,7,-11,STONE:0)
Block(-14,7,-10,STONE:0)
Block(-14,7,-9,STONE:0)
Block(-14,7,-8,STONE:0)
Block(-14,7,-7,STONE:0)
Block(-14,7,-6,STONE:0)
Block(-14,7,-5,STONE:0)
Block(-14,7,-4,STONE:0)
Block(-14,7,-3,STONE:0)
Block(-14,7,-2,STONE:0)
Block(-14,7,-1,STONE:0)
Block(-14,7,0,STONE:0)
Block(-14,7,1,STONE:0)
Block(-14,7,2,STONE:0)
Block(-14,8,-12,STONE:0)
Block(-14,8,-11,STONE:0)
Block(-14,8,-10,STONE:0)
Block(-14,8,-9,STONE:0)
Block(-14,8,-8,STONE:0)
Block(-14,8,-7,STONE:0)
Block(-14,8,-6,STONE:0)
Block(-14,8,-5,STONE:0)
Block(-14,8,-4,STONE:0)
Block(-14,8,-3,STONE:0)
Block(-14,8,-2,STONE:0)
Block(-14,8,-1,STONE:0)
Block(-14,8,0,STONE:0)
Block(-14,8,1,STONE:0)
Block(-14,8,2,STONE:0)
Block(-14,9,-12,STONE:0)
Block(-14,9,-11,STONE:0)
Block(-14,9,-10,STONE:0)
Block(-14,9,-9,STONE:0)
Block(-14,9,-8,STONE:0)
Block(-14,9,-7,STONE:0)
Block(-14,9,-6,STONE:0)
Block(-14,9,-5,STONE:0)
Block(-14,9,-4,STONE:0)
Block(-14,9,-3,STONE:0)
Block(-14,9,-2,STONE:0)
Block(-14,9,-1,STONE:0)
Block(-14,9,0,STONE:0)
Block(-14,9,1,STONE:0)
Block(-14,9,2,STONE:0)
Block(-14,10,-12,STONE:0)
Block(-14,10,-11,STONE:0)
Block(-14,10,-10,STONE:0)
Block(-14,10,-9,STONE:0)
Block(-14,10,-8,STONE:0)
Block(-14,10,-7,STONE:0)
Block(-14,10,-6,STONE:0)
Block(-14,10,-5,STONE:0)
Block(-14,10,-4,STONE:0)
Block(-14,10,-3,STONE:0)
Block(-14,10,-2,STONE:0)
Block(-14,10,-1,STONE:0)
Block(-14,10,0,STONE:0)
Block(-14,10,1,STONE:0)
Block(-14,11,-12,STONE:0)
Block(-14,11,-11,STONE:0)
Block(-14,11,-10,STONE:0)
Block(-14,11,-9,STONE:0)
Block(-14,11,-8,STONE:0)
Block(-14,11,-7,STONE:0)
Block(-14,11,-6,STONE:0)
Block(-14,11,-5,STONE:0)
Block(-14,11,-4,STONE:0)
Block(-14,11,-3,STONE:0)
Block(-14,11,-2,STONE:0)
Block(-14,11,-1,STONE:0)
Block(-14,11,0,STONE:0)
Block(-14,11,1,STONE:0)
Block(-14,12,-11,STONE:0)
Block(-14,12,-10,STONE:0)
Block(-14,12,-9,STONE:0)
Block(-14,12,-8,STONE:0)
Block(-14,12,-7,STONE:0)
Block(-14,12,-6,STONE:0)
Block(-14,12,-5,STONE:0)
Block(-14,12,-4,STONE:0)
Block(-14,12,-3,STONE:0)
Block(-14,12,-2,STONE:0)
Block(-14,12,-1,STONE:0)
Block(-14,12,0,STONE:0)
Block(-14,12,1,STONE:0)
Block(-14,13,-11,STONE:0)
Block(-14,13,-10,STONE:0)
Block(-14,13,-9,STONE:0)
Block(-14,13,-8,STONE:0)
Block(-14,13,-7,STONE:0)
Block(-14,13,-6,STONE:0)
Block(-14,13,-5,STONE:0)
Block(-14,13,-4,STONE:0)
Block(-14,13,-3,STONE:0)
Block(-14,13,-2,STONE:0)
Block(-14,13,-1,STONE:0)
Block(-14,13,0,STONE:0)
Block(-14,13,1,STONE:0)
Block(-14,14,-11,STONE:0)
Block(-14,14,-10,STONE:0)
Block(-14,14,-9,STONE:0)
Block(-14,14,-8,STONE:0)
Block(-14,14,-7,STONE:0)
Block(-14,14,-6,STONE:0)
Block(-14,14,-5,STONE:0)
Block(-14,14,-4,STONE:0)
Block(-14,14,-3,STONE:0)
Block(-14,14,-2,STONE:0)
Block(-14,14,-1,STONE:0)
Block(-14,14,0,STONE:0)
Block(-14,14,1,STONE:0)
Block(-14,15,-11,STONE:0)
Block(-14,15,-10,STONE:0)
Block(-14,15,-9,STONE:0)
Block(-14,15,-8,STONE:0)
Block(-14,15,-7,STONE:0)
Block(-14,15,-6,STONE:0)
Block(-14,15,-5,STONE:0)
Block(-14,15,-4,STONE:0)
Block(-14,15,-3,STONE:0)
Block(-14,15,-2,STONE:0)
Block(-14,15,-1,STONE:0)
Block(-14,15,0,STONE:0)
Block(-14,15,1,STONE:0)
Block(-14,16,-11,STONE:0)
Block(-14,16,-10,STONE:0)
Block(-14,16,-9,STONE:0)
Block(-14,16,-8,STONE:0)
Block(-14,16,-7,STONE:0)
Block(-14,16,-6,STONE:0)
Block(-14,16,-5,STONE:0)
Block(-14,16,-4,STONE:0)
Block(-14,16,-3,STONE:0)
Block(-14,16,-2,STONE:0)
Block(-14,16,-1,STONE:0)
Block(-14,16,0,STONE:0)
Block(-14,16,1,STONE:0)
Block(-14,17,-11,STONE:0)
Block(-14,17,-10,STONE:0)
Block(-14,17,-9,STONE:0)
Block(-14,17,-8,STONE:0)
Block(-14,17,-7,STONE:0)
Block(-14,17,-6,STONE:0)
Block(-14,17,-5,STONE:0)
Block(-14,17,-4,STONE:0)
Block(-14,17,-3,STONE:0)
Block(-14,17,-2,STONE:0)
Block(-14,17,-1,STONE:0)
Block(-14,17,0,STONE:0)
Block(-14,17,1,STONE:0)
Block(-14,18,-11,STONE:0)
Block(-14,18,-10,STONE:0)
Block(-14,18,-9,STONE:0)
Block(-14,18,-8,STONE:0)
Block(-14,18,-7,STONE:0)
Block(-14,18,-6,STONE:0)
Block(-14,18,-5,STONE:0)
Block(-14,18,-4,STONE:0)
Block(-14,18,-3,STONE:0)
Block(-14,18,-2,STONE:0)
Block(-14,18,-1,STONE:0)
Block(-14,18,0,STONE:0)
Block(-14,18,1,STONE:0)
Block(-14,19,-11,STONE:0)
Block(-14,19,-10,STONE:0)
Block(-14,19,-9,STONE:0)
Block(-14,19,-8,STONE:0)
Block(-14,19,-7,STONE:0)
Block(-14,19,-6,STONE:0)
Block(-14,19,-5,STONE:0)
Block(-14,19,-4,STONE:0)
Block(-14,19,-3,STONE:0)
Block(-14,19,-2,STONE:0)
Block(-14,19,-1,STONE:0)
Block(-14,19,0,STONE:0)
Block(-14,19,1,STONE:0)
Block(-14,20,-11,STONE:0)
Block(-14,20,-10,STONE:0)
Block(-14,20,-9,STONE:0)
Block(-14,20,-8,STONE:0)
Block(-14,20,-7,STONE:0)
Block(-14,20,-6,STONE:0)
Block(-14,20,-5,STONE:0)
Block(-14,20,-4,STONE:0)
Block(-14,20,-3,STONE:0)
Block(-14,20,-2,STONE:0)
Block(-14,20,-1,STONE:0)
Block(-14,20,0,STONE:0)
Block(-14,20,1,STONE:0)
Block(-14,21,-11,STONE:0)
Block(-14,21,-10,STONE:0)
Block(-14,21,-9,STONE:0)
Block(-14,21,-8,STONE:0)
Block(-14,21,-7,STONE:0)
Block(-14,21,-6,STONE:0)
Block(-14,21,-5,STONE:0)
Block(-14,21,-4,STONE:0)
Block(-14,21,-3,STONE:0)
Block(-14,21,-2,STONE:0)
Block(-14,21,-1,STONE:0)
Block(-14,21,0,STONE:0)
Block(-14,21,1,STONE:0)
Block(-14,22,-11,STONE:0)
Block(-14,22,-10,STONE:0)
Block(-14,22,-9,STONE:0)
Block(-14,22,-8,STONE:0)
Block(-14,22,-7,STONE:0)
Block(-14,22,-6,STONE:0)
Block(-14,22,-5,STONE:0)
Block(-14,22,-4,STONE:0)
Block(-14,22,-3,STONE:0)
Block(-14,22,-2,STONE:0)
Block(-14,22,-1,STONE:0)
Block(-14,22,0,STONE:0)
Block(-14,22,1,STONE:0)
Block(-14,23,-11,STONE:0)
Block(-14,23,-10,STONE:0)
Block(-14,23,-9,STONE:0)
Block(-14,23,-8,STONE:0)
Block(-14,23,-7,STONE:0)
Block(-14,23,-6,STONE:0)
Block(-14,23,-5,STONE:0)
Block(-14,23,-4,STONE:0)
Block(-14,23,-3,STONE:0)
Block(-14,23,-2,STONE:0)
Block(-14,23,-1,STONE:0)
Block(-14,23,0,STONE:0)
Block(-14,24,-11,STONE:0)
Block(-14,24,-10,STONE:0)
Block(-14,24,-9,STONE:0)
Block(-14,24,-8,STONE:0)
Block(-14,24,-7,STONE:0)
Block(-14,24,-6,STONE:0)
Block(-14,24,-5,STONE:0)
Block(-14,24,-4,STONE:0)
Block(-14,24,-3,STONE:0)
Block(-14,24,-2,STONE:0)
Block(-14,24,-1,STONE:0)
Block(-14,24,0,STONE:0)
Block(-14,25,-11,STONE:0)
Block(-14,25,-10,STONE:0)
Block(-14,25,-9,STONE:0)
Block(-14,25,-8,STONE:0)
Block(-14,25,-7,STONE:0)
Block(-14,25,-6,STONE:0)
Block(-14,25,-5,STONE:0)
Block(-14,25,-4,STONE:0)
Block(-14,25,-3,STONE:0)
Block(-14,25,-2,STONE:0)
Block(-14,25,-1,STONE:0)
Block(-14,25,0,STONE:0)
Block(-14,26,-11,STONE:0)
Block(-14,26,-10,STONE:0)
Block(-14,26,-9,STONE:0)
Block(-14,26,-8,STONE:0)
Block(-14,26,-7,STONE:0)
Block(-14,26,-6,STONE:0)
Block(-14,26,-5,STONE:0)
Block(-14,26,-4,STONE:0)
Block(-14,26,-3,STONE:0)
Block(-14,26,-2,STONE:0)
Block(-14,26,-1,STONE:0)
Block(-14,26,0,STONE:0)
Block(-14,27,-11,STONE:0)
Block(-14,27,-10,STONE:0)
Block(-14,27,-9,STONE:0)
Block(-14,27,-8,STONE:0)
Block(-14,27,-7,STONE:0)
Block(-14,27,-6,STONE:0)
Block(-14,27,-5,STONE:0)
Block(-14,27,-4,STONE:0)
Block(-14,27,-3,STONE:0)
Block(-14,27,-2,STONE:0)
Block(-14,27,-1,STONE:0)
Block(-14,27,0,STONE:0)
Block(-14,28,-10,STONE:0)
Block(-14,28,-9,STONE:0)
Block(-14,28,-8,STONE:0)
Block(-14,28,-7,STONE:0)
Block(-14,28,-6,STONE:0)
Block(-14,28,-5,STONE:0)
Block(-14,28,-4,STONE:0)
Block(-14,28,-3,STONE:0)
Block(-14,28,-2,STONE:0)
Block(-14,28,-1,STONE:0)
Block(-14,28,0,STONE:0)
Block(-14,29,-10,STONE:0)
Block(-14,29,-9,STONE:0)
Block(-14,29,-8,STONE:0)
Block(-14,29,-7,STONE:0)
Block(-14,29,-6,STONE:0)
Block(-14,29,-5,STONE:0)
Block(-14,29,-4,STONE:0)
Block(-14,29,-3,STONE:0)
Block(-14,29,-2,STONE:0)
Block(-14,29,-1,STONE:0)
Block(-14,29,0,STONE:0)
Block(-14,30,-10,STONE:0)
Block(-14,30,-9,STONE:0)
Block(-14,30,-8,STONE:0)
Block(-14,30,-7,STONE:0)
Block(-14,30,-6,STONE:0)
Block(-14,30,-5,STONE:0)
Block(-14,30,-4,STONE:0)
Block(-14,30,-3,STONE:0)
Block(-14,30,-2,STONE:0)
Block(-14,30,-1,STONE:0)
Block(-14,30,0,STONE:0)
Block(-14,31,-10,STONE:0)
Block(-14,31,-9,STONE:0)
Block(-14,31,-8,STONE:0)
Block(-14,31,-7,STONE:0)
Block(-14,31,-6,STONE:0)
Block(-14,31,-5,STONE:0)
Block(-14,31,-4,STONE:0)
Block(-14,31,-3,STONE:0)
Block(-14,31,-2,STONE:0)
Block(-14,31,-1,STONE:0)
Block(-14,31,0,STONE:0)
Block(-14,32,-10,STONE:0)
Block(-14,32,-9,STONE:0)
Block(-14,32,-8,STONE:0)
Block(-14,32,-7,STONE:0)
Block(-14,32,-6,STONE:0)
Block(-14,32,-5,STONE:0)
Block(-14,32,-4,STONE:0)
Block(-14,32,-3,STONE:0)
Block(-14,32,-2,STONE:0)
Block(-14,32,-1,STONE:0)
Block(-14,32,0,STONE:0)
Block(-14,33,-10,STONE:0)
Block(-14,33,-9,STONE:0)
Block(-14,33,-8,STONE:0)
Block(-14,33,-7,STONE:0)
Block(-14,33,-6,STONE:0)
Block(-14,33,-5,STONE:0)
Block(-14,33,-4,STONE:0)
Block(-14,33,-3,STONE:0)
Block(-14,33,-2,STONE:0)
Block(-14,33,-1,STONE:0)
Block(-14,33,0,STONE:0)
Block(-14,34,-10,STONE:0)
Block(-14,34,-9,STONE:0)
Block(-14,34,-8,STONE:0)
Block(-14,34,-7,STONE:0)
Block(-14,34,-6,STONE:0)
Block(-14,34,-5,STONE:0)
Block(-14,34,-4,STONE:0)
Block(-14,34,-3,STONE:0)
Block(-14,34,-2,STONE:0)
Block(-14,34,-1,STONE:0)
Block(-14,34,0,STONE:0)
Block(-14,35,-10,STONE:0)
Block(-14,35,-9,STONE:0)
Block(-14,35,-8,STONE:0)
Block(-14,35,-7,STONE:0)
Block(-14,35,-6,STONE:0)
Block(-14,35,-5,STONE:0)
Block(-14,35,-4,STONE:0)
Block(-14,35,-3,STONE:0)
Block(-14,35,-2,STONE:0)
Block(-14,35,-1,STONE:0)
Block(-14,35,0,STONE:0)
Block(-14,36,-10,STONE:0)
Block(-14,36,-9,STONE:0)
Block(-14,36,-8,STONE:0)
Block(-14,36,-7,STONE:0)
Block(-14,36,-6,STONE:0)
Block(-14,36,-5,STONE:0)
Block(-14,36,-4,STONE:0)
Block(-14,36,-3,STONE:0)
Block(-14,36,-2,STONE:0)
Block(-14,36,-1,STONE:0)
Block(-14,36,0,STONE:0)
Block(-14,37,-10,STONE:0)
Block(-14,37,-9,STONE:0)
Block(-14,37,-8,STONE:0)
Block(-14,37,-7,STONE:0)
Block(-14,37,-6,STONE:0)
Block(-14,37,-5,STONE:0)
Block(-14,37,-4,STONE:0)
Block(-14,37,-3,STONE:0)
Block(-14,37,-2,STONE:0)
Block(-14,37,-1,STONE:0)
Block(-14,37,0,STONE:0)
Block(-14,38,-10,STONE:0)
Block(-14,38,-9,STONE:0)
Block(-14,38,-8,STONE:0)
Block(-14,38,-7,STONE:0)
Block(-14,38,-6,STONE:0)
Block(-14,38,-5,STONE:0)
Block(-14,38,-4,STONE:0)
Block(-14,38,-3,STONE:0)
Block(-14,38,-2,STONE:0)
Block(-14,38,-1,STONE:0)
Block(-14,39,-9,STONE:0)
Block(-14,39,-8,STONE:0)
Block(-14,39,-7,STONE:0)
Block(-14,39,-6,STONE:0)
Block(-14,39,-5,STONE:0)
Block(-14,39,-4,STONE:0)
Block(-14,39,-3,STONE:0)
Block(-14,39,-2,STONE:0)
Block(-14,39,-1,STONE:0)
Block(-14,40,-9,STONE:0)
Block(-14,40,-8,STONE:0)
Block(-14,40,-7,STONE:0)
Block(-14,40,-6,STONE:0)
Block(-14,40,-5,STONE:0)
Block(-14,40,-4,STONE:0)
Block(-14,40,-3,STONE:0)
Block(-14,40,-2,STONE:0)
Block(-14,40,-1,STONE:0)
Block(-14,41,-9,STONE:0)
Block(-14,41,-8,STONE:0)
Block(-14,41,-7,STONE:0)
Block(-14,41,-6,STONE:0)
Block(-14,41,-5,STONE:0)
Block(-14,41,-4,STONE:0)
Block(-14,41,-3,STONE:0)
Block(-14,41,-2,STONE:0)
Block(-14,41,-1,STONE:0)
Block(-14,42,-9,STONE:0)
Block(-14,42,-8,STONE:0)
Block(-14,42,-7,GRASS:0)
Block(-14,42,-6,GRASS:0)
Block(-14,42,-5,GRASS:0)
Block(-14,42,-4,GRASS:0)
Block(-14,42,-3,GRASS:0)
Block(-14,42,-2,STONE:0)
Block(-14,42,-1,STONE:0)
Block(-13,0,-13,STONE:0)
Block(-13,0,-12,STONE:0)
Block(-13,0,-11,STONE:0)
Block(-13,0,-10,STONE:0)
Block(-13,0,-9,STONE:0)
Block(-13,0,-8,STONE:0)
Block(-13,0,-7,STONE:0)
Block(-13,0,-6,STONE:0)
Block(-13,0,-5,STONE:0)
Block(-13,0,-4,STONE:0)
Block(-13,0,-3,STONE:0)
Block(-13,0,-2,STONE:0)
Block(-13,0,-1,STONE:0)
Block(-13,0,0,STONE:0)
Block(-13,0,1,STONE:0)
Block(-13,0,2,STONE:0)
Block(-13,0,3,STONE:0)
Block(-13,0,4,STONE:0)
Block(-13,0,5,STONE:0)
Block(-13,1,-13,STONE:0)
Block(-13,1,-12,STONE:0)
Block(-13,1,-11,STONE:0)
Block(-13,1,-10,STONE:0)
Block(-13,1,-9,STONE:0)
Block(-13,1,-8,STONE:0)
Block(-13,1,-7,STONE:0)
Block(-13,1,-6,STONE:0)
Block(-13,1,-5,STONE:0)
Block(-13,1,-4,STONE:0)
Block(-13,1,-3,STONE:0)
Block(-13,1,-2,STONE:0)
Block(-13,1,-1,STONE:0)
Block(-13,1,0,STONE:0)
Block(-13,1,1,STONE:0)
Block(-13,1,2,STONE:0)
Block(-13,1,3,STONE:0)
Block(-13,2,-13,STONE:0)
Block(-13,2,-12,STONE:0)
Block(-13,2,-11,STONE:0)
Block(-13,2,-10,STONE:0)
Block(-13,2,-9,STONE:0)
Block(-13,2,-8,STONE:0)
Block(-13,2,-7,STONE:0)
Block(-13,2,-6,STONE:0)
Block(-13,2,-5,STONE:0)
Block(-13,2,-4,STONE:0)
Block(-13,2,-3,STONE:0)
Block(-13,2,-2,STONE:0)
Block(-13,2,-1,STONE:0)
Block(-13,2,0,STONE:0)
Block(-13,2,1,STONE:0)
Block(-13,2,2,STONE:0)
Block(-13,2,3,STONE:0)
Block(-13,3,-13,STONE:0)
Block(-13,3,-12,STONE:0)
Block(-13,3,-11,STONE:0)
Block(-13,3,-10,STONE:0)
Block(-13,3,-9,STONE:0)
Block(-13,3,-8,STONE:0)
Block(-13,3,-7,STONE:0)
Block(-13,3,-6,STONE:0)
Block(-13,3,-5,STONE:0)
Block(-13,3,-4,STONE:0)
Block(-13,3,-3,STONE:0)
Block(-13,3,-2,STONE:0)
Block(-13,3,-1,STONE:0)
Block(-13,3,0,STONE:0)
Block(-13,3,1,STONE:0)
Block(-13,3,2,STONE:0)
Block(-13,4,-13,STONE:0)
Block(-13,4,-12,STONE:0)
Block(-13,4,-11,STONE:0)
Block(-13,4,-10,STONE:0)
Block(-13,4,-9,STONE:0)
Block(-13,4,-8,STONE:0)
Block(-13,4,-7,STONE:0)
Block(-13,4,-6,STONE:0)
Block(-13,4,-5,STONE:0)
Block(-13,4,-4,STONE:0)
Block(-13,4,-3,STONE:0)
Block(-13,4,-2,STONE:0)
Block(-13,4,-1,STONE:0)
Block(-13,4,0,STONE:0)
Block(-13,4,1,STONE:0)
Block(-13,4,2,STONE:0)
Block(-13,5,-12,STONE:0)
Block(-13,5,-11,STONE:0)
Block(-13,5,-10,STONE:0)
Block(-13,5,-9,STONE:0)
Block(-13,5,-8,STONE:0)
Block(-13,5,-7,STONE:0)
Block(-13,5,-6,STONE:0)
Block(-13,5,-5,STONE:0)
Block(-13,5,-4,STONE:0)
Block(-13,5,-3,STONE:0)
Block(-13,5,-2,STONE:0)
Block(-13,5,-1,STONE:0)
Block(-13,5,0,STONE:0)
Block(-13,5,1,STONE:0)
Block(-13,5,2,STONE:0)
Block(-13,6,-12,STONE:0)
Block(-13,6,-11,STONE:0)
Block(-13,6,-10,STONE:0)
Block(-13,6,-9,STONE:0)
Block(-13,6,-8,STONE:0)
Block(-13,6,-7,STONE:0)
Block(-13,6,-6,STONE:0)
Block(-13,6,-5,STONE:0)
Block(-13,6,-4,STONE:0)
Block(-13,6,-3,STONE:0)
Block(-13,6,-2,STONE:0)
Block(-13,6,-1,STONE:0)
Block(-13,6,0,STONE:0)
Block(-13,6,1,STONE:0)
Block(-13,6,2,STONE:0)
Block(-13,7,-12,STONE:0)
Block(-13,7,-11,STONE:0)
Block(-13,7,-10,STONE:0)
Block(-13,7,-9,STONE:0)
Block(-13,7,-8,STONE:0)
Block(-13,7,-7,STONE:0)
Block(-13,7,-6,STONE:0)
Block(-13,7,-5,STONE:0)
Block(-13,7,-4,STONE:0)
Block(-13,7,-3,STONE:0)
Block(-13,7,-2,STONE:0)
Block(-13,7,-1,STONE:0)
Block(-13,7,0,STONE:0)
Block(-13,7,1,STONE:0)
Block(-13,7,2,STONE:0)
Block(-13,8,-12,STONE:0)
Block(-13,8,-11,STONE:0)
Block(-13,8,-10,STONE:0)
Block(-13,8,-9,STONE:0)
Block(-13,8,-8,STONE:0)
Block(-13,8,-7,STONE:0)
Block(-13,8,-6,STONE:0)
Block(-13,8,-5,STONE:0)
Block(-13,8,-4,STONE:0)
Block(-13,8,-3,STONE:0)
Block(-13,8,-2,STONE:0)
Block(-13,8,-1,STONE:0)
Block(-13,8,0,STONE:0)
Block(-13,8,1,STONE:0)
Block(-13,8,2,STONE:0)
Block(-13,9,-12,STONE:0)
Block(-13,9,-11,STONE:0)
Block(-13,9,-10,STONE:0)
Block(-13,9,-9,STONE:0)
Block(-13,9,-8,STONE:0)
Block(-13,9,-7,STONE:0)
Block(-13,9,-6,STONE:0)
Block(-13,9,-5,STONE:0)
Block(-13,9,-4,STONE:0)
Block(-13,9,-3,STONE:0)
Block(-13,9,-2,STONE:0)
Block(-13,9,-1,STONE:0)
Block(-13,9,0,STONE:0)
Block(-13,9,1,STONE:0)
Block(-13,10,-12,STONE:0)
Block(-13,10,-11,STONE:0)
Block(-13,10,-10,STONE:0)
Block(-13,10,-9,STONE:0)
Block(-13,10,-8,STONE:0)
Block(-13,10,-7,STONE:0)
Block(-13,10,-6,STONE:0)
Block(-13,10,-5,STONE:0)
Block(-13,10,-4,STONE:0)
Block(-13,10,-3,STONE:0)
Block(-13,10,-2,STONE:0)
Block(-13,10,-1,STONE:0)
Block(-13,10,0,STONE:0)
Block(-13,10,1,STONE:0)
Block(-13,11,-12,STONE:0)
Block(-13,11,-11,STONE:0)
Block(-13,11,-10,STONE:0)
Block(-13,11,-9,STONE:0)
Block(-13,11,-8,STONE:0)
Block(-13,11,-7,STONE:0)
Block(-13,11,-6,STONE:0)
Block(-13,11,-5,STONE:0)
Block(-13,11,-4,STONE:0)
Block(-13,11,-3,STONE:0)
Block(-13,11,-2,STONE:0)
Block(-13,11,-1,STONE:0)
Block(-13,11,0,STONE:0)
Block(-13,11,1,STONE:0)
Block(-13,12,-12,STONE:0)
Block(-13,12,-11,STONE:0)
Block(-13,12,-10,STONE:0)
Block(-13,12,-9,STONE:0)
Block(-13,12,-8,STONE:0)
Block(-13,12,-7,STONE:0)
Block(-13,12,-6,STONE:0)
Block(-13,12,-5,STONE:0)
Block(-13,12,-4,STONE:0)
Block(-13,12,-3,STONE:0)
Block(-13,12,-2,STONE:0)
Block(-13,12,-1,STONE:0)
Block(-13,12,0,STONE:0)
Block(-13,12,1,STONE:0)
Block(-13,13,-12,STONE:0)
Block(-13,13,-11,STONE:0)
Block(-13,13,-10,STONE:0)
Block(-13,13,-9,STONE:0)
Block(-13,13,-8,STONE:0)
Block(-13,13,-7,STONE:0)
Block(-13,13,-6,STONE:0)
Block(-13,13,-5,STONE:0)
Block(-13,13,-4,STONE:0)
Block(-13,13,-3,STONE:0)
Block(-13,13,-2,STONE:0)
Block(-13,13,-1,STONE:0)
Block(-13,13,0,STONE:0)
Block(-13,13,1,STONE:0)
Block(-13,14,-12,STONE:0)
Block(-13,14,-11,STONE:0)
Block(-13,14,-10,STONE:0)
Block(-13,14,-9,STONE:0)
Block(-13,14,-8,STONE:0)
Block(-13,14,-7,STONE:0)
Block(-13,14,-6,STONE:0)
Block(-13,14,-5,STONE:0)
Block(-13,14,-4,STONE:0)
Block(-13,14,-3,STONE:0)
Block(-13,14,-2,STONE:0)
Block(-13,14,-1,STONE:0)
Block(-13,14,0,STONE:0)
Block(-13,14,1,STONE:0)
Block(-13,15,-12,STONE:0)
Block(-13,15,-11,STONE:0)
Block(-13,15,-10,STONE:0)
Block(-13,15,-9,STONE:0)
Block(-13,15,-8,STONE:0)
Block(-13,15,-7,STONE:0)
Block(-13,15,-6,STONE:0)
Block(-13,15,-5,STONE:0)
Block(-13,15,-4,STONE:0)
Block(-13,15,-3,STONE:0)
Block(-13,15,-2,STONE:0)
Block(-13,15,-1,STONE:0)
Block(-13,15,0,STONE:0)
Block(-13,15,1,STONE:0)
Block(-13,16,-12,STONE:0)
Block(-13,16,-11,STONE:0)
Block(-13,16,-10,STONE:0)
Block(-13,16,-9,STONE:0)
Block(-13,16,-8,STONE:0)
Block(-13,16,-7,STONE:0)
Block(-13,16,-6,STONE:0)
Block(-13,16,-5,STONE:0)
Block(-13,16,-4,STONE:0)
Block(-13,16,-3,STONE:0)
Block(-13,16,-2,STONE:0)
Block(-13,16,-1,STONE:0)
Block(-13,16,0,STONE:0)
Block(-13,16,1,STONE:0)
Block(-13,17,-12,STONE:0)
Block(-13,17,-11,STONE:0)
Block(-13,17,-10,STONE:0)
Block(-13,17,-9,STONE:0)
Block(-13,17,-8,STONE:0)
Block(-13,17,-7,STONE:0)
Block(-13,17,-6,STONE:0)
Block(-13,17,-5,STONE:0)
Block(-13,17,-4,STONE:0)
Block(-13,17,-3,STONE:0)
Block(-13,17,-2,STONE:0)
Block(-13,17,-1,STONE:0)
Block(-13,17,0,STONE:0)
Block(-13,17,1,STONE:0)
Block(-13,18,-11,STONE:0)
Block(-13,18,-10,STONE:0)
Block(-13,18,-9,STONE:0)
Block(-13,18,-8,STONE:0)
Block(-13,18,-7,STONE:0)
Block(-13,18,-6,STONE:0)
Block(-13,18,-5,STONE:0)
Block(-13,18,-4,STONE:0)
Block(-13,18,-3,STONE:0)
Block(-13,18,-2,STONE:0)
Block(-13,18,-1,STONE:0)
Block(-13,18,0,STONE:0)
Block(-13,18,1,STONE:0)
Block(-13,19,-11,STONE:0)
Block(-13,19,-10,STONE:0)
Block(-13,19,-9,STONE:0)
Block(-13,19,-8,STONE:0)
Block(-13,19,-7,STONE:0)
Block(-13,19,-6,STONE:0)
Block(-13,19,-5,STONE:0)
Block(-13,19,-4,STONE:0)
Block(-13,19,-3,STONE:0)
Block(-13,19,-2,STONE:0)
Block(-13,19,-1,STONE:0)
Block(-13,19,0,STONE:0)
Block(-13,19,1,STONE:0)
Block(-13,20,-11,STONE:0)
Block(-13,20,-10,STONE:0)
Block(-13,20,-9,STONE:0)
Block(-13,20,-8,STONE:0)
Block(-13,20,-7,STONE:0)
Block(-13,20,-6,STONE:0)
Block(-13,20,-5,STONE:0)
Block(-13,20,-4,STONE:0)
Block(-13,20,-3,STONE:0)
Block(-13,20,-2,STONE:0)
Block(-13,20,-1,STONE:0)
Block(-13,20,0,STONE:0)
Block(-13,21,-11,STONE:0)
Block(-13,21,-10,STONE:0)
Block(-13,21,-9,STONE:0)
Block(-13,21,-8,STONE:0)
Block(-13,21,-7,STONE:0)
Block(-13,21,-6,STONE:0)
Block(-13,21,-5,STONE:0)
Block(-13,21,-4,STONE:0)
Block(-13,21,-3,STONE:0)
Block(-13,21,-2,STONE:0)
Block(-13,21,-1,STONE:0)
Block(-13,21,0,STONE:0)
Block(-13,22,-11,STONE:0)
Block(-13,22,-10,STONE:0)
Block(-13,22,-9,STONE:0)
Block(-13,22,-8,STONE:0)
Block(-13,22,-7,STONE:0)
Block(-13,22,-6,STONE:0)
Block(-13,22,-5,STONE:0)
Block(-13,22,-4,STONE:0)
Block(-13,22,-3,STONE:0)
Block(-13,22,-2,STONE:0)
Block(-13,22,-1,STONE:0)
Block(-13,22,0,STONE:0)
Block(-13,23,-11,STONE:0)
Block(-13,23,-10,STONE:0)
Block(-13,23,-9,STONE:0)
Block(-13,23,-8,STONE:0)
Block(-13,23,-7,STONE:0)
Block(-13,23,-6,STONE:0)
Block(-13,23,-5,STONE:0)
Block(-13,23,-4,STONE:0)
Block(-13,23,-3,STONE:0)
Block(-13,23,-2,STONE:0)
Block(-13,23,-1,STONE:0)
Block(-13,23,0,STONE:0)
Block(-13,24,-11,STONE:0)
Block(-13,24,-10,STONE:0)
Block(-13,24,-9,STONE:0)
Block(-13,24,-8,STONE:0)
Block(-13,24,-7,STONE:0)
Block(-13,24,-6,STONE:0)
Block(-13,24,-5,STONE:0)
Block(-13,24,-4,STONE:0)
Block(-13,24,-3,STONE:0)
Block(-13,24,-2,STONE:0)
Block(-13,24,-1,STONE:0)
Block(-13,24,0,STONE:0)
Block(-13,25,-11,STONE:0)
Block(-13,25,-10,STONE:0)
Block(-13,25,-9,STONE:0)
Block(-13,25,-8,STONE:0)
Block(-13,25,-7,STONE:0)
Block(-13,25,-6,STONE:0)
Block(-13,25,-5,STONE:0)
Block(-13,25,-4,STONE:0)
Block(-13,25,-3,STONE:0)
Block(-13,25,-2,STONE:0)
Block(-13,25,-1,STONE:0)
Block(-13,25,0,STONE:0)
Block(-13,26,-11,STONE:0)
Block(-13,26,-10,STONE:0)
Block(-13,26,-9,STONE:0)
Block(-13,26,-8,STONE:0)
Block(-13,26,-7,STONE:0)
Block(-13,26,-6,STONE:0)
Block(-13,26,-5,STONE:0)
Block(-13,26,-4,STONE:0)
Block(-13,26,-3,STONE:0)
Block(-13,26,-2,STONE:0)
Block(-13,26,-1,STONE:0)
Block(-13,26,0,STONE:0)
Block(-13,27,-11,STONE:0)
Block(-13,27,-10,STONE:0)
Block(-13,27,-9,STONE:0)
Block(-13,27,-8,STONE:0)
Block(-13,27,-7,STONE:0)
Block(-13,27,-6,STONE:0)
Block(-13,27,-5,STONE:0)
Block(-13,27,-4,STONE:0)
Block(-13,27,-3,STONE:0)
Block(-13,27,-2,STONE:0)
Block(-13,27,-1,STONE:0)
Block(-13,27,0,STONE:0)
Block(-13,28,-11,STONE:0)
Block(-13,28,-10,STONE:0)
Block(-13,28,-9,STONE:0)
Block(-13,28,-8,STONE:0)
Block(-13,28,-7,STONE:0)
Block(-13,28,-6,STONE:0)
Block(-13,28,-5,STONE:0)
Block(-13,28,-4,STONE:0)
Block(-13,28,-3,STONE:0)
Block(-13,28,-2,STONE:0)
Block(-13,28,-1,STONE:0)
Block(-13,28,0,STONE:0)
Block(-13,29,-11,STONE:0)
Block(-13,29,-10,STONE:0)
Block(-13,29,-9,STONE:0)
Block(-13,29,-8,STONE:0)
Block(-13,29,-7,STONE:0)
Block(-13,29,-6,STONE:0)
Block(-13,29,-5,STONE:0)
Block(-13,29,-4,STONE:0)
Block(-13,29,-3,STONE:0)
Block(-13,29,-2,STONE:0)
Block(-13,29,-1,STONE:0)
Block(-13,29,0,STONE:0)
Block(-13,30,-11,STONE:0)
Block(-13,30,-10,STONE:0)
Block(-13,30,-9,STONE:0)
Block(-13,30,-8,STONE:0)
Block(-13,30,-7,STONE:0)
Block(-13,30,-6,STONE:0)
Block(-13,30,-5,STONE:0)
Block(-13,30,-4,STONE:0)
Block(-13,30,-3,STONE:0)
Block(-13,30,-2,STONE:0)
Block(-13,30,-1,STONE:0)
Block(-13,30,0,STONE:0)
Block(-13,31,-11,STONE:0)
Block(-13,31,-10,STONE:0)
Block(-13,31,-9,STONE:0)
Block(-13,31,-8,STONE:0)
Block(-13,31,-7,STONE:0)
Block(-13,31,-6,STONE:0)
Block(-13,31,-5,STONE:0)
Block(-13,31,-4,STONE:0)
Block(-13,31,-3,STONE:0)
Block(-13,31,-2,STONE:0)
Block(-13,31,-1,STONE:0)
Block(-13,31,0,STONE:0)
Block(-13,32,-10,STONE:0)
Block(-13,32,-9,STONE:0)
Block(-13,32,-8,STONE:0)
Block(-13,32,-7,STONE:0)
Block(-13,32,-6,STONE:0)
Block(-13,32,-5,STONE:0)
Block(-13,32,-4,STONE:0)
Block(-13,32,-3,STONE:0)
Block(-13,32,-2,STONE:0)
Block(-13,32,-1,STONE:0)
Block(-13,32,0,STONE:0)
Block(-13,33,-10,STONE:0)
Block(-13,33,-9,STONE:0)
Block(-13,33,-8,STONE:0)
Block(-13,33,-7,STONE:0)
Block(-13,33,-6,STONE:0)
Block(-13,33,-5,STONE:0)
Block(-13,33,-4,STONE:0)
Block(-13,33,-3,STONE:0)
Block(-13,33,-2,STONE:0)
Block(-13,33,-1,STONE:0)
Block(-13,33,0,STONE:0)
Block(-13,34,-10,STONE:0)
Block(-13,34,-9,STONE:0)
Block(-13,34,-8,STONE:0)
Block(-13,34,-7,STONE:0)
Block(-13,34,-6,STONE:0)
Block(-13,34,-5,STONE:0)
Block(-13,34,-4,STONE:0)
Block(-13,34,-3,STONE:0)
Block(-13,34,-2,STONE:0)
Block(-13,34,-1,STONE:0)
Block(-13,34,0,STONE:0)
Block(-13,35,-10,STONE:0)
Block(-13,35,-9,STONE:0)
Block(-13,35,-8,STONE:0)
Block(-13,35,-7,STONE:0)
Block(-13,35,-6,STONE:0)
Block(-13,35,-5,STONE:0)
Block(-13,35,-4,STONE:0)
Block(-13,35,-3,STONE:0)
Block(-13,35,-2,STONE:0)
Block(-13,35,-1,STONE:0)
Block(-13,36,-10,STONE:0)
Block(-13,36,-9,STONE:0)
Block(-13,36,-8,STONE:0)
Block(-13,36,-7,STONE:0)
Block(-13,36,-6,STONE:0)
Block(-13,36,-5,STONE:0)
Block(-13,36,-4,STONE:0)
Block(-13,36,-3,STONE:0)
Block(-13,36,-2,STONE:0)
Block(-13,36,-1,STONE:0)
Block(-13,37,-10,STONE:0)
Block(-13,37,-9,STONE:0)
Block(-13,37,-8,STONE:0)
Block(-13,37,-7,STONE:0)
Block(-13,37,-6,STONE:0)
Block(-13,37,-5,STONE:0)
Block(-13,37,-4,STONE:0)
Block(-13,37,-3,STONE:0)
Block(-13,37,-2,STONE:0)
Block(-13,37,-1,STONE:0)
Block(-13,38,-10,STONE:0)
Block(-13,38,-9,STONE:0)
Block(-13,38,-8,STONE:0)
Block(-13,38,-7,STONE:0)
Block(-13,38,-6,STONE:0)
Block(-13,38,-5,STONE:0)
Block(-13,38,-4,STONE:0)
Block(-13,38,-3,STONE:0)
Block(-13,38,-2,STONE:0)
Block(-13,38,-1,STONE:0)
Block(-13,39,-10,STONE:0)
Block(-13,39,-9,STONE:0)
Block(-13,39,-8,STONE:0)
Block(-13,39,-7,STONE:0)
Block(-13,39,-6,STONE:0)
Block(-13,39,-5,STONE:0)
Block(-13,39,-4,STONE:0)
Block(-13,39,-3,STONE:0)
Block(-13,39,-2,STONE:0)
Block(-13,39,-1,STONE:0)
Block(-13,40,-10,STONE:0)
Block(-13,40,-9,STONE:0)
Block(-13,40,-8,STONE:0)
Block(-13,40,-7,STONE:0)
Block(-13,40,-6,STONE:0)
Block(-13,40,-5,STONE:0)
Block(-13,40,-4,STONE:0)
Block(-13,40,-3,STONE:0)
Block(-13,40,-2,STONE:0)
Block(-13,40,-1,STONE:0)
Block(-13,41,-10,STONE:0)
Block(-13,41,-9,STONE:0)
Block(-13,41,-8,STONE:0)
Block(-13,41,-7,STONE:0)
Block(-13,41,-6,STONE:0)
Block(-13,41,-5,STONE:0)
Block(-13,41,-4,STONE:0)
Block(-13,41,-3,STONE:0)
Block(-13,41,-2,STONE:0)
Block(-13,41,-1,STONE:0)
Block(-13,42,-10,STONE:0)
Block(-13,42,-9,STONE:0)
Block(-13,42,-8,GRASS:0)
Block(-13,42,-7,GRASS:0)
Block(-13,42,-6,GRASS:0)
Block(-13,42,-5,GRASS:0)
Block(-13,42,-4,GRASS:0)
Block(-13,42,-3,GRASS:0)
Block(-13,42,-2,GRASS:0)
Block(-13,42,-1,STONE:0)
Block(-12,0,-14,STONE:0)
Block(-12,0,-13,STONE:0)
Block(-12,0,-12,STONE:0)
Block(-12,0,-11,STONE:0)
Block(-12,0,-10,STONE:0)
Block(-12,0,-9,STONE:0)
Block(-12,0,-8,STONE:0)
Block(-12,0,-7,STONE:0)
Block(-12,0,-6,STONE:0)
Block(-12,0,-5,STONE:0)
Block(-12,0,-4,STONE:0)
Block(-12,0,-3,STONE:0)
Block(-12,0,-2,STONE:0)
Block(-12,0,-1,STONE:0)
Block(-12,0,0,STONE:0)
Block(-12,0,1,STONE:0)
Block(-12,0,2,STONE:0)
Block(-12,0,3,STONE:0)
Block(-12,0,4,STONE:0)
Block(-12,0,5,STONE:0)
Block(-12,0,6,STONE:0)
Block(-12,1,-14,STONE:0)
Block(-12,1,-13,STONE:0)
Block(-12,1,-12,STONE:0)
Block(-12,1,-11,STONE:0)
Block(-12,1,-10,STONE:0)
Block(-12,1,-9,STONE:0)
Block(-12,1,-8,STONE:0)
Block(-12,1,-7,STONE:0)
Block(-12,1,-6,STONE:0)
Block(-12,1,-5,STONE:0)
Block(-12,1,-4,STONE:0)
Block(-12,1,-3,STONE:0)
Block(-12,1,-2,STONE:0)
Block(-12,1,-1,STONE:0)
Block(-12,1,0,STONE:0)
Block(-12,1,1,STONE:0)
Block(-12,1,2,STONE:0)
Block(-12,1,3,STONE:0)
Block(-12,1,4,STONE:0)
Block(-12,1,5,STONE:0)
Block(-12,1,6,STONE:0)
Block(-12,2,-14,STONE:0)
Block(-12,2,-13,STONE:0)
Block(-12,2,-12,STONE:0)
Block(-12,2,-11,STONE:0)
Block(-12,2,-10,STONE:0)
Block(-12,2,-9,STONE:0)
Block(-12,2,-8,STONE:0)
Block(-12,2,-7,STONE:0)
Block(-12,2,-6,STONE:0)
Block(-12,2,-5,STONE:0)
Block(-12,2,-4,STONE:0)
Block(-12,2,-3,STONE:0)
Block(-12,2,-2,STONE:0)
Block(-12,2,-1,STONE:0)
Block(-12,2,0,STONE:0)
Block(-12,2,1,STONE:0)
Block(-12,2,2,STONE:0)
Block(-12,2,3,STONE:0)
Block(-12,2,4,STONE:0)
Block(-12,2,5,STONE:0)
Block(-12,3,-13,STONE:0)
Block(-12,3,-12,STONE:0)
Block(-12,3,-11,STONE:0)
Block(-12,3,-10,STONE:0)
Block(-12,3,-9,STONE:0)
Block(-12,3,-8,STONE:0)
Block(-12,3,-7,STONE:0)
Block(-12,3,-6,STONE:0)
Block(-12,3,-5,STONE:0)
Block(-12,3,-4,STONE:0)
Block(-12,3,-3,STONE:0)
Block(-12,3,-2,STONE:0)
Block(-12,3,-1,STONE:0)
Block(-12,3,0,STONE:0)
Block(-12,3,1,STONE:0)
Block(-12,3,2,STONE:0)
Block(-12,3,3,STONE:0)
Block(-12,3,4,STONE:0)
Block(-12,3,5,STONE:0)
Block(-12,4,-13,STONE:0)
Block(-12,4,-12,STONE:0)
Block(-12,4,-11,STONE:0)
Block(-12,4,-10,STONE:0)
Block(-12,4,-9,STONE:0)
Block(-12,4,-8,STONE:0)
Block(-12,4,-7,STONE:0)
Block(-12,4,-6,STONE:0)
Block(-12,4,-5,STONE:0)
Block(-12,4,-4,STONE:0)
Block(-12,4,-3,STONE:0)
Block(-12,4,-2,STONE:0)
Block(-12,4,-1,STONE:0)
Block(-12,4,0,STONE:0)
Block(-12,4,1,STONE:0)
Block(-12,4,2,STONE:0)
Block(-12,4,3,STONE:0)
Block(-12,4,4,STONE:0)
Block(-12,4,5,STONE:0)
Block(-12,5,-13,STONE:0)
Block(-12,5,-12,STONE:0)
Block(-12,5,-11,STONE:0)
Block(-12,5,-10,STONE:0)
Block(-12,5,-9,STONE:0)
Block(-12,5,-8,STONE:0)
Block(-12,5,-7,STONE:0)
Block(-12,5,-6,STONE:0)
Block(-12,5,-5,STONE:0)
Block(-12,5,-4,STONE:0)
Block(-12,5,-3,STONE:0)
Block(-12,5,-2,STONE:0)
Block(-12,5,-1,STONE:0)
Block(-12,5,0,STONE:0)
Block(-12,5,1,STONE:0)
Block(-12,5,2,STONE:0)
Block(-12,5,3,STONE:0)
Block(-12,5,4,STONE:0)
Block(-12,6,-13,STONE:0)
Block(-12,6,-12,STONE:0)
Block(-12,6,-11,STONE:0)
Block(-12,6,-10,STONE:0)
Block(-12,6,-9,STONE:0)
Block(-12,6,-8,STONE:0)
Block(-12,6,-7,STONE:0)
Block(-12,6,-6,STONE:0)
Block(-12,6,-5,STONE:0)
Block(-12,6,-4,STONE:0)
Block(-12,6,-3,STONE:0)
Block(-12,6,-2,STONE:0)
Block(-12,6,-1,STONE:0)
Block(-12,6,0,STONE:0)
Block(-12,6,1,STONE:0)
Block(-12,6,2,STONE:0)
Block(-12,6,3,STONE:0)
Block(-12,6,4,STONE:0)
Block(-12,7,-13,STONE:0)
Block(-12,7,-12,STONE:0)
Block(-12,7,-11,STONE:0)
Block(-12,7,-10,STONE:0)
Block(-12,7,-9,STONE:0)
Block(-12,7,-8,STONE:0)
Block(-12,7,-7,STONE:0)
Block(-12,7,-6,STONE:0)
Block(-12,7,-5,STONE:0)
Block(-12,7,-4,STONE:0)
Block(-12,7,-3,STONE:0)
Block(-12,7,-2,STONE:0)
Block(-12,7,-1,STONE:0)
Block(-12,7,0,STONE:0)
Block(-12,7,1,STONE:0)
Block(-12,7,2,STONE:0)
Block(-12,7,3,STONE:0)
Block(-12,8,-13,STONE:0)
Block(-12,8,-12,STONE:0)
Block(-12,8,-11,STONE:0)
Block(-12,8,-10,STONE:0)
Block(-12,8,-9,STONE:0)
Block(-12,8,-8,STONE:0)
Block(-12,8,-7,STONE:0)
Block(-12,8,-6,STONE:0)
Block(-12,8,-5,STONE:0)
Block(-12,8,-4,STONE:0)
Block(-12,8,-3,STONE:0)
Block(-12,8,-2,STONE:0)
Block(-12,8,-1,STONE:0)
Block(-12,8,0,STONE:0)
Block(-12,8,1,STONE:0)
Block(-12,8,2,STONE:0)
Block(-12,9,-13,STONE:0)
Block(-12,9,-12,STONE:0)
Block(-12,9,-11,STONE:0)
Block(-12,9,-10,STONE:0)
Block(-12,9,-9,STONE:0)
Block(-12,9,-8,STONE:0)
Block(-12,9,-7,STONE:0)
Block(-12,9,-6,STONE:0)
Block(-12,9,-5,STONE:0)
Block(-12,9,-4,STONE:0)
Block(-12,9,-3,STONE:0)
Block(-12,9,-2,STONE:0)
Block(-12,9,-1,STONE:0)
Block(-12,9,0,STONE:0)
Block(-12,9,1,STONE:0)
Block(-12,9,2,STONE:0)
Block(-12,10,-13,STONE:0)
Block(-12,10,-12,STONE:0)
Block(-12,10,-11,STONE:0)
Block(-12,10,-10,STONE:0)
Block(-12,10,-9,STONE:0)
Block(-12,10,-8,STONE:0)
Block(-12,10,-7,STONE:0)
Block(-12,10,-6,STONE:0)
Block(-12,10,-5,STONE:0)
Block(-12,10,-4,STONE:0)
Block(-12,10,-3,STONE:0)
Block(-12,10,-2,STONE:0)
Block(-12,10,-1,STONE:0)
Block(-12,10,0,STONE:0)
Block(-12,10,1,STONE:0)
Block(-12,10,2,STONE:0)
Block(-12,11,-13,STONE:0)
Block(-12,11,-12,STONE:0)
Block(-12,11,-11,STONE:0)
Block(-12,11,-10,STONE:0)
Block(-12,11,-9,STONE:0)
Block(-12,11,-8,STONE:0)
Block(-12,11,-7,STONE:0)
Block(-12,11,-6,STONE:0)
Block(-12,11,-5,STONE:0)
Block(-12,11,-4,STONE:0)
Block(-12,11,-3,STONE:0)
Block(-12,11,-2,STONE:0)
Block(-12,11,-1,STONE:0)
Block(-12,11,0,STONE:0)
Block(-12,11,1,STONE:0)
Block(-12,11,2,STONE:0)
Block(-12,12,-13,STONE:0)
Block(-12,12,-12,STONE:0)
Block(-12,12,-11,STONE:0)
Block(-12,12,-10,STONE:0)
Block(-12,12,-9,STONE:0)
Block(-12,12,-8,STONE:0)
Block(-12,12,-7,STONE:0)
Block(-12,12,-6,STONE:0)
Block(-12,12,-5,STONE:0)
Block(-12,12,-4,STONE:0)
Block(-12,12,-3,STONE:0)
Block(-12,12,-2,STONE:0)
Block(-12,12,-1,STONE:0)
Block(-12,12,0,STONE:0)
Block(-12,12,1,STONE:0)
Block(-12,13,-13,STONE:0)
Block(-12,13,-12,STONE:0)
Block(-12,13,-11,STONE:0)
Block(-12,13,-10,STONE:0)
Block(-12,13,-9,STONE:0)
Block(-12,13,-8,STONE:0)
Block(-12,13,-7,STONE:0)
Block(-12,13,-6,STONE:0)
Block(-12,13,-5,STONE:0)
Block(-12,13,-4,STONE:0)
Block(-12,13,-3,STONE:0)
Block(-12,13,-2,STONE:0)
Block(-12,13,-1,STONE:0)
Block(-12,13,0,STONE:0)
Block(-12,13,1,STONE:0)
Block(-12,14,-13,STONE:0)
Block(-12,14,-12,STONE:0)
Block(-12,14,-11,STONE:0)
Block(-12,14,-10,STONE:0)
Block(-12,14,-9,STONE:0)
Block(-12,14,-8,STONE:0)
Block(-12,14,-7,STONE:0)
Block(-12,14,-6,STONE:0)
Block(-12,14,-5,STONE:0)
Block(-12,14,-4,STONE:0)
Block(-12,14,-3,STONE:0)
Block(-12,14,-2,STONE:0)
Block(-12,14,-1,STONE:0)
Block(-12,14,0,STONE:0)
Block(-12,14,1,STONE:0)
Block(-12,15,-13,STONE:0)
Block(-12,15,-12,STONE:0)
Block(-12,15,-11,STONE:0)
Block(-12,15,-10,STONE:0)
Block(-12,15,-9,STONE:0)
Block(-12,15,-8,STONE:0)
Block(-12,15,-7,STONE:0)
Block(-12,15,-6,STONE:0)
Block(-12,15,-5,STONE:0)
Block(-12,15,-4,STONE:0)
Block(-12,15,-3,STONE:0)
Block(-12,15,-2,STONE:0)
Block(-12,15,-1,STONE:0)
Block(-12,15,0,STONE:0)
Block(-12,15,1,STONE:0)
Block(-12,16,-12,STONE:0)
Block(-12,16,-11,STONE:0)
Block(-12,16,-10,STONE:0)
Block(-12,16,-9,STONE:0)
Block(-12,16,-8,STONE:0)
Block(-12,16,-7,STONE:0)
Block(-12,16,-6,STONE:0)
Block(-12,16,-5,STONE:0)
Block(-12,16,-4,STONE:0)
Block(-12,16,-3,STONE:0)
Block(-12,16,-2,STONE:0)
Block(-12,16,-1,STONE:0)
Block(-12,16,0,STONE:0)
Block(-12,16,1,STONE:0)
Block(-12,17,-12,STONE:0)
Block(-12,17,-11,STONE:0)
Block(-12,17,-10,STONE:0)
Block(-12,17,-9,STONE:0)
Block(-12,17,-8,STONE:0)
Block(-12,17,-7,STONE:0)
Block(-12,17,-6,STONE:0)
Block(-12,17,-5,STONE:0)
Block(-12,17,-4,STONE:0)
Block(-12,17,-3,STONE:0)
Block(-12,17,-2,STONE:0)
Block(-12,17,-1,STONE:0)
Block(-12,17,0,STONE:0)
Block(-12,17,1,STONE:0)
Block(-12,18,-12,STONE:0)
Block(-12,18,-11,STONE:0)
Block(-12,18,-10,STONE:0)
Block(-12,18,-9,STONE:0)
Block(-12,18,-8,STONE:0)
Block(-12,18,-7,STONE:0)
Block(-12,18,-6,STONE:0)
Block(-12,18,-5,STONE:0)
Block(-12,18,-4,STONE:0)
Block(-12,18,-3,STONE:0)
Block(-12,18,-2,STONE:0)
Block(-12,18,-1,STONE:0)
Block(-12,18,0,STONE:0)
Block(-12,18,1,STONE:0)
Block(-12,19,-12,STONE:0)
Block(-12,19,-11,STONE:0)
Block(-12,19,-10,STONE:0)
Block(-12,19,-9,STONE:0)
Block(-12,19,-8,STONE:0)
Block(-12,19,-7,STONE:0)
Block(-12,19,-6,STONE:0)
Block(-12,19,-5,STONE:0)
Block(-12,19,-4,STONE:0)
Block(-12,19,-3,STONE:0)
Block(-12,19,-2,STONE:0)
Block(-12,19,-1,STONE:0)
Block(-12,19,0,STONE:0)
Block(-12,19,1,STONE:0)
Block(-12,20,-12,STONE:0)
Block(-12,20,-11,STONE:0)
Block(-12,20,-10,STONE:0)
Block(-12,20,-9,STONE:0)
Block(-12,20,-8,STONE:0)
Block(-12,20,-7,STONE:0)
Block(-12,20,-6,STONE:0)
Block(-12,20,-5,STONE:0)
Block(-12,20,-4,STONE:0)
Block(-12,20,-3,STONE:0)
Block(-12,20,-2,STONE:0)
Block(-12,20,-1,STONE:0)
Block(-12,20,0,STONE:0)
Block(-12,20,1,STONE:0)
Block(-12,21,-12,STONE:0)
Block(-12,21,-11,STONE:0)
Block(-12,21,-10,STONE:0)
Block(-12,21,-9,STONE:0)
Block(-12,21,-8,STONE:0)
Block(-12,21,-7,STONE:0)
Block(-12,21,-6,STONE:0)
Block(-12,21,-5,STONE:0)
Block(-12,21,-4,STONE:0)
Block(-12,21,-3,STONE:0)
Block(-12,21,-2,STONE:0)
Block(-12,21,-1,STONE:0)
Block(-12,21,0,STONE:0)
Block(-12,21,1,STONE:0)
Block(-12,22,-12,STONE:0)
Block(-12,22,-11,STONE:0)
Block(-12,22,-10,STONE:0)
Block(-12,22,-9,STONE:0)
Block(-12,22,-8,STONE:0)
Block(-12,22,-7,STONE:0)
Block(-12,22,-6,STONE:0)
Block(-12,22,-5,STONE:0)
Block(-12,22,-4,STONE:0)
Block(-12,22,-3,STONE:0)
Block(-12,22,-2,STONE:0)
Block(-12,22,-1,STONE:0)
Block(-12,22,0,STONE:0)
Block(-12,22,1,STONE:0)
Block(-12,23,-12,STONE:0)
Block(-12,23,-11,STONE:0)
Block(-12,23,-10,STONE:0)
Block(-12,23,-9,STONE:0)
Block(-12,23,-8,STONE:0)
Block(-12,23,-7,STONE:0)
Block(-12,23,-6,STONE:0)
Block(-12,23,-5,STONE:0)
Block(-12,23,-4,STONE:0)
Block(-12,23,-3,STONE:0)
Block(-12,23,-2,STONE:0)
Block(-12,23,-1,STONE:0)
Block(-12,23,0,STONE:0)
Block(-12,24,-12,STONE:0)
Block(-12,24,-11,STONE:0)
Block(-12,24,-10,STONE:0)
Block(-12,24,-9,STONE:0)
Block(-12,24,-8,STONE:0)
Block(-12,24,-7,STONE:0)
Block(-12,24,-6,STONE:0)
Block(-12,24,-5,STONE:0)
Block(-12,24,-4,STONE:0)
Block(-12,24,-3,STONE:0)
Block(-12,24,-2,STONE:0)
Block(-12,24,-1,STONE:0)
Block(-12,24,0,STONE:0)
Block(-12,25,-12,STONE:0)
Block(-12,25,-11,STONE:0)
Block(-12,25,-10,STONE:0)
Block(-12,25,-9,STONE:0)
Block(-12,25,-8,STONE:0)
Block(-12,25,-7,STONE:0)
Block(-12,25,-6,STONE:0)
Block(-12,25,-5,STONE:0)
Block(-12,25,-4,STONE:0)
Block(-12,25,-3,STONE:0)
Block(-12,25,-2,STONE:0)
Block(-12,25,-1,STONE:0)
Block(-12,25,0,STONE:0)
Block(-12,26,-12,STONE:0)
Block(-12,26,-11,STONE:0)
Block(-12,26,-10,STONE:0)
Block(-12,26,-9,STONE:0)
Block(-12,26,-8,STONE:0)
Block(-12,26,-7,STONE:0)
Block(-12,26,-6,STONE:0)
Block(-12,26,-5,STONE:0)
Block(-12,26,-4,STONE:0)
Block(-12,26,-3,STONE:0)
Block(-12,26,-2,STONE:0)
Block(-12,26,-1,STONE:0)
Block(-12,26,0,STONE:0)
Block(-12,27,-12,STONE:0)
Block(-12,27,-11,STONE:0)
Block(-12,27,-10,STONE:0)
Block(-12,27,-9,STONE:0)
Block(-12,27,-8,STONE:0)
Block(-12,27,-7,STONE:0)
Block(-12,27,-6,STONE:0)
Block(-12,27,-5,STONE:0)
Block(-12,27,-4,STONE:0)
Block(-12,27,-3,STONE:0)
Block(-12,27,-2,STONE:0)
Block(-12,27,-1,STONE:0)
Block(-12,27,0,STONE:0)
Block(-12,28,-11,STONE:0)
Block(-12,28,-10,STONE:0)
Block(-12,28,-9,STONE:0)
Block(-12,28,-8,STONE:0)
Block(-12,28,-7,STONE:0)
Block(-12,28,-6,STONE:0)
Block(-12,28,-5,STONE:0)
Block(-12,28,-4,STONE:0)
Block(-12,28,-3,STONE:0)
Block(-12,28,-2,STONE:0)
Block(-12,28,-1,STONE:0)
Block(-12,28,0,STONE:0)
Block(-12,29,-11,STONE:0)
Block(-12,29,-10,STONE:0)
Block(-12,29,-9,STONE:0)
Block(-12,29,-8,STONE:0)
Block(-12,29,-7,STONE:0)
Block(-12,29,-6,STONE:0)
Block(-12,29,-5,STONE:0)
Block(-12,29,-4,STONE:0)
Block(-12,29,-3,STONE:0)
Block(-12,29,-2,STONE:0)
Block(-12,29,-1,STONE:0)
Block(-12,29,0,STONE:0)
Block(-12,30,-11,STONE:0)
Block(-12,30,-10,STONE:0)
Block(-12,30,-9,STONE:0)
Block(-12,30,-8,STONE:0)
Block(-12,30,-7,STONE:0)
Block(-12,30,-6,STONE:0)
Block(-12,30,-5,STONE:0)
Block(-12,30,-4,STONE:0)
Block(-12,30,-3,STONE:0)
Block(-12,30,-2,STONE:0)
Block(-12,30,-1,STONE:0)
Block(-12,30,0,STONE:0)
Block(-12,31,-11,STONE:0)
Block(-12,31,-10,STONE:0)
Block(-12,31,-9,STONE:0)
Block(-12,31,-8,STONE:0)
Block(-12,31,-7,STONE:0)
Block(-12,31,-6,STONE:0)
Block(-12,31,-5,STONE:0)
Block(-12,31,-4,STONE:0)
Block(-12,31,-3,STONE:0)
Block(-12,31,-2,STONE:0)
Block(-12,31,-1,STONE:0)
Block(-12,31,0,STONE:0)
Block(-12,32,-11,STONE:0)
Block(-12,32,-10,STONE:0)
Block(-12,32,-9,STONE:0)
Block(-12,32,-8,STONE:0)
Block(-12,32,-7,STONE:0)
Block(-12,32,-6,STONE:0)
Block(-12,32,-5,STONE:0)
Block(-12,32,-4,STONE:0)
Block(-12,32,-3,STONE:0)
Block(-12,32,-2,STONE:0)
Block(-12,32,-1,STONE:0)
Block(-12,32,0,STONE:0)
Block(-12,33,-11,STONE:0)
Block(-12,33,-10,STONE:0)
Block(-12,33,-9,STONE:0)
Block(-12,33,-8,STONE:0)
Block(-12,33,-7,STONE:0)
Block(-12,33,-6,STONE:0)
Block(-12,33,-5,STONE:0)
Block(-12,33,-4,STONE:0)
Block(-12,33,-3,STONE:0)
Block(-12,33,-2,STONE:0)
Block(-12,33,-1,STONE:0)
Block(-12,33,0,STONE:0)
Block(-12,34,-11,STONE:0)
Block(-12,34,-10,STONE:0)
Block(-12,34,-9,STONE:0)
Block(-12,34,-8,STONE:0)
Block(-12,34,-7,STONE:0)
Block(-12,34,-6,STONE:0)
Block(-12,34,-5,STONE:0)
Block(-12,34,-4,STONE:0)
Block(-12,34,-3,STONE:0)
Block(-12,34,-2,STONE:0)
Block(-12,34,-1,STONE:0)
Block(-12,34,0,STONE:0)
Block(-12,35,-11,STONE:0)
Block(-12,35,-10,STONE:0)
Block(-12,35,-9,STONE:0)
Block(-12,35,-8,STONE:0)
Block(-12,35,-7,STONE:0)
Block(-12,35,-6,STONE:0)
Block(-12,35,-5,STONE:0)
Block(-12,35,-4,STONE:0)
Block(-12,35,-3,STONE:0)
Block(-12,35,-2,STONE:0)
Block(-12,35,-1,STONE:0)
Block(-12,36,-11,STONE:0)
Block(-12,36,-10,STONE:0)
Block(-12,36,-9,STONE:0)
Block(-12,36,-8,STONE:0)
Block(-12,36,-7,STONE:0)
Block(-12,36,-6,STONE:0)
Block(-12,36,-5,STONE:0)
Block(-12,36,-4,STONE:0)
Block(-12,36,-3,STONE:0)
Block(-12,36,-2,STONE:0)
Block(-12,36,-1,STONE:0)
Block(-12,37,-11,STONE:0)
Block(-12,37,-10,STONE:0)
Block(-12,37,-9,STONE:0)
Block(-12,37,-8,STONE:0)
Block(-12,37,-7,STONE:0)
Block(-12,37,-6,STONE:0)
Block(-12,37,-5,STONE:0)
Block(-12,37,-4,STONE:0)
Block(-12,37,-3,STONE:0)
Block(-12,37,-2,STONE:0)
Block(-12,37,-1,STONE:0)
Block(-12,38,-11,STONE:0)
Block(-12,38,-10,STONE:0)
Block(-12,38,-9,STONE:0)
Block(-12,38,-8,STONE:0)
Block(-12,38,-7,STONE:0)
Block(-12,38,-6,STONE:0)
Block(-12,38,-5,STONE:0)
Block(-12,38,-4,STONE:0)
Block(-12,38,-3,STONE:0)
Block(-12,38,-2,STONE:0)
Block(-12,38,-1,STONE:0)
Block(-12,39,-11,STONE:0)
Block(-12,39,-10,STONE:0)
Block(-12,39,-9,STONE:0)
Block(-12,39,-8,STONE:0)
Block(-12,39,-7,STONE:0)
Block(-12,39,-6,STONE:0)
Block(-12,39,-5,STONE:0)
Block(-12,39,-4,STONE:0)
Block(-12,39,-3,STONE:0)
Block(-12,39,-2,STONE:0)
Block(-12,39,-1,STONE:0)
Block(-12,40,-10,STONE:0)
Block(-12,40,-9,STONE:0)
Block(-12,40,-8,STONE:0)
Block(-12,40,-7,STONE:0)
Block(-12,40,-6,STONE:0)
Block(-12,40,-5,STONE:0)
Block(-12,40,-4,STONE:0)
Block(-12,40,-3,STONE:0)
Block(-12,40,-2,STONE:0)
Block(-12,40,-1,STONE:0)
Block(-12,41,-10,STONE:0)
Block(-12,41,-9,STONE:0)
Block(-12,41,-8,STONE:0)
Block(-12,41,-7,STONE:0)
Block(-12,41,-6,STONE:0)
Block(-12,41,-5,STONE:0)
Block(-12,41,-4,STONE:0)
Block(-12,41,-3,STONE:0)
Block(-12,41,-2,STONE:0)
Block(-12,41,-1,STONE:0)
Block(-12,42,-10,STONE:0)
Block(-12,42,-9,GRASS:0)
Block(-12,42,-8,GRASS:0)
Block(-12,42,-7,GRASS:0)
Block(-12,42,-6,GRASS:0)
Block(-12,42,-5,GRASS:0)
Block(-12,42,-4,GRASS:0)
Block(-12,42,-3,GRASS:0)
Block(-12,42,-2,GRASS:0)
Block(-12,42,-1,STONE:0)
Block(-11,0,-14,STONE:0)
Block(-11,0,-13,STONE:0)
Block(-11,0,-12,STONE:0)
Block(-11,0,-11,STONE:0)
Block(-11,0,-10,STONE:0)
Block(-11,0,-9,STONE:0)
Block(-11,0,-8,STONE:0)
Block(-11,0,-7,STONE:0)
Block(-11,0,-6,STONE:0)
Block(-11,0,-5,STONE:0)
Block(-11,0,-4,STONE:0)
Block(-11,0,-3,STONE:0)
Block(-11,0,-2,STONE:0)
Block(-11,0,-1,STONE:0)
Block(-11,0,0,STONE:0)
Block(-11,0,1,STONE:0)
Block(-11,0,2,STONE:0)
Block(-11,0,3,STONE:0)
Block(-11,0,4,STONE:0)
Block(-11,0,5,STONE:0)
Block(-11,0,6,STONE:0)
Block(-11,0,7,STONE:0)
Block(-11,0,8,STONE:0)
Block(-11,1,-14,STONE:0)
Block(-11,1,-13,STONE:0)
Block(-11,1,-12,STONE:0)
Block(-11,1,-11,STONE:0)
Block(-11,1,-10,STONE:0)
Block(-11,1,-9,STONE:0)
Block(-11,1,-8,STONE:0)
Block(-11,1,-7,STONE:0)
Block(-11,1,-6,STONE:0)
Block(-11,1,-5,STONE:0)
Block(-11,1,-4,STONE:0)
Block(-11,1,-3,STONE:0)
Block(-11,1,-2,STONE:0)
Block(-11,1,-1,STONE:0)
Block(-11,1,0,STONE:0)
Block(-11,1,1,STONE:0)
Block(-11,1,2,STONE:0)
Block(-11,1,3,STONE:0)
Block(-11,1,4,STONE:0)
Block(-11,1,5,STONE:0)
Block(-11,1,6,STONE:0)
Block(-11,1,7,STONE:0)
Block(-11,2,-14,STONE:0)
Block(-11,2,-13,STONE:0)
Block(-11,2,-12,STONE:0)
Block(-11,2,-11,STONE:0)
Block(-11,2,-10,STONE:0)
Block(-11,2,-9,STONE:0)
Block(-11,2,-8,STONE:0)
Block(-11,2,-7,STONE:0)
Block(-11,2,-6,STONE:0)
Block(-11,2,-5,STONE:0)
Block(-11,2,-4,STONE:0)
Block(-11,2,-3,STONE:0)
Block(-11,2,-2,STONE:0)
Block(-11,2,-1,STONE:0)
Block(-11,2,0,STONE:0)
Block(-11,2,1,STONE:0)
Block(-11,2,2,STONE:0)
Block(-11,2,3,STONE:0)
Block(-11,2,4,STONE:0)
Block(-11,2,5,STONE:0)
Block(-11,2,6,STONE:0)
Block(-11,2,7,STONE:0)
Block(-11,3,-14,STONE:0)
Block(-11,3,-13,STONE:0)
Block(-11,3,-12,STONE:0)
Block(-11,3,-11,STONE:0)
Block(-11,3,-10,STONE:0)
Block(-11,3,-9,STONE:0)
Block(-11,3,-8,STONE:0)
Block(-11,3,-7,STONE:0)
Block(-11,3,-6,STONE:0)
Block(-11,3,-5,STONE:0)
Block(-11,3,-4,STONE:0)
Block(-11,3,-3,STONE:0)
Block(-11,3,-2,STONE:0)
Block(-11,3,-1,STONE:0)
Block(-11,3,0,STONE:0)
Block(-11,3,1,STONE:0)
Block(-11,3,2,STONE:0)
Block(-11,3,3,STONE:0)
Block(-11,3,4,STONE:0)
Block(-11,3,5,STONE:0)
Block(-11,3,6,STONE:0)
Block(-11,4,-14,STONE:0)
Block(-11,4,-13,STONE:0)
Block(-11,4,-12,STONE:0)
Block(-11,4,-11,STONE:0)
Block(-11,4,-10,STONE:0)
Block(-11,4,-9,STONE:0)
Block(-11,4,-8,STONE:0)
Block(-11,4,-7,STONE:0)
Block(-11,4,-6,STONE:0)
Block(-11,4,-5,STONE:0)
Block(-11,4,-4,STONE:0)
Block(-11,4,-3,STONE:0)
Block(-11,4,-2,STONE:0)
Block(-11,4,-1,STONE:0)
Block(-11,4,0,STONE:0)
Block(-11,4,1,STONE:0)
Block(-11,4,2,STONE:0)
Block(-11,4,3,STONE:0)
Block(-11,4,4,STONE:0)
Block(-11,4,5,STONE:0)
Block(-11,4,6,STONE:0)
Block(-11,5,-14,STONE:0)
Block(-11,5,-13,STONE:0)
Block(-11,5,-12,STONE:0)
Block(-11,5,-11,STONE:0)
Block(-11,5,-10,STONE:0)
Block(-11,5,-9,STONE:0)
Block(-11,5,-8,STONE:0)
Block(-11,5,-7,STONE:0)
Block(-11,5,-6,STONE:0)
Block(-11,5,-5,STONE:0)
Block(-11,5,-4,STONE:0)
Block(-11,5,-3,STONE:0)
Block(-11,5,-2,STONE:0)
Block(-11,5,-1,STONE:0)
Block(-11,5,0,STONE:0)
Block(-11,5,1,STONE:0)
Block(-11,5,2,STONE:0)
Block(-11,5,3,STONE:0)
Block(-11,5,4,STONE:0)
Block(-11,5,5,STONE:0)
Block(-11,5,6,STONE:0)
Block(-11,6,-14,STONE:0)
Block(-11,6,-13,STONE:0)
Block(-11,6,-12,STONE:0)
Block(-11,6,-11,STONE:0)
Block(-11,6,-10,STONE:0)
Block(-11,6,-9,STONE:0)
Block(-11,6,-8,STONE:0)
Block(-11,6,-7,STONE:0)
Block(-11,6,-6,STONE:0)
Block(-11,6,-5,STONE:0)
Block(-11,6,-4,STONE:0)
Block(-11,6,-3,STONE:0)
Block(-11,6,-2,STONE:0)
Block(-11,6,-1,STONE:0)
Block(-11,6,0,STONE:0)
Block(-11,6,1,STONE:0)
Block(-11,6,2,STONE:0)
Block(-11,6,3,STONE:0)
Block(-11,6,4,STONE:0)
Block(-11,6,5,STONE:0)
Block(-11,6,6,STONE:0)
Block(-11,7,-14,STONE:0)
Block(-11,7,-13,STONE:0)
Block(-11,7,-12,STONE:0)
Block(-11,7,-11,STONE:0)
Block(-11,7,-10,STONE:0)
Block(-11,7,-9,STONE:0)
Block(-11,7,-8,STONE:0)
Block(-11,7,-7,STONE:0)
Block(-11,7,-6,STONE:0)
Block(-11,7,-5,STONE:0)
Block(-11,7,-4,STONE:0)
Block(-11,7,-3,STONE:0)
Block(-11,7,-2,STONE:0)
Block(-11,7,-1,STONE:0)
Block(-11,7,0,STONE:0)
Block(-11,7,1,STONE:0)
Block(-11,7,2,STONE:0)
Block(-11,7,3,STONE:0)
Block(-11,7,4,STONE:0)
Block(-11,7,5,STONE:0)
Block(-11,7,6,STONE:0)
Block(-11,8,-14,STONE:0)
Block(-11,8,-13,STONE:0)
Block(-11,8,-12,STONE:0)
Block(-11,8,-11,STONE:0)
Block(-11,8,-10,STONE:0)
Block(-11,8,-9,STONE:0)
Block(-11,8,-8,STONE:0)
Block(-11,8,-7,STONE:0)
Block(-11,8,-6,STONE:0)
Block(-11,8,-5,STONE:0)
Block(-11,8,-4,STONE:0)
Block(-11,8,-3,STONE:0)
Block(-11,8,-2,STONE:0)
Block(-11,8,-1,STONE:0)
Block(-11,8,0,STONE:0)
Block(-11,8,1,STONE:0)
Block(-11,8,2,STONE:0)
Block(-11,8,3,STONE:0)
Block(-11,8,4,STONE:0)
Block(-11,8,5,STONE:0)
Block(-11,9,-14,STONE:0)
Block(-11,9,-13,STONE:0)
Block(-11,9,-12,STONE:0)
Block(-11,9,-11,STONE:0)
Block(-11,9,-10,STONE:0)
Block(-11,9,-9,STONE:0)
Block(-11,9,-8,STONE:0)
Block(-11,9,-7,STONE:0)
Block(-11,9,-6,STONE:0)
Block(-11,9,-5,STONE:0)
Block(-11,9,-4,STONE:0)
Block(-11,9,-3,STONE:0)
Block(-11,9,-2,STONE:0)
Block(-11,9,-1,STONE:0)
Block(-11,9,0,STONE:0)
Block(-11,9,1,STONE:0)
Block(-11,9,2,STONE:0)
Block(-11,9,3,STONE:0)
Block(-11,9,4,STONE:0)
Block(-11,9,5,STONE:0)
Block(-11,10,-14,STONE:0)
Block(-11,10,-13,STONE:0)
Block(-11,10,-12,STONE:0)
Block(-11,10,-11,STONE:0)
Block(-11,10,-10,STONE:0)
Block(-11,10,-9,STONE:0)
Block(-11,10,-8,STONE:0)
Block(-11,10,-7,STONE:0)
Block(-11,10,-6,STONE:0)
Block(-11,10,-5,STONE:0)
Block(-11,10,-4,STONE:0)
Block(-11,10,-3,STONE:0)
Block(-11,10,-2,STONE:0)
Block(-11,10,-1,STONE:0)
Block(-11,10,0,STONE:0)
Block(-11,10,1,STONE:0)
Block(-11,10,2,STONE:0)
Block(-11,10,3,STONE:0)
Block(-11,10,4,STONE:0)
Block(-11,10,5,STONE:0)
Block(-11,11,-14,STONE:0)
Block(-11,11,-13,STONE:0)
Block(-11,11,-12,STONE:0)
Block(-11,11,-11,STONE:0)
Block(-11,11,-10,STONE:0)
Block(-11,11,-9,STONE:0)
Block(-11,11,-8,STONE:0)
Block(-11,11,-7,STONE:0)
Block(-11,11,-6,STONE:0)
Block(-11,11,-5,STONE:0)
Block(-11,11,-4,STONE:0)
Block(-11,11,-3,STONE:0)
Block(-11,11,-2,STONE:0)
Block(-11,11,-1,STONE:0)
Block(-11,11,0,STONE:0)
Block(-11,11,1,STONE:0)
Block(-11,11,2,STONE:0)
Block(-11,11,3,STONE:0)
Block(-11,11,4,STONE:0)
Block(-11,11,5,STONE:0)
Block(-11,12,-14,STONE:0)
Block(-11,12,-13,STONE:0)
Block(-11,12,-12,STONE:0)
Block(-11,12,-11,STONE:0)
Block(-11,12,-10,STONE:0)
Block(-11,12,-9,STONE:0)
Block(-11,12,-8,STONE:0)
Block(-11,12,-7,STONE:0)
Block(-11,12,-6,STONE:0)
Block(-11,12,-5,STONE:0)
Block(-11,12,-4,STONE:0)
Block(-11,12,-3,STONE:0)
Block(-11,12,-2,STONE:0)
Block(-11,12,-1,STONE:0)
Block(-11,12,0,STONE:0)
Block(-11,12,1,STONE:0)
Block(-11,12,2,STONE:0)
Block(-11,12,3,STONE:0)
Block(-11,12,4,STONE:0)
Block(-11,12,5,STONE:0)
Block(-11,13,-14,STONE:0)
Block(-11,13,-13,STONE:0)
Block(-11,13,-12,STONE:0)
Block(-11,13,-11,STONE:0)
Block(-11,13,-10,STONE:0)
Block(-11,13,-9,STONE:0)
Block(-11,13,-8,STONE:0)
Block(-11,13,-7,STONE:0)
Block(-11,13,-6,STONE:0)
Block(-11,13,-5,STONE:0)
Block(-11,13,-4,STONE:0)
Block(-11,13,-3,STONE:0)
Block(-11,13,-2,STONE:0)
Block(-11,13,-1,STONE:0)
Block(-11,13,0,STONE:0)
Block(-11,13,1,STONE:0)
Block(-11,13,2,STONE:0)
Block(-11,13,3,STONE:0)
Block(-11,13,4,STONE:0)
Block(-11,13,5,STONE:0)
Block(-11,14,-14,STONE:0)
Block(-11,14,-13,STONE:0)
Block(-11,14,-12,STONE:0)
Block(-11,14,-11,STONE:0)
Block(-11,14,-10,STONE:0)
Block(-11,14,-9,STONE:0)
Block(-11,14,-8,STONE:0)
Block(-11,14,-7,STONE:0)
Block(-11,14,-6,STONE:0)
Block(-11,14,-5,STONE:0)
Block(-11,14,-4,STONE:0)
Block(-11,14,-3,STONE:0)
Block(-11,14,-2,STONE:0)
Block(-11,14,-1,STONE:0)
Block(-11,14,0,STONE:0)
Block(-11,14,1,STONE:0)
Block(-11,14,2,STONE:0)
Block(-11,14,3,STONE:0)
Block(-11,14,4,STONE:0)
Block(-11,15,-13,STONE:0)
Block(-11,15,-12,STONE:0)
Block(-11,15,-11,STONE:0)
Block(-11,15,-10,STONE:0)
Block(-11,15,-9,STONE:0)
Block(-11,15,-8,STONE:0)
Block(-11,15,-7,STONE:0)
Block(-11,15,-6,STONE:0)
Block(-11,15,-5,STONE:0)
Block(-11,15,-4,STONE:0)
Block(-11,15,-3,STONE:0)
Block(-11,15,-2,STONE:0)
Block(-11,15,-1,STONE:0)
Block(-11,15,0,STONE:0)
Block(-11,15,1,STONE:0)
Block(-11,15,2,STONE:0)
Block(-11,15,3,STONE:0)
Block(-11,15,4,STONE:0)
Block(-11,16,-13,STONE:0)
Block(-11,16,-12,STONE:0)
Block(-11,16,-11,STONE:0)
Block(-11,16,-10,STONE:0)
Block(-11,16,-9,STONE:0)
Block(-11,16,-8,STONE:0)
Block(-11,16,-7,STONE:0)
Block(-11,16,-6,STONE:0)
Block(-11,16,-5,STONE:0)
Block(-11,16,-4,STONE:0)
Block(-11,16,-3,STONE:0)
Block(-11,16,-2,STONE:0)
Block(-11,16,-1,STONE:0)
Block(-11,16,0,STONE:0)
Block(-11,16,1,STONE:0)
Block(-11,16,2,STONE:0)
Block(-11,16,3,STONE:0)
Block(-11,16,4,STONE:0)
Block(-11,17,-13,STONE:0)
Block(-11,17,-12,STONE:0)
Block(-11,17,-11,STONE:0)
Block(-11,17,-10,STONE:0)
Block(-11,17,-9,STONE:0)
Block(-11,17,-8,STONE:0)
Block(-11,17,-7,STONE:0)
Block(-11,17,-6,STONE:0)
Block(-11,17,-5,STONE:0)
Block(-11,17,-4,STONE:0)
Block(-11,17,-3,STONE:0)
Block(-11,17,-2,STONE:0)
Block(-11,17,-1,STONE:0)
Block(-11,17,0,STONE:0)
Block(-11,17,1,STONE:0)
Block(-11,17,2,STONE:0)
Block(-11,17,3,STONE:0)
Block(-11,18,-13,STONE:0)
Block(-11,18,-12,STONE:0)
Block(-11,18,-11,STONE:0)
Block(-11,18,-10,STONE:0)
Block(-11,18,-9,STONE:0)
Block(-11,18,-8,STONE:0)
Block(-11,18,-7,STONE:0)
Block(-11,18,-6,STONE:0)
Block(-11,18,-5,STONE:0)
Block(-11,18,-4,STONE:0)
Block(-11,18,-3,STONE:0)
Block(-11,18,-2,STONE:0)
Block(-11,18,-1,STONE:0)
Block(-11,18,0,STONE:0)
Block(-11,18,1,STONE:0)
Block(-11,18,2,STONE:0)
Block(-11,19,-13,STONE:0)
Block(-11,19,-12,STONE:0)
Block(-11,19,-11,STONE:0)
Block(-11,19,-10,STONE:0)
Block(-11,19,-9,STONE:0)
Block(-11,19,-8,STONE:0)
Block(-11,19,-7,STONE:0)
Block(-11,19,-6,STONE:0)
Block(-11,19,-5,STONE:0)
Block(-11,19,-4,STONE:0)
Block(-11,19,-3,STONE:0)
Block(-11,19,-2,STONE:0)
Block(-11,19,-1,STONE:0)
Block(-11,19,0,STONE:0)
Block(-11,19,1,STONE:0)
Block(-11,19,2,STONE:0)
Block(-11,20,-13,STONE:0)
Block(-11,20,-12,STONE:0)
Block(-11,20,-11,STONE:0)
Block(-11,20,-10,STONE:0)
Block(-11,20,-9,STONE:0)
Block(-11,20,-8,STONE:0)
Block(-11,20,-7,STONE:0)
Block(-11,20,-6,STONE:0)
Block(-11,20,-5,STONE:0)
Block(-11,20,-4,STONE:0)
Block(-11,20,-3,STONE:0)
Block(-11,20,-2,STONE:0)
Block(-11,20,-1,STONE:0)
Block(-11,20,0,STONE:0)
Block(-11,20,1,STONE:0)
Block(-11,20,2,STONE:0)
Block(-11,21,-13,STONE:0)
Block(-11,21,-12,STONE:0)
Block(-11,21,-11,STONE:0)
Block(-11,21,-10,STONE:0)
Block(-11,21,-9,STONE:0)
Block(-11,21,-8,STONE:0)
Block(-11,21,-7,STONE:0)
Block(-11,21,-6,STONE:0)
Block(-11,21,-5,STONE:0)
Block(-11,21,-4,STONE:0)
Block(-11,21,-3,STONE:0)
Block(-11,21,-2,STONE:0)
Block(-11,21,-1,STONE:0)
Block(-11,21,0,STONE:0)
Block(-11,21,1,STONE:0)
Block(-11,21,2,STONE:0)
Block(-11,22,-13,STONE:0)
Block(-11,22,-12,STONE:0)
Block(-11,22,-11,STONE:0)
Block(-11,22,-10,STONE:0)
Block(-11,22,-9,STONE:0)
Block(-11,22,-8,STONE:0)
Block(-11,22,-7,STONE:0)
Block(-11,22,-6,STONE:0)
Block(-11,22,-5,STONE:0)
Block(-11,22,-4,STONE:0)
Block(-11,22,-3,STONE:0)
Block(-11,22,-2,STONE:0)
Block(-11,22,-1,STONE:0)
Block(-11,22,0,STONE:0)
Block(-11,22,1,STONE:0)
Block(-11,22,2,STONE:0)
Block(-11,23,-13,STONE:0)
Block(-11,23,-12,STONE:0)
Block(-11,23,-11,STONE:0)
Block(-11,23,-10,STONE:0)
Block(-11,23,-9,STONE:0)
Block(-11,23,-8,STONE:0)
Block(-11,23,-7,STONE:0)
Block(-11,23,-6,STONE:0)
Block(-11,23,-5,STONE:0)
Block(-11,23,-4,STONE:0)
Block(-11,23,-3,STONE:0)
Block(-11,23,-2,STONE:0)
Block(-11,23,-1,STONE:0)
Block(-11,23,0,STONE:0)
Block(-11,23,1,STONE:0)
Block(-11,24,-13,STONE:0)
Block(-11,24,-12,STONE:0)
Block(-11,24,-11,STONE:0)
Block(-11,24,-10,STONE:0)
Block(-11,24,-9,STONE:0)
Block(-11,24,-8,STONE:0)
Block(-11,24,-7,STONE:0)
Block(-11,24,-6,STONE:0)
Block(-11,24,-5,STONE:0)
Block(-11,24,-4,STONE:0)
Block(-11,24,-3,STONE:0)
Block(-11,24,-2,STONE:0)
Block(-11,24,-1,STONE:0)
Block(-11,24,0,STONE:0)
Block(-11,24,1,STONE:0)
Block(-11,25,-13,STONE:0)
Block(-11,25,-12,STONE:0)
Block(-11,25,-11,STONE:0)
Block(-11,25,-10,STONE:0)
Block(-11,25,-9,STONE:0)
Block(-11,25,-8,STONE:0)
Block(-11,25,-7,STONE:0)
Block(-11,25,-6,STONE:0)
Block(-11,25,-5,STONE:0)
Block(-11,25,-4,STONE:0)
Block(-11,25,-3,STONE:0)
Block(-11,25,-2,STONE:0)
Block(-11,25,-1,STONE:0)
Block(-11,25,0,STONE:0)
Block(-11,25,1,STONE:0)
Block(-11,26,-13,STONE:0)
Block(-11,26,-12,STONE:0)
Block(-11,26,-11,STONE:0)
Block(-11,26,-10,STONE:0)
Block(-11,26,-9,STONE:0)
Block(-11,26,-8,STONE:0)
Block(-11,26,-7,STONE:0)
Block(-11,26,-6,STONE:0)
Block(-11,26,-5,STONE:0)
Block(-11,26,-4,STONE:0)
Block(-11,26,-3,STONE:0)
Block(-11,26,-2,STONE:0)
Block(-11,26,-1,STONE:0)
Block(-11,26,0,STONE:0)
Block(-11,26,1,STONE:0)
Block(-11,27,-13,STONE:0)
Block(-11,27,-12,STONE:0)
Block(-11,27,-11,STONE:0)
Block(-11,27,-10,STONE:0)
Block(-11,27,-9,STONE:0)
Block(-11,27,-8,STONE:0)
Block(-11,27,-7,STONE:0)
Block(-11,27,-6,STONE:0)
Block(-11,27,-5,STONE:0)
Block(-11,27,-4,STONE:0)
Block(-11,27,-3,STONE:0)
Block(-11,27,-2,STONE:0)
Block(-11,27,-1,STONE:0)
Block(-11,27,0,STONE:0)
Block(-11,27,1,STONE:0)
Block(-11,28,-12,STONE:0)
Block(-11,28,-11,STONE:0)
Block(-11,28,-10,STONE:0)
Block(-11,28,-9,STONE:0)
Block(-11,28,-8,STONE:0)
Block(-11,28,-7,STONE:0)
Block(-11,28,-6,STONE:0)
Block(-11,28,-5,STONE:0)
Block(-11,28,-4,STONE:0)
Block(-11,28,-3,STONE:0)
Block(-11,28,-2,STONE:0)
Block(-11,28,-1,STONE:0)
Block(-11,28,0,STONE:0)
Block(-11,28,1,STONE:0)
Block(-11,29,-12,STONE:0)
Block(-11,29,-11,STONE:0)
Block(-11,29,-10,STONE:0)
Block(-11,29,-9,STONE:0)
Block(-11,29,-8,STONE:0)
Block(-11,29,-7,STONE:0)
Block(-11,29,-6,STONE:0)
Block(-11,29,-5,STONE:0)
Block(-11,29,-4,STONE:0)
Block(-11,29,-3,STONE:0)
Block(-11,29,-2,STONE:0)
Block(-11,29,-1,STONE:0)
Block(-11,29,0,STONE:0)
Block(-11,29,1,STONE:0)
Block(-11,30,-12,STONE:0)
Block(-11,30,-11,STONE:0)
Block(-11,30,-10,STONE:0)
Block(-11,30,-9,STONE:0)
Block(-11,30,-8,STONE:0)
Block(-11,30,-7,STONE:0)
Block(-11,30,-6,STONE:0)
Block(-11,30,-5,STONE:0)
Block(-11,30,-4,STONE:0)
Block(-11,30,-3,STONE:0)
Block(-11,30,-2,STONE:0)
Block(-11,30,-1,STONE:0)
Block(-11,30,0,STONE:0)
Block(-11,30,1,STONE:0)
Block(-11,31,-12,STONE:0)
Block(-11,31,-11,STONE:0)
Block(-11,31,-10,STONE:0)
Block(-11,31,-9,STONE:0)
Block(-11,31,-8,STONE:0)
Block(-11,31,-7,STONE:0)
Block(-11,31,-6,STONE:0)
Block(-11,31,-5,STONE:0)
Block(-11,31,-4,STONE:0)
Block(-11,31,-3,STONE:0)
Block(-11,31,-2,STONE:0)
Block(-11,31,-1,STONE:0)
Block(-11,31,0,STONE:0)
Block(-11,31,1,STONE:0)
Block(-11,32,-12,STONE:0)
Block(-11,32,-11,STONE:0)
Block(-11,32,-10,STONE:0)
Block(-11,32,-9,STONE:0)
Block(-11,32,-8,STONE:0)
Block(-11,32,-7,STONE:0)
Block(-11,32,-6,STONE:0)
Block(-11,32,-5,STONE:0)
Block(-11,32,-4,STONE:0)
Block(-11,32,-3,STONE:0)
Block(-11,32,-2,STONE:0)
Block(-11,32,-1,STONE:0)
Block(-11,32,0,STONE:0)
Block(-11,33,-12,STONE:0)
Block(-11,33,-11,STONE:0)
Block(-11,33,-10,STONE:0)
Block(-11,33,-9,STONE:0)
Block(-11,33,-8,STONE:0)
Block(-11,33,-7,STONE:0)
Block(-11,33,-6,STONE:0)
Block(-11,33,-5,STONE:0)
Block(-11,33,-4,STONE:0)
Block(-11,33,-3,STONE:0)
Block(-11,33,-2,STONE:0)
Block(-11,33,-1,STONE:0)
Block(-11,33,0,STONE:0)
Block(-11,34,-12,STONE:0)
Block(-11,34,-11,STONE:0)
Block(-11,34,-10,STONE:0)
Block(-11,34,-9,STONE:0)
Block(-11,34,-8,STONE:0)
Block(-11,34,-7,STONE:0)
Block(-11,34,-6,STONE:0)
Block(-11,34,-5,STONE:0)
Block(-11,34,-4,STONE:0)
Block(-11,34,-3,STONE:0)
Block(-11,34,-2,STONE:0)
Block(-11,34,-1,STONE:0)
Block(-11,34,0,STONE:0)
Block(-11,35,-12,STONE:0)
Block(-11,35,-11,STONE:0)
Block(-11,35,-10,STONE:0)
Block(-11,35,-9,STONE:0)
Block(-11,35,-8,STONE:0)
Block(-11,35,-7,STONE:0)
Block(-11,35,-6,STONE:0)
Block(-11,35,-5,STONE:0)
Block(-11,35,-4,STONE:0)
Block(-11,35,-3,STONE:0)
Block(-11,35,-2,STONE:0)
Block(-11,35,-1,STONE:0)
Block(-11,35,0,STONE:0)
Block(-11,36,-12,STONE:0)
Block(-11,36,-11,STONE:0)
Block(-11,36,-10,STONE:0)
Block(-11,36,-9,STONE:0)
Block(-11,36,-8,STONE:0)
Block(-11,36,-7,STONE:0)
Block(-11,36,-6,STONE:0)
Block(-11,36,-5,STONE:0)
Block(-11,36,-4,STONE:0)
Block(-11,36,-3,STONE:0)
Block(-11,36,-2,STONE:0)
Block(-11,36,-1,STONE:0)
Block(-11,36,0,STONE:0)
Block(-11,37,-12,STONE:0)
Block(-11,37,-11,STONE:0)
Block(-11,37,-10,STONE:0)
Block(-11,37,-9,STONE:0)
Block(-11,37,-8,STONE:0)
Block(-11,37,-7,STONE:0)
Block(-11,37,-6,STONE:0)
Block(-11,37,-5,STONE:0)
Block(-11,37,-4,STONE:0)
Block(-11,37,-3,STONE:0)
Block(-11,37,-2,STONE:0)
Block(-11,37,-1,STONE:0)
Block(-11,37,0,STONE:0)
Block(-11,38,-11,STONE:0)
Block(-11,38,-10,STONE:0)
Block(-11,38,-9,STONE:0)
Block(-11,38,-8,STONE:0)
Block(-11,38,-7,STONE:0)
Block(-11,38,-6,STONE:0)
Block(-11,38,-5,STONE:0)
Block(-11,38,-4,STONE:0)
Block(-11,38,-3,STONE:0)
Block(-11,38,-2,STONE:0)
Block(-11,38,-1,STONE:0)
Block(-11,38,0,STONE:0)
Block(-11,39,-11,STONE:0)
Block(-11,39,-10,STONE:0)
Block(-11,39,-9,STONE:0)
Block(-11,39,-8,STONE:0)
Block(-11,39,-7,STONE:0)
Block(-11,39,-6,STONE:0)
Block(-11,39,-5,STONE:0)
Block(-11,39,-4,STONE:0)
Block(-11,39,-3,STONE:0)
Block(-11,39,-2,STONE:0)
Block(-11,39,-1,STONE:0)
Block(-11,39,0,STONE:0)
Block(-11,40,-11,STONE:0)
Block(-11,40,-10,STONE:0)
Block(-11,40,-9,STONE:0)
Block(-11,40,-8,STONE:0)
Block(-11,40,-7,STONE:0)
Block(-11,40,-6,STONE:0)
Block(-11,40,-5,STONE:0)
Block(-11,40,-4,STONE:0)
Block(-11,40,-3,STONE:0)
Block(-11,40,-2,STONE:0)
Block(-11,40,-1,STONE:0)
Block(-11,40,0,STONE:0)
Block(-11,41,-11,STONE:0)
Block(-11,41,-10,STONE:0)
Block(-11,41,-9,STONE:0)
Block(-11,41,-8,STONE:0)
Block(-11,41,-7,STONE:0)
Block(-11,41,-6,STONE:0)
Block(-11,41,-5,STONE:0)
Block(-11,41,-4,STONE:0)
Block(-11,41,-3,STONE:0)
Block(-11,41,-2,STONE:0)
Block(-11,41,-1,STONE:0)
Block(-11,41,0,STONE:0)
Block(-11,42,-11,STONE:0)
Block(-11,42,-10,STONE:0)
Block(-11,42,-9,GRASS:0)
Block(-11,42,-8,GRASS:0)
Block(-11,42,-7,GRASS:0)
Block(-11,42,-6,GRASS:0)
Block(-11,42,-5,GRASS:0)
Block(-11,42,-4,GRASS:0)
Block(-11,42,-3,GRASS:0)
Block(-11,42,-2,GRASS:0)
Block(-11,42,-1,STONE:0)
Block(-11,42,0,STONE:0)
Block(-10,0,-15,STONE:0)
Block(-10,0,-14,STONE:0)
Block(-10,0,-13,STONE:0)
Block(-10,0,-12,STONE:0)
Block(-10,0,-11,STONE:0)
Block(-10,0,-10,STONE:0)
Block(-10,0,-9,STONE:0)
Block(-10,0,-8,STONE:0)
Block(-10,0,-7,STONE:0)
Block(-10,0,-6,STONE:0)
Block(-10,0,-5,STONE:0)
Block(-10,0,-4,STONE:0)
Block(-10,0,-3,STONE:0)
Block(-10,0,-2,STONE:0)
Block(-10,0,-1,STONE:0)
Block(-10,0,0,STONE:0)
Block(-10,0,1,STONE:0)
Block(-10,0,2,STONE:0)
Block(-10,0,3,STONE:0)
Block(-10,0,4,STONE:0)
Block(-10,0,5,STONE:0)
Block(-10,0,6,STONE:0)
Block(-10,0,7,STONE:0)
Block(-10,0,8,STONE:0)
Block(-10,0,9,STONE:0)
Block(-10,1,-15,STONE:0)
Block(-10,1,-14,STONE:0)
Block(-10,1,-13,STONE:0)
Block(-10,1,-12,STONE:0)
Block(-10,1,-11,STONE:0)
Block(-10,1,-10,STONE:0)
Block(-10,1,-9,STONE:0)
Block(-10,1,-8,STONE:0)
Block(-10,1,-7,STONE:0)
Block(-10,1,-6,STONE:0)
Block(-10,1,-5,STONE:0)
Block(-10,1,-4,STONE:0)
Block(-10,1,-3,STONE:0)
Block(-10,1,-2,STONE:0)
Block(-10,1,-1,STONE:0)
Block(-10,1,0,STONE:0)
Block(-10,1,1,STONE:0)
Block(-10,1,2,STONE:0)
Block(-10,1,3,STONE:0)
Block(-10,1,4,STONE:0)
Block(-10,1,5,STONE:0)
Block(-10,1,6,STONE:0)
Block(-10,1,7,STONE:0)
Block(-10,1,8,STONE:0)
Block(-10,1,9,STONE:0)
Block(-10,2,-15,STONE:0)
Block(-10,2,-14,STONE:0)
Block(-10,2,-13,STONE:0)
Block(-10,2,-12,STONE:0)
Block(-10,2,-11,STONE:0)
Block(-10,2,-10,STONE:0)
Block(-10,2,-9,STONE:0)
Block(-10,2,-8,STONE:0)
Block(-10,2,-7,STONE:0)
Block(-10,2,-6,STONE:0)
Block(-10,2,-5,STONE:0)
Block(-10,2,-4,STONE:0)
Block(-10,2,-3,STONE:0)
Block(-10,2,-2,STONE:0)
Block(-10,2,-1,STONE:0)
Block(-10,2,0,STONE:0)
Block(-10,2,1,STONE:0)
Block(-10,2,2,STONE:0)
Block(-10,2,3,STONE:0)
Block(-10,2,4,STONE:0)
Block(-10,2,5,STONE:0)
Block(-10,2,6,STONE:0)
Block(-10,2,7,STONE:0)
Block(-10,2,8,STONE:0)
Block(-10,3,-15,STONE:0)
Block(-10,3,-14,STONE:0)
Block(-10,3,-13,STONE:0)
Block(-10,3,-12,STONE:0)
Block(-10,3,-11,STONE:0)
Block(-10,3,-10,STONE:0)
Block(-10,3,-9,STONE:0)
Block(-10,3,-8,STONE:0)
Block(-10,3,-7,STONE:0)
Block(-10,3,-6,STONE:0)
Block(-10,3,-5,STONE:0)
Block(-10,3,-4,STONE:0)
Block(-10,3,-3,STONE:0)
Block(-10,3,-2,STONE:0)
Block(-10,3,-1,STONE:0)
Block(-10,3,0,STONE:0)
Block(-10,3,1,STONE:0)
Block(-10,3,2,STONE:0)
Block(-10,3,3,STONE:0)
Block(-10,3,4,STONE:0)
Block(-10,3,5,STONE:0)
Block(-10,3,6,STONE:0)
Block(-10,3,7,STONE:0)
Block(-10,3,8,STONE:0)
Block(-10,4,-15,STONE:0)
Block(-10,4,-14,STONE:0)
Block(-10,4,-13,STONE:0)
Block(-10,4,-12,STONE:0)
Block(-10,4,-11,STONE:0)
Block(-10,4,-10,STONE:0)
Block(-10,4,-9,STONE:0)
Block(-10,4,-8,STONE:0)
Block(-10,4,-7,STONE:0)
Block(-10,4,-6,STONE:0)
Block(-10,4,-5,STONE:0)
Block(-10,4,-4,STONE:0)
Block(-10,4,-3,STONE:0)
Block(-10,4,-2,STONE:0)
Block(-10,4,-1,STONE:0)
Block(-10,4,0,STONE:0)
Block(-10,4,1,STONE:0)
Block(-10,4,2,STONE:0)
Block(-10,4,3,STONE:0)
Block(-10,4,4,STONE:0)
Block(-10,4,5,STONE:0)
Block(-10,4,6,STONE:0)
Block(-10,4,7,STONE:0)
Block(-10,4,8,STONE:0)
Block(-10,5,-15,STONE:0)
Block(-10,5,-14,STONE:0)
Block(-10,5,-13,STONE:0)
Block(-10,5,-12,STONE:0)
Block(-10,5,-11,STONE:0)
Block(-10,5,-10,STONE:0)
Block(-10,5,-9,STONE:0)
Block(-10,5,-8,STONE:0)
Block(-10,5,-7,STONE:0)
Block(-10,5,-6,STONE:0)
Block(-10,5,-5,STONE:0)
Block(-10,5,-4,STONE:0)
Block(-10,5,-3,STONE:0)
Block(-10,5,-2,STONE:0)
Block(-10,5,-1,STONE:0)
Block(-10,5,0,STONE:0)
Block(-10,5,1,STONE:0)
Block(-10,5,2,STONE:0)
Block(-10,5,3,STONE:0)
Block(-10,5,4,STONE:0)
Block(-10,5,5,STONE:0)
Block(-10,5,6,STONE:0)
Block(-10,5,7,STONE:0)
Block(-10,5,8,STONE:0)
Block(-10,6,-15,STONE:0)
Block(-10,6,-14,STONE:0)
Block(-10,6,-13,STONE:0)
Block(-10,6,-12,STONE:0)
Block(-10,6,-11,STONE:0)
Block(-10,6,-10,STONE:0)
Block(-10,6,-9,STONE:0)
Block(-10,6,-8,STONE:0)
Block(-10,6,-7,STONE:0)
Block(-10,6,-6,STONE:0)
Block(-10,6,-5,STONE:0)
Block(-10,6,-4,STONE:0)
Block(-10,6,-3,STONE:0)
Block(-10,6,-2,STONE:0)
Block(-10,6,-1,STONE:0)
Block(-10,6,0,STONE:0)
Block(-10,6,1,STONE:0)
Block(-10,6,2,STONE:0)
Block(-10,6,3,STONE:0)
Block(-10,6,4,STONE:0)
Block(-10,6,5,STONE:0)
Block(-10,6,6,STONE:0)
Block(-10,6,7,STONE:0)
Block(-10,6,8,STONE:0)
Block(-10,7,-15,STONE:0)
Block(-10,7,-14,STONE:0)
Block(-10,7,-13,STONE:0)
Block(-10,7,-12,STONE:0)
Block(-10,7,-11,STONE:0)
Block(-10,7,-10,STONE:0)
Block(-10,7,-9,STONE:0)
Block(-10,7,-8,STONE:0)
Block(-10,7,-7,STONE:0)
Block(-10,7,-6,STONE:0)
Block(-10,7,-5,STONE:0)
Block(-10,7,-4,STONE:0)
Block(-10,7,-3,STONE:0)
Block(-10,7,-2,STONE:0)
Block(-10,7,-1,STONE:0)
Block(-10,7,0,STONE:0)
Block(-10,7,1,STONE:0)
Block(-10,7,2,STONE:0)
Block(-10,7,3,STONE:0)
Block(-10,7,4,STONE:0)
Block(-10,7,5,STONE:0)
Block(-10,7,6,STONE:0)
Block(-10,7,7,STONE:0)
Block(-10,8,-15,STONE:0)
Block(-10,8,-14,STONE:0)
Block(-10,8,-13,STONE:0)
Block(-10,8,-12,STONE:0)
Block(-10,8,-11,STONE:0)
Block(-10,8,-10,STONE:0)
Block(-10,8,-9,STONE:0)
Block(-10,8,-8,STONE:0)
Block(-10,8,-7,STONE:0)
Block(-10,8,-6,STONE:0)
Block(-10,8,-5,STONE:0)
Block(-10,8,-4,STONE:0)
Block(-10,8,-3,STONE:0)
Block(-10,8,-2,STONE:0)
Block(-10,8,-1,STONE:0)
Block(-10,8,0,STONE:0)
Block(-10,8,1,STONE:0)
Block(-10,8,2,STONE:0)
Block(-10,8,3,STONE:0)
Block(-10,8,4,STONE:0)
Block(-10,8,5,STONE:0)
Block(-10,8,6,STONE:0)
Block(-10,8,7,STONE:0)
Block(-10,9,-15,STONE:0)
Block(-10,9,-14,STONE:0)
Block(-10,9,-13,STONE:0)
Block(-10,9,-12,STONE:0)
Block(-10,9,-11,STONE:0)
Block(-10,9,-10,STONE:0)
Block(-10,9,-9,STONE:0)
Block(-10,9,-8,STONE:0)
Block(-10,9,-7,STONE:0)
Block(-10,9,-6,STONE:0)
Block(-10,9,-5,STONE:0)
Block(-10,9,-4,STONE:0)
Block(-10,9,-3,STONE:0)
Block(-10,9,-2,STONE:0)
Block(-10,9,-1,STONE:0)
Block(-10,9,0,STONE:0)
Block(-10,9,1,STONE:0)
Block(-10,9,2,STONE:0)
Block(-10,9,3,STONE:0)
Block(-10,9,4,STONE:0)
Block(-10,9,5,STONE:0)
Block(-10,9,6,STONE:0)
Block(-10,9,7,STONE:0)
Block(-10,10,-15,STONE:0)
Block(-10,10,-14,STONE:0)
Block(-10,10,-13,STONE:0)
Block(-10,10,-12,STONE:0)
Block(-10,10,-11,STONE:0)
Block(-10,10,-10,STONE:0)
Block(-10,10,-9,STONE:0)
Block(-10,10,-8,STONE:0)
Block(-10,10,-7,STONE:0)
Block(-10,10,-6,STONE:0)
Block(-10,10,-5,STONE:0)
Block(-10,10,-4,STONE:0)
Block(-10,10,-3,STONE:0)
Block(-10,10,-2,STONE:0)
Block(-10,10,-1,STONE:0)
Block(-10,10,0,STONE:0)
Block(-10,10,1,STONE:0)
Block(-10,10,2,STONE:0)
Block(-10,10,3,STONE:0)
Block(-10,10,4,STONE:0)
Block(-10,10,5,STONE:0)
Block(-10,10,6,STONE:0)
Block(-10,10,7,STONE:0)
Block(-10,11,-15,STONE:0)
Block(-10,11,-14,STONE:0)
Block(-10,11,-13,STONE:0)
Block(-10,11,-12,STONE:0)
Block(-10,11,-11,STONE:0)
Block(-10,11,-10,STONE:0)
Block(-10,11,-9,STONE:0)
Block(-10,11,-8,STONE:0)
Block(-10,11,-7,STONE:0)
Block(-10,11,-6,STONE:0)
Block(-10,11,-5,STONE:0)
Block(-10,11,-4,STONE:0)
Block(-10,11,-3,STONE:0)
Block(-10,11,-2,STONE:0)
Block(-10,11,-1,STONE:0)
Block(-10,11,0,STONE:0)
Block(-10,11,1,STONE:0)
Block(-10,11,2,STONE:0)
Block(-10,11,3,STONE:0)
Block(-10,11,4,STONE:0)
Block(-10,11,5,STONE:0)
Block(-10,11,6,STONE:0)
Block(-10,11,7,STONE:0)
Block(-10,12,-15,STONE:0)
Block(-10,12,-14,STONE:0)
Block(-10,12,-13,STONE:0)
Block(-10,12,-12,STONE:0)
Block(-10,12,-11,STONE:0)
Block(-10,12,-10,STONE:0)
Block(-10,12,-9,STONE:0)
Block(-10,12,-8,STONE:0)
Block(-10,12,-7,STONE:0)
Block(-10,12,-6,STONE:0)
Block(-10,12,-5,STONE:0)
Block(-10,12,-4,STONE:0)
Block(-10,12,-3,STONE:0)
Block(-10,12,-2,STONE:0)
Block(-10,12,-1,STONE:0)
Block(-10,12,0,STONE:0)
Block(-10,12,1,STONE:0)
Block(-10,12,2,STONE:0)
Block(-10,12,3,STONE:0)
Block(-10,12,4,STONE:0)
Block(-10,12,5,STONE:0)
Block(-10,12,6,STONE:0)
Block(-10,12,7,STONE:0)
Block(-10,13,-15,STONE:0)
Block(-10,13,-14,STONE:0)
Block(-10,13,-13,STONE:0)
Block(-10,13,-12,STONE:0)
Block(-10,13,-11,STONE:0)
Block(-10,13,-10,STONE:0)
Block(-10,13,-9,STONE:0)
Block(-10,13,-8,STONE:0)
Block(-10,13,-7,STONE:0)
Block(-10,13,-6,STONE:0)
Block(-10,13,-5,STONE:0)
Block(-10,13,-4,STONE:0)
Block(-10,13,-3,STONE:0)
Block(-10,13,-2,STONE:0)
Block(-10,13,-1,STONE:0)
Block(-10,13,0,STONE:0)
Block(-10,13,1,STONE:0)
Block(-10,13,2,STONE:0)
Block(-10,13,3,STONE:0)
Block(-10,13,4,STONE:0)
Block(-10,13,5,STONE:0)
Block(-10,13,6,STONE:0)
Block(-10,13,7,STONE:0)
Block(-10,14,-14,STONE:0)
Block(-10,14,-13,STONE:0)
Block(-10,14,-12,STONE:0)
Block(-10,14,-11,STONE:0)
