
#######################################################################
# +-----------------------------------------------------------------+ #
# |                            BO3 object                           | #
# +-----------------------------------------------------------------+ #
#######################################################################

# This is the config file of a custom object.
# If you add this object correctly to your BiomeConfigs, it will spawn in the world.

# This is the creator of this BO3 object
Author: Unknown

# A short description of this BO3 object
Description: No description given

# The BO3 version, don't change this! It can be used by external applications to do a version check.
Version: 3

# The settings mode, WriteAll, WriteWithoutComments or WriteDisable. See WorldConfig.
SettingsMode: WriteAll


#######################################################################
# +-----------------------------------------------------------------+ #
# |                          Main settings                          | #
# +-----------------------------------------------------------------+ #
#######################################################################

# This needs to be set to true to spawn the object in the Tree and Sapling resources.
Tree: true

# The frequency of the BO3 from 1 to 200. Tries this many times to spawn this BO3 when using the CustomObject(...) resource.
# Ignored by Tree(..), Sapling(..) and CustomStructure(..)
Frequency: 1

# The rarity of the BO3 from 0 to 100. Each spawn attempt has rarity% chance to succeed when using the CustomObject(...) resource.
# Ignored by Tree(..), Sapling(..) and CustomStructure(..)
Rarity: 50.0

# If you set this to true, the BO3 will be placed with a random rotation.
RotateRandomly: true

# The spawn height of the BO3: randomY, highestBlock or highestSolidBlock.
SpawnHeight: highestSolidBlock

# The offset from the spawn height to spawn this BO3
# Ex. SpawnHeight = highestSolidBlock, SpawnHeightOffset = 3; This object will spawn 3 blocks above the highest solid block
SpawnHeightOffset: -3

# A random amount to offset the spawn location from the spawn offset height
# Ex. SpawnHeightOffset = 3, SpawnHeightVariance = 3; This object will spawn 3 to 6 blocks above the original spot it would have spawned
SpawnHeightVariance: 0

##############################
# Height Limits for the BO3. #
##############################

# When in randomY mode used as the minimum Y or in atMinY mode as the actual Y to spawn this BO3 at.
MinHeight: 90

# When in randomY mode used as the maximum Y to spawn this BO3 at.
MaxHeight: 95

######################
# Extrusion settings #
######################

# The style of extrusion you wish to use - BottomDown, TopUp, None (Default)
ExtrudeMode: None

# The blocks to extrude your BO3 through
ExtrudeThroughBlocks: AIR

# Objects can have other objects attacthed to it: branches. Branches can also
# have branches attached to it, which can also have branches, etc. This is the
# maximum branch depth for this objects.
MaxBranchDepth: 10

# When spawned with the UseWorld keyword, this BO3 should NOT spawn in the following biomes.
# If you write the BO3 name directly in the BiomeConfigs, this will be ignored.
ExcludedBiomes: All


#######################################################################
# +-----------------------------------------------------------------+ #
# |                      Source block settings                      | #
# +-----------------------------------------------------------------+ #
#######################################################################

# The block(s) the BO3 should spawn in.
SourceBlocks: AIR

# The maximum percentage of the BO3 that can be outside the SourceBlock.
# The BO3 won't be placed on a location with more blocks outside the SourceBlock than this percentage.
MaxPercentageOutsideSourceBlock: 100

# What to do when a block is about to be placed outside the SourceBlock? (dontPlace, placeAnyway)
OutsideSourceBlock: placeAnyway

# Disable doReplaceBlocks to make this BO3 ignore any ReplacedBlocks settings in biome configs, improves performance.
DoReplaceBlocks: true

# OTG+ settings #
# Legacy setting, rename this file to .BO4 instead. Set this to true to enable the advanced customstructure features of OTG+.
IsOTGPlus: false


#######################################################################
# +-----------------------------------------------------------------+ #
# |                              Blocks                             | #
# +-----------------------------------------------------------------+ #
#######################################################################

# All the blocks used in the BO3 are listed here. Possible blocks:
# Block(x,y,z,id[.data][,nbtfile.nbt)
# RandomBlock(x,y,z,id[:data][,nbtfile.nbt],chance[,id[:data][,nbtfile.nbt],chance[,...]])
#  So RandomBlock(0,0,0,CHEST,chest.nbt,50,CHEST,anotherchest.nbt,100) will spawn a chest at
#  the BO3 origin, and give it a 50% chance to have the contents of chest.nbt, or, if that
#  fails, a 100% percent chance to have the contents of anotherchest.nbt.
# *Note: Unlike Entity() and Spawner(), for Block() .txt files don't work, only .nbt files work.
# MinecraftObject(x,y,z,name) (TODO: This may not work anymore and needs to be tested.
#  Spawns an object in the Mojang NBT structure format. For example, 
#  MinecraftObject(0,0,0,minecraft:igloo/igloo_bottom)
#  spawns the bottom part of an igloo.
Block(-8,-8,2,STONE:0)
Block(-8,-7,1,STONE:0)
Block(-8,-7,2,STONE:0)
Block(-8,-7,3,STONE:0)
Block(-8,-6,1,STONE:0)
Block(-8,-6,2,STONE:0)
Block(-8,-6,3,STONE:0)
Block(-8,-5,1,STONE:0)
Block(-8,-5,2,STONE:0)
Block(-8,-5,3,STONE:0)
Block(-8,-4,1,STONE:0)
Block(-8,-4,2,STONE:0)
Block(-8,-3,0,STONE:0)
Block(-8,-3,1,STONE:0)
Block(-8,-3,2,STONE:0)
Block(-8,-2,0,STONE:0)
Block(-8,-2,1,STONE:0)
Block(-8,-2,2,STONE:0)
Block(-8,-1,-1,STONE:0)
Block(-8,-1,0,STONE:0)
Block(-8,-1,1,STONE:0)
Block(-8,-1,2,STONE:0)
Block(-8,0,-1,STONE:0)
Block(-8,0,0,STONE:0)
Block(-8,0,1,STONE:0)
Block(-8,0,2,STONE:0)
Block(-8,1,-1,STONE:0)
Block(-8,1,0,STONE:0)
Block(-8,1,1,STONE:0)
Block(-8,1,2,STONE:0)
Block(-8,2,-1,STONE:0)
Block(-8,2,0,STONE:0)
Block(-8,2,1,STONE:0)
Block(-8,2,2,STONE:0)
Block(-8,3,-2,DIRT:0)
Block(-8,3,-1,DIRT:0)
Block(-8,3,0,STONE:0)
Block(-8,3,1,STONE:0)
Block(-8,4,-2,GRASS:0)
Block(-8,4,-1,DIRT:0)
Block(-8,4,0,DIRT:0)
Block(-8,4,1,GRASS:0)
Block(-8,5,-1,GRASS:0)
Block(-8,5,0,GRASS:0)
Block(-7,-9,0,STONE:0)
Block(-7,-9,1,STONE:0)
Block(-7,-9,2,STONE:0)
Block(-7,-9,3,STONE:0)
Block(-7,-8,-1,STONE:0)
Block(-7,-8,0,STONE:0)
Block(-7,-8,1,STONE:0)
Block(-7,-8,2,STONE:0)
Block(-7,-8,3,STONE:0)
Block(-7,-8,4,STONE:0)
Block(-7,-7,-1,STONE:0)
Block(-7,-7,0,STONE:0)
Block(-7,-7,1,STONE:0)
Block(-7,-7,2,STONE:0)
Block(-7,-7,3,STONE:0)
Block(-7,-7,4,STONE:0)
Block(-7,-6,-1,STONE:0)
Block(-7,-6,0,STONE:0)
Block(-7,-6,1,STONE:0)
Block(-7,-6,2,STONE:0)
Block(-7,-6,3,STONE:0)
Block(-7,-6,4,STONE:0)
Block(-7,-5,-2,STONE:0)
Block(-7,-5,-1,STONE:0)
Block(-7,-5,0,STONE:0)
Block(-7,-5,1,STONE:0)
Block(-7,-5,2,STONE:0)
Block(-7,-5,3,STONE:0)
Block(-7,-5,4,STONE:0)
Block(-7,-4,-3,STONE:0)
Block(-7,-4,-2,STONE:0)
Block(-7,-4,-1,STONE:0)
Block(-7,-4,0,STONE:0)
Block(-7,-4,1,STONE:0)
Block(-7,-4,2,STONE:0)
Block(-7,-4,3,STONE:0)
Block(-7,-3,-3,STONE:0)
Block(-7,-3,-2,STONE:0)
Block(-7,-3,-1,STONE:0)
Block(-7,-3,0,STONE:0)
Block(-7,-3,1,STONE:0)
Block(-7,-3,2,STONE:0)
Block(-7,-3,3,STONE:0)
Block(-7,-2,-3,STONE:0)
Block(-7,-2,-2,STONE:0)
Block(-7,-2,-1,STONE:0)
Block(-7,-2,0,STONE:0)
Block(-7,-2,1,STONE:0)
Block(-7,-2,2,STONE:0)
Block(-7,-2,3,STONE:0)
Block(-7,-1,-3,STONE:0)
Block(-7,-1,-2,STONE:0)
Block(-7,-1,-1,STONE:0)
Block(-7,-1,0,STONE:0)
Block(-7,-1,1,STONE:0)
Block(-7,-1,2,STONE:0)
Block(-7,-1,3,STONE:0)
Block(-7,0,-3,STONE:0)
Block(-7,0,-2,STONE:0)
Block(-7,0,-1,STONE:0)
Block(-7,0,0,STONE:0)
Block(-7,0,1,STONE:0)
Block(-7,0,2,STONE:0)
Block(-7,0,3,STONE:0)
Block(-7,1,-3,STONE:0)
Block(-7,1,-2,STONE:0)
Block(-7,1,-1,STONE:0)
Block(-7,1,0,STONE:0)
Block(-7,1,1,STONE:0)
Block(-7,1,2,STONE:0)
Block(-7,1,3,STONE:0)
Block(-7,2,-4,STONE:0)
Block(-7,2,-3,STONE:0)
Block(-7,2,-2,STONE:0)
Block(-7,2,-1,STONE:0)
Block(-7,2,0,STONE:0)
Block(-7,2,1,STONE:0)
Block(-7,2,2,STONE:0)
Block(-7,2,3,STONE:0)
Block(-7,3,-4,DIRT:0)
Block(-7,3,-3,DIRT:0)
Block(-7,3,-2,STONE:0)
Block(-7,3,-1,STONE:0)
Block(-7,3,0,STONE:0)
Block(-7,3,1,STONE:0)
Block(-7,3,2,DIRT:0)
Block(-7,3,3,GRASS:0)
Block(-7,4,-4,GRASS:0)
Block(-7,4,-3,DIRT:0)
Block(-7,4,-2,STONE:0)
Block(-7,4,-1,STONE:0)
Block(-7,4,0,STONE:0)
Block(-7,4,1,STONE:0)
Block(-7,4,2,DIRT:0)
Block(-7,5,-3,DIRT:0)
Block(-7,5,-2,DIRT:0)
Block(-7,5,-1,STONE:0)
Block(-7,5,0,STONE:0)
Block(-7,5,1,DIRT:0)
Block(-7,5,2,GRASS:0)
Block(-7,6,-3,GRASS:0)
Block(-7,6,-2,GRASS:0)
Block(-7,6,-1,GRASS:0)
Block(-7,6,0,GRASS:0)
Block(-7,6,1,GRASS:0)
Block(-6,-10,0,STONE:0)
Block(-6,-10,1,STONE:0)
Block(-6,-10,2,STONE:0)
Block(-6,-10,3,STONE:0)
Block(-6,-9,-2,STONE:0)
Block(-6,-9,-1,STONE:0)
Block(-6,-9,0,STONE:0)
Block(-6,-9,1,STONE:0)
Block(-6,-9,2,STONE:0)
Block(-6,-9,3,STONE:0)
Block(-6,-9,4,STONE:0)
Block(-6,-8,-3,STONE:0)
Block(-6,-8,-2,STONE:0)
Block(-6,-8,-1,STONE:0)
Block(-6,-8,0,STONE:0)
Block(-6,-8,1,STONE:0)
Block(-6,-8,2,STONE:0)
Block(-6,-8,3,STONE:0)
Block(-6,-8,4,STONE:0)
Block(-6,-8,5,STONE:0)
Block(-6,-7,-3,STONE:0)
Block(-6,-7,-2,STONE:0)
Block(-6,-7,-1,STONE:0)
Block(-6,-7,0,STONE:0)
Block(-6,-7,1,STONE:0)
Block(-6,-7,2,STONE:0)
Block(-6,-7,3,STONE:0)
Block(-6,-7,4,STONE:0)
Block(-6,-7,5,STONE:0)
Block(-6,-6,-4,STONE:0)
Block(-6,-6,-3,STONE:0)
Block(-6,-6,-2,STONE:0)
Block(-6,-6,-1,STONE:0)
Block(-6,-6,0,STONE:0)
Block(-6,-6,1,STONE:0)
Block(-6,-6,2,STONE:0)
Block(-6,-6,3,STONE:0)
Block(-6,-6,4,STONE:0)
Block(-6,-6,5,STONE:0)
Block(-6,-5,-5,STONE:0)
Block(-6,-5,-4,STONE:0)
Block(-6,-5,-3,STONE:0)
Block(-6,-5,-2,STONE:0)
Block(-6,-5,-1,STONE:0)
Block(-6,-5,0,STONE:0)
Block(-6,-5,1,STONE:0)
Block(-6,-5,2,STONE:0)
Block(-6,-5,3,STONE:0)
Block(-6,-5,4,STONE:0)
Block(-6,-5,5,STONE:0)
Block(-6,-4,-5,STONE:0)
Block(-6,-4,-4,STONE:0)
Block(-6,-4,-3,STONE:0)
Block(-6,-4,-2,STONE:0)
Block(-6,-4,-1,STONE:0)
Block(-6,-4,0,STONE:0)
Block(-6,-4,1,STONE:0)
Block(-6,-4,2,STONE:0)
Block(-6,-4,3,STONE:0)
Block(-6,-4,4,STONE:0)
Block(-6,-3,-5,STONE:0)
Block(-6,-3,-4,STONE:0)
Block(-6,-3,-3,STONE:0)
Block(-6,-3,-2,STONE:0)
Block(-6,-3,-1,STONE:0)
Block(-6,-3,0,STONE:0)
Block(-6,-3,1,STONE:0)
Block(-6,-3,2,STONE:0)
Block(-6,-3,3,STONE:0)
Block(-6,-3,4,STONE:0)
Block(-6,-2,-5,STONE:0)
Block(-6,-2,-4,STONE:0)
Block(-6,-2,-3,STONE:0)
Block(-6,-2,-2,STONE:0)
Block(-6,-2,-1,STONE:0)
Block(-6,-2,0,STONE:0)
Block(-6,-2,1,STONE:0)
Block(-6,-2,2,STONE:0)
Block(-6,-2,3,STONE:0)
Block(-6,-2,4,STONE:0)
Block(-6,-1,-5,STONE:0)
Block(-6,-1,-4,STONE:0)
Block(-6,-1,-3,STONE:0)
Block(-6,-1,-2,STONE:0)
Block(-6,-1,-1,STONE:0)
Block(-6,-1,0,STONE:0)
Block(-6,-1,1,STONE:0)
Block(-6,-1,2,STONE:0)
Block(-6,-1,3,STONE:0)
Block(-6,-1,4,STONE:0)
Block(-6,0,-6,DIRT:0)
Block(-6,0,-5,DIRT:0)
Block(-6,0,-4,STONE:0)
Block(-6,0,-3,STONE:0)
Block(-6,0,-2,STONE:0)
Block(-6,0,-1,STONE:0)
Block(-6,0,0,STONE:0)
Block(-6,0,1,STONE:0)
Block(-6,0,2,STONE:0)
Block(-6,0,3,STONE:0)
Block(-6,0,4,STONE:0)
Block(-6,1,-6,DIRT:0)
Block(-6,1,-5,DIRT:0)
Block(-6,1,-4,DIRT:0)
Block(-6,1,-3,STONE:0)
Block(-6,1,-2,STONE:0)
Block(-6,1,-1,STONE:0)
Block(-6,1,0,STONE:0)
Block(-6,1,1,STONE:0)
Block(-6,1,2,STONE:0)
Block(-6,1,3,STONE:0)
Block(-6,1,4,STONE:0)
Block(-6,2,-6,GRASS:0)
Block(-6,2,-5,DIRT:0)
Block(-6,2,-4,STONE:0)
Block(-6,2,-3,STONE:0)
Block(-6,2,-2,STONE:0)
Block(-6,2,-1,STONE:0)
Block(-6,2,0,STONE:0)
Block(-6,2,1,STONE:0)
Block(-6,2,2,STONE:0)
Block(-6,2,3,STONE:0)
Block(-6,2,4,DIRT:0)
Block(-6,3,-5,DIRT:0)
Block(-6,3,-4,STONE:0)
Block(-6,3,-3,STONE:0)
Block(-6,3,-2,STONE:0)
Block(-6,3,-1,STONE:0)
Block(-6,3,0,STONE:0)
Block(-6,3,1,STONE:0)
Block(-6,3,2,STONE:0)
Block(-6,3,3,STONE:0)
Block(-6,3,4,GRASS:0)
Block(-6,4,-5,DIRT:0)
Block(-6,4,-4,STONE:0)
Block(-6,4,-3,STONE:0)
Block(-6,4,-2,STONE:0)
Block(-6,4,-1,STONE:0)
Block(-6,4,0,STONE:0)
Block(-6,4,1,STONE:0)
Block(-6,4,2,STONE:0)
Block(-6,4,3,DIRT:0)
Block(-6,5,-5,GRASS:0)
Block(-6,5,-4,DIRT:0)
Block(-6,5,-3,STONE:0)
Block(-6,5,-2,STONE:0)
Block(-6,5,-1,STONE:0)
Block(-6,5,0,STONE:0)
Block(-6,5,1,STONE:0)
Block(-6,5,2,STONE:0)
Block(-6,5,3,DIRT:0)
Block(-6,6,-4,GRASS:0)
Block(-6,6,-3,STONE:0)
Block(-6,6,-2,STONE:0)
Block(-6,6,-1,STONE:0)
Block(-6,6,0,STONE:0)
Block(-6,6,1,STONE:0)
Block(-6,6,2,DIRT:0)
Block(-6,6,3,GRASS:0)
Block(-6,7,-3,GRASS:0)
Block(-6,7,-2,GRASS:0)
Block(-6,7,-1,GRASS:0)
Block(-6,7,0,GRASS:0)
Block(-6,7,1,GRASS:0)
Block(-6,7,2,GRASS:0)
Block(-5,-11,2,STONE:0)
Block(-5,-10,-1,STONE:0)
Block(-5,-10,0,STONE:0)
Block(-5,-10,1,STONE:0)
Block(-5,-10,2,STONE:0)
Block(-5,-10,3,STONE:0)
Block(-5,-10,4,STONE:0)
Block(-5,-9,-2,STONE:0)
Block(-5,-9,-1,STONE:0)
Block(-5,-9,0,STONE:0)
Block(-5,-9,1,STONE:0)
Block(-5,-9,2,STONE:0)
Block(-5,-9,3,STONE:0)
Block(-5,-9,4,STONE:0)
Block(-5,-9,5,STONE:0)
Block(-5,-8,-4,STONE:0)
Block(-5,-8,-3,STONE:0)
Block(-5,-8,-2,STONE:0)
Block(-5,-8,-1,STONE:0)
Block(-5,-8,0,STONE:0)
Block(-5,-8,1,STONE:0)
Block(-5,-8,2,STONE:0)
Block(-5,-8,3,STONE:0)
Block(-5,-8,4,STONE:0)
Block(-5,-8,5,STONE:0)
Block(-5,-7,-5,STONE:0)
Block(-5,-7,-4,STONE:0)
Block(-5,-7,-3,STONE:0)
Block(-5,-7,-2,STONE:0)
Block(-5,-7,-1,STONE:0)
Block(-5,-7,0,STONE:0)
Block(-5,-7,1,STONE:0)
Block(-5,-7,2,STONE:0)
Block(-5,-7,3,STONE:0)
Block(-5,-7,4,STONE:0)
Block(-5,-7,5,STONE:0)
Block(-5,-7,6,STONE:0)
Block(-5,-6,-6,STONE:0)
Block(-5,-6,-5,STONE:0)
Block(-5,-6,-4,STONE:0)
Block(-5,-6,-3,STONE:0)
Block(-5,-6,-2,STONE:0)
Block(-5,-6,-1,STONE:0)
Block(-5,-6,0,STONE:0)
Block(-5,-6,1,STONE:0)
Block(-5,-6,2,STONE:0)
Block(-5,-6,3,STONE:0)
Block(-5,-6,4,STONE:0)
Block(-5,-6,5,STONE:0)
Block(-5,-6,6,STONE:0)
Block(-5,-5,-6,STONE:0)
Block(-5,-5,-5,STONE:0)
Block(-5,-5,-4,STONE:0)
Block(-5,-5,-3,STONE:0)
Block(-5,-5,-2,STONE:0)
Block(-5,-5,-1,STONE:0)
Block(-5,-5,0,STONE:0)
Block(-5,-5,1,STONE:0)
Block(-5,-5,2,STONE:0)
Block(-5,-5,3,STONE:0)
Block(-5,-5,4,STONE:0)
Block(-5,-5,5,STONE:0)
Block(-5,-4,-6,STONE:0)
Block(-5,-4,-5,STONE:0)
Block(-5,-4,-4,STONE:0)
Block(-5,-4,-3,STONE:0)
Block(-5,-4,-2,STONE:0)
Block(-5,-4,-1,STONE:0)
Block(-5,-4,0,STONE:0)
Block(-5,-4,1,STONE:0)
Block(-5,-4,2,STONE:0)
Block(-5,-4,3,STONE:0)
Block(-5,-4,4,STONE:0)
Block(-5,-4,5,STONE:0)
Block(-5,-3,-7,STONE:0)
Block(-5,-3,-6,STONE:0)
Block(-5,-3,-5,STONE:0)
Block(-5,-3,-4,STONE:0)
Block(-5,-3,-3,STONE:0)
Block(-5,-3,-2,STONE:0)
Block(-5,-3,-1,STONE:0)
Block(-5,-3,0,STONE:0)
Block(-5,-3,1,STONE:0)
Block(-5,-3,2,STONE:0)
Block(-5,-3,3,STONE:0)
Block(-5,-3,4,STONE:0)
Block(-5,-3,5,STONE:0)
Block(-5,-2,-7,STONE:0)
Block(-5,-2,-6,STONE:0)
Block(-5,-2,-5,STONE:0)
Block(-5,-2,-4,STONE:0)
Block(-5,-2,-3,STONE:0)
Block(-5,-2,-2,STONE:0)
Block(-5,-2,-1,STONE:0)
Block(-5,-2,0,STONE:0)
Block(-5,-2,1,STONE:0)
Block(-5,-2,2,STONE:0)
Block(-5,-2,3,STONE:0)
Block(-5,-2,4,STONE:0)
Block(-5,-2,5,STONE:0)
Block(-5,-1,-7,DIRT:0)
Block(-5,-1,-6,DIRT:0)
Block(-5,-1,-5,STONE:0)
Block(-5,-1,-4,STONE:0)
Block(-5,-1,-3,STONE:0)
Block(-5,-1,-2,STONE:0)
Block(-5,-1,-1,STONE:0)
Block(-5,-1,0,STONE:0)
Block(-5,-1,1,STONE:0)
Block(-5,-1,2,STONE:0)
Block(-5,-1,3,STONE:0)
Block(-5,-1,4,STONE:0)
Block(-5,-1,5,STONE:0)
Block(-5,0,-8,DIRT:0)
Block(-5,0,-7,DIRT:0)
Block(-5,0,-6,STONE:0)
Block(-5,0,-5,STONE:0)
Block(-5,0,-4,STONE:0)
Block(-5,0,-3,STONE:0)
Block(-5,0,-2,STONE:0)
Block(-5,0,-1,STONE:0)
Block(-5,0,0,STONE:0)
Block(-5,0,1,STONE:0)
Block(-5,0,2,STONE:0)
Block(-5,0,3,STONE:0)
Block(-5,0,4,STONE:0)
Block(-5,0,5,STONE:0)
Block(-5,1,-8,GRASS:0)
Block(-5,1,-7,DIRT:0)
Block(-5,1,-6,STONE:0)
Block(-5,1,-5,STONE:0)
Block(-5,1,-4,STONE:0)
Block(-5,1,-3,STONE:0)
Block(-5,1,-2,STONE:0)
Block(-5,1,-1,STONE:0)
Block(-5,1,0,STONE:0)
Block(-5,1,1,STONE:0)
Block(-5,1,2,STONE:0)
Block(-5,1,3,STONE:0)
Block(-5,1,4,STONE:0)
Block(-5,1,5,STONE:0)
Block(-5,2,-7,DIRT:0)
Block(-5,2,-6,STONE:0)
Block(-5,2,-5,STONE:0)
Block(-5,2,-4,STONE:0)
Block(-5,2,-3,STONE:0)
Block(-5,2,-2,STONE:0)
Block(-5,2,-1,STONE:0)
Block(-5,2,0,STONE:0)
Block(-5,2,1,STONE:0)
Block(-5,2,2,STONE:0)
Block(-5,2,3,STONE:0)
Block(-5,2,4,STONE:0)
Block(-5,2,5,DIRT:0)
Block(-5,3,-7,GRASS:0)
Block(-5,3,-6,DIRT:0)
Block(-5,3,-5,STONE:0)
Block(-5,3,-4,STONE:0)
Block(-5,3,-3,STONE:0)
Block(-5,3,-2,STONE:0)
Block(-5,3,-1,STONE:0)
Block(-5,3,0,STONE:0)
Block(-5,3,1,STONE:0)
Block(-5,3,2,STONE:0)
Block(-5,3,3,STONE:0)
Block(-5,3,4,STONE:0)
Block(-5,3,5,GRASS:0)
Block(-5,4,-6,GRASS:0)
Block(-5,4,-5,STONE:0)
Block(-5,4,-4,STONE:0)
Block(-5,4,-3,STONE:0)
Block(-5,4,-2,STONE:0)
Block(-5,4,-1,STONE:0)
Block(-5,4,0,STONE:0)
Block(-5,4,1,STONE:0)
Block(-5,4,2,STONE:0)
Block(-5,4,3,STONE:0)
Block(-5,4,4,DIRT:0)
Block(-5,5,-5,DIRT:0)
Block(-5,5,-4,STONE:0)
Block(-5,5,-3,STONE:0)
Block(-5,5,-2,STONE:0)
Block(-5,5,-1,STONE:0)
Block(-5,5,0,STONE:0)
Block(-5,5,1,STONE:0)
Block(-5,5,2,STONE:0)
Block(-5,5,3,STONE:0)
Block(-5,5,4,DIRT:0)
Block(-5,6,-5,GRASS:0)
Block(-5,6,-4,STONE:0)
Block(-5,6,-3,STONE:0)
Block(-5,6,-2,STONE:0)
Block(-5,6,-1,STONE:0)
Block(-5,6,0,STONE:0)
Block(-5,6,1,STONE:0)
Block(-5,6,2,STONE:0)
Block(-5,6,3,STONE:0)
Block(-5,6,4,GRASS:0)
Block(-5,7,-4,GRASS:0)
Block(-5,7,-3,GRASS:0)
Block(-5,7,-2,STONE:0)
Block(-5,7,-1,STONE:0)
Block(-5,7,0,STONE:0)
Block(-5,7,1,STONE:0)
Block(-5,7,2,GRASS:0)
Block(-5,7,3,GRASS:0)
Block(-5,8,-2,GRASS:0)
Block(-5,8,-1,GRASS:0)
Block(-5,8,0,GRASS:0)
Block(-5,8,1,GRASS:0)
Block(-4,-11,1,STONE:0)
Block(-4,-11,2,STONE:0)
Block(-4,-11,3,STONE:0)
Block(-4,-10,-1,STONE:0)
Block(-4,-10,0,STONE:0)
Block(-4,-10,1,STONE:0)
Block(-4,-10,2,STONE:0)
Block(-4,-10,3,STONE:0)
Block(-4,-10,4,STONE:0)
Block(-4,-9,-3,STONE:0)
Block(-4,-9,-2,STONE:0)
Block(-4,-9,-1,STONE:0)
Block(-4,-9,0,STONE:0)
Block(-4,-9,1,STONE:0)
Block(-4,-9,2,STONE:0)
Block(-4,-9,3,STONE:0)
Block(-4,-9,4,STONE:0)
Block(-4,-9,5,STONE:0)
Block(-4,-8,-5,STONE:0)
Block(-4,-8,-4,STONE:0)
Block(-4,-8,-3,STONE:0)
Block(-4,-8,-2,STONE:0)
Block(-4,-8,-1,STONE:0)
Block(-4,-8,0,STONE:0)
Block(-4,-8,1,STONE:0)
Block(-4,-8,2,STONE:0)
Block(-4,-8,3,STONE:0)
Block(-4,-8,4,STONE:0)
Block(-4,-8,5,STONE:0)
Block(-4,-8,6,STONE:0)
Block(-4,-7,-7,STONE:0)
Block(-4,-7,-6,STONE:0)
Block(-4,-7,-5,STONE:0)
Block(-4,-7,-4,STONE:0)
Block(-4,-7,-3,STONE:0)
Block(-4,-7,-2,STONE:0)
Block(-4,-7,-1,STONE:0)
Block(-4,-7,0,STONE:0)
Block(-4,-7,1,STONE:0)
Block(-4,-7,2,STONE:0)
Block(-4,-7,3,STONE:0)
Block(-4,-7,4,STONE:0)
Block(-4,-7,5,STONE:0)
Block(-4,-7,6,STONE:0)
Block(-4,-6,-8,STONE:0)
Block(-4,-6,-7,STONE:0)
Block(-4,-6,-6,STONE:0)
Block(-4,-6,-5,STONE:0)
Block(-4,-6,-4,STONE:0)
Block(-4,-6,-3,STONE:0)
Block(-4,-6,-2,STONE:0)
Block(-4,-6,-1,STONE:0)
Block(-4,-6,0,STONE:0)
Block(-4,-6,1,STONE:0)
Block(-4,-6,2,STONE:0)
Block(-4,-6,3,STONE:0)
Block(-4,-6,4,STONE:0)
Block(-4,-6,5,STONE:0)
Block(-4,-6,6,STONE:0)
Block(-4,-5,-8,STONE:0)
Block(-4,-5,-7,STONE:0)
Block(-4,-5,-6,STONE:0)
Block(-4,-5,-5,STONE:0)
Block(-4,-5,-4,STONE:0)
Block(-4,-5,-3,STONE:0)
Block(-4,-5,-2,STONE:0)
Block(-4,-5,-1,STONE:0)
Block(-4,-5,0,STONE:0)
Block(-4,-5,1,STONE:0)
Block(-4,-5,2,STONE:0)
Block(-4,-5,3,STONE:0)
Block(-4,-5,4,STONE:0)
Block(-4,-5,5,STONE:0)
Block(-4,-5,6,STONE:0)
Block(-4,-4,-9,STONE:0)
Block(-4,-4,-8,STONE:0)
Block(-4,-4,-7,STONE:0)
Block(-4,-4,-6,STONE:0)
Block(-4,-4,-5,STONE:0)
Block(-4,-4,-4,STONE:0)
Block(-4,-4,-3,STONE:0)
Block(-4,-4,-2,STONE:0)
Block(-4,-4,-1,STONE:0)
Block(-4,-4,0,STONE:0)
Block(-4,-4,1,STONE:0)
Block(-4,-4,2,STONE:0)
Block(-4,-4,3,STONE:0)
Block(-4,-4,4,STONE:0)
Block(-4,-4,5,STONE:0)
Block(-4,-4,6,STONE:0)
Block(-4,-3,-9,STONE:0)
Block(-4,-3,-8,STONE:0)
Block(-4,-3,-7,STONE:0)
Block(-4,-3,-6,STONE:0)
Block(-4,-3,-5,STONE:0)
Block(-4,-3,-4,STONE:0)
Block(-4,-3,-3,STONE:0)
Block(-4,-3,-2,STONE:0)
Block(-4,-3,-1,STONE:0)
Block(-4,-3,0,STONE:0)
Block(-4,-3,1,STONE:0)
Block(-4,-3,2,STONE:0)
Block(-4,-3,3,STONE:0)
Block(-4,-3,4,STONE:0)
Block(-4,-3,5,STONE:0)
Block(-4,-3,6,STONE:0)
Block(-4,-2,-10,STONE:0)
Block(-4,-2,-9,STONE:0)
Block(-4,-2,-8,DIRT:0)
Block(-4,-2,-7,STONE:0)
Block(-4,-2,-6,STONE:0)
Block(-4,-2,-5,STONE:0)
Block(-4,-2,-4,STONE:0)
Block(-4,-2,-3,STONE:0)
Block(-4,-2,-2,STONE:0)
Block(-4,-2,-1,STONE:0)
Block(-4,-2,0,STONE:0)
Block(-4,-2,1,STONE:0)
Block(-4,-2,2,STONE:0)
Block(-4,-2,3,STONE:0)
Block(-4,-2,4,STONE:0)
Block(-4,-2,5,STONE:0)
Block(-4,-2,6,STONE:0)
Block(-4,-1,-10,GRASS:0)
Block(-4,-1,-9,DIRT:0)
Block(-4,-1,-8,DIRT:0)
Block(-4,-1,-7,STONE:0)
Block(-4,-1,-6,STONE:0)
Block(-4,-1,-5,STONE:0)
Block(-4,-1,-4,STONE:0)
Block(-4,-1,-3,STONE:0)
Block(-4,-1,-2,STONE:0)
Block(-4,-1,-1,STONE:0)
Block(-4,-1,0,STONE:0)
Block(-4,-1,1,STONE:0)
Block(-4,-1,2,STONE:0)
Block(-4,-1,3,STONE:0)
Block(-4,-1,4,STONE:0)
Block(-4,-1,5,STONE:0)
Block(-4,-1,6,STONE:0)
Block(-4,0,-9,DIRT:0)
Block(-4,0,-8,STONE:0)
Block(-4,0,-7,STONE:0)
Block(-4,0,-6,STONE:0)
Block(-4,0,-5,STONE:0)
Block(-4,0,-4,STONE:0)
Block(-4,0,-3,STONE:0)
Block(-4,0,-2,STONE:0)
Block(-4,0,-1,STONE:0)
Block(-4,0,0,STONE:0)
Block(-4,0,1,STONE:0)
Block(-4,0,2,STONE:0)
Block(-4,0,3,STONE:0)
Block(-4,0,4,STONE:0)
Block(-4,0,5,STONE:0)
Block(-4,0,6,STONE:0)
Block(-4,1,-9,GRASS:0)
Block(-4,1,-8,STONE:0)
Block(-4,1,-7,STONE:0)
Block(-4,1,-6,STONE:0)
Block(-4,1,-5,STONE:0)
Block(-4,1,-4,STONE:0)
Block(-4,1,-3,STONE:0)
Block(-4,1,-2,STONE:0)
Block(-4,1,-1,STONE:0)
Block(-4,1,0,STONE:0)
Block(-4,1,1,STONE:0)
Block(-4,1,2,STONE:0)
Block(-4,1,3,STONE:0)
Block(-4,1,4,STONE:0)
Block(-4,1,5,STONE:0)
Block(-4,1,6,STONE:0)
Block(-4,2,-8,DIRT:0)
Block(-4,2,-7,STONE:0)
Block(-4,2,-6,STONE:0)
Block(-4,2,-5,STONE:0)
Block(-4,2,-4,STONE:0)
Block(-4,2,-3,STONE:0)
Block(-4,2,-2,STONE:0)
Block(-4,2,-1,STONE:0)
Block(-4,2,0,STONE:0)
Block(-4,2,1,STONE:0)
Block(-4,2,2,STONE:0)
Block(-4,2,3,STONE:0)
Block(-4,2,4,STONE:0)
Block(-4,2,5,STONE:0)
Block(-4,2,6,DIRT:0)
Block(-4,3,-8,GRASS:0)
Block(-4,3,-7,STONE:0)
Block(-4,3,-6,STONE:0)
Block(-4,3,-5,STONE:0)
Block(-4,3,-4,STONE:0)
Block(-4,3,-3,STONE:0)
Block(-4,3,-2,STONE:0)
Block(-4,3,-1,STONE:0)
Block(-4,3,0,STONE:0)
Block(-4,3,1,STONE:0)
Block(-4,3,2,STONE:0)
Block(-4,3,3,STONE:0)
Block(-4,3,4,STONE:0)
Block(-4,3,5,STONE:0)
Block(-4,3,6,DIRT:0)
Block(-4,4,-7,GRASS:0)
Block(-4,4,-6,STONE:0)
Block(-4,4,-5,STONE:0)
Block(-4,4,-4,STONE:0)
Block(-4,4,-3,STONE:0)
Block(-4,4,-2,STONE:0)
Block(-4,4,-1,STONE:0)
Block(-4,4,0,STONE:0)
Block(-4,4,1,STONE:0)
Block(-4,4,2,STONE:0)
Block(-4,4,3,STONE:0)
Block(-4,4,4,STONE:0)
Block(-4,4,5,DIRT:0)
Block(-4,4,6,GRASS:0)
Block(-4,5,-6,GRASS:0)
Block(-4,5,-5,STONE:0)
Block(-4,5,-4,STONE:0)
Block(-4,5,-3,STONE:0)
Block(-4,5,-2,STONE:0)
Block(-4,5,-1,STONE:0)
Block(-4,5,0,STONE:0)
Block(-4,5,1,STONE:0)
Block(-4,5,2,STONE:0)
Block(-4,5,3,STONE:0)
Block(-4,5,4,STONE:0)
Block(-4,5,5,GRASS:0)
Block(-4,6,-5,GRASS:0)
Block(-4,6,-4,STONE:0)
Block(-4,6,-3,STONE:0)
Block(-4,6,-2,STONE:0)
Block(-4,6,-1,STONE:0)
Block(-4,6,0,STONE:0)
Block(-4,6,1,STONE:0)
Block(-4,6,2,STONE:0)
Block(-4,6,3,STONE:0)
Block(-4,6,4,GRASS:0)
Block(-4,7,-4,GRASS:0)
Block(-4,7,-3,STONE:0)
Block(-4,7,-2,STONE:0)
Block(-4,7,-1,STONE:0)
Block(-4,7,0,STONE:0)
Block(-4,7,1,STONE:0)
Block(-4,7,2,STONE:0)
Block(-4,7,3,GRASS:0)
Block(-4,8,-3,GRASS:0)
Block(-4,8,-2,GRASS:0)
Block(-4,8,-1,GRASS:0)
Block(-4,8,0,GRASS:0)
Block(-4,8,1,GRASS:0)
Block(-4,8,2,GRASS:0)
Block(-3,-11,1,STONE:0)
Block(-3,-11,2,STONE:0)
Block(-3,-10,-1,STONE:0)
Block(-3,-10,0,STONE:0)
Block(-3,-10,1,STONE:0)
Block(-3,-10,2,STONE:0)
Block(-3,-10,3,STONE:0)
Block(-3,-10,4,STONE:0)
Block(-3,-9,-4,STONE:0)
Block(-3,-9,-3,STONE:0)
Block(-3,-9,-2,STONE:0)
Block(-3,-9,-1,STONE:0)
Block(-3,-9,0,STONE:0)
Block(-3,-9,1,STONE:0)
Block(-3,-9,2,STONE:0)
Block(-3,-9,3,STONE:0)
Block(-3,-9,4,STONE:0)
Block(-3,-9,5,STONE:0)
Block(-3,-8,-6,STONE:0)
Block(-3,-8,-5,STONE:0)
Block(-3,-8,-4,STONE:0)
Block(-3,-8,-3,STONE:0)
Block(-3,-8,-2,STONE:0)
Block(-3,-8,-1,STONE:0)
Block(-3,-8,0,STONE:0)
Block(-3,-8,1,STONE:0)
Block(-3,-8,2,STONE:0)
Block(-3,-8,3,STONE:0)
Block(-3,-8,4,STONE:0)
Block(-3,-8,5,STONE:0)
Block(-3,-8,6,STONE:0)
Block(-3,-7,-7,STONE:0)
Block(-3,-7,-6,STONE:0)
Block(-3,-7,-5,STONE:0)
Block(-3,-7,-4,STONE:0)
Block(-3,-7,-3,STONE:0)
Block(-3,-7,-2,STONE:0)
Block(-3,-7,-1,STONE:0)
Block(-3,-7,0,STONE:0)
Block(-3,-7,1,STONE:0)
Block(-3,-7,2,STONE:0)
Block(-3,-7,3,STONE:0)
Block(-3,-7,4,STONE:0)
Block(-3,-7,5,STONE:0)
Block(-3,-7,6,STONE:0)
Block(-3,-6,-9,STONE:0)
Block(-3,-6,-8,STONE:0)
Block(-3,-6,-7,STONE:0)
Block(-3,-6,-6,STONE:0)
Block(-3,-6,-5,STONE:0)
Block(-3,-6,-4,STONE:0)
Block(-3,-6,-3,STONE:0)
Block(-3,-6,-2,STONE:0)
Block(-3,-6,-1,STONE:0)
Block(-3,-6,0,STONE:0)
Block(-3,-6,1,STONE:0)
Block(-3,-6,2,STONE:0)
Block(-3,-6,3,STONE:0)
Block(-3,-6,4,STONE:0)
Block(-3,-6,5,STONE:0)
Block(-3,-6,6,STONE:0)
Block(-3,-6,7,STONE:0)
Block(-3,-5,-9,STONE:0)
Block(-3,-5,-8,STONE:0)
Block(-3,-5,-7,STONE:0)
Block(-3,-5,-6,STONE:0)
Block(-3,-5,-5,STONE:0)
Block(-3,-5,-4,STONE:0)
Block(-3,-5,-3,STONE:0)
Block(-3,-5,-2,STONE:0)
Block(-3,-5,-1,STONE:0)
Block(-3,-5,0,STONE:0)
Block(-3,-5,1,STONE:0)
Block(-3,-5,2,STONE:0)
Block(-3,-5,3,STONE:0)
Block(-3,-5,4,STONE:0)
Block(-3,-5,5,STONE:0)
Block(-3,-5,6,STONE:0)
Block(-3,-5,7,STONE:0)
Block(-3,-4,-10,STONE:0)
Block(-3,-4,-9,STONE:0)
Block(-3,-4,-8,STONE:0)
Block(-3,-4,-7,STONE:0)
Block(-3,-4,-6,STONE:0)
Block(-3,-4,-5,STONE:0)
Block(-3,-4,-4,STONE:0)
Block(-3,-4,-3,STONE:0)
Block(-3,-4,-2,STONE:0)
Block(-3,-4,-1,STONE:0)
Block(-3,-4,0,STONE:0)
Block(-3,-4,1,STONE:0)
Block(-3,-4,2,STONE:0)
Block(-3,-4,3,STONE:0)
Block(-3,-4,4,STONE:0)
Block(-3,-4,5,STONE:0)
Block(-3,-4,6,STONE:0)
Block(-3,-4,7,STONE:0)
Block(-3,-3,-10,STONE:0)
Block(-3,-3,-9,STONE:0)
Block(-3,-3,-8,STONE:0)
Block(-3,-3,-7,STONE:0)
Block(-3,-3,-6,STONE:0)
Block(-3,-3,-5,STONE:0)
Block(-3,-3,-4,STONE:0)
Block(-3,-3,-3,STONE:0)
Block(-3,-3,-2,STONE:0)
Block(-3,-3,-1,STONE:0)
Block(-3,-3,0,STONE:0)
Block(-3,-3,1,STONE:0)
Block(-3,-3,2,STONE:0)
Block(-3,-3,3,STONE:0)
Block(-3,-3,4,STONE:0)
Block(-3,-3,5,STONE:0)
Block(-3,-3,6,STONE:0)
Block(-3,-3,7,STONE:0)
Block(-3,-2,-11,STONE:0)
Block(-3,-2,-10,STONE:0)
Block(-3,-2,-9,STONE:0)
Block(-3,-2,-8,STONE:0)
Block(-3,-2,-7,STONE:0)
Block(-3,-2,-6,STONE:0)
Block(-3,-2,-5,STONE:0)
Block(-3,-2,-4,STONE:0)
Block(-3,-2,-3,STONE:0)
Block(-3,-2,-2,STONE:0)
Block(-3,-2,-1,STONE:0)
Block(-3,-2,0,STONE:0)
Block(-3,-2,1,STONE:0)
Block(-3,-2,2,STONE:0)
Block(-3,-2,3,STONE:0)
Block(-3,-2,4,STONE:0)
Block(-3,-2,5,STONE:0)
Block(-3,-2,6,STONE:0)
Block(-3,-2,7,STONE:0)
Block(-3,-1,-11,STONE:0)
Block(-3,-1,-10,STONE:0)
Block(-3,-1,-9,STONE:0)
Block(-3,-1,-8,STONE:0)
Block(-3,-1,-7,STONE:0)
Block(-3,-1,-6,STONE:0)
Block(-3,-1,-5,STONE:0)
Block(-3,-1,-4,STONE:0)
Block(-3,-1,-3,STONE:0)
Block(-3,-1,-2,STONE:0)
Block(-3,-1,-1,STONE:0)
Block(-3,-1,0,STONE:0)
Block(-3,-1,1,STONE:0)
Block(-3,-1,2,STONE:0)
Block(-3,-1,3,STONE:0)
Block(-3,-1,4,STONE:0)
Block(-3,-1,5,STONE:0)
Block(-3,-1,6,STONE:0)
Block(-3,-1,7,STONE:0)
Block(-3,0,-10,DIRT:0)
Block(-3,0,-9,STONE:0)
Block(-3,0,-8,STONE:0)
Block(-3,0,-7,STONE:0)
Block(-3,0,-6,STONE:0)
Block(-3,0,-5,STONE:0)
Block(-3,0,-4,STONE:0)
Block(-3,0,-3,STONE:0)
Block(-3,0,-2,STONE:0)
Block(-3,0,-1,STONE:0)
Block(-3,0,0,STONE:0)
Block(-3,0,1,STONE:0)
Block(-3,0,2,STONE:0)
Block(-3,0,3,STONE:0)
Block(-3,0,4,STONE:0)
Block(-3,0,5,STONE:0)
Block(-3,0,6,STONE:0)
Block(-3,0,7,STONE:0)
Block(-3,1,-10,GRASS:0)
Block(-3,1,-9,STONE:0)
Block(-3,1,-8,STONE:0)
Block(-3,1,-7,STONE:0)
Block(-3,1,-6,STONE:0)
Block(-3,1,-5,STONE:0)
Block(-3,1,-4,STONE:0)
Block(-3,1,-3,STONE:0)
Block(-3,1,-2,STONE:0)
Block(-3,1,-1,STONE:0)
Block(-3,1,0,STONE:0)
Block(-3,1,1,STONE:0)
Block(-3,1,2,STONE:0)
Block(-3,1,3,STONE:0)
Block(-3,1,4,STONE:0)
Block(-3,1,5,STONE:0)
Block(-3,1,6,STONE:0)
Block(-3,1,7,STONE:0)
Block(-3,2,-9,GRASS:0)
Block(-3,2,-8,STONE:0)
Block(-3,2,-7,STONE:0)
Block(-3,2,-6,STONE:0)
Block(-3,2,-5,STONE:0)
Block(-3,2,-4,STONE:0)
Block(-3,2,-3,STONE:0)
Block(-3,2,-2,STONE:0)
Block(-3,2,-1,STONE:0)
Block(-3,2,0,STONE:0)
Block(-3,2,1,STONE:0)
Block(-3,2,2,STONE:0)
Block(-3,2,3,STONE:0)
Block(-3,2,4,STONE:0)
Block(-3,2,5,STONE:0)
Block(-3,2,6,STONE:0)
Block(-3,2,7,STONE:0)
Block(-3,3,-8,GRASS:0)
Block(-3,3,-7,STONE:0)
Block(-3,3,-6,STONE:0)
Block(-3,3,-5,STONE:0)
Block(-3,3,-4,STONE:0)
Block(-3,3,-3,STONE:0)
Block(-3,3,-2,STONE:0)
Block(-3,3,-1,STONE:0)
Block(-3,3,0,STONE:0)
Block(-3,3,1,STONE:0)
Block(-3,3,2,STONE:0)
Block(-3,3,3,STONE:0)
Block(-3,3,4,STONE:0)
Block(-3,3,5,STONE:0)
Block(-3,3,6,STONE:0)
Block(-3,3,7,DIRT:0)
Block(-3,4,-7,GRASS:0)
Block(-3,4,-6,STONE:0)
Block(-3,4,-5,STONE:0)
Block(-3,4,-4,STONE:0)
Block(-3,4,-3,STONE:0)
Block(-3,4,-2,STONE:0)
Block(-3,4,-1,STONE:0)
Block(-3,4,0,STONE:0)
Block(-3,4,1,STONE:0)
Block(-3,4,2,STONE:0)
Block(-3,4,3,STONE:0)
Block(-3,4,4,STONE:0)
Block(-3,4,5,STONE:0)
Block(-3,4,6,STONE:0)
Block(-3,4,7,GRASS:0)
Block(-3,5,-6,GRASS:0)
Block(-3,5,-5,STONE:0)
Block(-3,5,-4,STONE:0)
Block(-3,5,-3,STONE:0)
Block(-3,5,-2,STONE:0)
Block(-3,5,-1,STONE:0)
Block(-3,5,0,STONE:0)
Block(-3,5,1,STONE:0)
Block(-3,5,2,STONE:0)
Block(-3,5,3,STONE:0)
Block(-3,5,4,STONE:0)
Block(-3,5,5,STONE:0)
Block(-3,5,6,GRASS:0)
Block(-3,6,-5,GRASS:0)
Block(-3,6,-4,STONE:0)
Block(-3,6,-3,STONE:0)
Block(-3,6,-2,STONE:0)
Block(-3,6,-1,STONE:0)
Block(-3,6,0,STONE:0)
Block(-3,6,1,STONE:0)
Block(-3,6,2,STONE:0)
Block(-3,6,3,STONE:0)
Block(-3,6,4,GRASS:0)
Block(-3,6,5,GRASS:0)
Block(-3,7,-4,GRASS:0)
Block(-3,7,-3,STONE:0)
Block(-3,7,-2,STONE:0)
Block(-3,7,-1,STONE:0)
Block(-3,7,0,STONE:0)
Block(-3,7,1,STONE:0)
Block(-3,7,2,STONE:0)
Block(-3,7,3,GRASS:0)
Block(-3,8,-3,GRASS:0)
Block(-3,8,-2,STONE:0)
Block(-3,8,-1,STONE:0)
Block(-3,8,0,GRASS:0)
Block(-3,8,1,GRASS:0)
Block(-3,8,2,GRASS:0)
Block(-3,9,-2,GRASS:0)
Block(-3,9,-1,GRASS:0)
Block(-2,-11,0,STONE:0)
Block(-2,-11,1,STONE:0)
Block(-2,-11,2,STONE:0)
Block(-2,-10,-2,STONE:0)
Block(-2,-10,-1,STONE:0)
Block(-2,-10,0,STONE:0)
Block(-2,-10,1,STONE:0)
Block(-2,-10,2,STONE:0)
Block(-2,-10,3,STONE:0)
Block(-2,-9,-4,STONE:0)
Block(-2,-9,-3,STONE:0)
Block(-2,-9,-2,STONE:0)
Block(-2,-9,-1,STONE:0)
Block(-2,-9,0,STONE:0)
Block(-2,-9,1,STONE:0)
Block(-2,-9,2,STONE:0)
Block(-2,-9,3,STONE:0)
Block(-2,-9,4,STONE:0)
Block(-2,-8,-6,STONE:0)
Block(-2,-8,-5,STONE:0)
Block(-2,-8,-4,STONE:0)
Block(-2,-8,-3,STONE:0)
Block(-2,-8,-2,STONE:0)
Block(-2,-8,-1,STONE:0)
Block(-2,-8,0,STONE:0)
Block(-2,-8,1,STONE:0)
Block(-2,-8,2,STONE:0)
Block(-2,-8,3,STONE:0)
Block(-2,-8,4,STONE:0)
Block(-2,-8,5,STONE:0)
Block(-2,-7,-8,STONE:0)
Block(-2,-7,-7,STONE:0)
Block(-2,-7,-6,STONE:0)
Block(-2,-7,-5,STONE:0)
Block(-2,-7,-4,STONE:0)
Block(-2,-7,-3,STONE:0)
Block(-2,-7,-2,STONE:0)
Block(-2,-7,-1,STONE:0)
Block(-2,-7,0,STONE:0)
Block(-2,-7,1,STONE:0)
Block(-2,-7,2,STONE:0)
Block(-2,-7,3,STONE:0)
Block(-2,-7,4,STONE:0)
Block(-2,-7,5,STONE:0)
Block(-2,-7,6,STONE:0)
Block(-2,-6,-9,STONE:0)
Block(-2,-6,-8,STONE:0)
Block(-2,-6,-7,STONE:0)
Block(-2,-6,-6,STONE:0)
Block(-2,-6,-5,STONE:0)
Block(-2,-6,-4,STONE:0)
Block(-2,-6,-3,STONE:0)
Block(-2,-6,-2,STONE:0)
Block(-2,-6,-1,STONE:0)
Block(-2,-6,0,STONE:0)
Block(-2,-6,1,STONE:0)
Block(-2,-6,2,STONE:0)
Block(-2,-6,3,STONE:0)
Block(-2,-6,4,STONE:0)
Block(-2,-6,5,STONE:0)
Block(-2,-6,6,STONE:0)
Block(-2,-6,7,STONE:0)
Block(-2,-5,-10,STONE:0)
Block(-2,-5,-9,STONE:0)
Block(-2,-5,-8,STONE:0)
Block(-2,-5,-7,STONE:0)
Block(-2,-5,-6,STONE:0)
Block(-2,-5,-5,STONE:0)
Block(-2,-5,-4,STONE:0)
Block(-2,-5,-3,STONE:0)
Block(-2,-5,-2,STONE:0)
Block(-2,-5,-1,STONE:0)
Block(-2,-5,0,STONE:0)
Block(-2,-5,1,STONE:0)
Block(-2,-5,2,STONE:0)
Block(-2,-5,3,STONE:0)
Block(-2,-5,4,STONE:0)
Block(-2,-5,5,STONE:0)
Block(-2,-5,6,STONE:0)
Block(-2,-5,7,STONE:0)
Block(-2,-5,8,STONE:0)
Block(-2,-4,-11,STONE:0)
Block(-2,-4,-10,STONE:0)
Block(-2,-4,-9,STONE:0)
Block(-2,-4,-8,STONE:0)
Block(-2,-4,-7,STONE:0)
Block(-2,-4,-6,STONE:0)
Block(-2,-4,-5,STONE:0)
Block(-2,-4,-4,STONE:0)
Block(-2,-4,-3,STONE:0)
Block(-2,-4,-2,STONE:0)
Block(-2,-4,-1,STONE:0)
Block(-2,-4,0,STONE:0)
Block(-2,-4,1,STONE:0)
Block(-2,-4,2,STONE:0)
Block(-2,-4,3,STONE:0)
Block(-2,-4,4,STONE:0)
Block(-2,-4,5,STONE:0)
Block(-2,-4,6,STONE:0)
Block(-2,-4,7,STONE:0)
Block(-2,-4,8,STONE:0)
Block(-2,-3,-11,STONE:0)
Block(-2,-3,-10,STONE:0)
Block(-2,-3,-9,STONE:0)
Block(-2,-3,-8,STONE:0)
Block(-2,-3,-7,STONE:0)
Block(-2,-3,-6,STONE:0)
Block(-2,-3,-5,STONE:0)
Block(-2,-3,-4,STONE:0)
Block(-2,-3,-3,STONE:0)
Block(-2,-3,-2,STONE:0)
Block(-2,-3,-1,STONE:0)
Block(-2,-3,0,STONE:0)
Block(-2,-3,1,STONE:0)
Block(-2,-3,2,STONE:0)
Block(-2,-3,3,STONE:0)
Block(-2,-3,4,STONE:0)
Block(-2,-3,5,STONE:0)
Block(-2,-3,6,STONE:0)
Block(-2,-3,7,STONE:0)
Block(-2,-3,8,STONE:0)
Block(-2,-2,-11,STONE:0)
Block(-2,-2,-10,STONE:0)
Block(-2,-2,-9,STONE:0)
Block(-2,-2,-8,STONE:0)
Block(-2,-2,-7,STONE:0)
Block(-2,-2,-6,STONE:0)
Block(-2,-2,-5,STONE:0)
Block(-2,-2,-4,STONE:0)
Block(-2,-2,-3,STONE:0)
Block(-2,-2,-2,STONE:0)
Block(-2,-2,-1,STONE:0)
Block(-2,-2,0,STONE:0)
Block(-2,-2,1,STONE:0)
Block(-2,-2,2,STONE:0)
Block(-2,-2,3,STONE:0)
Block(-2,-2,4,STONE:0)
Block(-2,-2,5,STONE:0)
Block(-2,-2,6,STONE:0)
Block(-2,-2,7,STONE:0)
Block(-2,-2,8,STONE:0)
Block(-2,-1,-11,DIRT:0)
Block(-2,-1,-10,STONE:0)
Block(-2,-1,-9,STONE:0)
Block(-2,-1,-8,STONE:0)
Block(-2,-1,-7,STONE:0)
Block(-2,-1,-6,STONE:0)
Block(-2,-1,-5,STONE:0)
Block(-2,-1,-4,STONE:0)
Block(-2,-1,-3,STONE:0)
Block(-2,-1,-2,STONE:0)
Block(-2,-1,-1,STONE:0)
Block(-2,-1,0,STONE:0)
Block(-2,-1,1,STONE:0)
Block(-2,-1,2,STONE:0)
Block(-2,-1,3,STONE:0)
Block(-2,-1,4,STONE:0)
Block(-2,-1,5,STONE:0)
Block(-2,-1,6,STONE:0)
Block(-2,-1,7,STONE:0)
Block(-2,-1,8,STONE:0)
Block(-2,0,-11,GRASS:0)
Block(-2,0,-10,STONE:0)
Block(-2,0,-9,STONE:0)
Block(-2,0,-8,STONE:0)
Block(-2,0,-7,STONE:0)
Block(-2,0,-6,STONE:0)
Block(-2,0,-5,STONE:0)
Block(-2,0,-4,STONE:0)
Block(-2,0,-3,STONE:0)
Block(-2,0,-2,STONE:0)
Block(-2,0,-1,STONE:0)
Block(-2,0,0,STONE:0)
Block(-2,0,1,STONE:0)
Block(-2,0,2,STONE:0)
Block(-2,0,3,STONE:0)
Block(-2,0,4,STONE:0)
Block(-2,0,5,STONE:0)
Block(-2,0,6,STONE:0)
Block(-2,0,7,STONE:0)
Block(-2,0,8,STONE:0)
Block(-2,1,-10,GRASS:0)
Block(-2,1,-9,STONE:0)
Block(-2,1,-8,STONE:0)
Block(-2,1,-7,STONE:0)
Block(-2,1,-6,STONE:0)
Block(-2,1,-5,STONE:0)
Block(-2,1,-4,STONE:0)
Block(-2,1,-3,STONE:0)
Block(-2,1,-2,STONE:0)
Block(-2,1,-1,STONE:0)
Block(-2,1,0,STONE:0)
Block(-2,1,1,STONE:0)
Block(-2,1,2,STONE:0)
Block(-2,1,3,STONE:0)
Block(-2,1,4,STONE:0)
Block(-2,1,5,STONE:0)
Block(-2,1,6,STONE:0)
Block(-2,1,7,STONE:0)
Block(-2,1,8,DIRT:0)
Block(-2,2,-9,GRASS:0)
Block(-2,2,-8,STONE:0)
Block(-2,2,-7,STONE:0)
Block(-2,2,-6,STONE:0)
Block(-2,2,-5,STONE:0)
Block(-2,2,-4,STONE:0)
Block(-2,2,-3,STONE:0)
Block(-2,2,-2,STONE:0)
Block(-2,2,-1,STONE:0)
Block(-2,2,0,STONE:0)
Block(-2,2,1,STONE:0)
Block(-2,2,2,STONE:0)
Block(-2,2,3,STONE:0)
Block(-2,2,4,STONE:0)
Block(-2,2,5,STONE:0)
Block(-2,2,6,STONE:0)
Block(-2,2,7,STONE:0)
Block(-2,2,8,DIRT:0)
Block(-2,3,-8,GRASS:0)
Block(-2,3,-7,STONE:0)
Block(-2,3,-6,STONE:0)
Block(-2,3,-5,STONE:0)
Block(-2,3,-4,STONE:0)
Block(-2,3,-3,STONE:0)
Block(-2,3,-2,STONE:0)
Block(-2,3,-1,STONE:0)
Block(-2,3,0,STONE:0)
Block(-2,3,1,STONE:0)
Block(-2,3,2,STONE:0)
Block(-2,3,3,STONE:0)
Block(-2,3,4,STONE:0)
Block(-2,3,5,STONE:0)
Block(-2,3,6,STONE:0)
Block(-2,3,7,STONE:0)
Block(-2,3,8,GRASS:0)
Block(-2,4,-7,GRASS:0)
Block(-2,4,-6,STONE:0)
Block(-2,4,-5,STONE:0)
Block(-2,4,-4,STONE:0)
Block(-2,4,-3,STONE:0)
Block(-2,4,-2,STONE:0)
Block(-2,4,-1,STONE:0)
Block(-2,4,0,STONE:0)
Block(-2,4,1,STONE:0)
Block(-2,4,2,STONE:0)
Block(-2,4,3,STONE:0)
Block(-2,4,4,STONE:0)
Block(-2,4,5,STONE:0)
Block(-2,4,6,STONE:0)
Block(-2,4,7,GRASS:0)
Block(-2,5,-6,GRASS:0)
Block(-2,5,-5,STONE:0)
Block(-2,5,-4,STONE:0)
Block(-2,5,-3,STONE:0)
Block(-2,5,-2,STONE:0)
Block(-2,5,-1,STONE:0)
Block(-2,5,0,STONE:0)
Block(-2,5,1,STONE:0)
Block(-2,5,2,STONE:0)
Block(-2,5,3,STONE:0)
Block(-2,5,4,STONE:0)
Block(-2,5,5,STONE:0)
Block(-2,5,6,GRASS:0)
Block(-2,6,-5,GRASS:0)
Block(-2,6,-4,STONE:0)
Block(-2,6,-3,STONE:0)
Block(-2,6,-2,STONE:0)
Block(-2,6,-1,STONE:0)
Block(-2,6,0,STONE:0)
Block(-2,6,1,STONE:0)
Block(-2,6,2,STONE:0)
Block(-2,6,3,STONE:0)
Block(-2,6,4,GRASS:0)
Block(-2,6,5,GRASS:0)
Block(-2,7,-4,GRASS:0)
Block(-2,7,-3,STONE:0)
Block(-2,7,-2,STONE:0)
Block(-2,7,-1,STONE:0)
Block(-2,7,0,STONE:0)
Block(-2,7,1,STONE:0)
Block(-2,7,2,STONE:0)
Block(-2,7,3,GRASS:0)
Block(-2,8,-3,GRASS:0)
Block(-2,8,-2,STONE:0)
Block(-2,8,-1,STONE:0)
Block(-2,8,0,GRASS:0)
Block(-2,8,1,GRASS:0)
Block(-2,8,2,GRASS:0)
Block(-2,9,-2,GRASS:0)
Block(-2,9,-1,GRASS:0)
Block(-1,-11,0,STONE:0)
Block(-1,-11,1,STONE:0)
Block(-1,-11,2,STONE:0)
Block(-1,-10,-2,STONE:0)
Block(-1,-10,-1,STONE:0)
Block(-1,-10,0,STONE:0)
Block(-1,-10,1,STONE:0)
Block(-1,-10,2,STONE:0)
Block(-1,-10,3,STONE:0)
Block(-1,-9,-4,STONE:0)
Block(-1,-9,-3,STONE:0)
Block(-1,-9,-2,STONE:0)
Block(-1,-9,-1,STONE:0)
Block(-1,-9,0,STONE:0)
Block(-1,-9,1,STONE:0)
Block(-1,-9,2,STONE:0)
Block(-1,-9,3,STONE:0)
Block(-1,-9,4,STONE:0)
Block(-1,-8,-6,STONE:0)
Block(-1,-8,-5,STONE:0)
Block(-1,-8,-4,STONE:0)
Block(-1,-8,-3,STONE:0)
Block(-1,-8,-2,STONE:0)
Block(-1,-8,-1,STONE:0)
Block(-1,-8,0,STONE:0)
Block(-1,-8,1,STONE:0)
Block(-1,-8,2,STONE:0)
Block(-1,-8,3,STONE:0)
Block(-1,-8,4,STONE:0)
Block(-1,-8,5,STONE:0)
Block(-1,-7,-8,STONE:0)
Block(-1,-7,-7,STONE:0)
Block(-1,-7,-6,STONE:0)
Block(-1,-7,-5,STONE:0)
Block(-1,-7,-4,STONE:0)
Block(-1,-7,-3,STONE:0)
Block(-1,-7,-2,STONE:0)
Block(-1,-7,-1,STONE:0)
Block(-1,-7,0,STONE:0)
Block(-1,-7,1,STONE:0)
Block(-1,-7,2,STONE:0)
Block(-1,-7,3,STONE:0)
Block(-1,-7,4,STONE:0)
Block(-1,-7,5,STONE:0)
Block(-1,-7,6,STONE:0)
Block(-1,-6,-9,STONE:0)
Block(-1,-6,-8,STONE:0)
Block(-1,-6,-7,STONE:0)
Block(-1,-6,-6,STONE:0)
Block(-1,-6,-5,STONE:0)
Block(-1,-6,-4,STONE:0)
Block(-1,-6,-3,STONE:0)
Block(-1,-6,-2,STONE:0)
Block(-1,-6,-1,STONE:0)
Block(-1,-6,0,STONE:0)
Block(-1,-6,1,STONE:0)
Block(-1,-6,2,STONE:0)
Block(-1,-6,3,STONE:0)
Block(-1,-6,4,STONE:0)
Block(-1,-6,5,STONE:0)
Block(-1,-6,6,STONE:0)
Block(-1,-6,7,STONE:0)
Block(-1,-5,-10,STONE:0)
Block(-1,-5,-9,STONE:0)
Block(-1,-5,-8,STONE:0)
Block(-1,-5,-7,STONE:0)
Block(-1,-5,-6,STONE:0)
Block(-1,-5,-5,STONE:0)
Block(-1,-5,-4,STONE:0)
Block(-1,-5,-3,STONE:0)
Block(-1,-5,-2,STONE:0)
Block(-1,-5,-1,STONE:0)
Block(-1,-5,0,STONE:0)
Block(-1,-5,1,STONE:0)
Block(-1,-5,2,STONE:0)
Block(-1,-5,3,STONE:0)
Block(-1,-5,4,STONE:0)
Block(-1,-5,5,STONE:0)
Block(-1,-5,6,STONE:0)
Block(-1,-5,7,STONE:0)
Block(-1,-5,8,STONE:0)
Block(-1,-4,-11,STONE:0)
Block(-1,-4,-10,STONE:0)
Block(-1,-4,-9,STONE:0)
Block(-1,-4,-8,STONE:0)
Block(-1,-4,-7,STONE:0)
Block(-1,-4,-6,STONE:0)
Block(-1,-4,-5,STONE:0)
Block(-1,-4,-4,STONE:0)
Block(-1,-4,-3,STONE:0)
Block(-1,-4,-2,STONE:0)
Block(-1,-4,-1,STONE:0)
Block(-1,-4,0,STONE:0)
Block(-1,-4,1,STONE:0)
Block(-1,-4,2,STONE:0)
Block(-1,-4,3,STONE:0)
Block(-1,-4,4,STONE:0)
Block(-1,-4,5,STONE:0)
Block(-1,-4,6,STONE:0)
Block(-1,-4,7,STONE:0)
Block(-1,-4,8,STONE:0)
Block(-1,-4,9,STONE:0)
Block(-1,-3,-11,STONE:0)
Block(-1,-3,-10,STONE:0)
Block(-1,-3,-9,STONE:0)
Block(-1,-3,-8,STONE:0)
Block(-1,-3,-7,STONE:0)
Block(-1,-3,-6,STONE:0)
Block(-1,-3,-5,STONE:0)
Block(-1,-3,-4,STONE:0)
Block(-1,-3,-3,STONE:0)
Block(-1,-3,-2,STONE:0)
Block(-1,-3,-1,STONE:0)
Block(-1,-3,0,STONE:0)
Block(-1,-3,1,STONE:0)
Block(-1,-3,2,STONE:0)
Block(-1,-3,3,STONE:0)
Block(-1,-3,4,STONE:0)
Block(-1,-3,5,STONE:0)
Block(-1,-3,6,STONE:0)
Block(-1,-3,7,STONE:0)
Block(-1,-3,8,STONE:0)
Block(-1,-3,9,STONE:0)
Block(-1,-2,-11,STONE:0)
Block(-1,-2,-10,STONE:0)
Block(-1,-2,-9,STONE:0)
Block(-1,-2,-8,STONE:0)
Block(-1,-2,-7,STONE:0)
Block(-1,-2,-6,STONE:0)
Block(-1,-2,-5,STONE:0)
Block(-1,-2,-4,STONE:0)
Block(-1,-2,-3,STONE:0)
Block(-1,-2,-2,STONE:0)
Block(-1,-2,-1,STONE:0)
Block(-1,-2,0,STONE:0)
Block(-1,-2,1,STONE:0)
Block(-1,-2,2,STONE:0)
Block(-1,-2,3,STONE:0)
Block(-1,-2,4,STONE:0)
Block(-1,-2,5,STONE:0)
Block(-1,-2,6,STONE:0)
Block(-1,-2,7,STONE:0)
Block(-1,-2,8,STONE:0)
Block(-1,-2,9,STONE:0)
Block(-1,-1,-11,DIRT:0)
Block(-1,-1,-10,STONE:0)
Block(-1,-1,-9,STONE:0)
Block(-1,-1,-8,STONE:0)
Block(-1,-1,-7,STONE:0)
Block(-1,-1,-6,STONE:0)
Block(-1,-1,-5,STONE:0)
Block(-1,-1,-4,STONE:0)
Block(-1,-1,-3,STONE:0)
Block(-1,-1,-2,STONE:0)
Block(-1,-1,-1,STONE:0)
Block(-1,-1,0,STONE:0)
Block(-1,-1,1,STONE:0)
Block(-1,-1,2,STONE:0)
Block(-1,-1,3,STONE:0)
Block(-1,-1,4,STONE:0)
Block(-1,-1,5,STONE:0)
Block(-1,-1,6,STONE:0)
Block(-1,-1,7,STONE:0)
Block(-1,-1,8,STONE:0)
Block(-1,-1,9,STONE:0)
Block(-1,0,-11,GRASS:0)
Block(-1,0,-10,STONE:0)
Block(-1,0,-9,STONE:0)
Block(-1,0,-8,STONE:0)
Block(-1,0,-7,STONE:0)
Block(-1,0,-6,STONE:0)
Block(-1,0,-5,STONE:0)
Block(-1,0,-4,STONE:0)
Block(-1,0,-3,STONE:0)
Block(-1,0,-2,STONE:0)
Block(-1,0,-1,STONE:0)
Block(-1,0,0,STONE:0)
Block(-1,0,1,STONE:0)
Block(-1,0,2,STONE:0)
Block(-1,0,3,STONE:0)
Block(-1,0,4,STONE:0)
Block(-1,0,5,STONE:0)
Block(-1,0,6,STONE:0)
Block(-1,0,7,STONE:0)
Block(-1,0,8,STONE:0)
Block(-1,0,9,STONE:0)
Block(-1,1,-10,DIRT:0)
Block(-1,1,-9,STONE:0)
Block(-1,1,-8,STONE:0)
Block(-1,1,-7,STONE:0)
Block(-1,1,-6,STONE:0)
Block(-1,1,-5,STONE:0)
Block(-1,1,-4,STONE:0)
Block(-1,1,-3,STONE:0)
Block(-1,1,-2,STONE:0)
Block(-1,1,-1,STONE:0)
Block(-1,1,0,STONE:0)
Block(-1,1,1,STONE:0)
Block(-1,1,2,STONE:0)
Block(-1,1,3,STONE:0)
Block(-1,1,4,STONE:0)
Block(-1,1,5,STONE:0)
Block(-1,1,6,STONE:0)
Block(-1,1,7,STONE:0)
Block(-1,1,8,STONE:0)
Block(-1,1,9,DIRT:0)
Block(-1,2,-10,GRASS:0)
Block(-1,2,-9,GRASS:0)
Block(-1,2,-8,STONE:0)
Block(-1,2,-7,STONE:0)
Block(-1,2,-6,STONE:0)
Block(-1,2,-5,STONE:0)
Block(-1,2,-4,STONE:0)
Block(-1,2,-3,STONE:0)
Block(-1,2,-2,STONE:0)
Block(-1,2,-1,STONE:0)
Block(-1,2,0,STONE:0)
Block(-1,2,1,STONE:0)
Block(-1,2,2,STONE:0)
Block(-1,2,3,STONE:0)
Block(-1,2,4,STONE:0)
Block(-1,2,5,STONE:0)
Block(-1,2,6,STONE:0)
Block(-1,2,7,STONE:0)
Block(-1,2,8,STONE:0)
Block(-1,2,9,GRASS:0)
Block(-1,3,-8,GRASS:0)
Block(-1,3,-7,STONE:0)
Block(-1,3,-6,STONE:0)
Block(-1,3,-5,STONE:0)
Block(-1,3,-4,STONE:0)
Block(-1,3,-3,STONE:0)
Block(-1,3,-2,STONE:0)
Block(-1,3,-1,STONE:0)
Block(-1,3,0,STONE:0)
Block(-1,3,1,STONE:0)
Block(-1,3,2,STONE:0)
Block(-1,3,3,STONE:0)
Block(-1,3,4,STONE:0)
Block(-1,3,5,STONE:0)
Block(-1,3,6,STONE:0)
Block(-1,3,7,STONE:0)
Block(-1,3,8,DIRT:0)
Block(-1,4,-7,GRASS:0)
Block(-1,4,-6,STONE:0)
Block(-1,4,-5,STONE:0)
Block(-1,4,-4,STONE:0)
Block(-1,4,-3,STONE:0)
Block(-1,4,-2,STONE:0)
Block(-1,4,-1,STONE:0)
Block(-1,4,0,STONE:0)
Block(-1,4,1,STONE:0)
Block(-1,4,2,STONE:0)
Block(-1,4,3,STONE:0)
Block(-1,4,4,STONE:0)
Block(-1,4,5,STONE:0)
Block(-1,4,6,STONE:0)
Block(-1,4,7,STONE:0)
Block(-1,4,8,GRASS:0)
Block(-1,5,-6,GRASS:0)
Block(-1,5,-5,STONE:0)
Block(-1,5,-4,STONE:0)
Block(-1,5,-3,STONE:0)
Block(-1,5,-2,STONE:0)
Block(-1,5,-1,STONE:0)
Block(-1,5,0,STONE:0)
Block(-1,5,1,STONE:0)
Block(-1,5,2,STONE:0)
Block(-1,5,3,STONE:0)
Block(-1,5,4,STONE:0)
Block(-1,5,5,STONE:0)
Block(-1,5,6,GRASS:0)
Block(-1,5,7,GRASS:0)
Block(-1,6,-5,GRASS:0)
Block(-1,6,-4,STONE:0)
Block(-1,6,-3,STONE:0)
Block(-1,6,-2,STONE:0)
Block(-1,6,-1,STONE:0)
Block(-1,6,0,STONE:0)
Block(-1,6,1,STONE:0)
Block(-1,6,2,STONE:0)
Block(-1,6,3,STONE:0)
Block(-1,6,4,GRASS:0)
Block(-1,6,5,GRASS:0)
Block(-1,7,-4,GRASS:0)
Block(-1,7,-3,STONE:0)
Block(-1,7,-2,STONE:0)
Block(-1,7,-1,STONE:0)
Block(-1,7,0,STONE:0)
Block(-1,7,1,STONE:0)
Block(-1,7,2,STONE:0)
Block(-1,7,3,GRASS:0)
Block(-1,8,-3,GRASS:0)
Block(-1,8,-2,STONE:0)
Block(-1,8,-1,STONE:0)
Block(-1,8,0,GRASS:0)
Block(-1,8,1,GRASS:0)
Block(-1,8,2,GRASS:0)
Block(-1,9,-2,GRASS:0)
Block(-1,9,-1,GRASS:0)
Block(0,-11,0,STONE:0)
Block(0,-11,1,STONE:0)
Block(0,-11,2,STONE:0)
Block(0,-10,-2,STONE:0)
Block(0,-10,-1,STONE:0)
Block(0,-10,0,STONE:0)
Block(0,-10,1,STONE:0)
Block(0,-10,2,STONE:0)
Block(0,-10,3,STONE:0)
Block(0,-9,-4,STONE:0)
Block(0,-9,-3,STONE:0)
Block(0,-9,-2,STONE:0)
Block(0,-9,-1,STONE:0)
Block(0,-9,0,STONE:0)
Block(0,-9,1,STONE:0)
Block(0,-9,2,STONE:0)
Block(0,-9,3,STONE:0)
Block(0,-9,4,STONE:0)
Block(0,-8,-6,STONE:0)
Block(0,-8,-5,STONE:0)
Block(0,-8,-4,STONE:0)
Block(0,-8,-3,STONE:0)
Block(0,-8,-2,STONE:0)
Block(0,-8,-1,STONE:0)
Block(0,-8,0,STONE:0)
Block(0,-8,1,STONE:0)
Block(0,-8,2,STONE:0)
Block(0,-8,3,STONE:0)
Block(0,-8,4,STONE:0)
Block(0,-8,5,STONE:0)
Block(0,-7,-8,STONE:0)
Block(0,-7,-7,STONE:0)
Block(0,-7,-6,STONE:0)
Block(0,-7,-5,STONE:0)
Block(0,-7,-4,STONE:0)
Block(0,-7,-3,STONE:0)
Block(0,-7,-2,STONE:0)
Block(0,-7,-1,STONE:0)
Block(0,-7,0,STONE:0)
Block(0,-7,1,STONE:0)
Block(0,-7,2,STONE:0)
Block(0,-7,3,STONE:0)
Block(0,-7,4,STONE:0)
Block(0,-7,5,STONE:0)
Block(0,-7,6,STONE:0)
Block(0,-6,-10,STONE:0)
Block(0,-6,-9,STONE:0)
Block(0,-6,-8,STONE:0)
Block(0,-6,-7,STONE:0)
Block(0,-6,-6,STONE:0)
Block(0,-6,-5,STONE:0)
Block(0,-6,-4,STONE:0)
Block(0,-6,-3,STONE:0)
Block(0,-6,-2,STONE:0)
Block(0,-6,-1,STONE:0)
Block(0,-6,0,STONE:0)
Block(0,-6,1,STONE:0)
Block(0,-6,2,STONE:0)
Block(0,-6,3,STONE:0)
Block(0,-6,4,STONE:0)
Block(0,-6,5,STONE:0)
Block(0,-6,6,STONE:0)
Block(0,-6,7,STONE:0)
Block(0,-5,-11,STONE:0)
Block(0,-5,-10,STONE:0)
Block(0,-5,-9,STONE:0)
Block(0,-5,-8,STONE:0)
Block(0,-5,-7,STONE:0)
Block(0,-5,-6,STONE:0)
Block(0,-5,-5,STONE:0)
Block(0,-5,-4,STONE:0)
Block(0,-5,-3,STONE:0)
Block(0,-5,-2,STONE:0)
Block(0,-5,-1,STONE:0)
Block(0,-5,0,STONE:0)
Block(0,-5,1,STONE:0)
Block(0,-5,2,STONE:0)
Block(0,-5,3,STONE:0)
Block(0,-5,4,STONE:0)
Block(0,-5,5,STONE:0)
Block(0,-5,6,STONE:0)
Block(0,-5,7,STONE:0)
Block(0,-5,8,STONE:0)
Block(0,-4,-11,STONE:0)
Block(0,-4,-10,STONE:0)
Block(0,-4,-9,STONE:0)
Block(0,-4,-8,STONE:0)
Block(0,-4,-7,STONE:0)
Block(0,-4,-6,STONE:0)
Block(0,-4,-5,STONE:0)
Block(0,-4,-4,STONE:0)
Block(0,-4,-3,STONE:0)
Block(0,-4,-2,STONE:0)
Block(0,-4,-1,STONE:0)
Block(0,-4,0,STONE:0)
Block(0,-4,1,STONE:0)
Block(0,-4,2,STONE:0)
Block(0,-4,3,STONE:0)
Block(0,-4,4,STONE:0)
Block(0,-4,5,STONE:0)
Block(0,-4,6,STONE:0)
Block(0,-4,7,STONE:0)
Block(0,-4,8,STONE:0)
Block(0,-4,9,STONE:0)
Block(0,-3,-11,STONE:0)
Block(0,-3,-10,STONE:0)
Block(0,-3,-9,STONE:0)
Block(0,-3,-8,STONE:0)
Block(0,-3,-7,STONE:0)
Block(0,-3,-6,STONE:0)
Block(0,-3,-5,STONE:0)
Block(0,-3,-4,STONE:0)
Block(0,-3,-3,STONE:0)
Block(0,-3,-2,STONE:0)
Block(0,-3,-1,STONE:0)
Block(0,-3,0,STONE:0)
Block(0,-3,1,STONE:0)
Block(0,-3,2,STONE:0)
Block(0,-3,3,STONE:0)
Block(0,-3,4,STONE:0)
Block(0,-3,5,STONE:0)
Block(0,-3,6,STONE:0)
Block(0,-3,7,STONE:0)
Block(0,-3,8,STONE:0)
Block(0,-3,9,STONE:0)
Block(0,-2,-12,STONE:0)
Block(0,-2,-11,STONE:0)
Block(0,-2,-10,STONE:0)
Block(0,-2,-9,STONE:0)
Block(0,-2,-8,STONE:0)
Block(0,-2,-7,STONE:0)
Block(0,-2,-6,STONE:0)
Block(0,-2,-5,STONE:0)
Block(0,-2,-4,STONE:0)
Block(0,-2,-3,STONE:0)
Block(0,-2,-2,STONE:0)
Block(0,-2,-1,STONE:0)
Block(0,-2,0,STONE:0)
Block(0,-2,1,STONE:0)
Block(0,-2,2,STONE:0)
Block(0,-2,3,STONE:0)
Block(0,-2,4,STONE:0)
Block(0,-2,5,STONE:0)
Block(0,-2,6,STONE:0)
Block(0,-2,7,STONE:0)
Block(0,-2,8,STONE:0)
Block(0,-2,9,STONE:0)
Block(0,-2,10,STONE:0)
Block(0,-1,-12,GRASS:0)
Block(0,-1,-11,STONE:0)
Block(0,-1,-10,STONE:0)
Block(0,-1,-9,STONE:0)
Block(0,-1,-8,STONE:0)
Block(0,-1,-7,STONE:0)
Block(0,-1,-6,STONE:0)
Block(0,-1,-5,STONE:0)
Block(0,-1,-4,STONE:0)
Block(0,-1,-3,STONE:0)
Block(0,-1,-2,STONE:0)
Block(0,-1,-1,STONE:0)
Block(0,-1,0,STONE:0)
Block(0,-1,1,STONE:0)
Block(0,-1,2,STONE:0)
Block(0,-1,3,STONE:0)
Block(0,-1,4,STONE:0)
Block(0,-1,5,STONE:0)
Block(0,-1,6,STONE:0)
Block(0,-1,7,STONE:0)
Block(0,-1,8,STONE:0)
Block(0,-1,9,STONE:0)
Block(0,-1,10,STONE:0)
Block(0,0,-11,DIRT:0)
Block(0,0,-10,STONE:0)
Block(0,0,-9,STONE:0)
Block(0,0,-8,STONE:0)
Block(0,0,-7,STONE:0)
Block(0,0,-6,STONE:0)
Block(0,0,-5,STONE:0)
Block(0,0,-4,STONE:0)
Block(0,0,-3,STONE:0)
Block(0,0,-2,STONE:0)
Block(0,0,-1,STONE:0)
Block(0,0,0,STONE:0)
Block(0,0,1,STONE:0)
Block(0,0,2,STONE:0)
Block(0,0,3,STONE:0)
Block(0,0,4,STONE:0)
Block(0,0,5,STONE:0)
Block(0,0,6,STONE:0)
Block(0,0,7,STONE:0)
Block(0,0,8,STONE:0)
Block(0,0,9,STONE:0)
Block(0,0,10,DIRT:0)
Block(0,1,-11,GRASS:0)
Block(0,1,-10,STONE:0)
Block(0,1,-9,STONE:0)
Block(0,1,-8,STONE:0)
Block(0,1,-7,STONE:0)
Block(0,1,-6,STONE:0)
Block(0,1,-5,STONE:0)
Block(0,1,-4,STONE:0)
Block(0,1,-3,STONE:0)
Block(0,1,-2,STONE:0)
Block(0,1,-1,STONE:0)
Block(0,1,0,STONE:0)
Block(0,1,1,STONE:0)
Block(0,1,2,STONE:0)
Block(0,1,3,STONE:0)
Block(0,1,4,STONE:0)
Block(0,1,5,STONE:0)
Block(0,1,6,STONE:0)
Block(0,1,7,STONE:0)
Block(0,1,8,STONE:0)
Block(0,1,9,STONE:0)
Block(0,1,10,GRASS:0)
Block(0,2,-10,GRASS:0)
Block(0,2,-9,STONE:0)
Block(0,2,-8,STONE:0)
Block(0,2,-7,STONE:0)
Block(0,2,-6,STONE:0)
Block(0,2,-5,STONE:0)
Block(0,2,-4,STONE:0)
Block(0,2,-3,STONE:0)
Block(0,2,-2,STONE:0)
Block(0,2,-1,STONE:0)
Block(0,2,0,STONE:0)
Block(0,2,1,STONE:0)
Block(0,2,2,STONE:0)
Block(0,2,3,STONE:0)
Block(0,2,4,STONE:0)
Block(0,2,5,STONE:0)
Block(0,2,6,STONE:0)
Block(0,2,7,STONE:0)
Block(0,2,8,STONE:0)
Block(0,2,9,DIRT:0)
Block(0,3,-9,GRASS:0)
Block(0,3,-8,STONE:0)
Block(0,3,-7,STONE:0)
Block(0,3,-6,STONE:0)
Block(0,3,-5,STONE:0)
Block(0,3,-4,STONE:0)
Block(0,3,-3,STONE:0)
Block(0,3,-2,STONE:0)
Block(0,3,-1,STONE:0)
Block(0,3,0,STONE:0)
Block(0,3,1,STONE:0)
Block(0,3,2,STONE:0)
Block(0,3,3,STONE:0)
Block(0,3,4,STONE:0)
Block(0,3,5,STONE:0)
Block(0,3,6,STONE:0)
Block(0,3,7,STONE:0)
Block(0,3,8,STONE:0)
Block(0,3,9,GRASS:0)
Block(0,4,-8,GRASS:0)
Block(0,4,-7,GRASS:0)
Block(0,4,-6,STONE:0)
Block(0,4,-5,STONE:0)
Block(0,4,-4,STONE:0)
Block(0,4,-3,STONE:0)
Block(0,4,-2,STONE:0)
Block(0,4,-1,STONE:0)
Block(0,4,0,STONE:0)
Block(0,4,1,STONE:0)
Block(0,4,2,STONE:0)
Block(0,4,3,STONE:0)
Block(0,4,4,STONE:0)
Block(0,4,5,STONE:0)
Block(0,4,6,STONE:0)
Block(0,4,7,STONE:0)
Block(0,4,8,GRASS:0)
Block(0,5,-6,GRASS:0)
Block(0,5,-5,STONE:0)
Block(0,5,-4,STONE:0)
Block(0,5,-3,STONE:0)
Block(0,5,-2,STONE:0)
Block(0,5,-1,STONE:0)
Block(0,5,0,STONE:0)
Block(0,5,1,STONE:0)
Block(0,5,2,STONE:0)
Block(0,5,3,STONE:0)
Block(0,5,4,STONE:0)
Block(0,5,5,STONE:0)
Block(0,5,6,GRASS:0)
Block(0,5,7,GRASS:0)
Block(0,6,-5,GRASS:0)
Block(0,6,-4,STONE:0)
Block(0,6,-3,STONE:0)
Block(0,6,-2,STONE:0)
Block(0,6,-1,STONE:0)
Block(0,6,0,STONE:0)
Block(0,6,1,STONE:0)
Block(0,6,2,STONE:0)
Block(0,6,3,STONE:0)
Block(0,6,4,GRASS:0)
Block(0,6,5,GRASS:0)
Block(0,7,-4,GRASS:0)
Block(0,7,-3,STONE:0)
Block(0,7,-2,STONE:0)
Block(0,7,-1,STONE:0)
Block(0,7,0,STONE:0)
Block(0,7,1,STONE:0)
Block(0,7,2,GRASS:0)
Block(0,7,3,GRASS:0)
Block(0,8,-3,GRASS:0)
Block(0,8,-2,STONE:0)
Block(0,8,-1,STONE:0)
Block(0,8,0,GRASS:0)
Block(0,8,1,GRASS:0)
Block(0,9,-2,GRASS:0)
Block(0,9,-1,GRASS:0)
Block(1,-11,0,STONE:0)
Block(1,-11,1,STONE:0)
Block(1,-11,2,STONE:0)
Block(1,-10,-2,STONE:0)
Block(1,-10,-1,STONE:0)
Block(1,-10,0,STONE:0)
Block(1,-10,1,STONE:0)
Block(1,-10,2,STONE:0)
Block(1,-10,3,STONE:0)
Block(1,-9,-4,STONE:0)
Block(1,-9,-3,STONE:0)
Block(1,-9,-2,STONE:0)
Block(1,-9,-1,STONE:0)
Block(1,-9,0,STONE:0)
Block(1,-9,1,STONE:0)
Block(1,-9,2,STONE:0)
Block(1,-9,3,STONE:0)
Block(1,-9,4,STONE:0)
Block(1,-8,-6,STONE:0)
Block(1,-8,-5,STONE:0)
Block(1,-8,-4,STONE:0)
Block(1,-8,-3,STONE:0)
Block(1,-8,-2,STONE:0)
Block(1,-8,-1,STONE:0)
Block(1,-8,0,STONE:0)
Block(1,-8,1,STONE:0)
Block(1,-8,2,STONE:0)
Block(1,-8,3,STONE:0)
Block(1,-8,4,STONE:0)
Block(1,-8,5,STONE:0)
Block(1,-7,-8,STONE:0)
Block(1,-7,-7,STONE:0)
Block(1,-7,-6,STONE:0)
Block(1,-7,-5,STONE:0)
Block(1,-7,-4,STONE:0)
Block(1,-7,-3,STONE:0)
Block(1,-7,-2,STONE:0)
Block(1,-7,-1,STONE:0)
Block(1,-7,0,STONE:0)
Block(1,-7,1,STONE:0)
Block(1,-7,2,STONE:0)
Block(1,-7,3,STONE:0)
Block(1,-7,4,STONE:0)
Block(1,-7,5,STONE:0)
Block(1,-7,6,STONE:0)
Block(1,-6,-10,STONE:0)
Block(1,-6,-9,STONE:0)
Block(1,-6,-8,STONE:0)
Block(1,-6,-7,STONE:0)
Block(1,-6,-6,STONE:0)
Block(1,-6,-5,STONE:0)
Block(1,-6,-4,STONE:0)
Block(1,-6,-3,STONE:0)
Block(1,-6,-2,STONE:0)
Block(1,-6,-1,STONE:0)
Block(1,-6,0,STONE:0)
Block(1,-6,1,STONE:0)
Block(1,-6,2,STONE:0)
Block(1,-6,3,STONE:0)
Block(1,-6,4,STONE:0)
Block(1,-6,5,STONE:0)
Block(1,-6,6,STONE:0)
Block(1,-6,7,STONE:0)
Block(1,-5,-11,STONE:0)
Block(1,-5,-10,STONE:0)
Block(1,-5,-9,STONE:0)
Block(1,-5,-8,STONE:0)
Block(1,-5,-7,STONE:0)
Block(1,-5,-6,STONE:0)
Block(1,-5,-5,STONE:0)
Block(1,-5,-4,STONE:0)
Block(1,-5,-3,STONE:0)
Block(1,-5,-2,STONE:0)
Block(1,-5,-1,STONE:0)
Block(1,-5,0,STONE:0)
Block(1,-5,1,STONE:0)
Block(1,-5,2,STONE:0)
Block(1,-5,3,STONE:0)
Block(1,-5,4,STONE:0)
Block(1,-5,5,STONE:0)
Block(1,-5,6,STONE:0)
Block(1,-5,7,STONE:0)
Block(1,-5,8,STONE:0)
Block(1,-4,-11,STONE:0)
Block(1,-4,-10,STONE:0)
Block(1,-4,-9,STONE:0)
Block(1,-4,-8,STONE:0)
Block(1,-4,-7,STONE:0)
Block(1,-4,-6,STONE:0)
Block(1,-4,-5,STONE:0)
Block(1,-4,-4,STONE:0)
Block(1,-4,-3,STONE:0)
Block(1,-4,-2,STONE:0)
Block(1,-4,-1,STONE:0)
Block(1,-4,0,STONE:0)
Block(1,-4,1,STONE:0)
Block(1,-4,2,STONE:0)
Block(1,-4,3,STONE:0)
Block(1,-4,4,STONE:0)
Block(1,-4,5,STONE:0)
Block(1,-4,6,STONE:0)
Block(1,-4,7,STONE:0)
Block(1,-4,8,STONE:0)
Block(1,-4,9,STONE:0)
Block(1,-3,-12,STONE:0)
Block(1,-3,-11,STONE:0)
Block(1,-3,-10,STONE:0)
Block(1,-3,-9,STONE:0)
Block(1,-3,-8,STONE:0)
Block(1,-3,-7,STONE:0)
Block(1,-3,-6,STONE:0)
Block(1,-3,-5,STONE:0)
Block(1,-3,-4,STONE:0)
Block(1,-3,-3,STONE:0)
Block(1,-3,-2,STONE:0)
Block(1,-3,-1,STONE:0)
Block(1,-3,0,STONE:0)
Block(1,-3,1,STONE:0)
Block(1,-3,2,STONE:0)
Block(1,-3,3,STONE:0)
Block(1,-3,4,STONE:0)
Block(1,-3,5,STONE:0)
Block(1,-3,6,STONE:0)
Block(1,-3,7,STONE:0)
Block(1,-3,8,STONE:0)
Block(1,-3,9,STONE:0)
Block(1,-3,10,STONE:0)
Block(1,-2,-12,STONE:0)
Block(1,-2,-11,STONE:0)
Block(1,-2,-10,STONE:0)
Block(1,-2,-9,STONE:0)
Block(1,-2,-8,STONE:0)
Block(1,-2,-7,STONE:0)
Block(1,-2,-6,STONE:0)
Block(1,-2,-5,STONE:0)
Block(1,-2,-4,STONE:0)
Block(1,-2,-3,STONE:0)
Block(1,-2,-2,STONE:0)
Block(1,-2,-1,STONE:0)
Block(1,-2,0,STONE:0)
Block(1,-2,1,STONE:0)
Block(1,-2,2,STONE:0)
Block(1,-2,3,STONE:0)
Block(1,-2,4,STONE:0)
Block(1,-2,5,STONE:0)
Block(1,-2,6,STONE:0)
Block(1,-2,7,STONE:0)
Block(1,-2,8,STONE:0)
Block(1,-2,9,STONE:0)
Block(1,-2,10,STONE:0)
Block(1,-1,-12,GRASS:0)
Block(1,-1,-11,STONE:0)
Block(1,-1,-10,STONE:0)
Block(1,-1,-9,STONE:0)
Block(1,-1,-8,STONE:0)
Block(1,-1,-7,STONE:0)
Block(1,-1,-6,STONE:0)
Block(1,-1,-5,STONE:0)
Block(1,-1,-4,STONE:0)
Block(1,-1,-3,STONE:0)
Block(1,-1,-2,STONE:0)
Block(1,-1,-1,STONE:0)
Block(1,-1,0,STONE:0)
Block(1,-1,1,STONE:0)
Block(1,-1,2,STONE:0)
Block(1,-1,3,STONE:0)
Block(1,-1,4,STONE:0)
Block(1,-1,5,STONE:0)
Block(1,-1,6,STONE:0)
Block(1,-1,7,STONE:0)
Block(1,-1,8,STONE:0)
Block(1,-1,9,STONE:0)
Block(1,-1,10,STONE:0)
Block(1,0,-11,DIRT:0)
Block(1,0,-10,STONE:0)
Block(1,0,-9,STONE:0)
Block(1,0,-8,STONE:0)
Block(1,0,-7,STONE:0)
Block(1,0,-6,STONE:0)
Block(1,0,-5,STONE:0)
Block(1,0,-4,STONE:0)
Block(1,0,-3,STONE:0)
Block(1,0,-2,STONE:0)
Block(1,0,-1,STONE:0)
Block(1,0,0,STONE:0)
Block(1,0,1,STONE:0)
Block(1,0,2,STONE:0)
Block(1,0,3,STONE:0)
Block(1,0,4,STONE:0)
Block(1,0,5,STONE:0)
Block(1,0,6,STONE:0)
Block(1,0,7,STONE:0)
Block(1,0,8,STONE:0)
Block(1,0,9,STONE:0)
Block(1,0,10,DIRT:0)
Block(1,1,-11,GRASS:0)
Block(1,1,-10,STONE:0)
Block(1,1,-9,STONE:0)
Block(1,1,-8,STONE:0)
Block(1,1,-7,STONE:0)
Block(1,1,-6,STONE:0)
Block(1,1,-5,STONE:0)
Block(1,1,-4,STONE:0)
Block(1,1,-3,STONE:0)
Block(1,1,-2,STONE:0)
Block(1,1,-1,STONE:0)
Block(1,1,0,STONE:0)
Block(1,1,1,STONE:0)
Block(1,1,2,STONE:0)
Block(1,1,3,STONE:0)
Block(1,1,4,STONE:0)
Block(1,1,5,STONE:0)
Block(1,1,6,STONE:0)
Block(1,1,7,STONE:0)
Block(1,1,8,STONE:0)
Block(1,1,9,STONE:0)
Block(1,1,10,DIRT:0)
Block(1,2,-10,GRASS:0)
Block(1,2,-9,STONE:0)
Block(1,2,-8,STONE:0)
Block(1,2,-7,STONE:0)
Block(1,2,-6,STONE:0)
Block(1,2,-5,STONE:0)
Block(1,2,-4,STONE:0)
Block(1,2,-3,STONE:0)
Block(1,2,-2,STONE:0)
Block(1,2,-1,STONE:0)
Block(1,2,0,STONE:0)
Block(1,2,1,STONE:0)
Block(1,2,2,STONE:0)
Block(1,2,3,STONE:0)
Block(1,2,4,STONE:0)
Block(1,2,5,STONE:0)
Block(1,2,6,STONE:0)
Block(1,2,7,STONE:0)
Block(1,2,8,STONE:0)
Block(1,2,9,STONE:0)
Block(1,2,10,GRASS:0)
Block(1,3,-9,GRASS:0)
Block(1,3,-8,STONE:0)
Block(1,3,-7,STONE:0)
Block(1,3,-6,STONE:0)
Block(1,3,-5,STONE:0)
Block(1,3,-4,STONE:0)
Block(1,3,-3,STONE:0)
Block(1,3,-2,STONE:0)
Block(1,3,-1,STONE:0)
Block(1,3,0,STONE:0)
Block(1,3,1,STONE:0)
Block(1,3,2,STONE:0)
Block(1,3,3,STONE:0)
Block(1,3,4,STONE:0)
Block(1,3,5,STONE:0)
Block(1,3,6,STONE:0)
Block(1,3,7,STONE:0)
Block(1,3,8,STONE:0)
Block(1,3,9,GRASS:0)
Block(1,4,-8,GRASS:0)
Block(1,4,-7,STONE:0)
Block(1,4,-6,STONE:0)
Block(1,4,-5,STONE:0)
Block(1,4,-4,STONE:0)
Block(1,4,-3,STONE:0)
Block(1,4,-2,STONE:0)
Block(1,4,-1,STONE:0)
Block(1,4,0,STONE:0)
Block(1,4,1,STONE:0)
Block(1,4,2,STONE:0)
Block(1,4,3,STONE:0)
Block(1,4,4,STONE:0)
Block(1,4,5,STONE:0)
Block(1,4,6,STONE:0)
Block(1,4,7,STONE:0)
Block(1,4,8,GRASS:0)
Block(1,5,-7,GRASS:0)
Block(1,5,-6,STONE:0)
Block(1,5,-5,STONE:0)
Block(1,5,-4,STONE:0)
Block(1,5,-3,STONE:0)
Block(1,5,-2,STONE:0)
Block(1,5,-1,STONE:0)
Block(1,5,0,STONE:0)
Block(1,5,1,STONE:0)
Block(1,5,2,STONE:0)
Block(1,5,3,STONE:0)
Block(1,5,4,STONE:0)
Block(1,5,5,STONE:0)
Block(1,5,6,GRASS:0)
Block(1,5,7,GRASS:0)
Block(1,6,-6,GRASS:0)
Block(1,6,-5,STONE:0)
Block(1,6,-4,STONE:0)
Block(1,6,-3,STONE:0)
Block(1,6,-2,STONE:0)
Block(1,6,-1,STONE:0)
Block(1,6,0,STONE:0)
Block(1,6,1,STONE:0)
Block(1,6,2,STONE:0)
Block(1,6,3,STONE:0)
Block(1,6,4,GRASS:0)
Block(1,6,5,GRASS:0)
Block(1,7,-5,GRASS:0)
Block(1,7,-4,GRASS:0)
Block(1,7,-3,STONE:0)
Block(1,7,-2,STONE:0)
Block(1,7,-1,STONE:0)
Block(1,7,0,STONE:0)
Block(1,7,1,STONE:0)
Block(1,7,2,GRASS:0)
Block(1,7,3,GRASS:0)
Block(1,8,-3,GRASS:0)
Block(1,8,-2,STONE:0)
Block(1,8,-1,STONE:0)
Block(1,8,0,GRASS:0)
Block(1,8,1,GRASS:0)
Block(1,9,-2,GRASS:0)
Block(1,9,-1,GRASS:0)
Block(2,-11,0,STONE:0)
Block(2,-11,1,STONE:0)
Block(2,-11,2,STONE:0)
Block(2,-10,-2,STONE:0)
Block(2,-10,-1,STONE:0)
Block(2,-10,0,STONE:0)
Block(2,-10,1,STONE:0)
Block(2,-10,2,STONE:0)
Block(2,-10,3,STONE:0)
Block(2,-9,-4,STONE:0)
Block(2,-9,-3,STONE:0)
Block(2,-9,-2,STONE:0)
Block(2,-9,-1,STONE:0)
Block(2,-9,0,STONE:0)
Block(2,-9,1,STONE:0)
Block(2,-9,2,STONE:0)
Block(2,-9,3,STONE:0)
Block(2,-9,4,STONE:0)
Block(2,-8,-7,STONE:0)
Block(2,-8,-6,STONE:0)
Block(2,-8,-5,STONE:0)
Block(2,-8,-4,STONE:0)
Block(2,-8,-3,STONE:0)
Block(2,-8,-2,STONE:0)
Block(2,-8,-1,STONE:0)
Block(2,-8,0,STONE:0)
Block(2,-8,1,STONE:0)
Block(2,-8,2,STONE:0)
Block(2,-8,3,STONE:0)
Block(2,-8,4,STONE:0)
Block(2,-8,5,STONE:0)
Block(2,-7,-8,STONE:0)
Block(2,-7,-7,STONE:0)
Block(2,-7,-6,STONE:0)
Block(2,-7,-5,STONE:0)
Block(2,-7,-4,STONE:0)
Block(2,-7,-3,STONE:0)
Block(2,-7,-2,STONE:0)
Block(2,-7,-1,STONE:0)
Block(2,-7,0,STONE:0)
Block(2,-7,1,STONE:0)
Block(2,-7,2,STONE:0)
Block(2,-7,3,STONE:0)
Block(2,-7,4,STONE:0)
Block(2,-7,5,STONE:0)
Block(2,-7,6,STONE:0)
Block(2,-6,-10,STONE:0)
Block(2,-6,-9,STONE:0)
Block(2,-6,-8,STONE:0)
Block(2,-6,-7,STONE:0)
Block(2,-6,-6,STONE:0)
Block(2,-6,-5,STONE:0)
Block(2,-6,-4,STONE:0)
Block(2,-6,-3,STONE:0)
Block(2,-6,-2,STONE:0)
Block(2,-6,-1,STONE:0)
Block(2,-6,0,STONE:0)
Block(2,-6,1,STONE:0)
Block(2,-6,2,STONE:0)
Block(2,-6,3,STONE:0)
Block(2,-6,4,STONE:0)
Block(2,-6,5,STONE:0)
Block(2,-6,6,STONE:0)
Block(2,-6,7,STONE:0)
Block(2,-5,-11,STONE:0)
Block(2,-5,-10,STONE:0)
Block(2,-5,-9,STONE:0)
Block(2,-5,-8,STONE:0)
Block(2,-5,-7,STONE:0)
Block(2,-5,-6,STONE:0)
Block(2,-5,-5,STONE:0)
Block(2,-5,-4,STONE:0)
Block(2,-5,-3,STONE:0)
Block(2,-5,-2,STONE:0)
Block(2,-5,-1,STONE:0)
Block(2,-5,0,STONE:0)
Block(2,-5,1,STONE:0)
Block(2,-5,2,STONE:0)
Block(2,-5,3,STONE:0)
Block(2,-5,4,STONE:0)
Block(2,-5,5,STONE:0)
Block(2,-5,6,STONE:0)
Block(2,-5,7,STONE:0)
Block(2,-5,8,STONE:0)
Block(2,-4,-11,STONE:0)
Block(2,-4,-10,STONE:0)
Block(2,-4,-9,STONE:0)
Block(2,-4,-8,STONE:0)
Block(2,-4,-7,STONE:0)
Block(2,-4,-6,STONE:0)
Block(2,-4,-5,STONE:0)
Block(2,-4,-4,STONE:0)
Block(2,-4,-3,STONE:0)
Block(2,-4,-2,STONE:0)
Block(2,-4,-1,STONE:0)
Block(2,-4,0,STONE:0)
Block(2,-4,1,STONE:0)
Block(2,-4,2,STONE:0)
Block(2,-4,3,STONE:0)
Block(2,-4,4,STONE:0)
Block(2,-4,5,STONE:0)
Block(2,-4,6,STONE:0)
Block(2,-4,7,STONE:0)
Block(2,-4,8,STONE:0)
Block(2,-4,9,STONE:0)
Block(2,-3,-11,STONE:0)
Block(2,-3,-10,STONE:0)
Block(2,-3,-9,STONE:0)
Block(2,-3,-8,STONE:0)
Block(2,-3,-7,STONE:0)
Block(2,-3,-6,STONE:0)
Block(2,-3,-5,STONE:0)
Block(2,-3,-4,STONE:0)
Block(2,-3,-3,STONE:0)
Block(2,-3,-2,STONE:0)
Block(2,-3,-1,STONE:0)
Block(2,-3,0,STONE:0)
Block(2,-3,1,STONE:0)
Block(2,-3,2,STONE:0)
Block(2,-3,3,STONE:0)
Block(2,-3,4,STONE:0)
Block(2,-3,5,STONE:0)
Block(2,-3,6,STONE:0)
Block(2,-3,7,STONE:0)
Block(2,-3,8,STONE:0)
Block(2,-3,9,STONE:0)
Block(2,-3,10,STONE:0)
Block(2,-2,-12,STONE:0)
Block(2,-2,-11,STONE:0)
Block(2,-2,-10,STONE:0)
Block(2,-2,-9,STONE:0)
Block(2,-2,-8,STONE:0)
Block(2,-2,-7,STONE:0)
Block(2,-2,-6,STONE:0)
Block(2,-2,-5,STONE:0)
Block(2,-2,-4,STONE:0)
Block(2,-2,-3,STONE:0)
Block(2,-2,-2,STONE:0)
Block(2,-2,-1,STONE:0)
Block(2,-2,0,STONE:0)
Block(2,-2,1,STONE:0)
Block(2,-2,2,STONE:0)
Block(2,-2,3,STONE:0)
Block(2,-2,4,STONE:0)
Block(2,-2,5,STONE:0)
Block(2,-2,6,STONE:0)
Block(2,-2,7,STONE:0)
Block(2,-2,8,STONE:0)
Block(2,-2,9,STONE:0)
Block(2,-2,10,STONE:0)
Block(2,-1,-12,GRASS:0)
Block(2,-1,-11,STONE:0)
Block(2,-1,-10,STONE:0)
Block(2,-1,-9,STONE:0)
Block(2,-1,-8,STONE:0)
Block(2,-1,-7,STONE:0)
Block(2,-1,-6,STONE:0)
Block(2,-1,-5,STONE:0)
Block(2,-1,-4,STONE:0)
Block(2,-1,-3,STONE:0)
Block(2,-1,-2,STONE:0)
Block(2,-1,-1,STONE:0)
Block(2,-1,0,STONE:0)
Block(2,-1,1,STONE:0)
Block(2,-1,2,STONE:0)
Block(2,-1,3,STONE:0)
Block(2,-1,4,STONE:0)
Block(2,-1,5,STONE:0)
Block(2,-1,6,STONE:0)
Block(2,-1,7,STONE:0)
Block(2,-1,8,STONE:0)
Block(2,-1,9,STONE:0)
Block(2,-1,10,STONE:0)
Block(2,0,-11,DIRT:0)
Block(2,0,-10,STONE:0)
Block(2,0,-9,STONE:0)
Block(2,0,-8,STONE:0)
Block(2,0,-7,STONE:0)
Block(2,0,-6,STONE:0)
Block(2,0,-5,STONE:0)
Block(2,0,-4,STONE:0)
Block(2,0,-3,STONE:0)
Block(2,0,-2,STONE:0)
Block(2,0,-1,STONE:0)
Block(2,0,0,STONE:0)
Block(2,0,1,STONE:0)
Block(2,0,2,STONE:0)
Block(2,0,3,STONE:0)
Block(2,0,4,STONE:0)
Block(2,0,5,STONE:0)
Block(2,0,6,STONE:0)
Block(2,0,7,STONE:0)
Block(2,0,8,STONE:0)
Block(2,0,9,STONE:0)
Block(2,0,10,DIRT:0)
Block(2,1,-11,GRASS:0)
Block(2,1,-10,STONE:0)
Block(2,1,-9,STONE:0)
Block(2,1,-8,STONE:0)
Block(2,1,-7,STONE:0)
Block(2,1,-6,STONE:0)
Block(2,1,-5,STONE:0)
Block(2,1,-4,STONE:0)
Block(2,1,-3,STONE:0)
Block(2,1,-2,STONE:0)
Block(2,1,-1,STONE:0)
Block(2,1,0,STONE:0)
Block(2,1,1,STONE:0)
Block(2,1,2,STONE:0)
Block(2,1,3,STONE:0)
Block(2,1,4,STONE:0)
Block(2,1,5,STONE:0)
Block(2,1,6,STONE:0)
Block(2,1,7,STONE:0)
Block(2,1,8,STONE:0)
Block(2,1,9,STONE:0)
Block(2,1,10,DIRT:0)
Block(2,2,-10,GRASS:0)
Block(2,2,-9,STONE:0)
Block(2,2,-8,STONE:0)
Block(2,2,-7,STONE:0)
Block(2,2,-6,STONE:0)
Block(2,2,-5,STONE:0)
Block(2,2,-4,STONE:0)
Block(2,2,-3,STONE:0)
Block(2,2,-2,STONE:0)
Block(2,2,-1,STONE:0)
Block(2,2,0,STONE:0)
Block(2,2,1,STONE:0)
Block(2,2,2,STONE:0)
Block(2,2,3,STONE:0)
Block(2,2,4,STONE:0)
Block(2,2,5,STONE:0)
Block(2,2,6,STONE:0)
Block(2,2,7,STONE:0)
Block(2,2,8,STONE:0)
Block(2,2,9,STONE:0)
Block(2,2,10,GRASS:0)
Block(2,3,-9,GRASS:0)
Block(2,3,-8,STONE:0)
Block(2,3,-7,STONE:0)
Block(2,3,-6,STONE:0)
Block(2,3,-5,STONE:0)
Block(2,3,-4,STONE:0)
Block(2,3,-3,STONE:0)
Block(2,3,-2,STONE:0)
Block(2,3,-1,STONE:0)
Block(2,3,0,STONE:0)
Block(2,3,1,STONE:0)
Block(2,3,2,STONE:0)
Block(2,3,3,STONE:0)
Block(2,3,4,STONE:0)
Block(2,3,5,STONE:0)
Block(2,3,6,STONE:0)
Block(2,3,7,STONE:0)
Block(2,3,8,STONE:0)
Block(2,3,9,GRASS:0)
Block(2,4,-8,GRASS:0)
Block(2,4,-7,STONE:0)
Block(2,4,-6,STONE:0)
Block(2,4,-5,STONE:0)
Block(2,4,-4,STONE:0)
Block(2,4,-3,STONE:0)
Block(2,4,-2,STONE:0)
Block(2,4,-1,STONE:0)
Block(2,4,0,STONE:0)
Block(2,4,1,STONE:0)
Block(2,4,2,STONE:0)
Block(2,4,3,STONE:0)
Block(2,4,4,STONE:0)
Block(2,4,5,STONE:0)
Block(2,4,6,STONE:0)
Block(2,4,7,STONE:0)
Block(2,4,8,GRASS:0)
Block(2,5,-7,GRASS:0)
Block(2,5,-6,STONE:0)
Block(2,5,-5,STONE:0)
Block(2,5,-4,STONE:0)
Block(2,5,-3,STONE:0)
Block(2,5,-2,STONE:0)
Block(2,5,-1,STONE:0)
Block(2,5,0,STONE:0)
Block(2,5,1,STONE:0)
Block(2,5,2,STONE:0)
Block(2,5,3,STONE:0)
Block(2,5,4,STONE:0)
Block(2,5,5,GRASS:0)
Block(2,5,6,GRASS:0)
Block(2,5,7,GRASS:0)
Block(2,6,-6,GRASS:0)
Block(2,6,-5,STONE:0)
Block(2,6,-4,STONE:0)
Block(2,6,-3,STONE:0)
Block(2,6,-2,STONE:0)
Block(2,6,-1,STONE:0)
Block(2,6,0,STONE:0)
Block(2,6,1,STONE:0)
Block(2,6,2,STONE:0)
Block(2,6,3,STONE:0)
Block(2,6,4,GRASS:0)
Block(2,7,-5,GRASS:0)
Block(2,7,-4,STONE:0)
Block(2,7,-3,STONE:0)
Block(2,7,-2,STONE:0)
Block(2,7,-1,STONE:0)
Block(2,7,0,STONE:0)
Block(2,7,1,STONE:0)
Block(2,7,2,GRASS:0)
Block(2,7,3,GRASS:0)
Block(2,8,-4,GRASS:0)
Block(2,8,-3,GRASS:0)
Block(2,8,-2,STONE:0)
Block(2,8,-1,STONE:0)
Block(2,8,0,GRASS:0)
Block(2,8,1,GRASS:0)
Block(2,9,-2,GRASS:0)
Block(2,9,-1,GRASS:0)
Block(3,-11,0,STONE:0)
Block(3,-11,1,STONE:0)
Block(3,-10,-3,STONE:0)
Block(3,-10,-2,STONE:0)
Block(3,-10,-1,STONE:0)
Block(3,-10,0,STONE:0)
Block(3,-10,1,STONE:0)
Block(3,-10,2,STONE:0)
Block(3,-9,-5,STONE:0)
Block(3,-9,-4,STONE:0)
Block(3,-9,-3,STONE:0)
Block(3,-9,-2,STONE:0)
Block(3,-9,-1,STONE:0)
Block(3,-9,0,STONE:0)
Block(3,-9,1,STONE:0)
Block(3,-9,2,STONE:0)
Block(3,-9,3,STONE:0)
Block(3,-8,-7,STONE:0)
Block(3,-8,-6,STONE:0)
Block(3,-8,-5,STONE:0)
Block(3,-8,-4,STONE:0)
Block(3,-8,-3,STONE:0)
Block(3,-8,-2,STONE:0)
Block(3,-8,-1,STONE:0)
Block(3,-8,0,STONE:0)
Block(3,-8,1,STONE:0)
Block(3,-8,2,STONE:0)
Block(3,-8,3,STONE:0)
Block(3,-8,4,STONE:0)
Block(3,-7,-8,STONE:0)
Block(3,-7,-7,STONE:0)
Block(3,-7,-6,STONE:0)
Block(3,-7,-5,STONE:0)
Block(3,-7,-4,STONE:0)
Block(3,-7,-3,STONE:0)
Block(3,-7,-2,STONE:0)
Block(3,-7,-1,STONE:0)
Block(3,-7,0,STONE:0)
Block(3,-7,1,STONE:0)
Block(3,-7,2,STONE:0)
Block(3,-7,3,STONE:0)
Block(3,-7,4,STONE:0)
Block(3,-7,5,STONE:0)
Block(3,-6,-9,STONE:0)
Block(3,-6,-8,STONE:0)
Block(3,-6,-7,STONE:0)
Block(3,-6,-6,STONE:0)
Block(3,-6,-5,STONE:0)
Block(3,-6,-4,STONE:0)
Block(3,-6,-3,STONE:0)
Block(3,-6,-2,STONE:0)
Block(3,-6,-1,STONE:0)
Block(3,-6,0,STONE:0)
Block(3,-6,1,STONE:0)
Block(3,-6,2,STONE:0)
Block(3,-6,3,STONE:0)
Block(3,-6,4,STONE:0)
Block(3,-6,5,STONE:0)
Block(3,-6,6,STONE:0)
Block(3,-6,7,STONE:0)
Block(3,-5,-10,STONE:0)
Block(3,-5,-9,STONE:0)
Block(3,-5,-8,STONE:0)
Block(3,-5,-7,STONE:0)
Block(3,-5,-6,STONE:0)
Block(3,-5,-5,STONE:0)
Block(3,-5,-4,STONE:0)
Block(3,-5,-3,STONE:0)
Block(3,-5,-2,STONE:0)
Block(3,-5,-1,STONE:0)
Block(3,-5,0,STONE:0)
Block(3,-5,1,STONE:0)
Block(3,-5,2,STONE:0)
Block(3,-5,3,STONE:0)
Block(3,-5,4,STONE:0)
Block(3,-5,5,STONE:0)
Block(3,-5,6,STONE:0)
Block(3,-5,7,STONE:0)
Block(3,-5,8,STONE:0)
Block(3,-4,-11,STONE:0)
Block(3,-4,-10,STONE:0)
Block(3,-4,-9,STONE:0)
Block(3,-4,-8,STONE:0)
Block(3,-4,-7,STONE:0)
Block(3,-4,-6,STONE:0)
Block(3,-4,-5,STONE:0)
Block(3,-4,-4,STONE:0)
Block(3,-4,-3,STONE:0)
Block(3,-4,-2,STONE:0)
Block(3,-4,-1,STONE:0)
Block(3,-4,0,STONE:0)
Block(3,-4,1,STONE:0)
Block(3,-4,2,STONE:0)
Block(3,-4,3,STONE:0)
Block(3,-4,4,STONE:0)
Block(3,-4,5,STONE:0)
Block(3,-4,6,STONE:0)
Block(3,-4,7,STONE:0)
Block(3,-4,8,STONE:0)
Block(3,-4,9,STONE:0)
Block(3,-3,-11,STONE:0)
Block(3,-3,-10,STONE:0)
Block(3,-3,-9,STONE:0)
Block(3,-3,-8,STONE:0)
Block(3,-3,-7,STONE:0)
Block(3,-3,-6,STONE:0)
Block(3,-3,-5,STONE:0)
Block(3,-3,-4,STONE:0)
Block(3,-3,-3,STONE:0)
Block(3,-3,-2,STONE:0)
Block(3,-3,-1,STONE:0)
Block(3,-3,0,STONE:0)
Block(3,-3,1,STONE:0)
Block(3,-3,2,STONE:0)
Block(3,-3,3,STONE:0)
Block(3,-3,4,STONE:0)
Block(3,-3,5,STONE:0)
Block(3,-3,6,STONE:0)
Block(3,-3,7,STONE:0)
Block(3,-3,8,STONE:0)
Block(3,-3,9,STONE:0)
Block(3,-3,10,STONE:0)
Block(3,-2,-11,STONE:0)
Block(3,-2,-10,STONE:0)
Block(3,-2,-9,STONE:0)
Block(3,-2,-8,STONE:0)
Block(3,-2,-7,STONE:0)
Block(3,-2,-6,STONE:0)
Block(3,-2,-5,STONE:0)
Block(3,-2,-4,STONE:0)
Block(3,-2,-3,STONE:0)
Block(3,-2,-2,STONE:0)
Block(3,-2,-1,STONE:0)
Block(3,-2,0,STONE:0)
Block(3,-2,1,STONE:0)
Block(3,-2,2,STONE:0)
Block(3,-2,3,STONE:0)
Block(3,-2,4,STONE:0)
Block(3,-2,5,STONE:0)
Block(3,-2,6,STONE:0)
Block(3,-2,7,STONE:0)
Block(3,-2,8,STONE:0)
Block(3,-2,9,STONE:0)
Block(3,-2,10,STONE:0)
Block(3,-1,-11,DIRT:0)
Block(3,-1,-10,STONE:0)
Block(3,-1,-9,STONE:0)
Block(3,-1,-8,STONE:0)
Block(3,-1,-7,STONE:0)
Block(3,-1,-6,STONE:0)
Block(3,-1,-5,STONE:0)
Block(3,-1,-4,STONE:0)
Block(3,-1,-3,STONE:0)
Block(3,-1,-2,STONE:0)
Block(3,-1,-1,STONE:0)
Block(3,-1,0,STONE:0)
Block(3,-1,1,STONE:0)
Block(3,-1,2,STONE:0)
Block(3,-1,3,STONE:0)
Block(3,-1,4,STONE:0)
Block(3,-1,5,STONE:0)
Block(3,-1,6,STONE:0)
Block(3,-1,7,STONE:0)
Block(3,-1,8,STONE:0)
Block(3,-1,9,STONE:0)
Block(3,-1,10,STONE:0)
Block(3,0,-11,GRASS:0)
Block(3,0,-10,STONE:0)
Block(3,0,-9,STONE:0)
Block(3,0,-8,STONE:0)
Block(3,0,-7,STONE:0)
Block(3,0,-6,STONE:0)
Block(3,0,-5,STONE:0)
Block(3,0,-4,STONE:0)
Block(3,0,-3,STONE:0)
Block(3,0,-2,STONE:0)
Block(3,0,-1,STONE:0)
Block(3,0,0,STONE:0)
Block(3,0,1,STONE:0)
Block(3,0,2,STONE:0)
Block(3,0,3,STONE:0)
Block(3,0,4,STONE:0)
Block(3,0,5,STONE:0)
Block(3,0,6,STONE:0)
Block(3,0,7,STONE:0)
Block(3,0,8,STONE:0)
Block(3,0,9,STONE:0)
Block(3,0,10,DIRT:0)
Block(3,1,-10,DIRT:0)
Block(3,1,-9,STONE:0)
Block(3,1,-8,STONE:0)
Block(3,1,-7,STONE:0)
Block(3,1,-6,STONE:0)
Block(3,1,-5,STONE:0)
Block(3,1,-4,STONE:0)
Block(3,1,-3,STONE:0)
Block(3,1,-2,STONE:0)
Block(3,1,-1,STONE:0)
Block(3,1,0,STONE:0)
Block(3,1,1,STONE:0)
Block(3,1,2,STONE:0)
Block(3,1,3,STONE:0)
Block(3,1,4,STONE:0)
Block(3,1,5,STONE:0)
Block(3,1,6,STONE:0)
Block(3,1,7,STONE:0)
Block(3,1,8,STONE:0)
Block(3,1,9,STONE:0)
Block(3,1,10,DIRT:0)
Block(3,2,-10,GRASS:0)
Block(3,2,-9,STONE:0)
Block(3,2,-8,STONE:0)
Block(3,2,-7,STONE:0)
Block(3,2,-6,STONE:0)
Block(3,2,-5,STONE:0)
Block(3,2,-4,STONE:0)
Block(3,2,-3,STONE:0)
Block(3,2,-2,STONE:0)
Block(3,2,-1,STONE:0)
Block(3,2,0,STONE:0)
Block(3,2,1,STONE:0)
Block(3,2,2,STONE:0)
Block(3,2,3,STONE:0)
Block(3,2,4,STONE:0)
Block(3,2,5,STONE:0)
Block(3,2,6,STONE:0)
Block(3,2,7,STONE:0)
Block(3,2,8,STONE:0)
Block(3,2,9,STONE:0)
Block(3,2,10,GRASS:0)
Block(3,3,-9,GRASS:0)
Block(3,3,-8,STONE:0)
Block(3,3,-7,STONE:0)
Block(3,3,-6,STONE:0)
Block(3,3,-5,STONE:0)
Block(3,3,-4,STONE:0)
Block(3,3,-3,STONE:0)
Block(3,3,-2,STONE:0)
Block(3,3,-1,STONE:0)
Block(3,3,0,STONE:0)
Block(3,3,1,STONE:0)
Block(3,3,2,STONE:0)
Block(3,3,3,STONE:0)
Block(3,3,4,STONE:0)
Block(3,3,5,STONE:0)
Block(3,3,6,STONE:0)
Block(3,3,7,STONE:0)
Block(3,3,8,STONE:0)
Block(3,3,9,GRASS:0)
Block(3,4,-8,GRASS:0)
Block(3,4,-7,STONE:0)
Block(3,4,-6,STONE:0)
Block(3,4,-5,STONE:0)
Block(3,4,-4,STONE:0)
Block(3,4,-3,STONE:0)
Block(3,4,-2,STONE:0)
Block(3,4,-1,STONE:0)
Block(3,4,0,STONE:0)
Block(3,4,1,STONE:0)
Block(3,4,2,STONE:0)
Block(3,4,3,STONE:0)
Block(3,4,4,STONE:0)
Block(3,4,5,STONE:0)
Block(3,4,6,STONE:0)
Block(3,4,7,STONE:0)
Block(3,4,8,GRASS:0)
Block(3,5,-7,GRASS:0)
Block(3,5,-6,STONE:0)
Block(3,5,-5,STONE:0)
Block(3,5,-4,STONE:0)
Block(3,5,-3,STONE:0)
Block(3,5,-2,STONE:0)
Block(3,5,-1,STONE:0)
Block(3,5,0,STONE:0)
Block(3,5,1,STONE:0)
Block(3,5,2,STONE:0)
Block(3,5,3,STONE:0)
Block(3,5,4,STONE:0)
Block(3,5,5,GRASS:0)
Block(3,5,6,GRASS:0)
Block(3,5,7,GRASS:0)
Block(3,6,-6,GRASS:0)
Block(3,6,-5,STONE:0)
Block(3,6,-4,STONE:0)
Block(3,6,-3,STONE:0)
Block(3,6,-2,STONE:0)
Block(3,6,-1,STONE:0)
Block(3,6,0,STONE:0)
Block(3,6,1,STONE:0)
Block(3,6,2,STONE:0)
Block(3,6,3,STONE:0)
Block(3,6,4,GRASS:0)
Block(3,7,-5,GRASS:0)
Block(3,7,-4,STONE:0)
Block(3,7,-3,STONE:0)
Block(3,7,-2,STONE:0)
Block(3,7,-1,STONE:0)
Block(3,7,0,STONE:0)
Block(3,7,1,STONE:0)
Block(3,7,2,GRASS:0)
Block(3,7,3,GRASS:0)
Block(3,8,-4,GRASS:0)
Block(3,8,-3,STONE:0)
Block(3,8,-2,STONE:0)
Block(3,8,-1,STONE:0)
Block(3,8,0,GRASS:0)
Block(3,8,1,GRASS:0)
Block(3,9,-3,GRASS:0)
Block(3,9,-2,GRASS:0)
Block(3,9,-1,GRASS:0)
Block(4,-11,-1,STONE:0)
Block(4,-11,0,STONE:0)
Block(4,-11,1,STONE:0)
Block(4,-10,-3,STONE:0)
Block(4,-10,-2,STONE:0)
Block(4,-10,-1,STONE:0)
Block(4,-10,0,STONE:0)
Block(4,-10,1,STONE:0)
Block(4,-10,2,STONE:0)
Block(4,-9,-5,STONE:0)
Block(4,-9,-4,STONE:0)
Block(4,-9,-3,STONE:0)
Block(4,-9,-2,STONE:0)
Block(4,-9,-1,STONE:0)
Block(4,-9,0,STONE:0)
Block(4,-9,1,STONE:0)
Block(4,-9,2,STONE:0)
Block(4,-9,3,STONE:0)
Block(4,-8,-7,STONE:0)
Block(4,-8,-6,STONE:0)
Block(4,-8,-5,STONE:0)
Block(4,-8,-4,STONE:0)
Block(4,-8,-3,STONE:0)
Block(4,-8,-2,STONE:0)
Block(4,-8,-1,STONE:0)
Block(4,-8,0,STONE:0)
Block(4,-8,1,STONE:0)
Block(4,-8,2,STONE:0)
Block(4,-8,3,STONE:0)
Block(4,-8,4,STONE:0)
Block(4,-7,-8,STONE:0)
Block(4,-7,-7,STONE:0)
Block(4,-7,-6,STONE:0)
Block(4,-7,-5,STONE:0)
Block(4,-7,-4,STONE:0)
Block(4,-7,-3,STONE:0)
Block(4,-7,-2,STONE:0)
Block(4,-7,-1,STONE:0)
Block(4,-7,0,STONE:0)
Block(4,-7,1,STONE:0)
Block(4,-7,2,STONE:0)
Block(4,-7,3,STONE:0)
Block(4,-7,4,STONE:0)
Block(4,-7,5,STONE:0)
Block(4,-6,-9,STONE:0)
Block(4,-6,-8,STONE:0)
Block(4,-6,-7,STONE:0)
Block(4,-6,-6,STONE:0)
Block(4,-6,-5,STONE:0)
Block(4,-6,-4,STONE:0)
Block(4,-6,-3,STONE:0)
Block(4,-6,-2,STONE:0)
Block(4,-6,-1,STONE:0)
Block(4,-6,0,STONE:0)
Block(4,-6,1,STONE:0)
Block(4,-6,2,STONE:0)
Block(4,-6,3,STONE:0)
Block(4,-6,4,STONE:0)
Block(4,-6,5,STONE:0)
Block(4,-6,6,STONE:0)
Block(4,-5,-10,STONE:0)
Block(4,-5,-9,STONE:0)
Block(4,-5,-8,STONE:0)
Block(4,-5,-7,STONE:0)
Block(4,-5,-6,STONE:0)
Block(4,-5,-5,STONE:0)
Block(4,-5,-4,STONE:0)
Block(4,-5,-3,STONE:0)
Block(4,-5,-2,STONE:0)
Block(4,-5,-1,STONE:0)
Block(4,-5,0,STONE:0)
Block(4,-5,1,STONE:0)
Block(4,-5,2,STONE:0)
Block(4,-5,3,STONE:0)
Block(4,-5,4,STONE:0)
Block(4,-5,5,STONE:0)
Block(4,-5,6,STONE:0)
Block(4,-5,7,STONE:0)
Block(4,-4,-10,STONE:0)
Block(4,-4,-9,STONE:0)
Block(4,-4,-8,STONE:0)
Block(4,-4,-7,STONE:0)
Block(4,-4,-6,STONE:0)
Block(4,-4,-5,STONE:0)
Block(4,-4,-4,STONE:0)
Block(4,-4,-3,STONE:0)
Block(4,-4,-2,STONE:0)
Block(4,-4,-1,STONE:0)
Block(4,-4,0,STONE:0)
Block(4,-4,1,STONE:0)
Block(4,-4,2,STONE:0)
Block(4,-4,3,STONE:0)
Block(4,-4,4,STONE:0)
Block(4,-4,5,STONE:0)
Block(4,-4,6,STONE:0)
Block(4,-4,7,STONE:0)
Block(4,-4,8,STONE:0)
Block(4,-4,9,STONE:0)
Block(4,-3,-10,STONE:0)
Block(4,-3,-9,STONE:0)
Block(4,-3,-8,STONE:0)
Block(4,-3,-7,STONE:0)
Block(4,-3,-6,STONE:0)
Block(4,-3,-5,STONE:0)
Block(4,-3,-4,STONE:0)
Block(4,-3,-3,STONE:0)
Block(4,-3,-2,STONE:0)
Block(4,-3,-1,STONE:0)
Block(4,-3,0,STONE:0)
Block(4,-3,1,STONE:0)
Block(4,-3,2,STONE:0)
Block(4,-3,3,STONE:0)
Block(4,-3,4,STONE:0)
Block(4,-3,5,STONE:0)
Block(4,-3,6,STONE:0)
Block(4,-3,7,STONE:0)
Block(4,-3,8,STONE:0)
Block(4,-3,9,STONE:0)
Block(4,-2,-10,STONE:0)
Block(4,-2,-9,STONE:0)
Block(4,-2,-8,STONE:0)
Block(4,-2,-7,STONE:0)
Block(4,-2,-6,STONE:0)
Block(4,-2,-5,STONE:0)
Block(4,-2,-4,STONE:0)
Block(4,-2,-3,STONE:0)
Block(4,-2,-2,STONE:0)
Block(4,-2,-1,STONE:0)
Block(4,-2,0,STONE:0)
Block(4,-2,1,STONE:0)
Block(4,-2,2,STONE:0)
Block(4,-2,3,STONE:0)
Block(4,-2,4,STONE:0)
Block(4,-2,5,STONE:0)
Block(4,-2,6,STONE:0)
Block(4,-2,7,STONE:0)
Block(4,-2,8,STONE:0)
Block(4,-2,9,STONE:0)
Block(4,-2,10,STONE:0)
Block(4,-1,-10,DIRT:0)
Block(4,-1,-9,STONE:0)
Block(4,-1,-8,STONE:0)
Block(4,-1,-7,STONE:0)
Block(4,-1,-6,STONE:0)
Block(4,-1,-5,STONE:0)
Block(4,-1,-4,STONE:0)
Block(4,-1,-3,STONE:0)
Block(4,-1,-2,STONE:0)
Block(4,-1,-1,STONE:0)
Block(4,-1,0,STONE:0)
Block(4,-1,1,STONE:0)
Block(4,-1,2,STONE:0)
Block(4,-1,3,STONE:0)
Block(4,-1,4,STONE:0)
Block(4,-1,5,STONE:0)
Block(4,-1,6,STONE:0)
Block(4,-1,7,STONE:0)
Block(4,-1,8,STONE:0)
Block(4,-1,9,STONE:0)
Block(4,-1,10,STONE:0)
Block(4,0,-10,DIRT:0)
Block(4,0,-9,STONE:0)
Block(4,0,-8,STONE:0)
Block(4,0,-7,STONE:0)
Block(4,0,-6,STONE:0)
Block(4,0,-5,STONE:0)
Block(4,0,-4,STONE:0)
Block(4,0,-3,STONE:0)
Block(4,0,-2,STONE:0)
Block(4,0,-1,STONE:0)
Block(4,0,0,STONE:0)
Block(4,0,1,STONE:0)
Block(4,0,2,STONE:0)
Block(4,0,3,STONE:0)
Block(4,0,4,STONE:0)
Block(4,0,5,STONE:0)
Block(4,0,6,STONE:0)
Block(4,0,7,STONE:0)
Block(4,0,8,STONE:0)
Block(4,0,9,STONE:0)
Block(4,0,10,DIRT:0)
Block(4,1,-10,DIRT:0)
Block(4,1,-9,STONE:0)
Block(4,1,-8,STONE:0)
Block(4,1,-7,STONE:0)
Block(4,1,-6,STONE:0)
Block(4,1,-5,STONE:0)
Block(4,1,-4,STONE:0)
Block(4,1,-3,STONE:0)
Block(4,1,-2,STONE:0)
Block(4,1,-1,STONE:0)
Block(4,1,0,STONE:0)
Block(4,1,1,STONE:0)
Block(4,1,2,STONE:0)
Block(4,1,3,STONE:0)
Block(4,1,4,STONE:0)
Block(4,1,5,STONE:0)
Block(4,1,6,STONE:0)
Block(4,1,7,STONE:0)
Block(4,1,8,STONE:0)
Block(4,1,9,STONE:0)
Block(4,1,10,DIRT:0)
Block(4,2,-10,GRASS:0)
Block(4,2,-9,STONE:0)
Block(4,2,-8,STONE:0)
Block(4,2,-7,STONE:0)
Block(4,2,-6,STONE:0)
Block(4,2,-5,STONE:0)
Block(4,2,-4,STONE:0)
Block(4,2,-3,STONE:0)
Block(4,2,-2,STONE:0)
Block(4,2,-1,STONE:0)
Block(4,2,0,STONE:0)
Block(4,2,1,STONE:0)
Block(4,2,2,STONE:0)
Block(4,2,3,STONE:0)
Block(4,2,4,STONE:0)
Block(4,2,5,STONE:0)
Block(4,2,6,STONE:0)
Block(4,2,7,STONE:0)
Block(4,2,8,STONE:0)
Block(4,2,9,STONE:0)
Block(4,2,10,GRASS:0)
Block(4,3,-9,GRASS:0)
Block(4,3,-8,STONE:0)
Block(4,3,-7,STONE:0)
Block(4,3,-6,STONE:0)
Block(4,3,-5,STONE:0)
Block(4,3,-4,STONE:0)
Block(4,3,-3,STONE:0)
Block(4,3,-2,STONE:0)
Block(4,3,-1,STONE:0)
Block(4,3,0,STONE:0)
Block(4,3,1,STONE:0)
Block(4,3,2,STONE:0)
Block(4,3,3,STONE:0)
Block(4,3,4,STONE:0)
Block(4,3,5,STONE:0)
Block(4,3,6,STONE:0)
Block(4,3,7,STONE:0)
Block(4,3,8,STONE:0)
Block(4,3,9,GRASS:0)
Block(4,4,-8,GRASS:0)
Block(4,4,-7,STONE:0)
Block(4,4,-6,STONE:0)
Block(4,4,-5,STONE:0)
Block(4,4,-4,STONE:0)
Block(4,4,-3,STONE:0)
Block(4,4,-2,STONE:0)
Block(4,4,-1,STONE:0)
Block(4,4,0,STONE:0)
Block(4,4,1,STONE:0)
Block(4,4,2,STONE:0)
Block(4,4,3,STONE:0)
Block(4,4,4,STONE:0)
Block(4,4,5,STONE:0)
Block(4,4,6,STONE:0)
Block(4,4,7,GRASS:0)
Block(4,4,8,GRASS:0)
Block(4,5,-7,GRASS:0)
Block(4,5,-6,STONE:0)
Block(4,5,-5,STONE:0)
Block(4,5,-4,STONE:0)
Block(4,5,-3,STONE:0)
Block(4,5,-2,STONE:0)
Block(4,5,-1,STONE:0)
Block(4,5,0,STONE:0)
Block(4,5,1,STONE:0)
Block(4,5,2,STONE:0)
Block(4,5,3,STONE:0)
Block(4,5,4,STONE:0)
Block(4,5,5,GRASS:0)
Block(4,5,6,GRASS:0)
Block(4,6,-6,GRASS:0)
Block(4,6,-5,STONE:0)
Block(4,6,-4,STONE:0)
Block(4,6,-3,STONE:0)
Block(4,6,-2,STONE:0)
Block(4,6,-1,STONE:0)
Block(4,6,0,STONE:0)
Block(4,6,1,STONE:0)
Block(4,6,2,STONE:0)
Block(4,6,3,STONE:0)
Block(4,6,4,GRASS:0)
Block(4,7,-5,GRASS:0)
Block(4,7,-4,STONE:0)
Block(4,7,-3,STONE:0)
Block(4,7,-2,STONE:0)
Block(4,7,-1,STONE:0)
Block(4,7,0,STONE:0)
Block(4,7,1,GRASS:0)
Block(4,7,2,GRASS:0)
Block(4,7,3,GRASS:0)
Block(4,8,-4,GRASS:0)
Block(4,8,-3,STONE:0)
Block(4,8,-2,STONE:0)
Block(4,8,-1,GRASS:0)
Block(4,8,0,GRASS:0)
Block(4,9,-3,GRASS:0)
Block(4,9,-2,GRASS:0)
Block(5,-11,-1,STONE:0)
Block(5,-11,0,STONE:0)
Block(5,-10,-3,STONE:0)
Block(5,-10,-2,STONE:0)
Block(5,-10,-1,STONE:0)
Block(5,-10,0,STONE:0)
Block(5,-10,1,STONE:0)
Block(5,-10,2,STONE:0)
Block(5,-9,-5,STONE:0)
Block(5,-9,-4,STONE:0)
Block(5,-9,-3,STONE:0)
Block(5,-9,-2,STONE:0)
Block(5,-9,-1,STONE:0)
Block(5,-9,0,STONE:0)
Block(5,-9,1,STONE:0)
Block(5,-9,2,STONE:0)
Block(5,-9,3,STONE:0)
Block(5,-8,-7,STONE:0)
Block(5,-8,-6,STONE:0)
Block(5,-8,-5,STONE:0)
Block(5,-8,-4,STONE:0)
Block(5,-8,-3,STONE:0)
Block(5,-8,-2,STONE:0)
Block(5,-8,-1,STONE:0)
Block(5,-8,0,STONE:0)
Block(5,-8,1,STONE:0)
Block(5,-8,2,STONE:0)
Block(5,-8,3,STONE:0)
Block(5,-8,4,STONE:0)
Block(5,-7,-8,STONE:0)
Block(5,-7,-7,STONE:0)
Block(5,-7,-6,STONE:0)
Block(5,-7,-5,STONE:0)
Block(5,-7,-4,STONE:0)
Block(5,-7,-3,STONE:0)
Block(5,-7,-2,STONE:0)
Block(5,-7,-1,STONE:0)
Block(5,-7,0,STONE:0)
Block(5,-7,1,STONE:0)
Block(5,-7,2,STONE:0)
Block(5,-7,3,STONE:0)
Block(5,-7,4,STONE:0)
Block(5,-7,5,STONE:0)
Block(5,-6,-9,STONE:0)
Block(5,-6,-8,STONE:0)
Block(5,-6,-7,STONE:0)
Block(5,-6,-6,STONE:0)
Block(5,-6,-5,STONE:0)
Block(5,-6,-4,STONE:0)
Block(5,-6,-3,STONE:0)
Block(5,-6,-2,STONE:0)
Block(5,-6,-1,STONE:0)
Block(5,-6,0,STONE:0)
Block(5,-6,1,STONE:0)
Block(5,-6,2,STONE:0)
Block(5,-6,3,STONE:0)
Block(5,-6,4,STONE:0)
Block(5,-6,5,STONE:0)
Block(5,-6,6,STONE:0)
Block(5,-5,-9,STONE:0)
Block(5,-5,-8,STONE:0)
Block(5,-5,-7,STONE:0)
Block(5,-5,-6,STONE:0)
Block(5,-5,-5,STONE:0)
Block(5,-5,-4,STONE:0)
Block(5,-5,-3,STONE:0)
Block(5,-5,-2,STONE:0)
Block(5,-5,-1,STONE:0)
Block(5,-5,0,STONE:0)
Block(5,-5,1,STONE:0)
Block(5,-5,2,STONE:0)
Block(5,-5,3,STONE:0)
Block(5,-5,4,STONE:0)
Block(5,-5,5,STONE:0)
Block(5,-5,6,STONE:0)
Block(5,-5,7,STONE:0)
Block(5,-4,-9,STONE:0)
Block(5,-4,-8,STONE:0)
Block(5,-4,-7,STONE:0)
Block(5,-4,-6,STONE:0)
Block(5,-4,-5,STONE:0)
Block(5,-4,-4,STONE:0)
Block(5,-4,-3,STONE:0)
Block(5,-4,-2,STONE:0)
Block(5,-4,-1,STONE:0)
Block(5,-4,0,STONE:0)
Block(5,-4,1,STONE:0)
Block(5,-4,2,STONE:0)
Block(5,-4,3,STONE:0)
Block(5,-4,4,STONE:0)
Block(5,-4,5,STONE:0)
Block(5,-4,6,STONE:0)
Block(5,-4,7,STONE:0)
Block(5,-4,8,STONE:0)
Block(5,-3,-9,STONE:0)
Block(5,-3,-8,STONE:0)
Block(5,-3,-7,STONE:0)
Block(5,-3,-6,STONE:0)
Block(5,-3,-5,STONE:0)
Block(5,-3,-4,STONE:0)
Block(5,-3,-3,STONE:0)
Block(5,-3,-2,STONE:0)
Block(5,-3,-1,STONE:0)
Block(5,-3,0,STONE:0)
Block(5,-3,1,STONE:0)
Block(5,-3,2,STONE:0)
Block(5,-3,3,STONE:0)
Block(5,-3,4,STONE:0)
Block(5,-3,5,STONE:0)
Block(5,-3,6,STONE:0)
Block(5,-3,7,STONE:0)
Block(5,-3,8,STONE:0)
Block(5,-3,9,STONE:0)
Block(5,-2,-9,STONE:0)
Block(5,-2,-8,STONE:0)
Block(5,-2,-7,STONE:0)
Block(5,-2,-6,STONE:0)
Block(5,-2,-5,STONE:0)
Block(5,-2,-4,STONE:0)
Block(5,-2,-3,STONE:0)
Block(5,-2,-2,STONE:0)
Block(5,-2,-1,STONE:0)
Block(5,-2,0,STONE:0)
Block(5,-2,1,STONE:0)
Block(5,-2,2,STONE:0)
Block(5,-2,3,STONE:0)
Block(5,-2,4,STONE:0)
Block(5,-2,5,STONE:0)
Block(5,-2,6,STONE:0)
Block(5,-2,7,STONE:0)
Block(5,-2,8,STONE:0)
Block(5,-2,9,STONE:0)
Block(5,-2,10,STONE:0)
Block(5,-1,-9,DIRT:0)
Block(5,-1,-8,STONE:0)
Block(5,-1,-7,STONE:0)
Block(5,-1,-6,STONE:0)
Block(5,-1,-5,STONE:0)
Block(5,-1,-4,STONE:0)
Block(5,-1,-3,STONE:0)
Block(5,-1,-2,STONE:0)
Block(5,-1,-1,STONE:0)
Block(5,-1,0,STONE:0)
Block(5,-1,1,STONE:0)
Block(5,-1,2,STONE:0)
Block(5,-1,3,STONE:0)
Block(5,-1,4,STONE:0)
Block(5,-1,5,STONE:0)
Block(5,-1,6,STONE:0)
Block(5,-1,7,STONE:0)
Block(5,-1,8,STONE:0)
Block(5,-1,9,STONE:0)
Block(5,-1,10,STONE:0)
Block(5,0,-10,DIRT:0)
Block(5,0,-9,STONE:0)
Block(5,0,-8,STONE:0)
Block(5,0,-7,STONE:0)
Block(5,0,-6,STONE:0)
Block(5,0,-5,STONE:0)
Block(5,0,-4,STONE:0)
Block(5,0,-3,STONE:0)
Block(5,0,-2,STONE:0)
Block(5,0,-1,STONE:0)
Block(5,0,0,STONE:0)
Block(5,0,1,STONE:0)
Block(5,0,2,STONE:0)
Block(5,0,3,STONE:0)
Block(5,0,4,STONE:0)
Block(5,0,5,STONE:0)
Block(5,0,6,STONE:0)
Block(5,0,7,STONE:0)
Block(5,0,8,STONE:0)
Block(5,0,9,STONE:0)
Block(5,0,10,STONE:0)
Block(5,1,-10,GRASS:0)
Block(5,1,-9,STONE:0)
Block(5,1,-8,STONE:0)
Block(5,1,-7,STONE:0)
Block(5,1,-6,STONE:0)
Block(5,1,-5,STONE:0)
Block(5,1,-4,STONE:0)
Block(5,1,-3,STONE:0)
Block(5,1,-2,STONE:0)
Block(5,1,-1,STONE:0)
Block(5,1,0,STONE:0)
Block(5,1,1,STONE:0)
Block(5,1,2,STONE:0)
Block(5,1,3,STONE:0)
Block(5,1,4,STONE:0)
Block(5,1,5,STONE:0)
Block(5,1,6,STONE:0)
Block(5,1,7,STONE:0)
Block(5,1,8,STONE:0)
Block(5,1,9,STONE:0)
Block(5,1,10,GRASS:0)
Block(5,2,-9,DIRT:0)
Block(5,2,-8,STONE:0)
Block(5,2,-7,STONE:0)
Block(5,2,-6,STONE:0)
Block(5,2,-5,STONE:0)
Block(5,2,-4,STONE:0)
Block(5,2,-3,STONE:0)
Block(5,2,-2,STONE:0)
Block(5,2,-1,STONE:0)
Block(5,2,0,STONE:0)
Block(5,2,1,STONE:0)
Block(5,2,2,STONE:0)
Block(5,2,3,STONE:0)
Block(5,2,4,STONE:0)
Block(5,2,5,STONE:0)
Block(5,2,6,STONE:0)
Block(5,2,7,STONE:0)
Block(5,2,8,STONE:0)
Block(5,2,9,DIRT:0)
Block(5,3,-9,GRASS:0)
Block(5,3,-8,STONE:0)
Block(5,3,-7,STONE:0)
Block(5,3,-6,STONE:0)
Block(5,3,-5,STONE:0)
Block(5,3,-4,STONE:0)
Block(5,3,-3,STONE:0)
Block(5,3,-2,STONE:0)
Block(5,3,-1,STONE:0)
Block(5,3,0,STONE:0)
Block(5,3,1,STONE:0)
Block(5,3,2,STONE:0)
Block(5,3,3,STONE:0)
Block(5,3,4,STONE:0)
Block(5,3,5,STONE:0)
Block(5,3,6,STONE:0)
Block(5,3,7,STONE:0)
Block(5,3,8,STONE:0)
Block(5,3,9,GRASS:0)
Block(5,4,-8,GRASS:0)
Block(5,4,-7,STONE:0)
Block(5,4,-6,STONE:0)
Block(5,4,-5,STONE:0)
Block(5,4,-4,STONE:0)
Block(5,4,-3,STONE:0)
Block(5,4,-2,STONE:0)
Block(5,4,-1,STONE:0)
Block(5,4,0,STONE:0)
Block(5,4,1,STONE:0)
Block(5,4,2,STONE:0)
Block(5,4,3,STONE:0)
Block(5,4,4,STONE:0)
Block(5,4,5,STONE:0)
Block(5,4,6,STONE:0)
Block(5,4,7,GRASS:0)
Block(5,4,8,GRASS:0)
Block(5,5,-7,DIRT:0)
Block(5,5,-6,STONE:0)
Block(5,5,-5,STONE:0)
Block(5,5,-4,STONE:0)
Block(5,5,-3,STONE:0)
Block(5,5,-2,STONE:0)
Block(5,5,-1,STONE:0)
Block(5,5,0,STONE:0)
Block(5,5,1,STONE:0)
Block(5,5,2,STONE:0)
Block(5,5,3,STONE:0)
Block(5,5,4,STONE:0)
Block(5,5,5,GRASS:0)
Block(5,5,6,GRASS:0)
Block(5,6,-7,GRASS:0)
Block(5,6,-6,STONE:0)
Block(5,6,-5,STONE:0)
Block(5,6,-4,STONE:0)
Block(5,6,-3,STONE:0)
Block(5,6,-2,STONE:0)
Block(5,6,-1,STONE:0)
Block(5,6,0,STONE:0)
Block(5,6,1,STONE:0)
Block(5,6,2,STONE:0)
Block(5,6,3,STONE:0)
Block(5,6,4,GRASS:0)
Block(5,7,-6,GRASS:0)
Block(5,7,-5,GRASS:0)
Block(5,7,-4,STONE:0)
Block(5,7,-3,STONE:0)
Block(5,7,-2,STONE:0)
Block(5,7,-1,STONE:0)
Block(5,7,0,STONE:0)
Block(5,7,1,GRASS:0)
Block(5,7,2,GRASS:0)
Block(5,7,3,GRASS:0)
Block(5,8,-4,GRASS:0)
Block(5,8,-3,STONE:0)
Block(5,8,-2,STONE:0)
Block(5,8,-1,GRASS:0)
Block(5,8,0,GRASS:0)
Block(5,9,-3,GRASS:0)
Block(5,9,-2,GRASS:0)
Block(6,-11,-1,STONE:0)
Block(6,-11,0,STONE:0)
Block(6,-10,-3,STONE:0)
Block(6,-10,-2,STONE:0)
Block(6,-10,-1,STONE:0)
Block(6,-10,0,STONE:0)
Block(6,-10,1,STONE:0)
Block(6,-10,2,STONE:0)
Block(6,-9,-5,STONE:0)
Block(6,-9,-4,STONE:0)
Block(6,-9,-3,STONE:0)
Block(6,-9,-2,STONE:0)
Block(6,-9,-1,STONE:0)
Block(6,-9,0,STONE:0)
Block(6,-9,1,STONE:0)
Block(6,-9,2,STONE:0)
Block(6,-9,3,STONE:0)
Block(6,-8,-6,STONE:0)
Block(6,-8,-5,STONE:0)
Block(6,-8,-4,STONE:0)
Block(6,-8,-3,STONE:0)
Block(6,-8,-2,STONE:0)
Block(6,-8,-1,STONE:0)
Block(6,-8,0,STONE:0)
Block(6,-8,1,STONE:0)
Block(6,-8,2,STONE:0)
Block(6,-8,3,STONE:0)
Block(6,-8,4,STONE:0)
Block(6,-7,-7,STONE:0)
Block(6,-7,-6,STONE:0)
Block(6,-7,-5,STONE:0)
Block(6,-7,-4,STONE:0)
Block(6,-7,-3,STONE:0)
Block(6,-7,-2,STONE:0)
Block(6,-7,-1,STONE:0)
Block(6,-7,0,STONE:0)
Block(6,-7,1,STONE:0)
Block(6,-7,2,STONE:0)
Block(6,-7,3,STONE:0)
Block(6,-7,4,STONE:0)
Block(6,-7,5,STONE:0)
Block(6,-6,-8,STONE:0)
Block(6,-6,-7,STONE:0)
Block(6,-6,-6,STONE:0)
Block(6,-6,-5,STONE:0)
Block(6,-6,-4,STONE:0)
Block(6,-6,-3,STONE:0)
Block(6,-6,-2,STONE:0)
Block(6,-6,-1,STONE:0)
Block(6,-6,0,STONE:0)
Block(6,-6,1,STONE:0)
Block(6,-6,2,STONE:0)
Block(6,-6,3,STONE:0)
Block(6,-6,4,STONE:0)
Block(6,-6,5,STONE:0)
Block(6,-6,6,STONE:0)
Block(6,-5,-8,STONE:0)
Block(6,-5,-7,STONE:0)
Block(6,-5,-6,STONE:0)
Block(6,-5,-5,STONE:0)
Block(6,-5,-4,STONE:0)
Block(6,-5,-3,STONE:0)
Block(6,-5,-2,STONE:0)
Block(6,-5,-1,STONE:0)
Block(6,-5,0,STONE:0)
Block(6,-5,1,STONE:0)
Block(6,-5,2,STONE:0)
Block(6,-5,3,STONE:0)
Block(6,-5,4,STONE:0)
Block(6,-5,5,STONE:0)
Block(6,-5,6,STONE:0)
Block(6,-5,7,STONE:0)
Block(6,-4,-8,STONE:0)
Block(6,-4,-7,STONE:0)
Block(6,-4,-6,STONE:0)
Block(6,-4,-5,STONE:0)
Block(6,-4,-4,STONE:0)
Block(6,-4,-3,STONE:0)
Block(6,-4,-2,STONE:0)
Block(6,-4,-1,STONE:0)
Block(6,-4,0,STONE:0)
Block(6,-4,1,STONE:0)
Block(6,-4,2,STONE:0)
Block(6,-4,3,STONE:0)
Block(6,-4,4,STONE:0)
Block(6,-4,5,STONE:0)
Block(6,-4,6,STONE:0)
Block(6,-4,7,STONE:0)
Block(6,-4,8,STONE:0)
Block(6,-3,-8,STONE:0)
Block(6,-3,-7,STONE:0)
Block(6,-3,-6,STONE:0)
Block(6,-3,-5,STONE:0)
Block(6,-3,-4,STONE:0)
Block(6,-3,-3,STONE:0)
Block(6,-3,-2,STONE:0)
Block(6,-3,-1,STONE:0)
Block(6,-3,0,STONE:0)
Block(6,-3,1,STONE:0)
Block(6,-3,2,STONE:0)
Block(6,-3,3,STONE:0)
Block(6,-3,4,STONE:0)
Block(6,-3,5,STONE:0)
Block(6,-3,6,STONE:0)
Block(6,-3,7,STONE:0)
Block(6,-3,8,STONE:0)
Block(6,-3,9,STONE:0)
Block(6,-2,-8,STONE:0)
Block(6,-2,-7,STONE:0)
Block(6,-2,-6,STONE:0)
Block(6,-2,-5,STONE:0)
Block(6,-2,-4,STONE:0)
Block(6,-2,-3,STONE:0)
Block(6,-2,-2,STONE:0)
Block(6,-2,-1,STONE:0)
Block(6,-2,0,STONE:0)
Block(6,-2,1,STONE:0)
Block(6,-2,2,STONE:0)
Block(6,-2,3,STONE:0)
Block(6,-2,4,STONE:0)
Block(6,-2,5,STONE:0)
Block(6,-2,6,STONE:0)
Block(6,-2,7,STONE:0)
Block(6,-2,8,STONE:0)
Block(6,-2,9,STONE:0)
Block(6,-1,-9,STONE:0)
Block(6,-1,-8,STONE:0)
Block(6,-1,-7,STONE:0)
Block(6,-1,-6,STONE:0)
Block(6,-1,-5,STONE:0)
Block(6,-1,-4,STONE:0)
Block(6,-1,-3,STONE:0)
Block(6,-1,-2,STONE:0)
Block(6,-1,-1,STONE:0)
Block(6,-1,0,STONE:0)
Block(6,-1,1,STONE:0)
Block(6,-1,2,STONE:0)
Block(6,-1,3,STONE:0)
Block(6,-1,4,STONE:0)
Block(6,-1,5,STONE:0)
Block(6,-1,6,STONE:0)
Block(6,-1,7,STONE:0)
Block(6,-1,8,STONE:0)
Block(6,-1,9,STONE:0)
Block(6,0,-9,DIRT:0)
Block(6,0,-8,STONE:0)
Block(6,0,-7,STONE:0)
Block(6,0,-6,STONE:0)
Block(6,0,-5,STONE:0)
Block(6,0,-4,STONE:0)
Block(6,0,-3,STONE:0)
Block(6,0,-2,STONE:0)
Block(6,0,-1,STONE:0)
Block(6,0,0,STONE:0)
Block(6,0,1,STONE:0)
Block(6,0,2,STONE:0)
Block(6,0,3,STONE:0)
Block(6,0,4,STONE:0)
Block(6,0,5,STONE:0)
Block(6,0,6,STONE:0)
Block(6,0,7,STONE:0)
Block(6,0,8,STONE:0)
Block(6,0,9,STONE:0)
Block(6,1,-9,DIRT:0)
Block(6,1,-8,STONE:0)
Block(6,1,-7,STONE:0)
Block(6,1,-6,STONE:0)
Block(6,1,-5,STONE:0)
Block(6,1,-4,STONE:0)
Block(6,1,-3,STONE:0)
Block(6,1,-2,STONE:0)
Block(6,1,-1,STONE:0)
Block(6,1,0,STONE:0)
Block(6,1,1,STONE:0)
Block(6,1,2,STONE:0)
Block(6,1,3,STONE:0)
Block(6,1,4,STONE:0)
Block(6,1,5,STONE:0)
Block(6,1,6,STONE:0)
Block(6,1,7,STONE:0)
Block(6,1,8,STONE:0)
Block(6,1,9,STONE:0)
Block(6,2,-9,GRASS:0)
Block(6,2,-8,STONE:0)
Block(6,2,-7,STONE:0)
Block(6,2,-6,STONE:0)
Block(6,2,-5,STONE:0)
Block(6,2,-4,STONE:0)
Block(6,2,-3,STONE:0)
Block(6,2,-2,STONE:0)
Block(6,2,-1,STONE:0)
Block(6,2,0,STONE:0)
Block(6,2,1,STONE:0)
Block(6,2,2,STONE:0)
Block(6,2,3,STONE:0)
Block(6,2,4,STONE:0)
Block(6,2,5,STONE:0)
Block(6,2,6,STONE:0)
Block(6,2,7,STONE:0)
Block(6,2,8,STONE:0)
Block(6,2,9,GRASS:0)
Block(6,3,-8,DIRT:0)
Block(6,3,-7,STONE:0)
Block(6,3,-6,STONE:0)
Block(6,3,-5,STONE:0)
Block(6,3,-4,STONE:0)
Block(6,3,-3,STONE:0)
Block(6,3,-2,STONE:0)
Block(6,3,-1,STONE:0)
Block(6,3,0,STONE:0)
Block(6,3,1,STONE:0)
Block(6,3,2,STONE:0)
Block(6,3,3,STONE:0)
Block(6,3,4,STONE:0)
Block(6,3,5,STONE:0)
Block(6,3,6,STONE:0)
Block(6,3,7,STONE:0)
Block(6,3,8,GRASS:0)
Block(6,4,-8,DIRT:0)
Block(6,4,-7,STONE:0)
Block(6,4,-6,STONE:0)
Block(6,4,-5,STONE:0)
Block(6,4,-4,STONE:0)
Block(6,4,-3,STONE:0)
Block(6,4,-2,STONE:0)
Block(6,4,-1,STONE:0)
Block(6,4,0,STONE:0)
Block(6,4,1,STONE:0)
Block(6,4,2,STONE:0)
Block(6,4,3,STONE:0)
Block(6,4,4,STONE:0)
Block(6,4,5,STONE:0)
Block(6,4,6,STONE:0)
Block(6,4,7,GRASS:0)
Block(6,5,-8,GRASS:0)
Block(6,5,-7,STONE:0)
Block(6,5,-6,STONE:0)
Block(6,5,-5,STONE:0)
Block(6,5,-4,STONE:0)
Block(6,5,-3,STONE:0)
Block(6,5,-2,STONE:0)
Block(6,5,-1,STONE:0)
Block(6,5,0,STONE:0)
Block(6,5,1,STONE:0)
Block(6,5,2,STONE:0)
Block(6,5,3,STONE:0)
Block(6,5,4,STONE:0)
Block(6,5,5,GRASS:0)
Block(6,5,6,GRASS:0)
Block(6,6,-7,GRASS:0)
Block(6,6,-6,STONE:0)
Block(6,6,-5,STONE:0)
Block(6,6,-4,STONE:0)
Block(6,6,-3,STONE:0)
Block(6,6,-2,STONE:0)
Block(6,6,-1,STONE:0)
Block(6,6,0,STONE:0)
Block(6,6,1,STONE:0)
Block(6,6,2,STONE:0)
Block(6,6,3,GRASS:0)
Block(6,6,4,GRASS:0)
Block(6,7,-6,GRASS:0)
Block(6,7,-5,STONE:0)
Block(6,7,-4,STONE:0)
Block(6,7,-3,STONE:0)
Block(6,7,-2,STONE:0)
Block(6,7,-1,STONE:0)
Block(6,7,0,STONE:0)
Block(6,7,1,GRASS:0)
Block(6,7,2,GRASS:0)
Block(6,8,-5,GRASS:0)
Block(6,8,-4,GRASS:0)
Block(6,8,-3,STONE:0)
Block(6,8,-2,STONE:0)
Block(6,8,-1,GRASS:0)
Block(6,8,0,GRASS:0)
Block(6,9,-3,GRASS:0)
Block(6,9,-2,GRASS:0)
Block(7,-11,-1,STONE:0)
Block(7,-11,0,STONE:0)
Block(7,-10,-3,STONE:0)
Block(7,-10,-2,STONE:0)
Block(7,-10,-1,STONE:0)
Block(7,-10,0,STONE:0)
Block(7,-10,1,STONE:0)
Block(7,-9,-5,STONE:0)
Block(7,-9,-4,STONE:0)
Block(7,-9,-3,STONE:0)
Block(7,-9,-2,STONE:0)
Block(7,-9,-1,STONE:0)
Block(7,-9,0,STONE:0)
Block(7,-9,1,STONE:0)
Block(7,-9,2,STONE:0)
Block(7,-8,-6,STONE:0)
Block(7,-8,-5,STONE:0)
Block(7,-8,-4,STONE:0)
Block(7,-8,-3,STONE:0)
Block(7,-8,-2,STONE:0)
Block(7,-8,-1,STONE:0)
Block(7,-8,0,STONE:0)
Block(7,-8,1,STONE:0)
Block(7,-8,2,STONE:0)
Block(7,-8,3,STONE:0)
Block(7,-7,-7,STONE:0)
Block(7,-7,-6,STONE:0)
Block(7,-7,-5,STONE:0)
Block(7,-7,-4,STONE:0)
Block(7,-7,-3,STONE:0)
Block(7,-7,-2,STONE:0)
Block(7,-7,-1,STONE:0)
Block(7,-7,0,STONE:0)
Block(7,-7,1,STONE:0)
Block(7,-7,2,STONE:0)
Block(7,-7,3,STONE:0)
Block(7,-7,4,STONE:0)
Block(7,-6,-7,STONE:0)
Block(7,-6,-6,STONE:0)
Block(7,-6,-5,STONE:0)
Block(7,-6,-4,STONE:0)
Block(7,-6,-3,STONE:0)
Block(7,-6,-2,STONE:0)
Block(7,-6,-1,STONE:0)
Block(7,-6,0,STONE:0)
Block(7,-6,1,STONE:0)
Block(7,-6,2,STONE:0)
Block(7,-6,3,STONE:0)
Block(7,-6,4,STONE:0)
Block(7,-6,5,STONE:0)
Block(7,-6,6,STONE:0)
Block(7,-5,-7,STONE:0)
Block(7,-5,-6,STONE:0)
Block(7,-5,-5,STONE:0)
Block(7,-5,-4,STONE:0)
Block(7,-5,-3,STONE:0)
Block(7,-5,-2,STONE:0)
Block(7,-5,-1,STONE:0)
Block(7,-5,0,STONE:0)
Block(7,-5,1,STONE:0)
Block(7,-5,2,STONE:0)
Block(7,-5,3,STONE:0)
Block(7,-5,4,STONE:0)
Block(7,-5,5,STONE:0)
Block(7,-5,6,STONE:0)
Block(7,-5,7,STONE:0)
Block(7,-4,-7,STONE:0)
Block(7,-4,-6,STONE:0)
Block(7,-4,-5,STONE:0)
Block(7,-4,-4,STONE:0)
Block(7,-4,-3,STONE:0)
Block(7,-4,-2,STONE:0)
Block(7,-4,-1,STONE:0)
Block(7,-4,0,STONE:0)
Block(7,-4,1,STONE:0)
Block(7,-4,2,STONE:0)
Block(7,-4,3,STONE:0)
Block(7,-4,4,STONE:0)
Block(7,-4,5,STONE:0)
Block(7,-4,6,STONE:0)
Block(7,-4,7,STONE:0)
Block(7,-3,-7,STONE:0)
Block(7,-3,-6,STONE:0)
Block(7,-3,-5,STONE:0)
Block(7,-3,-4,STONE:0)
Block(7,-3,-3,STONE:0)
Block(7,-3,-2,STONE:0)
Block(7,-3,-1,STONE:0)
Block(7,-3,0,STONE:0)
Block(7,-3,1,STONE:0)
Block(7,-3,2,STONE:0)
Block(7,-3,3,STONE:0)
Block(7,-3,4,STONE:0)
Block(7,-3,5,STONE:0)
Block(7,-3,6,STONE:0)
Block(7,-3,7,STONE:0)
Block(7,-3,8,STONE:0)
Block(7,-2,-7,STONE:0)
Block(7,-2,-6,STONE:0)
Block(7,-2,-5,STONE:0)
Block(7,-2,-4,STONE:0)
Block(7,-2,-3,STONE:0)
Block(7,-2,-2,STONE:0)
Block(7,-2,-1,STONE:0)
Block(7,-2,0,STONE:0)
Block(7,-2,1,STONE:0)
Block(7,-2,2,STONE:0)
Block(7,-2,3,STONE:0)
Block(7,-2,4,STONE:0)
Block(7,-2,5,STONE:0)
Block(7,-2,6,STONE:0)
Block(7,-2,7,STONE:0)
Block(7,-2,8,STONE:0)
Block(7,-1,-7,STONE:0)
Block(7,-1,-6,STONE:0)
Block(7,-1,-5,STONE:0)
Block(7,-1,-4,STONE:0)
Block(7,-1,-3,STONE:0)
Block(7,-1,-2,STONE:0)
Block(7,-1,-1,STONE:0)
Block(7,-1,0,STONE:0)
Block(7,-1,1,STONE:0)
Block(7,-1,2,STONE:0)
Block(7,-1,3,STONE:0)
Block(7,-1,4,STONE:0)
Block(7,-1,5,STONE:0)
Block(7,-1,6,STONE:0)
Block(7,-1,7,STONE:0)
Block(7,-1,8,STONE:0)
Block(7,0,-8,STONE:0)
Block(7,0,-7,STONE:0)
Block(7,0,-6,STONE:0)
Block(7,0,-5,STONE:0)
Block(7,0,-4,STONE:0)
Block(7,0,-3,STONE:0)
Block(7,0,-2,STONE:0)
Block(7,0,-1,STONE:0)
Block(7,0,0,STONE:0)
Block(7,0,1,STONE:0)
Block(7,0,2,STONE:0)
Block(7,0,3,STONE:0)
Block(7,0,4,STONE:0)
Block(7,0,5,STONE:0)
Block(7,0,6,STONE:0)
Block(7,0,7,STONE:0)
Block(7,0,8,STONE:0)
Block(7,1,-8,STONE:0)
Block(7,1,-7,STONE:0)
Block(7,1,-6,STONE:0)
Block(7,1,-5,STONE:0)
Block(7,1,-4,STONE:0)
Block(7,1,-3,STONE:0)
Block(7,1,-2,STONE:0)
Block(7,1,-1,STONE:0)
Block(7,1,0,STONE:0)
Block(7,1,1,STONE:0)
Block(7,1,2,STONE:0)
Block(7,1,3,STONE:0)
Block(7,1,4,STONE:0)
Block(7,1,5,STONE:0)
Block(7,1,6,STONE:0)
Block(7,1,7,STONE:0)
Block(7,1,8,STONE:0)
Block(7,2,-8,STONE:0)
Block(7,2,-7,STONE:0)
Block(7,2,-6,STONE:0)
Block(7,2,-5,STONE:0)
Block(7,2,-4,STONE:0)
Block(7,2,-3,STONE:0)
Block(7,2,-2,STONE:0)
Block(7,2,-1,STONE:0)
Block(7,2,0,STONE:0)
Block(7,2,1,STONE:0)
Block(7,2,2,STONE:0)
Block(7,2,3,STONE:0)
Block(7,2,4,STONE:0)
Block(7,2,5,STONE:0)
Block(7,2,6,STONE:0)
Block(7,2,7,DIRT:0)
Block(7,2,8,STONE:0)
Block(7,3,-8,DIRT:0)
Block(7,3,-7,STONE:0)
Block(7,3,-6,STONE:0)
Block(7,3,-5,STONE:0)
Block(7,3,-4,STONE:0)
Block(7,3,-3,STONE:0)
Block(7,3,-2,STONE:0)
Block(7,3,-1,STONE:0)
Block(7,3,0,STONE:0)
Block(7,3,1,STONE:0)
Block(7,3,2,STONE:0)
Block(7,3,3,STONE:0)
Block(7,3,4,STONE:0)
Block(7,3,5,STONE:0)
Block(7,3,6,STONE:0)
Block(7,3,7,DIRT:0)
Block(7,4,-8,GRASS:0)
Block(7,4,-7,STONE:0)
Block(7,4,-6,STONE:0)
Block(7,4,-5,STONE:0)
Block(7,4,-4,STONE:0)
Block(7,4,-3,STONE:0)
Block(7,4,-2,STONE:0)
Block(7,4,-1,STONE:0)
Block(7,4,0,STONE:0)
Block(7,4,1,STONE:0)
Block(7,4,2,STONE:0)
Block(7,4,3,STONE:0)
Block(7,4,4,STONE:0)
Block(7,4,5,STONE:0)
Block(7,4,6,GRASS:0)
Block(7,4,7,GRASS:0)
Block(7,5,-7,DIRT:0)
Block(7,5,-6,STONE:0)
Block(7,5,-5,STONE:0)
Block(7,5,-4,STONE:0)
Block(7,5,-3,STONE:0)
Block(7,5,-2,STONE:0)
Block(7,5,-1,STONE:0)
Block(7,5,0,STONE:0)
Block(7,5,1,STONE:0)
Block(7,5,2,STONE:0)
Block(7,5,3,STONE:0)
Block(7,5,4,GRASS:0)
Block(7,5,5,GRASS:0)
Block(7,6,-7,GRASS:0)
Block(7,6,-6,STONE:0)
Block(7,6,-5,STONE:0)
Block(7,6,-4,STONE:0)
Block(7,6,-3,STONE:0)
Block(7,6,-2,STONE:0)
Block(7,6,-1,STONE:0)
Block(7,6,0,STONE:0)
Block(7,6,1,STONE:0)
Block(7,6,2,STONE:0)
Block(7,6,3,GRASS:0)
Block(7,7,-6,GRASS:0)
Block(7,7,-5,STONE:0)
Block(7,7,-4,STONE:0)
Block(7,7,-3,STONE:0)
Block(7,7,-2,STONE:0)
Block(7,7,-1,STONE:0)
Block(7,7,0,STONE:0)
Block(7,7,1,GRASS:0)
Block(7,7,2,GRASS:0)
Block(7,8,-5,GRASS:0)
Block(7,8,-4,GRASS:0)
Block(7,8,-3,STONE:0)
Block(7,8,-2,STONE:0)
Block(7,8,-1,GRASS:0)
Block(7,8,0,GRASS:0)
Block(7,9,-3,GRASS:0)
Block(7,9,-2,GRASS:0)
Block(8,-11,0,STONE:0)
Block(8,-10,-3,STONE:0)
Block(8,-10,-2,STONE:0)
Block(8,-10,-1,STONE:0)
Block(8,-10,0,STONE:0)
Block(8,-10,1,STONE:0)
Block(8,-9,-5,STONE:0)
Block(8,-9,-4,STONE:0)
Block(8,-9,-3,STONE:0)
Block(8,-9,-2,STONE:0)
Block(8,-9,-1,STONE:0)
Block(8,-9,0,STONE:0)
Block(8,-9,1,STONE:0)
Block(8,-9,2,STONE:0)
Block(8,-8,-6,STONE:0)
Block(8,-8,-5,STONE:0)
Block(8,-8,-4,STONE:0)
Block(8,-8,-3,STONE:0)
Block(8,-8,-2,STONE:0)
Block(8,-8,-1,STONE:0)
Block(8,-8,0,STONE:0)
Block(8,-8,1,STONE:0)
Block(8,-8,2,STONE:0)
Block(8,-8,3,STONE:0)
Block(8,-7,-6,STONE:0)
Block(8,-7,-5,STONE:0)
Block(8,-7,-4,STONE:0)
Block(8,-7,-3,STONE:0)
Block(8,-7,-2,STONE:0)
Block(8,-7,-1,STONE:0)
Block(8,-7,0,STONE:0)
Block(8,-7,1,STONE:0)
Block(8,-7,2,STONE:0)
Block(8,-7,3,STONE:0)
Block(8,-7,4,STONE:0)
Block(8,-6,-6,STONE:0)
Block(8,-6,-5,STONE:0)
Block(8,-6,-4,STONE:0)
Block(8,-6,-3,STONE:0)
Block(8,-6,-2,STONE:0)
Block(8,-6,-1,STONE:0)
Block(8,-6,0,STONE:0)
Block(8,-6,1,STONE:0)
Block(8,-6,2,STONE:0)
Block(8,-6,3,STONE:0)
Block(8,-6,4,STONE:0)
Block(8,-6,5,STONE:0)
Block(8,-5,-6,STONE:0)
Block(8,-5,-5,STONE:0)
Block(8,-5,-4,STONE:0)
Block(8,-5,-3,STONE:0)
Block(8,-5,-2,STONE:0)
Block(8,-5,-1,STONE:0)
Block(8,-5,0,STONE:0)
Block(8,-5,1,STONE:0)
Block(8,-5,2,STONE:0)
Block(8,-5,3,STONE:0)
Block(8,-5,4,STONE:0)
Block(8,-5,5,STONE:0)
Block(8,-5,6,STONE:0)
Block(8,-4,-6,STONE:0)
Block(8,-4,-5,STONE:0)
Block(8,-4,-4,STONE:0)
Block(8,-4,-3,STONE:0)
Block(8,-4,-2,STONE:0)
Block(8,-4,-1,STONE:0)
Block(8,-4,0,STONE:0)
Block(8,-4,1,STONE:0)
Block(8,-4,2,STONE:0)
Block(8,-4,3,STONE:0)
Block(8,-4,4,STONE:0)
Block(8,-4,5,STONE:0)
Block(8,-4,6,STONE:0)
Block(8,-3,-6,STONE:0)
Block(8,-3,-5,STONE:0)
Block(8,-3,-4,STONE:0)
Block(8,-3,-3,STONE:0)
Block(8,-3,-2,STONE:0)
Block(8,-3,-1,STONE:0)
Block(8,-3,0,STONE:0)
Block(8,-3,1,STONE:0)
Block(8,-3,2,STONE:0)
Block(8,-3,3,STONE:0)
Block(8,-3,4,STONE:0)
Block(8,-3,5,STONE:0)
Block(8,-3,6,STONE:0)
Block(8,-3,7,STONE:0)
Block(8,-2,-6,STONE:0)
Block(8,-2,-5,STONE:0)
Block(8,-2,-4,STONE:0)
Block(8,-2,-3,STONE:0)
Block(8,-2,-2,STONE:0)
Block(8,-2,-1,STONE:0)
Block(8,-2,0,STONE:0)
Block(8,-2,1,STONE:0)
Block(8,-2,2,STONE:0)
Block(8,-2,3,STONE:0)
Block(8,-2,4,STONE:0)
Block(8,-2,5,STONE:0)
Block(8,-2,6,STONE:0)
Block(8,-2,7,STONE:0)
Block(8,-1,-6,STONE:0)
Block(8,-1,-5,STONE:0)
Block(8,-1,-4,STONE:0)
Block(8,-1,-3,STONE:0)
Block(8,-1,-2,STONE:0)
Block(8,-1,-1,STONE:0)
Block(8,-1,0,STONE:0)
Block(8,-1,1,STONE:0)
Block(8,-1,2,STONE:0)
Block(8,-1,3,STONE:0)
Block(8,-1,4,STONE:0)
Block(8,-1,5,STONE:0)
Block(8,-1,6,STONE:0)
Block(8,-1,7,STONE:0)
Block(8,0,-6,STONE:0)
Block(8,0,-5,STONE:0)
Block(8,0,-4,STONE:0)
Block(8,0,-3,STONE:0)
Block(8,0,-2,STONE:0)
Block(8,0,-1,STONE:0)
Block(8,0,0,STONE:0)
Block(8,0,1,STONE:0)
Block(8,0,2,STONE:0)
Block(8,0,3,STONE:0)
Block(8,0,4,STONE:0)
Block(8,0,5,STONE:0)
Block(8,0,6,STONE:0)
Block(8,1,-7,STONE:0)
Block(8,1,-6,STONE:0)
Block(8,1,-5,STONE:0)
Block(8,1,-4,STONE:0)
Block(8,1,-3,STONE:0)
Block(8,1,-2,STONE:0)
Block(8,1,-1,STONE:0)
Block(8,1,0,STONE:0)
Block(8,1,1,STONE:0)
Block(8,1,2,STONE:0)
Block(8,1,3,STONE:0)
Block(8,1,4,STONE:0)
Block(8,1,5,STONE:0)
Block(8,1,6,STONE:0)
Block(8,2,-7,STONE:0)
Block(8,2,-6,STONE:0)
Block(8,2,-5,STONE:0)
Block(8,2,-4,STONE:0)
Block(8,2,-3,STONE:0)
Block(8,2,-2,STONE:0)
Block(8,2,-1,STONE:0)
Block(8,2,0,STONE:0)
Block(8,2,1,STONE:0)
Block(8,2,2,STONE:0)
Block(8,2,3,STONE:0)
Block(8,2,4,STONE:0)
Block(8,2,5,DIRT:0)
Block(8,2,6,STONE:0)
Block(8,3,-7,DIRT:0)
Block(8,3,-6,STONE:0)
Block(8,3,-5,STONE:0)
Block(8,3,-4,STONE:0)
Block(8,3,-3,STONE:0)
Block(8,3,-2,STONE:0)
Block(8,3,-1,STONE:0)
Block(8,3,0,STONE:0)
Block(8,3,1,STONE:0)
Block(8,3,2,STONE:0)
Block(8,3,3,STONE:0)
Block(8,3,4,DIRT:0)
Block(8,3,5,DIRT:0)
Block(8,3,6,GRASS:0)
Block(8,4,-7,DIRT:0)
Block(8,4,-6,STONE:0)
Block(8,4,-5,STONE:0)
Block(8,4,-4,STONE:0)
Block(8,4,-3,STONE:0)
Block(8,4,-2,STONE:0)
Block(8,4,-1,STONE:0)
Block(8,4,0,STONE:0)
Block(8,4,1,STONE:0)
Block(8,4,2,STONE:0)
Block(8,4,3,STONE:0)
