
#######################################################################
# +-----------------------------------------------------------------+ #
# |                            BO3 object                           | #
# +-----------------------------------------------------------------+ #
#######################################################################

# This is the config file of a custom object.
# If you add this object correctly to your BiomeConfigs, it will spawn in the world.

# This is the creator of this BO3 object
Author: Unknown

# A short description of this BO3 object
Description: No description given

# The BO3 version, don't change this! It can be used by external applications to do a version check.
Version: 3

# The settings mode, WriteAll, WriteWithoutComments or WriteDisable. See WorldConfig.
SettingsMode: WriteAll


#######################################################################
# +-----------------------------------------------------------------+ #
# |                          Main settings                          | #
# +-----------------------------------------------------------------+ #
#######################################################################

# This needs to be set to true to spawn the object in the Tree and Sapling resources.
Tree: true

# The frequency of the BO3 from 1 to 200. Tries this many times to spawn this BO3 when using the CustomObject(...) resource.
# Ignored by Tree(..), Sapling(..) and CustomStructure(..)
Frequency: 0

# The rarity of the BO3 from 0 to 100. Each spawn attempt has rarity% chance to succeed when using the CustomObject(...) resource.
# Ignored by Tree(..), Sapling(..) and CustomStructure(..)
Rarity: 100.0

# If you set this to true, the BO3 will be placed with a random rotation.
RotateRandomly: true

# The spawn height of the BO3: randomY, highestBlock or highestSolidBlock.
SpawnHeight: highestSolidBlock

# The offset from the spawn height to spawn this BO3
# Ex. SpawnHeight = highestSolidBlock, SpawnHeightOffset = 3; This object will spawn 3 blocks above the highest solid block
SpawnHeightOffset: 0

# A random amount to offset the spawn location from the spawn offset height
# Ex. SpawnHeightOffset = 3, SpawnHeightVariance = 3; This object will spawn 3 to 6 blocks above the original spot it would have spawned
SpawnHeightVariance: 0

##############################
# Height Limits for the BO3. #
##############################

# When in randomY mode used as the minimum Y or in atMinY mode as the actual Y to spawn this BO3 at.
MinHeight: 63

# When in randomY mode used as the maximum Y to spawn this BO3 at.
MaxHeight: 255

######################
# Extrusion settings #
######################

# The style of extrusion you wish to use - BottomDown, TopUp, None (Default)
ExtrudeMode: BottomDown

# The blocks to extrude your BO3 through
ExtrudeThroughBlocks: AIR,STATIONARY_WATER

# Objects can have other objects attacthed to it: branches. Branches can also
# have branches attached to it, which can also have branches, etc. This is the
# maximum branch depth for this objects.
MaxBranchDepth: 10

# When spawned with the UseWorld keyword, this BO3 should NOT spawn in the following biomes.
# If you write the BO3 name directly in the BiomeConfigs, this will be ignored.
ExcludedBiomes: All


#######################################################################
# +-----------------------------------------------------------------+ #
# |                      Source block settings                      | #
# +-----------------------------------------------------------------+ #
#######################################################################

# The block(s) the BO3 should spawn in.
SourceBlocks: STONE:1,STONE:3,STONE:5,DIRT:1,DIRT:0,SAND:0,GRASS:0,DIRT:2,STATIONARY_WATER:0,HARD_CLAY,STAINED_CLAY:0,CLAY,SANDSTONE:0,SAND:1,AIR,STONE:0,GRAVEL,LONG_GRASS:0,LONG_GRASS:1,LONG_GRASS:2,DEAD_BUSH,YELLOW_FLOWER:0,RED_ROSE:0,BROWN_MUSHROOM,RED_MUSHROOM

# The maximum percentage of the BO3 that can be outside the SourceBlock.
# The BO3 won't be placed on a location with more blocks outside the SourceBlock than this percentage.
MaxPercentageOutsideSourceBlock: 0

# What to do when a block is about to be placed outside the SourceBlock? (dontPlace, placeAnyway)
OutsideSourceBlock: placeAnyway

# Disable doReplaceBlocks to make this BO3 ignore any ReplacedBlocks settings in biome configs, improves performance.
DoReplaceBlocks: true

# OTG+ settings #
# Legacy setting, rename this file to .BO4 instead. Set this to true to enable the advanced customstructure features of OTG+.
IsOTGPlus: false


#######################################################################
# +-----------------------------------------------------------------+ #
# |                              Blocks                             | #
# +-----------------------------------------------------------------+ #
#######################################################################

# All the blocks used in the BO3 are listed here. Possible blocks:
# Block(x,y,z,id[.data][,nbtfile.nbt)
# RandomBlock(x,y,z,id[:data][,nbtfile.nbt],chance[,id[:data][,nbtfile.nbt],chance[,...]])
#  So RandomBlock(0,0,0,CHEST,chest.nbt,50,CHEST,anotherchest.nbt,100) will spawn a chest at
#  the BO3 origin, and give it a 50% chance to have the contents of chest.nbt, or, if that
#  fails, a 100% percent chance to have the contents of anotherchest.nbt.
# *Note: Unlike Entity() and Spawner(), for Block() .txt files don't work, only .nbt files work.
# MinecraftObject(x,y,z,name) (TODO: This may not work anymore and needs to be tested.
#  Spawns an object in the Mojang NBT structure format. For example, 
#  MinecraftObject(0,0,0,minecraft:igloo/igloo_bottom)
#  spawns the bottom part of an igloo.
Block(-15,32,-5,LEAVES:3)
Block(-15,32,-4,LEAVES:3)
Block(-15,33,-6,LEAVES:3)
Block(-15,33,-5,LEAVES:3)
Block(-15,33,-4,LEAVES:3)
Block(-15,33,-3,LEAVES:3)
Block(-15,34,-4,LEAVES:3)
Block(-14,31,-7,LEAVES:3)
Block(-14,31,-6,LEAVES:3)
Block(-14,31,-5,LEAVES:3)
Block(-14,32,-7,LEAVES:3)
Block(-14,32,-6,LEAVES:3)
Block(-14,32,-5,LEAVES:3)
Block(-14,32,-4,LEAVES:3)
Block(-14,32,-3,LEAVES:3)
Block(-14,32,-2,LEAVES:3)
Block(-14,33,-7,LEAVES:3)
Block(-14,33,-6,LEAVES:3)
Block(-14,33,-5,LEAVES:3)
Block(-14,33,-4,LEAVES:3)
Block(-14,33,-3,LEAVES:3)
Block(-14,33,-2,LEAVES:3)
Block(-14,33,-1,LEAVES:3)
Block(-14,33,0,LEAVES:3)
Block(-14,33,1,LEAVES:3)
Block(-14,34,-6,LEAVES:3)
Block(-14,34,-5,LEAVES:3)
Block(-14,34,-4,LEAVES:3)
Block(-14,34,-3,LEAVES:3)
Block(-13,31,-10,LEAVES:3)
Block(-13,31,-9,LEAVES:3)
Block(-13,31,-8,LEAVES:3)
Block(-13,31,-7,LEAVES:3)
Block(-13,31,-6,LEAVES:3)
Block(-13,31,-5,LEAVES:3)
Block(-13,31,-4,LEAVES:3)
Block(-13,32,-12,LEAVES:3)
Block(-13,32,-11,LEAVES:3)
Block(-13,32,-10,LEAVES:3)
Block(-13,32,-9,LEAVES:3)
Block(-13,32,-8,LEAVES:3)
Block(-13,32,-7,LEAVES:3)
Block(-13,32,-6,LEAVES:3)
Block(-13,32,-5,LEAVES:3)
Block(-13,32,-4,LEAVES:3)
Block(-13,32,-3,LEAVES:3)
Block(-13,32,-2,LEAVES:3)
Block(-13,32,-1,LEAVES:3)
Block(-13,32,0,LEAVES:3)
Block(-13,33,-8,LEAVES:3)
Block(-13,33,-7,LEAVES:3)
Block(-13,33,-6,LEAVES:3)
Block(-13,33,-5,LEAVES:3)
Block(-13,33,-4,LEAVES:3)
Block(-13,33,-3,LEAVES:3)
Block(-13,33,-2,LEAVES:3)
Block(-13,33,-1,LEAVES:3)
Block(-13,33,0,LEAVES:3)
Block(-13,33,1,LEAVES:3)
Block(-13,33,2,LEAVES:3)
Block(-13,33,3,LEAVES:3)
Block(-13,34,-6,LEAVES:3)
Block(-13,34,-5,LEAVES:3)
Block(-13,34,-4,LEAVES:3)
Block(-13,34,-3,LEAVES:3)
Block(-13,34,-2,LEAVES:3)
Block(-13,34,-1,LEAVES:3)
Block(-13,34,0,LEAVES:3)
Block(-13,34,1,LEAVES:3)
Block(-13,34,2,LEAVES:3)
Block(-12,30,-8,LEAVES:3)
Block(-12,31,-12,LEAVES:3)
Block(-12,31,-11,LEAVES:3)
Block(-12,31,-10,LEAVES:3)
Block(-12,31,-9,LEAVES:3)
Block(-12,31,-8,LEAVES:3)
Block(-12,31,-7,LEAVES:3)
Block(-12,31,-6,LEAVES:3)
Block(-12,31,-5,LEAVES:3)
Block(-12,32,-13,LEAVES:3)
Block(-12,32,-12,LEAVES:3)
Block(-12,32,-11,LEAVES:3)
Block(-12,32,-10,LEAVES:3)
Block(-12,32,-9,LEAVES:3)
Block(-12,32,-8,LEAVES:3)
Block(-12,32,-7,LEAVES:3)
Block(-12,32,-6,LEAVES:3)
Block(-12,32,-5,LEAVES:3)
Block(-12,32,-4,LEAVES:3)
Block(-12,32,-3,LEAVES:3)
Block(-12,32,-2,LEAVES:3)
Block(-12,32,-1,LEAVES:3)
Block(-12,32,0,LEAVES:3)
Block(-12,32,1,LEAVES:3)
Block(-12,32,2,LEAVES:3)
Block(-12,33,-12,LEAVES:3)
Block(-12,33,-11,LEAVES:3)
Block(-12,33,-10,LEAVES:3)
Block(-12,33,-9,LEAVES:3)
Block(-12,33,-8,LEAVES:3)
Block(-12,33,-7,LEAVES:3)
Block(-12,33,-6,LEAVES:3)
Block(-12,33,-5,LEAVES:3)
Block(-12,33,-4,LEAVES:3)
Block(-12,33,-3,LEAVES:3)
Block(-12,33,-2,LEAVES:3)
Block(-12,33,-1,LEAVES:3)
Block(-12,33,0,LEAVES:3)
Block(-12,33,1,LEAVES:3)
Block(-12,33,2,LEAVES:3)
Block(-12,33,3,LEAVES:3)
Block(-12,34,-6,LEAVES:3)
Block(-12,34,-5,LEAVES:3)
Block(-12,34,-4,LEAVES:3)
Block(-12,34,-3,LEAVES:3)
Block(-12,34,-2,LEAVES:3)
Block(-12,34,-1,LEAVES:3)
Block(-12,34,0,LEAVES:3)
Block(-12,34,1,LEAVES:3)
Block(-12,34,2,LEAVES:3)
Block(-12,35,-4,LEAVES:3)
Block(-12,35,-3,LEAVES:3)
Block(-11,31,-13,LEAVES:3)
Block(-11,31,-12,LEAVES:3)
Block(-11,31,-11,LEAVES:3)
Block(-11,31,-10,LEAVES:3)
Block(-11,31,-9,LEAVES:3)
Block(-11,31,-8,LEAVES:3)
Block(-11,31,-7,LEAVES:3)
Block(-11,31,-6,LEAVES:3)
Block(-11,31,-5,LEAVES:3)
Block(-11,32,-14,LEAVES:3)
Block(-11,32,-13,LEAVES:3)
Block(-11,32,-12,LEAVES:3)
Block(-11,32,-11,LEAVES:3)
Block(-11,32,-10,LEAVES:3)
Block(-11,32,-9,LEAVES:3)
Block(-11,32,-8,LEAVES:3)
Block(-11,32,-7,LEAVES:3)
Block(-11,32,-6,LEAVES:3)
Block(-11,32,-5,LEAVES:3)
Block(-11,32,-4,LEAVES:3)
Block(-11,32,-3,LEAVES:3)
Block(-11,32,-2,LEAVES:3)
Block(-11,32,-1,LEAVES:3)
Block(-11,32,0,LEAVES:3)
Block(-11,32,1,LEAVES:3)
Block(-11,32,2,LEAVES:3)
Block(-11,32,3,LEAVES:3)
Block(-11,33,-13,LEAVES:3)
Block(-11,33,-12,LEAVES:3)
Block(-11,33,-11,LEAVES:3)
Block(-11,33,-10,LEAVES:3)
Block(-11,33,-9,LEAVES:3)
Block(-11,33,-8,LEAVES:3)
Block(-11,33,-7,LEAVES:3)
Block(-11,33,-6,LEAVES:3)
Block(-11,33,-5,LEAVES:3)
Block(-11,33,-4,LEAVES:3)
Block(-11,33,-3,LEAVES:3)
Block(-11,33,-2,LEAVES:3)
Block(-11,33,-1,LEAVES:3)
Block(-11,33,0,LEAVES:3)
Block(-11,33,1,LEAVES:3)
Block(-11,33,2,LEAVES:3)
Block(-11,33,3,LEAVES:3)
Block(-11,33,4,LEAVES:3)
Block(-11,34,-6,LEAVES:3)
Block(-11,34,-5,LEAVES:3)
Block(-11,34,-4,LEAVES:3)
Block(-11,34,-3,LEAVES:3)
Block(-11,34,-2,LEAVES:3)
Block(-11,34,-1,LEAVES:3)
Block(-11,34,0,LEAVES:3)
Block(-11,34,1,LEAVES:3)
Block(-11,34,2,LEAVES:3)
Block(-11,34,3,LEAVES:3)
Block(-11,35,-3,LEAVES:3)
Block(-11,35,-2,LEAVES:3)
Block(-11,35,-1,LEAVES:3)
Block(-10,31,-14,LEAVES:3)
Block(-10,31,-13,LEAVES:3)
Block(-10,31,-12,LEAVES:3)
Block(-10,31,-11,LEAVES:3)
Block(-10,31,-10,LEAVES:3)
Block(-10,31,-9,LEAVES:3)
Block(-10,31,-8,LEAVES:3)
Block(-10,31,-7,LEAVES:3)
Block(-10,31,-6,LEAVES:3)
Block(-10,31,-5,LEAVES:3)
Block(-10,32,-14,LEAVES:3)
Block(-10,32,-13,LEAVES:3)
Block(-10,32,-12,LEAVES:3)
Block(-10,32,-11,LEAVES:3)
Block(-10,32,-10,LEAVES:3)
Block(-10,32,-9,LEAVES:3)
Block(-10,32,-8,LEAVES:3)
Block(-10,32,-7,LEAVES:3)
Block(-10,32,-6,LEAVES:3)
Block(-10,32,-5,LEAVES:3)
Block(-10,32,-4,LEAVES:3)
Block(-10,32,-3,LEAVES:3)
Block(-10,32,-2,LEAVES:3)
Block(-10,32,-1,LEAVES:3)
Block(-10,32,0,LEAVES:3)
Block(-10,32,1,LEAVES:3)
Block(-10,32,2,LEAVES:3)
Block(-10,32,3,LEAVES:3)
Block(-10,32,4,LEAVES:3)
Block(-10,32,5,LEAVES:3)
Block(-10,32,6,LEAVES:3)
Block(-10,32,7,LEAVES:3)
Block(-10,33,-14,LEAVES:3)
Block(-10,33,-13,LEAVES:3)
Block(-10,33,-12,LEAVES:3)
Block(-10,33,-11,LEAVES:3)
Block(-10,33,-10,LEAVES:3)
Block(-10,33,-9,LEAVES:3)
Block(-10,33,-8,LEAVES:3)
Block(-10,33,-7,LEAVES:3)
Block(-10,33,-6,LEAVES:3)
Block(-10,33,-5,LEAVES:3)
Block(-10,33,-4,LEAVES:3)
Block(-10,33,-3,LEAVES:3)
Block(-10,33,-2,LOG:15)
Block(-10,33,-1,LEAVES:3)
Block(-10,33,0,LEAVES:3)
Block(-10,33,1,LEAVES:3)
Block(-10,33,2,LEAVES:3)
Block(-10,33,3,LEAVES:3)
Block(-10,33,4,LEAVES:3)
Block(-10,33,5,LEAVES:3)
Block(-10,33,6,LEAVES:3)
Block(-10,33,7,LEAVES:3)
Block(-10,34,-10,LEAVES:3)
Block(-10,34,-7,LEAVES:3)
Block(-10,34,-6,LEAVES:3)
Block(-10,34,-5,LEAVES:3)
Block(-10,34,-4,LEAVES:3)
Block(-10,34,-3,LEAVES:3)
Block(-10,34,-2,LEAVES:3)
Block(-10,34,-1,LEAVES:3)
Block(-10,34,0,LEAVES:3)
Block(-10,34,1,LEAVES:3)
Block(-10,34,2,LEAVES:3)
Block(-10,34,3,LEAVES:3)
Block(-10,34,4,LEAVES:3)
Block(-10,35,-3,LEAVES:3)
Block(-10,35,-2,LEAVES:3)
Block(-9,31,-14,LEAVES:3)
Block(-9,31,-13,LEAVES:3)
Block(-9,31,-12,LEAVES:3)
Block(-9,31,-11,LEAVES:3)
Block(-9,31,-10,LEAVES:3)
Block(-9,31,-8,LEAVES:3)
Block(-9,31,-7,LEAVES:3)
Block(-9,31,-6,LEAVES:3)
Block(-9,31,-5,LEAVES:3)
Block(-9,31,4,LEAVES:3)
Block(-9,31,5,LEAVES:3)
Block(-9,31,6,LEAVES:3)
Block(-9,32,-15,LEAVES:3)
Block(-9,32,-14,LEAVES:3)
Block(-9,32,-13,LEAVES:3)
Block(-9,32,-12,LEAVES:3)
Block(-9,32,-11,LEAVES:3)
Block(-9,32,-10,LEAVES:3)
Block(-9,32,-9,LEAVES:3)
Block(-9,32,-8,LEAVES:3)
Block(-9,32,-7,LEAVES:3)
Block(-9,32,-6,LEAVES:3)
Block(-9,32,-5,LEAVES:3)
Block(-9,32,-4,LEAVES:3)
Block(-9,32,-3,LEAVES:3)
Block(-9,32,-2,LOG:15)
Block(-9,32,-1,LEAVES:3)
Block(-9,32,0,LEAVES:3)
Block(-9,32,1,LEAVES:3)
Block(-9,32,2,LEAVES:3)
Block(-9,32,3,LEAVES:3)
Block(-9,32,4,LEAVES:3)
Block(-9,32,5,LEAVES:3)
Block(-9,32,6,LEAVES:3)
Block(-9,32,7,LEAVES:3)
Block(-9,32,8,LEAVES:3)
Block(-9,33,-14,LEAVES:3)
Block(-9,33,-13,LEAVES:3)
Block(-9,33,-12,LEAVES:3)
Block(-9,33,-11,LEAVES:3)
Block(-9,33,-10,LEAVES:3)
Block(-9,33,-9,LEAVES:3)
Block(-9,33,-8,LEAVES:3)
Block(-9,33,-7,LEAVES:3)
Block(-9,33,-6,LEAVES:3)
Block(-9,33,-5,LEAVES:3)
Block(-9,33,-4,LEAVES:3)
Block(-9,33,-3,LEAVES:3)
Block(-9,33,-2,LOG:15)
Block(-9,33,-1,LEAVES:3)
Block(-9,33,0,LEAVES:3)
Block(-9,33,1,LEAVES:3)
Block(-9,33,2,LEAVES:3)
Block(-9,33,3,LEAVES:3)
Block(-9,33,4,LEAVES:3)
Block(-9,33,5,LEAVES:3)
Block(-9,33,6,LEAVES:3)
Block(-9,33,7,LEAVES:3)
Block(-9,33,8,LEAVES:3)
Block(-9,33,9,LEAVES:3)
Block(-9,33,10,LEAVES:3)
Block(-9,34,-11,LEAVES:3)
Block(-9,34,-10,LEAVES:3)
Block(-9,34,-9,LEAVES:3)
Block(-9,34,-8,LEAVES:3)
Block(-9,34,-7,LEAVES:3)
Block(-9,34,-6,LEAVES:3)
Block(-9,34,-5,LEAVES:3)
Block(-9,34,-4,LEAVES:3)
Block(-9,34,-3,LEAVES:3)
Block(-9,34,-2,LEAVES:3)
Block(-9,34,-1,LEAVES:3)
Block(-9,34,0,LEAVES:3)
Block(-9,34,1,LEAVES:3)
Block(-9,34,2,LEAVES:3)
Block(-9,34,3,LEAVES:3)
Block(-9,34,4,LEAVES:3)
Block(-9,34,5,LEAVES:3)
Block(-9,34,6,LEAVES:3)
Block(-9,34,7,LEAVES:3)
Block(-9,34,8,LEAVES:3)
Block(-9,35,-5,LEAVES:3)
Block(-9,35,-3,LEAVES:3)
Block(-9,35,-2,LEAVES:3)
Block(-9,35,1,LEAVES:3)
Block(-9,35,2,LEAVES:3)
Block(-8,31,-15,LEAVES:3)
Block(-8,31,-14,LEAVES:3)
Block(-8,31,-13,LEAVES:3)
Block(-8,31,-12,LEAVES:3)
Block(-8,31,-11,LEAVES:3)
Block(-8,31,-8,LEAVES:3)
Block(-8,31,-7,LEAVES:3)
Block(-8,31,-6,LEAVES:3)
Block(-8,31,-5,LEAVES:3)
Block(-8,31,-4,LEAVES:3)
Block(-8,31,0,LEAVES:3)
Block(-8,31,5,LEAVES:3)
Block(-8,31,6,LEAVES:3)
Block(-8,32,-15,LEAVES:3)
Block(-8,32,-14,LEAVES:3)
Block(-8,32,-13,LEAVES:3)
Block(-8,32,-12,LEAVES:3)
Block(-8,32,-11,LEAVES:3)
Block(-8,32,-10,LEAVES:3)
Block(-8,32,-9,LOG:15)
Block(-8,32,-8,LEAVES:3)
Block(-8,32,-7,LEAVES:3)
Block(-8,32,-6,LEAVES:3)
Block(-8,32,-5,LEAVES:3)
Block(-8,32,-4,LEAVES:3)
Block(-8,32,-3,LEAVES:3)
Block(-8,32,-2,LOG:15)
Block(-8,32,-1,LEAVES:3)
Block(-8,32,0,LEAVES:3)
Block(-8,32,1,LEAVES:3)
Block(-8,32,2,LEAVES:3)
Block(-8,32,3,LEAVES:3)
Block(-8,32,4,LEAVES:3)
Block(-8,32,5,LEAVES:3)
Block(-8,32,6,LEAVES:3)
Block(-8,32,7,LEAVES:3)
Block(-8,32,8,LEAVES:3)
Block(-8,32,9,LEAVES:3)
Block(-8,32,10,LEAVES:3)
Block(-8,33,-14,LEAVES:3)
Block(-8,33,-13,LEAVES:3)
Block(-8,33,-12,LEAVES:3)
Block(-8,33,-11,LEAVES:3)
Block(-8,33,-10,LEAVES:3)
Block(-8,33,-9,LEAVES:3)
Block(-8,33,-8,LEAVES:3)
Block(-8,33,-7,LEAVES:3)
Block(-8,33,-6,LEAVES:3)
Block(-8,33,-5,LEAVES:3)
Block(-8,33,-4,LEAVES:3)
Block(-8,33,-3,LEAVES:3)
Block(-8,33,-2,LEAVES:3)
Block(-8,33,-1,LEAVES:3)
Block(-8,33,0,LEAVES:3)
Block(-8,33,1,LEAVES:3)
Block(-8,33,2,LEAVES:3)
Block(-8,33,3,LEAVES:3)
Block(-8,33,4,LEAVES:3)
Block(-8,33,5,LEAVES:3)
Block(-8,33,6,LEAVES:3)
Block(-8,33,7,LEAVES:3)
Block(-8,33,8,LEAVES:3)
Block(-8,33,9,LEAVES:3)
Block(-8,33,10,LEAVES:3)
Block(-8,33,11,LEAVES:3)
Block(-8,34,-11,LEAVES:3)
Block(-8,34,-10,LEAVES:3)
Block(-8,34,-9,LEAVES:3)
Block(-8,34,-8,LEAVES:3)
Block(-8,34,-7,LEAVES:3)
Block(-8,34,-6,LEAVES:3)
Block(-8,34,-5,LEAVES:3)
Block(-8,34,-4,LEAVES:3)
Block(-8,34,-3,LEAVES:3)
Block(-8,34,-2,LEAVES:3)
Block(-8,34,-1,LEAVES:3)
Block(-8,34,0,LEAVES:3)
Block(-8,34,1,LEAVES:3)
Block(-8,34,2,LEAVES:3)
Block(-8,34,3,LEAVES:3)
Block(-8,34,4,LEAVES:3)
Block(-8,34,5,LEAVES:3)
Block(-8,34,6,LEAVES:3)
Block(-8,34,7,LEAVES:3)
Block(-8,34,8,LEAVES:3)
Block(-8,34,9,LEAVES:3)
Block(-8,34,10,LEAVES:3)
Block(-8,35,-3,LEAVES:3)
Block(-8,35,-2,LEAVES:3)
Block(-8,35,1,LEAVES:3)
Block(-7,31,-16,LEAVES:3)
Block(-7,31,-15,LEAVES:3)
Block(-7,31,-14,LEAVES:3)
Block(-7,31,-13,LEAVES:3)
Block(-7,31,-12,LEAVES:3)
Block(-7,31,-11,LEAVES:3)
Block(-7,31,-9,LEAVES:3)
Block(-7,31,-8,LEAVES:3)
Block(-7,31,-7,LEAVES:3)
Block(-7,31,-6,LEAVES:3)
Block(-7,31,-5,LEAVES:3)
Block(-7,31,-4,LEAVES:3)
Block(-7,32,-16,LEAVES:3)
Block(-7,32,-15,LEAVES:3)
Block(-7,32,-14,LEAVES:3)
Block(-7,32,-13,LEAVES:3)
Block(-7,32,-12,LEAVES:3)
Block(-7,32,-11,LEAVES:3)
Block(-7,32,-10,LEAVES:3)
Block(-7,32,-9,LOG:15)
Block(-7,32,-8,LOG:15)
Block(-7,32,-7,LEAVES:3)
Block(-7,32,-6,LEAVES:3)
Block(-7,32,-5,LEAVES:3)
Block(-7,32,-4,LEAVES:3)
Block(-7,32,-3,LOG:15)
Block(-7,32,-2,LOG:15)
Block(-7,32,-1,LEAVES:3)
Block(-7,32,0,LEAVES:3)
Block(-7,32,1,LEAVES:3)
Block(-7,32,2,LEAVES:3)
Block(-7,32,3,LEAVES:3)
Block(-7,32,4,LEAVES:3)
Block(-7,32,5,LEAVES:3)
Block(-7,32,6,LEAVES:3)
Block(-7,32,7,LEAVES:3)
Block(-7,32,8,LEAVES:3)
Block(-7,32,9,LEAVES:3)
Block(-7,32,10,LEAVES:3)
Block(-7,33,-14,LEAVES:3)
Block(-7,33,-13,LEAVES:3)
Block(-7,33,-12,LEAVES:3)
Block(-7,33,-11,LEAVES:3)
Block(-7,33,-10,LEAVES:3)
Block(-7,33,-9,LEAVES:3)
Block(-7,33,-8,LEAVES:3)
Block(-7,33,-7,LEAVES:3)
Block(-7,33,-6,LEAVES:3)
Block(-7,33,-5,LEAVES:3)
Block(-7,33,-4,LEAVES:3)
Block(-7,33,-3,LEAVES:3)
Block(-7,33,-2,LEAVES:3)
Block(-7,33,-1,LEAVES:3)
Block(-7,33,0,LEAVES:3)
Block(-7,33,1,LEAVES:3)
Block(-7,33,2,LEAVES:3)
Block(-7,33,3,LEAVES:3)
Block(-7,33,4,LEAVES:3)
Block(-7,33,5,LEAVES:3)
Block(-7,33,6,LEAVES:3)
Block(-7,33,7,LEAVES:3)
Block(-7,33,8,LEAVES:3)
Block(-7,33,9,LEAVES:3)
Block(-7,33,10,LEAVES:3)
Block(-7,33,11,LEAVES:3)
Block(-7,34,-12,LEAVES:3)
Block(-7,34,-11,LEAVES:3)
Block(-7,34,-10,LEAVES:3)
Block(-7,34,-9,LEAVES:3)
Block(-7,34,-8,LEAVES:3)
Block(-7,34,-7,LEAVES:3)
Block(-7,34,-6,LEAVES:3)
Block(-7,34,-5,LEAVES:3)
Block(-7,34,-4,LEAVES:3)
Block(-7,34,-3,LEAVES:3)
Block(-7,34,-2,LEAVES:3)
Block(-7,34,-1,LEAVES:3)
Block(-7,34,0,LEAVES:3)
Block(-7,34,1,LEAVES:3)
Block(-7,34,2,LEAVES:3)
Block(-7,34,3,LEAVES:3)
Block(-7,34,4,LEAVES:3)
Block(-7,34,5,LEAVES:3)
Block(-7,34,6,LEAVES:3)
Block(-7,34,7,LEAVES:3)
Block(-7,34,8,LEAVES:3)
Block(-7,34,9,LEAVES:3)
Block(-7,34,10,LEAVES:3)
Block(-7,35,4,LEAVES:3)
Block(-7,35,5,LEAVES:3)
Block(-6,30,-14,LEAVES:3)
Block(-6,31,-17,LEAVES:3)
Block(-6,31,-16,LEAVES:3)
Block(-6,31,-15,LEAVES:3)
Block(-6,31,-14,LEAVES:3)
Block(-6,31,-13,LEAVES:3)
Block(-6,31,-12,LEAVES:3)
Block(-6,31,-11,LEAVES:3)
Block(-6,31,-10,LEAVES:3)
Block(-6,31,-9,LEAVES:3)
Block(-6,31,-8,LOG:15)
Block(-6,31,-7,LOG:15)
Block(-6,31,-6,LEAVES:3)
Block(-6,31,-5,LEAVES:3)
Block(-6,31,-4,LEAVES:3)
Block(-6,31,-3,LOG:15)
Block(-6,32,-15,LEAVES:3)
Block(-6,32,-14,LEAVES:3)
Block(-6,32,-13,LEAVES:3)
Block(-6,32,-12,LEAVES:3)
Block(-6,32,-11,LEAVES:3)
Block(-6,32,-10,LEAVES:3)
Block(-6,32,-9,LEAVES:3)
Block(-6,32,-8,LOG:15)
Block(-6,32,-7,LEAVES:3)
Block(-6,32,-6,LEAVES:3)
Block(-6,32,-5,LEAVES:3)
Block(-6,32,-4,LEAVES:3)
Block(-6,32,-3,LOG:15)
Block(-6,32,-2,LEAVES:3)
Block(-6,32,-1,LEAVES:3)
Block(-6,32,0,LEAVES:3)
Block(-6,32,1,LEAVES:3)
Block(-6,32,2,LEAVES:3)
Block(-6,32,3,LEAVES:3)
Block(-6,32,4,LEAVES:3)
Block(-6,32,5,LEAVES:3)
Block(-6,32,6,LEAVES:3)
Block(-6,32,7,LEAVES:3)
Block(-6,32,8,LEAVES:3)
Block(-6,32,9,LEAVES:3)
Block(-6,32,10,LEAVES:3)
Block(-6,33,-14,LEAVES:3)
Block(-6,33,-13,LEAVES:3)
Block(-6,33,-12,LEAVES:3)
Block(-6,33,-11,LEAVES:3)
Block(-6,33,-10,LEAVES:3)
Block(-6,33,-9,LEAVES:3)
Block(-6,33,-8,LEAVES:3)
Block(-6,33,-7,LEAVES:3)
Block(-6,33,-6,LEAVES:3)
Block(-6,33,-5,LEAVES:3)
Block(-6,33,-4,LEAVES:3)
Block(-6,33,-3,LEAVES:3)
Block(-6,33,-2,LEAVES:3)
Block(-6,33,-1,LEAVES:3)
Block(-6,33,0,LEAVES:3)
Block(-6,33,1,LEAVES:3)
Block(-6,33,2,LEAVES:3)
Block(-6,33,3,LEAVES:3)
Block(-6,33,4,LEAVES:3)
Block(-6,33,5,LEAVES:3)
Block(-6,33,6,LEAVES:3)
Block(-6,33,7,LEAVES:3)
Block(-6,33,8,LEAVES:3)
Block(-6,33,9,LEAVES:3)
Block(-6,33,10,LEAVES:3)
Block(-6,33,11,LEAVES:3)
Block(-6,34,-11,LEAVES:3)
Block(-6,34,-10,LEAVES:3)
Block(-6,34,-9,LEAVES:3)
Block(-6,34,-8,LEAVES:3)
Block(-6,34,-7,LEAVES:3)
Block(-6,34,-6,LEAVES:3)
Block(-6,34,-5,LEAVES:3)
Block(-6,34,-4,LEAVES:3)
Block(-6,34,-3,LEAVES:3)
Block(-6,34,-2,LEAVES:3)
Block(-6,34,-1,LEAVES:3)
Block(-6,34,0,LEAVES:3)
Block(-6,34,1,LEAVES:3)
Block(-6,34,2,LEAVES:3)
Block(-6,34,3,LEAVES:3)
Block(-6,34,4,LEAVES:3)
Block(-6,34,5,LEAVES:3)
Block(-6,34,6,LEAVES:3)
Block(-6,34,7,LEAVES:3)
Block(-6,34,8,LEAVES:3)
Block(-6,34,9,LEAVES:3)
Block(-6,34,10,LEAVES:3)
Block(-6,35,-7,LEAVES:3)
Block(-6,35,-6,LEAVES:3)
Block(-6,35,-5,LEAVES:3)
Block(-6,35,-4,LEAVES:3)
Block(-6,35,-3,LEAVES:3)
Block(-6,35,4,LEAVES:3)
Block(-6,35,5,LEAVES:3)
Block(-6,35,6,LEAVES:3)
Block(-6,35,7,LEAVES:3)
Block(-5,30,-15,LEAVES:3)
Block(-5,30,-14,LEAVES:3)
Block(-5,31,-15,LEAVES:3)
Block(-5,31,-14,LEAVES:3)
Block(-5,31,-13,LEAVES:3)
Block(-5,31,-9,LEAVES:3)
Block(-5,31,-8,LEAVES:3)
Block(-5,31,-7,LOG:15)
Block(-5,31,-6,LOG:15)
Block(-5,31,-5,LEAVES:3)
Block(-5,31,-4,LEAVES:3)
Block(-5,31,-3,LOG:15)
Block(-5,31,9,LEAVES:3)
Block(-5,32,-16,LEAVES:3)
Block(-5,32,-15,LEAVES:3)
Block(-5,32,-14,LEAVES:3)
Block(-5,32,-13,LEAVES:3)
Block(-5,32,-12,LEAVES:3)
Block(-5,32,-11,LEAVES:3)
Block(-5,32,-10,LEAVES:3)
Block(-5,32,-9,LEAVES:3)
Block(-5,32,-8,LEAVES:3)
Block(-5,32,-7,LEAVES:3)
Block(-5,32,-6,LEAVES:3)
Block(-5,32,-5,LEAVES:3)
Block(-5,32,-4,LEAVES:3)
Block(-5,32,-3,LEAVES:3)
Block(-5,32,-2,LEAVES:3)
Block(-5,32,-1,LEAVES:3)
Block(-5,32,0,LEAVES:3)
Block(-5,32,1,LEAVES:3)
Block(-5,32,2,LEAVES:3)
Block(-5,32,3,LEAVES:3)
Block(-5,32,4,LEAVES:3)
Block(-5,32,6,LEAVES:3)
Block(-5,32,7,LEAVES:3)
Block(-5,32,8,LEAVES:3)
Block(-5,32,9,LEAVES:3)
Block(-5,32,10,LEAVES:3)
Block(-5,33,-15,LEAVES:3)
Block(-5,33,-14,LEAVES:3)
Block(-5,33,-13,LEAVES:3)
Block(-5,33,-12,LEAVES:3)
Block(-5,33,-11,LEAVES:3)
Block(-5,33,-10,LEAVES:3)
Block(-5,33,-9,LEAVES:3)
Block(-5,33,-8,LEAVES:3)
Block(-5,33,-7,LEAVES:3)
Block(-5,33,-6,LEAVES:3)
Block(-5,33,-5,LEAVES:3)
Block(-5,33,-4,LEAVES:3)
Block(-5,33,-3,LEAVES:3)
Block(-5,33,-2,LEAVES:3)
Block(-5,33,-1,LEAVES:3)
Block(-5,33,0,LEAVES:3)
Block(-5,33,1,LEAVES:3)
Block(-5,33,2,LEAVES:3)
Block(-5,33,3,LEAVES:3)
Block(-5,33,4,LEAVES:3)
Block(-5,33,5,LEAVES:3)
Block(-5,33,6,LOG:15)
Block(-5,33,7,LEAVES:3)
Block(-5,33,8,LEAVES:3)
Block(-5,33,9,LEAVES:3)
Block(-5,33,10,LEAVES:3)
Block(-5,33,11,LEAVES:3)
Block(-5,33,12,LEAVES:3)
Block(-5,34,-11,LEAVES:3)
Block(-5,34,-10,LEAVES:3)
Block(-5,34,-9,LEAVES:3)
Block(-5,34,-8,LEAVES:3)
Block(-5,34,-7,LEAVES:3)
Block(-5,34,-6,LEAVES:3)
Block(-5,34,-5,LEAVES:3)
Block(-5,34,-4,LEAVES:3)
Block(-5,34,-3,LEAVES:3)
Block(-5,34,-2,LEAVES:3)
Block(-5,34,-1,LEAVES:3)
Block(-5,34,0,LEAVES:3)
Block(-5,34,1,LEAVES:3)
Block(-5,34,2,LEAVES:3)
Block(-5,34,3,LEAVES:3)
Block(-5,34,4,LEAVES:3)
Block(-5,34,5,LEAVES:3)
Block(-5,34,6,LEAVES:3)
Block(-5,34,7,LEAVES:3)
Block(-5,34,8,LEAVES:3)
Block(-5,34,9,LEAVES:3)
Block(-5,34,10,LEAVES:3)
Block(-5,35,-7,LEAVES:3)
Block(-5,35,-6,LEAVES:3)
Block(-5,35,-5,LEAVES:3)
Block(-5,35,-4,LEAVES:3)
Block(-5,35,-3,LEAVES:3)
Block(-5,35,-2,LEAVES:3)
Block(-5,35,-1,LEAVES:3)
Block(-5,35,3,LEAVES:3)
Block(-5,35,4,LEAVES:3)
Block(-5,35,5,LEAVES:3)
Block(-5,35,6,LEAVES:3)
Block(-5,36,-6,LEAVES:3)
Block(-4,30,-6,LOG:15)
Block(-4,30,-5,LOG:15)
Block(-4,30,-4,LOG:15)
Block(-4,30,-3,LOG:15)
Block(-4,31,-15,LEAVES:3)
Block(-4,31,-14,LEAVES:3)
Block(-4,31,-13,LEAVES:3)
Block(-4,31,-12,LEAVES:3)
Block(-4,31,-9,LEAVES:3)
Block(-4,31,-8,LEAVES:3)
Block(-4,31,-7,LEAVES:3)
Block(-4,31,-6,LOG:15)
Block(-4,31,-5,LEAVES:3)
Block(-4,31,-4,LEAVES:3)
Block(-4,31,-3,LOG:15)
Block(-4,32,-15,LEAVES:3)
Block(-4,32,-14,LEAVES:3)
Block(-4,32,-13,LEAVES:3)
Block(-4,32,-12,LEAVES:3)
Block(-4,32,-11,LEAVES:3)
Block(-4,32,-10,LEAVES:3)
Block(-4,32,-9,LEAVES:3)
Block(-4,32,-8,LEAVES:3)
Block(-4,32,-7,LEAVES:3)
Block(-4,32,-6,LEAVES:3)
Block(-4,32,-5,LEAVES:3)
Block(-4,32,-4,LEAVES:3)
Block(-4,32,-3,LEAVES:3)
Block(-4,32,-2,LEAVES:3)
Block(-4,32,-1,LEAVES:3)
Block(-4,32,0,LEAVES:3)
Block(-4,32,1,LEAVES:3)
Block(-4,32,2,LEAVES:3)
Block(-4,32,3,LEAVES:3)
Block(-4,32,6,LOG:15)
Block(-4,32,7,LEAVES:3)
Block(-4,32,8,LEAVES:3)
Block(-4,32,9,LEAVES:3)
Block(-4,32,10,LEAVES:3)
Block(-4,33,-15,LEAVES:3)
Block(-4,33,-14,LEAVES:3)
Block(-4,33,-13,LEAVES:3)
Block(-4,33,-12,LEAVES:3)
Block(-4,33,-11,LEAVES:3)
Block(-4,33,-10,LEAVES:3)
Block(-4,33,-9,LEAVES:3)
Block(-4,33,-8,LEAVES:3)
Block(-4,33,-7,LEAVES:3)
Block(-4,33,-6,LEAVES:3)
Block(-4,33,-5,LEAVES:3)
Block(-4,33,-4,LEAVES:3)
Block(-4,33,-3,LEAVES:3)
Block(-4,33,-2,LEAVES:3)
Block(-4,33,-1,LEAVES:3)
Block(-4,33,0,LEAVES:3)
Block(-4,33,1,LEAVES:3)
Block(-4,33,2,LEAVES:3)
Block(-4,33,3,LEAVES:3)
Block(-4,33,4,LEAVES:3)
Block(-4,33,5,LEAVES:3)
Block(-4,33,6,LOG:15)
Block(-4,33,7,LEAVES:3)
Block(-4,33,8,LEAVES:3)
Block(-4,33,9,LEAVES:3)
Block(-4,33,10,LEAVES:3)
Block(-4,33,11,LEAVES:3)
Block(-4,34,-14,LEAVES:3)
Block(-4,34,-12,LEAVES:3)
Block(-4,34,-11,LEAVES:3)
Block(-4,34,-10,LEAVES:3)
Block(-4,34,-9,LEAVES:3)
Block(-4,34,-8,LEAVES:3)
Block(-4,34,-7,LEAVES:3)
Block(-4,34,-6,LEAVES:3)
Block(-4,34,-5,LEAVES:3)
Block(-4,34,-4,LEAVES:3)
Block(-4,34,-3,LEAVES:3)
Block(-4,34,-2,LEAVES:3)
Block(-4,34,-1,LEAVES:3)
Block(-4,34,0,LEAVES:3)
Block(-4,34,1,LEAVES:3)
Block(-4,34,2,LEAVES:3)
Block(-4,34,3,LEAVES:3)
Block(-4,34,4,LEAVES:3)
Block(-4,34,5,LEAVES:3)
Block(-4,34,6,LEAVES:3)
Block(-4,34,7,LEAVES:3)
Block(-4,34,8,LEAVES:3)
Block(-4,34,9,LEAVES:3)
Block(-4,34,10,LEAVES:3)
Block(-4,35,-7,LEAVES:3)
Block(-4,35,-6,LEAVES:3)
Block(-4,35,-5,LEAVES:3)
Block(-4,35,-4,LEAVES:3)
Block(-4,35,-3,LEAVES:3)
Block(-4,35,-2,LEAVES:3)
Block(-4,35,-1,LEAVES:3)
Block(-4,35,0,LEAVES:3)
Block(-4,35,1,LEAVES:3)
Block(-4,35,2,LEAVES:3)
Block(-4,35,3,LEAVES:3)
Block(-4,35,4,LEAVES:3)
Block(-4,35,5,LEAVES:3)
Block(-4,35,6,LEAVES:3)
Block(-4,36,-6,LEAVES:3)
Block(-4,36,-5,LEAVES:3)
Block(-4,36,-4,LEAVES:3)
Block(-4,36,-3,LEAVES:3)
Block(-4,36,-2,LEAVES:3)
Block(-3,29,-3,LOG:15)
Block(-3,30,-4,LOG:15)
Block(-3,30,-3,LOG:15)
Block(-3,30,-2,LOG:15)
Block(-3,31,-15,LEAVES:3)
Block(-3,31,-13,LEAVES:3)
Block(-3,31,-12,LEAVES:3)
Block(-3,31,-11,LEAVES:3)
Block(-3,31,-10,LEAVES:3)
Block(-3,31,-9,LEAVES:3)
Block(-3,31,-8,LEAVES:3)
Block(-3,31,-7,LEAVES:3)
Block(-3,31,-6,LEAVES:3)
Block(-3,31,-5,LEAVES:3)
Block(-3,31,-4,LEAVES:3)
Block(-3,31,-3,LEAVES:3)
Block(-3,31,1,LEAVES:3)
Block(-3,31,7,LEAVES:3)
Block(-3,31,8,LEAVES:3)
Block(-3,32,-14,LEAVES:3)
Block(-3,32,-13,LEAVES:3)
Block(-3,32,-12,LEAVES:3)
Block(-3,32,-11,LEAVES:3)
Block(-3,32,-10,LEAVES:3)
Block(-3,32,-9,LEAVES:3)
Block(-3,32,-8,LEAVES:3)
Block(-3,32,-7,LEAVES:3)
Block(-3,32,-6,LEAVES:3)
Block(-3,32,-5,LEAVES:3)
Block(-3,32,-4,LEAVES:3)
Block(-3,32,-3,LEAVES:3)
Block(-3,32,-2,LEAVES:3)
Block(-3,32,-1,LEAVES:3)
Block(-3,32,0,LEAVES:3)
Block(-3,32,1,LEAVES:3)
Block(-3,32,2,LEAVES:3)
Block(-3,32,3,LEAVES:3)
Block(-3,32,4,LEAVES:3)
Block(-3,32,5,LOG:15)
Block(-3,32,6,LOG:15)
Block(-3,32,7,LEAVES:3)
Block(-3,32,8,LEAVES:3)
Block(-3,32,9,LEAVES:3)
Block(-3,32,10,LEAVES:3)
Block(-3,32,11,LEAVES:3)
Block(-3,32,12,LEAVES:3)
Block(-3,33,-14,LEAVES:3)
Block(-3,33,-13,LEAVES:3)
Block(-3,33,-12,LEAVES:3)
Block(-3,33,-11,LEAVES:3)
Block(-3,33,-10,LEAVES:3)
Block(-3,33,-9,LEAVES:3)
Block(-3,33,-8,LEAVES:3)
Block(-3,33,-7,LEAVES:3)
Block(-3,33,-6,LEAVES:3)
Block(-3,33,-5,LEAVES:3)
Block(-3,33,-4,LEAVES:3)
Block(-3,33,-3,LEAVES:3)
Block(-3,33,-2,LEAVES:3)
Block(-3,33,-1,LEAVES:3)
Block(-3,33,0,LEAVES:3)
Block(-3,33,1,LEAVES:3)
Block(-3,33,2,LEAVES:3)
Block(-3,33,3,LEAVES:3)
Block(-3,33,4,LEAVES:3)
Block(-3,33,5,LEAVES:3)
Block(-3,33,6,LEAVES:3)
Block(-3,33,7,LEAVES:3)
Block(-3,33,8,LEAVES:3)
Block(-3,33,9,LEAVES:3)
Block(-3,33,10,LEAVES:3)
Block(-3,33,11,LEAVES:3)
Block(-3,34,-14,LEAVES:3)
Block(-3,34,-13,LEAVES:3)
Block(-3,34,-12,LEAVES:3)
Block(-3,34,-11,LEAVES:3)
Block(-3,34,-10,LEAVES:3)
Block(-3,34,-9,LEAVES:3)
Block(-3,34,-8,LEAVES:3)
Block(-3,34,-7,LEAVES:3)
Block(-3,34,-6,LEAVES:3)
Block(-3,34,-5,LEAVES:3)
Block(-3,34,-4,LEAVES:3)
Block(-3,34,-3,LEAVES:3)
Block(-3,34,-2,LEAVES:3)
Block(-3,34,-1,LEAVES:3)
Block(-3,34,0,LEAVES:3)
Block(-3,34,1,LEAVES:3)
Block(-3,34,2,LEAVES:3)
Block(-3,34,3,LEAVES:3)
Block(-3,34,4,LEAVES:3)
Block(-3,34,5,LEAVES:3)
Block(-3,34,6,LEAVES:3)
Block(-3,34,7,LEAVES:3)
Block(-3,34,8,LEAVES:3)
Block(-3,34,9,LEAVES:3)
Block(-3,34,10,LEAVES:3)
Block(-3,35,-8,LEAVES:3)
Block(-3,35,-7,LEAVES:3)
Block(-3,35,-6,LEAVES:3)
Block(-3,35,-5,LEAVES:3)
Block(-3,35,-4,LEAVES:3)
Block(-3,35,-3,LEAVES:3)
Block(-3,35,-2,LEAVES:3)
Block(-3,35,-1,LEAVES:3)
Block(-3,35,0,LEAVES:3)
Block(-3,35,1,LEAVES:3)
Block(-3,35,2,LEAVES:3)
Block(-3,35,3,LEAVES:3)
Block(-3,35,4,LEAVES:3)
Block(-3,35,5,LEAVES:3)
Block(-3,35,6,LEAVES:3)
Block(-3,36,-6,LEAVES:3)
Block(-3,36,-5,LEAVES:3)
Block(-3,36,-4,LEAVES:3)
Block(-3,36,-3,LEAVES:3)
Block(-3,36,-2,LEAVES:3)
Block(-3,36,-1,LEAVES:3)
Block(-3,36,0,LEAVES:3)
Block(-3,36,1,LEAVES:3)
Block(-3,36,4,LEAVES:3)
Block(-2,27,-2,LOG:15)
Block(-2,28,-2,LOG:15)
Block(-2,28,-1,LOG:15)
Block(-2,29,-3,LOG:15)
Block(-2,29,-2,LOG:15)
Block(-2,29,-1,LOG:15)
Block(-2,30,-5,LOG:15)
Block(-2,30,-4,LOG:15)
Block(-2,31,-15,LEAVES:3)
Block(-2,31,-12,LEAVES:3)
Block(-2,31,-11,LEAVES:3)
Block(-2,31,-9,LEAVES:3)
Block(-2,31,-8,LEAVES:3)
Block(-2,31,-7,LEAVES:3)
Block(-2,31,-6,LEAVES:3)
Block(-2,31,-5,LOG:15)
Block(-2,31,-4,LEAVES:3)
Block(-2,31,-3,LEAVES:3)
Block(-2,31,0,LEAVES:3)
Block(-2,31,4,LOG:15)
Block(-2,31,5,LOG:15)
Block(-2,31,8,LEAVES:3)
Block(-2,31,9,LEAVES:3)
Block(-2,32,-14,LEAVES:3)
Block(-2,32,-13,LEAVES:3)
Block(-2,32,-12,LEAVES:3)
Block(-2,32,-11,LEAVES:3)
Block(-2,32,-10,LEAVES:3)
Block(-2,32,-9,LEAVES:3)
Block(-2,32,-8,LEAVES:3)
Block(-2,32,-7,LEAVES:3)
Block(-2,32,-6,LEAVES:3)
Block(-2,32,-5,LEAVES:3)
Block(-2,32,-4,LEAVES:3)
Block(-2,32,-3,LEAVES:3)
Block(-2,32,-2,LEAVES:3)
Block(-2,32,-1,LEAVES:3)
Block(-2,32,0,LEAVES:3)
Block(-2,32,1,LEAVES:3)
Block(-2,32,2,LEAVES:3)
Block(-2,32,3,LEAVES:3)
Block(-2,32,4,LEAVES:3)
Block(-2,32,5,LOG:15)
Block(-2,32,6,LEAVES:3)
Block(-2,32,7,LEAVES:3)
Block(-2,32,8,LEAVES:3)
Block(-2,32,9,LEAVES:3)
Block(-2,32,10,LEAVES:3)
Block(-2,32,12,LEAVES:3)
Block(-2,33,-16,LEAVES:3)
Block(-2,33,-15,LEAVES:3)
Block(-2,33,-14,LEAVES:3)
Block(-2,33,-13,LEAVES:3)
Block(-2,33,-12,LEAVES:3)
Block(-2,33,-11,LEAVES:3)
Block(-2,33,-10,LEAVES:3)
Block(-2,33,-9,LEAVES:3)
Block(-2,33,-8,LEAVES:3)
Block(-2,33,-7,LEAVES:3)
Block(-2,33,-6,LEAVES:3)
Block(-2,33,-5,LEAVES:3)
Block(-2,33,-4,LEAVES:3)
Block(-2,33,-3,LEAVES:3)
Block(-2,33,-2,LEAVES:3)
Block(-2,33,-1,LEAVES:3)
Block(-2,33,0,LEAVES:3)
Block(-2,33,1,LEAVES:3)
Block(-2,33,2,LEAVES:3)
Block(-2,33,3,LEAVES:3)
Block(-2,33,4,LEAVES:3)
Block(-2,33,5,LEAVES:3)
Block(-2,33,6,LEAVES:3)
Block(-2,33,7,LEAVES:3)
Block(-2,33,8,LEAVES:3)
Block(-2,33,9,LEAVES:3)
Block(-2,33,10,LEAVES:3)
Block(-2,33,11,LEAVES:3)
Block(-2,34,-13,LEAVES:3)
Block(-2,34,-12,LEAVES:3)
Block(-2,34,-11,LEAVES:3)
Block(-2,34,-10,LEAVES:3)
Block(-2,34,-9,LEAVES:3)
Block(-2,34,-8,LEAVES:3)
Block(-2,34,-7,LEAVES:3)
Block(-2,34,-6,LEAVES:3)
Block(-2,34,-5,LEAVES:3)
Block(-2,34,-4,LEAVES:3)
Block(-2,34,-3,LEAVES:3)
Block(-2,34,-2,LEAVES:3)
Block(-2,34,-1,LEAVES:3)
Block(-2,34,0,LEAVES:3)
Block(-2,34,1,LEAVES:3)
Block(-2,34,2,LEAVES:3)
Block(-2,34,3,LEAVES:3)
Block(-2,34,4,LEAVES:3)
Block(-2,34,5,LEAVES:3)
Block(-2,34,6,LEAVES:3)
Block(-2,34,7,LEAVES:3)
Block(-2,34,8,LEAVES:3)
Block(-2,34,9,LEAVES:3)
Block(-2,34,10,LEAVES:3)
Block(-2,35,-8,LEAVES:3)
Block(-2,35,-7,LEAVES:3)
Block(-2,35,-6,LEAVES:3)
Block(-2,35,-5,LEAVES:3)
Block(-2,35,-4,LEAVES:3)
Block(-2,35,-3,LEAVES:3)
Block(-2,35,-2,LEAVES:3)
Block(-2,35,-1,LEAVES:3)
Block(-2,35,0,LEAVES:3)
Block(-2,35,1,LEAVES:3)
Block(-2,35,2,LEAVES:3)
Block(-2,35,3,LEAVES:3)
Block(-2,35,4,LEAVES:3)
Block(-2,35,5,LEAVES:3)
Block(-2,35,6,LEAVES:3)
Block(-2,35,7,LEAVES:3)
Block(-2,36,-6,LEAVES:3)
Block(-2,36,-5,LEAVES:3)
Block(-2,36,-4,LEAVES:3)
Block(-2,36,-3,LEAVES:3)
Block(-2,36,-2,LEAVES:3)
Block(-2,36,-1,LEAVES:3)
Block(-2,36,0,LEAVES:3)
Block(-2,36,1,LEAVES:3)
Block(-2,36,2,LEAVES:3)
Block(-2,36,3,LEAVES:3)
Block(-2,36,4,LEAVES:3)
Block(-2,37,1,LEAVES:3)
Block(-1,24,-1,LOG:15)
Block(-1,25,-1,LOG:15)
Block(-1,26,-1,LOG:15)
Block(-1,26,0,LOG:15)
Block(-1,27,-2,LOG:15)
Block(-1,27,-1,LOG:15)
Block(-1,27,0,LOG:15)
Block(-1,28,-1,LOG:15)
Block(-1,30,2,LOG:15)
Block(-1,30,3,LOG:15)
Block(-1,30,4,LOG:15)
Block(-1,31,-6,LOG:15)
Block(-1,31,-5,LOG:15)
Block(-1,31,3,LEAVES:3)
Block(-1,31,4,LOG:15)
Block(-1,31,9,LEAVES:3)
Block(-1,31,10,LEAVES:3)
Block(-1,32,-14,LEAVES:3)
Block(-1,32,-13,LEAVES:3)
Block(-1,32,-12,LEAVES:3)
Block(-1,32,-11,LEAVES:3)
Block(-1,32,-10,LEAVES:3)
Block(-1,32,-9,LEAVES:3)
Block(-1,32,-6,LOG:15)
Block(-1,32,-5,LEAVES:3)
Block(-1,32,-4,LEAVES:3)
Block(-1,32,-3,LEAVES:3)
Block(-1,32,-2,LEAVES:3)
Block(-1,32,-1,LEAVES:3)
Block(-1,32,0,LEAVES:3)
Block(-1,32,1,LEAVES:3)
Block(-1,32,2,LEAVES:3)
Block(-1,32,3,LEAVES:3)
Block(-1,32,4,LEAVES:3)
Block(-1,32,5,LEAVES:3)
Block(-1,32,6,LEAVES:3)
Block(-1,32,7,LEAVES:3)
Block(-1,32,8,LEAVES:3)
Block(-1,32,9,LEAVES:3)
Block(-1,32,10,LEAVES:3)
Block(-1,33,-15,LEAVES:3)
Block(-1,33,-14,LEAVES:3)
Block(-1,33,-13,LEAVES:3)
Block(-1,33,-12,LEAVES:3)
Block(-1,33,-11,LEAVES:3)
Block(-1,33,-10,LEAVES:3)
Block(-1,33,-9,LEAVES:3)
Block(-1,33,-8,LEAVES:3)
Block(-1,33,-7,LEAVES:3)
Block(-1,33,-6,LEAVES:3)
Block(-1,33,-5,LEAVES:3)
Block(-1,33,-4,LEAVES:3)
Block(-1,33,-3,LEAVES:3)
Block(-1,33,-2,LEAVES:3)
Block(-1,33,-1,LEAVES:3)
Block(-1,33,0,LEAVES:3)
Block(-1,33,1,LEAVES:3)
Block(-1,33,2,LEAVES:3)
Block(-1,33,3,LEAVES:3)
Block(-1,33,4,LEAVES:3)
Block(-1,33,5,LEAVES:3)
Block(-1,33,6,LEAVES:3)
Block(-1,33,7,LEAVES:3)
Block(-1,33,8,LEAVES:3)
Block(-1,33,9,LEAVES:3)
Block(-1,33,10,LEAVES:3)
Block(-1,33,11,LEAVES:3)
Block(-1,34,-14,LEAVES:3)
Block(-1,34,-13,LEAVES:3)
Block(-1,34,-12,LEAVES:3)
Block(-1,34,-11,LEAVES:3)
Block(-1,34,-10,LEAVES:3)
Block(-1,34,-9,LEAVES:3)
Block(-1,34,-8,LEAVES:3)
Block(-1,34,-7,LEAVES:3)
Block(-1,34,-6,LEAVES:3)
Block(-1,34,-5,LEAVES:3)
Block(-1,34,-4,LEAVES:3)
Block(-1,34,-3,LEAVES:3)
Block(-1,34,-2,LEAVES:3)
Block(-1,34,-1,LEAVES:3)
Block(-1,34,0,LEAVES:3)
Block(-1,34,1,LEAVES:3)
Block(-1,34,2,LEAVES:3)
Block(-1,34,3,LEAVES:3)
Block(-1,34,4,LEAVES:3)
Block(-1,34,5,LEAVES:3)
Block(-1,34,6,LEAVES:3)
Block(-1,34,7,LEAVES:3)
Block(-1,34,8,LEAVES:3)
Block(-1,34,9,LEAVES:3)
Block(-1,34,10,LEAVES:3)
Block(-1,34,11,LEAVES:3)
Block(-1,34,12,LEAVES:3)
Block(-1,35,-9,LEAVES:3)
Block(-1,35,-8,LEAVES:3)
Block(-1,35,-7,LEAVES:3)
Block(-1,35,-6,LEAVES:3)
Block(-1,35,-5,LEAVES:3)
Block(-1,35,-4,LEAVES:3)
Block(-1,35,-3,LEAVES:3)
Block(-1,35,-2,LEAVES:3)
Block(-1,35,-1,LEAVES:3)
Block(-1,35,0,LEAVES:3)
Block(-1,35,1,LEAVES:3)
Block(-1,35,2,LEAVES:3)
Block(-1,35,3,LEAVES:3)
Block(-1,35,4,LEAVES:3)
Block(-1,35,5,LEAVES:3)
Block(-1,35,6,LEAVES:3)
Block(-1,35,7,LEAVES:3)
Block(-1,35,8,LEAVES:3)
Block(-1,35,9,LEAVES:3)
Block(-1,36,-5,LEAVES:3)
Block(-1,36,-4,LEAVES:3)
Block(-1,36,-3,LEAVES:3)
Block(-1,36,-2,LEAVES:3)
Block(-1,36,-1,LEAVES:3)
Block(-1,36,0,LEAVES:3)
Block(-1,36,1,LEAVES:3)
Block(-1,36,2,LEAVES:3)
Block(-1,36,3,LEAVES:3)
Block(-1,37,-3,LEAVES:3)
Block(-1,37,-2,LEAVES:3)
Block(0,0,-1,LOG:15)
Block(0,0,0,LOG:15)
Block(0,1,-1,LOG:15)
Block(0,1,0,LOG:15)
Block(0,2,-1,LOG:15)
Block(0,2,0,LOG:15)
Block(0,3,-1,LOG:15)
Block(0,3,0,LOG:15)
Block(0,4,-1,LOG:15)
Block(0,4,0,LOG:15)
Block(0,5,-1,LOG:15)
Block(0,5,0,LOG:15)
Block(0,6,-1,LOG:15)
Block(0,6,0,LOG:15)
Block(0,7,-1,LOG:15)
Block(0,7,0,LOG:15)
Block(0,8,-1,LOG:15)
Block(0,8,0,LOG:15)
Block(0,9,-1,LOG:15)
Block(0,9,0,LOG:15)
Block(0,10,-1,LOG:15)
Block(0,10,0,LOG:15)
Block(0,11,-1,LOG:15)
Block(0,11,0,LOG:15)
Block(0,12,-1,LOG:15)
Block(0,12,0,LOG:15)
Block(0,13,-1,LOG:15)
Block(0,13,0,LOG:15)
Block(0,14,-1,LOG:15)
Block(0,14,0,LOG:15)
Block(0,15,-1,LOG:15)
Block(0,15,0,LOG:15)
Block(0,16,-1,LOG:15)
Block(0,16,0,LOG:15)
Block(0,17,-1,LOG:15)
Block(0,17,0,LOG:15)
Block(0,18,-1,LOG:15)
Block(0,18,0,LOG:15)
Block(0,19,-1,LOG:15)
Block(0,19,0,LOG:15)
Block(0,20,-1,LOG:15)
Block(0,20,0,LOG:15)
Block(0,21,-1,LOG:15)
Block(0,21,0,LOG:15)
Block(0,22,-1,LOG:15)
Block(0,22,0,LOG:15)
Block(0,23,-1,LOG:15)
Block(0,23,0,LOG:15)
Block(0,24,-1,LOG:15)
Block(0,24,0,LOG:15)
Block(0,25,0,LOG:15)
Block(0,26,0,LOG:15)
Block(0,27,0,LOG:15)
Block(0,27,1,LOG:15)
Block(0,28,1,LOG:15)
Block(0,29,1,LOG:15)
Block(0,29,2,LOG:15)
Block(0,30,2,LOG:15)
Block(0,31,2,LEAVES:3)
Block(0,31,10,LEAVES:3)
Block(0,32,-16,LEAVES:3)
Block(0,32,-14,LEAVES:3)
Block(0,32,-13,LEAVES:3)
Block(0,32,-12,LEAVES:3)
Block(0,32,-11,LEAVES:3)
Block(0,32,-10,LEAVES:3)
Block(0,32,-9,LEAVES:3)
Block(0,32,-7,LOG:15)
Block(0,32,-6,LOG:15)
Block(0,32,-5,LEAVES:3)
Block(0,32,-4,LEAVES:3)
Block(0,32,-3,LEAVES:3)
Block(0,32,-2,LEAVES:3)
Block(0,32,-1,LEAVES:3)
Block(0,32,0,LEAVES:3)
Block(0,32,1,LEAVES:3)
Block(0,32,2,LEAVES:3)
Block(0,32,3,LEAVES:3)
Block(0,32,4,LEAVES:3)
Block(0,32,5,LEAVES:3)
Block(0,32,6,LEAVES:3)
Block(0,32,7,LEAVES:3)
Block(0,32,8,LEAVES:3)
Block(0,32,9,LEAVES:3)
Block(0,32,10,LEAVES:3)
Block(0,33,-15,LEAVES:3)
Block(0,33,-14,LEAVES:3)
Block(0,33,-13,LEAVES:3)
Block(0,33,-12,LEAVES:3)
Block(0,33,-11,LEAVES:3)
Block(0,33,-10,LEAVES:3)
Block(0,33,-9,LEAVES:3)
Block(0,33,-8,LEAVES:3)
Block(0,33,-7,LEAVES:3)
Block(0,33,-6,LEAVES:3)
Block(0,33,-5,LEAVES:3)
Block(0,33,-4,LEAVES:3)
Block(0,33,-3,LEAVES:3)
Block(0,33,-2,LEAVES:3)
Block(0,33,-1,LEAVES:3)
Block(0,33,0,LEAVES:3)
Block(0,33,1,LEAVES:3)
Block(0,33,2,LEAVES:3)
Block(0,33,3,LEAVES:3)
Block(0,33,4,LEAVES:3)
Block(0,33,5,LEAVES:3)
Block(0,33,6,LEAVES:3)
Block(0,33,7,LEAVES:3)
Block(0,33,8,LEAVES:3)
Block(0,33,9,LEAVES:3)
Block(0,33,10,LEAVES:3)
Block(0,33,11,LEAVES:3)
Block(0,34,-13,LEAVES:3)
Block(0,34,-12,LEAVES:3)
Block(0,34,-11,LEAVES:3)
Block(0,34,-10,LEAVES:3)
Block(0,34,-9,LEAVES:3)
Block(0,34,-8,LEAVES:3)
Block(0,34,-7,LEAVES:3)
Block(0,34,-6,LEAVES:3)
Block(0,34,-5,LEAVES:3)
Block(0,34,-4,LEAVES:3)
Block(0,34,-3,LEAVES:3)
Block(0,34,-2,LEAVES:3)
Block(0,34,-1,LEAVES:3)
Block(0,34,0,LEAVES:3)
Block(0,34,1,LEAVES:3)
Block(0,34,2,LEAVES:3)
Block(0,34,3,LEAVES:3)
Block(0,34,4,LEAVES:3)
Block(0,34,5,LEAVES:3)
Block(0,34,6,LEAVES:3)
Block(0,34,7,LEAVES:3)
Block(0,34,8,LEAVES:3)
Block(0,34,9,LEAVES:3)
Block(0,34,10,LEAVES:3)
Block(0,34,11,LEAVES:3)
Block(0,34,12,LEAVES:3)
Block(0,34,13,LEAVES:3)
Block(0,35,-11,LEAVES:3)
Block(0,35,-10,LEAVES:3)
Block(0,35,-9,LEAVES:3)
Block(0,35,-8,LEAVES:3)
Block(0,35,-7,LEAVES:3)
Block(0,35,-6,LEAVES:3)
Block(0,35,-5,LEAVES:3)
Block(0,35,-4,LEAVES:3)
Block(0,35,-3,LEAVES:3)
Block(0,35,-2,LEAVES:3)
Block(0,35,-1,LEAVES:3)
Block(0,35,0,LEAVES:3)
Block(0,35,1,LEAVES:3)
Block(0,35,2,LEAVES:3)
Block(0,35,3,LEAVES:3)
Block(0,35,4,LEAVES:3)
Block(0,35,5,LEAVES:3)
Block(0,35,6,LEAVES:3)
Block(0,35,7,LEAVES:3)
Block(0,35,8,LEAVES:3)
Block(0,35,9,LEAVES:3)
Block(0,35,10,LEAVES:3)
Block(0,35,12,LEAVES:3)
Block(0,36,-5,LEAVES:3)
Block(0,36,-4,LEAVES:3)
Block(0,36,-3,LEAVES:3)
Block(0,36,-2,LEAVES:3)
Block(0,36,-1,LEAVES:3)
Block(0,36,0,LEAVES:3)
Block(0,36,1,LEAVES:3)
Block(0,36,2,LEAVES:3)
Block(0,36,3,LEAVES:3)
Block(0,37,-2,LEAVES:3)
Block(0,37,-1,LEAVES:3)
Block(0,37,0,LEAVES:3)
Block(1,0,0,LOG:15)
Block(1,1,0,LOG:15)
Block(1,2,0,LOG:15)
Block(1,3,0,LOG:15)
Block(1,4,0,LOG:15)
Block(1,5,0,LOG:15)
Block(1,6,0,LOG:15)
Block(1,7,0,LOG:15)
Block(1,8,0,LOG:15)
Block(1,9,0,LOG:15)
Block(1,10,0,LOG:15)
Block(1,11,0,LOG:15)
Block(1,12,0,LOG:15)
Block(1,13,0,LOG:15)
Block(1,14,0,LOG:15)
Block(1,15,0,LOG:15)
Block(1,16,0,LOG:15)
Block(1,17,0,LOG:15)
Block(1,18,0,LOG:15)
Block(1,19,0,LOG:15)
Block(1,20,0,LOG:15)
Block(1,21,0,LOG:15)
Block(1,22,0,LOG:15)
Block(1,23,0,LOG:15)
Block(1,24,-1,LOG:15)
Block(1,24,0,LOG:15)
Block(1,25,-2,LOG:15)
Block(1,25,-1,LOG:15)
Block(1,28,1,LOG:15)
Block(1,29,1,LOG:15)
Block(1,30,1,LOG:15)
Block(1,30,2,LOG:15)
Block(1,30,3,LOG:15)
Block(1,30,4,LOG:15)
Block(1,31,0,LOG:15)
Block(1,31,1,LOG:15)
Block(1,31,2,LEAVES:3)
Block(1,31,3,LEAVES:3)
Block(1,31,4,LOG:15)
Block(1,32,-15,LEAVES:3)
Block(1,32,-13,LEAVES:3)
Block(1,32,-12,LEAVES:3)
Block(1,32,-10,LEAVES:3)
Block(1,32,-9,LEAVES:3)
Block(1,32,-8,LEAVES:3)
Block(1,32,-7,LOG:15)
Block(1,32,-6,LEAVES:3)
Block(1,32,-5,LEAVES:3)
Block(1,32,-4,LEAVES:3)
Block(1,32,-3,LEAVES:3)
Block(1,32,-2,LEAVES:3)
Block(1,32,-1,LEAVES:3)
Block(1,32,0,LOG:15)
Block(1,32,1,LEAVES:3)
Block(1,32,2,LEAVES:3)
Block(1,32,3,LEAVES:3)
Block(1,32,4,LEAVES:3)
Block(1,32,5,LEAVES:3)
Block(1,32,6,LEAVES:3)
Block(1,32,7,LEAVES:3)
Block(1,32,8,LEAVES:3)
Block(1,32,9,LEAVES:3)
Block(1,33,-15,LEAVES:3)
Block(1,33,-14,LEAVES:3)
Block(1,33,-13,LEAVES:3)
Block(1,33,-12,LEAVES:3)
Block(1,33,-11,LEAVES:3)
Block(1,33,-10,LEAVES:3)
Block(1,33,-9,LEAVES:3)
Block(1,33,-8,LOG:15)
Block(1,33,-7,LOG:15)
Block(1,33,-6,LEAVES:3)
Block(1,33,-5,LEAVES:3)
Block(1,33,-4,LEAVES:3)
Block(1,33,-3,LEAVES:3)
Block(1,33,-2,LEAVES:3)
Block(1,33,-1,LOG:15)
Block(1,33,0,LOG:15)
Block(1,33,1,LEAVES:3)
Block(1,33,2,LEAVES:3)
Block(1,33,3,LEAVES:3)
Block(1,33,4,LEAVES:3)
Block(1,33,5,LEAVES:3)
Block(1,33,6,LEAVES:3)
Block(1,33,7,LEAVES:3)
Block(1,33,8,LEAVES:3)
Block(1,33,9,LEAVES:3)
Block(1,33,10,LEAVES:3)
Block(1,33,11,LEAVES:3)
Block(1,34,-13,LEAVES:3)
Block(1,34,-12,LEAVES:3)
Block(1,34,-11,LEAVES:3)
Block(1,34,-10,LEAVES:3)
Block(1,34,-9,LEAVES:3)
Block(1,34,-8,LEAVES:3)
Block(1,34,-7,LEAVES:3)
Block(1,34,-6,LEAVES:3)
Block(1,34,-5,LEAVES:3)
Block(1,34,-4,LEAVES:3)
Block(1,34,-3,LEAVES:3)
Block(1,34,-2,LEAVES:3)
Block(1,34,-1,LOG:15)
Block(1,34,0,LEAVES:3)
Block(1,34,1,LEAVES:3)
Block(1,34,2,LEAVES:3)
Block(1,34,3,LEAVES:3)
Block(1,34,4,LEAVES:3)
Block(1,34,5,LEAVES:3)
Block(1,34,6,LEAVES:3)
Block(1,34,7,LEAVES:3)
Block(1,34,8,LEAVES:3)
Block(1,34,9,LEAVES:3)
Block(1,34,10,LEAVES:3)
Block(1,34,11,LEAVES:3)
Block(1,35,-10,LEAVES:3)
Block(1,35,-9,LEAVES:3)
Block(1,35,-8,LEAVES:3)
Block(1,35,-7,LEAVES:3)
Block(1,35,-6,LEAVES:3)
Block(1,35,-5,LEAVES:3)
Block(1,35,-4,LEAVES:3)
Block(1,35,-3,LEAVES:3)
Block(1,35,-2,LEAVES:3)
Block(1,35,-1,LOG:15)
Block(1,35,0,LEAVES:3)
Block(1,35,1,LEAVES:3)
Block(1,35,2,LEAVES:3)
Block(1,35,3,LEAVES:3)
Block(1,35,4,LEAVES:3)
Block(1,35,5,LEAVES:3)
Block(1,35,6,LEAVES:3)
Block(1,35,7,LEAVES:3)
Block(1,35,8,LEAVES:3)
Block(1,35,9,LEAVES:3)
Block(1,35,10,LEAVES:3)
Block(1,35,11,LEAVES:3)
Block(1,36,-6,LEAVES:3)
Block(1,36,-5,LEAVES:3)
Block(1,36,-4,LEAVES:3)
Block(1,36,-3,LEAVES:3)
Block(1,36,-2,LEAVES:3)
Block(1,36,-1,LEAVES:3)
Block(1,36,0,LEAVES:3)
Block(1,36,1,LEAVES:3)
Block(1,36,2,LEAVES:3)
Block(1,37,-2,LEAVES:3)
Block(1,37,-1,LEAVES:3)
Block(2,25,-2,WOOD_DOUBLE_STEP:5)
Block(2,30,0,LEAVES:3)
Block(2,30,1,LOG:15)
Block(2,31,-10,LEAVES:3)
Block(2,31,-9,LEAVES:3)
Block(2,31,-6,LEAVES:3)
Block(2,31,-5,LEAVES:3)
Block(2,31,-4,LEAVES:3)
Block(2,31,-3,LEAVES:3)
Block(2,31,-2,LEAVES:3)
Block(2,31,-1,LEAVES:3)
Block(2,31,0,LEAVES:3)
Block(2,31,1,LEAVES:3)
Block(2,31,2,LEAVES:3)
Block(2,31,4,LOG:15)
Block(2,31,5,LOG:15)
Block(2,32,-13,LEAVES:3)
Block(2,32,-12,LEAVES:3)
Block(2,32,-11,LEAVES:3)
Block(2,32,-10,LEAVES:3)
Block(2,32,-9,LEAVES:3)
Block(2,32,-8,LEAVES:3)
Block(2,32,-7,LEAVES:3)
Block(2,32,-6,LEAVES:3)
Block(2,32,-5,LEAVES:3)
Block(2,32,-4,LEAVES:3)
Block(2,32,-3,LEAVES:3)
Block(2,32,-2,LEAVES:3)
Block(2,32,-1,LEAVES:3)
Block(2,32,0,LEAVES:3)
Block(2,32,1,LEAVES:3)
Block(2,32,2,LEAVES:3)
Block(2,32,3,LEAVES:3)
Block(2,32,4,LEAVES:3)
Block(2,32,5,LOG:15)
Block(2,33,-14,LEAVES:3)
Block(2,33,-13,LEAVES:3)
Block(2,33,-12,LEAVES:3)
Block(2,33,-11,LEAVES:3)
Block(2,33,-10,LEAVES:3)
Block(2,33,-9,LOG:15)
Block(2,33,-8,LOG:15)
Block(2,33,-7,LEAVES:3)
Block(2,33,-6,LEAVES:3)
Block(2,33,-5,LEAVES:3)
Block(2,33,-4,LEAVES:3)
Block(2,33,-3,LEAVES:3)
Block(2,33,-2,LEAVES:3)
Block(2,33,-1,LEAVES:3)
Block(2,33,0,LEAVES:3)
Block(2,33,1,LEAVES:3)
Block(2,33,2,LEAVES:3)
Block(2,33,3,LEAVES:3)
Block(2,33,4,LEAVES:3)
Block(2,33,5,LEAVES:3)
Block(2,33,6,LEAVES:3)
Block(2,33,7,LEAVES:3)
Block(2,33,8,LEAVES:3)
Block(2,33,9,LEAVES:3)
Block(2,33,10,LEAVES:3)
Block(2,34,-14,LEAVES:3)
Block(2,34,-13,LEAVES:3)
Block(2,34,-12,LEAVES:3)
Block(2,34,-11,LEAVES:3)
Block(2,34,-10,LEAVES:3)
Block(2,34,-9,LEAVES:3)
Block(2,34,-8,LEAVES:3)
Block(2,34,-7,LEAVES:3)
Block(2,34,-6,LEAVES:3)
Block(2,34,-5,LEAVES:3)
Block(2,34,-4,LEAVES:3)
Block(2,34,-3,LEAVES:3)
Block(2,34,-2,LEAVES:3)
Block(2,34,-1,LEAVES:3)
Block(2,34,0,LEAVES:3)
Block(2,34,1,LEAVES:3)
Block(2,34,2,LEAVES:3)
Block(2,34,3,LEAVES:3)
Block(2,34,4,LEAVES:3)
Block(2,34,5,LEAVES:3)
Block(2,34,6,LEAVES:3)
Block(2,34,7,LEAVES:3)
Block(2,34,8,LEAVES:3)
Block(2,34,9,LEAVES:3)
Block(2,34,10,LEAVES:3)
Block(2,34,11,LEAVES:3)
Block(2,35,-10,LEAVES:3)
Block(2,35,-9,LEAVES:3)
Block(2,35,-8,LEAVES:3)
Block(2,35,-7,LEAVES:3)
Block(2,35,-6,LEAVES:3)
Block(2,35,-5,LEAVES:3)
Block(2,35,-4,LEAVES:3)
Block(2,35,-3,LEAVES:3)
Block(2,35,-2,LEAVES:3)
Block(2,35,-1,LEAVES:3)
Block(2,35,0,LEAVES:3)
Block(2,35,1,LEAVES:3)
Block(2,35,2,LEAVES:3)
Block(2,35,3,LEAVES:3)
Block(2,35,4,LEAVES:3)
Block(2,35,5,LEAVES:3)
Block(2,35,6,LEAVES:3)
Block(2,35,7,LEAVES:3)
Block(2,35,8,LEAVES:3)
Block(2,35,9,LEAVES:3)
Block(2,35,10,LEAVES:3)
Block(2,36,-6,LEAVES:3)
Block(2,36,-5,LEAVES:3)
Block(2,36,-4,LEAVES:3)
Block(2,36,-3,LEAVES:3)
Block(2,36,-2,LEAVES:3)
Block(2,36,-1,LEAVES:3)
Block(2,36,0,LEAVES:3)
Block(2,36,1,LEAVES:3)
Block(2,36,5,LEAVES:3)
Block(2,36,6,LEAVES:3)
Block(2,37,-4,LEAVES:3)
Block(2,37,-2,LEAVES:3)
Block(2,37,-1,LEAVES:3)
Block(3,30,-4,LEAVES:3)
Block(3,30,0,LEAVES:3)
Block(3,30,1,LOG:15)
Block(3,31,-11,LEAVES:3)
Block(3,31,-10,LEAVES:3)
Block(3,31,-9,LEAVES:3)
Block(3,31,-8,LEAVES:3)
Block(3,31,-7,LEAVES:3)
Block(3,31,-6,LEAVES:3)
Block(3,31,-5,LEAVES:3)
Block(3,31,-4,LEAVES:3)
Block(3,31,-3,LEAVES:3)
Block(3,31,-2,LEAVES:3)
Block(3,31,-1,LEAVES:3)
Block(3,31,0,LEAVES:3)
Block(3,31,1,LEAVES:3)
Block(3,31,2,LEAVES:3)
Block(3,32,-16,LEAVES:3)
Block(3,32,-14,LEAVES:3)
Block(3,32,-13,LEAVES:3)
Block(3,32,-12,LEAVES:3)
Block(3,32,-11,LEAVES:3)
Block(3,32,-10,LEAVES:3)
Block(3,32,-9,LEAVES:3)
Block(3,32,-8,LEAVES:3)
Block(3,32,-7,LEAVES:3)
Block(3,32,-6,LEAVES:3)
Block(3,32,-5,LEAVES:3)
Block(3,32,-4,LEAVES:3)
Block(3,32,-3,LEAVES:3)
Block(3,32,-2,LEAVES:3)
Block(3,32,-1,LEAVES:3)
Block(3,32,0,LEAVES:3)
Block(3,32,1,LEAVES:3)
Block(3,32,2,LEAVES:3)
Block(3,32,3,LEAVES:3)
Block(3,32,4,LEAVES:3)
Block(3,32,5,LOG:15)
Block(3,32,6,LOG:15)
Block(3,33,-16,LEAVES:3)
Block(3,33,-15,LEAVES:3)
Block(3,33,-14,LEAVES:3)
Block(3,33,-13,LEAVES:3)
Block(3,33,-12,LEAVES:3)
Block(3,33,-11,LEAVES:3)
Block(3,33,-10,LEAVES:3)
Block(3,33,-9,LEAVES:3)
Block(3,33,-8,LEAVES:3)
Block(3,33,-7,LEAVES:3)
Block(3,33,-6,LEAVES:3)
Block(3,33,-5,LEAVES:3)
Block(3,33,-4,LEAVES:3)
Block(3,33,-3,LEAVES:3)
Block(3,33,-2,LEAVES:3)
Block(3,33,-1,LEAVES:3)
Block(3,33,0,LEAVES:3)
Block(3,33,1,LEAVES:3)
Block(3,33,2,LEAVES:3)
Block(3,33,3,LEAVES:3)
Block(3,33,4,LEAVES:3)
Block(3,33,5,LEAVES:3)
Block(3,33,6,LOG:15)
Block(3,33,7,LEAVES:3)
Block(3,33,8,LEAVES:3)
Block(3,33,9,LEAVES:3)
Block(3,33,10,LEAVES:3)
Block(3,34,-13,LEAVES:3)
Block(3,34,-12,LEAVES:3)
Block(3,34,-11,LEAVES:3)
Block(3,34,-10,LEAVES:3)
Block(3,34,-9,LEAVES:3)
Block(3,34,-8,LEAVES:3)
Block(3,34,-7,LEAVES:3)
Block(3,34,-6,LEAVES:3)
Block(3,34,-5,LEAVES:3)
Block(3,34,-4,LEAVES:3)
Block(3,34,-3,LEAVES:3)
Block(3,34,-2,LEAVES:3)
Block(3,34,-1,LEAVES:3)
Block(3,34,0,LEAVES:3)
Block(3,34,1,LEAVES:3)
Block(3,34,2,LEAVES:3)
Block(3,34,3,LEAVES:3)
Block(3,34,4,LEAVES:3)
Block(3,34,5,LEAVES:3)
Block(3,34,6,LEAVES:3)
Block(3,34,7,LEAVES:3)
Block(3,34,8,LEAVES:3)
Block(3,34,9,LEAVES:3)
Block(3,34,10,LEAVES:3)
Block(3,35,-12,LEAVES:3)
Block(3,35,-10,LEAVES:3)
Block(3,35,-9,LEAVES:3)
Block(3,35,-8,LEAVES:3)
Block(3,35,-7,LEAVES:3)
Block(3,35,-6,LEAVES:3)
Block(3,35,-5,LEAVES:3)
Block(3,35,-4,LEAVES:3)
Block(3,35,-3,LEAVES:3)
Block(3,35,-2,LEAVES:3)
Block(3,35,-1,LEAVES:3)
Block(3,35,0,LEAVES:3)
Block(3,35,1,LEAVES:3)
Block(3,35,2,LEAVES:3)
Block(3,35,3,LEAVES:3)
Block(3,35,4,LEAVES:3)
Block(3,35,5,LEAVES:3)
Block(3,35,6,LEAVES:3)
Block(3,35,7,LEAVES:3)
Block(3,35,8,LEAVES:3)
Block(3,35,9,LEAVES:3)
Block(3,36,-6,LEAVES:3)
Block(3,36,-5,LEAVES:3)
Block(3,36,-4,LEAVES:3)
Block(3,36,-3,LEAVES:3)
Block(3,36,-2,LEAVES:3)
Block(3,36,-1,LEAVES:3)
Block(3,36,0,LEAVES:3)
Block(3,36,3,LEAVES:3)
Block(3,36,6,LEAVES:3)
Block(3,36,7,LEAVES:3)
Block(3,37,-2,LEAVES:3)
Block(3,37,-1,LEAVES:3)
Block(4,30,-11,LEAVES:3)
Block(4,30,-10,LEAVES:3)
Block(4,30,-4,LEAVES:3)
Block(4,30,1,LOG:15)
Block(4,31,-14,LEAVES:3)
Block(4,31,-12,LEAVES:3)
Block(4,31,-11,LEAVES:3)
Block(4,31,-10,LEAVES:3)
Block(4,31,-9,LEAVES:3)
Block(4,31,-8,LEAVES:3)
Block(4,31,-7,LEAVES:3)
Block(4,31,-6,LEAVES:3)
Block(4,31,-5,LEAVES:3)
Block(4,31,-4,LEAVES:3)
Block(4,31,-3,LEAVES:3)
Block(4,31,-2,LEAVES:3)
Block(4,31,-1,LEAVES:3)
Block(4,31,0,LOG:15)
Block(4,31,1,LOG:15)
Block(4,31,2,LEAVES:3)
Block(4,32,-17,LEAVES:3)
Block(4,32,-16,LEAVES:3)
Block(4,32,-15,LEAVES:3)
Block(4,32,-14,LEAVES:3)
Block(4,32,-13,LEAVES:3)
Block(4,32,-12,LEAVES:3)
Block(4,32,-11,LEAVES:3)
Block(4,32,-10,LEAVES:3)
Block(4,32,-9,LEAVES:3)
Block(4,32,-8,LEAVES:3)
Block(4,32,-7,LEAVES:3)
Block(4,32,-6,LEAVES:3)
Block(4,32,-5,LEAVES:3)
Block(4,32,-4,LEAVES:3)
Block(4,32,-3,LEAVES:3)
Block(4,32,-2,LEAVES:3)
Block(4,32,-1,LEAVES:3)
Block(4,32,0,LEAVES:3)
Block(4,32,1,LEAVES:3)
Block(4,32,2,LEAVES:3)
Block(4,32,3,LEAVES:3)
Block(4,32,4,LEAVES:3)
Block(4,33,-15,LEAVES:3)
Block(4,33,-14,LEAVES:3)
Block(4,33,-13,LEAVES:3)
Block(4,33,-12,LEAVES:3)
Block(4,33,-11,LEAVES:3)
Block(4,33,-10,LEAVES:3)
Block(4,33,-9,LEAVES:3)
Block(4,33,-8,LEAVES:3)
Block(4,33,-7,LEAVES:3)
Block(4,33,-6,LEAVES:3)
Block(4,33,-5,LEAVES:3)
Block(4,33,-4,LEAVES:3)
Block(4,33,-3,LEAVES:3)
Block(4,33,-2,LEAVES:3)
Block(4,33,-1,LEAVES:3)
Block(4,33,0,LEAVES:3)
Block(4,33,1,LEAVES:3)
Block(4,33,2,LEAVES:3)
Block(4,33,3,LEAVES:3)
Block(4,33,4,LEAVES:3)
Block(4,33,5,LEAVES:3)
Block(4,33,6,LOG:15)
Block(4,33,7,LOG:15)
Block(4,33,8,LEAVES:3)
Block(4,33,9,LEAVES:3)
Block(4,33,10,LEAVES:3)
Block(4,34,-14,LEAVES:3)
Block(4,34,-13,LEAVES:3)
Block(4,34,-12,LEAVES:3)
Block(4,34,-11,LEAVES:3)
Block(4,34,-10,LEAVES:3)
Block(4,34,-9,LEAVES:3)
Block(4,34,-8,LEAVES:3)
Block(4,34,-7,LEAVES:3)
Block(4,34,-6,LEAVES:3)
Block(4,34,-5,LEAVES:3)
Block(4,34,-4,LEAVES:3)
Block(4,34,-3,LEAVES:3)
Block(4,34,-2,LEAVES:3)
Block(4,34,-1,LEAVES:3)
Block(4,34,0,LEAVES:3)
Block(4,34,1,LEAVES:3)
Block(4,34,2,LEAVES:3)
Block(4,34,3,LEAVES:3)
Block(4,34,4,LEAVES:3)
Block(4,34,5,LEAVES:3)
Block(4,34,6,LEAVES:3)
Block(4,34,7,LOG:15)
Block(4,34,8,LEAVES:3)
Block(4,34,9,LEAVES:3)
Block(4,34,10,LEAVES:3)
Block(4,35,-10,LEAVES:3)
Block(4,35,-9,LEAVES:3)
Block(4,35,-8,LEAVES:3)
Block(4,35,-7,LEAVES:3)
Block(4,35,-6,LEAVES:3)
Block(4,35,-5,LEAVES:3)
Block(4,35,-4,LEAVES:3)
Block(4,35,-3,LEAVES:3)
Block(4,35,-2,LEAVES:3)
Block(4,35,-1,LEAVES:3)
Block(4,35,0,LEAVES:3)
Block(4,35,1,LEAVES:3)
Block(4,35,2,LEAVES:3)
Block(4,35,3,LEAVES:3)
Block(4,35,4,LEAVES:3)
Block(4,35,5,LEAVES:3)
Block(4,35,6,LEAVES:3)
Block(4,35,7,LEAVES:3)
Block(4,35,8,LEAVES:3)
Block(4,35,9,LEAVES:3)
Block(4,36,-5,LEAVES:3)
Block(4,36,-4,LEAVES:3)
Block(4,36,-3,LEAVES:3)
Block(4,36,-2,LEAVES:3)
Block(4,36,-1,LEAVES:3)
Block(4,36,0,LEAVES:3)
Block(4,36,6,LEAVES:3)
Block(4,36,7,LEAVES:3)
Block(5,30,-11,LEAVES:3)
Block(5,30,-7,LEAVES:3)
Block(5,30,-3,LEAVES:3)
Block(5,30,0,LEAVES:3)
Block(5,31,-15,LEAVES:3)
Block(5,31,-12,LEAVES:3)
Block(5,31,-11,LEAVES:3)
Block(5,31,-10,LEAVES:3)
Block(5,31,-9,LEAVES:3)
Block(5,31,-8,LEAVES:3)
Block(5,31,-7,LEAVES:3)
Block(5,31,-6,LEAVES:3)
Block(5,31,-4,LEAVES:3)
Block(5,31,-3,LEAVES:3)
Block(5,31,-2,LEAVES:3)
Block(5,31,-1,LEAVES:3)
Block(5,31,0,LOG:15)
Block(5,31,1,LEAVES:3)
Block(5,31,2,LEAVES:3)
Block(5,32,-14,LEAVES:3)
Block(5,32,-13,LEAVES:3)
Block(5,32,-12,LEAVES:3)
Block(5,32,-11,LEAVES:3)
Block(5,32,-10,LEAVES:3)
Block(5,32,-9,LEAVES:3)
Block(5,32,-8,LEAVES:3)
Block(5,32,-7,LEAVES:3)
Block(5,32,-6,LEAVES:3)
Block(5,32,-5,LEAVES:3)
Block(5,32,-4,LEAVES:3)
Block(5,32,-3,LEAVES:3)
Block(5,32,-2,LEAVES:3)
Block(5,32,-1,LEAVES:3)
Block(5,32,0,LEAVES:3)
Block(5,32,1,LEAVES:3)
Block(5,32,2,LEAVES:3)
Block(5,32,3,LEAVES:3)
Block(5,32,4,LEAVES:3)
Block(5,32,5,LEAVES:3)
Block(5,32,9,LEAVES:3)
Block(5,33,-16,LEAVES:3)
Block(5,33,-15,LEAVES:3)
Block(5,33,-14,LEAVES:3)
Block(5,33,-13,LEAVES:3)
Block(5,33,-12,LEAVES:3)
Block(5,33,-11,LEAVES:3)
Block(5,33,-10,LEAVES:3)
Block(5,33,-9,LEAVES:3)
Block(5,33,-8,LEAVES:3)
Block(5,33,-7,LEAVES:3)
Block(5,33,-6,LEAVES:3)
Block(5,33,-5,LEAVES:3)
Block(5,33,-4,LEAVES:3)
Block(5,33,-3,LEAVES:3)
Block(5,33,-2,LEAVES:3)
Block(5,33,-1,LEAVES:3)
Block(5,33,0,LEAVES:3)
Block(5,33,1,LEAVES:3)
Block(5,33,2,LEAVES:3)
Block(5,33,3,LEAVES:3)
Block(5,33,4,LEAVES:3)
Block(5,33,5,LEAVES:3)
Block(5,33,6,LEAVES:3)
Block(5,33,7,LEAVES:3)
Block(5,33,8,LEAVES:3)
Block(5,33,9,LEAVES:3)
Block(5,33,10,LEAVES:3)
Block(5,34,-14,LEAVES:3)
Block(5,34,-13,LEAVES:3)
Block(5,34,-12,LEAVES:3)
Block(5,34,-11,LEAVES:3)
Block(5,34,-10,LEAVES:3)
Block(5,34,-9,LEAVES:3)
Block(5,34,-8,LEAVES:3)
Block(5,34,-7,LEAVES:3)
Block(5,34,-6,LEAVES:3)
Block(5,34,-5,LEAVES:3)
Block(5,34,-4,LEAVES:3)
Block(5,34,-3,LEAVES:3)
Block(5,34,-2,LEAVES:3)
Block(5,34,-1,LEAVES:3)
Block(5,34,0,LEAVES:3)
Block(5,34,1,LEAVES:3)
Block(5,34,2,LEAVES:3)
Block(5,34,3,LEAVES:3)
Block(5,34,4,LEAVES:3)
Block(5,34,5,LEAVES:3)
Block(5,34,6,LEAVES:3)
Block(5,34,7,LEAVES:3)
Block(5,34,8,LEAVES:3)
Block(5,34,9,LEAVES:3)
Block(5,34,10,LEAVES:3)
Block(5,35,-10,LEAVES:3)
Block(5,35,-7,LEAVES:3)
Block(5,35,-6,LEAVES:3)
Block(5,35,-5,LEAVES:3)
Block(5,35,-4,LEAVES:3)
Block(5,35,-3,LEAVES:3)
Block(5,35,-2,LEAVES:3)
Block(5,35,-1,LEAVES:3)
Block(5,35,0,LEAVES:3)
Block(5,35,1,LEAVES:3)
Block(5,35,2,LEAVES:3)
Block(5,35,3,LEAVES:3)
Block(5,35,4,LEAVES:3)
Block(5,35,5,LEAVES:3)
Block(5,35,6,LEAVES:3)
Block(5,35,7,LEAVES:3)
Block(5,35,8,LEAVES:3)
Block(5,35,9,LEAVES:3)
Block(5,36,-7,LEAVES:3)
Block(5,36,-4,LEAVES:3)
Block(5,36,-3,LEAVES:3)
Block(5,36,-2,LEAVES:3)
Block(5,36,1,LEAVES:3)
Block(5,36,4,LEAVES:3)
Block(5,36,6,LEAVES:3)
Block(5,36,7,LEAVES:3)
Block(6,30,-3,LEAVES:3)
Block(6,31,-12,LEAVES:3)
Block(6,31,-7,LEAVES:3)
Block(6,31,-6,LEAVES:3)
Block(6,31,-5,LEAVES:3)
Block(6,31,-4,LEAVES:3)
Block(6,31,-3,LEAVES:3)
Block(6,31,-2,LEAVES:3)
Block(6,31,-1,LEAVES:3)
Block(6,31,0,LOG:15)
Block(6,31,1,LEAVES:3)
Block(6,31,2,LEAVES:3)
Block(6,31,3,LEAVES:3)
Block(6,32,-13,LEAVES:3)
Block(6,32,-12,LEAVES:3)
Block(6,32,-11,LEAVES:3)
Block(6,32,-10,LEAVES:3)
Block(6,32,-9,LEAVES:3)
Block(6,32,-8,LEAVES:3)
Block(6,32,-7,LEAVES:3)
Block(6,32,-6,LEAVES:3)
Block(6,32,-5,LEAVES:3)
Block(6,32,-4,LEAVES:3)
Block(6,32,-3,LEAVES:3)
Block(6,32,-2,LEAVES:3)
Block(6,32,-1,LEAVES:3)
Block(6,32,0,LOG:15)
Block(6,32,1,LEAVES:3)
Block(6,32,2,LEAVES:3)
Block(6,32,3,LEAVES:3)
Block(6,32,4,LEAVES:3)
Block(6,32,5,LEAVES:3)
Block(6,32,9,LEAVES:3)
Block(6,33,-14,LEAVES:3)
Block(6,33,-13,LEAVES:3)
Block(6,33,-12,LEAVES:3)
Block(6,33,-11,LEAVES:3)
Block(6,33,-10,LEAVES:3)
Block(6,33,-9,LEAVES:3)
Block(6,33,-8,LEAVES:3)
Block(6,33,-7,LEAVES:3)
Block(6,33,-6,LEAVES:3)
Block(6,33,-5,LEAVES:3)
Block(6,33,-4,LEAVES:3)
Block(6,33,-3,LEAVES:3)
Block(6,33,-2,LEAVES:3)
Block(6,33,-1,LEAVES:3)
Block(6,33,0,LEAVES:3)
Block(6,33,1,LEAVES:3)
Block(6,33,2,LEAVES:3)
Block(6,33,3,LEAVES:3)
Block(6,33,4,LEAVES:3)
Block(6,33,5,LEAVES:3)
Block(6,33,6,LEAVES:3)
Block(6,33,7,LEAVES:3)
Block(6,33,8,LEAVES:3)
Block(6,33,9,LEAVES:3)
Block(6,33,10,LEAVES:3)
Block(6,34,-15,LEAVES:3)
Block(6,34,-14,LEAVES:3)
Block(6,34,-11,LEAVES:3)
Block(6,34,-7,LEAVES:3)
Block(6,34,-6,LEAVES:3)
Block(6,34,-5,LEAVES:3)
Block(6,34,-4,LEAVES:3)
Block(6,34,-3,LEAVES:3)
Block(6,34,-2,LEAVES:3)
Block(6,34,-1,LEAVES:3)
Block(6,34,0,LEAVES:3)
Block(6,34,1,LEAVES:3)
Block(6,34,2,LEAVES:3)
Block(6,34,3,LEAVES:3)
Block(6,34,4,LEAVES:3)
Block(6,34,5,LEAVES:3)
Block(6,34,6,LEAVES:3)
Block(6,34,7,LEAVES:3)
Block(6,34,8,LEAVES:3)
Block(6,34,9,LEAVES:3)
Block(6,35,-6,LEAVES:3)
Block(6,35,-5,LEAVES:3)
Block(6,35,-4,LEAVES:3)
Block(6,35,-3,LEAVES:3)
Block(6,35,-2,LEAVES:3)
Block(6,35,-1,LEAVES:3)
Block(6,35,0,LEAVES:3)
Block(6,35,1,LEAVES:3)
Block(6,35,2,LEAVES:3)
Block(6,35,3,LEAVES:3)
Block(6,35,4,LEAVES:3)
Block(6,35,5,LEAVES:3)
Block(6,35,6,LEAVES:3)
Block(6,35,7,LEAVES:3)
Block(6,35,8,LEAVES:3)
Block(6,36,-4,LEAVES:3)
Block(6,36,-3,LEAVES:3)
Block(7,30,1,LEAVES:3)
Block(7,31,-8,LEAVES:3)
Block(7,31,-6,LEAVES:3)
Block(7,31,-5,LEAVES:3)
Block(7,31,-4,LEAVES:3)
Block(7,31,-3,LEAVES:3)
Block(7,31,-2,LEAVES:3)
Block(7,31,-1,LEAVES:3)
Block(7,31,0,LEAVES:3)
Block(7,31,1,LEAVES:3)
Block(7,31,2,LEAVES:3)
Block(7,31,3,LEAVES:3)
Block(7,32,-15,LEAVES:3)
Block(7,32,-14,LEAVES:3)
Block(7,32,-13,LEAVES:3)
Block(7,32,-12,LEAVES:3)
Block(7,32,-11,LEAVES:3)
Block(7,32,-10,LEAVES:3)
Block(7,32,-9,LEAVES:3)
Block(7,32,-8,LEAVES:3)
Block(7,32,-7,LEAVES:3)
Block(7,32,-6,LEAVES:3)
Block(7,32,-5,LEAVES:3)
Block(7,32,-4,LEAVES:3)
Block(7,32,-3,LEAVES:3)
Block(7,32,-2,LEAVES:3)
Block(7,32,-1,LOG:15)
Block(7,32,0,LOG:15)
Block(7,32,1,LEAVES:3)
Block(7,32,2,LEAVES:3)
Block(7,32,3,LEAVES:3)
Block(7,32,4,LEAVES:3)
Block(7,32,5,LEAVES:3)
Block(7,32,6,LEAVES:3)
Block(7,33,-13,LEAVES:3)
Block(7,33,-12,LEAVES:3)
Block(7,33,-11,LEAVES:3)
Block(7,33,-9,LEAVES:3)
Block(7,33,-8,LEAVES:3)
Block(7,33,-7,LEAVES:3)
Block(7,33,-6,LEAVES:3)
Block(7,33,-5,LEAVES:3)
Block(7,33,-4,LEAVES:3)
Block(7,33,-3,LEAVES:3)
Block(7,33,-2,LEAVES:3)
Block(7,33,-1,LEAVES:3)
Block(7,33,0,LEAVES:3)
Block(7,33,1,LEAVES:3)
Block(7,33,2,LEAVES:3)
Block(7,33,3,LEAVES:3)
Block(7,33,4,LEAVES:3)
Block(7,33,5,LEAVES:3)
Block(7,33,6,LEAVES:3)
Block(7,33,7,LEAVES:3)
Block(7,33,8,LEAVES:3)
Block(7,33,9,LEAVES:3)
Block(7,34,-12,LEAVES:3)
Block(7,34,-11,LEAVES:3)
Block(7,34,-6,LEAVES:3)
Block(7,34,-5,LEAVES:3)
Block(7,34,-4,LEAVES:3)
Block(7,34,-3,LEAVES:3)
Block(7,34,-2,LEAVES:3)
Block(7,34,-1,LEAVES:3)
Block(7,34,0,LEAVES:3)
Block(7,34,1,LEAVES:3)
Block(7,34,2,LEAVES:3)
Block(7,34,3,LEAVES:3)
Block(7,34,4,LEAVES:3)
Block(7,34,5,LEAVES:3)
Block(7,34,6,LEAVES:3)
Block(7,34,7,LEAVES:3)
Block(7,34,8,LEAVES:3)
Block(7,34,9,LEAVES:3)
Block(7,35,-6,LEAVES:3)
Block(7,35,-5,LEAVES:3)
Block(7,35,-4,LEAVES:3)
Block(7,35,-3,LEAVES:3)
Block(7,35,-2,LEAVES:3)
Block(7,35,-1,LEAVES:3)
Block(7,35,0,LEAVES:3)
Block(7,35,1,LEAVES:3)
Block(7,35,2,LEAVES:3)
Block(7,35,3,LEAVES:3)
Block(7,35,4,LEAVES:3)
Block(7,35,5,LEAVES:3)
Block(7,35,6,LEAVES:3)
Block(7,35,7,LEAVES:3)
Block(7,35,8,LEAVES:3)
Block(8,31,-7,LEAVES:3)
Block(8,31,-6,LEAVES:3)
Block(8,31,-5,LEAVES:3)
Block(8,31,-4,LEAVES:3)
Block(8,31,-3,LEAVES:3)
Block(8,31,-2,LEAVES:3)
Block(8,31,-1,LEAVES:3)
Block(8,31,0,LEAVES:3)
Block(8,31,1,LEAVES:3)
Block(8,31,2,LEAVES:3)
Block(8,31,3,LEAVES:3)
Block(8,31,6,LEAVES:3)
Block(8,32,-10,LEAVES:3)
Block(8,32,-9,LEAVES:3)
Block(8,32,-8,LEAVES:3)
Block(8,32,-7,LEAVES:3)
Block(8,32,-6,LEAVES:3)
Block(8,32,-5,LEAVES:3)
Block(8,32,-4,LEAVES:3)
Block(8,32,-3,LEAVES:3)
Block(8,32,-2,LEAVES:3)
Block(8,32,-1,LOG:15)
Block(8,32,0,LEAVES:3)
Block(8,32,1,LEAVES:3)
Block(8,32,2,LEAVES:3)
Block(8,32,3,LEAVES:3)
Block(8,32,4,LEAVES:3)
Block(8,32,5,LEAVES:3)
Block(8,32,6,LEAVES:3)
Block(8,33,-14,LEAVES:3)
Block(8,33,-13,LEAVES:3)
Block(8,33,-12,LEAVES:3)
Block(8,33,-8,LEAVES:3)
Block(8,33,-7,LEAVES:3)
Block(8,33,-6,LEAVES:3)
Block(8,33,-5,LEAVES:3)
Block(8,33,-4,LEAVES:3)
Block(8,33,-3,LEAVES:3)
Block(8,33,-2,LEAVES:3)
Block(8,33,-1,LEAVES:3)
Block(8,33,0,LEAVES:3)
Block(8,33,1,LEAVES:3)
Block(8,33,2,LEAVES:3)
Block(8,33,3,LEAVES:3)
Block(8,33,4,LEAVES:3)
Block(8,33,5,LEAVES:3)
Block(8,33,6,LEAVES:3)
Block(8,33,7,LEAVES:3)
Block(8,33,8,LEAVES:3)
Block(8,34,-5,LEAVES:3)
Block(8,34,-4,LEAVES:3)
Block(8,34,-3,LEAVES:3)
Block(8,34,-2,LEAVES:3)
Block(8,34,-1,LEAVES:3)
Block(8,34,0,LEAVES:3)
Block(8,34,1,LEAVES:3)
Block(8,34,2,LEAVES:3)
Block(8,34,3,LEAVES:3)
Block(8,34,4,LEAVES:3)
Block(8,34,5,LEAVES:3)
Block(8,34,6,LEAVES:3)
Block(8,34,7,LEAVES:3)
Block(8,34,8,LEAVES:3)
Block(8,35,1,LEAVES:3)
Block(8,35,2,LEAVES:3)
Block(8,35,3,LEAVES:3)
Block(8,35,4,LEAVES:3)
Block(8,35,5,LEAVES:3)
Block(9,30,-6,LEAVES:3)
Block(9,30,2,LEAVES:3)
Block(9,31,-7,LEAVES:3)
Block(9,31,-6,LEAVES:3)
Block(9,31,-5,LEAVES:3)
Block(9,31,-4,LEAVES:3)
Block(9,31,-3,LEAVES:3)
Block(9,31,-2,LEAVES:3)
Block(9,31,-1,LEAVES:3)
Block(9,31,0,LEAVES:3)
Block(9,31,1,LEAVES:3)
Block(9,31,2,LEAVES:3)
Block(9,31,3,LEAVES:3)
Block(9,32,-9,LEAVES:3)
Block(9,32,-8,LEAVES:3)
Block(9,32,-7,LEAVES:3)
Block(9,32,-6,LEAVES:3)
Block(9,32,-5,LEAVES:3)
Block(9,32,-4,LEAVES:3)
Block(9,32,-3,LEAVES:3)
Block(9,32,-2,LEAVES:3)
Block(9,32,-1,LOG:15)
Block(9,32,0,LEAVES:3)
Block(9,32,1,LEAVES:3)
Block(9,32,2,LEAVES:3)
Block(9,32,3,LEAVES:3)
Block(9,32,4,LEAVES:3)
Block(9,32,5,LEAVES:3)
Block(9,32,6,LEAVES:3)
Block(9,32,7,LEAVES:3)
Block(9,33,-7,LEAVES:3)
Block(9,33,-6,LEAVES:3)
Block(9,33,-5,LEAVES:3)
Block(9,33,-4,LEAVES:3)
Block(9,33,-3,LEAVES:3)
Block(9,33,-2,LEAVES:3)
Block(9,33,-1,LEAVES:3)
Block(9,33,0,LEAVES:3)
Block(9,33,1,LEAVES:3)
Block(9,33,2,LEAVES:3)
Block(9,33,3,LEAVES:3)
Block(9,33,4,LEAVES:3)
Block(9,33,5,LEAVES:3)
Block(9,33,6,LEAVES:3)
Block(9,33,7,LEAVES:3)
Block(9,34,-4,LEAVES:3)
Block(9,34,-3,LEAVES:3)
Block(9,34,-2,LEAVES:3)
Block(9,34,-1,LEAVES:3)
Block(9,34,0,LEAVES:3)
Block(9,34,1,LEAVES:3)
Block(9,34,2,LEAVES:3)
Block(9,34,3,LEAVES:3)
Block(9,34,4,LEAVES:3)
Block(9,34,5,LEAVES:3)
Block(9,34,6,LEAVES:3)
Block(9,35,-1,LEAVES:3)
Block(9,35,4,LEAVES:3)
Block(9,35,5,LEAVES:3)
Block(10,30,1,LEAVES:3)
Block(10,30,2,LEAVES:3)
Block(10,31,-7,LEAVES:3)
Block(10,31,-6,LEAVES:3)
Block(10,31,-5,LEAVES:3)
Block(10,31,-4,LEAVES:3)
Block(10,31,-3,LEAVES:3)
Block(10,31,-2,LEAVES:3)
Block(10,31,-1,LEAVES:3)
Block(10,31,0,LEAVES:3)
Block(10,31,1,LEAVES:3)
Block(10,31,2,LEAVES:3)
Block(10,31,3,LEAVES:3)
Block(10,32,-8,LEAVES:3)
Block(10,32,-7,LEAVES:3)
Block(10,32,-6,LEAVES:3)
Block(10,32,-5,LEAVES:3)
Block(10,32,-4,LEAVES:3)
Block(10,32,-3,LEAVES:3)
Block(10,32,-2,LEAVES:3)
Block(10,32,-1,LEAVES:3)
Block(10,32,0,LEAVES:3)
Block(10,32,1,LEAVES:3)
Block(10,32,2,LEAVES:3)
Block(10,32,3,LEAVES:3)
Block(10,32,4,LEAVES:3)
Block(10,32,5,LEAVES:3)
Block(10,33,-6,LEAVES:3)
Block(10,33,-5,LEAVES:3)
Block(10,33,-4,LEAVES:3)
Block(10,33,-3,LEAVES:3)
Block(10,33,-2,LEAVES:3)
Block(10,33,-1,LEAVES:3)
Block(10,33,0,LEAVES:3)
Block(10,33,1,LEAVES:3)
Block(10,33,2,LEAVES:3)
Block(10,33,3,LEAVES:3)
Block(10,33,4,LEAVES:3)
Block(10,33,5,LEAVES:3)
Block(10,33,6,LEAVES:3)
Block(10,34,-4,LEAVES:3)
Block(10,34,-3,LEAVES:3)
Block(10,34,-2,LEAVES:3)
Block(10,34,-1,LEAVES:3)
Block(10,34,0,LEAVES:3)
Block(10,34,1,LEAVES:3)
Block(10,34,2,LEAVES:3)
Block(10,34,3,LEAVES:3)
Block(10,34,4,LEAVES:3)
Block(11,30,-3,LEAVES:3)
Block(11,30,2,LEAVES:3)
Block(11,31,-7,LEAVES:3)
Block(11,31,-6,LEAVES:3)
Block(11,31,-5,LEAVES:3)
Block(11,31,-4,LEAVES:3)
Block(11,31,-3,LEAVES:3)
Block(11,31,-2,LEAVES:3)
Block(11,31,-1,LEAVES:3)
Block(11,31,0,LEAVES:3)
Block(11,31,1,LEAVES:3)
Block(11,31,2,LEAVES:3)
Block(11,31,3,LEAVES:3)
Block(11,31,4,LEAVES:3)
Block(11,31,5,LEAVES:3)
Block(11,32,-7,LEAVES:3)
Block(11,32,-6,LEAVES:3)
Block(11,32,-5,LEAVES:3)
Block(11,32,-4,LEAVES:3)
Block(11,32,-3,LEAVES:3)
Block(11,32,-2,LEAVES:3)
Block(11,32,-1,LEAVES:3)
Block(11,32,0,LEAVES:3)
Block(11,32,1,LEAVES:3)
Block(11,32,2,LEAVES:3)
Block(11,32,3,LEAVES:3)
Block(11,32,4,LEAVES:3)
Block(11,33,-6,LEAVES:3)
Block(11,33,-5,LEAVES:3)
Block(11,33,-4,LEAVES:3)
Block(11,33,-3,LEAVES:3)
Block(11,33,-2,LEAVES:3)
Block(11,33,-1,LEAVES:3)
Block(11,33,0,LEAVES:3)
Block(11,33,1,LEAVES:3)
Block(11,33,2,LEAVES:3)
Block(11,33,3,LEAVES:3)
Block(11,34,-3,LEAVES:3)
Block(11,34,-2,LEAVES:3)
Block(11,34,-1,LEAVES:3)
Block(12,31,-6,LEAVES:3)
Block(12,31,-5,LEAVES:3)
Block(12,31,-4,LEAVES:3)
Block(12,31,-3,LEAVES:3)
Block(12,31,-2,LEAVES:3)
Block(12,31,-1,LEAVES:3)
Block(12,31,0,LEAVES:3)
Block(12,31,1,LEAVES:3)
Block(12,31,2,LEAVES:3)
Block(12,31,5,LEAVES:3)
Block(12,32,-6,LEAVES:3)
Block(12,32,-5,LEAVES:3)
Block(12,32,-4,LEAVES:3)
Block(12,32,-3,LEAVES:3)
Block(12,32,-2,LEAVES:3)
Block(12,32,-1,LEAVES:3)
Block(12,32,0,LEAVES:3)
Block(12,32,1,LEAVES:3)
Block(12,32,2,LEAVES:3)
Block(12,33,-5,LEAVES:3)
Block(12,33,-4,LEAVES:3)
Block(12,33,-3,LEAVES:3)
Block(12,33,-2,LEAVES:3)
Block(12,33,-1,LEAVES:3)
Block(12,33,0,LEAVES:3)
Block(13,31,-4,LEAVES:3)
Block(13,32,-5,LEAVES:3)
Block(13,32,-4,LEAVES:3)
Block(13,32,0,LEAVES:3)

#######################################################################
# +-----------------------------------------------------------------+ #
# |                            BO3 checks                           | #
# +-----------------------------------------------------------------+ #
#######################################################################

# Require a condition at a certain location in order for the BO3 to be spawned.
# BlockCheck(x,y,z,BlockName[,BlockName[,...]]) - one of the blocks must be at the location
# BlockCheckNot(x,y,z,BlockName[,BlockName[,...]]) - all the blocks must not be at the location
# LightCheck(x,y,z,minLightLevel,maxLightLevel) - light must be between min and max (inclusive)
# ModCheck(ModName[,ModName[,...]]) - all the mods listed must be loaded
# ModCheckNot(ModName[,ModName[,...]]) - all the mods listed must not be loaded

# You can use "Solid" as a BlockName for matching all solid blocks or "All" to match all blocks that aren't air.

# Examples:
#   BlockCheck(0,-1,0,GRASS,DIRT)  Require grass or dirt just below the object
#   BlockCheck(0,-1,0,Solid)       Require any solid block just below the object
#   BlockCheck(0,-1,0,WOOL)        Require any type of wool just below the object
#   BlockCheck(0,-1,0,WOOL:0)      Require white wool just below the object
#   BlockCheckNot(0,-1,0,WOOL:0)   Require that there is no white wool below the object
#   LightCheck(0,0,0,0,1)          Require almost complete darkness just below the object
BlockCheck(0,-1,0,GRASS,DIRT)

#######################################################################
# +-----------------------------------------------------------------+ #
# |                             Branches                            | #
# +-----------------------------------------------------------------+ #
#######################################################################

# Branches are child-BO3's that spawn if this BO3 is configured to spawn as a
# CustomStructure resource in a biome config. Branches can have branches,
# making complex structures possible. See the wiki for more details.

# Regular Branches spawn each branch with an independent chance of spawning.
# Branch(x,y,z,branchName,rotation,chance[,anotherBranchName,rotation,chance[,...]][IndividualChance])
# branchName - name of the object to spawn.
# rotation - NORTH, SOUTH, EAST or WEST.
# IndividualChance - The chance each branch has to spawn, assumed to be 100 when left blank
# isRequiredBranch - If this is set to true then at least one of the branches in this BO3 must spawn at these x,y,z coordinates. If no branch can spawn there then this BO3 fails to spawn and its branch is rolled back.
# isRequiredBranch:true branches must spawn or the current branch is rolled back entirely. This is useful for grouping BO3's that must spawn together, for instance a single room made of multiple BO3's/branches.
# If all parts of the room are connected together via isRequiredBranch:true branches then either the entire room will spawns or no part of it will spawn.
# *Note: When isRequiredBranch:true only one BO3 can be added per Branch() and it will automatically have a rarity of 100.0.
# isRequiredBranch:false branches are used to make optional parts of structures, for instance the middle section of a tunnel that has a beginning, middle and end BO3/branch and can have a variable length by repeating the middle BO3/branch.
# By making the start and end branches isRequiredBranch:true and the middle branch isRequiredbranch:false you can make it so that either:
# A. A tunnel spawns with at least a beginning and end branch
# B. A tunnel spawns with a beginning and end branch and as many middle branches as will fit in the available space.
# C. No tunnel spawns at all because there wasn't enough space to spawn at least a beginning and end branch.
# branchDepth - When creating a chain of branches that contains optional (isRequiredBranch:false) branches branch depth is configured for the first BO3 in the chain to determine the maximum length of the chain.
# branchDepth - 1 is inherited by each isRequiredBranch:false branch in the chain. When branchDepth is zero isRequiredBranch:false branches cannot spawn and the chain ends. In the case of the tunnel this means the last middle branch would be
# rolled back and an IsRequiredBranch:true end branch could be spawned in its place to make sure the tunnel has a proper ending.
# Instead of inheriting branchDepth - 1 from the parent branchDepth can be overridden by child branches if it is set higher than 0 (the default value).
# isRequiredBranch:true branches do inherit branchDepth and pass it on to their own branches, however they cannot be prevented from spawning by it and also don't subtract 1 from branchDepth when inheriting it.

# Weighted Branches spawn branches with a dependent chance of spawning.
# WeightedBranch(x,y,z,branchName,rotation,chance[,anotherBranchName,rotation,chance[,...]][MaxChanceOutOf])
# *Note: isRequiredBranch must be set to false. It is not possible to use isRequiredBranch:true with WeightedBranch() since isRequired:true branches must spawn and automatically have a rarity of 100.0.
# MaxChanceOutOf - The chance all branches have to spawn out of, assumed to be 100 when left blank

#######################################################################
# +-----------------------------------------------------------------+ #
# |                             Entities                            | #
# +-----------------------------------------------------------------+ #
#######################################################################

# Forge only (this may have changed, check for updates).
# An EntityFunction spawns an entity instead of a block. The entity is spawned only once when the BO3 is spawned.
# Entities are persistent by default so they don't de-spawn when no player is near, they are only unloaded.
# Usage: Entity(x,y,z,entityName,groupSize,NameTagOrNBTFileName) or Entity(x,y,z,mobName,groupSize)
# Use /otg entities to get a list of entities that can be used as entityName, this includes entities added by other mods and non-living entities.
# NameTagOrNBTFileName can be either a nametag for the mob or an .txt file with nbt data (such as myentityinfo.txt).
# In the text file you can use the same mob spawning parameters used with the /summon command to equip the
# entity and give it custom attributes etc. You can copy the DATA part of a summon command including surrounding 
# curly braces to a .txt file, for instance for: "/summon Skeleton x y z {DATA}"
# *Note: Unlike Block(), for Entity() .nbt files don't work, only .txt files work.

#######################################################################
# +-----------------------------------------------------------------+ #
# |                            Particles                            | #
# +-----------------------------------------------------------------+ #
#######################################################################

# Forge only (this may have changed, check for updates).
# Creates an invisible particle spawner at the given location that spawns particles every x milliseconds.
# Usage: Particle(x,y,z,particleName,interval,velocityX,velocityY,velocityZ)
# velocityX, velocityY and velocityZ are optional.
# Only vanilla particle names can be used, for 1.11.2 these are;
# explode, largeexplode, hugeexplosion, fireworksSpark, bubble, splash, wake, suspended
# depthsuspend, crit, magicCrit, smoke, largesmoke, spell, instantSpell, mobSpell
# mobSpellAmbient, witchMagic, dripWater, dripLava, angryVillager, happyVillager
# townaura, note, portal, enchantmenttable, flame, lava, footstep, cloud, reddust
# snowballpoof,  snowshovel, slime, heart, barrier, iconcrack, blockcrack, blockdust
# droplet, take, mobappearance, dragonbreath, endRod, damageIndicator, sweepAttack
# fallingdust, totem, spit.
# velocityX,velocityY,velocityZ - Spawn the enemy with the given velocity. If this is not filled in then a small random velocity is applied.

#######################################################################
# +-----------------------------------------------------------------+ #
# |                             Spawners                            | #
# +-----------------------------------------------------------------+ #
#######################################################################

# Forge only (this may have changed, check for updates).
# Creates an invisible entity spawner at the given location that spawns entities every x seconds.
# Entities can only spawn if their spawn requirements are met (zombies/skeletons only spawn in the dark etc). Max entity count for the server is ignored, each spawner has its own maxCount setting.
# Usage: Spawner(x,y,z,entityName,nbtFileName,groupSize,interval,spawnChance,maxCount,despawnTime,velocityX,velocityY,velocityZ,yaw,pitch)
# nbtFileName, despawnTime, velocityX, velocityY, velocityZ, yaw and pitch are optional
# Example Spawner(0, 0, 0, Villager, 1, 5, 100, 5) or Spawner(0, 0, 0, Villager, villager1.txt, 1, 5, 100, 5) or Spawner(0, 0, 0, Villager, 1, 5, 100, 5, 30, 1, 1, 1, 0, 0)
# entityName - Name of the entity to spawn, use /otg entities to get a list of entities that can be used as entityName, this includes entities added by other mods and non-living entities.
# nbtFileName - A .txt file with nbt data (such as myentityinfo.txt).
# In the text file you can use the same mob spawning parameters used with the /summon command to equip the
# entity and give it custom attributes etc. You can copy the DATA part of a summon command including surrounding 
# curly braces to a .txt file, for instance for: "/summon Skeleton x y z {DATA}"
# *Note: Unlike Block(), for Spawner() .nbt files don't work, only .txt files work.
# groupSize - Number of entities that should spawn for each successful spawn attempt.
# interval - Time in seconds between each spawn attempt.
# spawnChance - For each spawn attempt, the chance between 0-100 that the spawn attempt will succeed.
# maxCount - The maximum amount of this kind of entity that can exist within 32 blocks. If there are already maxCount or more entities of this type in a 32 radius this spawner will not spawn anything.
# despawnTime - After despawnTime seconds, if there is no player within 32 blocks of the entity it will despawn..
# velocityX,velocityY,velocityZ,yaw,pitch - Spawn the enemy with the given velocity and angle, handy for making traps and launchers (shooting arrows and fireballs etc).

#######################################################################
# +-----------------------------------------------------------------+ #
# |                             ModData                             | #
# +-----------------------------------------------------------------+ #
#######################################################################

# Forge only.
# Use the ModData() tag to include data that other mods can use
# Mod makers can use ModData and the /otg GetModData command to test IMC communications between OTG
# and their mod.
# Normal users can use it to spawn some mobs and blocks on command.
# ModData(x,y,z,"ModName", "MyModDataAsText"
# Example: ModData(x,y,z,MyCystomNPCMod,SpawnBobHere/WithAPotato/And50Health)
# Try not to use exotic/reserved characters, like brackets and comma's etc, this stuff isn't fool-proof.
# Also, use this only to store IDs/object names etc for your mod, DO NOT include things like character dialogue,
# messages on signs, loot lists etc in this file. As much as possible just store id's/names here and store all the data related to those id's/names in your own mod.
# OTG has some built in ModData commands for basic mob and block spawning.
# These are mostly just a demonstration for mod makers to show how ModData.
# can be used by other mods.
# For mob spawning in OTG use: ModData(x,y,z,OTG,mob/MobType/Count/Persistent/Name)
# mob: Makes OTG recognise this as a mob spawning command.
# MobType: Lower-case, no spaces. Any vanilla mob like dragon, skeleton, wither, villager etc
# Count: The number of mobs to spawn
# Persistent (true/false): Should the mobs never de-spawn? If set to true the mob will get a
# name-tag ingame so you can recognise it.
# Name: A name-tag for the monster/npc.
# Example: ModData(0,0,0,OTG,villager/1/true/Bob)
# To spawn blocks using ModData use: ModData(x,y,z,OTG,block/material)
# block: Makes OTG recognise this as a block spawning command.
# material: id or text, custom blocks can be added using ModName:MaterialName.
# To send all ModData within a radius in chunks around the player to the specified mod
# use this console command: /otg GetModData ModName Radius
# ModName: name of the mod, for OTG commands use OTG 
# Radius (optional): Radius in chunks around the player.
