
#######################################################################
# +-----------------------------------------------------------------+ #
# |                            BO3 object                           | #
# +-----------------------------------------------------------------+ #
#######################################################################

Author: Unknown

Description: Converted version of the BO2 BirchPoplar3

Version: 3

SettingsMode: WriteWithoutComments


#######################################################################
# +-----------------------------------------------------------------+ #
# |                          Main settings                          | #
# +-----------------------------------------------------------------+ #
#######################################################################

Tree: true

Frequency: 1

Rarity: 10.0

RotateRandomly: true

SpawnHeight: highestSolidBlock

SpawnHeightOffset: 0

SpawnHeightVariance: 0

##############################
# Height Limits for the BO3. #
##############################

MinHeight: 63

MaxHeight: 256

######################
# Extrusion settings #
######################

ExtrudeMode: None

ExtrudeThroughBlocks: AIR

MaxBranchDepth: 10

ExcludedBiomes: All


#######################################################################
# +-----------------------------------------------------------------+ #
# |                      Source block settings                      | #
# +-----------------------------------------------------------------+ #
#######################################################################

SourceBlocks: STONE:1,STONE:3,STONE:5,DIRT:1,DIRT,SAND,GRASS,DIRT:2,STATIONARY_WATER,HARD_CLAY,STAINED_CLAY,CLAY,SANDSTONE,SAND:1,AIR,STONE,GRAVEL,LONG_GRASS,LONG_GRASS:1,LONG_GRASS:2,DEAD_BUSH,YELLOW_FLOWER,RED_ROSE,BROWN_MUSHROOM,RED_MUSHROOM

MaxPercentageOutsideSourceBlock: 0

OutsideSourceBlock: placeAnyway

IsOTGPlus: false


#######################################################################
# +-----------------------------------------------------------------+ #
# |                              Blocks                             | #
# +-----------------------------------------------------------------+ #
#######################################################################

Block(-1,10,1,LEAVES:2)
Block(-1,11,1,LEAVES:2)
Block(-1,12,1,LEAVES:2)
Block(-1,5,0,LEAVES:2)
Block(-1,4,0,LEAVES:2)
Block(-1,7,0,LEAVES:2)
Block(-1,6,0,LEAVES:2)
Block(-1,9,0,LEAVES:2)
Block(-1,8,0,LEAVES:2)
Block(1,10,1,LEAVES:2)
Block(1,11,1,LEAVES:2)
Block(1,12,1,LEAVES:2)
Block(-1,3,0,LEAVES:2)
Block(-1,2,0,LEAVES:2)
Block(0,5,-1,LEAVES:2)
Block(0,4,-1,LEAVES:2)
Block(0,7,-1,LEAVES:2)
Block(0,6,-1,LEAVES:2)
Block(0,9,-1,LEAVES:2)
Block(0,8,-1,LEAVES:2)
Block(0,3,-1,LEAVES:2)
Block(0,2,-1,LEAVES:2)
Block(1,12,-1,LEAVES:2)
Block(1,11,-1,LEAVES:2)
Block(1,10,-1,LEAVES:2)
Block(-1,6,-2,LEAVES:2)
Block(-1,5,-2,LEAVES:2)
Block(-1,9,-2,LEAVES:2)
Block(-1,8,-2,LEAVES:2)
Block(-1,7,-2,LEAVES:2)
Block(0,10,-1,LEAVES:2)
Block(0,12,-1,LEAVES:2)
Block(0,11,-1,LEAVES:2)
Block(0,14,-1,LEAVES:2)
Block(0,13,-1,LEAVES:2)
Block(0,1,0,LOG:2)
Block(0,0,0,LOG:2)
Block(0,3,0,LOG:2)
Block(0,2,0,LOG:2)
Block(0,5,0,LOG:2)
Block(0,4,0,LOG:2)
Block(0,7,0,LOG:2)
Block(0,6,0,LOG:2)
Block(-2,10,0,LEAVES:2)
Block(1,8,-2,LEAVES:2)
Block(1,9,-2,LEAVES:2)
Block(1,6,-2,LEAVES:2)
Block(1,7,-2,LEAVES:2)
Block(1,5,-2,LEAVES:2)
Block(-1,5,2,LEAVES:2)
Block(-1,7,2,LEAVES:2)
Block(-1,6,2,LEAVES:2)
Block(-1,9,2,LEAVES:2)
Block(-1,8,2,LEAVES:2)
Block(-2,9,0,LEAVES:2)
Block(-2,8,0,LEAVES:2)
Block(-2,7,0,LEAVES:2)
Block(-2,6,0,LEAVES:2)
Block(-2,5,0,LEAVES:2)
Block(-2,4,0,LEAVES:2)
Block(2,5,-1,LEAVES:2)
Block(0,8,1,LEAVES:2)
Block(2,9,-1,LEAVES:2)
Block(0,7,1,LEAVES:2)
Block(2,8,-1,LEAVES:2)
Block(2,7,-1,LEAVES:2)
Block(2,6,-1,LEAVES:2)
Block(0,9,1,LEAVES:2)
Block(-1,10,0,LEAVES:2)
Block(-1,11,0,LEAVES:2)
Block(-1,12,0,LEAVES:2)
Block(-1,13,0,LEAVES:2)
Block(-1,14,0,LEAVES:2)
Block(1,9,-1,LEAVES:2)
Block(1,7,-1,LEAVES:2)
Block(1,8,-1,LEAVES:2)
Block(1,5,-1,LEAVES:2)
Block(1,6,-1,LEAVES:2)
Block(1,3,-1,LEAVES:2)
Block(1,4,-1,LEAVES:2)
Block(-1,4,1,LEAVES:2)
Block(-1,3,1,LEAVES:2)
Block(-1,6,1,LEAVES:2)
Block(-1,5,1,LEAVES:2)
Block(-1,8,1,LEAVES:2)
Block(-1,7,1,LEAVES:2)
Block(-1,9,1,LEAVES:2)
Block(0,-2,0,LOG:2)
Block(0,-1,0,LOG:2)
Block(0,9,0,LOG:2)
Block(0,8,0,LOG:2)
Block(1,9,0,LEAVES:2)
Block(0,5,2,LEAVES:2)
Block(1,8,0,LEAVES:2)
Block(0,4,2,LEAVES:2)
Block(1,7,0,LEAVES:2)
Block(0,14,1,LEAVES:2)
Block(0,13,1,LEAVES:2)
Block(0,12,1,LEAVES:2)
Block(0,11,1,LEAVES:2)
Block(0,10,1,LEAVES:2)
Block(0,2,1,LEAVES:2)
Block(0,4,1,LEAVES:2)
Block(1,9,1,LEAVES:2)
Block(0,3,1,LEAVES:2)
Block(1,8,1,LEAVES:2)
Block(0,6,1,LEAVES:2)
Block(1,7,1,LEAVES:2)
Block(0,5,1,LEAVES:2)
Block(1,6,1,LEAVES:2)
Block(-1,10,-1,LEAVES:2)
Block(-2,9,1,LEAVES:2)
Block(-2,8,1,LEAVES:2)
Block(-2,7,1,LEAVES:2)
Block(-2,6,1,LEAVES:2)
Block(-2,5,1,LEAVES:2)
Block(-1,11,-1,LEAVES:2)
Block(-1,12,-1,LEAVES:2)
Block(0,14,0,LOG:2)
Block(0,13,0,LOG:2)
Block(0,12,0,LOG:2)
Block(0,11,0,LOG:2)
Block(0,18,0,LEAVES:2)
Block(0,17,0,LEAVES:2)
Block(0,16,0,LEAVES:2)
Block(0,15,0,LEAVES:2)
Block(1,6,0,LEAVES:2)
Block(0,7,2,LEAVES:2)
Block(1,5,0,LEAVES:2)
Block(0,6,2,LEAVES:2)
Block(1,4,0,LEAVES:2)
Block(0,9,2,LEAVES:2)
Block(1,3,0,LEAVES:2)
Block(0,8,2,LEAVES:2)
Block(1,2,0,LEAVES:2)
Block(0,10,0,LOG:2)
Block(0,4,-2,LEAVES:2)
Block(2,10,0,LEAVES:2)
Block(0,6,-2,LEAVES:2)
Block(0,5,-2,LEAVES:2)
Block(1,9,2,LEAVES:2)
Block(0,8,-2,LEAVES:2)
Block(1,8,2,LEAVES:2)
Block(0,7,-2,LEAVES:2)
Block(1,7,2,LEAVES:2)
Block(1,6,2,LEAVES:2)
Block(1,5,2,LEAVES:2)
Block(0,9,-2,LEAVES:2)
Block(-2,9,-1,LEAVES:2)
Block(2,7,0,LEAVES:2)
Block(2,6,0,LEAVES:2)
Block(2,9,0,LEAVES:2)
Block(2,8,0,LEAVES:2)
Block(-2,8,-1,LEAVES:2)
Block(-2,7,-1,LEAVES:2)
Block(-2,6,-1,LEAVES:2)
Block(-2,5,-1,LEAVES:2)
Block(-1,7,-1,LEAVES:2)
Block(-1,6,-1,LEAVES:2)
Block(-1,5,-1,LEAVES:2)
Block(-1,4,-1,LEAVES:2)
Block(-1,3,-1,LEAVES:2)
Block(1,14,0,LEAVES:2)
Block(1,13,0,LEAVES:2)
Block(1,12,0,LEAVES:2)
Block(1,11,0,LEAVES:2)
Block(1,10,0,LEAVES:2)
Block(-1,9,-1,LEAVES:2)
Block(-1,8,-1,LEAVES:2)
Block(1,5,1,LEAVES:2)
Block(1,4,1,LEAVES:2)
Block(0,10,2,LEAVES:2)
Block(1,3,1,LEAVES:2)
Block(2,9,1,LEAVES:2)
Block(2,6,1,LEAVES:2)
Block(2,5,1,LEAVES:2)
Block(2,8,1,LEAVES:2)
Block(2,7,1,LEAVES:2)
Block(0,10,-2,LEAVES:2)
Block(2,5,0,LEAVES:2)
Block(2,4,0,LEAVES:2)

#######################################################################
# +-----------------------------------------------------------------+ #
# |                            BO3 checks                           | #
# +-----------------------------------------------------------------+ #
#######################################################################

BlockCheck(0,-1,0,GRASS,DIRT,DIRT:2)

#######################################################################
# +-----------------------------------------------------------------+ #
# |                             Branches                            | #
# +-----------------------------------------------------------------+ #
#######################################################################


#######################################################################
# +-----------------------------------------------------------------+ #
# |                             Entities                            | #
# +-----------------------------------------------------------------+ #
#######################################################################


#######################################################################
# +-----------------------------------------------------------------+ #
# |                            Particles                            | #
# +-----------------------------------------------------------------+ #
#######################################################################


#######################################################################
# +-----------------------------------------------------------------+ #
# |                             Spawners                            | #
# +-----------------------------------------------------------------+ #
#######################################################################


#######################################################################
# +-----------------------------------------------------------------+ #
# |                             ModData                             | #
# +-----------------------------------------------------------------+ #
#######################################################################

