
#######################################################################
# +-----------------------------------------------------------------+ #
# |                            BO3 object                           | #
# +-----------------------------------------------------------------+ #
#######################################################################

Author: MC_Pitman

Description: No description given

Version: 3

SettingsMode: WriteWithoutComments


#######################################################################
# +-----------------------------------------------------------------+ #
# |                          Main settings                          | #
# +-----------------------------------------------------------------+ #
#######################################################################

Tree: true

Frequency: 1

Rarity: 100.0

RotateRandomly: true

SpawnHeight: highestSolidBlock

SpawnHeightOffset: 0

SpawnHeightVariance: 0

##############################
# Height Limits for the BO3. #
##############################

MinHeight: 63

MaxHeight: 100

######################
# Extrusion settings #
######################

ExtrudeMode: None

ExtrudeThroughBlocks: AIR

MaxBranchDepth: 10

ExcludedBiomes: All


#######################################################################
# +-----------------------------------------------------------------+ #
# |                      Source block settings                      | #
# +-----------------------------------------------------------------+ #
#######################################################################

SourceBlocks: STONE:1,STONE:3,STONE:5,DIRT:1,DIRT:0,SAND:0,GRASS:0,DIRT:2,HARD_CLAY,STAINED_CLAY:0,CLAY,SANDSTONE:0,SAND:1,AIR,STONE:0,GRAVEL,LONG_GRASS:0,LONG_GRASS:1,LONG_GRASS:2,DEAD_BUSH,YELLOW_FLOWER:0,RED_ROSE:0,BROWN_MUSHROOM,RED_MUSHROOM,SNOW_BLOCK,SNOW_BLOCK:0

MaxPercentageOutsideSourceBlock: 0

OutsideSourceBlock: placeAnyway

DoReplaceBlocks: true

IsOTGPlus: false


#######################################################################
# +-----------------------------------------------------------------+ #
# |                              Blocks                             | #
# +-----------------------------------------------------------------+ #
#######################################################################

Block(-6,5,0,LEAVES:0)
Block(-5,3,-1,LEAVES:0)
Block(-5,4,-2,LEAVES:0)
Block(-5,4,0,LEAVES:0)
Block(-5,5,0,LEAVES:0)
Block(-5,6,0,LEAVES:0)
Block(-4,3,-2,LEAVES:0)
Block(-4,3,-1,LEAVES:0)
Block(-4,3,1,LEAVES:0)
Block(-4,3,2,LEAVES:0)
Block(-4,4,-3,LEAVES:0)
Block(-4,4,-1,LEAVES:0)
Block(-4,4,0,LEAVES:0)
Block(-4,4,1,LEAVES:0)
Block(-4,5,-1,LEAVES:0)
Block(-4,5,0,LEAVES:0)
Block(-4,5,1,LEAVES:0)
Block(-4,6,-2,LEAVES:0)
Block(-4,6,0,LEAVES:0)
Block(-4,7,-1,LEAVES:0)
Block(-4,7,0,LEAVES:0)
Block(-4,10,0,LEAVES:0)
Block(-3,2,0,LEAVES:0)
Block(-3,3,-3,LEAVES:0)
Block(-3,3,-2,LEAVES:0)
Block(-3,3,-1,LEAVES:0)
Block(-3,3,0,LEAVES:0)
Block(-3,3,1,LEAVES:0)
Block(-3,3,2,LEAVES:0)
Block(-3,3,3,LEAVES:0)
Block(-3,4,-2,LEAVES:0)
Block(-3,4,-1,LEAVES:0)
Block(-3,4,0,LEAVES:0)
Block(-3,4,1,LEAVES:0)
Block(-3,4,2,LEAVES:0)
Block(-3,5,-2,LEAVES:0)
Block(-3,5,-1,LEAVES:0)
Block(-3,5,0,LEAVES:0)
Block(-3,5,1,LEAVES:0)
Block(-3,6,-3,LEAVES:0)
Block(-3,6,-2,LEAVES:0)
Block(-3,6,-1,LEAVES:0)
Block(-3,6,0,LEAVES:0)
Block(-3,6,1,LEAVES:0)
Block(-3,6,2,LEAVES:0)
Block(-3,7,-1,LEAVES:0)
Block(-3,7,0,LEAVES:0)
Block(-3,7,1,LEAVES:0)
Block(-3,8,2,LEAVES:0)
Block(-3,9,0,LEAVES:0)
Block(-3,9,1,LEAVES:0)
Block(-3,10,-1,LEAVES:0)
Block(-3,10,0,LEAVES:0)
Block(-3,11,1,LEAVES:0)
Block(-3,13,0,LEAVES:0)
Block(-3,13,2,LEAVES:0)
Block(-3,14,0,LEAVES:0)
Block(-2,3,-4,LEAVES:0)
Block(-2,3,-3,LEAVES:0)
Block(-2,3,0,LEAVES:0)
Block(-2,3,1,LEAVES:0)
Block(-2,3,2,LEAVES:0)
Block(-2,3,4,LEAVES:0)
Block(-2,4,-3,LEAVES:0)
Block(-2,4,-2,LEAVES:0)
Block(-2,4,-1,LEAVES:0)
Block(-2,4,0,LEAVES:0)
Block(-2,4,1,LEAVES:0)
Block(-2,4,3,LEAVES:0)
Block(-2,5,-4,LEAVES:0)
Block(-2,5,-2,LEAVES:0)
Block(-2,5,-1,LEAVES:0)
Block(-2,5,0,LEAVES:0)
Block(-2,5,1,LEAVES:0)
Block(-2,5,2,LEAVES:0)
Block(-2,6,-3,LEAVES:0)
Block(-2,6,-2,LEAVES:0)
Block(-2,6,-1,LEAVES:0)
Block(-2,6,0,LEAVES:0)
Block(-2,6,2,LEAVES:0)
Block(-2,6,3,LEAVES:0)
Block(-2,7,-2,LEAVES:0)
Block(-2,7,-1,LEAVES:0)
Block(-2,7,0,LEAVES:0)
Block(-2,7,1,LEAVES:0)
Block(-2,7,2,LEAVES:0)
Block(-2,7,3,LEAVES:0)
Block(-2,8,-3,LEAVES:0)
Block(-2,8,-1,LEAVES:0)
Block(-2,8,0,LEAVES:0)
Block(-2,8,1,LEAVES:0)
Block(-2,8,2,LEAVES:0)
Block(-2,8,3,LEAVES:0)
Block(-2,9,-2,LEAVES:0)
Block(-2,9,-1,LEAVES:0)
Block(-2,9,0,LEAVES:0)
Block(-2,9,1,LEAVES:0)
Block(-2,9,2,LEAVES:0)
Block(-2,10,0,LEAVES:0)
Block(-2,10,1,LEAVES:0)
Block(-2,11,0,LEAVES:0)
Block(-2,11,2,LEAVES:0)
Block(-2,12,-2,LEAVES:0)
Block(-2,12,1,LEAVES:0)
Block(-2,13,-1,LEAVES:0)
Block(-2,13,0,LEAVES:0)
Block(-2,13,1,LEAVES:0)
Block(-2,14,-1,LEAVES:0)
Block(-2,14,0,LEAVES:0)
Block(-2,15,0,LEAVES:0)
Block(-2,15,2,LEAVES:0)
Block(-2,17,1,LEAVES:0)
Block(-2,18,0,LEAVES:0)
Block(-2,20,1,LEAVES:0)
Block(-1,2,-3,LEAVES:0)
Block(-1,2,-1,LEAVES:0)
Block(-1,2,0,LEAVES:0)
Block(-1,2,1,LEAVES:0)
Block(-1,3,-5,LEAVES:0)
Block(-1,3,-4,LEAVES:0)
Block(-1,3,-3,LEAVES:0)
Block(-1,3,-2,LEAVES:0)
Block(-1,3,-1,LEAVES:0)
Block(-1,3,0,LEAVES:0)
Block(-1,3,1,LEAVES:0)
Block(-1,3,2,LEAVES:0)
Block(-1,3,3,LEAVES:0)
Block(-1,3,4,LEAVES:0)
Block(-1,4,-4,LEAVES:0)
Block(-1,4,-3,LEAVES:0)
Block(-1,4,-2,LOG:12)
Block(-1,4,-1,LEAVES:0)
Block(-1,4,0,LEAVES:0)
Block(-1,4,1,LEAVES:0)
Block(-1,4,2,LEAVES:0)
Block(-1,4,3,LEAVES:0)
Block(-1,4,4,LEAVES:0)
Block(-1,5,-5,LEAVES:0)
Block(-1,5,-2,LEAVES:0)
Block(-1,5,-1,LOG:12)
Block(-1,5,0,LEAVES:0)
Block(-1,5,1,LEAVES:0)
Block(-1,5,2,LEAVES:0)
Block(-1,5,3,LEAVES:0)
Block(-1,6,-4,LEAVES:0)
Block(-1,6,-2,LEAVES:0)
Block(-1,6,-1,LEAVES:0)
Block(-1,6,0,LEAVES:0)
Block(-1,6,1,LEAVES:0)
Block(-1,6,2,LEAVES:0)
Block(-1,6,4,LEAVES:0)
Block(-1,7,-3,LEAVES:0)
Block(-1,7,-1,LEAVES:0)
Block(-1,7,0,LEAVES:0)
Block(-1,7,1,LOG:12)
Block(-1,7,3,LEAVES:0)
Block(-1,8,-2,LEAVES:0)
Block(-1,8,-1,LEAVES:0)
Block(-1,8,0,LOG:12)
Block(-1,8,1,LEAVES:0)
Block(-1,8,2,LEAVES:0)
Block(-1,8,3,LEAVES:0)
Block(-1,8,4,LEAVES:0)
Block(-1,9,-2,LEAVES:0)
Block(-1,9,-1,LEAVES:0)
Block(-1,9,0,LEAVES:0)
Block(-1,9,1,LEAVES:0)
Block(-1,9,2,LEAVES:0)
Block(-1,9,3,LEAVES:0)
Block(-1,10,-2,LEAVES:0)
Block(-1,10,-1,LEAVES:0)
Block(-1,10,0,LEAVES:0)
Block(-1,10,1,LEAVES:0)
Block(-1,10,2,LEAVES:0)
Block(-1,11,-2,LEAVES:0)
Block(-1,11,-1,LEAVES:0)
Block(-1,11,0,LEAVES:0)
Block(-1,11,1,LEAVES:0)
Block(-1,11,2,LEAVES:0)
Block(-1,12,-1,LEAVES:0)
Block(-1,12,0,LEAVES:0)
Block(-1,12,1,LEAVES:0)
Block(-1,12,2,LEAVES:0)
Block(-1,13,-2,LEAVES:0)
Block(-1,13,-1,LEAVES:0)
Block(-1,13,0,LEAVES:0)
Block(-1,13,1,LEAVES:0)
Block(-1,13,2,LEAVES:0)
Block(-1,14,-1,LEAVES:0)
Block(-1,14,0,LEAVES:0)
Block(-1,14,1,LEAVES:0)
Block(-1,14,2,LEAVES:0)
Block(-1,15,-2,LEAVES:0)
Block(-1,15,-1,LEAVES:0)
Block(-1,15,0,LEAVES:0)
Block(-1,15,1,LEAVES:0)
Block(-1,16,-1,LEAVES:0)
Block(-1,16,0,LEAVES:0)
Block(-1,16,1,LEAVES:0)
Block(-1,17,0,LEAVES:0)
Block(-1,17,1,LEAVES:0)
Block(-1,18,0,LEAVES:0)
Block(-1,18,1,LEAVES:0)
Block(-1,19,0,LEAVES:0)
Block(-1,19,1,LEAVES:0)
Block(-1,20,-1,LEAVES:0)
Block(-1,20,0,LEAVES:0)
Block(-1,20,1,LEAVES:0)
Block(-1,21,-1,LEAVES:0)
Block(-1,21,0,LEAVES:0)
Block(-1,22,0,LEAVES:0)
Block(0,0,0,LOG:12)
Block(0,1,0,LOG:12)
Block(0,2,-2,LEAVES:0)
Block(0,2,-1,LEAVES:0)
Block(0,2,0,LOG:12)
Block(0,2,1,LEAVES:0)
Block(0,2,2,LEAVES:0)
Block(0,3,-5,LEAVES:0)
Block(0,3,-3,LEAVES:0)
Block(0,3,-2,LEAVES:0)
Block(0,3,-1,LEAVES:0)
Block(0,3,0,LOG:12)
Block(0,3,1,LEAVES:0)
Block(0,3,2,LEAVES:0)
Block(0,3,4,LEAVES:0)
Block(0,3,5,LEAVES:0)
Block(0,4,-2,LEAVES:0)
Block(0,4,-1,LEAVES:0)
Block(0,4,0,LOG:12)
Block(0,4,1,LEAVES:0)
Block(0,4,2,LEAVES:0)
Block(0,4,3,LEAVES:0)
Block(0,5,-4,LEAVES:0)
Block(0,5,-3,LEAVES:0)
Block(0,5,-2,LEAVES:0)
Block(0,5,-1,LEAVES:0)
Block(0,5,0,LOG:12)
Block(0,5,1,LEAVES:0)
Block(0,5,2,LEAVES:0)
Block(0,5,3,LEAVES:0)
Block(0,5,4,LEAVES:0)
Block(0,5,5,LEAVES:0)
Block(0,6,-3,LEAVES:0)
Block(0,6,-2,LEAVES:0)
Block(0,6,-1,LOG:12)
Block(0,6,0,LOG:12)
Block(0,6,1,LEAVES:0)
Block(0,6,2,LEAVES:0)
Block(0,6,3,LEAVES:0)
Block(0,7,-4,LEAVES:0)
Block(0,7,-3,LEAVES:0)
Block(0,7,-2,LEAVES:0)
Block(0,7,-1,LEAVES:0)
Block(0,7,0,LOG:12)
Block(0,7,1,LEAVES:0)
Block(0,7,2,LEAVES:0)
Block(0,7,3,LEAVES:0)
Block(0,7,4,LEAVES:0)
Block(0,8,-3,LEAVES:0)
Block(0,8,-2,LEAVES:0)
Block(0,8,-1,LEAVES:0)
Block(0,8,0,LOG:12)
Block(0,8,1,LEAVES:0)
Block(0,8,2,LEAVES:0)
Block(0,8,3,LEAVES:0)
Block(0,9,-2,LEAVES:0)
Block(0,9,-1,LEAVES:0)
Block(0,9,0,LOG:12)
Block(0,9,1,LEAVES:0)
Block(0,9,2,LEAVES:0)
Block(0,9,3,LEAVES:0)
Block(0,10,-2,LEAVES:0)
Block(0,10,-1,LEAVES:0)
Block(0,10,0,LOG:12)
Block(0,10,1,LEAVES:0)
Block(0,10,2,LEAVES:0)
Block(0,11,-3,LEAVES:0)
Block(0,11,-2,LEAVES:0)
Block(0,11,-1,LEAVES:0)
Block(0,11,0,LOG:12)
Block(0,11,1,LOG:12)
Block(0,11,2,LEAVES:0)
Block(0,11,3,LEAVES:0)
Block(0,12,-2,LEAVES:0)
Block(0,12,-1,LOG:12)
Block(0,12,0,LOG:12)
Block(0,12,1,LEAVES:0)
Block(0,12,2,LEAVES:0)
Block(0,13,-3,LEAVES:0)
Block(0,13,-2,LEAVES:0)
Block(0,13,-1,LEAVES:0)
Block(0,13,0,LOG:12)
Block(0,13,1,LEAVES:0)
Block(0,13,3,LEAVES:0)
Block(0,14,-2,LEAVES:0)
Block(0,14,-1,LEAVES:0)
Block(0,14,0,LOG:12)
Block(0,14,1,LEAVES:0)
Block(0,14,2,LEAVES:0)
Block(0,15,-1,LEAVES:0)
Block(0,15,0,LOG:12)
Block(0,15,1,LEAVES:0)
Block(0,15,2,LEAVES:0)
Block(0,16,-1,LEAVES:0)
Block(0,16,0,LOG:12)
Block(0,16,1,LEAVES:0)
Block(0,16,2,LEAVES:0)
Block(0,16,3,LEAVES:0)
Block(0,17,-2,LEAVES:0)
Block(0,17,-1,LEAVES:0)
Block(0,17,0,LOG:12)
Block(0,17,1,LEAVES:0)
Block(0,18,-2,LEAVES:0)
Block(0,18,-1,LEAVES:0)
Block(0,18,0,LOG:12)
Block(0,18,1,LOG:12)
Block(0,18,2,LEAVES:0)
Block(0,19,-1,LEAVES:0)
Block(0,19,0,LOG:12)
Block(0,19,1,LEAVES:0)
Block(0,20,-1,LEAVES:0)
Block(0,20,0,LOG:12)
Block(0,20,1,LEAVES:0)
Block(0,21,-1,LEAVES:0)
Block(0,21,0,LOG:12)
Block(0,21,1,LEAVES:0)
Block(0,22,-1,LEAVES:0)
Block(0,22,0,LOG:12)
Block(0,23,0,LEAVES:0)
Block(0,24,0,LEAVES:0)
Block(1,2,-1,LEAVES:0)
Block(1,2,0,LEAVES:0)
Block(1,2,1,LEAVES:0)
Block(1,2,3,LEAVES:0)
Block(1,3,-3,LEAVES:0)
Block(1,3,-1,LEAVES:0)
Block(1,3,0,LEAVES:0)
Block(1,3,1,LEAVES:0)
Block(1,3,2,LEAVES:0)
Block(1,3,3,LEAVES:0)
Block(1,3,4,LEAVES:0)
Block(1,3,5,LEAVES:0)
Block(1,4,-4,LEAVES:0)
Block(1,4,-3,LEAVES:0)
Block(1,4,-1,LEAVES:0)
Block(1,4,0,LEAVES:0)
Block(1,4,1,LEAVES:0)
Block(1,4,3,LEAVES:0)
Block(1,4,4,LEAVES:0)
Block(1,5,-4,LEAVES:0)
Block(1,5,-3,LEAVES:0)
Block(1,5,-2,LEAVES:0)
Block(1,5,-1,LEAVES:0)
Block(1,5,0,LOG:12)
Block(1,5,1,LEAVES:0)
Block(1,5,2,LEAVES:0)
Block(1,5,3,LEAVES:0)
Block(1,6,-4,LEAVES:0)
Block(1,6,-3,LEAVES:0)
Block(1,6,-2,LEAVES:0)
Block(1,6,-1,LEAVES:0)
Block(1,6,0,LEAVES:0)
Block(1,6,1,LEAVES:0)
Block(1,6,4,LEAVES:0)
Block(1,7,-2,LEAVES:0)
Block(1,7,-1,LEAVES:0)
Block(1,7,0,LEAVES:0)
Block(1,7,1,LEAVES:0)
Block(1,7,3,LEAVES:0)
Block(1,8,-3,LEAVES:0)
Block(1,8,-2,LEAVES:0)
Block(1,8,-1,LEAVES:0)
Block(1,8,0,LOG:12)
Block(1,8,1,LEAVES:0)
Block(1,8,2,LEAVES:0)
Block(1,8,3,LEAVES:0)
Block(1,9,-2,LEAVES:0)
Block(1,9,-1,LEAVES:0)
Block(1,9,0,LEAVES:0)
Block(1,9,1,LEAVES:0)
Block(1,9,2,LEAVES:0)
Block(1,9,4,LEAVES:0)
Block(1,10,-1,LEAVES:0)
Block(1,10,0,LEAVES:0)
Block(1,10,1,LEAVES:0)
Block(1,10,2,LOG:12)
Block(1,10,3,LEAVES:0)
Block(1,11,-1,LEAVES:0)
Block(1,11,0,LEAVES:0)
Block(1,11,1,LEAVES:0)
Block(1,11,2,LEAVES:0)
Block(1,12,-2,LEAVES:0)
Block(1,12,-1,LEAVES:0)
Block(1,12,0,LEAVES:0)
Block(1,12,1,LEAVES:0)
Block(1,12,2,LEAVES:0)
Block(1,12,3,LEAVES:0)
Block(1,13,-2,LEAVES:0)
Block(1,13,-1,LEAVES:0)
Block(1,13,0,LEAVES:0)
Block(1,13,1,LEAVES:0)
Block(1,13,2,LEAVES:0)
Block(1,14,-1,LEAVES:0)
Block(1,14,0,LEAVES:0)
Block(1,14,1,LEAVES:0)
Block(1,15,-2,LEAVES:0)
Block(1,15,-1,LEAVES:0)
Block(1,15,0,LOG:12)
Block(1,15,1,LEAVES:0)
Block(1,16,-1,LEAVES:0)
Block(1,16,0,LEAVES:0)
Block(1,16,1,LEAVES:0)
Block(1,17,-1,LEAVES:0)
Block(1,17,0,LEAVES:0)
Block(1,17,1,LEAVES:0)
Block(1,18,0,LEAVES:0)
Block(1,18,1,LEAVES:0)
Block(1,19,-1,LEAVES:0)
Block(1,19,0,LEAVES:0)
Block(1,20,0,LEAVES:0)
Block(1,20,1,LEAVES:0)
Block(1,21,0,LEAVES:0)
Block(1,22,0,LEAVES:0)
Block(2,2,0,LEAVES:0)
Block(2,2,2,LEAVES:0)
Block(2,3,-4,LEAVES:0)
Block(2,3,-3,LEAVES:0)
Block(2,3,-2,LEAVES:0)
Block(2,3,-1,LEAVES:0)
Block(2,3,0,LEAVES:0)
Block(2,3,1,LEAVES:0)
Block(2,3,2,LEAVES:0)
Block(2,3,3,LEAVES:0)
Block(2,3,4,LEAVES:0)
Block(2,4,-3,LEAVES:0)
Block(2,4,-2,LEAVES:0)
Block(2,4,-1,LEAVES:0)
Block(2,4,0,LEAVES:0)
Block(2,4,1,LOG:12)
Block(2,4,2,LEAVES:0)
Block(2,4,5,LEAVES:0)
Block(2,5,-5,LEAVES:0)
Block(2,5,-4,LEAVES:0)
Block(2,5,-3,LEAVES:0)
Block(2,5,-2,LEAVES:0)
Block(2,5,-1,LEAVES:0)
Block(2,5,0,LEAVES:0)
Block(2,5,1,LEAVES:0)
Block(2,5,2,LEAVES:0)
Block(2,5,4,LEAVES:0)
Block(2,6,-4,LEAVES:0)
Block(2,6,-3,LEAVES:0)
Block(2,6,-2,LEAVES:0)
Block(2,6,-1,LEAVES:0)
Block(2,6,0,LEAVES:0)
Block(2,6,1,LEAVES:0)
Block(2,6,3,LEAVES:0)
Block(2,7,-3,LEAVES:0)
Block(2,7,-2,LEAVES:0)
Block(2,7,-1,LEAVES:0)
Block(2,7,0,LEAVES:0)
Block(2,7,2,LEAVES:0)
Block(2,8,-1,LEAVES:0)
Block(2,8,1,LEAVES:0)
Block(2,8,3,LEAVES:0)
Block(2,9,-3,LEAVES:0)
Block(2,9,-1,LEAVES:0)
Block(2,9,0,LEAVES:0)
Block(2,9,1,LEAVES:0)
Block(2,9,2,LEAVES:0)
Block(2,10,-2,LEAVES:0)
Block(2,10,-1,LEAVES:0)
Block(2,10,1,LEAVES:0)
Block(2,10,2,LEAVES:0)
Block(2,11,-1,LEAVES:0)
Block(2,11,0,LEAVES:0)
Block(2,11,2,LEAVES:0)
Block(2,12,-1,LEAVES:0)
Block(2,12,0,LEAVES:0)
Block(2,12,1,LEAVES:0)
Block(2,13,-1,LEAVES:0)
Block(2,13,0,LEAVES:0)
Block(2,13,1,LEAVES:0)
Block(2,14,-1,LEAVES:0)
Block(2,14,0,LEAVES:0)
Block(2,15,0,LEAVES:0)
Block(2,15,2,LEAVES:0)
Block(2,16,1,LEAVES:0)
Block(2,17,-1,LEAVES:0)
Block(2,18,0,LEAVES:0)
Block(2,20,0,LEAVES:0)
Block(3,3,-3,LEAVES:0)
Block(3,3,-2,LEAVES:0)
Block(3,3,0,LEAVES:0)
Block(3,3,1,LEAVES:0)
Block(3,3,2,LEAVES:0)
Block(3,3,3,LEAVES:0)
Block(3,4,-4,LEAVES:0)
Block(3,4,-2,LEAVES:0)
Block(3,4,-1,LEAVES:0)
Block(3,4,0,LEAVES:0)
Block(3,4,1,LEAVES:0)
Block(3,4,3,LEAVES:0)
Block(3,4,4,LEAVES:0)
Block(3,5,-3,LEAVES:0)
Block(3,5,-1,LEAVES:0)
Block(3,5,0,LEAVES:0)
Block(3,5,1,LEAVES:0)
Block(3,5,2,LEAVES:0)
Block(3,5,3,LEAVES:0)
Block(3,6,-2,LEAVES:0)
Block(3,6,0,LEAVES:0)
Block(3,6,1,LEAVES:0)
Block(3,6,2,LEAVES:0)
Block(3,7,-1,LEAVES:0)
Block(3,7,1,LEAVES:0)
Block(3,8,-2,LEAVES:0)
Block(3,8,0,LEAVES:0)
Block(3,8,1,LEAVES:0)
Block(3,9,-1,LEAVES:0)
Block(3,9,0,LEAVES:0)
Block(3,10,-1,LEAVES:0)
Block(3,12,-1,LEAVES:0)
Block(3,12,1,LEAVES:0)
Block(3,13,0,LEAVES:0)
Block(4,2,1,LEAVES:0)
Block(4,3,-2,LEAVES:0)
Block(4,3,-1,LEAVES:0)
Block(4,3,0,LEAVES:0)
Block(4,3,1,LEAVES:0)
Block(4,3,2,LEAVES:0)
Block(4,4,-2,LEAVES:0)
Block(4,4,-1,LEAVES:0)
Block(4,4,0,LEAVES:0)
Block(4,5,-1,LEAVES:0)
Block(4,5,0,LEAVES:0)
Block(4,5,1,LEAVES:0)
Block(4,5,2,LEAVES:0)
Block(4,6,0,LEAVES:0)
Block(4,7,0,LEAVES:0)
Block(4,9,-1,LEAVES:0)
Block(5,3,-1,LEAVES:0)
Block(5,3,1,LEAVES:0)
Block(5,4,0,LEAVES:0)

#######################################################################
# +-----------------------------------------------------------------+ #
# |                            BO3 checks                           | #
# +-----------------------------------------------------------------+ #
#######################################################################

BlockCheck(0,-1,0,GRASS:0,DIRT:0,DIRT:1,DIRT:2,SNOW_BLOCK,SNOW_BLOCK:0)

#######################################################################
# +-----------------------------------------------------------------+ #
# |                             Branches                            | #
# +-----------------------------------------------------------------+ #
#######################################################################


#######################################################################
# +-----------------------------------------------------------------+ #
# |                             Entities                            | #
# +-----------------------------------------------------------------+ #
#######################################################################


#######################################################################
# +-----------------------------------------------------------------+ #
# |                            Particles                            | #
# +-----------------------------------------------------------------+ #
#######################################################################


#######################################################################
# +-----------------------------------------------------------------+ #
# |                             Spawners                            | #
# +-----------------------------------------------------------------+ #
#######################################################################


#######################################################################
# +-----------------------------------------------------------------+ #
# |                             ModData                             | #
# +-----------------------------------------------------------------+ #
#######################################################################

