
#######################################################################
# +-----------------------------------------------------------------+ #
# |                            BO3 object                           | #
# +-----------------------------------------------------------------+ #
#######################################################################

# This is the config file of a custom object.
# If you add this object correctly to your BiomeConfigs, it will spawn in the world.

# This is the creator of this BO3 object
Author: Unknown

# A short description of this BO3 object
Description: No description given

# The BO3 version, don't change this! It can be used by external applications to do a version check.
Version: 3

# The settings mode, WriteAll, WriteWithoutComments or WriteDisable. See WorldConfig.
SettingsMode: WriteAll


#######################################################################
# +-----------------------------------------------------------------+ #
# |                          Main settings                          | #
# +-----------------------------------------------------------------+ #
#######################################################################

# This needs to be set to true to spawn the object in the Tree and Sapling resources.
Tree: true

# The frequency of the BO3 from 1 to 200. Tries this many times to spawn this BO3 when using the CustomObject(...) resource.
# Ignored by Tree(..), Sapling(..) and CustomStructure(..)
Frequency: 1

# The rarity of the BO3 from 0 to 100. Each spawn attempt has rarity% chance to succeed when using the CustomObject(...) resource.
# Ignored by Tree(..), Sapling(..) and CustomStructure(..)
Rarity: 11.0

# If you set this to true, the BO3 will be placed with a random rotation.
RotateRandomly: true

# The spawn height of the BO3: randomY, highestBlock or highestSolidBlock.
SpawnHeight: highestSolidBlock

# The offset from the spawn height to spawn this BO3
# Ex. SpawnHeight = highestSolidBlock, SpawnHeightOffset = 3; This object will spawn 3 blocks above the highest solid block
SpawnHeightOffset: -12

# A random amount to offset the spawn location from the spawn offset height
# Ex. SpawnHeightOffset = 3, SpawnHeightVariance = 3; This object will spawn 3 to 6 blocks above the original spot it would have spawned
SpawnHeightVariance: 0

##############################
# Height Limits for the BO3. #
##############################

# When in randomY mode used as the minimum Y or in atMinY mode as the actual Y to spawn this BO3 at.
MinHeight: 80

# When in randomY mode used as the maximum Y to spawn this BO3 at.
MaxHeight: 255

######################
# Extrusion settings #
######################

# The style of extrusion you wish to use - BottomDown, TopUp, None (Default)
ExtrudeMode: BottomDown

# The blocks to extrude your BO3 through
ExtrudeThroughBlocks: AIR

# Objects can have other objects attacthed to it: branches. Branches can also
# have branches attached to it, which can also have branches, etc. This is the
# maximum branch depth for this objects.
MaxBranchDepth: 10

# When spawned with the UseWorld keyword, this BO3 should NOT spawn in the following biomes.
# If you write the BO3 name directly in the BiomeConfigs, this will be ignored.
ExcludedBiomes: All


#######################################################################
# +-----------------------------------------------------------------+ #
# |                      Source block settings                      | #
# +-----------------------------------------------------------------+ #
#######################################################################

# The block(s) the BO3 should spawn in.
SourceBlocks: AIR

# The maximum percentage of the BO3 that can be outside the SourceBlock.
# The BO3 won't be placed on a location with more blocks outside the SourceBlock than this percentage.
MaxPercentageOutsideSourceBlock: 100

# What to do when a block is about to be placed outside the SourceBlock? (dontPlace, placeAnyway)
OutsideSourceBlock: placeAnyway

# Disable doReplaceBlocks to make this BO3 ignore any ReplacedBlocks settings in biome configs, improves performance.
DoReplaceBlocks: true

# OTG+ settings #
# Legacy setting, rename this file to .BO4 instead. Set this to true to enable the advanced customstructure features of OTG+.
IsOTGPlus: false


#######################################################################
# +-----------------------------------------------------------------+ #
# |                              Blocks                             | #
# +-----------------------------------------------------------------+ #
#######################################################################

# All the blocks used in the BO3 are listed here. Possible blocks:
# Block(x,y,z,id[.data][,nbtfile.nbt)
# RandomBlock(x,y,z,id[:data][,nbtfile.nbt],chance[,id[:data][,nbtfile.nbt],chance[,...]])
#  So RandomBlock(0,0,0,CHEST,chest.nbt,50,CHEST,anotherchest.nbt,100) will spawn a chest at
#  the BO3 origin, and give it a 50% chance to have the contents of chest.nbt, or, if that
#  fails, a 100% percent chance to have the contents of anotherchest.nbt.
# *Note: Unlike Entity() and Spawner(), for Block() .txt files don't work, only .nbt files work.
# MinecraftObject(x,y,z,name) (TODO: This may not work anymore and needs to be tested.
#  Spawns an object in the Mojang NBT structure format. For example, 
#  MinecraftObject(0,0,0,minecraft:igloo/igloo_bottom)
#  spawns the bottom part of an igloo.
Block(-10,0,3,HARD_CLAY)
Block(-10,0,4,HARD_CLAY)
Block(-10,1,3,HARD_CLAY)
Block(-9,0,2,HARD_CLAY)
Block(-9,0,3,HARD_CLAY)
Block(-9,0,4,HARD_CLAY)
Block(-9,1,3,HARD_CLAY)
Block(-9,1,4,HARD_CLAY)
Block(-9,2,3,HARD_CLAY)
Block(-9,2,4,HARD_CLAY)
Block(-9,3,3,HARD_CLAY)
Block(-9,3,4,HARD_CLAY)
Block(-8,0,1,HARD_CLAY)
Block(-8,0,2,HARD_CLAY)
Block(-8,0,3,HARD_CLAY)
Block(-8,0,4,HARD_CLAY)
Block(-8,0,5,HARD_CLAY)
Block(-8,0,6,HARD_CLAY)
Block(-8,0,7,HARD_CLAY)
Block(-8,1,2,HARD_CLAY)
Block(-8,1,3,HARD_CLAY)
Block(-8,1,4,HARD_CLAY)
Block(-8,1,6,HARD_CLAY)
Block(-8,2,3,HARD_CLAY)
Block(-8,2,4,HARD_CLAY)
Block(-8,2,6,HARD_CLAY)
Block(-8,3,3,HARD_CLAY)
Block(-8,3,4,HARD_CLAY)
Block(-7,0,-1,HARD_CLAY)
Block(-7,0,0,HARD_CLAY)
Block(-7,0,1,HARD_CLAY)
Block(-7,0,2,HARD_CLAY)
Block(-7,0,3,HARD_CLAY)
Block(-7,0,4,HARD_CLAY)
Block(-7,0,5,HARD_CLAY)
Block(-7,0,6,HARD_CLAY)
Block(-7,0,7,HARD_CLAY)
Block(-7,1,0,HARD_CLAY)
Block(-7,1,1,HARD_CLAY)
Block(-7,1,2,HARD_CLAY)
Block(-7,1,3,HARD_CLAY)
Block(-7,1,4,HARD_CLAY)
Block(-7,1,5,HARD_CLAY)
Block(-7,1,6,HARD_CLAY)
Block(-7,1,7,HARD_CLAY)
Block(-7,2,2,HARD_CLAY)
Block(-7,2,3,HARD_CLAY)
Block(-7,2,4,HARD_CLAY)
Block(-7,2,5,HARD_CLAY)
Block(-7,2,6,HARD_CLAY)
Block(-7,3,2,HARD_CLAY)
Block(-7,3,3,HARD_CLAY)
Block(-7,3,4,HARD_CLAY)
Block(-7,3,6,HARD_CLAY)
Block(-7,4,4,HARD_CLAY)
Block(-6,0,-3,HARD_CLAY)
Block(-6,0,-2,HARD_CLAY)
Block(-6,0,-1,HARD_CLAY)
Block(-6,0,0,HARD_CLAY)
Block(-6,0,1,HARD_CLAY)
Block(-6,0,2,HARD_CLAY)
Block(-6,0,3,HARD_CLAY)
Block(-6,0,4,HARD_CLAY)
Block(-6,0,5,HARD_CLAY)
Block(-6,0,6,HARD_CLAY)
Block(-6,0,7,HARD_CLAY)
Block(-6,1,-2,HARD_CLAY)
Block(-6,1,-1,HARD_CLAY)
Block(-6,1,0,HARD_CLAY)
Block(-6,1,1,HARD_CLAY)
Block(-6,1,2,HARD_CLAY)
Block(-6,1,3,HARD_CLAY)
Block(-6,1,4,HARD_CLAY)
Block(-6,1,5,HARD_CLAY)
Block(-6,1,6,HARD_CLAY)
Block(-6,1,7,HARD_CLAY)
Block(-6,2,-1,HARD_CLAY)
Block(-6,2,0,HARD_CLAY)
Block(-6,2,1,HARD_CLAY)
Block(-6,2,2,HARD_CLAY)
Block(-6,2,3,HARD_CLAY)
Block(-6,2,4,HARD_CLAY)
Block(-6,2,5,HARD_CLAY)
Block(-6,2,6,HARD_CLAY)
Block(-6,3,0,HARD_CLAY)
Block(-6,3,1,HARD_CLAY)
Block(-6,3,2,HARD_CLAY)
Block(-6,3,3,HARD_CLAY)
Block(-6,3,4,HARD_CLAY)
Block(-6,3,5,HARD_CLAY)
Block(-6,3,6,HARD_CLAY)
Block(-6,4,0,HARD_CLAY)
Block(-6,4,1,HARD_CLAY)
Block(-6,4,2,HARD_CLAY)
Block(-6,4,3,HARD_CLAY)
Block(-6,4,4,HARD_CLAY)
Block(-6,4,5,HARD_CLAY)
Block(-6,5,1,HARD_CLAY)
Block(-6,5,2,HARD_CLAY)
Block(-6,6,1,HARD_CLAY)
Block(-6,6,2,HARD_CLAY)
Block(-6,7,2,HARD_CLAY)
Block(-6,8,2,HARD_CLAY)
Block(-6,9,2,HARD_CLAY)
Block(-5,0,-5,HARD_CLAY)
Block(-5,0,-4,HARD_CLAY)
Block(-5,0,-3,HARD_CLAY)
Block(-5,0,-2,HARD_CLAY)
Block(-5,0,-1,HARD_CLAY)
Block(-5,0,0,HARD_CLAY)
Block(-5,0,1,HARD_CLAY)
Block(-5,0,2,HARD_CLAY)
Block(-5,0,3,HARD_CLAY)
Block(-5,0,4,HARD_CLAY)
Block(-5,0,5,HARD_CLAY)
Block(-5,0,6,HARD_CLAY)
Block(-5,0,7,HARD_CLAY)
Block(-5,0,8,HARD_CLAY)
Block(-5,1,-4,HARD_CLAY)
Block(-5,1,-3,HARD_CLAY)
Block(-5,1,-2,HARD_CLAY)
Block(-5,1,-1,HARD_CLAY)
Block(-5,1,0,HARD_CLAY)
Block(-5,1,1,HARD_CLAY)
Block(-5,1,2,HARD_CLAY)
Block(-5,1,3,HARD_CLAY)
Block(-5,1,4,HARD_CLAY)
Block(-5,1,5,HARD_CLAY)
Block(-5,1,6,HARD_CLAY)
Block(-5,1,7,HARD_CLAY)
Block(-5,2,-3,HARD_CLAY)
Block(-5,2,-2,HARD_CLAY)
Block(-5,2,-1,HARD_CLAY)
Block(-5,2,0,HARD_CLAY)
Block(-5,2,1,HARD_CLAY)
Block(-5,2,2,HARD_CLAY)
Block(-5,2,3,HARD_CLAY)
Block(-5,2,4,HARD_CLAY)
Block(-5,2,5,HARD_CLAY)
Block(-5,2,6,HARD_CLAY)
Block(-5,2,7,HARD_CLAY)
Block(-5,3,-3,HARD_CLAY)
Block(-5,3,-2,HARD_CLAY)
Block(-5,3,-1,HARD_CLAY)
Block(-5,3,0,HARD_CLAY)
Block(-5,3,1,HARD_CLAY)
Block(-5,3,2,HARD_CLAY)
Block(-5,3,3,HARD_CLAY)
Block(-5,3,4,HARD_CLAY)
Block(-5,3,5,HARD_CLAY)
Block(-5,3,6,HARD_CLAY)
Block(-5,3,7,HARD_CLAY)
Block(-5,4,-1,HARD_CLAY)
Block(-5,4,0,HARD_CLAY)
Block(-5,4,1,HARD_CLAY)
Block(-5,4,2,HARD_CLAY)
Block(-5,4,3,HARD_CLAY)
Block(-5,4,4,HARD_CLAY)
Block(-5,4,5,HARD_CLAY)
Block(-5,4,7,HARD_CLAY)
Block(-5,5,-1,HARD_CLAY)
Block(-5,5,0,HARD_CLAY)
Block(-5,5,1,HARD_CLAY)
Block(-5,5,2,HARD_CLAY)
Block(-5,5,3,HARD_CLAY)
Block(-5,6,-1,HARD_CLAY)
Block(-5,6,0,HARD_CLAY)
Block(-5,6,1,HARD_CLAY)
Block(-5,6,2,HARD_CLAY)
Block(-5,6,3,HARD_CLAY)
Block(-5,7,-1,HARD_CLAY)
Block(-5,7,0,HARD_CLAY)
Block(-5,7,1,HARD_CLAY)
Block(-5,7,2,HARD_CLAY)
Block(-5,7,3,HARD_CLAY)
Block(-5,8,-1,HARD_CLAY)
Block(-5,8,0,HARD_CLAY)
Block(-5,8,1,HARD_CLAY)
Block(-5,8,2,HARD_CLAY)
Block(-5,8,3,HARD_CLAY)
Block(-5,9,-1,HARD_CLAY)
Block(-5,9,0,HARD_CLAY)
Block(-5,9,1,HARD_CLAY)
Block(-5,9,2,HARD_CLAY)
Block(-5,10,-1,HARD_CLAY)
Block(-5,10,0,HARD_CLAY)
Block(-5,10,1,HARD_CLAY)
Block(-5,10,2,HARD_CLAY)
Block(-5,11,0,HARD_CLAY)
Block(-5,11,1,HARD_CLAY)
Block(-5,11,2,HARD_CLAY)
Block(-5,12,1,HARD_CLAY)
Block(-5,12,2,HARD_CLAY)
Block(-5,13,1,HARD_CLAY)
Block(-5,13,2,HARD_CLAY)
Block(-5,14,1,HARD_CLAY)
Block(-5,14,2,HARD_CLAY)
Block(-5,15,1,HARD_CLAY)
Block(-5,15,2,HARD_CLAY)
Block(-5,16,1,HARD_CLAY)
Block(-5,16,2,HARD_CLAY)
Block(-5,17,1,HARD_CLAY)
Block(-5,18,1,HARD_CLAY)
Block(-5,19,1,HARD_CLAY)
Block(-5,20,1,HARD_CLAY)
Block(-5,21,1,HARD_CLAY)
Block(-5,22,1,HARD_CLAY)
Block(-5,23,1,HARD_CLAY)
Block(-5,24,1,HARD_CLAY)
Block(-4,0,-5,HARD_CLAY)
Block(-4,0,-4,HARD_CLAY)
Block(-4,0,-3,HARD_CLAY)
Block(-4,0,-2,HARD_CLAY)
Block(-4,0,-1,HARD_CLAY)
Block(-4,0,0,HARD_CLAY)
Block(-4,0,1,HARD_CLAY)
Block(-4,0,2,HARD_CLAY)
Block(-4,0,3,HARD_CLAY)
Block(-4,0,4,HARD_CLAY)
Block(-4,0,5,HARD_CLAY)
Block(-4,0,6,HARD_CLAY)
Block(-4,0,7,HARD_CLAY)
Block(-4,0,8,HARD_CLAY)
Block(-4,1,-4,HARD_CLAY)
Block(-4,1,-3,HARD_CLAY)
Block(-4,1,-2,HARD_CLAY)
Block(-4,1,-1,HARD_CLAY)
Block(-4,1,0,HARD_CLAY)
Block(-4,1,1,HARD_CLAY)
Block(-4,1,2,HARD_CLAY)
Block(-4,1,3,HARD_CLAY)
Block(-4,1,4,HARD_CLAY)
Block(-4,1,5,HARD_CLAY)
Block(-4,1,6,HARD_CLAY)
Block(-4,1,7,HARD_CLAY)
Block(-4,2,-4,HARD_CLAY)
Block(-4,2,-3,HARD_CLAY)
Block(-4,2,-2,HARD_CLAY)
Block(-4,2,-1,HARD_CLAY)
Block(-4,2,0,HARD_CLAY)
Block(-4,2,1,HARD_CLAY)
Block(-4,2,2,HARD_CLAY)
Block(-4,2,3,HARD_CLAY)
Block(-4,2,4,HARD_CLAY)
Block(-4,2,5,HARD_CLAY)
Block(-4,2,6,HARD_CLAY)
Block(-4,2,7,HARD_CLAY)
Block(-4,3,-4,HARD_CLAY)
Block(-4,3,-3,HARD_CLAY)
Block(-4,3,-2,HARD_CLAY)
Block(-4,3,-1,HARD_CLAY)
Block(-4,3,0,HARD_CLAY)
Block(-4,3,1,HARD_CLAY)
Block(-4,3,2,HARD_CLAY)
Block(-4,3,3,HARD_CLAY)
Block(-4,3,4,HARD_CLAY)
Block(-4,3,5,HARD_CLAY)
Block(-4,3,6,HARD_CLAY)
Block(-4,3,7,HARD_CLAY)
Block(-4,4,-4,HARD_CLAY)
Block(-4,4,-3,HARD_CLAY)
Block(-4,4,-2,HARD_CLAY)
Block(-4,4,-1,HARD_CLAY)
Block(-4,4,0,HARD_CLAY)
Block(-4,4,1,HARD_CLAY)
Block(-4,4,2,HARD_CLAY)
Block(-4,4,3,HARD_CLAY)
Block(-4,4,4,HARD_CLAY)
Block(-4,4,5,HARD_CLAY)
Block(-4,4,6,HARD_CLAY)
Block(-4,5,-4,HARD_CLAY)
Block(-4,5,-3,HARD_CLAY)
Block(-4,5,-2,HARD_CLAY)
Block(-4,5,-1,HARD_CLAY)
Block(-4,5,0,HARD_CLAY)
Block(-4,5,1,HARD_CLAY)
Block(-4,5,2,HARD_CLAY)
Block(-4,5,3,HARD_CLAY)
Block(-4,5,4,HARD_CLAY)
Block(-4,5,5,HARD_CLAY)
Block(-4,5,6,HARD_CLAY)
Block(-4,6,-4,HARD_CLAY)
Block(-4,6,-3,HARD_CLAY)
Block(-4,6,-2,HARD_CLAY)
Block(-4,6,-1,HARD_CLAY)
Block(-4,6,0,HARD_CLAY)
Block(-4,6,1,HARD_CLAY)
Block(-4,6,2,HARD_CLAY)
Block(-4,6,3,HARD_CLAY)
Block(-4,6,4,HARD_CLAY)
Block(-4,6,5,HARD_CLAY)
Block(-4,7,-3,HARD_CLAY)
Block(-4,7,-2,HARD_CLAY)
Block(-4,7,-1,HARD_CLAY)
Block(-4,7,0,HARD_CLAY)
Block(-4,7,1,HARD_CLAY)
Block(-4,7,2,HARD_CLAY)
Block(-4,7,3,HARD_CLAY)
Block(-4,7,4,HARD_CLAY)
Block(-4,8,-1,HARD_CLAY)
Block(-4,8,0,HARD_CLAY)
Block(-4,8,1,HARD_CLAY)
Block(-4,8,2,HARD_CLAY)
Block(-4,8,3,HARD_CLAY)
Block(-4,8,4,HARD_CLAY)
Block(-4,9,0,HARD_CLAY)
Block(-4,9,1,HARD_CLAY)
Block(-4,9,2,HARD_CLAY)
Block(-4,9,3,HARD_CLAY)
Block(-4,9,4,HARD_CLAY)
Block(-4,10,0,HARD_CLAY)
Block(-4,10,1,HARD_CLAY)
Block(-4,10,2,HARD_CLAY)
Block(-4,10,3,HARD_CLAY)
Block(-4,10,4,HARD_CLAY)
Block(-4,11,0,HARD_CLAY)
Block(-4,11,1,HARD_CLAY)
Block(-4,11,2,HARD_CLAY)
Block(-4,11,3,HARD_CLAY)
Block(-4,12,0,HARD_CLAY)
Block(-4,12,1,HARD_CLAY)
Block(-4,12,2,HARD_CLAY)
Block(-4,12,3,HARD_CLAY)
Block(-4,13,0,HARD_CLAY)
Block(-4,13,1,HARD_CLAY)
Block(-4,13,2,HARD_CLAY)
Block(-4,14,0,HARD_CLAY)
Block(-4,14,1,HARD_CLAY)
Block(-4,14,2,HARD_CLAY)
Block(-4,15,0,HARD_CLAY)
Block(-4,15,1,HARD_CLAY)
Block(-4,15,2,HARD_CLAY)
Block(-4,16,0,HARD_CLAY)
Block(-4,16,1,HARD_CLAY)
Block(-4,16,2,HARD_CLAY)
Block(-4,17,0,HARD_CLAY)
Block(-4,17,1,HARD_CLAY)
Block(-4,17,2,HARD_CLAY)
Block(-4,18,1,HARD_CLAY)
Block(-4,18,2,HARD_CLAY)
Block(-4,19,1,HARD_CLAY)
Block(-4,19,2,HARD_CLAY)
Block(-4,20,1,HARD_CLAY)
Block(-4,21,1,HARD_CLAY)
Block(-4,22,1,HARD_CLAY)
Block(-4,23,1,HARD_CLAY)
Block(-4,24,1,HARD_CLAY)
Block(-4,25,1,HARD_CLAY)
Block(-3,0,-4,HARD_CLAY)
Block(-3,0,-3,HARD_CLAY)
Block(-3,0,-2,HARD_CLAY)
Block(-3,0,-1,HARD_CLAY)
Block(-3,0,0,HARD_CLAY)
Block(-3,0,1,HARD_CLAY)
Block(-3,0,2,HARD_CLAY)
Block(-3,0,3,HARD_CLAY)
Block(-3,0,4,HARD_CLAY)
Block(-3,0,5,HARD_CLAY)
Block(-3,0,6,HARD_CLAY)
Block(-3,0,7,HARD_CLAY)
Block(-3,0,8,HARD_CLAY)
Block(-3,1,-4,HARD_CLAY)
Block(-3,1,-3,HARD_CLAY)
Block(-3,1,-2,HARD_CLAY)
Block(-3,1,-1,HARD_CLAY)
Block(-3,1,0,HARD_CLAY)
Block(-3,1,1,HARD_CLAY)
Block(-3,1,2,HARD_CLAY)
Block(-3,1,3,HARD_CLAY)
Block(-3,1,4,HARD_CLAY)
Block(-3,1,5,HARD_CLAY)
Block(-3,1,6,HARD_CLAY)
Block(-3,1,7,HARD_CLAY)
Block(-3,1,8,HARD_CLAY)
Block(-3,2,-4,HARD_CLAY)
Block(-3,2,-3,HARD_CLAY)
Block(-3,2,-2,HARD_CLAY)
Block(-3,2,-1,HARD_CLAY)
Block(-3,2,0,HARD_CLAY)
Block(-3,2,1,HARD_CLAY)
Block(-3,2,2,HARD_CLAY)
Block(-3,2,3,HARD_CLAY)
Block(-3,2,4,HARD_CLAY)
Block(-3,2,5,HARD_CLAY)
Block(-3,2,6,HARD_CLAY)
Block(-3,2,7,HARD_CLAY)
Block(-3,3,-3,HARD_CLAY)
Block(-3,3,-2,HARD_CLAY)
Block(-3,3,-1,HARD_CLAY)
Block(-3,3,0,HARD_CLAY)
Block(-3,3,1,HARD_CLAY)
Block(-3,3,2,HARD_CLAY)
Block(-3,3,3,HARD_CLAY)
Block(-3,3,4,HARD_CLAY)
Block(-3,3,5,HARD_CLAY)
Block(-3,3,6,HARD_CLAY)
Block(-3,3,7,HARD_CLAY)
Block(-3,4,-3,HARD_CLAY)
Block(-3,4,-2,HARD_CLAY)
Block(-3,4,-1,HARD_CLAY)
Block(-3,4,0,HARD_CLAY)
Block(-3,4,1,HARD_CLAY)
Block(-3,4,2,HARD_CLAY)
Block(-3,4,3,HARD_CLAY)
Block(-3,4,4,HARD_CLAY)
Block(-3,4,5,HARD_CLAY)
Block(-3,4,6,HARD_CLAY)
Block(-3,4,7,HARD_CLAY)
Block(-3,5,-3,HARD_CLAY)
Block(-3,5,-2,HARD_CLAY)
Block(-3,5,-1,HARD_CLAY)
Block(-3,5,0,HARD_CLAY)
Block(-3,5,1,HARD_CLAY)
Block(-3,5,2,HARD_CLAY)
Block(-3,5,3,HARD_CLAY)
Block(-3,5,4,HARD_CLAY)
Block(-3,5,5,HARD_CLAY)
Block(-3,5,6,HARD_CLAY)
Block(-3,5,7,HARD_CLAY)
Block(-3,6,-2,HARD_CLAY)
Block(-3,6,-1,HARD_CLAY)
Block(-3,6,0,HARD_CLAY)
Block(-3,6,1,HARD_CLAY)
Block(-3,6,2,HARD_CLAY)
Block(-3,6,3,HARD_CLAY)
Block(-3,6,4,HARD_CLAY)
Block(-3,6,5,HARD_CLAY)
Block(-3,6,6,HARD_CLAY)
Block(-3,6,7,HARD_CLAY)
Block(-3,7,-2,HARD_CLAY)
Block(-3,7,-1,HARD_CLAY)
Block(-3,7,0,HARD_CLAY)
Block(-3,7,1,HARD_CLAY)
Block(-3,7,2,HARD_CLAY)
Block(-3,7,3,HARD_CLAY)
Block(-3,7,4,HARD_CLAY)
Block(-3,7,5,HARD_CLAY)
Block(-3,7,6,HARD_CLAY)
Block(-3,8,-2,HARD_CLAY)
Block(-3,8,-1,HARD_CLAY)
Block(-3,8,0,HARD_CLAY)
Block(-3,8,1,HARD_CLAY)
Block(-3,8,2,HARD_CLAY)
Block(-3,8,3,HARD_CLAY)
Block(-3,8,4,HARD_CLAY)
Block(-3,8,5,HARD_CLAY)
Block(-3,9,-2,HARD_CLAY)
Block(-3,9,-1,HARD_CLAY)
Block(-3,9,0,HARD_CLAY)
Block(-3,9,1,HARD_CLAY)
Block(-3,9,2,HARD_CLAY)
Block(-3,9,3,HARD_CLAY)
Block(-3,9,4,HARD_CLAY)
Block(-3,9,5,HARD_CLAY)
Block(-3,10,-2,HARD_CLAY)
Block(-3,10,-1,HARD_CLAY)
Block(-3,10,0,HARD_CLAY)
Block(-3,10,1,HARD_CLAY)
Block(-3,10,2,HARD_CLAY)
Block(-3,10,3,HARD_CLAY)
Block(-3,10,4,HARD_CLAY)
Block(-3,11,-2,HARD_CLAY)
Block(-3,11,-1,HARD_CLAY)
Block(-3,11,0,HARD_CLAY)
Block(-3,11,1,HARD_CLAY)
Block(-3,11,2,HARD_CLAY)
Block(-3,11,3,HARD_CLAY)
Block(-3,11,4,HARD_CLAY)
Block(-3,12,-1,HARD_CLAY)
Block(-3,12,0,HARD_CLAY)
Block(-3,12,1,HARD_CLAY)
Block(-3,12,2,HARD_CLAY)
Block(-3,12,3,HARD_CLAY)
Block(-3,12,4,HARD_CLAY)
Block(-3,13,0,HARD_CLAY)
Block(-3,13,1,HARD_CLAY)
Block(-3,13,2,HARD_CLAY)
Block(-3,13,3,HARD_CLAY)
Block(-3,13,4,HARD_CLAY)
Block(-3,14,0,HARD_CLAY)
Block(-3,14,1,HARD_CLAY)
Block(-3,14,2,HARD_CLAY)
Block(-3,14,3,HARD_CLAY)
Block(-3,14,4,HARD_CLAY)
Block(-3,15,0,HARD_CLAY)
Block(-3,15,1,HARD_CLAY)
Block(-3,15,2,HARD_CLAY)
Block(-3,15,4,HARD_CLAY)
Block(-3,16,0,HARD_CLAY)
Block(-3,16,1,HARD_CLAY)
Block(-3,16,2,HARD_CLAY)
Block(-3,17,0,HARD_CLAY)
Block(-3,17,1,HARD_CLAY)
Block(-3,17,2,HARD_CLAY)
Block(-3,18,1,HARD_CLAY)
Block(-3,18,2,HARD_CLAY)
Block(-3,19,1,HARD_CLAY)
Block(-3,19,2,HARD_CLAY)
Block(-3,20,1,HARD_CLAY)
Block(-3,20,2,HARD_CLAY)
Block(-3,21,1,HARD_CLAY)
Block(-3,21,2,HARD_CLAY)
Block(-3,22,1,HARD_CLAY)
Block(-3,23,1,HARD_CLAY)
Block(-2,0,-6,HARD_CLAY)
Block(-2,0,-5,HARD_CLAY)
Block(-2,0,-4,HARD_CLAY)
Block(-2,0,-3,HARD_CLAY)
Block(-2,0,-2,HARD_CLAY)
Block(-2,0,-1,HARD_CLAY)
Block(-2,0,0,HARD_CLAY)
Block(-2,0,1,HARD_CLAY)
Block(-2,0,2,HARD_CLAY)
Block(-2,0,3,HARD_CLAY)
Block(-2,0,4,HARD_CLAY)
Block(-2,0,5,HARD_CLAY)
Block(-2,0,6,HARD_CLAY)
Block(-2,0,7,HARD_CLAY)
Block(-2,0,8,HARD_CLAY)
Block(-2,1,-6,HARD_CLAY)
Block(-2,1,-5,HARD_CLAY)
Block(-2,1,-4,HARD_CLAY)
Block(-2,1,-3,HARD_CLAY)
Block(-2,1,-2,HARD_CLAY)
Block(-2,1,-1,HARD_CLAY)
Block(-2,1,0,HARD_CLAY)
Block(-2,1,1,HARD_CLAY)
Block(-2,1,2,HARD_CLAY)
Block(-2,1,3,HARD_CLAY)
Block(-2,1,4,HARD_CLAY)
Block(-2,1,5,HARD_CLAY)
Block(-2,1,6,HARD_CLAY)
Block(-2,1,7,HARD_CLAY)
Block(-2,1,8,HARD_CLAY)
Block(-2,2,-6,HARD_CLAY)
Block(-2,2,-5,HARD_CLAY)
Block(-2,2,-4,HARD_CLAY)
Block(-2,2,-3,HARD_CLAY)
Block(-2,2,-2,HARD_CLAY)
Block(-2,2,-1,HARD_CLAY)
Block(-2,2,0,HARD_CLAY)
Block(-2,2,1,HARD_CLAY)
Block(-2,2,2,HARD_CLAY)
Block(-2,2,3,HARD_CLAY)
Block(-2,2,4,HARD_CLAY)
Block(-2,2,5,HARD_CLAY)
Block(-2,2,6,HARD_CLAY)
Block(-2,2,7,HARD_CLAY)
Block(-2,2,8,HARD_CLAY)
Block(-2,3,-5,HARD_CLAY)
Block(-2,3,-4,HARD_CLAY)
Block(-2,3,-3,HARD_CLAY)
Block(-2,3,-2,HARD_CLAY)
Block(-2,3,-1,HARD_CLAY)
Block(-2,3,0,HARD_CLAY)
Block(-2,3,1,HARD_CLAY)
Block(-2,3,2,HARD_CLAY)
Block(-2,3,3,HARD_CLAY)
Block(-2,3,4,HARD_CLAY)
Block(-2,3,5,HARD_CLAY)
Block(-2,3,6,HARD_CLAY)
Block(-2,3,7,HARD_CLAY)
Block(-2,4,-5,HARD_CLAY)
Block(-2,4,-4,HARD_CLAY)
Block(-2,4,-3,HARD_CLAY)
Block(-2,4,-2,HARD_CLAY)
Block(-2,4,-1,HARD_CLAY)
Block(-2,4,0,HARD_CLAY)
Block(-2,4,1,HARD_CLAY)
Block(-2,4,2,HARD_CLAY)
Block(-2,4,3,HARD_CLAY)
Block(-2,4,4,HARD_CLAY)
Block(-2,4,5,HARD_CLAY)
Block(-2,4,6,HARD_CLAY)
Block(-2,5,-5,HARD_CLAY)
Block(-2,5,-4,HARD_CLAY)
Block(-2,5,-3,HARD_CLAY)
Block(-2,5,-2,HARD_CLAY)
Block(-2,5,-1,HARD_CLAY)
Block(-2,5,0,HARD_CLAY)
Block(-2,5,1,HARD_CLAY)
Block(-2,5,2,HARD_CLAY)
Block(-2,5,3,HARD_CLAY)
Block(-2,5,4,HARD_CLAY)
Block(-2,5,5,HARD_CLAY)
Block(-2,5,6,HARD_CLAY)
Block(-2,6,-5,HARD_CLAY)
Block(-2,6,-4,HARD_CLAY)
Block(-2,6,-3,HARD_CLAY)
Block(-2,6,-2,HARD_CLAY)
Block(-2,6,-1,HARD_CLAY)
Block(-2,6,0,HARD_CLAY)
Block(-2,6,1,HARD_CLAY)
Block(-2,6,2,HARD_CLAY)
Block(-2,6,3,HARD_CLAY)
Block(-2,6,4,HARD_CLAY)
Block(-2,6,5,HARD_CLAY)
Block(-2,6,6,HARD_CLAY)
Block(-2,7,-5,HARD_CLAY)
Block(-2,7,-4,HARD_CLAY)
Block(-2,7,-3,HARD_CLAY)
Block(-2,7,-2,HARD_CLAY)
Block(-2,7,-1,HARD_CLAY)
Block(-2,7,0,HARD_CLAY)
Block(-2,7,1,HARD_CLAY)
Block(-2,7,2,HARD_CLAY)
Block(-2,7,3,HARD_CLAY)
Block(-2,7,4,HARD_CLAY)
Block(-2,7,5,HARD_CLAY)
Block(-2,7,6,HARD_CLAY)
Block(-2,8,-5,HARD_CLAY)
Block(-2,8,-4,HARD_CLAY)
Block(-2,8,-3,HARD_CLAY)
Block(-2,8,-2,HARD_CLAY)
Block(-2,8,-1,HARD_CLAY)
Block(-2,8,0,HARD_CLAY)
Block(-2,8,1,HARD_CLAY)
Block(-2,8,2,HARD_CLAY)
Block(-2,8,3,HARD_CLAY)
Block(-2,8,4,HARD_CLAY)
Block(-2,8,5,HARD_CLAY)
Block(-2,9,-5,HARD_CLAY)
Block(-2,9,-4,HARD_CLAY)
Block(-2,9,-3,HARD_CLAY)
Block(-2,9,-2,HARD_CLAY)
Block(-2,9,-1,HARD_CLAY)
Block(-2,9,0,HARD_CLAY)
Block(-2,9,1,HARD_CLAY)
Block(-2,9,2,HARD_CLAY)
Block(-2,9,3,HARD_CLAY)
Block(-2,9,4,HARD_CLAY)
Block(-2,9,5,HARD_CLAY)
Block(-2,10,-4,HARD_CLAY)
Block(-2,10,-3,HARD_CLAY)
Block(-2,10,-2,HARD_CLAY)
Block(-2,10,-1,HARD_CLAY)
Block(-2,10,0,HARD_CLAY)
Block(-2,10,1,HARD_CLAY)
Block(-2,10,2,HARD_CLAY)
Block(-2,10,3,HARD_CLAY)
Block(-2,10,4,HARD_CLAY)
Block(-2,10,5,HARD_CLAY)
Block(-2,11,-4,HARD_CLAY)
Block(-2,11,-3,HARD_CLAY)
Block(-2,11,-2,HARD_CLAY)
Block(-2,11,-1,HARD_CLAY)
Block(-2,11,0,HARD_CLAY)
Block(-2,11,1,HARD_CLAY)
Block(-2,11,2,HARD_CLAY)
Block(-2,11,3,HARD_CLAY)
Block(-2,11,4,HARD_CLAY)
Block(-2,11,5,HARD_CLAY)
Block(-2,12,-4,HARD_CLAY)
Block(-2,12,-3,HARD_CLAY)
Block(-2,12,-2,HARD_CLAY)
Block(-2,12,-1,HARD_CLAY)
Block(-2,12,0,HARD_CLAY)
Block(-2,12,1,HARD_CLAY)
Block(-2,12,2,HARD_CLAY)
Block(-2,12,3,HARD_CLAY)
Block(-2,12,5,HARD_CLAY)
Block(-2,13,-4,HARD_CLAY)
Block(-2,13,-3,HARD_CLAY)
Block(-2,13,-2,HARD_CLAY)
Block(-2,13,-1,HARD_CLAY)
Block(-2,13,0,HARD_CLAY)
Block(-2,13,1,HARD_CLAY)
Block(-2,13,2,HARD_CLAY)
Block(-2,13,3,HARD_CLAY)
Block(-2,13,5,HARD_CLAY)
Block(-2,14,-4,HARD_CLAY)
Block(-2,14,-3,HARD_CLAY)
Block(-2,14,-2,HARD_CLAY)
Block(-2,14,-1,HARD_CLAY)
Block(-2,14,0,HARD_CLAY)
Block(-2,14,1,HARD_CLAY)
Block(-2,14,2,HARD_CLAY)
Block(-2,14,3,HARD_CLAY)
Block(-2,15,-4,HARD_CLAY)
Block(-2,15,0,HARD_CLAY)
Block(-2,15,1,HARD_CLAY)
Block(-2,15,2,HARD_CLAY)
Block(-2,15,3,HARD_CLAY)
Block(-2,16,0,HARD_CLAY)
Block(-2,16,1,HARD_CLAY)
Block(-2,16,2,HARD_CLAY)
Block(-2,17,0,HARD_CLAY)
Block(-2,17,1,HARD_CLAY)
Block(-2,17,2,HARD_CLAY)
Block(-2,18,0,HARD_CLAY)
Block(-2,18,1,HARD_CLAY)
Block(-2,18,2,HARD_CLAY)
Block(-2,19,0,HARD_CLAY)
Block(-2,19,1,HARD_CLAY)
Block(-2,20,0,HARD_CLAY)
Block(-2,20,1,HARD_CLAY)
Block(-2,21,0,HARD_CLAY)
Block(-2,21,1,HARD_CLAY)
Block(-2,22,0,HARD_CLAY)
Block(-2,22,1,HARD_CLAY)
Block(-2,23,1,HARD_CLAY)
Block(-2,24,1,HARD_CLAY)
Block(-2,25,1,HARD_CLAY)
Block(-2,26,1,HARD_CLAY)
Block(-2,27,1,HARD_CLAY)
Block(-2,28,1,HARD_CLAY)
Block(-2,29,1,HARD_CLAY)
Block(-2,30,1,HARD_CLAY)
Block(-2,31,1,HARD_CLAY)
Block(-2,32,1,HARD_CLAY)
Block(-2,33,1,HARD_CLAY)
Block(-2,34,1,HARD_CLAY)
Block(-2,35,1,HARD_CLAY)
Block(-2,36,1,HARD_CLAY)
Block(-2,37,1,HARD_CLAY)
Block(-1,0,-9,HARD_CLAY)
Block(-1,0,-8,HARD_CLAY)
Block(-1,0,-7,HARD_CLAY)
Block(-1,0,-6,HARD_CLAY)
Block(-1,0,-5,HARD_CLAY)
Block(-1,0,-4,HARD_CLAY)
Block(-1,0,-3,HARD_CLAY)
Block(-1,0,-2,HARD_CLAY)
Block(-1,0,-1,HARD_CLAY)
Block(-1,0,0,HARD_CLAY)
Block(-1,0,1,HARD_CLAY)
Block(-1,0,2,HARD_CLAY)
Block(-1,0,3,HARD_CLAY)
Block(-1,0,4,HARD_CLAY)
Block(-1,0,5,HARD_CLAY)
Block(-1,0,6,HARD_CLAY)
Block(-1,0,7,HARD_CLAY)
Block(-1,1,-9,HARD_CLAY)
Block(-1,1,-8,HARD_CLAY)
Block(-1,1,-7,HARD_CLAY)
Block(-1,1,-6,HARD_CLAY)
Block(-1,1,-5,HARD_CLAY)
Block(-1,1,-4,HARD_CLAY)
Block(-1,1,-3,HARD_CLAY)
Block(-1,1,-2,HARD_CLAY)
Block(-1,1,-1,HARD_CLAY)
Block(-1,1,0,HARD_CLAY)
Block(-1,1,1,HARD_CLAY)
Block(-1,1,2,HARD_CLAY)
Block(-1,1,3,HARD_CLAY)
Block(-1,1,4,HARD_CLAY)
Block(-1,1,5,HARD_CLAY)
Block(-1,1,6,HARD_CLAY)
Block(-1,2,-8,HARD_CLAY)
Block(-1,2,-7,HARD_CLAY)
Block(-1,2,-6,HARD_CLAY)
Block(-1,2,-5,HARD_CLAY)
Block(-1,2,-4,HARD_CLAY)
Block(-1,2,-3,HARD_CLAY)
Block(-1,2,-2,HARD_CLAY)
Block(-1,2,-1,HARD_CLAY)
Block(-1,2,0,HARD_CLAY)
Block(-1,2,1,HARD_CLAY)
Block(-1,2,2,HARD_CLAY)
Block(-1,2,3,HARD_CLAY)
Block(-1,2,4,HARD_CLAY)
Block(-1,2,5,HARD_CLAY)
Block(-1,2,6,HARD_CLAY)
Block(-1,3,-6,HARD_CLAY)
Block(-1,3,-5,HARD_CLAY)
Block(-1,3,-4,HARD_CLAY)
Block(-1,3,-3,HARD_CLAY)
Block(-1,3,-2,HARD_CLAY)
Block(-1,3,-1,HARD_CLAY)
Block(-1,3,0,HARD_CLAY)
Block(-1,3,1,HARD_CLAY)
Block(-1,3,2,HARD_CLAY)
Block(-1,3,3,HARD_CLAY)
Block(-1,3,4,HARD_CLAY)
Block(-1,3,5,HARD_CLAY)
Block(-1,3,6,HARD_CLAY)
Block(-1,4,-6,HARD_CLAY)
Block(-1,4,-5,HARD_CLAY)
Block(-1,4,-4,HARD_CLAY)
Block(-1,4,-3,HARD_CLAY)
Block(-1,4,-2,HARD_CLAY)
Block(-1,4,-1,HARD_CLAY)
Block(-1,4,0,HARD_CLAY)
Block(-1,4,1,HARD_CLAY)
Block(-1,4,2,HARD_CLAY)
Block(-1,4,3,HARD_CLAY)
Block(-1,4,4,HARD_CLAY)
Block(-1,4,5,HARD_CLAY)
Block(-1,4,6,HARD_CLAY)
Block(-1,5,-6,HARD_CLAY)
Block(-1,5,-5,HARD_CLAY)
Block(-1,5,-4,HARD_CLAY)
Block(-1,5,-3,HARD_CLAY)
Block(-1,5,-2,HARD_CLAY)
Block(-1,5,-1,HARD_CLAY)
Block(-1,5,0,HARD_CLAY)
Block(-1,5,1,HARD_CLAY)
Block(-1,5,2,HARD_CLAY)
Block(-1,5,3,HARD_CLAY)
Block(-1,5,4,HARD_CLAY)
Block(-1,5,5,HARD_CLAY)
Block(-1,6,-5,HARD_CLAY)
Block(-1,6,-4,HARD_CLAY)
Block(-1,6,-3,HARD_CLAY)
Block(-1,6,-2,HARD_CLAY)
Block(-1,6,-1,HARD_CLAY)
Block(-1,6,0,HARD_CLAY)
Block(-1,6,1,HARD_CLAY)
Block(-1,6,2,HARD_CLAY)
Block(-1,6,3,HARD_CLAY)
Block(-1,6,4,HARD_CLAY)
Block(-1,6,5,HARD_CLAY)
Block(-1,7,-5,HARD_CLAY)
Block(-1,7,-4,HARD_CLAY)
Block(-1,7,-3,HARD_CLAY)
Block(-1,7,-2,HARD_CLAY)
Block(-1,7,-1,HARD_CLAY)
Block(-1,7,0,HARD_CLAY)
Block(-1,7,1,HARD_CLAY)
Block(-1,7,2,HARD_CLAY)
Block(-1,7,3,HARD_CLAY)
Block(-1,7,4,HARD_CLAY)
Block(-1,7,5,HARD_CLAY)
Block(-1,8,-5,HARD_CLAY)
Block(-1,8,-4,HARD_CLAY)
Block(-1,8,-3,HARD_CLAY)
Block(-1,8,-2,HARD_CLAY)
Block(-1,8,-1,HARD_CLAY)
Block(-1,8,0,HARD_CLAY)
Block(-1,8,1,HARD_CLAY)
Block(-1,8,2,HARD_CLAY)
Block(-1,8,3,HARD_CLAY)
Block(-1,8,4,HARD_CLAY)
Block(-1,8,5,HARD_CLAY)
Block(-1,9,-5,HARD_CLAY)
Block(-1,9,-4,HARD_CLAY)
Block(-1,9,-3,HARD_CLAY)
Block(-1,9,-2,HARD_CLAY)
Block(-1,9,-1,HARD_CLAY)
Block(-1,9,0,HARD_CLAY)
Block(-1,9,1,HARD_CLAY)
Block(-1,9,2,HARD_CLAY)
Block(-1,9,3,HARD_CLAY)
Block(-1,9,4,HARD_CLAY)
Block(-1,9,5,HARD_CLAY)
Block(-1,10,-5,HARD_CLAY)
Block(-1,10,-4,HARD_CLAY)
Block(-1,10,-3,HARD_CLAY)
Block(-1,10,-2,HARD_CLAY)
Block(-1,10,-1,HARD_CLAY)
Block(-1,10,0,HARD_CLAY)
Block(-1,10,1,HARD_CLAY)
Block(-1,10,2,HARD_CLAY)
Block(-1,10,3,HARD_CLAY)
Block(-1,10,4,HARD_CLAY)
Block(-1,10,5,HARD_CLAY)
Block(-1,11,-5,HARD_CLAY)
Block(-1,11,-4,HARD_CLAY)
Block(-1,11,-3,HARD_CLAY)
Block(-1,11,-2,HARD_CLAY)
Block(-1,11,-1,HARD_CLAY)
Block(-1,11,0,HARD_CLAY)
Block(-1,11,1,HARD_CLAY)
Block(-1,11,2,HARD_CLAY)
Block(-1,11,3,HARD_CLAY)
Block(-1,11,4,HARD_CLAY)
Block(-1,11,5,HARD_CLAY)
Block(-1,12,-5,HARD_CLAY)
Block(-1,12,-4,HARD_CLAY)
Block(-1,12,-3,HARD_CLAY)
Block(-1,12,-2,HARD_CLAY)
Block(-1,12,-1,HARD_CLAY)
Block(-1,12,0,HARD_CLAY)
Block(-1,12,1,HARD_CLAY)
Block(-1,12,2,HARD_CLAY)
Block(-1,12,3,HARD_CLAY)
Block(-1,12,4,HARD_CLAY)
Block(-1,12,5,HARD_CLAY)
Block(-1,13,-5,HARD_CLAY)
Block(-1,13,-4,HARD_CLAY)
Block(-1,13,-3,HARD_CLAY)
Block(-1,13,-2,HARD_CLAY)
Block(-1,13,-1,HARD_CLAY)
Block(-1,13,0,HARD_CLAY)
Block(-1,13,1,HARD_CLAY)
Block(-1,13,2,HARD_CLAY)
Block(-1,13,3,HARD_CLAY)
Block(-1,13,4,HARD_CLAY)
Block(-1,13,5,HARD_CLAY)
Block(-1,14,-4,HARD_CLAY)
Block(-1,14,-3,HARD_CLAY)
Block(-1,14,-2,HARD_CLAY)
Block(-1,14,-1,HARD_CLAY)
Block(-1,14,0,HARD_CLAY)
Block(-1,14,1,HARD_CLAY)
Block(-1,14,2,HARD_CLAY)
Block(-1,14,3,HARD_CLAY)
Block(-1,15,-2,HARD_CLAY)
Block(-1,15,-1,HARD_CLAY)
Block(-1,15,0,HARD_CLAY)
Block(-1,15,1,HARD_CLAY)
Block(-1,15,2,HARD_CLAY)
Block(-1,15,3,HARD_CLAY)
Block(-1,16,-2,HARD_CLAY)
Block(-1,16,-1,HARD_CLAY)
Block(-1,16,0,HARD_CLAY)
Block(-1,16,1,HARD_CLAY)
Block(-1,16,2,HARD_CLAY)
Block(-1,16,3,HARD_CLAY)
Block(-1,17,-2,HARD_CLAY)
Block(-1,17,-1,HARD_CLAY)
Block(-1,17,0,HARD_CLAY)
Block(-1,17,1,HARD_CLAY)
Block(-1,17,2,HARD_CLAY)
Block(-1,17,3,HARD_CLAY)
Block(-1,18,-2,HARD_CLAY)
Block(-1,18,-1,HARD_CLAY)
Block(-1,18,0,HARD_CLAY)
Block(-1,18,1,HARD_CLAY)
Block(-1,18,2,HARD_CLAY)
Block(-1,18,3,HARD_CLAY)
Block(-1,19,-1,HARD_CLAY)
Block(-1,19,0,HARD_CLAY)
Block(-1,19,1,HARD_CLAY)
Block(-1,19,2,HARD_CLAY)
Block(-1,19,3,HARD_CLAY)
Block(-1,20,-1,HARD_CLAY)
Block(-1,20,0,HARD_CLAY)
Block(-1,20,1,HARD_CLAY)
Block(-1,20,2,HARD_CLAY)
Block(-1,20,3,HARD_CLAY)
Block(-1,21,-1,HARD_CLAY)
Block(-1,21,0,HARD_CLAY)
Block(-1,21,1,HARD_CLAY)
Block(-1,21,2,HARD_CLAY)
Block(-1,21,3,HARD_CLAY)
Block(-1,22,-1,HARD_CLAY)
Block(-1,22,0,HARD_CLAY)
Block(-1,22,1,HARD_CLAY)
Block(-1,22,3,HARD_CLAY)
Block(-1,23,-1,HARD_CLAY)
Block(-1,23,0,HARD_CLAY)
Block(-1,23,1,HARD_CLAY)
Block(-1,23,3,HARD_CLAY)
Block(-1,24,-1,HARD_CLAY)
Block(-1,24,0,HARD_CLAY)
Block(-1,24,1,HARD_CLAY)
Block(-1,24,3,HARD_CLAY)
Block(-1,25,-1,HARD_CLAY)
Block(-1,25,0,HARD_CLAY)
Block(-1,25,1,HARD_CLAY)
Block(-1,25,3,HARD_CLAY)
Block(-1,26,-1,HARD_CLAY)
Block(-1,26,0,HARD_CLAY)
Block(-1,26,1,HARD_CLAY)
Block(-1,26,3,HARD_CLAY)
Block(-1,27,0,HARD_CLAY)
Block(-1,27,1,HARD_CLAY)
Block(-1,27,3,HARD_CLAY)
Block(-1,28,0,HARD_CLAY)
Block(-1,28,1,HARD_CLAY)
Block(-1,28,3,HARD_CLAY)
Block(-1,29,0,HARD_CLAY)
Block(-1,29,1,HARD_CLAY)
Block(-1,30,0,HARD_CLAY)
Block(-1,30,1,HARD_CLAY)
Block(-1,31,0,HARD_CLAY)
Block(-1,31,1,HARD_CLAY)
Block(-1,32,0,HARD_CLAY)
Block(-1,32,1,HARD_CLAY)
Block(-1,33,1,HARD_CLAY)
Block(-1,34,1,HARD_CLAY)
Block(0,0,-10,HARD_CLAY)
Block(0,0,-9,HARD_CLAY)
Block(0,0,-8,HARD_CLAY)
Block(0,0,-7,HARD_CLAY)
Block(0,0,-6,HARD_CLAY)
Block(0,0,-5,HARD_CLAY)
Block(0,0,-4,HARD_CLAY)
Block(0,0,-3,HARD_CLAY)
Block(0,0,-2,HARD_CLAY)
Block(0,0,-1,HARD_CLAY)
Block(0,0,0,HARD_CLAY)
Block(0,0,1,HARD_CLAY)
Block(0,0,2,HARD_CLAY)
Block(0,0,3,HARD_CLAY)
Block(0,0,4,HARD_CLAY)
Block(0,0,5,HARD_CLAY)
Block(0,0,6,HARD_CLAY)
Block(0,0,7,HARD_CLAY)
Block(0,1,-9,HARD_CLAY)
Block(0,1,-8,HARD_CLAY)
Block(0,1,-7,HARD_CLAY)
Block(0,1,-6,HARD_CLAY)
Block(0,1,-5,HARD_CLAY)
Block(0,1,-4,HARD_CLAY)
Block(0,1,-3,HARD_CLAY)
Block(0,1,-2,HARD_CLAY)
Block(0,1,-1,HARD_CLAY)
Block(0,1,0,HARD_CLAY)
Block(0,1,1,HARD_CLAY)
Block(0,1,2,HARD_CLAY)
Block(0,1,3,HARD_CLAY)
Block(0,1,4,HARD_CLAY)
Block(0,1,5,HARD_CLAY)
Block(0,1,6,HARD_CLAY)
Block(0,2,-8,HARD_CLAY)
Block(0,2,-7,HARD_CLAY)
Block(0,2,-6,HARD_CLAY)
Block(0,2,-5,HARD_CLAY)
Block(0,2,-4,HARD_CLAY)
Block(0,2,-3,HARD_CLAY)
Block(0,2,-2,HARD_CLAY)
Block(0,2,-1,HARD_CLAY)
Block(0,2,0,HARD_CLAY)
Block(0,2,1,HARD_CLAY)
Block(0,2,2,HARD_CLAY)
Block(0,2,3,HARD_CLAY)
Block(0,2,4,HARD_CLAY)
Block(0,2,5,HARD_CLAY)
Block(0,2,6,HARD_CLAY)
Block(0,3,-8,HARD_CLAY)
Block(0,3,-7,HARD_CLAY)
Block(0,3,-6,HARD_CLAY)
Block(0,3,-5,HARD_CLAY)
Block(0,3,-4,HARD_CLAY)
Block(0,3,-3,HARD_CLAY)
Block(0,3,-2,HARD_CLAY)
Block(0,3,-1,HARD_CLAY)
Block(0,3,0,HARD_CLAY)
Block(0,3,1,HARD_CLAY)
Block(0,3,2,HARD_CLAY)
Block(0,3,3,HARD_CLAY)
Block(0,3,4,HARD_CLAY)
Block(0,3,5,HARD_CLAY)
Block(0,4,-8,HARD_CLAY)
Block(0,4,-7,HARD_CLAY)
Block(0,4,-6,HARD_CLAY)
Block(0,4,-5,HARD_CLAY)
Block(0,4,-4,HARD_CLAY)
Block(0,4,-3,HARD_CLAY)
Block(0,4,-2,HARD_CLAY)
Block(0,4,-1,HARD_CLAY)
Block(0,4,0,HARD_CLAY)
Block(0,4,1,HARD_CLAY)
Block(0,4,2,HARD_CLAY)
Block(0,4,3,HARD_CLAY)
Block(0,4,4,HARD_CLAY)
Block(0,4,5,HARD_CLAY)
Block(0,5,-8,HARD_CLAY)
Block(0,5,-7,HARD_CLAY)
Block(0,5,-6,HARD_CLAY)
Block(0,5,-5,HARD_CLAY)
Block(0,5,-4,HARD_CLAY)
Block(0,5,-3,HARD_CLAY)
Block(0,5,-2,HARD_CLAY)
Block(0,5,-1,HARD_CLAY)
Block(0,5,0,HARD_CLAY)
Block(0,5,1,HARD_CLAY)
Block(0,5,2,HARD_CLAY)
Block(0,5,3,HARD_CLAY)
Block(0,5,4,HARD_CLAY)
Block(0,5,5,HARD_CLAY)
Block(0,6,-8,HARD_CLAY)
Block(0,6,-7,HARD_CLAY)
Block(0,6,-6,HARD_CLAY)
Block(0,6,-5,HARD_CLAY)
Block(0,6,-4,HARD_CLAY)
Block(0,6,-3,HARD_CLAY)
Block(0,6,-2,HARD_CLAY)
Block(0,6,-1,HARD_CLAY)
Block(0,6,0,HARD_CLAY)
Block(0,6,1,HARD_CLAY)
Block(0,6,2,HARD_CLAY)
Block(0,6,3,HARD_CLAY)
Block(0,6,4,HARD_CLAY)
Block(0,6,5,HARD_CLAY)
Block(0,7,-7,HARD_CLAY)
Block(0,7,-5,HARD_CLAY)
Block(0,7,-4,HARD_CLAY)
Block(0,7,-3,HARD_CLAY)
Block(0,7,-2,HARD_CLAY)
Block(0,7,-1,HARD_CLAY)
Block(0,7,0,HARD_CLAY)
Block(0,7,1,HARD_CLAY)
Block(0,7,2,HARD_CLAY)
Block(0,7,3,HARD_CLAY)
Block(0,7,4,HARD_CLAY)
Block(0,7,5,HARD_CLAY)
Block(0,8,-7,HARD_CLAY)
Block(0,8,-5,HARD_CLAY)
Block(0,8,-4,HARD_CLAY)
Block(0,8,-3,HARD_CLAY)
Block(0,8,-2,HARD_CLAY)
Block(0,8,-1,HARD_CLAY)
Block(0,8,0,HARD_CLAY)
Block(0,8,1,HARD_CLAY)
Block(0,8,2,HARD_CLAY)
Block(0,8,3,HARD_CLAY)
Block(0,8,4,HARD_CLAY)
Block(0,8,5,HARD_CLAY)
Block(0,9,-7,HARD_CLAY)
Block(0,9,-5,HARD_CLAY)
Block(0,9,-4,HARD_CLAY)
Block(0,9,-3,HARD_CLAY)
Block(0,9,-2,HARD_CLAY)
Block(0,9,-1,HARD_CLAY)
Block(0,9,0,HARD_CLAY)
Block(0,9,1,HARD_CLAY)
Block(0,9,2,HARD_CLAY)
Block(0,9,3,HARD_CLAY)
Block(0,9,4,HARD_CLAY)
Block(0,10,-7,HARD_CLAY)
Block(0,10,-5,HARD_CLAY)
Block(0,10,-4,HARD_CLAY)
Block(0,10,-3,HARD_CLAY)
Block(0,10,-2,HARD_CLAY)
Block(0,10,-1,HARD_CLAY)
Block(0,10,0,HARD_CLAY)
Block(0,10,1,HARD_CLAY)
Block(0,10,2,HARD_CLAY)
Block(0,10,3,HARD_CLAY)
Block(0,10,4,HARD_CLAY)
Block(0,11,-5,HARD_CLAY)
Block(0,11,-4,HARD_CLAY)
Block(0,11,-3,HARD_CLAY)
Block(0,11,-2,HARD_CLAY)
Block(0,11,-1,HARD_CLAY)
Block(0,11,0,HARD_CLAY)
Block(0,11,1,HARD_CLAY)
Block(0,11,2,HARD_CLAY)
Block(0,11,3,HARD_CLAY)
Block(0,11,4,HARD_CLAY)
Block(0,12,-5,HARD_CLAY)
Block(0,12,-4,HARD_CLAY)
Block(0,12,-3,HARD_CLAY)
Block(0,12,-2,HARD_CLAY)
Block(0,12,-1,HARD_CLAY)
Block(0,12,0,HARD_CLAY)
Block(0,12,1,HARD_CLAY)
Block(0,12,2,HARD_CLAY)
Block(0,12,3,HARD_CLAY)
Block(0,12,4,HARD_CLAY)
Block(0,13,-4,HARD_CLAY)
Block(0,13,-3,HARD_CLAY)
Block(0,13,-2,HARD_CLAY)
Block(0,13,-1,HARD_CLAY)
Block(0,13,0,HARD_CLAY)
Block(0,13,1,HARD_CLAY)
Block(0,13,2,HARD_CLAY)
Block(0,13,3,HARD_CLAY)
Block(0,13,4,HARD_CLAY)
Block(0,14,-2,HARD_CLAY)
Block(0,14,-1,HARD_CLAY)
Block(0,14,0,HARD_CLAY)
Block(0,14,1,HARD_CLAY)
Block(0,14,2,HARD_CLAY)
Block(0,14,3,HARD_CLAY)
Block(0,14,4,HARD_CLAY)
Block(0,15,-2,HARD_CLAY)
Block(0,15,-1,HARD_CLAY)
Block(0,15,0,HARD_CLAY)
Block(0,15,1,HARD_CLAY)
Block(0,15,2,HARD_CLAY)
Block(0,15,3,HARD_CLAY)
Block(0,15,4,HARD_CLAY)
Block(0,16,-2,HARD_CLAY)
Block(0,16,-1,HARD_CLAY)
Block(0,16,0,HARD_CLAY)
Block(0,16,1,HARD_CLAY)
Block(0,16,2,HARD_CLAY)
Block(0,16,3,HARD_CLAY)
Block(0,17,-2,HARD_CLAY)
Block(0,17,-1,HARD_CLAY)
Block(0,17,0,HARD_CLAY)
Block(0,17,1,HARD_CLAY)
Block(0,17,2,HARD_CLAY)
Block(0,17,3,HARD_CLAY)
Block(0,18,-2,HARD_CLAY)
Block(0,18,-1,HARD_CLAY)
Block(0,18,0,HARD_CLAY)
Block(0,18,1,HARD_CLAY)
Block(0,18,2,HARD_CLAY)
Block(0,19,-2,HARD_CLAY)
Block(0,19,-1,HARD_CLAY)
Block(0,19,0,HARD_CLAY)
Block(0,19,1,HARD_CLAY)
Block(0,19,2,HARD_CLAY)
Block(0,20,-1,HARD_CLAY)
Block(0,20,0,HARD_CLAY)
Block(0,20,1,HARD_CLAY)
Block(0,20,2,HARD_CLAY)
Block(0,21,-1,HARD_CLAY)
Block(0,21,0,HARD_CLAY)
Block(0,21,1,HARD_CLAY)
Block(0,21,2,HARD_CLAY)
Block(0,22,-1,HARD_CLAY)
Block(0,22,0,HARD_CLAY)
Block(0,22,1,HARD_CLAY)
Block(0,22,2,HARD_CLAY)
Block(0,23,-1,HARD_CLAY)
Block(0,23,0,HARD_CLAY)
Block(0,23,1,HARD_CLAY)
Block(0,23,2,HARD_CLAY)
Block(0,24,0,HARD_CLAY)
Block(0,24,1,HARD_CLAY)
Block(0,25,0,HARD_CLAY)
Block(0,25,1,HARD_CLAY)
Block(0,26,0,HARD_CLAY)
Block(0,26,1,HARD_CLAY)
Block(0,27,0,HARD_CLAY)
Block(0,27,1,HARD_CLAY)
Block(0,28,0,HARD_CLAY)
Block(0,28,1,HARD_CLAY)
Block(0,29,0,HARD_CLAY)
Block(0,29,1,HARD_CLAY)
Block(0,30,1,HARD_CLAY)
Block(0,31,1,HARD_CLAY)
Block(0,32,1,HARD_CLAY)
Block(1,0,-13,HARD_CLAY)
Block(1,0,-12,HARD_CLAY)
Block(1,0,-11,HARD_CLAY)
Block(1,0,-10,HARD_CLAY)
Block(1,0,-9,HARD_CLAY)
Block(1,0,-8,HARD_CLAY)
Block(1,0,-7,HARD_CLAY)
Block(1,0,-6,HARD_CLAY)
Block(1,0,-5,HARD_CLAY)
Block(1,0,-4,HARD_CLAY)
Block(1,0,-3,HARD_CLAY)
Block(1,0,-2,HARD_CLAY)
Block(1,0,-1,HARD_CLAY)
Block(1,0,0,HARD_CLAY)
Block(1,0,1,HARD_CLAY)
Block(1,0,2,HARD_CLAY)
Block(1,0,3,HARD_CLAY)
Block(1,0,4,HARD_CLAY)
Block(1,0,5,HARD_CLAY)
Block(1,0,6,HARD_CLAY)
Block(1,0,7,HARD_CLAY)
Block(1,1,-12,HARD_CLAY)
Block(1,1,-11,HARD_CLAY)
Block(1,1,-10,HARD_CLAY)
Block(1,1,-9,HARD_CLAY)
Block(1,1,-8,HARD_CLAY)
Block(1,1,-7,HARD_CLAY)
Block(1,1,-6,HARD_CLAY)
Block(1,1,-5,HARD_CLAY)
Block(1,1,-4,HARD_CLAY)
Block(1,1,-3,HARD_CLAY)
Block(1,1,-2,HARD_CLAY)
Block(1,1,-1,HARD_CLAY)
Block(1,1,0,HARD_CLAY)
Block(1,1,1,HARD_CLAY)
Block(1,1,2,HARD_CLAY)
Block(1,1,3,HARD_CLAY)
Block(1,1,4,HARD_CLAY)
Block(1,1,5,HARD_CLAY)
Block(1,1,6,HARD_CLAY)
Block(1,1,7,HARD_CLAY)
Block(1,2,-10,HARD_CLAY)
Block(1,2,-9,HARD_CLAY)
Block(1,2,-8,HARD_CLAY)
Block(1,2,-7,HARD_CLAY)
Block(1,2,-6,HARD_CLAY)
Block(1,2,-5,HARD_CLAY)
Block(1,2,-4,HARD_CLAY)
Block(1,2,-3,HARD_CLAY)
Block(1,2,-2,HARD_CLAY)
Block(1,2,-1,HARD_CLAY)
Block(1,2,0,HARD_CLAY)
Block(1,2,1,HARD_CLAY)
Block(1,2,2,HARD_CLAY)
Block(1,2,3,HARD_CLAY)
Block(1,2,4,HARD_CLAY)
Block(1,2,5,HARD_CLAY)
Block(1,2,6,HARD_CLAY)
Block(1,3,-10,HARD_CLAY)
Block(1,3,-9,HARD_CLAY)
Block(1,3,-8,HARD_CLAY)
Block(1,3,-7,HARD_CLAY)
Block(1,3,-6,HARD_CLAY)
Block(1,3,-5,HARD_CLAY)
Block(1,3,-4,HARD_CLAY)
Block(1,3,-3,HARD_CLAY)
Block(1,3,-2,HARD_CLAY)
Block(1,3,-1,HARD_CLAY)
Block(1,3,0,HARD_CLAY)
Block(1,3,1,HARD_CLAY)
Block(1,3,2,HARD_CLAY)
Block(1,3,3,HARD_CLAY)
Block(1,3,4,HARD_CLAY)
Block(1,3,5,HARD_CLAY)
Block(1,3,6,HARD_CLAY)
Block(1,4,-10,HARD_CLAY)
Block(1,4,-8,HARD_CLAY)
Block(1,4,-7,HARD_CLAY)
Block(1,4,-6,HARD_CLAY)
Block(1,4,-5,HARD_CLAY)
Block(1,4,-4,HARD_CLAY)
Block(1,4,-3,HARD_CLAY)
Block(1,4,-2,HARD_CLAY)
Block(1,4,-1,HARD_CLAY)
Block(1,4,0,HARD_CLAY)
Block(1,4,1,HARD_CLAY)
Block(1,4,2,HARD_CLAY)
Block(1,4,3,HARD_CLAY)
Block(1,4,4,HARD_CLAY)
Block(1,4,5,HARD_CLAY)
Block(1,4,6,HARD_CLAY)
Block(1,5,-8,HARD_CLAY)
Block(1,5,-7,HARD_CLAY)
Block(1,5,-6,HARD_CLAY)
Block(1,5,-5,HARD_CLAY)
Block(1,5,-4,HARD_CLAY)
Block(1,5,-3,HARD_CLAY)
Block(1,5,-2,HARD_CLAY)
Block(1,5,-1,HARD_CLAY)
Block(1,5,0,HARD_CLAY)
Block(1,5,1,HARD_CLAY)
Block(1,5,2,HARD_CLAY)
Block(1,5,3,HARD_CLAY)
Block(1,5,4,HARD_CLAY)
Block(1,5,5,HARD_CLAY)
Block(1,5,6,HARD_CLAY)
Block(1,6,-8,HARD_CLAY)
Block(1,6,-7,HARD_CLAY)
Block(1,6,-6,HARD_CLAY)
Block(1,6,-5,HARD_CLAY)
Block(1,6,-4,HARD_CLAY)
Block(1,6,-3,HARD_CLAY)
Block(1,6,-2,HARD_CLAY)
Block(1,6,-1,HARD_CLAY)
Block(1,6,0,HARD_CLAY)
Block(1,6,1,HARD_CLAY)
Block(1,6,2,HARD_CLAY)
Block(1,6,3,HARD_CLAY)
Block(1,6,4,HARD_CLAY)
Block(1,6,5,HARD_CLAY)
Block(1,7,-8,HARD_CLAY)
Block(1,7,-7,HARD_CLAY)
Block(1,7,-6,HARD_CLAY)
Block(1,7,-5,HARD_CLAY)
Block(1,7,-4,HARD_CLAY)
Block(1,7,-3,HARD_CLAY)
Block(1,7,-2,HARD_CLAY)
Block(1,7,-1,HARD_CLAY)
Block(1,7,0,HARD_CLAY)
Block(1,7,1,HARD_CLAY)
Block(1,7,2,HARD_CLAY)
Block(1,7,3,HARD_CLAY)
Block(1,7,4,HARD_CLAY)
Block(1,7,5,HARD_CLAY)
Block(1,8,-8,HARD_CLAY)
Block(1,8,-7,HARD_CLAY)
Block(1,8,-4,HARD_CLAY)
Block(1,8,-3,HARD_CLAY)
Block(1,8,-2,HARD_CLAY)
Block(1,8,-1,HARD_CLAY)
Block(1,8,0,HARD_CLAY)
Block(1,8,1,HARD_CLAY)
Block(1,8,2,HARD_CLAY)
Block(1,8,3,HARD_CLAY)
Block(1,8,4,HARD_CLAY)
Block(1,8,5,HARD_CLAY)
Block(1,9,-8,HARD_CLAY)
Block(1,9,-7,HARD_CLAY)
Block(1,9,-4,HARD_CLAY)
Block(1,9,-3,HARD_CLAY)
Block(1,9,-2,HARD_CLAY)
Block(1,9,-1,HARD_CLAY)
Block(1,9,0,HARD_CLAY)
Block(1,9,1,HARD_CLAY)
Block(1,9,2,HARD_CLAY)
Block(1,9,3,HARD_CLAY)
Block(1,9,4,HARD_CLAY)
Block(1,9,5,HARD_CLAY)
Block(1,10,-4,HARD_CLAY)
Block(1,10,-3,HARD_CLAY)
Block(1,10,-2,HARD_CLAY)
Block(1,10,-1,HARD_CLAY)
Block(1,10,0,HARD_CLAY)
Block(1,10,1,HARD_CLAY)
Block(1,10,2,HARD_CLAY)
Block(1,10,3,HARD_CLAY)
Block(1,10,4,HARD_CLAY)
Block(1,10,5,HARD_CLAY)
Block(1,11,-4,HARD_CLAY)
Block(1,11,-3,HARD_CLAY)
Block(1,11,-2,HARD_CLAY)
Block(1,11,-1,HARD_CLAY)
Block(1,11,0,HARD_CLAY)
Block(1,11,1,HARD_CLAY)
Block(1,11,2,HARD_CLAY)
Block(1,11,3,HARD_CLAY)
Block(1,11,4,HARD_CLAY)
Block(1,11,5,HARD_CLAY)
Block(1,12,-3,HARD_CLAY)
Block(1,12,-2,HARD_CLAY)
Block(1,12,-1,HARD_CLAY)
Block(1,12,0,HARD_CLAY)
Block(1,12,1,HARD_CLAY)
Block(1,12,2,HARD_CLAY)
Block(1,12,3,HARD_CLAY)
Block(1,12,4,HARD_CLAY)
Block(1,12,5,HARD_CLAY)
Block(1,13,-3,HARD_CLAY)
Block(1,13,-2,HARD_CLAY)
Block(1,13,-1,HARD_CLAY)
Block(1,13,0,HARD_CLAY)
Block(1,13,1,HARD_CLAY)
Block(1,13,2,HARD_CLAY)
Block(1,13,3,HARD_CLAY)
Block(1,13,4,HARD_CLAY)
Block(1,13,5,HARD_CLAY)
Block(1,14,-3,HARD_CLAY)
Block(1,14,-2,HARD_CLAY)
Block(1,14,-1,HARD_CLAY)
Block(1,14,0,HARD_CLAY)
Block(1,14,1,HARD_CLAY)
Block(1,14,2,HARD_CLAY)
Block(1,14,3,HARD_CLAY)
Block(1,14,4,HARD_CLAY)
Block(1,14,5,HARD_CLAY)
Block(1,15,-3,HARD_CLAY)
Block(1,15,-2,HARD_CLAY)
Block(1,15,-1,HARD_CLAY)
Block(1,15,0,HARD_CLAY)
Block(1,15,1,HARD_CLAY)
Block(1,15,2,HARD_CLAY)
Block(1,15,3,HARD_CLAY)
Block(1,15,4,HARD_CLAY)
Block(1,16,-3,HARD_CLAY)
Block(1,16,-2,HARD_CLAY)
Block(1,16,-1,HARD_CLAY)
Block(1,16,0,HARD_CLAY)
Block(1,16,1,HARD_CLAY)
Block(1,16,2,HARD_CLAY)
Block(1,16,3,HARD_CLAY)
Block(1,16,4,HARD_CLAY)
Block(1,17,-3,HARD_CLAY)
Block(1,17,-2,HARD_CLAY)
Block(1,17,-1,HARD_CLAY)
Block(1,17,0,HARD_CLAY)
Block(1,17,1,HARD_CLAY)
Block(1,17,2,HARD_CLAY)
Block(1,17,3,HARD_CLAY)
Block(1,17,4,HARD_CLAY)
Block(1,18,-2,HARD_CLAY)
Block(1,18,-1,HARD_CLAY)
Block(1,18,0,HARD_CLAY)
Block(1,18,1,HARD_CLAY)
Block(1,18,2,HARD_CLAY)
Block(1,18,3,HARD_CLAY)
Block(1,18,4,HARD_CLAY)
Block(1,19,-2,HARD_CLAY)
Block(1,19,-1,HARD_CLAY)
Block(1,19,0,HARD_CLAY)
Block(1,19,1,HARD_CLAY)
Block(1,19,2,HARD_CLAY)
Block(1,19,3,HARD_CLAY)
Block(1,19,4,HARD_CLAY)
Block(1,20,-2,HARD_CLAY)
Block(1,20,-1,HARD_CLAY)
Block(1,20,0,HARD_CLAY)
Block(1,20,1,HARD_CLAY)
Block(1,20,2,HARD_CLAY)
Block(1,20,3,HARD_CLAY)
Block(1,21,-1,HARD_CLAY)
Block(1,21,0,HARD_CLAY)
Block(1,21,1,HARD_CLAY)
Block(1,21,2,HARD_CLAY)
Block(1,21,3,HARD_CLAY)
Block(1,22,-1,HARD_CLAY)
Block(1,22,0,HARD_CLAY)
Block(1,22,1,HARD_CLAY)
Block(1,22,2,HARD_CLAY)
Block(1,23,-1,HARD_CLAY)
Block(1,23,0,HARD_CLAY)
Block(1,23,1,HARD_CLAY)
Block(1,23,2,HARD_CLAY)
Block(1,24,-1,HARD_CLAY)
Block(1,24,0,HARD_CLAY)
Block(1,24,1,HARD_CLAY)
Block(1,24,2,HARD_CLAY)
Block(1,25,-1,HARD_CLAY)
Block(1,25,0,HARD_CLAY)
Block(1,25,1,HARD_CLAY)
Block(1,25,2,HARD_CLAY)
Block(1,26,-1,HARD_CLAY)
Block(1,26,0,HARD_CLAY)
Block(1,26,1,HARD_CLAY)
Block(1,26,2,HARD_CLAY)
Block(1,27,-1,HARD_CLAY)
Block(1,27,0,HARD_CLAY)
Block(1,27,1,HARD_CLAY)
Block(1,27,2,HARD_CLAY)
Block(1,28,-1,HARD_CLAY)
Block(1,28,2,HARD_CLAY)
Block(1,29,2,HARD_CLAY)
Block(2,0,-13,HARD_CLAY)
Block(2,0,-12,HARD_CLAY)
Block(2,0,-11,HARD_CLAY)
Block(2,0,-10,HARD_CLAY)
Block(2,0,-9,HARD_CLAY)
Block(2,0,-8,HARD_CLAY)
Block(2,0,-7,HARD_CLAY)
Block(2,0,-6,HARD_CLAY)
Block(2,0,-5,HARD_CLAY)
Block(2,0,-4,HARD_CLAY)
Block(2,0,-3,HARD_CLAY)
Block(2,0,-2,HARD_CLAY)
Block(2,0,-1,HARD_CLAY)
Block(2,0,0,HARD_CLAY)
Block(2,0,1,HARD_CLAY)
Block(2,0,2,HARD_CLAY)
Block(2,0,3,HARD_CLAY)
Block(2,0,4,HARD_CLAY)
Block(2,0,5,HARD_CLAY)
Block(2,0,6,HARD_CLAY)
Block(2,0,7,HARD_CLAY)
Block(2,0,8,HARD_CLAY)
Block(2,0,9,HARD_CLAY)
Block(2,1,-13,HARD_CLAY)
Block(2,1,-12,HARD_CLAY)
Block(2,1,-11,HARD_CLAY)
Block(2,1,-10,HARD_CLAY)
Block(2,1,-9,HARD_CLAY)
Block(2,1,-8,HARD_CLAY)
Block(2,1,-7,HARD_CLAY)
Block(2,1,-6,HARD_CLAY)
Block(2,1,-5,HARD_CLAY)
Block(2,1,-4,HARD_CLAY)
Block(2,1,-3,HARD_CLAY)
Block(2,1,-2,HARD_CLAY)
Block(2,1,-1,HARD_CLAY)
Block(2,1,0,HARD_CLAY)
Block(2,1,1,HARD_CLAY)
Block(2,1,2,HARD_CLAY)
Block(2,1,3,HARD_CLAY)
Block(2,1,4,HARD_CLAY)
Block(2,1,5,HARD_CLAY)
Block(2,1,6,HARD_CLAY)
Block(2,1,7,HARD_CLAY)
Block(2,1,8,HARD_CLAY)
Block(2,2,-13,HARD_CLAY)
Block(2,2,-12,HARD_CLAY)
Block(2,2,-11,HARD_CLAY)
Block(2,2,-10,HARD_CLAY)
Block(2,2,-9,HARD_CLAY)
Block(2,2,-8,HARD_CLAY)
Block(2,2,-7,HARD_CLAY)
Block(2,2,-6,HARD_CLAY)
Block(2,2,-5,HARD_CLAY)
Block(2,2,-4,HARD_CLAY)
Block(2,2,-3,HARD_CLAY)
Block(2,2,-2,HARD_CLAY)
Block(2,2,-1,HARD_CLAY)
Block(2,2,0,HARD_CLAY)
Block(2,2,1,HARD_CLAY)
Block(2,2,2,HARD_CLAY)
Block(2,2,3,HARD_CLAY)
Block(2,2,4,HARD_CLAY)
Block(2,2,5,HARD_CLAY)
Block(2,2,6,HARD_CLAY)
Block(2,2,7,HARD_CLAY)
Block(2,2,8,HARD_CLAY)
Block(2,3,-12,HARD_CLAY)
Block(2,3,-11,HARD_CLAY)
Block(2,3,-10,HARD_CLAY)
Block(2,3,-9,HARD_CLAY)
Block(2,3,-8,HARD_CLAY)
Block(2,3,-7,HARD_CLAY)
Block(2,3,-6,HARD_CLAY)
Block(2,3,-5,HARD_CLAY)
Block(2,3,-4,HARD_CLAY)
Block(2,3,-3,HARD_CLAY)
Block(2,3,-2,HARD_CLAY)
Block(2,3,-1,HARD_CLAY)
Block(2,3,0,HARD_CLAY)
Block(2,3,1,HARD_CLAY)
Block(2,3,2,HARD_CLAY)
Block(2,3,3,HARD_CLAY)
Block(2,3,4,HARD_CLAY)
Block(2,3,5,HARD_CLAY)
Block(2,3,6,HARD_CLAY)
Block(2,3,7,HARD_CLAY)
Block(2,3,8,HARD_CLAY)
Block(2,4,-9,HARD_CLAY)
Block(2,4,-8,HARD_CLAY)
Block(2,4,-7,HARD_CLAY)
Block(2,4,-6,HARD_CLAY)
Block(2,4,-5,HARD_CLAY)
Block(2,4,-4,HARD_CLAY)
Block(2,4,-3,HARD_CLAY)
Block(2,4,-2,HARD_CLAY)
Block(2,4,-1,HARD_CLAY)
Block(2,4,0,HARD_CLAY)
Block(2,4,1,HARD_CLAY)
Block(2,4,2,HARD_CLAY)
Block(2,4,3,HARD_CLAY)
Block(2,4,4,HARD_CLAY)
Block(2,4,5,HARD_CLAY)
Block(2,4,6,HARD_CLAY)
Block(2,4,7,HARD_CLAY)
Block(2,5,-9,HARD_CLAY)
Block(2,5,-8,HARD_CLAY)
Block(2,5,-7,HARD_CLAY)
Block(2,5,-6,HARD_CLAY)
Block(2,5,-5,HARD_CLAY)
Block(2,5,-4,HARD_CLAY)
Block(2,5,-3,HARD_CLAY)
Block(2,5,-2,HARD_CLAY)
Block(2,5,-1,HARD_CLAY)
Block(2,5,0,HARD_CLAY)
Block(2,5,1,HARD_CLAY)
Block(2,5,2,HARD_CLAY)
Block(2,5,3,HARD_CLAY)
Block(2,5,4,HARD_CLAY)
Block(2,5,5,HARD_CLAY)
Block(2,5,6,HARD_CLAY)
Block(2,6,-8,HARD_CLAY)
Block(2,6,-7,HARD_CLAY)
Block(2,6,-5,HARD_CLAY)
Block(2,6,-4,HARD_CLAY)
Block(2,6,-3,HARD_CLAY)
Block(2,6,-2,HARD_CLAY)
Block(2,6,-1,HARD_CLAY)
Block(2,6,0,HARD_CLAY)
Block(2,6,1,HARD_CLAY)
Block(2,6,2,HARD_CLAY)
Block(2,6,3,HARD_CLAY)
Block(2,6,4,HARD_CLAY)
Block(2,6,5,HARD_CLAY)
Block(2,6,6,HARD_CLAY)
Block(2,7,-8,HARD_CLAY)
Block(2,7,-7,HARD_CLAY)
Block(2,7,-4,HARD_CLAY)
Block(2,7,-3,HARD_CLAY)
Block(2,7,-2,HARD_CLAY)
Block(2,7,-1,HARD_CLAY)
Block(2,7,0,HARD_CLAY)
Block(2,7,1,HARD_CLAY)
Block(2,7,2,HARD_CLAY)
Block(2,7,3,HARD_CLAY)
Block(2,7,4,HARD_CLAY)
Block(2,7,5,HARD_CLAY)
Block(2,7,6,HARD_CLAY)
Block(2,8,-8,HARD_CLAY)
Block(2,8,-4,HARD_CLAY)
Block(2,8,-3,HARD_CLAY)
Block(2,8,-2,HARD_CLAY)
Block(2,8,-1,HARD_CLAY)
Block(2,8,0,HARD_CLAY)
Block(2,8,1,HARD_CLAY)
Block(2,8,2,HARD_CLAY)
Block(2,8,3,HARD_CLAY)
Block(2,8,4,HARD_CLAY)
Block(2,8,5,HARD_CLAY)
Block(2,9,-8,HARD_CLAY)
Block(2,9,-4,HARD_CLAY)
Block(2,9,-3,HARD_CLAY)
Block(2,9,-2,HARD_CLAY)
Block(2,9,-1,HARD_CLAY)
Block(2,9,0,HARD_CLAY)
Block(2,9,1,HARD_CLAY)
Block(2,9,2,HARD_CLAY)
Block(2,9,3,HARD_CLAY)
Block(2,9,4,HARD_CLAY)
Block(2,9,5,HARD_CLAY)
Block(2,10,-8,HARD_CLAY)
Block(2,10,-4,HARD_CLAY)
Block(2,10,-3,HARD_CLAY)
Block(2,10,-2,HARD_CLAY)
Block(2,10,-1,HARD_CLAY)
Block(2,10,0,HARD_CLAY)
Block(2,10,1,HARD_CLAY)
Block(2,10,2,HARD_CLAY)
Block(2,10,3,HARD_CLAY)
Block(2,10,4,HARD_CLAY)
Block(2,10,5,HARD_CLAY)
Block(2,11,-8,HARD_CLAY)
Block(2,11,-4,HARD_CLAY)
Block(2,11,-3,HARD_CLAY)
Block(2,11,-2,HARD_CLAY)
Block(2,11,-1,HARD_CLAY)
Block(2,11,0,HARD_CLAY)
Block(2,11,1,HARD_CLAY)
Block(2,11,2,HARD_CLAY)
Block(2,11,3,HARD_CLAY)
Block(2,11,4,HARD_CLAY)
Block(2,11,5,HARD_CLAY)
Block(2,12,-4,HARD_CLAY)
Block(2,12,-3,HARD_CLAY)
Block(2,12,-2,HARD_CLAY)
Block(2,12,-1,HARD_CLAY)
Block(2,12,0,HARD_CLAY)
Block(2,12,1,HARD_CLAY)
Block(2,12,2,HARD_CLAY)
Block(2,12,3,HARD_CLAY)
Block(2,12,4,HARD_CLAY)
Block(2,13,-3,HARD_CLAY)
Block(2,13,-2,HARD_CLAY)
Block(2,13,-1,HARD_CLAY)
Block(2,13,0,HARD_CLAY)
Block(2,13,1,HARD_CLAY)
Block(2,13,2,HARD_CLAY)
Block(2,13,3,HARD_CLAY)
Block(2,13,4,HARD_CLAY)
Block(2,14,-3,HARD_CLAY)
Block(2,14,-2,HARD_CLAY)
Block(2,14,-1,HARD_CLAY)
Block(2,14,0,HARD_CLAY)
Block(2,14,1,HARD_CLAY)
Block(2,14,2,HARD_CLAY)
Block(2,14,3,HARD_CLAY)
Block(2,14,4,HARD_CLAY)
Block(2,15,-3,HARD_CLAY)
Block(2,15,-2,HARD_CLAY)
Block(2,15,-1,HARD_CLAY)
Block(2,15,0,HARD_CLAY)
Block(2,15,1,HARD_CLAY)
Block(2,15,2,HARD_CLAY)
Block(2,15,3,HARD_CLAY)
Block(2,15,4,HARD_CLAY)
Block(2,16,-3,HARD_CLAY)
Block(2,16,-2,HARD_CLAY)
Block(2,16,-1,HARD_CLAY)
Block(2,16,0,HARD_CLAY)
Block(2,16,1,HARD_CLAY)
Block(2,16,2,HARD_CLAY)
Block(2,16,3,HARD_CLAY)
Block(2,16,4,HARD_CLAY)
Block(2,17,-3,HARD_CLAY)
Block(2,17,-2,HARD_CLAY)
Block(2,17,-1,HARD_CLAY)
Block(2,17,0,HARD_CLAY)
Block(2,17,1,HARD_CLAY)
Block(2,17,2,HARD_CLAY)
Block(2,17,3,HARD_CLAY)
Block(2,17,4,HARD_CLAY)
Block(2,18,-3,HARD_CLAY)
Block(2,18,-2,HARD_CLAY)
Block(2,18,-1,HARD_CLAY)
Block(2,18,0,HARD_CLAY)
Block(2,18,1,HARD_CLAY)
Block(2,18,2,HARD_CLAY)
Block(2,18,3,HARD_CLAY)
Block(2,18,4,HARD_CLAY)
Block(2,19,-3,HARD_CLAY)
Block(2,19,-2,HARD_CLAY)
Block(2,19,-1,HARD_CLAY)
Block(2,19,0,HARD_CLAY)
Block(2,19,1,HARD_CLAY)
Block(2,19,2,HARD_CLAY)
Block(2,19,3,HARD_CLAY)
Block(2,19,4,HARD_CLAY)
Block(2,20,-2,HARD_CLAY)
Block(2,20,-1,HARD_CLAY)
Block(2,20,0,HARD_CLAY)
Block(2,20,1,HARD_CLAY)
Block(2,20,2,HARD_CLAY)
Block(2,20,3,HARD_CLAY)
Block(2,20,4,HARD_CLAY)
Block(2,21,-2,HARD_CLAY)
Block(2,21,-1,HARD_CLAY)
Block(2,21,0,HARD_CLAY)
Block(2,21,1,HARD_CLAY)
Block(2,21,2,HARD_CLAY)
Block(2,21,3,HARD_CLAY)
Block(2,21,4,HARD_CLAY)
Block(2,22,-2,HARD_CLAY)
Block(2,22,-1,HARD_CLAY)
Block(2,22,0,HARD_CLAY)
Block(2,22,1,HARD_CLAY)
Block(2,22,2,HARD_CLAY)
Block(2,22,3,HARD_CLAY)
Block(2,23,-2,HARD_CLAY)
Block(2,23,-1,HARD_CLAY)
Block(2,23,0,HARD_CLAY)
Block(2,23,1,HARD_CLAY)
Block(2,23,2,HARD_CLAY)
Block(2,23,3,HARD_CLAY)
Block(2,24,-2,HARD_CLAY)
Block(2,24,-1,HARD_CLAY)
Block(2,24,0,HARD_CLAY)
Block(2,24,1,HARD_CLAY)
Block(2,24,2,HARD_CLAY)
Block(2,24,3,HARD_CLAY)
Block(2,25,-2,HARD_CLAY)
Block(2,25,-1,HARD_CLAY)
Block(2,26,-2,HARD_CLAY)
Block(2,27,-2,HARD_CLAY)
Block(3,0,-13,HARD_CLAY)
Block(3,0,-12,HARD_CLAY)
Block(3,0,-11,HARD_CLAY)
Block(3,0,-10,HARD_CLAY)
Block(3,0,-9,HARD_CLAY)
Block(3,0,-8,HARD_CLAY)
Block(3,0,-7,HARD_CLAY)
Block(3,0,-6,HARD_CLAY)
Block(3,0,-5,HARD_CLAY)
Block(3,0,-4,HARD_CLAY)
Block(3,0,-3,HARD_CLAY)
Block(3,0,-2,HARD_CLAY)
Block(3,0,-1,HARD_CLAY)
Block(3,0,0,HARD_CLAY)
Block(3,0,1,HARD_CLAY)
Block(3,0,2,HARD_CLAY)
Block(3,0,3,HARD_CLAY)
Block(3,0,4,HARD_CLAY)
Block(3,0,5,HARD_CLAY)
Block(3,0,6,HARD_CLAY)
Block(3,0,7,HARD_CLAY)
Block(3,0,8,HARD_CLAY)
Block(3,0,9,HARD_CLAY)
Block(3,1,-12,HARD_CLAY)
Block(3,1,-11,HARD_CLAY)
Block(3,1,-10,HARD_CLAY)
Block(3,1,-9,HARD_CLAY)
Block(3,1,-8,HARD_CLAY)
Block(3,1,-7,HARD_CLAY)
Block(3,1,-6,HARD_CLAY)
Block(3,1,-5,HARD_CLAY)
Block(3,1,-4,HARD_CLAY)
Block(3,1,-3,HARD_CLAY)
Block(3,1,-2,HARD_CLAY)
Block(3,1,-1,HARD_CLAY)
Block(3,1,0,HARD_CLAY)
Block(3,1,1,HARD_CLAY)
Block(3,1,2,HARD_CLAY)
Block(3,1,3,HARD_CLAY)
Block(3,1,4,HARD_CLAY)
Block(3,1,5,HARD_CLAY)
Block(3,1,6,HARD_CLAY)
Block(3,1,7,HARD_CLAY)
Block(3,1,8,HARD_CLAY)
Block(3,2,-12,HARD_CLAY)
Block(3,2,-11,HARD_CLAY)
Block(3,2,-10,HARD_CLAY)
Block(3,2,-9,HARD_CLAY)
Block(3,2,-8,HARD_CLAY)
Block(3,2,-7,HARD_CLAY)
Block(3,2,-6,HARD_CLAY)
Block(3,2,-5,HARD_CLAY)
Block(3,2,-4,HARD_CLAY)
Block(3,2,-3,HARD_CLAY)
Block(3,2,-2,HARD_CLAY)
Block(3,2,-1,HARD_CLAY)
Block(3,2,0,HARD_CLAY)
Block(3,2,1,HARD_CLAY)
Block(3,2,2,HARD_CLAY)
Block(3,2,3,HARD_CLAY)
Block(3,2,4,HARD_CLAY)
Block(3,2,5,HARD_CLAY)
Block(3,2,6,HARD_CLAY)
Block(3,2,7,HARD_CLAY)
Block(3,2,8,HARD_CLAY)
Block(3,3,-11,HARD_CLAY)
Block(3,3,-10,HARD_CLAY)
Block(3,3,-9,HARD_CLAY)
Block(3,3,-8,HARD_CLAY)
Block(3,3,-7,HARD_CLAY)
Block(3,3,-6,HARD_CLAY)
Block(3,3,-5,HARD_CLAY)
Block(3,3,-4,HARD_CLAY)
Block(3,3,-3,HARD_CLAY)
Block(3,3,-2,HARD_CLAY)
Block(3,3,-1,HARD_CLAY)
Block(3,3,0,HARD_CLAY)
Block(3,3,1,HARD_CLAY)
Block(3,3,2,HARD_CLAY)
Block(3,3,3,HARD_CLAY)
Block(3,3,4,HARD_CLAY)
Block(3,3,5,HARD_CLAY)
Block(3,3,6,HARD_CLAY)
Block(3,3,7,HARD_CLAY)
Block(3,3,8,HARD_CLAY)
Block(3,4,-11,HARD_CLAY)
Block(3,4,-10,HARD_CLAY)
Block(3,4,-9,HARD_CLAY)
Block(3,4,-8,HARD_CLAY)
Block(3,4,-7,HARD_CLAY)
Block(3,4,-6,HARD_CLAY)
Block(3,4,-5,HARD_CLAY)
Block(3,4,-4,HARD_CLAY)
Block(3,4,-3,HARD_CLAY)
Block(3,4,-2,HARD_CLAY)
Block(3,4,-1,HARD_CLAY)
Block(3,4,0,HARD_CLAY)
Block(3,4,1,HARD_CLAY)
Block(3,4,2,HARD_CLAY)
Block(3,4,3,HARD_CLAY)
Block(3,4,4,HARD_CLAY)
Block(3,4,5,HARD_CLAY)
Block(3,4,6,HARD_CLAY)
Block(3,4,7,HARD_CLAY)
Block(3,4,8,HARD_CLAY)
Block(3,5,-9,HARD_CLAY)
Block(3,5,-8,HARD_CLAY)
Block(3,5,-7,HARD_CLAY)
Block(3,5,-6,HARD_CLAY)
Block(3,5,-5,HARD_CLAY)
Block(3,5,-4,HARD_CLAY)
Block(3,5,-3,HARD_CLAY)
Block(3,5,-2,HARD_CLAY)
Block(3,5,-1,HARD_CLAY)
Block(3,5,0,HARD_CLAY)
Block(3,5,1,HARD_CLAY)
Block(3,5,2,HARD_CLAY)
Block(3,5,3,HARD_CLAY)
Block(3,5,4,HARD_CLAY)
Block(3,5,5,HARD_CLAY)
Block(3,5,6,HARD_CLAY)
Block(3,5,7,HARD_CLAY)
Block(3,6,-9,HARD_CLAY)
Block(3,6,-8,HARD_CLAY)
Block(3,6,-7,HARD_CLAY)
Block(3,6,-6,HARD_CLAY)
Block(3,6,-5,HARD_CLAY)
Block(3,6,-4,HARD_CLAY)
Block(3,6,-3,HARD_CLAY)
Block(3,6,-2,HARD_CLAY)
Block(3,6,-1,HARD_CLAY)
Block(3,6,0,HARD_CLAY)
Block(3,6,1,HARD_CLAY)
Block(3,6,2,HARD_CLAY)
Block(3,6,3,HARD_CLAY)
Block(3,6,4,HARD_CLAY)
Block(3,6,5,HARD_CLAY)
Block(3,6,6,HARD_CLAY)
Block(3,7,-8,HARD_CLAY)
Block(3,7,-7,HARD_CLAY)
Block(3,7,-6,HARD_CLAY)
Block(3,7,-5,HARD_CLAY)
Block(3,7,-4,HARD_CLAY)
Block(3,7,-3,HARD_CLAY)
Block(3,7,-2,HARD_CLAY)
Block(3,7,-1,HARD_CLAY)
Block(3,7,0,HARD_CLAY)
Block(3,7,1,HARD_CLAY)
Block(3,7,2,HARD_CLAY)
Block(3,7,3,HARD_CLAY)
Block(3,7,4,HARD_CLAY)
Block(3,7,5,HARD_CLAY)
Block(3,7,6,HARD_CLAY)
Block(3,8,-7,HARD_CLAY)
Block(3,8,-6,HARD_CLAY)
Block(3,8,-5,HARD_CLAY)
Block(3,8,-4,HARD_CLAY)
Block(3,8,-3,HARD_CLAY)
Block(3,8,-2,HARD_CLAY)
Block(3,8,-1,HARD_CLAY)
Block(3,8,0,HARD_CLAY)
Block(3,8,1,HARD_CLAY)
Block(3,8,2,HARD_CLAY)
Block(3,8,3,HARD_CLAY)
Block(3,8,4,HARD_CLAY)
Block(3,8,5,HARD_CLAY)
Block(3,8,6,HARD_CLAY)
Block(3,9,-7,HARD_CLAY)
Block(3,9,-4,HARD_CLAY)
Block(3,9,-3,HARD_CLAY)
Block(3,9,-2,HARD_CLAY)
Block(3,9,-1,HARD_CLAY)
Block(3,9,0,HARD_CLAY)
Block(3,9,1,HARD_CLAY)
Block(3,9,2,HARD_CLAY)
Block(3,9,3,HARD_CLAY)
Block(3,9,4,HARD_CLAY)
Block(3,9,5,HARD_CLAY)
Block(3,10,-4,HARD_CLAY)
Block(3,10,-3,HARD_CLAY)
Block(3,10,-2,HARD_CLAY)
Block(3,10,-1,HARD_CLAY)
Block(3,10,0,HARD_CLAY)
Block(3,10,1,HARD_CLAY)
Block(3,10,2,HARD_CLAY)
Block(3,10,3,HARD_CLAY)
Block(3,10,4,HARD_CLAY)
Block(3,11,-4,HARD_CLAY)
Block(3,11,-3,HARD_CLAY)
Block(3,11,-2,HARD_CLAY)
Block(3,11,-1,HARD_CLAY)
Block(3,11,0,HARD_CLAY)
Block(3,11,1,HARD_CLAY)
Block(3,11,2,HARD_CLAY)
Block(3,11,3,HARD_CLAY)
Block(3,11,4,HARD_CLAY)
Block(3,12,-4,HARD_CLAY)
Block(3,12,-3,HARD_CLAY)
Block(3,12,-2,HARD_CLAY)
Block(3,12,-1,HARD_CLAY)
Block(3,12,0,HARD_CLAY)
Block(3,12,1,HARD_CLAY)
Block(3,12,2,HARD_CLAY)
Block(3,12,3,HARD_CLAY)
Block(3,12,4,HARD_CLAY)
Block(3,13,-4,HARD_CLAY)
Block(3,13,-3,HARD_CLAY)
Block(3,13,-2,HARD_CLAY)
Block(3,13,-1,HARD_CLAY)
Block(3,13,0,HARD_CLAY)
Block(3,13,1,HARD_CLAY)
Block(3,13,2,HARD_CLAY)
Block(3,13,3,HARD_CLAY)
Block(3,13,4,HARD_CLAY)
Block(3,14,-4,HARD_CLAY)
Block(3,14,-3,HARD_CLAY)
Block(3,14,-2,HARD_CLAY)
Block(3,14,-1,HARD_CLAY)
Block(3,14,0,HARD_CLAY)
Block(3,14,1,HARD_CLAY)
Block(3,14,2,HARD_CLAY)
Block(3,14,3,HARD_CLAY)
Block(3,14,4,HARD_CLAY)
Block(3,15,-4,HARD_CLAY)
Block(3,15,-3,HARD_CLAY)
Block(3,15,-2,HARD_CLAY)
Block(3,15,-1,HARD_CLAY)
Block(3,15,0,HARD_CLAY)
Block(3,15,1,HARD_CLAY)
Block(3,15,2,HARD_CLAY)
Block(3,15,3,HARD_CLAY)
Block(3,15,4,HARD_CLAY)
Block(3,16,-4,HARD_CLAY)
Block(3,16,-3,HARD_CLAY)
Block(3,16,-2,HARD_CLAY)
Block(3,16,-1,HARD_CLAY)
Block(3,16,0,HARD_CLAY)
Block(3,16,1,HARD_CLAY)
Block(3,16,2,HARD_CLAY)
Block(3,16,3,HARD_CLAY)
Block(3,17,-4,HARD_CLAY)
Block(3,17,-3,HARD_CLAY)
Block(3,17,-2,HARD_CLAY)
Block(3,17,-1,HARD_CLAY)
Block(3,17,1,HARD_CLAY)
Block(3,17,2,HARD_CLAY)
Block(3,17,3,HARD_CLAY)
Block(3,18,-4,HARD_CLAY)
Block(3,18,-3,HARD_CLAY)
Block(3,18,-2,HARD_CLAY)
Block(3,18,-1,HARD_CLAY)
Block(3,18,1,HARD_CLAY)
Block(3,18,2,HARD_CLAY)
Block(3,18,3,HARD_CLAY)
Block(3,19,-3,HARD_CLAY)
Block(3,19,-2,HARD_CLAY)
Block(3,19,1,HARD_CLAY)
Block(3,19,2,HARD_CLAY)
Block(3,19,3,HARD_CLAY)
Block(3,20,-3,HARD_CLAY)
Block(3,20,-2,HARD_CLAY)
Block(3,20,1,HARD_CLAY)
Block(3,20,2,HARD_CLAY)
Block(3,20,3,HARD_CLAY)
Block(3,21,-3,HARD_CLAY)
Block(3,21,-2,HARD_CLAY)
Block(3,21,1,HARD_CLAY)
Block(3,21,2,HARD_CLAY)
Block(3,21,3,HARD_CLAY)
Block(3,22,1,HARD_CLAY)
Block(3,22,2,HARD_CLAY)
Block(3,22,3,HARD_CLAY)
Block(3,23,1,HARD_CLAY)
Block(3,23,2,HARD_CLAY)
Block(3,24,2,HARD_CLAY)
Block(3,25,2,HARD_CLAY)
Block(3,26,2,HARD_CLAY)
Block(3,27,2,HARD_CLAY)
Block(3,28,2,HARD_CLAY)
Block(4,0,-15,HARD_CLAY)
Block(4,0,-14,HARD_CLAY)
Block(4,0,-13,HARD_CLAY)
Block(4,0,-12,HARD_CLAY)
Block(4,0,-11,HARD_CLAY)
Block(4,0,-10,HARD_CLAY)
Block(4,0,-9,HARD_CLAY)
Block(4,0,-8,HARD_CLAY)
Block(4,0,-7,HARD_CLAY)
Block(4,0,-6,HARD_CLAY)
Block(4,0,-5,HARD_CLAY)
Block(4,0,-4,HARD_CLAY)
Block(4,0,-3,HARD_CLAY)
Block(4,0,-2,HARD_CLAY)
Block(4,0,-1,HARD_CLAY)
Block(4,0,0,HARD_CLAY)
Block(4,0,1,HARD_CLAY)
Block(4,0,2,HARD_CLAY)
Block(4,0,3,HARD_CLAY)
Block(4,0,4,HARD_CLAY)
Block(4,0,5,HARD_CLAY)
Block(4,0,6,HARD_CLAY)
Block(4,0,7,HARD_CLAY)
Block(4,0,8,HARD_CLAY)
Block(4,0,9,HARD_CLAY)
Block(4,1,-14,HARD_CLAY)
Block(4,1,-13,HARD_CLAY)
Block(4,1,-12,HARD_CLAY)
Block(4,1,-11,HARD_CLAY)
Block(4,1,-10,HARD_CLAY)
Block(4,1,-9,HARD_CLAY)
Block(4,1,-8,HARD_CLAY)
Block(4,1,-7,HARD_CLAY)
Block(4,1,-6,HARD_CLAY)
Block(4,1,-5,HARD_CLAY)
Block(4,1,-4,HARD_CLAY)
Block(4,1,-3,HARD_CLAY)
Block(4,1,-2,HARD_CLAY)
Block(4,1,-1,HARD_CLAY)
Block(4,1,0,HARD_CLAY)
Block(4,1,1,HARD_CLAY)
Block(4,1,2,HARD_CLAY)
Block(4,1,3,HARD_CLAY)
Block(4,1,4,HARD_CLAY)
Block(4,1,5,HARD_CLAY)
Block(4,1,6,HARD_CLAY)
Block(4,1,7,HARD_CLAY)
Block(4,1,8,HARD_CLAY)
Block(4,2,-14,HARD_CLAY)
Block(4,2,-13,HARD_CLAY)
Block(4,2,-12,HARD_CLAY)
Block(4,2,-11,HARD_CLAY)
Block(4,2,-10,HARD_CLAY)
Block(4,2,-9,HARD_CLAY)
Block(4,2,-8,HARD_CLAY)
Block(4,2,-7,HARD_CLAY)
Block(4,2,-6,HARD_CLAY)
Block(4,2,-5,HARD_CLAY)
Block(4,2,-4,HARD_CLAY)
Block(4,2,-3,HARD_CLAY)
Block(4,2,-2,HARD_CLAY)
Block(4,2,-1,HARD_CLAY)
Block(4,2,0,HARD_CLAY)
Block(4,2,1,HARD_CLAY)
Block(4,2,2,HARD_CLAY)
Block(4,2,3,HARD_CLAY)
Block(4,2,4,HARD_CLAY)
Block(4,2,5,HARD_CLAY)
Block(4,2,6,HARD_CLAY)
Block(4,2,7,HARD_CLAY)
Block(4,2,8,HARD_CLAY)
Block(4,3,-14,HARD_CLAY)
Block(4,3,-13,HARD_CLAY)
Block(4,3,-12,HARD_CLAY)
Block(4,3,-11,HARD_CLAY)
Block(4,3,-10,HARD_CLAY)
Block(4,3,-9,HARD_CLAY)
Block(4,3,-8,HARD_CLAY)
Block(4,3,-7,HARD_CLAY)
Block(4,3,-6,HARD_CLAY)
Block(4,3,-5,HARD_CLAY)
Block(4,3,-4,HARD_CLAY)
Block(4,3,-3,HARD_CLAY)
Block(4,3,-2,HARD_CLAY)
Block(4,3,-1,HARD_CLAY)
Block(4,3,0,HARD_CLAY)
Block(4,3,1,HARD_CLAY)
Block(4,3,2,HARD_CLAY)
Block(4,3,3,HARD_CLAY)
Block(4,3,4,HARD_CLAY)
Block(4,3,5,HARD_CLAY)
Block(4,3,6,HARD_CLAY)
Block(4,3,7,HARD_CLAY)
Block(4,3,8,HARD_CLAY)
Block(4,4,-12,HARD_CLAY)
Block(4,4,-11,HARD_CLAY)
Block(4,4,-10,HARD_CLAY)
Block(4,4,-9,HARD_CLAY)
Block(4,4,-8,HARD_CLAY)
Block(4,4,-7,HARD_CLAY)
Block(4,4,-6,HARD_CLAY)
Block(4,4,-5,HARD_CLAY)
Block(4,4,-4,HARD_CLAY)
Block(4,4,-3,HARD_CLAY)
Block(4,4,-2,HARD_CLAY)
Block(4,4,-1,HARD_CLAY)
Block(4,4,0,HARD_CLAY)
Block(4,4,1,HARD_CLAY)
Block(4,4,2,HARD_CLAY)
Block(4,4,3,HARD_CLAY)
Block(4,4,4,HARD_CLAY)
Block(4,4,5,HARD_CLAY)
Block(4,4,6,HARD_CLAY)
Block(4,4,7,HARD_CLAY)
Block(4,5,-9,HARD_CLAY)
Block(4,5,-8,HARD_CLAY)
Block(4,5,-7,HARD_CLAY)
Block(4,5,-6,HARD_CLAY)
Block(4,5,-5,HARD_CLAY)
Block(4,5,-4,HARD_CLAY)
Block(4,5,-3,HARD_CLAY)
Block(4,5,-2,HARD_CLAY)
Block(4,5,-1,HARD_CLAY)
Block(4,5,0,HARD_CLAY)
Block(4,5,1,HARD_CLAY)
Block(4,5,2,HARD_CLAY)
Block(4,5,3,HARD_CLAY)
Block(4,5,4,HARD_CLAY)
Block(4,5,5,HARD_CLAY)
Block(4,5,6,HARD_CLAY)
Block(4,6,-9,HARD_CLAY)
Block(4,6,-8,HARD_CLAY)
Block(4,6,-7,HARD_CLAY)
Block(4,6,-6,HARD_CLAY)
Block(4,6,-5,HARD_CLAY)
Block(4,6,-4,HARD_CLAY)
Block(4,6,-3,HARD_CLAY)
Block(4,6,-2,HARD_CLAY)
Block(4,6,-1,HARD_CLAY)
Block(4,6,0,HARD_CLAY)
Block(4,6,1,HARD_CLAY)
Block(4,6,2,HARD_CLAY)
Block(4,6,3,HARD_CLAY)
Block(4,6,4,HARD_CLAY)
Block(4,6,5,HARD_CLAY)
Block(4,6,6,HARD_CLAY)
Block(4,7,-9,HARD_CLAY)
Block(4,7,-8,HARD_CLAY)
Block(4,7,-7,HARD_CLAY)
Block(4,7,-6,HARD_CLAY)
Block(4,7,-5,HARD_CLAY)
Block(4,7,-4,HARD_CLAY)
Block(4,7,-3,HARD_CLAY)
Block(4,7,-2,HARD_CLAY)
Block(4,7,-1,HARD_CLAY)
Block(4,7,0,HARD_CLAY)
Block(4,7,1,HARD_CLAY)
Block(4,7,2,HARD_CLAY)
Block(4,7,3,HARD_CLAY)
Block(4,7,4,HARD_CLAY)
Block(4,7,5,HARD_CLAY)
Block(4,8,-9,HARD_CLAY)
Block(4,8,-8,HARD_CLAY)
Block(4,8,-7,HARD_CLAY)
Block(4,8,-6,HARD_CLAY)
Block(4,8,-5,HARD_CLAY)
Block(4,8,-4,HARD_CLAY)
Block(4,8,-3,HARD_CLAY)
Block(4,8,-2,HARD_CLAY)
Block(4,8,-1,HARD_CLAY)
Block(4,8,0,HARD_CLAY)
Block(4,8,1,HARD_CLAY)
Block(4,8,2,HARD_CLAY)
Block(4,8,3,HARD_CLAY)
Block(4,8,4,HARD_CLAY)
Block(4,8,5,HARD_CLAY)
Block(4,9,-8,HARD_CLAY)
Block(4,9,-7,HARD_CLAY)
Block(4,9,-6,HARD_CLAY)
Block(4,9,-5,HARD_CLAY)
Block(4,9,-4,HARD_CLAY)
Block(4,9,-3,HARD_CLAY)
Block(4,9,-2,HARD_CLAY)
Block(4,9,-1,HARD_CLAY)
Block(4,9,0,HARD_CLAY)
Block(4,9,1,HARD_CLAY)
Block(4,9,2,HARD_CLAY)
Block(4,9,3,HARD_CLAY)
Block(4,9,4,HARD_CLAY)
Block(4,9,5,HARD_CLAY)
Block(4,10,-8,HARD_CLAY)
Block(4,10,-7,HARD_CLAY)
Block(4,10,-6,HARD_CLAY)
Block(4,10,-5,HARD_CLAY)
Block(4,10,-4,HARD_CLAY)
Block(4,10,-3,HARD_CLAY)
Block(4,10,-2,HARD_CLAY)
Block(4,10,-1,HARD_CLAY)
Block(4,10,0,HARD_CLAY)
Block(4,10,1,HARD_CLAY)
Block(4,10,2,HARD_CLAY)
Block(4,10,3,HARD_CLAY)
Block(4,10,4,HARD_CLAY)
Block(4,10,5,HARD_CLAY)
Block(4,11,-8,HARD_CLAY)
Block(4,11,-7,HARD_CLAY)
Block(4,11,-5,HARD_CLAY)
Block(4,11,-4,HARD_CLAY)
Block(4,11,-3,HARD_CLAY)
Block(4,11,-2,HARD_CLAY)
Block(4,11,-1,HARD_CLAY)
Block(4,11,0,HARD_CLAY)
Block(4,11,1,HARD_CLAY)
Block(4,11,2,HARD_CLAY)
Block(4,11,3,HARD_CLAY)
Block(4,11,4,HARD_CLAY)
Block(4,12,-8,HARD_CLAY)
Block(4,12,-5,HARD_CLAY)
Block(4,12,-4,HARD_CLAY)
Block(4,12,-3,HARD_CLAY)
Block(4,12,-2,HARD_CLAY)
Block(4,12,-1,HARD_CLAY)
Block(4,12,0,HARD_CLAY)
Block(4,12,1,HARD_CLAY)
Block(4,12,2,HARD_CLAY)
Block(4,12,3,HARD_CLAY)
Block(4,12,4,HARD_CLAY)
Block(4,13,-8,HARD_CLAY)
Block(4,13,-4,HARD_CLAY)
Block(4,13,-3,HARD_CLAY)
Block(4,13,-2,HARD_CLAY)
Block(4,13,-1,HARD_CLAY)
Block(4,13,0,HARD_CLAY)
Block(4,13,1,HARD_CLAY)
Block(4,13,2,HARD_CLAY)
Block(4,13,3,HARD_CLAY)
Block(4,13,4,HARD_CLAY)
Block(4,14,-8,HARD_CLAY)
Block(4,14,-4,HARD_CLAY)
Block(4,14,-3,HARD_CLAY)
Block(4,14,-2,HARD_CLAY)
Block(4,14,1,HARD_CLAY)
Block(4,14,2,HARD_CLAY)
Block(4,14,3,HARD_CLAY)
Block(4,14,4,HARD_CLAY)
Block(4,15,-4,HARD_CLAY)
Block(4,15,-3,HARD_CLAY)
Block(4,15,-2,HARD_CLAY)
Block(4,15,1,HARD_CLAY)
Block(4,15,2,HARD_CLAY)
Block(4,15,3,HARD_CLAY)
Block(4,15,4,HARD_CLAY)
Block(4,16,-4,HARD_CLAY)
Block(4,16,-3,HARD_CLAY)
Block(4,16,-2,HARD_CLAY)
Block(4,16,1,HARD_CLAY)
Block(4,16,2,HARD_CLAY)
Block(4,16,3,HARD_CLAY)
Block(4,16,4,HARD_CLAY)
Block(4,17,-4,HARD_CLAY)
Block(4,17,-2,HARD_CLAY)
Block(4,17,2,HARD_CLAY)
Block(4,17,3,HARD_CLAY)
Block(4,18,-2,HARD_CLAY)
Block(4,18,2,HARD_CLAY)
Block(4,18,3,HARD_CLAY)
Block(4,19,-2,HARD_CLAY)
Block(4,19,2,HARD_CLAY)
Block(4,19,3,HARD_CLAY)
Block(4,20,-2,HARD_CLAY)
Block(4,20,2,HARD_CLAY)
Block(4,20,3,HARD_CLAY)
Block(4,21,-2,HARD_CLAY)
Block(4,21,2,HARD_CLAY)
Block(4,21,3,HARD_CLAY)
Block(4,22,-2,HARD_CLAY)
Block(4,22,2,HARD_CLAY)
Block(4,22,3,HARD_CLAY)
Block(4,23,2,HARD_CLAY)
Block(4,24,2,HARD_CLAY)
Block(5,0,-15,HARD_CLAY)
Block(5,0,-14,HARD_CLAY)
Block(5,0,-13,HARD_CLAY)
Block(5,0,-12,HARD_CLAY)
Block(5,0,-11,HARD_CLAY)
Block(5,0,-10,HARD_CLAY)
Block(5,0,-9,HARD_CLAY)
Block(5,0,-8,HARD_CLAY)
Block(5,0,-7,HARD_CLAY)
Block(5,0,-6,HARD_CLAY)
Block(5,0,-5,HARD_CLAY)
Block(5,0,-4,HARD_CLAY)
Block(5,0,-3,HARD_CLAY)
Block(5,0,-2,HARD_CLAY)
Block(5,0,-1,HARD_CLAY)
Block(5,0,0,HARD_CLAY)
Block(5,0,1,HARD_CLAY)
Block(5,0,2,HARD_CLAY)
Block(5,0,3,HARD_CLAY)
Block(5,0,4,HARD_CLAY)
Block(5,0,5,HARD_CLAY)
Block(5,0,6,HARD_CLAY)
Block(5,0,7,HARD_CLAY)
Block(5,0,8,HARD_CLAY)
Block(5,0,9,HARD_CLAY)
Block(5,1,-14,HARD_CLAY)
Block(5,1,-13,HARD_CLAY)
Block(5,1,-12,HARD_CLAY)
Block(5,1,-11,HARD_CLAY)
Block(5,1,-10,HARD_CLAY)
Block(5,1,-9,HARD_CLAY)
Block(5,1,-8,HARD_CLAY)
Block(5,1,-7,HARD_CLAY)
Block(5,1,-6,HARD_CLAY)
Block(5,1,-5,HARD_CLAY)
Block(5,1,-4,HARD_CLAY)
Block(5,1,-3,HARD_CLAY)
Block(5,1,-2,HARD_CLAY)
Block(5,1,-1,HARD_CLAY)
Block(5,1,0,HARD_CLAY)
Block(5,1,1,HARD_CLAY)
Block(5,1,2,HARD_CLAY)
Block(5,1,3,HARD_CLAY)
Block(5,1,4,HARD_CLAY)
Block(5,1,5,HARD_CLAY)
Block(5,1,6,HARD_CLAY)
Block(5,1,7,HARD_CLAY)
Block(5,1,8,HARD_CLAY)
Block(5,2,-14,HARD_CLAY)
Block(5,2,-13,HARD_CLAY)
Block(5,2,-12,HARD_CLAY)
Block(5,2,-11,HARD_CLAY)
Block(5,2,-10,HARD_CLAY)
Block(5,2,-9,HARD_CLAY)
Block(5,2,-8,HARD_CLAY)
Block(5,2,-7,HARD_CLAY)
Block(5,2,-6,HARD_CLAY)
Block(5,2,-5,HARD_CLAY)
Block(5,2,-4,HARD_CLAY)
Block(5,2,-3,HARD_CLAY)
Block(5,2,-2,HARD_CLAY)
Block(5,2,-1,HARD_CLAY)
Block(5,2,0,HARD_CLAY)
Block(5,2,1,HARD_CLAY)
Block(5,2,2,HARD_CLAY)
Block(5,2,3,HARD_CLAY)
Block(5,2,4,HARD_CLAY)
Block(5,2,5,HARD_CLAY)
Block(5,2,6,HARD_CLAY)
Block(5,2,7,HARD_CLAY)
Block(5,2,8,HARD_CLAY)
Block(5,3,-14,HARD_CLAY)
Block(5,3,-13,HARD_CLAY)
Block(5,3,-12,HARD_CLAY)
Block(5,3,-11,HARD_CLAY)
Block(5,3,-10,HARD_CLAY)
Block(5,3,-9,HARD_CLAY)
Block(5,3,-8,HARD_CLAY)
Block(5,3,-7,HARD_CLAY)
Block(5,3,-6,HARD_CLAY)
Block(5,3,-5,HARD_CLAY)
Block(5,3,-4,HARD_CLAY)
Block(5,3,-3,HARD_CLAY)
Block(5,3,-2,HARD_CLAY)
Block(5,3,-1,HARD_CLAY)
Block(5,3,0,HARD_CLAY)
Block(5,3,1,HARD_CLAY)
Block(5,3,2,HARD_CLAY)
Block(5,3,3,HARD_CLAY)
Block(5,3,4,HARD_CLAY)
Block(5,3,5,HARD_CLAY)
Block(5,3,6,HARD_CLAY)
Block(5,3,7,HARD_CLAY)
Block(5,3,8,HARD_CLAY)
Block(5,4,-11,HARD_CLAY)
Block(5,4,-10,HARD_CLAY)
Block(5,4,-9,HARD_CLAY)
Block(5,4,-8,HARD_CLAY)
Block(5,4,-7,HARD_CLAY)
Block(5,4,-6,HARD_CLAY)
Block(5,4,-5,HARD_CLAY)
Block(5,4,-4,HARD_CLAY)
Block(5,4,-3,HARD_CLAY)
Block(5,4,-2,HARD_CLAY)
Block(5,4,-1,HARD_CLAY)
Block(5,4,0,HARD_CLAY)
Block(5,4,1,HARD_CLAY)
Block(5,4,2,HARD_CLAY)
Block(5,4,3,HARD_CLAY)
Block(5,4,4,HARD_CLAY)
Block(5,4,5,HARD_CLAY)
Block(5,4,6,HARD_CLAY)
Block(5,4,7,HARD_CLAY)
Block(5,5,-10,HARD_CLAY)
Block(5,5,-9,HARD_CLAY)
Block(5,5,-8,HARD_CLAY)
Block(5,5,-7,HARD_CLAY)
Block(5,5,-6,HARD_CLAY)
Block(5,5,-5,HARD_CLAY)
Block(5,5,-4,HARD_CLAY)
Block(5,5,-3,HARD_CLAY)
Block(5,5,-2,HARD_CLAY)
Block(5,5,-1,HARD_CLAY)
Block(5,5,0,HARD_CLAY)
Block(5,5,1,HARD_CLAY)
Block(5,5,2,HARD_CLAY)
Block(5,5,3,HARD_CLAY)
Block(5,5,4,HARD_CLAY)
Block(5,5,5,HARD_CLAY)
Block(5,5,6,HARD_CLAY)
Block(5,5,7,HARD_CLAY)
Block(5,6,-10,HARD_CLAY)
Block(5,6,-9,HARD_CLAY)
Block(5,6,-8,HARD_CLAY)
Block(5,6,-7,HARD_CLAY)
Block(5,6,-6,HARD_CLAY)
Block(5,6,-5,HARD_CLAY)
Block(5,6,-4,HARD_CLAY)
Block(5,6,-3,HARD_CLAY)
Block(5,6,-2,HARD_CLAY)
Block(5,6,-1,HARD_CLAY)
Block(5,6,0,HARD_CLAY)
Block(5,6,1,HARD_CLAY)
Block(5,6,2,HARD_CLAY)
Block(5,6,3,HARD_CLAY)
Block(5,6,4,HARD_CLAY)
Block(5,6,5,HARD_CLAY)
Block(5,6,6,HARD_CLAY)
Block(5,6,7,HARD_CLAY)
Block(5,7,-10,HARD_CLAY)
Block(5,7,-9,HARD_CLAY)
Block(5,7,-8,HARD_CLAY)
Block(5,7,-7,HARD_CLAY)
Block(5,7,-6,HARD_CLAY)
Block(5,7,-5,HARD_CLAY)
Block(5,7,-4,HARD_CLAY)
Block(5,7,-3,HARD_CLAY)
Block(5,7,-2,HARD_CLAY)
Block(5,7,-1,HARD_CLAY)
Block(5,7,0,HARD_CLAY)
Block(5,7,1,HARD_CLAY)
Block(5,7,2,HARD_CLAY)
Block(5,7,3,HARD_CLAY)
Block(5,7,4,HARD_CLAY)
Block(5,7,5,HARD_CLAY)
Block(5,7,6,HARD_CLAY)
Block(5,8,-10,HARD_CLAY)
Block(5,8,-9,HARD_CLAY)
Block(5,8,-8,HARD_CLAY)
Block(5,8,-7,HARD_CLAY)
Block(5,8,-6,HARD_CLAY)
Block(5,8,-5,HARD_CLAY)
Block(5,8,-4,HARD_CLAY)
Block(5,8,-3,HARD_CLAY)
Block(5,8,-2,HARD_CLAY)
Block(5,8,-1,HARD_CLAY)
Block(5,8,0,HARD_CLAY)
Block(5,8,1,HARD_CLAY)
Block(5,8,2,HARD_CLAY)
Block(5,8,3,HARD_CLAY)
Block(5,8,4,HARD_CLAY)
Block(5,8,5,HARD_CLAY)
Block(5,8,6,HARD_CLAY)
Block(5,9,-9,HARD_CLAY)
Block(5,9,-8,HARD_CLAY)
Block(5,9,-7,HARD_CLAY)
Block(5,9,-6,HARD_CLAY)
Block(5,9,-5,HARD_CLAY)
Block(5,9,-4,HARD_CLAY)
Block(5,9,-3,HARD_CLAY)
Block(5,9,-2,HARD_CLAY)
Block(5,9,-1,HARD_CLAY)
Block(5,9,0,HARD_CLAY)
Block(5,9,1,HARD_CLAY)
Block(5,9,2,HARD_CLAY)
Block(5,9,3,HARD_CLAY)
Block(5,10,-9,HARD_CLAY)
Block(5,10,-8,HARD_CLAY)
Block(5,10,-7,HARD_CLAY)
Block(5,10,-6,HARD_CLAY)
Block(5,10,-5,HARD_CLAY)
Block(5,10,-4,HARD_CLAY)
Block(5,10,-3,HARD_CLAY)
Block(5,10,-2,HARD_CLAY)
Block(5,10,0,HARD_CLAY)
Block(5,10,1,HARD_CLAY)
Block(5,10,2,HARD_CLAY)
Block(5,10,3,HARD_CLAY)
Block(5,11,-9,HARD_CLAY)
Block(5,11,-8,HARD_CLAY)
Block(5,11,-7,HARD_CLAY)
Block(5,11,-6,HARD_CLAY)
Block(5,11,-5,HARD_CLAY)
Block(5,11,-4,HARD_CLAY)
Block(5,11,-3,HARD_CLAY)
Block(5,11,-2,HARD_CLAY)
Block(5,11,1,HARD_CLAY)
Block(5,11,2,HARD_CLAY)
Block(5,11,3,HARD_CLAY)
Block(5,12,-8,HARD_CLAY)
Block(5,12,-7,HARD_CLAY)
Block(5,12,-6,HARD_CLAY)
Block(5,12,-5,HARD_CLAY)
Block(5,12,-4,HARD_CLAY)
Block(5,12,-3,HARD_CLAY)
Block(5,12,-2,HARD_CLAY)
Block(5,12,1,HARD_CLAY)
Block(5,12,2,HARD_CLAY)
Block(5,12,3,HARD_CLAY)
Block(5,13,-8,HARD_CLAY)
Block(5,13,-7,HARD_CLAY)
Block(5,13,-6,HARD_CLAY)
Block(5,13,-5,HARD_CLAY)
Block(5,13,-4,HARD_CLAY)
Block(5,13,-3,HARD_CLAY)
Block(5,13,-2,HARD_CLAY)
Block(5,13,1,HARD_CLAY)
Block(5,13,2,HARD_CLAY)
Block(5,13,3,HARD_CLAY)
Block(5,14,-7,HARD_CLAY)
Block(5,14,-6,HARD_CLAY)
Block(5,14,-5,HARD_CLAY)
Block(5,14,-4,HARD_CLAY)
Block(5,14,-3,HARD_CLAY)
Block(5,14,-2,HARD_CLAY)
Block(5,14,1,HARD_CLAY)
Block(5,14,2,HARD_CLAY)
Block(5,14,3,HARD_CLAY)
Block(5,15,-7,HARD_CLAY)
Block(5,15,-6,HARD_CLAY)
Block(5,15,-5,HARD_CLAY)
Block(5,15,-4,HARD_CLAY)
Block(5,15,-3,HARD_CLAY)
Block(5,15,1,HARD_CLAY)
Block(5,15,2,HARD_CLAY)
Block(5,16,-7,HARD_CLAY)
Block(5,16,-6,HARD_CLAY)
Block(5,16,-5,HARD_CLAY)
Block(5,16,-4,HARD_CLAY)
Block(5,16,-3,HARD_CLAY)
Block(5,16,1,HARD_CLAY)
Block(5,16,2,HARD_CLAY)
Block(5,17,-6,HARD_CLAY)
Block(5,17,-5,HARD_CLAY)
Block(5,17,-4,HARD_CLAY)
Block(5,17,-3,HARD_CLAY)
Block(5,17,1,HARD_CLAY)
Block(5,17,2,HARD_CLAY)
Block(5,18,-6,HARD_CLAY)
Block(5,18,-5,HARD_CLAY)
Block(5,18,-4,HARD_CLAY)
Block(5,18,1,HARD_CLAY)
Block(5,18,2,HARD_CLAY)
Block(5,19,-6,HARD_CLAY)
Block(5,19,-5,HARD_CLAY)
Block(5,19,2,HARD_CLAY)
Block(5,20,2,HARD_CLAY)
Block(5,21,2,HARD_CLAY)
Block(5,22,2,HARD_CLAY)
Block(5,23,2,HARD_CLAY)
Block(5,24,2,HARD_CLAY)
Block(5,25,2,HARD_CLAY)
Block(6,0,-14,HARD_CLAY)
Block(6,0,-13,HARD_CLAY)
Block(6,0,-12,HARD_CLAY)
Block(6,0,-11,HARD_CLAY)
Block(6,0,-10,HARD_CLAY)
Block(6,0,-9,HARD_CLAY)
Block(6,0,-8,HARD_CLAY)
Block(6,0,-7,HARD_CLAY)
Block(6,0,-6,HARD_CLAY)
Block(6,0,-5,HARD_CLAY)
Block(6,0,-4,HARD_CLAY)
Block(6,0,-3,HARD_CLAY)
Block(6,0,-2,HARD_CLAY)
Block(6,0,-1,HARD_CLAY)
Block(6,0,0,HARD_CLAY)
Block(6,0,1,HARD_CLAY)
Block(6,0,2,HARD_CLAY)
Block(6,0,3,HARD_CLAY)
Block(6,0,4,HARD_CLAY)
Block(6,0,5,HARD_CLAY)
Block(6,0,6,HARD_CLAY)
Block(6,0,7,HARD_CLAY)
Block(6,1,-13,HARD_CLAY)
Block(6,1,-12,HARD_CLAY)
Block(6,1,-11,HARD_CLAY)
Block(6,1,-10,HARD_CLAY)
Block(6,1,-9,HARD_CLAY)
Block(6,1,-8,HARD_CLAY)
Block(6,1,-7,HARD_CLAY)
Block(6,1,-6,HARD_CLAY)
Block(6,1,-5,HARD_CLAY)
Block(6,1,-4,HARD_CLAY)
Block(6,1,-3,HARD_CLAY)
Block(6,1,-2,HARD_CLAY)
Block(6,1,-1,HARD_CLAY)
Block(6,1,0,HARD_CLAY)
Block(6,1,1,HARD_CLAY)
Block(6,1,2,HARD_CLAY)
Block(6,1,3,HARD_CLAY)
Block(6,1,4,HARD_CLAY)
Block(6,1,5,HARD_CLAY)
Block(6,1,6,HARD_CLAY)
Block(6,2,-13,HARD_CLAY)
Block(6,2,-12,HARD_CLAY)
Block(6,2,-11,HARD_CLAY)
Block(6,2,-10,HARD_CLAY)
Block(6,2,-9,HARD_CLAY)
Block(6,2,-8,HARD_CLAY)
Block(6,2,-7,HARD_CLAY)
Block(6,2,-6,HARD_CLAY)
Block(6,2,-5,HARD_CLAY)
Block(6,2,-4,HARD_CLAY)
Block(6,2,-3,HARD_CLAY)
Block(6,2,-2,HARD_CLAY)
Block(6,2,-1,HARD_CLAY)
Block(6,2,0,HARD_CLAY)
Block(6,2,1,HARD_CLAY)
Block(6,2,2,HARD_CLAY)
Block(6,2,3,HARD_CLAY)
Block(6,2,4,HARD_CLAY)
Block(6,2,5,HARD_CLAY)
Block(6,2,6,HARD_CLAY)
Block(6,3,-12,HARD_CLAY)
Block(6,3,-11,HARD_CLAY)
Block(6,3,-10,HARD_CLAY)
Block(6,3,-9,HARD_CLAY)
Block(6,3,-8,HARD_CLAY)
Block(6,3,-7,HARD_CLAY)
Block(6,3,-6,HARD_CLAY)
Block(6,3,-5,HARD_CLAY)
Block(6,3,-4,HARD_CLAY)
Block(6,3,-3,HARD_CLAY)
Block(6,3,-2,HARD_CLAY)
Block(6,3,-1,HARD_CLAY)
Block(6,3,0,HARD_CLAY)
Block(6,3,1,HARD_CLAY)
Block(6,3,2,HARD_CLAY)
Block(6,3,3,HARD_CLAY)
Block(6,3,4,HARD_CLAY)
Block(6,3,5,HARD_CLAY)
Block(6,3,6,HARD_CLAY)
Block(6,4,-12,HARD_CLAY)
Block(6,4,-11,HARD_CLAY)
Block(6,4,-10,HARD_CLAY)
Block(6,4,-9,HARD_CLAY)
Block(6,4,-8,HARD_CLAY)
Block(6,4,-7,HARD_CLAY)
Block(6,4,-6,HARD_CLAY)
Block(6,4,-5,HARD_CLAY)
Block(6,4,-4,HARD_CLAY)
Block(6,4,-3,HARD_CLAY)
Block(6,4,-2,HARD_CLAY)
Block(6,4,-1,HARD_CLAY)
Block(6,4,0,HARD_CLAY)
Block(6,4,1,HARD_CLAY)
Block(6,4,2,HARD_CLAY)
Block(6,4,3,HARD_CLAY)
Block(6,4,4,HARD_CLAY)
Block(6,4,5,HARD_CLAY)
Block(6,4,6,HARD_CLAY)
Block(6,5,-12,HARD_CLAY)
Block(6,5,-11,HARD_CLAY)
Block(6,5,-10,HARD_CLAY)
Block(6,5,-9,HARD_CLAY)
Block(6,5,-8,HARD_CLAY)
Block(6,5,-7,HARD_CLAY)
Block(6,5,-6,HARD_CLAY)
Block(6,5,-5,HARD_CLAY)
Block(6,5,-4,HARD_CLAY)
Block(6,5,-3,HARD_CLAY)
Block(6,5,-2,HARD_CLAY)
Block(6,5,-1,HARD_CLAY)
Block(6,5,0,HARD_CLAY)
Block(6,5,1,HARD_CLAY)
Block(6,5,2,HARD_CLAY)
Block(6,5,3,HARD_CLAY)
Block(6,5,4,HARD_CLAY)
Block(6,5,5,HARD_CLAY)
Block(6,6,-12,HARD_CLAY)
Block(6,6,-11,HARD_CLAY)
Block(6,6,-10,HARD_CLAY)
Block(6,6,-9,HARD_CLAY)
Block(6,6,-8,HARD_CLAY)
Block(6,6,-7,HARD_CLAY)
Block(6,6,-6,HARD_CLAY)
Block(6,6,-5,HARD_CLAY)
Block(6,6,-4,HARD_CLAY)
Block(6,6,-3,HARD_CLAY)
Block(6,6,-2,HARD_CLAY)
Block(6,6,-1,HARD_CLAY)
Block(6,6,0,HARD_CLAY)
Block(6,6,1,HARD_CLAY)
Block(6,6,2,HARD_CLAY)
Block(6,6,3,HARD_CLAY)
Block(6,6,4,HARD_CLAY)
Block(6,6,5,HARD_CLAY)
Block(6,7,-10,HARD_CLAY)
Block(6,7,-9,HARD_CLAY)
Block(6,7,-8,HARD_CLAY)
Block(6,7,-7,HARD_CLAY)
Block(6,7,-6,HARD_CLAY)
Block(6,7,-5,HARD_CLAY)
Block(6,7,-4,HARD_CLAY)
Block(6,7,-3,HARD_CLAY)
Block(6,7,-2,HARD_CLAY)
Block(6,7,-1,HARD_CLAY)
Block(6,7,0,HARD_CLAY)
Block(6,7,1,HARD_CLAY)
Block(6,7,2,HARD_CLAY)
Block(6,7,3,HARD_CLAY)
Block(6,7,4,HARD_CLAY)
Block(6,8,-10,HARD_CLAY)
Block(6,8,-9,HARD_CLAY)
Block(6,8,-8,HARD_CLAY)
Block(6,8,-7,HARD_CLAY)
Block(6,8,-6,HARD_CLAY)
Block(6,8,-5,HARD_CLAY)
Block(6,8,-4,HARD_CLAY)
Block(6,8,-3,HARD_CLAY)
Block(6,8,-2,HARD_CLAY)
Block(6,8,-1,HARD_CLAY)
Block(6,8,0,HARD_CLAY)
Block(6,8,1,HARD_CLAY)
Block(6,8,2,HARD_CLAY)
Block(6,8,3,HARD_CLAY)
Block(6,8,4,HARD_CLAY)
Block(6,9,-9,HARD_CLAY)
Block(6,9,-8,HARD_CLAY)
Block(6,9,-7,HARD_CLAY)
Block(6,9,-6,HARD_CLAY)
Block(6,9,-5,HARD_CLAY)
Block(6,9,-4,HARD_CLAY)
Block(6,9,-3,HARD_CLAY)
Block(6,9,-2,HARD_CLAY)
Block(6,9,-1,HARD_CLAY)
Block(6,9,1,HARD_CLAY)
Block(6,9,2,HARD_CLAY)
Block(6,9,3,HARD_CLAY)
Block(6,9,4,HARD_CLAY)
Block(6,10,-9,HARD_CLAY)
Block(6,10,-8,HARD_CLAY)
Block(6,10,-7,HARD_CLAY)
Block(6,10,-6,HARD_CLAY)
Block(6,10,-5,HARD_CLAY)
Block(6,10,-4,HARD_CLAY)
Block(6,10,-3,HARD_CLAY)
Block(6,10,-2,HARD_CLAY)
Block(6,10,1,HARD_CLAY)
Block(6,10,2,HARD_CLAY)
Block(6,10,3,HARD_CLAY)
Block(6,11,-9,HARD_CLAY)
Block(6,11,-8,HARD_CLAY)
Block(6,11,-7,HARD_CLAY)
Block(6,11,-6,HARD_CLAY)
Block(6,11,-5,HARD_CLAY)
Block(6,11,-4,HARD_CLAY)
Block(6,11,-2,HARD_CLAY)
Block(6,11,1,HARD_CLAY)
Block(6,11,2,HARD_CLAY)
Block(6,11,3,HARD_CLAY)
Block(6,12,-9,HARD_CLAY)
Block(6,12,-8,HARD_CLAY)
Block(6,12,-7,HARD_CLAY)
Block(6,12,-6,HARD_CLAY)
Block(6,12,-5,HARD_CLAY)
Block(6,12,-4,HARD_CLAY)
Block(6,12,1,HARD_CLAY)
Block(6,12,2,HARD_CLAY)
Block(6,12,3,HARD_CLAY)
Block(6,13,-9,HARD_CLAY)
Block(6,13,-8,HARD_CLAY)
Block(6,13,-7,HARD_CLAY)
Block(6,13,-6,HARD_CLAY)
Block(6,13,-5,HARD_CLAY)
Block(6,13,-4,HARD_CLAY)
Block(6,13,1,HARD_CLAY)
Block(6,13,2,HARD_CLAY)
Block(6,14,-9,HARD_CLAY)
Block(6,14,-8,HARD_CLAY)
Block(6,14,-7,HARD_CLAY)
Block(6,14,-6,HARD_CLAY)
Block(6,14,-5,HARD_CLAY)
Block(6,14,1,HARD_CLAY)
Block(6,14,2,HARD_CLAY)
Block(6,15,-8,HARD_CLAY)
Block(6,15,-7,HARD_CLAY)
Block(6,15,-6,HARD_CLAY)
Block(6,15,-5,HARD_CLAY)
Block(6,15,1,HARD_CLAY)
Block(6,15,2,HARD_CLAY)
Block(6,16,-8,HARD_CLAY)
Block(6,16,-7,HARD_CLAY)
Block(6,16,-5,HARD_CLAY)
Block(6,16,1,HARD_CLAY)
Block(6,16,2,HARD_CLAY)
Block(6,17,-5,HARD_CLAY)
Block(6,17,2,HARD_CLAY)
Block(6,18,-5,HARD_CLAY)
Block(6,19,-5,HARD_CLAY)
Block(6,20,-5,HARD_CLAY)
Block(6,21,-5,HARD_CLAY)
Block(6,22,-5,HARD_CLAY)
Block(6,23,-5,HARD_CLAY)
Block(7,0,-14,HARD_CLAY)
Block(7,0,-13,HARD_CLAY)
Block(7,0,-12,HARD_CLAY)
Block(7,0,-11,HARD_CLAY)
Block(7,0,-10,HARD_CLAY)
Block(7,0,-9,HARD_CLAY)
Block(7,0,-8,HARD_CLAY)
Block(7,0,-7,HARD_CLAY)
Block(7,0,-6,HARD_CLAY)
Block(7,0,-5,HARD_CLAY)
Block(7,0,-4,HARD_CLAY)
Block(7,0,-3,HARD_CLAY)
Block(7,0,-2,HARD_CLAY)
Block(7,0,-1,HARD_CLAY)
Block(7,0,0,HARD_CLAY)
Block(7,0,1,HARD_CLAY)
Block(7,0,2,HARD_CLAY)
Block(7,0,3,HARD_CLAY)
Block(7,0,4,HARD_CLAY)
Block(7,0,5,HARD_CLAY)
Block(7,0,6,HARD_CLAY)
Block(7,0,7,HARD_CLAY)
Block(7,1,-13,HARD_CLAY)
Block(7,1,-12,HARD_CLAY)
Block(7,1,-11,HARD_CLAY)
Block(7,1,-10,HARD_CLAY)
Block(7,1,-9,HARD_CLAY)
Block(7,1,-8,HARD_CLAY)
Block(7,1,-7,HARD_CLAY)
Block(7,1,-6,HARD_CLAY)
Block(7,1,-5,HARD_CLAY)
Block(7,1,-4,HARD_CLAY)
Block(7,1,-3,HARD_CLAY)
Block(7,1,-2,HARD_CLAY)
Block(7,1,-1,HARD_CLAY)
Block(7,1,0,HARD_CLAY)
Block(7,1,1,HARD_CLAY)
Block(7,1,2,HARD_CLAY)
Block(7,1,3,HARD_CLAY)
Block(7,1,4,HARD_CLAY)
Block(7,1,5,HARD_CLAY)
Block(7,1,6,HARD_CLAY)
Block(7,1,7,HARD_CLAY)
Block(7,2,-12,HARD_CLAY)
Block(7,2,-11,HARD_CLAY)
Block(7,2,-10,HARD_CLAY)
Block(7,2,-9,HARD_CLAY)
Block(7,2,-8,HARD_CLAY)
Block(7,2,-7,HARD_CLAY)
Block(7,2,-6,HARD_CLAY)
Block(7,2,-5,HARD_CLAY)
Block(7,2,-4,HARD_CLAY)
Block(7,2,-3,HARD_CLAY)
Block(7,2,-2,HARD_CLAY)
Block(7,2,-1,HARD_CLAY)
Block(7,2,0,HARD_CLAY)
Block(7,2,1,HARD_CLAY)
Block(7,2,2,HARD_CLAY)
Block(7,2,3,HARD_CLAY)
Block(7,2,4,HARD_CLAY)
Block(7,2,5,HARD_CLAY)
Block(7,2,6,HARD_CLAY)
Block(7,2,7,HARD_CLAY)
Block(7,3,-12,HARD_CLAY)
Block(7,3,-11,HARD_CLAY)
Block(7,3,-10,HARD_CLAY)
Block(7,3,-9,HARD_CLAY)
Block(7,3,-8,HARD_CLAY)
Block(7,3,-7,HARD_CLAY)
Block(7,3,-6,HARD_CLAY)
Block(7,3,-5,HARD_CLAY)
Block(7,3,-4,HARD_CLAY)
Block(7,3,-3,HARD_CLAY)
Block(7,3,-2,HARD_CLAY)
Block(7,3,-1,HARD_CLAY)
Block(7,3,0,HARD_CLAY)
Block(7,3,1,HARD_CLAY)
Block(7,3,2,HARD_CLAY)
Block(7,3,3,HARD_CLAY)
Block(7,3,4,HARD_CLAY)
Block(7,3,5,HARD_CLAY)
Block(7,3,6,HARD_CLAY)
Block(7,4,-12,HARD_CLAY)
Block(7,4,-11,HARD_CLAY)
Block(7,4,-10,HARD_CLAY)
Block(7,4,-9,HARD_CLAY)
Block(7,4,-8,HARD_CLAY)
Block(7,4,-7,HARD_CLAY)
Block(7,4,-6,HARD_CLAY)
Block(7,4,-5,HARD_CLAY)
Block(7,4,-4,HARD_CLAY)
Block(7,4,-3,HARD_CLAY)
Block(7,4,-2,HARD_CLAY)
Block(7,4,-1,HARD_CLAY)
Block(7,4,0,HARD_CLAY)
Block(7,4,1,HARD_CLAY)
Block(7,4,2,HARD_CLAY)
Block(7,4,3,HARD_CLAY)
Block(7,5,-12,HARD_CLAY)
Block(7,5,-11,HARD_CLAY)
Block(7,5,-10,HARD_CLAY)
Block(7,5,-9,HARD_CLAY)
Block(7,5,-8,HARD_CLAY)
Block(7,5,-7,HARD_CLAY)
Block(7,5,-6,HARD_CLAY)
Block(7,5,-5,HARD_CLAY)
Block(7,5,-4,HARD_CLAY)
Block(7,5,-3,HARD_CLAY)
Block(7,5,-2,HARD_CLAY)
Block(7,5,-1,HARD_CLAY)
Block(7,5,0,HARD_CLAY)
Block(7,5,1,HARD_CLAY)
Block(7,5,2,HARD_CLAY)
Block(7,5,3,HARD_CLAY)
Block(7,6,-12,HARD_CLAY)
Block(7,6,-11,HARD_CLAY)
Block(7,6,-10,HARD_CLAY)
Block(7,6,-9,HARD_CLAY)
Block(7,6,-8,HARD_CLAY)
Block(7,6,-7,HARD_CLAY)
Block(7,6,-6,HARD_CLAY)
Block(7,6,-5,HARD_CLAY)
Block(7,6,-4,HARD_CLAY)
Block(7,6,-3,HARD_CLAY)
Block(7,6,-2,HARD_CLAY)
Block(7,6,-1,HARD_CLAY)
Block(7,6,0,HARD_CLAY)
Block(7,6,1,HARD_CLAY)
Block(7,6,2,HARD_CLAY)
Block(7,6,3,HARD_CLAY)
Block(7,7,-11,HARD_CLAY)
Block(7,7,-10,HARD_CLAY)
Block(7,7,-9,HARD_CLAY)
Block(7,7,-8,HARD_CLAY)
Block(7,7,-7,HARD_CLAY)
Block(7,7,-6,HARD_CLAY)
Block(7,7,-5,HARD_CLAY)
Block(7,7,-4,HARD_CLAY)
Block(7,7,-3,HARD_CLAY)
Block(7,7,-2,HARD_CLAY)
Block(7,7,1,HARD_CLAY)
Block(7,7,2,HARD_CLAY)
Block(7,8,-11,HARD_CLAY)
Block(7,8,-10,HARD_CLAY)
Block(7,8,-9,HARD_CLAY)
Block(7,8,-8,HARD_CLAY)
Block(7,8,-7,HARD_CLAY)
Block(7,8,-6,HARD_CLAY)
Block(7,8,-5,HARD_CLAY)
Block(7,8,-4,HARD_CLAY)
Block(7,8,-3,HARD_CLAY)
Block(7,8,-2,HARD_CLAY)
Block(7,8,2,HARD_CLAY)
Block(7,9,-10,HARD_CLAY)
Block(7,9,-9,HARD_CLAY)
Block(7,9,-8,HARD_CLAY)
Block(7,9,-7,HARD_CLAY)
Block(7,9,-6,HARD_CLAY)
Block(7,9,-5,HARD_CLAY)
Block(7,9,-4,HARD_CLAY)
Block(7,9,-3,HARD_CLAY)
Block(7,9,-2,HARD_CLAY)
Block(7,9,2,HARD_CLAY)
Block(7,10,-10,HARD_CLAY)
Block(7,10,-9,HARD_CLAY)
Block(7,10,-8,HARD_CLAY)
Block(7,10,-7,HARD_CLAY)
Block(7,10,-6,HARD_CLAY)
Block(7,10,-5,HARD_CLAY)
Block(7,10,-4,HARD_CLAY)
Block(7,10,-3,HARD_CLAY)
Block(7,10,-2,HARD_CLAY)
Block(7,10,2,HARD_CLAY)
Block(7,11,-10,HARD_CLAY)
Block(7,11,-9,HARD_CLAY)
Block(7,11,-8,HARD_CLAY)
Block(7,11,-7,HARD_CLAY)
Block(7,11,-6,HARD_CLAY)
Block(7,11,-5,HARD_CLAY)
Block(7,11,-4,HARD_CLAY)
Block(7,12,-10,HARD_CLAY)
Block(7,12,-9,HARD_CLAY)
Block(7,12,-8,HARD_CLAY)
Block(7,12,-7,HARD_CLAY)
Block(7,12,-6,HARD_CLAY)
Block(7,13,-8,HARD_CLAY)
Block(7,13,-7,HARD_CLAY)
Block(7,13,-6,HARD_CLAY)
Block(7,14,-8,HARD_CLAY)
Block(7,14,-7,HARD_CLAY)
Block(7,14,-6,HARD_CLAY)
Block(7,15,-8,HARD_CLAY)
Block(7,15,-7,HARD_CLAY)
Block(7,15,-6,HARD_CLAY)
Block(7,16,-8,HARD_CLAY)
Block(7,16,-7,HARD_CLAY)
Block(7,16,-6,HARD_CLAY)
Block(7,17,-7,HARD_CLAY)
Block(7,18,-7,HARD_CLAY)
Block(7,19,-7,HARD_CLAY)
Block(8,0,-13,HARD_CLAY)
Block(8,0,-12,HARD_CLAY)
Block(8,0,-11,HARD_CLAY)
Block(8,0,-10,HARD_CLAY)
Block(8,0,-9,HARD_CLAY)
Block(8,0,-8,HARD_CLAY)
Block(8,0,-7,HARD_CLAY)
Block(8,0,-6,HARD_CLAY)
Block(8,0,-5,HARD_CLAY)
Block(8,0,-4,HARD_CLAY)
Block(8,0,-3,HARD_CLAY)
Block(8,0,-2,HARD_CLAY)
Block(8,0,-1,HARD_CLAY)
Block(8,0,0,HARD_CLAY)
Block(8,0,1,HARD_CLAY)
Block(8,0,2,HARD_CLAY)
Block(8,0,3,HARD_CLAY)
Block(8,0,4,HARD_CLAY)
Block(8,0,5,HARD_CLAY)
Block(8,0,6,HARD_CLAY)
Block(8,0,7,HARD_CLAY)
Block(8,1,-13,HARD_CLAY)
Block(8,1,-12,HARD_CLAY)
Block(8,1,-11,HARD_CLAY)
Block(8,1,-10,HARD_CLAY)
Block(8,1,-9,HARD_CLAY)
Block(8,1,-8,HARD_CLAY)
Block(8,1,-7,HARD_CLAY)
Block(8,1,-6,HARD_CLAY)
Block(8,1,-5,HARD_CLAY)
Block(8,1,-4,HARD_CLAY)
Block(8,1,-3,HARD_CLAY)
Block(8,1,-2,HARD_CLAY)
Block(8,1,-1,HARD_CLAY)
Block(8,1,0,HARD_CLAY)
Block(8,1,1,HARD_CLAY)
Block(8,1,2,HARD_CLAY)
Block(8,1,3,HARD_CLAY)
Block(8,1,4,HARD_CLAY)
Block(8,1,5,HARD_CLAY)
Block(8,1,6,HARD_CLAY)
Block(8,2,-12,HARD_CLAY)
Block(8,2,-11,HARD_CLAY)
Block(8,2,-10,HARD_CLAY)
Block(8,2,-9,HARD_CLAY)
Block(8,2,-8,HARD_CLAY)
Block(8,2,-7,HARD_CLAY)
Block(8,2,-6,HARD_CLAY)
Block(8,2,-5,HARD_CLAY)
Block(8,2,-4,HARD_CLAY)
Block(8,2,-3,HARD_CLAY)
Block(8,2,-2,HARD_CLAY)
Block(8,2,-1,HARD_CLAY)
Block(8,2,0,HARD_CLAY)
Block(8,2,1,HARD_CLAY)
Block(8,2,2,HARD_CLAY)
Block(8,2,3,HARD_CLAY)
Block(8,2,4,HARD_CLAY)
Block(8,3,-12,HARD_CLAY)
Block(8,3,-11,HARD_CLAY)
Block(8,3,-10,HARD_CLAY)
Block(8,3,-9,HARD_CLAY)
Block(8,3,-8,HARD_CLAY)
Block(8,3,-7,HARD_CLAY)
Block(8,3,-6,HARD_CLAY)
Block(8,3,-5,HARD_CLAY)
Block(8,3,-4,HARD_CLAY)
Block(8,3,-3,HARD_CLAY)
Block(8,3,-2,HARD_CLAY)
Block(8,3,-1,HARD_CLAY)
Block(8,3,0,HARD_CLAY)
Block(8,3,1,HARD_CLAY)
Block(8,3,2,HARD_CLAY)
Block(8,3,3,HARD_CLAY)
Block(8,3,4,HARD_CLAY)
Block(8,4,-12,HARD_CLAY)
Block(8,4,-11,HARD_CLAY)
Block(8,4,-10,HARD_CLAY)
Block(8,4,-9,HARD_CLAY)
Block(8,4,-8,HARD_CLAY)
Block(8,4,-7,HARD_CLAY)
Block(8,4,-6,HARD_CLAY)
Block(8,4,-5,HARD_CLAY)
Block(8,4,-4,HARD_CLAY)
Block(8,4,-3,HARD_CLAY)
Block(8,4,-2,HARD_CLAY)
Block(8,4,-1,HARD_CLAY)
Block(8,4,2,HARD_CLAY)
Block(8,4,4,HARD_CLAY)
Block(8,5,-11,HARD_CLAY)
Block(8,5,-10,HARD_CLAY)
Block(8,5,-9,HARD_CLAY)
Block(8,5,-8,HARD_CLAY)
Block(8,5,-7,HARD_CLAY)
Block(8,5,-6,HARD_CLAY)
Block(8,5,-5,HARD_CLAY)
Block(8,5,-4,HARD_CLAY)
Block(8,5,-3,HARD_CLAY)
Block(8,5,-2,HARD_CLAY)
Block(8,5,-1,HARD_CLAY)
Block(8,5,2,HARD_CLAY)
Block(8,6,-11,HARD_CLAY)
Block(8,6,-10,HARD_CLAY)
Block(8,6,-9,HARD_CLAY)
Block(8,6,-8,HARD_CLAY)
Block(8,6,-7,HARD_CLAY)
Block(8,6,-6,HARD_CLAY)
Block(8,6,-5,HARD_CLAY)
Block(8,6,-4,HARD_CLAY)
Block(8,6,-3,HARD_CLAY)
Block(8,6,-2,HARD_CLAY)
Block(8,6,-1,HARD_CLAY)
Block(8,6,2,HARD_CLAY)
Block(8,7,-11,HARD_CLAY)
Block(8,7,-10,HARD_CLAY)
Block(8,7,-9,HARD_CLAY)
Block(8,7,-8,HARD_CLAY)
Block(8,7,-7,HARD_CLAY)
Block(8,7,-6,HARD_CLAY)
Block(8,7,-5,HARD_CLAY)
Block(8,7,-4,HARD_CLAY)
Block(8,7,-3,HARD_CLAY)
Block(8,7,-2,HARD_CLAY)
Block(8,7,-1,HARD_CLAY)
Block(8,8,-11,HARD_CLAY)
Block(8,8,-10,HARD_CLAY)
Block(8,8,-9,HARD_CLAY)
Block(8,8,-8,HARD_CLAY)
Block(8,8,-7,HARD_CLAY)
Block(8,8,-6,HARD_CLAY)
Block(8,8,-5,HARD_CLAY)
Block(8,8,-4,HARD_CLAY)
Block(8,8,-3,HARD_CLAY)
Block(8,8,-1,HARD_CLAY)
Block(8,9,-11,HARD_CLAY)
Block(8,9,-10,HARD_CLAY)
Block(8,9,-9,HARD_CLAY)
Block(8,9,-8,HARD_CLAY)
Block(8,9,-7,HARD_CLAY)
Block(8,9,-6,HARD_CLAY)
Block(8,9,-5,HARD_CLAY)
Block(8,9,-4,HARD_CLAY)
Block(8,9,-3,HARD_CLAY)
Block(8,10,-10,HARD_CLAY)
Block(8,10,-9,HARD_CLAY)
Block(8,10,-8,HARD_CLAY)
Block(8,10,-7,HARD_CLAY)
Block(8,10,-6,HARD_CLAY)
Block(8,10,-5,HARD_CLAY)
Block(8,10,-4,HARD_CLAY)
Block(8,10,-3,HARD_CLAY)
Block(8,11,-10,HARD_CLAY)
Block(8,11,-9,HARD_CLAY)
Block(8,11,-8,HARD_CLAY)
Block(8,11,-7,HARD_CLAY)
Block(8,11,-6,HARD_CLAY)
Block(8,11,-5,HARD_CLAY)
Block(8,12,-10,HARD_CLAY)
Block(8,12,-9,HARD_CLAY)
Block(8,12,-8,HARD_CLAY)
Block(8,12,-7,HARD_CLAY)
Block(8,12,-6,HARD_CLAY)
Block(8,12,-5,HARD_CLAY)
Block(8,13,-10,HARD_CLAY)
Block(8,13,-9,HARD_CLAY)
Block(8,13,-8,HARD_CLAY)
Block(8,13,-7,HARD_CLAY)
Block(8,13,-6,HARD_CLAY)
Block(8,13,-5,HARD_CLAY)
Block(8,14,-9,HARD_CLAY)
Block(8,14,-8,HARD_CLAY)
Block(8,14,-7,HARD_CLAY)
Block(8,14,-6,HARD_CLAY)
Block(8,14,-5,HARD_CLAY)
Block(8,15,-9,HARD_CLAY)
Block(8,15,-8,HARD_CLAY)
Block(8,15,-7,HARD_CLAY)
Block(8,15,-6,HARD_CLAY)
Block(8,15,-5,HARD_CLAY)
Block(8,16,-9,HARD_CLAY)
Block(8,16,-8,HARD_CLAY)
Block(8,16,-7,HARD_CLAY)
Block(8,16,-6,HARD_CLAY)
Block(8,17,-9,HARD_CLAY)
Block(8,17,-8,HARD_CLAY)
Block(8,17,-7,HARD_CLAY)
Block(8,17,-6,HARD_CLAY)
Block(8,18,-9,HARD_CLAY)
Block(8,18,-7,HARD_CLAY)
Block(8,18,-6,HARD_CLAY)
Block(8,19,-9,HARD_CLAY)
Block(9,0,-14,HARD_CLAY)
Block(9,0,-13,HARD_CLAY)
Block(9,0,-12,HARD_CLAY)
Block(9,0,-11,HARD_CLAY)
Block(9,0,-10,HARD_CLAY)
Block(9,0,-9,HARD_CLAY)
Block(9,0,-8,HARD_CLAY)
Block(9,0,-7,HARD_CLAY)
Block(9,0,-6,HARD_CLAY)
Block(9,0,-5,HARD_CLAY)
Block(9,0,-4,HARD_CLAY)
Block(9,0,-3,HARD_CLAY)
Block(9,0,-2,HARD_CLAY)
Block(9,0,-1,HARD_CLAY)
Block(9,0,1,HARD_CLAY)
Block(9,0,2,HARD_CLAY)
Block(9,0,3,HARD_CLAY)
Block(9,0,4,HARD_CLAY)
Block(9,1,-13,HARD_CLAY)
Block(9,1,-12,HARD_CLAY)
Block(9,1,-11,HARD_CLAY)
Block(9,1,-10,HARD_CLAY)
Block(9,1,-9,HARD_CLAY)
Block(9,1,-8,HARD_CLAY)
Block(9,1,-7,HARD_CLAY)
Block(9,1,-6,HARD_CLAY)
Block(9,1,-5,HARD_CLAY)
Block(9,1,-4,HARD_CLAY)
Block(9,1,-3,HARD_CLAY)
Block(9,1,-2,HARD_CLAY)
Block(9,1,-1,HARD_CLAY)
Block(9,1,1,HARD_CLAY)
Block(9,2,-13,HARD_CLAY)
Block(9,2,-12,HARD_CLAY)
Block(9,2,-11,HARD_CLAY)
Block(9,2,-10,HARD_CLAY)
Block(9,2,-9,HARD_CLAY)
Block(9,2,-8,HARD_CLAY)
Block(9,2,-7,HARD_CLAY)
Block(9,2,-6,HARD_CLAY)
Block(9,2,-5,HARD_CLAY)
Block(9,2,-4,HARD_CLAY)
Block(9,2,-3,HARD_CLAY)
Block(9,2,-2,HARD_CLAY)
Block(9,2,-1,HARD_CLAY)
Block(9,2,1,HARD_CLAY)
Block(9,3,-13,HARD_CLAY)
Block(9,3,-12,HARD_CLAY)
Block(9,3,-11,HARD_CLAY)
Block(9,3,-10,HARD_CLAY)
Block(9,3,-9,HARD_CLAY)
Block(9,3,-8,HARD_CLAY)
Block(9,3,-7,HARD_CLAY)
Block(9,3,-6,HARD_CLAY)
Block(9,3,-5,HARD_CLAY)
Block(9,3,-4,HARD_CLAY)
Block(9,3,-3,HARD_CLAY)
Block(9,3,-2,HARD_CLAY)
Block(9,3,-1,HARD_CLAY)
Block(9,4,-13,HARD_CLAY)
Block(9,4,-12,HARD_CLAY)
Block(9,4,-11,HARD_CLAY)
Block(9,4,-10,HARD_CLAY)
Block(9,4,-9,HARD_CLAY)
Block(9,4,-8,HARD_CLAY)
Block(9,4,-7,HARD_CLAY)
Block(9,4,-6,HARD_CLAY)
Block(9,4,-5,HARD_CLAY)
Block(9,4,-4,HARD_CLAY)
Block(9,4,-3,HARD_CLAY)
Block(9,4,-2,HARD_CLAY)
Block(9,4,-1,HARD_CLAY)
Block(9,5,-13,HARD_CLAY)
Block(9,5,-12,HARD_CLAY)
Block(9,5,-11,HARD_CLAY)
Block(9,5,-10,HARD_CLAY)
Block(9,5,-9,HARD_CLAY)
Block(9,5,-8,HARD_CLAY)
Block(9,5,-7,HARD_CLAY)
Block(9,5,-6,HARD_CLAY)
Block(9,5,-5,HARD_CLAY)
Block(9,5,-4,HARD_CLAY)
Block(9,5,-3,HARD_CLAY)
Block(9,5,-2,HARD_CLAY)
Block(9,5,-1,HARD_CLAY)
Block(9,6,-13,HARD_CLAY)
Block(9,6,-12,HARD_CLAY)
Block(9,6,-11,HARD_CLAY)
Block(9,6,-10,HARD_CLAY)
Block(9,6,-9,HARD_CLAY)
Block(9,6,-8,HARD_CLAY)
Block(9,6,-7,HARD_CLAY)
Block(9,6,-6,HARD_CLAY)
Block(9,6,-5,HARD_CLAY)
Block(9,6,-4,HARD_CLAY)
Block(9,6,-3,HARD_CLAY)
Block(9,6,-2,HARD_CLAY)
Block(9,7,-13,HARD_CLAY)
Block(9,7,-12,HARD_CLAY)
Block(9,7,-11,HARD_CLAY)
Block(9,7,-10,HARD_CLAY)
Block(9,7,-9,HARD_CLAY)
Block(9,7,-8,HARD_CLAY)
Block(9,7,-7,HARD_CLAY)
Block(9,7,-6,HARD_CLAY)
Block(9,7,-5,HARD_CLAY)
Block(9,7,-4,HARD_CLAY)
Block(9,7,-3,HARD_CLAY)
Block(9,8,-12,HARD_CLAY)
Block(9,8,-11,HARD_CLAY)
Block(9,8,-10,HARD_CLAY)
Block(9,8,-9,HARD_CLAY)
Block(9,8,-8,HARD_CLAY)
Block(9,8,-7,HARD_CLAY)
Block(9,8,-6,HARD_CLAY)
Block(9,8,-5,HARD_CLAY)
Block(9,8,-4,HARD_CLAY)
Block(9,8,-3,HARD_CLAY)
Block(9,9,-12,HARD_CLAY)
Block(9,9,-11,HARD_CLAY)
Block(9,9,-10,HARD_CLAY)
Block(9,9,-9,HARD_CLAY)
Block(9,9,-8,HARD_CLAY)
Block(9,9,-7,HARD_CLAY)
Block(9,9,-6,HARD_CLAY)
Block(9,9,-5,HARD_CLAY)
Block(9,9,-3,HARD_CLAY)
Block(9,10,-12,HARD_CLAY)
Block(9,10,-11,HARD_CLAY)
Block(9,10,-10,HARD_CLAY)
Block(9,10,-9,HARD_CLAY)
Block(9,10,-8,HARD_CLAY)
Block(9,10,-7,HARD_CLAY)
Block(9,10,-6,HARD_CLAY)
Block(9,10,-5,HARD_CLAY)
Block(9,10,-3,HARD_CLAY)
Block(9,11,-12,HARD_CLAY)
Block(9,11,-11,HARD_CLAY)
Block(9,11,-10,HARD_CLAY)
Block(9,11,-9,HARD_CLAY)
Block(9,11,-8,HARD_CLAY)
Block(9,11,-7,HARD_CLAY)
Block(9,11,-6,HARD_CLAY)
Block(9,11,-5,HARD_CLAY)
Block(9,11,-3,HARD_CLAY)
Block(9,12,-12,HARD_CLAY)
Block(9,12,-11,HARD_CLAY)
Block(9,12,-9,HARD_CLAY)
Block(9,12,-8,HARD_CLAY)
Block(9,12,-7,HARD_CLAY)
Block(9,12,-6,HARD_CLAY)
Block(9,12,-5,HARD_CLAY)
Block(9,13,-12,HARD_CLAY)
Block(9,13,-9,HARD_CLAY)
Block(9,13,-8,HARD_CLAY)
Block(9,13,-7,HARD_CLAY)
Block(9,13,-6,HARD_CLAY)
Block(9,13,-5,HARD_CLAY)
Block(9,14,-12,HARD_CLAY)
Block(9,14,-9,HARD_CLAY)
Block(9,14,-8,HARD_CLAY)
Block(9,14,-7,HARD_CLAY)
Block(9,14,-6,HARD_CLAY)
Block(9,14,-5,HARD_CLAY)
Block(9,15,-9,HARD_CLAY)
Block(9,15,-8,HARD_CLAY)
Block(9,15,-7,HARD_CLAY)
Block(9,15,-6,HARD_CLAY)
Block(9,16,-8,HARD_CLAY)
Block(9,16,-7,HARD_CLAY)
Block(9,16,-6,HARD_CLAY)
Block(9,17,-8,HARD_CLAY)
Block(9,17,-7,HARD_CLAY)
Block(9,18,-7,HARD_CLAY)
Block(9,19,-7,HARD_CLAY)
Block(9,20,-7,HARD_CLAY)
Block(9,21,-7,HARD_CLAY)
Block(9,22,-7,HARD_CLAY)
Block(9,23,-7,HARD_CLAY)
Block(9,24,-7,HARD_CLAY)
Block(9,25,-7,HARD_CLAY)
Block(9,26,-7,HARD_CLAY)
Block(9,27,-7,HARD_CLAY)
Block(10,0,-14,HARD_CLAY)
Block(10,0,-13,HARD_CLAY)
Block(10,0,-12,HARD_CLAY)
Block(10,0,-11,HARD_CLAY)
Block(10,0,-10,HARD_CLAY)
Block(10,0,-9,HARD_CLAY)
Block(10,0,-8,HARD_CLAY)
Block(10,0,-7,HARD_CLAY)
Block(10,0,-6,HARD_CLAY)
Block(10,0,-5,HARD_CLAY)
Block(10,0,-4,HARD_CLAY)
Block(10,0,-3,HARD_CLAY)
Block(10,0,-2,HARD_CLAY)
Block(10,1,-14,HARD_CLAY)
Block(10,1,-13,HARD_CLAY)
Block(10,1,-12,HARD_CLAY)
Block(10,1,-11,HARD_CLAY)
Block(10,1,-10,HARD_CLAY)
Block(10,1,-9,HARD_CLAY)
Block(10,1,-8,HARD_CLAY)
Block(10,1,-7,HARD_CLAY)
Block(10,1,-6,HARD_CLAY)
Block(10,1,-5,HARD_CLAY)
Block(10,1,-4,HARD_CLAY)
Block(10,1,-3,HARD_CLAY)
Block(10,1,-2,HARD_CLAY)
Block(10,2,-13,HARD_CLAY)
Block(10,2,-12,HARD_CLAY)
Block(10,2,-11,HARD_CLAY)
Block(10,2,-10,HARD_CLAY)
Block(10,2,-9,HARD_CLAY)
Block(10,2,-8,HARD_CLAY)
Block(10,2,-7,HARD_CLAY)
Block(10,2,-6,HARD_CLAY)
Block(10,2,-5,HARD_CLAY)
Block(10,2,-4,HARD_CLAY)
Block(10,2,-3,HARD_CLAY)
Block(10,3,-13,HARD_CLAY)
Block(10,3,-12,HARD_CLAY)
Block(10,3,-11,HARD_CLAY)
Block(10,3,-10,HARD_CLAY)
Block(10,3,-9,HARD_CLAY)
Block(10,3,-8,HARD_CLAY)
Block(10,3,-7,HARD_CLAY)
Block(10,3,-6,HARD_CLAY)
Block(10,3,-5,HARD_CLAY)
Block(10,3,-4,HARD_CLAY)
Block(10,3,-3,HARD_CLAY)
Block(10,4,-13,HARD_CLAY)
Block(10,4,-12,HARD_CLAY)
Block(10,4,-11,HARD_CLAY)
Block(10,4,-10,HARD_CLAY)
Block(10,4,-9,HARD_CLAY)
Block(10,4,-8,HARD_CLAY)
Block(10,4,-7,HARD_CLAY)
Block(10,4,-6,HARD_CLAY)
Block(10,4,-5,HARD_CLAY)
Block(10,4,-4,HARD_CLAY)
Block(10,5,-13,HARD_CLAY)
Block(10,5,-12,HARD_CLAY)
Block(10,5,-11,HARD_CLAY)
Block(10,5,-10,HARD_CLAY)
Block(10,5,-9,HARD_CLAY)
Block(10,5,-8,HARD_CLAY)
Block(10,5,-7,HARD_CLAY)
Block(10,5,-6,HARD_CLAY)
Block(10,5,-5,HARD_CLAY)
Block(10,5,-4,HARD_CLAY)
Block(10,6,-13,HARD_CLAY)
Block(10,6,-12,HARD_CLAY)
Block(10,6,-11,HARD_CLAY)
Block(10,6,-10,HARD_CLAY)
Block(10,6,-9,HARD_CLAY)
Block(10,6,-8,HARD_CLAY)
Block(10,6,-7,HARD_CLAY)
Block(10,6,-6,HARD_CLAY)
Block(10,6,-5,HARD_CLAY)
Block(10,7,-13,HARD_CLAY)
Block(10,7,-12,HARD_CLAY)
Block(10,7,-11,HARD_CLAY)
Block(10,7,-10,HARD_CLAY)
Block(10,7,-9,HARD_CLAY)
Block(10,7,-8,HARD_CLAY)
Block(10,7,-7,HARD_CLAY)
Block(10,7,-6,HARD_CLAY)
Block(10,7,-5,HARD_CLAY)
Block(10,8,-13,HARD_CLAY)
Block(10,8,-12,HARD_CLAY)
Block(10,8,-11,HARD_CLAY)
Block(10,8,-10,HARD_CLAY)
Block(10,8,-9,HARD_CLAY)
Block(10,8,-8,HARD_CLAY)
Block(10,8,-7,HARD_CLAY)
Block(10,8,-6,HARD_CLAY)
Block(10,8,-5,HARD_CLAY)
Block(10,9,-12,HARD_CLAY)
Block(10,9,-11,HARD_CLAY)
Block(10,9,-10,HARD_CLAY)
Block(10,9,-9,HARD_CLAY)
Block(10,9,-8,HARD_CLAY)
Block(10,9,-7,HARD_CLAY)
Block(10,9,-6,HARD_CLAY)
Block(10,9,-5,HARD_CLAY)
Block(10,10,-12,HARD_CLAY)
Block(10,10,-11,HARD_CLAY)
Block(10,10,-10,HARD_CLAY)
Block(10,10,-9,HARD_CLAY)
Block(10,10,-8,HARD_CLAY)
Block(10,10,-7,HARD_CLAY)
Block(10,10,-6,HARD_CLAY)
Block(10,10,-5,HARD_CLAY)
Block(10,11,-12,HARD_CLAY)
Block(10,11,-11,HARD_CLAY)
Block(10,11,-10,HARD_CLAY)
Block(10,11,-9,HARD_CLAY)
Block(10,11,-8,HARD_CLAY)
Block(10,11,-7,HARD_CLAY)
Block(10,11,-6,HARD_CLAY)
Block(10,11,-5,HARD_CLAY)
Block(10,12,-11,HARD_CLAY)
Block(10,12,-10,HARD_CLAY)
Block(10,12,-9,HARD_CLAY)
Block(10,12,-8,HARD_CLAY)
Block(10,12,-7,HARD_CLAY)
Block(10,12,-6,HARD_CLAY)
Block(10,12,-5,HARD_CLAY)
Block(10,13,-10,HARD_CLAY)
Block(10,13,-9,HARD_CLAY)
Block(10,13,-8,HARD_CLAY)
Block(10,13,-7,HARD_CLAY)
Block(10,13,-6,HARD_CLAY)
Block(10,14,-10,HARD_CLAY)
Block(10,14,-9,HARD_CLAY)
Block(10,14,-8,HARD_CLAY)
Block(10,14,-7,HARD_CLAY)
Block(10,14,-6,HARD_CLAY)
Block(10,15,-8,HARD_CLAY)
Block(10,15,-7,HARD_CLAY)
Block(10,15,-6,HARD_CLAY)
Block(10,16,-8,HARD_CLAY)
Block(10,16,-7,HARD_CLAY)
Block(10,16,-6,HARD_CLAY)
Block(10,17,-8,HARD_CLAY)
Block(10,17,-7,HARD_CLAY)
Block(10,18,-8,HARD_CLAY)
Block(10,18,-7,HARD_CLAY)
Block(10,19,-8,HARD_CLAY)
Block(10,19,-7,HARD_CLAY)
Block(10,20,-7,HARD_CLAY)
Block(10,21,-7,HARD_CLAY)
Block(11,0,-16,HARD_CLAY)
Block(11,0,-15,HARD_CLAY)
Block(11,0,-14,HARD_CLAY)
Block(11,0,-13,HARD_CLAY)
Block(11,0,-12,HARD_CLAY)
Block(11,0,-11,HARD_CLAY)
Block(11,0,-10,HARD_CLAY)
Block(11,0,-9,HARD_CLAY)
Block(11,0,-8,HARD_CLAY)
Block(11,0,-7,HARD_CLAY)
Block(11,0,-6,HARD_CLAY)
Block(11,0,-5,HARD_CLAY)
Block(11,0,-4,HARD_CLAY)
Block(11,0,-3,HARD_CLAY)
Block(11,0,-2,HARD_CLAY)
Block(11,1,-16,HARD_CLAY)
Block(11,1,-15,HARD_CLAY)
Block(11,1,-14,HARD_CLAY)
Block(11,1,-13,HARD_CLAY)
Block(11,1,-12,HARD_CLAY)
Block(11,1,-11,HARD_CLAY)
Block(11,1,-10,HARD_CLAY)
Block(11,1,-9,HARD_CLAY)
Block(11,1,-8,HARD_CLAY)
Block(11,1,-7,HARD_CLAY)
Block(11,1,-6,HARD_CLAY)
Block(11,1,-5,HARD_CLAY)
Block(11,1,-4,HARD_CLAY)
Block(11,1,-3,HARD_CLAY)
Block(11,1,-2,HARD_CLAY)
Block(11,2,-15,HARD_CLAY)
Block(11,2,-14,HARD_CLAY)
Block(11,2,-13,HARD_CLAY)
Block(11,2,-12,HARD_CLAY)
Block(11,2,-11,HARD_CLAY)
Block(11,2,-10,HARD_CLAY)
Block(11,2,-9,HARD_CLAY)
Block(11,2,-8,HARD_CLAY)
Block(11,2,-7,HARD_CLAY)
Block(11,2,-6,HARD_CLAY)
Block(11,2,-5,HARD_CLAY)
Block(11,2,-4,HARD_CLAY)
Block(11,2,-3,HARD_CLAY)
Block(11,2,-2,HARD_CLAY)
Block(11,3,-14,HARD_CLAY)
Block(11,3,-13,HARD_CLAY)
Block(11,3,-12,HARD_CLAY)
Block(11,3,-11,HARD_CLAY)
Block(11,3,-10,HARD_CLAY)
Block(11,3,-9,HARD_CLAY)
Block(11,3,-8,HARD_CLAY)
Block(11,3,-7,HARD_CLAY)
Block(11,3,-6,HARD_CLAY)
Block(11,3,-5,HARD_CLAY)
Block(11,3,-4,HARD_CLAY)
Block(11,3,-3,HARD_CLAY)
Block(11,4,-14,HARD_CLAY)
Block(11,4,-13,HARD_CLAY)
Block(11,4,-12,HARD_CLAY)
Block(11,4,-11,HARD_CLAY)
Block(11,4,-10,HARD_CLAY)
Block(11,4,-9,HARD_CLAY)
Block(11,4,-8,HARD_CLAY)
Block(11,4,-7,HARD_CLAY)
Block(11,4,-6,HARD_CLAY)
Block(11,4,-5,HARD_CLAY)
Block(11,5,-13,HARD_CLAY)
Block(11,5,-12,HARD_CLAY)
Block(11,5,-11,HARD_CLAY)
Block(11,5,-10,HARD_CLAY)
Block(11,5,-9,HARD_CLAY)
Block(11,5,-8,HARD_CLAY)
Block(11,5,-7,HARD_CLAY)
Block(11,5,-6,HARD_CLAY)
Block(11,5,-5,HARD_CLAY)
Block(11,6,-13,HARD_CLAY)
Block(11,6,-12,HARD_CLAY)
Block(11,6,-11,HARD_CLAY)
Block(11,6,-10,HARD_CLAY)
Block(11,6,-9,HARD_CLAY)
Block(11,6,-8,HARD_CLAY)
Block(11,6,-7,HARD_CLAY)
Block(11,6,-6,HARD_CLAY)
Block(11,6,-5,HARD_CLAY)
Block(11,7,-13,HARD_CLAY)
Block(11,7,-12,HARD_CLAY)
Block(11,7,-11,HARD_CLAY)
Block(11,7,-10,HARD_CLAY)
Block(11,7,-9,HARD_CLAY)
Block(11,7,-8,HARD_CLAY)
Block(11,7,-7,HARD_CLAY)
Block(11,7,-6,HARD_CLAY)
Block(11,7,-5,HARD_CLAY)
Block(11,8,-13,HARD_CLAY)
Block(11,8,-12,HARD_CLAY)
Block(11,8,-11,HARD_CLAY)
Block(11,8,-10,HARD_CLAY)
Block(11,8,-9,HARD_CLAY)
Block(11,8,-8,HARD_CLAY)
Block(11,8,-7,HARD_CLAY)
Block(11,8,-6,HARD_CLAY)
Block(11,8,-5,HARD_CLAY)
Block(11,9,-13,HARD_CLAY)
Block(11,9,-12,HARD_CLAY)
Block(11,9,-11,HARD_CLAY)
Block(11,9,-10,HARD_CLAY)
Block(11,9,-9,HARD_CLAY)
Block(11,9,-8,HARD_CLAY)
Block(11,9,-7,HARD_CLAY)
Block(11,9,-6,HARD_CLAY)
Block(11,9,-5,HARD_CLAY)
Block(11,10,-12,HARD_CLAY)
Block(11,10,-11,HARD_CLAY)
Block(11,10,-10,HARD_CLAY)
Block(11,10,-9,HARD_CLAY)
Block(11,10,-8,HARD_CLAY)
Block(11,10,-7,HARD_CLAY)
Block(11,10,-6,HARD_CLAY)
Block(11,11,-12,HARD_CLAY)
Block(11,11,-11,HARD_CLAY)
Block(11,11,-10,HARD_CLAY)
Block(11,11,-9,HARD_CLAY)
Block(11,11,-8,HARD_CLAY)
Block(11,11,-7,HARD_CLAY)
Block(11,11,-6,HARD_CLAY)
Block(11,12,-11,HARD_CLAY)
Block(11,12,-10,HARD_CLAY)
Block(11,12,-9,HARD_CLAY)
Block(11,12,-8,HARD_CLAY)
Block(11,12,-7,HARD_CLAY)
Block(11,12,-6,HARD_CLAY)
Block(11,13,-11,HARD_CLAY)
Block(11,13,-10,HARD_CLAY)
Block(11,13,-9,HARD_CLAY)
Block(11,13,-8,HARD_CLAY)
Block(11,13,-7,HARD_CLAY)
Block(11,13,-6,HARD_CLAY)
Block(11,14,-11,HARD_CLAY)
Block(11,14,-10,HARD_CLAY)
Block(11,14,-9,HARD_CLAY)
Block(11,14,-8,HARD_CLAY)
Block(11,14,-7,HARD_CLAY)
Block(11,15,-11,HARD_CLAY)
Block(11,15,-10,HARD_CLAY)
Block(11,15,-8,HARD_CLAY)
Block(11,15,-7,HARD_CLAY)
Block(11,16,-11,HARD_CLAY)
Block(11,16,-10,HARD_CLAY)
Block(11,16,-7,HARD_CLAY)
Block(11,17,-10,HARD_CLAY)
Block(11,17,-7,HARD_CLAY)
Block(11,18,-10,HARD_CLAY)
Block(12,0,-18,HARD_CLAY)
Block(12,0,-17,HARD_CLAY)
Block(12,0,-16,HARD_CLAY)
Block(12,0,-15,HARD_CLAY)
Block(12,0,-14,HARD_CLAY)
Block(12,0,-13,HARD_CLAY)
Block(12,0,-12,HARD_CLAY)
Block(12,0,-11,HARD_CLAY)
Block(12,0,-10,HARD_CLAY)
Block(12,0,-9,HARD_CLAY)
Block(12,0,-8,HARD_CLAY)
Block(12,0,-7,HARD_CLAY)
Block(12,0,-6,HARD_CLAY)
Block(12,0,-5,HARD_CLAY)
Block(12,0,-4,HARD_CLAY)
Block(12,0,-3,HARD_CLAY)
Block(12,1,-16,HARD_CLAY)
Block(12,1,-15,HARD_CLAY)
Block(12,1,-14,HARD_CLAY)
Block(12,1,-13,HARD_CLAY)
Block(12,1,-12,HARD_CLAY)
Block(12,1,-11,HARD_CLAY)
Block(12,1,-10,HARD_CLAY)
Block(12,1,-9,HARD_CLAY)
Block(12,1,-8,HARD_CLAY)
Block(12,1,-7,HARD_CLAY)
Block(12,1,-6,HARD_CLAY)
Block(12,1,-5,HARD_CLAY)
Block(12,1,-4,HARD_CLAY)
Block(12,1,-3,HARD_CLAY)
Block(12,2,-16,HARD_CLAY)
Block(12,2,-15,HARD_CLAY)
Block(12,2,-14,HARD_CLAY)
Block(12,2,-13,HARD_CLAY)
Block(12,2,-12,HARD_CLAY)
Block(12,2,-11,HARD_CLAY)
Block(12,2,-10,HARD_CLAY)
Block(12,2,-9,HARD_CLAY)
Block(12,2,-8,HARD_CLAY)
Block(12,2,-7,HARD_CLAY)
Block(12,2,-6,HARD_CLAY)
Block(12,2,-5,HARD_CLAY)
Block(12,2,-4,HARD_CLAY)
Block(12,3,-16,HARD_CLAY)
Block(12,3,-15,HARD_CLAY)
Block(12,3,-14,HARD_CLAY)
Block(12,3,-13,HARD_CLAY)
Block(12,3,-12,HARD_CLAY)
Block(12,3,-11,HARD_CLAY)
Block(12,3,-10,HARD_CLAY)
Block(12,3,-9,HARD_CLAY)
Block(12,3,-8,HARD_CLAY)
Block(12,3,-7,HARD_CLAY)
Block(12,3,-6,HARD_CLAY)
Block(12,3,-5,HARD_CLAY)
Block(12,4,-16,HARD_CLAY)
Block(12,4,-15,HARD_CLAY)
Block(12,4,-14,HARD_CLAY)
Block(12,4,-13,HARD_CLAY)
Block(12,4,-12,HARD_CLAY)
Block(12,4,-11,HARD_CLAY)
Block(12,4,-10,HARD_CLAY)
Block(12,4,-9,HARD_CLAY)
Block(12,4,-8,HARD_CLAY)
Block(12,4,-7,HARD_CLAY)
Block(12,4,-6,HARD_CLAY)
Block(12,4,-5,HARD_CLAY)
Block(12,5,-13,HARD_CLAY)
Block(12,5,-12,HARD_CLAY)
Block(12,5,-11,HARD_CLAY)
Block(12,5,-10,HARD_CLAY)
Block(12,5,-9,HARD_CLAY)
Block(12,5,-8,HARD_CLAY)
Block(12,5,-7,HARD_CLAY)
Block(12,5,-6,HARD_CLAY)
Block(12,5,-5,HARD_CLAY)
Block(12,6,-13,HARD_CLAY)
Block(12,6,-12,HARD_CLAY)
Block(12,6,-11,HARD_CLAY)
Block(12,6,-10,HARD_CLAY)
Block(12,6,-9,HARD_CLAY)
Block(12,6,-8,HARD_CLAY)
Block(12,6,-7,HARD_CLAY)
Block(12,6,-6,HARD_CLAY)
Block(12,6,-5,HARD_CLAY)
Block(12,7,-13,HARD_CLAY)
Block(12,7,-12,HARD_CLAY)
Block(12,7,-11,HARD_CLAY)
Block(12,7,-10,HARD_CLAY)
Block(12,7,-9,HARD_CLAY)
Block(12,7,-8,HARD_CLAY)
Block(12,7,-7,HARD_CLAY)
Block(12,7,-6,HARD_CLAY)
Block(12,7,-5,HARD_CLAY)
Block(12,8,-12,HARD_CLAY)
Block(12,8,-11,HARD_CLAY)
Block(12,8,-10,HARD_CLAY)
Block(12,8,-9,HARD_CLAY)
Block(12,8,-8,HARD_CLAY)
Block(12,8,-7,HARD_CLAY)
Block(12,8,-6,HARD_CLAY)
Block(12,8,-5,HARD_CLAY)
Block(12,9,-11,HARD_CLAY)
Block(12,9,-10,HARD_CLAY)
Block(12,9,-9,HARD_CLAY)
Block(12,9,-8,HARD_CLAY)
Block(12,9,-7,HARD_CLAY)
Block(12,9,-6,HARD_CLAY)
Block(12,9,-5,HARD_CLAY)
Block(12,10,-11,HARD_CLAY)
Block(12,10,-10,HARD_CLAY)
Block(12,10,-9,HARD_CLAY)
Block(12,10,-8,HARD_CLAY)
Block(12,10,-7,HARD_CLAY)
Block(12,10,-6,HARD_CLAY)
Block(12,11,-11,HARD_CLAY)
Block(12,11,-10,HARD_CLAY)
Block(12,11,-9,HARD_CLAY)
Block(12,11,-8,HARD_CLAY)
Block(12,11,-7,HARD_CLAY)
Block(12,11,-6,HARD_CLAY)
Block(12,12,-11,HARD_CLAY)
Block(12,12,-10,HARD_CLAY)
Block(12,12,-9,HARD_CLAY)
