#######################################################################
# +-----------------------------------------------------------------+ #
# |                            BO3 object                           | #
# +-----------------------------------------------------------------+ #
#######################################################################

# The descriptions in this file are accurate only for TerrainControl and OTG.
# For MCW and OTG+ these descriptions are only accurate if the BO3 is used as a CustomObject.
# MCW and OTG+ completely reimplemented CustomStructure, check the MCW/OTG+ documentation for more information.

# This is the config file of a custom object.
# If you add this object correctly to your BiomeConfigs, it will spawn in the world.

# This is the creator of this BO3 object
Author: Unknown

# A short description of this BO3 object
Description: This BO3 was converted from a schematic using OTGEdit. The author and description information of the schematic could not be found. If you know who the author of the schematic is then please add this information.

# The BO3 version, don't change this! It can be used by external applications to do a version check.
Version: 3

# The settings mode, WriteAll, WriteWithoutComments or WriteDisable. See WorldConfig.
SettingsMode: WriteDisable

#######################################################################
# +-----------------------------------------------------------------+ #
# |                          Main settings                          | #
# +-----------------------------------------------------------------+ #
#######################################################################

# This needs to be set to true to spawn the object in the Tree and Sapling resources.
Tree: false

# The frequency of the BO3 from 1 to 200. Tries this many times to spawn this BO3 when using the CustomObject(...) resource.
# Ignored by Tree(..), Sapling(..) and CustomStructure(..)
Frequency: 1

# The rarity of the BO3 from 0 to 100. Each spawn attempt has rarity% chance to succeed when using the CustomObject(...) resource.
# Ignored by Tree(..), Sapling(..) and CustomStructure(..)
Rarity: 0.5

# If you set this to true, the BO3 will be placed with a random rotation.
RotateRandomly: true

# The spawn height of the BO3 - randomY, highestBlock or highestSolidBlock.
SpawnHeight: highestSolidBlock

# The offset from the spawn height to spawn this BO3
# Ex. SpawnHeight = highestSolidBlock, SpawnHeightOffset = 3; This object will spawn 3 blocks above the highest solid block
SpawnHeightOffset: 0

# A random amount to offset the spawn location from the spawn offset height
# Ex. SpawnHeightOffset = 3, SpawnHeightVariance = 3; This object will spawn 3 to 6 blocks above the original spot it would have spawned
SpawnHeightVariance: 0

# The height limits for the BO3.
MinHeight: 0

MaxHeight: 100

# The style of extrusion you wish to use - BottomDown, TopUp, None (Default)
ExtrudeMode: BottomDown

# The blocks to extrude your BO3 through
ExtrudeThroughBlocks: AIR

# Objects can have other objects attached to it: branches. Branches can also
# have branches attached to it, which can also have branches, etc. This is the
# maximum branch depth for this objects.
MaxBranchDepth: 10

# When spawned with the UseWorld keyword, this BO3 should NOT spawn in the following biomes.
# If you writer.write the BO3 name directly in the BiomeConfigs, this will be ignored.
ExcludedBiomes: All

# To optimise this BO3 for faster loading times you can use Notepad++ to find/replace comments and abbreviate things.
# Notepad++ find/replace with regex:
# Find: ^[#;].* replace to nothing removes all lines starting with # 
# Find: ^\s*$ replace to nothing removes most empty lines 
# Notepad++ find/replace without regex:
# *Warning: This will only work for OTG 1.10.2 v21 / OTG 1.11.2 v6 or higher. B( is not recognised by lower versions.
# Find: Block( replace to B(

#######################################################################
# +-----------------------------------------------------------------+ #
# |                      Source block settings                      | #
# +-----------------------------------------------------------------+ #
#######################################################################

# The block(s) the BO3 should spawn in.
SourceBlocks: AIR,SAND,HARD_CLAY,STAINED_CLAY,GRAVEL,STONE,GRASS,DIRT

# The maximum percentage of the BO3 that can be outside the SourceBlock.
# The BO3 won't be placed on a location with more blocks outside the SourceBlock than this percentage.
MaxPercentageOutsideSourceBlock: 0

# What to do when a block is about to be placed outside the SourceBlock? (dontPlace, placeAnyway)
OutsideSourceBlock: placeAnyway

#######################################################################
# +-----------------------------------------------------------------+ #
# |                              Blocks                             | #
# +-----------------------------------------------------------------+ #
#######################################################################

# All the blocks used in the BO3 are listed here. Possible blocks:
# Block(x,y,z,id[.data][,nbtfile.nbt) or B(x,y,z,id[.data][,nbtfile.nbt)
# RandomBlock(x,y,z,id[:data][,nbtfile.nbt],chance[,id[:data][,nbtfile.nbt],chance[,...]])
# So RandomBlock(0,0,0,CHEST,chest.nbt,50,CHEST,anotherchest.nbt,100) will spawn a chest at
# the BO3 origin, and give it a 50% chance to have the contents of chest.nbt, or, if that
# fails, a 100% percent chance to have the contents of anotherchest.nbt.

Block(-7,0,-2,172)
Block(-7,0,-1,172)
Block(-7,0,0,172)
Block(-7,0,1,172)
Block(-7,0,2,172)
Block(-7,0,3,172)
Block(-7,0,4,172)
Block(-7,1,0,172)
Block(-7,1,1,172)
Block(-7,1,2,172)
Block(-7,1,3,172)
Block(-7,2,1,172)
Block(-7,2,2,172)
Block(-6,0,-5,172)
Block(-6,0,-4,172)
Block(-6,0,-3,172)
Block(-6,0,-2,172)
Block(-6,0,-1,172)
Block(-6,0,0,172)
Block(-6,0,1,172)
Block(-6,0,2,172)
Block(-6,0,3,172)
Block(-6,0,4,172)
Block(-6,0,5,172)
Block(-6,0,6,172)
Block(-6,0,7,172)
Block(-6,1,-5,172)
Block(-6,1,-4,172)
Block(-6,1,-3,172)
Block(-6,1,-2,172)
Block(-6,1,-1,172)
Block(-6,1,0,172)
Block(-6,1,1,172)
Block(-6,1,2,172)
Block(-6,1,3,172)
Block(-6,1,4,172)
Block(-6,1,5,172)
Block(-6,2,-4,172)
Block(-6,2,-3,172)
Block(-6,2,-2,172)
Block(-6,2,-1,172)
Block(-6,2,0,172)
Block(-6,2,1,172)
Block(-6,2,2,172)
Block(-6,2,3,172)
Block(-6,2,4,172)
Block(-6,3,-3,172)
Block(-6,3,-2,172)
Block(-6,3,-1,172)
Block(-6,3,0,172)
Block(-6,3,1,172)
Block(-6,4,-1,172)
Block(-6,4,0,172)
Block(-6,5,-1,172)
Block(-6,6,-1,172)
Block(-5,0,-6,172)
Block(-5,0,-5,172)
Block(-5,0,-4,172)
Block(-5,0,-3,172)
Block(-5,0,-2,172)
Block(-5,0,-1,172)
Block(-5,0,0,172)
Block(-5,0,1,172)
Block(-5,0,2,172)
Block(-5,0,3,172)
Block(-5,0,4,172)
Block(-5,0,5,172)
Block(-5,0,6,172)
Block(-5,0,7,172)
Block(-5,0,8,172)
Block(-5,1,-5,172)
Block(-5,1,-4,172)
Block(-5,1,-3,172)
Block(-5,1,-2,172)
Block(-5,1,-1,172)
Block(-5,1,0,172)
Block(-5,1,1,172)
Block(-5,1,2,172)
Block(-5,1,3,172)
Block(-5,1,4,172)
Block(-5,1,5,172)
Block(-5,1,6,172)
Block(-5,1,7,172)
Block(-5,2,-4,172)
Block(-5,2,-3,172)
Block(-5,2,-2,172)
Block(-5,2,-1,172)
Block(-5,2,0,172)
Block(-5,2,1,172)
Block(-5,2,2,172)
Block(-5,2,3,172)
Block(-5,2,4,172)
Block(-5,2,5,172)
Block(-5,2,6,172)
Block(-5,3,-4,172)
Block(-5,3,-3,172)
Block(-5,3,-2,172)
Block(-5,3,-1,172)
Block(-5,3,0,172)
Block(-5,3,1,172)
Block(-5,3,2,172)
Block(-5,3,3,172)
Block(-5,3,4,172)
Block(-5,3,5,172)
Block(-5,4,-3,172)
Block(-5,4,-2,172)
Block(-5,4,-1,172)
Block(-5,4,0,172)
Block(-5,4,1,172)
Block(-5,4,2,172)
Block(-5,4,3,172)
Block(-5,4,4,172)
Block(-5,4,5,172)
Block(-5,5,-2,172)
Block(-5,5,-1,172)
Block(-5,5,0,172)
Block(-5,5,1,172)
Block(-5,5,2,172)
Block(-5,5,3,172)
Block(-5,5,4,172)
Block(-5,5,5,172)
Block(-5,6,-2,172)
Block(-5,6,-1,172)
Block(-5,6,0,172)
Block(-5,6,1,172)
Block(-5,6,2,172)
Block(-5,6,3,172)
Block(-5,6,4,172)
Block(-5,6,5,172)
Block(-5,7,-2,172)
Block(-5,7,-1,172)
Block(-5,7,0,172)
Block(-5,7,1,172)
Block(-5,7,2,172)
Block(-5,7,3,172)
Block(-5,7,4,172)
Block(-5,7,5,172)
Block(-5,8,-1,172)
Block(-5,8,0,172)
Block(-5,8,1,172)
Block(-5,8,2,172)
Block(-5,8,3,172)
Block(-5,8,4,172)
Block(-5,8,5,172)
Block(-5,9,-1,172)
Block(-5,9,0,172)
Block(-5,9,1,172)
Block(-5,9,2,172)
Block(-5,9,3,172)
Block(-5,9,4,172)
Block(-5,9,5,172)
Block(-5,10,-1,172)
Block(-5,10,0,172)
Block(-5,10,1,172)
Block(-5,10,2,172)
Block(-5,10,3,172)
Block(-5,10,4,172)
Block(-5,10,5,172)
Block(-5,11,-1,172)
Block(-5,11,0,172)
Block(-5,11,1,172)
Block(-5,11,2,172)
Block(-5,11,3,172)
Block(-5,11,4,172)
Block(-5,11,5,172)
Block(-5,12,-1,172)
Block(-5,12,0,172)
Block(-5,12,1,172)
Block(-5,12,2,172)
Block(-5,12,3,172)
Block(-5,12,4,172)
Block(-5,13,-1,172)
Block(-5,13,0,172)
Block(-5,13,1,172)
Block(-5,13,2,172)
Block(-5,13,3,172)
Block(-5,13,4,172)
Block(-5,14,1,172)
Block(-5,14,2,172)
Block(-5,14,3,172)
Block(-5,14,4,172)
Block(-4,0,-7,172)
Block(-4,0,-6,172)
Block(-4,0,-5,172)
Block(-4,0,-4,172)
Block(-4,0,-3,172)
Block(-4,0,-2,172)
Block(-4,0,-1,172)
Block(-4,0,0,172)
Block(-4,0,1,172)
Block(-4,0,2,172)
Block(-4,0,3,172)
Block(-4,0,4,172)
Block(-4,0,5,172)
Block(-4,0,6,172)
Block(-4,0,7,172)
Block(-4,0,8,172)
Block(-4,1,-6,172)
Block(-4,1,-5,172)
Block(-4,1,-4,172)
Block(-4,1,-3,172)
Block(-4,1,-2,172)
Block(-4,1,-1,172)
Block(-4,1,0,172)
Block(-4,1,1,172)
Block(-4,1,2,172)
Block(-4,1,3,172)
Block(-4,1,4,172)
Block(-4,1,5,172)
Block(-4,1,6,172)
Block(-4,1,7,172)
Block(-4,1,8,172)
Block(-4,2,-5,172)
Block(-4,2,-4,172)
Block(-4,2,-3,172)
Block(-4,2,-2,172)
Block(-4,2,-1,172)
Block(-4,2,0,172)
Block(-4,2,1,172)
Block(-4,2,2,172)
Block(-4,2,3,172)
Block(-4,2,4,172)
Block(-4,2,5,172)
Block(-4,2,6,172)
Block(-4,2,7,172)
Block(-4,3,-4,172)
Block(-4,3,-3,172)
Block(-4,3,-2,172)
Block(-4,3,-1,172)
Block(-4,3,0,172)
Block(-4,3,1,172)
Block(-4,3,2,172)
Block(-4,3,3,172)
Block(-4,3,4,172)
Block(-4,3,5,172)
Block(-4,3,6,172)
Block(-4,4,-4,172)
Block(-4,4,-3,172)
Block(-4,4,-2,172)
Block(-4,4,-1,172)
Block(-4,4,0,172)
Block(-4,4,1,172)
Block(-4,4,2,172)
Block(-4,4,3,172)
Block(-4,4,4,172)
Block(-4,4,5,172)
Block(-4,4,6,172)
Block(-4,5,-3,172)
Block(-4,5,-2,172)
Block(-4,5,-1,172)
Block(-4,5,0,172)
Block(-4,5,1,172)
Block(-4,5,2,172)
Block(-4,5,3,172)
Block(-4,5,4,172)
Block(-4,5,5,172)
Block(-4,5,6,172)
Block(-4,6,-3,172)
Block(-4,6,-2,172)
Block(-4,6,-1,172)
Block(-4,6,0,172)
Block(-4,6,1,172)
Block(-4,6,2,172)
Block(-4,6,3,172)
Block(-4,6,4,172)
Block(-4,6,5,172)
Block(-4,6,6,172)
Block(-4,7,-3,172)
Block(-4,7,-2,172)
Block(-4,7,-1,172)
Block(-4,7,0,172)
Block(-4,7,1,172)
Block(-4,7,2,172)
Block(-4,7,3,172)
Block(-4,7,4,172)
Block(-4,7,5,172)
Block(-4,7,6,172)
Block(-4,8,-3,172)
Block(-4,8,-2,172)
Block(-4,8,-1,172)
Block(-4,8,0,172)
Block(-4,8,1,172)
Block(-4,8,2,172)
Block(-4,8,3,172)
Block(-4,8,4,172)
Block(-4,8,5,172)
Block(-4,8,6,172)
Block(-4,9,-2,172)
Block(-4,9,-1,172)
Block(-4,9,0,172)
Block(-4,9,1,172)
Block(-4,9,2,172)
Block(-4,9,3,172)
Block(-4,9,4,172)
Block(-4,9,5,172)
Block(-4,9,6,172)
Block(-4,10,-2,172)
Block(-4,10,-1,172)
Block(-4,10,0,172)
Block(-4,10,1,172)
Block(-4,10,2,172)
Block(-4,10,3,172)
Block(-4,10,4,172)
Block(-4,10,5,172)
Block(-4,10,6,172)
Block(-4,11,-2,172)
Block(-4,11,-1,172)
Block(-4,11,0,172)
Block(-4,11,1,172)
Block(-4,11,2,172)
Block(-4,11,3,172)
Block(-4,11,4,172)
Block(-4,11,5,172)
Block(-4,11,6,172)
Block(-4,12,-2,172)
Block(-4,12,-1,172)
Block(-4,12,0,172)
Block(-4,12,1,172)
Block(-4,12,2,172)
Block(-4,12,3,172)
Block(-4,12,4,172)
Block(-4,12,5,172)
Block(-4,12,6,172)
Block(-4,13,-2,172)
Block(-4,13,-1,172)
Block(-4,13,0,172)
Block(-4,13,1,172)
Block(-4,13,2,172)
Block(-4,13,3,172)
Block(-4,13,4,172)
Block(-4,13,5,172)
Block(-4,13,6,172)
Block(-4,14,-1,172)
Block(-4,14,0,172)
Block(-4,14,1,172)
Block(-4,14,2,172)
Block(-4,14,3,172)
Block(-4,14,4,172)
Block(-4,14,5,172)
Block(-4,14,6,172)
Block(-4,15,0,172)
Block(-4,15,1,172)
Block(-4,15,2,172)
Block(-4,15,3,172)
Block(-4,15,4,172)
Block(-4,15,5,172)
Block(-4,16,0,172)
Block(-4,16,1,172)
Block(-4,16,2,172)
Block(-4,16,3,172)
Block(-4,16,4,172)
Block(-4,16,5,172)
Block(-4,17,0,172)
Block(-4,17,1,172)
Block(-4,17,2,172)
Block(-4,17,3,172)
Block(-4,17,4,172)
Block(-4,17,5,172)
Block(-4,18,0,172)
Block(-4,18,1,172)
Block(-4,18,2,172)
Block(-4,18,3,172)
Block(-4,18,4,172)
Block(-4,18,5,172)
Block(-4,19,0,172)
Block(-4,19,1,172)
Block(-4,19,2,172)
Block(-4,19,3,172)
Block(-4,19,4,172)
Block(-4,19,5,172)
Block(-4,20,0,172)
Block(-4,20,1,172)
Block(-4,20,2,172)
Block(-4,20,3,172)
Block(-4,20,4,172)
Block(-4,20,5,172)
Block(-4,21,1,172)
Block(-4,21,2,172)
Block(-4,21,3,172)
Block(-3,0,-7,172)
Block(-3,0,-6,172)
Block(-3,0,-5,172)
Block(-3,0,-4,172)
Block(-3,0,-3,172)
Block(-3,0,-2,172)
Block(-3,0,-1,172)
Block(-3,0,0,172)
Block(-3,0,1,172)
Block(-3,0,2,172)
Block(-3,0,3,172)
Block(-3,0,4,172)
Block(-3,0,5,172)
Block(-3,0,6,172)
Block(-3,0,7,172)
Block(-3,0,8,172)
Block(-3,1,-6,172)
Block(-3,1,-5,172)
Block(-3,1,-4,172)
Block(-3,1,-3,172)
Block(-3,1,-2,172)
Block(-3,1,-1,172)
Block(-3,1,0,172)
Block(-3,1,1,172)
Block(-3,1,2,172)
Block(-3,1,3,172)
Block(-3,1,4,172)
Block(-3,1,5,172)
Block(-3,1,6,172)
Block(-3,1,7,172)
Block(-3,1,8,172)
Block(-3,2,-6,172)
Block(-3,2,-5,172)
Block(-3,2,-4,172)
Block(-3,2,-3,172)
Block(-3,2,-2,172)
Block(-3,2,-1,172)
Block(-3,2,0,172)
Block(-3,2,1,172)
Block(-3,2,2,172)
Block(-3,2,3,172)
Block(-3,2,4,172)
Block(-3,2,5,172)
Block(-3,2,6,172)
Block(-3,2,7,172)
Block(-3,3,-5,172)
Block(-3,3,-4,172)
Block(-3,3,-3,172)
Block(-3,3,-2,172)
Block(-3,3,-1,172)
Block(-3,3,0,172)
Block(-3,3,1,172)
Block(-3,3,2,172)
Block(-3,3,3,172)
Block(-3,3,4,172)
Block(-3,3,5,172)
Block(-3,3,6,172)
Block(-3,4,-5,172)
Block(-3,4,-4,172)
Block(-3,4,-3,172)
Block(-3,4,-2,172)
Block(-3,4,-1,172)
Block(-3,4,0,172)
Block(-3,4,1,172)
Block(-3,4,2,172)
Block(-3,4,3,172)
Block(-3,4,4,172)
Block(-3,4,5,172)
Block(-3,4,6,172)
Block(-3,5,-5,172)
Block(-3,5,-4,172)
Block(-3,5,-3,172)
Block(-3,5,-2,172)
Block(-3,5,-1,172)
Block(-3,5,0,172)
Block(-3,5,1,172)
Block(-3,5,2,172)
Block(-3,5,3,172)
Block(-3,5,4,172)
Block(-3,5,5,172)
Block(-3,5,6,172)
Block(-3,6,-5,172)
Block(-3,6,-4,172)
Block(-3,6,-3,172)
Block(-3,6,-2,172)
Block(-3,6,-1,172)
Block(-3,6,0,172)
Block(-3,6,1,172)
Block(-3,6,2,172)
Block(-3,6,3,172)
Block(-3,6,4,172)
Block(-3,6,5,172)
Block(-3,6,6,172)
Block(-3,7,-4,172)
Block(-3,7,-3,172)
Block(-3,7,-2,172)
Block(-3,7,-1,172)
Block(-3,7,0,172)
Block(-3,7,1,172)
Block(-3,7,2,172)
Block(-3,7,3,172)
Block(-3,7,4,172)
Block(-3,7,5,172)
Block(-3,7,6,172)
Block(-3,8,-4,172)
Block(-3,8,-3,172)
Block(-3,8,-2,172)
Block(-3,8,-1,172)
Block(-3,8,0,172)
Block(-3,8,1,172)
Block(-3,8,2,172)
Block(-3,8,3,172)
Block(-3,8,4,172)
Block(-3,8,5,172)
Block(-3,8,6,172)
Block(-3,9,-3,172)
Block(-3,9,-2,172)
Block(-3,9,-1,172)
Block(-3,9,0,172)
Block(-3,9,1,172)
Block(-3,9,2,172)
Block(-3,9,3,172)
Block(-3,9,4,172)
Block(-3,9,5,172)
Block(-3,9,6,172)
Block(-3,10,-3,172)
Block(-3,10,-2,172)
Block(-3,10,-1,172)
Block(-3,10,0,172)
Block(-3,10,1,172)
Block(-3,10,2,172)
Block(-3,10,3,172)
Block(-3,10,4,172)
Block(-3,10,5,172)
Block(-3,10,6,172)
Block(-3,11,-2,172)
Block(-3,11,-1,172)
Block(-3,11,0,172)
Block(-3,11,1,172)
Block(-3,11,2,172)
Block(-3,11,3,172)
Block(-3,11,4,172)
Block(-3,11,5,172)
Block(-3,11,6,172)
Block(-3,12,-2,172)
Block(-3,12,-1,172)
Block(-3,12,0,172)
Block(-3,12,1,172)
Block(-3,12,2,172)
Block(-3,12,3,172)
Block(-3,12,4,172)
Block(-3,12,5,172)
Block(-3,12,6,172)
Block(-3,13,-2,172)
Block(-3,13,-1,172)
Block(-3,13,0,172)
Block(-3,13,1,172)
Block(-3,13,2,172)
Block(-3,13,3,172)
Block(-3,13,4,172)
Block(-3,13,5,172)
Block(-3,13,6,172)
Block(-3,14,-2,172)
Block(-3,14,-1,172)
Block(-3,14,0,172)
Block(-3,14,1,172)
Block(-3,14,2,172)
Block(-3,14,3,172)
Block(-3,14,4,172)
Block(-3,14,5,172)
Block(-3,14,6,172)
Block(-3,15,-1,172)
Block(-3,15,0,172)
Block(-3,15,1,172)
Block(-3,15,2,172)
Block(-3,15,3,172)
Block(-3,15,4,172)
Block(-3,15,5,172)
Block(-3,15,6,172)
Block(-3,16,-1,172)
Block(-3,16,0,172)
Block(-3,16,1,172)
Block(-3,16,2,172)
Block(-3,16,3,172)
Block(-3,16,4,172)
Block(-3,16,5,172)
Block(-3,16,6,172)
Block(-3,17,-1,172)
Block(-3,17,0,172)
Block(-3,17,1,172)
Block(-3,17,2,172)
Block(-3,17,3,172)
Block(-3,17,4,172)
Block(-3,17,5,172)
Block(-3,18,-1,172)
Block(-3,18,0,172)
Block(-3,18,1,172)
Block(-3,18,2,172)
Block(-3,18,3,172)
Block(-3,18,4,172)
Block(-3,18,5,172)
Block(-3,19,-1,172)
Block(-3,19,0,172)
Block(-3,19,1,172)
Block(-3,19,2,172)
Block(-3,19,3,172)
Block(-3,19,4,172)
Block(-3,19,5,172)
Block(-3,20,-1,172)
Block(-3,20,0,172)
Block(-3,20,1,172)
Block(-3,20,2,172)
Block(-3,20,3,172)
Block(-3,20,4,172)
Block(-3,20,5,172)
Block(-3,21,-1,172)
Block(-3,21,0,172)
Block(-3,21,1,172)
Block(-3,21,2,172)
Block(-3,21,3,172)
Block(-3,21,4,172)
Block(-3,21,5,172)
Block(-3,22,1,172)
Block(-3,22,2,172)
Block(-3,23,1,172)
Block(-3,23,2,172)
Block(-3,24,1,172)
Block(-3,24,2,172)
Block(-3,25,1,172)
Block(-3,26,1,172)
Block(-3,27,1,172)
Block(-3,28,1,172)
Block(-3,29,1,172)
Block(-2,0,-7,172)
Block(-2,0,-6,172)
Block(-2,0,-5,172)
Block(-2,0,-4,172)
Block(-2,0,-3,172)
Block(-2,0,-2,172)
Block(-2,0,-1,172)
Block(-2,0,0,172)
Block(-2,0,1,172)
Block(-2,0,2,172)
Block(-2,0,3,172)
Block(-2,0,4,172)
Block(-2,0,5,172)
Block(-2,0,6,172)
Block(-2,0,7,172)
Block(-2,0,8,172)
Block(-2,0,9,172)
Block(-2,1,-7,172)
Block(-2,1,-6,172)
Block(-2,1,-5,172)
Block(-2,1,-4,172)
Block(-2,1,-3,172)
Block(-2,1,-2,172)
Block(-2,1,-1,172)
Block(-2,1,0,172)
Block(-2,1,1,172)
Block(-2,1,2,172)
Block(-2,1,3,172)
Block(-2,1,4,172)
Block(-2,1,5,172)
Block(-2,1,6,172)
Block(-2,1,7,172)
Block(-2,1,8,172)
Block(-2,2,-6,172)
Block(-2,2,-5,172)
Block(-2,2,-4,172)
Block(-2,2,-3,172)
Block(-2,2,-2,172)
Block(-2,2,-1,172)
Block(-2,2,0,172)
Block(-2,2,1,172)
Block(-2,2,2,172)
Block(-2,2,3,172)
Block(-2,2,4,172)
Block(-2,2,5,172)
Block(-2,2,6,172)
Block(-2,2,7,172)
Block(-2,3,-6,172)
Block(-2,3,-5,172)
Block(-2,3,-4,172)
Block(-2,3,-3,172)
Block(-2,3,-2,172)
Block(-2,3,-1,172)
Block(-2,3,0,172)
Block(-2,3,1,172)
Block(-2,3,2,172)
Block(-2,3,3,172)
Block(-2,3,4,172)
Block(-2,3,5,172)
Block(-2,3,6,172)
Block(-2,3,7,172)
Block(-2,4,-5,172)
Block(-2,4,-4,172)
Block(-2,4,-3,172)
Block(-2,4,-2,172)
Block(-2,4,-1,172)
Block(-2,4,0,172)
Block(-2,4,1,172)
Block(-2,4,2,172)
Block(-2,4,3,172)
Block(-2,4,4,172)
Block(-2,4,5,172)
Block(-2,4,6,172)
Block(-2,5,-5,172)
Block(-2,5,-4,172)
Block(-2,5,-3,172)
Block(-2,5,-2,172)
Block(-2,5,-1,172)
Block(-2,5,0,172)
Block(-2,5,1,172)
Block(-2,5,2,172)
Block(-2,5,3,172)
Block(-2,5,4,172)
Block(-2,5,5,172)
Block(-2,5,6,172)
Block(-2,6,-5,172)
Block(-2,6,-4,172)
Block(-2,6,-3,172)
Block(-2,6,-2,172)
Block(-2,6,-1,172)
Block(-2,6,0,172)
Block(-2,6,1,172)
Block(-2,6,2,172)
Block(-2,6,3,172)
Block(-2,6,4,172)
Block(-2,6,5,172)
Block(-2,6,6,172)
Block(-2,7,-4,172)
Block(-2,7,-3,172)
Block(-2,7,-2,172)
Block(-2,7,-1,172)
Block(-2,7,0,172)
Block(-2,7,1,172)
Block(-2,7,2,172)
Block(-2,7,3,172)
Block(-2,7,4,172)
Block(-2,7,5,172)
Block(-2,8,-3,172)
Block(-2,8,-2,172)
Block(-2,8,-1,172)
Block(-2,8,0,172)
Block(-2,8,1,172)
Block(-2,8,2,172)
Block(-2,8,3,172)
Block(-2,8,4,172)
Block(-2,8,5,172)
Block(-2,9,-2,172)
Block(-2,9,-1,172)
Block(-2,9,0,172)
Block(-2,9,1,172)
Block(-2,9,2,172)
Block(-2,9,3,172)
Block(-2,9,4,172)
Block(-2,9,5,172)
Block(-2,10,-2,172)
Block(-2,10,-1,172)
Block(-2,10,0,172)
Block(-2,10,1,172)
Block(-2,10,2,172)
Block(-2,10,3,172)
Block(-2,10,4,172)
Block(-2,10,5,172)
Block(-2,11,-2,172)
Block(-2,11,-1,172)
Block(-2,11,0,172)
Block(-2,11,1,172)
Block(-2,11,2,172)
Block(-2,11,3,172)
Block(-2,11,4,172)
Block(-2,11,5,172)
Block(-2,12,-2,172)
Block(-2,12,-1,172)
Block(-2,12,0,172)
Block(-2,12,1,172)
Block(-2,12,2,172)
Block(-2,12,3,172)
Block(-2,12,4,172)
Block(-2,12,5,172)
Block(-2,13,-2,172)
Block(-2,13,-1,172)
Block(-2,13,0,172)
Block(-2,13,1,172)
Block(-2,13,2,172)
Block(-2,13,3,172)
Block(-2,13,4,172)
Block(-2,13,5,172)
Block(-2,14,-2,172)
Block(-2,14,-1,172)
Block(-2,14,0,172)
Block(-2,14,1,172)
Block(-2,14,2,172)
Block(-2,14,3,172)
Block(-2,14,4,172)
Block(-2,14,5,172)
Block(-2,15,-1,172)
Block(-2,15,0,172)
Block(-2,15,1,172)
Block(-2,15,2,172)
Block(-2,15,3,172)
Block(-2,15,4,172)
Block(-2,15,5,172)
Block(-2,16,-1,172)
Block(-2,16,0,172)
Block(-2,16,1,172)
Block(-2,16,2,172)
Block(-2,16,3,172)
Block(-2,16,4,172)
Block(-2,16,5,172)
Block(-2,17,-1,172)
Block(-2,17,0,172)
Block(-2,17,1,172)
Block(-2,17,2,172)
Block(-2,17,3,172)
Block(-2,17,4,172)
Block(-2,17,5,172)
Block(-2,18,-1,172)
Block(-2,18,0,172)
Block(-2,18,1,172)
Block(-2,18,2,172)
Block(-2,18,3,172)
Block(-2,18,4,172)
Block(-2,18,5,172)
Block(-2,19,-1,172)
Block(-2,19,0,172)
Block(-2,19,1,172)
Block(-2,19,2,172)
Block(-2,19,3,172)
Block(-2,19,4,172)
Block(-2,19,5,172)
Block(-2,20,-1,172)
Block(-2,20,0,172)
Block(-2,20,1,172)
Block(-2,20,2,172)
Block(-2,20,3,172)
Block(-2,20,4,172)
Block(-2,20,5,172)
Block(-2,21,-1,172)
Block(-2,21,0,172)
Block(-2,21,1,172)
Block(-2,21,2,172)
Block(-2,21,3,172)
Block(-2,21,4,172)
Block(-2,21,5,172)
Block(-2,22,0,172)
Block(-2,22,1,172)
Block(-2,22,2,172)
Block(-2,22,3,172)
Block(-2,23,0,172)
Block(-2,23,1,172)
Block(-2,23,2,172)
Block(-2,23,3,172)
Block(-2,24,0,172)
Block(-2,24,1,172)
Block(-2,24,2,172)
Block(-2,24,3,172)
Block(-2,25,0,172)
Block(-2,25,1,172)
Block(-2,25,2,172)
Block(-2,25,3,172)
Block(-2,26,0,172)
Block(-2,26,1,172)
Block(-2,26,2,172)
Block(-2,26,3,172)
Block(-2,27,0,172)
Block(-2,27,1,172)
Block(-2,27,2,172)
Block(-2,27,3,172)
Block(-2,28,0,172)
Block(-2,28,1,172)
Block(-2,28,2,172)
Block(-2,28,3,172)
Block(-2,29,0,172)
Block(-2,29,1,172)
Block(-2,29,2,172)
Block(-1,0,-6,172)
Block(-1,0,-5,172)
Block(-1,0,-4,172)
Block(-1,0,-3,172)
Block(-1,0,-2,172)
Block(-1,0,-1,172)
Block(-1,0,0,172)
Block(-1,0,1,172)
Block(-1,0,2,172)
Block(-1,0,3,172)
Block(-1,0,4,172)
Block(-1,0,5,172)
Block(-1,0,6,172)
Block(-1,0,7,172)
Block(-1,0,8,172)
Block(-1,0,9,172)
Block(-1,1,-6,172)
Block(-1,1,-5,172)
Block(-1,1,-4,172)
Block(-1,1,-3,172)
Block(-1,1,-2,172)
Block(-1,1,-1,172)
Block(-1,1,0,172)
Block(-1,1,1,172)
Block(-1,1,2,172)
Block(-1,1,3,172)
Block(-1,1,4,172)
Block(-1,1,5,172)
Block(-1,1,6,172)
Block(-1,1,7,172)
Block(-1,1,8,172)
Block(-1,1,9,172)
Block(-1,2,-6,172)
Block(-1,2,-5,172)
Block(-1,2,-4,172)
Block(-1,2,-3,172)
Block(-1,2,-2,172)
Block(-1,2,-1,172)
Block(-1,2,0,172)
Block(-1,2,1,172)
Block(-1,2,2,172)
Block(-1,2,3,172)
Block(-1,2,4,172)
Block(-1,2,5,172)
Block(-1,2,6,172)
Block(-1,2,7,172)
Block(-1,2,8,172)
Block(-1,2,9,172)
Block(-1,3,-5,172)
Block(-1,3,-4,172)
Block(-1,3,-3,172)
Block(-1,3,-2,172)
Block(-1,3,-1,172)
Block(-1,3,0,172)
Block(-1,3,1,172)
Block(-1,3,2,172)
Block(-1,3,3,172)
Block(-1,3,4,172)
Block(-1,3,5,172)
Block(-1,3,6,172)
Block(-1,3,7,172)
Block(-1,3,8,172)
Block(-1,4,-5,172)
Block(-1,4,-4,172)
Block(-1,4,-3,172)
Block(-1,4,-2,172)
Block(-1,4,-1,172)
Block(-1,4,0,172)
Block(-1,4,1,172)
Block(-1,4,2,172)
Block(-1,4,3,172)
Block(-1,4,4,172)
Block(-1,4,5,172)
Block(-1,4,6,172)
Block(-1,4,7,172)
Block(-1,5,-5,172)
Block(-1,5,-4,172)
Block(-1,5,-3,172)
Block(-1,5,-2,172)
Block(-1,5,-1,172)
Block(-1,5,0,172)
Block(-1,5,1,172)
Block(-1,5,2,172)
Block(-1,5,3,172)
Block(-1,5,4,172)
Block(-1,5,5,172)
Block(-1,5,6,172)
Block(-1,5,7,172)
Block(-1,6,-4,172)
Block(-1,6,-3,172)
Block(-1,6,-2,172)
Block(-1,6,-1,172)
Block(-1,6,0,172)
Block(-1,6,1,172)
Block(-1,6,2,172)
Block(-1,6,3,172)
Block(-1,6,4,172)
Block(-1,6,5,172)
Block(-1,6,6,172)
Block(-1,7,-3,172)
Block(-1,7,-2,172)
Block(-1,7,-1,172)
Block(-1,7,0,172)
Block(-1,7,1,172)
Block(-1,7,2,172)
Block(-1,7,3,172)
Block(-1,7,4,172)
Block(-1,7,5,172)
Block(-1,8,-2,172)
Block(-1,8,-1,172)
Block(-1,8,0,172)
Block(-1,8,1,172)
Block(-1,8,2,172)
Block(-1,8,3,172)
Block(-1,8,4,172)
Block(-1,8,5,172)
Block(-1,9,-2,172)
Block(-1,9,-1,172)
Block(-1,9,0,172)
Block(-1,9,1,172)
Block(-1,9,2,172)
Block(-1,9,3,172)
Block(-1,9,4,172)
Block(-1,9,5,172)
Block(-1,10,-2,172)
Block(-1,10,-1,172)
Block(-1,10,0,172)
Block(-1,10,1,172)
Block(-1,10,2,172)
Block(-1,10,3,172)
Block(-1,10,4,172)
Block(-1,10,5,172)
Block(-1,11,-2,172)
Block(-1,11,-1,172)
Block(-1,11,0,172)
Block(-1,11,1,172)
Block(-1,11,2,172)
Block(-1,11,3,172)
Block(-1,11,4,172)
Block(-1,11,5,172)
Block(-1,12,-2,172)
Block(-1,12,-1,172)
Block(-1,12,0,172)
Block(-1,12,1,172)
Block(-1,12,2,172)
Block(-1,12,3,172)
Block(-1,12,4,172)
Block(-1,12,5,172)
Block(-1,13,-2,172)
Block(-1,13,-1,172)
Block(-1,13,0,172)
Block(-1,13,1,172)
Block(-1,13,2,172)
Block(-1,13,3,172)
Block(-1,13,4,172)
Block(-1,13,5,172)
Block(-1,14,-2,172)
Block(-1,14,-1,172)
Block(-1,14,0,172)
Block(-1,14,1,172)
Block(-1,14,2,172)
Block(-1,14,3,172)
Block(-1,14,4,172)
Block(-1,14,5,172)
Block(-1,15,-2,172)
Block(-1,15,-1,172)
Block(-1,15,0,172)
Block(-1,15,1,172)
Block(-1,15,2,172)
Block(-1,15,3,172)
Block(-1,15,4,172)
Block(-1,15,5,172)
Block(-1,16,-2,172)
Block(-1,16,-1,172)
Block(-1,16,0,172)
Block(-1,16,1,172)
Block(-1,16,2,172)
Block(-1,16,3,172)
Block(-1,16,4,172)
Block(-1,16,5,172)
Block(-1,17,-2,172)
Block(-1,17,-1,172)
Block(-1,17,0,172)
Block(-1,17,1,172)
Block(-1,17,2,172)
Block(-1,17,3,172)
Block(-1,17,4,172)
Block(-1,17,5,172)
Block(-1,18,-2,172)
Block(-1,18,-1,172)
Block(-1,18,0,172)
Block(-1,18,1,172)
Block(-1,18,2,172)
Block(-1,18,3,172)
Block(-1,18,4,172)
Block(-1,18,5,172)
Block(-1,19,-2,172)
Block(-1,19,-1,172)
Block(-1,19,0,172)
Block(-1,19,1,172)
Block(-1,19,2,172)
Block(-1,19,3,172)
Block(-1,19,4,172)
Block(-1,19,5,172)
Block(-1,20,-2,172)
Block(-1,20,-1,172)
Block(-1,20,0,172)
Block(-1,20,1,172)
Block(-1,20,2,172)
Block(-1,20,3,172)
Block(-1,20,4,172)
Block(-1,20,5,172)
Block(-1,21,-1,172)
Block(-1,21,0,172)
Block(-1,21,1,172)
Block(-1,21,2,172)
Block(-1,21,3,172)
Block(-1,21,4,172)
Block(-1,21,5,172)
Block(-1,22,0,172)
Block(-1,22,1,172)
Block(-1,22,2,172)
Block(-1,22,3,172)
Block(-1,22,4,172)
Block(-1,23,0,172)
Block(-1,23,1,172)
Block(-1,23,2,172)
Block(-1,23,3,172)
Block(-1,23,4,172)
Block(-1,24,0,172)
Block(-1,24,1,172)
Block(-1,24,2,172)
Block(-1,24,3,172)
Block(-1,24,4,172)
Block(-1,25,0,172)
Block(-1,25,1,172)
Block(-1,25,2,172)
Block(-1,25,3,172)
Block(-1,26,0,172)
Block(-1,26,1,172)
Block(-1,26,2,172)
Block(-1,26,3,172)
Block(-1,27,0,172)
Block(-1,27,1,172)
Block(-1,27,2,172)
Block(-1,27,3,172)
Block(-1,28,0,172)
Block(-1,28,1,172)
Block(-1,28,2,172)
Block(-1,28,3,172)
Block(-1,29,0,172)
Block(-1,29,1,172)
Block(-1,29,2,172)
Block(-1,29,3,172)
Block(0,0,-6,172)
Block(0,0,-5,172)
Block(0,0,-4,172)
Block(0,0,-3,172)
Block(0,0,-2,172)
Block(0,0,-1,172)
Block(0,0,0,172)
Block(0,0,1,172)
Block(0,0,2,172)
Block(0,0,3,172)
Block(0,0,4,172)
Block(0,0,5,172)
Block(0,0,6,172)
Block(0,0,7,172)
Block(0,0,8,172)
Block(0,0,9,172)
Block(0,1,-5,172)
Block(0,1,-4,172)
Block(0,1,-3,172)
Block(0,1,-2,172)
Block(0,1,-1,172)
Block(0,1,0,172)
Block(0,1,1,172)
Block(0,1,2,172)
Block(0,1,3,172)
Block(0,1,4,172)
Block(0,1,5,172)
Block(0,1,6,172)
Block(0,1,7,172)
Block(0,1,8,172)
Block(0,1,9,172)
Block(0,2,-5,172)
Block(0,2,-4,172)
Block(0,2,-3,172)
Block(0,2,-2,172)
Block(0,2,-1,172)
Block(0,2,0,172)
Block(0,2,1,172)
Block(0,2,2,172)
Block(0,2,3,172)
Block(0,2,4,172)
Block(0,2,5,172)
Block(0,2,6,172)
Block(0,2,7,172)
Block(0,2,8,172)
Block(0,2,9,172)
Block(0,3,-5,172)
Block(0,3,-4,172)
Block(0,3,-3,172)
Block(0,3,-2,172)
Block(0,3,-1,172)
Block(0,3,0,172)
Block(0,3,1,172)
Block(0,3,2,172)
Block(0,3,3,172)
Block(0,3,4,172)
Block(0,3,5,172)
Block(0,3,6,172)
Block(0,3,7,172)
Block(0,3,8,172)
Block(0,3,9,172)
Block(0,4,-4,172)
Block(0,4,-3,172)
Block(0,4,-2,172)
Block(0,4,-1,172)
Block(0,4,0,172)
Block(0,4,1,172)
Block(0,4,2,172)
Block(0,4,3,172)
Block(0,4,4,172)
Block(0,4,5,172)
Block(0,4,6,172)
Block(0,4,7,172)
Block(0,5,-4,172)
Block(0,5,-3,172)
Block(0,5,-2,172)
Block(0,5,-1,172)
Block(0,5,0,172)
Block(0,5,1,172)
Block(0,5,2,172)
Block(0,5,3,172)
Block(0,5,4,172)
Block(0,5,5,172)
Block(0,5,6,172)
Block(0,6,-3,172)
Block(0,6,-2,172)
Block(0,6,-1,172)
Block(0,6,0,172)
Block(0,6,1,172)
Block(0,6,2,172)
Block(0,6,3,172)
Block(0,6,4,172)
Block(0,6,5,172)
Block(0,7,-2,172)
Block(0,7,-1,172)
Block(0,7,0,172)
Block(0,7,1,172)
Block(0,7,2,172)
Block(0,7,3,172)
Block(0,7,4,172)
Block(0,7,5,172)
Block(0,8,-2,172)
Block(0,8,-1,172)
Block(0,8,0,172)
Block(0,8,1,172)
Block(0,8,2,172)
Block(0,8,3,172)
Block(0,8,4,172)
Block(0,8,5,172)
Block(0,9,-2,172)
Block(0,9,-1,172)
Block(0,9,0,172)
Block(0,9,1,172)
Block(0,9,2,172)
Block(0,9,3,172)
Block(0,9,4,172)
Block(0,9,5,172)
Block(0,10,-2,172)
Block(0,10,-1,172)
Block(0,10,0,172)
Block(0,10,1,172)
Block(0,10,2,172)
Block(0,10,3,172)
Block(0,10,4,172)
Block(0,10,5,172)
Block(0,11,-2,172)
Block(0,11,-1,172)
Block(0,11,0,172)
Block(0,11,1,172)
Block(0,11,2,172)
Block(0,11,3,172)
Block(0,11,4,172)
Block(0,11,5,172)
Block(0,12,-2,172)
Block(0,12,-1,172)
Block(0,12,0,172)
Block(0,12,1,172)
Block(0,12,2,172)
Block(0,12,3,172)
Block(0,12,4,172)
Block(0,12,5,172)
Block(0,13,-2,172)
Block(0,13,-1,172)
Block(0,13,0,172)
Block(0,13,1,172)
Block(0,13,2,172)
Block(0,13,3,172)
Block(0,13,4,172)
Block(0,13,5,172)
Block(0,14,-2,172)
Block(0,14,-1,172)
Block(0,14,0,172)
Block(0,14,1,172)
Block(0,14,2,172)
Block(0,14,3,172)
Block(0,14,4,172)
Block(0,14,5,172)
Block(0,15,-2,172)
Block(0,15,-1,172)
Block(0,15,0,172)
Block(0,15,1,172)
Block(0,15,2,172)
Block(0,15,3,172)
Block(0,15,4,172)
Block(0,15,5,172)
Block(0,16,-2,172)
Block(0,16,-1,172)
Block(0,16,0,172)
Block(0,16,1,172)
Block(0,16,2,172)
Block(0,16,3,172)
Block(0,16,4,172)
Block(0,16,5,172)
Block(0,17,-2,172)
Block(0,17,-1,172)
Block(0,17,0,172)
Block(0,17,1,172)
Block(0,17,2,172)
Block(0,17,3,172)
Block(0,17,4,172)
Block(0,17,5,172)
Block(0,18,-2,172)
Block(0,18,-1,172)
Block(0,18,0,172)
Block(0,18,1,172)
Block(0,18,2,172)
Block(0,18,3,172)
Block(0,18,4,172)
Block(0,18,5,172)
Block(0,19,-2,172)
Block(0,19,-1,172)
Block(0,19,0,172)
Block(0,19,1,172)
Block(0,19,2,172)
Block(0,19,3,172)
Block(0,19,4,172)
Block(0,19,5,172)
Block(0,20,-2,172)
Block(0,20,-1,172)
Block(0,20,0,172)
Block(0,20,1,172)
Block(0,20,2,172)
Block(0,20,3,172)
Block(0,20,4,172)
Block(0,20,5,172)
Block(0,21,-1,172)
Block(0,21,0,172)
Block(0,21,1,172)
Block(0,21,2,172)
Block(0,21,3,172)
Block(0,21,4,172)
Block(0,21,5,172)
Block(0,22,1,172)
Block(0,22,2,172)
Block(0,22,3,172)
Block(0,23,1,172)
Block(0,23,2,172)
Block(0,23,3,172)
Block(0,24,2,172)
Block(0,24,3,172)
Block(0,25,2,172)
Block(0,25,3,172)
Block(0,26,2,172)
Block(0,26,3,172)
Block(0,27,2,172)
Block(0,27,3,172)
Block(0,28,2,172)
Block(0,28,3,172)
Block(0,29,3,172)
Block(1,0,-5,172)
Block(1,0,-4,172)
Block(1,0,-3,172)
Block(1,0,-2,172)
Block(1,0,-1,172)
Block(1,0,0,172)
Block(1,0,1,172)
Block(1,0,2,172)
Block(1,0,3,172)
Block(1,0,4,172)
Block(1,0,5,172)
Block(1,0,6,172)
Block(1,0,7,172)
Block(1,0,8,172)
Block(1,0,9,172)
Block(1,1,-4,172)
Block(1,1,-3,172)
Block(1,1,-2,172)
Block(1,1,-1,172)
Block(1,1,0,172)
Block(1,1,1,172)
Block(1,1,2,172)
Block(1,1,3,172)
Block(1,1,4,172)
Block(1,1,5,172)
Block(1,1,6,172)
Block(1,1,7,172)
Block(1,1,8,172)
Block(1,1,9,172)
Block(1,2,-4,172)
Block(1,2,-3,172)
Block(1,2,-2,172)
Block(1,2,-1,172)
Block(1,2,0,172)
Block(1,2,1,172)
Block(1,2,2,172)
Block(1,2,3,172)
Block(1,2,4,172)
Block(1,2,5,172)
Block(1,2,6,172)
Block(1,2,7,172)
Block(1,2,8,172)
Block(1,3,-4,172)
Block(1,3,-3,172)
Block(1,3,-2,172)
Block(1,3,-1,172)
Block(1,3,0,172)
Block(1,3,1,172)
Block(1,3,2,172)
Block(1,3,3,172)
Block(1,3,4,172)
Block(1,3,5,172)
Block(1,3,6,172)
Block(1,3,7,172)
Block(1,3,8,172)
Block(1,4,-4,172)
Block(1,4,-3,172)
Block(1,4,-2,172)
Block(1,4,-1,172)
Block(1,4,0,172)
Block(1,4,1,172)
Block(1,4,2,172)
Block(1,4,3,172)
Block(1,4,4,172)
Block(1,4,5,172)
Block(1,4,6,172)
Block(1,5,-3,172)
Block(1,5,-2,172)
Block(1,5,-1,172)
Block(1,5,0,172)
Block(1,5,1,172)
Block(1,5,2,172)
Block(1,5,3,172)
Block(1,5,4,172)
Block(1,5,5,172)
Block(1,5,6,172)
Block(1,6,-2,172)
Block(1,6,-1,172)
Block(1,6,0,172)
Block(1,6,1,172)
Block(1,6,2,172)
Block(1,6,3,172)
Block(1,6,4,172)
Block(1,6,5,172)
Block(1,7,-2,172)
Block(1,7,-1,172)
Block(1,7,0,172)
Block(1,7,1,172)
Block(1,7,2,172)
Block(1,7,3,172)
Block(1,7,4,172)
Block(1,7,5,172)
Block(1,8,-2,172)
Block(1,8,-1,172)
Block(1,8,0,172)
Block(1,8,1,172)
Block(1,8,2,172)
Block(1,8,3,172)
Block(1,8,4,172)
Block(1,8,5,172)
Block(1,9,-2,172)
Block(1,9,-1,172)
Block(1,9,0,172)
Block(1,9,1,172)
Block(1,9,2,172)
Block(1,9,3,172)
Block(1,9,4,172)
Block(1,9,5,172)
Block(1,10,-2,172)
Block(1,10,-1,172)
Block(1,10,0,172)
Block(1,10,1,172)
Block(1,10,2,172)
Block(1,10,3,172)
Block(1,10,4,172)
Block(1,10,5,172)
Block(1,11,-2,172)
Block(1,11,-1,172)
Block(1,11,0,172)
Block(1,11,1,172)
Block(1,11,2,172)
Block(1,11,3,172)
Block(1,11,4,172)
Block(1,11,5,172)
Block(1,12,-2,172)
Block(1,12,-1,172)
Block(1,12,0,172)
Block(1,12,1,172)
Block(1,12,2,172)
Block(1,12,3,172)
Block(1,12,4,172)
Block(1,12,5,172)
Block(1,13,-2,172)
Block(1,13,-1,172)
Block(1,13,0,172)
Block(1,13,1,172)
Block(1,13,2,172)
Block(1,13,3,172)
Block(1,13,4,172)
Block(1,13,5,172)
Block(1,14,-2,172)
Block(1,14,-1,172)
Block(1,14,0,172)
Block(1,14,1,172)
Block(1,14,2,172)
Block(1,14,3,172)
Block(1,14,4,172)
Block(1,14,5,172)
Block(1,15,-1,172)
Block(1,15,0,172)
Block(1,15,1,172)
Block(1,15,2,172)
Block(1,15,3,172)
Block(1,15,4,172)
Block(1,15,5,172)
Block(1,16,-1,172)
Block(1,16,0,172)
Block(1,16,1,172)
Block(1,16,2,172)
Block(1,16,3,172)
Block(1,16,4,172)
Block(1,16,5,172)
Block(1,17,0,172)
Block(1,17,1,172)
Block(1,17,2,172)
Block(1,17,3,172)
Block(1,17,4,172)
Block(1,18,0,172)
Block(1,18,1,172)
Block(1,18,2,172)
Block(1,18,3,172)
Block(1,18,4,172)
Block(1,19,0,172)
Block(1,19,1,172)
Block(1,19,2,172)
Block(1,19,3,172)
Block(1,19,4,172)
Block(1,20,0,172)
Block(1,20,1,172)
Block(1,20,2,172)
Block(1,20,3,172)
Block(1,20,4,172)
Block(1,21,0,172)
Block(1,21,1,172)
Block(1,21,2,172)
Block(1,21,3,172)
Block(1,21,4,172)
Block(2,0,-5,172)
Block(2,0,-4,172)
Block(2,0,-3,172)
Block(2,0,-2,172)
Block(2,0,-1,172)
Block(2,0,0,172)
Block(2,0,1,172)
Block(2,0,2,172)
Block(2,0,3,172)
Block(2,0,4,172)
Block(2,0,5,172)
Block(2,0,6,172)
Block(2,0,7,172)
Block(2,0,8,172)
Block(2,0,9,172)
Block(2,1,-4,172)
Block(2,1,-3,172)
Block(2,1,-2,172)
Block(2,1,-1,172)
Block(2,1,0,172)
Block(2,1,1,172)
Block(2,1,2,172)
Block(2,1,3,172)
Block(2,1,4,172)
Block(2,1,5,172)
Block(2,1,6,172)
Block(2,1,7,172)
Block(2,1,8,172)
Block(2,2,-3,172)
Block(2,2,-2,172)
Block(2,2,-1,172)
Block(2,2,0,172)
Block(2,2,1,172)
Block(2,2,2,172)
Block(2,2,3,172)
Block(2,2,4,172)
Block(2,2,5,172)
Block(2,2,6,172)
Block(2,2,7,172)
Block(2,2,8,172)
Block(2,3,-3,172)
Block(2,3,-2,172)
Block(2,3,-1,172)
Block(2,3,0,172)
Block(2,3,1,172)
Block(2,3,2,172)
Block(2,3,3,172)
Block(2,3,4,172)
Block(2,3,5,172)
Block(2,3,6,172)
Block(2,3,7,172)
Block(2,4,-3,172)
Block(2,4,-2,172)
Block(2,4,-1,172)
Block(2,4,0,172)
Block(2,4,1,172)
Block(2,4,2,172)
Block(2,4,3,172)
Block(2,4,4,172)
Block(2,4,5,172)
Block(2,4,6,172)
Block(2,5,-2,172)
Block(2,5,-1,172)
Block(2,5,0,172)
Block(2,5,1,172)
Block(2,5,2,172)
Block(2,5,3,172)
Block(2,5,4,172)
Block(2,5,5,172)
Block(2,5,6,172)
Block(2,6,-2,172)
Block(2,6,-1,172)
Block(2,6,0,172)
Block(2,6,1,172)
Block(2,6,2,172)
Block(2,6,3,172)
Block(2,6,4,172)
Block(2,6,5,172)
Block(2,7,-2,172)
Block(2,7,-1,172)
Block(2,7,0,172)
Block(2,7,1,172)
Block(2,7,2,172)
Block(2,7,3,172)
Block(2,7,4,172)
Block(2,7,5,172)
Block(2,8,-2,172)
Block(2,8,-1,172)
Block(2,8,0,172)
Block(2,8,1,172)
Block(2,8,2,172)
Block(2,8,3,172)
Block(2,8,4,172)
Block(2,8,5,172)
Block(2,9,-2,172)
Block(2,9,-1,172)
Block(2,9,0,172)
Block(2,9,1,172)
Block(2,9,2,172)
Block(2,9,3,172)
Block(2,9,4,172)
Block(2,9,5,172)
Block(2,10,-2,172)
Block(2,10,-1,172)
Block(2,10,0,172)
Block(2,10,1,172)
Block(2,10,2,172)
Block(2,10,3,172)
Block(2,10,4,172)
Block(2,10,5,172)
Block(2,11,-2,172)
Block(2,11,-1,172)
Block(2,11,0,172)
Block(2,11,1,172)
Block(2,11,2,172)
Block(2,11,3,172)
Block(2,11,4,172)
Block(2,11,5,172)
Block(2,12,-1,172)
Block(2,12,0,172)
Block(2,12,1,172)
Block(2,12,2,172)
Block(2,12,3,172)
Block(2,12,4,172)
Block(2,12,5,172)
Block(2,13,-1,172)
Block(2,13,0,172)
Block(2,13,1,172)
Block(2,13,2,172)
Block(2,13,3,172)
Block(2,13,4,172)
Block(2,14,0,172)
Block(2,14,1,172)
Block(2,14,2,172)
Block(2,14,3,172)
Block(2,14,4,172)
Block(2,15,0,172)
Block(2,15,1,172)
Block(2,15,2,172)
Block(2,15,3,172)
Block(2,15,4,172)
Block(2,16,0,172)
Block(2,16,1,172)
Block(2,16,2,172)
Block(2,16,3,172)
Block(2,16,4,172)
Block(2,17,0,172)
Block(2,17,1,172)
Block(2,17,2,172)
Block(2,17,3,172)
Block(2,17,4,172)
Block(2,18,0,172)
Block(2,18,1,172)
Block(2,18,2,172)
Block(2,18,3,172)
Block(2,18,4,172)
Block(2,19,0,172)
Block(2,19,1,172)
Block(2,19,2,172)
Block(2,19,3,172)
Block(2,19,4,172)
Block(2,20,0,172)
Block(2,20,1,172)
Block(2,20,2,172)
Block(2,20,3,172)
Block(2,20,4,172)
Block(2,21,1,172)
Block(2,21,2,172)
Block(2,21,3,172)
Block(2,21,4,172)
Block(3,0,-3,172)
Block(3,0,-2,172)
Block(3,0,-1,172)
Block(3,0,0,172)
Block(3,0,1,172)
Block(3,0,2,172)
Block(3,0,3,172)
Block(3,0,4,172)
Block(3,0,5,172)
Block(3,0,6,172)
Block(3,0,7,172)
Block(3,0,8,172)
Block(3,0,9,172)
Block(3,1,-3,172)
Block(3,1,-2,172)
Block(3,1,-1,172)
Block(3,1,0,172)
Block(3,1,1,172)
Block(3,1,2,172)
Block(3,1,3,172)
Block(3,1,4,172)
Block(3,1,5,172)
Block(3,1,6,172)
Block(3,1,7,172)
Block(3,1,8,172)
Block(3,2,-3,172)
Block(3,2,-2,172)
Block(3,2,-1,172)
Block(3,2,0,172)
Block(3,2,1,172)
Block(3,2,2,172)
Block(3,2,3,172)
Block(3,2,4,172)
Block(3,2,5,172)
Block(3,2,6,172)
Block(3,2,7,172)
Block(3,3,-2,172)
Block(3,3,-1,172)
Block(3,3,0,172)
Block(3,3,1,172)
Block(3,3,2,172)
Block(3,3,3,172)
Block(3,3,4,172)
Block(3,3,5,172)
Block(3,3,7,172)
Block(3,4,-2,172)
Block(3,4,-1,172)
Block(3,4,0,172)
Block(3,4,1,172)
Block(3,4,2,172)
Block(3,4,3,172)
Block(3,4,4,172)
Block(3,4,5,172)
Block(3,4,6,172)
Block(3,5,-2,172)
Block(3,5,-1,172)
Block(3,5,0,172)
Block(3,5,1,172)
Block(3,5,2,172)
Block(3,5,3,172)
Block(3,5,4,172)
Block(3,5,5,172)
Block(3,5,6,172)
Block(3,6,-2,172)
Block(3,6,-1,172)
Block(3,6,0,172)
Block(3,6,1,172)
Block(3,6,2,172)
Block(3,6,3,172)
Block(3,6,4,172)
Block(3,6,5,172)
Block(3,7,-1,172)
Block(3,7,0,172)
Block(3,7,1,172)
Block(3,7,2,172)
Block(3,7,3,172)
Block(3,7,4,172)
Block(3,7,5,172)
Block(3,8,0,172)
Block(3,8,1,172)
Block(3,8,2,172)
Block(3,8,3,172)
Block(3,8,4,172)
Block(3,9,0,172)
Block(3,9,1,172)
Block(3,9,2,172)
Block(3,9,3,172)
Block(3,9,4,172)
Block(3,10,0,172)
Block(3,10,1,172)
Block(3,10,2,172)
Block(3,10,3,172)
Block(3,11,0,172)
Block(3,11,1,172)
Block(3,11,2,172)
Block(3,12,1,172)
Block(4,0,-2,172)
Block(4,0,-1,172)
Block(4,0,0,172)
Block(4,0,1,172)
Block(4,0,2,172)
Block(4,0,3,172)
Block(4,0,4,172)
Block(4,0,5,172)
Block(4,0,6,172)
Block(4,0,7,172)
Block(4,0,8,172)
Block(4,1,-2,172)
Block(4,1,-1,172)
Block(4,1,0,172)
Block(4,1,1,172)
Block(4,1,2,172)
Block(4,1,3,172)
Block(4,1,4,172)
Block(4,1,5,172)
Block(4,1,6,172)
Block(4,1,7,172)
Block(4,2,-1,172)
Block(4,2,0,172)
Block(4,2,1,172)
Block(4,2,2,172)
Block(4,2,3,172)
Block(4,2,4,172)
Block(4,2,5,172)
Block(4,2,6,172)
Block(4,3,-1,172)
Block(4,3,0,172)
Block(4,3,1,172)
Block(4,3,2,172)
Block(4,3,3,172)
Block(4,3,4,172)
Block(4,3,5,172)
Block(4,3,6,172)
Block(4,4,0,172)
Block(4,4,1,172)
Block(4,4,2,172)
Block(4,4,3,172)
Block(4,4,4,172)
Block(4,5,0,172)
Block(4,5,1,172)
Block(4,5,2,172)
Block(4,5,3,172)
Block(4,5,4,172)
Block(4,6,1,172)
Block(4,6,2,172)
Block(4,7,1,172)
Block(4,7,2,172)
Block(4,8,1,172)
Block(5,0,-2,172)
Block(5,0,-1,172)
Block(5,0,0,172)
Block(5,0,1,172)
Block(5,0,2,172)
Block(5,0,3,172)
Block(5,0,4,172)
Block(5,0,5,172)
Block(5,0,6,172)
Block(5,0,7,172)
Block(5,1,-1,172)
Block(5,1,0,172)
Block(5,1,1,172)
Block(5,1,2,172)
Block(5,1,3,172)
Block(5,1,4,172)
Block(5,1,5,172)
Block(5,2,-1,172)
Block(5,2,0,172)
Block(5,2,1,172)
Block(5,2,2,172)
Block(5,2,3,172)
Block(5,2,4,172)
Block(5,3,0,172)
Block(5,3,1,172)
Block(5,3,2,172)
Block(5,3,3,172)
Block(5,3,4,172)
Block(5,4,1,172)
Block(5,4,2,172)
Block(5,5,2,172)
Block(6,0,-1,172)
Block(6,0,0,172)
Block(6,0,1,172)
Block(6,0,2,172)
Block(6,0,3,172)
Block(6,0,4,172)
Block(6,0,5,172)
Block(6,0,6,172)
Block(6,1,0,172)
Block(6,1,1,172)
Block(6,1,2,172)
Block(6,2,1,172)


#######################################################################
# +-----------------------------------------------------------------+ #
# |                             Entities                            | #
# +-----------------------------------------------------------------+ #
#######################################################################

# Entity() spawns an entity instead of a block. The entity is spawned only once when the BO3 is spawned.
# Entities are persistent by default so they don't de-spawn when no player is near, they are only unloaded.
# Usage: Entity(x,y,z,mobName,groupSize,NameTagOrNBTFileName) or Entity(x,y,z,mobName,groupSize)
# Use /tc entities or /otg entities to get a list of entities that can be used as mobName, this includes entities added by other mods.
# NameTagOrNBTFileName can be either a nametag for the mob or an nbt file (such as mymobinfo.nbt or mymobinfo.txt).
# When using a text file you can use the same mob spawning parameters used with the /summon command to equip the
# entity and give it custom attributes etc. You can copy the DATA part of a summon command including surrounding
# curly braces to a .txt file, for instance for: "/summon Skeleton x y z {DATA}"

#######################################################################
# +-----------------------------------------------------------------+ #
# |                            BO3 checks                           | #
# +-----------------------------------------------------------------+ #
#######################################################################

# Require a condition at a certain location in order for the BO3 to be spawned.
# BlockCheck(x,y,z,BlockName[,BlockName[,...]]) - one of the blocks must be at the location
# BlockCheckNot(x,y,z,BlockName[,BlockName[,...]]) - all the blocks must not be at the location
# LightCheck(x,y,z,minLightLevel,maxLightLevel) - light must be between min and max (inclusive)

# You can use "Solid" as a BlockName for matching all solid blocks or "All" to match all blocks that aren't air.

# Examples:
#   BlockCheck(0,-1,0,GRASS,DIRT)  Require grass or dirt just below the object
#   BlockCheck(0,-1,0,Solid)       Require any solid block just below the object
#   BlockCheck(0,-1,0,WOOL)        Require any type of wool just below the object
#   BlockCheck(0,-1,0,WOOL:0)      Require white wool just below the object
#   BlockCheckNot(0,-1,0,WOOL:0)   Require that there is no white wool below the object
#   LightCheck(0,0,0,0,1)          Require almost complete darkness just below the object

#Block(-7,-1,-2,41)
#Block(-7,-1,-1,41)
#Block(-7,-1,0,41)
#Block(-7,-1,1,41)
#Block(-7,-1,2,41)
#Block(-7,-1,3,41)
#Block(-7,-1,4,41)
#Block(-6,-1,-5,41)
#Block(-6,-1,-4,41)
#Block(-6,-1,-3,41)
#Block(-6,-1,-2,41)
#Block(-6,-1,-1,41)
#Block(-6,-1,0,41)
#Block(-6,-1,1,41)
#Block(-6,-1,2,41)
#Block(-6,-1,3,41)
#Block(-6,-1,4,41)
#Block(-6,-1,5,41)
#Block(-6,-1,6,41)
#Block(-6,-1,7,41)
#Block(-5,-1,-6,41)
#Block(-5,-1,-5,41)
#Block(-5,-1,-4,41)
#Block(-5,-1,-3,41)
#Block(-5,-1,-2,41)
#Block(-5,-1,-1,41)
#Block(-5,-1,0,41)
#Block(-5,-1,1,41)
#Block(-5,-1,2,41)
#Block(-5,-1,3,41)
#Block(-5,-1,4,41)
#Block(-5,-1,5,41)
#Block(-5,-1,6,41)
#Block(-5,-1,7,41)
#Block(-5,-1,8,41)
#Block(-4,-1,-7,41)
#Block(-4,-1,-6,41)
#Block(-4,-1,-5,41)
#Block(-4,-1,-4,41)
#Block(-4,-1,-3,41)
#Block(-4,-1,-2,41)
#Block(-4,-1,-1,41)
#Block(-4,-1,0,41)
#Block(-4,-1,1,41)
#Block(-4,-1,2,41)
#Block(-4,-1,3,41)
#Block(-4,-1,4,41)
#Block(-4,-1,5,41)
#Block(-4,-1,6,41)
#Block(-4,-1,7,41)
#Block(-4,-1,8,41)
#Block(-3,-1,-7,41)
#Block(-3,-1,-6,41)
#Block(-3,-1,-5,41)
#Block(-3,-1,-4,41)
#Block(-3,-1,-3,41)
#Block(-3,-1,-2,41)
#Block(-3,-1,-1,41)
#Block(-3,-1,0,41)
#Block(-3,-1,1,41)
#Block(-3,-1,2,41)
#Block(-3,-1,3,41)
#Block(-3,-1,4,41)
#Block(-3,-1,5,41)
#Block(-3,-1,6,41)
#Block(-3,-1,7,41)
#Block(-3,-1,8,41)
#Block(-2,-1,-7,41)
#Block(-2,-1,-6,41)
#Block(-2,-1,-5,41)
#Block(-2,-1,-4,41)
#Block(-2,-1,-3,41)
#Block(-2,-1,-2,41)
#Block(-2,-1,-1,41)
#Block(-2,-1,0,41)
#Block(-2,-1,1,41)
#Block(-2,-1,2,41)
#Block(-2,-1,3,41)
#Block(-2,-1,4,41)
#Block(-2,-1,5,41)
#Block(-2,-1,6,41)
#Block(-2,-1,7,41)
#Block(-2,-1,8,41)
#Block(-2,-1,9,41)
#Block(-1,-1,-6,41)
#Block(-1,-1,-5,41)
#Block(-1,-1,-4,41)
#Block(-1,-1,-3,41)
#Block(-1,-1,-2,41)
#Block(-1,-1,-1,41)
#Block(-1,-1,0,41)
#Block(-1,-1,1,41)
#Block(-1,-1,2,41)
#Block(-1,-1,3,41)
#Block(-1,-1,4,41)
#Block(-1,-1,5,41)
#Block(-1,-1,6,41)
#Block(-1,-1,7,41)
#Block(-1,-1,8,41)
#Block(-1,-1,9,41)
#Block(0,-1,-6,41)
#Block(0,-1,-5,41)
#Block(0,-1,-4,41)
#Block(0,-1,-3,41)
#Block(0,-1,-2,41)
#Block(0,-1,-1,41)
#Block(0,-1,0,41)
#Block(0,-1,1,41)
#Block(0,-1,2,41)
#Block(0,-1,3,41)
#Block(0,-1,4,41)
#Block(0,-1,5,41)
#Block(0,-1,6,41)
#Block(0,-1,7,41)
#Block(0,-1,8,41)
#Block(0,-1,9,41)
#Block(1,-1,-5,41)
#Block(1,-1,-4,41)
#Block(1,-1,-3,41)
#Block(1,-1,-2,41)
#Block(1,-1,-1,41)
#Block(1,-1,0,41)
#Block(1,-1,1,41)
#Block(1,-1,2,41)
#Block(1,-1,3,41)
#Block(1,-1,4,41)
#Block(1,-1,5,41)
#Block(1,-1,6,41)
#Block(1,-1,7,41)
#Block(1,-1,8,41)
#Block(1,-1,9,41)
#Block(2,-1,-5,41)
#Block(2,-1,-4,41)
#Block(2,-1,-3,41)
#Block(2,-1,-2,41)
#Block(2,-1,-1,41)
#Block(2,-1,0,41)
#Block(2,-1,1,41)
#Block(2,-1,2,41)
#Block(2,-1,3,41)
#Block(2,-1,4,41)
#Block(2,-1,5,41)
#Block(2,-1,6,41)
#Block(2,-1,7,41)
#Block(2,-1,8,41)
#Block(2,-1,9,41)
#Block(3,-1,-3,41)
#Block(3,-1,-2,41)
#Block(3,-1,-1,41)
#Block(3,-1,0,41)
#Block(3,-1,1,41)
#Block(3,-1,2,41)
#Block(3,-1,3,41)
#Block(3,-1,4,41)
#Block(3,-1,5,41)
#Block(3,-1,6,41)
#Block(3,-1,7,41)
#Block(3,-1,8,41)
#Block(3,-1,9,41)
#Block(4,-1,-2,41)
#Block(4,-1,-1,41)
#Block(4,-1,0,41)
#Block(4,-1,1,41)
#Block(4,-1,2,41)
#Block(4,-1,3,41)
#Block(4,-1,4,41)
#Block(4,-1,5,41)
#Block(4,-1,6,41)
#Block(4,-1,7,41)
#Block(4,-1,8,41)
#Block(5,-1,-2,41)
#Block(5,-1,-1,41)
#Block(5,-1,0,41)
#Block(5,-1,1,41)
#Block(5,-1,2,41)
#Block(5,-1,3,41)
#Block(5,-1,4,41)
#Block(5,-1,5,41)
#Block(5,-1,6,41)
#Block(5,-1,7,41)
#Block(6,-1,-1,41)
#Block(6,-1,0,41)
#Block(6,-1,1,41)
#Block(6,-1,2,41)
#Block(6,-1,3,41)
#Block(6,-1,4,41)
#Block(6,-1,5,41)
#Block(6,-1,6,41)