
#######################################################################
# +-----------------------------------------------------------------+ #
# |                            BO3 object                           | #
# +-----------------------------------------------------------------+ #
#######################################################################

Author: LordSmellyPants

Description: No description given

Version: 3

SettingsMode: WriteWithoutComments


#######################################################################
# +-----------------------------------------------------------------+ #
# |                          Main settings                          | #
# +-----------------------------------------------------------------+ #
#######################################################################

Tree: true

Frequency: 1

Rarity: 100.0

RotateRandomly: true

SpawnHeight: highestSolidBlock

SpawnHeightOffset: 0

SpawnHeightVariance: 0

##############################
# Height Limits for the BO3. #
##############################

MinHeight: 63

MaxHeight: 70

######################
# Extrusion settings #
######################

ExtrudeMode: None

ExtrudeThroughBlocks: AIR

MaxBranchDepth: 10

ExcludedBiomes: All


#######################################################################
# +-----------------------------------------------------------------+ #
# |                      Source block settings                      | #
# +-----------------------------------------------------------------+ #
#######################################################################

SourceBlocks: STONE:1,STONE:3,STONE:5,DIRT:1,DIRT:0,SAND:0,GRASS:0,DIRT:2,STATIONARY_WATER:0,HARD_CLAY,STAINED_CLAY:0,CLAY,SANDSTONE:0,SAND:1,AIR,STONE:0,GRAVEL,LONG_GRASS:0,LONG_GRASS:1,LONG_GRASS:2,DEAD_BUSH,YELLOW_FLOWER:0,RED_ROSE:0,BROWN_MUSHROOM,RED_MUSHROOM

MaxPercentageOutsideSourceBlock: 0

OutsideSourceBlock: placeAnyway

DoReplaceBlocks: true

IsOTGPlus: false


#######################################################################
# +-----------------------------------------------------------------+ #
# |                              Blocks                             | #
# +-----------------------------------------------------------------+ #
#######################################################################

Block(-10,8,1,LEAVES:1)
Block(-10,15,5,LEAVES:1)
Block(-10,16,4,LEAVES:1)
Block(-9,7,2,LEAVES:1)
Block(-9,8,0,LEAVES:1)
Block(-9,8,2,LEAVES:1)
Block(-9,9,1,LEAVES:1)
Block(-9,14,3,LEAVES:1)
Block(-9,15,4,LEAVES:1)
Block(-9,15,6,LEAVES:1)
Block(-9,16,3,LEAVES:1)
Block(-9,16,4,LEAVES:1)
Block(-9,16,5,LEAVES:1)
Block(-9,17,4,LEAVES:1)
Block(-8,7,-1,LEAVES:1)
Block(-8,8,1,LEAVES:1)
Block(-8,8,3,LEAVES:1)
Block(-8,9,0,LEAVES:1)
Block(-8,9,1,LEAVES:1)
Block(-8,9,2,LEAVES:1)
Block(-8,10,1,LEAVES:1)
Block(-8,15,1,LEAVES:1)
Block(-8,15,3,LEAVES:1)
Block(-8,16,2,LEAVES:1)
Block(-8,16,3,LEAVES:1)
Block(-8,16,4,LOG:13)
Block(-8,16,5,LEAVES:1)
Block(-8,17,3,LEAVES:1)
Block(-8,17,4,LEAVES:1)
Block(-7,7,1,LEAVES:1)
Block(-7,8,0,LEAVES:1)
Block(-7,8,1,LEAVES:1)
Block(-7,9,0,LEAVES:1)
Block(-7,9,1,LEAVES:1)
Block(-7,9,2,LEAVES:1)
Block(-7,9,3,LEAVES:1)
Block(-7,10,1,LEAVES:1)
Block(-7,10,2,LEAVES:1)
Block(-7,15,5,LEAVES:1)
Block(-7,16,1,LEAVES:1)
Block(-7,16,4,LEAVES:1)
Block(-7,17,2,LEAVES:1)
Block(-7,17,3,LOG:13)
Block(-7,17,4,LEAVES:1)
Block(-7,18,3,LEAVES:1)
Block(-7,23,2,LEAVES:1)
Block(-7,24,1,LEAVES:1)
Block(-6,8,-1,LEAVES:1)
Block(-6,8,1,LEAVES:1)
Block(-6,8,3,LEAVES:1)
Block(-6,9,0,LEAVES:1)
Block(-6,9,1,LOG:13)
Block(-6,9,2,LEAVES:1)
Block(-6,10,0,LEAVES:1)
Block(-6,10,1,LEAVES:1)
Block(-6,10,2,LEAVES:1)
Block(-6,11,1,LEAVES:1)
Block(-6,16,2,LEAVES:1)
Block(-6,16,4,LEAVES:1)
Block(-6,17,1,LEAVES:1)
Block(-6,17,2,LEAVES:1)
Block(-6,17,3,LOG:13)
Block(-6,17,4,LEAVES:1)
Block(-6,17,5,LEAVES:1)
Block(-6,18,1,LEAVES:1)
Block(-6,18,2,LEAVES:1)
Block(-6,18,3,LEAVES:1)
Block(-6,18,4,LEAVES:1)
Block(-6,19,2,LEAVES:1)
Block(-6,23,-3,LEAVES:1)
Block(-6,23,-1,LEAVES:1)
Block(-6,23,1,LEAVES:1)
Block(-6,24,0,LEAVES:1)
Block(-6,24,1,LEAVES:1)
Block(-6,24,2,LEAVES:1)
Block(-6,25,1,LEAVES:1)
Block(-5,9,1,LEAVES:1)
Block(-5,9,3,LEAVES:1)
Block(-5,10,0,LEAVES:1)
Block(-5,10,1,LOG:13)
Block(-5,10,2,LEAVES:1)
Block(-5,11,1,LEAVES:1)
Block(-5,15,4,LEAVES:1)
Block(-5,16,0,LEAVES:1)
Block(-5,16,5,LEAVES:1)
Block(-5,17,0,LEAVES:1)
Block(-5,17,3,LEAVES:1)
Block(-5,17,4,LEAVES:1)
Block(-5,18,1,LEAVES:1)
Block(-5,18,2,LOG:13)
Block(-5,18,3,LEAVES:1)
Block(-5,19,2,LEAVES:1)
Block(-5,23,-4,LEAVES:1)
Block(-5,23,1,LEAVES:1)
Block(-5,23,3,LEAVES:1)
Block(-5,24,-3,LEAVES:1)
Block(-5,24,-1,LEAVES:1)
Block(-5,24,0,LEAVES:1)
Block(-5,24,1,LOG:13)
Block(-5,24,2,LEAVES:1)
Block(-5,24,3,LEAVES:1)
Block(-5,25,-2,LEAVES:1)
Block(-5,25,0,LEAVES:1)
Block(-5,25,1,LEAVES:1)
Block(-5,25,2,LEAVES:1)
Block(-4,-7,-4,LOG:1)
Block(-4,-7,0,LOG:1)
Block(-4,-6,-4,LOG:13)
Block(-4,-6,0,LOG:13)
Block(-4,8,2,LEAVES:1)
Block(-4,9,-1,LEAVES:1)
Block(-4,9,2,LEAVES:1)
Block(-4,10,0,LEAVES:1)
Block(-4,10,1,LOG:13)
Block(-4,10,2,LEAVES:1)
Block(-4,10,3,LEAVES:1)
Block(-4,10,8,LEAVES:1)
Block(-4,10,10,LEAVES:1)
Block(-4,11,1,LEAVES:1)
Block(-4,11,2,LEAVES:1)
Block(-4,11,6,LEAVES:1)
Block(-4,11,9,LEAVES:1)
Block(-4,12,7,LEAVES:1)
Block(-4,13,-7,LEAVES:1)
Block(-4,14,-5,LEAVES:1)
Block(-4,15,-3,LEAVES:1)
Block(-4,16,-4,LEAVES:1)
Block(-4,16,2,LEAVES:1)
Block(-4,17,1,LEAVES:1)
Block(-4,17,2,LEAVES:1)
Block(-4,18,0,LEAVES:1)
Block(-4,18,1,LEAVES:1)
Block(-4,18,2,LOG:13)
Block(-4,18,3,LEAVES:1)
Block(-4,19,1,LEAVES:1)
Block(-4,19,2,LEAVES:1)
Block(-4,21,3,LEAVES:1)
Block(-4,22,-5,LEAVES:1)
Block(-4,24,-2,LEAVES:1)
Block(-4,24,0,LEAVES:1)
Block(-4,24,1,LEAVES:1)
Block(-4,24,2,LEAVES:1)
Block(-4,25,-3,LEAVES:1)
Block(-4,25,-2,LEAVES:1)
Block(-4,25,-1,LEAVES:1)
Block(-4,25,0,LOG:13)
Block(-4,25,1,LEAVES:1)
Block(-4,25,2,LEAVES:1)
Block(-4,25,3,LEAVES:1)
Block(-4,26,-2,LEAVES:1)
Block(-4,26,0,LEAVES:1)
Block(-4,26,1,LEAVES:1)
Block(-4,26,2,LEAVES:1)
Block(-3,-7,-4,LOG:1)
Block(-3,-7,-2,LOG:1)
Block(-3,-7,-1,LOG:5)
Block(-3,-7,1,LOG:1)
Block(-3,-7,2,LOG:1)
Block(-3,-6,-4,LOG:13)
Block(-3,-6,-2,LOG:13)
Block(-3,-6,1,LOG:13)
Block(-3,-6,2,LOG:13)
Block(-3,-5,-4,LOG:1)
Block(-3,-5,1,LOG:13)
Block(-3,-4,1,LOG:1)
Block(-3,10,2,LEAVES:1)
Block(-3,11,-1,LEAVES:1)
Block(-3,11,0,LEAVES:1)
Block(-3,11,1,LOG:13)
Block(-3,11,2,LEAVES:1)
Block(-3,11,8,LEAVES:1)
Block(-3,11,9,LOG:13)
Block(-3,11,10,LEAVES:1)
Block(-3,12,0,LEAVES:1)
Block(-3,12,1,LEAVES:1)
Block(-3,12,6,LEAVES:1)
Block(-3,12,7,LEAVES:1)
Block(-3,12,8,LEAVES:1)
Block(-3,12,9,LEAVES:1)
Block(-3,13,-8,LEAVES:1)
Block(-3,13,5,LEAVES:1)
Block(-3,13,7,LEAVES:1)
Block(-3,14,-7,LEAVES:1)
Block(-3,15,-7,LEAVES:1)
Block(-3,15,-4,LEAVES:1)
Block(-3,16,-5,LEAVES:1)
Block(-3,16,-4,LEAVES:1)
Block(-3,16,-3,LEAVES:1)
Block(-3,17,-4,LEAVES:1)
Block(-3,17,3,LEAVES:1)
Block(-3,18,-1,LEAVES:1)
Block(-3,18,1,LEAVES:1)
Block(-3,19,0,LEAVES:1)
Block(-3,19,1,LOG:13)
Block(-3,19,2,LEAVES:1)
Block(-3,20,1,LEAVES:1)
Block(-3,20,3,LEAVES:1)
Block(-3,21,2,LEAVES:1)
Block(-3,21,3,LEAVES:1)
Block(-3,21,4,LEAVES:1)
Block(-3,22,-7,LEAVES:1)
Block(-3,22,-3,LEAVES:1)
Block(-3,23,-6,LEAVES:1)
Block(-3,23,-5,LEAVES:1)
Block(-3,23,-4,LEAVES:1)
Block(-3,24,-3,LEAVES:1)
Block(-3,24,-1,LEAVES:1)
Block(-3,25,-4,LEAVES:1)
Block(-3,25,-3,LEAVES:1)
Block(-3,25,-2,LEAVES:1)
Block(-3,25,-1,LOG:13)
Block(-3,25,0,LEAVES:1)
Block(-3,25,1,LEAVES:1)
Block(-3,25,2,LEAVES:1)
Block(-3,26,-3,LEAVES:1)
Block(-3,26,-1,LEAVES:1)
Block(-3,26,0,LOG:13)
Block(-3,26,1,LEAVES:1)
Block(-3,27,-1,LEAVES:1)
Block(-3,27,0,LEAVES:1)
Block(-3,27,1,LEAVES:1)
Block(-3,28,-2,LEAVES:1)
Block(-3,28,2,LEAVES:1)
Block(-3,28,4,LEAVES:1)
Block(-3,29,-1,LEAVES:1)
Block(-3,30,0,LEAVES:1)
Block(-2,-7,-4,LOG:9)
Block(-2,-7,-3,LOG:1)
Block(-2,-7,-1,LOG:1)
Block(-2,-6,-3,LOG:13)
Block(-2,-6,-2,LOG:5)
Block(-2,-6,-1,LOG:13)
Block(-2,-6,0,LOG:13)
Block(-2,-6,1,LOG:13)
Block(-2,-5,-3,LOG:13)
Block(-2,-5,-1,LOG:13)
Block(-2,-5,0,LOG:13)
Block(-2,-4,-1,LOG:1)
Block(-2,-4,0,LOG:13)
Block(-2,-3,0,LOG:13)
Block(-2,-2,0,LOG:1)
Block(-2,6,-6,LEAVES:1)
Block(-2,7,-5,LEAVES:1)
Block(-2,8,-6,LEAVES:1)
Block(-2,8,-3,LEAVES:1)
Block(-2,9,2,LEAVES:1)
Block(-2,9,10,LEAVES:1)
Block(-2,10,-1,LEAVES:1)
Block(-2,10,1,LEAVES:1)
Block(-2,10,9,LEAVES:1)
Block(-2,11,-2,LEAVES:1)
Block(-2,11,-1,LEAVES:1)
Block(-2,11,0,LEAVES:1)
Block(-2,11,1,LOG:13)
Block(-2,11,2,LEAVES:1)
Block(-2,11,4,LEAVES:1)
Block(-2,11,9,LEAVES:1)
Block(-2,11,10,LEAVES:1)
Block(-2,12,-1,LEAVES:1)
Block(-2,12,0,LEAVES:1)
Block(-2,12,1,LEAVES:1)
Block(-2,12,5,LEAVES:1)
Block(-2,12,6,LEAVES:1)
Block(-2,12,7,LOG:13)
Block(-2,12,8,LOG:13)
Block(-2,12,9,LEAVES:1)
Block(-2,12,10,LEAVES:1)
Block(-2,13,0,LEAVES:1)
Block(-2,13,4,LEAVES:1)
Block(-2,13,5,LEAVES:1)
Block(-2,13,6,LEAVES:1)
Block(-2,13,7,LEAVES:1)
Block(-2,13,8,LEAVES:1)
Block(-2,13,9,LEAVES:1)
Block(-2,14,-8,LEAVES:1)
Block(-2,14,-7,LEAVES:1)
Block(-2,14,-6,LEAVES:1)
Block(-2,14,5,LEAVES:1)
Block(-2,15,-7,LEAVES:1)
Block(-2,15,-6,LEAVES:1)
Block(-2,15,-5,LEAVES:1)
Block(-2,16,-7,LEAVES:1)
Block(-2,16,-6,LEAVES:1)
Block(-2,16,-5,LEAVES:1)
Block(-2,16,-4,LEAVES:1)
Block(-2,16,-3,LEAVES:1)
Block(-2,16,-2,LEAVES:1)
Block(-2,17,-5,LEAVES:1)
Block(-2,17,-4,LEAVES:1)
Block(-2,17,-2,LEAVES:1)
Block(-2,17,2,LEAVES:1)
Block(-2,18,-4,LEAVES:1)
Block(-2,18,1,LEAVES:1)
Block(-2,18,2,LEAVES:1)
Block(-2,19,-1,LEAVES:1)
Block(-2,19,0,LOG:13)
Block(-2,19,1,LEAVES:1)
Block(-2,19,2,LEAVES:1)
Block(-2,20,0,LEAVES:1)
Block(-2,20,1,LEAVES:1)
Block(-2,21,2,LEAVES:1)
Block(-2,21,3,LOG:13)
Block(-2,22,-4,LEAVES:1)
Block(-2,22,1,LEAVES:1)
Block(-2,22,3,LEAVES:1)
Block(-2,22,4,LEAVES:1)
Block(-2,23,-7,LEAVES:1)
Block(-2,23,-6,LEAVES:1)
Block(-2,23,-5,LOG:13)
Block(-2,23,-4,LOG:13)
Block(-2,23,-3,LEAVES:1)
Block(-2,23,-2,LEAVES:1)
Block(-2,24,-6,LEAVES:1)
Block(-2,24,-5,LEAVES:1)
Block(-2,24,-4,LEAVES:1)
Block(-2,24,-3,LEAVES:1)
Block(-2,25,-2,LEAVES:1)
Block(-2,26,-5,LEAVES:1)
Block(-2,26,-2,LEAVES:1)
Block(-2,26,-1,LEAVES:1)
Block(-2,26,0,LOG:13)
Block(-2,26,1,LEAVES:1)
Block(-2,27,-4,LEAVES:1)
Block(-2,27,-3,LEAVES:1)
Block(-2,27,-1,LEAVES:1)
Block(-2,27,0,LEAVES:1)
Block(-2,27,1,LEAVES:1)
Block(-2,28,-3,LEAVES:1)
Block(-2,28,-2,LEAVES:1)
Block(-2,28,-1,LEAVES:1)
Block(-2,28,0,LEAVES:1)
Block(-2,28,1,LEAVES:1)
Block(-2,28,5,LEAVES:1)
Block(-2,29,-2,LEAVES:1)
Block(-2,29,0,LEAVES:1)
Block(-2,29,2,LEAVES:1)
Block(-2,29,3,LEAVES:1)
Block(-2,29,4,LEAVES:1)
Block(-2,30,-1,LEAVES:1)
Block(-2,30,0,LEAVES:1)
Block(-2,30,1,LEAVES:1)
Block(-2,30,3,LEAVES:1)
Block(-2,31,0,LEAVES:1)
Block(-2,33,0,LEAVES:1)
Block(-1,-7,-5,LOG:1)
Block(-1,-7,-4,LOG:1)
Block(-1,-7,0,LOG:1)
Block(-1,-7,2,LOG:1)
Block(-1,-6,-5,LOG:13)
Block(-1,-6,-4,LOG:13)
Block(-1,-6,-3,LOG:13)
Block(-1,-6,-2,LOG:13)
Block(-1,-6,-1,LOG:13)
Block(-1,-6,0,LOG:13)
Block(-1,-6,1,LOG:13)
Block(-1,-6,2,LOG:13)
Block(-1,-5,-5,LOG:1)
Block(-1,-5,-4,LOG:13)
Block(-1,-5,-3,LOG:13)
Block(-1,-5,-2,LOG:13)
Block(-1,-5,-1,LOG:13)
Block(-1,-5,0,LOG:13)
Block(-1,-5,1,LOG:13)
Block(-1,-5,2,LOG:1)
Block(-1,-4,-3,LOG:13)
Block(-1,-4,-2,LOG:13)
Block(-1,-4,-1,LOG:13)
Block(-1,-4,0,LOG:13)
Block(-1,-3,-3,LOG:1)
Block(-1,-3,-2,LOG:13)
Block(-1,-3,-1,LOG:13)
Block(-1,-3,0,LOG:13)
Block(-1,-2,-2,LOG:13)
Block(-1,-2,-1,LOG:13)
Block(-1,-2,0,LOG:13)
Block(-1,-1,-2,LOG:13)
Block(-1,-1,-1,LOG:13)
Block(-1,-1,0,LOG:13)
Block(-1,0,-1,LOG:13)
Block(-1,0,0,LOG:13)
Block(-1,1,-1,LOG:13)
Block(-1,1,0,LOG:13)
Block(-1,2,-1,LOG:13)
Block(-1,2,0,LOG:13)
Block(-1,3,-1,LOG:13)
Block(-1,3,0,LOG:13)
Block(-1,4,-1,LOG:13)
Block(-1,4,0,LOG:13)
Block(-1,5,-1,LOG:13)
Block(-1,5,0,LOG:13)
Block(-1,6,-7,LEAVES:1)
Block(-1,6,-1,LOG:13)
Block(-1,6,0,LOG:13)
Block(-1,7,-6,LEAVES:1)
Block(-1,7,0,LOG:13)
Block(-1,8,-7,LEAVES:1)
Block(-1,8,-6,LEAVES:1)
Block(-1,8,-5,LEAVES:1)
Block(-1,8,-4,LEAVES:1)
Block(-1,8,0,LOG:13)
Block(-1,9,-6,LEAVES:1)
Block(-1,9,-3,LEAVES:1)
Block(-1,9,-2,LEAVES:1)
Block(-1,9,0,LOG:13)
Block(-1,9,3,LEAVES:1)
Block(-1,10,0,LOG:13)
Block(-1,10,2,LEAVES:1)
Block(-1,11,-2,LEAVES:1)
Block(-1,11,-1,LEAVES:1)
Block(-1,11,0,LEAVES:1)
Block(-1,11,1,LEAVES:1)
Block(-1,11,9,LEAVES:1)
Block(-1,11,10,LEAVES:1)
Block(-1,12,-1,LEAVES:1)
Block(-1,12,0,LOG:13)
Block(-1,12,1,LEAVES:1)
Block(-1,12,7,LEAVES:1)
Block(-1,12,8,LEAVES:1)
Block(-1,12,9,LEAVES:1)
Block(-1,13,-8,LEAVES:1)
Block(-1,13,0,LEAVES:1)
Block(-1,13,4,LEAVES:1)
Block(-1,13,5,LOG:13)
Block(-1,13,6,LOG:13)
Block(-1,13,7,LEAVES:1)
Block(-1,14,-9,LEAVES:1)
Block(-1,14,-8,LEAVES:1)
Block(-1,14,-7,LOG:13)
Block(-1,14,2,LEAVES:1)
Block(-1,14,4,LEAVES:1)
Block(-1,14,5,LEAVES:1)
Block(-1,14,6,LEAVES:1)
Block(-1,15,-8,LEAVES:1)
Block(-1,15,-7,LEAVES:1)
Block(-1,15,-6,LOG:13)
Block(-1,15,-5,LEAVES:1)
Block(-1,15,-4,LEAVES:1)
Block(-1,15,-3,LEAVES:1)
Block(-1,15,1,LEAVES:1)
Block(-1,16,-6,LEAVES:1)
Block(-1,16,-5,LOG:13)
Block(-1,16,-4,LOG:13)
Block(-1,16,-3,LEAVES:1)
Block(-1,17,-5,LEAVES:1)
Block(-1,17,-4,LEAVES:1)
Block(-1,17,-3,LEAVES:1)
Block(-1,17,-2,LEAVES:1)
Block(-1,18,-1,LEAVES:1)
Block(-1,18,3,LEAVES:1)
Block(-1,19,-2,LEAVES:1)
Block(-1,19,-1,LEAVES:1)
Block(-1,19,0,LOG:13)
Block(-1,19,1,LEAVES:1)
Block(-1,20,0,LEAVES:1)
Block(-1,20,3,LEAVES:1)
Block(-1,21,2,LEAVES:1)
Block(-1,21,3,LEAVES:1)
Block(-1,21,4,LEAVES:1)
Block(-1,22,-4,LEAVES:1)
Block(-1,22,1,LEAVES:1)
Block(-1,22,2,LOG:13)
Block(-1,22,3,LEAVES:1)
Block(-1,22,4,LEAVES:1)
Block(-1,22,5,LEAVES:1)
Block(-1,23,-6,LEAVES:1)
Block(-1,23,-5,LEAVES:1)
Block(-1,23,-4,LEAVES:1)
Block(-1,23,0,LEAVES:1)
Block(-1,23,1,LEAVES:1)
Block(-1,23,2,LEAVES:1)
Block(-1,23,3,LEAVES:1)
Block(-1,24,-5,LEAVES:1)
Block(-1,24,-4,LEAVES:1)
Block(-1,24,-3,LOG:13)
Block(-1,24,-2,LEAVES:1)
Block(-1,24,0,LEAVES:1)
Block(-1,24,1,LEAVES:1)
Block(-1,25,-4,LEAVES:1)
Block(-1,25,-3,LEAVES:1)
Block(-1,25,-2,LEAVES:1)
Block(-1,25,-1,LEAVES:1)
Block(-1,26,-6,LEAVES:1)
Block(-1,26,-4,LEAVES:1)
Block(-1,26,-3,LEAVES:1)
Block(-1,26,-1,LEAVES:1)
Block(-1,26,0,LEAVES:1)
Block(-1,26,1,LEAVES:1)
Block(-1,26,2,LEAVES:1)
Block(-1,27,-5,LEAVES:1)
Block(-1,27,-4,LEAVES:1)
Block(-1,27,-3,LOG:13)
Block(-1,27,-2,LEAVES:1)
Block(-1,27,-1,LEAVES:1)
Block(-1,27,0,LOG:13)
Block(-1,27,1,LEAVES:1)
Block(-1,28,-4,LEAVES:1)
Block(-1,28,-3,LEAVES:1)
Block(-1,28,-2,LOG:13)
Block(-1,28,0,LEAVES:1)
Block(-1,28,2,LEAVES:1)
Block(-1,28,4,LEAVES:1)
Block(-1,29,-2,LEAVES:1)
Block(-1,29,-1,LEAVES:1)
Block(-1,29,2,LOG:13)
Block(-1,29,3,LOG:13)
Block(-1,29,4,LEAVES:1)
Block(-1,29,5,LEAVES:1)
Block(-1,30,-2,LEAVES:1)
Block(-1,30,-1,LEAVES:1)
Block(-1,30,0,LEAVES:1)
Block(-1,30,1,LEAVES:1)
Block(-1,30,2,LEAVES:1)
Block(-1,30,3,LEAVES:1)
Block(-1,30,4,LEAVES:1)
Block(-1,31,-1,LEAVES:1)
Block(-1,31,0,LEAVES:1)
Block(-1,31,1,LEAVES:1)
Block(-1,31,3,LEAVES:1)
Block(-1,32,0,LEAVES:1)
Block(-1,33,0,LEAVES:1)
Block(-1,34,-1,LEAVES:1)
Block(-1,34,0,LEAVES:1)
Block(-1,36,0,LEAVES:1)
Block(-1,38,0,LEAVES:1)
Block(-1,39,-1,LEAVES:1)
Block(-1,39,0,LEAVES:1)
Block(-1,40,0,LEAVES:1)
Block(0,-7,-7,LOG:9)
Block(0,-7,-6,LOG:1)
Block(0,-7,-4,LOG:9)
Block(0,-7,-3,LOG:1)
Block(0,-7,3,LOG:1)
Block(0,-7,4,LOG:1)
Block(0,-6,-6,LOG:13)
Block(0,-6,-3,LOG:13)
Block(0,-6,-2,LOG:13)

#######################################################################
# +-----------------------------------------------------------------+ #
# |                            BO3 checks                           | #
# +-----------------------------------------------------------------+ #
#######################################################################


#######################################################################
# +-----------------------------------------------------------------+ #
# |                             Branches                            | #
# +-----------------------------------------------------------------+ #
#######################################################################


#######################################################################
# +-----------------------------------------------------------------+ #
# |                             Entities                            | #
# +-----------------------------------------------------------------+ #
#######################################################################


#######################################################################
# +-----------------------------------------------------------------+ #
# |                            Particles                            | #
# +-----------------------------------------------------------------+ #
#######################################################################


#######################################################################
# +-----------------------------------------------------------------+ #
# |                             Spawners                            | #
# +-----------------------------------------------------------------+ #
#######################################################################


#######################################################################
# +-----------------------------------------------------------------+ #
# |                             ModData                             | #
# +-----------------------------------------------------------------+ #
#######################################################################

