
#######################################################################
# +-----------------------------------------------------------------+ #
# |                            BO4 object                           | #
# +-----------------------------------------------------------------+ #
#######################################################################

Author: BasieBrinkie

Description: No description given

SettingsMode: WriteWithoutComments


#######################################################################
# +-----------------------------------------------------------------+ #
# |                          Main settings                          | #
# +-----------------------------------------------------------------+ #
#######################################################################

Frequency: 0

SpawnHeight: highestBlock

UseCenterForHighestBlock: true

##############################
# Height Limits for the BO4. #
##############################

MinHeight: 0

MaxHeight: 255

InheritBO3: 

InheritBO3Rotation: NORTH

OverrideChildSettings: true

OverrideParentHeight: false

CanOverride: false

BranchFrequency: 0

BranchFrequencyGroup: 

MustBeBelowOther: false

MustBeInside: 

CannotBeInside: 

ReplacesBO3: 

MustBeInsideWorldBorders: false

CanSpawnOnWater: true

SpawnOnWaterOnly: false

SpawnUnderWater: false

SpawnAtWaterLevel: false

HeightOffset: 0

RemoveAir: true

ReplaceAbove: 

ReplaceBelow: 

ReplaceWithBiomeBlocks: true

ReplaceWithSurfaceBlock: GRASS

ReplaceWithGroundBlock: DIRT

ReplaceWithStoneBlock: STONE

SmoothRadius: 0

SmoothHeightOffset: 0

SmoothStartTop: false

SmoothStartWood: false

SmoothingSurfaceBlock: 

SmoothingGroundBlock: 

BO3Group: 

IsSpawnPoint: false

DoReplaceBlocks: true


#######################################################################
# +-----------------------------------------------------------------+ #
# |                              Blocks                             | #
# +-----------------------------------------------------------------+ #
#######################################################################

Block(-8,0,7,STONE:0)
Block(-8,2,7,STONE:0)
Block(-8,2,8,STONE:0)
Block(-8,3,7,STONE:0)
Block(-8,3,8,STONE:0)
Block(-8,4,8,STONE:0)
Block(-8,5,7,STONE:0)
Block(-8,5,8,STONE:0)
Block(-8,6,7,STONE:0)
Block(-8,6,8,STONE:0)
Block(-7,-1,7,STONE:0)
Block(-7,-1,8,STONE:0)
Block(-7,0,6,STONE:0)
Block(-7,0,7,COAL_ORE:0)
Block(-7,0,8,STONE:0)
Block(-7,1,6,STONE:0)
Block(-7,1,7,STONE:0)
Block(-7,2,5,STONE:0)
Block(-7,2,6,STONE:0)
Block(-7,2,7,COAL_ORE:0)
Block(-7,2,8,STONE:0)
Block(-7,3,4,STONE:0)
Block(-7,3,5,STONE:0)
Block(-7,3,6,STONE:0)
Block(-7,3,7,COAL_ORE:0)
Block(-7,3,8,STONE:0)
Block(-7,4,6,STONE:0)
Block(-7,4,7,STONE:0)
Block(-7,4,8,STONE:0)
Block(-7,5,7,COAL_ORE:0)
Block(-7,5,8,STONE:0)
Block(-7,6,4,STONE:0)
Block(-7,6,7,STONE:0)
Block(-7,7,4,STONE:0)
Block(-7,7,5,STONE:0)
Block(-7,7,6,STONE:0)
Block(-7,8,5,STONE:0)
Block(-7,8,6,STONE:0)
Block(-6,-2,8,STONE:0)
Block(-6,-1,5,STONE:0)
Block(-6,-1,6,STONE:0)
Block(-6,-1,7,STONE:0)
Block(-6,-1,8,COAL_ORE:0)
Block(-6,0,5,STONE:0)
Block(-6,0,6,COAL_ORE:0)
Block(-6,0,7,COAL_ORE:0)
Block(-6,0,8,COAL_ORE:0)
Block(-6,1,6,STONE:0)
Block(-6,1,7,COAL_ORE:0)
Block(-6,1,8,STONE:0)
Block(-6,2,5,STONE:0)
Block(-6,2,6,COAL_ORE:0)
Block(-6,2,7,STONE:0)
Block(-6,3,4,STONE:0)
Block(-6,3,5,COAL_ORE:0)
Block(-6,3,6,COAL_ORE:0)
Block(-6,3,7,STONE:0)
Block(-6,4,5,STONE:0)
Block(-6,4,6,COAL_ORE:0)
Block(-6,4,7,STONE:0)
Block(-6,4,8,STONE:0)
Block(-6,5,6,STONE:0)
Block(-6,5,7,STONE:0)
Block(-6,5,8,STONE:0)
Block(-6,6,3,STONE:0)
Block(-6,6,4,STONE:0)
Block(-6,6,5,STONE:0)
Block(-6,7,4,STONE:0)
Block(-6,7,5,COAL_ORE:0)
Block(-6,7,6,STONE:0)
Block(-6,8,4,STONE:0)
Block(-6,8,5,STONE:0)
Block(-6,8,6,STONE:0)
Block(-6,9,3,STONE:0)
Block(-6,9,4,STONE:0)
Block(-5,-1,5,STONE:0)
Block(-5,-1,6,STONE:0)
Block(-5,-1,7,STONE:0)
Block(-5,-1,8,STONE:0)
Block(-5,0,4,STONE:0)
Block(-5,0,5,COAL_ORE:0)
Block(-5,0,6,COAL_ORE:0)
Block(-5,0,7,COAL_ORE:0)
Block(-5,0,8,STONE:0)
Block(-5,1,4,STONE:0)
Block(-5,1,5,STONE:0)
Block(-5,1,6,COAL_ORE:0)
Block(-5,1,7,STONE:0)
Block(-5,2,5,COAL_ORE:0)
Block(-5,2,6,COAL_ORE:0)
Block(-5,2,7,STONE:0)
Block(-5,3,5,COAL_ORE:0)
Block(-5,3,6,COAL_ORE:0)
Block(-5,3,7,STONE:0)
Block(-5,4,4,STONE:0)
Block(-5,4,5,COAL_ORE:0)
Block(-5,4,6,STONE:0)
Block(-5,5,3,STONE:0)
Block(-5,5,4,COAL_ORE:0)
Block(-5,5,5,STONE:0)
Block(-5,6,3,STONE:0)
Block(-5,6,4,COAL_ORE:0)
Block(-5,6,5,STONE:0)
Block(-5,7,3,STONE:0)
Block(-5,7,4,COAL_ORE:0)
Block(-5,7,5,COAL_ORE:0)
Block(-5,7,6,STONE:0)
Block(-5,8,3,STONE:0)
Block(-5,8,4,STONE:0)
Block(-5,8,5,STONE:0)
Block(-5,8,6,STONE:0)
Block(-5,9,4,STONE:0)
Block(-5,10,2,STONE:0)
Block(-5,10,3,STONE:0)
Block(-5,10,4,STONE:0)
Block(-5,11,4,STONE:0)
Block(-4,-4,7,STONE:0)
Block(-4,-2,5,STONE:0)
Block(-4,-2,6,STONE:0)
Block(-4,-2,7,STONE:0)
Block(-4,-1,3,STONE:0)
Block(-4,-1,5,STONE:0)
Block(-4,-1,6,COAL_ORE:0)
Block(-4,-1,7,COAL_ORE:0)
Block(-4,-1,8,STONE:0)
Block(-4,0,4,STONE:0)
Block(-4,0,5,COAL_ORE:0)
Block(-4,0,6,COAL_ORE:0)
Block(-4,0,7,COAL_ORE:0)
Block(-4,0,8,COAL_ORE:0)
Block(-4,1,4,STONE:0)
Block(-4,1,5,COAL_ORE:0)
Block(-4,1,6,COAL_ORE:0)
Block(-4,1,7,COAL_ORE:0)
Block(-4,1,8,STONE:0)
Block(-4,2,4,STONE:0)
Block(-4,2,5,COAL_ORE:0)
Block(-4,2,6,COAL_ORE:0)
Block(-4,2,7,COAL_ORE:0)
Block(-4,2,8,STONE:0)
Block(-4,3,4,STONE:0)
Block(-4,3,5,COAL_ORE:0)
Block(-4,3,6,COAL_ORE:0)
Block(-4,3,7,STONE:0)
Block(-4,4,5,STONE:0)
Block(-4,4,6,COAL_ORE:0)
Block(-4,4,7,STONE:0)
Block(-4,4,8,STONE:0)
Block(-4,5,3,STONE:0)
Block(-4,5,4,STONE:0)
Block(-4,5,5,COAL_ORE:0)
Block(-4,5,6,STONE:0)
Block(-4,5,7,STONE:0)
Block(-4,6,4,STONE:0)
Block(-4,6,5,STONE:0)
Block(-4,6,6,STONE:0)
Block(-4,7,3,STONE:0)
Block(-4,7,4,STONE:0)
Block(-4,7,5,STONE:0)
Block(-4,8,5,STONE:0)
Block(-4,9,4,STONE:0)
Block(-3,-4,6,STONE:0)
Block(-3,-4,7,STONE:0)
Block(-3,-4,8,STONE:0)
Block(-3,-3,7,STONE:0)
Block(-3,-3,8,STONE:0)
Block(-3,-2,8,STONE:0)
Block(-3,-1,5,STONE:0)
Block(-3,-1,6,STONE:0)
Block(-3,-1,7,STONE:0)
Block(-3,-1,8,COAL_ORE:0)
Block(-3,0,5,STONE:0)
Block(-3,0,6,STONE:0)
Block(-3,0,7,STONE:0)
Block(-3,0,8,COAL_ORE:0)
Block(-3,1,4,STONE:0)
Block(-3,1,5,COAL_ORE:0)
Block(-3,1,6,COAL_ORE:0)
Block(-3,1,7,COAL_ORE:0)
Block(-3,1,8,COAL_ORE:0)
Block(-3,2,4,STONE:0)
Block(-3,2,5,COAL_ORE:0)
Block(-3,2,6,COAL_ORE:0)
Block(-3,2,7,COAL_ORE:0)
Block(-3,2,8,COAL_ORE:0)
Block(-3,3,5,STONE:0)
Block(-3,3,6,COAL_ORE:0)
Block(-3,3,7,COAL_ORE:0)
Block(-3,3,8,STONE:0)
Block(-3,4,6,STONE:0)
Block(-3,4,7,STONE:0)
Block(-3,4,8,STONE:0)
Block(-3,5,4,STONE:0)
Block(-3,5,5,STONE:0)
Block(-3,9,4,STONE:0)
Block(-3,9,5,STONE:0)
Block(-2,-4,5,STONE:0)
Block(-2,-4,6,STONE:0)
Block(-2,-4,7,STONE:0)
Block(-2,-4,8,STONE:0)
Block(-2,-3,7,STONE:0)
Block(-2,-3,8,STONE:0)
Block(-2,-2,5,STONE:0)
Block(-2,-2,6,STONE:0)
Block(-2,-1,5,STONE:0)
Block(-2,-1,6,STONE:0)
Block(-2,-1,8,STONE:0)
Block(-2,0,8,STONE:0)
Block(-2,1,5,STONE:0)
Block(-2,1,6,STONE:0)
Block(-2,1,7,STONE:0)
Block(-2,1,8,STONE:0)
Block(-2,2,5,STONE:0)
Block(-2,2,6,STONE:0)
Block(-2,2,7,STONE:0)
Block(-2,2,8,STONE:0)
Block(-2,3,5,STONE:0)
Block(-2,3,6,STONE:0)
Block(-2,3,7,STONE:0)
Block(-2,3,8,STONE:0)
Block(-2,4,6,STONE:0)
Block(-2,5,5,STONE:0)
Block(-2,5,6,STONE:0)
Block(-2,5,7,STONE:0)
Block(-1,-4,3,STONE:0)
Block(-1,-4,4,STONE:0)
Block(-1,-4,5,STONE:0)
Block(-1,-4,6,STONE:0)
Block(-1,-4,7,STONE:0)
Block(-1,-4,8,STONE:0)
Block(-1,-3,7,STONE:0)
Block(-1,-3,8,STONE:0)
Block(-1,-2,5,STONE:0)
Block(-1,-2,7,STONE:0)
Block(-1,-2,8,STONE:0)
Block(-1,-1,7,STONE:0)
Block(-1,-1,8,STONE:0)
Block(-1,1,5,STONE:0)
Block(-1,1,8,STONE:0)
Block(-1,5,6,STONE:0)
Block(0,-4,4,STONE:0)
Block(0,-4,5,STONE:0)
Block(0,-4,6,STONE:0)
Block(0,-4,7,STONE:0)
Block(0,-4,8,STONE:0)
Block(0,-3,7,STONE:0)
Block(0,-3,8,STONE:0)
Block(0,-2,7,STONE:0)
Block(0,-2,8,COAL_ORE:0)
Block(0,-1,8,STONE:0)
Block(0,0,8,STONE:0)
Block(0,1,7,STONE:0)
Block(0,1,8,STONE:0)
Block(1,-4,6,STONE:0)
Block(1,-4,7,STONE:0)
Block(1,-4,8,STONE:0)
Block(1,-3,6,STONE:0)
Block(1,-3,7,STONE:0)
Block(1,-3,8,STONE:0)
Block(1,-2,7,STONE:0)
Block(1,-2,8,COAL_ORE:0)
Block(1,-1,8,STONE:0)
Block(1,1,8,STONE:0)
Block(1,2,7,STONE:0)
Block(1,2,8,STONE:0)
Block(2,-4,1,STONE:0)
Block(2,-4,2,STONE:0)
Block(2,-4,3,STONE:0)
Block(2,-4,5,STONE:0)
Block(2,-4,6,STONE:0)
Block(2,-4,7,STONE:0)
Block(2,-4,8,STONE:0)
Block(2,-3,6,STONE:0)
Block(2,-3,7,STONE:0)
Block(2,-3,8,STONE:0)
Block(2,-2,6,STONE:0)
Block(2,-2,7,STONE:0)
Block(2,-2,8,STONE:0)
Block(2,-1,6,STONE:0)
Block(2,1,8,STONE:0)
Block(2,13,7,STONE:0)
Block(3,-5,0,STONE:0)
Block(3,-5,1,STONE:0)
Block(3,-5,2,STONE:0)
Block(3,-5,3,STONE:0)
Block(3,-5,4,STONE:0)
Block(3,-5,5,STONE:0)
Block(3,-5,6,STONE:0)
Block(3,-5,7,STONE:0)
Block(3,-5,8,STONE:0)
Block(3,-4,3,STONE:0)
Block(3,-4,5,STONE:0)
Block(3,-4,6,STONE:0)
Block(3,-4,7,STONE:0)
Block(3,-4,8,STONE:0)
Block(3,-3,5,STONE:0)
Block(3,-3,6,STONE:0)
Block(3,-3,7,STONE:0)
Block(3,-3,8,STONE:0)
Block(3,-2,6,STONE:0)
Block(3,10,7,STONE:0)
Block(3,11,8,STONE:0)
Block(3,12,8,STONE:0)
Block(3,13,8,STONE:0)
Block(4,-5,-1,STONE:0)
Block(4,-5,0,STONE:0)
Block(4,-5,1,STONE:0)
Block(4,-5,2,STONE:0)
Block(4,-5,3,STONE:0)
Block(4,-5,4,STONE:0)
Block(4,-5,5,STONE:0)
Block(4,-5,6,STONE:0)
Block(4,-5,7,STONE:0)
Block(4,-5,8,STONE:0)
Block(4,-4,2,STONE:0)
Block(4,-4,3,STONE:0)
Block(4,-4,4,STONE:0)
Block(4,-4,5,STONE:0)
Block(4,-4,6,STONE:0)
Block(4,-4,7,STONE:0)
Block(4,-4,8,STONE:0)
Block(4,-3,0,STONE:0)
Block(4,-3,2,STONE:0)
Block(4,-3,5,STONE:0)
Block(4,-3,6,STONE:0)
Block(4,-3,7,STONE:0)
Block(4,-3,8,STONE:0)
Block(4,-2,6,STONE:0)
Block(4,-2,7,STONE:0)
Block(4,-2,8,STONE:0)
Block(4,-1,6,STONE:0)
Block(4,-1,7,STONE:0)
Block(4,-1,8,STONE:0)
Block(4,0,-5,STONE:0)
Block(4,0,-4,STONE:0)
Block(4,0,-3,STONE:0)
Block(4,0,6,STONE:0)
Block(4,1,5,STONE:0)
Block(4,9,8,STONE:0)
Block(4,10,8,STONE:0)
Block(4,12,8,STONE:0)
Block(5,-5,0,STONE:0)
Block(5,-5,1,STONE:0)
Block(5,-5,2,STONE:0)
Block(5,-5,3,STONE:0)
Block(5,-5,4,STONE:0)
Block(5,-5,5,STONE:0)
Block(5,-5,6,STONE:0)
Block(5,-5,7,STONE:0)
Block(5,-5,8,STONE:0)
Block(5,-4,1,STONE:0)
Block(5,-4,2,STONE:0)
Block(5,-4,3,STONE:0)
Block(5,-4,4,STONE:0)
Block(5,-4,5,STONE:0)
Block(5,-4,6,STONE:0)
Block(5,-4,7,STONE:0)
Block(5,-4,8,STONE:0)
Block(5,-3,0,STONE:0)
Block(5,-3,1,STONE:0)
Block(5,-3,2,STONE:0)
Block(5,-3,3,STONE:0)
Block(5,-3,4,STONE:0)
Block(5,-3,5,STONE:0)
Block(5,-3,6,STONE:0)
Block(5,-3,7,STONE:0)
Block(5,-3,8,STONE:0)
Block(5,-2,-1,STONE:0)
Block(5,-2,0,STONE:0)
Block(5,-2,1,STONE:0)
Block(5,-2,2,STONE:0)
Block(5,-2,7,STONE:0)
Block(5,-2,8,STONE:0)
Block(5,-1,-2,STONE:0)
Block(5,-1,-1,STONE:0)
Block(5,-1,7,STONE:0)
Block(5,-1,8,STONE:0)
Block(5,0,-4,STONE:0)
Block(5,0,-3,STONE:0)
Block(5,0,6,STONE:0)
Block(5,0,7,STONE:0)
Block(5,1,-6,STONE:0)
Block(5,1,-5,STONE:0)
Block(5,1,-4,STONE:0)
Block(5,1,7,STONE:0)
Block(5,1,8,STONE:0)
Block(6,-5,1,STONE:0)
Block(6,-5,2,STONE:0)
Block(6,-5,3,STONE:0)
Block(6,-5,4,STONE:0)
Block(6,-5,5,STONE:0)
Block(6,-5,6,STONE:0)
Block(6,-5,7,STONE:0)
Block(6,-5,8,STONE:0)
Block(6,-4,1,STONE:0)
Block(6,-4,2,STONE:0)
Block(6,-4,3,STONE:0)
Block(6,-4,4,STONE:0)
Block(6,-4,5,STONE:0)
Block(6,-4,6,STONE:0)
Block(6,-4,7,STONE:0)
Block(6,-4,8,STONE:0)
Block(6,-3,0,STONE:0)
Block(6,-3,1,STONE:0)
Block(6,-3,2,STONE:0)
Block(6,-3,3,STONE:0)
Block(6,-3,4,STONE:0)
Block(6,-3,5,STONE:0)
Block(6,-3,6,STONE:0)
Block(6,-3,7,STONE:0)
Block(6,-3,8,STONE:0)
Block(6,-2,-1,STONE:0)
Block(6,-2,0,STONE:0)
Block(6,-2,1,STONE:0)
Block(6,-2,2,COAL_ORE:0)
Block(6,-2,3,STONE:0)
Block(6,-2,4,STONE:0)
Block(6,-2,5,STONE:0)
Block(6,-2,7,STONE:0)
Block(6,-2,8,COAL_ORE:0)
Block(6,-1,-2,STONE:0)
Block(6,-1,-1,STONE:0)
Block(6,-1,2,STONE:0)
Block(6,-1,7,STONE:0)
Block(6,-1,8,COAL_ORE:0)
Block(6,0,5,STONE:0)
Block(6,0,6,STONE:0)
Block(6,0,7,COAL_ORE:0)
Block(6,0,8,STONE:0)
Block(6,1,6,STONE:0)
Block(6,1,7,COAL_ORE:0)
Block(6,1,8,STONE:0)
Block(6,2,4,STONE:0)
Block(6,2,5,STONE:0)
Block(6,2,6,STONE:0)
Block(6,2,7,STONE:0)
Block(6,2,8,STONE:0)
Block(7,-5,1,STONE:0)
Block(7,-5,2,STONE:0)
Block(7,-5,3,STONE:0)
Block(7,-5,4,STONE:0)
Block(7,-5,5,STONE:0)
Block(7,-5,6,STONE:0)
Block(7,-5,7,STONE:0)
Block(7,-5,8,STONE:0)
Block(7,-4,0,STONE:0)
Block(7,-4,1,STONE:0)
Block(7,-4,2,STONE:0)
Block(7,-4,3,STONE:0)
Block(7,-4,4,STONE:0)
Block(7,-4,5,STONE:0)
Block(7,-4,6,STONE:0)
Block(7,-4,7,STONE:0)
Block(7,-4,8,STONE:0)
Block(7,-3,-1,STONE:0)
Block(7,-3,0,STONE:0)
Block(7,-3,1,STONE:0)
Block(7,-3,2,STONE:0)
Block(7,-3,3,STONE:0)
Block(7,-3,4,STONE:0)
Block(7,-3,5,STONE:0)
Block(7,-3,6,STONE:0)
Block(7,-3,7,STONE:0)
Block(7,-3,8,STONE:0)
Block(7,-2,-2,STONE:0)
Block(7,-2,-1,COAL_ORE:0)
Block(7,-2,0,COAL_ORE:0)
Block(7,-2,1,COAL_ORE:0)
Block(7,-2,2,COAL_ORE:0)
Block(7,-2,3,COAL_ORE:0)
Block(7,-2,4,COAL_ORE:0)
Block(7,-2,5,STONE:0)
Block(7,-2,6,STONE:0)
Block(7,-2,7,COAL_ORE:0)
Block(7,-2,8,COAL_ORE:0)
Block(7,-1,-3,STONE:0)
Block(7,-1,-2,STONE:0)
Block(7,-1,-1,STONE:0)
Block(7,-1,0,STONE:0)
Block(7,-1,1,STONE:0)
Block(7,-1,2,STONE:0)
Block(7,-1,3,STONE:0)
Block(7,-1,4,STONE:0)
Block(7,-1,6,STONE:0)
Block(7,-1,7,COAL_ORE:0)
Block(7,-1,8,COAL_ORE:0)
Block(7,0,5,STONE:0)
Block(7,0,6,COAL_ORE:0)
Block(7,0,7,COAL_ORE:0)
Block(7,0,8,COAL_ORE:0)
Block(7,1,5,STONE:0)
Block(7,1,6,COAL_ORE:0)
Block(7,1,7,COAL_ORE:0)
Block(7,1,8,COAL_ORE:0)
Block(7,2,5,STONE:0)
Block(7,2,6,COAL_ORE:0)
Block(7,2,7,COAL_ORE:0)
Block(7,2,8,STONE:0)
Block(7,3,4,STONE:0)
Block(7,3,6,STONE:0)
Block(7,3,7,STONE:0)
Block(7,3,8,STONE:0)
Block(7,4,4,COAL_ORE:0)
Block(7,4,5,STONE:0)
Block(7,4,6,STONE:0)
Block(7,5,5,STONE:0)

#######################################################################
# +-----------------------------------------------------------------+ #
# |                             Branches                            | #
# +-----------------------------------------------------------------+ #
#######################################################################

Branch(16,0,0,true,SpikeClusterOreC1R0,NORTH,100.0,0)

#######################################################################
# +-----------------------------------------------------------------+ #
# |                             Entities                            | #
# +-----------------------------------------------------------------+ #
#######################################################################


#######################################################################
# +-----------------------------------------------------------------+ #
# |                            Particles                            | #
# +-----------------------------------------------------------------+ #
#######################################################################


#######################################################################
# +-----------------------------------------------------------------+ #
# |                             Spawners                            | #
# +-----------------------------------------------------------------+ #
#######################################################################


#######################################################################
# +-----------------------------------------------------------------+ #
# |                             ModData                             | #
# +-----------------------------------------------------------------+ #
#######################################################################

