#######################################################################
# +-----------------------------------------------------------------+ #
# |                            BO3 object                           | #
# +-----------------------------------------------------------------+ #
#######################################################################

# This BO3 is made for use with MCW and OTG+.
# The descriptions in this file are only accurate for MCW and OTG+.
# For TerrainControl and OTG these descriptions are only accurate if the BO3 is used as a CustomObject.
# MCW and OTG+ completely reimplemented CustomStructure, check the MCW/OTG+ documentation for more information.

# This is the config file of a custom object.
# If you add this object correctly to your BiomeConfigs, it will spawn in the world.

# This is the creator of this BO3 object
Author: Unknown

# A short description of this BO3 object
Description: No description

# The BO3 version, don't change this! It can be used by external applications to do a version check.
Version: 4

# The settings mode, WriteAll, WriteWithoutComments or WriteDisable. See WorldConfig.
SettingsMode: WriteDisable

#######################################################################
# +-----------------------------------------------------------------+ #
# |                          Main settings                          | #
# +-----------------------------------------------------------------+ #
#######################################################################

IsOTGPlus: true
# This settings is currently unavailable for MCW/OTG+.
Tree: false

# The rarity of the BO3 from 0 to 100. Each spawn attempt has rarity% chance to succeed when using the CustomObject(...) resource.
# Ignored by MCW/OTG+ for Tree(..), Sapling(..) and CustomStructure(..).
Rarity: 100

# Minimum distance in chunks between structures with the same filename.
Frequency: 0

# This settings is currently unavailable for MCW/OTG+, you can easily work around this though by creating a master bo3 without blocks that
# has the real starting BO3 as a branch.
# You can then duplicate the master BO3 3 times and give each copy's branch a different rotation.
RotateRandomly: false

# The spawn height of the BO3 - randomY or highestBlock.
SpawnHeight: highestBlock

# The height limits for the BO3. Can be combined with randomY to spawn the BO3 at a random height
# between MinHeight and MaxHeight. Can be combined with highestBlock to make sure that the BO3 spawns
# only between MinHeight and MaxHeight.
MinHeight: 0

MaxHeight: 256

# This settings is disabled for MCW/OTG+.
ExcludedBiomes: All

# To optimise this BO3 for faster loading times you can use Notepad++ to find/replace comments and abbreviate things.
# Notepad++ find/replace with regex:
# Find: ^[#;].* replace to nothing removes all lines starting with #
# Find: ^\s*$ replace to nothing removes most empty lines
# Notepad++ find/replace without regex:
# *Warning: This will only work for OTG 1.10.2 v21 / OTG 1.11.2 v6 or higher. B( is not recognised by lower versions.
# Find: Block( replace to B(

#######################################################################
# +-----------------------------------------------------------------+ #
# |                      Source block settings                      | #
# +-----------------------------------------------------------------+ #
#######################################################################

# This settings is disabled for MCW/OTG+.
SourceBlocks: AIR

# This settings is disabled for MCW/OTG+.
MaxPercentageOutsideSourceBlock: 100

# This settings is disabled for MCW/OTG+.
OutsideSourceBlock: placeAnyway

# MineCraft Worlds mod settings #
# NOTE: you can delete any of these settings if you're not using them, the default values will automatically be used. #

# Copies the blocks and branches of an existing BO3 into this BO3.
#InheritBO3:

# Defaults to true, if true and this is the root BO3 for this branching structure then this BO3's smoothing and height settings are used for all its children (branches).
#OverrideChildSettings: true

# If this is set to true then this BO3 can spawn as a branch on top of or inside an existing BO3/branch (only within the same customstructure).
CanOverride: true

# If this is set to true then this BO3 can only spawn underneath an existing BO3. Used to make sure that dungeons only appear underneath buildings
#MustBeBelowOther: false

# A comma-seperated list of BO3s, this BO3 must touch one of these when spawned or it will not be able to spawn.
#MustBeInside:

# A comma-seperated list of BO3s, this BO3 cannot touch one of these when spawned, if it does it will not be able to spawn.
#CannotBeInside:

# Defaults to true. Set to false if the BO3 is not allowed to spawn on a water block
#CanSpawnOnWater: true

# Defaults to false. Set to true if the BO3 is allowed to spawn only on a water block
#SpawnOnWaterOnly: false

# Defaults to false. Set to true if the BO3 and its smoothing area should ignore water when looking for the highest block to spawn on. Defaults to false (things spawn on top of water)
#SpawnUnderWater: false

# Defaults to false. Set to true if the BO3 should spawn at water level
#SpawnAtWaterLevel: false


# Spawns the BO3 at a Y offset of this value. Handy when using highestBlock for lowering BO3s into the surrounding terrain when there are layers of ground included in the BO3, also handy when using SpawnAtWaterLevel to lower objects like ships into the water.
#HeightOffset: 0

# If set to true removes all AIR blocks from the BO3 so that it can be flooded or buried.
#RemoveAir: true

# Replaces all the non-air blocks that are above this BO3 or its smoothing area with the given block material (should be WATER or AIR or NONE), also applies to smoothing areas although it intentionally leaves some of the terrain above them intact. WATER can be used in combination with SpawnUnderWater to fill any air blocks underneath waterlevel with water (and any above waterlevel with air).
#ReplaceAbove: AIR

# Replaces all air blocks underneath the BO3 (but not its smoothing area) with the designated material until a solid block is found.
#ReplaceBelow:

# Defaults to true. If set to true then every block in the BO3 of the materials defined in ReplaceWithGroundBlock or ReplaceWithSurfaceBlock will be replaced by the GroundBlock or SurfaceBlock materials configured for the biome the block is spawned in.
#ReplaceWithBiomeBlocks: true

# Defaults to DIRT, Replaces all the blocks of the given material in the BO3 with the GroundBlock configured for the biome it spawns in
#ReplaceWithGroundBlock: DIRT

# Defaults to GRASS, Replaces all the blocks of the given material in the BO3 with the SurfaceBlock configured for the biome it spawns in
#ReplaceWithSurfaceBlock: GRASS


# Makes the terrain around the BO3 slope gradually towards the edges of the BO3. The given value is the distance in blocks around the BO3 from where the slope should start and can be any positive number.
#SmoothRadius: 0

# Moves the smoothing area up or down relative to the BO3 (at the points where the smoothing area is connected to the BO3). Handy when using SmoothStartTop: false and the BO3 has some layers of ground included, in that case we can set the HeightOffset to a negative value to lower the BO3 into the ground and we can set the SmoothHeightOffset to a positive value to move the smoothing area starting height up
#SmoothHeightOffset: 0

# Should the smoothing area be attached at the bottom or the top of the edges of the BO3? Defaults to false (bottom). Using this setting can make things slower so try to avoid using it and use SmoothHeightOffset instead if for instance you have a BO3 with some ground layers included. The only reason you should need to use this setting is if you have a BO3 with edges that have an irregular height (like some hills).
#SmoothStartTop: false

# Should the smoothing area attach itself to "log" block or ignore them? Defaults to false (ignore logs).
#SmoothStartWood: false

# The block used for smoothing area surface blocks, defaults to biome SurfaceBlock
#SmoothingSurfaceBlock:

# The block used for smoothing area ground blocks, defaults to biome GroundBlock
#SmoothingGroundBlock:


# Define groups that this BO3 belongs to along with a minimum range in chunks that this BO3 must have between it and any other members of this group if it is to be allowed to spawn. Syntax is "GroupName:Frequency, GoupName2:Frequency2" etc so for example a BO3 that belongs to 3 groups: "BO3Group: Ships:10, Vehicles:5, FloatingThings:3"
#BO3Group:

# Defaults to false. Set to true if this BO3 should spawn at the player spawn point. When the server starts the spawn point is determined and the BO3's for the biome it is in are loaded, one of these BO3s that has IsSpawnPoint set to true (if any) is selected randomly and is spawned at the spawn point regardless of its rarity (so even Rarity:0, IsSpawnPoint: true BO3's can get spawned as the spawn point!).
#IsSpawnPoint: false

# Defaults to 8, if SpawnPointY > -1 and this BO3 is spawned at the spawn point then the player spawn point is placed within this BO3 at x y and z offsets (spawnPointX, spawnPointY, spawnPointZ) relative to x0y0z0 in this BO3.
#SpawnPointX: 8

# Defaults to highestBlock, if this is defined and this BO3 is spawned at the spawn point then the player spawn point is placed at a y offset of this value relative to y = 0 in this BO3.)
#SpawnPointY: -1

# Defaults to 7, if spawnPointY > -1 and this BO3 is spawned at the spawn point then the player spawn point is placed within this BO3 at a x y and z offsets (spawnPointX, spawnPointY, spawnPointZ) relative to x0y0z0 in this BO3.
#SpawnPointZ: 7

#######################################################################
# +-----------------------------------------------------------------+ #
# |                              Blocks                             | #
# +-----------------------------------------------------------------+ #
#######################################################################

# All the blocks used in the BO3 are listed here. Possible blocks:
# Block(x,y,z,id[.data][,nbtfile.nbt) or B(x,y,z,id[.data][,nbtfile.nbt)
# RandomBlock(x,y,z,id[:data][,nbtfile.nbt],chance[,id[:data][,nbtfile.nbt],chance[,...]])
# So RandomBlock(0,0,0,CHEST,chest.nbt,50,CHEST,anotherchest.nbt,100) will spawn a chest at
# the BO3 origin, and give it a 50% chance to have the contents of chest.nbt, or, if that
# fails, a 100% percent chance to have the contents of anotherchest.nbt.

Block(-8,0,-7,SMOOTH_BRICK:0)
Block(-8,0,-6,SMOOTH_BRICK:0)
Block(-8,0,-5,SMOOTH_BRICK:0)
Block(-8,0,-4,SMOOTH_BRICK:0)
Block(-8,0,-3,SMOOTH_BRICK:0)
Block(-8,0,-2,SMOOTH_BRICK:0)
Block(-8,0,-1,SMOOTH_BRICK:0)
Block(-8,0,0,SMOOTH_BRICK:0)
Block(-8,0,1,STONE:0)
Block(-8,0,2,STONE:0)
Block(-8,0,3,MONSTER_EGGS:4)
Block(-8,0,4,MONSTER_EGGS:4)
Block(-8,0,5,MONSTER_EGGS:4)
Block(-8,0,6,STONE:0)
Block(-8,0,7,MONSTER_EGGS:4)
Block(-8,0,8,SMOOTH_BRICK:0)
Block(-8,1,-7,SMOOTH_BRICK:0)
Block(-8,1,-6,STONE:0)
Block(-8,1,-5,SMOOTH_BRICK:0)
Block(-8,1,-4,SMOOTH_BRICK:0)
Block(-8,1,-3,SMOOTH_BRICK:0)
Block(-8,1,-2,SMOOTH_BRICK:0)
Block(-8,1,-1,SMOOTH_BRICK:0)
Block(-8,1,0,SMOOTH_BRICK:0)
Block(-8,1,1,SMOOTH_BRICK:0)
Block(-8,1,2,SMOOTH_BRICK:0)
Block(-8,1,3,SMOOTH_BRICK:0)
Block(-8,1,4,MONSTER_EGGS:4)
Block(-8,1,5,MONSTER_EGGS:4)
Block(-8,1,6,SMOOTH_BRICK:0)
Block(-8,1,7,SMOOTH_BRICK:0)
Block(-8,1,8,SMOOTH_BRICK:0)
Block(-8,2,-7,STONE:0)
Block(-8,2,-6,SMOOTH_BRICK:0)
Block(-8,2,-5,SMOOTH_BRICK:0)
Block(-8,2,-4,SMOOTH_BRICK:0)
Block(-8,2,-3,SMOOTH_BRICK:0)
Block(-8,2,-2,MONSTER_EGGS:4)
Block(-8,2,-1,SMOOTH_BRICK:0)
Block(-8,2,0,SMOOTH_BRICK:0)
Block(-8,2,1,STONE:0)
Block(-8,2,2,SMOOTH_BRICK:0)
Block(-8,2,3,SMOOTH_BRICK:0)
Block(-8,2,4,SMOOTH_BRICK:0)
Block(-8,2,5,SMOOTH_BRICK:0)
Block(-8,2,6,SMOOTH_BRICK:0)
Block(-8,2,7,SMOOTH_BRICK:0)
Block(-8,2,8,MONSTER_EGGS:4)
Block(-8,3,-7,SMOOTH_BRICK:0)
Block(-8,3,-6,SMOOTH_BRICK:0)
Block(-8,3,-5,SMOOTH_BRICK:0)
Block(-8,3,-4,MONSTER_EGGS:4)
Block(-8,3,-3,STONE:0)
Block(-8,3,-2,MONSTER_EGGS:4)
Block(-8,3,-1,MONSTER_EGGS:4)
Block(-8,3,0,SMOOTH_BRICK:0)
Block(-8,3,1,STONE:0)
Block(-8,3,2,MONSTER_EGGS:4)
Block(-8,3,3,SMOOTH_BRICK:0)
Block(-8,3,4,SMOOTH_BRICK:0)
Block(-8,3,5,STONE:0)
Block(-8,3,6,SMOOTH_BRICK:0)
Block(-8,3,7,SMOOTH_BRICK:0)
Block(-8,3,8,MONSTER_EGGS:4)
Block(-8,4,-7,SMOOTH_BRICK:0)
Block(-8,4,-6,STONE:0)
Block(-8,4,-5,STONE:0)
Block(-8,4,-4,SMOOTH_BRICK:0)
Block(-8,4,-3,SMOOTH_BRICK:0)
Block(-8,4,-2,SMOOTH_BRICK:0)
Block(-8,4,-1,SMOOTH_BRICK:0)
Block(-8,4,0,SMOOTH_BRICK:0)
Block(-8,4,1,SMOOTH_BRICK:0)
Block(-8,4,2,SMOOTH_BRICK:0)
Block(-8,4,3,SMOOTH_BRICK:0)
Block(-8,4,4,SMOOTH_BRICK:0)
Block(-8,4,5,SMOOTH_BRICK:0)
Block(-8,4,6,SMOOTH_BRICK:0)
Block(-8,4,7,SMOOTH_BRICK:0)
Block(-8,4,8,SMOOTH_BRICK:0)
Block(-8,5,-7,SMOOTH_BRICK:0)
Block(-8,5,-6,STONE:0)
Block(-8,5,-5,SMOOTH_BRICK:0)
Block(-8,5,-4,STONE:0)
Block(-8,5,-3,SMOOTH_BRICK:0)
Block(-8,5,-2,SMOOTH_BRICK:0)
Block(-8,5,-1,SMOOTH_BRICK:0)
Block(-8,5,0,SMOOTH_BRICK:0)
Block(-8,5,1,SMOOTH_BRICK:0)
Block(-8,5,2,STONE:0)
Block(-8,5,3,SMOOTH_BRICK:0)
Block(-8,5,4,SMOOTH_BRICK:0)
Block(-8,5,5,SMOOTH_BRICK:0)
Block(-8,5,6,MONSTER_EGGS:4)
Block(-8,5,7,STONE:0)
Block(-8,5,8,MONSTER_EGGS:4)
Block(-8,6,-7,STONE:0)
Block(-8,6,-6,SMOOTH_BRICK:0)
Block(-8,6,-5,SMOOTH_BRICK:0)
Block(-8,6,-4,SMOOTH_BRICK:0)
Block(-8,6,-3,MONSTER_EGGS:4)
Block(-8,6,-2,SMOOTH_BRICK:0)
Block(-8,6,-1,SMOOTH_BRICK:0)
Block(-8,6,0,SMOOTH_BRICK:0)
Block(-8,6,1,SMOOTH_BRICK:0)
Block(-8,6,2,SMOOTH_BRICK:0)
Block(-8,6,3,MONSTER_EGGS:4)
Block(-8,6,4,MONSTER_EGGS:4)
Block(-8,6,5,SMOOTH_BRICK:0)
Block(-8,6,6,SMOOTH_BRICK:0)
Block(-8,6,7,STONE:0)
Block(-8,6,8,MONSTER_EGGS:4)
Block(-8,7,-7,SMOOTH_BRICK:0)
Block(-8,7,-6,SMOOTH_BRICK:0)
Block(-8,7,-5,SMOOTH_BRICK:0)
Block(-8,7,-4,SMOOTH_BRICK:0)
Block(-8,7,-3,STONE:0)
Block(-8,7,-2,SMOOTH_BRICK:0)
Block(-8,7,-1,SMOOTH_BRICK:0)
Block(-8,7,0,SMOOTH_BRICK:0)
Block(-8,7,1,SMOOTH_BRICK:0)
Block(-8,7,2,SMOOTH_BRICK:0)
Block(-8,7,3,MONSTER_EGGS:4)
Block(-8,7,4,SMOOTH_BRICK:0)
Block(-8,7,5,MONSTER_EGGS:4)
Block(-8,7,6,MONSTER_EGGS:4)
Block(-8,7,7,SMOOTH_BRICK:0)
Block(-8,7,8,SMOOTH_BRICK:0)
Block(-8,8,-7,STONE:0)
Block(-8,8,-6,STONE:0)
Block(-8,8,-5,STONE:0)
Block(-8,8,-4,STONE:0)
Block(-8,8,-3,STONE:0)
Block(-8,8,-2,STONE:0)
Block(-8,8,-1,STONE:0)
Block(-8,8,0,STONE:0)
Block(-8,8,1,STONE:0)
Block(-8,8,2,STONE:0)
Block(-8,8,3,STONE:0)
Block(-8,8,4,STONE:0)
Block(-8,8,5,STONE:0)
Block(-8,8,6,STONE:0)
Block(-8,8,7,STONE:0)
Block(-8,8,8,STONE:0)
Block(-8,9,-7,STONE:0)
Block(-8,9,-6,STONE:0)
Block(-8,9,-5,STONE:0)
Block(-8,9,-4,STONE:0)
Block(-8,9,-3,STONE:0)
Block(-8,9,-2,STONE:0)
Block(-8,9,-1,STONE:0)
Block(-8,9,0,STONE:0)
Block(-8,9,1,STONE:0)
Block(-8,9,2,STONE:0)
Block(-8,9,3,STONE:0)
Block(-8,9,4,STONE:0)
Block(-8,9,5,STONE:0)
Block(-8,9,6,STONE:0)
Block(-8,9,7,STONE:0)
Block(-8,9,8,STONE:0)
Block(-7,0,-7,SMOOTH_BRICK:0)
Block(-7,0,-6,WOOD:1)
Block(-7,0,-5,WOOD:1)
Block(-7,0,-4,WOOD:1)
Block(-7,0,-3,WOOD:1)
Block(-7,0,-2,WOOD:1)
Block(-7,0,-1,WOOD:1)
Block(-7,0,0,WOOD:1)
Block(-7,0,1,WOOD:1)
Block(-7,0,2,WOOD:1)
Block(-7,0,3,WOOD:1)
Block(-7,0,4,WOOD:1)
Block(-7,0,5,WOOD:1)
Block(-7,0,6,WOOD:1)
Block(-7,0,7,WOOD:1)
Block(-7,0,8,STONE:0)
Block(-7,1,-7,SMOOTH_BRICK:0)
Block(-7,1,-6,LOG:2)
Block(-7,1,-5,DARK_OAK_FENCE:0)
Block(-7,1,-4,WOOD_STAIRS:5)
Block(-7,1,-3,COBBLE_WALL:0)
Block(-7,1,-2,COBBLESTONE_STAIRS:1)
Block(-7,1,-1,WOOD_STAIRS:5)
Block(-7,1,0,LOG:2)
Block(-7,1,1,DARK_OAK_FENCE:0)
Block(-7,1,2,GLASS)
Block(-7,1,3,VINE:9)
Block(-7,1,4,VINE:2)
Block(-7,1,5,VINE:12)
Block(-7,1,6,GLASS)
Block(-7,1,7,LOG:2)
Block(-7,1,8,STONE:0)
Block(-7,2,-7,SMOOTH_BRICK:0)
Block(-7,2,-6,LEAVES:7)
Block(-7,2,-5,SPONGE:0)
Block(-7,2,-4,DARK_OAK_STAIRS:5)
Block(-7,2,-3,WEB)
Block(-7,2,-2,COBBLE_WALL:0)
Block(-7,2,-1,DARK_OAK_STAIRS:5)
Block(-7,2,0,LEAVES:7)
Block(-7,2,1,DARK_OAK_STAIRS:5)
Block(-7,2,2,DARK_OAK_STAIRS:5)
Block(-7,2,3,VINE:9)
Block(-7,2,4,VINE:2)
Block(-7,2,5,VINE:12)
Block(-7,2,6,LEAVES:15)
Block(-7,2,7,LEAVES:15)
Block(-7,2,8,SMOOTH_BRICK:0)
Block(-7,3,-7,MONSTER_EGGS:4)
Block(-7,3,-6,LEAVES:7)
Block(-7,3,-5,LEAVES:7)
Block(-7,3,-4,DARK_OAK_STAIRS:5)
Block(-7,3,-3,VINE:10)
Block(-7,3,-2,VINE:2)
Block(-7,3,-1,DARK_OAK_STAIRS:5)
Block(-7,3,0,GLASS)
Block(-7,3,1,LEAVES:15)
Block(-7,3,2,LEAVES:15)
Block(-7,3,3,VINE:9)
Block(-7,3,4,VINE:2)
Block(-7,3,5,VINE:2)
Block(-7,3,6,VINE:2)
Block(-7,3,7,LEAVES:15)
Block(-7,3,8,SMOOTH_BRICK:0)
Block(-7,4,-7,MONSTER_EGGS:4)
Block(-7,4,-6,LEAVES:7)
Block(-7,4,-5,GLASS)
Block(-7,4,-4,DARK_OAK_STAIRS:0)
Block(-7,4,-3,LEAVES:7)
Block(-7,4,-2,WEB)
Block(-7,4,-1,DARK_OAK_STAIRS:0)
Block(-7,4,0,LEAVES:7)
Block(-7,4,1,DARK_OAK_FENCE:0)
Block(-7,4,2,LEAVES:15)
Block(-7,4,3,VINE:2)
Block(-7,4,4,VINE:2)
Block(-7,4,5,VINE:2)
Block(-7,4,6,VINE:2)
Block(-7,4,7,WEB)
Block(-7,4,8,SMOOTH_BRICK:0)
Block(-7,5,-7,MONSTER_EGGS:4)
Block(-7,5,-6,GLASS)
Block(-7,5,-5,GLASS)
Block(-7,5,-4,LEAVES:7)
Block(-7,5,-3,LEAVES:7)
Block(-7,5,-2,GLASS)
Block(-7,5,-1,GLASS)
Block(-7,5,0,GLASS)
Block(-7,5,1,GLASS)
Block(-7,5,2,VINE:2)
Block(-7,5,3,VINE:2)
Block(-7,5,4,VINE:2)
Block(-7,5,5,LEAVES:15)
Block(-7,5,6,COBBLESTONE)
Block(-7,5,7,LEAVES:15)
Block(-7,5,8,SMOOTH_BRICK:0)
Block(-7,6,-7,SMOOTH_BRICK:0)
Block(-7,6,-6,LEAVES:7)
Block(-7,6,-5,LEAVES:7)
Block(-7,6,-4,LEAVES:7)
Block(-7,6,-3,GLASS)
Block(-7,6,-2,LEAVES:7)
Block(-7,6,-1,GLASS)
Block(-7,6,0,GLASS)
Block(-7,6,1,LEAVES:7)
Block(-7,6,2,LEAVES:7)
Block(-7,6,3,LEAVES:7)
Block(-7,6,4,LEAVES:7)
Block(-7,6,5,LEAVES:7)
Block(-7,6,6,COBBLESTONE)
Block(-7,6,7,LEAVES:7)
Block(-7,6,8,SMOOTH_BRICK:0)
Block(-7,7,-7,STONE:0)
Block(-7,7,-6,STONE:0)
Block(-7,7,-5,LEAVES:7)
Block(-7,7,-4,LEAVES:4)
Block(-7,7,-3,LEAVES:4)
Block(-7,7,-2,LEAVES:4)
Block(-7,7,-1,LEAVES:7)
Block(-7,7,0,LEAVES:7)
Block(-7,7,1,LEAVES:7)
Block(-7,7,2,STONE:0)
Block(-7,7,3,STONE:0)
Block(-7,7,4,STONE:0)
Block(-7,7,5,STONE:0)
Block(-7,7,6,COBBLESTONE)
Block(-7,7,7,STONE:0)
Block(-7,7,8,MONSTER_EGGS:4)
Block(-7,8,-7,STONE:0)
Block(-7,8,-6,STONE:0)
Block(-7,8,-5,STONE:0)
Block(-7,8,-4,STONE:0)
Block(-7,8,-3,STONE:0)
Block(-7,8,-2,STONE:0)
Block(-7,8,-1,STONE:0)
Block(-7,8,0,STONE:0)
Block(-7,8,1,STONE:0)
Block(-7,8,2,STONE:0)
Block(-7,8,3,STONE:0)
Block(-7,8,4,STONE:0)
Block(-7,8,5,STONE:0)
Block(-7,8,6,COBBLESTONE)
Block(-7,8,7,STONE:0)
Block(-7,8,8,STONE:0)
Block(-7,9,-7,STONE:0)
Block(-7,9,-6,STONE:0)
Block(-7,9,-5,STONE:0)
Block(-7,9,-4,STONE:0)
Block(-7,9,-3,STONE:0)
Block(-7,9,-2,STONE:0)
Block(-7,9,-1,STONE:0)
Block(-7,9,0,STONE:0)
Block(-7,9,1,STONE:0)
Block(-7,9,2,STONE:0)
Block(-7,9,3,STONE:0)
Block(-7,9,4,STONE:0)
Block(-7,9,5,STONE:0)
Block(-7,9,6,STONE:0)
Block(-7,9,7,STONE:0)
Block(-7,9,8,STONE:0)
Block(-6,0,-7,SMOOTH_BRICK:0)
Block(-6,0,-6,WOOD:1)
Block(-6,0,-5,WOOD:1)
Block(-6,0,-4,SPRUCE_WOOD_STAIRS:3)
Block(-6,0,-3,WOOD:1)
Block(-6,0,-2,WOOD:1)
Block(-6,0,-1,SPRUCE_WOOD_STAIRS:1)
Block(-6,0,0,WOOD:1)
Block(-6,0,1,WOOD:1)
Block(-6,0,2,WOOD:1)
Block(-6,0,3,WOOD:1)
Block(-6,0,4,SPRUCE_WOOD_STAIRS:1)
Block(-6,0,5,WOOD:1)
Block(-6,0,6,WOOD:1)
Block(-6,0,7,WOOD:1)
Block(-6,0,8,SMOOTH_BRICK:0)
Block(-6,1,-7,SMOOTH_BRICK:0)
Block(-6,1,-6,COBBLESTONE)
Block(-6,1,-5,GLASS)
Block(-6,1,-4,WOOD_STEP:8)
Block(-6,1,-3,GLASS)
Block(-6,1,-2,GLASS)
Block(-6,1,-1,WOOD_STEP:8)
Block(-6,1,0,GLASS)
Block(-6,1,1,GLASS)
Block(-6,1,2,GLASS)
Block(-6,1,3,GLASS)
Block(-6,1,4,GLASS)
Block(-6,1,5,GLASS)
Block(-6,1,6,GLASS)
Block(-6,1,7,LEAVES:15)
Block(-6,1,8,SMOOTH_BRICK:0)
Block(-6,2,-7,SMOOTH_BRICK:0)
Block(-6,2,-6,COBBLE_WALL:0)
Block(-6,2,-5,GLASS)
Block(-6,2,-4,BOOKSHELF)
Block(-6,2,-3,DARK_OAK_FENCE:0)
Block(-6,2,-2,GLASS)
Block(-6,2,-1,BOOKSHELF)
Block(-6,2,0,GLASS)
Block(-6,2,1,GLASS)
Block(-6,2,2,GLASS)
Block(-6,2,3,GLASS)
Block(-6,2,4,GLASS)
Block(-6,2,5,GLASS)
Block(-6,2,6,GLASS)
Block(-6,2,7,VINE:12)
Block(-6,2,8,SMOOTH_BRICK:0)
Block(-6,3,-7,MONSTER_EGGS:4)
Block(-6,3,-6,WEB)
Block(-6,3,-5,GLASS)
Block(-6,3,-4,WOOD:0)
Block(-6,3,-3,LEAVES:7)
Block(-6,3,-2,GLASS)
Block(-6,3,-1,BOOKSHELF)
Block(-6,3,0,LEAVES:7)
Block(-6,3,1,GLASS)
Block(-6,3,2,GLASS)
Block(-6,3,3,GLASS)
Block(-6,3,4,GLASS)
Block(-6,3,5,GLASS)
Block(-6,3,6,GLASS)
Block(-6,3,7,VINE:12)
Block(-6,3,8,SMOOTH_BRICK:0)
Block(-6,4,-7,SMOOTH_BRICK:0)
Block(-6,4,-6,LEAVES:7)
Block(-6,4,-5,GLASS)
Block(-6,4,-4,BOOKSHELF)
Block(-6,4,-3,GLASS)
Block(-6,4,-2,GLASS)
Block(-6,4,-1,WOOD:0)
Block(-6,4,0,LEAVES:7)
Block(-6,4,1,GLASS)
Block(-6,4,2,GLASS)
Block(-6,4,3,GLASS)
Block(-6,4,4,GLASS)
Block(-6,4,5,GLASS)
Block(-6,4,6,GLASS)
Block(-6,4,7,VINE:1)
Block(-6,4,8,SMOOTH_BRICK:0)
Block(-6,5,-7,MONSTER_EGGS:4)
Block(-6,5,-6,GLASS)
Block(-6,5,-5,LEAVES:7)
Block(-6,5,-4,GLASS)
Block(-6,5,-3,GLASS)
Block(-6,5,-2,GLASS)
Block(-6,5,-1,LEAVES:4)
Block(-6,5,0,LEAVES:4)
Block(-6,5,1,LEAVES:7)
Block(-6,5,2,GLASS)
Block(-6,5,3,GLASS)
Block(-6,5,4,GLASS)
Block(-6,5,5,LEAVES:15)
Block(-6,5,6,LEAVES:15)
Block(-6,5,7,LEAVES:15)
Block(-6,5,8,MONSTER_EGGS:4)
Block(-6,6,-7,SMOOTH_BRICK:0)
Block(-6,6,-6,LEAVES:7)
Block(-6,6,-5,LEAVES:7)
Block(-6,6,-4,LEAVES:7)
Block(-6,6,-3,LEAVES:4)
Block(-6,6,-2,LEAVES:7)
Block(-6,6,-1,LEAVES:7)
Block(-6,6,0,LEAVES:4)
Block(-6,6,1,COBBLESTONE)
Block(-6,6,2,LEAVES:4)
Block(-6,6,3,LEAVES:7)
Block(-6,6,4,LEAVES:7)
Block(-6,6,5,GLASS)
Block(-6,6,6,COBBLESTONE)
Block(-6,6,7,VINE:1)
Block(-6,6,8,SMOOTH_BRICK:0)
Block(-6,7,-7,SMOOTH_BRICK:0)
Block(-6,7,-6,STONE:0)
Block(-6,7,-5,COBBLESTONE)
Block(-6,7,-4,STONE:0)
Block(-6,7,-3,GLASS)
Block(-6,7,-2,LEAVES:7)
Block(-6,7,-1,LEAVES:7)
Block(-6,7,0,COBBLESTONE)
Block(-6,7,1,COBBLESTONE)
Block(-6,7,2,LEAVES:4)
Block(-6,7,3,GLASS)
Block(-6,7,4,STONE:0)
Block(-6,7,5,GLASS)
Block(-6,7,6,COBBLESTONE)
Block(-6,7,7,COBBLESTONE)
Block(-6,7,8,SMOOTH_BRICK:0)
Block(-6,8,-7,STONE:0)
Block(-6,8,-6,STONE:0)
Block(-6,8,-5,STONE:0)
Block(-6,8,-4,STONE:0)
Block(-6,8,-3,STONE:0)
Block(-6,8,-2,STONE:0)
Block(-6,8,-1,STONE:0)
Block(-6,8,0,STONE:0)
Block(-6,8,1,COBBLESTONE)
Block(-6,8,2,COBBLESTONE)
Block(-6,8,3,STONE:0)
Block(-6,8,4,STONE:0)
Block(-6,8,5,STONE:0)
Block(-6,8,6,STONE:0)
Block(-6,8,7,STONE:0)
Block(-6,8,8,STONE:0)
Block(-6,9,-7,STONE:0)
Block(-6,9,-6,STONE:0)
Block(-6,9,-5,STONE:0)
Block(-6,9,-4,STONE:0)
Block(-6,9,-3,STONE:0)
Block(-6,9,-2,STONE:0)
Block(-6,9,-1,STONE:0)
Block(-6,9,0,STONE:0)
Block(-6,9,1,STONE:0)
Block(-6,9,2,STONE:0)
Block(-6,9,3,STONE:0)
Block(-6,9,4,STONE:0)
Block(-6,9,5,STONE:0)
Block(-6,9,6,STONE:0)
Block(-6,9,7,STONE:0)
Block(-6,9,8,STONE:0)
Block(-5,0,-7,SMOOTH_BRICK:0)
Block(-5,0,-6,WOOD:1)
Block(-5,0,-5,WOOD:1)
Block(-5,0,-4,WOOD:1)
Block(-5,0,-3,WOOD:1)
Block(-5,0,-2,WOOD:1)
Block(-5,0,-1,WOOD:1)
Block(-5,0,0,WOOD:1)
Block(-5,0,1,SPRUCE_WOOD_STAIRS:1)
Block(-5,0,2,WOOD:1)
Block(-5,0,3,WOOD:1)
Block(-5,0,4,WOOD:1)
Block(-5,0,5,WOOD:1)
Block(-5,0,6,WOOD:1)
Block(-5,0,7,WOOD:1)
Block(-5,0,8,SMOOTH_BRICK:0)
Block(-5,1,-7,SMOOTH_BRICK:0)
Block(-5,1,-6,COBBLESTONE_STAIRS:1)
Block(-5,1,-5,GLASS)
Block(-5,1,-4,WOOD_STEP:8)
Block(-5,1,-3,GLASS)
Block(-5,1,-2,VINE:6)
Block(-5,1,-1,WOOD_STEP:8)
Block(-5,1,0,GLASS)
Block(-5,1,1,GLASS)
Block(-5,1,2,VINE:1)
Block(-5,1,3,WOOD_STAIRS:7)
Block(-5,1,4,WOOD_STEP:8)
Block(-5,1,5,WOOD_DOUBLE_STEP:0)
Block(-5,1,6,GLASS)
Block(-5,1,7,DARK_OAK_STAIRS:2)
Block(-5,1,8,MONSTER_EGGS:4)
Block(-5,2,-7,SMOOTH_BRICK:0)
Block(-5,2,-6,DARK_OAK_FENCE:0)
Block(-5,2,-5,GLASS)
Block(-5,2,-4,BOOKSHELF)
Block(-5,2,-3,GLASS)
Block(-5,2,-2,VINE:6)
Block(-5,2,-1,BOOKSHELF)
Block(-5,2,0,GLASS)
Block(-5,2,1,GLASS)
Block(-5,2,2,VINE:1)
Block(-5,2,3,DARK_OAK_STAIRS:7)
Block(-5,2,4,BOOKSHELF)
Block(-5,2,5,LOG_2:1)
Block(-5,2,6,GLASS)
Block(-5,2,7,VINE:1)
Block(-5,2,8,SMOOTH_BRICK:0)
Block(-5,3,-7,MONSTER_EGGS:4)
Block(-5,3,-6,LEAVES:7)
Block(-5,3,-5,GLASS)
Block(-5,3,-4,BOOKSHELF)
Block(-5,3,-3,GLASS)
Block(-5,3,-2,VINE:6)
Block(-5,3,-1,BOOKSHELF)
Block(-5,3,0,DARK_OAK_FENCE:0)
Block(-5,3,1,GLASS)
Block(-5,3,2,VINE:1)
Block(-5,3,3,DARK_OAK_STAIRS:7)
Block(-5,3,4,BOOKSHELF)
Block(-5,3,5,LEAVES:15)
Block(-5,3,6,GLASS)
Block(-5,3,7,VINE:1)
Block(-5,3,8,MONSTER_EGGS:4)
Block(-5,4,-7,MONSTER_EGGS:4)
Block(-5,4,-6,GLASS)
Block(-5,4,-5,LEAVES:7)
Block(-5,4,-4,WOOD:0)
Block(-5,4,-3,GLASS)
Block(-5,4,-2,VINE:6)
Block(-5,4,-1,BOOKSHELF)
Block(-5,4,0,WEB)
Block(-5,4,1,GLASS)
Block(-5,4,2,GLASS)
Block(-5,4,3,DARK_OAK_STAIRS:2)
Block(-5,4,4,BOOKSHELF)
Block(-5,4,5,LEAVES:15)
Block(-5,4,6,GLASS)
Block(-5,4,7,VINE:1)
Block(-5,4,8,SMOOTH_BRICK:0)
Block(-5,5,-7,SMOOTH_BRICK:0)
Block(-5,5,-6,GLASS)
Block(-5,5,-5,LEAVES:7)
Block(-5,5,-4,LEAVES:7)
Block(-5,5,-3,LEAVES:4)
Block(-5,5,-2,LEAVES:4)
Block(-5,5,-1,LEAVES:7)
Block(-5,5,0,LEAVES:4)
Block(-5,5,1,LEAVES:4)
Block(-5,5,2,GLASS)
Block(-5,5,3,GLASS)
Block(-5,5,4,GLASS)
Block(-5,5,5,LEAVES:15)
Block(-5,5,6,GLASS)
Block(-5,5,7,LEAVES:12)
Block(-5,5,8,STONE:0)
Block(-5,6,-7,SMOOTH_BRICK:0)
Block(-5,6,-6,LEAVES:7)
Block(-5,6,-5,COBBLESTONE)
Block(-5,6,-4,LEAVES:7)
Block(-5,6,-3,LEAVES:4)
Block(-5,6,-2,LEAVES:4)
Block(-5,6,-1,LEAVES:7)
Block(-5,6,0,LEAVES:4)
Block(-5,6,1,LEAVES:7)
Block(-5,6,2,LEAVES:4)
Block(-5,6,3,LEAVES:7)
Block(-5,6,4,LEAVES:4)
Block(-5,6,5,COBBLESTONE)
Block(-5,6,6,LEAVES:7)
Block(-5,6,7,LEAVES:7)
Block(-5,6,8,MONSTER_EGGS:4)
Block(-5,7,-7,SMOOTH_BRICK:0)
Block(-5,7,-6,COBBLESTONE)
Block(-5,7,-5,STONE:0)
Block(-5,7,-4,GLASS)
Block(-5,7,-3,LEAVES:4)
Block(-5,7,-2,COBBLESTONE)
Block(-5,7,-1,COBBLESTONE)
Block(-5,7,0,COBBLESTONE)
Block(-5,7,1,STONE:0)
Block(-5,7,2,LEAVES:4)
Block(-5,7,3,GLASS)
Block(-5,7,4,COBBLESTONE)
Block(-5,7,5,COBBLESTONE)
Block(-5,7,6,GLASS)
Block(-5,7,7,VINE:15)
Block(-5,7,8,SMOOTH_BRICK:0)
Block(-5,8,-7,STONE:0)
Block(-5,8,-6,STONE:0)
Block(-5,8,-5,STONE:0)
Block(-5,8,-4,STONE:0)
Block(-5,8,-3,STONE:0)
Block(-5,8,-2,STONE:0)
Block(-5,8,-1,STONE:0)
Block(-5,8,0,STONE:0)
Block(-5,8,1,STONE:0)
Block(-5,8,2,STONE:0)
Block(-5,8,3,STONE:0)
Block(-5,8,4,STONE:0)
Block(-5,8,5,COBBLESTONE)
Block(-5,8,6,STONE:0)
Block(-5,8,7,STONE:0)
Block(-5,8,8,STONE:0)
Block(-5,9,-7,STONE:0)
Block(-5,9,-6,STONE:0)
Block(-5,9,-5,STONE:0)
Block(-5,9,-4,STONE:0)
Block(-5,9,-3,STONE:0)
Block(-5,9,-2,STONE:0)
Block(-5,9,-1,STONE:0)
Block(-5,9,0,STONE:0)
Block(-5,9,1,STONE:0)
Block(-5,9,2,STONE:0)
Block(-5,9,3,STONE:0)
Block(-5,9,4,STONE:0)
Block(-5,9,5,STONE:0)
Block(-5,9,6,STONE:0)
Block(-5,9,7,STONE:0)
Block(-5,9,8,STONE:0)
Block(-4,0,-7,SMOOTH_BRICK:0)
Block(-4,0,-6,WOOD:1)
Block(-4,0,-5,WOOD:1)
Block(-4,0,-4,WOOD:1)
Block(-4,0,-3,WOOD:1)
Block(-4,0,-2,WOOD:1)
Block(-4,0,-1,WOOD:1)
Block(-4,0,0,WOOD:1)
Block(-4,0,1,WOOD:1)
Block(-4,0,2,SPRUCE_WOOD_STAIRS:3)
Block(-4,0,3,WOOD:1)
Block(-4,0,4,WOOD:1)
Block(-4,0,5,SPRUCE_WOOD_STAIRS:3)
Block(-4,0,6,WOOD:1)
Block(-4,0,7,WOOD:1)
Block(-4,0,8,STONE:0)
Block(-4,1,-7,MONSTER_EGGS:4)
Block(-4,1,-6,WOOD_STAIRS:5)
Block(-4,1,-5,GLASS)
Block(-4,1,-4,WOOD_STEP:8)
Block(-4,1,-3,GLASS)
Block(-4,1,-2,GLASS)
Block(-4,1,-1,WOOD_STEP:8)
Block(-4,1,0,GLASS)
Block(-4,1,1,VINE:8)
Block(-4,1,2,GLASS)
Block(-4,1,3,GLASS)
Block(-4,1,4,VINE:12)
Block(-4,1,5,WOOD_STEP:8)
Block(-4,1,6,GLASS)
Block(-4,1,7,GLASS)
Block(-4,1,8,SMOOTH_BRICK:0)
Block(-4,2,-7,STONE:0)
Block(-4,2,-6,DARK_OAK_STAIRS:5)
Block(-4,2,-5,GLASS)
Block(-4,2,-4,BOOKSHELF)
Block(-4,2,-3,GLASS)
Block(-4,2,-2,GLASS)
Block(-4,2,-1,BOOKSHELF)
Block(-4,2,0,GLASS)
Block(-4,2,1,VINE:8)
Block(-4,2,2,GLASS)
Block(-4,2,3,GLASS)
Block(-4,2,4,VINE:12)
Block(-4,2,5,BOOKSHELF)
Block(-4,2,6,GLASS)
Block(-4,2,7,GLASS)
Block(-4,2,8,MONSTER_EGGS:4)
Block(-4,3,-7,SMOOTH_BRICK:0)
Block(-4,3,-6,DARK_OAK_STAIRS:5)
Block(-4,3,-5,GLASS)
Block(-4,3,-4,BOOKSHELF)
Block(-4,3,-3,GLASS)
Block(-4,3,-2,GLASS)
Block(-4,3,-1,WOOD:0)
Block(-4,3,0,GLASS)
Block(-4,3,1,VINE:8)
Block(-4,3,2,LEAVES:15)
Block(-4,3,3,GLASS)
Block(-4,3,4,VINE:12)
Block(-4,3,5,WOOL:7)
Block(-4,3,6,GLASS)
Block(-4,3,7,GLASS)
Block(-4,3,8,MONSTER_EGGS:4)
Block(-4,4,-7,SMOOTH_BRICK:0)
Block(-4,4,-6,DARK_OAK_STAIRS:0)
Block(-4,4,-5,GLASS)
Block(-4,4,-4,BOOKSHELF)
Block(-4,4,-3,GLASS)
Block(-4,4,-2,LEAVES:7)
Block(-4,4,-1,BOOKSHELF)
Block(-4,4,0,GLASS)
Block(-4,4,1,VINE:8)
Block(-4,4,2,WEB)
Block(-4,4,3,GLASS)
Block(-4,4,4,VINE:12)
Block(-4,4,5,BOOKSHELF)
Block(-4,4,6,LEAVES:15)
Block(-4,4,7,GLASS)
Block(-4,4,8,SMOOTH_BRICK:0)
Block(-4,5,-7,SMOOTH_BRICK:0)
Block(-4,5,-6,LEAVES:4)
Block(-4,5,-5,LEAVES:7)
Block(-4,5,-4,LEAVES:4)
Block(-4,5,-3,GLASS)
Block(-4,5,-2,LEAVES:4)
Block(-4,5,-1,LEAVES:7)
Block(-4,5,0,LEAVES:4)
Block(-4,5,1,LEAVES:4)
Block(-4,5,2,GLASS)
Block(-4,5,3,GLASS)
Block(-4,5,4,VINE:1)
Block(-4,5,5,LEAVES:15)
Block(-4,5,6,GLASS)
Block(-4,5,7,GLASS)
Block(-4,5,8,SMOOTH_BRICK:0)
Block(-4,6,-7,MONSTER_EGGS:4)
Block(-4,6,-6,GLASS)
Block(-4,6,-5,GLASS)
Block(-4,6,-4,LEAVES:7)
Block(-4,6,-3,LEAVES:4)
Block(-4,6,-2,GLASS)
Block(-4,6,-1,GLASS)
Block(-4,6,0,LEAVES:4)
Block(-4,6,1,LEAVES:4)
Block(-4,6,2,LEAVES:4)
Block(-4,6,3,LEAVES:4)
Block(-4,6,4,LEAVES:7)
Block(-4,6,5,LEAVES:7)
Block(-4,6,6,LEAVES:7)
Block(-4,6,7,LEAVES:7)
Block(-4,6,8,SMOOTH_BRICK:0)
Block(-4,7,-7,SMOOTH_BRICK:0)
Block(-4,7,-6,STONE:0)
Block(-4,7,-5,STONE:0)
Block(-4,7,-4,COBBLESTONE)
Block(-4,7,-3,COBBLESTONE)
Block(-4,7,-2,STONE:0)
Block(-4,7,-1,STONE:0)
Block(-4,7,0,GLASS)
Block(-4,7,1,GLASS)
Block(-4,7,2,COBBLESTONE)
Block(-4,7,3,LEAVES:4)
Block(-4,7,4,STONE:0)
Block(-4,7,5,LEAVES:4)
Block(-4,7,6,STONE:0)
Block(-4,7,7,STONE:0)
Block(-4,7,8,MONSTER_EGGS:4)
Block(-4,8,-7,STONE:0)
Block(-4,8,-6,STONE:0)
Block(-4,8,-5,STONE:0)
Block(-4,8,-4,STONE:0)
Block(-4,8,-3,STONE:0)
Block(-4,8,-2,STONE:0)
Block(-4,8,-1,STONE:0)
Block(-4,8,0,STONE:0)
Block(-4,8,1,STONE:0)
Block(-4,8,2,STONE:0)
Block(-4,8,3,COBBLESTONE)
Block(-4,8,4,STONE:0)
Block(-4,8,5,STONE:0)
Block(-4,8,6,STONE:0)
Block(-4,8,7,STONE:0)
Block(-4,8,8,STONE:0)
Block(-4,9,-7,STONE:0)
Block(-4,9,-6,STONE:0)
Block(-4,9,-5,STONE:0)
Block(-4,9,-4,STONE:0)
Block(-4,9,-3,STONE:0)
Block(-4,9,-2,STONE:0)
Block(-4,9,-1,STONE:0)
Block(-4,9,0,STONE:0)
Block(-4,9,1,STONE:0)
Block(-4,9,2,STONE:0)
Block(-4,9,3,STONE:0)
Block(-4,9,4,STONE:0)
Block(-4,9,5,STONE:0)
Block(-4,9,6,STONE:0)
Block(-4,9,7,STONE:0)
Block(-4,9,8,STONE:0)
Block(-3,0,-7,SMOOTH_BRICK:0)
Block(-3,0,-6,WOOD:1)
Block(-3,0,-5,WOOD:1)
Block(-3,0,-4,SPRUCE_WOOD_STAIRS:3)
Block(-3,0,-3,WOOD:1)
Block(-3,0,-2,SPRUCE_WOOD_STAIRS:1)
Block(-3,0,-1,WOOD:1)
Block(-3,0,0,SPRUCE_WOOD_STAIRS:1)
Block(-3,0,1,WOOD:1)
Block(-3,0,2,WOOD:1)
Block(-3,0,3,WOOD:1)
Block(-3,0,4,WOOD:1)
Block(-3,0,5,WOOD:1)
Block(-3,0,6,WOOD:1)
Block(-3,0,7,WOOD:1)
Block(-3,0,8,SMOOTH_BRICK:0)
Block(-3,1,-7,SMOOTH_BRICK:0)
Block(-3,1,-6,WOOD_STEP:8)
Block(-3,1,-5,GLASS)
Block(-3,1,-4,WOOD_STAIRS:4)
Block(-3,1,-3,GLASS)
Block(-3,1,-2,GLASS)
Block(-3,1,-1,WOOD_STAIRS:4)
Block(-3,1,0,GLASS)
Block(-3,1,1,WOOD_DOUBLE_STEP:0)
Block(-3,1,2,WOOD_STEP:8)
Block(-3,1,3,WOOD_STAIRS:6)
Block(-3,1,4,VINE:4)
Block(-3,1,5,WOOD_STAIRS:4)
Block(-3,1,6,GLASS)
Block(-3,1,7,STONE:6)
Block(-3,1,8,STONE:0)
Block(-3,2,-7,SMOOTH_BRICK:0)
Block(-3,2,-6,BOOKSHELF)
Block(-3,2,-5,GLASS)
Block(-3,2,-4,DARK_OAK_STAIRS:4)
Block(-3,2,-3,GLASS)
Block(-3,2,-2,GLASS)
Block(-3,2,-1,DARK_OAK_STAIRS:4)
Block(-3,2,0,GLASS)
Block(-3,2,1,LOG:2)
Block(-3,2,2,BOOKSHELF)
Block(-3,2,3,DARK_OAK_STAIRS:6)
Block(-3,2,4,VINE:4)
Block(-3,2,5,DARK_OAK_STAIRS:4)
Block(-3,2,6,GLASS)
Block(-3,2,7,STONE:6)
Block(-3,2,8,MONSTER_EGGS:4)
Block(-3,3,-7,STONE:0)
Block(-3,3,-6,WOOD:0)
Block(-3,3,-5,GLASS)
Block(-3,3,-4,DARK_OAK_STAIRS:4)
Block(-3,3,-3,GLASS)
Block(-3,3,-2,GLASS)
Block(-3,3,-1,DARK_OAK_STAIRS:4)
Block(-3,3,0,GLASS)
Block(-3,3,1,LEAVES:15)
Block(-3,3,2,WOOD:0)
Block(-3,3,3,DARK_OAK_STAIRS:6)
Block(-3,3,4,VINE:4)
Block(-3,3,5,DARK_OAK_STAIRS:4)
Block(-3,3,6,GLASS)
Block(-3,3,7,STONE:6)
Block(-3,3,8,MONSTER_EGGS:4)
Block(-3,4,-7,MONSTER_EGGS:4)
Block(-3,4,-6,BOOKSHELF)
Block(-3,4,-5,GLASS)
Block(-3,4,-4,DARK_OAK_STAIRS:1)
Block(-3,4,-3,LEAVES:7)
Block(-3,4,-2,GLASS)
Block(-3,4,-1,DARK_OAK_STAIRS:1)
Block(-3,4,0,GLASS)
Block(-3,4,1,LEAVES:15)
Block(-3,4,2,BOOKSHELF)
Block(-3,4,3,DARK_OAK_STAIRS:3)
Block(-3,4,4,GLASS)
Block(-3,4,5,DARK_OAK_STAIRS:1)
Block(-3,4,6,GLASS)
Block(-3,4,7,STONE:6)
Block(-3,4,8,MONSTER_EGGS:4)
Block(-3,5,-7,SMOOTH_BRICK:0)
Block(-3,5,-6,LEAVES:4)
Block(-3,5,-5,LEAVES:4)
Block(-3,5,-4,LEAVES:4)
Block(-3,5,-3,GLASS)
Block(-3,5,-2,LEAVES:4)
Block(-3,5,-1,LEAVES:7)
Block(-3,5,0,GLASS)
Block(-3,5,1,LEAVES:7)
Block(-3,5,2,LEAVES:15)
Block(-3,5,3,GLASS)
Block(-3,5,4,GLASS)
Block(-3,5,5,GLASS)
Block(-3,5,6,LEAVES:15)
Block(-3,5,7,STONE:6)
Block(-3,5,8,MONSTER_EGGS:4)
Block(-3,6,-7,MONSTER_EGGS:4)
Block(-3,6,-6,COBBLESTONE)
Block(-3,6,-5,LEAVES:4)
Block(-3,6,-4,COBBLESTONE)
Block(-3,6,-3,COBBLESTONE)
Block(-3,6,-2,LEAVES:7)
Block(-3,6,-1,LEAVES:7)
Block(-3,6,0,LEAVES:7)
Block(-3,6,1,LEAVES:7)
Block(-3,6,2,LEAVES:4)
Block(-3,6,3,GLASS)
Block(-3,6,4,LEAVES:4)
Block(-3,6,5,LEAVES:7)
Block(-3,6,6,LEAVES:7)
Block(-3,6,7,STONE:6)
Block(-3,6,8,STONE:0)
Block(-3,7,-7,MONSTER_EGGS:4)
Block(-3,7,-6,GLASS)
Block(-3,7,-5,COBBLESTONE)
Block(-3,7,-4,COBBLESTONE)
Block(-3,7,-3,STONE:0)
Block(-3,7,-2,STONE:0)
Block(-3,7,-1,STONE:0)
Block(-3,7,0,COBBLESTONE)
Block(-3,7,1,COBBLESTONE)
Block(-3,7,2,LEAVES:4)
Block(-3,7,3,LEAVES:4)
Block(-3,7,4,GLASS)
Block(-3,7,5,LEAVES:4)
Block(-3,7,6,GLASS)
Block(-3,7,7,STONE:6)
Block(-3,7,8,STONE:0)
Block(-3,8,-7,STONE:0)
Block(-3,8,-6,STONE:0)
Block(-3,8,-5,STONE:0)
Block(-3,8,-4,STONE:0)
Block(-3,8,-3,STONE:0)
Block(-3,8,-2,STONE:0)
Block(-3,8,-1,STONE:0)
Block(-3,8,0,STONE:0)
Block(-3,8,1,STONE:0)
Block(-3,8,2,STONE:0)
Block(-3,8,3,LEAVES:4)
Block(-3,8,4,STONE:0)
Block(-3,8,5,STONE:0)
Block(-3,8,6,STONE:0)
Block(-3,8,7,STONE:0)
Block(-3,8,8,STONE:0)
Block(-3,9,-7,STONE:0)
Block(-3,9,-6,STONE:0)
Block(-3,9,-5,STONE:0)
Block(-3,9,-4,STONE:0)
Block(-3,9,-3,STONE:0)
Block(-3,9,-2,STONE:0)
Block(-3,9,-1,STONE:0)
Block(-3,9,0,STONE:0)
Block(-3,9,1,STONE:0)
Block(-3,9,2,STONE:0)
Block(-3,9,3,STONE:0)
Block(-3,9,4,STONE:0)
Block(-3,9,5,STONE:0)
Block(-3,9,6,STONE:0)
Block(-3,9,7,STONE:0)
Block(-3,9,8,STONE:0)
Block(-2,0,-7,SMOOTH_BRICK:0)
Block(-2,0,-6,WOOD:1)
Block(-2,0,-5,SPRUCE_WOOD_STAIRS:1)
Block(-2,0,-4,WOOD:1)
Block(-2,0,-3,WOOD:1)
Block(-2,0,-2,WOOD:1)
Block(-2,0,-1,WOOD:1)
Block(-2,0,0,WOOD:1)
Block(-2,0,1,WOOD:1)
Block(-2,0,2,WOOD:1)
Block(-2,0,3,WOOD:1)
Block(-2,0,4,WOOD:1)
Block(-2,0,5,WOOD:1)
Block(-2,0,6,WOOD:1)
Block(-2,0,7,WOOD:1)
Block(-2,0,8,STONE:6)
Block(-2,1,-7,SMOOTH_BRICK:0)
Block(-2,1,-6,WOOD_STEP:8)
Block(-2,1,-5,GLASS)
Block(-2,1,-4,VINE:9)
Block(-2,1,-3,GLASS)
Block(-2,1,-2,GLASS)
Block(-2,1,-1,GLASS)
Block(-2,1,0,GLASS)
Block(-2,1,1,WOOD_STEP:8)
Block(-2,1,2,VINE:9)
Block(-2,1,3,GLASS)
Block(-2,1,4,GLASS)
Block(-2,1,5,GLASS)
Block(-2,1,6,GLASS)
Block(-2,1,7,GLASS)
Block(-2,1,8,STONE:6)
Block(-2,2,-7,MONSTER_EGGS:4)
Block(-2,2,-6,WOOD:0)
Block(-2,2,-5,GLASS)
Block(-2,2,-4,VINE:9)
Block(-2,2,-3,GLASS)
Block(-2,2,-2,GLASS)
Block(-2,2,-1,GLASS)
Block(-2,2,0,GLASS)
Block(-2,2,1,WOOL:7)
Block(-2,2,2,VINE:9)
Block(-2,2,3,GLASS)
Block(-2,2,4,GLASS)
Block(-2,2,5,GLASS)
Block(-2,2,6,GLASS)
Block(-2,2,7,GLASS)
Block(-2,2,8,SMOOTH_BRICK:2)
Block(-2,3,-7,STONE:0)
Block(-2,3,-6,BOOKSHELF)
Block(-2,3,-5,DARK_OAK_FENCE:0)
Block(-2,3,-4,VINE:9)
Block(-2,3,-3,GLASS)
Block(-2,3,-2,GLASS)
Block(-2,3,-1,LEAVES:7)
Block(-2,3,0,GLASS)
Block(-2,3,1,BOOKSHELF)
Block(-2,3,2,VINE:9)
Block(-2,3,3,DARK_OAK_FENCE:0)
Block(-2,3,4,GLASS)
Block(-2,3,5,GLASS)
Block(-2,3,6,GLASS)
Block(-2,3,7,GLASS)
Block(-2,3,8,SMOOTH_BRICK:2)
Block(-2,4,-7,SMOOTH_BRICK:0)
Block(-2,4,-6,WOOD:0)
Block(-2,4,-5,LEAVES:7)
Block(-2,4,-4,VINE:4)
Block(-2,4,-3,GLASS)
Block(-2,4,-2,GLASS)
Block(-2,4,-1,GLASS)
Block(-2,4,0,GLASS)
Block(-2,4,1,WOOD:0)
Block(-2,4,2,LEAVES:15)
Block(-2,4,3,LEAVES:15)
Block(-2,4,4,GLASS)
Block(-2,4,5,GLASS)
Block(-2,4,6,GLASS)
Block(-2,4,7,GLASS)
Block(-2,4,8,STONE:6)
Block(-2,5,-7,SMOOTH_BRICK:0)
Block(-2,5,-6,LEAVES:7)
Block(-2,5,-5,LEAVES:4)
Block(-2,5,-4,LEAVES:4)
Block(-2,5,-3,LEAVES:7)
Block(-2,5,-2,LEAVES:4)
Block(-2,5,-1,LEAVES:7)
Block(-2,5,0,LEAVES:7)
Block(-2,5,1,LEAVES:15)
Block(-2,5,2,GLASS)
Block(-2,5,3,GLASS)
Block(-2,5,4,LEAVES:12)
Block(-2,5,5,GLASS)
Block(-2,5,6,GLASS)
Block(-2,5,7,GLASS)
Block(-2,5,8,STONE:6)
Block(-2,6,-7,SMOOTH_BRICK:0)
Block(-2,6,-6,COBBLESTONE)
Block(-2,6,-5,GLASS)
Block(-2,6,-4,LEAVES:4)
Block(-2,6,-3,COBBLESTONE)
Block(-2,6,-2,GLASS)
Block(-2,6,-1,STONE:0)
Block(-2,6,0,COBBLESTONE)
Block(-2,6,1,LEAVES:4)
Block(-2,6,2,LEAVES:4)
Block(-2,6,3,LEAVES:4)
Block(-2,6,4,LEAVES:4)
Block(-2,6,5,LEAVES:7)
Block(-2,6,6,LEAVES:7)
Block(-2,6,7,STONE:6)
Block(-2,6,8,STONE:0)
Block(-2,7,-7,MONSTER_EGGS:4)
Block(-2,7,-6,COBBLESTONE)
Block(-2,7,-5,STONE:0)
Block(-2,7,-4,GLASS)
Block(-2,7,-3,GLASS)
Block(-2,7,-2,GLASS)
Block(-2,7,-1,STONE:0)
Block(-2,7,0,STONE:0)
Block(-2,7,1,STONE:0)
Block(-2,7,2,STONE:0)
Block(-2,7,3,LEAVES:4)
Block(-2,7,4,LEAVES:4)
Block(-2,7,5,GLASS)
Block(-2,7,6,GLASS)
Block(-2,7,7,GLASS)
Block(-2,7,8,SMOOTH_BRICK:0)
Block(-2,8,-7,STONE:0)
Block(-2,8,-6,STONE:0)
Block(-2,8,-5,STONE:0)
Block(-2,8,-4,STONE:0)
Block(-2,8,-3,STONE:0)
Block(-2,8,-2,STONE:0)
Block(-2,8,-1,STONE:0)
Block(-2,8,0,STONE:0)
Block(-2,8,1,STONE:0)
Block(-2,8,2,STONE:0)
Block(-2,8,3,STONE:0)
Block(-2,8,4,STONE:0)
Block(-2,8,5,STONE:0)
Block(-2,8,6,STONE:0)
Block(-2,8,7,STONE:0)
Block(-2,8,8,STONE:0)
Block(-2,9,-7,STONE:0)
Block(-2,9,-6,STONE:0)
Block(-2,9,-5,STONE:0)
Block(-2,9,-4,STONE:0)
Block(-2,9,-3,STONE:0)
Block(-2,9,-2,STONE:0)
Block(-2,9,-1,STONE:0)
Block(-2,9,0,STONE:0)
Block(-2,9,1,STONE:0)
Block(-2,9,2,STONE:0)
Block(-2,9,3,STONE:0)
Block(-2,9,4,STONE:0)
Block(-2,9,5,STONE:0)
Block(-2,9,6,STONE:0)
Block(-2,9,7,STONE:0)
Block(-2,9,8,STONE:0)
Block(-1,0,-7,SMOOTH_BRICK:0)
Block(-1,0,-6,WOOD:1)
Block(-1,0,-5,WOOD:1)
Block(-1,0,-4,WOOD:1)
Block(-1,0,-3,SPRUCE_WOOD_STAIRS:0)
Block(-1,0,-2,WOOD:1)
Block(-1,0,-1,SPRUCE_WOOD_STAIRS:3)
Block(-1,0,0,WOOD:1)
Block(-1,0,1,WOOD:1)
Block(-1,0,2,SPRUCE_WOOD_STAIRS:3)
Block(-1,0,3,WOOD:1)
Block(-1,0,4,WOOD:1)
Block(-1,0,5,WOOD:1)
Block(-1,0,6,WOOD:1)
Block(-1,0,7,WOOD:1)
Block(-1,0,8,WOOD:1)
Block(-1,1,-7,SMOOTH_BRICK:0)
Block(-1,1,-6,WOOD_STEP:8)
Block(-1,1,-5,GLASS)
Block(-1,1,-4,GLASS)
Block(-1,1,-3,VINE:8)
Block(-1,1,-2,GLASS)
Block(-1,1,-1,GLASS)
Block(-1,1,0,GLASS)
Block(-1,1,1,WOOD_STEP:8)
Block(-1,1,2,GLASS)
Block(-1,1,3,GLASS)
Block(-1,1,4,GLASS)
Block(-1,1,5,VINE:8)
Block(-1,1,6,GLASS)
Block(-1,1,7,GLASS)
Block(-1,1,8,GLASS)
Block(-1,2,-7,SMOOTH_BRICK:0)
Block(-1,2,-6,BOOKSHELF)
Block(-1,2,-5,GLASS)
Block(-1,2,-4,GLASS)
Block(-1,2,-3,VINE:8)
Block(-1,2,-2,GLASS)
Block(-1,2,-1,GLASS)
Block(-1,2,0,GLASS)
Block(-1,2,1,BOOKSHELF)
Block(-1,2,2,GLASS)
Block(-1,2,3,GLASS)
Block(-1,2,4,GLASS)
Block(-1,2,5,VINE:8)
Block(-1,2,6,GLASS)
Block(-1,2,7,GLASS)
Block(-1,2,8,GLASS)
Block(-1,3,-7,MONSTER_EGGS:4)
Block(-1,3,-6,BOOKSHELF)
Block(-1,3,-5,GLASS)
Block(-1,3,-4,GLASS)
Block(-1,3,-3,VINE:8)
Block(-1,3,-2,GLASS)
Block(-1,3,-1,GLASS)
Block(-1,3,0,GLASS)
Block(-1,3,1,BOOKSHELF)
Block(-1,3,2,GLASS)
Block(-1,3,3,GLASS)
Block(-1,3,4,GLASS)
Block(-1,3,5,VINE:8)
Block(-1,3,6,GLASS)
Block(-1,3,7,GLASS)
Block(-1,3,8,GLASS)
Block(-1,4,-7,SMOOTH_BRICK:0)
Block(-1,4,-6,WOOD:0)
Block(-1,4,-5,GLASS)
Block(-1,4,-4,GLASS)
Block(-1,4,-3,VINE:8)
Block(-1,4,-2,LEAVES:7)
Block(-1,4,-1,WEB)
Block(-1,4,0,LEAVES:15)
Block(-1,4,1,WOOL:7)
Block(-1,4,2,GLASS)
Block(-1,4,3,GLASS)
Block(-1,4,4,LEAVES:15)
Block(-1,4,5,VINE:8)
Block(-1,4,6,LEAVES:12)
Block(-1,4,7,GLASS)
Block(-1,4,8,GLASS)
Block(-1,5,-7,MONSTER_EGGS:4)
Block(-1,5,-6,LEAVES:7)
Block(-1,5,-5,LEAVES:4)
Block(-1,5,-4,LEAVES:7)
Block(-1,5,-3,COBBLESTONE)
Block(-1,5,-2,LEAVES:7)
Block(-1,5,-1,LEAVES:7)
Block(-1,5,0,LEAVES:7)
Block(-1,5,1,LEAVES:7)
Block(-1,5,2,LEAVES:4)
Block(-1,5,3,GLASS)
Block(-1,5,4,LEAVES:15)
Block(-1,5,5,GLASS)
Block(-1,5,6,LEAVES:12)
Block(-1,5,7,GLASS)
Block(-1,5,8,STONE:6)
Block(-1,6,-7,SMOOTH_BRICK:0)
Block(-1,6,-6,GLASS)
Block(-1,6,-5,LEAVES:7)
Block(-1,6,-4,LEAVES:7)
Block(-1,6,-3,COBBLESTONE)
Block(-1,6,-2,GLASS)
Block(-1,6,-1,LEAVES:15)
Block(-1,6,0,LEAVES:15)
Block(-1,6,1,LEAVES:12)
Block(-1,6,2,LEAVES:4)
Block(-1,6,3,LEAVES:4)
Block(-1,6,4,LEAVES:7)
Block(-1,6,5,LEAVES:7)
Block(-1,6,6,LEAVES:4)
Block(-1,6,7,STONE:6)
Block(-1,6,8,SMOOTH_BRICK:0)
Block(-1,7,-7,SMOOTH_BRICK:0)
Block(-1,7,-6,COBBLESTONE)
Block(-1,7,-5,GLASS)
Block(-1,7,-4,GLASS)
Block(-1,7,-3,COBBLESTONE)
Block(-1,7,-2,STONE:0)
Block(-1,7,-1,COBBLESTONE)
Block(-1,7,0,GLASS)
Block(-1,7,1,COBBLESTONE)
Block(-1,7,2,GLASS)
Block(-1,7,3,COBBLESTONE)
Block(-1,7,4,GLASS)
Block(-1,7,5,GLASS)
Block(-1,7,6,LEAVES:4)
Block(-1,7,7,GLASS)
Block(-1,7,8,SMOOTH_BRICK:0)
Block(-1,8,-7,STONE:0)
Block(-1,8,-6,COBBLESTONE)
Block(-1,8,-5,STONE:0)
Block(-1,8,-4,STONE:0)
Block(-1,8,-3,STONE:0)
Block(-1,8,-2,STONE:0)
Block(-1,8,-1,STONE:0)
Block(-1,8,0,STONE:0)
Block(-1,8,1,STONE:0)
Block(-1,8,2,STONE:0)
Block(-1,8,3,STONE:0)
Block(-1,8,4,STONE:0)
Block(-1,8,5,STONE:0)
Block(-1,8,6,STONE:0)
Block(-1,8,7,STONE:0)
Block(-1,8,8,STONE:0)
Block(-1,9,-7,STONE:0)
Block(-1,9,-6,STONE:0)
Block(-1,9,-5,STONE:0)
Block(-1,9,-4,STONE:0)
Block(-1,9,-3,STONE:0)
Block(-1,9,-2,STONE:0)
Block(-1,9,-1,STONE:0)
Block(-1,9,0,STONE:0)
Block(-1,9,1,STONE:0)
Block(-1,9,2,STONE:0)
Block(-1,9,3,STONE:0)
Block(-1,9,4,STONE:0)
Block(-1,9,5,STONE:0)
Block(-1,9,6,STONE:0)
Block(-1,9,7,STONE:0)
Block(-1,9,8,STONE:0)
Block(0,0,-7,STONE:0)
Block(0,0,-6,WOOD:1)
Block(0,0,-5,SPRUCE_WOOD_STAIRS:0)
Block(0,0,-4,SPRUCE_WOOD_STAIRS:0)
Block(0,0,-3,WOOD:1)
Block(0,0,-2,WOOD:1)
Block(0,0,-1,WOOD:1)
Block(0,0,0,WOOD:1)
Block(0,0,1,WOOD:1)
Block(0,0,2,WOOD:1)
Block(0,0,3,WOOD:1)
Block(0,0,4,WOOD:1)
Block(0,0,5,WOOD:1)
Block(0,0,6,WOOD:1)
Block(0,0,7,SPRUCE_WOOD_STAIRS:3)
Block(0,0,8,WOOD:1)
Block(0,1,-7,SMOOTH_BRICK:0)
Block(0,1,-6,WOOD_STEP:8)
Block(0,1,-5,GLASS)
Block(0,1,-4,WOOD_STAIRS:7)
Block(0,1,-3,WOOD_STEP:8)
Block(0,1,-2,WOOD_STEP:8)
Block(0,1,-1,WOOD_DOUBLE_STEP:0)
Block(0,1,0,VINE:2)
Block(0,1,1,WOOD_STEP:8)
Block(0,1,2,GLASS)
Block(0,1,3,WOOD_STAIRS:7)
Block(0,1,4,WOOD_STEP:8)
Block(0,1,5,WOOD_DOUBLE_STEP:0)
Block(0,1,6,GLASS)
Block(0,1,7,GLASS)
Block(0,1,8,GLASS)
Block(0,2,-7,SMOOTH_BRICK:0)
Block(0,2,-6,BOOKSHELF)
Block(0,2,-5,GLASS)
Block(0,2,-4,DARK_OAK_STAIRS:7)
Block(0,2,-3,WOOD:0)
Block(0,2,-2,BOOKSHELF)
Block(0,2,-1,LOG:2)
Block(0,2,0,VINE:2)
Block(0,2,1,BOOKSHELF)
Block(0,2,2,GLASS)
Block(0,2,3,DARK_OAK_STAIRS:7)
Block(0,2,4,BOOKSHELF)
Block(0,2,5,LOG_2:1)
Block(0,2,6,GLASS)
Block(0,2,7,GLASS)
Block(0,2,8,GLASS)
Block(0,3,-7,SMOOTH_BRICK:0)
Block(0,3,-6,WOOD:0)
Block(0,3,-5,GLASS)
Block(0,3,-4,DARK_OAK_STAIRS:7)
Block(0,3,-3,BOOKSHELF)
Block(0,3,-2,BOOKSHELF)
Block(0,3,-1,LEAVES:15)
Block(0,3,0,VINE:2)
Block(0,3,1,WOOD:0)
Block(0,3,2,GLASS)
Block(0,3,3,DARK_OAK_STAIRS:7)
Block(0,3,4,WOOL:7)
Block(0,3,5,LEAVES:15)
Block(0,3,6,GLASS)
Block(0,3,7,GLASS)
Block(0,3,8,GLASS)
Block(0,4,-7,MONSTER_EGGS:4)
Block(0,4,-6,BOOKSHELF)
Block(0,4,-5,GLASS)
Block(0,4,-4,DARK_OAK_STAIRS:2)
Block(0,4,-3,BOOKSHELF)
Block(0,4,-2,WOOD:0)
Block(0,4,-1,LEAVES:15)
Block(0,4,0,VINE:2)
Block(0,4,1,BOOKSHELF)
Block(0,4,2,GLASS)
Block(0,4,3,DARK_OAK_STAIRS:2)
Block(0,4,4,BOOKSHELF)
Block(0,4,5,LEAVES:15)
Block(0,4,6,GLASS)
Block(0,4,7,GLASS)
Block(0,4,8,GLASS)
Block(0,5,-7,STONE:0)
Block(0,5,-6,LEAVES:7)
Block(0,5,-5,LEAVES:4)
Block(0,5,-4,LEAVES:4)
Block(0,5,-3,LEAVES:4)
Block(0,5,-2,LEAVES:15)
Block(0,5,-1,LEAVES:7)
Block(0,5,0,LEAVES:7)
Block(0,5,1,LEAVES:7)
Block(0,5,2,LEAVES:4)
Block(0,5,3,LEAVES:4)
Block(0,5,4,LEAVES:15)
Block(0,5,5,LEAVES:15)
Block(0,5,6,GLASS)
Block(0,5,7,GLASS)
Block(0,5,8,SMOOTH_BRICK:2)
Block(0,6,-7,STONE:0)
Block(0,6,-6,STONE:0)
Block(0,6,-5,LEAVES:4)
Block(0,6,-4,COBBLESTONE)
Block(0,6,-3,LEAVES:4)
Block(0,6,-2,COBBLESTONE)
Block(0,6,-1,COBBLESTONE)
Block(0,6,0,LEAVES:12)
Block(0,6,1,STONE:0)
Block(0,6,2,COBBLESTONE)
Block(0,6,3,LEAVES:4)
Block(0,6,4,LEAVES:7)
Block(0,6,5,LEAVES:7)
Block(0,6,6,LEAVES:4)
Block(0,6,7,STONE:6)
Block(0,6,8,SMOOTH_BRICK:0)
Block(0,7,-7,SMOOTH_BRICK:0)
Block(0,7,-6,GLASS)
Block(0,7,-5,COBBLESTONE)
Block(0,7,-4,GLASS)
Block(0,7,-3,GLASS)
Block(0,7,-2,GLASS)
Block(0,7,-1,STONE:0)
Block(0,7,0,COBBLESTONE)
Block(0,7,1,STONE:0)
Block(0,7,2,STONE:0)
Block(0,7,3,COBBLESTONE)
Block(0,7,4,GLASS)
Block(0,7,5,COBBLESTONE)
Block(0,7,6,LEAVES:4)
Block(0,7,7,GLASS)
Block(0,7,8,SMOOTH_BRICK:0)
Block(0,8,-7,STONE:0)
Block(0,8,-6,STONE:0)
Block(0,8,-5,STONE:0)
Block(0,8,-4,STONE:0)
Block(0,8,-3,STONE:0)
Block(0,8,-2,STONE:0)
Block(0,8,-1,STONE:0)
Block(0,8,0,STONE:0)
Block(0,8,1,STONE:0)
Block(0,8,2,STONE:0)
Block(0,8,3,COBBLESTONE)
Block(0,8,4,STONE:0)
Block(0,8,5,COBBLESTONE)
Block(0,8,6,LEAVES:4)
Block(0,8,7,STONE:0)
Block(0,8,8,STONE:0)
Block(0,9,-7,STONE:0)
Block(0,9,-6,STONE:0)
Block(0,9,-5,STONE:0)
Block(0,9,-4,STONE:0)
Block(0,9,-3,STONE:0)
Block(0,9,-2,STONE:0)
Block(0,9,-1,STONE:0)
Block(0,9,0,STONE:0)
Block(0,9,1,STONE:0)
Block(0,9,2,STONE:0)
Block(0,9,3,STONE:0)
Block(0,9,4,STONE:0)
Block(0,9,5,STONE:0)
Block(0,9,6,STONE:0)
Block(0,9,7,STONE:0)
Block(0,9,8,STONE:0)
Block(1,0,-7,SMOOTH_BRICK:0)
Block(1,0,-6,WOOD:1)
Block(1,0,-5,WOOD:1)
Block(1,0,-4,WOOD:1)
Block(1,0,-3,WOOD:1)
Block(1,0,-2,WOOD:1)
Block(1,0,-1,WOOD:1)
Block(1,0,0,WOOD:1)
Block(1,0,1,WOOD:1)
Block(1,0,2,WOOD:1)
Block(1,0,3,SPRUCE_WOOD_STAIRS:1)
Block(1,0,4,WOOD:1)
Block(1,0,5,WOOD:1)
Block(1,0,6,WOOD:1)
Block(1,0,7,WOOD:1)
Block(1,0,8,SMOOTH_BRICK:2)
Block(1,1,-7,SMOOTH_BRICK:0)
Block(1,1,-6,WOOD_STAIRS:4)
Block(1,1,-5,GLASS)
Block(1,1,-4,GLASS)
Block(1,1,-3,VINE:14)
Block(1,1,-2,GLASS)
Block(1,1,-1,WOOD_STEP:8)
Block(1,1,0,GLASS)
Block(1,1,1,WOOD_STAIRS:4)
Block(1,1,2,GLASS)
Block(1,1,3,GLASS)
Block(1,1,4,GLASS)
Block(1,1,5,WOOD_STEP:8)
Block(1,1,6,GLASS)
Block(1,1,7,GLASS)
Block(1,1,8,SMOOTH_BRICK:2)
Block(1,2,-7,SMOOTH_BRICK:0)
Block(1,2,-6,DARK_OAK_STAIRS:4)
Block(1,2,-5,GLASS)
Block(1,2,-4,GLASS)
Block(1,2,-3,VINE:14)
Block(1,2,-2,GLASS)
Block(1,2,-1,BOOKSHELF)
Block(1,2,0,GLASS)
Block(1,2,1,DARK_OAK_STAIRS:4)
Block(1,2,2,GLASS)
Block(1,2,3,GLASS)
Block(1,2,4,GLASS)
Block(1,2,5,BOOKSHELF)
Block(1,2,6,GLASS)
Block(1,2,7,GLASS)
Block(1,2,8,STONE:6)
Block(1,3,-7,MONSTER_EGGS:4)
Block(1,3,-6,DARK_OAK_STAIRS:4)
Block(1,3,-5,GLASS)
Block(1,3,-4,GLASS)
Block(1,3,-3,VINE:14)
Block(1,3,-2,DARK_OAK_FENCE:0)
Block(1,3,-1,WOOD:0)
Block(1,3,0,GLASS)
Block(1,3,1,DARK_OAK_STAIRS:4)
Block(1,3,2,DARK_OAK_FENCE:0)
Block(1,3,3,GLASS)
Block(1,3,4,LEAVES:15)
Block(1,3,5,WOOD:0)
Block(1,3,6,GLASS)
Block(1,3,7,GLASS)
Block(1,3,8,STONE:6)
Block(1,4,-7,MONSTER_EGGS:4)
Block(1,4,-6,DARK_OAK_STAIRS:1)
Block(1,4,-5,LEAVES:7)
Block(1,4,-4,LEAVES:7)
Block(1,4,-3,VINE:12)
Block(1,4,-2,LEAVES:15)
Block(1,4,-1,BOOKSHELF)
Block(1,4,0,GLASS)
Block(1,4,1,DARK_OAK_STAIRS:1)
Block(1,4,2,LEAVES:15)
Block(1,4,3,GLASS)
Block(1,4,4,VINE:12)
Block(1,4,5,BOOKSHELF)
Block(1,4,6,GLASS)
Block(1,4,7,GLASS)
Block(1,4,8,SMOOTH_BRICK:2)
Block(1,5,-7,SMOOTH_BRICK:0)
Block(1,5,-6,LEAVES:7)
Block(1,5,-5,LEAVES:7)
Block(1,5,-4,LEAVES:7)
Block(1,5,-3,LEAVES:4)
Block(1,5,-2,LEAVES:4)
Block(1,5,-1,LEAVES:15)
Block(1,5,0,GLASS)
Block(1,5,1,LEAVES:7)
Block(1,5,2,LEAVES:7)
Block(1,5,3,LEAVES:7)
Block(1,5,4,LEAVES:15)
Block(1,5,5,LEAVES:15)
Block(1,5,6,LEAVES:15)
Block(1,5,7,GLASS)
Block(1,5,8,SMOOTH_BRICK:2)
Block(1,6,-7,MONSTER_EGGS:4)
Block(1,6,-6,STONE:0)
Block(1,6,-5,COBBLESTONE)
Block(1,6,-4,GLASS)
Block(1,6,-3,COBBLESTONE)
Block(1,6,-2,COBBLESTONE)
Block(1,6,-1,GLASS)
Block(1,6,0,LEAVES:12)
Block(1,6,1,LEAVES:4)
Block(1,6,2,GLASS)
Block(1,6,3,COBBLESTONE)
Block(1,6,4,GLASS)
Block(1,6,5,LEAVES:7)
Block(1,6,6,LEAVES:4)
Block(1,6,7,STONE:6)
Block(1,6,8,SMOOTH_BRICK:0)
Block(1,7,-7,SMOOTH_BRICK:0)
Block(1,7,-6,GLASS)
Block(1,7,-5,COBBLESTONE)
Block(1,7,-4,STONE:0)
Block(1,7,-3,COBBLESTONE)
Block(1,7,-2,COBBLESTONE)
Block(1,7,-1,GLASS)
Block(1,7,0,STONE:0)
Block(1,7,1,STONE:0)
Block(1,7,2,GLASS)
Block(1,7,3,COBBLESTONE)
Block(1,7,4,COBBLESTONE)
Block(1,7,5,LEAVES:7)
Block(1,7,6,STONE:0)
Block(1,7,7,STONE:0)
Block(1,7,8,SMOOTH_BRICK:0)
Block(1,8,-7,STONE:0)
Block(1,8,-6,STONE:0)
Block(1,8,-5,STONE:0)
Block(1,8,-4,STONE:0)
Block(1,8,-3,STONE:0)
Block(1,8,-2,STONE:0)
Block(1,8,-1,STONE:0)
Block(1,8,0,STONE:0)
Block(1,8,1,STONE:0)
Block(1,8,2,STONE:0)
Block(1,8,3,STONE:0)
Block(1,8,4,STONE:0)
Block(1,8,5,STONE:0)
Block(1,8,6,STONE:0)
Block(1,8,7,STONE:0)
Block(1,8,8,STONE:0)
Block(1,9,-7,STONE:0)
Block(1,9,-6,STONE:0)
Block(1,9,-5,STONE:0)
Block(1,9,-4,STONE:0)
Block(1,9,-3,STONE:0)
Block(1,9,-2,STONE:0)
Block(1,9,-1,STONE:0)
Block(1,9,0,STONE:0)
Block(1,9,1,STONE:0)
Block(1,9,2,STONE:0)
Block(1,9,3,STONE:0)
Block(1,9,4,STONE:0)
Block(1,9,5,STONE:0)
Block(1,9,6,STONE:0)
Block(1,9,7,STONE:0)
Block(1,9,8,STONE:0)
Block(2,0,-7,SMOOTH_BRICK:0)
Block(2,0,-6,WOOD:1)
Block(2,0,-5,SPRUCE_WOOD_STAIRS:3)
Block(2,0,-4,WOOD:1)
Block(2,0,-3,WOOD:1)
Block(2,0,-2,WOOD:1)
Block(2,0,-1,WOOD:1)
Block(2,0,0,WOOD:1)
Block(2,0,1,WOOD:1)
Block(2,0,2,WOOD:1)
Block(2,0,3,WOOD:1)
Block(2,0,4,SPRUCE_WOOD_STAIRS:0)
Block(2,0,5,WOOD:1)
Block(2,0,6,WOOD:1)
Block(2,0,7,WOOD:1)
Block(2,0,8,SMOOTH_BRICK:0)
Block(2,1,-7,MONSTER_EGGS:4)
Block(2,1,-6,LOG:2)
Block(2,1,-5,VINE:9)
Block(2,1,-4,GLASS)
Block(2,1,-3,WOOD_STAIRS:5)
Block(2,1,-2,GLASS)
Block(2,1,-1,WOOD_STAIRS:4)
Block(2,1,0,GLASS)
Block(2,1,1,GLASS)
Block(2,1,2,GLASS)
Block(2,1,3,GLASS)
Block(2,1,4,GLASS)
Block(2,1,5,WOOD_STEP:8)
Block(2,1,6,GLASS)
Block(2,1,7,STONE:6)
Block(2,1,8,MONSTER_EGGS:4)
Block(2,2,-7,SMOOTH_BRICK:0)
Block(2,2,-6,LEAVES:15)
Block(2,2,-5,VINE:9)
Block(2,2,-4,GLASS)
Block(2,2,-3,DARK_OAK_STAIRS:5)
Block(2,2,-2,GLASS)
Block(2,2,-1,DARK_OAK_STAIRS:4)
Block(2,2,0,GLASS)
Block(2,2,1,GLASS)
Block(2,2,2,GLASS)
Block(2,2,3,GLASS)
Block(2,2,4,GLASS)
Block(2,2,5,WOOD:0)
Block(2,2,6,GLASS)
Block(2,2,7,STONE:6)
Block(2,2,8,MONSTER_EGGS:4)
Block(2,3,-7,STONE:0)
Block(2,3,-6,LEAVES:15)
Block(2,3,-5,VINE:9)
Block(2,3,-4,GLASS)
Block(2,3,-3,DARK_OAK_STAIRS:5)
Block(2,3,-2,GLASS)
Block(2,3,-1,DARK_OAK_STAIRS:4)
Block(2,3,0,GLASS)
Block(2,3,1,GLASS)
Block(2,3,2,GLASS)
Block(2,3,3,GLASS)
Block(2,3,4,WEB)
Block(2,3,5,BOOKSHELF)
Block(2,3,6,GLASS)
Block(2,3,7,STONE:6)
Block(2,3,8,MONSTER_EGGS:4)
Block(2,4,-7,MONSTER_EGGS:4)
Block(2,4,-6,LEAVES:15)
Block(2,4,-5,VINE:9)
Block(2,4,-4,GLASS)
Block(2,4,-3,DARK_OAK_STAIRS:0)
Block(2,4,-2,LEAVES:15)
Block(2,4,-1,DARK_OAK_STAIRS:1)
Block(2,4,0,GLASS)
Block(2,4,1,GLASS)
Block(2,4,2,GLASS)
Block(2,4,3,GLASS)
Block(2,4,4,LEAVES:15)
Block(2,4,5,WOOD:0)
Block(2,4,6,GLASS)
Block(2,4,7,STONE:6)
Block(2,4,8,SMOOTH_BRICK:0)
Block(2,5,-7,SMOOTH_BRICK:0)
Block(2,5,-6,LEAVES:7)
Block(2,5,-5,LEAVES:7)
Block(2,5,-4,GLASS)
Block(2,5,-3,LEAVES:4)
Block(2,5,-2,LEAVES:4)
Block(2,5,-1,GLASS)
Block(2,5,0,GLASS)
Block(2,5,1,LEAVES:4)
Block(2,5,2,LEAVES:7)
Block(2,5,3,LEAVES:7)
Block(2,5,4,LEAVES:7)
Block(2,5,5,LEAVES:7)
Block(2,5,6,LEAVES:7)
Block(2,5,7,STONE:6)
Block(2,5,8,SMOOTH_BRICK:0)
Block(2,6,-7,SMOOTH_BRICK:0)
Block(2,6,-6,LEAVES:7)
Block(2,6,-5,COBBLESTONE)
Block(2,6,-4,LEAVES:7)
Block(2,6,-3,LEAVES:4)
Block(2,6,-2,LEAVES:4)
Block(2,6,-1,LEAVES:4)
Block(2,6,0,LEAVES:4)
Block(2,6,1,STONE:0)
Block(2,6,2,GLASS)
Block(2,6,3,LEAVES:7)
Block(2,6,4,COBBLESTONE)
Block(2,6,5,GLASS)
Block(2,6,6,LEAVES:7)
Block(2,6,7,STONE:6)
Block(2,6,8,SMOOTH_BRICK:0)
Block(2,7,-7,MONSTER_EGGS:4)
Block(2,7,-6,GLASS)
Block(2,7,-5,GLASS)
Block(2,7,-4,STONE:0)
Block(2,7,-3,GLASS)
Block(2,7,-2,COBBLESTONE)
Block(2,7,-1,STONE:0)
Block(2,7,0,GLASS)
Block(2,7,1,STONE:0)
Block(2,7,2,GLASS)
Block(2,7,3,GLASS)
Block(2,7,4,COBBLESTONE)
Block(2,7,5,COBBLESTONE)
Block(2,7,6,GLASS)
Block(2,7,7,STONE:6)
Block(2,7,8,SMOOTH_BRICK:0)
Block(2,8,-7,STONE:0)
Block(2,8,-6,STONE:0)
Block(2,8,-5,STONE:0)
Block(2,8,-4,STONE:0)
Block(2,8,-3,STONE:0)
Block(2,8,-2,STONE:0)
Block(2,8,-1,STONE:0)
Block(2,8,0,STONE:0)
Block(2,8,1,STONE:0)
Block(2,8,2,STONE:0)
Block(2,8,3,STONE:0)
Block(2,8,4,STONE:0)
Block(2,8,5,STONE:0)
Block(2,8,6,STONE:0)
Block(2,8,7,STONE:0)
Block(2,8,8,STONE:0)
Block(2,9,-7,STONE:0)
Block(2,9,-6,STONE:0)
Block(2,9,-5,STONE:0)
Block(2,9,-4,STONE:0)
Block(2,9,-3,STONE:0)
Block(2,9,-2,STONE:0)
Block(2,9,-1,STONE:0)
Block(2,9,0,STONE:0)
Block(2,9,1,STONE:0)
Block(2,9,2,STONE:0)
Block(2,9,3,STONE:0)
Block(2,9,4,STONE:0)
Block(2,9,5,STONE:0)
Block(2,9,6,STONE:0)
Block(2,9,7,STONE:0)
Block(2,9,8,STONE:0)
Block(3,0,-7,SMOOTH_BRICK:0)
Block(3,0,-6,WOOD:1)
Block(3,0,-5,WOOD:1)
Block(3,0,-4,WOOD:1)
Block(3,0,-3,WOOD:1)
Block(3,0,-2,WOOD:1)
Block(3,0,-1,WOOD:1)
Block(3,0,0,SPRUCE_WOOD_STAIRS:3)
Block(3,0,1,WOOD:1)
Block(3,0,2,SPRUCE_WOOD_STAIRS:0)
Block(3,0,3,WOOD:1)
Block(3,0,4,WOOD:1)
Block(3,0,5,WOOD:1)
Block(3,0,6,WOOD:1)
Block(3,0,7,WOOD:1)
Block(3,0,8,SMOOTH_BRICK:0)
Block(3,1,-7,SMOOTH_BRICK:0)
Block(3,1,-6,LOG:2)
Block(3,1,-5,DARK_OAK_FENCE:0)
Block(3,1,-4,GLASS)
Block(3,1,-3,WOOD_STEP:8)
Block(3,1,-2,GLASS)
Block(3,1,-1,GLASS)
Block(3,1,0,GLASS)
Block(3,1,1,GLASS)
Block(3,1,2,GLASS)
Block(3,1,3,GLASS)
Block(3,1,4,GLASS)
Block(3,1,5,WOOD_STEP:8)
Block(3,1,6,GLASS)
Block(3,1,7,GLASS)
Block(3,1,8,SMOOTH_BRICK:0)
Block(3,2,-7,SMOOTH_BRICK:0)
Block(3,2,-6,LEAVES:15)
Block(3,2,-5,GLASS)
Block(3,2,-4,GLASS)
Block(3,2,-3,BOOKSHELF)
Block(3,2,-2,GLASS)
Block(3,2,-1,GLASS)
Block(3,2,0,GLASS)
Block(3,2,1,GLASS)
Block(3,2,2,GLASS)
Block(3,2,3,GLASS)
Block(3,2,4,GLASS)
Block(3,2,5,BOOKSHELF)
Block(3,2,6,GLASS)
Block(3,2,7,GLASS)
Block(3,2,8,MONSTER_EGGS:4)
Block(3,3,-7,SMOOTH_BRICK:0)
Block(3,3,-6,LEAVES:15)
Block(3,3,-5,GLASS)
Block(3,3,-4,GLASS)
Block(3,3,-3,BOOKSHELF)
Block(3,3,-2,GLASS)
Block(3,3,-1,GLASS)
Block(3,3,0,DARK_OAK_FENCE:0)
Block(3,3,1,GLASS)
Block(3,3,2,GLASS)
Block(3,3,3,GLASS)
Block(3,3,4,GLASS)
Block(3,3,5,BOOKSHELF)
Block(3,3,6,GLASS)
Block(3,3,7,DARK_OAK_FENCE:0)
Block(3,3,8,MONSTER_EGGS:4)
Block(3,4,-7,SMOOTH_BRICK:0)
Block(3,4,-6,LEAVES:15)
Block(3,4,-5,GLASS)
Block(3,4,-4,WEB)
Block(3,4,-3,BOOKSHELF)
Block(3,4,-2,WEB)
Block(3,4,-1,GLASS)
Block(3,4,0,LEAVES:15)
Block(3,4,1,WEB)
Block(3,4,2,GLASS)
Block(3,4,3,GLASS)
Block(3,4,4,GLASS)
Block(3,4,5,BOOKSHELF)
Block(3,4,6,GLASS)
Block(3,4,7,GLASS)
Block(3,4,8,MONSTER_EGGS:4)
Block(3,5,-7,SMOOTH_BRICK:0)
Block(3,5,-6,LEAVES:4)
Block(3,5,-5,LEAVES:4)
Block(3,5,-4,GLASS)
Block(3,5,-3,LEAVES:15)
Block(3,5,-2,LEAVES:4)
Block(3,5,-1,GLASS)
Block(3,5,0,LEAVES:4)
Block(3,5,1,LEAVES:4)
Block(3,5,2,GLASS)
Block(3,5,3,GLASS)
Block(3,5,4,LEAVES:7)
Block(3,5,5,LEAVES:7)
Block(3,5,6,LEAVES:7)
Block(3,5,7,COBBLESTONE)
Block(3,5,8,SMOOTH_BRICK:0)
Block(3,6,-7,SMOOTH_BRICK:0)
Block(3,6,-6,COBBLESTONE)
Block(3,6,-5,VINE:4)
Block(3,6,-4,LEAVES:7)
Block(3,6,-3,LEAVES:4)
Block(3,6,-2,LEAVES:4)
Block(3,6,-1,LEAVES:4)
Block(3,6,0,LEAVES:4)
Block(3,6,1,LEAVES:4)
Block(3,6,2,LEAVES:4)
Block(3,6,3,LEAVES:7)
Block(3,6,4,LEAVES:7)
Block(3,6,5,LEAVES:7)
Block(3,6,6,LEAVES:4)
Block(3,6,7,COBBLESTONE)
Block(3,6,8,SMOOTH_BRICK:0)
Block(3,7,-7,SMOOTH_BRICK:0)
Block(3,7,-6,COBBLESTONE)
Block(3,7,-5,STONE:0)
Block(3,7,-4,STONE:0)
Block(3,7,-3,GLASS)
Block(3,7,-2,COBBLESTONE)
Block(3,7,-1,GLASS)
Block(3,7,0,COBBLESTONE)
Block(3,7,1,STONE:0)
Block(3,7,2,GLASS)
Block(3,7,3,LEAVES:7)
Block(3,7,4,LEAVES:7)
Block(3,7,5,COBBLESTONE)
Block(3,7,6,COBBLESTONE)
Block(3,7,7,COBBLESTONE)
Block(3,7,8,SMOOTH_BRICK:0)
Block(3,8,-7,STONE:0)
Block(3,8,-6,STONE:0)
Block(3,8,-5,STONE:0)
Block(3,8,-4,STONE:0)
Block(3,8,-3,STONE:0)
Block(3,8,-2,STONE:0)
Block(3,8,-1,STONE:0)
Block(3,8,0,STONE:0)
Block(3,8,1,STONE:0)
Block(3,8,2,STONE:0)
Block(3,8,3,STONE:0)
Block(3,8,4,STONE:0)
Block(3,8,5,STONE:0)
Block(3,8,6,COBBLESTONE)
Block(3,8,7,COBBLESTONE)
Block(3,8,8,STONE:0)
Block(3,9,-7,STONE:0)
Block(3,9,-6,STONE:0)
Block(3,9,-5,STONE:0)
Block(3,9,-4,STONE:0)
Block(3,9,-3,STONE:0)
Block(3,9,-2,STONE:0)
Block(3,9,-1,STONE:0)
Block(3,9,0,STONE:0)
Block(3,9,1,STONE:0)
Block(3,9,2,STONE:0)
Block(3,9,3,STONE:0)
Block(3,9,4,STONE:0)
Block(3,9,5,STONE:0)
Block(3,9,6,STONE:0)
Block(3,9,7,STONE:0)
Block(3,9,8,STONE:0)
Block(4,0,-7,SMOOTH_BRICK:0)
Block(4,0,-6,WOOD:1)
Block(4,0,-5,SPRUCE_WOOD_STAIRS:0)
Block(4,0,-4,WOOD:1)
Block(4,0,-3,WOOD:1)
Block(4,0,-2,WOOD:1)
Block(4,0,-1,WOOD:1)
Block(4,0,0,WOOD:1)
Block(4,0,1,WOOD:1)
Block(4,0,2,WOOD:1)
Block(4,0,3,WOOD:1)
Block(4,0,4,WOOD:1)
Block(4,0,5,WOOD:1)
Block(4,0,6,WOOD:1)
Block(4,0,7,WOOD:1)
Block(4,0,8,SMOOTH_BRICK:0)
Block(4,1,-7,MONSTER_EGGS:4)
Block(4,1,-6,WOOD_STAIRS:5)
Block(4,1,-5,GLASS)
Block(4,1,-4,GLASS)
Block(4,1,-3,WOOD_STAIRS:4)
Block(4,1,-2,GLASS)
Block(4,1,-1,WOOD_STAIRS:7)
Block(4,1,0,WOOD_STEP:8)
Block(4,1,1,WOOD_DOUBLE_STEP:0)
Block(4,1,2,WOOD_STEP:8)
Block(4,1,3,WOOD_STAIRS:6)
Block(4,1,4,GLASS)
Block(4,1,5,WOOD_STAIRS:4)
Block(4,1,6,GLASS)
Block(4,1,7,DARK_OAK_STAIRS:2)
Block(4,1,8,MONSTER_EGGS:4)
Block(4,2,-7,STONE:0)
Block(4,2,-6,DARK_OAK_STAIRS:5)
Block(4,2,-5,GLASS)
Block(4,2,-4,GLASS)
Block(4,2,-3,DARK_OAK_STAIRS:4)
Block(4,2,-2,GLASS)
Block(4,2,-1,DARK_OAK_STAIRS:7)
Block(4,2,0,BOOKSHELF)
Block(4,2,1,LOG_2:1)
Block(4,2,2,BOOKSHELF)
Block(4,2,3,DARK_OAK_STAIRS:6)
Block(4,2,4,GLASS)
Block(4,2,5,DARK_OAK_STAIRS:4)
Block(4,2,6,GLASS)
Block(4,2,7,GLASS)
Block(4,2,8,STONE:0)
Block(4,3,-7,MONSTER_EGGS:4)
Block(4,3,-6,DARK_OAK_STAIRS:5)
Block(4,3,-5,GLASS)
Block(4,3,-4,GLASS)
Block(4,3,-3,DARK_OAK_STAIRS:4)
Block(4,3,-2,GLASS)
Block(4,3,-1,DARK_OAK_STAIRS:7)
Block(4,3,0,BOOKSHELF)
Block(4,3,1,LEAVES:15)
Block(4,3,2,BOOKSHELF)
Block(4,3,3,DARK_OAK_STAIRS:6)
Block(4,3,4,GLASS)
Block(4,3,5,DARK_OAK_STAIRS:4)
Block(4,3,6,GLASS)
Block(4,3,7,GLASS)
Block(4,3,8,MONSTER_EGGS:4)
Block(4,4,-7,SMOOTH_BRICK:0)
Block(4,4,-6,DARK_OAK_STAIRS:0)
Block(4,4,-5,GLASS)
Block(4,4,-4,LEAVES:7)
Block(4,4,-3,DARK_OAK_STAIRS:1)
Block(4,4,-2,GLASS)
Block(4,4,-1,DARK_OAK_STAIRS:2)
Block(4,4,0,BOOKSHELF)
Block(4,4,1,LEAVES:15)
Block(4,4,2,WOOD:0)
Block(4,4,3,DARK_OAK_STAIRS:3)
Block(4,4,4,GLASS)
Block(4,4,5,DARK_OAK_STAIRS:1)
Block(4,4,6,GLASS)
Block(4,4,7,LEAVES:15)
Block(4,4,8,SMOOTH_BRICK:0)
Block(4,5,-7,STONE:0)
Block(4,5,-6,LEAVES:15)
Block(4,5,-5,LEAVES:4)
Block(4,5,-4,LEAVES:4)
Block(4,5,-3,LEAVES:4)
Block(4,5,-2,LEAVES:7)
Block(4,5,-1,GLASS)
Block(4,5,0,LEAVES:4)
Block(4,5,1,LEAVES:4)
Block(4,5,2,LEAVES:15)
Block(4,5,3,GLASS)
Block(4,5,4,GLASS)
Block(4,5,5,GLASS)
Block(4,5,6,LEAVES:7)
Block(4,5,7,LEAVES:15)
Block(4,5,8,SMOOTH_BRICK:0)
Block(4,6,-7,MONSTER_EGGS:4)
Block(4,6,-6,LEAVES:15)
Block(4,6,-5,VINE:3)
Block(4,6,-4,GLASS)
Block(4,6,-3,LEAVES:7)
Block(4,6,-2,LEAVES:7)
Block(4,6,-1,LEAVES:7)
Block(4,6,0,LEAVES:4)
Block(4,6,1,LEAVES:7)
Block(4,6,2,LEAVES:7)
Block(4,6,3,LEAVES:7)
Block(4,6,4,LEAVES:4)
Block(4,6,5,LEAVES:7)
Block(4,6,6,LEAVES:4)
Block(4,6,7,LEAVES:4)
Block(4,6,8,SMOOTH_BRICK:0)
Block(4,7,-7,SMOOTH_BRICK:0)
Block(4,7,-6,COBBLESTONE)
Block(4,7,-5,GLASS)
Block(4,7,-4,STONE:0)
Block(4,7,-3,STONE:0)
Block(4,7,-2,STONE:0)
Block(4,7,-1,GLASS)
Block(4,7,0,COBBLESTONE)
Block(4,7,1,GLASS)
Block(4,7,2,STONE:0)
Block(4,7,3,STONE:0)
Block(4,7,4,LEAVES:4)
Block(4,7,5,GLASS)
Block(4,7,6,LEAVES:4)
Block(4,7,7,COBBLESTONE)
Block(4,7,8,MONSTER_EGGS:4)
Block(4,8,-7,STONE:0)
Block(4,8,-6,STONE:0)
Block(4,8,-5,STONE:0)
Block(4,8,-4,STONE:0)
Block(4,8,-3,STONE:0)
Block(4,8,-2,STONE:0)
Block(4,8,-1,STONE:0)
Block(4,8,0,STONE:0)
Block(4,8,1,STONE:0)
Block(4,8,2,STONE:0)
Block(4,8,3,STONE:0)
Block(4,8,4,STONE:0)
Block(4,8,5,STONE:0)
Block(4,8,6,STONE:0)
Block(4,8,7,STONE:0)
Block(4,8,8,STONE:0)
Block(4,9,-7,STONE:0)
Block(4,9,-6,STONE:0)
Block(4,9,-5,STONE:0)
Block(4,9,-4,STONE:0)
Block(4,9,-3,STONE:0)
Block(4,9,-2,STONE:0)
Block(4,9,-1,STONE:0)
Block(4,9,0,STONE:0)
Block(4,9,1,STONE:0)
Block(4,9,2,STONE:0)
Block(4,9,3,STONE:0)
Block(4,9,4,STONE:0)
Block(4,9,5,STONE:0)
Block(4,9,6,STONE:0)
Block(4,9,7,STONE:0)
Block(4,9,8,STONE:0)
Block(5,0,-7,SMOOTH_BRICK:0)
Block(5,0,-6,WOOD:1)
Block(5,0,-5,WOOD:1)
Block(5,0,-4,WOOD:1)
Block(5,0,-3,WOOD:1)
Block(5,0,-2,SPRUCE_WOOD_STAIRS:0)
Block(5,0,-1,WOOD:1)
Block(5,0,0,WOOD:1)
Block(5,0,1,WOOD:1)
Block(5,0,2,WOOD:1)
Block(5,0,3,SPRUCE_WOOD_STAIRS:0)
Block(5,0,4,SPRUCE_WOOD_STAIRS:0)
Block(5,0,5,WOOD:1)
Block(5,0,6,WOOD:1)
Block(5,0,7,WOOD:1)
Block(5,0,8,SMOOTH_BRICK:0)
Block(5,1,-7,STONE:0)
Block(5,1,-6,WOOD_STAIRS:7)
Block(5,1,-5,GLASS)
Block(5,1,-4,GLASS)
Block(5,1,-3,GLASS)
Block(5,1,-2,GLASS)
Block(5,1,-1,GLASS)
Block(5,1,0,GLASS)
Block(5,1,1,WOOD_STEP:8)
Block(5,1,2,VINE:4)
Block(5,1,3,GLASS)
Block(5,1,4,GLASS)
Block(5,1,5,GLASS)
Block(5,1,6,VINE:8)
Block(5,1,7,DARK_OAK_STAIRS:6)
Block(5,1,8,STONE:0)
Block(5,2,-7,SMOOTH_BRICK:0)
Block(5,2,-6,BOOKSHELF)
Block(5,2,-5,GLASS)
Block(5,2,-4,GLASS)
Block(5,2,-3,GLASS)
Block(5,2,-2,GLASS)
Block(5,2,-1,GLASS)
Block(5,2,0,GLASS)
Block(5,2,1,BOOKSHELF)
Block(5,2,2,VINE:4)
Block(5,2,3,GLASS)
Block(5,2,4,GLASS)
Block(5,2,5,GLASS)
Block(5,2,6,VINE:8)
Block(5,2,7,WEB)
Block(5,2,8,SMOOTH_BRICK:0)
Block(5,3,-7,SMOOTH_BRICK:0)
Block(5,3,-6,WOOD:0)
Block(5,3,-5,GLASS)
Block(5,3,-4,DARK_OAK_FENCE:0)
Block(5,3,-3,GLASS)
Block(5,3,-2,GLASS)
Block(5,3,-1,LEAVES:15)
Block(5,3,0,DARK_OAK_FENCE:0)
Block(5,3,1,WOOD:0)
Block(5,3,2,LEAVES:15)
Block(5,3,3,GLASS)
Block(5,3,4,GLASS)
Block(5,3,5,GLASS)
Block(5,3,6,VINE:8)
Block(5,3,7,LEAVES:15)
Block(5,3,8,SMOOTH_BRICK:0)
Block(5,4,-7,SMOOTH_BRICK:0)
Block(5,4,-6,BOOKSHELF)
Block(5,4,-5,WEB)
Block(5,4,-4,LEAVES:7)
Block(5,4,-3,LEAVES:15)
Block(5,4,-2,GLASS)
Block(5,4,-1,LEAVES:15)
Block(5,4,0,GLASS)
Block(5,4,1,BOOKSHELF)
Block(5,4,2,GLASS)
Block(5,4,3,GLASS)
Block(5,4,4,GLASS)
Block(5,4,5,GLASS)
Block(5,4,6,VINE:8)
Block(5,4,7,VINE:1)
Block(5,4,8,SMOOTH_BRICK:0)
Block(5,5,-7,MONSTER_EGGS:4)
Block(5,5,-6,LEAVES:4)
Block(5,5,-5,LEAVES:4)
Block(5,5,-4,LEAVES:4)
Block(5,5,-3,LEAVES:4)
Block(5,5,-2,LEAVES:7)
Block(5,5,-1,LEAVES:4)
Block(5,5,0,LEAVES:4)
Block(5,5,1,LEAVES:15)
Block(5,5,2,GLASS)
Block(5,5,3,GLASS)
Block(5,5,4,GLASS)
Block(5,5,5,GLASS)
Block(5,5,6,GLASS)
Block(5,5,7,VINE:1)
Block(5,5,8,SMOOTH_BRICK:0)
Block(5,6,-7,STONE:0)
Block(5,6,-6,VINE:5)
Block(5,6,-5,LEAVES:4)
Block(5,6,-4,LEAVES:4)
Block(5,6,-3,COBBLESTONE)
Block(5,6,-2,LEAVES:4)
Block(5,6,-1,LEAVES:4)
Block(5,6,0,LEAVES:4)
Block(5,6,1,LEAVES:7)
Block(5,6,2,LEAVES:4)
Block(5,6,3,LEAVES:7)
Block(5,6,4,LEAVES:4)
Block(5,6,5,LEAVES:7)
Block(5,6,6,LEAVES:4)
Block(5,6,7,LEAVES:4)
Block(5,6,8,STONE:0)
Block(5,7,-7,SMOOTH_BRICK:0)
Block(5,7,-6,STONE:0)
Block(5,7,-5,COBBLESTONE)
Block(5,7,-4,STONE:0)
Block(5,7,-3,STONE:0)
Block(5,7,-2,STONE:0)
Block(5,7,-1,STONE:0)
Block(5,7,0,GLASS)
Block(5,7,1,LEAVES:4)
Block(5,7,2,STONE:0)
Block(5,7,3,LEAVES:7)
Block(5,7,4,COBBLESTONE)
Block(5,7,5,COBBLESTONE)
Block(5,7,6,LEAVES:4)
Block(5,7,7,STONE:0)
Block(5,7,8,MONSTER_EGGS:4)
Block(5,8,-7,STONE:0)
Block(5,8,-6,STONE:0)
Block(5,8,-5,STONE:0)
Block(5,8,-4,STONE:0)
Block(5,8,-3,STONE:0)
Block(5,8,-2,STONE:0)
Block(5,8,-1,STONE:0)
Block(5,8,0,STONE:0)
Block(5,8,1,STONE:0)
Block(5,8,2,STONE:0)
Block(5,8,3,STONE:0)
Block(5,8,4,STONE:0)
Block(5,8,5,STONE:0)
Block(5,8,6,COBBLESTONE)
Block(5,8,7,STONE:0)
Block(5,8,8,STONE:0)
Block(5,9,-7,STONE:0)
Block(5,9,-6,STONE:0)
Block(5,9,-5,STONE:0)
Block(5,9,-4,STONE:0)
Block(5,9,-3,STONE:0)
Block(5,9,-2,STONE:0)
Block(5,9,-1,STONE:0)
Block(5,9,0,STONE:0)
Block(5,9,1,STONE:0)
Block(5,9,2,STONE:0)
Block(5,9,3,STONE:0)
Block(5,9,4,STONE:0)
Block(5,9,5,STONE:0)
Block(5,9,6,STONE:0)
Block(5,9,7,STONE:0)
Block(5,9,8,STONE:0)
Block(6,0,-7,SMOOTH_BRICK:0)
Block(6,0,-6,WOOD:1)
Block(6,0,-5,WOOD:1)
Block(6,0,-4,WOOD:1)
Block(6,0,-3,WOOD:1)
Block(6,0,-2,WOOD:1)
Block(6,0,-1,WOOD:1)
Block(6,0,0,WOOD:1)
Block(6,0,1,WOOD:1)
Block(6,0,2,WOOD:1)
Block(6,0,3,WOOD:1)
Block(6,0,4,WOOD:1)
Block(6,0,5,SPRUCE_WOOD_STAIRS:0)
Block(6,0,6,WOOD:1)
Block(6,0,7,WOOD:1)
Block(6,0,8,STONE:0)
Block(6,1,-7,MONSTER_EGGS:4)
Block(6,1,-6,WOOD_STAIRS:4)
Block(6,1,-5,WOOD_STAIRS:4)
Block(6,1,-4,WOOD_STAIRS:4)
Block(6,1,-3,WOOD_STAIRS:6)
Block(6,1,-2,COBBLESTONE_STAIRS:0)
Block(6,1,-1,COBBLESTONE)
Block(6,1,0,SPONGE:0)
Block(6,1,1,WOOD_STAIRS:4)
Block(6,1,2,COBBLESTONE_STAIRS:0)
Block(6,1,3,COBBLESTONE)
Block(6,1,4,COBBLE_WALL:0)
Block(6,1,5,VINE:6)
Block(6,1,6,DARK_OAK_FENCE:0)
Block(6,1,7,LOG:2)
Block(6,1,8,MONSTER_EGGS:4)
Block(6,2,-7,SMOOTH_BRICK:0)
Block(6,2,-6,LOG:2)
Block(6,2,-5,BOOKSHELF)
Block(6,2,-4,BOOKSHELF)
Block(6,2,-3,DARK_OAK_STAIRS:6)
Block(6,2,-2,VINE:3)
Block(6,2,-1,COBBLE_WALL:0)
Block(6,2,0,VINE:8)
Block(6,2,1,DARK_OAK_STAIRS:4)
Block(6,2,2,GLASS)
Block(6,2,3,COBBLE_WALL:0)
Block(6,2,4,VINE:8)
Block(6,2,5,VINE:6)
Block(6,2,6,DARK_OAK_FENCE:0)
Block(6,2,7,LEAVES:15)
Block(6,2,8,STONE:0)
Block(6,3,-7,SMOOTH_BRICK:0)
Block(6,3,-6,LOG:2)
Block(6,3,-5,BOOKSHELF)
Block(6,3,-4,WOOD:0)
Block(6,3,-3,DARK_OAK_STAIRS:6)
Block(6,3,-2,VINE:3)
Block(6,3,-1,WEB)
Block(6,3,0,VINE:8)
Block(6,3,1,DARK_OAK_STAIRS:4)
Block(6,3,2,DARK_OAK_FENCE:0)
Block(6,3,3,WEB)
Block(6,3,4,VINE:8)
Block(6,3,5,VINE:6)
Block(6,3,6,LEAVES:15)
Block(6,3,7,VINE:14)
Block(6,3,8,SMOOTH_BRICK:0)
Block(6,4,-7,MONSTER_EGGS:4)
Block(6,4,-6,LOG:2)
Block(6,4,-5,BOOKSHELF)
Block(6,4,-4,BOOKSHELF)
Block(6,4,-3,DARK_OAK_STAIRS:3)
Block(6,4,-2,VINE:8)
Block(6,4,-1,GLASS)
Block(6,4,0,VINE:8)
Block(6,4,1,DARK_OAK_STAIRS:1)
Block(6,4,2,LEAVES:15)
Block(6,4,3,GLASS)
Block(6,4,4,VINE:8)
Block(6,4,5,VINE:6)
Block(6,4,6,LEAVES:15)
Block(6,4,7,VINE:14)
Block(6,4,8,SMOOTH_BRICK:0)
Block(6,5,-7,MONSTER_EGGS:4)
Block(6,5,-6,LEAVES:7)
Block(6,5,-5,LEAVES:7)
Block(6,5,-4,LEAVES:7)
Block(6,5,-3,LEAVES:4)
Block(6,5,-2,LEAVES:4)
Block(6,5,-1,LEAVES:4)
Block(6,5,0,VINE:8)
Block(6,5,1,GLASS)
Block(6,5,2,GLASS)
Block(6,5,3,GLASS)
Block(6,5,4,VINE:8)
Block(6,5,5,LEAVES:7)
Block(6,5,6,COBBLESTONE)
Block(6,5,7,VINE:14)
Block(6,5,8,SMOOTH_BRICK:0)
Block(6,6,-7,MONSTER_EGGS:4)
Block(6,6,-6,VINE:9)
Block(6,6,-5,GLASS)
Block(6,6,-4,LEAVES:4)
Block(6,6,-3,LEAVES:4)
Block(6,6,-2,LEAVES:4)
Block(6,6,-1,LEAVES:4)
Block(6,6,0,LEAVES:4)
Block(6,6,1,LEAVES:4)
Block(6,6,2,LEAVES:4)
Block(6,6,3,LEAVES:7)
Block(6,6,4,LEAVES:7)
Block(6,6,5,COBBLESTONE)
Block(6,6,6,COBBLESTONE)
Block(6,6,7,VINE:14)
Block(6,6,8,SMOOTH_BRICK:0)
Block(6,7,-7,SMOOTH_BRICK:0)
Block(6,7,-6,VINE:9)
Block(6,7,-5,STONE:0)
Block(6,7,-4,STONE:0)
Block(6,7,-3,GLASS)
Block(6,7,-2,COBBLESTONE)
Block(6,7,-1,STONE:0)
Block(6,7,0,COBBLESTONE)
Block(6,7,1,COBBLESTONE)
Block(6,7,2,LEAVES:4)
Block(6,7,3,COBBLESTONE)
Block(6,7,4,STONE:0)
Block(6,7,5,STONE:0)
Block(6,7,6,COBBLESTONE)
Block(6,7,7,LEAVES:4)
Block(6,7,8,MONSTER_EGGS:4)
Block(6,8,-7,STONE:0)
Block(6,8,-6,STONE:0)
Block(6,8,-5,STONE:0)
Block(6,8,-4,STONE:0)
Block(6,8,-3,STONE:0)
Block(6,8,-2,COBBLESTONE)
Block(6,8,-1,STONE:0)
Block(6,8,0,STONE:0)
Block(6,8,1,STONE:0)
Block(6,8,2,STONE:0)
Block(6,8,3,STONE:0)
Block(6,8,4,STONE:0)
Block(6,8,5,STONE:0)
Block(6,8,6,STONE:0)
Block(6,8,7,STONE:0)
Block(6,8,8,STONE:0)
Block(6,9,-7,STONE:0)
Block(6,9,-6,STONE:0)
Block(6,9,-5,STONE:0)
Block(6,9,-4,STONE:0)
Block(6,9,-3,STONE:0)
Block(6,9,-2,STONE:0)
Block(6,9,-1,STONE:0)
Block(6,9,0,STONE:0)
Block(6,9,1,STONE:0)
Block(6,9,2,STONE:0)
Block(6,9,3,STONE:0)
Block(6,9,4,STONE:0)
Block(6,9,5,STONE:0)
Block(6,9,6,STONE:0)
Block(6,9,7,STONE:0)
Block(6,9,8,STONE:0)
Block(7,0,-7,MONSTER_EGGS:4)
Block(7,0,-6,MONSTER_EGGS:4)
Block(7,0,-5,SMOOTH_BRICK:0)
Block(7,0,-4,MONSTER_EGGS:4)
Block(7,0,-3,SMOOTH_BRICK:0)
Block(7,0,-2,SMOOTH_BRICK:0)
Block(7,0,-1,SMOOTH_BRICK:0)
Block(7,0,0,SMOOTH_BRICK:0)
Block(7,0,1,SMOOTH_BRICK:0)
Block(7,0,2,SMOOTH_BRICK:0)
Block(7,0,3,SMOOTH_BRICK:0)
Block(7,0,4,SMOOTH_BRICK:0)
Block(7,0,5,SMOOTH_BRICK:0)
Block(7,0,6,SMOOTH_BRICK:0)
Block(7,0,7,MONSTER_EGGS:4)
Block(7,0,8,MONSTER_EGGS:4)
Block(7,1,-7,SMOOTH_BRICK:0)
Block(7,1,-6,SMOOTH_BRICK:0)
Block(7,1,-5,SMOOTH_BRICK:0)
Block(7,1,-4,STONE:0)
Block(7,1,-3,SMOOTH_BRICK:0)
Block(7,1,-2,MONSTER_EGGS:4)
Block(7,1,-1,SMOOTH_BRICK:0)
Block(7,1,0,MONSTER_EGGS:4)
Block(7,1,1,SMOOTH_BRICK:0)
Block(7,1,2,SMOOTH_BRICK:0)
Block(7,1,3,SMOOTH_BRICK:0)
Block(7,1,4,SMOOTH_BRICK:0)
Block(7,1,5,STONE:0)
Block(7,1,6,SMOOTH_BRICK:0)
Block(7,1,7,MONSTER_EGGS:4)
Block(7,1,8,MONSTER_EGGS:4)
Block(7,2,-7,MONSTER_EGGS:4)
Block(7,2,-6,SMOOTH_BRICK:0)
Block(7,2,-5,SMOOTH_BRICK:0)
Block(7,2,-4,SMOOTH_BRICK:0)
Block(7,2,-3,STONE:0)
Block(7,2,-2,MONSTER_EGGS:4)
Block(7,2,-1,MONSTER_EGGS:4)
Block(7,2,0,STONE:0)
Block(7,2,1,SMOOTH_BRICK:0)
Block(7,2,2,STONE:0)
Block(7,2,3,MONSTER_EGGS:4)
Block(7,2,4,SMOOTH_BRICK:0)
Block(7,2,5,SMOOTH_BRICK:0)
Block(7,2,6,SMOOTH_BRICK:0)
Block(7,2,7,SMOOTH_BRICK:0)
Block(7,2,8,MONSTER_EGGS:4)
Block(7,3,-7,MONSTER_EGGS:4)
Block(7,3,-6,SMOOTH_BRICK:0)
Block(7,3,-5,SMOOTH_BRICK:0)
Block(7,3,-4,SMOOTH_BRICK:0)
Block(7,3,-3,SMOOTH_BRICK:0)
Block(7,3,-2,SMOOTH_BRICK:0)
Block(7,3,-1,MONSTER_EGGS:4)
Block(7,3,0,SMOOTH_BRICK:0)
Block(7,3,1,MONSTER_EGGS:4)
Block(7,3,2,SMOOTH_BRICK:0)
Block(7,3,3,MONSTER_EGGS:4)
Block(7,3,4,SMOOTH_BRICK:0)
Block(7,3,5,STONE:0)
Block(7,3,6,SMOOTH_BRICK:0)
Block(7,3,7,SMOOTH_BRICK:0)
Block(7,3,8,STONE:0)
Block(7,4,-7,STONE:0)
Block(7,4,-6,MONSTER_EGGS:4)
Block(7,4,-5,SMOOTH_BRICK:0)
Block(7,4,-4,SMOOTH_BRICK:0)
Block(7,4,-3,SMOOTH_BRICK:0)
Block(7,4,-2,SMOOTH_BRICK:0)
Block(7,4,-1,SMOOTH_BRICK:0)
Block(7,4,0,SMOOTH_BRICK:0)
Block(7,4,1,SMOOTH_BRICK:0)
Block(7,4,2,MONSTER_EGGS:4)
Block(7,4,3,SMOOTH_BRICK:0)
Block(7,4,4,STONE:0)
Block(7,4,5,SMOOTH_BRICK:0)
Block(7,4,6,MONSTER_EGGS:4)
Block(7,4,7,SMOOTH_BRICK:0)
Block(7,4,8,SMOOTH_BRICK:0)
Block(7,5,-7,STONE:0)
Block(7,5,-6,MONSTER_EGGS:4)
Block(7,5,-5,SMOOTH_BRICK:0)
Block(7,5,-4,STONE:0)
Block(7,5,-3,SMOOTH_BRICK:0)
Block(7,5,-2,MONSTER_EGGS:4)
Block(7,5,-1,SMOOTH_BRICK:0)
Block(7,5,0,SMOOTH_BRICK:0)
Block(7,5,1,SMOOTH_BRICK:0)
Block(7,5,2,STONE:0)
Block(7,5,3,SMOOTH_BRICK:0)
Block(7,5,4,SMOOTH_BRICK:0)
Block(7,5,5,MONSTER_EGGS:4)
Block(7,5,6,SMOOTH_BRICK:0)
Block(7,5,7,MONSTER_EGGS:4)
Block(7,5,8,SMOOTH_BRICK:0)
Block(7,6,-7,SMOOTH_BRICK:0)
Block(7,6,-6,SMOOTH_BRICK:0)
Block(7,6,-5,STONE:0)
Block(7,6,-4,SMOOTH_BRICK:0)
Block(7,6,-3,MONSTER_EGGS:4)
Block(7,6,-2,MONSTER_EGGS:4)
Block(7,6,-1,MONSTER_EGGS:4)
Block(7,6,0,STONE:0)
Block(7,6,1,SMOOTH_BRICK:0)
Block(7,6,2,SMOOTH_BRICK:0)
Block(7,6,3,SMOOTH_BRICK:0)
Block(7,6,4,MONSTER_EGGS:4)
Block(7,6,5,SMOOTH_BRICK:0)
Block(7,6,6,SMOOTH_BRICK:0)
Block(7,6,7,MONSTER_EGGS:4)
Block(7,6,8,SMOOTH_BRICK:0)
Block(7,7,-7,MONSTER_EGGS:4)
Block(7,7,-6,SMOOTH_BRICK:0)
Block(7,7,-5,SMOOTH_BRICK:0)
Block(7,7,-4,SMOOTH_BRICK:0)
Block(7,7,-3,MONSTER_EGGS:4)
Block(7,7,-2,STONE:0)
Block(7,7,-1,SMOOTH_BRICK:0)
Block(7,7,0,SMOOTH_BRICK:0)
Block(7,7,1,MONSTER_EGGS:4)
Block(7,7,2,SMOOTH_BRICK:0)
Block(7,7,3,SMOOTH_BRICK:0)
Block(7,7,4,STONE:0)
Block(7,7,5,SMOOTH_BRICK:0)
Block(7,7,6,SMOOTH_BRICK:0)
Block(7,7,7,SMOOTH_BRICK:0)
Block(7,7,8,SMOOTH_BRICK:0)
Block(7,8,-7,STONE:0)
Block(7,8,-6,STONE:0)
Block(7,8,-5,STONE:0)
Block(7,8,-4,STONE:0)
Block(7,8,-3,STONE:0)
Block(7,8,-2,STONE:0)
Block(7,8,-1,STONE:0)
Block(7,8,0,STONE:0)
Block(7,8,1,STONE:0)
Block(7,8,2,STONE:0)
Block(7,8,3,STONE:0)
Block(7,8,4,STONE:0)
Block(7,8,5,STONE:0)
Block(7,8,6,STONE:0)
Block(7,8,7,STONE:0)
Block(7,8,8,STONE:0)
Block(7,9,-7,STONE:0)
Block(7,9,-6,STONE:0)
Block(7,9,-5,STONE:0)
Block(7,9,-4,STONE:0)
Block(7,9,-3,STONE:0)
Block(7,9,-2,STONE:0)
Block(7,9,-1,STONE:0)
Block(7,9,0,STONE:0)
Block(7,9,1,STONE:0)
Block(7,9,2,STONE:0)
Block(7,9,3,STONE:0)
Block(7,9,4,STONE:0)
Block(7,9,5,STONE:0)
Block(7,9,6,STONE:0)
Block(7,9,7,STONE:0)
Block(7,9,8,STONE:0)

#######################################################################
# +-----------------------------------------------------------------+ #
# |                             ModData                             | #
# +-----------------------------------------------------------------+ #
#######################################################################

# Currently only available for MCW, this feature will be added to OTG+ a.s.a.p.# Use the ModData() tag to include data that other mods can use
# ModData(x,y,z,ModName,DataText)
# Example: ModData(x,y,z,MyCystomNPCMod,SpawnBobHere/WithAPotato/And50Health)
# MCW has some built in ModData commands for basic mob and block spawning.
# These are mostly just a demonstration for mod makers to show how ModData.
# can be used by other mods.
# For mob spawning in MCW use: ModData(x,y,z,TC/MCW,mob/MobType/Count/Persistent/Name)
# mob: Makes MCW recognise this as a mob spawning command.
# MobType: Lower-case, no spaces. Any vanilla mob like dragon, skeleton, wither, villager etc
# Count: The number of mobs to spawn
# Persistent (true/false): Should the mobs never de-spawn? If set to true the mob will get a
# name-tag ingame so you can recognise it.
# Name: A name-tag for the monster/npc.
# Example: ModData(0,0,0,TC/MCW,villager/1/true/Bob)
# For a complete list of possible creatures check the mc forums or the mctcp forums.
# To spawn blocks using ModData use: ModData(x,y,z,TC/MCW,block/material)
# block: Makes MCW recognise this as a block spawning command.
# material: id or text, custom blocks can be added using ModName:MaterialName.
# To send all ModData within a radius in chunks around the player to the specified mod
# use this console command: /mcw GetModData ModName Radius
# ModName: name of the mod, for MCW commands use TC/MCW
# Radius (optional): Radius in chunks around the player.
# Mod makers can use ModData and the /mcw GetModData command to test IMC communications between MCW
# and their mod.
# Normal users can use it to spawn some mobs and blocks on command!

#######################################################################
# +-----------------------------------------------------------------+ #
# |                             Entities                            | #
# +-----------------------------------------------------------------+ #
#######################################################################

# Entity() spawns an entity instead of a block. The entity is spawned only once when the BO3 is spawned.
# Entities are persistent by default so they don't de-spawn when no player is near, they are only unloaded.
# Usage: Entity(x,y,z,mobName,groupSize,NameTagOrNBTFileName) or Entity(x,y,z,mobName,groupSize)
# Use /tc entities or /otg entities to get a list of entities that can be used as mobName, this includes entities added by other mods.
# NameTagOrNBTFileName can be either a nametag for the mob or an nbt file (such as mymobinfo.nbt or mymobinfo.txt).
# When using a text file you can use the same mob spawning parameters used with the /summon command to equip the
# entity and give it custom attributes etc. You can copy the DATA part of a summon command including surrounding
# curly braces to a .txt file, for instance for: "/summon Skeleton x y z {DATA}"

#######################################################################
# +-----------------------------------------------------------------+ #
# |                             Spawners                            | #
# +-----------------------------------------------------------------+ #
#######################################################################

# Currently only available for MCW, this feature will be added to OTG+ a.s.a.p.# Spawner(x,y,z,EntityType,count,interval,chance,max,despawnTime,velocityX,velocityY,velocityZ,yaw,pitch) tag for BO3's,
# works just like the Block() tag and is spawned when the BO3 is spawned. Spawners are invisible ingame but can be blocked
# up with a solid or liquid block (depending on if the entity being spawned can spawn in those blocks) to prevent entities
# from spawning. A spawner tries to spawn <count> number of <entityType> each <interval> seconds, with each entity having
# a spawn chance of <chance>%. The spawner can only spawn an entity if there are not more than <max> of the same EntityType
# in the surrounding chunks (3x3 chunk area centered on the spawner). If an entity is assigned a <despawnTime> in seconds
# then the entity will automatically be despawned after the specified time. Entities spawned using a Spawner will have the
# same light level requirements as they do when they normally spawn in the world, so most monsters only spawn in the dark.
# A spawner will not spawn if the spawn location is blocked by another entity, it can however spawn multiple mobs at once.
# The last 6 parameters are optional and are set to 0 by default (despawnTime,velocityX,velocityY,velocityZ,yaw,pitch), you
# only need to add as many of those parameters as you need. So for instance all of these work: "Spawner(0,0,0,Arrow,1,5,100,5)"
# "Spawner(0,0,0,Arrow,1,5,100,5, 1,0,1)" "Spawner(0,0,0,Arrow,1,5,100,5,1,0,1,180,180)"
# Use the /mcw entities or /otg entities console command (ops only) to see a list of available entityTypes.

#######################################################################
# +-----------------------------------------------------------------+ #
# |                             Particles                           | #
# +-----------------------------------------------------------------+ #
#######################################################################

# Currently only available for MCW, this feature will be added to OTG+ a.s.a.p.# Continually spawns particles in the world at the specified coordinates, interval and velocity.
# For a list of particles use /mcw particles or /otg particles.
# When no velocity is supplied a small random velocity is used.
# Particles will disappear if a solid block is placed on them for at least one second.
# Usage1: Particle(x, y , z, particleName, interval
# Usage2: Particle(x, y , z, particleName, interval, velocityX, velocityY, velocityZ)

#######################################################################
# +-----------------------------------------------------------------+ #
# |                            BO3 checks                           | #
# +-----------------------------------------------------------------+ #
#######################################################################

# This settings is disabled for MCW/OTG+.

#######################################################################
# +-----------------------------------------------------------------+ #
# |                             Branches                            | #
# +-----------------------------------------------------------------+ #
#######################################################################

# Check the otg docs, mctcp forums, the mc forums and PeeGee85 YT channel for.
# Documentation and tutorials for the branching features.
# Branch(x,y,z,isBranchEnding,branchName,rotation,chance,branchLength)
# branchName - filename of the object to spawn (without extension).
# rotation - NORTH, SOUTH, EAST or WEST.
# chance - Chance to spawn between 0 and 100

# WeightedBranch(x,y,z,isBranchEnding,branchName,rotation,chance,branchLength,[anotherBranchName,rotation,chance,branchLength[,...]],maxChanceOutOf)
# maxChanceOutOf - The chance all branches have to spawn out of, assumed to be 100 when left blank
# Example: WeightedBranch(0,0,0,true,RandomInterior1,NORTH,20,0,RandomInterior2,NORTH,20,0,RandomInterior3,NORTH,20,0,RandomInterior4,NORTH,20,0)
