










Author: Zedd Grayhem


Description: No description given


SettingsMode: WriteDisable










Frequency: 10



RotateRandomly: false


SpawnHeight: randomY






MinHeight: 100


MaxHeight: 110


InheritBO3:


InheritBO3Rotation: NORTH


OverrideChildSettings: true


OverrideParentHeight: false


CanOverride: true


BranchFrequency: 0


BranchFrequencyGroup:


MustBeBelowOther: false


MustBeInside: branchingCorridorE branchingCorridorN branchingCorridorS branchingCorridorW


CannotBeInside: PLUS


ReplacesBO3: TNorth, TSouth, TWest, TEast, IEastWest, INorthSouth, LNorth, LSouth, LWest, LEast, EWest, EEast, ENorth, ESouth


CanSpawnOnWater: true


SpawnOnWaterOnly: false


SpawnUnderWater: false


SpawnAtWaterLevel: false


HeightOffset: 0


RemoveBLANK: false


ReplaceAbove:


ReplaceBelow:


replaceWithBiomeBlocks: false


ReplaceWithGroundBlock: DIRT


ReplaceWithSurfaceBlock: GRASS


SmoothRadius: 0


SmoothHeightOffset: 0


SmoothStartTop: false


SmoothStartWood: false


SmoothingSurfaceBlock:


SmoothingGroundBlock:


BO3Group:


IsSpawnPoint: false





















Block(-8,0,0,BLANK)
Block(-8,0,1,BLANK)
Block(-8,1,0,BLANK)
Block(-8,1,1,BLANK)
Block(-8,2,0,BLANK)
Block(-8,2,1,BLANK)
Block(-8,3,0,BLANK)
Block(-8,3,1,BLANK)
Block(-8,4,0,BLANK)
Block(-8,4,1,BLANK)
Block(-8,5,0,BLANK)
Block(-8,5,1,BLANK)
Block(-8,6,0,BLANK)
Block(-8,6,1,BLANK)
Block(-7,0,0,BLANK)
Block(-7,0,1,BLANK)
Block(-7,1,0,BLANK)
Block(-7,1,1,BLANK)
Block(-7,2,0,BLANK)
Block(-7,2,1,BLANK)
Block(-7,3,0,BLANK)
Block(-7,3,1,BLANK)
Block(-7,4,0,BLANK)
Block(-7,4,1,BLANK)
Block(-7,5,0,BLANK)
Block(-7,5,1,BLANK)
Block(-7,6,0,BLANK)
Block(-7,6,1,BLANK)
Block(-6,0,0,BLANK)
Block(-6,0,1,BLANK)
Block(-6,1,0,BLANK)
Block(-6,1,1,BLANK)
Block(-6,2,0,BLANK)
Block(-6,2,1,BLANK)
Block(-6,3,0,BLANK)
Block(-6,3,1,BLANK)
Block(-6,4,0,BLANK)
Block(-6,4,1,BLANK)
Block(-6,5,0,BLANK)
Block(-6,5,1,BLANK)
Block(-6,6,0,BLANK)
Block(-6,6,1,BLANK)
Block(-5,0,0,BLANK)
Block(-5,0,1,BLANK)
Block(-5,1,0,BLANK)
Block(-5,1,1,BLANK)
Block(-5,2,0,BLANK)
Block(-5,2,1,BLANK)
Block(-5,3,0,BLANK)
Block(-5,3,1,BLANK)
Block(-5,4,0,BLANK)
Block(-5,4,1,BLANK)
Block(-5,5,0,BLANK)
Block(-5,5,1,BLANK)
Block(-5,6,0,BLANK)
Block(-5,6,1,BLANK)
Block(-4,0,0,BLANK)
Block(-4,0,1,BLANK)
Block(-4,1,0,BLANK)
Block(-4,1,1,BLANK)
Block(-4,2,0,BLANK)
Block(-4,2,1,BLANK)
Block(-4,3,0,BLANK)
Block(-4,3,1,BLANK)
Block(-4,4,0,BLANK)
Block(-4,4,1,BLANK)
Block(-4,5,0,BLANK)
Block(-4,5,1,BLANK)
Block(-4,6,0,BLANK)
Block(-4,6,1,BLANK)
Block(-3,0,0,BLANK)
Block(-3,0,1,BLANK)
Block(-3,1,0,BLANK)
Block(-3,1,1,BLANK)
Block(-3,2,0,BLANK)
Block(-3,2,1,BLANK)
Block(-3,3,0,BLANK)
Block(-3,3,1,BLANK)
Block(-3,4,0,BLANK)
Block(-3,4,1,BLANK)
Block(-3,5,0,BLANK)
Block(-3,5,1,BLANK)
Block(-3,6,0,BLANK)
Block(-3,6,1,BLANK)
Block(-2,0,0,BLANK)
Block(-2,0,1,BLANK)
Block(-2,1,0,BLANK)
Block(-2,1,1,BLANK)
Block(-2,2,0,BLANK)
Block(-2,2,1,BLANK)
Block(-2,3,0,BLANK)
Block(-2,3,1,BLANK)
Block(-2,4,0,BLANK)
Block(-2,4,1,BLANK)
Block(-2,5,0,BLANK)
Block(-2,5,1,BLANK)
Block(-2,6,0,BLANK)
Block(-2,6,1,BLANK)
Block(-1,0,-7,BLANK)
Block(-1,0,-6,BLANK)
Block(-1,0,-5,BLANK)
Block(-1,0,-4,BLANK)
Block(-1,0,-3,BLANK)
Block(-1,0,-2,BLANK)
Block(-1,0,-1,BLANK)
Block(-1,0,0,BLANK)
Block(-1,0,1,BLANK)
Block(-1,0,2,BLANK)
Block(-1,0,3,BLANK)
Block(-1,0,4,BLANK)
Block(-1,0,5,BLANK)
Block(-1,0,6,BLANK)
Block(-1,0,7,BLANK)
Block(-1,0,8,BLANK)
Block(-1,1,-7,BLANK)
Block(-1,1,-6,BLANK)
Block(-1,1,-5,BLANK)
Block(-1,1,-4,BLANK)
Block(-1,1,-3,BLANK)
Block(-1,1,-2,BLANK)
Block(-1,1,-1,BLANK)
Block(-1,1,0,BLANK)
Block(-1,1,1,BLANK)
Block(-1,1,2,BLANK)
Block(-1,1,3,BLANK)
Block(-1,1,4,BLANK)
Block(-1,1,5,BLANK)
Block(-1,1,6,BLANK)
Block(-1,1,7,BLANK)
Block(-1,1,8,BLANK)
Block(-1,2,-7,BLANK)
Block(-1,2,-6,BLANK)
Block(-1,2,-5,BLANK)
Block(-1,2,-4,BLANK)
Block(-1,2,-3,BLANK)
Block(-1,2,-2,BLANK)
Block(-1,2,-1,BLANK)
Block(-1,2,0,BLANK)
Block(-1,2,1,BLANK)
Block(-1,2,2,BLANK)
Block(-1,2,3,BLANK)
Block(-1,2,4,BLANK)
Block(-1,2,5,BLANK)
Block(-1,2,6,BLANK)
Block(-1,2,7,BLANK)
Block(-1,2,8,BLANK)
Block(-1,3,-7,BLANK)
Block(-1,3,-6,BLANK)
Block(-1,3,-5,BLANK)
Block(-1,3,-4,BLANK)
Block(-1,3,-3,BLANK)
Block(-1,3,-2,BLANK)
Block(-1,3,-1,BLANK)
Block(-1,3,0,BLANK)
Block(-1,3,1,BLANK)
Block(-1,3,2,BLANK)
Block(-1,3,3,BLANK)
Block(-1,3,4,BLANK)
Block(-1,3,5,BLANK)
Block(-1,3,6,BLANK)
Block(-1,3,7,BLANK)
Block(-1,3,8,BLANK)
Block(-1,4,-7,BLANK)
Block(-1,4,-6,BLANK)
Block(-1,4,-5,BLANK)
Block(-1,4,-4,BLANK)
Block(-1,4,-3,BLANK)
Block(-1,4,-2,BLANK)
Block(-1,4,-1,BLANK)
Block(-1,4,0,BLANK)
Block(-1,4,1,BLANK)
Block(-1,4,2,BLANK)
Block(-1,4,3,BLANK)
Block(-1,4,4,BLANK)
Block(-1,4,5,BLANK)
Block(-1,4,6,BLANK)
Block(-1,4,7,BLANK)
Block(-1,4,8,BLANK)
Block(-1,5,-7,BLANK)
Block(-1,5,-6,BLANK)
Block(-1,5,-5,BLANK)
Block(-1,5,-4,BLANK)
Block(-1,5,-3,BLANK)
Block(-1,5,-2,BLANK)
Block(-1,5,-1,BLANK)
Block(-1,5,0,BLANK)
Block(-1,5,1,BLANK)
Block(-1,5,2,BLANK)
Block(-1,5,3,BLANK)
Block(-1,5,4,BLANK)
Block(-1,5,5,BLANK)
Block(-1,5,6,BLANK)
Block(-1,5,7,BLANK)
Block(-1,5,8,BLANK)
Block(-1,6,-7,BLANK)
Block(-1,6,-6,BLANK)
Block(-1,6,-5,BLANK)
Block(-1,6,-4,BLANK)
Block(-1,6,-3,BLANK)
Block(-1,6,-2,BLANK)
Block(-1,6,-1,BLANK)
Block(-1,6,0,BLANK)
Block(-1,6,1,BLANK)
Block(-1,6,2,BLANK)
Block(-1,6,3,BLANK)
Block(-1,6,4,BLANK)
Block(-1,6,5,BLANK)
Block(-1,6,6,BLANK)
Block(-1,6,7,BLANK)
Block(-1,6,8,BLANK)
Block(0,0,-7,BLANK)
Block(0,0,-6,BLANK)
Block(0,0,-5,BLANK)
Block(0,0,-4,BLANK)
Block(0,0,-3,BLANK)
Block(0,0,-2,BLANK)
Block(0,0,-1,BLANK)
Block(0,0,0,BLANK)
Block(0,0,1,BLANK)
Block(0,0,2,BLANK)
Block(0,0,3,BLANK)
Block(0,0,4,BLANK)
Block(0,0,5,BLANK)
Block(0,0,6,BLANK)
Block(0,0,7,BLANK)
Block(0,0,8,BLANK)
Block(0,1,-7,BLANK)
Block(0,1,-6,BLANK)
Block(0,1,-5,BLANK)
Block(0,1,-4,BLANK)
Block(0,1,-3,BLANK)
Block(0,1,-2,BLANK)
Block(0,1,-1,BLANK)
Block(0,1,0,BLANK)
Block(0,1,1,BLANK)
Block(0,1,2,BLANK)
Block(0,1,3,BLANK)
Block(0,1,4,BLANK)
Block(0,1,5,BLANK)
Block(0,1,6,BLANK)
Block(0,1,7,BLANK)
Block(0,1,8,BLANK)
Block(0,2,-7,BLANK)
Block(0,2,-6,BLANK)
Block(0,2,-5,BLANK)
Block(0,2,-4,BLANK)
Block(0,2,-3,BLANK)
Block(0,2,-2,BLANK)
Block(0,2,-1,BLANK)
Block(0,2,0,BLANK)
Block(0,2,1,BLANK)
Block(0,2,2,BLANK)
Block(0,2,3,BLANK)
Block(0,2,4,BLANK)
Block(0,2,5,BLANK)
Block(0,2,6,BLANK)
Block(0,2,7,BLANK)
Block(0,2,8,BLANK)
Block(0,3,-7,BLANK)
Block(0,3,-6,BLANK)
Block(0,3,-5,BLANK)
Block(0,3,-4,BLANK)
Block(0,3,-3,BLANK)
Block(0,3,-2,BLANK)
Block(0,3,-1,BLANK)
Block(0,3,0,BLANK)
Block(0,3,1,BLANK)
Block(0,3,2,BLANK)
Block(0,3,3,BLANK)
Block(0,3,4,BLANK)
Block(0,3,5,BLANK)
Block(0,3,6,BLANK)
Block(0,3,7,BLANK)
Block(0,3,8,BLANK)
Block(0,4,-7,BLANK)
Block(0,4,-6,BLANK)
Block(0,4,-5,BLANK)
Block(0,4,-4,BLANK)
Block(0,4,-3,BLANK)
Block(0,4,-2,BLANK)
Block(0,4,-1,BLANK)
Block(0,4,0,BLANK)
Block(0,4,1,BLANK)
Block(0,4,2,BLANK)
Block(0,4,3,BLANK)
Block(0,4,4,BLANK)
Block(0,4,5,BLANK)
Block(0,4,6,BLANK)
Block(0,4,7,BLANK)
Block(0,4,8,BLANK)
Block(0,5,-7,BLANK)
Block(0,5,-6,BLANK)
Block(0,5,-5,BLANK)
Block(0,5,-4,BLANK)
Block(0,5,-3,BLANK)
Block(0,5,-2,BLANK)
Block(0,5,-1,BLANK)
Block(0,5,0,BLANK)
Block(0,5,1,BLANK)
Block(0,5,2,BLANK)
Block(0,5,3,BLANK)
Block(0,5,4,BLANK)
Block(0,5,5,BLANK)
Block(0,5,6,BLANK)
Block(0,5,7,BLANK)
Block(0,5,8,BLANK)
Block(0,6,-7,BLANK)
Block(0,6,-6,BLANK)
Block(0,6,-5,BLANK)
Block(0,6,-4,BLANK)
Block(0,6,-3,BLANK)
Block(0,6,-2,BLANK)
Block(0,6,-1,BLANK)
Block(0,6,0,BLANK)
Block(0,6,1,BLANK)
Block(0,6,2,BLANK)
Block(0,6,3,BLANK)
Block(0,6,4,BLANK)
Block(0,6,5,BLANK)
Block(0,6,6,BLANK)
Block(0,6,7,BLANK)
Block(0,6,8,BLANK)
Block(1,0,0,BLANK)
Block(1,0,1,BLANK)
Block(1,1,0,BLANK)
Block(1,1,1,BLANK)
Block(1,2,0,BLANK)
Block(1,2,1,BLANK)
Block(1,3,0,BLANK)
Block(1,3,1,BLANK)
Block(1,4,0,BLANK)
Block(1,4,1,BLANK)
Block(1,5,0,BLANK)
Block(1,5,1,BLANK)
Block(1,6,0,BLANK)
Block(1,6,1,BLANK)
Block(2,0,0,BLANK)
Block(2,0,1,BLANK)
Block(2,1,0,BLANK)
Block(2,1,1,BLANK)
Block(2,2,0,BLANK)
Block(2,2,1,BLANK)
Block(2,3,0,BLANK)
Block(2,3,1,BLANK)
Block(2,4,0,BLANK)
Block(2,4,1,BLANK)
Block(2,5,0,BLANK)
Block(2,5,1,BLANK)
Block(2,6,0,BLANK)
Block(2,6,1,BLANK)
Block(3,0,0,BLANK)
Block(3,0,1,BLANK)
Block(3,1,0,BLANK)
Block(3,1,1,BLANK)
Block(3,2,0,BLANK)
Block(3,2,1,BLANK)
Block(3,3,0,BLANK)
Block(3,3,1,BLANK)
Block(3,4,0,BLANK)
Block(3,4,1,BLANK)
Block(3,5,0,BLANK)
Block(3,5,1,BLANK)
Block(3,6,0,BLANK)
Block(3,6,1,BLANK)
Block(4,0,0,BLANK)
Block(4,0,1,BLANK)
Block(4,1,0,BLANK)
Block(4,1,1,BLANK)
Block(4,2,0,BLANK)
Block(4,2,1,BLANK)
Block(4,3,0,BLANK)
Block(4,3,1,BLANK)
Block(4,4,0,BLANK)
Block(4,4,1,BLANK)
Block(4,5,0,BLANK)
Block(4,5,1,BLANK)
Block(4,6,0,BLANK)
Block(4,6,1,BLANK)
Block(5,0,0,BLANK)
Block(5,0,1,BLANK)
Block(5,1,0,BLANK)
Block(5,1,1,BLANK)
Block(5,2,0,BLANK)
Block(5,2,1,BLANK)
Block(5,3,0,BLANK)
Block(5,3,1,BLANK)
Block(5,4,0,BLANK)
Block(5,4,1,BLANK)
Block(5,5,0,BLANK)
Block(5,5,1,BLANK)
Block(5,6,0,BLANK)
Block(5,6,1,BLANK)
Block(6,0,0,BLANK)
Block(6,0,1,BLANK)
Block(6,1,0,BLANK)
Block(6,1,1,BLANK)
Block(6,2,0,BLANK)
Block(6,2,1,BLANK)
Block(6,3,0,BLANK)
Block(6,3,1,BLANK)
Block(6,4,0,BLANK)
Block(6,4,1,BLANK)
Block(6,5,0,BLANK)
Block(6,5,1,BLANK)
Block(6,6,0,BLANK)
Block(6,6,1,BLANK)
Block(7,0,0,BLANK)
Block(7,0,1,BLANK)
Block(7,1,0,BLANK)
Block(7,1,1,BLANK)
Block(7,2,0,BLANK)
Block(7,2,1,BLANK)
Block(7,3,0,BLANK)
Block(7,3,1,BLANK)
Block(7,4,0,BLANK)
Block(7,4,1,BLANK)
Block(7,5,0,BLANK)
Block(7,5,1,BLANK)
Block(7,6,0,BLANK)
Block(7,6,1,BLANK)

Branch(0,0,0,false,PlusDecider,NORTH,100.0,10)
